{"version":8,"blockIdVersion":11,"anchorX":0,"anchorY":0,"anchorZ":0,"blocks":[{"x":-14,"y":0,"z":-14,"name":"Soil_Dirt"},{"x":-14,"y":1,"z":-14,"name":"Soil_Dirt"},{"x":-14,"y":2,"z":-14,"name":"Soil_Dirt"},{"x":-14,"y":3,"z":-14,"name":"Soil_Dirt"},{"x":-14,"y":4,"z":-14,"name":"Soil_Dirt"},{"x":-14,"y":5,"z":-14,"name":"Rock_Stone_Brick_Smooth"},{"x":-14,"y":0,"z":-13,"name":"Soil_Dirt"},{"x":-14,"y":1,"z":-13,"name":"Soil_Dirt"},{"x":-14,"y":2,"z":-13,"name":"Soil_Dirt"},{"x":-14,"y":3,"z":-13,"name":"Soil_Dirt"},{"x":-14,"y":4,"z":-13,"name":"Soil_Dirt"},{"x":-14,"y":5,"z":-13,"name":"Rock_Stone_Brick_Smooth"},{"x":-14,"y":0,"z":-12,"name":"Soil_Dirt"},{"x":-14,"y":1,"z":-12,"name":"Soil_Dirt"},{"x":-14,"y":2,"z":-12,"name":"Soil_Dirt"},{"x":-14,"y":3,"z":-12,"name":"Soil_Dirt"},{"x":-14,"y":4,"z":-12,"name":"Soil_Dirt"},{"x":-14,"y":5,"z":-12,"name":"Rock_Stone_Brick_Smooth"},{"x":-14,"y":0,"z":-11,"name":"Soil_Dirt"},{"x":-14,"y":1,"z":-11,"name":"Soil_Dirt"},{"x":-14,"y":2,"z":-11,"name":"Soil_Dirt"},{"x":-14,"y":3,"z":-11,"name":"Soil_Dirt"},{"x":-14,"y":4,"z":-11,"name":"Soil_Dirt"},{"x":-14,"y":5,"z":-11,"name":"Rock_Stone_Brick_Smooth"},{"x":-14,"y":0,"z":-10,"name":"Soil_Dirt"},{"x":-14,"y":1,"z":-10,"name":"Soil_Dirt"},{"x":-14,"y":2,"z":-10,"name":"Soil_Dirt"},{"x":-14,"y":3,"z":-10,"name":"Soil_Dirt"},{"x":-14,"y":4,"z":-10,"name":"Soil_Dirt"},{"x":-14,"y":5,"z":-10,"name":"Rock_Stone_Brick_Smooth"},{"x":-14,"y":0,"z":-9,"name":"Soil_Dirt"},{"x":-14,"y":1,"z":-9,"name":"Soil_Dirt"},{"x":-14,"y":2,"z":-9,"name":"Soil_Dirt"},{"x":-14,"y":3,"z":-9,"name":"Soil_Dirt"},{"x":-14,"y":4,"z":-9,"name":"Soil_Dirt"},{"x":-14,"y":5,"z":-9,"name":"Rock_Stone_Brick_Smooth"},{"x":-14,"y":0,"z":-8,"name":"Soil_Dirt"},{"x":-14,"y":1,"z":-8,"name":"Soil_Dirt"},{"x":-14,"y":2,"z":-8,"name":"Soil_Dirt"},{"x":-14,"y":3,"z":-8,"name":"Soil_Dirt"},{"x":-14,"y":4,"z":-8,"name":"Soil_Dirt"},{"x":-14,"y":5,"z":-8,"name":"Rock_Stone_Brick_Smooth"},{"x":-14,"y":0,"z":-7,"name":"Soil_Dirt"},{"x":-14,"y":1,"z":-7,"name":"Soil_Dirt"},{"x":-14,"y":2,"z":-7,"name":"Soil_Dirt"},{"x":-14,"y":3,"z":-7,"name":"Soil_Dirt"},{"x":-14,"y":4,"z":-7,"name":"Soil_Dirt"},{"x":-14,"y":5,"z":-7,"name":"Rock_Stone_Brick_Smooth"},{"x":-14,"y":0,"z":-6,"name":"Soil_Dirt"},{"x":-14,"y":1,"z":-6,"name":"Soil_Dirt"},{"x":-14,"y":2,"z":-6,"name":"Soil_Dirt"},{"x":-14,"y":3,"z":-6,"name":"Soil_Dirt"},{"x":-14,"y":4,"z":-6,"name":"Soil_Dirt"},{"x":-14,"y":5,"z":-6,"name":"Rock_Stone_Brick_Smooth"},{"x":-14,"y":0,"z":-5,"name":"Soil_Dirt"},{"x":-14,"y":1,"z":-5,"name":"Soil_Dirt"},{"x":-14,"y":2,"z":-5,"name":"Soil_Dirt"},{"x":-14,"y":3,"z":-5,"name":"Soil_Dirt"},{"x":-14,"y":4,"z":-5,"name":"Soil_Dirt"},{"x":-14,"y":5,"z":-5,"name":"Rock_Stone_Brick_Smooth"},{"x":-14,"y":0,"z":-4,"name":"Soil_Dirt"},{"x":-14,"y":1,"z":-4,"name":"Soil_Dirt"},{"x":-14,"y":2,"z":-4,"name":"Soil_Dirt"},{"x":-14,"y":3,"z":-4,"name":"Soil_Dirt"},{"x":-14,"y":4,"z":-4,"name":"Soil_Dirt"},{"x":-14,"y":5,"z":-4,"name":"Rock_Stone_Brick_Smooth"},{"x":-14,"y":0,"z":-3,"name":"Soil_Dirt"},{"x":-14,"y":1,"z":-3,"name":"Soil_Dirt"},{"x":-14,"y":2,"z":-3,"name":"Soil_Dirt"},{"x":-14,"y":3,"z":-3,"name":"Soil_Dirt"},{"x":-14,"y":4,"z":-3,"name":"Soil_Dirt"},{"x":-14,"y":5,"z":-3,"name":"Rock_Stone_Brick_Smooth"},{"x":-14,"y":0,"z":-2,"name":"Soil_Dirt"},{"x":-14,"y":1,"z":-2,"name":"Soil_Dirt"},{"x":-14,"y":2,"z":-2,"name":"Soil_Dirt"},{"x":-14,"y":3,"z":-2,"name":"Soil_Dirt"},{"x":-14,"y":4,"z":-2,"name":"Soil_Dirt"},{"x":-14,"y":5,"z":-2,"name":"Rock_Stone_Brick_Smooth"},{"x":-14,"y":0,"z":-1,"name":"Soil_Dirt"},{"x":-14,"y":1,"z":-1,"name":"Soil_Dirt"},{"x":-14,"y":2,"z":-1,"name":"Soil_Dirt"},{"x":-14,"y":3,"z":-1,"name":"Soil_Dirt"},{"x":-14,"y":4,"z":-1,"name":"Soil_Dirt"},{"x":-14,"y":5,"z":-1,"name":"Rock_Stone_Brick_Smooth"},{"x":-14,"y":0,"z":0,"name":"Soil_Dirt"},{"x":-14,"y":1,"z":0,"name":"Soil_Dirt"},{"x":-14,"y":2,"z":0,"name":"Soil_Dirt"},{"x":-14,"y":3,"z":0,"name":"Soil_Dirt"},{"x":-14,"y":4,"z":0,"name":"Soil_Dirt"},{"x":-14,"y":5,"z":0,"name":"Rock_Stone_Brick_Smooth"},{"x":-14,"y":0,"z":1,"name":"Soil_Dirt"},{"x":-14,"y":1,"z":1,"name":"Soil_Dirt"},{"x":-14,"y":2,"z":1,"name":"Soil_Dirt"},{"x":-14,"y":3,"z":1,"name":"Soil_Dirt"},{"x":-14,"y":4,"z":1,"name":"Soil_Dirt"},{"x":-14,"y":5,"z":1,"name":"Rock_Stone_Brick_Smooth"},{"x":-14,"y":0,"z":2,"name":"Soil_Dirt"},{"x":-14,"y":1,"z":2,"name":"Soil_Dirt"},{"x":-14,"y":2,"z":2,"name":"Soil_Dirt"},{"x":-14,"y":3,"z":2,"name":"Soil_Dirt"},{"x":-14,"y":4,"z":2,"name":"Soil_Dirt"},{"x":-14,"y":5,"z":2,"name":"Rock_Stone_Brick_Smooth"},{"x":-14,"y":0,"z":3,"name":"Soil_Dirt"},{"x":-14,"y":1,"z":3,"name":"Soil_Dirt"},{"x":-14,"y":2,"z":3,"name":"Soil_Dirt"},{"x":-14,"y":3,"z":3,"name":"Soil_Dirt"},{"x":-14,"y":4,"z":3,"name":"Soil_Dirt"},{"x":-14,"y":5,"z":3,"name":"Rock_Stone_Brick_Smooth"},{"x":-14,"y":0,"z":4,"name":"Soil_Dirt"},{"x":-14,"y":1,"z":4,"name":"Soil_Dirt"},{"x":-14,"y":2,"z":4,"name":"Soil_Dirt"},{"x":-14,"y":3,"z":4,"name":"Soil_Dirt"},{"x":-14,"y":4,"z":4,"name":"Soil_Dirt"},{"x":-14,"y":5,"z":4,"name":"Rock_Stone_Brick_Smooth"},{"x":-14,"y":0,"z":5,"name":"Soil_Dirt"},{"x":-14,"y":1,"z":5,"name":"Soil_Dirt"},{"x":-14,"y":2,"z":5,"name":"Soil_Dirt"},{"x":-14,"y":3,"z":5,"name":"Soil_Dirt"},{"x":-14,"y":4,"z":5,"name":"Soil_Dirt"},{"x":-14,"y":5,"z":5,"name":"Rock_Stone_Brick_Smooth"},{"x":-14,"y":0,"z":6,"name":"Soil_Dirt"},{"x":-14,"y":1,"z":6,"name":"Soil_Dirt"},{"x":-14,"y":2,"z":6,"name":"Soil_Dirt"},{"x":-14,"y":3,"z":6,"name":"Soil_Dirt"},{"x":-14,"y":4,"z":6,"name":"Soil_Dirt"},{"x":-14,"y":5,"z":6,"name":"Rock_Stone_Brick_Smooth"},{"x":-14,"y":0,"z":7,"name":"Soil_Dirt"},{"x":-14,"y":1,"z":7,"name":"Soil_Dirt"},{"x":-14,"y":2,"z":7,"name":"Soil_Dirt"},{"x":-14,"y":3,"z":7,"name":"Soil_Dirt"},{"x":-14,"y":4,"z":7,"name":"Soil_Dirt"},{"x":-14,"y":5,"z":7,"name":"Rock_Stone_Brick_Smooth"},{"x":-14,"y":0,"z":8,"name":"Soil_Dirt"},{"x":-14,"y":1,"z":8,"name":"Soil_Dirt"},{"x":-14,"y":2,"z":8,"name":"Soil_Dirt"},{"x":-14,"y":3,"z":8,"name":"Soil_Dirt"},{"x":-14,"y":4,"z":8,"name":"Soil_Dirt"},{"x":-14,"y":5,"z":8,"name":"Rock_Stone_Brick_Smooth"},{"x":-14,"y":0,"z":9,"name":"Soil_Dirt"},{"x":-14,"y":1,"z":9,"name":"Soil_Dirt"},{"x":-14,"y":2,"z":9,"name":"Soil_Dirt"},{"x":-14,"y":3,"z":9,"name":"Soil_Dirt"},{"x":-14,"y":4,"z":9,"name":"Soil_Dirt"},{"x":-14,"y":5,"z":9,"name":"Rock_Stone_Brick_Smooth"},{"x":-14,"y":0,"z":10,"name":"Soil_Dirt"},{"x":-14,"y":1,"z":10,"name":"Soil_Dirt"},{"x":-14,"y":2,"z":10,"name":"Soil_Dirt"},{"x":-14,"y":3,"z":10,"name":"Soil_Dirt"},{"x":-14,"y":4,"z":10,"name":"Soil_Dirt"},{"x":-14,"y":5,"z":10,"name":"Rock_Stone_Brick_Smooth"},{"x":-14,"y":0,"z":11,"name":"Soil_Dirt"},{"x":-14,"y":1,"z":11,"name":"Soil_Dirt"},{"x":-14,"y":2,"z":11,"name":"Soil_Dirt"},{"x":-14,"y":3,"z":11,"name":"Soil_Dirt"},{"x":-14,"y":4,"z":11,"name":"Soil_Dirt"},{"x":-14,"y":5,"z":11,"name":"Rock_Stone_Brick_Smooth"},{"x":-14,"y":0,"z":12,"name":"Soil_Dirt"},{"x":-14,"y":1,"z":12,"name":"Soil_Dirt"},{"x":-14,"y":2,"z":12,"name":"Soil_Dirt"},{"x":-14,"y":3,"z":12,"name":"Soil_Dirt"},{"x":-14,"y":4,"z":12,"name":"Soil_Dirt"},{"x":-14,"y":5,"z":12,"name":"Rock_Stone_Brick_Smooth"},{"x":-14,"y":0,"z":13,"name":"Soil_Dirt"},{"x":-14,"y":1,"z":13,"name":"Soil_Dirt"},{"x":-14,"y":2,"z":13,"name":"Soil_Dirt"},{"x":-14,"y":3,"z":13,"name":"Soil_Dirt"},{"x":-14,"y":4,"z":13,"name":"Soil_Dirt"},{"x":-14,"y":5,"z":13,"name":"Rock_Stone_Brick_Smooth"},{"x":-14,"y":0,"z":14,"name":"Soil_Dirt"},{"x":-14,"y":1,"z":14,"name":"Soil_Dirt"},{"x":-14,"y":2,"z":14,"name":"Soil_Dirt"},{"x":-14,"y":3,"z":14,"name":"Soil_Dirt"},{"x":-14,"y":4,"z":14,"name":"Soil_Dirt"},{"x":-14,"y":5,"z":14,"name":"Rock_Stone_Brick_Smooth"},{"x":-14,"y":0,"z":15,"name":"Soil_Dirt"},{"x":-14,"y":1,"z":15,"name":"Soil_Dirt"},{"x":-14,"y":2,"z":15,"name":"Soil_Dirt"},{"x":-14,"y":3,"z":15,"name":"Soil_Dirt"},{"x":-14,"y":4,"z":15,"name":"Soil_Dirt"},{"x":-14,"y":5,"z":15,"name":"Rock_Stone_Brick_Smooth"},{"x":-13,"y":0,"z":-14,"name":"Soil_Dirt"},{"x":-13,"y":1,"z":-14,"name":"Soil_Dirt"},{"x":-13,"y":2,"z":-14,"name":"Soil_Dirt"},{"x":-13,"y":3,"z":-14,"name":"Soil_Dirt"},{"x":-13,"y":4,"z":-14,"name":"Soil_Dirt"},{"x":-13,"y":5,"z":-14,"name":"Rock_Stone_Brick_Smooth"},{"x":-13,"y":0,"z":-13,"name":"Soil_Dirt"},{"x":-13,"y":1,"z":-13,"name":"Soil_Dirt"},{"x":-13,"y":2,"z":-13,"name":"Soil_Dirt"},{"x":-13,"y":3,"z":-13,"name":"Soil_Dirt"},{"x":-13,"y":4,"z":-13,"name":"Soil_Dirt"},{"x":-13,"y":5,"z":-13,"name":"Soil_Grass_Sunny","support":15},{"x":-13,"y":6,"z":-13,"name":"Plant_Grass_Sharp"},{"x":-13,"y":0,"z":-12,"name":"Soil_Dirt"},{"x":-13,"y":1,"z":-12,"name":"Soil_Dirt"},{"x":-13,"y":2,"z":-12,"name":"Soil_Dirt"},{"x":-13,"y":3,"z":-12,"name":"Soil_Dirt"},{"x":-13,"y":4,"z":-12,"name":"Soil_Dirt"},{"x":-13,"y":5,"z":-12,"name":"Soil_Grass_Sunny","support":15},{"x":-13,"y":6,"z":-12,"name":"Plant_Grass_Sharp_Short"},{"x":-13,"y":0,"z":-11,"name":"Soil_Dirt"},{"x":-13,"y":1,"z":-11,"name":"Soil_Dirt"},{"x":-13,"y":2,"z":-11,"name":"Soil_Dirt"},{"x":-13,"y":3,"z":-11,"name":"Soil_Dirt"},{"x":-13,"y":4,"z":-11,"name":"Soil_Dirt"},{"x":-13,"y":5,"z":-11,"name":"Soil_Grass_Sunny","support":15},{"x":-13,"y":6,"z":-11,"name":"Plant_Grass_Sharp_Short"},{"x":-13,"y":0,"z":-10,"name":"Soil_Dirt"},{"x":-13,"y":1,"z":-10,"name":"Soil_Dirt"},{"x":-13,"y":2,"z":-10,"name":"Soil_Dirt"},{"x":-13,"y":3,"z":-10,"name":"Soil_Dirt"},{"x":-13,"y":4,"z":-10,"name":"Soil_Dirt"},{"x":-13,"y":5,"z":-10,"name":"Soil_Grass_Sunny","support":15},{"x":-13,"y":6,"z":-10,"name":"Plant_Grass_Sharp_Short"},{"x":-13,"y":0,"z":-9,"name":"Soil_Dirt"},{"x":-13,"y":1,"z":-9,"name":"Soil_Dirt"},{"x":-13,"y":2,"z":-9,"name":"Soil_Dirt"},{"x":-13,"y":3,"z":-9,"name":"Soil_Dirt"},{"x":-13,"y":4,"z":-9,"name":"Soil_Dirt"},{"x":-13,"y":5,"z":-9,"name":"Soil_Grass_Sunny","support":15},{"x":-13,"y":6,"z":-9,"name":"Plant_Grass_Sharp_Short"},{"x":-13,"y":0,"z":-8,"name":"Soil_Dirt"},{"x":-13,"y":1,"z":-8,"name":"Soil_Dirt"},{"x":-13,"y":2,"z":-8,"name":"Soil_Dirt"},{"x":-13,"y":3,"z":-8,"name":"Soil_Dirt"},{"x":-13,"y":4,"z":-8,"name":"Soil_Dirt"},{"x":-13,"y":5,"z":-8,"name":"Soil_Grass_Sunny","support":15},{"x":-13,"y":6,"z":-8,"name":"Plant_Grass_Sharp"},{"x":-13,"y":0,"z":-7,"name":"Soil_Dirt"},{"x":-13,"y":1,"z":-7,"name":"Soil_Dirt"},{"x":-13,"y":2,"z":-7,"name":"Soil_Dirt"},{"x":-13,"y":3,"z":-7,"name":"Soil_Dirt"},{"x":-13,"y":4,"z":-7,"name":"Soil_Dirt"},{"x":-13,"y":5,"z":-7,"name":"Soil_Grass_Sunny","support":15},{"x":-13,"y":6,"z":-7,"name":"Plant_Grass_Sharp_Short"},{"x":-13,"y":0,"z":-6,"name":"Soil_Dirt"},{"x":-13,"y":1,"z":-6,"name":"Soil_Dirt"},{"x":-13,"y":2,"z":-6,"name":"Soil_Dirt"},{"x":-13,"y":3,"z":-6,"name":"Soil_Dirt"},{"x":-13,"y":4,"z":-6,"name":"Soil_Dirt"},{"x":-13,"y":5,"z":-6,"name":"Soil_Grass_Sunny","support":15},{"x":-13,"y":6,"z":-6,"name":"Plant_Grass_Sharp_Short"},{"x":-13,"y":0,"z":-5,"name":"Soil_Dirt"},{"x":-13,"y":1,"z":-5,"name":"Soil_Dirt"},{"x":-13,"y":2,"z":-5,"name":"Soil_Dirt"},{"x":-13,"y":3,"z":-5,"name":"Soil_Dirt"},{"x":-13,"y":4,"z":-5,"name":"Soil_Dirt"},{"x":-13,"y":5,"z":-5,"name":"Soil_Grass_Sunny","support":15},{"x":-13,"y":0,"z":-4,"name":"Soil_Dirt"},{"x":-13,"y":1,"z":-4,"name":"Soil_Dirt"},{"x":-13,"y":2,"z":-4,"name":"Soil_Dirt"},{"x":-13,"y":3,"z":-4,"name":"Soil_Dirt"},{"x":-13,"y":4,"z":-4,"name":"Soil_Dirt"},{"x":-13,"y":5,"z":-4,"name":"Soil_Grass_Sunny","support":15},{"x":-13,"y":0,"z":-3,"name":"Soil_Dirt"},{"x":-13,"y":1,"z":-3,"name":"Soil_Dirt"},{"x":-13,"y":2,"z":-3,"name":"Soil_Dirt"},{"x":-13,"y":3,"z":-3,"name":"Soil_Dirt"},{"x":-13,"y":4,"z":-3,"name":"Soil_Dirt"},{"x":-13,"y":5,"z":-3,"name":"Soil_Grass_Sunny","support":15},{"x":-13,"y":0,"z":-2,"name":"Soil_Dirt"},{"x":-13,"y":1,"z":-2,"name":"Soil_Dirt"},{"x":-13,"y":2,"z":-2,"name":"Soil_Dirt"},{"x":-13,"y":3,"z":-2,"name":"Soil_Dirt"},{"x":-13,"y":4,"z":-2,"name":"Soil_Dirt"},{"x":-13,"y":5,"z":-2,"name":"Soil_Grass_Sunny","support":15},{"x":-13,"y":0,"z":-1,"name":"Soil_Dirt"},{"x":-13,"y":1,"z":-1,"name":"Soil_Dirt"},{"x":-13,"y":2,"z":-1,"name":"Soil_Dirt"},{"x":-13,"y":3,"z":-1,"name":"Soil_Dirt"},{"x":-13,"y":4,"z":-1,"name":"Soil_Dirt"},{"x":-13,"y":5,"z":-1,"name":"Soil_Grass_Sunny","support":15},{"x":-13,"y":0,"z":0,"name":"Soil_Dirt"},{"x":-13,"y":1,"z":0,"name":"Soil_Dirt"},{"x":-13,"y":2,"z":0,"name":"Soil_Dirt"},{"x":-13,"y":3,"z":0,"name":"Soil_Dirt"},{"x":-13,"y":4,"z":0,"name":"Soil_Dirt"},{"x":-13,"y":5,"z":0,"name":"Soil_Grass_Sunny","support":15},{"x":-13,"y":6,"z":0,"name":"Plant_Grass_Sharp_Short"},{"x":-13,"y":0,"z":1,"name":"Soil_Dirt"},{"x":-13,"y":1,"z":1,"name":"Soil_Dirt"},{"x":-13,"y":2,"z":1,"name":"Soil_Dirt"},{"x":-13,"y":3,"z":1,"name":"Soil_Dirt"},{"x":-13,"y":4,"z":1,"name":"Soil_Dirt"},{"x":-13,"y":5,"z":1,"name":"Soil_Grass_Sunny","support":15},{"x":-13,"y":0,"z":2,"name":"Soil_Dirt"},{"x":-13,"y":1,"z":2,"name":"Soil_Dirt"},{"x":-13,"y":2,"z":2,"name":"Soil_Dirt"},{"x":-13,"y":3,"z":2,"name":"Soil_Dirt"},{"x":-13,"y":4,"z":2,"name":"Soil_Dirt"},{"x":-13,"y":5,"z":2,"name":"Soil_Grass_Sunny","support":15},{"x":-13,"y":6,"z":2,"name":"Plant_Grass_Sharp"},{"x":-13,"y":0,"z":3,"name":"Soil_Dirt"},{"x":-13,"y":1,"z":3,"name":"Soil_Dirt"},{"x":-13,"y":2,"z":3,"name":"Soil_Dirt"},{"x":-13,"y":3,"z":3,"name":"Soil_Dirt"},{"x":-13,"y":4,"z":3,"name":"Soil_Dirt"},{"x":-13,"y":5,"z":3,"name":"Soil_Grass_Sunny","support":15},{"x":-13,"y":6,"z":3,"name":"Plant_Grass_Sharp"},{"x":-13,"y":0,"z":4,"name":"Soil_Dirt"},{"x":-13,"y":1,"z":4,"name":"Soil_Dirt"},{"x":-13,"y":2,"z":4,"name":"Soil_Dirt"},{"x":-13,"y":3,"z":4,"name":"Soil_Dirt"},{"x":-13,"y":4,"z":4,"name":"Soil_Dirt"},{"x":-13,"y":5,"z":4,"name":"Soil_Grass_Sunny","support":15},{"x":-13,"y":6,"z":4,"name":"Plant_Grass_Sharp_Short"},{"x":-13,"y":0,"z":5,"name":"Soil_Dirt"},{"x":-13,"y":1,"z":5,"name":"Soil_Dirt"},{"x":-13,"y":2,"z":5,"name":"Soil_Dirt"},{"x":-13,"y":3,"z":5,"name":"Soil_Dirt"},{"x":-13,"y":4,"z":5,"name":"Soil_Dirt"},{"x":-13,"y":5,"z":5,"name":"Soil_Grass_Sunny","support":15},{"x":-13,"y":6,"z":5,"name":"Plant_Crop_Mushroom_Common_Brown"},{"x":-13,"y":0,"z":6,"name":"Soil_Dirt"},{"x":-13,"y":1,"z":6,"name":"Soil_Dirt"},{"x":-13,"y":2,"z":6,"name":"Soil_Dirt"},{"x":-13,"y":3,"z":6,"name":"Soil_Dirt","support":15},{"x":-13,"y":4,"z":6,"name":"Soil_Dirt"},{"x":-13,"y":5,"z":6,"name":"Soil_Grass_Sunny","support":15},{"x":-13,"y":0,"z":7,"name":"Soil_Dirt"},{"x":-13,"y":1,"z":7,"name":"Soil_Dirt"},{"x":-13,"y":2,"z":7,"name":"Soil_Dirt"},{"x":-13,"y":3,"z":7,"name":"Soil_Dirt"},{"x":-13,"y":4,"z":7,"name":"Soil_Dirt","support":15},{"x":-13,"y":5,"z":7,"name":"Soil_Grass_Sunny","support":15},{"x":-13,"y":0,"z":8,"name":"Soil_Dirt"},{"x":-13,"y":1,"z":8,"name":"Soil_Dirt"},{"x":-13,"y":2,"z":8,"name":"Soil_Dirt"},{"x":-13,"y":3,"z":8,"name":"Soil_Dirt"},{"x":-13,"y":4,"z":8,"name":"Soil_Dirt"},{"x":-13,"y":5,"z":8,"name":"Soil_Grass_Sunny","support":15},{"x":-13,"y":0,"z":9,"name":"Soil_Dirt"},{"x":-13,"y":1,"z":9,"name":"Soil_Dirt"},{"x":-13,"y":2,"z":9,"name":"Soil_Dirt"},{"x":-13,"y":3,"z":9,"name":"Soil_Dirt"},{"x":-13,"y":4,"z":9,"name":"Soil_Dirt"},{"x":-13,"y":5,"z":9,"name":"Soil_Grass_Sunny","support":15},{"x":-13,"y":0,"z":10,"name":"Soil_Dirt"},{"x":-13,"y":1,"z":10,"name":"Soil_Dirt"},{"x":-13,"y":2,"z":10,"name":"Soil_Dirt"},{"x":-13,"y":3,"z":10,"name":"Soil_Dirt"},{"x":-13,"y":4,"z":10,"name":"Soil_Dirt"},{"x":-13,"y":5,"z":10,"name":"Soil_Grass_Sunny","support":15},{"x":-13,"y":0,"z":11,"name":"Soil_Dirt"},{"x":-13,"y":1,"z":11,"name":"Soil_Dirt"},{"x":-13,"y":2,"z":11,"name":"Soil_Dirt"},{"x":-13,"y":3,"z":11,"name":"Soil_Dirt"},{"x":-13,"y":4,"z":11,"name":"Soil_Dirt"},{"x":-13,"y":5,"z":11,"name":"Soil_Grass_Sunny","support":15},{"x":-13,"y":6,"z":11,"name":"Plant_Grass_Sharp_Short"},{"x":-13,"y":0,"z":12,"name":"Soil_Dirt"},{"x":-13,"y":1,"z":12,"name":"Soil_Dirt"},{"x":-13,"y":2,"z":12,"name":"Soil_Dirt"},{"x":-13,"y":3,"z":12,"name":"Soil_Dirt"},{"x":-13,"y":4,"z":12,"name":"Soil_Dirt"},{"x":-13,"y":5,"z":12,"name":"Soil_Grass_Sunny","support":15},{"x":-13,"y":6,"z":12,"name":"Plant_Grass_Sharp_Short"},{"x":-13,"y":0,"z":13,"name":"Soil_Dirt"},{"x":-13,"y":1,"z":13,"name":"Soil_Dirt"},{"x":-13,"y":2,"z":13,"name":"Soil_Dirt"},{"x":-13,"y":3,"z":13,"name":"Soil_Dirt"},{"x":-13,"y":4,"z":13,"name":"Soil_Dirt"},{"x":-13,"y":5,"z":13,"name":"Soil_Grass_Sunny","support":15},{"x":-13,"y":6,"z":13,"name":"Plant_Grass_Sharp_Short"},{"x":-13,"y":0,"z":14,"name":"Soil_Dirt"},{"x":-13,"y":1,"z":14,"name":"Soil_Dirt"},{"x":-13,"y":2,"z":14,"name":"Soil_Dirt"},{"x":-13,"y":3,"z":14,"name":"Soil_Dirt"},{"x":-13,"y":4,"z":14,"name":"Soil_Dirt"},{"x":-13,"y":5,"z":14,"name":"Soil_Grass_Sunny","support":15},{"x":-13,"y":6,"z":14,"name":"Plant_Flower_Common_Red2","support":15},{"x":-13,"y":0,"z":15,"name":"Soil_Dirt"},{"x":-13,"y":1,"z":15,"name":"Soil_Dirt"},{"x":-13,"y":2,"z":15,"name":"Soil_Dirt"},{"x":-13,"y":3,"z":15,"name":"Soil_Dirt"},{"x":-13,"y":4,"z":15,"name":"Soil_Dirt"},{"x":-13,"y":5,"z":15,"name":"Rock_Stone_Brick_Smooth"},{"x":-12,"y":0,"z":-14,"name":"Soil_Dirt"},{"x":-12,"y":1,"z":-14,"name":"Soil_Dirt"},{"x":-12,"y":2,"z":-14,"name":"Soil_Dirt"},{"x":-12,"y":3,"z":-14,"name":"Soil_Dirt"},{"x":-12,"y":4,"z":-14,"name":"Soil_Dirt"},{"x":-12,"y":5,"z":-14,"name":"Rock_Stone_Brick_Smooth"},{"x":-12,"y":0,"z":-13,"name":"Soil_Dirt"},{"x":-12,"y":1,"z":-13,"name":"Soil_Dirt"},{"x":-12,"y":2,"z":-13,"name":"Soil_Dirt"},{"x":-12,"y":3,"z":-13,"name":"Soil_Dirt"},{"x":-12,"y":4,"z":-13,"name":"Soil_Dirt"},{"x":-12,"y":5,"z":-13,"name":"Soil_Grass_Sunny","support":15},{"x":-12,"y":6,"z":-13,"name":"Plant_Grass_Sharp_Short"},{"x":-12,"y":0,"z":-12,"name":"Soil_Dirt"},{"x":-12,"y":1,"z":-12,"name":"Soil_Dirt"},{"x":-12,"y":2,"z":-12,"name":"Soil_Dirt"},{"x":-12,"y":3,"z":-12,"name":"Soil_Dirt"},{"x":-12,"y":4,"z":-12,"name":"Soil_Dirt"},{"x":-12,"y":5,"z":-12,"name":"Soil_Grass_Sunny","support":15},{"x":-12,"y":6,"z":-12,"name":"Plant_Grass_Sharp_Short"},{"x":-12,"y":0,"z":-11,"name":"Soil_Dirt"},{"x":-12,"y":1,"z":-11,"name":"Soil_Dirt"},{"x":-12,"y":2,"z":-11,"name":"Soil_Dirt"},{"x":-12,"y":3,"z":-11,"name":"Soil_Dirt"},{"x":-12,"y":4,"z":-11,"name":"Soil_Dirt"},{"x":-12,"y":5,"z":-11,"name":"Soil_Pathway"},{"x":-12,"y":0,"z":-10,"name":"Soil_Dirt"},{"x":-12,"y":1,"z":-10,"name":"Soil_Dirt"},{"x":-12,"y":2,"z":-10,"name":"Soil_Dirt"},{"x":-12,"y":3,"z":-10,"name":"Soil_Dirt"},{"x":-12,"y":4,"z":-10,"name":"Soil_Dirt"},{"x":-12,"y":5,"z":-10,"name":"Soil_Pathway"},{"x":-12,"y":0,"z":-9,"name":"Soil_Dirt"},{"x":-12,"y":1,"z":-9,"name":"Soil_Dirt"},{"x":-12,"y":2,"z":-9,"name":"Soil_Dirt"},{"x":-12,"y":3,"z":-9,"name":"Soil_Dirt"},{"x":-12,"y":4,"z":-9,"name":"Soil_Dirt"},{"x":-12,"y":5,"z":-9,"name":"Soil_Pathway"},{"x":-12,"y":6,"z":-9,"name":"Plant_Flower_Common_Red2","support":15},{"x":-12,"y":0,"z":-8,"name":"Soil_Dirt"},{"x":-12,"y":1,"z":-8,"name":"Soil_Dirt"},{"x":-12,"y":2,"z":-8,"name":"Soil_Dirt"},{"x":-12,"y":3,"z":-8,"name":"Soil_Dirt"},{"x":-12,"y":4,"z":-8,"name":"Soil_Dirt"},{"x":-12,"y":5,"z":-8,"name":"Soil_Grass_Sunny"},{"x":-12,"y":6,"z":-8,"name":"Plant_Grass_Sharp_Short"},{"x":-12,"y":0,"z":-7,"name":"Soil_Dirt"},{"x":-12,"y":1,"z":-7,"name":"Soil_Dirt"},{"x":-12,"y":2,"z":-7,"name":"Soil_Dirt"},{"x":-12,"y":3,"z":-7,"name":"Soil_Dirt"},{"x":-12,"y":4,"z":-7,"name":"Soil_Dirt"},{"x":-12,"y":5,"z":-7,"name":"Soil_Clay"},{"x":-12,"y":0,"z":-6,"name":"Soil_Dirt"},{"x":-12,"y":1,"z":-6,"name":"Soil_Dirt"},{"x":-12,"y":2,"z":-6,"name":"Soil_Dirt"},{"x":-12,"y":3,"z":-6,"name":"Soil_Dirt"},{"x":-12,"y":4,"z":-6,"name":"Soil_Dirt"},{"x":-12,"y":5,"z":-6,"name":"Soil_Pathway"},{"x":-12,"y":0,"z":-5,"name":"Soil_Dirt"},{"x":-12,"y":1,"z":-5,"name":"Soil_Dirt"},{"x":-12,"y":2,"z":-5,"name":"Soil_Dirt"},{"x":-12,"y":3,"z":-5,"name":"Soil_Dirt"},{"x":-12,"y":4,"z":-5,"name":"Soil_Dirt"},{"x":-12,"y":5,"z":-5,"name":"Soil_Clay"},{"x":-12,"y":0,"z":-4,"name":"Soil_Dirt"},{"x":-12,"y":1,"z":-4,"name":"Soil_Dirt"},{"x":-12,"y":2,"z":-4,"name":"Soil_Dirt"},{"x":-12,"y":3,"z":-4,"name":"Soil_Dirt"},{"x":-12,"y":4,"z":-4,"name":"Soil_Dirt"},{"x":-12,"y":5,"z":-4,"name":"Soil_Pathway"},{"x":-12,"y":0,"z":-3,"name":"Soil_Dirt"},{"x":-12,"y":1,"z":-3,"name":"Soil_Dirt"},{"x":-12,"y":2,"z":-3,"name":"Soil_Dirt"},{"x":-12,"y":3,"z":-3,"name":"Soil_Dirt"},{"x":-12,"y":4,"z":-3,"name":"Soil_Dirt"},{"x":-12,"y":5,"z":-3,"name":"Soil_Pathway"},{"x":-12,"y":0,"z":-2,"name":"Soil_Dirt"},{"x":-12,"y":1,"z":-2,"name":"Soil_Dirt"},{"x":-12,"y":2,"z":-2,"name":"Soil_Dirt"},{"x":-12,"y":3,"z":-2,"name":"Soil_Dirt"},{"x":-12,"y":4,"z":-2,"name":"Soil_Dirt"},{"x":-12,"y":5,"z":-2,"name":"Soil_Pathway"},{"x":-12,"y":0,"z":-1,"name":"Soil_Dirt"},{"x":-12,"y":1,"z":-1,"name":"Soil_Dirt"},{"x":-12,"y":2,"z":-1,"name":"Soil_Dirt"},{"x":-12,"y":3,"z":-1,"name":"Soil_Dirt"},{"x":-12,"y":4,"z":-1,"name":"Soil_Dirt"},{"x":-12,"y":5,"z":-1,"name":"Soil_Pathway"},{"x":-12,"y":0,"z":0,"name":"Soil_Dirt"},{"x":-12,"y":1,"z":0,"name":"Soil_Dirt"},{"x":-12,"y":2,"z":0,"name":"Soil_Dirt"},{"x":-12,"y":3,"z":0,"name":"Soil_Dirt"},{"x":-12,"y":4,"z":0,"name":"Soil_Dirt"},{"x":-12,"y":5,"z":0,"name":"Soil_Grass_Sunny","support":15},{"x":-12,"y":0,"z":1,"name":"Soil_Dirt"},{"x":-12,"y":1,"z":1,"name":"Soil_Dirt"},{"x":-12,"y":2,"z":1,"name":"Soil_Dirt"},{"x":-12,"y":3,"z":1,"name":"Soil_Dirt"},{"x":-12,"y":4,"z":1,"name":"Soil_Dirt"},{"x":-12,"y":5,"z":1,"name":"Soil_Grass_Sunny","support":15},{"x":-12,"y":6,"z":1,"name":"Plant_Grass_Sharp_Short"},{"x":-12,"y":0,"z":2,"name":"Soil_Dirt"},{"x":-12,"y":1,"z":2,"name":"Soil_Dirt"},{"x":-12,"y":2,"z":2,"name":"Soil_Dirt"},{"x":-12,"y":3,"z":2,"name":"Soil_Dirt"},{"x":-12,"y":4,"z":2,"name":"Soil_Dirt"},{"x":-12,"y":5,"z":2,"name":"Soil_Grass_Sunny","support":15},{"x":-12,"y":6,"z":2,"name":"Plant_Grass_Sharp"},{"x":-12,"y":0,"z":3,"name":"Soil_Dirt"},{"x":-12,"y":1,"z":3,"name":"Soil_Dirt"},{"x":-12,"y":2,"z":3,"name":"Soil_Dirt"},{"x":-12,"y":3,"z":3,"name":"Soil_Dirt","support":15},{"x":-12,"y":4,"z":3,"name":"Soil_Dirt"},{"x":-12,"y":5,"z":3,"name":"Soil_Grass_Sunny","support":15},{"x":-12,"y":6,"z":3,"name":"Plant_Grass_Sharp_Short"},{"x":-12,"y":15,"z":3,"name":"Plant_Leaves_Maple","rotation":2},{"x":-12,"y":16,"z":3,"name":"Plant_Leaves_Maple","rotation":2},{"x":-12,"y":0,"z":4,"name":"Soil_Dirt"},{"x":-12,"y":2,"z":4,"name":"Soil_Dirt"},{"x":-12,"y":3,"z":4,"name":"Soil_Dirt","support":15},{"x":-12,"y":4,"z":4,"name":"Soil_Grass_Sunny","support":15},{"x":-12,"y":5,"z":4,"name":"Plant_Grass_Sharp_Short"},{"x":-12,"y":15,"z":4,"name":"Plant_Leaves_Maple","rotation":2},{"x":-12,"y":16,"z":4,"name":"Plant_Leaves_Maple","rotation":2},{"x":-12,"y":17,"z":4,"name":"Plant_Leaves_Maple","rotation":2},{"x":-12,"y":0,"z":5,"name":"Soil_Dirt"},{"x":-12,"y":2,"z":5,"name":"Soil_Pathway","support":15},{"x":-12,"y":3,"z":5,"name":"Soil_Dirt","support":15},{"x":-12,"y":4,"z":5,"name":"Soil_Grass_Sunny","support":15},{"x":-12,"y":5,"z":5,"name":"Plant_Reeds_Marsh","support":15},{"x":-12,"y":15,"z":5,"name":"Plant_Leaves_Maple","rotation":2},{"x":-12,"y":16,"z":5,"name":"Plant_Leaves_Maple","rotation":2},{"x":-12,"y":17,"z":5,"name":"Plant_Leaves_Maple","rotation":2},{"x":-12,"y":0,"z":6,"name":"Soil_Dirt"},{"x":-12,"y":2,"z":6,"name":"Soil_Dirt","support":15},{"x":-12,"y":3,"z":6,"name":"Soil_Dirt","support":15},{"x":-12,"y":4,"z":6,"name":"Soil_Grass_Sunny","support":15},{"x":-12,"y":15,"z":6,"name":"Plant_Leaves_Maple","rotation":2},{"x":-12,"y":16,"z":6,"name":"Plant_Leaves_Maple","rotation":2},{"x":-12,"y":17,"z":6,"name":"Plant_Leaves_Maple","rotation":2},{"x":-12,"y":0,"z":7,"name":"Soil_Dirt"},{"x":-12,"y":1,"z":7,"name":"Soil_Dirt"},{"x":-12,"y":2,"z":7,"name":"Soil_Dirt","support":15},{"x":-12,"y":3,"z":7,"name":"Soil_Dirt","support":15},{"x":-12,"y":4,"z":7,"name":"Soil_Grass_Sunny","support":15},{"x":-12,"y":16,"z":7,"name":"Plant_Leaves_Maple","rotation":2},{"x":-12,"y":0,"z":8,"name":"Soil_Dirt"},{"x":-12,"y":2,"z":8,"name":"Soil_Pathway","support":15},{"x":-12,"y":3,"z":8,"name":"Soil_Dirt","support":15},{"x":-12,"y":4,"z":8,"name":"Soil_Dirt"},{"x":-12,"y":5,"z":8,"name":"Soil_Grass_Sunny","support":15},{"x":-12,"y":0,"z":9,"name":"Soil_Dirt"},{"x":-12,"y":1,"z":9,"name":"Soil_Dirt"},{"x":-12,"y":2,"z":9,"name":"Soil_Dirt"},{"x":-12,"y":3,"z":9,"name":"Soil_Dirt"},{"x":-12,"y":4,"z":9,"name":"Soil_Dirt"},{"x":-12,"y":5,"z":9,"name":"Soil_Grass_Sunny","support":15},{"x":-12,"y":6,"z":9,"name":"Plant_Crop_Mushroom_Common_Brown"},{"x":-12,"y":0,"z":10,"name":"Soil_Dirt"},{"x":-12,"y":1,"z":10,"name":"Soil_Dirt"},{"x":-12,"y":2,"z":10,"name":"Soil_Dirt"},{"x":-12,"y":3,"z":10,"name":"Soil_Dirt"},{"x":-12,"y":4,"z":10,"name":"Soil_Dirt"},{"x":-12,"y":5,"z":10,"name":"Soil_Grass_Sunny","support":15},{"x":-12,"y":6,"z":10,"name":"Plant_Grass_Sharp_Short"},{"x":-12,"y":0,"z":11,"name":"Soil_Dirt"},{"x":-12,"y":1,"z":11,"name":"Soil_Dirt"},{"x":-12,"y":2,"z":11,"name":"Soil_Dirt"},{"x":-12,"y":3,"z":11,"name":"Soil_Dirt"},{"x":-12,"y":4,"z":11,"name":"Soil_Dirt"},{"x":-12,"y":5,"z":11,"name":"Soil_Grass_Sunny","support":15},{"x":-12,"y":0,"z":12,"name":"Soil_Dirt"},{"x":-12,"y":1,"z":12,"name":"Soil_Dirt"},{"x":-12,"y":2,"z":12,"name":"Soil_Dirt"},{"x":-12,"y":3,"z":12,"name":"Soil_Dirt"},{"x":-12,"y":4,"z":12,"name":"Soil_Dirt"},{"x":-12,"y":5,"z":12,"name":"Soil_Grass_Sunny","support":15},{"x":-12,"y":6,"z":12,"name":"Plant_Grass_Sharp"},{"x":-12,"y":0,"z":13,"name":"Soil_Dirt"},{"x":-12,"y":1,"z":13,"name":"Soil_Dirt"},{"x":-12,"y":2,"z":13,"name":"Soil_Dirt"},{"x":-12,"y":3,"z":13,"name":"Soil_Dirt"},{"x":-12,"y":4,"z":13,"name":"Soil_Dirt"},{"x":-12,"y":5,"z":13,"name":"Soil_Grass_Sunny","support":15},{"x":-12,"y":6,"z":13,"name":"Plant_Grass_Sharp_Short"},{"x":-12,"y":0,"z":14,"name":"Soil_Dirt"},{"x":-12,"y":1,"z":14,"name":"Soil_Dirt"},{"x":-12,"y":2,"z":14,"name":"Soil_Dirt"},{"x":-12,"y":3,"z":14,"name":"Soil_Dirt"},{"x":-12,"y":4,"z":14,"name":"Soil_Dirt"},{"x":-12,"y":5,"z":14,"name":"Soil_Grass_Sunny","support":15},{"x":-12,"y":6,"z":14,"name":"Plant_Grass_Sharp_Short"},{"x":-12,"y":0,"z":15,"name":"Soil_Dirt"},{"x":-12,"y":1,"z":15,"name":"Soil_Dirt"},{"x":-12,"y":2,"z":15,"name":"Soil_Dirt"},{"x":-12,"y":3,"z":15,"name":"Soil_Dirt"},{"x":-12,"y":4,"z":15,"name":"Soil_Dirt"},{"x":-12,"y":5,"z":15,"name":"Rock_Stone_Brick_Smooth"},{"x":-11,"y":0,"z":-14,"name":"Soil_Dirt"},{"x":-11,"y":1,"z":-14,"name":"Soil_Dirt"},{"x":-11,"y":2,"z":-14,"name":"Soil_Dirt"},{"x":-11,"y":3,"z":-14,"name":"Soil_Dirt"},{"x":-11,"y":4,"z":-14,"name":"Soil_Dirt"},{"x":-11,"y":5,"z":-14,"name":"Rock_Stone_Brick_Smooth"},{"x":-11,"y":0,"z":-13,"name":"Soil_Dirt"},{"x":-11,"y":1,"z":-13,"name":"Soil_Dirt"},{"x":-11,"y":2,"z":-13,"name":"Soil_Dirt"},{"x":-11,"y":3,"z":-13,"name":"Soil_Dirt"},{"x":-11,"y":4,"z":-13,"name":"Soil_Dirt"},{"x":-11,"y":5,"z":-13,"name":"Soil_Grass_Sunny","support":15},{"x":-11,"y":6,"z":-13,"name":"Plant_Flower_Common_Yellow2","support":15},{"x":-11,"y":0,"z":-12,"name":"Soil_Dirt"},{"x":-11,"y":1,"z":-12,"name":"Soil_Dirt"},{"x":-11,"y":2,"z":-12,"name":"Soil_Dirt"},{"x":-11,"y":3,"z":-12,"name":"Soil_Dirt"},{"x":-11,"y":4,"z":-12,"name":"Soil_Dirt"},{"x":-11,"y":5,"z":-12,"name":"Soil_Pathway"},{"x":-11,"y":0,"z":-11,"name":"Soil_Dirt"},{"x":-11,"y":1,"z":-11,"name":"Soil_Dirt"},{"x":-11,"y":2,"z":-11,"name":"Soil_Dirt"},{"x":-11,"y":3,"z":-11,"name":"Soil_Dirt"},{"x":-11,"y":4,"z":-11,"name":"Soil_Dirt"},{"x":-11,"y":5,"z":-11,"name":"Soil_Pathway"},{"x":-11,"y":6,"z":-11,"name":"Wood_Hardwood_Decorative"},{"x":-11,"y":7,"z":-11,"name":"Wood_Hardwood_Planks"},{"x":-11,"y":8,"z":-11,"name":"Wood_Hardwood_Planks"},{"x":-11,"y":9,"z":-11,"name":"Wood_Hardwood_Stairs","rotation":3},{"x":-11,"y":0,"z":-10,"name":"Soil_Dirt"},{"x":-11,"y":1,"z":-10,"name":"Soil_Dirt"},{"x":-11,"y":2,"z":-10,"name":"Soil_Dirt"},{"x":-11,"y":3,"z":-10,"name":"Soil_Dirt"},{"x":-11,"y":4,"z":-10,"name":"Soil_Dirt"},{"x":-11,"y":5,"z":-10,"name":"Soil_Dirt"},{"x":-11,"y":6,"z":-10,"name":"Wood_Hardwood_Decorative"},{"x":-11,"y":7,"z":-10,"name":"Wood_Hardwood_Planks"},{"x":-11,"y":9,"z":-10,"name":"Cloth_Modern_Orange_Roof","rotation":3},{"x":-11,"y":0,"z":-9,"name":"Soil_Dirt"},{"x":-11,"y":1,"z":-9,"name":"Soil_Dirt"},{"x":-11,"y":2,"z":-9,"name":"Soil_Dirt"},{"x":-11,"y":3,"z":-9,"name":"Soil_Dirt"},{"x":-11,"y":4,"z":-9,"name":"Soil_Dirt"},{"x":-11,"y":5,"z":-9,"name":"Soil_Dirt"},{"x":-11,"y":6,"z":-9,"name":"Wood_Hardwood_Decorative"},{"x":-11,"y":7,"z":-9,"name":"Wood_Hardwood_Beam"},{"x":-11,"y":8,"z":-9,"name":"Wood_Hardwood_Beam"},{"x":-11,"y":9,"z":-9,"name":"*Cloth_Modern_Orange_Roof_State_Definitions_Corner_Left","rotation":3},{"x":-11,"y":0,"z":-8,"name":"Soil_Dirt"},{"x":-11,"y":1,"z":-8,"name":"Soil_Dirt"},{"x":-11,"y":2,"z":-8,"name":"Soil_Dirt"},{"x":-11,"y":3,"z":-8,"name":"Soil_Dirt"},{"x":-11,"y":4,"z":-8,"name":"Soil_Dirt"},{"x":-11,"y":5,"z":-8,"name":"Soil_Pathway"},{"x":-11,"y":0,"z":-7,"name":"Soil_Dirt"},{"x":-11,"y":1,"z":-7,"name":"Soil_Dirt"},{"x":-11,"y":2,"z":-7,"name":"Soil_Dirt"},{"x":-11,"y":3,"z":-7,"name":"Soil_Dirt"},{"x":-11,"y":4,"z":-7,"name":"Soil_Dirt"},{"x":-11,"y":5,"z":-7,"name":"Soil_Grass_Sunny"},{"x":-11,"y":0,"z":-6,"name":"Soil_Dirt"},{"x":-11,"y":1,"z":-6,"name":"Soil_Dirt"},{"x":-11,"y":2,"z":-6,"name":"Soil_Dirt"},{"x":-11,"y":3,"z":-6,"name":"Soil_Dirt"},{"x":-11,"y":4,"z":-6,"name":"Soil_Dirt"},{"x":-11,"y":5,"z":-6,"name":"Soil_Pathway"},{"x":-11,"y":0,"z":-5,"name":"Soil_Dirt"},{"x":-11,"y":1,"z":-5,"name":"Soil_Dirt"},{"x":-11,"y":2,"z":-5,"name":"Soil_Dirt"},{"x":-11,"y":3,"z":-5,"name":"Soil_Dirt"},{"x":-11,"y":4,"z":-5,"name":"Soil_Dirt"},{"x":-11,"y":5,"z":-5,"name":"Soil_Pathway"},{"x":-11,"y":0,"z":-4,"name":"Soil_Dirt"},{"x":-11,"y":1,"z":-4,"name":"Soil_Dirt"},{"x":-11,"y":2,"z":-4,"name":"Soil_Dirt"},{"x":-11,"y":3,"z":-4,"name":"Soil_Dirt"},{"x":-11,"y":4,"z":-4,"name":"Soil_Dirt"},{"x":-11,"y":5,"z":-4,"name":"Soil_Pathway"},{"x":-11,"y":0,"z":-3,"name":"Soil_Dirt"},{"x":-11,"y":1,"z":-3,"name":"Soil_Dirt"},{"x":-11,"y":2,"z":-3,"name":"Soil_Dirt"},{"x":-11,"y":3,"z":-3,"name":"Soil_Dirt"},{"x":-11,"y":4,"z":-3,"name":"Soil_Dirt"},{"x":-11,"y":5,"z":-3,"name":"Soil_Clay"},{"x":-11,"y":0,"z":-2,"name":"Soil_Dirt"},{"x":-11,"y":1,"z":-2,"name":"Soil_Dirt"},{"x":-11,"y":2,"z":-2,"name":"Soil_Dirt"},{"x":-11,"y":3,"z":-2,"name":"Soil_Dirt"},{"x":-11,"y":4,"z":-2,"name":"Soil_Dirt"},{"x":-11,"y":5,"z":-2,"name":"Soil_Dirt"},{"x":-11,"y":0,"z":-1,"name":"Soil_Dirt"},{"x":-11,"y":1,"z":-1,"name":"Soil_Dirt"},{"x":-11,"y":2,"z":-1,"name":"Soil_Dirt"},{"x":-11,"y":3,"z":-1,"name":"Soil_Dirt"},{"x":-11,"y":4,"z":-1,"name":"Soil_Dirt"},{"x":-11,"y":5,"z":-1,"name":"Soil_Clay"},{"x":-11,"y":0,"z":0,"name":"Soil_Dirt"},{"x":-11,"y":1,"z":0,"name":"Soil_Dirt"},{"x":-11,"y":2,"z":0,"name":"Soil_Dirt"},{"x":-11,"y":3,"z":0,"name":"Soil_Dirt"},{"x":-11,"y":4,"z":0,"name":"Soil_Dirt"},{"x":-11,"y":5,"z":0,"name":"Soil_Pathway"},{"x":-11,"y":0,"z":1,"name":"Soil_Dirt"},{"x":-11,"y":1,"z":1,"name":"Soil_Dirt"},{"x":-11,"y":2,"z":1,"name":"Soil_Dirt"},{"x":-11,"y":3,"z":1,"name":"Soil_Dirt"},{"x":-11,"y":4,"z":1,"name":"Soil_Dirt"},{"x":-11,"y":5,"z":1,"name":"Soil_Grass_Sunny","support":15},{"x":-11,"y":6,"z":1,"name":"Plant_Grass_Sharp_Short"},{"x":-11,"y":0,"z":2,"name":"Soil_Dirt"},{"x":-11,"y":1,"z":2,"name":"Soil_Dirt"},{"x":-11,"y":2,"z":2,"name":"Soil_Dirt"},{"x":-11,"y":3,"z":2,"name":"Soil_Dirt"},{"x":-11,"y":4,"z":2,"name":"Soil_Dirt"},{"x":-11,"y":5,"z":2,"name":"Soil_Grass_Sunny","support":15},{"x":-11,"y":6,"z":2,"name":"Plant_Grass_Sharp_Short"},{"x":-11,"y":14,"z":2,"name":"Plant_Leaves_Maple","rotation":2},{"x":-11,"y":15,"z":2,"name":"Plant_Leaves_Maple","rotation":2},{"x":-11,"y":16,"z":2,"name":"Plant_Leaves_Maple","rotation":2},{"x":-11,"y":17,"z":2,"name":"Plant_Leaves_Maple","rotation":2},{"x":-11,"y":0,"z":3,"name":"Soil_Dirt"},{"x":-11,"y":1,"z":3,"name":"Soil_Dirt"},{"x":-11,"y":2,"z":3,"name":"Soil_Dirt"},{"x":-11,"y":3,"z":3,"name":"Soil_Dirt","support":15},{"x":-11,"y":4,"z":3,"name":"Soil_Dirt","support":15},{"x":-11,"y":5,"z":3,"name":"Soil_Grass_Sunny","support":15},{"x":-11,"y":6,"z":3,"name":"Plant_Grass_Sharp_Short"},{"x":-11,"y":14,"z":3,"name":"Plant_Leaves_Maple","rotation":2},{"x":-11,"y":15,"z":3,"name":"Plant_Leaves_Maple","rotation":2},{"x":-11,"y":17,"z":3,"name":"Plant_Leaves_Maple","rotation":2},{"x":-11,"y":0,"z":4,"name":"Soil_Dirt"},{"x":-11,"y":2,"z":4,"name":"Soil_Pathway","support":15},{"x":-11,"y":3,"z":4,"name":"Soil_Dirt","support":15},{"x":-11,"y":4,"z":4,"name":"Soil_Grass_Sunny","support":15},{"x":-11,"y":6,"z":4,"name":"Plant_Flower_Water_White","support":15},{"x":-11,"y":14,"z":4,"name":"Plant_Leaves_Maple","rotation":2},{"x":-11,"y":16,"z":4,"name":"Wood_Oak_Branch_Long","rotation":7},{"x":-11,"y":17,"z":4,"name":"Plant_Leaves_Maple","rotation":2},{"x":-11,"y":0,"z":5,"name":"Soil_Dirt"},{"x":-11,"y":1,"z":5,"name":"Soil_Dirt"},{"x":-11,"y":2,"z":5,"name":"Soil_Pathway","support":15},{"x":-11,"y":3,"z":5,"name":"Soil_Grass_Sunny","support":15},{"x":-11,"y":15,"z":5,"name":"Plant_Leaves_Maple","rotation":2},{"x":-11,"y":16,"z":5,"name":"Plant_Leaves_Maple","rotation":2},{"x":-11,"y":17,"z":5,"name":"Plant_Leaves_Maple","rotation":2},{"x":-11,"y":18,"z":5,"name":"Plant_Leaves_Maple","rotation":2},{"x":-11,"y":0,"z":6,"name":"Soil_Dirt"},{"x":-11,"y":1,"z":6,"name":"Soil_Dirt"},{"x":-11,"y":2,"z":6,"name":"Soil_Pathway","support":15},{"x":-11,"y":3,"z":6,"name":"Soil_Grass_Sunny","support":15},{"x":-11,"y":15,"z":6,"name":"Plant_Leaves_Maple","rotation":2},{"x":-11,"y":16,"z":6,"name":"Plant_Leaves_Maple","rotation":2},{"x":-11,"y":17,"z":6,"name":"Plant_Leaves_Maple","rotation":2},{"x":-11,"y":0,"z":7,"name":"Soil_Dirt"},{"x":-11,"y":1,"z":7,"name":"Soil_Dirt"},{"x":-11,"y":2,"z":7,"name":"Soil_Dirt","support":15},{"x":-11,"y":3,"z":7,"name":"Soil_Dirt","support":15},{"x":-11,"y":4,"z":7,"name":"Rock_Crystal_Cyan_Small","support":15},{"x":-11,"y":16,"z":7,"name":"Plant_Leaves_Maple","rotation":2},{"x":-11,"y":17,"z":7,"name":"Plant_Leaves_Maple","rotation":2},{"x":-11,"y":18,"z":7,"name":"Plant_Leaves_Maple","rotation":2},{"x":-11,"y":0,"z":8,"name":"Soil_Dirt"},{"x":-11,"y":2,"z":8,"name":"Soil_Dirt","support":15},{"x":-11,"y":3,"z":8,"name":"Soil_Dirt","support":15},{"x":-11,"y":4,"z":8,"name":"Soil_Grass_Sunny","support":15},{"x":-11,"y":15,"z":8,"name":"Plant_Leaves_Maple","rotation":2},{"x":-11,"y":16,"z":8,"name":"Plant_Leaves_Maple","rotation":2},{"x":-11,"y":17,"z":8,"name":"Plant_Leaves_Maple","rotation":2},{"x":-11,"y":18,"z":8,"name":"Plant_Leaves_Maple","rotation":2},{"x":-11,"y":0,"z":9,"name":"Soil_Dirt"},{"x":-11,"y":1,"z":9,"name":"Soil_Dirt"},{"x":-11,"y":3,"z":9,"name":"Soil_Dirt","support":15},{"x":-11,"y":4,"z":9,"name":"Soil_Grass_Sunny"},{"x":-11,"y":16,"z":9,"name":"Plant_Leaves_Maple","rotation":2},{"x":-11,"y":17,"z":9,"name":"Plant_Leaves_Maple","rotation":2},{"x":-11,"y":0,"z":10,"name":"Soil_Dirt"},{"x":-11,"y":1,"z":10,"name":"Soil_Dirt"},{"x":-11,"y":2,"z":10,"name":"Soil_Dirt"},{"x":-11,"y":3,"z":10,"name":"Soil_Dirt"},{"x":-11,"y":4,"z":10,"name":"Soil_Dirt"},{"x":-11,"y":5,"z":10,"name":"Soil_Grass_Sunny","support":15},{"x":-11,"y":6,"z":10,"name":"Plant_Grass_Sharp_Short"},{"x":-11,"y":16,"z":10,"name":"Plant_Leaves_Maple","rotation":2},{"x":-11,"y":0,"z":11,"name":"Soil_Dirt"},{"x":-11,"y":1,"z":11,"name":"Soil_Dirt"},{"x":-11,"y":2,"z":11,"name":"Soil_Dirt"},{"x":-11,"y":3,"z":11,"name":"Soil_Dirt"},{"x":-11,"y":4,"z":11,"name":"Soil_Dirt"},{"x":-11,"y":5,"z":11,"name":"Soil_Grass_Sunny","support":15},{"x":-11,"y":6,"z":11,"name":"Plant_Grass_Sharp"},{"x":-11,"y":0,"z":12,"name":"Soil_Dirt"},{"x":-11,"y":1,"z":12,"name":"Soil_Dirt"},{"x":-11,"y":2,"z":12,"name":"Soil_Dirt"},{"x":-11,"y":3,"z":12,"name":"Soil_Dirt"},{"x":-11,"y":4,"z":12,"name":"Soil_Dirt"},{"x":-11,"y":5,"z":12,"name":"Soil_Grass_Sunny","support":15},{"x":-11,"y":6,"z":12,"name":"Plant_Grass_Sharp_Short"},{"x":-11,"y":0,"z":13,"name":"Soil_Dirt"},{"x":-11,"y":1,"z":13,"name":"Soil_Dirt"},{"x":-11,"y":2,"z":13,"name":"Soil_Dirt"},{"x":-11,"y":3,"z":13,"name":"Soil_Dirt"},{"x":-11,"y":4,"z":13,"name":"Soil_Dirt"},{"x":-11,"y":5,"z":13,"name":"Soil_Grass_Sunny","support":15},{"x":-11,"y":6,"z":13,"name":"Plant_Grass_Sharp"},{"x":-11,"y":0,"z":14,"name":"Soil_Dirt"},{"x":-11,"y":1,"z":14,"name":"Soil_Dirt"},{"x":-11,"y":2,"z":14,"name":"Soil_Dirt"},{"x":-11,"y":3,"z":14,"name":"Soil_Dirt"},{"x":-11,"y":4,"z":14,"name":"Soil_Dirt"},{"x":-11,"y":5,"z":14,"name":"Soil_Grass_Sunny","support":15},{"x":-11,"y":6,"z":14,"name":"Plant_Crop_Mushroom_Cap_Red"},{"x":-11,"y":0,"z":15,"name":"Soil_Dirt"},{"x":-11,"y":1,"z":15,"name":"Soil_Dirt"},{"x":-11,"y":2,"z":15,"name":"Soil_Dirt"},{"x":-11,"y":3,"z":15,"name":"Soil_Dirt"},{"x":-11,"y":4,"z":15,"name":"Soil_Dirt"},{"x":-11,"y":5,"z":15,"name":"Rock_Stone_Brick_Smooth"},{"x":-10,"y":0,"z":-14,"name":"Soil_Dirt"},{"x":-10,"y":1,"z":-14,"name":"Soil_Dirt"},{"x":-10,"y":2,"z":-14,"name":"Soil_Dirt"},{"x":-10,"y":3,"z":-14,"name":"Soil_Dirt"},{"x":-10,"y":4,"z":-14,"name":"Soil_Dirt"},{"x":-10,"y":5,"z":-14,"name":"Rock_Stone_Brick_Smooth"},{"x":-10,"y":0,"z":-13,"name":"Soil_Dirt"},{"x":-10,"y":1,"z":-13,"name":"Soil_Dirt"},{"x":-10,"y":2,"z":-13,"name":"Soil_Dirt"},{"x":-10,"y":3,"z":-13,"name":"Soil_Dirt"},{"x":-10,"y":4,"z":-13,"name":"Soil_Dirt"},{"x":-10,"y":5,"z":-13,"name":"Soil_Grass_Sunny","support":15},{"x":-10,"y":0,"z":-12,"name":"Soil_Dirt"},{"x":-10,"y":1,"z":-12,"name":"Soil_Dirt"},{"x":-10,"y":2,"z":-12,"name":"Soil_Dirt"},{"x":-10,"y":3,"z":-12,"name":"Soil_Dirt"},{"x":-10,"y":4,"z":-12,"name":"Soil_Dirt"},{"x":-10,"y":5,"z":-12,"name":"Soil_Pathway"},{"x":-10,"y":0,"z":-11,"name":"Soil_Dirt"},{"x":-10,"y":1,"z":-11,"name":"Soil_Dirt"},{"x":-10,"y":2,"z":-11,"name":"Soil_Dirt"},{"x":-10,"y":3,"z":-11,"name":"Soil_Dirt"},{"x":-10,"y":4,"z":-11,"name":"Soil_Dirt"},{"x":-10,"y":5,"z":-11,"name":"Soil_Pathway"},{"x":-10,"y":6,"z":-11,"name":"Wood_Hardwood_Decorative"},{"x":-10,"y":7,"z":-11,"name":"Wood_Hardwood_Planks"},{"x":-10,"y":8,"z":-11,"name":"Wood_Hardwood_Planks"},{"x":-10,"y":9,"z":-11,"name":"Wood_Hardwood_Planks"},{"x":-10,"y":0,"z":-10,"name":"Soil_Dirt"},{"x":-10,"y":1,"z":-10,"name":"Soil_Dirt"},{"x":-10,"y":2,"z":-10,"name":"Soil_Dirt"},{"x":-10,"y":3,"z":-10,"name":"Soil_Dirt"},{"x":-10,"y":4,"z":-10,"name":"Soil_Dirt"},{"x":-10,"y":5,"z":-10,"name":"Soil_Dirt"},{"x":-10,"y":6,"z":-10,"name":"Wood_Hardwood_Decorative"},{"x":-10,"y":7,"z":-10,"name":"Wood_Hardwood_Stairs"},{"x":-10,"y":10,"z":-10,"name":"Cloth_Modern_Orange_Roof_Flat"},{"x":-10,"y":0,"z":-9,"name":"Soil_Dirt"},{"x":-10,"y":1,"z":-9,"name":"Soil_Dirt"},{"x":-10,"y":2,"z":-9,"name":"Soil_Dirt"},{"x":-10,"y":3,"z":-9,"name":"Soil_Dirt"},{"x":-10,"y":4,"z":-9,"name":"Soil_Dirt"},{"x":-10,"y":5,"z":-9,"name":"Soil_Pathway"},{"x":-10,"y":6,"z":-9,"name":"Wood_Hardwood_Decorative"},{"x":-10,"y":9,"z":-9,"name":"Cloth_Modern_Orange_Roof"},{"x":-10,"y":0,"z":-8,"name":"Soil_Dirt"},{"x":-10,"y":1,"z":-8,"name":"Soil_Dirt"},{"x":-10,"y":2,"z":-8,"name":"Soil_Dirt"},{"x":-10,"y":3,"z":-8,"name":"Soil_Dirt"},{"x":-10,"y":4,"z":-8,"name":"Soil_Dirt"},{"x":-10,"y":5,"z":-8,"name":"Soil_Pathway"},{"x":-10,"y":0,"z":-7,"name":"Soil_Dirt"},{"x":-10,"y":1,"z":-7,"name":"Soil_Dirt"},{"x":-10,"y":2,"z":-7,"name":"Soil_Dirt"},{"x":-10,"y":3,"z":-7,"name":"Soil_Dirt"},{"x":-10,"y":4,"z":-7,"name":"Soil_Dirt"},{"x":-10,"y":5,"z":-7,"name":"Soil_Pathway"},{"x":-10,"y":0,"z":-6,"name":"Soil_Dirt"},{"x":-10,"y":1,"z":-6,"name":"Soil_Dirt"},{"x":-10,"y":2,"z":-6,"name":"Soil_Dirt"},{"x":-10,"y":3,"z":-6,"name":"Soil_Dirt"},{"x":-10,"y":4,"z":-6,"name":"Soil_Dirt"},{"x":-10,"y":5,"z":-6,"name":"Soil_Clay"},{"x":-10,"y":0,"z":-5,"name":"Soil_Dirt"},{"x":-10,"y":1,"z":-5,"name":"Soil_Dirt"},{"x":-10,"y":2,"z":-5,"name":"Soil_Dirt"},{"x":-10,"y":3,"z":-5,"name":"Soil_Dirt"},{"x":-10,"y":4,"z":-5,"name":"Soil_Dirt"},{"x":-10,"y":5,"z":-5,"name":"Soil_Pathway"},{"x":-10,"y":0,"z":-4,"name":"Soil_Dirt"},{"x":-10,"y":1,"z":-4,"name":"Soil_Dirt"},{"x":-10,"y":2,"z":-4,"name":"Soil_Dirt"},{"x":-10,"y":3,"z":-4,"name":"Soil_Dirt"},{"x":-10,"y":4,"z":-4,"name":"Soil_Dirt"},{"x":-10,"y":5,"z":-4,"name":"Soil_Pathway"},{"x":-10,"y":0,"z":-3,"name":"Soil_Dirt"},{"x":-10,"y":1,"z":-3,"name":"Soil_Dirt"},{"x":-10,"y":2,"z":-3,"name":"Soil_Dirt"},{"x":-10,"y":3,"z":-3,"name":"Soil_Dirt"},{"x":-10,"y":4,"z":-3,"name":"Soil_Dirt"},{"x":-10,"y":5,"z":-3,"name":"Soil_Dirt"},{"x":-10,"y":0,"z":-2,"name":"Soil_Dirt"},{"x":-10,"y":1,"z":-2,"name":"Soil_Dirt"},{"x":-10,"y":2,"z":-2,"name":"Soil_Dirt"},{"x":-10,"y":3,"z":-2,"name":"Soil_Dirt"},{"x":-10,"y":4,"z":-2,"name":"Soil_Dirt"},{"x":-10,"y":5,"z":-2,"name":"Soil_Pathway"},{"x":-10,"y":0,"z":-1,"name":"Soil_Dirt"},{"x":-10,"y":1,"z":-1,"name":"Soil_Dirt"},{"x":-10,"y":2,"z":-1,"name":"Soil_Dirt"},{"x":-10,"y":3,"z":-1,"name":"Soil_Dirt"},{"x":-10,"y":4,"z":-1,"name":"Soil_Dirt"},{"x":-10,"y":5,"z":-1,"name":"Soil_Pathway"},{"x":-10,"y":0,"z":0,"name":"Soil_Dirt"},{"x":-10,"y":1,"z":0,"name":"Soil_Dirt"},{"x":-10,"y":2,"z":0,"name":"Soil_Dirt"},{"x":-10,"y":3,"z":0,"name":"Soil_Dirt"},{"x":-10,"y":4,"z":0,"name":"Soil_Dirt"},{"x":-10,"y":5,"z":0,"name":"Soil_Pathway"},{"x":-10,"y":6,"z":0,"name":"Plant_Crop_Mushroom_Cap_Red","components":{"Components":{"FarmingBlock":{"LastTickGameTime":"0001-01-21T12:00:00Z","SpreadRate":0.0}}}},{"x":-10,"y":0,"z":1,"name":"Soil_Dirt"},{"x":-10,"y":1,"z":1,"name":"Soil_Dirt"},{"x":-10,"y":2,"z":1,"name":"Soil_Dirt"},{"x":-10,"y":3,"z":1,"name":"Soil_Dirt"},{"x":-10,"y":4,"z":1,"name":"Soil_Dirt"},{"x":-10,"y":5,"z":1,"name":"Soil_Grass_Sunny","support":15},{"x":-10,"y":14,"z":1,"name":"Plant_Leaves_Maple","rotation":2},{"x":-10,"y":15,"z":1,"name":"Plant_Leaves_Maple","rotation":2},{"x":-10,"y":16,"z":1,"name":"Plant_Leaves_Maple","rotation":2},{"x":-10,"y":0,"z":2,"name":"Soil_Dirt"},{"x":-10,"y":1,"z":2,"name":"Soil_Dirt"},{"x":-10,"y":2,"z":2,"name":"Soil_Dirt"},{"x":-10,"y":3,"z":2,"name":"Soil_Dirt","support":15},{"x":-10,"y":4,"z":2,"name":"Soil_Dirt","support":15},{"x":-10,"y":5,"z":2,"name":"Soil_Grass_Sunny","support":15},{"x":-10,"y":6,"z":2,"name":"Plant_Flower_Common_Yellow2","support":15},{"x":-10,"y":14,"z":2,"name":"Plant_Leaves_Maple","rotation":2},{"x":-10,"y":16,"z":2,"name":"Plant_Leaves_Maple","rotation":2},{"x":-10,"y":17,"z":2,"name":"Plant_Leaves_Maple","rotation":2},{"x":-10,"y":0,"z":3,"name":"Soil_Dirt"},{"x":-10,"y":2,"z":3,"name":"Soil_Pathway","support":15},{"x":-10,"y":3,"z":3,"name":"Soil_Dirt","support":15},{"x":-10,"y":4,"z":3,"name":"Soil_Grass_Sunny","support":15},{"x":-10,"y":19,"z":3,"name":"Plant_Leaves_Maple","rotation":2},{"x":-10,"y":20,"z":3,"name":"Plant_Leaves_Maple","rotation":2},{"x":-10,"y":0,"z":4,"name":"Soil_Dirt"},{"x":-10,"y":1,"z":4,"name":"Soil_Dirt"},{"x":-10,"y":2,"z":4,"name":"Soil_Dirt","support":15},{"x":-10,"y":3,"z":4,"name":"Soil_Grass_Sunny","support":15},{"x":-10,"y":16,"z":4,"name":"Wood_Maple_Trunk_Full","rotation":2},{"x":-10,"y":19,"z":4,"name":"Plant_Leaves_Maple","rotation":2},{"x":-10,"y":21,"z":4,"name":"Plant_Leaves_Maple","rotation":2},{"x":-10,"y":0,"z":5,"name":"Soil_Dirt"},{"x":-10,"y":2,"z":5,"name":"Soil_Dirt","support":15},{"x":-10,"y":3,"z":5,"name":"Soil_Grass_Sunny","support":15},{"x":-10,"y":19,"z":5,"name":"Plant_Leaves_Maple","rotation":2},{"x":-10,"y":0,"z":6,"name":"Soil_Dirt"},{"x":-10,"y":1,"z":6,"name":"Soil_Dirt"},{"x":-10,"y":2,"z":6,"name":"Soil_Dirt","support":15},{"x":-10,"y":3,"z":6,"name":"Soil_Grass_Sunny","support":15},{"x":-10,"y":18,"z":6,"name":"Plant_Leaves_Maple","rotation":2},{"x":-10,"y":0,"z":7,"name":"Soil_Dirt"},{"x":-10,"y":1,"z":7,"name":"Soil_Dirt"},{"x":-10,"y":2,"z":7,"name":"Soil_Dirt","support":15},{"x":-10,"y":3,"z":7,"name":"Soil_Grass_Sunny","support":15},{"x":-10,"y":17,"z":7,"name":"Plant_Leaves_Maple","rotation":2},{"x":-10,"y":18,"z":7,"name":"Plant_Leaves_Maple","rotation":2},{"x":-10,"y":0,"z":8,"name":"Soil_Dirt"},{"x":-10,"y":1,"z":8,"name":"Soil_Dirt"},{"x":-10,"y":2,"z":8,"name":"Soil_Dirt","support":15},{"x":-10,"y":3,"z":8,"name":"Soil_Grass_Sunny","support":15},{"x":-10,"y":4,"z":8,"name":"Plant_Crop_Mushroom_Common_Brown","components":{"Components":{"FarmingBlock":{"LastTickGameTime":"0001-01-21T12:00:00Z","SpreadRate":0.0}}}},{"x":-10,"y":6,"z":8,"name":"Plant_Flower_Water_Green","support":15},{"x":-10,"y":16,"z":8,"name":"Wood_Maple_Branch_Long","rotation":7},{"x":-10,"y":17,"z":8,"name":"Plant_Leaves_Maple","rotation":2},{"x":-10,"y":18,"z":8,"name":"Plant_Leaves_Maple","rotation":2},{"x":-10,"y":19,"z":8,"name":"Plant_Leaves_Maple","rotation":2},{"x":-10,"y":0,"z":9,"name":"Soil_Dirt"},{"x":-10,"y":1,"z":9,"name":"Soil_Dirt"},{"x":-10,"y":2,"z":9,"name":"Soil_Pathway","support":15},{"x":-10,"y":3,"z":9,"name":"Soil_Dirt","support":15},{"x":-10,"y":4,"z":9,"name":"Soil_Grass_Sunny","support":15},{"x":-10,"y":14,"z":9,"name":"Plant_Leaves_Maple","rotation":2},{"x":-10,"y":15,"z":9,"name":"Plant_Leaves_Maple","rotation":2},{"x":-10,"y":16,"z":9,"name":"Plant_Leaves_Maple","rotation":2},{"x":-10,"y":17,"z":9,"name":"Plant_Leaves_Maple","rotation":2},{"x":-10,"y":18,"z":9,"name":"Plant_Leaves_Maple","rotation":2},{"x":-10,"y":0,"z":10,"name":"Soil_Dirt"},{"x":-10,"y":1,"z":10,"name":"Soil_Dirt"},{"x":-10,"y":2,"z":10,"name":"Soil_Dirt"},{"x":-10,"y":3,"z":10,"name":"Plant_Grass_Sharp_Short"},{"x":-10,"y":4,"z":10,"name":"Soil_Dirt"},{"x":-10,"y":5,"z":10,"name":"Soil_Grass_Sunny","support":15},{"x":-10,"y":6,"z":10,"name":"Plant_Grass_Sharp_Short"},{"x":-10,"y":16,"z":10,"name":"Plant_Leaves_Maple","rotation":2},{"x":-10,"y":17,"z":10,"name":"Plant_Leaves_Maple","rotation":2},{"x":-10,"y":0,"z":11,"name":"Soil_Dirt"},{"x":-10,"y":1,"z":11,"name":"Soil_Dirt"},{"x":-10,"y":2,"z":11,"name":"Soil_Dirt"},{"x":-10,"y":3,"z":11,"name":"Soil_Dirt"},{"x":-10,"y":4,"z":11,"name":"Soil_Dirt"},{"x":-10,"y":5,"z":11,"name":"Soil_Grass_Sunny","support":15},{"x":-10,"y":6,"z":11,"name":"Plant_Grass_Sharp_Short"},{"x":-10,"y":0,"z":12,"name":"Soil_Dirt"},{"x":-10,"y":1,"z":12,"name":"Soil_Dirt"},{"x":-10,"y":2,"z":12,"name":"Soil_Dirt"},{"x":-10,"y":3,"z":12,"name":"Soil_Dirt"},{"x":-10,"y":4,"z":12,"name":"Soil_Dirt"},{"x":-10,"y":5,"z":12,"name":"Soil_Grass_Sunny","support":15},{"x":-10,"y":6,"z":12,"name":"Plant_Grass_Sharp"},{"x":-10,"y":0,"z":13,"name":"Soil_Dirt"},{"x":-10,"y":1,"z":13,"name":"Soil_Dirt"},{"x":-10,"y":2,"z":13,"name":"Soil_Dirt"},{"x":-10,"y":3,"z":13,"name":"Soil_Dirt"},{"x":-10,"y":4,"z":13,"name":"Soil_Dirt"},{"x":-10,"y":5,"z":13,"name":"Soil_Grass_Sunny","support":15},{"x":-10,"y":6,"z":13,"name":"Plant_Grass_Sharp_Short"},{"x":-10,"y":0,"z":14,"name":"Soil_Dirt"},{"x":-10,"y":1,"z":14,"name":"Soil_Dirt"},{"x":-10,"y":2,"z":14,"name":"Soil_Dirt"},{"x":-10,"y":3,"z":14,"name":"Soil_Dirt"},{"x":-10,"y":4,"z":14,"name":"Soil_Dirt"},{"x":-10,"y":5,"z":14,"name":"Soil_Grass_Sunny","support":15},{"x":-10,"y":6,"z":14,"name":"Plant_Grass_Sharp_Short"},{"x":-10,"y":0,"z":15,"name":"Soil_Dirt"},{"x":-10,"y":1,"z":15,"name":"Soil_Dirt"},{"x":-10,"y":2,"z":15,"name":"Soil_Dirt"},{"x":-10,"y":3,"z":15,"name":"Soil_Dirt"},{"x":-10,"y":4,"z":15,"name":"Soil_Dirt"},{"x":-10,"y":5,"z":15,"name":"Rock_Stone_Brick_Smooth"},{"x":-9,"y":0,"z":-14,"name":"Soil_Dirt"},{"x":-9,"y":1,"z":-14,"name":"Soil_Dirt"},{"x":-9,"y":2,"z":-14,"name":"Soil_Dirt"},{"x":-9,"y":3,"z":-14,"name":"Soil_Dirt"},{"x":-9,"y":4,"z":-14,"name":"Soil_Dirt"},{"x":-9,"y":5,"z":-14,"name":"Rock_Stone_Brick_Smooth"},{"x":-9,"y":0,"z":-13,"name":"Soil_Dirt"},{"x":-9,"y":1,"z":-13,"name":"Soil_Dirt"},{"x":-9,"y":2,"z":-13,"name":"Soil_Dirt"},{"x":-9,"y":3,"z":-13,"name":"Soil_Dirt"},{"x":-9,"y":4,"z":-13,"name":"Soil_Dirt"},{"x":-9,"y":5,"z":-13,"name":"Soil_Grass_Sunny","support":15},{"x":-9,"y":0,"z":-12,"name":"Soil_Dirt"},{"x":-9,"y":1,"z":-12,"name":"Soil_Dirt"},{"x":-9,"y":2,"z":-12,"name":"Soil_Dirt"},{"x":-9,"y":3,"z":-12,"name":"Soil_Dirt"},{"x":-9,"y":4,"z":-12,"name":"Soil_Dirt"},{"x":-9,"y":5,"z":-12,"name":"Soil_Pathway"},{"x":-9,"y":0,"z":-11,"name":"Soil_Dirt"},{"x":-9,"y":1,"z":-11,"name":"Soil_Dirt"},{"x":-9,"y":2,"z":-11,"name":"Soil_Dirt"},{"x":-9,"y":3,"z":-11,"name":"Soil_Dirt"},{"x":-9,"y":4,"z":-11,"name":"Soil_Dirt"},{"x":-9,"y":5,"z":-11,"name":"Soil_Dirt"},{"x":-9,"y":6,"z":-11,"name":"Wood_Hardwood_Decorative"},{"x":-9,"y":7,"z":-11,"name":"Wood_Hardwood_Planks"},{"x":-9,"y":8,"z":-11,"name":"Wood_Hardwood_Planks"},{"x":-9,"y":9,"z":-11,"name":"Wood_Hardwood_Planks"},{"x":-9,"y":0,"z":-10,"name":"Soil_Dirt"},{"x":-9,"y":1,"z":-10,"name":"Soil_Dirt"},{"x":-9,"y":2,"z":-10,"name":"Soil_Dirt"},{"x":-9,"y":3,"z":-10,"name":"Soil_Dirt"},{"x":-9,"y":4,"z":-10,"name":"Soil_Dirt"},{"x":-9,"y":5,"z":-10,"name":"Soil_Pathway"},{"x":-9,"y":6,"z":-10,"name":"Wood_Hardwood_Decorative"},{"x":-9,"y":7,"z":-10,"name":"Wood_Hardwood_Stairs"},{"x":-9,"y":10,"z":-10,"name":"Cloth_Modern_Orange_Roof_Flat"},{"x":-9,"y":0,"z":-9,"name":"Soil_Dirt"},{"x":-9,"y":1,"z":-9,"name":"Soil_Dirt"},{"x":-9,"y":2,"z":-9,"name":"Soil_Dirt"},{"x":-9,"y":3,"z":-9,"name":"Soil_Dirt"},{"x":-9,"y":4,"z":-9,"name":"Soil_Dirt"},{"x":-9,"y":5,"z":-9,"name":"Soil_Pathway"},{"x":-9,"y":6,"z":-9,"name":"Wood_Hardwood_Decorative"},{"x":-9,"y":9,"z":-9,"name":"Cloth_Modern_Orange_Roof"},{"x":-9,"y":0,"z":-8,"name":"Soil_Dirt"},{"x":-9,"y":1,"z":-8,"name":"Soil_Dirt"},{"x":-9,"y":2,"z":-8,"name":"Soil_Dirt"},{"x":-9,"y":3,"z":-8,"name":"Soil_Dirt"},{"x":-9,"y":4,"z":-8,"name":"Soil_Dirt"},{"x":-9,"y":5,"z":-8,"name":"Soil_Dirt"},{"x":-9,"y":0,"z":-7,"name":"Soil_Dirt"},{"x":-9,"y":1,"z":-7,"name":"Soil_Dirt"},{"x":-9,"y":2,"z":-7,"name":"Soil_Dirt"},{"x":-9,"y":3,"z":-7,"name":"Soil_Dirt"},{"x":-9,"y":4,"z":-7,"name":"Soil_Dirt"},{"x":-9,"y":5,"z":-7,"name":"Soil_Clay"},{"x":-9,"y":0,"z":-6,"name":"Soil_Dirt"},{"x":-9,"y":1,"z":-6,"name":"Soil_Dirt"},{"x":-9,"y":2,"z":-6,"name":"Soil_Dirt"},{"x":-9,"y":3,"z":-6,"name":"Soil_Dirt"},{"x":-9,"y":4,"z":-6,"name":"Soil_Dirt"},{"x":-9,"y":5,"z":-6,"name":"Soil_Pathway"},{"x":-9,"y":0,"z":-5,"name":"Soil_Dirt"},{"x":-9,"y":1,"z":-5,"name":"Soil_Dirt"},{"x":-9,"y":2,"z":-5,"name":"Soil_Dirt"},{"x":-9,"y":3,"z":-5,"name":"Soil_Dirt"},{"x":-9,"y":4,"z":-5,"name":"Soil_Dirt"},{"x":-9,"y":5,"z":-5,"name":"Soil_Pathway"},{"x":-9,"y":0,"z":-4,"name":"Soil_Dirt"},{"x":-9,"y":1,"z":-4,"name":"Soil_Dirt"},{"x":-9,"y":2,"z":-4,"name":"Soil_Dirt"},{"x":-9,"y":3,"z":-4,"name":"Soil_Dirt"},{"x":-9,"y":4,"z":-4,"name":"Soil_Dirt"},{"x":-9,"y":5,"z":-4,"name":"Soil_Pathway"},{"x":-9,"y":0,"z":-3,"name":"Soil_Dirt"},{"x":-9,"y":1,"z":-3,"name":"Soil_Dirt"},{"x":-9,"y":2,"z":-3,"name":"Soil_Dirt"},{"x":-9,"y":3,"z":-3,"name":"Soil_Dirt"},{"x":-9,"y":4,"z":-3,"name":"Soil_Dirt"},{"x":-9,"y":5,"z":-3,"name":"Soil_Pathway"},{"x":-9,"y":0,"z":-2,"name":"Soil_Dirt"},{"x":-9,"y":1,"z":-2,"name":"Soil_Dirt"},{"x":-9,"y":2,"z":-2,"name":"Soil_Dirt"},{"x":-9,"y":3,"z":-2,"name":"Soil_Dirt"},{"x":-9,"y":4,"z":-2,"name":"Soil_Dirt"},{"x":-9,"y":5,"z":-2,"name":"Soil_Clay"},{"x":-9,"y":0,"z":-1,"name":"Soil_Dirt"},{"x":-9,"y":1,"z":-1,"name":"Soil_Dirt"},{"x":-9,"y":2,"z":-1,"name":"Soil_Dirt"},{"x":-9,"y":3,"z":-1,"name":"Soil_Dirt"},{"x":-9,"y":4,"z":-1,"name":"Soil_Dirt"},{"x":-9,"y":5,"z":-1,"name":"Soil_Pathway"},{"x":-9,"y":18,"z":-1,"name":"Plant_Leaves_Maple","rotation":2},{"x":-9,"y":19,"z":-1,"name":"Plant_Leaves_Maple","rotation":2},{"x":-9,"y":0,"z":0,"name":"Soil_Dirt"},{"x":-9,"y":1,"z":0,"name":"Soil_Dirt"},{"x":-9,"y":2,"z":0,"name":"Soil_Dirt"},{"x":-9,"y":3,"z":0,"name":"Soil_Dirt"},{"x":-9,"y":4,"z":0,"name":"Soil_Dirt"},{"x":-9,"y":5,"z":0,"name":"Soil_Pathway"},{"x":-9,"y":19,"z":0,"name":"Plant_Leaves_Maple","rotation":2},{"x":-9,"y":0,"z":1,"name":"Soil_Dirt"},{"x":-9,"y":1,"z":1,"name":"Soil_Dirt"},{"x":-9,"y":2,"z":1,"name":"Soil_Dirt"},{"x":-9,"y":3,"z":1,"name":"Soil_Dirt"},{"x":-9,"y":4,"z":1,"name":"Soil_Dirt"},{"x":-9,"y":5,"z":1,"name":"Soil_Grass_Sunny","support":15},{"x":-9,"y":16,"z":1,"name":"Plant_Leaves_Maple","rotation":2},{"x":-9,"y":20,"z":1,"name":"Plant_Leaves_Maple","rotation":2},{"x":-9,"y":0,"z":2,"name":"Soil_Dirt"},{"x":-9,"y":1,"z":2,"name":"Soil_Dirt"},{"x":-9,"y":2,"z":2,"name":"Soil_Pathway","support":15},{"x":-9,"y":3,"z":2,"name":"Soil_Dirt","support":15},{"x":-9,"y":4,"z":2,"name":"Soil_Grass_Sunny","support":15},{"x":-9,"y":5,"z":2,"name":"Plant_Reeds_Marsh","support":15},{"x":-9,"y":19,"z":2,"name":"Plant_Leaves_Maple","rotation":2},{"x":-9,"y":20,"z":2,"name":"Plant_Leaves_Maple","rotation":2},{"x":-9,"y":21,"z":2,"name":"Plant_Leaves_Maple","rotation":2},{"x":-9,"y":0,"z":3,"name":"Soil_Dirt"},{"x":-9,"y":2,"z":3,"name":"Soil_Pathway","support":15},{"x":-9,"y":3,"z":3,"name":"Soil_Grass_Sunny","support":15},{"x":-9,"y":19,"z":3,"name":"Plant_Leaves_Maple","rotation":2},{"x":-9,"y":20,"z":3,"name":"Plant_Leaves_Maple","rotation":2},{"x":-9,"y":0,"z":4,"name":"Soil_Dirt"},{"x":-9,"y":1,"z":4,"name":"Soil_Dirt"},{"x":-9,"y":2,"z":4,"name":"Soil_Pathway","support":15},{"x":-9,"y":3,"z":4,"name":"Soil_Grass_Sunny","support":15},{"x":-9,"y":15,"z":4,"name":"Furniture_Kweebec_Lantern_Ceiling","support":15},{"x":-9,"y":16,"z":4,"name":"Wood_Maple_Trunk_Full","rotation":2},{"x":-9,"y":21,"z":4,"name":"Plant_Leaves_Maple","rotation":2},{"x":-9,"y":0,"z":5,"name":"Soil_Dirt"},{"x":-9,"y":2,"z":5,"name":"Soil_Grass_Sunny","support":15},{"x":-9,"y":16,"z":5,"name":"Wood_Maple_Trunk_Full","rotation":2},{"x":-9,"y":21,"z":5,"name":"Plant_Leaves_Maple","rotation":2},{"x":-9,"y":0,"z":6,"name":"Soil_Dirt"},{"x":-9,"y":1,"z":6,"name":"Soil_Dirt","support":15},{"x":-9,"y":2,"z":6,"name":"Soil_Grass_Sunny","support":15},{"x":-9,"y":0,"z":7,"name":"Soil_Dirt"},{"x":-9,"y":1,"z":7,"name":"Soil_Dirt"},{"x":-9,"y":2,"z":7,"name":"Soil_Grass_Sunny","support":15},{"x":-9,"y":18,"z":7,"name":"Plant_Leaves_Maple","rotation":2},{"x":-9,"y":0,"z":8,"name":"Soil_Dirt"},{"x":-9,"y":2,"z":8,"name":"Soil_Pathway","support":15},{"x":-9,"y":3,"z":8,"name":"Soil_Grass_Sunny","support":15},{"x":-9,"y":16,"z":8,"name":"Wood_Maple_Trunk_Full","rotation":2},{"x":-9,"y":18,"z":8,"name":"Plant_Leaves_Maple","rotation":2},{"x":-9,"y":19,"z":8,"name":"Plant_Leaves_Maple","rotation":2},{"x":-9,"y":0,"z":9,"name":"Soil_Dirt"},{"x":-9,"y":1,"z":9,"name":"Soil_Dirt"},{"x":-9,"y":2,"z":9,"name":"Soil_Pathway","support":15},{"x":-9,"y":3,"z":9,"name":"Soil_Dirt","support":15},{"x":-9,"y":4,"z":9,"name":"Soil_Grass_Sunny","support":15},{"x":-9,"y":5,"z":9,"name":"Plant_Reeds_Marsh","support":15},{"x":-9,"y":17,"z":9,"name":"Plant_Leaves_Maple","rotation":2},{"x":-9,"y":18,"z":9,"name":"Plant_Leaves_Maple","rotation":2},{"x":-9,"y":19,"z":9,"name":"Plant_Leaves_Maple","rotation":2},{"x":-9,"y":0,"z":10,"name":"Soil_Dirt"},{"x":-9,"y":2,"z":10,"name":"Soil_Dirt"},{"x":-9,"y":3,"z":10,"name":"Soil_Dirt"},{"x":-9,"y":4,"z":10,"name":"Soil_Dirt","support":15},{"x":-9,"y":5,"z":10,"name":"Soil_Grass_Sunny","support":15},{"x":-9,"y":6,"z":10,"name":"Plant_Crop_Mushroom_Cap_Red","components":{"Components":{"FarmingBlock":{"LastTickGameTime":"0001-01-21T12:00:00Z","SpreadRate":0.0}}}},{"x":-9,"y":15,"z":10,"name":"Plant_Leaves_Maple","rotation":2},{"x":-9,"y":18,"z":10,"name":"Plant_Leaves_Maple","rotation":2},{"x":-9,"y":0,"z":11,"name":"Soil_Dirt"},{"x":-9,"y":1,"z":11,"name":"Soil_Dirt"},{"x":-9,"y":2,"z":11,"name":"Soil_Dirt"},{"x":-9,"y":3,"z":11,"name":"Soil_Dirt"},{"x":-9,"y":4,"z":11,"name":"Soil_Dirt"},{"x":-9,"y":5,"z":11,"name":"Soil_Grass_Sunny","support":15},{"x":-9,"y":6,"z":11,"name":"Plant_Grass_Sharp_Short"},{"x":-9,"y":0,"z":12,"name":"Soil_Dirt"},{"x":-9,"y":1,"z":12,"name":"Soil_Dirt"},{"x":-9,"y":2,"z":12,"name":"Soil_Dirt"},{"x":-9,"y":3,"z":12,"name":"Soil_Dirt"},{"x":-9,"y":4,"z":12,"name":"Soil_Dirt"},{"x":-9,"y":5,"z":12,"name":"Soil_Grass_Sunny","support":15},{"x":-9,"y":6,"z":12,"name":"Plant_Grass_Sharp_Short"},{"x":-9,"y":0,"z":13,"name":"Soil_Dirt"},{"x":-9,"y":1,"z":13,"name":"Soil_Dirt"},{"x":-9,"y":2,"z":13,"name":"Soil_Dirt"},{"x":-9,"y":3,"z":13,"name":"Soil_Dirt"},{"x":-9,"y":4,"z":13,"name":"Soil_Dirt"},{"x":-9,"y":5,"z":13,"name":"Soil_Grass_Sunny","support":15},{"x":-9,"y":6,"z":13,"name":"Plant_Grass_Sharp_Short"},{"x":-9,"y":0,"z":14,"name":"Soil_Dirt"},{"x":-9,"y":1,"z":14,"name":"Soil_Dirt"},{"x":-9,"y":2,"z":14,"name":"Soil_Dirt"},{"x":-9,"y":3,"z":14,"name":"Soil_Dirt"},{"x":-9,"y":4,"z":14,"name":"Soil_Dirt"},{"x":-9,"y":5,"z":14,"name":"Soil_Grass_Sunny","support":15},{"x":-9,"y":0,"z":15,"name":"Soil_Dirt"},{"x":-9,"y":1,"z":15,"name":"Soil_Dirt"},{"x":-9,"y":2,"z":15,"name":"Soil_Dirt"},{"x":-9,"y":3,"z":15,"name":"Soil_Dirt"},{"x":-9,"y":4,"z":15,"name":"Soil_Dirt"},{"x":-9,"y":5,"z":15,"name":"Rock_Stone_Brick_Smooth"},{"x":-8,"y":0,"z":-14,"name":"Soil_Dirt"},{"x":-8,"y":1,"z":-14,"name":"Soil_Dirt"},{"x":-8,"y":2,"z":-14,"name":"Soil_Dirt"},{"x":-8,"y":3,"z":-14,"name":"Soil_Dirt"},{"x":-8,"y":4,"z":-14,"name":"Soil_Dirt"},{"x":-8,"y":5,"z":-14,"name":"Rock_Stone_Brick_Smooth"},{"x":-8,"y":0,"z":-13,"name":"Soil_Dirt"},{"x":-8,"y":1,"z":-13,"name":"Soil_Dirt"},{"x":-8,"y":2,"z":-13,"name":"Soil_Dirt"},{"x":-8,"y":3,"z":-13,"name":"Soil_Dirt"},{"x":-8,"y":4,"z":-13,"name":"Soil_Dirt"},{"x":-8,"y":5,"z":-13,"name":"Soil_Grass_Sunny","support":15},{"x":-8,"y":0,"z":-12,"name":"Soil_Dirt"},{"x":-8,"y":1,"z":-12,"name":"Soil_Dirt"},{"x":-8,"y":2,"z":-12,"name":"Soil_Dirt"},{"x":-8,"y":3,"z":-12,"name":"Soil_Dirt"},{"x":-8,"y":4,"z":-12,"name":"Soil_Dirt"},{"x":-8,"y":5,"z":-12,"name":"Soil_Grass_Sunny"},{"x":-8,"y":0,"z":-11,"name":"Soil_Dirt"},{"x":-8,"y":1,"z":-11,"name":"Soil_Dirt"},{"x":-8,"y":2,"z":-11,"name":"Soil_Dirt"},{"x":-8,"y":3,"z":-11,"name":"Soil_Dirt"},{"x":-8,"y":4,"z":-11,"name":"Soil_Dirt"},{"x":-8,"y":5,"z":-11,"name":"Soil_Pathway"},{"x":-8,"y":6,"z":-11,"name":"Wood_Hardwood_Decorative"},{"x":-8,"y":7,"z":-11,"name":"Wood_Hardwood_Planks"},{"x":-8,"y":8,"z":-11,"name":"Wood_Hardwood_Planks"},{"x":-8,"y":9,"z":-11,"name":"Wood_Hardwood_Planks"},{"x":-8,"y":0,"z":-10,"name":"Soil_Dirt"},{"x":-8,"y":1,"z":-10,"name":"Soil_Dirt"},{"x":-8,"y":2,"z":-10,"name":"Soil_Dirt"},{"x":-8,"y":3,"z":-10,"name":"Soil_Dirt"},{"x":-8,"y":4,"z":-10,"name":"Soil_Dirt"},{"x":-8,"y":5,"z":-10,"name":"Soil_Dirt"},{"x":-8,"y":6,"z":-10,"name":"Wood_Hardwood_Decorative"},{"x":-8,"y":7,"z":-10,"name":"Wood_Hardwood_Stairs"},{"x":-8,"y":10,"z":-10,"name":"Cloth_Modern_Orange_Roof_Flat"},{"x":-8,"y":0,"z":-9,"name":"Soil_Dirt"},{"x":-8,"y":1,"z":-9,"name":"Soil_Dirt"},{"x":-8,"y":2,"z":-9,"name":"Soil_Dirt"},{"x":-8,"y":3,"z":-9,"name":"Soil_Dirt"},{"x":-8,"y":4,"z":-9,"name":"Soil_Dirt"},{"x":-8,"y":5,"z":-9,"name":"Soil_Clay"},{"x":-8,"y":6,"z":-9,"name":"Wood_Hardwood_Decorative"},{"x":-8,"y":9,"z":-9,"name":"Cloth_Modern_Orange_Roof"},{"x":-8,"y":0,"z":-8,"name":"Soil_Dirt"},{"x":-8,"y":1,"z":-8,"name":"Soil_Dirt"},{"x":-8,"y":2,"z":-8,"name":"Soil_Dirt"},{"x":-8,"y":3,"z":-8,"name":"Soil_Dirt"},{"x":-8,"y":4,"z":-8,"name":"Soil_Dirt"},{"x":-8,"y":5,"z":-8,"name":"Soil_Dirt"},{"x":-8,"y":0,"z":-7,"name":"Soil_Dirt"},{"x":-8,"y":1,"z":-7,"name":"Soil_Dirt"},{"x":-8,"y":2,"z":-7,"name":"Soil_Dirt"},{"x":-8,"y":3,"z":-7,"name":"Soil_Dirt"},{"x":-8,"y":4,"z":-7,"name":"Soil_Dirt"},{"x":-8,"y":5,"z":-7,"name":"Soil_Pathway"},{"x":-8,"y":0,"z":-6,"name":"Soil_Dirt"},{"x":-8,"y":1,"z":-6,"name":"Soil_Dirt"},{"x":-8,"y":2,"z":-6,"name":"Soil_Dirt"},{"x":-8,"y":3,"z":-6,"name":"Soil_Dirt"},{"x":-8,"y":4,"z":-6,"name":"Soil_Dirt"},{"x":-8,"y":5,"z":-6,"name":"Soil_Dirt"},{"x":-8,"y":0,"z":-5,"name":"Soil_Dirt"},{"x":-8,"y":1,"z":-5,"name":"Soil_Dirt"},{"x":-8,"y":2,"z":-5,"name":"Soil_Dirt"},{"x":-8,"y":3,"z":-5,"name":"Soil_Dirt"},{"x":-8,"y":4,"z":-5,"name":"Soil_Dirt"},{"x":-8,"y":5,"z":-5,"name":"Soil_Clay"},{"x":-8,"y":0,"z":-4,"name":"Soil_Dirt"},{"x":-8,"y":1,"z":-4,"name":"Soil_Dirt"},{"x":-8,"y":2,"z":-4,"name":"Soil_Dirt"},{"x":-8,"y":3,"z":-4,"name":"Soil_Dirt"},{"x":-8,"y":4,"z":-4,"name":"Soil_Dirt"},{"x":-8,"y":5,"z":-4,"name":"Soil_Pathway"},{"x":-8,"y":0,"z":-3,"name":"Soil_Dirt"},{"x":-8,"y":1,"z":-3,"name":"Soil_Dirt"},{"x":-8,"y":2,"z":-3,"name":"Soil_Dirt"},{"x":-8,"y":3,"z":-3,"name":"Soil_Dirt"},{"x":-8,"y":4,"z":-3,"name":"Soil_Dirt"},{"x":-8,"y":5,"z":-3,"name":"Soil_Pathway"},{"x":-8,"y":19,"z":-3,"name":"Plant_Leaves_Maple","rotation":2},{"x":-8,"y":0,"z":-2,"name":"Soil_Dirt"},{"x":-8,"y":1,"z":-2,"name":"Soil_Dirt"},{"x":-8,"y":2,"z":-2,"name":"Soil_Dirt"},{"x":-8,"y":3,"z":-2,"name":"Soil_Dirt"},{"x":-8,"y":4,"z":-2,"name":"Soil_Dirt"},{"x":-8,"y":5,"z":-2,"name":"Soil_Clay"},{"x":-8,"y":17,"z":-2,"name":"Plant_Leaves_Maple","rotation":2},{"x":-8,"y":18,"z":-2,"name":"Plant_Leaves_Maple","rotation":2},{"x":-8,"y":19,"z":-2,"name":"Plant_Leaves_Maple","rotation":2},{"x":-8,"y":0,"z":-1,"name":"Soil_Dirt"},{"x":-8,"y":1,"z":-1,"name":"Soil_Dirt"},{"x":-8,"y":2,"z":-1,"name":"Soil_Dirt"},{"x":-8,"y":3,"z":-1,"name":"Soil_Dirt"},{"x":-8,"y":4,"z":-1,"name":"Soil_Dirt"},{"x":-8,"y":5,"z":-1,"name":"Soil_Pathway"},{"x":-8,"y":18,"z":-1,"name":"Plant_Leaves_Maple","rotation":2},{"x":-8,"y":19,"z":-1,"name":"Plant_Leaves_Maple","rotation":2},{"x":-8,"y":20,"z":-1,"name":"Plant_Leaves_Maple","rotation":2},{"x":-8,"y":0,"z":0,"name":"Soil_Dirt"},{"x":-8,"y":1,"z":0,"name":"Soil_Dirt"},{"x":-8,"y":2,"z":0,"name":"Soil_Dirt"},{"x":-8,"y":3,"z":0,"name":"Soil_Dirt"},{"x":-8,"y":4,"z":0,"name":"Soil_Dirt"},{"x":-8,"y":5,"z":0,"name":"Soil_Pathway"},{"x":-8,"y":19,"z":0,"name":"Plant_Leaves_Maple","rotation":2},{"x":-8,"y":20,"z":0,"name":"Plant_Leaves_Maple","rotation":2},{"x":-8,"y":0,"z":1,"name":"Soil_Dirt"},{"x":-8,"y":1,"z":1,"name":"Soil_Dirt"},{"x":-8,"y":2,"z":1,"name":"Soil_Dirt"},{"x":-8,"y":3,"z":1,"name":"Soil_Dirt"},{"x":-8,"y":4,"z":1,"name":"Soil_Dirt"},{"x":-8,"y":5,"z":1,"name":"Soil_Clay"},{"x":-8,"y":0,"z":2,"name":"Soil_Dirt"},{"x":-8,"y":2,"z":2,"name":"Soil_Dirt"},{"x":-8,"y":3,"z":2,"name":"Soil_Dirt"},{"x":-8,"y":4,"z":2,"name":"Soil_Dirt","support":15},{"x":-8,"y":5,"z":2,"name":"Soil_Grass_Sunny","support":15},{"x":-8,"y":19,"z":2,"name":"Plant_Leaves_Maple","rotation":2},{"x":-8,"y":20,"z":2,"name":"Plant_Leaves_Maple","rotation":2},{"x":-8,"y":21,"z":2,"name":"Plant_Leaves_Maple","rotation":2},{"x":-8,"y":22,"z":2,"name":"Plant_Leaves_Maple","rotation":2},{"x":-8,"y":0,"z":3,"name":"Soil_Dirt"},{"x":-8,"y":2,"z":3,"name":"Soil_Pathway","support":15},{"x":-8,"y":3,"z":3,"name":"Soil_Dirt","support":15},{"x":-8,"y":4,"z":3,"name":"Soil_Grass_Sunny","support":15},{"x":-8,"y":6,"z":3,"name":"Plant_Flower_Water_Red","support":15},{"x":-8,"y":20,"z":3,"name":"Wood_Maple_Branch_Corner","rotation":3},{"x":-8,"y":21,"z":3,"name":"Plant_Leaves_Maple","rotation":2},{"x":-8,"y":22,"z":3,"name":"Plant_Leaves_Maple","rotation":2},{"x":-8,"y":0,"z":4,"name":"Soil_Dirt"},{"x":-8,"y":1,"z":4,"name":"Soil_Dirt"},{"x":-8,"y":2,"z":4,"name":"Soil_Pathway","support":15},{"x":-8,"y":3,"z":4,"name":"Soil_Dirt","support":15},{"x":-8,"y":4,"z":4,"name":"Rock_Crystal_Cyan_Small","support":15},{"x":-8,"y":21,"z":4,"name":"Plant_Leaves_Maple","rotation":2},{"x":-8,"y":22,"z":4,"name":"Plant_Leaves_Maple","rotation":2},{"x":-8,"y":0,"z":5,"name":"Soil_Dirt"},{"x":-8,"y":2,"z":5,"name":"Soil_Dirt","support":15},{"x":-8,"y":3,"z":5,"name":"Soil_Grass_Sunny","support":15},{"x":-8,"y":15,"z":5,"name":"Wood_Maple_Trunk_Full","rotation":2},{"x":-8,"y":16,"z":5,"name":"Wood_Maple_Trunk_Full","rotation":2},{"x":-8,"y":21,"z":5,"name":"Plant_Leaves_Maple","rotation":2},{"x":-8,"y":22,"z":5,"name":"Plant_Leaves_Maple","rotation":2},{"x":-8,"y":0,"z":6,"name":"Soil_Dirt"},{"x":-8,"y":2,"z":6,"name":"Soil_Grass_Sunny","support":15},{"x":-8,"y":6,"z":6,"name":"Plant_Flower_Water_Blue","support":15},{"x":-8,"y":15,"z":6,"name":"Wood_Maple_Trunk_Full","rotation":2},{"x":-8,"y":23,"z":6,"name":"Plant_Leaves_Maple","rotation":2},{"x":-8,"y":0,"z":7,"name":"Soil_Dirt"},{"x":-8,"y":1,"z":7,"name":"Soil_Dirt"},{"x":-8,"y":2,"z":7,"name":"Soil_Dirt","support":15},{"x":-8,"y":3,"z":7,"name":"Soil_Grass_Sunny","support":15},{"x":-8,"y":15,"z":7,"name":"Wood_Maple_Trunk_Full","rotation":2},{"x":-8,"y":16,"z":7,"name":"Wood_Maple_Trunk_Full","rotation":2},{"x":-8,"y":22,"z":7,"name":"Plant_Leaves_Maple","rotation":2},{"x":-8,"y":23,"z":7,"name":"Plant_Leaves_Maple","rotation":2},{"x":-8,"y":0,"z":8,"name":"Soil_Dirt"},{"x":-8,"y":1,"z":8,"name":"Soil_Dirt"},{"x":-8,"y":2,"z":8,"name":"Soil_Dirt","support":15},{"x":-8,"y":3,"z":8,"name":"Soil_Dirt","support":15},{"x":-8,"y":4,"z":8,"name":"Rock_Crystal_Cyan_Medium","support":15},{"x":-8,"y":15,"z":8,"name":"Furniture_Kweebec_Lantern_Ceiling","support":15},{"x":-8,"y":16,"z":8,"name":"Wood_Maple_Trunk_Full","rotation":2},{"x":-8,"y":22,"z":8,"name":"Plant_Leaves_Maple","rotation":2},{"x":-8,"y":0,"z":9,"name":"Soil_Dirt"},{"x":-8,"y":1,"z":9,"name":"Soil_Dirt"},{"x":-8,"y":2,"z":9,"name":"Soil_Pathway","support":15},{"x":-8,"y":3,"z":9,"name":"Soil_Dirt","support":15},{"x":-8,"y":4,"z":9,"name":"Soil_Grass_Sunny","support":15},{"x":-8,"y":0,"z":10,"name":"Soil_Dirt"},{"x":-8,"y":1,"z":10,"name":"Soil_Dirt"},{"x":-8,"y":2,"z":10,"name":"Soil_Dirt"},{"x":-8,"y":3,"z":10,"name":"Soil_Dirt"},{"x":-8,"y":4,"z":10,"name":"Soil_Dirt"},{"x":-8,"y":5,"z":10,"name":"Soil_Grass_Sunny","support":15},{"x":-8,"y":15,"z":10,"name":"Plant_Leaves_Maple","rotation":2},{"x":-8,"y":0,"z":11,"name":"Soil_Dirt"},{"x":-8,"y":1,"z":11,"name":"Soil_Dirt"},{"x":-8,"y":2,"z":11,"name":"Soil_Dirt"},{"x":-8,"y":3,"z":11,"name":"Soil_Dirt"},{"x":-8,"y":4,"z":11,"name":"Soil_Dirt"},{"x":-8,"y":5,"z":11,"name":"Soil_Grass_Sunny","support":15},{"x":-8,"y":0,"z":12,"name":"Soil_Dirt"},{"x":-8,"y":1,"z":12,"name":"Soil_Dirt"},{"x":-8,"y":2,"z":12,"name":"Soil_Dirt"},{"x":-8,"y":3,"z":12,"name":"Soil_Dirt"},{"x":-8,"y":4,"z":12,"name":"Soil_Dirt"},{"x":-8,"y":5,"z":12,"name":"Soil_Grass_Sunny","support":15},{"x":-8,"y":6,"z":12,"name":"Plant_Flower_Common_Yellow2","support":15},{"x":-8,"y":0,"z":13,"name":"Soil_Dirt"},{"x":-8,"y":1,"z":13,"name":"Soil_Dirt"},{"x":-8,"y":2,"z":13,"name":"Soil_Dirt"},{"x":-8,"y":3,"z":13,"name":"Soil_Dirt"},{"x":-8,"y":4,"z":13,"name":"Soil_Dirt"},{"x":-8,"y":5,"z":13,"name":"Soil_Grass_Sunny","support":15},{"x":-8,"y":0,"z":14,"name":"Soil_Dirt"},{"x":-8,"y":1,"z":14,"name":"Soil_Dirt"},{"x":-8,"y":2,"z":14,"name":"Soil_Dirt"},{"x":-8,"y":3,"z":14,"name":"Soil_Dirt"},{"x":-8,"y":4,"z":14,"name":"Soil_Dirt"},{"x":-8,"y":5,"z":14,"name":"Soil_Grass_Sunny","support":15},{"x":-8,"y":0,"z":15,"name":"Soil_Dirt"},{"x":-8,"y":1,"z":15,"name":"Soil_Dirt"},{"x":-8,"y":2,"z":15,"name":"Soil_Dirt"},{"x":-8,"y":3,"z":15,"name":"Soil_Dirt"},{"x":-8,"y":4,"z":15,"name":"Soil_Dirt"},{"x":-8,"y":5,"z":15,"name":"Rock_Stone_Brick_Smooth"},{"x":-7,"y":0,"z":-14,"name":"Soil_Dirt"},{"x":-7,"y":1,"z":-14,"name":"Soil_Dirt"},{"x":-7,"y":2,"z":-14,"name":"Soil_Dirt"},{"x":-7,"y":3,"z":-14,"name":"Soil_Dirt"},{"x":-7,"y":4,"z":-14,"name":"Soil_Dirt"},{"x":-7,"y":5,"z":-14,"name":"Rock_Stone_Brick_Smooth"},{"x":-7,"y":0,"z":-13,"name":"Soil_Dirt"},{"x":-7,"y":1,"z":-13,"name":"Soil_Dirt"},{"x":-7,"y":2,"z":-13,"name":"Soil_Dirt"},{"x":-7,"y":3,"z":-13,"name":"Soil_Dirt"},{"x":-7,"y":4,"z":-13,"name":"Soil_Dirt"},{"x":-7,"y":5,"z":-13,"name":"Soil_Grass_Sunny","support":15},{"x":-7,"y":0,"z":-12,"name":"Soil_Dirt"},{"x":-7,"y":1,"z":-12,"name":"Soil_Dirt"},{"x":-7,"y":2,"z":-12,"name":"Soil_Dirt"},{"x":-7,"y":3,"z":-12,"name":"Soil_Dirt"},{"x":-7,"y":4,"z":-12,"name":"Soil_Dirt"},{"x":-7,"y":5,"z":-12,"name":"Soil_Pathway"},{"x":-7,"y":0,"z":-11,"name":"Soil_Dirt"},{"x":-7,"y":1,"z":-11,"name":"Soil_Dirt"},{"x":-7,"y":2,"z":-11,"name":"Soil_Dirt"},{"x":-7,"y":3,"z":-11,"name":"Soil_Dirt"},{"x":-7,"y":4,"z":-11,"name":"Soil_Dirt"},{"x":-7,"y":5,"z":-11,"name":"Soil_Pathway"},{"x":-7,"y":6,"z":-11,"name":"Wood_Hardwood_Decorative"},{"x":-7,"y":7,"z":-11,"name":"Wood_Hardwood_Planks"},{"x":-7,"y":8,"z":-11,"name":"Wood_Hardwood_Planks"},{"x":-7,"y":9,"z":-11,"name":"Wood_Hardwood_Stairs","rotation":1},{"x":-7,"y":0,"z":-10,"name":"Soil_Dirt"},{"x":-7,"y":1,"z":-10,"name":"Soil_Dirt"},{"x":-7,"y":2,"z":-10,"name":"Soil_Dirt"},{"x":-7,"y":3,"z":-10,"name":"Soil_Dirt"},{"x":-7,"y":4,"z":-10,"name":"Soil_Dirt"},{"x":-7,"y":5,"z":-10,"name":"Soil_Clay"},{"x":-7,"y":6,"z":-10,"name":"Wood_Hardwood_Decorative"},{"x":-7,"y":7,"z":-10,"name":"Wood_Hardwood_Planks"},{"x":-7,"y":9,"z":-10,"name":"Cloth_Modern_Orange_Roof","rotation":1},{"x":-7,"y":0,"z":-9,"name":"Soil_Dirt"},{"x":-7,"y":1,"z":-9,"name":"Soil_Dirt"},{"x":-7,"y":2,"z":-9,"name":"Soil_Dirt"},{"x":-7,"y":3,"z":-9,"name":"Soil_Dirt"},{"x":-7,"y":4,"z":-9,"name":"Soil_Dirt"},{"x":-7,"y":5,"z":-9,"name":"Soil_Clay"},{"x":-7,"y":6,"z":-9,"name":"Wood_Hardwood_Decorative"},{"x":-7,"y":7,"z":-9,"name":"Wood_Hardwood_Beam"},{"x":-7,"y":8,"z":-9,"name":"Wood_Hardwood_Beam"},{"x":-7,"y":9,"z":-9,"name":"*Cloth_Modern_Orange_Roof_State_Definitions_Corner_Left"},{"x":-7,"y":0,"z":-8,"name":"Soil_Dirt"},{"x":-7,"y":1,"z":-8,"name":"Soil_Dirt"},{"x":-7,"y":2,"z":-8,"name":"Soil_Dirt"},{"x":-7,"y":3,"z":-8,"name":"Soil_Dirt"},{"x":-7,"y":4,"z":-8,"name":"Soil_Dirt"},{"x":-7,"y":5,"z":-8,"name":"Soil_Pathway"},{"x":-7,"y":0,"z":-7,"name":"Soil_Dirt"},{"x":-7,"y":1,"z":-7,"name":"Soil_Dirt"},{"x":-7,"y":2,"z":-7,"name":"Soil_Dirt"},{"x":-7,"y":3,"z":-7,"name":"Soil_Dirt"},{"x":-7,"y":4,"z":-7,"name":"Soil_Dirt"},{"x":-7,"y":5,"z":-7,"name":"Soil_Dirt"},{"x":-7,"y":0,"z":-6,"name":"Soil_Dirt"},{"x":-7,"y":1,"z":-6,"name":"Soil_Dirt"},{"x":-7,"y":2,"z":-6,"name":"Soil_Dirt"},{"x":-7,"y":3,"z":-6,"name":"Soil_Dirt"},{"x":-7,"y":4,"z":-6,"name":"Soil_Dirt"},{"x":-7,"y":5,"z":-6,"name":"Soil_Pathway"},{"x":-7,"y":0,"z":-5,"name":"Soil_Dirt"},{"x":-7,"y":1,"z":-5,"name":"Soil_Dirt"},{"x":-7,"y":2,"z":-5,"name":"Soil_Dirt"},{"x":-7,"y":3,"z":-5,"name":"Soil_Dirt"},{"x":-7,"y":4,"z":-5,"name":"Soil_Dirt"},{"x":-7,"y":5,"z":-5,"name":"Soil_Pathway"},{"x":-7,"y":0,"z":-4,"name":"Soil_Dirt"},{"x":-7,"y":1,"z":-4,"name":"Soil_Dirt"},{"x":-7,"y":2,"z":-4,"name":"Soil_Dirt"},{"x":-7,"y":3,"z":-4,"name":"Soil_Dirt"},{"x":-7,"y":4,"z":-4,"name":"Soil_Dirt"},{"x":-7,"y":5,"z":-4,"name":"Soil_Clay"},{"x":-7,"y":0,"z":-3,"name":"Soil_Dirt"},{"x":-7,"y":1,"z":-3,"name":"Soil_Dirt"},{"x":-7,"y":2,"z":-3,"name":"Soil_Dirt"},{"x":-7,"y":3,"z":-3,"name":"Soil_Dirt"},{"x":-7,"y":4,"z":-3,"name":"Soil_Dirt"},{"x":-7,"y":5,"z":-3,"name":"Soil_Clay"},{"x":-7,"y":17,"z":-3,"name":"Plant_Leaves_Maple","rotation":2},{"x":-7,"y":18,"z":-3,"name":"Plant_Leaves_Maple","rotation":2},{"x":-7,"y":19,"z":-3,"name":"Plant_Leaves_Maple","rotation":2},{"x":-7,"y":20,"z":-3,"name":"Plant_Leaves_Maple","rotation":2},{"x":-7,"y":0,"z":-2,"name":"Soil_Dirt"},{"x":-7,"y":1,"z":-2,"name":"Soil_Dirt"},{"x":-7,"y":2,"z":-2,"name":"Soil_Dirt"},{"x":-7,"y":3,"z":-2,"name":"Soil_Dirt"},{"x":-7,"y":4,"z":-2,"name":"Soil_Dirt"},{"x":-7,"y":5,"z":-2,"name":"Soil_Clay"},{"x":-7,"y":17,"z":-2,"name":"Plant_Leaves_Maple","rotation":2},{"x":-7,"y":18,"z":-2,"name":"Plant_Leaves_Maple","rotation":2},{"x":-7,"y":19,"z":-2,"name":"Plant_Leaves_Maple","rotation":2},{"x":-7,"y":20,"z":-2,"name":"Plant_Leaves_Maple","rotation":2},{"x":-7,"y":0,"z":-1,"name":"Soil_Dirt"},{"x":-7,"y":1,"z":-1,"name":"Soil_Dirt"},{"x":-7,"y":2,"z":-1,"name":"Soil_Dirt"},{"x":-7,"y":3,"z":-1,"name":"Soil_Dirt"},{"x":-7,"y":4,"z":-1,"name":"Soil_Dirt"},{"x":-7,"y":5,"z":-1,"name":"Soil_Pathway"},{"x":-7,"y":19,"z":-1,"name":"Wood_Maple_Branch_Long","rotation":7},{"x":-7,"y":21,"z":-1,"name":"Plant_Leaves_Maple","rotation":2},{"x":-7,"y":0,"z":0,"name":"Soil_Dirt"},{"x":-7,"y":1,"z":0,"name":"Soil_Dirt"},{"x":-7,"y":2,"z":0,"name":"Soil_Dirt"},{"x":-7,"y":3,"z":0,"name":"Soil_Dirt"},{"x":-7,"y":4,"z":0,"name":"Soil_Dirt"},{"x":-7,"y":5,"z":0,"name":"Soil_Pathway"},{"x":-7,"y":21,"z":0,"name":"Plant_Leaves_Maple","rotation":2},{"x":-7,"y":0,"z":1,"name":"Soil_Dirt"},{"x":-7,"y":1,"z":1,"name":"Soil_Dirt"},{"x":-7,"y":2,"z":1,"name":"Soil_Dirt"},{"x":-7,"y":3,"z":1,"name":"Soil_Dirt"},{"x":-7,"y":4,"z":1,"name":"Soil_Dirt"},{"x":-7,"y":5,"z":1,"name":"Soil_Pathway"},{"x":-7,"y":20,"z":1,"name":"Plant_Leaves_Maple","rotation":2},{"x":-7,"y":21,"z":1,"name":"Plant_Leaves_Maple","rotation":2},{"x":-7,"y":22,"z":1,"name":"Plant_Leaves_Maple","rotation":2},{"x":-7,"y":0,"z":2,"name":"Soil_Dirt"},{"x":-7,"y":1,"z":2,"name":"Soil_Dirt"},{"x":-7,"y":2,"z":2,"name":"Soil_Dirt"},{"x":-7,"y":3,"z":2,"name":"Soil_Dirt"},{"x":-7,"y":4,"z":2,"name":"Soil_Dirt"},{"x":-7,"y":5,"z":2,"name":"Soil_Grass_Sunny","support":15},{"x":-7,"y":20,"z":2,"name":"Plant_Leaves_Maple","rotation":2},{"x":-7,"y":22,"z":2,"name":"Plant_Leaves_Maple","rotation":2},{"x":-7,"y":0,"z":3,"name":"Soil_Dirt"},{"x":-7,"y":1,"z":3,"name":"Soil_Dirt"},{"x":-7,"y":2,"z":3,"name":"Soil_Pathway","support":15},{"x":-7,"y":3,"z":3,"name":"Soil_Dirt"},{"x":-7,"y":4,"z":3,"name":"Soil_Grass_Sunny","support":15},{"x":-7,"y":20,"z":3,"name":"Wood_Maple_Branch_Long","rotation":7},{"x":-7,"y":21,"z":3,"name":"Plant_Leaves_Maple","rotation":2},{"x":-7,"y":0,"z":4,"name":"Soil_Dirt"},{"x":-7,"y":1,"z":4,"name":"Soil_Dirt"},{"x":-7,"y":2,"z":4,"name":"Soil_Pathway","support":15},{"x":-7,"y":3,"z":4,"name":"Soil_Grass_Sunny","support":15},{"x":-7,"y":22,"z":4,"name":"Plant_Leaves_Maple","rotation":2},{"x":-7,"y":23,"z":4,"name":"Plant_Leaves_Maple","rotation":2},{"x":-7,"y":0,"z":5,"name":"Soil_Dirt"},{"x":-7,"y":1,"z":5,"name":"Soil_Dirt"},{"x":-7,"y":2,"z":5,"name":"Soil_Dirt","support":15},{"x":-7,"y":3,"z":5,"name":"Soil_Grass_Sunny","support":15},{"x":-7,"y":24,"z":5,"name":"Plant_Leaves_Maple","rotation":2},{"x":-7,"y":0,"z":6,"name":"Soil_Dirt"},{"x":-7,"y":2,"z":6,"name":"Soil_Dirt","support":15},{"x":-7,"y":3,"z":6,"name":"Soil_Grass_Sunny","support":15},{"x":-7,"y":24,"z":6,"name":"Plant_Leaves_Maple","rotation":2},{"x":-7,"y":0,"z":7,"name":"Soil_Dirt"},{"x":-7,"y":1,"z":7,"name":"Soil_Dirt"},{"x":-7,"y":2,"z":7,"name":"Soil_Dirt","support":15},{"x":-7,"y":3,"z":7,"name":"Soil_Grass_Sunny","support":15},{"x":-7,"y":15,"z":7,"name":"Wood_Maple_Trunk_Full","rotation":2},{"x":-7,"y":23,"z":7,"name":"Wood_Maple_Branch_Long","rotation":7},{"x":-7,"y":24,"z":7,"name":"Plant_Leaves_Maple","rotation":2},{"x":-7,"y":0,"z":8,"name":"Soil_Dirt"},{"x":-7,"y":2,"z":8,"name":"Soil_Pathway","support":15},{"x":-7,"y":3,"z":8,"name":"Soil_Dirt","support":15},{"x":-7,"y":4,"z":8,"name":"Soil_Grass_Sunny","support":15},{"x":-7,"y":21,"z":8,"name":"Plant_Leaves_Maple","rotation":2},{"x":-7,"y":22,"z":8,"name":"Plant_Leaves_Maple","rotation":2},{"x":-7,"y":23,"z":8,"name":"Plant_Leaves_Maple","rotation":2},{"x":-7,"y":0,"z":9,"name":"Soil_Dirt"},{"x":-7,"y":2,"z":9,"name":"Soil_Dirt"},{"x":-7,"y":3,"z":9,"name":"Soil_Dirt","support":15},{"x":-7,"y":4,"z":9,"name":"Soil_Dirt"},{"x":-7,"y":5,"z":9,"name":"Soil_Grass_Sunny","support":15},{"x":-7,"y":21,"z":9,"name":"Plant_Leaves_Maple","rotation":2},{"x":-7,"y":22,"z":9,"name":"Plant_Leaves_Maple","rotation":2},{"x":-7,"y":23,"z":9,"name":"Plant_Leaves_Maple","rotation":2},{"x":-7,"y":0,"z":10,"name":"Soil_Dirt"},{"x":-7,"y":1,"z":10,"name":"Soil_Dirt"},{"x":-7,"y":2,"z":10,"name":"Soil_Dirt"},{"x":-7,"y":3,"z":10,"name":"Soil_Dirt"},{"x":-7,"y":4,"z":10,"name":"Soil_Dirt"},{"x":-7,"y":5,"z":10,"name":"Soil_Grass_Sunny","support":15},{"x":-7,"y":6,"z":10,"name":"Plant_Crop_Mushroom_Common_Brown"},{"x":-7,"y":0,"z":11,"name":"Soil_Dirt"},{"x":-7,"y":1,"z":11,"name":"Soil_Dirt"},{"x":-7,"y":2,"z":11,"name":"Soil_Dirt"},{"x":-7,"y":3,"z":11,"name":"Soil_Dirt"},{"x":-7,"y":4,"z":11,"name":"Soil_Dirt"},{"x":-7,"y":5,"z":11,"name":"Soil_Grass_Sunny","support":15},{"x":-7,"y":6,"z":11,"name":"Plant_Grass_Sharp_Short"},{"x":-7,"y":0,"z":12,"name":"Soil_Dirt"},{"x":-7,"y":1,"z":12,"name":"Soil_Dirt"},{"x":-7,"y":2,"z":12,"name":"Soil_Dirt"},{"x":-7,"y":3,"z":12,"name":"Soil_Dirt"},{"x":-7,"y":4,"z":12,"name":"Soil_Dirt"},{"x":-7,"y":5,"z":12,"name":"Soil_Grass_Sunny","support":15},{"x":-7,"y":6,"z":12,"name":"Plant_Grass_Sharp_Short"},{"x":-7,"y":17,"z":12,"name":"Plant_Leaves_Maple","rotation":2},{"x":-7,"y":0,"z":13,"name":"Soil_Dirt"},{"x":-7,"y":1,"z":13,"name":"Soil_Dirt"},{"x":-7,"y":2,"z":13,"name":"Soil_Dirt"},{"x":-7,"y":3,"z":13,"name":"Soil_Dirt"},{"x":-7,"y":4,"z":13,"name":"Soil_Dirt"},{"x":-7,"y":5,"z":13,"name":"Soil_Grass_Sunny","support":15},{"x":-7,"y":6,"z":13,"name":"Plant_Grass_Sharp_Short"},{"x":-7,"y":15,"z":13,"name":"Plant_Leaves_Maple","rotation":2},{"x":-7,"y":16,"z":13,"name":"Plant_Leaves_Maple","rotation":2},{"x":-7,"y":17,"z":13,"name":"Plant_Leaves_Maple","rotation":2},{"x":-7,"y":0,"z":14,"name":"Soil_Dirt"},{"x":-7,"y":1,"z":14,"name":"Soil_Dirt"},{"x":-7,"y":2,"z":14,"name":"Soil_Dirt"},{"x":-7,"y":3,"z":14,"name":"Soil_Dirt"},{"x":-7,"y":4,"z":14,"name":"Soil_Dirt"},{"x":-7,"y":5,"z":14,"name":"Soil_Grass_Sunny","support":15},{"x":-7,"y":6,"z":14,"name":"Plant_Crop_Mushroom_Cap_Red"},{"x":-7,"y":0,"z":15,"name":"Soil_Dirt"},{"x":-7,"y":1,"z":15,"name":"Soil_Dirt"},{"x":-7,"y":2,"z":15,"name":"Soil_Dirt"},{"x":-7,"y":3,"z":15,"name":"Soil_Dirt"},{"x":-7,"y":4,"z":15,"name":"Soil_Dirt"},{"x":-7,"y":5,"z":15,"name":"Rock_Stone_Brick_Smooth"},{"x":-6,"y":0,"z":-14,"name":"Soil_Dirt"},{"x":-6,"y":1,"z":-14,"name":"Soil_Dirt"},{"x":-6,"y":2,"z":-14,"name":"Soil_Dirt"},{"x":-6,"y":3,"z":-14,"name":"Soil_Dirt"},{"x":-6,"y":4,"z":-14,"name":"Soil_Dirt"},{"x":-6,"y":5,"z":-14,"name":"Rock_Stone_Brick_Smooth"},{"x":-6,"y":0,"z":-13,"name":"Soil_Dirt"},{"x":-6,"y":1,"z":-13,"name":"Soil_Dirt"},{"x":-6,"y":2,"z":-13,"name":"Soil_Dirt"},{"x":-6,"y":3,"z":-13,"name":"Soil_Dirt"},{"x":-6,"y":4,"z":-13,"name":"Soil_Dirt"},{"x":-6,"y":5,"z":-13,"name":"Soil_Grass_Sunny","support":15},{"x":-6,"y":0,"z":-12,"name":"Soil_Dirt"},{"x":-6,"y":1,"z":-12,"name":"Soil_Dirt"},{"x":-6,"y":2,"z":-12,"name":"Soil_Dirt"},{"x":-6,"y":3,"z":-12,"name":"Soil_Dirt"},{"x":-6,"y":4,"z":-12,"name":"Soil_Dirt"},{"x":-6,"y":5,"z":-12,"name":"Soil_Pathway"},{"x":-6,"y":0,"z":-11,"name":"Soil_Dirt"},{"x":-6,"y":1,"z":-11,"name":"Soil_Dirt"},{"x":-6,"y":2,"z":-11,"name":"Soil_Dirt"},{"x":-6,"y":3,"z":-11,"name":"Soil_Dirt"},{"x":-6,"y":4,"z":-11,"name":"Soil_Dirt"},{"x":-6,"y":5,"z":-11,"name":"Soil_Pathway"},{"x":-6,"y":0,"z":-10,"name":"Soil_Dirt"},{"x":-6,"y":1,"z":-10,"name":"Soil_Dirt"},{"x":-6,"y":2,"z":-10,"name":"Soil_Dirt"},{"x":-6,"y":3,"z":-10,"name":"Soil_Dirt"},{"x":-6,"y":4,"z":-10,"name":"Soil_Dirt"},{"x":-6,"y":5,"z":-10,"name":"Soil_Pathway"},{"x":-6,"y":0,"z":-9,"name":"Soil_Dirt"},{"x":-6,"y":1,"z":-9,"name":"Soil_Dirt"},{"x":-6,"y":2,"z":-9,"name":"Soil_Dirt"},{"x":-6,"y":3,"z":-9,"name":"Soil_Dirt"},{"x":-6,"y":4,"z":-9,"name":"Soil_Dirt"},{"x":-6,"y":5,"z":-9,"name":"Soil_Pathway"},{"x":-6,"y":6,"z":-9,"name":"Wood_Hardwood_Beam"},{"x":-6,"y":7,"z":-9,"name":"Deco_Lantern"},{"x":-6,"y":0,"z":-8,"name":"Soil_Dirt"},{"x":-6,"y":1,"z":-8,"name":"Soil_Dirt"},{"x":-6,"y":2,"z":-8,"name":"Soil_Dirt"},{"x":-6,"y":3,"z":-8,"name":"Soil_Dirt"},{"x":-6,"y":4,"z":-8,"name":"Soil_Dirt"},{"x":-6,"y":5,"z":-8,"name":"Soil_Pathway"},{"x":-6,"y":0,"z":-7,"name":"Soil_Dirt"},{"x":-6,"y":1,"z":-7,"name":"Soil_Dirt"},{"x":-6,"y":2,"z":-7,"name":"Soil_Dirt"},{"x":-6,"y":3,"z":-7,"name":"Soil_Dirt"},{"x":-6,"y":4,"z":-7,"name":"Soil_Dirt"},{"x":-6,"y":5,"z":-7,"name":"Soil_Pathway"},{"x":-6,"y":0,"z":-6,"name":"Soil_Dirt"},{"x":-6,"y":1,"z":-6,"name":"Soil_Dirt"},{"x":-6,"y":2,"z":-6,"name":"Soil_Dirt"},{"x":-6,"y":3,"z":-6,"name":"Soil_Dirt"},{"x":-6,"y":4,"z":-6,"name":"Soil_Dirt"},{"x":-6,"y":5,"z":-6,"name":"Soil_Clay"},{"x":-6,"y":0,"z":-5,"name":"Soil_Dirt"},{"x":-6,"y":1,"z":-5,"name":"Soil_Dirt"},{"x":-6,"y":2,"z":-5,"name":"Soil_Dirt"},{"x":-6,"y":3,"z":-5,"name":"Soil_Dirt"},{"x":-6,"y":4,"z":-5,"name":"Soil_Dirt"},{"x":-6,"y":5,"z":-5,"name":"Soil_Clay"},{"x":-6,"y":0,"z":-4,"name":"Soil_Dirt"},{"x":-6,"y":1,"z":-4,"name":"Soil_Dirt"},{"x":-6,"y":2,"z":-4,"name":"Soil_Dirt"},{"x":-6,"y":3,"z":-4,"name":"Soil_Dirt"},{"x":-6,"y":4,"z":-4,"name":"Soil_Dirt"},{"x":-6,"y":5,"z":-4,"name":"Soil_Dirt"},{"x":-6,"y":19,"z":-4,"name":"Plant_Leaves_Maple","rotation":2},{"x":-6,"y":0,"z":-3,"name":"Soil_Dirt"},{"x":-6,"y":1,"z":-3,"name":"Soil_Dirt"},{"x":-6,"y":2,"z":-3,"name":"Soil_Dirt"},{"x":-6,"y":3,"z":-3,"name":"Soil_Dirt"},{"x":-6,"y":4,"z":-3,"name":"Soil_Dirt"},{"x":-6,"y":5,"z":-3,"name":"Soil_Pathway"},{"x":-6,"y":18,"z":-3,"name":"Plant_Leaves_Maple","rotation":2},{"x":-6,"y":19,"z":-3,"name":"Plant_Leaves_Maple","rotation":2},{"x":-6,"y":20,"z":-3,"name":"Plant_Leaves_Maple","rotation":2},{"x":-6,"y":0,"z":-2,"name":"Soil_Dirt"},{"x":-6,"y":1,"z":-2,"name":"Soil_Dirt"},{"x":-6,"y":2,"z":-2,"name":"Soil_Dirt"},{"x":-6,"y":3,"z":-2,"name":"Soil_Dirt"},{"x":-6,"y":4,"z":-2,"name":"Soil_Dirt"},{"x":-6,"y":5,"z":-2,"name":"Soil_Pathway"},{"x":-6,"y":21,"z":-2,"name":"Plant_Leaves_Maple","rotation":2},{"x":-6,"y":0,"z":-1,"name":"Soil_Dirt"},{"x":-6,"y":1,"z":-1,"name":"Soil_Dirt"},{"x":-6,"y":2,"z":-1,"name":"Soil_Dirt"},{"x":-6,"y":3,"z":-1,"name":"Soil_Dirt"},{"x":-6,"y":4,"z":-1,"name":"Soil_Dirt"},{"x":-6,"y":5,"z":-1,"name":"Soil_Pathway"},{"x":-6,"y":6,"z":-1,"name":"Plant_Crop_Mushroom_Cap_Red"},{"x":-6,"y":19,"z":-1,"name":"Wood_Maple_Branch_Long","rotation":7},{"x":-6,"y":21,"z":-1,"name":"Plant_Leaves_Maple","rotation":2},{"x":-6,"y":0,"z":0,"name":"Soil_Dirt"},{"x":-6,"y":1,"z":0,"name":"Soil_Dirt"},{"x":-6,"y":2,"z":0,"name":"Soil_Dirt"},{"x":-6,"y":3,"z":0,"name":"Soil_Dirt"},{"x":-6,"y":4,"z":0,"name":"Soil_Dirt"},{"x":-6,"y":5,"z":0,"name":"Soil_Dirt"},{"x":-6,"y":21,"z":0,"name":"Plant_Leaves_Maple","rotation":2},{"x":-6,"y":22,"z":0,"name":"Plant_Leaves_Maple","rotation":2},{"x":-6,"y":0,"z":1,"name":"Soil_Dirt"},{"x":-6,"y":1,"z":1,"name":"Soil_Dirt"},{"x":-6,"y":2,"z":1,"name":"Soil_Dirt"},{"x":-6,"y":3,"z":1,"name":"Soil_Dirt"},{"x":-6,"y":4,"z":1,"name":"Soil_Dirt"},{"x":-6,"y":5,"z":1,"name":"Soil_Clay"},{"x":-6,"y":22,"z":1,"name":"Plant_Leaves_Maple","rotation":2},{"x":-6,"y":0,"z":2,"name":"Soil_Dirt"},{"x":-6,"y":1,"z":2,"name":"Soil_Dirt"},{"x":-6,"y":2,"z":2,"name":"Soil_Dirt"},{"x":-6,"y":3,"z":2,"name":"Soil_Dirt"},{"x":-6,"y":4,"z":2,"name":"Soil_Dirt"},{"x":-6,"y":5,"z":2,"name":"Soil_Grass_Sunny","support":15},{"x":-6,"y":23,"z":2,"name":"Plant_Leaves_Maple","rotation":2},{"x":-6,"y":0,"z":3,"name":"Soil_Dirt"},{"x":-6,"y":1,"z":3,"name":"Soil_Dirt"},{"x":-6,"y":2,"z":3,"name":"Soil_Grass_Sunny"},{"x":-6,"y":4,"z":3,"name":"Soil_Dirt","support":15},{"x":-6,"y":5,"z":3,"name":"Soil_Grass_Sunny","support":15},{"x":-6,"y":20,"z":3,"name":"Wood_Maple_Branch_Long","rotation":7},{"x":-6,"y":23,"z":3,"name":"Plant_Leaves_Maple","rotation":2},{"x":-6,"y":0,"z":4,"name":"Soil_Dirt"},{"x":-6,"y":1,"z":4,"name":"Soil_Dirt"},{"x":-6,"y":2,"z":4,"name":"Soil_Pathway","support":15},{"x":-6,"y":3,"z":4,"name":"Soil_Dirt"},{"x":-6,"y":4,"z":4,"name":"Soil_Grass_Sunny","support":15},{"x":-6,"y":23,"z":4,"name":"Plant_Leaves_Maple","rotation":2},{"x":-6,"y":24,"z":4,"name":"Plant_Leaves_Maple","rotation":2},{"x":-6,"y":0,"z":5,"name":"Soil_Dirt"},{"x":-6,"y":2,"z":5,"name":"Soil_Pathway","support":15},{"x":-6,"y":3,"z":5,"name":"Soil_Dirt","support":15},{"x":-6,"y":4,"z":5,"name":"Soil_Grass_Sunny","support":15},{"x":-6,"y":5,"z":5,"name":"Plant_Reeds_Marsh","support":15},{"x":-6,"y":0,"z":6,"name":"Soil_Dirt"},{"x":-6,"y":1,"z":6,"name":"Soil_Dirt"},{"x":-6,"y":2,"z":6,"name":"Soil_Pathway","support":15},{"x":-6,"y":3,"z":6,"name":"Soil_Dirt","support":15},{"x":-6,"y":4,"z":6,"name":"Soil_Grass_Sunny","support":15},{"x":-6,"y":5,"z":6,"name":"Plant_Crop_Mushroom_Common_Brown","components":{"Components":{"FarmingBlock":{"LastTickGameTime":"0001-01-21T12:00:00Z","SpreadRate":0.0}}}},{"x":-6,"y":15,"z":6,"name":"Wood_Maple_Trunk_Full","rotation":2},{"x":-6,"y":24,"z":6,"name":"Plant_Leaves_Maple","rotation":2},{"x":-6,"y":0,"z":7,"name":"Soil_Dirt"},{"x":-6,"y":1,"z":7,"name":"Soil_Dirt"},{"x":-6,"y":2,"z":7,"name":"Soil_Dirt","support":15},{"x":-6,"y":3,"z":7,"name":"Soil_Dirt","support":15},{"x":-6,"y":4,"z":7,"name":"Soil_Grass_Sunny","support":15},{"x":-6,"y":15,"z":7,"name":"Wood_Maple_Trunk_Full","rotation":2},{"x":-6,"y":23,"z":7,"name":"Wood_Maple_Trunk_Full","rotation":2},{"x":-6,"y":24,"z":7,"name":"Plant_Leaves_Maple","rotation":2},{"x":-6,"y":25,"z":7,"name":"Plant_Leaves_Maple","rotation":2},{"x":-6,"y":0,"z":8,"name":"Soil_Dirt"},{"x":-6,"y":1,"z":8,"name":"Soil_Dirt"},{"x":-6,"y":2,"z":8,"name":"Soil_Pathway","support":15},{"x":-6,"y":3,"z":8,"name":"Soil_Dirt","support":15},{"x":-6,"y":4,"z":8,"name":"Soil_Dirt","support":15},{"x":-6,"y":5,"z":8,"name":"Soil_Grass_Sunny","support":15},{"x":-6,"y":24,"z":8,"name":"Plant_Leaves_Maple","rotation":2},{"x":-6,"y":0,"z":9,"name":"Soil_Dirt"},{"x":-6,"y":3,"z":9,"name":"Soil_Dirt"},{"x":-6,"y":4,"z":9,"name":"Soil_Dirt","support":15},{"x":-6,"y":5,"z":9,"name":"Soil_Grass_Sunny","support":15},{"x":-6,"y":23,"z":9,"name":"Plant_Leaves_Maple","rotation":2},{"x":-6,"y":24,"z":9,"name":"Plant_Leaves_Maple","rotation":2},{"x":-6,"y":0,"z":10,"name":"Soil_Dirt"},{"x":-6,"y":1,"z":10,"name":"Soil_Dirt"},{"x":-6,"y":2,"z":10,"name":"Soil_Dirt"},{"x":-6,"y":3,"z":10,"name":"Soil_Dirt"},{"x":-6,"y":4,"z":10,"name":"Soil_Dirt"},{"x":-6,"y":5,"z":10,"name":"Soil_Grass_Sunny","support":15},{"x":-6,"y":6,"z":10,"name":"Plant_Grass_Sharp_Short"},{"x":-6,"y":21,"z":10,"name":"Plant_Leaves_Maple","rotation":2},{"x":-6,"y":22,"z":10,"name":"Plant_Leaves_Maple","rotation":2},{"x":-6,"y":23,"z":10,"name":"Plant_Leaves_Maple","rotation":2},{"x":-6,"y":0,"z":11,"name":"Soil_Dirt"},{"x":-6,"y":1,"z":11,"name":"Soil_Dirt"},{"x":-6,"y":2,"z":11,"name":"Soil_Dirt"},{"x":-6,"y":3,"z":11,"name":"Soil_Dirt"},{"x":-6,"y":4,"z":11,"name":"Soil_Dirt"},{"x":-6,"y":5,"z":11,"name":"Soil_Grass_Sunny","support":15},{"x":-6,"y":6,"z":11,"name":"Plant_Grass_Sharp_Short"},{"x":-6,"y":0,"z":12,"name":"Soil_Dirt"},{"x":-6,"y":1,"z":12,"name":"Soil_Dirt"},{"x":-6,"y":2,"z":12,"name":"Soil_Dirt"},{"x":-6,"y":3,"z":12,"name":"Soil_Dirt"},{"x":-6,"y":4,"z":12,"name":"Soil_Dirt"},{"x":-6,"y":5,"z":12,"name":"Soil_Grass_Sunny","support":15},{"x":-6,"y":6,"z":12,"name":"Plant_Grass_Sharp"},{"x":-6,"y":0,"z":13,"name":"Soil_Dirt"},{"x":-6,"y":1,"z":13,"name":"Soil_Dirt"},{"x":-6,"y":2,"z":13,"name":"Soil_Dirt"},{"x":-6,"y":3,"z":13,"name":"Soil_Dirt"},{"x":-6,"y":4,"z":13,"name":"Soil_Dirt"},{"x":-6,"y":5,"z":13,"name":"Soil_Grass_Sunny","support":15},{"x":-6,"y":6,"z":13,"name":"Plant_Grass_Sharp_Short"},{"x":-6,"y":15,"z":13,"name":"Plant_Leaves_Maple","rotation":2},{"x":-6,"y":17,"z":13,"name":"Plant_Leaves_Maple","rotation":2},{"x":-6,"y":18,"z":13,"name":"Plant_Leaves_Maple","rotation":2},{"x":-6,"y":0,"z":14,"name":"Soil_Dirt"},{"x":-6,"y":1,"z":14,"name":"Soil_Dirt"},{"x":-6,"y":2,"z":14,"name":"Soil_Dirt"},{"x":-6,"y":3,"z":14,"name":"Soil_Dirt"},{"x":-6,"y":4,"z":14,"name":"Soil_Dirt"},{"x":-6,"y":5,"z":14,"name":"Soil_Grass_Sunny","support":15},{"x":-6,"y":6,"z":14,"name":"Plant_Grass_Sharp_Short"},{"x":-6,"y":15,"z":14,"name":"Plant_Leaves_Maple","rotation":2},{"x":-6,"y":16,"z":14,"name":"Plant_Leaves_Maple","rotation":2},{"x":-6,"y":17,"z":14,"name":"Plant_Leaves_Maple","rotation":2},{"x":-6,"y":18,"z":14,"name":"Plant_Leaves_Maple","rotation":2},{"x":-6,"y":0,"z":15,"name":"Soil_Dirt"},{"x":-6,"y":1,"z":15,"name":"Soil_Dirt"},{"x":-6,"y":2,"z":15,"name":"Soil_Dirt"},{"x":-6,"y":3,"z":15,"name":"Soil_Dirt"},{"x":-6,"y":4,"z":15,"name":"Soil_Dirt"},{"x":-6,"y":5,"z":15,"name":"Rock_Stone_Brick_Smooth"},{"x":-5,"y":0,"z":-14,"name":"Soil_Dirt"},{"x":-5,"y":1,"z":-14,"name":"Soil_Dirt"},{"x":-5,"y":2,"z":-14,"name":"Soil_Dirt"},{"x":-5,"y":3,"z":-14,"name":"Soil_Dirt"},{"x":-5,"y":4,"z":-14,"name":"Soil_Dirt"},{"x":-5,"y":5,"z":-14,"name":"Rock_Stone_Brick_Smooth"},{"x":-5,"y":0,"z":-13,"name":"Soil_Dirt"},{"x":-5,"y":1,"z":-13,"name":"Soil_Dirt"},{"x":-5,"y":2,"z":-13,"name":"Soil_Dirt"},{"x":-5,"y":3,"z":-13,"name":"Soil_Dirt"},{"x":-5,"y":4,"z":-13,"name":"Soil_Dirt"},{"x":-5,"y":5,"z":-13,"name":"Soil_Grass_Sunny","support":15},{"x":-5,"y":0,"z":-12,"name":"Soil_Dirt"},{"x":-5,"y":1,"z":-12,"name":"Soil_Dirt"},{"x":-5,"y":2,"z":-12,"name":"Soil_Dirt"},{"x":-5,"y":3,"z":-12,"name":"Soil_Dirt"},{"x":-5,"y":4,"z":-12,"name":"Soil_Dirt"},{"x":-5,"y":5,"z":-12,"name":"Soil_Pathway"},{"x":-5,"y":6,"z":-12,"name":"Plant_Flower_Common_Yellow2","support":15},{"x":-5,"y":0,"z":-11,"name":"Soil_Dirt"},{"x":-5,"y":1,"z":-11,"name":"Soil_Dirt"},{"x":-5,"y":2,"z":-11,"name":"Soil_Dirt"},{"x":-5,"y":3,"z":-11,"name":"Soil_Dirt"},{"x":-5,"y":4,"z":-11,"name":"Soil_Dirt"},{"x":-5,"y":5,"z":-11,"name":"Soil_Pathway"},{"x":-5,"y":6,"z":-11,"name":"Wood_Hardwood_Decorative"},{"x":-5,"y":7,"z":-11,"name":"Wood_Hardwood_Planks"},{"x":-5,"y":8,"z":-11,"name":"Wood_Hardwood_Planks"},{"x":-5,"y":9,"z":-11,"name":"Wood_Hardwood_Stairs","rotation":3},{"x":-5,"y":0,"z":-10,"name":"Soil_Dirt"},{"x":-5,"y":1,"z":-10,"name":"Soil_Dirt"},{"x":-5,"y":2,"z":-10,"name":"Soil_Dirt"},{"x":-5,"y":3,"z":-10,"name":"Soil_Dirt"},{"x":-5,"y":4,"z":-10,"name":"Soil_Dirt"},{"x":-5,"y":5,"z":-10,"name":"Soil_Clay"},{"x":-5,"y":6,"z":-10,"name":"Wood_Hardwood_Decorative"},{"x":-5,"y":7,"z":-10,"name":"Wood_Hardwood_Planks"},{"x":-5,"y":9,"z":-10,"name":"Cloth_Modern_Red_Roof","support":15,"rotation":3},{"x":-5,"y":0,"z":-9,"name":"Soil_Dirt"},{"x":-5,"y":1,"z":-9,"name":"Soil_Dirt"},{"x":-5,"y":2,"z":-9,"name":"Soil_Dirt"},{"x":-5,"y":3,"z":-9,"name":"Soil_Dirt"},{"x":-5,"y":4,"z":-9,"name":"Soil_Dirt"},{"x":-5,"y":5,"z":-9,"name":"Soil_Pathway"},{"x":-5,"y":6,"z":-9,"name":"Wood_Hardwood_Decorative"},{"x":-5,"y":7,"z":-9,"name":"Wood_Hardwood_Beam"},{"x":-5,"y":8,"z":-9,"name":"Wood_Hardwood_Beam"},{"x":-5,"y":9,"z":-9,"name":"*Cloth_Modern_Red_Roof_State_Definitions_Corner_Right"},{"x":-5,"y":0,"z":-8,"name":"Soil_Dirt"},{"x":-5,"y":1,"z":-8,"name":"Soil_Dirt"},{"x":-5,"y":2,"z":-8,"name":"Soil_Dirt"},{"x":-5,"y":3,"z":-8,"name":"Soil_Dirt"},{"x":-5,"y":4,"z":-8,"name":"Soil_Dirt"},{"x":-5,"y":5,"z":-8,"name":"Soil_Clay"},{"x":-5,"y":0,"z":-7,"name":"Soil_Dirt"},{"x":-5,"y":1,"z":-7,"name":"Soil_Dirt"},{"x":-5,"y":2,"z":-7,"name":"Soil_Dirt"},{"x":-5,"y":3,"z":-7,"name":"Soil_Dirt"},{"x":-5,"y":4,"z":-7,"name":"Soil_Dirt"},{"x":-5,"y":5,"z":-7,"name":"Soil_Pathway"},{"x":-5,"y":0,"z":-6,"name":"Soil_Dirt"},{"x":-5,"y":1,"z":-6,"name":"Soil_Dirt"},{"x":-5,"y":2,"z":-6,"name":"Soil_Dirt"},{"x":-5,"y":3,"z":-6,"name":"Soil_Dirt"},{"x":-5,"y":4,"z":-6,"name":"Soil_Dirt"},{"x":-5,"y":5,"z":-6,"name":"Soil_Pathway"},{"x":-5,"y":0,"z":-5,"name":"Soil_Dirt"},{"x":-5,"y":1,"z":-5,"name":"Soil_Dirt"},{"x":-5,"y":2,"z":-5,"name":"Soil_Dirt"},{"x":-5,"y":3,"z":-5,"name":"Soil_Dirt"},{"x":-5,"y":4,"z":-5,"name":"Soil_Dirt"},{"x":-5,"y":5,"z":-5,"name":"Soil_Dirt"},{"x":-5,"y":0,"z":-4,"name":"Soil_Dirt"},{"x":-5,"y":1,"z":-4,"name":"Soil_Dirt"},{"x":-5,"y":2,"z":-4,"name":"Soil_Dirt"},{"x":-5,"y":3,"z":-4,"name":"Soil_Dirt"},{"x":-5,"y":4,"z":-4,"name":"Soil_Dirt"},{"x":-5,"y":5,"z":-4,"name":"Soil_Dirt"},{"x":-5,"y":18,"z":-4,"name":"Plant_Leaves_Maple","rotation":2},{"x":-5,"y":19,"z":-4,"name":"Plant_Leaves_Maple","rotation":2},{"x":-5,"y":0,"z":-3,"name":"Soil_Dirt"},{"x":-5,"y":1,"z":-3,"name":"Soil_Dirt"},{"x":-5,"y":2,"z":-3,"name":"Soil_Dirt"},{"x":-5,"y":3,"z":-3,"name":"Soil_Dirt"},{"x":-5,"y":4,"z":-3,"name":"Soil_Dirt"},{"x":-5,"y":5,"z":-3,"name":"Soil_Clay"},{"x":-5,"y":17,"z":-3,"name":"Plant_Leaves_Maple","rotation":2},{"x":-5,"y":18,"z":-3,"name":"Plant_Leaves_Maple","rotation":2},{"x":-5,"y":19,"z":-3,"name":"Wood_Maple_Branch_Long","rotation":6},{"x":-5,"y":20,"z":-3,"name":"Plant_Leaves_Maple","rotation":2},{"x":-5,"y":0,"z":-2,"name":"Soil_Dirt"},{"x":-5,"y":1,"z":-2,"name":"Soil_Dirt"},{"x":-5,"y":2,"z":-2,"name":"Soil_Dirt"},{"x":-5,"y":3,"z":-2,"name":"Soil_Dirt"},{"x":-5,"y":4,"z":-2,"name":"Soil_Dirt"},{"x":-5,"y":5,"z":-2,"name":"Soil_Clay"},{"x":-5,"y":19,"z":-2,"name":"Wood_Maple_Branch_Long","rotation":6},{"x":-5,"y":21,"z":-2,"name":"Plant_Leaves_Maple","rotation":2},{"x":-5,"y":0,"z":-1,"name":"Soil_Dirt"},{"x":-5,"y":1,"z":-1,"name":"Soil_Dirt"},{"x":-5,"y":2,"z":-1,"name":"Soil_Dirt"},{"x":-5,"y":3,"z":-1,"name":"Soil_Dirt"},{"x":-5,"y":4,"z":-1,"name":"Soil_Dirt"},{"x":-5,"y":5,"z":-1,"name":"Soil_Pathway"},{"x":-5,"y":19,"z":-1,"name":"Wood_Maple_Trunk_Full","rotation":2},{"x":-5,"y":20,"z":-1,"name":"Wood_Maple_Branch_Long","rotation":2},{"x":-5,"y":21,"z":-1,"name":"Plant_Leaves_Maple","rotation":2},{"x":-5,"y":0,"z":0,"name":"Soil_Dirt"},{"x":-5,"y":1,"z":0,"name":"Soil_Dirt"},{"x":-5,"y":2,"z":0,"name":"Soil_Dirt"},{"x":-5,"y":3,"z":0,"name":"Soil_Dirt"},{"x":-5,"y":4,"z":0,"name":"Soil_Dirt"},{"x":-5,"y":5,"z":0,"name":"Soil_Clay"},{"x":-5,"y":19,"z":0,"name":"Wood_Maple_Trunk_Full","rotation":2},{"x":-5,"y":21,"z":0,"name":"Plant_Leaves_Maple","rotation":2},{"x":-5,"y":22,"z":0,"name":"Plant_Leaves_Maple","rotation":2},{"x":-5,"y":0,"z":1,"name":"Soil_Dirt"},{"x":-5,"y":1,"z":1,"name":"Soil_Dirt"},{"x":-5,"y":2,"z":1,"name":"Soil_Dirt"},{"x":-5,"y":3,"z":1,"name":"Soil_Dirt"},{"x":-5,"y":4,"z":1,"name":"Soil_Dirt"},{"x":-5,"y":5,"z":1,"name":"Soil_Pathway"},{"x":-5,"y":23,"z":1,"name":"Plant_Leaves_Maple","rotation":2},{"x":-5,"y":0,"z":2,"name":"Soil_Dirt"},{"x":-5,"y":1,"z":2,"name":"Soil_Dirt"},{"x":-5,"y":2,"z":2,"name":"Soil_Dirt"},{"x":-5,"y":3,"z":2,"name":"Soil_Dirt"},{"x":-5,"y":4,"z":2,"name":"Soil_Dirt"},{"x":-5,"y":5,"z":2,"name":"Soil_Grass_Sunny"},{"x":-5,"y":23,"z":2,"name":"Plant_Leaves_Maple","rotation":2},{"x":-5,"y":0,"z":3,"name":"Soil_Dirt"},{"x":-5,"y":1,"z":3,"name":"Soil_Dirt"},{"x":-5,"y":2,"z":3,"name":"Soil_Dirt"},{"x":-5,"y":3,"z":3,"name":"Soil_Dirt"},{"x":-5,"y":4,"z":3,"name":"Soil_Dirt"},{"x":-5,"y":5,"z":3,"name":"Soil_Grass_Sunny","support":15},{"x":-5,"y":6,"z":3,"name":"Plant_Crop_Mushroom_Cap_Red"},{"x":-5,"y":20,"z":3,"name":"Wood_Maple_Trunk_Full","rotation":2},{"x":-5,"y":23,"z":3,"name":"Plant_Leaves_Maple","rotation":2},{"x":-5,"y":0,"z":4,"name":"Soil_Dirt"},{"x":-5,"y":1,"z":4,"name":"Soil_Dirt"},{"x":-5,"y":2,"z":4,"name":"Soil_Dirt"},{"x":-5,"y":3,"z":4,"name":"Soil_Dirt"},{"x":-5,"y":4,"z":4,"name":"Soil_Dirt"},{"x":-5,"y":5,"z":4,"name":"Soil_Grass_Sunny","support":15},{"x":-5,"y":24,"z":4,"name":"Plant_Leaves_Maple","rotation":2},{"x":-5,"y":0,"z":5,"name":"Soil_Dirt"},{"x":-5,"y":2,"z":5,"name":"Soil_Pathway","support":15},{"x":-5,"y":4,"z":5,"name":"Soil_Dirt"},{"x":-5,"y":5,"z":5,"name":"Soil_Grass_Sunny","support":15},{"x":-5,"y":6,"z":5,"name":"Plant_Flower_Common_Red2","support":15},{"x":-5,"y":24,"z":5,"name":"Plant_Leaves_Maple","rotation":2},{"x":-5,"y":0,"z":6,"name":"Soil_Dirt"},{"x":-5,"y":2,"z":6,"name":"Soil_Dirt"},{"x":-5,"y":4,"z":6,"name":"Soil_Dirt","support":15},{"x":-5,"y":5,"z":6,"name":"Soil_Grass_Sunny","support":15},{"x":-5,"y":14,"z":6,"name":"Wood_Maple_Trunk_Full","rotation":2},{"x":-5,"y":15,"z":6,"name":"Wood_Maple_Trunk_Full","rotation":2},{"x":-5,"y":23,"z":6,"name":"Plant_Leaves_Maple","rotation":2},{"x":-5,"y":24,"z":6,"name":"Plant_Leaves_Maple","rotation":2},{"x":-5,"y":25,"z":6,"name":"Plant_Leaves_Maple","rotation":2},{"x":-5,"y":0,"z":7,"name":"Soil_Dirt"},{"x":-5,"y":1,"z":7,"name":"Soil_Dirt"},{"x":-5,"y":2,"z":7,"name":"Soil_Dirt"},{"x":-5,"y":3,"z":7,"name":"Soil_Dirt"},{"x":-5,"y":4,"z":7,"name":"Soil_Dirt"},{"x":-5,"y":5,"z":7,"name":"Soil_Grass_Sunny","support":15},{"x":-5,"y":22,"z":7,"name":"Wood_Maple_Trunk_Full","rotation":2},{"x":-5,"y":23,"z":7,"name":"Wood_Maple_Trunk_Full","rotation":2},{"x":-5,"y":24,"z":7,"name":"Plant_Leaves_Maple","rotation":2},{"x":-5,"y":25,"z":7,"name":"Plant_Leaves_Maple","rotation":2},{"x":-5,"y":0,"z":8,"name":"Soil_Dirt"},{"x":-5,"y":1,"z":8,"name":"Soil_Dirt"},{"x":-5,"y":2,"z":8,"name":"Soil_Dirt"},{"x":-5,"y":3,"z":8,"name":"Soil_Dirt"},{"x":-5,"y":4,"z":8,"name":"Soil_Dirt"},{"x":-5,"y":5,"z":8,"name":"Soil_Grass_Sunny","support":15},{"x":-5,"y":25,"z":8,"name":"Plant_Leaves_Maple","rotation":2},{"x":-5,"y":0,"z":9,"name":"Soil_Dirt"},{"x":-5,"y":1,"z":9,"name":"Soil_Dirt"},{"x":-5,"y":2,"z":9,"name":"Soil_Dirt"},{"x":-5,"y":3,"z":9,"name":"Soil_Dirt"},{"x":-5,"y":4,"z":9,"name":"Soil_Dirt"},{"x":-5,"y":5,"z":9,"name":"Soil_Grass_Sunny","support":15},{"x":-5,"y":6,"z":9,"name":"Plant_Leaves_Autumn_Floor","support":15},{"x":-5,"y":21,"z":9,"name":"Plant_Leaves_Maple","rotation":2},{"x":-5,"y":24,"z":9,"name":"Plant_Leaves_Maple","rotation":2},{"x":-5,"y":0,"z":10,"name":"Soil_Dirt"},{"x":-5,"y":1,"z":10,"name":"Soil_Dirt"},{"x":-5,"y":2,"z":10,"name":"Soil_Dirt"},{"x":-5,"y":3,"z":10,"name":"Soil_Dirt"},{"x":-5,"y":4,"z":10,"name":"Soil_Dirt"},{"x":-5,"y":5,"z":10,"name":"Soil_Grass_Sunny","support":15},{"x":-5,"y":6,"z":10,"name":"Plant_Grass_Sharp_Short"},{"x":-5,"y":22,"z":10,"name":"Plant_Leaves_Maple","rotation":2},{"x":-5,"y":23,"z":10,"name":"Plant_Leaves_Maple","rotation":2},{"x":-5,"y":0,"z":11,"name":"Soil_Dirt"},{"x":-5,"y":1,"z":11,"name":"Soil_Dirt"},{"x":-5,"y":2,"z":11,"name":"Soil_Dirt"},{"x":-5,"y":3,"z":11,"name":"Soil_Dirt"},{"x":-5,"y":4,"z":11,"name":"Soil_Dirt"},{"x":-5,"y":5,"z":11,"name":"Soil_Grass_Sunny","support":15},{"x":-5,"y":6,"z":11,"name":"Plant_Grass_Sharp"},{"x":-5,"y":0,"z":12,"name":"Soil_Dirt"},{"x":-5,"y":1,"z":12,"name":"Soil_Dirt"},{"x":-5,"y":2,"z":12,"name":"Soil_Dirt"},{"x":-5,"y":3,"z":12,"name":"Soil_Dirt"},{"x":-5,"y":4,"z":12,"name":"Soil_Dirt"},{"x":-5,"y":5,"z":12,"name":"Soil_Grass_Sunny","support":15},{"x":-5,"y":6,"z":12,"name":"Plant_Grass_Sharp"},{"x":-5,"y":0,"z":13,"name":"Soil_Dirt"},{"x":-5,"y":1,"z":13,"name":"Soil_Dirt"},{"x":-5,"y":2,"z":13,"name":"Soil_Dirt"},{"x":-5,"y":3,"z":13,"name":"Soil_Dirt"},{"x":-5,"y":4,"z":13,"name":"Soil_Dirt"},{"x":-5,"y":5,"z":13,"name":"Soil_Grass_Sunny","support":15},{"x":-5,"y":6,"z":13,"name":"Plant_Grass_Sharp"},{"x":-5,"y":0,"z":14,"name":"Soil_Dirt"},{"x":-5,"y":1,"z":14,"name":"Soil_Dirt"},{"x":-5,"y":2,"z":14,"name":"Soil_Dirt"},{"x":-5,"y":3,"z":14,"name":"Soil_Dirt"},{"x":-5,"y":4,"z":14,"name":"Soil_Dirt"},{"x":-5,"y":5,"z":14,"name":"Soil_Grass_Sunny","support":15},{"x":-5,"y":6,"z":14,"name":"Plant_Grass_Sharp_Short"},{"x":-5,"y":15,"z":14,"name":"Plant_Leaves_Maple","rotation":2},{"x":-5,"y":16,"z":14,"name":"Plant_Leaves_Maple","rotation":2},{"x":-5,"y":18,"z":14,"name":"Plant_Leaves_Maple","rotation":2},{"x":-5,"y":0,"z":15,"name":"Soil_Dirt"},{"x":-5,"y":1,"z":15,"name":"Soil_Dirt"},{"x":-5,"y":2,"z":15,"name":"Soil_Dirt"},{"x":-5,"y":3,"z":15,"name":"Soil_Dirt"},{"x":-5,"y":4,"z":15,"name":"Soil_Dirt"},{"x":-5,"y":5,"z":15,"name":"Rock_Stone_Brick_Smooth"},{"x":-5,"y":16,"z":15,"name":"Plant_Leaves_Maple","rotation":2},{"x":-5,"y":17,"z":15,"name":"Plant_Leaves_Maple","rotation":2},{"x":-4,"y":0,"z":-14,"name":"Soil_Dirt"},{"x":-4,"y":1,"z":-14,"name":"Soil_Dirt"},{"x":-4,"y":2,"z":-14,"name":"Soil_Dirt"},{"x":-4,"y":3,"z":-14,"name":"Soil_Dirt"},{"x":-4,"y":4,"z":-14,"name":"Soil_Dirt"},{"x":-4,"y":5,"z":-14,"name":"Rock_Stone_Brick_Smooth"},{"x":-4,"y":0,"z":-13,"name":"Soil_Dirt"},{"x":-4,"y":1,"z":-13,"name":"Soil_Dirt"},{"x":-4,"y":2,"z":-13,"name":"Soil_Dirt"},{"x":-4,"y":3,"z":-13,"name":"Soil_Dirt"},{"x":-4,"y":4,"z":-13,"name":"Soil_Dirt"},{"x":-4,"y":5,"z":-13,"name":"Soil_Grass_Sunny","support":15},{"x":-4,"y":6,"z":-13,"name":"Plant_Grass_Sharp_Short"},{"x":-4,"y":0,"z":-12,"name":"Soil_Dirt"},{"x":-4,"y":1,"z":-12,"name":"Soil_Dirt"},{"x":-4,"y":2,"z":-12,"name":"Soil_Dirt"},{"x":-4,"y":3,"z":-12,"name":"Soil_Dirt"},{"x":-4,"y":4,"z":-12,"name":"Soil_Dirt"},{"x":-4,"y":5,"z":-12,"name":"Soil_Pathway"},{"x":-4,"y":0,"z":-11,"name":"Soil_Dirt"},{"x":-4,"y":1,"z":-11,"name":"Soil_Dirt"},{"x":-4,"y":2,"z":-11,"name":"Soil_Dirt"},{"x":-4,"y":3,"z":-11,"name":"Soil_Dirt"},