{
  "version": 8,
  "blockIdVersion": 11,
  "anchorX": 0,
  "anchorY": 0,
  "anchorZ": 0,
  "blocks": [
    {
      "x": -14,
      "y": 0,
      "z": -14,
      "name": "Soil_Dirt"
    },
    {
      "x": -14,
      "y": 1,
      "z": -14,
      "name": "Soil_Dirt"
    },
    {
      "x": -14,
      "y": 2,
      "z": -14,
      "name": "Soil_Dirt"
    },
    {
      "x": -14,
      "y": 3,
      "z": -14,
      "name": "Soil_Dirt"
    },
    {
      "x": -14,
      "y": 4,
      "z": -14,
      "name": "Soil_Dirt"
    },
    {
      "x": -14,
      "y": 5,
      "z": -14,
      "name": "Rock_Stone_Brick_Smooth"
    },
    {
      "x": -14,
      "y": 0,
      "z": -13,
      "name": "Soil_Dirt"
    },
    {
      "x": -14,
      "y": 1,
      "z": -13,
      "name": "Soil_Dirt"
    },
    {
      "x": -14,
      "y": 2,
      "z": -13,
      "name": "Soil_Dirt"
    },
    {
      "x": -14,
      "y": 3,
      "z": -13,
      "name": "Soil_Dirt"
    },
    {
      "x": -14,
      "y": 4,
      "z": -13,
      "name": "Soil_Dirt"
    },
    {
      "x": -14,
      "y": 5,
      "z": -13,
      "name": "Rock_Stone_Brick_Smooth"
    },
    {
      "x": -14,
      "y": 0,
      "z": -12,
      "name": "Soil_Dirt"
    },
    {
      "x": -14,
      "y": 1,
      "z": -12,
      "name": "Soil_Dirt"
    },
    {
      "x": -14,
      "y": 2,
      "z": -12,
      "name": "Soil_Dirt"
    },
    {
      "x": -14,
      "y": 3,
      "z": -12,
      "name": "Soil_Dirt"
    },
    {
      "x": -14,
      "y": 4,
      "z": -12,
      "name": "Soil_Dirt"
    },
    {
      "x": -14,
      "y": 5,
      "z": -12,
      "name": "Rock_Stone_Brick_Smooth"
    },
    {
      "x": -14,
      "y": 0,
      "z": -11,
      "name": "Soil_Dirt"
    },
    {
      "x": -14,
      "y": 1,
      "z": -11,
      "name": "Soil_Dirt"
    },
    {
      "x": -14,
      "y": 2,
      "z": -11,
      "name": "Soil_Dirt"
    },
    {
      "x": -14,
      "y": 3,
      "z": -11,
      "name": "Soil_Dirt"
    },
    {
      "x": -14,
      "y": 4,
      "z": -11,
      "name": "Soil_Dirt"
    },
    {
      "x": -14,
      "y": 5,
      "z": -11,
      "name": "Rock_Stone_Brick_Smooth"
    },
    {
      "x": -14,
      "y": 0,
      "z": -10,
      "name": "Soil_Dirt"
    },
    {
      "x": -14,
      "y": 1,
      "z": -10,
      "name": "Soil_Dirt"
    },
    {
      "x": -14,
      "y": 2,
      "z": -10,
      "name": "Soil_Dirt"
    },
    {
      "x": -14,
      "y": 3,
      "z": -10,
      "name": "Soil_Dirt"
    },
    {
      "x": -14,
      "y": 4,
      "z": -10,
      "name": "Soil_Dirt"
    },
    {
      "x": -14,
      "y": 5,
      "z": -10,
      "name": "Rock_Stone_Brick_Smooth"
    },
    {
      "x": -14,
      "y": 0,
      "z": -9,
      "name": "Soil_Dirt"
    },
    {
      "x": -14,
      "y": 1,
      "z": -9,
      "name": "Soil_Dirt"
    },
    {
      "x": -14,
      "y": 2,
      "z": -9,
      "name": "Soil_Dirt"
    },
    {
      "x": -14,
      "y": 3,
      "z": -9,
      "name": "Soil_Dirt"
    },
    {
      "x": -14,
      "y": 4,
      "z": -9,
      "name": "Soil_Dirt"
    },
    {
      "x": -14,
      "y": 5,
      "z": -9,
      "name": "Rock_Stone_Brick_Smooth"
    },
    {
      "x": -14,
      "y": 0,
      "z": -8,
      "name": "Soil_Dirt"
    },
    {
      "x": -14,
      "y": 1,
      "z": -8,
      "name": "Soil_Dirt"
    },
    {
      "x": -14,
      "y": 2,
      "z": -8,
      "name": "Soil_Dirt"
    },
    {
      "x": -14,
      "y": 3,
      "z": -8,
      "name": "Soil_Dirt"
    },
    {
      "x": -14,
      "y": 4,
      "z": -8,
      "name": "Soil_Dirt"
    },
    {
      "x": -14,
      "y": 5,
      "z": -8,
      "name": "Rock_Stone_Brick_Smooth"
    },
    {
      "x": -14,
      "y": 0,
      "z": -7,
      "name": "Soil_Dirt"
    },
    {
      "x": -14,
      "y": 1,
      "z": -7,
      "name": "Soil_Dirt"
    },
    {
      "x": -14,
      "y": 2,
      "z": -7,
      "name": "Soil_Dirt"
    },
    {
      "x": -14,
      "y": 3,
      "z": -7,
      "name": "Soil_Dirt"
    },
    {
      "x": -14,
      "y": 4,
      "z": -7,
      "name": "Soil_Dirt"
    },
    {
      "x": -14,
      "y": 5,
      "z": -7,
      "name": "Rock_Stone_Brick_Smooth"
    },
    {
      "x": -14,
      "y": 0,
      "z": -6,
      "name": "Soil_Dirt"
    },
    {
      "x": -14,
      "y": 1,
      "z": -6,
      "name": "Soil_Dirt"
    },
    {
      "x": -14,
      "y": 2,
      "z": -6,
      "name": "Soil_Dirt"
    },
    {
      "x": -14,
      "y": 3,
      "z": -6,
      "name": "Soil_Dirt"
    },
    {
      "x": -14,
      "y": 4,
      "z": -6,
      "name": "Soil_Dirt"
    },
    {
      "x": -14,
      "y": 5,
      "z": -6,
      "name": "Rock_Stone_Brick_Smooth"
    },
    {
      "x": -14,
      "y": 0,
      "z": -5,
      "name": "Soil_Dirt"
    },
    {
      "x": -14,
      "y": 1,
      "z": -5,
      "name": "Soil_Dirt"
    },
    {
      "x": -14,
      "y": 2,
      "z": -5,
      "name": "Soil_Dirt"
    },
    {
      "x": -14,
      "y": 3,
      "z": -5,
      "name": "Soil_Dirt"
    },
    {
      "x": -14,
      "y": 4,
      "z": -5,
      "name": "Soil_Dirt"
    },
    {
      "x": -14,
      "y": 5,
      "z": -5,
      "name": "Rock_Stone_Brick_Smooth"
    },
    {
      "x": -14,
      "y": 0,
      "z": -4,
      "name": "Soil_Dirt"
    },
    {
      "x": -14,
      "y": 1,
      "z": -4,
      "name": "Soil_Dirt"
    },
    {
      "x": -14,
      "y": 2,
      "z": -4,
      "name": "Soil_Dirt"
    },
    {
      "x": -14,
      "y": 3,
      "z": -4,
      "name": "Soil_Dirt"
    },
    {
      "x": -14,
      "y": 4,
      "z": -4,
      "name": "Soil_Dirt"
    },
    {
      "x": -14,
      "y": 5,
      "z": -4,
      "name": "Rock_Stone_Brick_Smooth"
    },
    {
      "x": -14,
      "y": 0,
      "z": -3,
      "name": "Soil_Dirt"
    },
    {
      "x": -14,
      "y": 1,
      "z": -3,
      "name": "Soil_Dirt"
    },
    {
      "x": -14,
      "y": 2,
      "z": -3,
      "name": "Soil_Dirt"
    },
    {
      "x": -14,
      "y": 3,
      "z": -3,
      "name": "Soil_Dirt"
    },
    {
      "x": -14,
      "y": 4,
      "z": -3,
      "name": "Soil_Dirt"
    },
    {
      "x": -14,
      "y": 5,
      "z": -3,
      "name": "Rock_Stone_Brick_Smooth"
    },
    {
      "x": -14,
      "y": 0,
      "z": -2,
      "name": "Soil_Dirt"
    },
    {
      "x": -14,
      "y": 1,
      "z": -2,
      "name": "Soil_Dirt"
    },
    {
      "x": -14,
      "y": 2,
      "z": -2,
      "name": "Soil_Dirt"
    },
    {
      "x": -14,
      "y": 3,
      "z": -2,
      "name": "Soil_Dirt"
    },
    {
      "x": -14,
      "y": 4,
      "z": -2,
      "name": "Soil_Dirt"
    },
    {
      "x": -14,
      "y": 5,
      "z": -2,
      "name": "Rock_Stone_Brick_Smooth"
    },
    {
      "x": -14,
      "y": 0,
      "z": -1,
      "name": "Soil_Dirt"
    },
    {
      "x": -14,
      "y": 1,
      "z": -1,
      "name": "Soil_Dirt"
    },
    {
      "x": -14,
      "y": 2,
      "z": -1,
      "name": "Soil_Dirt"
    },
    {
      "x": -14,
      "y": 3,
      "z": -1,
      "name": "Soil_Dirt"
    },
    {
      "x": -14,
      "y": 4,
      "z": -1,
      "name": "Soil_Dirt"
    },
    {
      "x": -14,
      "y": 5,
      "z": -1,
      "name": "Rock_Stone_Brick_Smooth"
    },
    {
      "x": -14,
      "y": 0,
      "z": 0,
      "name": "Soil_Dirt"
    },
    {
      "x": -14,
      "y": 1,
      "z": 0,
      "name": "Soil_Dirt"
    },
    {
      "x": -14,
      "y": 2,
      "z": 0,
      "name": "Soil_Dirt"
    },
    {
      "x": -14,
      "y": 3,
      "z": 0,
      "name": "Soil_Dirt"
    },
    {
      "x": -14,
      "y": 4,
      "z": 0,
      "name": "Soil_Dirt"
    },
    {
      "x": -14,
      "y": 5,
      "z": 0,
      "name": "Rock_Stone_Brick_Smooth"
    },
    {
      "x": -14,
      "y": 0,
      "z": 1,
      "name": "Soil_Dirt"
    },
    {
      "x": -14,
      "y": 1,
      "z": 1,
      "name": "Soil_Dirt"
    },
    {
      "x": -14,
      "y": 2,
      "z": 1,
      "name": "Soil_Dirt"
    },
    {
      "x": -14,
      "y": 3,
      "z": 1,
      "name": "Soil_Dirt"
    },
    {
      "x": -14,
      "y": 4,
      "z": 1,
      "name": "Soil_Dirt"
    },
    {
      "x": -14,
      "y": 5,
      "z": 1,
      "name": "Rock_Stone_Brick_Smooth"
    },
    {
      "x": -14,
      "y": 0,
      "z": 2,
      "name": "Soil_Dirt"
    },
    {
      "x": -14,
      "y": 1,
      "z": 2,
      "name": "Soil_Dirt"
    },
    {
      "x": -14,
      "y": 2,
      "z": 2,
      "name": "Soil_Dirt"
    },
    {
      "x": -14,
      "y": 3,
      "z": 2,
      "name": "Soil_Dirt"
    },
    {
      "x": -14,
      "y": 4,
      "z": 2,
      "name": "Soil_Dirt"
    },
    {
      "x": -14,
      "y": 5,
      "z": 2,
      "name": "Rock_Stone_Brick_Smooth"
    },
    {
      "x": -14,
      "y": 0,
      "z": 3,
      "name": "Soil_Dirt"
    },
    {
      "x": -14,
      "y": 1,
      "z": 3,
      "name": "Soil_Dirt"
    },
    {
      "x": -14,
      "y": 2,
      "z": 3,
      "name": "Soil_Dirt"
    },
    {
      "x": -14,
      "y": 3,
      "z": 3,
      "name": "Soil_Dirt"
    },
    {
      "x": -14,
      "y": 4,
      "z": 3,
      "name": "Soil_Dirt"
    },
    {
      "x": -14,
      "y": 5,
      "z": 3,
      "name": "Rock_Stone_Brick_Smooth"
    },
    {
      "x": -14,
      "y": 0,
      "z": 4,
      "name": "Soil_Dirt"
    },
    {
      "x": -14,
      "y": 1,
      "z": 4,
      "name": "Soil_Dirt"
    },
    {
      "x": -14,
      "y": 2,
      "z": 4,
      "name": "Soil_Dirt"
    },
    {
      "x": -14,
      "y": 3,
      "z": 4,
      "name": "Soil_Dirt"
    },
    {
      "x": -14,
      "y": 4,
      "z": 4,
      "name": "Soil_Dirt"
    },
    {
      "x": -14,
      "y": 5,
      "z": 4,
      "name": "Rock_Stone_Brick_Smooth"
    },
    {
      "x": -14,
      "y": 0,
      "z": 5,
      "name": "Soil_Dirt"
    },
    {
      "x": -14,
      "y": 1,
      "z": 5,
      "name": "Soil_Dirt"
    },
    {
      "x": -14,
      "y": 2,
      "z": 5,
      "name": "Soil_Dirt"
    },
    {
      "x": -14,
      "y": 3,
      "z": 5,
      "name": "Soil_Dirt"
    },
    {
      "x": -14,
      "y": 4,
      "z": 5,
      "name": "Soil_Dirt"
    },
    {
      "x": -14,
      "y": 5,
      "z": 5,
      "name": "Rock_Stone_Brick_Smooth"
    },
    {
      "x": -14,
      "y": 0,
      "z": 6,
      "name": "Soil_Dirt"
    },
    {
      "x": -14,
      "y": 1,
      "z": 6,
      "name": "Soil_Dirt"
    },
    {
      "x": -14,
      "y": 2,
      "z": 6,
      "name": "Soil_Dirt"
    },
    {
      "x": -14,
      "y": 3,
      "z": 6,
      "name": "Soil_Dirt"
    },
    {
      "x": -14,
      "y": 4,
      "z": 6,
      "name": "Soil_Dirt"
    },
    {
      "x": -14,
      "y": 5,
      "z": 6,
      "name": "Rock_Stone_Brick_Smooth"
    },
    {
      "x": -14,
      "y": 0,
      "z": 7,
      "name": "Soil_Dirt"
    },
    {
      "x": -14,
      "y": 1,
      "z": 7,
      "name": "Soil_Dirt"
    },
    {
      "x": -14,
      "y": 2,
      "z": 7,
      "name": "Soil_Dirt"
    },
    {
      "x": -14,
      "y": 3,
      "z": 7,
      "name": "Soil_Dirt"
    },
    {
      "x": -14,
      "y": 4,
      "z": 7,
      "name": "Soil_Dirt"
    },
    {
      "x": -14,
      "y": 5,
      "z": 7,
      "name": "Rock_Stone_Brick_Smooth"
    },
    {
      "x": -14,
      "y": 0,
      "z": 8,
      "name": "Soil_Dirt"
    },
    {
      "x": -14,
      "y": 1,
      "z": 8,
      "name": "Soil_Dirt"
    },
    {
      "x": -14,
      "y": 2,
      "z": 8,
      "name": "Soil_Dirt"
    },
    {
      "x": -14,
      "y": 3,
      "z": 8,
      "name": "Soil_Dirt"
    },
    {
      "x": -14,
      "y": 4,
      "z": 8,
      "name": "Soil_Dirt"
    },
    {
      "x": -14,
      "y": 5,
      "z": 8,
      "name": "Rock_Stone_Brick_Smooth"
    },
    {
      "x": -14,
      "y": 0,
      "z": 9,
      "name": "Soil_Dirt"
    },
    {
      "x": -14,
      "y": 1,
      "z": 9,
      "name": "Soil_Dirt"
    },
    {
      "x": -14,
      "y": 2,
      "z": 9,
      "name": "Soil_Dirt"
    },
    {
      "x": -14,
      "y": 3,
      "z": 9,
      "name": "Soil_Dirt"
    },
    {
      "x": -14,
      "y": 4,
      "z": 9,
      "name": "Soil_Dirt"
    },
    {
      "x": -14,
      "y": 5,
      "z": 9,
      "name": "Rock_Stone_Brick_Smooth"
    },
    {
      "x": -14,
      "y": 0,
      "z": 10,
      "name": "Soil_Dirt"
    },
    {
      "x": -14,
      "y": 1,
      "z": 10,
      "name": "Soil_Dirt"
    },
    {
      "x": -14,
      "y": 2,
      "z": 10,
      "name": "Soil_Dirt"
    },
    {
      "x": -14,
      "y": 3,
      "z": 10,
      "name": "Soil_Dirt"
    },
    {
      "x": -14,
      "y": 4,
      "z": 10,
      "name": "Soil_Dirt"
    },
    {
      "x": -14,
      "y": 5,
      "z": 10,
      "name": "Rock_Stone_Brick_Smooth"
    },
    {
      "x": -14,
      "y": 0,
      "z": 11,
      "name": "Soil_Dirt"
    },
    {
      "x": -14,
      "y": 1,
      "z": 11,
      "name": "Soil_Dirt"
    },
    {
      "x": -14,
      "y": 2,
      "z": 11,
      "name": "Soil_Dirt"
    },
    {
      "x": -14,
      "y": 3,
      "z": 11,
      "name": "Soil_Dirt"
    },
    {
      "x": -14,
      "y": 4,
      "z": 11,
      "name": "Soil_Dirt"
    },
    {
      "x": -14,
      "y": 5,
      "z": 11,
      "name": "Rock_Stone_Brick_Smooth"
    },
    {
      "x": -14,
      "y": 0,
      "z": 12,
      "name": "Soil_Dirt"
    },
    {
      "x": -14,
      "y": 1,
      "z": 12,
      "name": "Soil_Dirt"
    },
    {
      "x": -14,
      "y": 2,
      "z": 12,
      "name": "Soil_Dirt"
    },
    {
      "x": -14,
      "y": 3,
      "z": 12,
      "name": "Soil_Dirt"
    },
    {
      "x": -14,
      "y": 4,
      "z": 12,
      "name": "Soil_Dirt"
    },
    {
      "x": -14,
      "y": 5,
      "z": 12,
      "name": "Rock_Stone_Brick_Smooth"
    },
    {
      "x": -14,
      "y": 0,
      "z": 13,
      "name": "Soil_Dirt"
    },
    {
      "x": -14,
      "y": 1,
      "z": 13,
      "name": "Soil_Dirt"
    },
    {
      "x": -14,
      "y": 2,
      "z": 13,
      "name": "Soil_Dirt"
    },
    {
      "x": -14,
      "y": 3,
      "z": 13,
      "name": "Soil_Dirt"
    },
    {
      "x": -14,
      "y": 4,
      "z": 13,
      "name": "Soil_Dirt"
    },
    {
      "x": -14,
      "y": 5,
      "z": 13,
      "name": "Rock_Stone_Brick_Smooth"
    },
    {
      "x": -14,
      "y": 0,
      "z": 14,
      "name": "Soil_Dirt"
    },
    {
      "x": -14,
      "y": 1,
      "z": 14,
      "name": "Soil_Dirt"
    },
    {
      "x": -14,
      "y": 2,
      "z": 14,
      "name": "Soil_Dirt"
    },
    {
      "x": -14,
      "y": 3,
      "z": 14,
      "name": "Soil_Dirt"
    },
    {
      "x": -14,
      "y": 4,
      "z": 14,
      "name": "Soil_Dirt"
    },
    {
      "x": -14,
      "y": 5,
      "z": 14,
      "name": "Rock_Stone_Brick_Smooth"
    },
    {
      "x": -14,
      "y": 0,
      "z": 15,
      "name": "Soil_Dirt"
    },
    {
      "x": -14,
      "y": 1,
      "z": 15,
      "name": "Soil_Dirt"
    },
    {
      "x": -14,
      "y": 2,
      "z": 15,
      "name": "Soil_Dirt"
    },
    {
      "x": -14,
      "y": 3,
      "z": 15,
      "name": "Soil_Dirt"
    },
    {
      "x": -14,
      "y": 4,
      "z": 15,
      "name": "Soil_Dirt"
    },
    {
      "x": -14,
      "y": 5,
      "z": 15,
      "name": "Rock_Stone_Brick_Smooth"
    },
    {
      "x": -13,
      "y": 0,
      "z": -14,
      "name": "Soil_Dirt"
    },
    {
      "x": -13,
      "y": 1,
      "z": -14,
      "name": "Soil_Dirt"
    },
    {
      "x": -13,
      "y": 2,
      "z": -14,
      "name": "Soil_Dirt"
    },
    {
      "x": -13,
      "y": 3,
      "z": -14,
      "name": "Soil_Dirt"
    },
    {
      "x": -13,
      "y": 4,
      "z": -14,
      "name": "Soil_Dirt"
    },
    {
      "x": -13,
      "y": 5,
      "z": -14,
      "name": "Rock_Stone_Brick_Smooth"
    },
    {
      "x": -13,
      "y": 0,
      "z": -13,
      "name": "Soil_Dirt"
    },
    {
      "x": -13,
      "y": 1,
      "z": -13,
      "name": "Soil_Dirt"
    },
    {
      "x": -13,
      "y": 2,
      "z": -13,
      "name": "Soil_Dirt"
    },
    {
      "x": -13,
      "y": 3,
      "z": -13,
      "name": "Soil_Dirt"
    },
    {
      "x": -13,
      "y": 4,
      "z": -13,
      "name": "Soil_Dirt"
    },
    {
      "x": -13,
      "y": 5,
      "z": -13,
      "name": "Soil_Ash"
    },
    {
      "x": -13,
      "y": 0,
      "z": -12,
      "name": "Soil_Dirt"
    },
    {
      "x": -13,
      "y": 1,
      "z": -12,
      "name": "Soil_Dirt"
    },
    {
      "x": -13,
      "y": 2,
      "z": -12,
      "name": "Soil_Dirt"
    },
    {
      "x": -13,
      "y": 3,
      "z": -12,
      "name": "Soil_Dirt"
    },
    {
      "x": -13,
      "y": 4,
      "z": -12,
      "name": "Soil_Dirt"
    },
    {
      "x": -13,
      "y": 5,
      "z": -12,
      "name": "Soil_Hive"
    },
    {
      "x": -13,
      "y": 0,
      "z": -11,
      "name": "Soil_Dirt"
    },
    {
      "x": -13,
      "y": 1,
      "z": -11,
      "name": "Soil_Dirt"
    },
    {
      "x": -13,
      "y": 2,
      "z": -11,
      "name": "Soil_Dirt"
    },
    {
      "x": -13,
      "y": 3,
      "z": -11,
      "name": "Soil_Dirt"
    },
    {
      "x": -13,
      "y": 4,
      "z": -11,
      "name": "Soil_Dirt"
    },
    {
      "x": -13,
      "y": 5,
      "z": -11,
      "name": "Soil_Hive"
    },
    {
      "x": -13,
      "y": 6,
      "z": -11,
      "name": "Plant_Bush_Dead",
      "support": 15
    },
    {
      "x": -13,
      "y": 7,
      "z": -11,
      "name": "Plant_Bush_Dead",
      "support": 15,
      "filler": 1024
    },
    {
      "x": -13,
      "y": 0,
      "z": -10,
      "name": "Soil_Dirt"
    },
    {
      "x": -13,
      "y": 1,
      "z": -10,
      "name": "Soil_Dirt"
    },
    {
      "x": -13,
      "y": 2,
      "z": -10,
      "name": "Soil_Dirt"
    },
    {
      "x": -13,
      "y": 3,
      "z": -10,
      "name": "Soil_Dirt"
    },
    {
      "x": -13,
      "y": 4,
      "z": -10,
      "name": "Soil_Dirt"
    },
    {
      "x": -13,
      "y": 5,
      "z": -10,
      "name": "Soil_Hive"
    },
    {
      "x": -13,
      "y": 0,
      "z": -9,
      "name": "Soil_Dirt"
    },
    {
      "x": -13,
      "y": 1,
      "z": -9,
      "name": "Soil_Dirt"
    },
    {
      "x": -13,
      "y": 2,
      "z": -9,
      "name": "Soil_Dirt"
    },
    {
      "x": -13,
      "y": 3,
      "z": -9,
      "name": "Soil_Dirt"
    },
    {
      "x": -13,
      "y": 4,
      "z": -9,
      "name": "Soil_Dirt"
    },
    {
      "x": -13,
      "y": 5,
      "z": -9,
      "name": "Soil_Roots_Poisoned"
    },
    {
      "x": -13,
      "y": 0,
      "z": -8,
      "name": "Soil_Dirt"
    },
    {
      "x": -13,
      "y": 1,
      "z": -8,
      "name": "Soil_Dirt"
    },
    {
      "x": -13,
      "y": 2,
      "z": -8,
      "name": "Soil_Dirt"
    },
    {
      "x": -13,
      "y": 3,
      "z": -8,
      "name": "Soil_Dirt"
    },
    {
      "x": -13,
      "y": 4,
      "z": -8,
      "name": "Soil_Dirt"
    },
    {
      "x": -13,
      "y": 5,
      "z": -8,
      "name": "Soil_Ash"
    },
    {
      "x": -13,
      "y": 0,
      "z": -7,
      "name": "Soil_Dirt"
    },
    {
      "x": -13,
      "y": 1,
      "z": -7,
      "name": "Soil_Dirt"
    },
    {
      "x": -13,
      "y": 2,
      "z": -7,
      "name": "Soil_Dirt"
    },
    {
      "x": -13,
      "y": 3,
      "z": -7,
      "name": "Soil_Dirt"
    },
    {
      "x": -13,
      "y": 4,
      "z": -7,
      "name": "Soil_Dirt"
    },
    {
      "x": -13,
      "y": 5,
      "z": -7,
      "name": "Soil_Hive"
    },
    {
      "x": -13,
      "y": 0,
      "z": -6,
      "name": "Soil_Dirt"
    },
    {
      "x": -13,
      "y": 1,
      "z": -6,
      "name": "Soil_Dirt"
    },
    {
      "x": -13,
      "y": 2,
      "z": -6,
      "name": "Soil_Dirt"
    },
    {
      "x": -13,
      "y": 3,
      "z": -6,
      "name": "Soil_Dirt"
    },
    {
      "x": -13,
      "y": 4,
      "z": -6,
      "name": "Soil_Dirt"
    },
    {
      "x": -13,
      "y": 5,
      "z": -6,
      "name": "Soil_Hive_Corrupted"
    },
    {
      "x": -13,
      "y": 6,
      "z": -6,
      "name": "Plant_Bush_Dead",
      "support": 15
    },
    {
      "x": -13,
      "y": 7,
      "z": -6,
      "name": "Plant_Bush_Dead",
      "support": 15,
      "filler": 1024
    },
    {
      "x": -13,
      "y": 0,
      "z": -5,
      "name": "Soil_Dirt"
    },
    {
      "x": -13,
      "y": 1,
      "z": -5,
      "name": "Soil_Dirt"
    },
    {
      "x": -13,
      "y": 2,
      "z": -5,
      "name": "Soil_Dirt"
    },
    {
      "x": -13,
      "y": 3,
      "z": -5,
      "name": "Soil_Dirt"
    },
    {
      "x": -13,
      "y": 4,
      "z": -5,
      "name": "Soil_Dirt"
    },
    {
      "x": -13,
      "y": 5,
      "z": -5,
      "name": "Soil_Hive_Corrupted"
    },
    {
      "x": -13,
      "y": 0,
      "z": -4,
      "name": "Soil_Dirt"
    },
    {
      "x": -13,
      "y": 1,
      "z": -4,
      "name": "Soil_Dirt"
    },
    {
      "x": -13,
      "y": 2,
      "z": -4,
      "name": "Soil_Dirt"
    },
    {
      "x": -13,
      "y": 3,
      "z": -4,
      "name": "Soil_Dirt"
    },
    {
      "x": -13,
      "y": 4,
      "z": -4,
      "name": "Soil_Dirt"
    },
    {
      "x": -13,
      "y": 5,
      "z": -4,
      "name": "Soil_Ash"
    },
    {
      "x": -13,
      "y": 0,
      "z": -3,
      "name": "Soil_Dirt"
    },
    {
      "x": -13,
      "y": 1,
      "z": -3,
      "name": "Soil_Dirt"
    },
    {
      "x": -13,
      "y": 2,
      "z": -3,
      "name": "Soil_Dirt"
    },
    {
      "x": -13,
      "y": 3,
      "z": -3,
      "name": "Soil_Dirt"
    },
    {
      "x": -13,
      "y": 4,
      "z": -3,
      "name": "Soil_Dirt"
    },
    {
      "x": -13,
      "y": 5,
      "z": -3,
      "name": "Soil_Roots_Poisoned"
    },
    {
      "x": -13,
      "y": 0,
      "z": -2,
      "name": "Soil_Dirt"
    },
    {
      "x": -13,
      "y": 1,
      "z": -2,
      "name": "Soil_Dirt"
    },
    {
      "x": -13,
      "y": 2,
      "z": -2,
      "name": "Soil_Dirt"
    },
    {
      "x": -13,
      "y": 3,
      "z": -2,
      "name": "Soil_Dirt"
    },
    {
      "x": -13,
      "y": 4,
      "z": -2,
      "name": "Soil_Dirt"
    },
    {
      "x": -13,
      "y": 5,
      "z": -2,
      "name": "Soil_Ash"
    },
    {
      "x": -13,
      "y": 0,
      "z": -1,
      "name": "Soil_Dirt"
    },
    {
      "x": -13,
      "y": 1,
      "z": -1,
      "name": "Soil_Dirt"
    },
    {
      "x": -13,
      "y": 2,
      "z": -1,
      "name": "Soil_Dirt"
    },
    {
      "x": -13,
      "y": 3,
      "z": -1,
      "name": "Soil_Dirt"
    },
    {
      "x": -13,
      "y": 4,
      "z": -1,
      "name": "Soil_Dirt"
    },
    {
      "x": -13,
      "y": 5,
      "z": -1,
      "name": "Soil_Hive"
    },
    {
      "x": -13,
      "y": 0,
      "z": 0,
      "name": "Soil_Dirt"
    },
    {
      "x": -13,
      "y": 1,
      "z": 0,
      "name": "Soil_Dirt"
    },
    {
      "x": -13,
      "y": 2,
      "z": 0,
      "name": "Soil_Dirt"
    },
    {
      "x": -13,
      "y": 3,
      "z": 0,
      "name": "Soil_Dirt"
    },
    {
      "x": -13,
      "y": 4,
      "z": 0,
      "name": "Soil_Dirt"
    },
    {
      "x": -13,
      "y": 5,
      "z": 0,
      "name": "Soil_Hive"
    },
    {
      "x": -13,
      "y": 0,
      "z": 1,
      "name": "Soil_Dirt"
    },
    {
      "x": -13,
      "y": 1,
      "z": 1,
      "name": "Soil_Dirt"
    },
    {
      "x": -13,
      "y": 2,
      "z": 1,
      "name": "Soil_Dirt"
    },
    {
      "x": -13,
      "y": 3,
      "z": 1,
      "name": "Soil_Dirt"
    },
    {
      "x": -13,
      "y": 4,
      "z": 1,
      "name": "Soil_Dirt"
    },
    {
      "x": -13,
      "y": 5,
      "z": 1,
      "name": "Soil_Hive"
    },
    {
      "x": -13,
      "y": 0,
      "z": 2,
      "name": "Soil_Dirt"
    },
    {
      "x": -13,
      "y": 1,
      "z": 2,
      "name": "Soil_Dirt"
    },
    {
      "x": -13,
      "y": 2,
      "z": 2,
      "name": "Soil_Dirt"
    },
    {
      "x": -13,
      "y": 3,
      "z": 2,
      "name": "Soil_Dirt"
    },
    {
      "x": -13,
      "y": 4,
      "z": 2,
      "name": "Soil_Dirt"
    },
    {
      "x": -13,
      "y": 5,
      "z": 2,
      "name": "Soil_Ash"
    },
    {
      "x": -13,
      "y": 0,
      "z": 3,
      "name": "Soil_Dirt"
    },
    {
      "x": -13,
      "y": 1,
      "z": 3,
      "name": "Soil_Dirt"
    },
    {
      "x": -13,
      "y": 2,
      "z": 3,
      "name": "Soil_Dirt"
    },
    {
      "x": -13,
      "y": 3,
      "z": 3,
      "name": "Soil_Dirt"
    },
    {
      "x": -13,
      "y": 4,
      "z": 3,
      "name": "Soil_Dirt"
    },
    {
      "x": -13,
      "y": 5,
      "z": 3,
      "name": "Soil_Ash"
    },
    {
      "x": -13,
      "y": 6,
      "z": 3,
      "name": "Plant_Leaves_Dead",
      "support": 15
    },
    {
      "x": -13,
      "y": 0,
      "z": 4,
      "name": "Soil_Dirt"
    },
    {
      "x": -13,
      "y": 1,
      "z": 4,
      "name": "Soil_Dirt"
    },
    {
      "x": -13,
      "y": 2,
      "z": 4,
      "name": "Soil_Dirt"
    },
    {
      "x": -13,
      "y": 3,
      "z": 4,
      "name": "Soil_Dirt"
    },
    {
      "x": -13,
      "y": 4,
      "z": 4,
      "name": "Soil_Dirt"
    },
    {
      "x": -13,
      "y": 5,
      "z": 4,
      "name": "Soil_Roots_Poisoned"
    },
    {
      "x": -13,
      "y": 0,
      "z": 5,
      "name": "Soil_Dirt"
    },
    {
      "x": -13,
      "y": 1,
      "z": 5,
      "name": "Soil_Dirt"
    },
    {
      "x": -13,
      "y": 2,
      "z": 5,
      "name": "Soil_Dirt"
    },
    {
      "x": -13,
      "y": 3,
      "z": 5,
      "name": "Soil_Dirt"
    },
    {
      "x": -13,
      "y": 4,
      "z": 5,
      "name": "Soil_Dirt"
    },
    {
      "x": -13,
      "y": 5,
      "z": 5,
      "name": "Soil_Hive"
    },
    {
      "x": -13,
      "y": 0,
      "z": 6,
      "name": "Soil_Dirt"
    },
    {
      "x": -13,
      "y": 1,
      "z": 6,
      "name": "Soil_Dirt"
    },
    {
      "x": -13,
      "y": 2,
      "z": 6,
      "name": "Soil_Dirt"
    },
    {
      "x": -13,
      "y": 3,
      "z": 6,
      "name": "Soil_Dirt"
    },
    {
      "x": -13,
      "y": 4,
      "z": 6,
      "name": "Soil_Dirt"
    },
    {
      "x": -13,
      "y": 5,
      "z": 6,
      "name": "Soil_Roots_Poisoned"
    },
    {
      "x": -13,
      "y": 6,
      "z": 6,
      "name": "Plant_Bush_Dead",
      "support": 15
    },
    {
      "x": -13,
      "y": 7,
      "z": 6,
      "name": "Plant_Bush_Dead",
      "support": 15,
      "filler": 1024
    },
    {
      "x": -13,
      "y": 0,
      "z": 7,
      "name": "Soil_Dirt"
    },
    {
      "x": -13,
      "y": 1,
      "z": 7,
      "name": "Soil_Dirt"
    },
    {
      "x": -13,
      "y": 2,
      "z": 7,
      "name": "Soil_Dirt"
    },
    {
      "x": -13,
      "y": 3,
      "z": 7,
      "name": "Soil_Dirt"
    },
    {
      "x": -13,
      "y": 4,
      "z": 7,
      "name": "Soil_Dirt"
    },
    {
      "x": -13,
      "y": 5,
      "z": 7,
      "name": "Soil_Hive"
    },
    {
      "x": -13,
      "y": 0,
      "z": 8,
      "name": "Soil_Dirt"
    },
    {
      "x": -13,
      "y": 1,
      "z": 8,
      "name": "Soil_Dirt"
    },
    {
      "x": -13,
      "y": 2,
      "z": 8,
      "name": "Soil_Dirt"
    },
    {
      "x": -13,
      "y": 3,
      "z": 8,
      "name": "Soil_Dirt"
    },
    {
      "x": -13,
      "y": 4,
      "z": 8,
      "name": "Soil_Dirt"
    },
    {
      "x": -13,
      "y": 5,
      "z": 8,
      "name": "Soil_Roots_Poisoned"
    },
    {
      "x": -13,
      "y": 0,
      "z": 9,
      "name": "Soil_Dirt"
    },
    {
      "x": -13,
      "y": 1,
      "z": 9,
      "name": "Soil_Dirt"
    },
    {
      "x": -13,
      "y": 2,
      "z": 9,
      "name": "Soil_Dirt"
    },
    {
      "x": -13,
      "y": 3,
      "z": 9,
      "name": "Soil_Dirt"
    },
    {
      "x": -13,
      "y": 4,
      "z": 9,
      "name": "Soil_Dirt"
    },
    {
      "x": -13,
      "y": 5,
      "z": 9,
      "name": "Soil_Ash"
    },
    {
      "x": -13,
      "y": 0,
      "z": 10,
      "name": "Soil_Dirt"
    },
    {
      "x": -13,
      "y": 1,
      "z": 10,
      "name": "Soil_Dirt"
    },
    {
      "x": -13,
      "y": 2,
      "z": 10,
      "name": "Soil_Dirt"
    },
    {
      "x": -13,
      "y": 3,
      "z": 10,
      "name": "Soil_Dirt"
    },
    {
      "x": -13,
      "y": 4,
      "z": 10,
      "name": "Soil_Dirt"
    },
    {
      "x": -13,
      "y": 5,
      "z": 10,
      "name": "Soil_Ash"
    },
    {
      "x": -13,
      "y": 0,
      "z": 11,
      "name": "Soil_Dirt"
    },
    {
      "x": -13,
      "y": 1,
      "z": 11,
      "name": "Soil_Dirt"
    },
    {
      "x": -13,
      "y": 2,
      "z": 11,
      "name": "Soil_Dirt"
    },
    {
      "x": -13,
      "y": 3,
      "z": 11,
      "name": "Soil_Dirt"
    },
    {
      "x": -13,
      "y": 4,
      "z": 11,
      "name": "Soil_Dirt"
    },
    {
      "x": -13,
      "y": 5,
      "z": 11,
      "name": "Soil_Hive"
    },
    {
      "x": -13,
      "y": 0,
      "z": 12,
      "name": "Soil_Dirt"
    },
    {
      "x": -13,
      "y": 1,
      "z": 12,
      "name": "Soil_Dirt"
    },
    {
      "x": -13,
      "y": 2,
      "z": 12,
      "name": "Soil_Dirt"
    },
    {
      "x": -13,
      "y": 3,
      "z": 12,
      "name": "Soil_Dirt"
    },
    {
      "x": -13,
      "y": 4,
      "z": 12,
      "name": "Soil_Dirt"
    },
    {
      "x": -13,
      "y": 5,
      "z": 12,
      "name": "Soil_Ash"
    },
    {
      "x": -13,
      "y": 0,
      "z": 13,
      "name": "Soil_Dirt"
    },
    {
      "x": -13,
      "y": 1,
      "z": 13,
      "name": "Soil_Dirt"
    },
    {
      "x": -13,
      "y": 2,
      "z": 13,
      "name": "Soil_Dirt"
    },
    {
      "x": -13,
      "y": 3,
      "z": 13,
      "name": "Soil_Dirt"
    },
    {
      "x": -13,
      "y": 4,
      "z": 13,
      "name": "Soil_Dirt"
    },
    {
      "x": -13,
      "y": 5,
      "z": 13,
      "name": "Soil_Hive"
    },
    {
      "x": -13,
      "y": 0,
      "z": 14,
      "name": "Soil_Dirt"
    },
    {
      "x": -13,
      "y": 1,
      "z": 14,
      "name": "Soil_Dirt"
    },
    {
      "x": -13,
      "y": 2,
      "z": 14,
      "name": "Soil_Dirt"
    },
    {
      "x": -13,
      "y": 3,
      "z": 14,
      "name": "Soil_Dirt"
    },
    {
      "x": -13,
      "y": 4,
      "z": 14,
      "name": "Soil_Dirt"
    },
    {
      "x": -13,
      "y": 5,
      "z": 14,
      "name": "Soil_Hive"
    },
    {
      "x": -13,
      "y": 0,
      "z": 15,
      "name": "Soil_Dirt"
    },
    {
      "x": -13,
      "y": 1,
      "z": 15,
      "name": "Soil_Dirt"
    },
    {
      "x": -13,
      "y": 2,
      "z": 15,
      "name": "Soil_Dirt"
    },
    {
      "x": -13,
      "y": 3,
      "z": 15,
      "name": "Soil_Dirt"
    },
    {
      "x": -13,
      "y": 4,
      "z": 15,
      "name": "Soil_Dirt"
    },
    {
      "x": -13,
      "y": 5,
      "z": 15,
      "name": "Rock_Stone_Brick_Smooth"
    },
    {
      "x": -12,
      "y": 0,
      "z": -14,
      "name": "Soil_Dirt"
    },
    {
      "x": -12,
      "y": 1,
      "z": -14,
      "name": "Soil_Dirt"
    },
    {
      "x": -12,
      "y": 2,
      "z": -14,
      "name": "Soil_Dirt"
    },
    {
      "x": -12,
      "y": 3,
      "z": -14,
      "name": "Soil_Dirt"
    },
    {
      "x": -12,
      "y": 4,
      "z": -14,
      "name": "Soil_Dirt"
    },
    {
      "x": -12,
      "y": 5,
      "z": -14,
      "name": "Rock_Stone_Brick_Smooth"
    },
    {
      "x": -12,
      "y": 0,
      "z": -13,
      "name": "Soil_Dirt"
    },
    {
      "x": -12,
      "y": 1,
      "z": -13,
      "name": "Soil_Dirt"
    },
    {
      "x": -12,
      "y": 2,
      "z": -13,
      "name": "Soil_Dirt"
    },
    {
      "x": -12,
      "y": 3,
      "z": -13,
      "name": "Soil_Dirt"
    },
    {
      "x": -12,
      "y": 4,
      "z": -13,
      "name": "Soil_Dirt"
    },
    {
      "x": -12,
      "y": 5,
      "z": -13,
      "name": "Soil_Hive_Corrupted"
    },
    {
      "x": -12,
      "y": 0,
      "z": -12,
      "name": "Soil_Dirt"
    },
    {
      "x": -12,
      "y": 1,
      "z": -12,
      "name": "Soil_Dirt"
    },
    {
      "x": -12,
      "y": 2,
      "z": -12,
      "name": "Soil_Dirt"
    },
    {
      "x": -12,
      "y": 3,
      "z": -12,
      "name": "Soil_Dirt"
    },
    {
      "x": -12,
      "y": 4,
      "z": -12,
      "name": "Soil_Dirt"
    },
    {
      "x": -12,
      "y": 5,
      "z": -12,
      "name": "Soil_Roots_Poisoned"
    },
    {
      "x": -12,
      "y": 0,
      "z": -11,
      "name": "Soil_Dirt"
    },
    {
      "x": -12,
      "y": 1,
      "z": -11,
      "name": "Soil_Dirt"
    },
    {
      "x": -12,
      "y": 2,
      "z": -11,
      "name": "Soil_Dirt"
    },
    {
      "x": -12,
      "y": 3,
      "z": -11,
      "name": "Soil_Dirt"
    },
    {
      "x": -12,
      "y": 4,
      "z": -11,
      "name": "Soil_Dirt"
    },
    {
      "x": -12,
      "y": 5,
      "z": -11,
      "name": "Soil_Ash"
    },
    {
      "x": -12,
      "y": 0,
      "z": -10,
      "name": "Soil_Dirt"
    },
    {
      "x": -12,
      "y": 1,
      "z": -10,
      "name": "Soil_Dirt"
    },
    {
      "x": -12,
      "y": 2,
      "z": -10,
      "name": "Soil_Dirt"
    },
    {
      "x": -12,
      "y": 3,
      "z": -10,
      "name": "Soil_Dirt"
    },
    {
      "x": -12,
      "y": 4,
      "z": -10,
      "name": "Soil_Dirt"
    },
    {
      "x": -12,
      "y": 5,
      "z": -10,
      "name": "Soil_Hive"
    },
    {
      "x": -12,
      "y": 0,
      "z": -9,
      "name": "Soil_Dirt"
    },
    {
      "x": -12,
      "y": 1,
      "z": -9,
      "name": "Soil_Dirt"
    },
    {
      "x": -12,
      "y": 2,
      "z": -9,
      "name": "Soil_Dirt"
    },
    {
      "x": -12,
      "y": 3,
      "z": -9,
      "name": "Soil_Dirt"
    },
    {
      "x": -12,
      "y": 4,
      "z": -9,
      "name": "Soil_Dirt"
    },
    {
      "x": -12,
      "y": 5,
      "z": -9,
      "name": "Soil_Ash"
    },
    {
      "x": -12,
      "y": 0,
      "z": -8,
      "name": "Soil_Dirt"
    },
    {
      "x": -12,
      "y": 1,
      "z": -8,
      "name": "Soil_Dirt"
    },
    {
      "x": -12,
      "y": 2,
      "z": -8,
      "name": "Soil_Dirt"
    },
    {
      "x": -12,
      "y": 3,
      "z": -8,
      "name": "Soil_Dirt"
    },
    {
      "x": -12,
      "y": 4,
      "z": -8,
      "name": "Soil_Dirt"
    },
    {
      "x": -12,
      "y": 5,
      "z": -8,
      "name": "Soil_Hive"
    },
    {
      "x": -12,
      "y": 0,
      "z": -7,
      "name": "Soil_Dirt"
    },
    {
      "x": -12,
      "y": 1,
      "z": -7,
      "name": "Soil_Dirt"
    },
    {
      "x": -12,
      "y": 2,
      "z": -7,
      "name": "Soil_Dirt"
    },
    {
      "x": -12,
      "y": 3,
      "z": -7,
      "name": "Soil_Dirt"
    },
    {
      "x": -12,
      "y": 4,
      "z": -7,
      "name": "Soil_Dirt"
    },
    {
      "x": -12,
      "y": 5,
      "z": -7,
      "name": "Soil_Ash"
    },
    {
      "x": -12,
      "y": 0,
      "z": -6,
      "name": "Soil_Dirt"
    },
    {
      "x": -12,
      "y": 1,
      "z": -6,
      "name": "Soil_Dirt"
    },
    {
      "x": -12,
      "y": 2,
      "z": -6,
      "name": "Soil_Dirt"
    },
    {
      "x": -12,
      "y": 3,
      "z": -6,
      "name": "Soil_Dirt"
    },
    {
      "x": -12,
      "y": 4,
      "z": -6,
      "name": "Soil_Dirt"
    },
    {
      "x": -12,
      "y": 5,
      "z": -6,
      "name": "Soil_Ash"
    },
    {
      "x": -12,
      "y": 0,
      "z": -5,
      "name": "Soil_Dirt"
    },
    {
      "x": -12,
      "y": 1,
      "z": -5,
      "name": "Soil_Dirt"
    },
    {
      "x": -12,
      "y": 2,
      "z": -5,
      "name": "Soil_Dirt"
    },
    {
      "x": -12,
      "y": 3,
      "z": -5,
      "name": "Soil_Dirt"
    },
    {
      "x": -12,
      "y": 4,
      "z": -5,
      "name": "Soil_Dirt"
    },
    {
      "x": -12,
      "y": 5,
      "z": -5,
      "name": "Soil_Hive_Corrupted"
    },
    {
      "x": -12,
      "y": 0,
      "z": -4,
      "name": "Soil_Dirt"
    },
    {
      "x": -12,
      "y": 1,
      "z": -4,
      "name": "Soil_Dirt"
    },
    {
      "x": -12,
      "y": 2,
      "z": -4,
      "name": "Soil_Dirt"
    },
    {
      "x": -12,
      "y": 3,
      "z": -4,
      "name": "Soil_Dirt"
    },
    {
      "x": -12,
      "y": 4,
      "z": -4,
      "name": "Soil_Dirt"
    },
    {
      "x": -12,
      "y": 5,
      "z": -4,
      "name": "Soil_Hive"
    },
    {
      "x": -12,
      "y": 0,
      "z": -3,
      "name": "Soil_Dirt"
    },
    {
      "x": -12,
      "y": 1,
      "z": -3,
      "name": "Soil_Dirt"
    },
    {
      "x": -12,
      "y": 2,
      "z": -3,
      "name": "Soil_Dirt"
    },
    {
      "x": -12,
      "y": 3,
      "z": -3,
      "name": "Soil_Dirt"
    },
    {
      "x": -12,
      "y": 4,
      "z": -3,
      "name": "Soil_Dirt"
    },
    {
      "x": -12,
      "y": 5,
      "z": -3,
      "name": "Soil_Hive"
    },
    {
      "x": -12,
      "y": 6,
      "z": -3,
      "name": "Plant_Leaves_Dead",
      "support": 15
    },
    {
      "x": -12,
      "y": 0,
      "z": -2,
      "name": "Soil_Dirt"
    },
    {
      "x": -12,
      "y": 1,
      "z": -2,
      "name": "Soil_Dirt"
    },
    {
      "x": -12,
      "y": 2,
      "z": -2,
      "name": "Soil_Dirt"
    },
    {
      "x": -12,
      "y": 3,
      "z": -2,
      "name": "Soil_Dirt"
    },
    {
      "x": -12,
      "y": 4,
      "z": -2,
      "name": "Soil_Dirt"
    },
    {
      "x": -12,
      "y": 5,
      "z": -2,
      "name": "Soil_Roots_Poisoned"
    },
    {
      "x": -12,
      "y": 0,
      "z": -1,
      "name": "Soil_Dirt"
    },
    {
      "x": -12,
      "y": 1,
      "z": -1,
      "name": "Soil_Dirt"
    },
    {
      "x": -12,
      "y": 2,
      "z": -1,
      "name": "Soil_Dirt"
    },
    {
      "x": -12,
      "y": 3,
      "z": -1,
      "name": "Soil_Dirt"
    },
    {
      "x": -12,
      "y": 4,
      "z": -1,
      "name": "Soil_Dirt"
    },
    {
      "x": -12,
      "y": 5,
      "z": -1,
      "name": "Soil_Hive"
    },
    {
      "x": -12,
      "y": 0,
      "z": 0,
      "name": "Soil_Dirt"
    },
    {
      "x": -12,
      "y": 1,
      "z": 0,
      "name": "Soil_Dirt"
    },
    {
      "x": -12,
      "y": 2,
      "z": 0,
      "name": "Soil_Dirt"
    },
    {
      "x": -12,
      "y": 3,
      "z": 0,
      "name": "Soil_Dirt"
    },
    {
      "x": -12,
      "y": 4,
      "z": 0,
      "name": "Soil_Dirt"
    },
    {
      "x": -12,
      "y": 5,
      "z": 0,
      "name": "Soil_Ash"
    },
    {
      "x": -12,
      "y": 6,
      "z": 0,
      "name": "Plant_Bush_Dead",
      "support": 15
    },
    {
      "x": -12,
      "y": 7,
      "z": 0,
      "name": "Plant_Bush_Dead",
      "support": 15,
      "filler": 1024
    },
    {
      "x": -12,
      "y": 0,
      "z": 1,
      "name": "Soil_Dirt"
    },
    {
      "x": -12,
      "y": 1,
      "z": 1,
      "name": "Soil_Dirt"
    },
    {
      "x": -12,
      "y": 2,
      "z": 1,
      "name": "Soil_Dirt"
    },
    {
      "x": -12,
      "y": 3,
      "z": 1,
      "name": "Soil_Dirt"
    },
    {
      "x": -12,
      "y": 4,
      "z": 1,
      "name": "Soil_Dirt"
    },
    {
      "x": -12,
      "y": 5,
      "z": 1,
      "name": "Soil_Ash"
    },
    {
      "x": -12,
      "y": 0,
      "z": 2,
      "name": "Soil_Dirt"
    },
    {
      "x": -12,
      "y": 1,
      "z": 2,
      "name": "Soil_Dirt"
    },
    {
      "x": -12,
      "y": 2,
      "z": 2,
      "name": "Soil_Dirt"
    },
    {
      "x": -12,
      "y": 3,
      "z": 2,
      "name": "Soil_Dirt"
    },
    {
      "x": -12,
      "y": 4,
      "z": 2,
      "name": "Soil_Dirt"
    },
    {
      "x": -12,
      "y": 5,
      "z": 2,
      "name": "Soil_Hive"
    },
    {
      "x": -12,
      "y": 0,
      "z": 3,
      "name": "Soil_Dirt"
    },
    {
      "x": -12,
      "y": 1,
      "z": 3,
      "name": "Soil_Dirt"
    },
    {
      "x": -12,
      "y": 2,
      "z": 3,
      "name": "Soil_Dirt"
    },
    {
      "x": -12,
      "y": 3,
      "z": 3,
      "name": "Soil_Dirt"
    },
    {
      "x": -12,
      "y": 4,
      "z": 3,
      "name": "Soil_Dirt"
    },
    {
      "x": -12,
      "y": 5,
      "z": 3,
      "name": "Soil_Roots_Poisoned"
    },
    {
      "x": -12,
      "y": 0,
      "z": 4,
      "name": "Soil_Dirt"
    },
    {
      "x": -12,
      "y": 1,
      "z": 4,
      "name": "Soil_Dirt"
    },
    {
      "x": -12,
      "y": 2,
      "z": 4,
      "name": "Soil_Dirt"
    },
    {
      "x": -12,
      "y": 3,
      "z": 4,
      "name": "Soil_Dirt"
    },
    {
      "x": -12,
      "y": 4,
      "z": 4,
      "name": "Soil_Dirt"
    },
    {
      "x": -12,
      "y": 5,
      "z": 4,
      "name": "Soil_Hive"
    },
    {
      "x": -12,
      "y": 0,
      "z": 5,
      "name": "Soil_Dirt"
    },
    {
      "x": -12,
      "y": 1,
      "z": 5,
      "name": "Soil_Dirt"
    },
    {
      "x": -12,
      "y": 2,
      "z": 5,
      "name": "Soil_Dirt"
    },
    {
      "x": -12,
      "y": 3,
      "z": 5,
      "name": "Soil_Dirt"
    },
    {
      "x": -12,
      "y": 4,
      "z": 5,
      "name": "Soil_Dirt"
    },
    {
      "x": -12,
      "y": 5,
      "z": 5,
      "name": "Soil_Ash"
    },
    {
      "x": -12,
      "y": 0,
      "z": 6,
      "name": "Soil_Dirt"
    },
    {
      "x": -12,
      "y": 1,
      "z": 6,
      "name": "Soil_Dirt"
    },
    {
      "x": -12,
      "y": 2,
      "z": 6,
      "name": "Soil_Dirt"
    },
    {
      "x": -12,
      "y": 3,
      "z": 6,
      "name": "Soil_Dirt"
    },
    {
      "x": -12,
      "y": 4,
      "z": 6,
      "name": "Soil_Dirt"
    },
    {
      "x": -12,
      "y": 5,
      "z": 6,
      "name": "Soil_Hive_Corrupted"
    },
    {
      "x": -12,
      "y": 0,
      "z": 7,
      "name": "Soil_Dirt"
    },
    {
      "x": -12,
      "y": 1,
      "z": 7,
      "name": "Soil_Dirt"
    },
    {
      "x": -12,
      "y": 2,
      "z": 7,
      "name": "Soil_Dirt"
    },
    {
      "x": -12,
      "y": 3,
      "z": 7,
      "name": "Soil_Dirt"
    },
    {
      "x": -12,
      "y": 4,
      "z": 7,
      "name": "Soil_Dirt"
    },
    {
      "x": -12,
      "y": 5,
      "z": 7,
      "name": "Soil_Ash"
    },
    {
      "x": -12,
      "y": 0,
      "z": 8,
      "name": "Soil_Dirt"
    },
    {
      "x": -12,
      "y": 1,
      "z": 8,
      "name": "Soil_Dirt"
    },
    {
      "x": -12,
      "y": 2,
      "z": 8,
      "name": "Soil_Dirt"
    },
    {
      "x": -12,
      "y": 3,
      "z": 8,
      "name": "Soil_Dirt"
    },
    {
      "x": -12,
      "y": 4,
      "z": 8,
      "name": "Soil_Dirt"
    },
    {
      "x": -12,
      "y": 5,
      "z": 8,
      "name": "Soil_Ash"
    },
    {
      "x": -12,
      "y": 0,
      "z": 9,
      "name": "Soil_Dirt"
    },
    {
      "x": -12,
      "y": 1,
      "z": 9,
      "name": "Soil_Dirt"
    },
    {
      "x": -12,
      "y": 2,
      "z": 9,
      "name": "Soil_Dirt"
    },
    {
      "x": -12,
      "y": 3,
      "z": 9,
      "name": "Soil_Dirt"
    },
    {
      "x": -12,
      "y": 4,
      "z": 9,
      "name": "Soil_Dirt"
    },
    {
      "x": -12,
      "y": 5,
      "z": 9,
      "name": "Soil_Hive"
    },
    {
      "x": -12,
      "y": 0,
      "z": 10,
      "name": "Soil_Dirt"
    },
    {
      "x": -12,
      "y": 1,
      "z": 10,
      "name": "Soil_Dirt"
    },
    {
      "x": -12,
      "y": 2,
      "z": 10,
      "name": "Soil_Dirt"
    },
    {
      "x": -12,
      "y": 3,
      "z": 10,
      "name": "Soil_Dirt"
    },
    {
      "x": -12,
      "y": 4,
      "z": 10,
      "name": "Soil_Dirt"
    },
    {
      "x": -12,
      "y": 5,
      "z": 10,
      "name": "Soil_Ash"
    },
    {
      "x": -12,
      "y": 6,
      "z": 10,
      "name": "Plant_Leaves_Dead",
      "support": 15
    },
    {
      "x": -12,
      "y": 0,
      "z": 11,
      "name": "Soil_Dirt"
    },
    {
      "x": -12,
      "y": 1,
      "z": 11,
      "name": "Soil_Dirt"
    },
    {
      "x": -12,
      "y": 2,
      "z": 11,
      "name": "Soil_Dirt"
    },
    {
      "x": -12,
      "y": 3,
      "z": 11,
      "name": "Soil_Dirt"
    },
    {
      "x": -12,
      "y": 4,
      "z": 11,
      "name": "Soil_Dirt"
    },
    {
      "x": -12,
      "y": 5,
      "z": 11,
      "name": "Soil_Hive"
    },
    {
      "x": -12,
      "y": 0,
      "z": 12,
      "name": "Soil_Dirt"
    },
    {
      "x": -12,
      "y": 1,
      "z": 12,
      "name": "Soil_Dirt"
    },
    {
      "x": -12,
      "y": 2,
      "z": 12,
      "name": "Soil_Dirt"
    },
    {
      "x": -12,
      "y": 3,
      "z": 12,
      "name": "Soil_Dirt"
    },
    {
      "x": -12,
      "y": 4,
      "z": 12,
      "name": "Soil_Dirt"
    },
    {
      "x": -12,
      "y": 5,
      "z": 12,
      "name": "Soil_Roots_Poisoned"
    },
    {
      "x": -12,
      "y": 6,
      "z": 12,
      "name": "Plant_Bush_Dead",
      "support": 15
    },
    {
      "x": -12,
      "y": 7,
      "z": 12,
      "name": "Plant_Bush_Dead",
      "support": 15,
      "filler": 1024
    },
    {
      "x": -12,
      "y": 0,
      "z": 13,
      "name": "Soil_Dirt"
    },
    {
      "x": -12,
      "y": 1,
      "z": 13,
      "name": "Soil_Dirt"
    },
    {
      "x": -12,
      "y": 2,
      "z": 13,
      "name": "Soil_Dirt"
    },
    {
      "x": -12,
      "y": 3,
      "z": 13,
      "name": "Soil_Dirt"
    },
    {
      "x": -12,
      "y": 4,
      "z": 13,
      "name": "Soil_Dirt"
    },
    {
      "x": -12,
      "y": 5,
      "z": 13,
      "name": "Soil_Hive"
    },
    {
      "x": -12,
      "y": 0,
      "z": 14,
      "name": "Soil_Dirt"
    },
    {
      "x": -12,
      "y": 1,
      "z": 14,
      "name": "Soil_Dirt"
    },
    {
      "x": -12,
      "y": 2,
      "z": 14,
      "name": "Soil_Dirt"
    },
    {
      "x": -12,
      "y": 3,
      "z": 14,
      "name": "Soil_Dirt"
    },
    {
      "x": -12,
      "y": 4,
      "z": 14,
      "name": "Soil_Dirt"
    },
    {
      "x": -12,
      "y": 5,
      "z": 14,
      "name": "Soil_Hive"
    },
    {
      "x": -12,
      "y": 0,
      "z": 15,
      "name": "Soil_Dirt"
    },
    {
      "x": -12,
      "y": 1,
      "z": 15,
      "name": "Soil_Dirt"
    },
    {
      "x": -12,
      "y": 2,
      "z": 15,
      "name": "Soil_Dirt"
    },
    {
      "x": -12,
      "y": 3,
      "z": 15,
      "name": "Soil_Dirt"
    },
    {
      "x": -12,
      "y": 4,
      "z": 15,
      "name": "Soil_Dirt"
    },
    {
      "x": -12,
      "y": 5,
      "z": 15,
      "name": "Rock_Stone_Brick_Smooth"
    },
    {
      "x": -11,
      "y": 0,
      "z": -14,
      "name": "Soil_Dirt"
    },
    {
      "x": -11,
      "y": 1,
      "z": -14,
      "name": "Soil_Dirt"
    },
    {
      "x": -11,
      "y": 2,
      "z": -14,
      "name": "Soil_Dirt"
    },
    {
      "x": -11,
      "y": 3,
      "z": -14,
      "name": "Soil_Dirt"
    },
    {
      "x": -11,
      "y": 4,
      "z": -14,
      "name": "Soil_Dirt"
    },
    {
      "x": -11,
      "y": 5,
      "z": -14,
      "name": "Rock_Stone_Brick_Smooth"
    },
    {
      "x": -11,
      "y": 0,
      "z": -13,
      "name": "Soil_Dirt"
    },
    {
      "x": -11,
      "y": 1,
      "z": -13,
      "name": "Soil_Dirt"
    },
    {
      "x": -11,
      "y": 2,
      "z": -13,
      "name": "Soil_Dirt"
    },
    {
      "x": -11,
      "y": 3,
      "z": -13,
      "name": "Soil_Dirt"
    },
    {
      "x": -11,
      "y": 4,
      "z": -13,
      "name": "Soil_Dirt"
    },
    {
      "x": -11,
      "y": 5,
      "z": -13,
      "name": "Soil_Ash"
    },
    {
      "x": -11,
      "y": 6,
      "z": -13,
      "name": "Plant_Leaves_Dead",
      "support": 15
    },
    {
      "x": -11,
      "y": 0,
      "z": -12,
      "name": "Soil_Dirt"
    },
    {
      "x": -11,
      "y": 1,
      "z": -12,
      "name": "Soil_Dirt"
    },
    {
      "x": -11,
      "y": 2,
      "z": -12,
      "name": "Soil_Dirt"
    },
    {
      "x": -11,
      "y": 3,
      "z": -12,
      "name": "Soil_Dirt"
    },
    {
      "x": -11,
      "y": 4,
      "z": -12,
      "name": "Soil_Dirt"
    },
    {
      "x": -11,
      "y": 5,
      "z": -12,
      "name": "Soil_Hive"
    },
    {
      "x": -11,
      "y": 0,
      "z": -11,
      "name": "Soil_Dirt"
    },
    {
      "x": -11,
      "y": 1,
      "z": -11,
      "name": "Soil_Dirt"
    },
    {
      "x": -11,
      "y": 2,
      "z": -11,
      "name": "Soil_Dirt"
    },
    {
      "x": -11,
      "y": 3,
      "z": -11,
      "name": "Soil_Dirt"
    },
    {
      "x": -11,
      "y": 4,
      "z": -11,
      "name": "Soil_Dirt"
    },
    {
      "x": -11,
      "y": 5,
      "z": -11,
      "name": "Soil_Roots_Poisoned"
    },
    {
      "x": -11,
      "y": 6,
      "z": -11,
      "name": "*Wood_Deadwood_Fence_State_Definitions_Corner",
      "rotation": 1
    },
    {
      "x": -11,
      "y": 7,
      "z": -11,
      "name": "*Wood_Deadwood_Fence_State_Definitions_Corner",
      "rotation": 1
    },
    {
      "x": -11,
      "y": 8,
      "z": -11,
      "name": "*Wood_Deadwood_Fence_State_Definitions_Corner",
      "rotation": 1
    },
    {
      "x": -11,
      "y": 9,
      "z": -11,
      "name": "Barrier",
      "support": 15,
      "rotation": 2
    },
    {
      "x": -11,
      "y": 10,
      "z": -11,
      "name": "Barrier",
      "support": 15,
      "rotation": 2
    },
    {
      "x": -11,
      "y": 11,
      "z": -11,
      "name": "Barrier",
      "support": 15,
      "rotation": 2
    },
    {
      "x": -11,
      "y": 12,
      "z": -11,
      "name": "Barrier",
      "support": 15,
      "rotation": 2
    },
    {
      "x": -11,
      "y": 13,
      "z": -11,
      "name": "Barrier",
      "support": 15,
      "rotation": 2
    },
    {
      "x": -11,
      "y": 14,
      "z": -11,
      "name": "Barrier",
      "support": 15,
      "rotation": 2
    },
    {
      "x": -11,
      "y": 15,
      "z": -11,
      "name": "Barrier",
      "support": 15,
      "rotation": 2
    },
    {
      "x": -11,
      "y": 0,
      "z": -10,
      "name": "Soil_Dirt"
    },
    {
      "x": -11,
      "y": 1,
      "z": -10,
      "name": "Soil_Dirt"
    },
    {
      "x": -11,
      "y": 2,
      "z": -10,
      "name": "Soil_Dirt"
    },
    {
      "x": -11,
      "y": 3,
      "z": -10,
      "name": "Soil_Dirt"
    },
    {
      "x": -11,
      "y": 4,
      "z": -10,
      "name": "Soil_Dirt"
    },
    {
      "x": -11,
      "y": 5,
      "z": -10,
      "name": "Soil_Hive_Corrupted"
    },
    {
      "x": -11,
      "y": 6,
      "z": -10,
      "name": "Wood_Deadwood_Fence",
      "support": 15,
      "rotation": 1
    },
    {
      "x": -11,
      "y": 7,
      "z": -10,
      "name": "Wood_Deadwood_Fence",
      "support": 15,
      "rotation": 1
    },
    {
      "x": -11,
      "y": 8,
      "z": -10,
      "name": "Wood_Deadwood_Fence",
      "support": 15,
      "rotation": 1
    },
    {
      "x": -11,
      "y": 9,
      "z": -10,
      "name": "Barrier",
      "support": 15,
      "rotation": 2
    },
    {
      "x": -11,
      "y": 10,
      "z": -10,
      "name": "Barrier",
      "support": 15,
      "rotation": 2
    },
    {
      "x": -11,
      "y": 11,
      "z": -10,
      "name": "Barrier",
      "support": 15,
      "rotation": 2
    },
    {
      "x": -11,
      "y": 12,
      "z": -10,
      "name": "Barrier",
      "support": 15,
      "rotation": 2
    },
    {
      "x": -11,
      "y": 13,
      "z": -10,
      "name": "Barrier",
      "support": 15,
      "rotation": 2
    },
    {
      "x": -11,
      "y": 14,
      "z": -10,
      "name": "Barrier",
      "support": 15,
      "rotation": 2
    },
    {
      "x": -11,
      "y": 15,
      "z": -10,
      "name": "Barrier",
      "support": 15,
      "rotation": 2
    },
    {
      "x": -11,
      "y": 0,
      "z": -9,
      "name": "Soil_Dirt"
    },
    {
      "x": -11,
      "y": 1,
      "z": -9,
      "name": "Soil_Dirt"
    },
    {
      "x": -11,
      "y": 2,
      "z": -9,
      "name": "Soil_Dirt"
    },
    {
      "x": -11,
      "y": 3,
      "z": -9,
      "name": "Soil_Dirt"
    },
    {
      "x": -11,
      "y": 4,
      "z": -9,
      "name": "Soil_Dirt"
    },
    {
      "x": -11,
      "y": 5,
      "z": -9,
      "name": "Soil_Roots_Poisoned"
    },
    {
      "x": -11,
      "y": 6,
      "z": -9,
      "name": "Wood_Deadwood_Fence",
      "support": 15,
      "rotation": 1
    },
    {
      "x": -11,
      "y": 7,
      "z": -9,
      "name": "Wood_Deadwood_Fence",
      "support": 15,
      "rotation": 1
    },
    {
      "x": -11,
      "y": 8,
      "z": -9,
      "name": "Wood_Deadwood_Fence",
      "support": 15,
      "rotation": 1
    },
    {
      "x": -11,
      "y": 9,
      "z": -9,
      "name": "Barrier",
      "support": 15,
      "rotation": 2
    },
    {
      "x": -11,
      "y": 10,
      "z": -9,
      "name": "Barrier",
      "support": 15,
      "rotation": 2
    },
    {
      "x": -11,
      "y": 11,
      "z": -9,
      "name": "Barrier",
      "support": 15,
      "rotation": 2
    },
    {
      "x": -11,
      "y": 12,
      "z": -9,
      "name": "Barrier",
      "support": 15,
      "rotation": 2
    },
    {
      "x": -11,
      "y": 13,
      "z": -9,
      "name": "Barrier",
      "support": 15,
      "rotation": 2
    },
    {
      "x": -11,
      "y": 14,
      "z": -9,
      "name": "Barrier",
      "support": 15,
      "rotation": 2
    },
    {
      "x": -11,
      "y": 15,
      "z": -9,
      "name": "Barrier",
      "support": 15,
      "rotation": 2
    },
    {
      "x": -11,
      "y": 0,
      "z": -8,
      "name": "Soil_Dirt"
    },
    {
      "x": -11,
      "y": 1,
      "z": -8,
      "name": "Soil_Dirt"
    },
    {
      "x": -11,
      "y": 2,
      "z": -8,
      "name": "Soil_Dirt"
    },
    {
      "x": -11,
      "y": 3,
      "z": -8,
      "name": "Soil_Dirt"
    },
    {
      "x": -11,
      "y": 4,
      "z": -8,
      "name": "Soil_Dirt"
    },
    {
      "x": -11,
      "y": 5,
      "z": -8,
      "name": "Soil_Ash"
    },
    {
      "x": -11,
      "y": 6,
      "z": -8,
      "name": "Wood_Deadwood_Fence",
      "support": 15,
      "rotation": 1
    },
    {
      "x": -11,
      "y": 7,
      "z": -8,
      "name": "Wood_Deadwood_Fence",
      "support": 15,
      "rotation": 1
    },
    {
      "x": -11,
      "y": 8,
      "z": -8,
      "name": "Wood_Deadwood_Fence",
      "support": 15,
      "rotation": 1
    },
    {
      "x": -11,
      "y": 9,
      "z": -8,
      "name": "Barrier",
      "support": 15,
      "rotation": 2
    },
    {
      "x": -11,
      "y": 10,
      "z": -8,
      "name": "Barrier",
      "support": 15,
      "rotation": 2
    },
    {
      "x": -11,
      "y": 11,
      "z": -8,
      "name": "Barrier",
      "support": 15,
      "rotation": 2
    },
    {
      "x": -11,
      "y": 12,
      "z": -8,
      "name": "Barrier",
      "support": 15,
      "rotation": 2
    },
    {
      "x": -11,
      "y": 13,
      "z": -8,
      "name": "Barrier",
      "support": 15,
      "rotation": 2
    },
    {
      "x": -11,
      "y": 14,
      "z": -8,
      "name": "Barrier",
      "support": 15,
      "rotation": 2
    },
    {
      "x": -11,
      "y": 15,
      "z": -8,
      "name": "Barrier",
      "support": 15,
      "rotation": 2
    },
    {
      "x": -11,
      "y": 0,
      "z": -7,
      "name": "Soil_Dirt"
    },
    {
      "x": -11,
      "y": 1,
      "z": -7,
      "name": "Soil_Dirt"
    },
    {
      "x": -11,
      "y": 2,
      "z": -7,
      "name": "Soil_Dirt"
    },
    {
      "x": -11,
      "y": 3,
      "z": -7,
      "name": "Soil_Dirt"
    },
    {
      "x": -11,
      "y": 4,
      "z": -7,
      "name": "Soil_Dirt"
    },
    {
      "x": -11,
      "y": 5,
      "z": -7,
      "name": "Soil_Ash"
    },
    {
      "x": -11,
      "y": 6,
      "z": -7,
      "name": "*Wood_Deadwood_Fence_State_Definitions_T",
      "rotation": 1
    },
    {
      "x": -11,
      "y": 7,
      "z": -7,
      "name": "*Wood_Deadwood_Fence_State_Definitions_T",
      "rotation": 1
    },
    {
      "x": -11,
      "y": 8,
      "z": -7,
      "name": "*Wood_Deadwood_Fence_State_Definitions_T",
      "rotation": 1
    },
    {
      "x": -11,
      "y": 9,
      "z": -7,
      "name": "Barrier",
      "support": 15,
      "rotation": 2
    },
    {
      "x": -11,
      "y": 10,
      "z": -7,
      "name": "Barrier",
      "support": 15,
      "rotation": 2
    },
    {
      "x": -11,
      "y": 11,
      "z": -7,
      "name": "Barrier",
      "support": 15,
      "rotation": 2
    },
    {
      "x": -11,
      "y": 12,
      "z": -7,
      "name": "Barrier",
      "support": 15,
      "rotation": 2
    },
    {
      "x": -11,
      "y": 13,
      "z": -7,
      "name": "Barrier",
      "support": 15,
      "rotation": 2
    },
    {
      "x": -11,
      "y": 14,
      "z": -7,
      "name": "Barrier",
      "support": 15,
      "rotation": 2
    },
    {
      "x": -11,
      "y": 15,
      "z": -7,
      "name": "Barrier",
      "support": 15,
      "rotation": 2
    },
    {
      "x": -11,
      "y": 0,
      "z": -6,
      "name": "Soil_Dirt"
    },
    {
      "x": -11,
      "y": 1,
      "z": -6,
      "name": "Soil_Dirt"
    },
    {
      "x": -11,
      "y": 2,
      "z": -6,
      "name": "Soil_Dirt"
    },
    {
      "x": -11,
      "y": 3,
      "z": -6,
      "name": "Soil_Dirt"
    },
    {
      "x": -11,
      "y": 4,
      "z": -6,
      "name": "Soil_Dirt"
    },
    {
      "x": -11,
      "y": 5,
      "z": -6,
      "name": "Soil_Ash"
    },
    {
      "x": -11,
      "y": 6,
      "z": -6,
      "name": "Wood_Deadwood_Fence",
      "support": 15,
      "rotation": 1
    },
    {
      "x": -11,
      "y": 7,
      "z": -6,
      "name": "Wood_Deadwood_Fence",
      "support": 15,
      "rotation": 1
    },
    {
      "x": -11,
      "y": 8,
      "z": -6,
      "name": "Wood_Deadwood_Fence",
      "support": 15,
      "rotation": 1
    },
    {
      "x": -11,
      "y": 9,
      "z": -6,
      "name": "Barrier",
      "support": 15,
      "rotation": 2
    },
    {
      "x": -11,
      "y": 10,
      "z": -6,
      "name": "Barrier",
      "support": 15,
      "rotation": 2
    },
    {
      "x": -11,
      "y": 11,
      "z": -6,
      "name": "Barrier",
      "support": 15,
      "rotation": 2
    },
    {
      "x": -11,
      "y": 12,
      "z": -6,
      "name": "Barrier",
      "support": 15,
      "rotation": 2
    },
    {
      "x": -11,
      "y": 13,
      "z": -6,
      "name": "Barrier",
      "support": 15,
      "rotation": 2
    },
    {
      "x": -11,
      "y": 14,
      "z": -6,
      "name": "Barrier",
      "support": 15,
      "rotation": 2
    },
    {
      "x": -11,
      "y": 15,
      "z": -6,
      "name": "Barrier",
      "support": 15,
      "rotation": 2
    },
    {
      "x": -11,
      "y": 0,
      "z": -5,
      "name": "Soil_Dirt"
    },
    {
      "x": -11,
      "y": 1,
      "z": -5,
      "name": "Soil_Dirt"
    },
    {
      "x": -11,
      "y": 2,
      "z": -5,
      "name": "Soil_Dirt"
    },
    {
      "x": -11,
      "y": 3,
      "z": -5,
      "name": "Soil_Dirt"
    },
    {
      "x": -11,
      "y": 4,
      "z": -5,
      "name": "Soil_Dirt"
    },
    {
      "x": -11,
      "y": 5,
      "z": -5,
      "name": "Soil_Ash"
    },
    {
      "x": -11,
      "y": 6,
      "z": -5,
      "name": "Wood_Deadwood_Fence",
      "support": 15,
      "rotation": 1
    },
    {
      "x": -11,
      "y": 7,
      "z": -5,
      "name": "Wood_Deadwood_Fence",
      "support": 15,
      "rotation": 1
    },
    {
      "x": -11,
      "y": 8,
      "z": -5,
      "name": "Wood_Deadwood_Fence",
      "support": 15,
      "rotation": 1
    },
    {
      "x": -11,
      "y": 9,
      "z": -5,
      "name": "Barrier",
      "support": 15,
      "rotation": 2
    },
    {
      "x": -11,
      "y": 10,
      "z": -5,
      "name": "Barrier",
      "support": 15,
      "rotation": 2
    },
    {
      "x": -11,
      "y": 11,
      "z": -5,
      "name": "Barrier",
      "support": 15,
      "rotation": 2
    },
    {
      "x": -11,
      "y": 12,
      "z": -5,
      "name": "Barrier",
      "support": 15,
      "rotation": 2
    },
    {
      "x": -11,
      "y": 13,
      "z": -5,
      "name": "Barrier",
      "support": 15,
      "rotation": 2
    },
    {
      "x": -11,
      "y": 14,
      "z": -5,
      "name": "Barrier",
      "support": 15,
      "rotation": 2
    },
    {
      "x": -11,
      "y": 15,
      "z": -5,
      "name": "Barrier",
      "support": 15,
      "rotation": 2
    },
    {
      "x": -11,
      "y": 0,
      "z": -4,
      "name": "Soil_Dirt"
    },
    {
      "x": -11,
      "y": 1,
      "z": -4,
      "name": "Soil_Dirt"
    },
    {
      "x": -11,
      "y": 2,
      "z": -4,
      "name": "Soil_Dirt"
    },
    {
      "x": -11,
      "y": 3,
      "z": -4,
      "name": "Soil_Dirt"
    },
    {
      "x": -11,
      "y": 4,
      "z": -4,
      "name": "Soil_Dirt"
    },
    {
      "x": -11,
      "y": 5,
      "z": -4,
      "name": "Soil_Ash"
    },
    {
      "x": -11,
      "y": 6,
      "z": -4,
      "name": "Wood_Deadwood_Fence",
      "support": 15,
      "rotation": 1
    },
    {
      "x": -11,
      "y": 7,
      "z": -4,
      "name": "Wood_Deadwood_Fence",
      "support": 15,
      "rotation": 1
    },
    {
      "x": -11,
      "y": 8,
      "z": -4,
      "name": "Wood_Deadwood_Fence",
      "support": 15,
      "rotation": 1
    },
    {
      "x": -11,
      "y": 9,
      "z": -4,
      "name": "Barrier",
      "support": 15,
      "rotation": 2
    },
    {
      "x": -11,
      "y": 10,
      "z": -4,
      "name": "Barrier",
      "support": 15,
      "rotation": 2
    },
    {
      "x": -11,
      "y": 11,
      "z": -4,
      "name": "Barrier",
      "support": 15,
      "rotation": 2
    },
    {
      "x": -11,
      "y": 12,
      "z": -4,
      "name": "Barrier",
      "support": 15,
      "rotation": 2
    },
    {
      "x": -11,
      "y": 13,
      "z": -4,
      "name": "Barrier",
      "support": 15,
      "rotation": 2
    },
    {
      "x": -11,
      "y": 14,
      "z": -4,
      "name": "Barrier",
      "support": 15,
      "rotation": 2
    },
    {
      "x": -11,
      "y": 15,
      "z": -4,
      "name": "Barrier",
      "support": 15,
      "rotation": 2
    },
    {
      "x": -11,
      "y": 0,
      "z": -3,
      "name": "Soil_Dirt"
    },
    {
      "x": -11,
      "y": 1,
      "z": -3,
      "name": "Soil_Dirt"
    },
    {
      "x": -11,
      "y": 2,
      "z": -3,
      "name": "Soil_Dirt"
    },
    {
      "x": -11,
      "y": 3,
      "z": -3,
      "name": "Soil_Dirt"
    },
    {
      "x": -11,
      "y": 4,
      "z": -3,
      "name": "Soil_Dirt"
    },
    {
      "x": -11,
      "y": 5,
      "z": -3,
      "name": "Soil_Ash"
    },
    {
      "x": -11,
      "y": 6,
      "z": -3,
      "name": "Wood_Deadwood_Fence",
      "support": 15,
      "rotation": 1
    },
    {
      "x": -11,
      "y": 7,
      "z": -3,
      "name": "Wood_Deadwood_Fence",
      "support": 15,
      "rotation": 1
    },
    {
      "x": -11,
      "y": 8,
      "z": -3,
      "name": "Wood_Deadwood_Fence",
      "support": 15,
      "rotation": 1
    },
    {
      "x": -11,
      "y": 9,
      "z": -3,
      "name": "Barrier",
      "support": 15,
      "rotation": 2
    },
    {
      "x": -11,
      "y": 10,
      "z": -3,
      "name": "Barrier",
      "support": 15,
      "rotation": 2
    },
    {
      "x": -11,
      "y": 11,
      "z": -3,
      "name": "Barrier",
      "support": 15,
      "rotation": 2
    },
    {
      "x": -11,
      "y": 12,
      "z": -3,
      "name": "Barrier",
      "support": 15,
      "rotation": 2
    },
    {
      "x": -11,
      "y": 13,
      "z": -3,
      "name": "Barrier",
      "support": 15,
      "rotation": 2
    },
    {
      "x": -11,
      "y": 14,
      "z": -3,
      "name": "Barrier",
      "support": 15,
      "rotation": 2
    },
    {
      "x": -11,
      "y": 15,
      "z": -3,
      "name": "Barrier",
      "support": 15,
      "rotation": 2
    },
    {
      "x": -11,
      "y": 0,
      "z": -2,
      "name": "Soil_Dirt"
    },
    {
      "x": -11,
      "y": 1,
      "z": -2,
      "name": "Soil_Dirt"
    },
    {
      "x": -11,
      "y": 2,
      "z": -2,
      "name": "Soil_Dirt"
    },
    {
      "x": -11,
      "y": 3,
      "z": -2,
      "name": "Soil_Dirt"
    },
    {
      "x": -11,
      "y": 4,
      "z": -2,
      "name": "Soil_Dirt"
    },
    {
      "x": -11,
      "y": 5,
      "z": -2,
      "name": "Soil_Hive"
    },
    {
      "x": -11,
      "y": 6,
      "z": -2,
      "name": "Wood_Deadwood_Fence",
      "support": 15,
      "rotation": 1
    },
    {
      "x": -11,
      "y": 7,
      "z": -2,
      "name": "Wood_Deadwood_Fence",
      "support": 15,
      "rotation": 1
    },
    {
      "x": -11,
      "y": 8,
      "z": -2,
      "name": "Wood_Deadwood_Fence",
      "support": 15,
      "rotation": 1
    },
    {
      "x": -11,
      "y": 9,
      "z": -2,
      "name": "Barrier",
      "support": 15,
      "rotation": 2
    },
    {
      "x": -11,
      "y": 10,
      "z": -2,
      "name": "Barrier",
      "support": 15,
      "rotation": 2
    },
    {
      "x": -11,
      "y": 11,
      "z": -2,
      "name": "Barrier",
      "support": 15,
      "rotation": 2
    },
    {
      "x": -11,
      "y": 12,
      "z": -2,
      "name": "Barrier",
      "support": 15,
      "rotation": 2
    },
    {
      "x": -11,
      "y": 13,
      "z": -2,
      "name": "Barrier",
      "support": 15,
      "rotation": 2
    },
    {
      "x": -11,
      "y": 14,
      "z": -2,
      "name": "Barrier",
      "support": 15,
      "rotation": 2
    },
    {
      "x": -11,
      "y": 15,
      "z": -2,
      "name": "Barrier",
      "support": 15,
      "rotation": 2
    },
    {
      "x": -11,
      "y": 0,
      "z": -1,
      "name": "Soil_Dirt"
    },
    {
      "x": -11,
      "y": 1,
      "z": -1,
      "name": "Soil_Dirt"
    },
    {
      "x": -11,
      "y": 2,
      "z": -1,
      "name": "Soil_Dirt"
    },
    {
      "x": -11,
      "y": 3,
      "z": -1,
      "name": "Soil_Dirt"
    },
    {
      "x": -11,
      "y": 4,
      "z": -1,
      "name": "Soil_Dirt"
    },
    {
      "x": -11,
      "y": 5,
      "z": -1,
      "name": "Soil_Hive"
    },
    {
      "x": -11,
      "y": 6,
      "z": -1,
      "name": "Wood_Deadwood_Fence",
      "support": 15,
      "rotation": 1
    },
    {
      "x": -11,
      "y": 7,
      "z": -1,
      "name": "Wood_Deadwood_Fence",
      "support": 15,
      "rotation": 1
    },
    {
      "x": -11,
      "y": 8,
      "z": -1,
      "name": "Wood_Deadwood_Fence",
      "support": 15,
      "rotation": 1
    },
    {
      "x": -11,
      "y": 9,
      "z": -1,
      "name": "Barrier",
      "support": 15,
      "rotation": 2
    },
    {
      "x": -11,
      "y": 10,
      "z": -1,
      "name": "Barrier",
      "support": 15,
      "rotation": 2
    },
    {
      "x": -11,
      "y": 11,
      "z": -1,
      "name": "Barrier",
      "support": 15,
      "rotation": 2
    },
    {
      "x": -11,
      "y": 12,
      "z": -1,
      "name": "Barrier",
      "support": 15,
      "rotation": 2
    },
    {
      "x": -11,
      "y": 13,
      "z": -1,
      "name": "Barrier",
      "support": 15,
      "rotation": 2
    },
    {
      "x": -11,
      "y": 14,
      "z": -1,
      "name": "Barrier",
      "support": 15,
      "rotation": 2
    },
    {
      "x": -11,
      "y": 15,
      "z": -1,
      "name": "Barrier",
      "support": 15,
      "rotation": 2
    },
    {
      "x": -11,
      "y": 0,
      "z": 0,
      "name": "Soil_Dirt"
    },
    {
      "x": -11,
      "y": 1,
      "z": 0,
      "name": "Soil_Dirt"
    },
    {
      "x": -11,
      "y": 2,
      "z": 0,
      "name": "Soil_Dirt"
    },
    {
      "x": -11,
      "y": 3,
      "z": 0,
      "name": "Soil_Dirt"
    },
    {
      "x": -11,
      "y": 4,
      "z": 0,
      "name": "Soil_Dirt"
    },
    {
      "x": -11,
      "y": 5,
      "z": 0,
      "name": "Soil_Hive"
    },
    {
      "x": -11,
      "y": 6,
      "z": 0,
      "name": "Wood_Deadwood_Fence",
      "support": 15,
      "rotation": 1
    },
    {
      "x": -11,
      "y": 7,
      "z": 0,
      "name": "Wood_Deadwood_Fence",
      "support": 15,
      "rotation": 1
    },
    {
      "x": -11,
      "y": 8,
      "z": 0,
      "name": "Wood_Deadwood_Fence",
      "support": 15,
      "rotation": 1
    },
    {
      "x": -11,
      "y": 9,
      "z": 0,
      "name": "Barrier",
      "support": 15,
      "rotation": 2
    },
    {
      "x": -11,
      "y": 10,
      "z": 0,
      "name": "Barrier",
      "support": 15,
      "rotation": 2
    },
    {
      "x": -11,
      "y": 11,
      "z": 0,
      "name": "Barrier",
      "support": 15,
      "rotation": 2
    },
    {
      "x": -11,
      "y": 12,
      "z": 0,
      "name": "Barrier",
      "support": 15,
      "rotation": 2
    },
    {
      "x": -11,
      "y": 13,
      "z": 0,
      "name": "Barrier",
      "support": 15,
      "rotation": 2
    },
    {
      "x": -11,
      "y": 14,
      "z": 0,
      "name": "Barrier",
      "support": 15,
      "rotation": 2
    },
    {
      "x": -11,
      "y": 15,
      "z": 0,
      "name": "Barrier",
      "support": 15,
      "rotation": 2
    },
    {
      "x": -11,
      "y": 0,
      "z": 1,
      "name": "Soil_Dirt"
    },
    {
      "x": -11,
      "y": 1,
      "z": 1,
      "name": "Soil_Dirt"
    },
    {
      "x": -11,
      "y": 2,
      "z": 1,
      "name": "Soil_Dirt"
    },
    {
      "x": -11,
      "y": 3,
      "z": 1,
      "name": "Soil_Dirt"
    },
    {
      "x": -11,
      "y": 4,
      "z": 1,
      "name": "Soil_Dirt"
    },
    {
      "x": -11,
      "y": 5,
      "z": 1,
      "name": "Soil_Roots_Poisoned"
    },
    {
      "x": -11,
      "y": 6,
      "z": 1,
      "name": "Wood_Deadwood_Fence",
      "support": 15,
      "rotation": 1
    },
    {
      "x": -11,
      "y": 7,
      "z": 1,
      "name": "Wood_Deadwood_Fence",
      "support": 15,
      "rotation": 1
    },
    {
      "x": -11,
      "y": 8,
      "z": 1,
      "name": "Wood_Deadwood_Fence",
      "support": 15,
      "rotation": 1
    },
    {
      "x": -11,
      "y": 9,
      "z": 1,
      "name": "Barrier",
      "support": 15,
      "rotation": 2
    },
    {
      "x": -11,
      "y": 10,
      "z": 1,
      "name": "Barrier",
      "support": 15,
      "rotation": 2
    },
    {
      "x": -11,
      "y": 11,
      "z": 1,
      "name": "Barrier",
      "support": 15,
      "rotation": 2
    },
    {
      "x": -11,
      "y": 12,
      "z": 1,
      "name": "Barrier",
      "support": 15,
      "rotation": 2
    },
    {
      "x": -11,
      "y": 13,
      "z": 1,
      "name": "Barrier",
      "support": 15,
      "rotation": 2
    },
    {
      "x": -11,
      "y": 14,
      "z": 1,
      "name": "Barrier",
      "support": 15,
      "rotation": 2
    },
    {
      "x": -11,
      "y": 15,
      "z": 1,
      "name": "Barrier",
      "support": 15,
      "rotation": 2
    },
    {
      "x": -11,
      "y": 0,
      "z": 2,
      "name": "Soil_Dirt"
    },
    {
      "x": -11,
      "y": 1,
      "z": 2,
      "name": "Soil_Dirt"
    },
    {
      "x": -11,
      "y": 2,
      "z": 2,
      "name": "Soil_Dirt"
    },
    {
      "x": -11,
      "y": 3,
      "z": 2,
      "name": "Soil_Dirt"
    },
    {
      "x": -11,
      "y": 4,
      "z": 2,
      "name": "Soil_Dirt"
    },
    {
      "x": -11,
      "y": 5,
      "z": 2,
      "name": "Soil_Ash"
    },
    {
      "x": -11,
      "y": 6,
      "z": 2,
      "name": "Wood_Deadwood_Fence",
      "support": 15,
      "rotation": 1
    },
    {
      "x": -11,
      "y": 7,
      "z": 2,
      "name": "Wood_Deadwood_Fence",
      "support": 15,
      "rotation": 1
    },
    {
      "x": -11,
      "y": 8,
      "z": 2,
      "name": "Wood_Deadwood_Fence",
      "support": 15,
      "rotation": 1
    },
    {
      "x": -11,
      "y": 9,
      "z": 2,
      "name": "Barrier",
      "support": 15,
      "rotation": 2
    },
    {
      "x": -11,
      "y": 10,
      "z": 2,
      "name": "Barrier",
      "support": 15,
      "rotation": 2
    },
    {
      "x": -11,
      "y": 11,
      "z": 2,
      "name": "Barrier",
      "support": 15,
      "rotation": 2
    },
    {
      "x": -11,
      "y": 12,
      "z": 2,
      "name": "Barrier",
      "support": 15,
      "rotation": 2
    },
    {
      "x": -11,
      "y": 13,
      "z": 2,
      "name": "Barrier",
      "support": 15,
      "rotation": 2
    },
    {
      "x": -11,
      "y": 14,
      "z": 2,
      "name": "Barrier",
      "support": 15,
      "rotation": 2
    },
    {
      "x": -11,
      "y": 15,
      "z": 2,
      "name": "Barrier",
      "support": 15,
      "rotation": 2
    },
    {
      "x": -11,
      "y": 0,
      "z": 3,
      "name": "Soil_Dirt"
    },
    {
      "x": -11,
      "y": 1,
      "z": 3,
      "name": "Soil_Dirt"
    },
    {
      "x": -11,
      "y": 2,
      "z": 3,
      "name": "Soil_Dirt"
    },
    {
      "x": -11,
      "y": 3,
      "z": 3,
      "name": "Soil_Dirt"
    },
    {
      "x": -11,
      "y": 4,
      "z": 3,
      "name": "Soil_Dirt"
    },
    {
      "x": -11,
      "y": 5,
      "z": 3,
      "name": "Soil_Roots_Poisoned"
    },
    {
      "x": -11,
      "y": 6,
      "z": 3,
      "name": "Wood_Deadwood_Fence",
      "support": 15,
      "rotation": 1
    },
    {
      "x": -11,
      "y": 7,
      "z": 3,
      "name": "Wood_Deadwood_Fence",
      "support": 15,
      "rotation": 1
    },
    {
      "x": -11,
      "y": 8,
      "z": 3,
      "name": "Wood_Deadwood_Fence",
      "support": 15,
      "rotation": 1
    },
    {
      "x": -11,
      "y": 9,
      "z": 3,
      "name": "Barrier",
      "support": 15,
      "rotation": 2
    },
    {
      "x": -11,
      "y": 10,
      "z": 3,
      "name": "Barrier",
      "support": 15,
      "rotation": 2
    },
    {
      "x": -11,
      "y": 11,
      "z": 3,
      "name": "Barrier",
      "support": 15,
      "rotation": 2
    },
    {
      "x": -11,
      "y": 12,
      "z": 3,
      "name": "Barrier",
      "support": 15,
      "rotation": 2
    },
    {
      "x": -11,
      "y": 13,
      "z": 3,
      "name": "Barrier",
      "support": 15,
      "rotation": 2
    },
    {
      "x": -11,
      "y": 14,
      "z": 3,
      "name": "Barrier",
      "support": 15,
      "rotation": 2
    },
    {
      "x": -11,
      "y": 15,
      "z": 3,
      "name": "Barrier",
      "support": 15,
      "rotation": 2
    },
    {
      "x": -11,
      "y": 0,
      "z": 4,
      "name": "Soil_Dirt"
    },
    {
      "x": -11,
      "y": 1,
      "z": 4,
      "name": "Soil_Dirt"
    },
    {
      "x": -11,
      "y": 2,
      "z": 4,
      "name": "Soil_Dirt"
    },
    {
      "x": -11,
      "y": 3,
      "z": 4,
      "name": "Soil_Dirt"
    },
    {
      "x": -11,
      "y": 4,
      "z": 4,
      "name": "Soil_Dirt"
    },
    {
      "x": -11,
      "y": 5,
      "z": 4,
      "name": "Soil_Hive_Corrupted"
    },
    {
      "x": -11,
      "y": 6,
      "z": 4,
      "name": "Wood_Deadwood_Fence",
      "support": 15,
      "rotation": 1
    },
    {
      "x": -11,
      "y": 7,
      "z": 4,
      "name": "Wood_Deadwood_Fence",
      "support": 15,
      "rotation": 1
    },
    {
      "x": -11,
      "y": 8,
      "z": 4,
      "name": "Wood_Deadwood_Fence",
      "support": 15,
      "rotation": 1
    },
    {
      "x": -11,
      "y": 9,
      "z": 4,
      "name": "Barrier",
      "support": 15,
      "rotation": 2
    },
    {
      "x": -11,
      "y": 10,
      "z": 4,
      "name": "Barrier",
      "support": 15,
      "rotation": 2
    },
    {
      "x": -11,
      "y": 11,
      "z": 4,
      "name": "Barrier",
      "support": 15,
      "rotation": 2
    },
    {
      "x": -11,
      "y": 12,
      "z": 4,
      "name": "Barrier",
      "support": 15,
      "rotation": 2
    },
    {
      "x": -11,
      "y": 13,
      "z": 4,
      "name": "Barrier",
      "support": 15,
      "rotation": 2
    },
    {
      "x": -11,
      "y": 14,
      "z": 4,
      "name": "Barrier",
      "support": 15,
      "rotation": 2
    },
    {
      "x": -11,
      "y": 15,
      "z": 4,
      "name": "Barrier",
      "support": 15,
      "rotation": 2
    },
    {
      "x": -11,
      "y": 0,
      "z": 5,
      "name": "Soil_Dirt"
    },
    {
      "x": -11,
      "y": 1,
      "z": 5,
      "name": "Soil_Dirt"
    },
    {
      "x": -11,
      "y": 2,
      "z": 5,
      "name": "Soil_Dirt"
    },
    {
      "x": -11,
      "y": 3,
      "z": 5,
      "name": "Soil_Dirt"
    },
    {
      "x": -11,
      "y": 4,
      "z": 5,
      "name": "Soil_Dirt"
    },
    {
      "x": -11,
      "y": 5,
      "z": 5,
      "name": "Soil_Hive"
    },
    {
      "x": -11,
      "y": 6,
      "z": 5,
      "name": "Wood_Deadwood_Fence",
      "support": 15,
      "rotation": 1
    },
    {
      "x": -11,
      "y": 7,
      "z": 5,
      "name": "Wood_Deadwood_Fence",
      "support": 15,
      "rotation": 1
    },
    {
      "x": -11,
      "y": 8,
      "z": 5,
      "name": "Wood_Deadwood_Fence",
      "support": 15,
      "rotation": 1
    },
    {
      "x": -11,
      "y": 9,
      "z": 5,
      "name": "Barrier",
      "support": 15,
      "rotation": 2
    },
    {
      "x": -11,
      "y": 10,
      "z": 5,
      "name": "Barrier",
      "support": 15,
      "rotation": 2
    },
    {
      "x": -11,
      "y": 11,
      "z": 5,
      "name": "Barrier",
      "support": 15,
      "rotation": 2
    },
    {
      "x": -11,
      "y": 12,
      "z": 5,
      "name": "Barrier",
      "support": 15,
      "rotation": 2
    },
    {
      "x": -11,
      "y": 13,
      "z": 5,
      "name": "Barrier",
      "support": 15,
      "rotation": 2
    },
    {
      "x": -11,
      "y": 14,
      "z": 5,
      "name": "Barrier",
      "support": 15,
      "rotation": 2
    },
    {
      "x": -11,
      "y": 15,
      "z": 5,
      "name": "Barrier",
      "support": 15,
      "rotation": 2
    },
    {
      "x": -11,
      "y": 0,
      "z": 6,
      "name": "Soil_Dirt"
    },
    {
      "x": -11,
      "y": 1,
      "z": 6,
      "name": "Soil_Dirt"
    },
    {
      "x": -11,
      "y": 2,
      "z": 6,
      "name": "Soil_Dirt"
    },
    {
      "x": -11,
      "y": 3,
      "z": 6,
      "name": "Soil_Dirt"
    },
    {
      "x": -11,
      "y": 4,
      "z": 6,
      "name": "Soil_Dirt"
    },
    {
      "x": -11,
      "y": 5,
      "z": 6,
      "name": "Soil_Roots_Poisoned"
    },
    {
      "x": -11,
      "y": 6,
      "z": 6,
      "name": "Wood_Deadwood_Fence",
      "support": 15,
      "rotation": 1
    },
    {
      "x": -11,
      "y": 7,
      "z": 6,
      "name": "Wood_Deadwood_Fence",
      "support": 15,
      "rotation": 1
    },
    {
      "x": -11,
      "y": 8,
      "z": 6,
      "name": "Wood_Deadwood_Fence",
      "support": 15,
      "rotation": 1
    },
    {
      "x": -11,
      "y": 9,
      "z": 6,
      "name": "Barrier",
      "support": 15,
      "rotation": 2
    },
    {
      "x": -11,
      "y": 10,
      "z": 6,
      "name": "Barrier",
      "support": 15,
      "rotation": 2
    },
    {
      "x": -11,
      "y": 11,
      "z": 6,
      "name": "Barrier",
      "support": 15,
      "rotation": 2
    },
    {
      "x": -11,
      "y": 12,
      "z": 6,
      "name": "Barrier",
      "support": 15,
      "rotation": 2
    },
    {
      "x": -11,
      "y": 13,
      "z": 6,
      "name": "Barrier",
      "support": 15,
      "rotation": 2
    },
    {
      "x": -11,
      "y": 14,
      "z": 6,
      "name": "Barrier",
      "support": 15,
      "rotation": 2
    },
    {
      "x": -11,
      "y": 15,
      "z": 6,
      "name": "Barrier",
      "support": 15,
      "rotation": 2
    },
    {
      "x": -11,
      "y": 0,
      "z": 7,
      "name": "Soil_Dirt"
    },
    {
      "x": -11,
      "y": 1,
      "z": 7,
      "name": "Soil_Dirt"
    },
    {
      "x": -11,
      "y": 2,
      "z": 7,
      "name": "Soil_Dirt"
    },
    {
      "x": -11,
      "y": 3,
      "z": 7,
      "name": "Soil_Dirt"
    },
    {
      "x": -11,
      "y": 4,
      "z": 7,
      "name": "Soil_Dirt"
    },
    {
      "x": -11,
      "y": 5,
      "z": 7,
      "name": "Soil_Ash"
    },
    {
      "x": -11,
      "y": 6,
      "z": 7,
      "name": "Wood_Deadwood_Fence",
      "support": 15,
      "rotation": 1
    },
    {
      "x": -11,
      "y": 7,
      "z": 7,
      "name": "Wood_Deadwood_Fence",
      "support": 15,
      "rotation": 1
    },
    {
      "x": -11,
      "y": 8,
      "z": 7,
      "name": "Wood_Deadwood_Fence",
      "support": 15,
      "rotation": 1
    },
    {
      "x": -11,
      "y": 9,
      "z": 7,
      "name": "Barrier",
      "support": 15,
      "rotation": 2
    },
    {
      "x": -11,
      "y": 10,
      "z": 7,
      "name": "Barrier",
      "support": 15,
      "rotation": 2
    },
    {
      "x": -11,
      "y": 11,
      "z": 7,
      "name": "Barrier",
      "support": 15,
      "rotation": 2
    },
    {
      "x": -11,
      "y": 12,
      "z": 7,
      "name": "Barrier",
      "support": 15,
      "rotation": 2
    },
    {
      "x": -11,
      "y": 13,
      "z": 7,
      "name": "Barrier",
      "support": 15,
      "rotation": 2
    },
    {
      "x": -11,
      "y": 14,
      "z": 7,
      "name": "Barrier",
      "support": 15,
      "rotation": 2
    },
    {
      "x": -11,
      "y": 15,
      "z": 7,
      "name": "Barrier",
      "support": 15,
      "rotation": 2
    },
    {
      "x": -11,
      "y": 0,
      "z": 8,
      "name": "Soil_Dirt"
    },
    {
      "x": -11,
      "y": 1,
      "z": 8,
      "name": "Soil_Dirt"
    },
    {
      "x": -11,
      "y": 2,
      "z": 8,
      "name": "Soil_Dirt"
    },
    {
      "x": -11,
      "y": 3,
      "z": 8,
      "name": "Soil_Dirt"
    },
    {
      "x": -11,
      "y": 4,
      "z": 8,
      "name": "Soil_Dirt"
    },
    {
      "x": -11,
      "y": 5,
      "z": 8,
      "name": "Soil_Hive_Corrupted"
    },
    {
      "x": -11,
      "y": 6,
      "z": 8,
      "name": "Wood_Deadwood_Fence",
      "support": 15,
      "rotation": 1
    },
    {
      "x": -11,
      "y": 7,
      "z": 8,
      "name": "Wood_Deadwood_Fence",
      "support": 15,
      "rotation": 1
    },
    {
      "x": -11,
      "y": 8,
      "z": 8,
      "name": "Wood_Deadwood_Fence",
      "support": 15,
      "rotation": 1
    },
    {
      "x": -11,
      "y": 9,
      "z": 8,
      "name": "Barrier",
      "support": 15,
      "rotation": 2
    },
    {
      "x": -11,
      "y": 10,
      "z": 8,
      "name": "Barrier",
      "support": 15,
      "rotation": 2
    },
    {
      "x": -11,
      "y": 11,
      "z": 8,
      "name": "Barrier",
      "support": 15,
      "rotation": 2
    },
    {
      "x": -11,
      "y": 12,
      "z": 8,
      "name": "Barrier",
      "support": 15,
      "rotation": 2
    },
    {
      "x": -11,
      "y": 13,
      "z": 8,
      "name": "Barrier",
      "support": 15,
      "rotation": 2
    },
    {
      "x": -11,
      "y": 14,
      "z": 8,
      "name": "Barrier",
      "support": 15,
      "rotation": 2
    },
    {
      "x": -11,
      "y": 15,
      "z": 8,
      "name": "Barrier",
      "support": 15,
      "rotation": 2
    },
    {
      "x": -11,
      "y": 0,
      "z": 9,
      "name": "Soil_Dirt"
    },
    {
      "x": -11,
      "y": 1,
      "z": 9,
      "name": "Soil_Dirt"
    },
    {
      "x": -11,
      "y": 2,
      "z": 9,
      "name": "Soil_Dirt"
    },
    {
      "x": -11,
      "y": 3,
      "z": 9,
      "name": "Soil_Dirt"
    },
    {
      "x": -11,
      "y": 4,
      "z": 9,
      "name": "Soil_Dirt"
    },
    {
      "x": -11,
      "y": 5,
      "z": 9,
      "name": "Soil_Roots_Poisoned"
    },
    {
      "x": -11,
      "y": 6,
      "z": 9,
      "name": "Wood_Deadwood_Fence",
      "support": 15,
      "rotation": 1
    },
    {
      "x": -11,
      "y": 7,
      "z": 9,
      "name": "Wood_Deadwood_Fence",
      "support": 15,
      "rotation": 1
    },
    {
      "x": -11,
      "y": 8,
      "z": 9,
      "name": "Wood_Deadwood_Fence",
      "support": 15,
      "rotation": 1
    },
    {
      "x": -11,
      "y": 9,
      "z": 9,
      "name": "Barrier",
      "support": 15,
      "rotation": 2
    },
    {
      "x": -11,
      "y": 10,
      "z": 9,
      "name": "Barrier",
      "support": 15,
      "rotation": 2
    },
    {
      "x": -11,
      "y": 11,
      "z": 9,
      "name": "Barrier",
      "support": 15,
      "rotation": 2
    },
    {
      "x": -11,
      "y": 12,
      "z": 9,
      "name": "Barrier",
      "support": 15,
      "rotation": 2
    },
    {
      "x": -11,
      "y": 13,
      "z": 9,
      "name": "Barrier",
      "support": 15,
      "rotation": 2
    },
    {
      "x": -11,
      "y": 14,
      "z": 9,
      "name": "Barrier",
      "support": 15,
      "rotation": 2
    },
    {
      "x": -11,
      "y": 15,
      "z": 9,
      "name": "Barrier",
      "support": 15,
      "rotation": 2
    },
    {
      "x": -11,
      "y": 0,
      "z": 10,
      "name": "Soil_Dirt"
    },
    {
      "x": -11,
      "y": 1,
      "z": 10,
      "name": "Soil_Dirt"
    },
    {
      "x": -11,
      "y": 2,
      "z": 10,
      "name": "Soil_Dirt"
    },
    {
      "x": -11,
      "y": 3,
      "z": 10,
      "name": "Soil_Dirt"
    },
    {
      "x": -11,
      "y": 4,
      "z": 10,
      "name": "Soil_Dirt"
    },
    {
      "x": -11,
      "y": 5,
      "z": 10,
      "name": "Soil_Hive"
    },
    {
      "x": -11,
      "y": 6,
      "z": 10,
      "name": "Wood_Deadwood_Fence",
      "support": 15,
      "rotation": 1
    },
    {
      "x": -11,
      "y": 7,
      "z": 10,
      "name": "Wood_Deadwood_Fence",
      "support": 15,
      "rotation": 1
    },
    {
      "x": -11,
      "y": 8,
      "z": 10,
      "name": "Wood_Deadwood_Fence",
      "support": 15,
      "rotation": 1
    },
    {
      "x": -11,
      "y": 9,
      "z": 10,
      "name": "Barrier",
      "support": 15,
      "rotation": 2
    },
    {
      "x": -11,
      "y": 10,
      "z": 10,
      "name": "Barrier",
      "support": 15,
      "rotation": 2
    },
    {
      "x": -11,
      "y": 11,
      "z": 10,
      "name": "Barrier",
      "support": 15,
      "rotation": 2
    },
    {
      "x": -11,
      "y": 12,
      "z": 10,
      "name": "Barrier",
      "support": 15,
      "rotation": 2
    },
    {
      "x": -11,
      "y": 13,
      "z": 10,
      "name": "Barrier",
      "support": 15,
      "rotation": 2
    },
    {
      "x": -11,
      "y": 14,
      "z": 10,
      "name": "Barrier",
      "support": 15,
      "rotation": 2
    },
    {
      "x": -11,
      "y": 15,
      "z": 10,
      "name": "Barrier",
      "support": 15,
      "rotation": 2
    },
    {
      "x": -11,
      "y": 0,
      "z": 11,
      "name": "Soil_Dirt"
    },
    {
      "x": -11,
      "y": 1,
      "z": 11,
      "name": "Soil_Dirt"
    },
    {
      "x": -11,
      "y": 2,
      "z": 11,
      "name": "Soil_Dirt"
    },
    {
      "x": -11,
      "y": 3,
      "z": 11,
      "name": "Soil_Dirt"
    },
    {
      "x": -11,
      "y": 4,
      "z": 11,
      "name": "Soil_Dirt"
    },
    {
      "x": -11,
      "y": 5,
      "z": 11,
      "name": "Soil_Hive_Corrupted"
    },
    {
      "x": -11,
      "y": 6,
      "z": 11,
      "name": "Wood_Deadwood_Fence",
      "support": 15,
      "rotation": 1
    },
    {
      "x": -11,
      "y": 7,
      "z": 11,
      "name": "Wood_Deadwood_Fence",
      "support": 15,
      "rotation": 1
    },
    {
      "x": -11,
      "y": 8,
      "z": 11,
      "name": "Wood_Deadwood_Fence",
      "support": 15,
      "rotation": 1
    },
    {
      "x": -11,
      "y": 9,
      "z": 11,
      "name": "Barrier",
      "support": 15,
      "rotation": 2
    },
    {
      "x": -11,
      "y": 10,
      "z": 11,
      "name": "Barrier",
      "support": 15,
      "rotation": 2
    },
    {
      "x": -11,
      "y": 11,
      "z": 11,
      "name": "Barrier",
      "support": 15,
      "rotation": 2
    },
    {
      "x": -11,
      "y": 12,
      "z": 11,
      "name": "Barrier",
      "support": 15,
      "rotation": 2
    },
    {
      "x": -11,
      "y": 13,
      "z": 11,
      "name": "Barrier",
      "support": 15,
      "rotation": 2
    },
    {
      "x": -11,
      "y": 14,
      "z": 11,
      "name": "Barrier",
      "support": 15,
      "rotation": 2
    },
    {
      "x": -11,
      "y": 15,
      "z": 11,
      "name": "Barrier",
      "support": 15,
      "rotation": 2
    },
    {
      "x": -11,
      "y": 0,
      "z": 12,
      "name": "Soil_Dirt"
    },
    {
      "x": -11,
      "y": 1,
      "z": 12,
      "name": "Soil_Dirt"
    },
    {
      "x": -11,
      "y": 2,
      "z": 12,
      "name": "Soil_Dirt"
    },
    {
      "x": -11,
      "y": 3,
      "z": 12,
      "name": "Soil_Dirt"
    },
    {
      "x": -11,
      "y": 4,
      "z": 12,
      "name": "Soil_Dirt"
    },
    {
      "x": -11,
      "y": 5,
      "z": 12,
      "name": "Soil_Ash"
    },
    {
      "x": -11,
      "y": 6,
      "z": 12,
      "name": "*Wood_Deadwood_Fence_State_Definitions_Corner",
      "rotation": 2
    },
    {
      "x": -11,
      "y": 7,
      "z": 12,
      "name": "*Wood_Deadwood_Fence_State_Definitions_Corner",
      "rotation": 2
    },
    {
      "x": -11,
      "y": 8,
      "z": 12,
      "name": "*Wood_Deadwood_Fence_State_Definitions_Corner",
      "rotation": 2
    },
    {
      "x": -11,
      "y": 9,
      "z": 12,
      "name": "Barrier",
      "support": 15,
      "rotation": 3
    },
    {
      "x": -11,
      "y": 10,
      "z": 12,
      "name": "Barrier",
      "support": 15,
      "rotation": 3
    },
    {
      "x": -11,
      "y": 11,
      "z": 12,
      "name": "Barrier",
      "support": 15,
      "rotation": 3
    },
    {
      "x": -11,
      "y": 12,
      "z": 12,
      "name": "Barrier",
      "support": 15,
      "rotation": 3
    },
    {
      "x": -11,
      "y": 13,
      "z": 12,
      "name": "Barrier",
      "support": 15,
      "rotation": 3
    },
    {
      "x": -11,
      "y": 14,
      "z": 12,
      "name": "Barrier",
      "support": 15,
      "rotation": 3
    },
    {
      "x": -11,
      "y": 15,
      "z": 12,
      "name": "Barrier",
      "support": 15,
      "rotation": 3
    },
    {
      "x": -11,
      "y": 0,
      "z": 13,
      "name": "Soil_Dirt"
    },
    {
      "x": -11,
      "y": 1,
      "z": 13,
      "name": "Soil_Dirt"
    },
    {
      "x": -11,
      "y": 2,
      "z": 13,
      "name": "Soil_Dirt"
    },
    {
      "x": -11,
      "y": 3,
      "z": 13,
      "name": "Soil_Dirt"
    },
    {
      "x": -11,
      "y": 4,
      "z": 13,
      "name": "Soil_Dirt"
    },
    {
      "x": -11,
      "y": 5,
      "z": 13,
      "name": "Soil_Hive"
    },
    {
      "x": -11,
      "y": 0,
      "z": 14,
      "name": "Soil_Dirt"
    },
    {
      "x": -11,
      "y": 1,
      "z": 14,
      "name": "Soil_Dirt"
    },
    {
      "x": -11,
      "y": 2,
      "z": 14,
      "name": "Soil_Dirt"
    },
    {
      "x": -11,
      "y": 3,
      "z": 14,
      "name": "Soil_Dirt"
    },
    {
      "x": -11,
      "y": 4,
      "z": 14,
      "name": "Soil_Dirt"
    },
    {
      "x": -11,
      "y": 5,
      "z": 14,
      "name": "Soil_Hive"
    },
    {
      "x": -11,
      "y": 0,
      "z": 15,
      "name": "Soil_Dirt"
    },
    {
      "x": -11,
      "y": 1,
      "z": 15,
      "name": "Soil_Dirt"
    },
    {
      "x": -11,
      "y": 2,
      "z": 15,
      "name": "Soil_Dirt"
    },
    {
      "x": -11,
      "y": 3,
      "z": 15,
      "name": "Soil_Dirt"
    },
    {
      "x": -11,
      "y": 4,
      "z": 15,
      "name": "Soil_Dirt"
    },
    {
      "x": -11,
      "y": 5,
      "z": 15,
      "name": "Rock_Stone_Brick_Smooth"
    },
    {
      "x": -10,
      "y": 0,
      "z": -14,
      "name": "Soil_Dirt"
    },
    {
      "x": -10,
      "y": 1,
      "z": -14,
      "name": "Soil_Dirt"
    },
    {
      "x": -10,
      "y": 2,
      "z": -14,
      "name": "Soil_Dirt"
    },
    {
      "x": -10,
      "y": 3,
      "z": -14,
      "name": "Soil_Dirt"
    },
    {
      "x": -10,
      "y": 4,
      "z": -14,
      "name": "Soil_Dirt"
    },
    {
      "x": -10,
      "y": 5,
      "z": -14,
      "name": "Rock_Stone_Brick_Smooth"
    },
    {
      "x": -10,
      "y": 0,
      "z": -13,
      "name": "Soil_Dirt"
    },
    {
      "x": -10,
      "y": 1,
      "z": -13,
      "name": "Soil_Dirt"
    },
    {
      "x": -10,
      "y": 2,
      "z": -13,
      "name": "Soil_Dirt"
    },
    {
      "x": -10,
      "y": 3,
      "z": -13,
      "name": "Soil_Dirt"
    },
    {
      "x": -10,
      "y": 4,
      "z": -13,
      "name": "Soil_Dirt"
    },
    {
      "x": -10,
      "y": 5,
      "z": -13,
      "name": "Soil_Hive"
    },
    {
      "x": -10,
      "y": 0,
      "z": -12,
      "name": "Soil_Dirt"
    },
    {
      "x": -10,
      "y": 1,
      "z": -12,
      "name": "Soil_Dirt"
    },
    {
      "x": -10,
      "y": 2,
      "z": -12,
      "name": "Soil_Dirt"
    },
    {
      "x": -10,
      "y": 3,
      "z": -12,
      "name": "Soil_Dirt"
    },
    {
      "x": -10,
      "y": 4,
      "z": -12,
      "name": "Soil_Dirt"
    },
    {
      "x": -10,
      "y": 5,
      "z": -12,
      "name": "Soil_Ash"
    },
    {
      "x": -10,
      "y": 6,
      "z": -12,
      "name": "Plant_Bush_Dead",
      "support": 15
    },
    {
      "x": -10,
      "y": 7,
      "z": -12,
      "name": "Plant_Bush_Dead",
      "support": 15,
      "filler": 1024
    },
    {
      "x": -10,
      "y": 0,
      "z": -11,
      "name": "Soil_Dirt"
    },
    {
      "x": -10,
      "y": 1,
      "z": -11,
      "name": "Soil_Dirt"
    },
    {
      "x": -10,
      "y": 2,
      "z": -11,
      "name": "Soil_Dirt"
    },
    {
      "x": -10,
      "y": 3,
      "z": -11,
      "name": "Soil_Dirt"
    },
    {
      "x": -10,
      "y": 4,
      "z": -11,
      "name": "Soil_Dirt"
    },
    {
      "x": -10,
      "y": 5,
      "z": -11,
      "name": "Soil_Hive"
    },
    {
      "x": -10,
      "y": 6,
      "z": -11,
      "name": "Wood_Deadwood_Fence",
      "support": 15
    },
    {
      "x": -10,
      "y": 7,
      "z": -11,
      "name": "Wood_Deadwood_Fence",
      "support": 15
    },
    {
      "x": -10,
      "y": 8,
      "z": -11,
      "name": "Wood_Deadwood_Fence",
      "support": 15
    },
    {
      "x": -10,
      "y": 9,
      "z": -11,
      "name": "Barrier",
      "support": 15,
      "rotation": 1
    },
    {
      "x": -10,
      "y": 10,
      "z": -11,
      "name": "Barrier",
      "support": 15,
      "rotation": 1
    },
    {
      "x": -10,
      "y": 11,
      "z": -11,
      "name": "Barrier",
      "support": 15,
      "rotation": 1
    },
    {
      "x": -10,
      "y": 12,
      "z": -11,
      "name": "Barrier",
      "support": 15,
      "rotation": 1
    },
    {
      "x": -10,
      "y": 13,
      "z": -11,
      "name": "Barrier",
      "support": 15,
      "rotation": 1
    },
    {
      "x": -10,
      "y": 14,
      "z": -11,
      "name": "Barrier",
      "support": 15,
      "rotation": 1
    },
    {
      "x": -10,
      "y": 15,
      "z": -11,
      "name": "Barrier",
      "support": 15,
      "rotation": 1
    },
    {
      "x": -10,
      "y": 0,
      "z": -10,
      "name": "Soil_Dirt"
    },
    {
      "x": -10,
      "y": 1,
      "z": -10,
      "name": "Soil_Dirt"
    },
    {
      "x": -10,
      "y": 2,
      "z": -10,
      "name": "Soil_Dirt"
    },
    {
      "x": -10,
      "y": 3,
      "z": -10,
      "name": "Soil_Dirt"
    },
    {
      "x": -10,
      "y": 4,
      "z": -10,
      "name": "Soil_Dirt"
    },
    {
      "x": -10,
      "y": 5,
      "z": -10,
      "name": "Soil_Roots_Poisoned"
    },
    {
      "x": -10,
      "y": 0,
      "z": -9,
      "name": "Soil_Dirt"
    },
    {
      "x": -10,
      "y": 1,
      "z": -9,
      "name": "Soil_Dirt"
    },
    {
      "x": -10,
      "y": 2,
      "z": -9,
      "name": "Soil_Dirt"
    },
    {
      "x": -10,
      "y": 3,
      "z": -9,
      "name": "Soil_Dirt"
    },
    {
      "x": -10,
      "y": 4,
      "z": -9,
      "name": "Soil_Dirt"
    },
    {
      "x": -10,
      "y": 5,
      "z": -9,
      "name": "Soil_Roots_Poisoned"
    },
    {
      "x": -10,
      "y": 6,
      "z": -9,
      "name": "*Furniture_Temple_Dark_Chest_Small_State_Definitions_CloseWindow",
      "components": {
        "Components": {
          "PlacedByInteraction": {
            "WhoPlacedUuid": {
              "$binary": "v7RyWIT/TYKnXA2XcxdQtw==",
              "$type": "04"
            }
          },
          "ItemContainerBlock": {
            "ItemContainer": {
              "Capacity": 18,
              "Items": {
                "4": {
                  "Id": "Aetherhaven_Heartberry",
                  "Quantity": 1,
                  "Durability": 0.0,
                  "MaxDurability": 0.0,
                  "OverrideDroppedItemAnimation": false
                }
              }
            },
            "Capacity": 18
          }
        }
      },
      "support": 15,
      "rotation": 1
    },
    {
      "x": -10,
      "y": 0,
      "z": -8,
      "name": "Soil_Dirt"
    },
    {
      "x": -10,
      "y": 1,
      "z": -8,
      "name": "Soil_Dirt"
    },
    {
      "x": -10,
      "y": 2,
      "z": -8,
      "name": "Soil_Dirt"
    },
    {
      "x": -10,
      "y": 3,
      "z": -8,
      "name": "Soil_Dirt"
    },
    {
      "x": -10,
      "y": 4,
      "z": -8,
      "name": "Soil_Dirt"
    },
    {
      "x": -10,
      "y": 5,
      "z": -8,
      "name": "Soil_Hive"
    },
    {
      "x": -10,
      "y": 0,
      "z": -7,
      "name": "Soil_Dirt"
    },
    {
      "x": -10,
      "y": 1,
      "z": -7,
      "name": "Soil_Dirt"
    },
    {
      "x": -10,
      "y": 2,
      "z": -7,
      "name": "Soil_Dirt"
    },
    {
      "x": -10,
      "y": 3,
      "z": -7,
      "name": "Soil_Dirt"
    },
    {
      "x": -10,
      "y": 4,
      "z": -7,
      "name": "Soil_Dirt"
    },
    {
      "x": -10,
      "y": 5,
      "z": -7,
      "name": "Soil_Hive"
