{"version":8,"blockIdVersion":11,"anchorX":0,"anchorY":0,"anchorZ":0,"blocks":[{"x":-14,"y":0,"z":-14,"name":"Soil_Dirt"},{"x":-14,"y":1,"z":-14,"name":"Soil_Dirt"},{"x":-14,"y":2,"z":-14,"name":"Soil_Dirt"},{"x":-14,"y":3,"z":-14,"name":"Soil_Dirt"},{"x":-14,"y":4,"z":-14,"name":"Soil_Dirt"},{"x":-14,"y":5,"z":-14,"name":"Rock_Stone_Brick_Smooth"},{"x":-14,"y":0,"z":-13,"name":"Soil_Dirt"},{"x":-14,"y":1,"z":-13,"name":"Soil_Dirt"},{"x":-14,"y":2,"z":-13,"name":"Soil_Dirt"},{"x":-14,"y":3,"z":-13,"name":"Soil_Dirt"},{"x":-14,"y":4,"z":-13,"name":"Soil_Dirt"},{"x":-14,"y":5,"z":-13,"name":"Rock_Stone_Brick_Smooth"},{"x":-14,"y":0,"z":-12,"name":"Soil_Dirt"},{"x":-14,"y":1,"z":-12,"name":"Soil_Dirt"},{"x":-14,"y":2,"z":-12,"name":"Soil_Dirt"},{"x":-14,"y":3,"z":-12,"name":"Soil_Dirt"},{"x":-14,"y":4,"z":-12,"name":"Soil_Dirt"},{"x":-14,"y":5,"z":-12,"name":"Rock_Stone_Brick_Smooth"},{"x":-14,"y":0,"z":-11,"name":"Soil_Dirt"},{"x":-14,"y":1,"z":-11,"name":"Soil_Dirt"},{"x":-14,"y":2,"z":-11,"name":"Soil_Dirt"},{"x":-14,"y":3,"z":-11,"name":"Soil_Dirt"},{"x":-14,"y":4,"z":-11,"name":"Soil_Dirt"},{"x":-14,"y":5,"z":-11,"name":"Rock_Stone_Brick_Smooth"},{"x":-14,"y":0,"z":-10,"name":"Soil_Dirt"},{"x":-14,"y":1,"z":-10,"name":"Soil_Dirt"},{"x":-14,"y":2,"z":-10,"name":"Soil_Dirt"},{"x":-14,"y":3,"z":-10,"name":"Soil_Dirt"},{"x":-14,"y":4,"z":-10,"name":"Soil_Dirt"},{"x":-14,"y":5,"z":-10,"name":"Rock_Stone_Brick_Smooth"},{"x":-14,"y":0,"z":-9,"name":"Soil_Dirt"},{"x":-14,"y":1,"z":-9,"name":"Soil_Dirt"},{"x":-14,"y":2,"z":-9,"name":"Soil_Dirt"},{"x":-14,"y":3,"z":-9,"name":"Soil_Dirt"},{"x":-14,"y":4,"z":-9,"name":"Soil_Dirt"},{"x":-14,"y":5,"z":-9,"name":"Rock_Stone_Brick_Smooth"},{"x":-14,"y":0,"z":-8,"name":"Soil_Dirt"},{"x":-14,"y":1,"z":-8,"name":"Soil_Dirt"},{"x":-14,"y":2,"z":-8,"name":"Soil_Dirt"},{"x":-14,"y":3,"z":-8,"name":"Soil_Dirt"},{"x":-14,"y":4,"z":-8,"name":"Soil_Dirt"},{"x":-14,"y":5,"z":-8,"name":"Rock_Stone_Brick_Smooth"},{"x":-14,"y":0,"z":-7,"name":"Soil_Dirt"},{"x":-14,"y":1,"z":-7,"name":"Soil_Dirt"},{"x":-14,"y":2,"z":-7,"name":"Soil_Dirt"},{"x":-14,"y":3,"z":-7,"name":"Soil_Dirt"},{"x":-14,"y":4,"z":-7,"name":"Soil_Dirt"},{"x":-14,"y":5,"z":-7,"name":"Rock_Stone_Brick_Smooth"},{"x":-14,"y":0,"z":-6,"name":"Soil_Dirt"},{"x":-14,"y":1,"z":-6,"name":"Soil_Dirt"},{"x":-14,"y":2,"z":-6,"name":"Soil_Dirt"},{"x":-14,"y":3,"z":-6,"name":"Soil_Dirt"},{"x":-14,"y":4,"z":-6,"name":"Soil_Dirt"},{"x":-14,"y":5,"z":-6,"name":"Rock_Stone_Brick_Smooth"},{"x":-14,"y":0,"z":-5,"name":"Soil_Dirt"},{"x":-14,"y":1,"z":-5,"name":"Soil_Dirt"},{"x":-14,"y":2,"z":-5,"name":"Soil_Dirt"},{"x":-14,"y":3,"z":-5,"name":"Soil_Dirt"},{"x":-14,"y":4,"z":-5,"name":"Soil_Dirt"},{"x":-14,"y":5,"z":-5,"name":"Rock_Stone_Brick_Smooth"},{"x":-14,"y":0,"z":-4,"name":"Soil_Dirt"},{"x":-14,"y":1,"z":-4,"name":"Soil_Dirt"},{"x":-14,"y":2,"z":-4,"name":"Soil_Dirt"},{"x":-14,"y":3,"z":-4,"name":"Soil_Dirt"},{"x":-14,"y":4,"z":-4,"name":"Soil_Dirt"},{"x":-14,"y":5,"z":-4,"name":"Rock_Stone_Brick_Smooth"},{"x":-14,"y":0,"z":-3,"name":"Soil_Dirt"},{"x":-14,"y":1,"z":-3,"name":"Soil_Dirt"},{"x":-14,"y":2,"z":-3,"name":"Soil_Dirt"},{"x":-14,"y":3,"z":-3,"name":"Soil_Dirt"},{"x":-14,"y":4,"z":-3,"name":"Soil_Dirt"},{"x":-14,"y":5,"z":-3,"name":"Rock_Stone_Brick_Smooth"},{"x":-14,"y":0,"z":-2,"name":"Soil_Dirt"},{"x":-14,"y":1,"z":-2,"name":"Soil_Dirt"},{"x":-14,"y":2,"z":-2,"name":"Soil_Dirt"},{"x":-14,"y":3,"z":-2,"name":"Soil_Dirt"},{"x":-14,"y":4,"z":-2,"name":"Soil_Dirt"},{"x":-14,"y":5,"z":-2,"name":"Rock_Stone_Brick_Smooth"},{"x":-14,"y":0,"z":-1,"name":"Soil_Dirt"},{"x":-14,"y":1,"z":-1,"name":"Soil_Dirt"},{"x":-14,"y":2,"z":-1,"name":"Soil_Dirt"},{"x":-14,"y":3,"z":-1,"name":"Soil_Dirt"},{"x":-14,"y":4,"z":-1,"name":"Soil_Dirt"},{"x":-14,"y":5,"z":-1,"name":"Rock_Stone_Brick_Smooth"},{"x":-14,"y":0,"z":0,"name":"Soil_Dirt"},{"x":-14,"y":1,"z":0,"name":"Soil_Dirt"},{"x":-14,"y":2,"z":0,"name":"Soil_Dirt"},{"x":-14,"y":3,"z":0,"name":"Soil_Dirt"},{"x":-14,"y":4,"z":0,"name":"Soil_Dirt"},{"x":-14,"y":5,"z":0,"name":"Rock_Stone_Brick_Smooth"},{"x":-14,"y":0,"z":1,"name":"Soil_Dirt"},{"x":-14,"y":1,"z":1,"name":"Soil_Dirt"},{"x":-14,"y":2,"z":1,"name":"Soil_Dirt"},{"x":-14,"y":3,"z":1,"name":"Soil_Dirt"},{"x":-14,"y":4,"z":1,"name":"Soil_Dirt"},{"x":-14,"y":5,"z":1,"name":"Rock_Stone_Brick_Smooth"},{"x":-14,"y":0,"z":2,"name":"Soil_Dirt"},{"x":-14,"y":1,"z":2,"name":"Soil_Dirt"},{"x":-14,"y":2,"z":2,"name":"Soil_Dirt"},{"x":-14,"y":3,"z":2,"name":"Soil_Dirt"},{"x":-14,"y":4,"z":2,"name":"Soil_Dirt"},{"x":-14,"y":5,"z":2,"name":"Rock_Stone_Brick_Smooth"},{"x":-14,"y":0,"z":3,"name":"Soil_Dirt"},{"x":-14,"y":1,"z":3,"name":"Soil_Dirt"},{"x":-14,"y":2,"z":3,"name":"Soil_Dirt"},{"x":-14,"y":3,"z":3,"name":"Soil_Dirt"},{"x":-14,"y":4,"z":3,"name":"Soil_Dirt"},{"x":-14,"y":5,"z":3,"name":"Rock_Stone_Brick_Smooth"},{"x":-14,"y":0,"z":4,"name":"Soil_Dirt"},{"x":-14,"y":1,"z":4,"name":"Soil_Dirt"},{"x":-14,"y":2,"z":4,"name":"Soil_Dirt"},{"x":-14,"y":3,"z":4,"name":"Soil_Dirt"},{"x":-14,"y":4,"z":4,"name":"Soil_Dirt"},{"x":-14,"y":5,"z":4,"name":"Rock_Stone_Brick_Smooth"},{"x":-14,"y":0,"z":5,"name":"Soil_Dirt"},{"x":-14,"y":1,"z":5,"name":"Soil_Dirt"},{"x":-14,"y":2,"z":5,"name":"Soil_Dirt"},{"x":-14,"y":3,"z":5,"name":"Soil_Dirt"},{"x":-14,"y":4,"z":5,"name":"Soil_Dirt"},{"x":-14,"y":5,"z":5,"name":"Rock_Stone_Brick_Smooth"},{"x":-14,"y":0,"z":6,"name":"Soil_Dirt"},{"x":-14,"y":1,"z":6,"name":"Soil_Dirt"},{"x":-14,"y":2,"z":6,"name":"Soil_Dirt"},{"x":-14,"y":3,"z":6,"name":"Soil_Dirt"},{"x":-14,"y":4,"z":6,"name":"Soil_Dirt"},{"x":-14,"y":5,"z":6,"name":"Rock_Stone_Brick_Smooth"},{"x":-14,"y":0,"z":7,"name":"Soil_Dirt"},{"x":-14,"y":1,"z":7,"name":"Soil_Dirt"},{"x":-14,"y":2,"z":7,"name":"Soil_Dirt"},{"x":-14,"y":3,"z":7,"name":"Soil_Dirt"},{"x":-14,"y":4,"z":7,"name":"Soil_Dirt"},{"x":-14,"y":5,"z":7,"name":"Rock_Stone_Brick_Smooth"},{"x":-14,"y":0,"z":8,"name":"Soil_Dirt"},{"x":-14,"y":1,"z":8,"name":"Soil_Dirt"},{"x":-14,"y":2,"z":8,"name":"Soil_Dirt"},{"x":-14,"y":3,"z":8,"name":"Soil_Dirt"},{"x":-14,"y":4,"z":8,"name":"Soil_Dirt"},{"x":-14,"y":5,"z":8,"name":"Rock_Stone_Brick_Smooth"},{"x":-14,"y":0,"z":9,"name":"Soil_Dirt"},{"x":-14,"y":1,"z":9,"name":"Soil_Dirt"},{"x":-14,"y":2,"z":9,"name":"Soil_Dirt"},{"x":-14,"y":3,"z":9,"name":"Soil_Dirt"},{"x":-14,"y":4,"z":9,"name":"Soil_Dirt"},{"x":-14,"y":5,"z":9,"name":"Rock_Stone_Brick_Smooth"},{"x":-14,"y":0,"z":10,"name":"Soil_Dirt"},{"x":-14,"y":1,"z":10,"name":"Soil_Dirt"},{"x":-14,"y":2,"z":10,"name":"Soil_Dirt"},{"x":-14,"y":3,"z":10,"name":"Soil_Dirt"},{"x":-14,"y":4,"z":10,"name":"Soil_Dirt"},{"x":-14,"y":5,"z":10,"name":"Rock_Stone_Brick_Smooth"},{"x":-14,"y":0,"z":11,"name":"Soil_Dirt"},{"x":-14,"y":1,"z":11,"name":"Soil_Dirt"},{"x":-14,"y":2,"z":11,"name":"Soil_Dirt"},{"x":-14,"y":3,"z":11,"name":"Soil_Dirt"},{"x":-14,"y":4,"z":11,"name":"Soil_Dirt"},{"x":-14,"y":5,"z":11,"name":"Rock_Stone_Brick_Smooth"},{"x":-14,"y":0,"z":12,"name":"Soil_Dirt"},{"x":-14,"y":1,"z":12,"name":"Soil_Dirt"},{"x":-14,"y":2,"z":12,"name":"Soil_Dirt"},{"x":-14,"y":3,"z":12,"name":"Soil_Dirt"},{"x":-14,"y":4,"z":12,"name":"Soil_Dirt"},{"x":-14,"y":5,"z":12,"name":"Rock_Stone_Brick_Smooth"},{"x":-14,"y":0,"z":13,"name":"Soil_Dirt"},{"x":-14,"y":1,"z":13,"name":"Soil_Dirt"},{"x":-14,"y":2,"z":13,"name":"Soil_Dirt"},{"x":-14,"y":3,"z":13,"name":"Soil_Dirt"},{"x":-14,"y":4,"z":13,"name":"Soil_Dirt"},{"x":-14,"y":5,"z":13,"name":"Rock_Stone_Brick_Smooth"},{"x":-14,"y":0,"z":14,"name":"Soil_Dirt"},{"x":-14,"y":1,"z":14,"name":"Soil_Dirt"},{"x":-14,"y":2,"z":14,"name":"Soil_Dirt"},{"x":-14,"y":3,"z":14,"name":"Soil_Dirt"},{"x":-14,"y":4,"z":14,"name":"Soil_Dirt"},{"x":-14,"y":5,"z":14,"name":"Rock_Stone_Brick_Smooth"},{"x":-14,"y":0,"z":15,"name":"Soil_Dirt"},{"x":-14,"y":1,"z":15,"name":"Soil_Dirt"},{"x":-14,"y":2,"z":15,"name":"Soil_Dirt"},{"x":-14,"y":3,"z":15,"name":"Soil_Dirt"},{"x":-14,"y":4,"z":15,"name":"Soil_Dirt"},{"x":-14,"y":5,"z":15,"name":"Rock_Stone_Brick_Smooth"},{"x":-13,"y":0,"z":-14,"name":"Soil_Dirt"},{"x":-13,"y":1,"z":-14,"name":"Soil_Dirt"},{"x":-13,"y":2,"z":-14,"name":"Soil_Dirt"},{"x":-13,"y":3,"z":-14,"name":"Soil_Dirt"},{"x":-13,"y":4,"z":-14,"name":"Soil_Dirt"},{"x":-13,"y":5,"z":-14,"name":"Rock_Stone_Brick_Smooth"},{"x":-13,"y":0,"z":-13,"name":"Soil_Dirt"},{"x":-13,"y":1,"z":-13,"name":"Soil_Dirt"},{"x":-13,"y":2,"z":-13,"name":"Soil_Dirt"},{"x":-13,"y":3,"z":-13,"name":"Soil_Dirt"},{"x":-13,"y":4,"z":-13,"name":"Soil_Dirt"},{"x":-13,"y":5,"z":-13,"name":"Soil_Snow"},{"x":-13,"y":0,"z":-12,"name":"Soil_Dirt"},{"x":-13,"y":1,"z":-12,"name":"Soil_Dirt"},{"x":-13,"y":2,"z":-12,"name":"Soil_Dirt"},{"x":-13,"y":3,"z":-12,"name":"Soil_Dirt"},{"x":-13,"y":4,"z":-12,"name":"Soil_Dirt"},{"x":-13,"y":5,"z":-12,"name":"Soil_Snow"},{"x":-13,"y":0,"z":-11,"name":"Soil_Dirt"},{"x":-13,"y":1,"z":-11,"name":"Soil_Dirt"},{"x":-13,"y":2,"z":-11,"name":"Soil_Dirt"},{"x":-13,"y":3,"z":-11,"name":"Soil_Dirt"},{"x":-13,"y":4,"z":-11,"name":"Soil_Dirt"},{"x":-13,"y":5,"z":-11,"name":"Soil_Snow"},{"x":-13,"y":0,"z":-10,"name":"Soil_Dirt"},{"x":-13,"y":1,"z":-10,"name":"Soil_Dirt"},{"x":-13,"y":2,"z":-10,"name":"Soil_Dirt"},{"x":-13,"y":3,"z":-10,"name":"Soil_Dirt"},{"x":-13,"y":4,"z":-10,"name":"Soil_Dirt"},{"x":-13,"y":5,"z":-10,"name":"Soil_Snow"},{"x":-13,"y":0,"z":-9,"name":"Soil_Dirt"},{"x":-13,"y":1,"z":-9,"name":"Soil_Dirt"},{"x":-13,"y":2,"z":-9,"name":"Soil_Dirt"},{"x":-13,"y":3,"z":-9,"name":"Soil_Dirt"},{"x":-13,"y":4,"z":-9,"name":"Soil_Dirt"},{"x":-13,"y":5,"z":-9,"name":"Soil_Snow"},{"x":-13,"y":0,"z":-8,"name":"Soil_Dirt"},{"x":-13,"y":1,"z":-8,"name":"Soil_Dirt"},{"x":-13,"y":2,"z":-8,"name":"Soil_Dirt"},{"x":-13,"y":3,"z":-8,"name":"Soil_Dirt"},{"x":-13,"y":4,"z":-8,"name":"Soil_Dirt"},{"x":-13,"y":5,"z":-8,"name":"Soil_Snow"},{"x":-13,"y":0,"z":-7,"name":"Soil_Dirt"},{"x":-13,"y":1,"z":-7,"name":"Soil_Dirt"},{"x":-13,"y":2,"z":-7,"name":"Soil_Dirt"},{"x":-13,"y":3,"z":-7,"name":"Soil_Dirt"},{"x":-13,"y":4,"z":-7,"name":"Soil_Dirt"},{"x":-13,"y":5,"z":-7,"name":"Soil_Snow"},{"x":-13,"y":0,"z":-6,"name":"Soil_Dirt"},{"x":-13,"y":1,"z":-6,"name":"Soil_Dirt"},{"x":-13,"y":2,"z":-6,"name":"Soil_Dirt"},{"x":-13,"y":3,"z":-6,"name":"Soil_Dirt"},{"x":-13,"y":4,"z":-6,"name":"Soil_Dirt"},{"x":-13,"y":5,"z":-6,"name":"Soil_Snow"},{"x":-13,"y":0,"z":-5,"name":"Soil_Dirt"},{"x":-13,"y":1,"z":-5,"name":"Soil_Dirt"},{"x":-13,"y":2,"z":-5,"name":"Soil_Dirt"},{"x":-13,"y":3,"z":-5,"name":"Soil_Dirt"},{"x":-13,"y":4,"z":-5,"name":"Soil_Dirt"},{"x":-13,"y":5,"z":-5,"name":"Soil_Snow"},{"x":-13,"y":0,"z":-4,"name":"Soil_Dirt"},{"x":-13,"y":1,"z":-4,"name":"Soil_Dirt"},{"x":-13,"y":2,"z":-4,"name":"Soil_Dirt"},{"x":-13,"y":3,"z":-4,"name":"Soil_Dirt"},{"x":-13,"y":4,"z":-4,"name":"Soil_Dirt"},{"x":-13,"y":5,"z":-4,"name":"Soil_Snow"},{"x":-13,"y":0,"z":-3,"name":"Soil_Dirt"},{"x":-13,"y":1,"z":-3,"name":"Soil_Dirt"},{"x":-13,"y":2,"z":-3,"name":"Soil_Dirt"},{"x":-13,"y":3,"z":-3,"name":"Soil_Dirt"},{"x":-13,"y":4,"z":-3,"name":"Soil_Dirt"},{"x":-13,"y":5,"z":-3,"name":"Soil_Snow"},{"x":-13,"y":0,"z":-2,"name":"Soil_Dirt"},{"x":-13,"y":1,"z":-2,"name":"Soil_Dirt"},{"x":-13,"y":2,"z":-2,"name":"Soil_Dirt"},{"x":-13,"y":3,"z":-2,"name":"Soil_Dirt"},{"x":-13,"y":4,"z":-2,"name":"Soil_Dirt"},{"x":-13,"y":5,"z":-2,"name":"Soil_Snow"},{"x":-13,"y":0,"z":-1,"name":"Soil_Dirt"},{"x":-13,"y":1,"z":-1,"name":"Soil_Dirt"},{"x":-13,"y":2,"z":-1,"name":"Soil_Dirt"},{"x":-13,"y":3,"z":-1,"name":"Soil_Dirt"},{"x":-13,"y":4,"z":-1,"name":"Soil_Dirt"},{"x":-13,"y":5,"z":-1,"name":"Soil_Snow"},{"x":-13,"y":0,"z":0,"name":"Soil_Dirt"},{"x":-13,"y":1,"z":0,"name":"Soil_Dirt"},{"x":-13,"y":2,"z":0,"name":"Soil_Dirt"},{"x":-13,"y":3,"z":0,"name":"Soil_Dirt"},{"x":-13,"y":4,"z":0,"name":"Soil_Dirt"},{"x":-13,"y":5,"z":0,"name":"Rock_Calcite_Brick","support":15},{"x":-13,"y":0,"z":1,"name":"Soil_Dirt"},{"x":-13,"y":1,"z":1,"name":"Soil_Dirt"},{"x":-13,"y":2,"z":1,"name":"Soil_Dirt"},{"x":-13,"y":3,"z":1,"name":"Soil_Dirt"},{"x":-13,"y":4,"z":1,"name":"Soil_Dirt"},{"x":-13,"y":5,"z":1,"name":"Rock_Calcite_Brick","support":15},{"x":-13,"y":0,"z":2,"name":"Soil_Dirt"},{"x":-13,"y":1,"z":2,"name":"Soil_Dirt"},{"x":-13,"y":2,"z":2,"name":"Soil_Dirt"},{"x":-13,"y":3,"z":2,"name":"Soil_Dirt"},{"x":-13,"y":4,"z":2,"name":"Soil_Dirt"},{"x":-13,"y":5,"z":2,"name":"Soil_Snow"},{"x":-13,"y":0,"z":3,"name":"Soil_Dirt"},{"x":-13,"y":1,"z":3,"name":"Soil_Dirt"},{"x":-13,"y":2,"z":3,"name":"Soil_Dirt"},{"x":-13,"y":3,"z":3,"name":"Soil_Dirt"},{"x":-13,"y":4,"z":3,"name":"Soil_Dirt"},{"x":-13,"y":5,"z":3,"name":"Soil_Snow"},{"x":-13,"y":0,"z":4,"name":"Soil_Dirt"},{"x":-13,"y":1,"z":4,"name":"Soil_Dirt"},{"x":-13,"y":2,"z":4,"name":"Soil_Dirt"},{"x":-13,"y":3,"z":4,"name":"Soil_Dirt"},{"x":-13,"y":4,"z":4,"name":"Soil_Dirt"},{"x":-13,"y":5,"z":4,"name":"Soil_Snow"},{"x":-13,"y":0,"z":5,"name":"Soil_Dirt"},{"x":-13,"y":1,"z":5,"name":"Soil_Dirt"},{"x":-13,"y":2,"z":5,"name":"Soil_Dirt"},{"x":-13,"y":3,"z":5,"name":"Soil_Dirt"},{"x":-13,"y":4,"z":5,"name":"Soil_Dirt"},{"x":-13,"y":5,"z":5,"name":"Soil_Snow"},{"x":-13,"y":0,"z":6,"name":"Soil_Dirt"},{"x":-13,"y":1,"z":6,"name":"Soil_Dirt"},{"x":-13,"y":2,"z":6,"name":"Soil_Dirt"},{"x":-13,"y":3,"z":6,"name":"Soil_Dirt"},{"x":-13,"y":4,"z":6,"name":"Soil_Dirt"},{"x":-13,"y":5,"z":6,"name":"Soil_Snow"},{"x":-13,"y":0,"z":7,"name":"Soil_Dirt"},{"x":-13,"y":1,"z":7,"name":"Soil_Dirt"},{"x":-13,"y":2,"z":7,"name":"Soil_Dirt"},{"x":-13,"y":3,"z":7,"name":"Soil_Dirt"},{"x":-13,"y":4,"z":7,"name":"Soil_Dirt"},{"x":-13,"y":5,"z":7,"name":"Soil_Snow"},{"x":-13,"y":0,"z":8,"name":"Soil_Dirt"},{"x":-13,"y":1,"z":8,"name":"Soil_Dirt"},{"x":-13,"y":2,"z":8,"name":"Soil_Dirt"},{"x":-13,"y":3,"z":8,"name":"Soil_Dirt"},{"x":-13,"y":4,"z":8,"name":"Soil_Dirt"},{"x":-13,"y":5,"z":8,"name":"Soil_Snow"},{"x":-13,"y":0,"z":9,"name":"Soil_Dirt"},{"x":-13,"y":1,"z":9,"name":"Soil_Dirt"},{"x":-13,"y":2,"z":9,"name":"Soil_Dirt"},{"x":-13,"y":3,"z":9,"name":"Soil_Dirt"},{"x":-13,"y":4,"z":9,"name":"Soil_Dirt"},{"x":-13,"y":5,"z":9,"name":"Soil_Snow"},{"x":-13,"y":0,"z":10,"name":"Soil_Dirt"},{"x":-13,"y":1,"z":10,"name":"Soil_Dirt"},{"x":-13,"y":2,"z":10,"name":"Soil_Dirt"},{"x":-13,"y":3,"z":10,"name":"Soil_Dirt"},{"x":-13,"y":4,"z":10,"name":"Soil_Dirt"},{"x":-13,"y":5,"z":10,"name":"Soil_Snow"},{"x":-13,"y":0,"z":11,"name":"Soil_Dirt"},{"x":-13,"y":1,"z":11,"name":"Soil_Dirt"},{"x":-13,"y":2,"z":11,"name":"Soil_Dirt"},{"x":-13,"y":3,"z":11,"name":"Soil_Dirt"},{"x":-13,"y":4,"z":11,"name":"Soil_Dirt"},{"x":-13,"y":5,"z":11,"name":"Soil_Snow"},{"x":-13,"y":0,"z":12,"name":"Soil_Dirt"},{"x":-13,"y":1,"z":12,"name":"Soil_Dirt"},{"x":-13,"y":2,"z":12,"name":"Soil_Dirt"},{"x":-13,"y":3,"z":12,"name":"Soil_Dirt"},{"x":-13,"y":4,"z":12,"name":"Soil_Dirt"},{"x":-13,"y":5,"z":12,"name":"Soil_Snow"},{"x":-13,"y":0,"z":13,"name":"Soil_Dirt"},{"x":-13,"y":1,"z":13,"name":"Soil_Dirt"},{"x":-13,"y":2,"z":13,"name":"Soil_Dirt"},{"x":-13,"y":3,"z":13,"name":"Soil_Dirt"},{"x":-13,"y":4,"z":13,"name":"Soil_Dirt"},{"x":-13,"y":5,"z":13,"name":"Soil_Snow"},{"x":-13,"y":0,"z":14,"name":"Soil_Dirt"},{"x":-13,"y":1,"z":14,"name":"Soil_Dirt"},{"x":-13,"y":2,"z":14,"name":"Soil_Dirt"},{"x":-13,"y":3,"z":14,"name":"Soil_Dirt"},{"x":-13,"y":4,"z":14,"name":"Soil_Dirt"},{"x":-13,"y":5,"z":14,"name":"Soil_Snow"},{"x":-13,"y":0,"z":15,"name":"Soil_Dirt"},{"x":-13,"y":1,"z":15,"name":"Soil_Dirt"},{"x":-13,"y":2,"z":15,"name":"Soil_Dirt"},{"x":-13,"y":3,"z":15,"name":"Soil_Dirt"},{"x":-13,"y":4,"z":15,"name":"Soil_Dirt"},{"x":-13,"y":5,"z":15,"name":"Rock_Stone_Brick_Smooth"},{"x":-12,"y":0,"z":-14,"name":"Soil_Dirt"},{"x":-12,"y":1,"z":-14,"name":"Soil_Dirt"},{"x":-12,"y":2,"z":-14,"name":"Soil_Dirt"},{"x":-12,"y":3,"z":-14,"name":"Soil_Dirt"},{"x":-12,"y":4,"z":-14,"name":"Soil_Dirt"},{"x":-12,"y":5,"z":-14,"name":"Rock_Stone_Brick_Smooth"},{"x":-12,"y":0,"z":-13,"name":"Soil_Dirt"},{"x":-12,"y":1,"z":-13,"name":"Soil_Dirt"},{"x":-12,"y":2,"z":-13,"name":"Soil_Dirt"},{"x":-12,"y":3,"z":-13,"name":"Soil_Dirt"},{"x":-12,"y":4,"z":-13,"name":"Soil_Dirt"},{"x":-12,"y":5,"z":-13,"name":"Soil_Snow"},{"x":-12,"y":0,"z":-12,"name":"Soil_Dirt"},{"x":-12,"y":1,"z":-12,"name":"Soil_Dirt"},{"x":-12,"y":2,"z":-12,"name":"Soil_Dirt"},{"x":-12,"y":3,"z":-12,"name":"Soil_Dirt"},{"x":-12,"y":4,"z":-12,"name":"Soil_Dirt"},{"x":-12,"y":5,"z":-12,"name":"Soil_Snow"},{"x":-12,"y":0,"z":-11,"name":"Soil_Dirt"},{"x":-12,"y":1,"z":-11,"name":"Soil_Dirt"},{"x":-12,"y":2,"z":-11,"name":"Soil_Dirt"},{"x":-12,"y":3,"z":-11,"name":"Soil_Dirt"},{"x":-12,"y":4,"z":-11,"name":"Soil_Dirt"},{"x":-12,"y":5,"z":-11,"name":"Soil_Snow"},{"x":-12,"y":6,"z":-11,"name":"Soil_Snow_Half","support":15},{"x":-12,"y":8,"z":-11,"name":"Winter_Holiday_Wreath","support":15,"rotation":3},{"x":-12,"y":11,"z":-11,"name":"WinterHoliday_Garland","support":15,"rotation":3},{"x":-12,"y":0,"z":-10,"name":"Soil_Dirt"},{"x":-12,"y":1,"z":-10,"name":"Soil_Dirt"},{"x":-12,"y":2,"z":-10,"name":"Soil_Dirt"},{"x":-12,"y":3,"z":-10,"name":"Soil_Dirt"},{"x":-12,"y":4,"z":-10,"name":"Soil_Dirt"},{"x":-12,"y":5,"z":-10,"name":"Soil_Snow"},{"x":-12,"y":6,"z":-10,"name":"Soil_Snow_Half","support":15},{"x":-12,"y":11,"z":-10,"name":"WinterHoliday_Garland","support":15,"rotation":3},{"x":-12,"y":0,"z":-9,"name":"Soil_Dirt"},{"x":-12,"y":1,"z":-9,"name":"Soil_Dirt"},{"x":-12,"y":2,"z":-9,"name":"Soil_Dirt"},{"x":-12,"y":3,"z":-9,"name":"Soil_Dirt"},{"x":-12,"y":4,"z":-9,"name":"Soil_Dirt"},{"x":-12,"y":5,"z":-9,"name":"Soil_Snow"},{"x":-12,"y":11,"z":-9,"name":"WinterHoliday_Garland","support":15,"rotation":3},{"x":-12,"y":0,"z":-8,"name":"Soil_Dirt"},{"x":-12,"y":1,"z":-8,"name":"Soil_Dirt"},{"x":-12,"y":2,"z":-8,"name":"Soil_Dirt"},{"x":-12,"y":3,"z":-8,"name":"Soil_Dirt"},{"x":-12,"y":4,"z":-8,"name":"Soil_Dirt"},{"x":-12,"y":5,"z":-8,"name":"Soil_Snow"},{"x":-12,"y":11,"z":-8,"name":"WinterHoliday_Garland","support":15,"rotation":3},{"x":-12,"y":0,"z":-7,"name":"Soil_Dirt"},{"x":-12,"y":1,"z":-7,"name":"Soil_Dirt"},{"x":-12,"y":2,"z":-7,"name":"Soil_Dirt"},{"x":-12,"y":3,"z":-7,"name":"Soil_Dirt"},{"x":-12,"y":4,"z":-7,"name":"Soil_Dirt"},{"x":-12,"y":5,"z":-7,"name":"Soil_Snow"},{"x":-12,"y":11,"z":-7,"name":"WinterHoliday_Garland","support":15,"rotation":3},{"x":-12,"y":0,"z":-6,"name":"Soil_Dirt"},{"x":-12,"y":1,"z":-6,"name":"Soil_Dirt"},{"x":-12,"y":2,"z":-6,"name":"Soil_Dirt"},{"x":-12,"y":3,"z":-6,"name":"Soil_Dirt"},{"x":-12,"y":4,"z":-6,"name":"Soil_Dirt"},{"x":-12,"y":5,"z":-6,"name":"Soil_Snow"},{"x":-12,"y":11,"z":-6,"name":"WinterHoliday_Garland","support":15,"rotation":3},{"x":-12,"y":0,"z":-5,"name":"Soil_Dirt"},{"x":-12,"y":1,"z":-5,"name":"Soil_Dirt"},{"x":-12,"y":2,"z":-5,"name":"Soil_Dirt"},{"x":-12,"y":3,"z":-5,"name":"Soil_Dirt"},{"x":-12,"y":4,"z":-5,"name":"Soil_Dirt"},{"x":-12,"y":5,"z":-5,"name":"Soil_Snow"},{"x":-12,"y":11,"z":-5,"name":"WinterHoliday_Garland","support":15,"rotation":3},{"x":-12,"y":0,"z":-4,"name":"Soil_Dirt"},{"x":-12,"y":1,"z":-4,"name":"Soil_Dirt"},{"x":-12,"y":2,"z":-4,"name":"Soil_Dirt"},{"x":-12,"y":3,"z":-4,"name":"Soil_Dirt"},{"x":-12,"y":4,"z":-4,"name":"Soil_Dirt"},{"x":-12,"y":5,"z":-4,"name":"Soil_Snow"},{"x":-12,"y":11,"z":-4,"name":"WinterHoliday_Garland","support":15,"rotation":3},{"x":-12,"y":0,"z":-3,"name":"Soil_Dirt"},{"x":-12,"y":1,"z":-3,"name":"Soil_Dirt"},{"x":-12,"y":2,"z":-3,"name":"Soil_Dirt"},{"x":-12,"y":3,"z":-3,"name":"Soil_Dirt"},{"x":-12,"y":4,"z":-3,"name":"Soil_Dirt"},{"x":-12,"y":5,"z":-3,"name":"Soil_Snow"},{"x":-12,"y":8,"z":-3,"name":"Winter_Holiday_Wreath","support":15,"rotation":3},{"x":-12,"y":11,"z":-3,"name":"WinterHoliday_Garland","support":15,"rotation":3},{"x":-12,"y":0,"z":-2,"name":"Soil_Dirt"},{"x":-12,"y":1,"z":-2,"name":"Soil_Dirt"},{"x":-12,"y":2,"z":-2,"name":"Soil_Dirt"},{"x":-12,"y":3,"z":-2,"name":"Soil_Dirt"},{"x":-12,"y":4,"z":-2,"name":"Soil_Dirt"},{"x":-12,"y":5,"z":-2,"name":"Soil_Snow"},{"x":-12,"y":11,"z":-2,"name":"WinterHoliday_Garland","support":15,"rotation":3},{"x":-12,"y":0,"z":-1,"name":"Soil_Dirt"},{"x":-12,"y":1,"z":-1,"name":"Soil_Dirt"},{"x":-12,"y":2,"z":-1,"name":"Soil_Dirt"},{"x":-12,"y":3,"z":-1,"name":"Soil_Dirt"},{"x":-12,"y":4,"z":-1,"name":"Soil_Dirt"},{"x":-12,"y":5,"z":-1,"name":"Soil_Snow"},{"x":-12,"y":11,"z":-1,"name":"WinterHoliday_Garland","support":15,"rotation":3},{"x":-12,"y":0,"z":0,"name":"Soil_Dirt"},{"x":-12,"y":1,"z":0,"name":"Soil_Dirt"},{"x":-12,"y":2,"z":0,"name":"Soil_Dirt"},{"x":-12,"y":3,"z":0,"name":"Soil_Dirt"},{"x":-12,"y":4,"z":0,"name":"Soil_Dirt"},{"x":-12,"y":5,"z":0,"name":"Rock_Calcite_Brick","support":15},{"x":-12,"y":11,"z":0,"name":"WinterHoliday_Garland","support":15,"rotation":3},{"x":-12,"y":0,"z":1,"name":"Soil_Dirt"},{"x":-12,"y":1,"z":1,"name":"Soil_Dirt"},{"x":-12,"y":2,"z":1,"name":"Soil_Dirt"},{"x":-12,"y":3,"z":1,"name":"Soil_Dirt"},{"x":-12,"y":4,"z":1,"name":"Soil_Dirt"},{"x":-12,"y":5,"z":1,"name":"Rock_Calcite_Brick","support":15},{"x":-12,"y":11,"z":1,"name":"WinterHoliday_Garland","support":15,"rotation":3},{"x":-12,"y":0,"z":2,"name":"Soil_Dirt"},{"x":-12,"y":1,"z":2,"name":"Soil_Dirt"},{"x":-12,"y":2,"z":2,"name":"Soil_Dirt"},{"x":-12,"y":3,"z":2,"name":"Soil_Dirt"},{"x":-12,"y":4,"z":2,"name":"Soil_Dirt"},{"x":-12,"y":5,"z":2,"name":"Soil_Snow"},{"x":-12,"y":11,"z":2,"name":"WinterHoliday_Garland","support":15,"rotation":3},{"x":-12,"y":0,"z":3,"name":"Soil_Dirt"},{"x":-12,"y":1,"z":3,"name":"Soil_Dirt"},{"x":-12,"y":2,"z":3,"name":"Soil_Dirt"},{"x":-12,"y":3,"z":3,"name":"Soil_Dirt"},{"x":-12,"y":4,"z":3,"name":"Soil_Dirt"},{"x":-12,"y":5,"z":3,"name":"Soil_Snow"},{"x":-12,"y":11,"z":3,"name":"WinterHoliday_Garland","support":15,"rotation":3},{"x":-12,"y":0,"z":4,"name":"Soil_Dirt"},{"x":-12,"y":1,"z":4,"name":"Soil_Dirt"},{"x":-12,"y":2,"z":4,"name":"Soil_Dirt"},{"x":-12,"y":3,"z":4,"name":"Soil_Dirt"},{"x":-12,"y":4,"z":4,"name":"Soil_Dirt"},{"x":-12,"y":5,"z":4,"name":"Soil_Snow"},{"x":-12,"y":8,"z":4,"name":"Winter_Holiday_Wreath","support":15,"rotation":3},{"x":-12,"y":11,"z":4,"name":"WinterHoliday_Garland","support":15,"rotation":3},{"x":-12,"y":0,"z":5,"name":"Soil_Dirt"},{"x":-12,"y":1,"z":5,"name":"Soil_Dirt"},{"x":-12,"y":2,"z":5,"name":"Soil_Dirt"},{"x":-12,"y":3,"z":5,"name":"Soil_Dirt"},{"x":-12,"y":4,"z":5,"name":"Soil_Dirt"},{"x":-12,"y":5,"z":5,"name":"Soil_Snow"},{"x":-12,"y":11,"z":5,"name":"WinterHoliday_Garland","support":15,"rotation":3},{"x":-12,"y":0,"z":6,"name":"Soil_Dirt"},{"x":-12,"y":1,"z":6,"name":"Soil_Dirt"},{"x":-12,"y":2,"z":6,"name":"Soil_Dirt"},{"x":-12,"y":3,"z":6,"name":"Soil_Dirt"},{"x":-12,"y":4,"z":6,"name":"Soil_Dirt"},{"x":-12,"y":5,"z":6,"name":"Soil_Snow"},{"x":-12,"y":11,"z":6,"name":"WinterHoliday_Garland","support":15,"rotation":3},{"x":-12,"y":0,"z":7,"name":"Soil_Dirt"},{"x":-12,"y":1,"z":7,"name":"Soil_Dirt"},{"x":-12,"y":2,"z":7,"name":"Soil_Dirt"},{"x":-12,"y":3,"z":7,"name":"Soil_Dirt"},{"x":-12,"y":4,"z":7,"name":"Soil_Dirt"},{"x":-12,"y":5,"z":7,"name":"Soil_Snow"},{"x":-12,"y":11,"z":7,"name":"WinterHoliday_Garland","support":15,"rotation":3},{"x":-12,"y":0,"z":8,"name":"Soil_Dirt"},{"x":-12,"y":1,"z":8,"name":"Soil_Dirt"},{"x":-12,"y":2,"z":8,"name":"Soil_Dirt"},{"x":-12,"y":3,"z":8,"name":"Soil_Dirt"},{"x":-12,"y":4,"z":8,"name":"Soil_Dirt"},{"x":-12,"y":5,"z":8,"name":"Soil_Snow"},{"x":-12,"y":11,"z":8,"name":"WinterHoliday_Garland","support":15,"rotation":3},{"x":-12,"y":0,"z":9,"name":"Soil_Dirt"},{"x":-12,"y":1,"z":9,"name":"Soil_Dirt"},{"x":-12,"y":2,"z":9,"name":"Soil_Dirt"},{"x":-12,"y":3,"z":9,"name":"Soil_Dirt"},{"x":-12,"y":4,"z":9,"name":"Soil_Dirt"},{"x":-12,"y":5,"z":9,"name":"Soil_Snow"},{"x":-12,"y":11,"z":9,"name":"WinterHoliday_Garland","support":15,"rotation":3},{"x":-12,"y":0,"z":10,"name":"Soil_Dirt"},{"x":-12,"y":1,"z":10,"name":"Soil_Dirt"},{"x":-12,"y":2,"z":10,"name":"Soil_Dirt"},{"x":-12,"y":3,"z":10,"name":"Soil_Dirt"},{"x":-12,"y":4,"z":10,"name":"Soil_Dirt"},{"x":-12,"y":5,"z":10,"name":"Soil_Snow"},{"x":-12,"y":11,"z":10,"name":"WinterHoliday_Garland","support":15,"rotation":3},{"x":-12,"y":0,"z":11,"name":"Soil_Dirt"},{"x":-12,"y":1,"z":11,"name":"Soil_Dirt"},{"x":-12,"y":2,"z":11,"name":"Soil_Dirt"},{"x":-12,"y":3,"z":11,"name":"Soil_Dirt"},{"x":-12,"y":4,"z":11,"name":"Soil_Dirt"},{"x":-12,"y":5,"z":11,"name":"Soil_Snow"},{"x":-12,"y":11,"z":11,"name":"WinterHoliday_Garland","support":15,"rotation":3},{"x":-12,"y":0,"z":12,"name":"Soil_Dirt"},{"x":-12,"y":1,"z":12,"name":"Soil_Dirt"},{"x":-12,"y":2,"z":12,"name":"Soil_Dirt"},{"x":-12,"y":3,"z":12,"name":"Soil_Dirt"},{"x":-12,"y":4,"z":12,"name":"Soil_Dirt"},{"x":-12,"y":5,"z":12,"name":"Soil_Snow"},{"x":-12,"y":8,"z":12,"name":"Winter_Holiday_Wreath","support":15,"rotation":3},{"x":-12,"y":11,"z":12,"name":"WinterHoliday_Garland","support":15,"rotation":3},{"x":-12,"y":0,"z":13,"name":"Soil_Dirt"},{"x":-12,"y":1,"z":13,"name":"Soil_Dirt"},{"x":-12,"y":2,"z":13,"name":"Soil_Dirt"},{"x":-12,"y":3,"z":13,"name":"Soil_Dirt"},{"x":-12,"y":4,"z":13,"name":"Soil_Dirt"},{"x":-12,"y":5,"z":13,"name":"Soil_Snow"},{"x":-12,"y":0,"z":14,"name":"Soil_Dirt"},{"x":-12,"y":1,"z":14,"name":"Soil_Dirt"},{"x":-12,"y":2,"z":14,"name":"Soil_Dirt"},{"x":-12,"y":3,"z":14,"name":"Soil_Dirt"},{"x":-12,"y":4,"z":14,"name":"Soil_Dirt"},{"x":-12,"y":5,"z":14,"name":"Soil_Snow"},{"x":-12,"y":0,"z":15,"name":"Soil_Dirt"},{"x":-12,"y":1,"z":15,"name":"Soil_Dirt"},{"x":-12,"y":2,"z":15,"name":"Soil_Dirt"},{"x":-12,"y":3,"z":15,"name":"Soil_Dirt"},{"x":-12,"y":4,"z":15,"name":"Soil_Dirt"},{"x":-12,"y":5,"z":15,"name":"Rock_Stone_Brick_Smooth"},{"x":-11,"y":0,"z":-14,"name":"Soil_Dirt"},{"x":-11,"y":1,"z":-14,"name":"Soil_Dirt"},{"x":-11,"y":2,"z":-14,"name":"Soil_Dirt"},{"x":-11,"y":3,"z":-14,"name":"Soil_Dirt"},{"x":-11,"y":4,"z":-14,"name":"Soil_Dirt"},{"x":-11,"y":5,"z":-14,"name":"Rock_Stone_Brick_Smooth"},{"x":-11,"y":0,"z":-13,"name":"Soil_Dirt"},{"x":-11,"y":1,"z":-13,"name":"Soil_Dirt"},{"x":-11,"y":2,"z":-13,"name":"Soil_Dirt"},{"x":-11,"y":3,"z":-13,"name":"Soil_Dirt"},{"x":-11,"y":4,"z":-13,"name":"Soil_Dirt"},{"x":-11,"y":5,"z":-13,"name":"Soil_Snow"},{"x":-11,"y":0,"z":-12,"name":"Soil_Dirt"},{"x":-11,"y":1,"z":-12,"name":"Soil_Dirt"},{"x":-11,"y":2,"z":-12,"name":"Soil_Dirt"},{"x":-11,"y":3,"z":-12,"name":"Soil_Dirt"},{"x":-11,"y":4,"z":-12,"name":"Soil_Dirt"},{"x":-11,"y":5,"z":-12,"name":"Soil_Snow"},{"x":-11,"y":8,"z":-12,"name":"Winter_Holiday_Wreath","support":15,"rotation":2},{"x":-11,"y":11,"z":-12,"name":"WinterHoliday_Garland","support":15,"rotation":2},{"x":-11,"y":0,"z":-11,"name":"Soil_Dirt"},{"x":-11,"y":1,"z":-11,"name":"Soil_Dirt"},{"x":-11,"y":2,"z":-11,"name":"Soil_Dirt"},{"x":-11,"y":3,"z":-11,"name":"Soil_Dirt"},{"x":-11,"y":4,"z":-11,"name":"Soil_Dirt"},{"x":-11,"y":5,"z":-11,"name":"Soil_Snow"},{"x":-11,"y":6,"z":-11,"name":"Wood_Fir_Trunk","support":15,"rotation":1},{"x":-11,"y":7,"z":-11,"name":"Wood_Fir_Trunk","support":15,"rotation":1},{"x":-11,"y":8,"z":-11,"name":"Wood_Fir_Trunk","support":15,"rotation":1},{"x":-11,"y":9,"z":-11,"name":"Wood_Fir_Trunk","support":15,"rotation":1},{"x":-11,"y":10,"z":-11,"name":"Wood_Fir_Trunk","support":15,"rotation":1},{"x":-11,"y":11,"z":-11,"name":"Wood_Fir_Trunk","support":15,"rotation":1},{"x":-11,"y":12,"z":-11,"name":"Wood_Darkwood_Planks_Half","support":15,"rotation":1},{"x":-11,"y":0,"z":-10,"name":"Soil_Dirt"},{"x":-11,"y":1,"z":-10,"name":"Soil_Dirt"},{"x":-11,"y":2,"z":-10,"name":"Soil_Dirt"},{"x":-11,"y":3,"z":-10,"name":"Soil_Dirt"},{"x":-11,"y":4,"z":-10,"name":"Soil_Dirt"},{"x":-11,"y":5,"z":-10,"name":"Soil_Snow"},{"x":-11,"y":6,"z":-10,"name":"*Soil_Snow_Half_State_Definitions_Block"},{"x":-11,"y":8,"z":-10,"name":"WinterHoliday_Cane","support":15},{"x":-11,"y":10,"z":-10,"name":"Wood_Darkwood_Stairs","support":15,"rotation":32},{"x":-11,"y":11,"z":-10,"name":"Wood_Fir_Trunk","support":15,"rotation":6},{"x":-11,"y":12,"z":-10,"name":"Wood_Darkwood_Roof_Flat","support":15,"rotation":3},{"x":-11,"y":0,"z":-9,"name":"Soil_Dirt"},{"x":-11,"y":1,"z":-9,"name":"Soil_Dirt"},{"x":-11,"y":2,"z":-9,"name":"Soil_Dirt"},{"x":-11,"y":3,"z":-9,"name":"Soil_Dirt"},{"x":-11,"y":4,"z":-9,"name":"Soil_Dirt"},{"x":-11,"y":5,"z":-9,"name":"Soil_Snow"},{"x":-11,"y":6,"z":-9,"name":"Soil_Snow_Half","support":15},{"x":-11,"y":11,"z":-9,"name":"Wood_Fir_Trunk","support":15,"rotation":6},{"x":-11,"y":12,"z":-9,"name":"Wood_Darkwood_Roof_Flat","support":15,"rotation":3},{"x":-11,"y":0,"z":-8,"name":"Soil_Dirt"},{"x":-11,"y":1,"z":-8,"name":"Soil_Dirt"},{"x":-11,"y":2,"z":-8,"name":"Soil_Dirt"},{"x":-11,"y":3,"z":-8,"name":"Soil_Dirt"},{"x":-11,"y":4,"z":-8,"name":"Soil_Dirt"},{"x":-11,"y":5,"z":-8,"name":"Soil_Snow"},{"x":-11,"y":11,"z":-8,"name":"Wood_Fir_Trunk","support":15,"rotation":6},{"x":-11,"y":12,"z":-8,"name":"Wood_Darkwood_Roof_Flat","support":15,"rotation":3},{"x":-11,"y":0,"z":-7,"name":"Soil_Dirt"},{"x":-11,"y":1,"z":-7,"name":"Soil_Dirt"},{"x":-11,"y":2,"z":-7,"name":"Soil_Dirt"},{"x":-11,"y":3,"z":-7,"name":"Soil_Dirt"},{"x":-11,"y":4,"z":-7,"name":"Soil_Dirt"},{"x":-11,"y":5,"z":-7,"name":"Soil_Snow"},{"x":-11,"y":11,"z":-7,"name":"Wood_Fir_Trunk","support":15,"rotation":6},{"x":-11,"y":12,"z":-7,"name":"Wood_Darkwood_Roof_Flat","support":15,"rotation":3},{"x":-11,"y":0,"z":-6,"name":"Soil_Dirt"},{"x":-11,"y":1,"z":-6,"name":"Soil_Dirt"},{"x":-11,"y":2,"z":-6,"name":"Soil_Dirt"},{"x":-11,"y":3,"z":-6,"name":"Soil_Dirt"},{"x":-11,"y":4,"z":-6,"name":"Soil_Dirt"},{"x":-11,"y":5,"z":-6,"name":"Soil_Snow"},{"x":-11,"y":11,"z":-6,"name":"Wood_Fir_Trunk","support":15,"rotation":6},{"x":-11,"y":12,"z":-6,"name":"Wood_Darkwood_Roof_Flat","support":15,"rotation":3},{"x":-11,"y":0,"z":-5,"name":"Soil_Dirt"},{"x":-11,"y":1,"z":-5,"name":"Soil_Dirt"},{"x":-11,"y":2,"z":-5,"name":"Soil_Dirt"},{"x":-11,"y":3,"z":-5,"name":"Soil_Dirt"},{"x":-11,"y":4,"z":-5,"name":"Soil_Dirt"},{"x":-11,"y":5,"z":-5,"name":"Soil_Snow"},{"x":-11,"y":11,"z":-5,"name":"Wood_Fir_Trunk","support":15,"rotation":6},{"x":-11,"y":12,"z":-5,"name":"Wood_Darkwood_Roof_Flat","support":15,"rotation":3},{"x":-11,"y":0,"z":-4,"name":"Soil_Dirt"},{"x":-11,"y":1,"z":-4,"name":"Soil_Dirt"},{"x":-11,"y":2,"z":-4,"name":"Soil_Dirt"},{"x":-11,"y":3,"z":-4,"name":"Soil_Dirt"},{"x":-11,"y":4,"z":-4,"name":"Soil_Dirt"},{"x":-11,"y":5,"z":-4,"name":"Soil_Snow"},{"x":-11,"y":10,"z":-4,"name":"Wood_Darkwood_Stairs","support":15,"rotation":34},{"x":-11,"y":11,"z":-4,"name":"Wood_Fir_Trunk","support":15,"rotation":6},{"x":-11,"y":12,"z":-4,"name":"Wood_Darkwood_Roof_Flat","support":15,"rotation":3},{"x":-11,"y":0,"z":-3,"name":"Soil_Dirt"},{"x":-11,"y":1,"z":-3,"name":"Soil_Dirt"},{"x":-11,"y":2,"z":-3,"name":"Soil_Dirt"},{"x":-11,"y":3,"z":-3,"name":"Soil_Dirt"},{"x":-11,"y":4,"z":-3,"name":"Soil_Dirt"},{"x":-11,"y":5,"z":-3,"name":"Soil_Snow"},{"x":-11,"y":6,"z":-3,"name":"Wood_Fir_Trunk","support":15,"rotation":1},{"x":-11,"y":7,"z":-3,"name":"Wood_Fir_Trunk","support":15,"rotation":1},{"x":-11,"y":8,"z":-3,"name":"Wood_Fir_Trunk","support":15,"rotation":1},{"x":-11,"y":9,"z":-3,"name":"Wood_Fir_Trunk","support":15,"rotation":1},{"x":-11,"y":10,"z":-3,"name":"Wood_Fir_Trunk","support":15,"rotation":1},{"x":-11,"y":11,"z":-3,"name":"Wood_Fir_Trunk","support":15,"rotation":6},{"x":-11,"y":12,"z":-3,"name":"Wood_Darkwood_Roof_Flat","support":15,"rotation":1},{"x":-11,"y":0,"z":-2,"name":"Soil_Dirt"},{"x":-11,"y":1,"z":-2,"name":"Soil_Dirt"},{"x":-11,"y":2,"z":-2,"name":"Soil_Dirt"},{"x":-11,"y":3,"z":-2,"name":"Soil_Dirt"},{"x":-11,"y":4,"z":-2,"name":"Soil_Dirt"},{"x":-11,"y":5,"z":-2,"name":"Soil_Snow"},{"x":-11,"y":10,"z":-2,"name":"Wood_Darkwood_Stairs","support":15,"rotation":32},{"x":-11,"y":11,"z":-2,"name":"Wood_Fir_Trunk","support":15,"rotation":6},{"x":-11,"y":12,"z":-2,"name":"Wood_Darkwood_Roof_Flat","support":15,"rotation":3},{"x":-11,"y":0,"z":-1,"name":"Soil_Dirt"},{"x":-11,"y":1,"z":-1,"name":"Soil_Dirt"},{"x":-11,"y":2,"z":-1,"name":"Soil_Dirt"},{"x":-11,"y":3,"z":-1,"name":"Soil_Dirt"},{"x":-11,"y":4,"z":-1,"name":"Soil_Dirt"},{"x":-11,"y":5,"z":-1,"name":"Soil_Snow"},{"x":-11,"y":11,"z":-1,"name":"Wood_Fir_Trunk","support":15,"rotation":6},{"x":-11,"y":12,"z":-1,"name":"Wood_Darkwood_Roof_Flat","support":15,"rotation":3},{"x":-11,"y":0,"z":0,"name":"Soil_Dirt"},{"x":-11,"y":1,"z":0,"name":"Soil_Dirt"},{"x":-11,"y":2,"z":0,"name":"Soil_Dirt"},{"x":-11,"y":3,"z":0,"name":"Soil_Dirt"},{"x":-11,"y":4,"z":0,"name":"Soil_Dirt"},{"x":-11,"y":5,"z":0,"name":"Rock_Calcite_Brick","support":15},{"x":-11,"y":11,"z":0,"name":"Wood_Fir_Trunk","support":15,"rotation":6},{"x":-11,"y":12,"z":0,"name":"Wood_Darkwood_Roof_Flat","support":15,"rotation":3},{"x":-11,"y":0,"z":1,"name":"Soil_Dirt"},{"x":-11,"y":1,"z":1,"name":"Soil_Dirt"},{"x":-11,"y":2,"z":1,"name":"Soil_Dirt"},{"x":-11,"y":3,"z":1,"name":"Soil_Dirt"},{"x":-11,"y":4,"z":1,"name":"Soil_Dirt"},{"x":-11,"y":5,"z":1,"name":"Rock_Calcite_Brick","support":15},{"x":-11,"y":11,"z":1,"name":"Wood_Fir_Trunk","support":15,"rotation":6},{"x":-11,"y":12,"z":1,"name":"Wood_Darkwood_Roof_Flat","support":15,"rotation":3},{"x":-11,"y":0,"z":2,"name":"Soil_Dirt"},{"x":-11,"y":1,"z":2,"name":"Soil_Dirt"},{"x":-11,"y":2,"z":2,"name":"Soil_Dirt"},{"x":-11,"y":3,"z":2,"name":"Soil_Dirt"},{"x":-11,"y":4,"z":2,"name":"Soil_Dirt"},{"x":-11,"y":5,"z":2,"name":"Soil_Snow"},{"x":-11,"y":11,"z":2,"name":"Wood_Fir_Trunk","support":15,"rotation":6},{"x":-11,"y":12,"z":2,"name":"Wood_Darkwood_Roof_Flat","support":15,"rotation":3},{"x":-11,"y":0,"z":3,"name":"Soil_Dirt"},{"x":-11,"y":1,"z":3,"name":"Soil_Dirt"},{"x":-11,"y":2,"z":3,"name":"Soil_Dirt"},{"x":-11,"y":3,"z":3,"name":"Soil_Dirt"},{"x":-11,"y":4,"z":3,"name":"Soil_Dirt"},{"x":-11,"y":5,"z":3,"name":"Soil_Snow"},{"x":-11,"y":6,"z":3,"name":"Soil_Snow_Half","support":15},{"x":-11,"y":10,"z":3,"name":"Wood_Darkwood_Stairs","support":15,"rotation":34},{"x":-11,"y":11,"z":3,"name":"Wood_Fir_Trunk","support":15,"rotation":6},{"x":-11,"y":12,"z":3,"name":"Wood_Darkwood_Roof_Flat","support":15,"rotation":3},{"x":-11,"y":0,"z":4,"name":"Soil_Dirt"},{"x":-11,"y":1,"z":4,"name":"Soil_Dirt"},{"x":-11,"y":2,"z":4,"name":"Soil_Dirt"},{"x":-11,"y":3,"z":4,"name":"Soil_Dirt"},{"x":-11,"y":4,"z":4,"name":"Soil_Dirt"},{"x":-11,"y":5,"z":4,"name":"Soil_Snow"},{"x":-11,"y":6,"z":4,"name":"Wood_Fir_Trunk","support":15,"rotation":1},{"x":-11,"y":7,"z":4,"name":"Wood_Fir_Trunk","support":15,"rotation":1},{"x":-11,"y":8,"z":4,"name":"Wood_Fir_Trunk","support":15,"rotation":1},{"x":-11,"y":9,"z":4,"name":"Wood_Fir_Trunk","support":15,"rotation":1},{"x":-11,"y":10,"z":4,"name":"Wood_Fir_Trunk","support":15,"rotation":1},{"x":-11,"y":11,"z":4,"name":"Wood_Fir_Trunk","support":15,"rotation":6},{"x":-11,"y":12,"z":4,"name":"Wood_Darkwood_Roof_Flat","support":15,"rotation":3},{"x":-11,"y":0,"z":5,"name":"Soil_Dirt"},{"x":-11,"y":1,"z":5,"name":"Soil_Dirt"},{"x":-11,"y":2,"z":5,"name":"Soil_Dirt"},{"x":-11,"y":3,"z":5,"name":"Soil_Dirt"},{"x":-11,"y":4,"z":5,"name":"Soil_Dirt"},{"x":-11,"y":5,"z":5,"name":"Soil_Snow"},{"x":-11,"y":10,"z":5,"name":"Wood_Darkwood_Stairs","support":15,"rotation":32},{"x":-11,"y":11,"z":5,"name":"Wood_Fir_Trunk","support":15,"rotation":6},{"x":-11,"y":12,"z":5,"name":"Wood_Darkwood_Roof_Flat","support":15,"rotation":3},{"x":-11,"y":0,"z":6,"name":"Soil_Dirt"},{"x":-11,"y":1,"z":6,"name":"Soil_Dirt"},{"x":-11,"y":2,"z":6,"name":"Soil_Dirt"},{"x":-11,"y":3,"z":6,"name":"Soil_Dirt"},{"x":-11,"y":4,"z":6,"name":"Soil_Dirt"},{"x":-11,"y":5,"z":6,"name":"Soil_Snow"},{"x":-11,"y":11,"z":6,"name":"Wood_Fir_Trunk","support":15,"rotation":6},{"x":-11,"y":12,"z":6,"name":"Wood_Darkwood_Roof_Flat","support":15,"rotation":3},{"x":-11,"y":0,"z":7,"name":"Soil_Dirt"},{"x":-11,"y":1,"z":7,"name":"Soil_Dirt"},{"x":-11,"y":2,"z":7,"name":"Soil_Dirt"},{"x":-11,"y":3,"z":7,"name":"Soil_Dirt"},{"x":-11,"y":4,"z":7,"name":"Soil_Dirt"},{"x":-11,"y":5,"z":7,"name":"Soil_Snow"},{"x":-11,"y":11,"z":7,"name":"Wood_Fir_Trunk","support":15,"rotation":6},{"x":-11,"y":12,"z":7,"name":"Wood_Darkwood_Roof_Flat","support":15,"rotation":3},{"x":-11,"y":0,"z":8,"name":"Soil_Dirt"},{"x":-11,"y":1,"z":8,"name":"Soil_Dirt"},{"x":-11,"y":2,"z":8,"name":"Soil_Dirt"},{"x":-11,"y":3,"z":8,"name":"Soil_Dirt"},{"x":-11,"y":4,"z":8,"name":"Soil_Dirt"},{"x":-11,"y":5,"z":8,"name":"Soil_Snow"},{"x":-11,"y":11,"z":8,"name":"Wood_Fir_Trunk","support":15,"rotation":6},{"x":-11,"y":12,"z":8,"name":"Wood_Darkwood_Roof_Flat","support":15,"rotation":3},{"x":-11,"y":0,"z":9,"name":"Soil_Dirt"},{"x":-11,"y":1,"z":9,"name":"Soil_Dirt"},{"x":-11,"y":2,"z":9,"name":"Soil_Dirt"},{"x":-11,"y":3,"z":9,"name":"Soil_Dirt"},{"x":-11,"y":4,"z":9,"name":"Soil_Dirt"},{"x":-11,"y":5,"z":9,"name":"Soil_Snow"},{"x":-11,"y":11,"z":9,"name":"Wood_Fir_Trunk","support":15,"rotation":6},{"x":-11,"y":12,"z":9,"name":"Wood_Darkwood_Roof_Flat","support":15,"rotation":3},{"x":-11,"y":0,"z":10,"name":"Soil_Dirt"},{"x":-11,"y":1,"z":10,"name":"Soil_Dirt"},{"x":-11,"y":2,"z":10,"name":"Soil_Dirt"},{"x":-11,"y":3,"z":10,"name":"Soil_Dirt"},{"x":-11,"y":4,"z":10,"name":"Soil_Dirt"},{"x":-11,"y":5,"z":10,"name":"Soil_Snow"},{"x":-11,"y":11,"z":10,"name":"Wood_Fir_Trunk","support":15,"rotation":6},{"x":-11,"y":12,"z":10,"name":"Wood_Darkwood_Roof_Flat","support":15,"rotation":3},{"x":-11,"y":0,"z":11,"name":"Soil_Dirt"},{"x":-11,"y":1,"z":11,"name":"Soil_Dirt"},{"x":-11,"y":2,"z":11,"name":"Soil_Dirt"},{"x":-11,"y":3,"z":11,"name":"Soil_Dirt"},{"x":-11,"y":4,"z":11,"name":"Soil_Dirt"},{"x":-11,"y":5,"z":11,"name":"Soil_Snow"},{"x":-11,"y":6,"z":11,"name":"Soil_Snow_Half","support":15},{"x":-11,"y":8,"z":11,"name":"WinterHoliday_Cane","support":15,"rotation":2},{"x":-11,"y":10,"z":11,"name":"Wood_Darkwood_Stairs","support":15,"rotation":34},{"x":-11,"y":11,"z":11,"name":"Wood_Fir_Trunk","support":15,"rotation":6},{"x":-11,"y":12,"z":11,"name":"Wood_Darkwood_Roof_Flat","support":15,"rotation":3},{"x":-11,"y":0,"z":12,"name":"Soil_Dirt"},{"x":-11,"y":1,"z":12,"name":"Soil_Dirt"},{"x":-11,"y":2,"z":12,"name":"Soil_Dirt"},{"x":-11,"y":3,"z":12,"name":"Soil_Dirt"},{"x":-11,"y":4,"z":12,"name":"Soil_Dirt"},{"x":-11,"y":5,"z":12,"name":"Soil_Snow"},{"x":-11,"y":6,"z":12,"name":"Wood_Fir_Trunk","support":15,"rotation":1},{"x":-11,"y":7,"z":12,"name":"Wood_Fir_Trunk","support":15,"rotation":1},{"x":-11,"y":8,"z":12,"name":"Wood_Fir_Trunk","support":15,"rotation":1},{"x":-11,"y":9,"z":12,"name":"Wood_Fir_Trunk","support":15,"rotation":1},{"x":-11,"y":10,"z":12,"name":"Wood_Fir_Trunk","support":15,"rotation":1},{"x":-11,"y":11,"z":12,"name":"Wood_Fir_Trunk","support":15,"rotation":1},{"x":-11,"y":12,"z":12,"name":"Wood_Darkwood_Planks_Half","support":15,"rotation":1},{"x":-11,"y":0,"z":13,"name":"Soil_Dirt"},{"x":-11,"y":1,"z":13,"name":"Soil_Dirt"},{"x":-11,"y":2,"z":13,"name":"Soil_Dirt"},{"x":-11,"y":3,"z":13,"name":"Soil_Dirt"},{"x":-11,"y":4,"z":13,"name":"Soil_Dirt"},{"x":-11,"y":5,"z":13,"name":"Soil_Snow"},{"x":-11,"y":8,"z":13,"name":"Winter_Holiday_Wreath","support":15},{"x":-11,"y":11,"z":13,"name":"WinterHoliday_Garland","support":15},{"x":-11,"y":0,"z":14,"name":"Soil_Dirt"},{"x":-11,"y":1,"z":14,"name":"Soil_Dirt"},{"x":-11,"y":2,"z":14,"name":"Soil_Dirt"},{"x":-11,"y":3,"z":14,"name":"Soil_Dirt"},{"x":-11,"y":4,"z":14,"name":"Soil_Dirt"},{"x":-11,"y":5,"z":14,"name":"Soil_Snow"},{"x":-11,"y":0,"z":15,"name":"Soil_Dirt"},{"x":-11,"y":1,"z":15,"name":"Soil_Dirt"},{"x":-11,"y":2,"z":15,"name":"Soil_Dirt"},{"x":-11,"y":3,"z":15,"name":"Soil_Dirt"},{"x":-11,"y":4,"z":15,"name":"Soil_Dirt"},{"x":-11,"y":5,"z":15,"name":"Rock_Stone_Brick_Smooth"},{"x":-10,"y":0,"z":-14,"name":"Soil_Dirt"},{"x":-10,"y":1,"z":-14,"name":"Soil_Dirt"},{"x":-10,"y":2,"z":-14,"name":"Soil_Dirt"},{"x":-10,"y":3,"z":-14,"name":"Soil_Dirt"},{"x":-10,"y":4,"z":-14,"name":"Soil_Dirt"},{"x":-10,"y":5,"z":-14,"name":"Rock_Stone_Brick_Smooth"},{"x":-10,"y":0,"z":-13,"name":"Soil_Dirt"},{"x":-10,"y":1,"z":-13,"name":"Soil_Dirt"},{"x":-10,"y":2,"z":-13,"name":"Soil_Dirt"},{"x":-10,"y":3,"z":-13,"name":"Soil_Dirt"},{"x":-10,"y":4,"z":-13,"name":"Soil_Dirt"},{"x":-10,"y":5,"z":-13,"name":"Soil_Snow"},{"x":-10,"y":0,"z":-12,"name":"Soil_Dirt"},{"x":-10,"y":1,"z":-12,"name":"Soil_Dirt"},{"x":-10,"y":2,"z":-12,"name":"Soil_Dirt"},{"x":-10,"y":3,"z":-12,"name":"Soil_Dirt"},{"x":-10,"y":4,"z":-12,"name":"Soil_Dirt"},{"x":-10,"y":5,"z":-12,"name":"Soil_Snow"},{"x":-10,"y":11,"z":-12,"name":"WinterHoliday_Garland","support":15,"rotation":2},{"x":-10,"y":0,"z":-11,"name":"Soil_Dirt"},{"x":-10,"y":1,"z":-11,"name":"Soil_Dirt"},{"x":-10,"y":2,"z":-11,"name":"Soil_Dirt"},{"x":-10,"y":3,"z":-11,"name":"Soil_Dirt"},{"x":-10,"y":4,"z":-11,"name":"Soil_Dirt"},{"x":-10,"y":5,"z":-11,"name":"Soil_Snow"},{"x":-10,"y":6,"z":-11,"name":"Soil_Snow_Half","support":15},{"x":-10,"y":8,"z":-11,"name":"WinterHoliday_WinterRoll","support":15,"rotation":1},{"x":-10,"y":10,"z":-11,"name":"Wood_Darkwood_Stairs","support":15,"rotation":11},{"x":-10,"y":11,"z":-11,"name":"Wood_Fir_Trunk","support":15,"rotation":5},{"x":-10,"y":12,"z":-11,"name":"Wood_Darkwood_Roof_Flat","support":15,"rotation":2},{"x":-10,"y":0,"z":-10,"name":"Soil_Dirt"},{"x":-10,"y":1,"z":-10,"name":"Soil_Dirt"},{"x":-10,"y":2,"z":-10,"name":"Soil_Dirt"},{"x":-10,"y":3,"z":-10,"name":"Soil_Dirt"},{"x":-10,"y":4,"z":-10,"name":"Soil_Dirt"},{"x":-10,"y":5,"z":-10,"name":"Soil_Snow"},{"x":-10,"y":6,"z":-10,"name":"Soil_Snow_Half","support":15},{"x":-10,"y":0,"z":-9,"name":"Soil_Dirt"},{"x":-10,"y":1,"z":-9,"name":"Soil_Dirt"},{"x":-10,"y":2,"z":-9,"name":"Soil_Dirt"},{"x":-10,"y":3,"z":-9,"name":"Soil_Dirt"},{"x":-10,"y":4,"z":-9,"name":"Soil_Dirt"},{"x":-10,"y":5,"z":-9,"name":"Soil_Snow"},{"x":-10,"y":11,"z":-9,"name":"WinterHoliday_Lights","support":15,"rotation":1},{"x":-10,"y":0,"z":-8,"name":"Soil_Dirt"},{"x":-10,"y":1,"z":-8,"name":"Soil_Dirt"},{"x":-10,"y":2,"z":-8,"name":"Soil_Dirt"},{"x":-10,"y":3,"z":-8,"name":"Soil_Dirt"},{"x":-10,"y":4,"z":-8,"name":"Soil_Dirt"},{"x":-10,"y":5,"z":-8,"name":"Soil_Snow"},{"x":-10,"y":11,"z":-8,"name":"WinterHoliday_Lights","support":15,"rotation":1},{"x":-10,"y":0,"z":-7,"name":"Soil_Dirt"},{"x":-10,"y":1,"z":-7,"name":"Soil_Dirt"},{"x":-10,"y":2,"z":-7,"name":"Soil_Dirt"},{"x":-10,"y":3,"z":-7,"name":"Soil_Dirt"},{"x":-10,"y":4,"z":-7,"name":"Soil_Dirt"},{"x":-10,"y":5,"z":-7,"name":"Soil_Snow"},{"x":-10,"y":11,"z":-7,"name":"WinterHoliday_Lights","support":15,"rotation":1},{"x":-10,"y":0,"z":-6,"name":"Soil_Dirt"},{"x":-10,"y":1,"z":-6,"name":"Soil_Dirt"},{"x":-10,"y":2,"z":-6,"name":"Soil_Dirt"},{"x":-10,"y":3,"z":-6,"name":"Soil_Dirt"},{"x":-10,"y":4,"z":-6,"name":"Soil_Dirt"},{"x":-10,"y":5,"z":-6,"name":"Soil_Snow"},{"x":-10,"y":11,"z":-6,"name":"WinterHoliday_Lights","support":15,"rotation":1},{"x":-10,"y":0,"z":-5,"name":"Soil_Dirt"},{"x":-10,"y":1,"z":-5,"name":"Soil_Dirt"},{"x":-10,"y":2,"z":-5,"name":"Soil_Dirt"},{"x":-10,"y":3,"z":-5,"name":"Soil_Dirt"},{"x":-10,"y":4,"z":-5,"name":"Soil_Dirt"},{"x":-10,"y":5,"z":-5,"name":"Soil_Snow"},{"x":-10,"y":6,"z":-5,"name":"WinterHoliday_Snowman","support":15,"rotation":1},{"x":-10,"y":7,"z":-5,"name":"WinterHoliday_Snowman","filler":1024,"rotation":1},{"x":-10,"y":11,"z":-5,"name":"WinterHoliday_Lights","support":15,"rotation":1},{"x":-10,"y":0,"z":-4,"name":"Soil_Dirt"},{"x":-10,"y":1,"z":-4,"name":"Soil_Dirt"},{"x":-10,"y":2,"z":-4,"name":"Soil_Dirt"},{"x":-10,"y":3,"z":-4,"name":"Soil_Dirt"},{"x":-10,"y":4,"z":-4,"name":"Soil_Dirt"},{"x":-10,"y":5,"z":-4,"name":"Soil_Snow"},{"x":-10,"y":11,"z":-4,"name":"WinterHoliday_Lights","support":15,"rotation":1},{"x":-10,"y":0,"z":-3,"name":"Soil_Dirt"},{"x":-10,"y":1,"z":-3,"name":"Soil_Dirt"},{"x":-10,"y":2,"z":-3,"name":"Soil_Dirt"},{"x":-10,"y":3,"z":-3,"name":"Soil_Dirt"},{"x":-10,"y":4,"z":-3,"name":"Soil_Dirt"},{"x":-10,"y":5,"z":-3,"name":"Soil_Snow"},{"x":-10,"y":8,"z":-3,"name":"WinterHoliday_Stocking","support":15,"rotation":1},{"x":-10,"y":11,"z":-3,"name":"WinterHoliday_Lights","support":15,"rotation":1},{"x":-10,"y":0,"z":-2,"name":"Soil_Dirt"},{"x":-10,"y":1,"z":-2,"name":"Soil_Dirt"},{"x":-10,"y":2,"z":-2,"name":"Soil_Dirt"},{"x":-10,"y":3,"z":-2,"name":"Soil_Dirt"},{"x":-10,"y":4,"z":-2,"name":"Soil_Dirt"},{"x":-10,"y":5,"z":-2,"name":"Soil_Snow"},{"x":-10,"y":11,"z":-2,"name":"WinterHoliday_Lights","support":15,"rotation":1},{"x":-10,"y":0,"z":-1,"name":"Soil_Dirt"},{"x":-10,"y":1,"z":-1,"name":"Soil_Dirt"},{"x":-10,"y":2,"z":-1,"name":"Soil_Dirt"},{"x":-10,"y":3,"z":-1,"name":"Soil_Dirt"},{"x":-10,"y":4,"z":-1,"name":"Soil_Dirt"},{"x":-10,"y":5,"z":-1,"name":"Soil_Snow"},{"x":-10,"y":11,"z":-1,"name":"WinterHoliday_Lights","support":15,"rotation":1},{"x":-10,"y":0,"z":0,"name":"Soil_Dirt"},{"x":-10,"y":1,"z":0,"name":"Soil_Dirt"},{"x":-10,"y":2,"z":0,"name":"Soil_Dirt"},{"x":-10,"y":3,"z":0,"name":"Soil_Dirt"},{"x":-10,"y":4,"z":0,"name":"Soil_Dirt"},{"x":-10,"y":5,"z":0,"name":"Rock_Calcite_Brick","support":15},{"x":-10,"y":11,"z":0,"name":"WinterHoliday_Lights","support":15,"rotation":1},{"x":-10,"y":0,"z":1,"name":"Soil_Dirt"},{"x":-10,"y":1,"z":1,"name":"Soil_Dirt"},{"x":-10,"y":2,"z":1,"name":"Soil_Dirt"},{"x":-10,"y":3,"z":1,"name":"Soil_Dirt"},{"x":-10,"y":4,"z":1,"name":"Soil_Dirt"},{"x":-10,"y":5,"z":1,"name":"Rock_Calcite_Brick","support":15},{"x":-10,"y":11,"z":1,"name":"WinterHoliday_Lights","support":15,"rotation":1},{"x":-10,"y":0,"z":2,"name":"Soil_Dirt"},{"x":-10,"y":1,"z":2,"name":"Soil_Dirt"},{"x":-10,"y":2,"z":2,"name":"Soil_Dirt"},{"x":-10,"y":3,"z":2,"name":"Soil_Dirt"},{"x":-10,"y":4,"z":2,"name":"Soil_Dirt"},{"x":-10,"y":5,"z":2,"name":"Soil_Snow"},{"x":-10,"y":11,"z":2,"name":"WinterHoliday_Lights","support":15,"rotation":1},{"x":-10,"y":0,"z":3,"name":"Soil_Dirt"},{"x":-10,"y":1,"z":3,"name":"Soil_Dirt"},{"x":-10,"y":2,"z":3,"name":"Soil_Dirt"},{"x":-10,"y":3,"z":3,"name":"Soil_Dirt"},{"x":-10,"y":4,"z":3,"name":"Soil_Dirt"},{"x":-10,"y":5,"z":3,"name":"Soil_Snow"},{"x":-10,"y":11,"z":3,"name":"WinterHoliday_Lights","support":15,"rotation":1},{"x":-10,"y":0,"z":4,"name":"Soil_Dirt"},{"x":-10,"y":1,"z":4,"name":"Soil_Dirt"},{"x":-10,"y":2,"z":4,"name":"Soil_Dirt"},{"x":-10,"y":3,"z":4,"name":"Soil_Dirt"},{"x":-10,"y":4,"z":4,"name":"Soil_Dirt"},{"x":-10,"y":5,"z":4,"name":"Soil_Snow"},{"x":-10,"y":6,"z":4,"name":"Plant_Bush_Winter_Snow","support":15},{"x":-10,"y":8,"z":4,"name":"WinterHoliday_Stocking","support":15,"rotation":1},{"x":-10,"y":11,"z":4,"name":"WinterHoliday_Lights","support":15,"rotation":1},{"x":-10,"y":0,"z":5,"name":"Soil_Dirt"},{"x":-10,"y":1,"z":5,"name":"Soil_Dirt"},{"x":-10,"y":2,"z":5,"name":"Soil_Dirt"},{"x":-10,"y":3,"z":5,"name":"Soil_Dirt"},{"x":-10,"y":4,"z":5,"name":"Soil_Dirt"},{"x":-10,"y":5,"z":5,"name":"Soil_Snow"},{"x":-10,"y":11,"z":5,"name":"WinterHoliday_Lights","support":15,"rotation":1},{"x":-10,"y":0,"z":6,"name":"Soil_Dirt"},{"x":-10,"y":1,"z":6,"name":"Soil_Dirt"},{"x":-10,"y":2,"z":6,"name":"Soil_Dirt"},{"x":-10,"y":3,"z":6,"name":"Soil_Dirt"},{"x":-10,"y":4,"z":6,"name":"Soil_Dirt"},{"x":-10,"y":5,"z":6,"name":"Soil_Snow"},{"x":-10,"y":11,"z":6,"name":"WinterHoliday_Lights","support":15,"rotation":1},{"x":-10,"y":0,"z":7,"name":"Soil_Dirt"},{"x":-10,"y":1,"z":7,"name":"Soil_Dirt"},{"x":-10,"y":2,"z":7,"name":"Soil_Dirt"},{"x":-10,"y":3,"z":7,"name":"Soil_Dirt"},{"x":-10,"y":4,"z":7,"name":"Soil_Dirt"},{"x":-10,"y":5,"z":7,"name":"Soil_Snow"},{"x":-10,"y":11,"z":7,"name":"WinterHoliday_Lights","support":15,"rotation":1},{"x":-10,"y":0,"z":8,"name":"Soil_Dirt"},{"x":-10,"y":1,"z":8,"name":"Soil_Dirt"},{"x":-10,"y":2,"z":8,"name":"Soil_Dirt"},{"x":-10,"y":3,"z":8,"name":"Soil_Dirt"},{"x":-10,"y":4,"z":8,"name":"Soil_Dirt"},{"x":-10,"y":5,"z":8,"name":"Soil_Snow","support":15},{"x":-10,"y":11,"z":8,"name":"WinterHoliday_Lights","support":15,"rotation":1},{"x":-10,"y":0,"z":9,"name":"Soil_Dirt"},{"x":-10,"y":1,"z":9,"name":"Soil_Dirt"},{"x":-10,"y":2,"z":9,"name":"Soil_Dirt"},{"x":-10,"y":3,"z":9,"name":"Soil_Dirt"},{"x":-10,"y":4,"z":9,"name":"Soil_Dirt"},{"x":-10,"y":5,"z":9,"name":"Soil_Snow","support":15},{"x":-10,"y":11,"z":9,"name":"WinterHoliday_Lights","support":15,"rotation":1},{"x":-10,"y":0,"z":10,"name":"Soil_Dirt"},{"x":-10,"y":1,"z":10,"name":"Soil_Dirt"},{"x":-10,"y":2,"z":10,"name":"Soil_Dirt"},{"x":-10,"y":3,"z":10,"name":"Soil_Dirt"},{"x":-10,"y":4,"z":10,"name":"Soil_Dirt"},{"x":-10,"y":5,"z":10,"name":"Soil_Snow"},{"x":-10,"y":11,"z":10,"name":"WinterHoliday_Lights","support":15,"rotation":1},{"x":-10,"y":0,"z":11,"name":"Soil_Dirt"},{"x":-10,"y":1,"z":11,"name":"Soil_Dirt"},{"x":-10,"y":2,"z":11,"name":"Soil_Dirt"},{"x":-10,"y":3,"z":11,"name":"Soil_Dirt"},{"x":-10,"y":4,"z":11,"name":"Soil_Dirt"},{"x":-10,"y":5,"z":11,"name":"Soil_Snow"},{"x":-10,"y":0,"z":12,"name":"Soil_Dirt"},{"x":-10,"y":1,"z":12,"name":"Soil_Dirt"},{"x":-10,"y":2,"z":12,"name":"Soil_Dirt"},{"x":-10,"y":3,"z":12,"name":"Soil_Dirt"},{"x":-10,"y":4,"z":12,"name":"Soil_Dirt"},{"x":-10,"y":5,"z":12,"name":"Soil_Snow"},{"x":-10,"y":6,"z":12,"name":"Soil_Snow_Half","support":15},{"x":-10,"y":8,"z":12,"name":"WinterHoliday_WinterRoll","support":15,"rotation":1},{"x":-10,"y":10,"z":12,"name":"Wood_Darkwood_Stairs","support":15,"rotation":33},{"x":-10,"y":11,"z":12,"name":"Wood_Fir_Trunk","support":15,"rotation":7},{"x":-10,"y":12,"z":12,"name":"Wood_Darkwood_Roof_Flat","support":15},{"x":-10,"y":0,"z":13,"name":"Soil_Dirt"},{"x":-10,"y":1,"z":13,"name":"Soil_Dirt"},{"x":-10,"y":2,"z":13,"name":"Soil_Dirt"},{"x":-10,"y":3,"z":13,"name":"Soil_Dirt"},{"x":-10,"y":4,"z":13,"name":"Soil_Dirt"},{"x":-10,"y":5,"z":13,"name":"Soil_Snow"},{"x":-10,"y":11,"z":13,"name":"WinterHoliday_Garland","support":15},{"x":-10,"y":0,"z":14,"name":"Soil_Dirt"},{"x":-10,"y":1,"z":14,"name":"Soil_Dirt"},{"x":-10,"y":2,"z":14,"name":"Soil_Dirt"},{"x":-10,"y":3,"z":14,"name":"Soil_Dirt"},{"x":-10,"y":4,"z":14,"name":"Soil_Dirt"},{"x":-10,"y":5,"z":14,"name":"Soil_Snow"},{"x":-10,"y":0,"z":15,"name":"Soil_Dirt"},{"x":-10,"y":1,"z":15,"name":"Soil_Dirt"},{"x":-10,"y":2,"z":15,"name":"Soil_Dirt"},{"x":-10,"y":3,"z":15,"name":"Soil_Dirt"},{"x":-10,"y":4,"z":15,"name":"Soil_Dirt"},{"x":-10,"y":5,"z":15,"name":"Rock_Stone_Brick_Smooth"},{"x":-9,"y":0,"z":-14,"name":"Soil_Dirt"},{"x":-9,"y":1,"z":-14,"name":"Soil_Dirt"},{"x":-9,"y":2,"z":-14,"name":"Soil_Dirt"},{"x":-9,"y":3,"z":-14,"name":"Soil_Dirt"},{"x":-9,"y":4,"z":-14,"name":"Soil_Dirt"},{"x":-9,"y":5,"z":-14,"name":"Rock_Stone_Brick_Smooth"},{"x":-9,"y":0,"z":-13,"name":"Soil_Dirt"},{"x":-9,"y":1,"z":-13,"name":"Soil_Dirt"},{"x":-9,"y":2,"z":-13,"name":"Soil_Dirt"},{"x":-9,"y":3,"z":-13,"name":"Soil_Dirt"},{"x":-9,"y":4,"z":-13,"name":"Soil_Dirt"},{"x":-9,"y":5,"z":-13,"name":"Soil_Snow"},{"x":-9,"y":0,"z":-12,"name":"Soil_Dirt"},{"x":-9,"y":1,"z":-12,"name":"Soil_Dirt"},{"x":-9,"y":2,"z":-12,"name":"Soil_Dirt"},{"x":-9,"y":3,"z":-12,"name":"Soil_Dirt"},{"x":-9,"y":4,"z":-12,"name":"Soil_Dirt"},{"x":-9,"y":5,"z":-12,"name":"Soil_Snow"},{"x":-9,"y":11,"z":-12,"name":"WinterHoliday_Garland","support":15,"rotation":2},{"x":-9,"y":0,"z":-11,"name":"Soil_Dirt"},{"x":-9,"y":1,"z":-11,"name":"Soil_Dirt"},{"x":-9,"y":2,"z":-11,"name":"Soil_Dirt"},{"x":-9,"y":3,"z":-11,"name":"Soil_Dirt"},{"x":-9,"y":4,"z":-11,"name":"Soil_Dirt"},{"x":-9,"y":5,"z":-11,"name":"Soil_Snow"},{"x":-9,"y":11,"z":-11,"name":"Wood_Fir_Trunk","support":15,"rotation":5},{"x":-9,"y":12,"z":-11,"name":"Wood_Darkwood_Roof_Flat","support":15,"rotation":2},{"x":-9,"y":0,"z":-10,"name":"Soil_Dirt"},{"x":-9,"y":1,"z":-10,"name":"Soil_Dirt"},{"x":-9,"y":2,"z":-10,"name":"Soil_Dirt"},{"x":-9,"y":3,"z":-10,"name":"Soil_Dirt"},{"x":-9,"y":4,"z":-10,"name":"Soil_Dirt"},{"x":-9,"y":5,"z":-10,"name":"Soil_Snow"},{"x":-9,"y":11,"z":-10,"name":"WinterHoliday_Lights","support":15},{"x":-9,"y":0,"z":-9,"name":"Soil_Dirt"},{"x":-9,"y":1,"z":-9,"name":"Soil_Dirt"},{"x":-9,"y":2,"z":-9,"name":"Soil_Dirt"},{"x":-9,"y":3,"z":-9,"name":"Soil_Dirt"},{"x":-9,"y":4,"z":-9,"name":"Soil_Dirt"},{"x":-9,"y":5,"z":-9,"name":"Soil_Snow"},{"x":-9,"y":0,"z":-8,"name":"Soil_Dirt"},{"x":-9,"y":1,"z":-8,"name":"Soil_Dirt"},{"x":-9,"y":2,"z":-8,"name":"Soil_Dirt"},{"x":-9,"y":3,"z":-8,"name":"Soil_Dirt"},{"x":-9,"y":4,"z":-8,"name":"Soil_Dirt"},{"x":-9,"y":5,"z":-8,"name":"Soil_Snow"},{"x":-9,"y":0,"z":-7,"name":"Soil_Dirt"},{"x":-9,"y":1,"z":-7,"name":"Soil_Dirt"},{"x":-9,"y":2,"z":-7,"name":"Soil_Dirt"},{"x":-9,"y":3,"z":-7,"name":"Soil_Dirt"},{"x":-9,"y":4,"z":-7,"name":"Soil_Dirt"},{"x":-9,"y":5,"z":-7,"name":"Soil_Snow"},{"x":-9,"y":0,"z":-6,"name":"Soil_Dirt"},{"x":-9,"y":1,"z":-6,"name":"Soil_Dirt"},{"x":-9,"y":2,"z":-6,"name":"Soil_Dirt"},{"x":-9,"y":3,"z":-6,"name":"Soil_Dirt"},{"x":-9,"y":4,"z":-6,"name":"Soil_Dirt"},{"x":-9,"y":5,"z":-6,"name":"Soil_Snow"},{"x":-9,"y":0,"z":-5,"name":"Soil_Dirt"},{"x":-9,"y":1,"z":-5,"name":"Soil_Dirt"},{"x":-9,"y":2,"z":-5,"name":"Soil_Dirt"},{"x":-9,"y":3,"z":-5,"name":"Soil_Dirt"},{"x":-9,"y":4,"z":-5,"name":"Soil_Dirt"},{"x":-9,"y":5,"z":-5,"name":"Soil_Snow"},{"x":-9,"y":0,"z":-4,"name":"Soil_Dirt"},{"x":-9,"y":1,"z":-4,"name":"Soil_Dirt"},{"x":-9,"y":2,"z":-4,"name":"Soil_Dirt"},{"x":-9,"y":3,"z":-4,"name":"Soil_Dirt"},{"x":-9,"y":4,"z":-4,"name":"Soil_Dirt"},{"x":-9,"y":5,"z":-4,"name":"Soil_Snow"},{"x":-9,"y":0,"z":-3,"name":"Soil_Dirt"},{"x":-9,"y":1,"z":-3,"name":"Soil_Dirt"},{"x":-9,"y":2,"z":-3,"name":"Soil_Dirt"},{"x":-9,"y":3,"z":-3,"name":"Soil_Dirt"},{"x":-9,"y":4,"z":-3,"name":"Soil_Dirt"},{"x":-9,"y":5,"z":-3,"name":"Soil_Snow"},{"x":-9,"y":0,"z":-2,"name":"Soil_Dirt"},{"x":-9,"y":1,"z":-2,"name":"Soil_Dirt"},{"x":-9,"y":2,"z":-2,"name":"Soil_Dirt"},{"x":-9,"y":3,"z":-2,"name":"Soil_Dirt"},{"x":-9,"y":4,"z":-2,"name":"Soil_Dirt"},{"x":-9,"y":5,"z":-2,"name":"Soil_Snow"},{"x":-9,"y":0,"z":-1,"name":"Soil_Dirt"},{"x":-9,"y":1,"z":-1,"name":"Soil_Dirt"},{"x":-9,"y":2,"z":-1,"name":"Soil_Dirt"},{"x":-9,"y":3,"z":-1,"name":"Soil_Dirt"},{"x":-9,"y":4,"z":-1,"name":"Soil_Dirt"},{"x":-9,"y":5,"z":-1,"name":"Soil_Snow"},{"x":-9,"y":0,"z":0,"name":"Soil_Dirt"},{"x":-9,"y":1,"z":0,"name":"Soil_Dirt"},{"x":-9,"y":2,"z":0,"name":"Soil_Dirt"},{"x":-9,"y":3,"z":0,"name":"Soil_Dirt"},{"x":-9,"y":4,"z":0,"name":"Soil_Dirt"},{"x":-9,"y":5,"z":0,"name":"Rock_Calcite_Brick","support":15},{"x":-9,"y":0,"z":1,"name":"Soil_Dirt"},{"x":-9,"y":1,"z":1,"name":"Soil_Dirt"},{"x":-9,"y":2,"z":1,"name":"Soil_Dirt"},{"x":-9,"y":3,"z":1,"name":"Soil_Dirt"},{"x":-9,"y":4,"z":1,"name":"Soil_Dirt"},{"x":-9,"y":5,"z":1,"name":"Rock_Calcite_Brick","support":15},{"x":-9,"y":0,"z":2,"name":"Soil_Dirt"},{"x":-9,"y":1,"z":2,"name":"Soil_Dirt"},{"x":-9,"y":2,"z":2,"name":"Soil_Dirt"},{"x":-9,"y":3,"z":2,"name":"Soil_Dirt"},{"x":-9,"y":4,"z":2,"name":"Soil_Dirt"},{"x":-9,"y":5,"z":2,"name":"Soil_Snow"},{"x":-9,"y":0,"z":3,"name":"Soil_Dirt"},{"x":-9,"y":1,"z":3,"name":"Soil_Dirt"},{"x":-9,"y":2,"z":3,"name":"Soil_Dirt"},{"x":-9,"y":3,"z":3,"name":"Soil_Dirt"},{"x":-9,"y":4,"z":3,"name":"Soil_Dirt"},{"x":-9,"y":5,"z":3,"name":"Soil_Snow"},{"x":-9,"y":0,"z":4,"name":"Soil_Dirt"},{"x":-9,"y":1,"z":4,"name":"Soil_Dirt"},{"x":-9,"y":2,"z":4,"name":"Soil_Dirt"},{"x":-9,"y":3,"z":4,"name":"Soil_Dirt"},{"x":-9,"y":4,"z":4,"name":"Soil_Dirt"},{"x":-9,"y":5,"z":4,"name":"Soil_Snow"},{"x":-9,"y":0,"z":5,"name":"Soil_Dirt"},{"x":-9,"y":1,"z":5,"name":"Soil_Dirt"},{"x":-9,"y":2,"z":5,"name":"Soil_Dirt"},{"x":-9,"y":3,"z":5,"name":"Soil_Dirt"},{"x":-9,"y":4,"z":5,"name":"Soil_Dirt"},{"x":-9,"y":5,"z":5,"name":"Soil_Snow"},{"x":-9,"y":0,"z":6,"name":"Soil_Dirt"},{"x":-9,"y":1,"z":6,"name":"Soil_Dirt"},{"x":-9,"y":2,"z":6,"name":"Soil_Dirt"},{"x":-9,"y":3,"z":6,"name":"Soil_Dirt"},{"x":-9,"y":4,"z":6,"name":"Soil_Dirt"},{"x":-9,"y":5,"z":6,"name":"Soil_Snow"},{"x":-9,"y":0,"z":7,"name":"Soil_Dirt"},{"x":-9,"y":1,"z":7,"name":"Soil_Dirt"},{"x":-9,"y":2,"z":7,"name":"Soil_Dirt"},{"x":-9,"y":3,"z":7,"name":"Soil_Dirt"},{"x":-9,"y":4,"z":7,"name":"Soil_Dirt"},{"x":-9,"y":5,"z":7,"name":"Soil_Snow"},{"x":-9,"y":0,"z":8,"name":"Soil_Dirt"},{"x":-9,"y":1,"z":8,"name":"Soil_Dirt"},{"x":-9,"y":2,"z":8,"name":"Soil_Dirt"},{"x":-9,"y":3,"z":8,"name":"Soil_Dirt"},{"x":-9,"y":4,"z":8,"name":"Soil_Dirt"},{"x":-9,"y":5,"z":8,"name":"Soil_Snow"},{"x":-9,"y":0,"z":9,"name":"Soil_Dirt"},{"x":-9,"y":1,"z":9,"name":"Soil_Dirt"},{"x":-9,"y":2,"z":9,"name":"Soil_Dirt"},{"x":-9,"y":3,"z":9,"name":"Soil_Dirt"},{"x":-9,"y":4,"z":9,"name":"Soil_Dirt"},{"x":-9,"y":5,"z":9,"name":"Soil_Snow"},{"x":-9,"y":0,"z":10,"name":"Soil_Dirt"},{"x":-9,"y":1,"z":10,"name":"Soil_Dirt"},{"x":-9,"y":2,"z":10,"name":"Soil_Dirt"},{"x":-9,"y":3,"z":10,"name":"Soil_Dirt"},{"x":-9,"y":4,"z":10,"name":"Soil_Dirt"},{"x":-9,"y":5,"z":10,"name":"Soil_Snow"},{"x":-9,"y":0,"z":11,"name":"Soil_Dirt"},{"x":-9,"y":1,"z":11,"name":"Soil_Dirt"},{"x":-9,"y":2,"z":11,"name":"Soil_Dirt"},{"x":-9,"y":3,"z":11,"name":"Soil_Dirt"},{"x":-9,"y":4,"z":11,"name":"Soil_Dirt"},{"x":-9,"y":5,"z":11,"name":"Soil_Snow"},{"x":-9,"y":11,"z":11,"name":"WinterHoliday_Lights","support":15,"rotation":2},{"x":-9,"y":0,"z":12,"name":"Soil_Dirt"},{"x":-9,"y":1,"z":12,"name":"Soil_Dirt"},{"x":-9,"y":2,"z":12,"name":"Soil_Dirt"},{"x":-9,"y":3,"z":12,"name":"Soil_Dirt"},{"x":-9,"y":4,"z":12,"name":"Soil_Dirt"},{"x":-9,"y":5,"z":12,"name":"Soil_Snow"},{"x":-9,"y":11,"z":12,"name":"Wood_Fir_Trunk","support":15,"rotation":7},{"x":-9,"y":12,"z":12,"name":"Wood_Darkwood_Roof_Flat","support":15},{"x":-9,"y":0,"z":13,"name":"Soil_Dirt"},{"x":-9,"y":1,"z":13,"name":"Soil_Dirt"},{"x":-9,"y":2,"z":13,"name":"Soil_Dirt"},{"x":-9,"y":3,"z":13,"name":"Soil_Dirt"},{"x":-9,"y":4,"z":13,"name":"Soil_Dirt"},{"x":-9,"y":5,"z":13,"name":"Soil_Snow"},{"x":-9,"y":11,"z":13,"name":"WinterHoliday_Garland","support":15},{"x":-9,"y":0,"z":14,"name":"Soil_Dirt"},{"x":-9,"y":1,"z":14,"name":"Soil_Dirt"},{"x":-9,"y":2,"z":14,"name":"Soil_Dirt"},{"x":-9,"y":3,"z":14,"name":"Soil_Dirt"},{"x":-9,"y":4,"z":14,"name":"Soil_Dirt"},{"x":-9,"y":5,"z":14,"name":"Soil_Snow"},{"x":-9,"y":0,"z":15,"name":"Soil_Dirt"},{"x":-9,"y":1,"z":15,"name":"Soil_Dirt"},{"x":-9,"y":2,"z":15,"name":"Soil_Dirt"},{"x":-9,"y":3,"z":15,"name":"Soil_Dirt"},{"x":-9,"y":4,"z":15,"name":"Soil_Dirt"},{"x":-9,"y":5,"z":15,"name":"Rock_Stone_Brick_Smooth"},{"x":-8,"y":0,"z":-14,"name":"Soil_Dirt"},{"x":-8,"y":1,"z":-14,"name":"Soil_Dirt"},{"x":-8,"y":2,"z":-14,"name":"Soil_Dirt"},{"x":-8,"y":3,"z":-14,"name":"Soil_Dirt"},{"x":-8,"y":4,"z":-14,"name":"Soil_Dirt"},{"x":-8,"y":5,"z":-14,"name":"Rock_Stone_Brick_Smooth"},{"x":-8,"y":0,"z":-13,"name":"Soil_Dirt"},{"x":-8,"y":1,"z":-13,"name":"Soil_Dirt"},{"x":-8,"y":2,"z":-13,"name":"Soil_Dirt"},{"x":-8,"y":3,"z":-13,"name":"Soil_Dirt"},{"x":-8,"y":4,"z":-13,"name":"Soil_Dirt"},{"x":-8,"y":5,"z":-13,"name":"Soil_Snow"},{"x":-8,"y":0,"z":-12,"name":"Soil_Dirt"},{"x":-8,"y":1,"z":-12,"name":"Soil_Dirt"},{"x":-8,"y":2,"z":-12,"name":"Soil_Dirt"},{"x":-8,"y":3,"z":-12,"name":"Soil_Dirt"},{"x":-8,"y":4,"z":-12,"name":"Soil_Dirt"},{"x":-8,"y":5,"z":-12,"name":"Soil_Snow"},{"x":-8,"y":11,"z":-12,"name":"WinterHoliday_Garland","support":15,"rotation":2},{"x":-8,"y":0,"z":-11,"name":"Soil_Dirt"},{"x":-8,"y":1,"z":-11,"name":"Soil_Dirt"},{"x":-8,"y":2,"z":-11,"name":"Soil_Dirt"},{"x":-8,"y":3,"z":-11,"name":"Soil_Dirt"},{"x":-8,"y":4,"z":-11,"name":"Soil_Dirt"},{"x":-8,"y":5,"z":-11,"name":"Soil_Snow"},{"x":-8,"y":11,"z":-11,"name":"Wood_Fir_Trunk","support":15,"rotation":5},{"x":-8,"y":12,"z":-11,"name":"Wood_Darkwood_Roof_Flat","support":15,"rotation":2},{"x":-8,"y":0,"z":-10,"name":"Soil_Dirt"},{"x":-8,"y":1,"z":-10,"name":"Soil_Dirt"},{"x":-8,"y":2,"z":-10,"name":"Soil_Dirt"},{"x":-8,"y":3,"z":-10,"name":"Soil_Dirt"},{"x":-8,"y":4,"z":-10,"name":"Soil_Dirt"},{"x":-8,"y":5,"z":-10,"name":"Soil_Snow"},{"x":-8,"y":11,"z":-10,"name":"WinterHoliday_Lights","support":15},{"x":-8,"y":0,"z":-9,"name":"Soil_Dirt"},{"x":-8,"y":1,"z":-9,"name":"Soil_Dirt"},{"x":-8,"y":2,"z":-9,"name":"Soil_Dirt"},{"x":-8,"y":3,"z":-9,"name":"Soil_Dirt"},{"x":-8,"y":4,"z":-9,"name":"Soil_Dirt"},{"x":-8,"y":5,"z":-9,"name":"Soil_Snow"},{"x":-8,"y":0,"z":-8,"name":"Soil_Dirt"},{"x":-8,"y":1,"z":-8,"name":"Soil_Dirt"},{"x":-8,"y":2,"z":-8,"name":"Soil_Dirt"},{"x":-8,"y":3,"z":-8,"name":"Soil_Dirt"},{"x":-8,"y":4,"z":-8,"name":"Soil_Dirt"},{"x":-8,"y":5,"z":-8,"name":"Soil_Snow"},{"x":-8,"y":0,"z":-7,"name":"Soil_Dirt"},{"x":-8,"y":1,"z":-7,"name":"Soil_Dirt"},{"x":-8,"y":2,"z":-7,"name":"Soil_Dirt"},{"x":-8,"y":3,"z":-7,"name":"Soil_Dirt"},{"x":-8,"y":4,"z":-7,"name":"Soil_Dirt"},{"x":-8,"y":5,"z":-7,"name":"Soil_Snow"},{"x":-8,"y":0,"z":-6,"name":"Soil_Dirt"},{"x":-8,"y":1,"z":-6,"name":"Soil_Dirt"},{"x":-8,"y":2,"z":-6,"name":"Soil_Dirt"},{"x":-8,"y":3,"z":-6,"name":"Soil_Dirt"},{"x":-8,"y":4,"z":-6,"name":"Soil_Dirt"},{"x":-8,"y":5,"z":-6,"name":"Soil_Snow"},{"x":-8,"y":0,"z":-5,"name":"Soil_Dirt"},{"x":-8,"y":1,"z":-5,"name":"Soil_Dirt"},{"x":-8,"y":2,"z":-5,"name":"Soil_Dirt"},{"x":-8,"y":3,"z":-5,"name":"Soil_Dirt"},{"x":-8,"y":4,"z":-5,"name":"Soil_Dirt"},{"x":-8,"y":5,"z":-5,"name":"Soil_Snow"},{"x":-8,"y":0,"z":-4,"name":"Soil_Dirt"},{"x":-8,"y":1,"z":-4,"name":"Soil_Dirt"},{"x":-8,"y":2,"z":-4,"name":"Soil_Dirt"},{"x":-8,"y":3,"z":-4,"name":"Soil_Dirt"},{"x":-8,"y":4,"z":-4,"name":"Soil_Dirt"},{"x":-8,"y":5,"z":-4,"name":"Soil_Snow"},{"x":-8,"y":0,"z":-3,"name":"Soil_Dirt"},{"x":-8,"y":1,"z":-3,"name":"Soil_Dirt"},{"x":-8,"y":2,"z":-3,"name":"Soil_Dirt"},{"x":-8,"y":3,"z":-3,"name":"Soil_Dirt"},{"x":-8,"y":4,"z":-3,"name":"Soil_Dirt"},{"x":-8,"y":5,"z":-3,"name":"Soil_Snow"},{"x":-8,"y":0,"z":-2,"name":"Soil_Dirt"},{"x":-8,"y":1,"z":-2,"name":"Soil_Dirt"},{"x":-8,"y":2,"z":-2,"name":"Soil_Dirt"},{"x":-8,"y":3,"z":-2,"name":"Soil_Dirt"},{"x":-8,"y":4,"z":-2,"name":"Soil_Dirt"},{"x":-8,"y":5,"z":-2,"name":"Soil_Snow"},{"x":-8,"y":0,"z":-1,"name":"Soil_Dirt"},{"x":-8,"y":1,"z":-1,"name":"Soil_Dirt"},{"x":-8,"y":2,"z":-1,"name":"Soil_Dirt"},{"x":-8,"y":3,"z":-1,"name":"Soil_Dirt"},{"x":-8,"y":4,"z":-1,"name":"Soil_Dirt"},{"x":-8,"y":5,"z":-1,"name":"Soil_Snow"},{"x":-8,"y":0,"z":0,"name":"Soil_Dirt"},{"x":-8,"y":1,"z":0,"name":"Soil_Dirt"},{"x":-8,"y":2,"z":0,"name":"Soil_Dirt"},{"x":-8,"y":3,"z":0,"name":"Soil_Dirt"},{"x":-8,"y":4,"z":0,"name":"Soil_Dirt"},{"x":-8,"y":5,"z":0,"name":"Rock_Calcite_Brick","support":15},{"x":-8,"y":0,"z":1,"name":"Soil_Dirt"},{"x":-8,"y":1,"z":1,"name":"Soil_Dirt"},{"x":-8,"y":2,"z":1,"name":"Soil_Dirt"},{"x":-8,"y":3,"z":1,"name":"Soil_Dirt"},{"x":-8,"y":4,"z":1,"name":"Soil_Dirt"},{"x":-8,"y":5,"z":1,"name":"Rock_Calcite_Brick","support":15},{"x":-8,"y":0,"z":2,"name":"Soil_Dirt"},{"x":-8,"y":1,"z":2,"name":"Soil_Dirt"},{"x":-8,"y":2,"z":2,"name":"Soil_Dirt"},{"x":-8,"y":3,"z":2,"name":"Soil_Dirt"},{"x":-8,"y":4,"z":2,"name":"Soil_Dirt"},{"x":-8,"y":5,"z":2,"name":"Soil_Snow"},{"x":-8,"y":0,"z":3,"name":"Soil_Dirt"},{"x":-8,"y":1,"z":3,"name":"Soil_Dirt"},{"x":-8,"y":2,"z":3,"name":"Soil_Dirt"},{"x":-8,"y":3,"z":3,"name":"Soil_Dirt"},{"x":-8,"y":4,"z":3,"name":"Soil_Dirt"},{"x":-8,"y":5,"z":3,"name":"Soil_Snow"},{"x":-8,"y":0,"z":4,"name":"Soil_Dirt"},{"x":-8,"y":1,"z":4,"name":"Soil_Dirt"},{"x":-8,"y":2,"z":4,"name":"Soil_Dirt"},{"x":-8,"y":3,"z":4,"name":"Soil_Dirt"},{"x":-8,"y":4,"z":4,"name":"Soil_Dirt"},{"x":-8,"y":5,"z":4,"name":"Soil_Snow"},{"x":-8,"y":0,"z":5,"name":"Soil_Dirt"},{"x":-8,"y":1,"z":5,"name":"Soil_Dirt"},{"x":-8,"y":2,"z":5,"name":"Soil_Dirt"},{"x":-8,"y":3,"z":5,"name":"Soil_Dirt"},{"x":-8,"y":4,"z":5,"name":"Soil_Dirt"},{"x":-8,"y":5,"z":5,"name":"Soil_Snow"},{"x":-8,"y":0,"z":6,"name":"Soil_Dirt"},{"x":-8,"y":1,"z":6,"name":"Soil_Dirt"},{"x":-8,"y":2,"z":6,"name":"Soil_Dirt"},{"x":-8,"y":3,"z":6,"name":"Soil_Dirt"},{"x":-8,"y":4,"z":6,"name":"Soil_Dirt"},{"x":-8,"y":5,"z":6,"name":"Soil_Snow"},{"x":-8,"y":0,"z":7,"name":"Soil_Dirt"},{"x":-8,"y":1,"z":7,"name":"Soil_Dirt"},{"x":-8,"y":2,"z":7,"name":"Soil_Dirt"},{"x":-8,"y":3,"z":7,"name":"Soil_Dirt"},{"x":-8,"y":4,"z":7,"name":"Soil_Dirt"},{"x":-8,"y":5,"z":7,"name":"Soil_Snow"},{"x":-8,"y":0,"z":8,"name":"Soil_Dirt"},{"x":-8,"y":1,"z":8,"name":"Soil_Dirt"},{"x":-8,"y":2,"z":8,"name":"Soil_Dirt"},{"x":-8,"y":3,"z":8,"name":"Soil_Dirt"},{"x":-8,"y":4,"z":8,"name":"Soil_Dirt"},{"x":-8,"y":5,"z":8,"name":"Soil_Snow"},{"x":-8,"y":6,"z":8,"name":"WinterHoliday_Snowman","support":15,"rotation":1},{"x":-8,"y":7,"z":8,"name":"WinterHoliday_Snowman","filler":1024,"rotation":1},{"x":-8,"y":0,"z":9,"name":"Soil_Dirt"},{"x":-8,"y":1,"z":9,"name":"Soil_Dirt"},{"x":-8,"y":2,"z":9,"name":"Soil_Dirt"},{"x":-8,"y":3,"z":9,"name":"Soil_Dirt"},{"x":-8,"y":4,"z":9,"name":"Soil_Dirt"},{"x":-8,"y":5,"z":9,"name":"Soil_Snow"},{"x":-8,"y":0,"z":10,"name":"Soil_Dirt"},{"x":-8,"y":1,"z":10,"name":"Soil_Dirt"},{"x":-8,"y":2,"z":10,"name":"Soil_Dirt"},{"x":-8,"y":3,"z":10,"name":"Soil_Dirt"},{"x":-8,"y":4,"z":10,"name":"Soil_Dirt"},{"x":-8,"y":5,"z":10,"name":"Soil_Snow"},{"x":-8,"y":0,"z":11,"name":"Soil_Dirt"},{"x":-8,"y":1,"z":11,"name":"Soil_Dirt"},{"x":-8,"y":2,"z":11,"name":"Soil_Dirt"},{"x":-8,"y":3,"z":11,"name":"Soil_Dirt"},{"x":-8,"y":4,"z":11,"name":"Soil_Dirt"},{"x":-8,"y":5,"z":11,"name":"Soil_Snow"},{"x":-8,"y":11,"z":11,"name":"WinterHoliday_Lights","support":15,"rotation":2},{"x":-8,"y":0,"z":12,"name":"Soil_Dirt"},{"x":-8,"y":1,"z":12,"name":"Soil_Dirt"},{"x":-8,"y":2,"z":12,"name":"Soil_Dirt"},{"x":-8,"y":3,"z":12,"name":"Soil_Dirt"},{"x":-8,"y":4,"z":12,"name":"Soil_Dirt"},{"x":-8,"y":5,"z":12,"name":"Soil_Snow"},{"x":-8,"y":11,"z":12,"name":"Wood_Fir_Trunk","support":15,"rotation":7},{"x":-8,"y":12,"z":12,"name":"Wood_Darkwood_Roof_Flat","support":15},{"x":-8,"y":0,"z":13,"name":"Soil_Dirt"},{"x":-8,"y":1,"z":13,"name":"Soil_Dirt"},{"x":-8,"y":2,"z":13,"name":"Soil_Dirt"},{"x":-8,"y":3,"z":13,"name":"Soil_Dirt"},{"x":-8,"y":4,"z":13,"name":"Soil_Dirt"},{"x":-8,"y":5,"z":13,"name":"Soil_Snow"},{"x":-8,"y":11,"z":13,"name":"WinterHoliday_Garland","support":15},{"x":-8,"y":0,"z":14,"name":"Soil_Dirt"},{"x":-8,"y":1,"z":14,"name":"Soil_Dirt"},{"x":-8,"y":2,"z":14,"name":"Soil_Dirt"},{"x":-8,"y":3,"z":14,"name":"Soil_Dirt"},{"x":-8,"y":4,"z":14,"name":"Soil_Dirt"},{"x":-8,"y":5,"z":14,"name":"Soil_Snow"},{"x":-8,"y":0,"z":15,"name":"Soil_Dirt"},{"x":-8,"y":1,"z":15,"name":"Soil_Dirt"},{"x":-8,"y":2,"z":15,"name":"Soil_Dirt"},{"x":-8,"y":3,"z":15,"name":"Soil_Dirt"},{"x":-8,"y":4,"z":15,"name":"Soil_Dirt"},{"x":-8,"y":5,"z":15,"name":"Rock_Stone_Brick_Smooth"},{"x":-7,"y":0,"z":-14,"name":"Soil_Dirt"},{"x":-7,"y":1,"z":-14,"name":"Soil_Dirt"},{"x":-7,"y":2,"z":-14,"name":"Soil_Dirt"},{"x":-7,"y":3,"z":-14,"name":"Soil_Dirt"},{"x":-7,"y":4,"z":-14,"name":"Soil_Dirt"},{"x":-7,"y":5,"z":-14,"name":"Rock_Stone_Brick_Smooth"},{"x":-7,"y":0,"z":-13,"name":"Soil_Dirt"},{"x":-7,"y":1,"z":-13,"name":"Soil_Dirt"},{"x":-7,"y":2,"z":-13,"name":"Soil_Dirt"},{"x":-7,"y":3,"z":-13,"name":"Soil_Dirt"},{"x":-7,"y":4,"z":-13,"name":"Soil_Dirt"},{"x":-7,"y":5,"z":-13,"name":"Soil_Snow"},{"x":-7,"y":0,"z":-12,"name":"Soil_Dirt"},{"x":-7,"y":1,"z":-12,"name":"Soil_Dirt"},{"x":-7,"y":2,"z":-12,"name":"Soil_Dirt"},{"x":-7,"y":3,"z":-12,"name":"Soil_Dirt"},{"x":-7,"y":4,"z":-12,"name":"Soil_Dirt"},{"x":-7,"y":5,"z":-12,"name":"Soil_Snow"},{"x":-7,"y":11,"z":-12,"name":"WinterHoliday_Garland","support":15,"rotation":2},{"x":-7,"y":0,"z":-11,"name":"Soil_Dirt"},{"x":-7,"y":1,"z":-11,"name":"Soil_Dirt"},{"x":-7,"y":2,"z":-11,"name":"Soil_Dirt"},{"x":-7,"y":3,"z":-11,"name":"Soil_Dirt"},{"x":-7,"y":4,"z":-11,"name":"Soil_Dirt"},{"x":-7,"y":5,"z":-11,"name":"Soil_Snow"},{"x":-7,"y":11,"z":-11,"name":"Wood_Fir_Trunk","support":15,"rotation":5},{"x":-7,"y":12,"z":-11,"name":"Wood_Darkwood_Roof_Flat","support":15,"rotation":2},{"x":-7,"y":0,"z":-10,"name":"Soil_Dirt"},{"x":-7,"y":1,"z":-10,"name":"Soil_Dirt"},{"x":-7,"y":2,"z":-10,"name":"Soil_Dirt"},{"x":-7,"y":3,"z":-10,"name":"Soil_Dirt"},{"x":-7,"y":4,"z":-10,"name":"Soil_Dirt"},{"x":-7,"y":5,"z":-10,"name":"Soil_Snow"},{"x":-7,"y":11,"z":-10,"name":"WinterHoliday_Lights","support":15},{"x":-7,"y":0,"z":-9,"name":"Soil_Dirt"},{"x":-7,"y":1,"z":-9,"name":"Soil_Dirt"},{"x":-7,"y":2,"z":-9,"name":"Soil_Dirt"},{"x":-7,"y":3,"z":-9,"name":"Soil_Dirt"},{"x":-7,"y":4,"z":-9,"name":"Soil_Dirt"},{"x":-7,"y":5,"z":-9,"name":"Soil_Snow"},{"x":-7,"y":0,"z":-8,"name":"Soil_Dirt"},{"x":-7,"y":1,"z":-8,"name":"Soil_Dirt"},{"x":-7,"y":2,"z":-8,"name":"Soil_Dirt"},{"x":-7,"y":3,"z":-8,"name":"Soil_Dirt"},{"x":-7,"y":4,"z":-8,"name":"Soil_Dirt"},{"x":-7,"y":5,"z":-8,"name":"Soil_Snow"},{"x":-7,"y":0,"z":-7,"name":"Soil_Dirt"},{"x":-7,"y":1,"z":-7,"name":"Soil_Dirt"},{"x":-7,"y":2,"z":-7,"name":"Soil_Dirt"},{"x":-7,"y":3,"z":-7,"name":"Soil_Dirt"},{"x":-7,"y":4,"z":-7,"name":"Soil_Dirt"},{"x":-7,"y":5,"z":-7,"name":"Soil_Snow"},{"x":-7,"y":0,"z":-6,"name":"Soil_Dirt"},{"x":-7,"y":1,"z":-6,"name":"Soil_Dirt"},{"x":-7,"y":2,"z":-6,"name":"Soil_Dirt"},{"x":-7,"y":3,"z":-6,"name":"Soil_Dirt"},{"x":-7,"y":4,"z":-6,"name":"Soil_Dirt"},{"x":-7,"y":5,"z":-6,"name":"Soil_Snow"},{"x":-7,"y":0,"z":-5,"name":"Soil_Dirt"},{"x":-7,"y":1,"z":-5,"name":"Soil_Dirt"},{"x":-7,"y":2,"z":-5,"name":"Soil_Dirt"},{"x":-7,"y":3,"z":-5,"name":"Soil_Dirt"},{"x":-7,"y":4,"z":-5,"name":"Soil_Dirt"},{"x":-7,"y":5,"z":-5,"name":"Soil_Snow"},{"x":-7,"y":0,"z":-4,"name":"Soil_Dirt"},{"x":-7,"y":1,"z":-4,"name":"Soil_Dirt"},{"x":-7,"y":2,"z":-4,"name":"Soil_Dirt"},{"x":-7,"y":3,"z":-4,"name":"Soil_Dirt"},{"x":-7,"y":4,"z":-4,"name":"Soil_Dirt"},{"x":-7,"y":5,"z":-4,"name":"Soil_Snow"},{"x":-7,"y":0,"z":-3,"name":"Soil_Dirt"},{"x":-7,"y":1,"z":-3,"name":"Soil_Dirt"},{"x":-7,"y":2,"z":-3,"name":"Soil_Dirt"},{"x":-7,"y":3,"z":-3,"name":"Soil_Dirt"},{"x":-7,"y":4,"z":-3,"name":"Soil_Dirt"},{"x":-7,"y":5,"z":-3,"name":"Soil_Snow"},{"x":-7,"y":0,"z":-2,"name":"Soil_Dirt"},{"x":-7,"y":1,"z":-2,"name":"Soil_Dirt"},{"x":-7,"y":2,"z":-2,"name":"Soil_Dirt"},{"x":-7,"y":3,"z":-2,"name":"Soil_Dirt"},{"x":-7,"y":4,"z":-2,"name":"Soil_Dirt"},{"x":-7,"y":5,"z":-2,"name":"Soil_Snow"},{"x":-7,"y":0,"z":-1,"name":"Soil_Dirt"},{"x":-7,"y":1,"z":-1,"name":"Soil_Dirt"},{"x":-7,"y":2,"z":-1,"name":"Soil_Dirt"},{"x":-7,"y":3,"z":-1,"name":"Soil_Dirt"},{"x":-7,"y":4,"z":-1,"name":"Soil_Dirt"},{"x":-7,"y":5,"z":-1,"name":"Soil_Snow"},{"x":-7,"y":0,"z":0,"name":"Soil_Dirt"},{"x":-7,"y":1,"z":0,"name":"Soil_Dirt"},{"x":-7,"y":2,"z":0,"name":"Soil_Dirt"},{"x":-7,"y":3,"z":0,"name":"Soil_Dirt"},{"x":-7,"y":4,"z":0,"name":"Soil_Dirt"},{"x":-7,"y":5,"z":0,"name":"Rock_Calcite_Brick","support":15},{"x":-7,"y":0,"z":1,"name":"Soil_Dirt"},{"x":-7,"y":1,"z":1,"name":"Soil_Dirt"},{"x":-7,"y":2,"z":1,"name":"Soil_Dirt"},{"x":-7,"y":3,"z":1,"name":"Soil_Dirt"},{"x":-7,"y":4,"z":1,"name":"Soil_Dirt"},{"x":-7,"y":5,"z":1,"name":"Rock_Calcite_Brick","support":15},{"x":-7,"y":0,"z":2,"name":"Soil_Dirt"},{"x":-7,"y":1,"z":2,"name":"Soil_Dirt"},{"x":-7,"y":2,"z":2,"name":"Soil_Dirt"},{"x":-7,"y":3,"z":2,"name":"Soil_Dirt"},{"x":-7,"y":4,"z":2,"name":"Soil_Dirt"},{"x":-7,"y":5,"z":2,"name":"Soil_Snow"},{"x":-7,"y":0,"z":3,"name":"Soil_Dirt"},{"x":-7,"y":1,"z":3,"name":"Soil_Dirt"},{"x":-7,"y":2,"z":3,"name":"Soil_Dirt"},{"x":-7,"y":3,"z":3,"name":"Soil_Dirt"},{"x":-7,"y":4,"z":3,"name":"Soil_Dirt"},{"x":-7,"y":5,"z":3,"name":"Soil_Snow"},{"x":-7,"y":0,"z":4,"name":"Soil_Dirt"},{"x":-7,"y":1,"z":4,"name":"Soil_Dirt"},{"x":-7,"y":2,"z":4,"name":"Soil_Dirt"},{"x":-7,"y":3,"z":4,"name":"Soil_Dirt"},{"x":-7,"y":4,"z":4,"name":"Soil_Dirt"},{"x":-7,"y":5,"z":4,"name":"Soil_Snow"},{"x":-7,"y":0,"z":5,"name":"Soil_Dirt"},{"x":-7,"y":1,"z":5,"name":"Soil_Dirt"},{"x":-7,"y":2,"z":5,"name":"Soil_Dirt"},{"x":-7,"y":3,"z":5,"name":"Soil_Dirt"},{"x":-7,"y":4,"z":5,"name":"Soil_Dirt"},{"x":-7,"y":5,"z":5,"name":"Soil_Snow"},{"x":-7,"y":0,"z":6,"name":"Soil_Dirt"},{"x":-7,"y":1,"z":6,"name":"Soil_Dirt"},{"x":-7,"y":2,"z":6,"name":"Soil_Dirt"},{"x":-7,"y":3,"z":6,"name":"Soil_Dirt"},{"x":-7,"y":4,"z":6,"name":"Soil_Dirt"},{"x":-7,"y":5,"z":6,"name":"Soil_Snow"},{"x":-7,"y":0,"z":7,"name":"Soil_Dirt"},{"x":-7,"y":1,"z":7,"name":"Soil_Dirt"},{"x":-7,"y":2,"z":7,"name":"Soil_Dirt"},{"x":-7,"y":3,"z":7,"name":"Soil_Dirt"},{"x":-7,"y":4,"z":7,"name":"Soil_Dirt"},{"x":-7,"y":5,"z":7,"name":"Soil_Snow"},{"x":-7,"y":0,"z":8,"name":"Soil_Dirt"},{"x":-7,"y":1,"z":8,"name":"Soil_Dirt"},{"x":-7,"y":2,"z":8,"name":"Soil_Dirt"},{"x":-7,"y":3,"z":8,"name":"Soil_Dirt"},{"x":-7,"y":4,"z":8,"name":"Soil_Dirt"},{"x":-7,"y":5,"z":8,"name":"Soil_Snow"},{"x":-7,"y":0,"z":9,"name":"Soil_Dirt"},{"x":-7,"y":1,"z":9,"name":"Soil_Dirt"},{"x":-7,"y":2,"z":9,"name":"Soil_Dirt"},{"x":-7,"y":3,"z":9,"name":"Soil_Dirt"},{"x":-7,"y":4,"z":9,"name":"Soil_Dirt"},{"x":-7,"y":5,"z":9,"name":"Soil_Snow"},{"x":-7,"y":0,"z":10,"name":"Soil_Dirt"},{"x":-7,"y":1,"z":10,"name":"Soil_Dirt"},{"x":-7,"y":2,"z":10,"name":"Soil_Dirt"},{"x":-7,"y":3,"z":10,"name":"Soil_Dirt"},{"x":-7,"y":4,"z":10,"name":"Soil_Dirt"},{"x":-7,"y":5,"z":10,"name":"Soil_Snow"},{"x":-7,"y":0,"z":11,"name":"Soil_Dirt"},{"x":-7,"y":1,"z":11,"name":"Soil_Dirt"},{"x":-7,"y":2,"z":11,"name":"Soil_Dirt"},{"x":-7,"y":3,"z":11,"name":"Soil_Dirt"},{"x":-7,"y":4,"z":11,"name":"Soil_Dirt"},{"x":-7,"y":5,"z":11,"name":"Soil_Snow"},{"x":-7,"y":11,"z":11,"name":"WinterHoliday_Lights","support":15,"rotation":2},{"x":-7,"y":0,"z":12,"name":"Soil_Dirt"},{"x":-7,"y":1,"z":12,"name":"Soil_Dirt"},{"x":-7,"y":2,"z":12,"name":"Soil_Dirt"},{"x":-7,"y":3,"z":12,"name":"Soil_Dirt"},{"x":-7,"y":4,"z":12,"name":"Soil_Dirt"},{"x":-7,"y":5,"z":12,"name":"Soil_Snow"},{"x":-7,"y":11,"z":12,"name":"Wood_Fir_Trunk","support":15,"rotation":7},{"x":-7,"y":12,"z":12,"name":"Wood_Darkwood_Roof_Flat","support":15},{"x":-7,"y":0,"z":13,"name":"Soil_Dirt"},{"x":-7,"y":1,"z":13,"name":"Soil_Dirt"},{"x":-7,"y":2,"z":13,"name":"Soil_Dirt"},{"x":-7,"y":3,"z":13,"name":"Soil_Dirt"},{"x":-7,"y":4,"z":13,"name":"Soil_Dirt"},{"x":-7,"y":5,"z":13,"name":"Soil_Snow"},{"x":-7,"y":11,"z":13,"name":"WinterHoliday_Garland","support":15},{"x":-7,"y":0,"z":14,"name":"Soil_Dirt"},{"x":-7,"y":1,"z":14,"name":"Soil_Dirt"},{"x":-7,"y":2,"z":14,"name":"Soil_Dirt"},{"x":-7,"y":3,"z":14,"name":"Soil_Dirt"},{"x":-7,"y":4,"z":14,"name":"Soil_Dirt"},{"x":-7,"y":5,"z":14,"name":"Soil_Snow"},{"x":-7,"y":0,"z":15,"name":"Soil_Dirt"},{"x":-7,"y":1,"z":15,"name":"Soil_Dirt"},{"x":-7,"y":2,"z":15,"name":"Soil_Dirt"},{"x":-7,"y":3,"z":15,"name":"Soil_Dirt"},{"x":-7,"y":4,"z":15,"name":"Soil_Dirt"},{"x":-7,"y":5,"z":15,"name":"Rock_Stone_Brick_Smooth"},{"x":-6,"y":0,"z":-14,"name":"Soil_Dirt"},{"x":-6,"y":1,"z":-14,"name":"Soil_Dirt"},{"x":-6,"y":2,"z":-14,"name":"Soil_Dirt"},{"x":-6,"y":3,"z":-14,"name":"Soil_Dirt"},{"x":-6,"y":4,"z":-14,"name":"Soil_Dirt"},{"x":-6,"y":5,"z":-14,"name":"Rock_Stone_Brick_Smooth"},{"x":-6,"y":0,"z":-13,"name":"Soil_Dirt"},{"x":-6,"y":1,"z":-13,"name":"Soil_Dirt"},{"x":-6,"y":2,"z":-13,"name":"Soil_Dirt"},{"x":-6,"y":3,"z":-13,"name":"Soil_Dirt"},{"x":-6,"y":4,"z":-13,"name":"Soil_Dirt"},{"x":-6,"y":5,"z":-13,"name":"Soil_Snow"},{"x":-6,"y":0,"z":-12,"name":"Soil_Dirt"},{"x":-6,"y":1,"z":-12,"name":"Soil_Dirt"},{"x":-6,"y":2,"z":-12,"name":"Soil_Dirt"},{"x":-6,"y":3,"z":-12,"name":"Soil_Dirt"},{"x":-6,"y":4,"z":-12,"name":"Soil_Dirt"},{"x":-6,"y":5,"z":-12,"name":"Soil_Snow"},{"x":-6,"y":11,"z":-12,"name":"WinterHoliday_Garland","support":15,"rotation":2},{"x":-6,"y":0,"z":-11,"name":"Soil_Dirt"},{"x":-6,"y":1,"z":-11,"name":"Soil_Dirt"},{"x":-6,"y":2,"z":-11,"name":"Soil_Dirt"},{"x":-6,"y":3,"z":-11,"name":"Soil_Dirt"},{"x":-6,"y":4,"z":-11,"name":"Soil_Dirt"},{"x":-6,"y":5,"z":-11,"name":"Soil_Snow"},{"x":-6,"y":11,"z":-11,"name":"Wood_Fir_Trunk","support":15,"rotation":5},{"x":-6,"y":12,"z":-11,"name":"Wood_Darkwood_Roof_Flat","support":15,"rotation":2},{"x":-6,"y":0,"z":-10,"name":"Soil_Dirt"},{"x":-6,"y":1,"z":-10,"name":"Soil_Dirt"},{"x":-6,"y":2,"z":-10,"name":"Soil_Dirt"},{"x":-6,"y":3,"z":-10,"name":"Soil_Dirt"},{"x":-6,"y":4,"z":-10,"name":"Soil_Dirt"},{"x":-6,"y":5,"z":-10,"name":"Soil_Snow"},{"x":-6,"y":11,"z":-10,"name":"WinterHoliday_Lights","support":15},{"x":-6,"y":0,"z":-9,"name":"Soil_Dirt"},{"x":-6,"y":1,"z":-9,"name":"Soil_Dirt"},{"x":-6,"y":2,"z":-9,"name":"Soil_Dirt"},{"x":-6,"y":3,"z":-9,"name":"Soil_Dirt"},{"x":-6,"y":4,"z":-9,"name":"Soil_Dirt"},{"x":-6,"y":5,"z":-9,"name":"Soil_Snow"},{"x":-6,"y":0,"z":-8,"name":"Soil_Dirt"},{"x":-6,"y":1,"z":-8,"name":"Soil_Dirt"},{"x":-6,"y":2,"z":-8,"name":"Soil_Dirt"},{"x":-6,"y":3,"z":-8,"name":"Soil_Dirt"},{"x":-6,"y":4,"z":-8,"name":"Soil_Dirt"},{"x":-6,"y":5,"z":-8,"name":"Soil_Snow"},{"x":-6,"y":0,"z":-7,"name":"Soil_Dirt"},{"x":-6,"y":1,"z":-7,"name":"Soil_Dirt"},{"x":-6,"y":2,"z":-7,"name":"Soil_Dirt"},{"x":-6,"y":3,"z":-7,"name":"Soil_Dirt"},{"x":-6,"y":4,"z":-7,"name":"Soil_Dirt"},{"x":-6,"y":5,"z":-7,"name":"Soil_Snow"},{"x":-6,"y":0,"z":-6,"name":"Soil_Dirt"},{"x":-6,"y":1,"z":-6,"name":"Soil_Dirt"},{"x":-6,"y":2,"z":-6,"name":"Soil_Dirt"},{"x":-6,"y":3,"z":-6,"name":"Soil_Dirt"},{"x":-6,"y":4,"z":-6,"name":"Soil_Dirt"},{"x":-6,"y":5,"z":-6,"name":"Soil_Snow"},{"x":-6,"y":0,"z":-5,"name":"Soil_Dirt"},{"x":-6,"y":1,"z":-5,"name":"Soil_Dirt"},{"x":-6,"y":2,"z":-5,"name":"Soil_Dirt"},{"x":-6,"y":3,"z":-5,"name":"Soil_Dirt"},{"x":-6,"y":4,"z":-5,"name":"Soil_Dirt"},{"x":-6,"y":5,"z":-5,"name":"Soil_Snow"},{"x":-6,"y":0,"z":-4,"name":"Soil_Dirt"},{"x":-6,"y":1,"z":-4,"name":"Soil_Dirt"},{"x":-6,"y":2,"z":-4,"name":"Soil_Dirt"},{"x":-6,"y":3,"z":-4,"name":"Soil_Dirt"},{"x":-6,"y":4,"z":-4,"name":"Soil_Dirt"},{"x":-6,"y":5,"z":-4,"name":"Soil_Snow"},{"x":-6,"y":0,"z":-3,"name":"Soil_Dirt"},{"x":-6,"y":1,"z":-3,"name":"Soil_Dirt"},{"x":-6,"y":2,"z":-3,"name":"Soil_Dirt"},{"x":-6,"y":3,"z":-3,"name":"Soil_Dirt"},{"x":-6,"y":4,"z":-3,"name":"Soil_Dirt"},{"x":-6,"y":5,"z":-3,"name":"Soil_Snow"},{"x":-6,"y":0,"z":-2,"name":"Soil_Dirt"},{"x":-6,"y":1,"z":-2,"name":"Soil_Dirt"},{"x":-6,"y":2,"z":-2,"name":"Soil_Dirt"},{"x":-6,"y":3,"z":-2,"name":"Soil_Dirt"},{"x":-6,"y":4,"z":-2,"name":"Soil_Dirt"},{"x":-6,"y":5,"z":-2,"name":"Rock_Calcite_Brick","support":15},{"x":-6,"y":0,"z":-1,"name":"Soil_Dirt"},{"x":-6,"y":1,"z":-1,"name":"Soil_Dirt"},{"x":-6,"y":2,"z":-1,"name":"Soil_Dirt"},{"x":-6,"y":3,"z":-1,"name":"Soil_Dirt"},{"x":-6,"y":4,"z":-1,"name":"Soil_Dirt"},{"x":-6,"y":5,"z":-1,"name":"Rock_Calcite_Brick","support":15},{"x":-6,"y":0,"z":0,"name":"Soil_Dirt"},{"x":-6,"y":1,"z":0,"name":"Soil_Dirt"},{"x":-6,"y":2,"z":0,"name":"Soil_Dirt"},{"x":-6,"y":3,"z":0,"name":"Soil_Dirt"},{"x":-6,"y":4,"z":0,"name":"Soil_Dirt"},{"x":-6,"y":5,"z":0,"name":"Rock_Calcite_Brick","support":15},{"x":-6,"y":0,"z":1,"name":"Soil_Dirt"},{"x":-6,"y":1,"z":1,"name":"Soil_Dirt"},{"x":-6,"y":2,"z":1,"name":"Soil_Dirt"},{"x":-6,"y":3,"z":1,"name":"Soil_Dirt"},{"x":-6,"y":4,"z":1,"name":"Soil_Dirt"},{"x":-6,"y":5,"z":1,"name":"Rock_Calcite_Brick","support":15},{"x":-6,"y":0,"z":2,"name":"Soil_Dirt"},{"x":-6,"y":1,"z":2,"name":"Soil_Dirt"},{"x":-6,"y":2,"z":2,"name":"Soil_Dirt"},{"x":-6,"y":3,"z":2,"name":"Soil_Dirt"},{"x":-6,"y":4,"z":2,"name":"Soil_Dirt"},{"x":-6,"y":5,"z":2,"name":"Rock_Calcite_Brick","support":15},{"x":-6,"y":0,"z":3,"name":"Soil_Dirt"},{"x":-6,"y":1,"z":3,"name":"Soil_Dirt"},{"x":-6,"y":2,"z":3,"name":"Soil_Dirt"},{"x":-6,"y":3,"z":3,"name":"Soil_Dirt"},{"x":-6,"y":4,"z":3,"name":"Soil_Dirt"},{"x":-6,"y":5,"z":3,"name":"Rock_Calcite_Brick","support":15},{"x":-6,"y":0,"z":4,"name":"Soil_Dirt"},{"x":-6,"y":1,"z":4,"name":"Soil_Dirt"},{"x":-6,"y":2,"z":4,"name":"Soil_Dirt"},{"x":-6,"y":3,"z":4,"name":"Soil_Dirt"},{"x":-6,"y":4,"z":4,"name":"Soil_Dirt"},{"x":-6,"y":5,"z":4,"name":"Soil_Snow"},{"x":-6,"y":0,"z":5,"name":"Soil_Dirt"},{"x":-6,"y":1,"z":5,"name":"Soil_Dirt"},{"x":-6,"y":2,"z":5,"name":"Soil_Dirt"},{"x":-6,"y":3,"z":5,"name":"Soil_Dirt"},{"x":-6,"y":4,"z":5,"name":"Soil_Dirt"},{"x":-6,"y":5,"z":5,"name":"Soil_Snow"},{"x":-6,"y":0,"z":6,"name":"Soil_Dirt"},{"x":-6,"y":1,"z":6,"name":"Soil_Dirt"},{"x":-6,"y":2,"z":6,"name":"Soil_Dirt"},{"x":-6,"y":3,"z":6,"name":"Soil_Dirt"},{"x":-6,"y":4,"z":6,"name":"Soil_Dirt"},{"x":-6,"y":5,"z":6,"name":"Soil_Snow"},{"x":-6,"y":0,"z":7,"name":"Soil_Dirt"},{"x":-6,"y":1,"z":7,"name":"Soil_Dirt"},{"x":-6,"y":2,"z":7,"name":"Soil_Dirt"},{"x":-6,"y":3,"z":7,"name":"Soil_Dirt"},{"x":-6,"y":4,"z":7,"name":"Soil_Dirt"},{"x":-6,"y":5,"z":7,"name":"Soil_Snow"},{"x":-6,"y":0,"z":8,"name":"Soil_Dirt"},{"x":-6,"y":1,"z":8,"name":"Soil_Dirt"},{"x":-6,"y":2,"z":8,"name":"Soil_Dirt"},{"x":-6,"y":3,"z":8,"name":"Soil_Dirt"},{"x":-6,"y":4,"z":8,"name":"Soil_Dirt"},{"x":-6,"y":5,"z":8,"name":"Soil_Snow"},{"x":-6,"y":0,"z":9,"name":"Soil_Dirt"},{"x":-6,"y":1,"z":9,"name":"Soil_Dirt"},{"x":-6,"y":2,"z":9,"name":"Soil_Dirt"},{"x":-6,"y":3,"z":9,"name":"Soil_Dirt"},{"x":-6,"y":4,"z":9,"name":"Soil_Dirt"},{"x":-6,"y":5,"z":9,"name":"Soil_Snow"},{"x":-6,"y":0,"z":10,"name":"Soil_Dirt"},{"x":-6,"y":1,"z":10,"name":"Soil_Dirt"},{"x":-6,"y":2,"z":10,"name":"Soil_Dirt"},{"x":-6,"y":3,"z":10,"name":"Soil_Dirt"},{"x":-6,"y":4,"z":10,"name":"Soil_Dirt"},{"x":-6,"y":5,"z":10,"name":"Soil_Snow"},{"x":-6,"y":0,"z":11,"name":"Soil_Dirt"},{"x":-6,"y":1,"z":11,"name":"Soil_Dirt"},{"x":-6,"y":2,"z":11,"name":"Soil_Dirt"},{"x":-6,"y":3,"z":11,"name":"Soil_Dirt"},{"x":-6,"y":4,"z":11,"name":"Soil_Dirt"},{"x":-6,"y":5,"z":11,"name":"Soil_Snow"},{"x":-6,"y":11,"z":11,"name":"WinterHoliday_Lights","support":15,"rotation":2},{"x":-6,"y":0,"z":12,"name":"Soil_Dirt"},{"x":-6,"y":1,"z":12,"name":"Soil_Dirt"},{"x":-6,"y":2,"z":12,"name":"Soil_Dirt"},{"x":-6,"y":3,"z":12,"name":"Soil_Dirt"},{"x":-6,"y":4,"z":12,"name":"Soil_Dirt"},{"x":-6,"y":5,"z":12,"name":"Soil_Snow"},{"x":-6,"y":11,"z":12,"name":"Wood_Fir_Trunk","support":15,"rotation":7},{"x":-6,"y":12,"z":12,"name":"Wood_Darkwood_Roof_Flat","support":15},{"x":-6,"y":0,"z":13,"name":"Soil_Dirt"},{"x":-6,"y":1,"z":13,"name":"Soil_Dirt"},{"x":-6,"y":2,"z":13,"name":"Soil_Dirt"},{"x":-6,"y":3,"z":13,"name":"Soil_Dirt"},{"x":-6,"y":4,"z":13,"name":"Soil_Dirt"},{"x":-6,"y":5,"z":13,"name":"Soil_Snow"},{"x":-6,"y":11,"z":13,"name":"WinterHoliday_Garland","support":15},{"x":-6,"y":0,"z":14,"name":"Soil_Dirt"},{"x":-6,"y":1,"z":14,"name":"Soil_Dirt"},{"x":-6,"y":2,"z":14,"name":"Soil_Dirt"},{"x":-6,"y":3,"z":14,"name":"Soil_Dirt"},{"x":-6,"y":4,"z":14,"name":"Soil_Dirt"},{"x":-6,"y":5,"z":14,"name":"Soil_Snow"},{"x":-6,"y":0,"z":15,"name":"Soil_Dirt"},{"x":-6,"y":1,"z":15,"name":"Soil_Dirt"},{"x":-6,"y":2,"z":15,"name":"Soil_Dirt"},{"x":-6,"y":3,"z":15,"name":"Soil_Dirt"},{"x":-6,"y":4,"z":15,"name":"Soil_Dirt"},{"x":-6,"y":5,"z":15,"name":"Rock_Stone_Brick_Smooth"},{"x":-5,"y":0,"z":-14,"name":"Soil_Dirt"},{"x":-5,"y":1,"z":-14,"name":"Soil_Dirt"},{"x":-5,"y":2,"z":-14,"name":"Soil_Dirt"},{"x":-5,"y":3,"z":-14,"name":"Soil_Dirt"},{"x":-5,"y":4,"z":-14,"name":"Soil_Dirt"},{"x":-5,"y":5,"z":-14,"name":"Rock_Stone_Brick_Smooth"},{"x":-5,"y":0,"z":-13,"name":"Soil_Dirt"},{"x":-5,"y":1,"z":-13,"name":"Soil_Dirt"},{"x":-5,"y":2,"z":-13,"name":"Soil_Dirt"},{"x":-5,"y":3,"z":-13,"name":"Soil_Dirt"},{"x":-5,"y":4,"z":-13,"name":"Soil_Dirt"},{"x":-5,"y":5,"z":-13,"name":"Soil_Snow"},{"x":-5,"y":0,"z":-12,"name":"Soil_Dirt"},{"x":-5,"y":1,"z":-12,"name":"Soil_Dirt"},{"x":-5,"y":2,"z":-12,"name":"Soil_Dirt"},{"x":-5,"y":3,"z":-12,"name":"Soil_Dirt"},{"x":-5,"y":4,"z":-12,"name":"Soil_Dirt"},{"x":-5,"y":5,"z":-12,"name":"Soil_Snow"},{"x":-5,"y":11,"z":-12,"name":"WinterHoliday_Garland","support":15,"rotation":2},{"x":-5,"y":0,"z":-11,"name":"Soil_Dirt"},{"x":-5,"y":1,"z":-11,"name":"Soil_Dirt"},{"x":-5,"y":2,"z":-11,"name":"Soil_Dirt"},{"x":-5,"y":3,"z":-11,"name":"Soil_Dirt"},{"x":-5,"y":4,"z":-11,"name":"Soil_Dirt"},{"x":-5,"y":5,"z":-11,"name":"Soil_Snow"},{"x":-5,"y":11,"z":-11,"name":"Wood_Fir_Trunk","support":15,"rotation":5},{"x":-5,"y":12,"z":-11,"name":"Wood_Darkwood_Roof_Flat","support":15,"rotation":2},{"x":-5,"y":0,"z":-10,"name":"Soil_Dirt"},{"x":-5,"y":1,"z":-10,"name":"Soil_Dirt"},{"x":-5,"y":2,"z":-10,"name":"Soil_Dirt"},{"x":-5,"y":3,"z":-10,"name":"Soil_Dirt"},{"x":-5,"y":4,"z":-10,"name":"Soil_Dirt"},{"x":-5,"y":5,"z":-10,"name":"Soil_Snow"},{"x":-5,"y":11,"z":-10,"name":"WinterHoliday_Lights","support":15},{"x":-5,"y":0,"z":-9,"name":"Soil_Dirt"},{"x":-5,"y":1,"z":-9,"name":"Soil_Dirt"},{"x":-5,"y":2,"z":-9,"name":"Soil_Dirt"},{"x":-5,"y":3,"z":-9,"name":"Soil_Dirt"},{"x":-5,"y":4,"z":-9,"name":"Soil_Dirt"},{"x":-5,"y":5,"z":-9,"name":"Soil_Snow"},{"x":-5,"y":0,"z":-8,"name":"Soil_Dirt"},{"x":-5,"y":1,"z":-8,"name":"Soil_Dirt"},{"x":-5,"y":2,"z":-8,"name":"Soil_Dirt"},{"x":-5,"y":3,"z":-8,"name":"Soil_Dirt"},{"x":-5,"y":4,"z":-8,"name":"Soil_Dirt"},{"x":-5,"y":5,"z":-8,"name":"Soil_Snow"},{"x":-5,"y":0,"z":-7,"name":"Soil_Dirt"},{"x":-5,"y":1,"z":-7,"name":"Soil_Dirt"},{"x":-5,"y":2,"z":-7,"name":"Soil_Dirt"},{"x":-5,"y":3,"z":-7,"name":"Soil_Dirt"},{"x":-5,"y":4,"z":-7,"name":"Soil_Dirt"},{"x":-5,"y":5,"z":-7,"name":"Soil_Snow"},{"x":-5,"y":0,"z":-6,"name":"Soil_Dirt"},{"x":-5,"y":1,"z":-6,"name":"Soil_Dirt"},{"x":-5,"y":2,"z":-6,"name":"Soil_Dirt"},{"x":-5,"y":3,"z":-6,"name":"Soil_Dirt"},{"x":-5,"y":4,"z":-6,"name":"Soil_Dirt"},{"x":-5,"y":5,"z":-6,"name":"Soil_Snow"},{"x":-5,"y":0,"z":-5,"name":"Soil_Dirt"},{"x":-5,"y":1,"z":-5,"name":"Soil_Dirt"},{"x":-5,"y":2,"z":-5,"name":"Soil_Dirt"},{"x":-5,"y":3,"z":-5,"name":"Soil_Dirt"},{"x":-5,"y":4,"z":-5,"name":"Soil_Dirt"},{"x":-5,"y":5,"z":-5,"name":"Soil_Snow"},{"x":-5,"y":0,"z":-4,"name":"Soil_Dirt"},{"x":-5,"y":1,"z":-4,"name":"Soil_Dirt"},{"x":-5,"y":2,"z":-4,"name":"Soil_Dirt"},{"x":-5,"y":3,"z":-4,"name":"Soil_Dirt"},{"x":-5,"y":4,"z":-4,"name":"Soil_Dirt"},{"x":-5,"y":5,"z":-4,"name":"Soil_Snow"},{"x":-5,"y":0,"z":-3,"name":"Soil_Dirt"},{"x":-5,"y":1,"z":-3,"name":"Soil_Dirt"},{"x":-5,"y":2,"z":-3,"name":"Soil_Dirt"},{"x":-5,"y":3,"z":-3,"name":"Soil_Dirt"},{"x":-5,"y":4,"z":-3,"name":"Soil_Dirt"},{"x":-5,"y":5,"z":-3,"name":"Rock_Calcite_Brick","support":15},{"x":-5,"y":0,"z":-2,"name":"Soil_Dirt"},{"x":-5,"y":1,"z":-2,"name":"Soil_Dirt"},{"x":-5,"y":2,"z":-2,"name":"Soil_Dirt"},{"x":-5,"y":3,"z":-2,"name":"Soil_Dirt"},{"x":-5,"y":4,"z":-2,"name":"Soil_Dirt"},{"x":-5,"y":5,"z":-2,"name":"Rock_Calcite_Brick","support":15},{"x":-5,"y":0,"z":-1,"name":"Soil_Dirt"},{"x":-5,"y":1,"z":-1,"name":"Soil_Dirt"},{"x":-5,"y":2,"z":-1,"name":"Soil_Dirt"},{"x":-5,"y":3,"z":-1,"name":"Soil_Dirt"},{"x":-5,"y":4,"z":-1,"name":"Soil_Dirt"},{"x":-5,"y":5,"z":-1,"name":"Rock_Calcite_Brick","support":15},{"x":-5,"y":0,"z":0,"name":"Soil_Dirt"},{"x":-5,"y":1,"z":0,"name":"Soil_Dirt"},{"x":-5,"y":2,"z":0,"name":"Soil_Dirt"},{"x":-5,"y":3,"z":0,"name":"Soil_Dirt"},{"x":-5,"y":4,"z":0,"name":"Soil_Dirt"},{"x":-5,"y":5,"z":0,"name":"Rock_Calcite_Brick","support":15},{"x":-5,"y":8,"z":0,"name":"WinterHoliday_Ornament_Bauble","support":15,"rotation":3},{"x":-5,"y":9,"z":0,"name":"WinterHoliday_Lights","support":15,"rotation":3},{"x":-5,"y":0,"z":1,"name":"Soil_Dirt"},{"x":-5,"y":1,"z":1,"name":"Soil_Dirt"},{"x":-5,"y":2,"z":1,"name":"Soil_Dirt"},{"x":-5,"y":3,"z":1,"name":"Soil_Dirt"},{"x":-5,"y":4,"z":1,"name":"Soil_Dirt"},{"x":-5,"y":5,"z":1,"name":"Rock_Calcite_Brick","support":15},{"x":-5,"y":9,"z":1,"name":"WinterHoliday_Lights","support":15,"rotation":3},{"x":-5,"y":0,"z":2,"name":"Soil_Dirt"},{"x":-5,"y":1,"z":2,"name":"Soil_Dirt"},{"x":-5,"y":2,"z":2,"name":"Soil_Dirt"},{"x":-5,"y":3,"z":2,"name":"Soil_Dirt"},{"x":-5,"y":4,"z":2,"name":"Soil_Dirt"},{"x":-5,"y":5,"z":2,"name":"Rock_Calcite_Brick","support":15},{"x":-5,"y":0,"z":3,"name":"Soil_Dirt"},{"x":-5,"y":1,"z":3,"name":"Soil_Dirt"},{"x":-5,"y":2,"z":3,"name":"Soil_Dirt"},{"x":-5,"y":3,"z":3,"name":"Soil_Dirt"},{"x":-5,"y":4,"z":3,"name":"Soil_Dirt"},{"x":-5,"y":5,"z":3,"name":"Rock_Calcite_Brick","support":15},{"x":-5,"y":0,"z":4,"name":"Soil_Dirt"},{"x":-5,"y":1,"z":4,"name":"Soil_Dirt"},{"x":-5,"y":2,"z":4,"name":"Soil_Dirt"},{"x":-5,"y":3,"z":4,"name":"Soil_Dirt"},{"x":-5,"y":4,"z":4,"name":"Soil_Dirt"},{"x":-5,"y":5,"z":4,"name":"Rock_Calcite_Brick","support":15},{"x":-5,"y":0,"z":5,"name":"Soil_Dirt"},{"x":-5,"y":1,"z":5,"name":"Soil_Dirt"},{"x":-5,"y":2,"z":5,"name":"Soil_Dirt"},{"x":-5,"y":3,"z":5,"name":"Soil_Dirt"},{"x":-5,"y":4,"z":5,"name":"Soil_Dirt"},{"x":-5,"y":5,"z":5,"name":"Soil_Snow"},{"x":-5,"y":0,"z":6,"name":"Soil_Dirt"},{"x":-5,"y":1,"z":6,"name":"Soil_Dirt"},{"x":-5,"y":2,"z":6,"name":"Soil_Dirt"},{"x":-5,"y":3,"z":6,"name":"Soil_Dirt"},{"x":-5,"y":4,"z":6,"name":"Soil_Dirt"},{"x":-5,"y":5,"z":6,"name":"Soil_Snow"},{"x":-5,"y":0,"z":7,"name":"Soil_Dirt"},{"x":-5,"y":1,"z":7,"name":"Soil_Dirt"},{"x":-5,"y":2,"z":7,"name":"Soil_Dirt"},{"x":-5,"y":3,"z":7,"name":"Soil_Dirt"},{"x":-5,"y":4,"z":7,"name":"Soil_Dirt"},{"x":-5,"y":5,"z":7,"name":"Soil_Snow"},{"x":-5,"y":0,"z":8,"name":"Soil_Dirt"},{"x":-5,"y":1,"z":8,"name":"Soil_Dirt"},{"x":-5,"y":2,"z":8,"name":"Soil_Dirt"},{"x":-5,"y":3,"z":8,"name":"Soil_Dirt"},{"x":-5,"y":4,"z":8,"name":"Soil_Dirt"},{"x":-5,"y":5,"z":8,"name":"Soil_Snow"},{"x":-5,"y":0,"z":9,"name":"Soil_Dirt"},{"x":-5,"y":1,"z":9,"name":"Soil_Dirt"},{"x":-5,"y":2,"z":9,"name":"Soil_Dirt"},{"x":-5,"y":3,"z":9,"name":"Soil_Dirt"},{"x":-5,"y":4,"z":9,"name":"Soil_Dirt"},{"x":-5,"y":5,"z":9,"name":"Soil_Snow"},{"x":-5,"y":0,"z":10,"name":"Soil_Dirt"},{"x":-5,"y":1,"z":10,"name":"Soil_Dirt"},{"x":-5,"y":2,"z":10,"name":"Soil_Dirt"},{"x":-5,"y":3,"z":10,"name":"Soil_Dirt"},{"x":-5,"y":4,"z":10,"name":"Soil_Dirt"},{"x":-5,"y":5,"z":10,"name":"Soil_Snow"},{"x":-5,"y":0,"z":11,"name":"Soil_Dirt"},{"x":-5,"y":1,"z":11,"name":"Soil_Dirt"},{"x":-5,"y":2,"z":11,"name":"Soil_Dirt"},{"x":-5,"y":3,"z":11,"name":"Soil_Dirt"},{"x":-5,"y":4,"z":11,"name":"Soil_Dirt"},{"x":-5,"y":5,"z":11,"name":"Soil_Snow"},{"x":-5,"y":11,"z":11,"name":"WinterHoliday_Lights","support":15,"rotation":2},{"x":-5,"y":0,"z":12,"name":"Soil_Dirt"},{"x":-5,"y":1,"z":12,"name":"Soil_Dirt"},{"x":-5,"y":2,"z":12,"name":"Soil_Dirt"},{"x":-5,"y":3,"z":12,"name":"Soil_Dirt"},{"x":-5,"y":4,"z":12,"name":"Soil_Dirt"},{"x":-5,"y":5,"z":12,"name":"Soil_Snow"},{"x":-5,"y":11,"z":12,"name":"Wood_Fir_Trunk","support":15,"rotation":7},{"x":-5,"y":12,"z":12,"name":"Wood_Darkwood_Roof_Flat","support":15},{"x":-5,"y":0,"z":13,"name":"Soil_Dirt"},{"x":-5,"y":1,"z":13,"name":"Soil_Dirt"},{"x":-5,"y":2,"z":13,"name":"Soil_Dirt"},{"x":-5,"y":3,"z":13,"name":"Soil_Dirt"},{"x":-5,"y":4,"z":13,"name":"Soil_Dirt"},{"x":-5,"y":5,"z":13,"name":"Soil_Snow"},{"x":-5,"y":11,"z":13,"name":"WinterHoliday_Garland","support":15},{"x":-5,"y":0,"z":14,"name":"Soil_Dirt"},{"x":-5,"y":1,"z":14,"name":"Soil_Dirt"},{"x":-5,"y":2,"z":14,"name":"Soil_Dirt"},{"x":-5,"y":3,"z":14,"name":"Soil_Dirt"},{"x":-5,"y":4,"z":14,"name":"Soil_Dirt"},{"x":-5,"y":5,"z":14,"name":"Soil_Snow"},{"x":-5,"y":0,"z":15,"name":"Soil_Dirt"},{"x":-5,"y":1,"z":15,"name":"Soil_Dirt"},{"x":-5,"y":2,"z":15,"name":"Soil_Dirt"},{"x":-5,"y":3,"z":15,"name":"Soil_Dirt"},{"x":-5,"y":4,"z":15,"name":"Soil_Dirt"},{"x":-5,"y":5,"z":15,"name":"Rock_Stone_Brick_Smooth"},{"x":-4,"y":0,"z":-14,"name":"Soil_Dirt"},{"x":-4,"y":1,"z":-14,"name":"Soil_Dirt"},{"x":-4,"y":2,"z":-14,"name":"Soil_Dirt"},{"x":-4,"y":3,"z":-14,"name":"Soil_Dirt"},{"x":-4,"y":4,"z":-14,"name":"Soil_Dirt"},{"x":-4,"y":5,"z":-14,"name":"Rock_Stone_Brick_Smooth"},{"x":-4,"y":0,"z":-13,"name":"Soil_Dirt"},{"x":-4,"y":1,"z":-13,"name":"Soil_Dirt"},{"x":-4,"y":2,"z":-13,"name":"Soil_Dirt"},{"x":-4,"y":3,"z":-13,"name":"Soil_Dirt"},{"x":-4,"y":4,"z":-13,"name":"Soil_Dirt"},{"x":-4,"y":5,"z":-13,"name":"Soil_Snow"},{"x":-4,"y":0,"z":-12,"name":"Soil_Dirt"},{"x":-4,"y":1,"z":-12,"name":"Soil_Dirt"},{"x":-4,"y":2,"z":-12,"name":"Soil_Dirt"},{"x":-4,"y":3,"z":-12,"name":"Soil_Dirt"},{"x":-4,"y":4,"z":-12,"name":"Soil_Dirt"},{"x":-4,"y":5,"z":-12,"name":"Soil_Snow"},{"x":-4,"y":11,"z":-12,"name":"WinterHoliday_Garland","support":15,"rotation":2},{"x":-4,"y":0,"z":-11,"name":"Soil_Dirt"},{"x":-4,"y":1,"z":-11,"name":"Soil_Dirt"},{"x":-4,"y":2,"z":-11,"name":"Soil_Dirt"},{"x":-4,"y":3,"z":-11,"name":"Soil_Dirt"},{"x":-4,"y":4,"z":-11,"name":"Soil_Dirt"},{"x":-4,"y":5,"z":-11,"name":"Soil_Snow"},{"x":-4,"y":10,"z":-11,"name":"Wood_Darkwood_Stairs","support":15,"rotation":9},{"x":-4,"y":11,"z":-11,"name":"Wood_Fir_Trunk","support":15,"rotation":5},{"x":-4,"y":12,"z":-11,"name":"Wood_Darkwood_Roof_Flat","support":15,"rotation":2},{"x":-4,"y":0,"z":-10,"name":"Soil_Dirt"},{"x":-4,"y":1,"z":-10,"name":"Soil_Dirt"},{"x":-4,"y":2,"z":-10,"name":"Soil_Dirt"},{"x":-4,"y":3,"z":-10,"name":"Soil_Dirt"},{"x":-4,"y":4,"z":-10,"name":"Soil_Dirt"},{"x":-4,"y":5,"z":-10,"name":"Soil_Snow"},{"x":-4,"y":11,"z":-10,"name":"WinterHoliday_Lights","support":15},{"x":-4,"y":0,"z":-9,"name":"Soil_Dirt"},{"x":-4,"y":1,"z":-9,"name":"Soil_Dirt"},{"x":-4,"y":2,"z":-9,"name":"Soil_Dirt"},{"x":-4,"y":3,"z":-9,"name":"Soil_Dirt"},{"x":-4,"y":4,"z":-9,"name":"Soil_Dirt"},{"x":-4,"y":5,"z":-9,"name":"Soil_Snow"},{"x":-4,"y":0,"z":-8,"name":"Soil_Dirt"},{"x":-4,"y":1,"z":-8,"name":"Soil_Dirt"},{"x":-4,"y":2,"z":-8,"name":"Soil_Dirt"},{"x":-4,"y":3,"z":-8,"name":"Soil_Dirt"},{"x":-4,"y":4,"z":-8,"name":"Soil_Dirt"},{"x":-4,"y":5,"z":-8,"name":"Soil_Snow"},{"x":-4,"y":0,"z":-7,"name":"Soil_Dirt"},{"x":-4,"y":1,"z":-7,"name":"Soil_Dirt"},{"x":-4,"y":2,"z":-7,"name":"Soil_Dirt"},{"x":-4,"y":3,"z":-7,"name":"Soil_Dirt"},{"x":-4,"y":4,"z":-7,"name":"Soil_Dirt"},{"x":-4,"y":5,"z":-7,"name":"Soil_Snow"},{"x":-4,"y":0,"z":-6,"name":"Soil_Dirt"},{"x":-4,"y":1,"z":-6,"name":"Soil_Dirt"},{"x":-4,"y":2,"z":-6,"name":"Soil_Dirt"},{"x":-4,"y":3,"z":-6,"name":"Soil_Dirt"},{"x":-4,"y":4,"z":-6,"name":"Soil_Dirt"},{"x":-4,"y":5,"z":-6,"name":"Soil_Snow"},{"x":-4,"y":0,"z":-5,"name":"Soil_Dirt"},{"x":-4,"y":1,"z":-5,"name":"Soil_Dirt"},{"x":-4,"y":2,"z":-5,"name":"Soil_Dirt"},{"x":-4,"y":3,"z":-5,"name":"Soil_Dirt"},{"x":-4,"y":4,"z":-5,"name":"Soil_Dirt"},{"x":-4,"y":5,"z":-5,"name":"Soil_Snow"},{"x":-4,"y":0,"z":-4,"name":"Soil_Dirt"},{"x":-4,"y":1,"z":-4,"name":"Soil_Dirt"},{"x":-4,"y":2,"z":-4,"name":"Soil_Dirt"},{"x":-4,"y":3,"z":-4,"name":"Soil_Dirt"},{"x":-4,"y":4,"z":-4,"name":"Soil_Dirt"},{"x":-4,"y":5,"z":-4,"name":"Rock_Calcite_Brick","support":15},{"x":-4,"y":0,"z":-3,"name":"Soil_Dirt"},{"x":-4,"y":1,"z":-3,"name":"Soil_Dirt"},{"x":-4,"y":2,"z":-3,"name":"Soil_Dirt"},{"x":-4,"y":3,"z":-3,"name":"Soil_Dirt"},{"x":-4,"y":4,"z":-3,"name":"Soil_Dirt"},{"x":-4,"y":5,"z":-3,"name":"Rock_Calcite_Brick","support":15},{"x":-4,"y":0,"z":-2,"name":"Soil_Dirt"},{"x":-4,"y":1,"z":-2,"name":"Soil_Dirt"},{"x":-4,"y":2,"z":-2,"name":"Soil_Dirt"},{"x":-4,"y":3,"z":-2,"name":"Soil_Dirt"},{"x":-4,"y":4,"z":-2,"name":"Soil_Dirt"},{"x":-4,"y":5,"z":-2,"name":"Rock_Calcite_Brick","support":15},{"x":-4,"y":9,"z":-2,"name":"WinterHoliday_Lights","support":15,"rotation":3},{"x":-4,"y":0,"z":-1,"name":"Soil_Dirt"},{"x":-4,"y":1,"z":-1,"name":"Soil_Dirt"},{"x":-4,"y":2,"z":-1,"name":"Soil_Dirt"},{"x":-4,"y":3,"z":-1,"name":"Soil_Dirt"},{"x":-4,"y":4,"z":-1,"name":"Soil_Dirt"},{"x":-4,"y":5,"z":-1,"name":"Soil_Pathway","support":15},{"x":-4,"y":9,"z":-1,"name":"WinterHoliday_Lights","support":15,"rotation":3},{"x":-4,"y":0,"z":0,"name":"Soil_Dirt"},{"x":-4,"y":1,"z":0,"name":"Soil_Dirt"},{"x":-4,"y":2,"z":0,"name":"Soil_Dirt"},{"x":-4,"y":3,"z":0,"name":"Soil_Dirt"},{"x":-4,"y":4,"z":0,"name":"Soil_Dirt"},{"x":-4,"y":5,"z":0,"name":"Soil_Pathway","support":15},{"x":-4,"y":8,"z":0,"name":"Plant_Leaves_Fir","support":15,"rotation":3},{"x":-4,"y":9,"z":0,"name":"Plant_Leaves_Fir","support":15,"rotation":3},{"x":-4,"y":10,"z":0,"name":"Plant_Leaves_Fir_Snow","support":15,"rotation":3},{"x":-4,"y":0,"z":1,"name":"Soil_Dirt"},{"x":-4,"y":1,"z":1,"name":"Soil_Dirt"},{"x":-4,"y":2,"z":1,"name":"Soil_Dirt"},{"x":-4,"y":3,"z":1,"name":"Soil_Dirt"},{"x":-4,"y":4,"z":1,"name":"Soil_Dirt"},{"x":-4,"y":5,"z":1,"name":"Soil_Pathway","support":15},{"x":-4,"y":8,"z":1,"name":"Plant_Leaves_Fir","support":15,"rotation":3},{"x":-4,"y":9,"z":1,"name":"Plant_Leaves_Fir","support":15,"rotation":3},{"x":-4,"y":10,"z":1,"name":"Plant_Leaves_Fir_Snow","support":15,"rotation":3},{"x":-4,"y":0,"z":2,"name":"Soil_Dirt"},{"x":-4,"y":1,"z":2,"name":"Soil_Dirt"},{"x":-4,"y":2,"z":2,"name":"Soil_Dirt"},{"x":-4,"y":3,"z":2,"name":"Soil_Dirt"},{"x":-4,"y":4,"z":2,"name":"Soil_Dirt"},{"x":-4,"y":5,"z":2,"name":"Soil_Pathway","support":15},{"x":-4,"y":9,"z":2,"name":"WinterHoliday_Lights","support":15,"rotation":3},{"x":-4,"y":0,"z":3,"name":"Soil_Dirt"},{"x":-4,"y":1,"z":3,"name":"Soil_Dirt"},{"x":-4,"y":2,"z":3,"name":"Soil_Dirt"},{"x":-4,"y":3,"z":3,"name":"Soil_Dirt"},{"x":-4,"y":4,"z":3,"name":"Soil_Dirt"},{"x":-4,"y":5,"z":3,"name":"Rock_Calcite_Brick","support":15},{"x":-4,"y":9,"z":3,"name":"WinterHoliday_Lights","support":15,"rotation":3},{"x":-4,"y":10,"z":3,"name":"WinterHoliday_Single_Light","support":15,"rotation":3},{"x":-4,"y":0,"z":4,"name":"Soil_Dirt"},{"x":-4,"y":1,"z":4,"name":"Soil_Dirt"},{"x":-4,"y":2,"z":4,"name":"Soil_Dirt"},{"x":-4,"y":3,"z":4,"name":"Soil_Dirt"},{"x":-4,"y":4,"z":4,"name":"Soil_Dirt"},{"x":-4,"y":5,"z":4,"name":"Rock_Calcite_Brick","support":15},{"x":-4,"y":0,"z":5,"name":"Soil_Dirt"},{"x":-4,"y":1,"z":5,"name":"Soil_Dirt"},{"x":-4,"y":2,"z":5,"name":"Soil_Dirt"},{"x":-4,"y":3,"z":5,"name":"Soil_Dirt"},{"x":-4,"y":4,"z":5,"name":"Soil_Dirt"},{"x":-4,"y":5,"z":5,"name":"Rock_Calcite_Brick","support":15},{"x":-4,"y":0,"z":6,"name":"Soil_Dirt"},{"x":-4,"y":1,"z":6,"name":"Soil_Dirt"},{"x":-4,"y":2,"z":6,"name":"Soil_Dirt"},{"x":-4,"y":3,"z":6,"name":"Soil_Dirt"},{"x":-4,"y":4,"z":6,"name":"Soil_Dirt"},{"x":-4,"y":5,"z":6,"name":"Soil_Snow"},{"x":-4,"y":0,"z":7,"name":"Soil_Dirt"},{"x":-4,"y":1,"z":7,"name":"Soil_Dirt"},{"x":-4,"y":2,"z":7,"name":"Soil_Dirt"},{"x":-4,"y":3,"z":7,"name":"Soil_Dirt"},{"x":-4,"y":4,"z":7,"name":"Soil_Dirt"},{"x":-4,"y":5,"z":7,"name":"Soil_Snow"},{"x":-4,"y":0,"z":8,"name":"Soil_Dirt"},{"x":-4,"y":1,"z":8,"name":"Soil_Dirt"},{"x":-4,"y":2,"z":8,"name":"Soil_Dirt"},{"x":-4,"y":3,"z":8,"name":"Soil_Dirt"},{"x":-4,"y":4,"z":8,"name":"Soil_Dirt"},{"x":-4,"y":5,"z":8,"name":"Soil_Snow"},{"x":-4,"y":0,"z":9,"name":"Soil_Dirt"},{"x":-4,"y":1,"z":9,"name":"Soil_Dirt"},{"x":-4,"y":2,"z":9,"name":"Soil_Dirt"},{"x":-4,"y":3,"z":9,"name":"Soil_Dirt"},{"x":-4,"y":4,"z":9,"name":"Soil_Dirt"},{"x":-4,"y":5,"z":9,"name":"Soil_Snow"},{"x":-4,"y":0,"z":10,"name":"Soil_Dirt"},{"x":-4,"y":1,"z":10,"name":"Soil_Dirt"},{"x":-4,"y":2,"z":10,"name":"Soil_Dirt"},{"x":-4,"y":3,"z":10,"name":"Soil_Dirt"},{"x":-4,"y":4,"z":10,"name":"Soil_Dirt"},{"x":-4,"y":5,"z":10,"name":"Soil_Snow"},{"x":-4,"y":0,"z":11,"name":"Soil_Dirt"},{"x":-4,"y":1,"z":11,"name":"Soil_Dirt"},{"x":-4,"y":2,"z":11,"name":"Soil_Dirt"},{"x":-4,"y":3,"z":11,"name":"Soil_Dirt"},{"x":-4,"y":4,"z":11,"name":"Soil_Dirt"},{"x":-4,"y":5,"z":11,"name":"Soil_Snow"},{"x":-4,"y":11,"z":11,"name":"WinterHoliday_Lights","support":15,"rotation":2},{"x":-4,"y":0,"z":12,"name":"Soil_Dirt"},{"x":-4,"y":1,"z":12,"name":"Soil_Dirt"},{"x":-4,"y":2,"z":12,"name":"Soil_Dirt"},{"x":-4,"y":3,"z":12,"name":"Soil_Dirt"},{"x":-4,"y":4,"z":12,"name":"Soil_Dirt"},{"x":-4,"y":5,"z":12,"name":"Soil_Snow"},{"x":-4,"y":10,"z":12,"name":"Wood_Darkwood_Stairs","support":15,"rotation":35},{"x":-4,"y":11,"z":12,"name":"Wood_Fir_Trunk","support":15,"rotation":7},{"x":-4,"y":12,"z":12,"name":"Wood_Darkwood_Roof_Flat","support":15},{"x":-4,"y":0,"z":13,"name":"Soil_Dirt"},{"x":-4,"y":1,"z":13,"name":"Soil_Dirt"},{"x":-4,"y":2,"z":13,"name":"Soil_Dirt"},{"x":-4,"y":3,"z":13,"name":"Soil_Dirt"},{"x":-4,"y":4,"z":13,"name":"Soil_Dirt"},{"x":-4,"y":5,"z":13,"name":"Soil_Snow"},{"x":-4,"y":11,"z":13,"name":"WinterHoliday_Garland","support":15},{"x":-4,"y":0,"z":14,"name":"Soil_Dirt"},{"x":-4,"y":1,"z":14,"name":"Soil_Dirt"},{"x":-4,"y":2,"z":14,"name":"Soil_Dirt"},{"x":-4,"y":3,"z":14,"name":"Soil_Dirt"},{"x":-4,"y":4,"z":14,"name":"Soil_Dirt"},{"x":-4,"y":5,"z":14,"name":"Soil_Snow"},{"x":-4,"y":0,"z":15,"name":"Soil_Dirt"},{"x":-4,"y":1,"z":15,"name":"Soil_Dirt"},{"x":-4,"y":2,"z":15,"name":"Soil_Dirt"},{"x":-4,"y":3,"z":15,"name":"Soil_Dirt"},{"x":-4,"y":4,"z":15,"name":"Soil_Dirt"},