{
  "version": 8,
  "blockIdVersion": 11,
  "anchorX": 0,
  "anchorY": 0,
  "anchorZ": 0,
  "blocks": [
    {
      "x": -14,
      "y": 0,
      "z": -14,
      "name": "Soil_Dirt"
    },
    {
      "x": -14,
      "y": 1,
      "z": -14,
      "name": "Soil_Dirt"
    },
    {
      "x": -14,
      "y": 2,
      "z": -14,
      "name": "Soil_Dirt"
    },
    {
      "x": -14,
      "y": 3,
      "z": -14,
      "name": "Soil_Dirt"
    },
    {
      "x": -14,
      "y": 4,
      "z": -14,
      "name": "Soil_Dirt"
    },
    {
      "x": -14,
      "y": 5,
      "z": -14,
      "name": "Rock_Stone_Brick_Smooth"
    },
    {
      "x": -14,
      "y": 0,
      "z": -13,
      "name": "Soil_Dirt"
    },
    {
      "x": -14,
      "y": 1,
      "z": -13,
      "name": "Soil_Dirt"
    },
    {
      "x": -14,
      "y": 2,
      "z": -13,
      "name": "Soil_Dirt"
    },
    {
      "x": -14,
      "y": 3,
      "z": -13,
      "name": "Soil_Dirt"
    },
    {
      "x": -14,
      "y": 4,
      "z": -13,
      "name": "Soil_Dirt"
    },
    {
      "x": -14,
      "y": 5,
      "z": -13,
      "name": "Rock_Stone_Brick_Smooth"
    },
    {
      "x": -14,
      "y": 0,
      "z": -12,
      "name": "Soil_Dirt"
    },
    {
      "x": -14,
      "y": 1,
      "z": -12,
      "name": "Soil_Dirt"
    },
    {
      "x": -14,
      "y": 2,
      "z": -12,
      "name": "Soil_Dirt"
    },
    {
      "x": -14,
      "y": 3,
      "z": -12,
      "name": "Soil_Dirt"
    },
    {
      "x": -14,
      "y": 4,
      "z": -12,
      "name": "Soil_Dirt"
    },
    {
      "x": -14,
      "y": 5,
      "z": -12,
      "name": "Rock_Stone_Brick_Smooth"
    },
    {
      "x": -14,
      "y": 0,
      "z": -11,
      "name": "Soil_Dirt"
    },
    {
      "x": -14,
      "y": 1,
      "z": -11,
      "name": "Soil_Dirt"
    },
    {
      "x": -14,
      "y": 2,
      "z": -11,
      "name": "Soil_Dirt"
    },
    {
      "x": -14,
      "y": 3,
      "z": -11,
      "name": "Soil_Dirt"
    },
    {
      "x": -14,
      "y": 4,
      "z": -11,
      "name": "Soil_Dirt"
    },
    {
      "x": -14,
      "y": 5,
      "z": -11,
      "name": "Rock_Stone_Brick_Smooth"
    },
    {
      "x": -14,
      "y": 0,
      "z": -10,
      "name": "Soil_Dirt"
    },
    {
      "x": -14,
      "y": 1,
      "z": -10,
      "name": "Soil_Dirt"
    },
    {
      "x": -14,
      "y": 2,
      "z": -10,
      "name": "Soil_Dirt"
    },
    {
      "x": -14,
      "y": 3,
      "z": -10,
      "name": "Soil_Dirt"
    },
    {
      "x": -14,
      "y": 4,
      "z": -10,
      "name": "Soil_Dirt"
    },
    {
      "x": -14,
      "y": 5,
      "z": -10,
      "name": "Rock_Stone_Brick_Smooth"
    },
    {
      "x": -14,
      "y": 0,
      "z": -9,
      "name": "Soil_Dirt"
    },
    {
      "x": -14,
      "y": 1,
      "z": -9,
      "name": "Soil_Dirt"
    },
    {
      "x": -14,
      "y": 2,
      "z": -9,
      "name": "Soil_Dirt"
    },
    {
      "x": -14,
      "y": 3,
      "z": -9,
      "name": "Soil_Dirt"
    },
    {
      "x": -14,
      "y": 4,
      "z": -9,
      "name": "Soil_Dirt"
    },
    {
      "x": -14,
      "y": 5,
      "z": -9,
      "name": "Rock_Stone_Brick_Smooth"
    },
    {
      "x": -14,
      "y": 0,
      "z": -8,
      "name": "Soil_Dirt"
    },
    {
      "x": -14,
      "y": 1,
      "z": -8,
      "name": "Soil_Dirt"
    },
    {
      "x": -14,
      "y": 2,
      "z": -8,
      "name": "Soil_Dirt"
    },
    {
      "x": -14,
      "y": 3,
      "z": -8,
      "name": "Soil_Dirt"
    },
    {
      "x": -14,
      "y": 4,
      "z": -8,
      "name": "Soil_Dirt"
    },
    {
      "x": -14,
      "y": 5,
      "z": -8,
      "name": "Rock_Stone_Brick_Smooth"
    },
    {
      "x": -14,
      "y": 0,
      "z": -7,
      "name": "Soil_Dirt"
    },
    {
      "x": -14,
      "y": 1,
      "z": -7,
      "name": "Soil_Dirt"
    },
    {
      "x": -14,
      "y": 2,
      "z": -7,
      "name": "Soil_Dirt"
    },
    {
      "x": -14,
      "y": 3,
      "z": -7,
      "name": "Soil_Dirt"
    },
    {
      "x": -14,
      "y": 4,
      "z": -7,
      "name": "Soil_Dirt"
    },
    {
      "x": -14,
      "y": 5,
      "z": -7,
      "name": "Rock_Stone_Brick_Smooth"
    },
    {
      "x": -14,
      "y": 0,
      "z": -6,
      "name": "Soil_Dirt"
    },
    {
      "x": -14,
      "y": 1,
      "z": -6,
      "name": "Soil_Dirt"
    },
    {
      "x": -14,
      "y": 2,
      "z": -6,
      "name": "Soil_Dirt"
    },
    {
      "x": -14,
      "y": 3,
      "z": -6,
      "name": "Soil_Dirt"
    },
    {
      "x": -14,
      "y": 4,
      "z": -6,
      "name": "Soil_Dirt"
    },
    {
      "x": -14,
      "y": 5,
      "z": -6,
      "name": "Rock_Stone_Brick_Smooth"
    },
    {
      "x": -14,
      "y": 0,
      "z": -5,
      "name": "Soil_Dirt"
    },
    {
      "x": -14,
      "y": 1,
      "z": -5,
      "name": "Soil_Dirt"
    },
    {
      "x": -14,
      "y": 2,
      "z": -5,
      "name": "Soil_Dirt"
    },
    {
      "x": -14,
      "y": 3,
      "z": -5,
      "name": "Soil_Dirt"
    },
    {
      "x": -14,
      "y": 4,
      "z": -5,
      "name": "Soil_Dirt"
    },
    {
      "x": -14,
      "y": 5,
      "z": -5,
      "name": "Rock_Stone_Brick_Smooth"
    },
    {
      "x": -14,
      "y": 0,
      "z": -4,
      "name": "Soil_Dirt"
    },
    {
      "x": -14,
      "y": 1,
      "z": -4,
      "name": "Soil_Dirt"
    },
    {
      "x": -14,
      "y": 2,
      "z": -4,
      "name": "Soil_Dirt"
    },
    {
      "x": -14,
      "y": 3,
      "z": -4,
      "name": "Soil_Dirt"
    },
    {
      "x": -14,
      "y": 4,
      "z": -4,
      "name": "Soil_Dirt"
    },
    {
      "x": -14,
      "y": 5,
      "z": -4,
      "name": "Rock_Stone_Brick_Smooth"
    },
    {
      "x": -14,
      "y": 0,
      "z": -3,
      "name": "Soil_Dirt"
    },
    {
      "x": -14,
      "y": 1,
      "z": -3,
      "name": "Soil_Dirt"
    },
    {
      "x": -14,
      "y": 2,
      "z": -3,
      "name": "Soil_Dirt"
    },
    {
      "x": -14,
      "y": 3,
      "z": -3,
      "name": "Soil_Dirt"
    },
    {
      "x": -14,
      "y": 4,
      "z": -3,
      "name": "Soil_Dirt"
    },
    {
      "x": -14,
      "y": 5,
      "z": -3,
      "name": "Rock_Stone_Brick_Smooth"
    },
    {
      "x": -14,
      "y": 0,
      "z": -2,
      "name": "Soil_Dirt"
    },
    {
      "x": -14,
      "y": 1,
      "z": -2,
      "name": "Soil_Dirt"
    },
    {
      "x": -14,
      "y": 2,
      "z": -2,
      "name": "Soil_Dirt"
    },
    {
      "x": -14,
      "y": 3,
      "z": -2,
      "name": "Soil_Dirt"
    },
    {
      "x": -14,
      "y": 4,
      "z": -2,
      "name": "Soil_Dirt"
    },
    {
      "x": -14,
      "y": 5,
      "z": -2,
      "name": "Rock_Stone_Brick_Smooth"
    },
    {
      "x": -14,
      "y": 0,
      "z": -1,
      "name": "Soil_Dirt"
    },
    {
      "x": -14,
      "y": 1,
      "z": -1,
      "name": "Soil_Dirt"
    },
    {
      "x": -14,
      "y": 2,
      "z": -1,
      "name": "Soil_Dirt"
    },
    {
      "x": -14,
      "y": 3,
      "z": -1,
      "name": "Soil_Dirt"
    },
    {
      "x": -14,
      "y": 4,
      "z": -1,
      "name": "Soil_Dirt"
    },
    {
      "x": -14,
      "y": 5,
      "z": -1,
      "name": "Rock_Stone_Brick_Smooth"
    },
    {
      "x": -14,
      "y": 0,
      "z": 0,
      "name": "Soil_Dirt"
    },
    {
      "x": -14,
      "y": 1,
      "z": 0,
      "name": "Soil_Dirt"
    },
    {
      "x": -14,
      "y": 2,
      "z": 0,
      "name": "Soil_Dirt"
    },
    {
      "x": -14,
      "y": 3,
      "z": 0,
      "name": "Soil_Dirt"
    },
    {
      "x": -14,
      "y": 4,
      "z": 0,
      "name": "Soil_Dirt"
    },
    {
      "x": -14,
      "y": 5,
      "z": 0,
      "name": "Rock_Stone_Brick_Smooth"
    },
    {
      "x": -14,
      "y": 0,
      "z": 1,
      "name": "Soil_Dirt"
    },
    {
      "x": -14,
      "y": 1,
      "z": 1,
      "name": "Soil_Dirt"
    },
    {
      "x": -14,
      "y": 2,
      "z": 1,
      "name": "Soil_Dirt"
    },
    {
      "x": -14,
      "y": 3,
      "z": 1,
      "name": "Soil_Dirt"
    },
    {
      "x": -14,
      "y": 4,
      "z": 1,
      "name": "Soil_Dirt"
    },
    {
      "x": -14,
      "y": 5,
      "z": 1,
      "name": "Rock_Stone_Brick_Smooth"
    },
    {
      "x": -14,
      "y": 0,
      "z": 2,
      "name": "Soil_Dirt"
    },
    {
      "x": -14,
      "y": 1,
      "z": 2,
      "name": "Soil_Dirt"
    },
    {
      "x": -14,
      "y": 2,
      "z": 2,
      "name": "Soil_Dirt"
    },
    {
      "x": -14,
      "y": 3,
      "z": 2,
      "name": "Soil_Dirt"
    },
    {
      "x": -14,
      "y": 4,
      "z": 2,
      "name": "Soil_Dirt"
    },
    {
      "x": -14,
      "y": 5,
      "z": 2,
      "name": "Rock_Stone_Brick_Smooth"
    },
    {
      "x": -14,
      "y": 0,
      "z": 3,
      "name": "Soil_Dirt"
    },
    {
      "x": -14,
      "y": 1,
      "z": 3,
      "name": "Soil_Dirt"
    },
    {
      "x": -14,
      "y": 2,
      "z": 3,
      "name": "Soil_Dirt"
    },
    {
      "x": -14,
      "y": 3,
      "z": 3,
      "name": "Soil_Dirt"
    },
    {
      "x": -14,
      "y": 4,
      "z": 3,
      "name": "Soil_Dirt"
    },
    {
      "x": -14,
      "y": 5,
      "z": 3,
      "name": "Rock_Stone_Brick_Smooth"
    },
    {
      "x": -14,
      "y": 0,
      "z": 4,
      "name": "Soil_Dirt"
    },
    {
      "x": -14,
      "y": 1,
      "z": 4,
      "name": "Soil_Dirt"
    },
    {
      "x": -14,
      "y": 2,
      "z": 4,
      "name": "Soil_Dirt"
    },
    {
      "x": -14,
      "y": 3,
      "z": 4,
      "name": "Soil_Dirt"
    },
    {
      "x": -14,
      "y": 4,
      "z": 4,
      "name": "Soil_Dirt"
    },
    {
      "x": -14,
      "y": 5,
      "z": 4,
      "name": "Rock_Stone_Brick_Smooth"
    },
    {
      "x": -14,
      "y": 0,
      "z": 5,
      "name": "Soil_Dirt"
    },
    {
      "x": -14,
      "y": 1,
      "z": 5,
      "name": "Soil_Dirt"
    },
    {
      "x": -14,
      "y": 2,
      "z": 5,
      "name": "Soil_Dirt"
    },
    {
      "x": -14,
      "y": 3,
      "z": 5,
      "name": "Soil_Dirt"
    },
    {
      "x": -14,
      "y": 4,
      "z": 5,
      "name": "Soil_Dirt"
    },
    {
      "x": -14,
      "y": 5,
      "z": 5,
      "name": "Rock_Stone_Brick_Smooth"
    },
    {
      "x": -14,
      "y": 0,
      "z": 6,
      "name": "Soil_Dirt"
    },
    {
      "x": -14,
      "y": 1,
      "z": 6,
      "name": "Soil_Dirt"
    },
    {
      "x": -14,
      "y": 2,
      "z": 6,
      "name": "Soil_Dirt"
    },
    {
      "x": -14,
      "y": 3,
      "z": 6,
      "name": "Soil_Dirt"
    },
    {
      "x": -14,
      "y": 4,
      "z": 6,
      "name": "Soil_Dirt"
    },
    {
      "x": -14,
      "y": 5,
      "z": 6,
      "name": "Rock_Stone_Brick_Smooth"
    },
    {
      "x": -14,
      "y": 0,
      "z": 7,
      "name": "Soil_Dirt"
    },
    {
      "x": -14,
      "y": 1,
      "z": 7,
      "name": "Soil_Dirt"
    },
    {
      "x": -14,
      "y": 2,
      "z": 7,
      "name": "Soil_Dirt"
    },
    {
      "x": -14,
      "y": 3,
      "z": 7,
      "name": "Soil_Dirt"
    },
    {
      "x": -14,
      "y": 4,
      "z": 7,
      "name": "Soil_Dirt"
    },
    {
      "x": -14,
      "y": 5,
      "z": 7,
      "name": "Rock_Stone_Brick_Smooth"
    },
    {
      "x": -14,
      "y": 0,
      "z": 8,
      "name": "Soil_Dirt"
    },
    {
      "x": -14,
      "y": 1,
      "z": 8,
      "name": "Soil_Dirt"
    },
    {
      "x": -14,
      "y": 2,
      "z": 8,
      "name": "Soil_Dirt"
    },
    {
      "x": -14,
      "y": 3,
      "z": 8,
      "name": "Soil_Dirt"
    },
    {
      "x": -14,
      "y": 4,
      "z": 8,
      "name": "Soil_Dirt"
    },
    {
      "x": -14,
      "y": 5,
      "z": 8,
      "name": "Rock_Stone_Brick_Smooth"
    },
    {
      "x": -14,
      "y": 0,
      "z": 9,
      "name": "Soil_Dirt"
    },
    {
      "x": -14,
      "y": 1,
      "z": 9,
      "name": "Soil_Dirt"
    },
    {
      "x": -14,
      "y": 2,
      "z": 9,
      "name": "Soil_Dirt"
    },
    {
      "x": -14,
      "y": 3,
      "z": 9,
      "name": "Soil_Dirt"
    },
    {
      "x": -14,
      "y": 4,
      "z": 9,
      "name": "Soil_Dirt"
    },
    {
      "x": -14,
      "y": 5,
      "z": 9,
      "name": "Rock_Stone_Brick_Smooth"
    },
    {
      "x": -14,
      "y": 0,
      "z": 10,
      "name": "Soil_Dirt"
    },
    {
      "x": -14,
      "y": 1,
      "z": 10,
      "name": "Soil_Dirt"
    },
    {
      "x": -14,
      "y": 2,
      "z": 10,
      "name": "Soil_Dirt"
    },
    {
      "x": -14,
      "y": 3,
      "z": 10,
      "name": "Soil_Dirt"
    },
    {
      "x": -14,
      "y": 4,
      "z": 10,
      "name": "Soil_Dirt"
    },
    {
      "x": -14,
      "y": 5,
      "z": 10,
      "name": "Rock_Stone_Brick_Smooth"
    },
    {
      "x": -14,
      "y": 0,
      "z": 11,
      "name": "Soil_Dirt"
    },
    {
      "x": -14,
      "y": 1,
      "z": 11,
      "name": "Soil_Dirt"
    },
    {
      "x": -14,
      "y": 2,
      "z": 11,
      "name": "Soil_Dirt"
    },
    {
      "x": -14,
      "y": 3,
      "z": 11,
      "name": "Soil_Dirt"
    },
    {
      "x": -14,
      "y": 4,
      "z": 11,
      "name": "Soil_Dirt"
    },
    {
      "x": -14,
      "y": 5,
      "z": 11,
      "name": "Rock_Stone_Brick_Smooth"
    },
    {
      "x": -14,
      "y": 0,
      "z": 12,
      "name": "Soil_Dirt"
    },
    {
      "x": -14,
      "y": 1,
      "z": 12,
      "name": "Soil_Dirt"
    },
    {
      "x": -14,
      "y": 2,
      "z": 12,
      "name": "Soil_Dirt"
    },
    {
      "x": -14,
      "y": 3,
      "z": 12,
      "name": "Soil_Dirt"
    },
    {
      "x": -14,
      "y": 4,
      "z": 12,
      "name": "Soil_Dirt"
    },
    {
      "x": -14,
      "y": 5,
      "z": 12,
      "name": "Rock_Stone_Brick_Smooth"
    },
    {
      "x": -14,
      "y": 0,
      "z": 13,
      "name": "Soil_Dirt"
    },
    {
      "x": -14,
      "y": 1,
      "z": 13,
      "name": "Soil_Dirt"
    },
    {
      "x": -14,
      "y": 2,
      "z": 13,
      "name": "Soil_Dirt"
    },
    {
      "x": -14,
      "y": 3,
      "z": 13,
      "name": "Soil_Dirt"
    },
    {
      "x": -14,
      "y": 4,
      "z": 13,
      "name": "Soil_Dirt"
    },
    {
      "x": -14,
      "y": 5,
      "z": 13,
      "name": "Rock_Stone_Brick_Smooth"
    },
    {
      "x": -14,
      "y": 0,
      "z": 14,
      "name": "Soil_Dirt"
    },
    {
      "x": -14,
      "y": 1,
      "z": 14,
      "name": "Soil_Dirt"
    },
    {
      "x": -14,
      "y": 2,
      "z": 14,
      "name": "Soil_Dirt"
    },
    {
      "x": -14,
      "y": 3,
      "z": 14,
      "name": "Soil_Dirt"
    },
    {
      "x": -14,
      "y": 4,
      "z": 14,
      "name": "Soil_Dirt"
    },
    {
      "x": -14,
      "y": 5,
      "z": 14,
      "name": "Rock_Stone_Brick_Smooth"
    },
    {
      "x": -14,
      "y": 0,
      "z": 15,
      "name": "Soil_Dirt"
    },
    {
      "x": -14,
      "y": 1,
      "z": 15,
      "name": "Soil_Dirt"
    },
    {
      "x": -14,
      "y": 2,
      "z": 15,
      "name": "Soil_Dirt"
    },
    {
      "x": -14,
      "y": 3,
      "z": 15,
      "name": "Soil_Dirt"
    },
    {
      "x": -14,
      "y": 4,
      "z": 15,
      "name": "Soil_Dirt"
    },
    {
      "x": -14,
      "y": 5,
      "z": 15,
      "name": "Rock_Stone_Brick_Smooth"
    },
    {
      "x": -13,
      "y": 0,
      "z": -14,
      "name": "Soil_Dirt"
    },
    {
      "x": -13,
      "y": 1,
      "z": -14,
      "name": "Soil_Dirt"
    },
    {
      "x": -13,
      "y": 2,
      "z": -14,
      "name": "Soil_Dirt"
    },
    {
      "x": -13,
      "y": 3,
      "z": -14,
      "name": "Soil_Dirt"
    },
    {
      "x": -13,
      "y": 4,
      "z": -14,
      "name": "Soil_Dirt"
    },
    {
      "x": -13,
      "y": 5,
      "z": -14,
      "name": "Rock_Stone_Brick_Smooth"
    },
    {
      "x": -13,
      "y": 0,
      "z": -13,
      "name": "Soil_Dirt"
    },
    {
      "x": -13,
      "y": 1,
      "z": -13,
      "name": "Soil_Dirt"
    },
    {
      "x": -13,
      "y": 2,
      "z": -13,
      "name": "Soil_Dirt"
    },
    {
      "x": -13,
      "y": 3,
      "z": -13,
      "name": "Soil_Dirt"
    },
    {
      "x": -13,
      "y": 4,
      "z": -13,
      "name": "Soil_Dirt"
    },
    {
      "x": -13,
      "y": 5,
      "z": -13,
      "name": "Soil_Dirt"
    },
    {
      "x": -13,
      "y": 0,
      "z": -12,
      "name": "Soil_Dirt"
    },
    {
      "x": -13,
      "y": 1,
      "z": -12,
      "name": "Soil_Dirt"
    },
    {
      "x": -13,
      "y": 2,
      "z": -12,
      "name": "Soil_Dirt"
    },
    {
      "x": -13,
      "y": 3,
      "z": -12,
      "name": "Soil_Dirt"
    },
    {
      "x": -13,
      "y": 4,
      "z": -12,
      "name": "Soil_Dirt"
    },
    {
      "x": -13,
      "y": 5,
      "z": -12,
      "name": "Soil_Pathway"
    },
    {
      "x": -13,
      "y": 0,
      "z": -11,
      "name": "Soil_Dirt"
    },
    {
      "x": -13,
      "y": 1,
      "z": -11,
      "name": "Soil_Dirt"
    },
    {
      "x": -13,
      "y": 2,
      "z": -11,
      "name": "Soil_Dirt"
    },
    {
      "x": -13,
      "y": 3,
      "z": -11,
      "name": "Soil_Dirt"
    },
    {
      "x": -13,
      "y": 4,
      "z": -11,
      "name": "Soil_Dirt"
    },
    {
      "x": -13,
      "y": 5,
      "z": -11,
      "name": "Soil_Clay"
    },
    {
      "x": -13,
      "y": 0,
      "z": -10,
      "name": "Soil_Dirt"
    },
    {
      "x": -13,
      "y": 1,
      "z": -10,
      "name": "Soil_Dirt"
    },
    {
      "x": -13,
      "y": 2,
      "z": -10,
      "name": "Soil_Dirt"
    },
    {
      "x": -13,
      "y": 3,
      "z": -10,
      "name": "Soil_Dirt"
    },
    {
      "x": -13,
      "y": 4,
      "z": -10,
      "name": "Soil_Dirt"
    },
    {
      "x": -13,
      "y": 5,
      "z": -10,
      "name": "Soil_Pathway"
    },
    {
      "x": -13,
      "y": 0,
      "z": -9,
      "name": "Soil_Dirt"
    },
    {
      "x": -13,
      "y": 1,
      "z": -9,
      "name": "Soil_Dirt"
    },
    {
      "x": -13,
      "y": 2,
      "z": -9,
      "name": "Soil_Dirt"
    },
    {
      "x": -13,
      "y": 3,
      "z": -9,
      "name": "Soil_Dirt"
    },
    {
      "x": -13,
      "y": 4,
      "z": -9,
      "name": "Soil_Dirt"
    },
    {
      "x": -13,
      "y": 5,
      "z": -9,
      "name": "Soil_Pathway"
    },
    {
      "x": -13,
      "y": 0,
      "z": -8,
      "name": "Soil_Dirt"
    },
    {
      "x": -13,
      "y": 1,
      "z": -8,
      "name": "Soil_Dirt"
    },
    {
      "x": -13,
      "y": 2,
      "z": -8,
      "name": "Soil_Dirt"
    },
    {
      "x": -13,
      "y": 3,
      "z": -8,
      "name": "Soil_Dirt"
    },
    {
      "x": -13,
      "y": 4,
      "z": -8,
      "name": "Soil_Dirt"
    },
    {
      "x": -13,
      "y": 5,
      "z": -8,
      "name": "Soil_Pathway"
    },
    {
      "x": -13,
      "y": 0,
      "z": -7,
      "name": "Soil_Dirt"
    },
    {
      "x": -13,
      "y": 1,
      "z": -7,
      "name": "Soil_Dirt"
    },
    {
      "x": -13,
      "y": 2,
      "z": -7,
      "name": "Soil_Dirt"
    },
    {
      "x": -13,
      "y": 3,
      "z": -7,
      "name": "Soil_Dirt"
    },
    {
      "x": -13,
      "y": 4,
      "z": -7,
      "name": "Soil_Dirt"
    },
    {
      "x": -13,
      "y": 5,
      "z": -7,
      "name": "Soil_Pathway"
    },
    {
      "x": -13,
      "y": 0,
      "z": -6,
      "name": "Soil_Dirt"
    },
    {
      "x": -13,
      "y": 1,
      "z": -6,
      "name": "Soil_Dirt"
    },
    {
      "x": -13,
      "y": 2,
      "z": -6,
      "name": "Soil_Dirt"
    },
    {
      "x": -13,
      "y": 3,
      "z": -6,
      "name": "Soil_Dirt"
    },
    {
      "x": -13,
      "y": 4,
      "z": -6,
      "name": "Soil_Dirt"
    },
    {
      "x": -13,
      "y": 5,
      "z": -6,
      "name": "Soil_Pathway"
    },
    {
      "x": -13,
      "y": 0,
      "z": -5,
      "name": "Soil_Dirt"
    },
    {
      "x": -13,
      "y": 1,
      "z": -5,
      "name": "Soil_Dirt"
    },
    {
      "x": -13,
      "y": 2,
      "z": -5,
      "name": "Soil_Dirt"
    },
    {
      "x": -13,
      "y": 3,
      "z": -5,
      "name": "Soil_Dirt"
    },
    {
      "x": -13,
      "y": 4,
      "z": -5,
      "name": "Soil_Dirt"
    },
    {
      "x": -13,
      "y": 5,
      "z": -5,
      "name": "Soil_Dirt"
    },
    {
      "x": -13,
      "y": 0,
      "z": -4,
      "name": "Soil_Dirt"
    },
    {
      "x": -13,
      "y": 1,
      "z": -4,
      "name": "Soil_Dirt"
    },
    {
      "x": -13,
      "y": 2,
      "z": -4,
      "name": "Soil_Dirt"
    },
    {
      "x": -13,
      "y": 3,
      "z": -4,
      "name": "Soil_Dirt"
    },
    {
      "x": -13,
      "y": 4,
      "z": -4,
      "name": "Soil_Dirt"
    },
    {
      "x": -13,
      "y": 5,
      "z": -4,
      "name": "Soil_Pathway"
    },
    {
      "x": -13,
      "y": 0,
      "z": -3,
      "name": "Soil_Dirt"
    },
    {
      "x": -13,
      "y": 1,
      "z": -3,
      "name": "Soil_Dirt"
    },
    {
      "x": -13,
      "y": 2,
      "z": -3,
      "name": "Soil_Dirt"
    },
    {
      "x": -13,
      "y": 3,
      "z": -3,
      "name": "Soil_Dirt"
    },
    {
      "x": -13,
      "y": 4,
      "z": -3,
      "name": "Soil_Dirt"
    },
    {
      "x": -13,
      "y": 5,
      "z": -3,
      "name": "Soil_Clay"
    },
    {
      "x": -13,
      "y": 0,
      "z": -2,
      "name": "Soil_Dirt"
    },
    {
      "x": -13,
      "y": 1,
      "z": -2,
      "name": "Soil_Dirt"
    },
    {
      "x": -13,
      "y": 2,
      "z": -2,
      "name": "Soil_Dirt"
    },
    {
      "x": -13,
      "y": 3,
      "z": -2,
      "name": "Soil_Dirt"
    },
    {
      "x": -13,
      "y": 4,
      "z": -2,
      "name": "Soil_Dirt"
    },
    {
      "x": -13,
      "y": 5,
      "z": -2,
      "name": "Soil_Clay"
    },
    {
      "x": -13,
      "y": 0,
      "z": -1,
      "name": "Soil_Dirt"
    },
    {
      "x": -13,
      "y": 1,
      "z": -1,
      "name": "Soil_Dirt"
    },
    {
      "x": -13,
      "y": 2,
      "z": -1,
      "name": "Soil_Dirt"
    },
    {
      "x": -13,
      "y": 3,
      "z": -1,
      "name": "Soil_Dirt"
    },
    {
      "x": -13,
      "y": 4,
      "z": -1,
      "name": "Soil_Dirt"
    },
    {
      "x": -13,
      "y": 5,
      "z": -1,
      "name": "Soil_Pathway"
    },
    {
      "x": -13,
      "y": 0,
      "z": 0,
      "name": "Soil_Dirt"
    },
    {
      "x": -13,
      "y": 1,
      "z": 0,
      "name": "Soil_Dirt"
    },
    {
      "x": -13,
      "y": 2,
      "z": 0,
      "name": "Soil_Dirt"
    },
    {
      "x": -13,
      "y": 3,
      "z": 0,
      "name": "Soil_Dirt"
    },
    {
      "x": -13,
      "y": 4,
      "z": 0,
      "name": "Soil_Dirt"
    },
    {
      "x": -13,
      "y": 5,
      "z": 0,
      "name": "Soil_Pathway"
    },
    {
      "x": -13,
      "y": 0,
      "z": 1,
      "name": "Soil_Dirt"
    },
    {
      "x": -13,
      "y": 1,
      "z": 1,
      "name": "Soil_Dirt"
    },
    {
      "x": -13,
      "y": 2,
      "z": 1,
      "name": "Soil_Dirt"
    },
    {
      "x": -13,
      "y": 3,
      "z": 1,
      "name": "Soil_Dirt"
    },
    {
      "x": -13,
      "y": 4,
      "z": 1,
      "name": "Soil_Dirt"
    },
    {
      "x": -13,
      "y": 5,
      "z": 1,
      "name": "Soil_Pathway"
    },
    {
      "x": -13,
      "y": 0,
      "z": 2,
      "name": "Soil_Dirt"
    },
    {
      "x": -13,
      "y": 1,
      "z": 2,
      "name": "Soil_Dirt"
    },
    {
      "x": -13,
      "y": 2,
      "z": 2,
      "name": "Soil_Dirt"
    },
    {
      "x": -13,
      "y": 3,
      "z": 2,
      "name": "Soil_Dirt"
    },
    {
      "x": -13,
      "y": 4,
      "z": 2,
      "name": "Soil_Dirt"
    },
    {
      "x": -13,
      "y": 5,
      "z": 2,
      "name": "Soil_Dirt"
    },
    {
      "x": -13,
      "y": 0,
      "z": 3,
      "name": "Soil_Dirt"
    },
    {
      "x": -13,
      "y": 1,
      "z": 3,
      "name": "Soil_Dirt"
    },
    {
      "x": -13,
      "y": 2,
      "z": 3,
      "name": "Soil_Dirt"
    },
    {
      "x": -13,
      "y": 3,
      "z": 3,
      "name": "Soil_Dirt"
    },
    {
      "x": -13,
      "y": 4,
      "z": 3,
      "name": "Soil_Dirt"
    },
    {
      "x": -13,
      "y": 5,
      "z": 3,
      "name": "Soil_Pathway"
    },
    {
      "x": -13,
      "y": 0,
      "z": 4,
      "name": "Soil_Dirt"
    },
    {
      "x": -13,
      "y": 1,
      "z": 4,
      "name": "Soil_Dirt"
    },
    {
      "x": -13,
      "y": 2,
      "z": 4,
      "name": "Soil_Dirt"
    },
    {
      "x": -13,
      "y": 3,
      "z": 4,
      "name": "Soil_Dirt"
    },
    {
      "x": -13,
      "y": 4,
      "z": 4,
      "name": "Soil_Dirt"
    },
    {
      "x": -13,
      "y": 5,
      "z": 4,
      "name": "Soil_Clay"
    },
    {
      "x": -13,
      "y": 0,
      "z": 5,
      "name": "Soil_Dirt"
    },
    {
      "x": -13,
      "y": 1,
      "z": 5,
      "name": "Soil_Dirt"
    },
    {
      "x": -13,
      "y": 2,
      "z": 5,
      "name": "Soil_Dirt"
    },
    {
      "x": -13,
      "y": 3,
      "z": 5,
      "name": "Soil_Dirt"
    },
    {
      "x": -13,
      "y": 4,
      "z": 5,
      "name": "Soil_Dirt"
    },
    {
      "x": -13,
      "y": 5,
      "z": 5,
      "name": "Soil_Pathway"
    },
    {
      "x": -13,
      "y": 0,
      "z": 6,
      "name": "Soil_Dirt"
    },
    {
      "x": -13,
      "y": 1,
      "z": 6,
      "name": "Soil_Dirt"
    },
    {
      "x": -13,
      "y": 2,
      "z": 6,
      "name": "Soil_Dirt"
    },
    {
      "x": -13,
      "y": 3,
      "z": 6,
      "name": "Soil_Dirt"
    },
    {
      "x": -13,
      "y": 4,
      "z": 6,
      "name": "Soil_Dirt"
    },
    {
      "x": -13,
      "y": 5,
      "z": 6,
      "name": "Soil_Pathway"
    },
    {
      "x": -13,
      "y": 0,
      "z": 7,
      "name": "Soil_Dirt"
    },
    {
      "x": -13,
      "y": 1,
      "z": 7,
      "name": "Soil_Dirt"
    },
    {
      "x": -13,
      "y": 2,
      "z": 7,
      "name": "Soil_Dirt"
    },
    {
      "x": -13,
      "y": 3,
      "z": 7,
      "name": "Soil_Dirt"
    },
    {
      "x": -13,
      "y": 4,
      "z": 7,
      "name": "Soil_Dirt"
    },
    {
      "x": -13,
      "y": 5,
      "z": 7,
      "name": "Soil_Pathway"
    },
    {
      "x": -13,
      "y": 0,
      "z": 8,
      "name": "Soil_Dirt"
    },
    {
      "x": -13,
      "y": 1,
      "z": 8,
      "name": "Soil_Dirt"
    },
    {
      "x": -13,
      "y": 2,
      "z": 8,
      "name": "Soil_Dirt"
    },
    {
      "x": -13,
      "y": 3,
      "z": 8,
      "name": "Soil_Dirt"
    },
    {
      "x": -13,
      "y": 4,
      "z": 8,
      "name": "Soil_Dirt"
    },
    {
      "x": -13,
      "y": 5,
      "z": 8,
      "name": "Soil_Clay"
    },
    {
      "x": -13,
      "y": 0,
      "z": 9,
      "name": "Soil_Dirt"
    },
    {
      "x": -13,
      "y": 1,
      "z": 9,
      "name": "Soil_Dirt"
    },
    {
      "x": -13,
      "y": 2,
      "z": 9,
      "name": "Soil_Dirt"
    },
    {
      "x": -13,
      "y": 3,
      "z": 9,
      "name": "Soil_Dirt"
    },
    {
      "x": -13,
      "y": 4,
      "z": 9,
      "name": "Soil_Dirt"
    },
    {
      "x": -13,
      "y": 5,
      "z": 9,
      "name": "Soil_Pathway"
    },
    {
      "x": -13,
      "y": 0,
      "z": 10,
      "name": "Soil_Dirt"
    },
    {
      "x": -13,
      "y": 1,
      "z": 10,
      "name": "Soil_Dirt"
    },
    {
      "x": -13,
      "y": 2,
      "z": 10,
      "name": "Soil_Dirt"
    },
    {
      "x": -13,
      "y": 3,
      "z": 10,
      "name": "Soil_Dirt"
    },
    {
      "x": -13,
      "y": 4,
      "z": 10,
      "name": "Soil_Dirt"
    },
    {
      "x": -13,
      "y": 5,
      "z": 10,
      "name": "Soil_Pathway"
    },
    {
      "x": -13,
      "y": 0,
      "z": 11,
      "name": "Soil_Dirt"
    },
    {
      "x": -13,
      "y": 1,
      "z": 11,
      "name": "Soil_Dirt"
    },
    {
      "x": -13,
      "y": 2,
      "z": 11,
      "name": "Soil_Dirt"
    },
    {
      "x": -13,
      "y": 3,
      "z": 11,
      "name": "Soil_Dirt"
    },
    {
      "x": -13,
      "y": 4,
      "z": 11,
      "name": "Soil_Dirt"
    },
    {
      "x": -13,
      "y": 5,
      "z": 11,
      "name": "Soil_Clay"
    },
    {
      "x": -13,
      "y": 0,
      "z": 12,
      "name": "Soil_Dirt"
    },
    {
      "x": -13,
      "y": 1,
      "z": 12,
      "name": "Soil_Dirt"
    },
    {
      "x": -13,
      "y": 2,
      "z": 12,
      "name": "Soil_Dirt"
    },
    {
      "x": -13,
      "y": 3,
      "z": 12,
      "name": "Soil_Dirt"
    },
    {
      "x": -13,
      "y": 4,
      "z": 12,
      "name": "Soil_Dirt"
    },
    {
      "x": -13,
      "y": 5,
      "z": 12,
      "name": "Soil_Dirt"
    },
    {
      "x": -13,
      "y": 0,
      "z": 13,
      "name": "Soil_Dirt"
    },
    {
      "x": -13,
      "y": 1,
      "z": 13,
      "name": "Soil_Dirt"
    },
    {
      "x": -13,
      "y": 2,
      "z": 13,
      "name": "Soil_Dirt"
    },
    {
      "x": -13,
      "y": 3,
      "z": 13,
      "name": "Soil_Dirt"
    },
    {
      "x": -13,
      "y": 4,
      "z": 13,
      "name": "Soil_Dirt"
    },
    {
      "x": -13,
      "y": 5,
      "z": 13,
      "name": "Soil_Pathway"
    },
    {
      "x": -13,
      "y": 0,
      "z": 14,
      "name": "Soil_Dirt"
    },
    {
      "x": -13,
      "y": 1,
      "z": 14,
      "name": "Soil_Dirt"
    },
    {
      "x": -13,
      "y": 2,
      "z": 14,
      "name": "Soil_Dirt"
    },
    {
      "x": -13,
      "y": 3,
      "z": 14,
      "name": "Soil_Dirt"
    },
    {
      "x": -13,
      "y": 4,
      "z": 14,
      "name": "Soil_Dirt"
    },
    {
      "x": -13,
      "y": 5,
      "z": 14,
      "name": "Soil_Clay"
    },
    {
      "x": -13,
      "y": 0,
      "z": 15,
      "name": "Soil_Dirt"
    },
    {
      "x": -13,
      "y": 1,
      "z": 15,
      "name": "Soil_Dirt"
    },
    {
      "x": -13,
      "y": 2,
      "z": 15,
      "name": "Soil_Dirt"
    },
    {
      "x": -13,
      "y": 3,
      "z": 15,
      "name": "Soil_Dirt"
    },
    {
      "x": -13,
      "y": 4,
      "z": 15,
      "name": "Soil_Dirt"
    },
    {
      "x": -13,
      "y": 5,
      "z": 15,
      "name": "Rock_Stone_Brick_Smooth"
    },
    {
      "x": -12,
      "y": 0,
      "z": -14,
      "name": "Soil_Dirt"
    },
    {
      "x": -12,
      "y": 1,
      "z": -14,
      "name": "Soil_Dirt"
    },
    {
      "x": -12,
      "y": 2,
      "z": -14,
      "name": "Soil_Dirt"
    },
    {
      "x": -12,
      "y": 3,
      "z": -14,
      "name": "Soil_Dirt"
    },
    {
      "x": -12,
      "y": 4,
      "z": -14,
      "name": "Soil_Dirt"
    },
    {
      "x": -12,
      "y": 5,
      "z": -14,
      "name": "Rock_Stone_Brick_Smooth"
    },
    {
      "x": -12,
      "y": 0,
      "z": -13,
      "name": "Soil_Dirt"
    },
    {
      "x": -12,
      "y": 1,
      "z": -13,
      "name": "Soil_Dirt"
    },
    {
      "x": -12,
      "y": 2,
      "z": -13,
      "name": "Soil_Dirt"
    },
    {
      "x": -12,
      "y": 3,
      "z": -13,
      "name": "Soil_Dirt"
    },
    {
      "x": -12,
      "y": 4,
      "z": -13,
      "name": "Soil_Dirt"
    },
    {
      "x": -12,
      "y": 5,
      "z": -13,
      "name": "Soil_Dirt"
    },
    {
      "x": -12,
      "y": 0,
      "z": -12,
      "name": "Soil_Dirt"
    },
    {
      "x": -12,
      "y": 1,
      "z": -12,
      "name": "Soil_Dirt"
    },
    {
      "x": -12,
      "y": 2,
      "z": -12,
      "name": "Soil_Dirt"
    },
    {
      "x": -12,
      "y": 3,
      "z": -12,
      "name": "Soil_Dirt"
    },
    {
      "x": -12,
      "y": 4,
      "z": -12,
      "name": "Soil_Dirt"
    },
    {
      "x": -12,
      "y": 5,
      "z": -12,
      "name": "Soil_Dirt"
    },
    {
      "x": -12,
      "y": 0,
      "z": -11,
      "name": "Soil_Dirt"
    },
    {
      "x": -12,
      "y": 1,
      "z": -11,
      "name": "Soil_Dirt"
    },
    {
      "x": -12,
      "y": 2,
      "z": -11,
      "name": "Soil_Dirt"
    },
    {
      "x": -12,
      "y": 3,
      "z": -11,
      "name": "Soil_Dirt"
    },
    {
      "x": -12,
      "y": 4,
      "z": -11,
      "name": "Soil_Dirt"
    },
    {
      "x": -12,
      "y": 5,
      "z": -11,
      "name": "Soil_Pathway"
    },
    {
      "x": -12,
      "y": 6,
      "z": -11,
      "name": "Cloth_Modern_Red_Roof_Vertical",
      "support": 15,
      "rotation": 3
    },
    {
      "x": -12,
      "y": 7,
      "z": -11,
      "name": "Cloth_Modern_Red_Roof_Vertical",
      "support": 15,
      "rotation": 3
    },
    {
      "x": -12,
      "y": 8,
      "z": -11,
      "name": "Cloth_Modern_Red_Roof_Vertical",
      "support": 15,
      "rotation": 3
    },
    {
      "x": -12,
      "y": 9,
      "z": -11,
      "name": "Cloth_Modern_Red_Roof_Vertical",
      "support": 15,
      "rotation": 3
    },
    {
      "x": -12,
      "y": 10,
      "z": -11,
      "name": "Cloth_Roof_Yellow_Flap",
      "support": 15,
      "rotation": 3
    },
    {
      "x": -12,
      "y": 0,
      "z": -10,
      "name": "Soil_Dirt"
    },
    {
      "x": -12,
      "y": 1,
      "z": -10,
      "name": "Soil_Dirt"
    },
    {
      "x": -12,
      "y": 2,
      "z": -10,
      "name": "Soil_Dirt"
    },
    {
      "x": -12,
      "y": 3,
      "z": -10,
      "name": "Soil_Dirt"
    },
    {
      "x": -12,
      "y": 4,
      "z": -10,
      "name": "Soil_Dirt"
    },
    {
      "x": -12,
      "y": 5,
      "z": -10,
      "name": "Soil_Pathway"
    },
    {
      "x": -12,
      "y": 6,
      "z": -10,
      "name": "Cloth_Modern_Red_Roof_Vertical",
      "support": 15,
      "rotation": 3
    },
    {
      "x": -12,
      "y": 7,
      "z": -10,
      "name": "Cloth_Modern_Red_Roof_Vertical",
      "support": 15,
      "rotation": 3
    },
    {
      "x": -12,
      "y": 8,
      "z": -10,
      "name": "Cloth_Modern_Red_Roof_Vertical",
      "support": 15,
      "rotation": 3
    },
    {
      "x": -12,
      "y": 9,
      "z": -10,
      "name": "Cloth_Modern_Red_Roof_Vertical",
      "support": 15,
      "rotation": 3
    },
    {
      "x": -12,
      "y": 10,
      "z": -10,
      "name": "Cloth_Roof_Yellow_Flap",
      "support": 15,
      "rotation": 3
    },
    {
      "x": -12,
      "y": 0,
      "z": -9,
      "name": "Soil_Dirt"
    },
    {
      "x": -12,
      "y": 1,
      "z": -9,
      "name": "Soil_Dirt"
    },
    {
      "x": -12,
      "y": 2,
      "z": -9,
      "name": "Soil_Dirt"
    },
    {
      "x": -12,
      "y": 3,
      "z": -9,
      "name": "Soil_Dirt"
    },
    {
      "x": -12,
      "y": 4,
      "z": -9,
      "name": "Soil_Dirt"
    },
    {
      "x": -12,
      "y": 5,
      "z": -9,
      "name": "Soil_Pathway"
    },
    {
      "x": -12,
      "y": 6,
      "z": -9,
      "name": "Cloth_Modern_Red_Roof_Vertical",
      "support": 15,
      "rotation": 3
    },
    {
      "x": -12,
      "y": 7,
      "z": -9,
      "name": "Cloth_Modern_Red_Roof_Vertical",
      "support": 15,
      "rotation": 3
    },
    {
      "x": -12,
      "y": 8,
      "z": -9,
      "name": "Cloth_Modern_Red_Roof_Vertical",
      "support": 15,
      "rotation": 3
    },
    {
      "x": -12,
      "y": 9,
      "z": -9,
      "name": "Cloth_Modern_Red_Roof_Vertical",
      "support": 15,
      "rotation": 3
    },
    {
      "x": -12,
      "y": 10,
      "z": -9,
      "name": "Cloth_Roof_Yellow_Flap",
      "support": 15,
      "rotation": 3
    },
    {
      "x": -12,
      "y": 0,
      "z": -8,
      "name": "Soil_Dirt"
    },
    {
      "x": -12,
      "y": 1,
      "z": -8,
      "name": "Soil_Dirt"
    },
    {
      "x": -12,
      "y": 2,
      "z": -8,
      "name": "Soil_Dirt"
    },
    {
      "x": -12,
      "y": 3,
      "z": -8,
      "name": "Soil_Dirt"
    },
    {
      "x": -12,
      "y": 4,
      "z": -8,
      "name": "Soil_Dirt"
    },
    {
      "x": -12,
      "y": 5,
      "z": -8,
      "name": "Soil_Dirt"
    },
    {
      "x": -12,
      "y": 6,
      "z": -8,
      "name": "Cloth_Modern_Red_Roof_Vertical",
      "support": 15,
      "rotation": 3
    },
    {
      "x": -12,
      "y": 7,
      "z": -8,
      "name": "Cloth_Modern_Red_Roof_Vertical",
      "support": 15,
      "rotation": 3
    },
    {
      "x": -12,
      "y": 8,
      "z": -8,
      "name": "Cloth_Modern_Red_Roof_Vertical",
      "support": 15,
      "rotation": 3
    },
    {
      "x": -12,
      "y": 9,
      "z": -8,
      "name": "Cloth_Modern_Red_Roof_Vertical",
      "support": 15,
      "rotation": 3
    },
    {
      "x": -12,
      "y": 10,
      "z": -8,
      "name": "Cloth_Roof_Yellow_Flap",
      "support": 15,
      "rotation": 3
    },
    {
      "x": -12,
      "y": 0,
      "z": -7,
      "name": "Soil_Dirt"
    },
    {
      "x": -12,
      "y": 1,
      "z": -7,
      "name": "Soil_Dirt"
    },
    {
      "x": -12,
      "y": 2,
      "z": -7,
      "name": "Soil_Dirt"
    },
    {
      "x": -12,
      "y": 3,
      "z": -7,
      "name": "Soil_Dirt"
    },
    {
      "x": -12,
      "y": 4,
      "z": -7,
      "name": "Soil_Dirt"
    },
    {
      "x": -12,
      "y": 5,
      "z": -7,
      "name": "Soil_Clay"
    },
    {
      "x": -12,
      "y": 6,
      "z": -7,
      "name": "Cloth_Modern_Red_Roof_Vertical",
      "support": 15,
      "rotation": 3
    },
    {
      "x": -12,
      "y": 7,
      "z": -7,
      "name": "Cloth_Modern_Red_Roof_Vertical",
      "support": 15,
      "rotation": 3
    },
    {
      "x": -12,
      "y": 8,
      "z": -7,
      "name": "Cloth_Modern_Red_Roof_Vertical",
      "support": 15,
      "rotation": 3
    },
    {
      "x": -12,
      "y": 9,
      "z": -7,
      "name": "Cloth_Modern_Red_Roof_Vertical",
      "support": 15,
      "rotation": 3
    },
    {
      "x": -12,
      "y": 10,
      "z": -7,
      "name": "Cloth_Roof_Yellow_Flap",
      "support": 15,
      "rotation": 3
    },
    {
      "x": -12,
      "y": 0,
      "z": -6,
      "name": "Soil_Dirt"
    },
    {
      "x": -12,
      "y": 1,
      "z": -6,
      "name": "Soil_Dirt"
    },
    {
      "x": -12,
      "y": 2,
      "z": -6,
      "name": "Soil_Dirt"
    },
    {
      "x": -12,
      "y": 3,
      "z": -6,
      "name": "Soil_Dirt"
    },
    {
      "x": -12,
      "y": 4,
      "z": -6,
      "name": "Soil_Dirt"
    },
    {
      "x": -12,
      "y": 5,
      "z": -6,
      "name": "Soil_Clay"
    },
    {
      "x": -12,
      "y": 6,
      "z": -6,
      "name": "Cloth_Modern_Red_Roof_Vertical",
      "support": 15,
      "rotation": 3
    },
    {
      "x": -12,
      "y": 7,
      "z": -6,
      "name": "Cloth_Modern_Red_Roof_Vertical",
      "support": 15,
      "rotation": 3
    },
    {
      "x": -12,
      "y": 8,
      "z": -6,
      "name": "Cloth_Modern_Red_Roof_Vertical",
      "support": 15,
      "rotation": 3
    },
    {
      "x": -12,
      "y": 9,
      "z": -6,
      "name": "Cloth_Modern_Red_Roof_Vertical",
      "support": 15,
      "rotation": 3
    },
    {
      "x": -12,
      "y": 10,
      "z": -6,
      "name": "Cloth_Roof_Yellow_Flap",
      "support": 15,
      "rotation": 3
    },
    {
      "x": -12,
      "y": 0,
      "z": -5,
      "name": "Soil_Dirt"
    },
    {
      "x": -12,
      "y": 1,
      "z": -5,
      "name": "Soil_Dirt"
    },
    {
      "x": -12,
      "y": 2,
      "z": -5,
      "name": "Soil_Dirt"
    },
    {
      "x": -12,
      "y": 3,
      "z": -5,
      "name": "Soil_Dirt"
    },
    {
      "x": -12,
      "y": 4,
      "z": -5,
      "name": "Soil_Dirt"
    },
    {
      "x": -12,
      "y": 5,
      "z": -5,
      "name": "Soil_Clay"
    },
    {
      "x": -12,
      "y": 6,
      "z": -5,
      "name": "Cloth_Modern_Red_Roof_Vertical",
      "support": 15,
      "rotation": 3
    },
    {
      "x": -12,
      "y": 7,
      "z": -5,
      "name": "Cloth_Modern_Red_Roof_Vertical",
      "support": 15,
      "rotation": 3
    },
    {
      "x": -12,
      "y": 8,
      "z": -5,
      "name": "Cloth_Modern_Red_Roof_Vertical",
      "support": 15,
      "rotation": 3
    },
    {
      "x": -12,
      "y": 9,
      "z": -5,
      "name": "Cloth_Modern_Red_Roof_Vertical",
      "support": 15,
      "rotation": 3
    },
    {
      "x": -12,
      "y": 10,
      "z": -5,
      "name": "Cloth_Roof_Yellow_Flap",
      "support": 15,
      "rotation": 3
    },
    {
      "x": -12,
      "y": 0,
      "z": -4,
      "name": "Soil_Dirt"
    },
    {
      "x": -12,
      "y": 1,
      "z": -4,
      "name": "Soil_Dirt"
    },
    {
      "x": -12,
      "y": 2,
      "z": -4,
      "name": "Soil_Dirt"
    },
    {
      "x": -12,
      "y": 3,
      "z": -4,
      "name": "Soil_Dirt"
    },
    {
      "x": -12,
      "y": 4,
      "z": -4,
      "name": "Soil_Dirt"
    },
    {
      "x": -12,
      "y": 5,
      "z": -4,
      "name": "Soil_Clay"
    },
    {
      "x": -12,
      "y": 6,
      "z": -4,
      "name": "Cloth_Modern_Red_Roof_Vertical",
      "support": 15,
      "rotation": 3
    },
    {
      "x": -12,
      "y": 7,
      "z": -4,
      "name": "Cloth_Modern_Red_Roof_Vertical",
      "support": 15,
      "rotation": 3
    },
    {
      "x": -12,
      "y": 8,
      "z": -4,
      "name": "Cloth_Modern_Red_Roof_Vertical",
      "support": 15,
      "rotation": 3
    },
    {
      "x": -12,
      "y": 9,
      "z": -4,
      "name": "Cloth_Modern_Red_Roof_Vertical",
      "support": 15,
      "rotation": 3
    },
    {
      "x": -12,
      "y": 10,
      "z": -4,
      "name": "Cloth_Roof_Yellow_Flap",
      "support": 15,
      "rotation": 3
    },
    {
      "x": -12,
      "y": 0,
      "z": -3,
      "name": "Soil_Dirt"
    },
    {
      "x": -12,
      "y": 1,
      "z": -3,
      "name": "Soil_Dirt"
    },
    {
      "x": -12,
      "y": 2,
      "z": -3,
      "name": "Soil_Dirt"
    },
    {
      "x": -12,
      "y": 3,
      "z": -3,
      "name": "Soil_Dirt"
    },
    {
      "x": -12,
      "y": 4,
      "z": -3,
      "name": "Soil_Dirt"
    },
    {
      "x": -12,
      "y": 5,
      "z": -3,
      "name": "Soil_Clay"
    },
    {
      "x": -12,
      "y": 6,
      "z": -3,
      "name": "Cloth_Modern_Red_Roof_Vertical",
      "support": 15,
      "rotation": 3
    },
    {
      "x": -12,
      "y": 7,
      "z": -3,
      "name": "Cloth_Modern_Red_Roof_Vertical",
      "support": 15,
      "rotation": 3
    },
    {
      "x": -12,
      "y": 8,
      "z": -3,
      "name": "Cloth_Modern_Red_Roof_Vertical",
      "support": 15,
      "rotation": 3
    },
    {
      "x": -12,
      "y": 9,
      "z": -3,
      "name": "Cloth_Modern_Red_Roof_Vertical",
      "support": 15,
      "rotation": 3
    },
    {
      "x": -12,
      "y": 10,
      "z": -3,
      "name": "Cloth_Roof_Yellow_Flap",
      "support": 15,
      "rotation": 3
    },
    {
      "x": -12,
      "y": 0,
      "z": -2,
      "name": "Soil_Dirt"
    },
    {
      "x": -12,
      "y": 1,
      "z": -2,
      "name": "Soil_Dirt"
    },
    {
      "x": -12,
      "y": 2,
      "z": -2,
      "name": "Soil_Dirt"
    },
    {
      "x": -12,
      "y": 3,
      "z": -2,
      "name": "Soil_Dirt"
    },
    {
      "x": -12,
      "y": 4,
      "z": -2,
      "name": "Soil_Dirt"
    },
    {
      "x": -12,
      "y": 5,
      "z": -2,
      "name": "Soil_Pathway"
    },
    {
      "x": -12,
      "y": 6,
      "z": -2,
      "name": "Cloth_Modern_Red_Roof_Vertical",
      "support": 15,
      "rotation": 3
    },
    {
      "x": -12,
      "y": 7,
      "z": -2,
      "name": "Cloth_Modern_Red_Roof_Vertical",
      "support": 15,
      "rotation": 3
    },
    {
      "x": -12,
      "y": 8,
      "z": -2,
      "name": "Cloth_Modern_Red_Roof_Vertical",
      "support": 15,
      "rotation": 3
    },
    {
      "x": -12,
      "y": 9,
      "z": -2,
      "name": "Cloth_Modern_Red_Roof_Vertical",
      "support": 15,
      "rotation": 3
    },
    {
      "x": -12,
      "y": 10,
      "z": -2,
      "name": "Cloth_Roof_Yellow_Flap",
      "support": 15,
      "rotation": 3
    },
    {
      "x": -12,
      "y": 0,
      "z": -1,
      "name": "Soil_Dirt"
    },
    {
      "x": -12,
      "y": 1,
      "z": -1,
      "name": "Soil_Dirt"
    },
    {
      "x": -12,
      "y": 2,
      "z": -1,
      "name": "Soil_Dirt"
    },
    {
      "x": -12,
      "y": 3,
      "z": -1,
      "name": "Soil_Dirt"
    },
    {
      "x": -12,
      "y": 4,
      "z": -1,
      "name": "Soil_Dirt"
    },
    {
      "x": -12,
      "y": 5,
      "z": -1,
      "name": "Soil_Clay"
    },
    {
      "x": -12,
      "y": 6,
      "z": -1,
      "name": "Cloth_Modern_Red_Roof_Vertical",
      "support": 15,
      "rotation": 3
    },
    {
      "x": -12,
      "y": 7,
      "z": -1,
      "name": "Cloth_Modern_Red_Roof_Vertical",
      "support": 15,
      "rotation": 3
    },
    {
      "x": -12,
      "y": 8,
      "z": -1,
      "name": "Cloth_Modern_Red_Roof_Vertical",
      "support": 15,
      "rotation": 3
    },
    {
      "x": -12,
      "y": 9,
      "z": -1,
      "name": "Cloth_Modern_Red_Roof_Vertical",
      "support": 15,
      "rotation": 3
    },
    {
      "x": -12,
      "y": 10,
      "z": -1,
      "name": "Cloth_Roof_Yellow_Flap",
      "support": 15,
      "rotation": 3
    },
    {
      "x": -12,
      "y": 0,
      "z": 0,
      "name": "Soil_Dirt"
    },
    {
      "x": -12,
      "y": 1,
      "z": 0,
      "name": "Soil_Dirt"
    },
    {
      "x": -12,
      "y": 2,
      "z": 0,
      "name": "Soil_Dirt"
    },
    {
      "x": -12,
      "y": 3,
      "z": 0,
      "name": "Soil_Dirt"
    },
    {
      "x": -12,
      "y": 4,
      "z": 0,
      "name": "Soil_Dirt"
    },
    {
      "x": -12,
      "y": 5,
      "z": 0,
      "name": "Soil_Dirt"
    },
    {
      "x": -12,
      "y": 6,
      "z": 0,
      "name": "Cloth_Modern_Red_Roof_Vertical",
      "support": 15,
      "rotation": 3
    },
    {
      "x": -12,
      "y": 7,
      "z": 0,
      "name": "Cloth_Modern_Red_Roof_Vertical",
      "support": 15,
      "rotation": 3
    },
    {
      "x": -12,
      "y": 8,
      "z": 0,
      "name": "Cloth_Modern_Red_Roof_Vertical",
      "support": 15,
      "rotation": 3
    },
    {
      "x": -12,
      "y": 9,
      "z": 0,
      "name": "Cloth_Modern_Red_Roof_Vertical",
      "support": 15,
      "rotation": 3
    },
    {
      "x": -12,
      "y": 10,
      "z": 0,
      "name": "Cloth_Roof_Yellow_Flap",
      "support": 15,
      "rotation": 3
    },
    {
      "x": -12,
      "y": 0,
      "z": 1,
      "name": "Soil_Dirt"
    },
    {
      "x": -12,
      "y": 1,
      "z": 1,
      "name": "Soil_Dirt"
    },
    {
      "x": -12,
      "y": 2,
      "z": 1,
      "name": "Soil_Dirt"
    },
    {
      "x": -12,
      "y": 3,
      "z": 1,
      "name": "Soil_Dirt"
    },
    {
      "x": -12,
      "y": 4,
      "z": 1,
      "name": "Soil_Dirt"
    },
    {
      "x": -12,
      "y": 5,
      "z": 1,
      "name": "Soil_Clay"
    },
    {
      "x": -12,
      "y": 6,
      "z": 1,
      "name": "Cloth_Modern_Red_Roof_Vertical",
      "support": 15,
      "rotation": 3
    },
    {
      "x": -12,
      "y": 7,
      "z": 1,
      "name": "Cloth_Modern_Red_Roof_Vertical",
      "support": 15,
      "rotation": 3
    },
    {
      "x": -12,
      "y": 8,
      "z": 1,
      "name": "Cloth_Modern_Red_Roof_Vertical",
      "support": 15,
      "rotation": 3
    },
    {
      "x": -12,
      "y": 9,
      "z": 1,
      "name": "Cloth_Modern_Red_Roof_Vertical",
      "support": 15,
      "rotation": 3
    },
    {
      "x": -12,
      "y": 10,
      "z": 1,
      "name": "Cloth_Roof_Yellow_Flap",
      "support": 15,
      "rotation": 3
    },
    {
      "x": -12,
      "y": 0,
      "z": 2,
      "name": "Soil_Dirt"
    },
    {
      "x": -12,
      "y": 1,
      "z": 2,
      "name": "Soil_Dirt"
    },
    {
      "x": -12,
      "y": 2,
      "z": 2,
      "name": "Soil_Dirt"
    },
    {
      "x": -12,
      "y": 3,
      "z": 2,
      "name": "Soil_Dirt"
    },
    {
      "x": -12,
      "y": 4,
      "z": 2,
      "name": "Soil_Dirt"
    },
    {
      "x": -12,
      "y": 5,
      "z": 2,
      "name": "Soil_Dirt"
    },
    {
      "x": -12,
      "y": 6,
      "z": 2,
      "name": "Cloth_Modern_Red_Roof_Vertical",
      "support": 15,
      "rotation": 3
    },
    {
      "x": -12,
      "y": 7,
      "z": 2,
      "name": "Cloth_Modern_Red_Roof_Vertical",
      "support": 15,
      "rotation": 3
    },
    {
      "x": -12,
      "y": 8,
      "z": 2,
      "name": "Cloth_Modern_Red_Roof_Vertical",
      "support": 15,
      "rotation": 3
    },
    {
      "x": -12,
      "y": 9,
      "z": 2,
      "name": "Cloth_Modern_Red_Roof_Vertical",
      "support": 15,
      "rotation": 3
    },
    {
      "x": -12,
      "y": 10,
      "z": 2,
      "name": "Cloth_Roof_Yellow_Flap",
      "support": 15,
      "rotation": 3
    },
    {
      "x": -12,
      "y": 0,
      "z": 3,
      "name": "Soil_Dirt"
    },
    {
      "x": -12,
      "y": 1,
      "z": 3,
      "name": "Soil_Dirt"
    },
    {
      "x": -12,
      "y": 2,
      "z": 3,
      "name": "Soil_Dirt"
    },
    {
      "x": -12,
      "y": 3,
      "z": 3,
      "name": "Soil_Dirt"
    },
    {
      "x": -12,
      "y": 4,
      "z": 3,
      "name": "Soil_Dirt"
    },
    {
      "x": -12,
      "y": 5,
      "z": 3,
      "name": "Soil_Pathway"
    },
    {
      "x": -12,
      "y": 6,
      "z": 3,
      "name": "Cloth_Modern_Red_Roof_Vertical",
      "support": 15,
      "rotation": 3
    },
    {
      "x": -12,
      "y": 7,
      "z": 3,
      "name": "Cloth_Modern_Red_Roof_Vertical",
      "support": 15,
      "rotation": 3
    },
    {
      "x": -12,
      "y": 8,
      "z": 3,
      "name": "Cloth_Modern_Red_Roof_Vertical",
      "support": 15,
      "rotation": 3
    },
    {
      "x": -12,
      "y": 9,
      "z": 3,
      "name": "Cloth_Modern_Red_Roof_Vertical",
      "support": 15,
      "rotation": 3
    },
    {
      "x": -12,
      "y": 10,
      "z": 3,
      "name": "Cloth_Roof_Yellow_Flap",
      "support": 15,
      "rotation": 3
    },
    {
      "x": -12,
      "y": 0,
      "z": 4,
      "name": "Soil_Dirt"
    },
    {
      "x": -12,
      "y": 1,
      "z": 4,
      "name": "Soil_Dirt"
    },
    {
      "x": -12,
      "y": 2,
      "z": 4,
      "name": "Soil_Dirt"
    },
    {
      "x": -12,
      "y": 3,
      "z": 4,
      "name": "Soil_Dirt"
    },
    {
      "x": -12,
      "y": 4,
      "z": 4,
      "name": "Soil_Dirt"
    },
    {
      "x": -12,
      "y": 5,
      "z": 4,
      "name": "Soil_Dirt"
    },
    {
      "x": -12,
      "y": 6,
      "z": 4,
      "name": "Cloth_Modern_Red_Roof_Vertical",
      "support": 15,
      "rotation": 3
    },
    {
      "x": -12,
      "y": 7,
      "z": 4,
      "name": "Cloth_Modern_Red_Roof_Vertical",
      "support": 15,
      "rotation": 3
    },
    {
      "x": -12,
      "y": 8,
      "z": 4,
      "name": "Cloth_Modern_Red_Roof_Vertical",
      "support": 15,
      "rotation": 3
    },
    {
      "x": -12,
      "y": 9,
      "z": 4,
      "name": "Cloth_Modern_Red_Roof_Vertical",
      "support": 15,
      "rotation": 3
    },
    {
      "x": -12,
      "y": 10,
      "z": 4,
      "name": "Cloth_Roof_Yellow_Flap",
      "support": 15,
      "rotation": 3
    },
    {
      "x": -12,
      "y": 0,
      "z": 5,
      "name": "Soil_Dirt"
    },
    {
      "x": -12,
      "y": 1,
      "z": 5,
      "name": "Soil_Dirt"
    },
    {
      "x": -12,
      "y": 2,
      "z": 5,
      "name": "Soil_Dirt"
    },
    {
      "x": -12,
      "y": 3,
      "z": 5,
      "name": "Soil_Dirt"
    },
    {
      "x": -12,
      "y": 4,
      "z": 5,
      "name": "Soil_Dirt"
    },
    {
      "x": -12,
      "y": 5,
      "z": 5,
      "name": "Soil_Pathway"
    },
    {
      "x": -12,
      "y": 6,
      "z": 5,
      "name": "Cloth_Modern_Red_Roof_Vertical",
      "support": 15,
      "rotation": 3
    },
    {
      "x": -12,
      "y": 7,
      "z": 5,
      "name": "Cloth_Modern_Red_Roof_Vertical",
      "support": 15,
      "rotation": 3
    },
    {
      "x": -12,
      "y": 8,
      "z": 5,
      "name": "Cloth_Modern_Red_Roof_Vertical",
      "support": 15,
      "rotation": 3
    },
    {
      "x": -12,
      "y": 9,
      "z": 5,
      "name": "Cloth_Modern_Red_Roof_Vertical",
      "support": 15,
      "rotation": 3
    },
    {
      "x": -12,
      "y": 10,
      "z": 5,
      "name": "Cloth_Roof_Yellow_Flap",
      "support": 15,
      "rotation": 3
    },
    {
      "x": -12,
      "y": 0,
      "z": 6,
      "name": "Soil_Dirt"
    },
    {
      "x": -12,
      "y": 1,
      "z": 6,
      "name": "Soil_Dirt"
    },
    {
      "x": -12,
      "y": 2,
      "z": 6,
      "name": "Soil_Dirt"
    },
    {
      "x": -12,
      "y": 3,
      "z": 6,
      "name": "Soil_Dirt"
    },
    {
      "x": -12,
      "y": 4,
      "z": 6,
      "name": "Soil_Dirt"
    },
    {
      "x": -12,
      "y": 5,
      "z": 6,
      "name": "Soil_Pathway"
    },
    {
      "x": -12,
      "y": 6,
      "z": 6,
      "name": "Cloth_Modern_Red_Roof_Vertical",
      "support": 15,
      "rotation": 3
    },
    {
      "x": -12,
      "y": 7,
      "z": 6,
      "name": "Cloth_Modern_Red_Roof_Vertical",
      "support": 15,
      "rotation": 3
    },
    {
      "x": -12,
      "y": 8,
      "z": 6,
      "name": "Cloth_Modern_Red_Roof_Vertical",
      "support": 15,
      "rotation": 3
    },
    {
      "x": -12,
      "y": 9,
      "z": 6,
      "name": "Cloth_Modern_Red_Roof_Vertical",
      "support": 15,
      "rotation": 3
    },
    {
      "x": -12,
      "y": 10,
      "z": 6,
      "name": "Cloth_Roof_Yellow_Flap",
      "support": 15,
      "rotation": 3
    },
    {
      "x": -12,
      "y": 0,
      "z": 7,
      "name": "Soil_Dirt"
    },
    {
      "x": -12,
      "y": 1,
      "z": 7,
      "name": "Soil_Dirt"
    },
    {
      "x": -12,
      "y": 2,
      "z": 7,
      "name": "Soil_Dirt"
    },
    {
      "x": -12,
      "y": 3,
      "z": 7,
      "name": "Soil_Dirt"
    },
    {
      "x": -12,
      "y": 4,
      "z": 7,
      "name": "Soil_Dirt"
    },
    {
      "x": -12,
      "y": 5,
      "z": 7,
      "name": "Soil_Clay"
    },
    {
      "x": -12,
      "y": 6,
      "z": 7,
      "name": "Cloth_Modern_Red_Roof_Vertical",
      "support": 15,
      "rotation": 3
    },
    {
      "x": -12,
      "y": 7,
      "z": 7,
      "name": "Cloth_Modern_Red_Roof_Vertical",
      "support": 15,
      "rotation": 3
    },
    {
      "x": -12,
      "y": 8,
      "z": 7,
      "name": "Cloth_Modern_Red_Roof_Vertical",
      "support": 15,
      "rotation": 3
    },
    {
      "x": -12,
      "y": 9,
      "z": 7,
      "name": "Cloth_Modern_Red_Roof_Vertical",
      "support": 15,
      "rotation": 3
    },
    {
      "x": -12,
      "y": 10,
      "z": 7,
      "name": "Cloth_Roof_Yellow_Flap",
      "support": 15,
      "rotation": 3
    },
    {
      "x": -12,
      "y": 0,
      "z": 8,
      "name": "Soil_Dirt"
    },
    {
      "x": -12,
      "y": 1,
      "z": 8,
      "name": "Soil_Dirt"
    },
    {
      "x": -12,
      "y": 2,
      "z": 8,
      "name": "Soil_Dirt"
    },
    {
      "x": -12,
      "y": 3,
      "z": 8,
      "name": "Soil_Dirt"
    },
    {
      "x": -12,
      "y": 4,
      "z": 8,
      "name": "Soil_Dirt"
    },
    {
      "x": -12,
      "y": 5,
      "z": 8,
      "name": "Soil_Clay"
    },
    {
      "x": -12,
      "y": 6,
      "z": 8,
      "name": "Cloth_Modern_Red_Roof_Vertical",
      "support": 15,
      "rotation": 3
    },
    {
      "x": -12,
      "y": 7,
      "z": 8,
      "name": "Cloth_Modern_Red_Roof_Vertical",
      "support": 15,
      "rotation": 3
    },
    {
      "x": -12,
      "y": 8,
      "z": 8,
      "name": "Cloth_Modern_Red_Roof_Vertical",
      "support": 15,
      "rotation": 3
    },
    {
      "x": -12,
      "y": 9,
      "z": 8,
      "name": "Cloth_Modern_Red_Roof_Vertical",
      "support": 15,
      "rotation": 3
    },
    {
      "x": -12,
      "y": 10,
      "z": 8,
      "name": "Cloth_Roof_Yellow_Flap",
      "support": 15,
      "rotation": 3
    },
    {
      "x": -12,
      "y": 0,
      "z": 9,
      "name": "Soil_Dirt"
    },
    {
      "x": -12,
      "y": 1,
      "z": 9,
      "name": "Soil_Dirt"
    },
    {
      "x": -12,
      "y": 2,
      "z": 9,
      "name": "Soil_Dirt"
    },
    {
      "x": -12,
      "y": 3,
      "z": 9,
      "name": "Soil_Dirt"
    },
    {
      "x": -12,
      "y": 4,
      "z": 9,
      "name": "Soil_Dirt"
    },
    {
      "x": -12,
      "y": 5,
      "z": 9,
      "name": "Soil_Pathway"
    },
    {
      "x": -12,
      "y": 6,
      "z": 9,
      "name": "Cloth_Modern_Red_Roof_Vertical",
      "support": 15,
      "rotation": 3
    },
    {
      "x": -12,
      "y": 7,
      "z": 9,
      "name": "Cloth_Modern_Red_Roof_Vertical",
      "support": 15,
      "rotation": 3
    },
    {
      "x": -12,
      "y": 8,
      "z": 9,
      "name": "Cloth_Modern_Red_Roof_Vertical",
      "support": 15,
      "rotation": 3
    },
    {
      "x": -12,
      "y": 9,
      "z": 9,
      "name": "Cloth_Modern_Red_Roof_Vertical",
      "support": 15,
      "rotation": 3
    },
    {
      "x": -12,
      "y": 10,
      "z": 9,
      "name": "Cloth_Roof_Yellow_Flap",
      "support": 15,
      "rotation": 3
    },
    {
      "x": -12,
      "y": 0,
      "z": 10,
      "name": "Soil_Dirt"
    },
    {
      "x": -12,
      "y": 1,
      "z": 10,
      "name": "Soil_Dirt"
    },
    {
      "x": -12,
      "y": 2,
      "z": 10,
      "name": "Soil_Dirt"
    },
    {
      "x": -12,
      "y": 3,
      "z": 10,
      "name": "Soil_Dirt"
    },
    {
      "x": -12,
      "y": 4,
      "z": 10,
      "name": "Soil_Dirt"
    },
    {
      "x": -12,
      "y": 5,
      "z": 10,
      "name": "Soil_Dirt"
    },
    {
      "x": -12,
      "y": 6,
      "z": 10,
      "name": "Cloth_Modern_Red_Roof_Vertical",
      "support": 15,
      "rotation": 3
    },
    {
      "x": -12,
      "y": 7,
      "z": 10,
      "name": "Cloth_Modern_Red_Roof_Vertical",
      "support": 15,
      "rotation": 3
    },
    {
      "x": -12,
      "y": 8,
      "z": 10,
      "name": "Cloth_Modern_Red_Roof_Vertical",
      "support": 15,
      "rotation": 3
    },
    {
      "x": -12,
      "y": 9,
      "z": 10,
      "name": "Cloth_Modern_Red_Roof_Vertical",
      "support": 15,
      "rotation": 3
    },
    {
      "x": -12,
      "y": 10,
      "z": 10,
      "name": "Cloth_Roof_Yellow_Flap",
      "support": 15,
      "rotation": 3
    },
    {
      "x": -12,
      "y": 0,
      "z": 11,
      "name": "Soil_Dirt"
    },
    {
      "x": -12,
      "y": 1,
      "z": 11,
      "name": "Soil_Dirt"
    },
    {
      "x": -12,
      "y": 2,
      "z": 11,
      "name": "Soil_Dirt"
    },
    {
      "x": -12,
      "y": 3,
      "z": 11,
      "name": "Soil_Dirt"
    },
    {
      "x": -12,
      "y": 4,
      "z": 11,
      "name": "Soil_Dirt"
    },
    {
      "x": -12,
      "y": 5,
      "z": 11,
      "name": "Soil_Clay"
    },
    {
      "x": -12,
      "y": 6,
      "z": 11,
      "name": "Cloth_Modern_Red_Roof_Vertical",
      "support": 15,
      "rotation": 3
    },
    {
      "x": -12,
      "y": 7,
      "z": 11,
      "name": "Cloth_Modern_Red_Roof_Vertical",
      "support": 15,
      "rotation": 3
    },
    {
      "x": -12,
      "y": 8,
      "z": 11,
      "name": "Cloth_Modern_Red_Roof_Vertical",
      "support": 15,
      "rotation": 3
    },
    {
      "x": -12,
      "y": 9,
      "z": 11,
      "name": "Cloth_Modern_Red_Roof_Vertical",
      "support": 15,
      "rotation": 3
    },
    {
      "x": -12,
      "y": 10,
      "z": 11,
      "name": "Cloth_Roof_Yellow_Flap",
      "support": 15,
      "rotation": 3
    },
    {
      "x": -12,
      "y": 0,
      "z": 12,
      "name": "Soil_Dirt"
    },
    {
      "x": -12,
      "y": 1,
      "z": 12,
      "name": "Soil_Dirt"
    },
    {
      "x": -12,
      "y": 2,
      "z": 12,
      "name": "Soil_Dirt"
    },
    {
      "x": -12,
      "y": 3,
      "z": 12,
      "name": "Soil_Dirt"
    },
    {
      "x": -12,
      "y": 4,
      "z": 12,
      "name": "Soil_Dirt"
    },
    {
      "x": -12,
      "y": 5,
      "z": 12,
      "name": "Soil_Dirt"
    },
    {
      "x": -12,
      "y": 6,
      "z": 12,
      "name": "Cloth_Modern_Red_Roof_Vertical",
      "support": 15,
      "rotation": 3
    },
    {
      "x": -12,
      "y": 7,
      "z": 12,
      "name": "Cloth_Modern_Red_Roof_Vertical",
      "support": 15,
      "rotation": 3
    },
    {
      "x": -12,
      "y": 8,
      "z": 12,
      "name": "Cloth_Modern_Red_Roof_Vertical",
      "support": 15,
      "rotation": 3
    },
    {
      "x": -12,
      "y": 9,
      "z": 12,
      "name": "Cloth_Modern_Red_Roof_Vertical",
      "support": 15,
      "rotation": 3
    },
    {
      "x": -12,
      "y": 10,
      "z": 12,
      "name": "Cloth_Roof_Yellow_Flap",
      "support": 15,
      "rotation": 3
    },
    {
      "x": -12,
      "y": 0,
      "z": 13,
      "name": "Soil_Dirt"
    },
    {
      "x": -12,
      "y": 1,
      "z": 13,
      "name": "Soil_Dirt"
    },
    {
      "x": -12,
      "y": 2,
      "z": 13,
      "name": "Soil_Dirt"
    },
    {
      "x": -12,
      "y": 3,
      "z": 13,
      "name": "Soil_Dirt"
    },
    {
      "x": -12,
      "y": 4,
      "z": 13,
      "name": "Soil_Dirt"
    },
    {
      "x": -12,
      "y": 5,
      "z": 13,
      "name": "Soil_Dirt"
    },
    {
      "x": -12,
      "y": 0,
      "z": 14,
      "name": "Soil_Dirt"
    },
    {
      "x": -12,
      "y": 1,
      "z": 14,
      "name": "Soil_Dirt"
    },
    {
      "x": -12,
      "y": 2,
      "z": 14,
      "name": "Soil_Dirt"
    },
    {
      "x": -12,
      "y": 3,
      "z": 14,
      "name": "Soil_Dirt"
    },
    {
      "x": -12,
      "y": 4,
      "z": 14,
      "name": "Soil_Dirt"
    },
    {
      "x": -12,
      "y": 5,
      "z": 14,
      "name": "Soil_Clay"
    },
    {
      "x": -12,
      "y": 0,
      "z": 15,
      "name": "Soil_Dirt"
    },
    {
      "x": -12,
      "y": 1,
      "z": 15,
      "name": "Soil_Dirt"
    },
    {
      "x": -12,
      "y": 2,
      "z": 15,
      "name": "Soil_Dirt"
    },
    {
      "x": -12,
      "y": 3,
      "z": 15,
      "name": "Soil_Dirt"
    },
    {
      "x": -12,
      "y": 4,
      "z": 15,
      "name": "Soil_Dirt"
    },
    {
      "x": -12,
      "y": 5,
      "z": 15,
      "name": "Rock_Stone_Brick_Smooth"
    },
    {
      "x": -11,
      "y": 0,
      "z": -14,
      "name": "Soil_Dirt"
    },
    {
      "x": -11,
      "y": 1,
      "z": -14,
      "name": "Soil_Dirt"
    },
    {
      "x": -11,
      "y": 2,
      "z": -14,
      "name": "Soil_Dirt"
    },
    {
      "x": -11,
      "y": 3,
      "z": -14,
      "name": "Soil_Dirt"
    },
    {
      "x": -11,
      "y": 4,
      "z": -14,
      "name": "Soil_Dirt"
    },
    {
      "x": -11,
      "y": 5,
      "z": -14,
      "name": "Rock_Stone_Brick_Smooth"
    },
    {
      "x": -11,
      "y": 0,
      "z": -13,
      "name": "Soil_Dirt"
    },
    {
      "x": -11,
      "y": 1,
      "z": -13,
      "name": "Soil_Dirt"
    },
    {
      "x": -11,
      "y": 2,
      "z": -13,
      "name": "Soil_Dirt"
    },
    {
      "x": -11,
      "y": 3,
      "z": -13,
      "name": "Soil_Dirt"
    },
    {
      "x": -11,
      "y": 4,
      "z": -13,
      "name": "Soil_Dirt"
    },
    {
      "x": -11,
      "y": 5,
      "z": -13,
      "name": "Soil_Pathway"
    },
    {
      "x": -11,
      "y": 0,
      "z": -12,
      "name": "Soil_Dirt"
    },
    {
      "x": -11,
      "y": 1,
      "z": -12,
      "name": "Soil_Dirt"
    },
    {
      "x": -11,
      "y": 2,
      "z": -12,
      "name": "Soil_Dirt"
    },
    {
      "x": -11,
      "y": 3,
      "z": -12,
      "name": "Soil_Dirt"
    },
    {
      "x": -11,
      "y": 4,
      "z": -12,
      "name": "Soil_Dirt"
    },
    {
      "x": -11,
      "y": 5,
      "z": -12,
      "name": "Soil_Pathway"
    },
    {
      "x": -11,
      "y": 6,
      "z": -12,
      "name": "Cloth_Modern_Red_Roof_Vertical",
      "support": 15,
      "rotation": 2
    },
    {
      "x": -11,
      "y": 7,
      "z": -12,
      "name": "Cloth_Modern_Red_Roof_Vertical",
      "support": 15,
      "rotation": 2
    },
    {
      "x": -11,
      "y": 8,
      "z": -12,
      "name": "Cloth_Modern_Red_Roof_Vertical",
      "support": 15,
      "rotation": 2
    },
    {
      "x": -11,
      "y": 9,
      "z": -12,
      "name": "Cloth_Modern_Red_Roof_Vertical",
      "support": 15,
      "rotation": 2
    },
    {
      "x": -11,
      "y": 10,
      "z": -12,
      "name": "Cloth_Roof_Yellow_Flap",
      "support": 15,
      "rotation": 2
    },
    {
      "x": -11,
      "y": 0,
      "z": -11,
      "name": "Soil_Dirt"
    },
    {
      "x": -11,
      "y": 1,
      "z": -11,
      "name": "Soil_Dirt"
    },
    {
      "x": -11,
      "y": 2,
      "z": -11,
      "name": "Soil_Dirt"
    },
    {
      "x": -11,
      "y": 3,
      "z": -11,
      "name": "Soil_Dirt"
    },
    {
      "x": -11,
      "y": 4,
      "z": -11,
      "name": "Soil_Dirt"
    },
    {
      "x": -11,
      "y": 5,
      "z": -11,
      "name": "Soil_Pathway"
    },
    {
      "x": -11,
      "y": 10,
      "z": -11,
      "name": "Cloth_Block_Wool_White",
      "support": 15
    },
    {
      "x": -11,
      "y": 11,
      "z": -11,
      "name": "*Cloth_Modern_Red_Roof_State_Definitions_Corner_Left",
      "rotation": 2
    },
    {
      "x": -11,
      "y": 0,
      "z": -10,
      "name": "Soil_Dirt"
    },
    {
      "x": -11,
      "y": 1,
      "z": -10,
      "name": "Soil_Dirt"
    },
    {
      "x": -11,
      "y": 2,
      "z": -10,
      "name": "Soil_Dirt"
    },
    {
      "x": -11,
      "y": 3,
      "z": -10,
      "name": "Soil_Dirt"
    },
    {
      "x": -11,
      "y": 4,
      "z": -10,
      "name": "Soil_Dirt"
    },
    {
      "x": -11,
      "y": 5,
      "z": -10,
      "name": "Soil_Pathway"
    },
    {
      "x": -11,
      "y": 10,
      "z": -10,
      "name": "Cloth_Block_Wool_White",
      "support": 15
    },
    {
      "x": -11,
      "y": 11,
      "z": -10,
      "name": "Cloth_Modern_Red_Roof",
      "support": 15,
      "rotation": 3
    },
    {
      "x": -11,
      "y": 13,
      "z": -10,
      "name": "Cloth_Roof_Yellow_Flap",
      "support": 15,
      "rotation": 3
    },
    {
      "x": -11,
      "y": 0,
      "z": -9,
      "name": "Soil_Dirt"
    },
    {
      "x": -11,
      "y": 1,
      "z": -9,
      "name": "Soil_Dirt"
    },
    {
      "x": -11,
      "y": 2,
      "z": -9,
      "name": "Soil_Dirt"
    },
    {
      "x": -11,
      "y": 3,
      "z": -9,
      "name": "Soil_Dirt"
    },
    {
      "x": -11,
      "y": 4,
      "z": -9,
      "name": "Soil_Dirt"
    },
    {
      "x": -11,
      "y": 5,
      "z": -9,
      "name": "Soil_Pathway"
    },
    {
      "x": -11,
      "y": 10,
      "z": -9,
      "name": "Cloth_Block_Wool_White",
      "support": 15
    },
    {
      "x": -11,
      "y": 11,
      "z": -9,
      "name": "Cloth_Modern_Red_Roof",
      "support": 15,
      "rotation": 3
    },
    {
      "x": -11,
      "y": 13,
      "z": -9,
      "name": "Cloth_Roof_Yellow_Flap",
      "support": 15,
      "rotation": 3
    },
    {
      "x": -11,
      "y": 0,
      "z": -8,
      "name": "Soil_Dirt"
    },
    {
      "x": -11,
      "y": 1,
      "z": -8,
      "name": "Soil_Dirt"
    },
    {
      "x": -11,
      "y": 2,
      "z": -8,
      "name": "Soil_Dirt"
    },
    {
      "x": -11,
      "y": 3,
      "z": -8,
      "name": "Soil_Dirt"
    },
    {
      "x": -11,
      "y": 4,
      "z": -8,
      "name": "Soil_Dirt"
    },
    {
      "x": -11,
      "y": 5,
      "z": -8,
      "name": "Soil_Dirt"
    },
    {
      "x": -11,
      "y": 10,
      "z": -8,
      "name": "Cloth_Block_Wool_White",
      "support": 15
    },
    {
      "x": -11,
      "y": 11,
      "z": -8,
      "name": "Cloth_Modern_Red_Roof",
      "support": 15,
      "rotation": 3
    },
    {
      "x": -11,
      "y": 0,
      "z": -7,
      "name": "Soil_Dirt"
    },
    {
      "x": -11,
      "y": 1,
      "z": -7,
      "name": "Soil_Dirt"
    },
    {
      "x": -11,
      "y": 2,
      "z": -7,
      "name": "Soil_Dirt"
    },
    {
      "x": -11,
      "y": 3,
      "z": -7,
      "name": "Soil_Dirt"
    },
    {
      "x": -11,
      "y": 4,
      "z": -7,
      "name": "Soil_Dirt"
    },
    {
      "x": -11,
      "y": 5,
      "z": -7,
      "name": "Soil_Dirt"
    },
    {
      "x": -11,
      "y": 10,
      "z": -7,
      "name": "Cloth_Block_Wool_White",
      "support": 15
    },
    {
      "x": -11,
      "y": 11,
      "z": -7,
      "name": "Cloth_Modern_Red_Roof",
      "support": 15,
      "rotation": 3
    },
    {
      "x": -11,
      "y": 0,
      "z": -6,
      "name": "Soil_Dirt"
    },
    {
      "x": -11,
      "y": 1,
      "z": -6,
      "name": "Soil_Dirt"
    },
    {
      "x": -11,
      "y": 2,
      "z": -6,
      "name": "Soil_Dirt"
    },
    {
      "x": -11,
      "y": 3,
      "z": -6,
      "name": "Soil_Dirt"
    },
    {
      "x": -11,
      "y": 4,
      "z": -6,
      "name": "Soil_Dirt"
    },
    {
      "x": -11,
      "y": 5,
      "z": -6,
      "name": "Soil_Pathway"
    },
    {
      "x": -11,
      "y": 10,
      "z": -6,
      "name": "Cloth_Block_Wool_White",
      "support": 15
    },
    {
      "x": -11,
      "y": 11,
      "z": -6,
      "name": "Cloth_Modern_Red_Roof",
      "support": 15,
      "rotation": 3
    },
    {
      "x": -11,
      "y": 0,
      "z": -5,
      "name": "Soil_Dirt"
    },
    {
      "x": -11,
      "y": 1,
      "z": -5,
      "name": "Soil_Dirt"
    },
    {
      "x": -11,
      "y": 2,
      "z": -5,
      "name": "Soil_Dirt"
    },
    {
      "x": -11,
      "y": 3,
      "z": -5,
      "name": "Soil_Dirt"
    },
    {
      "x": -11,
      "y": 4,
      "z": -5,
      "name": "Soil_Dirt"
    },
    {
      "x": -11,
      "y": 5,
      "z": -5,
      "name": "Soil_Pathway"
    },
    {
      "x": -11,
      "y": 10,
      "z": -5,
      "name": "Cloth_Block_Wool_White",
      "support": 15
    },
    {
      "x": -11,
      "y": 11,
      "z": -5,
      "name": "Cloth_Modern_Red_Roof",
      "support": 15,
      "rotation": 3
    },
    {
      "x": -11,
      "y": 0,
      "z": -4,
      "name": "Soil_Dirt"
    },
    {
      "x": -11,
      "y": 1,
      "z": -4,
      "name": "Soil_Dirt"
    },
    {
      "x": -11,
      "y": 2,
      "z": -4,
      "name": "Soil_Dirt"
    },
    {
      "x": -11,
      "y": 3,
      "z": -4,
      "name": "Soil_Dirt"
    },
    {
      "x": -11,
      "y": 4,
      "z": -4,
      "name": "Soil_Dirt"
    },
    {
      "x": -11,
      "y": 5,
      "z": -4,
      "name": "Soil_Pathway"
    },
    {
      "x": -11,
      "y": 10,
      "z": -4,
      "name": "Cloth_Block_Wool_White",
      "support": 15
    },
    {
      "x": -11,
      "y": 11,
      "z": -4,
      "name": "Cloth_Modern_Red_Roof",
      "support": 15,
      "rotation": 3
    },
    {
      "x": -11,
      "y": 0,
      "z": -3,
      "name": "Soil_Dirt"
    },
    {
      "x": -11,
      "y": 1,
      "z": -3,
      "name": "Soil_Dirt"
    },
    {
      "x": -11,
      "y": 2,
      "z": -3,
      "name": "Soil_Dirt"
    },
    {
      "x": -11,
      "y": 3,
      "z": -3,
      "name": "Soil_Dirt"
    },
    {
      "x": -11,
      "y": 4,
      "z": -3,
      "name": "Soil_Dirt"
    },
    {
      "x": -11,
      "y": 5,
      "z": -3,
      "name": "Soil_Dirt"
    },
    {
      "x": -11,
      "y": 10,
      "z": -3,
      "name": "Cloth_Block_Wool_White",
      "support": 15
    },
    {
      "x": -11,
      "y": 11,
      "z": -3,
      "name": "Cloth_Modern_Red_Roof",
      "support": 15,
      "rotation": 3
    },
    {
      "x": -11,
      "y": 0,
      "z": -2,
      "name": "Soil_Dirt"
    },
    {
      "x": -11,
      "y": 1,
      "z": -2,
      "name": "Soil_Dirt"
    },
    {
      "x": -11,
      "y": 2,
      "z": -2,
      "name": "Soil_Dirt"
    },
    {
      "x": -11,
      "y": 3,
      "z": -2,
      "name": "Soil_Dirt"
    },
    {
      "x": -11,
      "y": 4,
      "z": -2,
      "name": "Soil_Dirt"
    },
    {
      "x": -11,
      "y": 5,
      "z": -2,
      "name": "Soil_Pathway"
    },
    {
      "x": -11,
      "y": 6,
      "z": -2,
      "name": "Wood_Hardwood_Fence",
      "support": 15,
      "rotation": 2
    },
    {
      "x": -11,
      "y": 10,
      "z": -2,
      "name": "Cloth_Block_Wool_White",
      "support": 15
    },
    {
      "x": -11,
      "y": 11,
      "z": -2,
      "name": "Cloth_Modern_Red_Roof",
      "support": 15,
      "rotation": 3
    },
    {
      "x": -11,
      "y": 0,
      "z": -1,
      "name": "Soil_Dirt"
    },
    {
      "x": -11,
      "y": 1,
      "z": -1,
      "name": "Soil_Dirt"
    },
    {
      "x": -11,
      "y": 2,
      "z": -1,
      "name": "Soil_Dirt"
    },
    {
      "x": -11,
      "y": 3,
      "z": -1,
      "name": "Soil_Dirt"
    },
    {
      "x": -11,
      "y": 4,
      "z": -1,
      "name": "Soil_Dirt"
    },
    {
      "x": -11,
      "y": 5,
      "z": -1,
      "name": "Soil_Pathway"
    },
    {
      "x": -11,
      "y": 10,
      "z": -1,
      "name": "Cloth_Block_Wool_White",
      "support": 15
    },
    {
      "x": -11,
      "y": 11,
      "z": -1,
      "name": "Cloth_Modern_Red_Roof",
      "support": 15,
      "rotation": 3
    },
    {
      "x": -11,
      "y": 0,
      "z": 0,
      "name": "Soil_Dirt"
    },
    {
      "x": -11,
      "y": 1,
      "z": 0,
      "name": "Soil_Dirt"
    },
    {
      "x": -11,
      "y": 2,
      "z": 0,
      "name": "Soil_Dirt"
    },
    {
      "x": -11,
      "y": 3,
      "z": 0,
      "name": "Soil_Dirt"
    },
    {
      "x": -11,
      "y": 4,
      "z": 0,
      "name": "Soil_Dirt"
    },
    {
      "x": -11,
      "y": 5,
      "z": 0,
      "name": "Soil_Pathway"
    },
    {
      "x": -11,
      "y": 10,
      "z": 0,
      "name": "Cloth_Block_Wool_White",
      "support": 15
    },
    {
      "x": -11,
      "y": 11,
      "z": 0,
      "name": "Cloth_Modern_Red_Roof",
      "support": 15,
      "rotation": 3
    },
    {
      "x": -11,
      "y": 0,
      "z": 1,
      "name": "Soil_Dirt"
    },
    {
      "x": -11,
      "y": 1,
      "z": 1,
      "name": "Soil_Dirt"
    },
    {
      "x": -11,
      "y": 2,
      "z": 1,
      "name": "Soil_Dirt"
    },
    {
      "x": -11,
      "y": 3,
      "z": 1,
      "name": "Soil_Dirt"
    },
    {
      "x": -11,
      "y": 4,
      "z": 1,
      "name": "Soil_Dirt"
    },
    {
      "x": -11,
      "y": 5,
      "z": 1,
      "name": "Soil_Pathway"
    },
    {
      "x": -11,
      "y": 10,
      "z": 1,
      "name": "Cloth_Block_Wool_White",
      "support": 15
    },
    {
      "x": -11,
      "y": 11,
      "z": 1,
      "name": "Cloth_Modern_Red_Roof",
      "support": 15,
      "rotation": 3
    },
    {
      "x": -11,
      "y": 0,
      "z": 2,
      "name": "Soil_Dirt"
    },
    {
      "x": -11,
      "y": 1,
      "z": 2,
      "name": "Soil_Dirt"
    },
    {
      "x": -11,
      "y": 2,
      "z": 2,
      "name": "Soil_Dirt"
    },
    {
      "x": -11,
      "y": 3,
      "z": 2,
      "name": "Soil_Dirt"
    },
    {
      "x": -11,
      "y": 4,
      "z": 2,
      "name": "Soil_Dirt"
    },
    {
      "x": -11,
      "y": 5,
      "z": 2,
      "name": "Soil_Dirt"
    },
    {
      "x": -11,
      "y": 10,
      "z": 2,
      "name": "Cloth_Block_Wool_White",
      "support": 15
    },
    {
      "x": -11,
      "y": 11,
      "z": 2,
      "name": "Cloth_Modern_Red_Roof",
      "support": 15,
      "rotation": 3
    },
    {
      "x": -11,
      "y": 0,
      "z": 3,
      "name": "Soil_Dirt"
    },
    {
      "x": -11,
      "y": 1,
      "z": 3,
      "name": "Soil_Dirt"
    },
    {
      "x": -11,
      "y": 2,
      "z": 3,
      "name": "Soil_Dirt"
    },
    {
      "x": -11,
      "y": 3,
      "z": 3,
      "name": "Soil_Dirt"
    },
    {
      "x": -11,
      "y": 4,
      "z": 3,
      "name": "Soil_Dirt"
    },
    {
      "x": -11,
      "y": 5,
      "z": 3,
      "name": "Soil_Pathway"
    },
    {
      "x": -11,
      "y": 10,
      "z": 3,
      "name": "Cloth_Block_Wool_White",
      "support": 15,
      "rotation": 4
    },
    {
      "x": -11,
      "y": 11,
      "z": 3,
      "name": "Cloth_Modern_Red_Roof",
      "support": 15,
      "rotation": 3
    },
    {
      "x": -11,
      "y": 0,
      "z": 4,
      "name": "Soil_Dirt"
    },
    {
      "x": -11,
      "y": 1,
      "z": 4,
      "name": "Soil_Dirt"
    },
    {
      "x": -11,
      "y": 2,
      "z": 4,
      "name": "Soil_Dirt"
    },
    {
      "x": -11,
      "y": 3,
      "z": 4,
      "name": "Soil_Dirt"
    },
    {
      "x": -11,
      "y": 4,
      "z": 4,
      "name": "Soil_Dirt"
    },
    {
      "x": -11,
      "y": 5,
      "z": 4,
      "name": "Soil_Clay"
    },
    {
      "x": -11,
      "y": 10,
      "z": 4,
      "name": "Cloth_Block_Wool_White",
      "support": 15,
      "rotation": 4
    },
    {
      "x": -11,
      "y": 11,
      "z": 4,
      "name": "Cloth_Modern_Red_Roof",
      "support": 15,
      "rotation": 3
    },
    {
      "x": -11,
      "y": 0,
      "z": 5,
      "name": "Soil_Dirt"
    },
    {
      "x": -11,
      "y": 1,
      "z": 5,
      "name": "Soil_Dirt"
    },
    {
      "x": -11,
      "y": 2,
      "z": 5,
      "name": "Soil_Dirt"
    },
    {
      "x": -11,
      "y": 3,
      "z": 5,
      "name": "Soil_Dirt"
    },
    {
      "x": -11,
      "y": 4,
      "z": 5,
      "name": "Soil_Dirt"
    },
    {
      "x": -11,
      "y": 5,
      "z": 5,
      "name": "Soil_Clay"
    },
    {
      "x": -11,
      "y": 8,
      "z": 5,
      "name": "Cloth_Modern_Blue_Roof_Vertical_Flap",
      "support": 15,
      "rotation": 2
    },
    {
      "x": -11,
      "y": 10,
      "z": 5,
      "name": "Cloth_Block_Wool_White",
      "support": 15,
      "rotation": 4
    },
    {
      "x": -11,
      "y": 11,
      "z": 5,
      "name": "Cloth_Modern_Red_Roof",
      "support": 15,
      "rotation": 3
    },
    {
      "x": -11,
      "y": 0,
      "z": 6,
      "name": "Soil_Dirt"
    },
    {
      "x": -11,
      "y": 1,
      "z": 6,
      "name": "Soil_Dirt"
    },
    {
      "x": -11,
      "y": 2,
      "z": 6,
      "name": "Soil_Dirt"
    },
    {
      "x": -11,
      "y": 3,
      "z": 6,
      "name": "Soil_Dirt"
    },
    {
      "x": -11,
      "y": 4,
      "z": 6,
      "name": "Soil_Dirt"
    },
    {
      "x": -11,
      "y": 5,
      "z": 6,
      "name": "Soil_Clay"
    },
    {
      "x": -11,
      "y": 6,
      "z": 6,
      "name": "Wood_Hardwood_Decorative",
      "support": 15
    },
    {
      "x": -11,
      "y": 7,
      "z": 6,
      "name": "Wood_Hardwood_Planks",
      "support": 15
    },
    {
      "x": -11,
      "y": 8,
      "z": 6,
      "name": "Wood_Hardwood_Planks",
      "support": 15
    },
    {
      "x": -11,
      "y": 9,
      "z": 6,
      "name": "Cloth_Modern_Blue_Roof",
      "support": 15,
      "rotation": 2
    },
    {
      "x": -11,
      "y": 10,
      "z": 6,
      "name": "Cloth_Block_Wool_White",
      "support": 15,
      "rotation": 4
    },
    {
      "x": -11,
      "y": 11,
      "z": 6,
      "name": "Cloth_Modern_Red_Roof",
      "support": 15,
      "rotation": 3
    },
    {
      "x": -11,
      "y": 0,
      "z": 7,
      "name": "Soil_Dirt"
    },
    {
      "x": -11,
      "y": 1,
      "z": 7,
      "name": "Soil_Dirt"
    },
    {
      "x": -11,
      "y": 2,
      "z": 7,
      "name": "Soil_Dirt"
    },
    {
      "x": -11,
      "y": 3,
      "z": 7,
      "name": "Soil_Dirt"
    },
    {
      "x": -11,
      "y": 4,
      "z": 7,
      "name": "Soil_Dirt"
    },
    {
      "x": -11,
      "y": 5,
      "z": 7,
      "name": "Soil_Dirt"
    },
    {
      "x": -11,
      "y": 6,
      "z": 7,
      "name": "Wood_Hardwood_Decorative",
      "support": 15
    },
    {
      "x": -11,
      "y": 7,
      "z": 7,
      "name": "Wood_Hardwood_Planks",
      "support": 15
    },
    {
      "x": -11,
      "y": 8,
      "z": 7,
      "name": "Wood_Hardwood_Planks",
      "support": 15
    },
    {
      "x": -11,
      "y": 9,
      "z": 7,
      "name": "Cloth_Block_Wool_White",
      "support": 15
    },
    {
      "x": -11,
      "y": 10,
      "z": 7,
      "name": "Cloth_Block_Wool_White",
      "support": 15,
      "rotation": 4
    },
    {
      "x": -11,
      "y": 11,
      "z": 7,
      "name": "Cloth_Modern_Red_Roof",
      "support": 15,
      "rotation": 3
    },
    {
      "x": -11,
      "y": 0,
      "z": 8,
      "name": "Soil_Dirt"
    },
    {
      "x": -11,
      "y": 1,
      "z": 8,
      "name": "Soil_Dirt"
    },
    {
      "x": -11,
      "y": 2,
      "z": 8,
      "name": "Soil_Dirt"
    },
    {
      "x": -11,
      "y": 3,
      "z": 8,
      "name": "Soil_Dirt"
    },
    {
      "x": -11,
      "y": 4,
      "z": 8,
      "name": "Soil_Dirt"
    },
    {
      "x": -11,
      "y": 5,
      "z": 8,
      "name": "Soil_Pathway"
    },
    {
      "x": -11,
      "y": 6,
      "z": 8,
      "name": "Wood_Hardwood_Decorative",
      "support": 15
    },
    {
      "x": -11,
      "y": 7,
      "z": 8,
      "name": "Wood_Hardwood_Planks",
      "support": 15
    },
    {
      "x": -11,
      "y": 8,
      "z": 8,
      "name": "Wood_Hardwood_Planks",
      "support": 15
    },
    {
      "x": -11,
      "y": 9,
      "z": 8,
      "name": "Wood_Hardwood_Planks",
      "support": 15
    },
    {
      "x": -11,
      "y": 10,
      "z": 8,
      "name": "Cloth_Block_Wool_White",
      "support": 15,
      "rotation": 4
    },
    {
      "x": -11,
      "y": 11,
      "z": 8,
      "name": "Cloth_Modern_Red_Roof",
      "support": 15,
      "rotation": 3
    },
    {
      "x": -11,
      "y": 0,
      "z": 9,
      "name": "Soil_Dirt"
    },
    {
      "x": -11,
      "y": 1,
      "z": 9,
      "name": "Soil_Dirt"
    },
    {
      "x": -11,
      "y": 2,
      "z": 9,
      "name": "Soil_Dirt"
    },
    {
      "x": -11,
      "y": 3,
      "z": 9,
      "name": "Soil_Dirt"
    },
    {
      "x": -11,
      "y": 4,
      "z": 9,
      "name": "Soil_Dirt"
    },
    {
      "x": -11,
      "y": 5,
      "z": 9,
      "name": "Soil_Pathway"
    },
    {
      "x": -11,
      "y": 6,
      "z": 9,
      "name": "Wood_Hardwood_Decorative",
      "support": 15
    },
    {
      "x": -11,
      "y": 7,
      "z": 9,
      "name": "Wood_Hardwood_Planks",
      "support": 15
    },
    {
      "x": -11,
      "y": 8,
      "z": 9,
      "name": "Wood_Hardwood_Planks",
      "support": 15
    },
    {
      "x": -11,
      "y": 9,
      "z": 9,
      "name": "Wood_Hardwood_Planks",
      "support": 15
    },
    {
      "x": -11,
      "y": 10,
      "z": 9,
      "name": "Cloth_Block_Wool_White",
      "support": 15,
      "rotation": 4
    },
    {
      "x": -11,
      "y": 11,
      "z": 9,
      "name": "Cloth_Modern_Red_Roof",
      "support": 15,
      "rotation": 3
    },
    {
      "x": -11,
      "y": 0,
      "z": 10,
      "name": "Soil_Dirt"
    },
    {
      "x": -11,
      "y": 1,
      "z": 10,
      "name": "Soil_Dirt"
    },
    {
      "x": -11,
      "y": 2,
      "z": 10,
      "name": "Soil_Dirt"
    },
    {
      "x": -11,
      "y": 3,
      "z": 10,
      "name": "Soil_Dirt"
    },
    {
      "x": -11,
      "y": 4,
      "z": 10,
      "name": "Soil_Dirt"
    },
    {
      "x": -11,
      "y": 5,
      "z": 10,
      "name": "Soil_Clay"
    },
    {
      "x": -11,
      "y": 6,
      "z": 10,
      "name": "Wood_Hardwood_Decorative",
      "support": 15
    },
    {
      "x": -11,
      "y": 7,
      "z": 10,
      "name": "Wood_Hardwood_Planks",
      "support": 15
    },
    {
      "x": -11,
      "y": 8,
      "z": 10,
      "name": "Wood_Hardwood_Planks",
      "support": 15
    },
    {
      "x": -11,
      "y": 9,
      "z": 10,
      "name": "Wood_Hardwood_Planks",
      "support": 15
    },
    {
      "x": -11,
      "y": 10,
      "z": 10,
      "name": "Cloth_Block_Wool_White",
      "support": 15,
      "rotation": 4
    },
    {
      "x": -11,
      "y": 11,
      "z": 10,
      "name": "Cloth_Modern_Red_Roof",
      "support": 15,
      "rotation": 3
    },
    {
      "x": -11,
      "y": 13,
      "z": 10,
      "name": "Cloth_Roof_Yellow_Flap",
      "support": 15,
      "rotation": 3
    },
    {
      "x": -11,
      "y": 0,
      "z": 11,
      "name": "Soil_Dirt"
    },
    {
      "x": -11,
      "y": 1,
      "z": 11,
      "name": "Soil_Dirt"
    },
    {
      "x": -11,
      "y": 2,
      "z": 11,
      "name": "Soil_Dirt"
    },
    {
      "x": -11,
      "y": 3,
      "z": 11,
      "name": "Soil_Dirt"
    },
    {
      "x": -11,
      "y": 4,
      "z": 11,
      "name": "Soil_Dirt"
    },
    {
      "x": -11,
      "y": 5,
      "z": 11,
      "name": "Soil_Dirt"
    },
    {
      "x": -11,
      "y": 6,
      "z": 11,
      "name": "Wood_Hardwood_Decorative",
      "support": 15
    },
    {
      "x": -11,
      "y": 7,
      "z": 11,
      "name": "Wood_Hardwood_Planks",
      "support": 15
    },
    {
      "x": -11,
      "y": 8,
      "z": 11,
      "name": "Wood_Hardwood_Planks",
      "support": 15
    },
    {
      "x": -11,
      "y": 9,
      "z": 11,
      "name": "Wood_Hardwood_Planks",
      "support": 15
    },
    {
      "x": -11,
      "y": 10,
      "z": 11,
      "name": "Cloth_Block_Wool_White",
      "support": 15,
      "rotation": 4
    },
    {
      "x": -11,
      "y": 11,
      "z": 11,
      "name": "Cloth_Modern_Red_Roof",
      "support": 15,
      "rotation": 3
    },
    {
      "x": -11,
      "y": 13,
      "z": 11,
      "name": "Cloth_Roof_Yellow_Flap",
      "support": 15,
      "rotation": 3
    },
    {
      "x": -11,
      "y": 0,
      "z": 12,
      "name": "Soil_Dirt"
    },
    {
      "x": -11,
      "y": 1,
      "z": 12,
      "name": "Soil_Dirt"
    },
    {
      "x": -11,
      "y": 2,
      "z": 12,
      "name": "Soil_Dirt"
    },
    {
      "x": -11,
      "y": 3,
      "z": 12,
      "name": "Soil_Dirt"
    },
    {
      "x": -11,
      "y": 4,
      "z": 12,
      "name": "Soil_Dirt"
    },
    {
      "x": -11,
      "y": 5,
      "z": 12,
      "name": "Soil_Pathway"
    },
    {
      "x": -11,
      "y": 6,
      "z": 12,
      "name": "Wood_Hardwood_Decorative",
      "support": 15
    },
    {
      "x": -11,
      "y": 7,
      "z": 12,
      "name": "Wood_Hardwood_Planks",
      "support": 15
    },
    {
      "x": -11,
      "y": 8,
      "z": 12,
      "name": "Wood_Hardwood_Planks",
      "support": 15
    },
    {
      "x": -11,
      "y": 9,
      "z": 12,
      "name": "Wood_Hardwood_Planks",
      "support": 15
    },
    {
      "x": -11,
      "y": 10,
      "z": 12,
      "name": "Cloth_Block_Wool_White",
      "support": 15
    },
    {
      "x": -11,
      "y": 11,
      "z": 12,
      "name": "*Cloth_Modern_Red_Roof_State_Definitions_Corner_Left",
      "rotation": 3
    },
    {
      "x": -11,
      "y": 0,
      "z": 13,
      "name": "Soil_Dirt"
    },
    {
      "x": -11,
      "y": 1,
      "z": 13,
      "name": "Soil_Dirt"
    },
    {
      "x": -11,
      "y": 2,
      "z": 13,
      "name": "Soil_Dirt"
    },
    {
      "x": -11,
      "y": 3,
      "z": 13,
      "name": "Soil_Dirt"
    },
    {
      "x": -11,
      "y": 4,
      "z": 13,
      "name": "Soil_Dirt"
    },
    {
      "x": -11,
      "y": 5,
      "z": 13,
      "name": "Soil_Dirt"
    },
    {
      "x": -11,
      "y": 6,
      "z": 13,
      "name": "Cloth_Modern_Red_Roof_Vertical",
      "support": 15
    },
    {
      "x": -11,
      "y": 7,
      "z": 13,
      "name": "Cloth_Modern_Red_Roof_Vertical",
      "support": 15
    },
    {
      "x": -11,
      "y": 8,
      "z": 13,
      "name": "Cloth_Modern_Red_Roof_Vertical",
      "support": 15
    },
    {
      "x": -11,
      "y": 9,
      "z": 13,
      "name": "Cloth_Modern_Red_Roof_Vertical",
      "support": 15
    },
    {
      "x": -11,
      "y": 10,
      "z": 13,
      "name": "Cloth_Roof_Yellow_Flap",
      "support": 15
    },
    {
      "x": -11,
      "y": 0,
      "z": 14,
      "name": "Soil_Dirt"
    },
    {
      "x": -11,
      "y": 1,
      "z": 14,
      "name": "Soil_Dirt"
    },
    {
      "x": -11,
      "y": 2,
      "z": 14,
      "name": "Soil_Dirt"
    },
    {
      "x": -11,
      "y": 3,
      "z": 14,
      "name": "Soil_Dirt"
    },
    {
      "x": -11,
      "y": 4,
      "z": 14,
      "name": "Soil_Dirt"
    },
    {
      "x": -11,
      "y": 5,
      "z": 14,
      "name": "Soil_Pathway"
    },
    {
      "x": -11,
      "y": 0,
      "z": 15,
      "name": "Soil_Dirt"
    },
    {
      "x": -11,
      "y": 1,
      "z": 15,
      "name": "Soil_Dirt"
    },
    {
      "x": -11,
      "y": 2,
      "z": 15,
      "name": "Soil_Dirt"
    },
    {
      "x": -11,
      "y": 3,
      "z": 15,
      "name": "Soil_Dirt"
    },
    {
      "x": -11,
      "y": 4,
      "z": 15,
      "name": "Soil_Dirt"
    },
    {
      "x": -11,
      "y": 5,
      "z": 15,
      "name": "Rock_Stone_Brick_Smooth"
    },
    {
      "x": -10,
      "y": 0,
      "z": -14,
      "name": "Soil_Dirt"
    },
    {
      "x": -10,
      "y": 1,
      "z": -14,
      "name": "Soil_Dirt"
    },
    {
      "x": -10,
      "y": 2,
      "z": -14,
      "name": "Soil_Dirt"
    },
    {
      "x": -10,
      "y": 3,
      "z": -14,
      "name": "Soil_Dirt"
    },
    {
      "x": -10,
      "y": 4,
      "z": -14,
      "name": "Soil_Dirt"
    },
    {
      "x": -10,
      "y": 5,
      "z": -14,
      "name": "Rock_Stone_Brick_Smooth"
    },
    {
      "x": -10,
      "y": 0,
      "z": -13,
      "name": "Soil_Dirt"
    },
    {
      "x": -10,
      "y": 1,
      "z": -13,
      "name": "Soil_Dirt"
    },
    {
      "x": -10,
      "y": 2,
      "z": -13,
      "name": "Soil_Dirt"
    },
    {
      "x": -10,
      "y": 3,
      "z": -13,
      "name": "Soil_Dirt"
    },
    {
      "x": -10,
      "y": 4,
      "z": -13,
      "name": "Soil_Dirt"
    },
    {
      "x": -10,
      "y": 5,
      "z": -13,
      "name": "Soil_Pathway"
    },
    {
      "x": -10,
      "y": 0,
      "z": -12,
      "name": "Soil_Dirt"
    },
    {
      "x": -10,
      "y": 1,
      "z": -12,
      "name": "Soil_Dirt"
    },
    {
      "x": -10,
      "y": 2,
      "z": -12,
      "name": "Soil_Dirt"
    },
    {
      "x": -10,
      "y": 3,
      "z": -12,
      "name": "Soil_Dirt"
    },
    {
      "x": -10,
      "y": 4,
      "z": -12,
      "name": "Soil_Dirt"
    },
    {
      "x": -10,
      "y": 5,
      "z": -12,
      "name": "Soil_Clay"
    },
    {
      "x": -10,
      "y": 6,
      "z": -12,
      "name": "Cloth_Modern_Red_Roof_Vertical",
      "support": 15,
      "rotation": 2
    },
    {
      "x": -10,
      "y": 7,
      "z": -12,
      "name": "Cloth_Modern_Red_Roof_Vertical",
      "support": 15,
      "rotation": 2
    },
    {
      "x": -10,
      "y": 8,
      "z": -12,
      "name": "Cloth_Modern_Red_Roof_Vertical",
      "support": 15,
      "rotation": 2
    },
    {
      "x": -10,
      "y": 9,
      "z": -12,
      "name": "Cloth_Modern_Red_Roof_Vertical",
      "support": 15,
      "rotation": 2
    },
    {
      "x": -10,
      "y": 10,
      "z": -12,
      "name": "Cloth_Roof_Yellow_Flap",
      "support": 15,
      "rotation": 2
    },
    {
      "x": -10,
      "y": 0,
      "z": -11,
      "name": "Soil_Dirt"
    },
    {
      "x": -10,
      "y": 1,
      "z": -11,
      "name": "Soil_Dirt"
    },
    {
      "x": -10,
      "y": 2,
      "z": -11,
      "name": "Soil_Dirt"
    },
    {
      "x": -10,
      "y": 3,
      "z": -11,
      "name": "Soil_Dirt"
    },
    {
      "x": -10,
      "y": 4,
      "z": -11,
      "name": "Soil_Dirt"
    },
    {
      "x": -10,
      "y": 5,
      "z": -11,
      "name": "Soil_Pathway"
    },
    {
      "x": -10,
      "y": 10,
      "z": -11,
      "name": "Cloth_Block_Wool_White",
      "support": 15
    },
    {
      "x": -10,
      "y": 11,
      "z": -11,
      "name": "Cloth_Modern_Red_Roof",
      "support": 15,
      "rotation": 2
    },
    {
      "x": -10,
      "y": 13,
      "z": -11,
      "name": "Cloth_Roof_Yellow_Flap",
      "support": 15,
      "rotation": 2
    },
    {
      "x": -10,
      "y": 0,
      "z": -10,
      "name": "Soil_Dirt"
    },
    {
      "x": -10,
      "y": 1,
      "z": -10,
      "name": "Soil_Dirt"
    },
    {
      "x": -10,
      "y": 2,
      "z": -10,
      "name": "Soil_Dirt"
    },
    {
      "x": -10,
      "y": 3,
      "z": -10,
      "name": "Soil_Dirt"
    },
    {
      "x": -10,
      "y": 4,
      "z": -10,
      "name": "Soil_Dirt"
    },
    {
      "x": -10,
      "y": 5,
      "z": -10,
      "name": "Soil_Dirt"
    },
    {
      "x": -10,
      "y": 6,
      "z": -10,
      "name": "Wood_Beech_Trunk",
      "support": 15
    },
    {
      "x": -10,
      "y": 7,
      "z": -10,
      "name": "Wood_Beech_Trunk",
      "support": 15
    },
    {
      "x": -10,
      "y": 8,
      "z": -10,
      "name": "Wood_Beech_Trunk",
      "support": 15
    },
    {
      "x": -10,
      "y": 9,
      "z": -10,
      "name": "Wood_Beech_Trunk",
      "support": 15
    },
    {
      "x": -10,
      "y": 10,
      "z": -10,
      "name": "Wood_Beech_Trunk",
      "support": 15
    },
    {
      "x": -10,
      "y": 11,
      "z": -10,
      "name": "Wood_Beech_Trunk",
      "support": 15
    },
    {
      "x": -10,
      "y": 12,
      "z": -10,
      "name": "Cloth_Block_Wool_Red",
      "support": 15
    },
    {
      "x": -10,
      "y": 13,
      "z": -10,
      "name": "Cloth_Block_Wool_White",
      "support": 15
    },
    {
      "x": -10,
      "y": 0,
      "z": -9,
      "name": "Soil_Dirt"
    },
    {
      "x": -10,
      "y": 1,
      "z": -9,
      "name": "Soil_Dirt"
    },
    {
      "x": -10,
      "y": 2,
      "z": -9,
      "name": "Soil_Dirt"
    },
    {
      "x": -10,
      "y": 3,
      "z": -9,
      "name": "Soil_Dirt"
    },
    {
      "x": -10,
      "y": 4,
      "z": -9,
      "name": "Soil_Dirt"
    },
    {
      "x": -10,
      "y": 5,
      "z": -9,
      "name": "Soil_Pathway"
    },
    {
      "x": -10,
      "y": 6,
      "z": -9,
      "name": "Wood_Beech_Trunk",
      "support": 15
    },
    {
      "x": -10,
      "y": 7,
      "z": -9,
      "name": "Wood_Beech_Trunk",
      "support": 15
    },
    {
      "x": -10,
      "y": 8,
      "z": -9,
      "name": "Wood_Beech_Trunk",
      "support": 15
    },
    {
      "x": -10,
      "y": 9,
      "z": -9,
      "name": "Wood_Beech_Trunk",
      "support": 15
    },
    {
      "x": -10,
      "y": 10,
      "z": -9,
      "name": "Wood_Beech_Trunk",
      "support": 15
    },
    {
      "x": -10,
      "y": 11,
      "z": -9,
      "name": "Wood_Beech_Trunk",
      "support": 15
    },
    {
      "x": -10,
      "y": 12,
      "z": -9,
      "name": "Cloth_Block_Wool_White",
      "support": 15
    },
    {
      "x": -10,
      "y": 13,
      "z": -9,
      "name": "Cloth_Block_Wool_Red",
      "support": 15
    },
    {
      "x": -10,
      "y": 0,
      "z": -8,
      "name": "Soil_Dirt"
    },
    {
      "x": -10,
      "y": 1,
      "z": -8,
      "name": "Soil_Dirt"
    },
    {
      "x": -10,
      "y": 2,
      "z": -8,
      "name": "Soil_Dirt"
    },
    {
      "x": -10,
      "y": 3,
      "z": -8,
      "name": "Soil_Dirt"
    },
    {
      "x": -10,
      "y": 4,
      "z": -8,
      "name": "Soil_Dirt"
    },
    {
      "x": -10,
      "y": 5,
      "z": -8,
      "name": "Soil_Pathway"
    },
    {
      "x": -10,
      "y": 10,
      "z": -8,
      "name": "WinterHoliday_Lights",
      "support": 15,
      "rotation": 1
    },
    {
      "x": -10,
      "y": 12,
      "z": -8,
      "name": "Cloth_Modern_Red_Roof_Shallow",
      "support": 15,
      "rotation": 3
    },
    {
      "x": -10,
      "y": 13,
      "z": -8,
      "name": "Cloth_Roof_Yellow_Flap",
      "support": 15
    },
    {
      "x": -10,
      "y": 0,
      "z": -7,
      "name": "Soil_Dirt"
    },
    {
      "x": -10,
      "y": 1,
      "z": -7,
      "name": "Soil_Dirt"
    },
    {
      "x": -10,
      "y": 2,
      "z": -7,
      "name": "Soil_Dirt"
    },
    {
      "x": -10,
      "y": 3,
      "z": -7,
      "name": "Soil_Dirt"
    },
    {
      "x": -10,
      "y": 4,
      "z": -7,
      "name": "Soil_Dirt"
    },
    {
      "x": -10,
      "y": 5,
      "z": -7,
      "name": "Soil_Pathway"
    },
    {
      "x": -10,
      "y": 6,
      "z": -7,
      "name": "Wood_Hardwood_Planks_Half",
      "support": 15,
      "rotation": 7
    },
    {
      "x": -10,
      "y": 7,
      "z": -7,
      "name": "Wood_Hardwood_Planks_Half",
      "support": 15,
      "rotation": 7
    },
    {
      "x": -10,
      "y": 8,
      "z": -7,
      "name": "Wood_Hardwood_Planks_Half",
      "support": 15,
      "rotation": 7
    },
    {
      "x": -10,
      "y": 9,
      "z": -7,
      "name": "Wood_Hardwood_Planks_Half",
      "support": 15,
      "rotation": 7
    },
    {
      "x": -10,
      "y": 10,
      "z": -7,
      "name": "WinterHoliday_Lights",
      "support": 15,
      "rotation": 1
    },
    {
      "x": -10,
      "y": 12,
      "z": -7,
      "name": "Cloth_Modern_Red_Roof_Shallow",
      "support": 15,
      "rotation": 3
    },
    {
      "x": -10,
      "y": 0,
      "z": -6,
      "name": "Soil_Dirt"
    },
    {
      "x": -10,
      "y": 1,
      "z": -6,
      "name": "Soil_Dirt"
    },
    {
      "x": -10,
      "y": 2,
      "z": -6,
      "name": "Soil_Dirt"
    },
    {
      "x": -10,
      "y": 3,
      "z": -6,
      "name": "Soil_Dirt"
    },
    {
      "x": -10,
      "y": 4,
      "z": -6,
      "name": "Soil_Dirt"
    },
    {
      "x": -10,
      "y": 5,
      "z": -6,
      "name": "Soil_Pathway"
    },
    {
      "x": -10,
      "y": 6,
      "z": -6,
      "name": "Wood_Hardwood_Planks_Half",
      "support": 15,
      "rotation": 7
    },
    {
      "x": -10,
      "y": 7,
      "z": -6,
      "name": "Wood_Hardwood_Planks_Half",
      "support": 15,
      "rotation": 7
    },
    {
      "x": -10,
      "y": 8,
      "z": -6,
      "name": "Wood_Hardwood_Planks_Half",
      "support": 15,
      "rotation": 7
    },
    {
      "x": -10,
      "y": 9,
      "z": -6,
      "name": "Wood_Hardwood_Planks_Half",
      "support": 15,
      "rotation": 7
    },
    {
      "x": -10,
      "y": 10,
      "z": -6,
      "name": "WinterHoliday_Lights",
      "support": 15,
      "rotation": 1
    },
    {
      "x": -10,
      "y": 12,
      "z": -6,
