{"version":8,"blockIdVersion":11,"anchorX":0,"anchorY":0,"anchorZ":0,"blocks":[{"x":-14,"y":0,"z":-14,"name":"Soil_Dirt"},{"x":-14,"y":1,"z":-14,"name":"Soil_Dirt"},{"x":-14,"y":2,"z":-14,"name":"Soil_Dirt"},{"x":-14,"y":3,"z":-14,"name":"Soil_Dirt"},{"x":-14,"y":4,"z":-14,"name":"Soil_Dirt"},{"x":-14,"y":5,"z":-14,"name":"Rock_Stone_Brick_Smooth"},{"x":-14,"y":0,"z":-13,"name":"Soil_Dirt"},{"x":-14,"y":1,"z":-13,"name":"Soil_Dirt"},{"x":-14,"y":2,"z":-13,"name":"Soil_Dirt"},{"x":-14,"y":3,"z":-13,"name":"Soil_Dirt"},{"x":-14,"y":4,"z":-13,"name":"Soil_Dirt"},{"x":-14,"y":5,"z":-13,"name":"Rock_Stone_Brick_Smooth"},{"x":-14,"y":0,"z":-12,"name":"Soil_Dirt"},{"x":-14,"y":1,"z":-12,"name":"Soil_Dirt"},{"x":-14,"y":2,"z":-12,"name":"Soil_Dirt"},{"x":-14,"y":3,"z":-12,"name":"Soil_Dirt"},{"x":-14,"y":4,"z":-12,"name":"Soil_Dirt"},{"x":-14,"y":5,"z":-12,"name":"Rock_Stone_Brick_Smooth"},{"x":-14,"y":0,"z":-11,"name":"Soil_Dirt"},{"x":-14,"y":1,"z":-11,"name":"Soil_Dirt"},{"x":-14,"y":2,"z":-11,"name":"Soil_Dirt"},{"x":-14,"y":3,"z":-11,"name":"Soil_Dirt"},{"x":-14,"y":4,"z":-11,"name":"Soil_Dirt"},{"x":-14,"y":5,"z":-11,"name":"Rock_Stone_Brick_Smooth"},{"x":-14,"y":0,"z":-10,"name":"Soil_Dirt"},{"x":-14,"y":1,"z":-10,"name":"Soil_Dirt"},{"x":-14,"y":2,"z":-10,"name":"Soil_Dirt"},{"x":-14,"y":3,"z":-10,"name":"Soil_Dirt"},{"x":-14,"y":4,"z":-10,"name":"Soil_Dirt"},{"x":-14,"y":5,"z":-10,"name":"Rock_Stone_Brick_Smooth"},{"x":-14,"y":0,"z":-9,"name":"Soil_Dirt"},{"x":-14,"y":1,"z":-9,"name":"Soil_Dirt"},{"x":-14,"y":2,"z":-9,"name":"Soil_Dirt"},{"x":-14,"y":3,"z":-9,"name":"Soil_Dirt"},{"x":-14,"y":4,"z":-9,"name":"Soil_Dirt"},{"x":-14,"y":5,"z":-9,"name":"Rock_Stone_Brick_Smooth"},{"x":-14,"y":0,"z":-8,"name":"Soil_Dirt"},{"x":-14,"y":1,"z":-8,"name":"Soil_Dirt"},{"x":-14,"y":2,"z":-8,"name":"Soil_Dirt"},{"x":-14,"y":3,"z":-8,"name":"Soil_Dirt"},{"x":-14,"y":4,"z":-8,"name":"Soil_Dirt"},{"x":-14,"y":5,"z":-8,"name":"Rock_Stone_Brick_Smooth"},{"x":-14,"y":0,"z":-7,"name":"Soil_Dirt"},{"x":-14,"y":1,"z":-7,"name":"Soil_Dirt"},{"x":-14,"y":2,"z":-7,"name":"Soil_Dirt"},{"x":-14,"y":3,"z":-7,"name":"Soil_Dirt"},{"x":-14,"y":4,"z":-7,"name":"Soil_Dirt"},{"x":-14,"y":5,"z":-7,"name":"Rock_Stone_Brick_Smooth"},{"x":-14,"y":0,"z":-6,"name":"Soil_Dirt"},{"x":-14,"y":1,"z":-6,"name":"Soil_Dirt"},{"x":-14,"y":2,"z":-6,"name":"Soil_Dirt"},{"x":-14,"y":3,"z":-6,"name":"Soil_Dirt"},{"x":-14,"y":4,"z":-6,"name":"Soil_Dirt"},{"x":-14,"y":5,"z":-6,"name":"Rock_Stone_Brick_Smooth"},{"x":-14,"y":0,"z":-5,"name":"Soil_Dirt"},{"x":-14,"y":1,"z":-5,"name":"Soil_Dirt"},{"x":-14,"y":2,"z":-5,"name":"Soil_Dirt"},{"x":-14,"y":3,"z":-5,"name":"Soil_Dirt"},{"x":-14,"y":4,"z":-5,"name":"Soil_Dirt"},{"x":-14,"y":5,"z":-5,"name":"Rock_Stone_Brick_Smooth"},{"x":-14,"y":0,"z":-4,"name":"Soil_Dirt"},{"x":-14,"y":1,"z":-4,"name":"Soil_Dirt"},{"x":-14,"y":2,"z":-4,"name":"Soil_Dirt"},{"x":-14,"y":3,"z":-4,"name":"Soil_Dirt"},{"x":-14,"y":4,"z":-4,"name":"Soil_Dirt"},{"x":-14,"y":5,"z":-4,"name":"Rock_Stone_Brick_Smooth"},{"x":-14,"y":0,"z":-3,"name":"Soil_Dirt"},{"x":-14,"y":1,"z":-3,"name":"Soil_Dirt"},{"x":-14,"y":2,"z":-3,"name":"Soil_Dirt"},{"x":-14,"y":3,"z":-3,"name":"Soil_Dirt"},{"x":-14,"y":4,"z":-3,"name":"Soil_Dirt"},{"x":-14,"y":5,"z":-3,"name":"Rock_Stone_Brick_Smooth"},{"x":-14,"y":0,"z":-2,"name":"Soil_Dirt"},{"x":-14,"y":1,"z":-2,"name":"Soil_Dirt"},{"x":-14,"y":2,"z":-2,"name":"Soil_Dirt"},{"x":-14,"y":3,"z":-2,"name":"Soil_Dirt"},{"x":-14,"y":4,"z":-2,"name":"Soil_Dirt"},{"x":-14,"y":5,"z":-2,"name":"Rock_Stone_Brick_Smooth"},{"x":-14,"y":0,"z":-1,"name":"Soil_Dirt"},{"x":-14,"y":1,"z":-1,"name":"Soil_Dirt"},{"x":-14,"y":2,"z":-1,"name":"Soil_Dirt"},{"x":-14,"y":3,"z":-1,"name":"Soil_Dirt"},{"x":-14,"y":4,"z":-1,"name":"Soil_Dirt"},{"x":-14,"y":5,"z":-1,"name":"Rock_Stone_Brick_Smooth"},{"x":-14,"y":0,"z":0,"name":"Soil_Dirt"},{"x":-14,"y":1,"z":0,"name":"Soil_Dirt"},{"x":-14,"y":2,"z":0,"name":"Soil_Dirt"},{"x":-14,"y":3,"z":0,"name":"Soil_Dirt"},{"x":-14,"y":4,"z":0,"name":"Soil_Dirt"},{"x":-14,"y":5,"z":0,"name":"Rock_Stone_Brick_Smooth"},{"x":-14,"y":0,"z":1,"name":"Soil_Dirt"},{"x":-14,"y":1,"z":1,"name":"Soil_Dirt"},{"x":-14,"y":2,"z":1,"name":"Soil_Dirt"},{"x":-14,"y":3,"z":1,"name":"Soil_Dirt"},{"x":-14,"y":4,"z":1,"name":"Soil_Dirt"},{"x":-14,"y":5,"z":1,"name":"Rock_Stone_Brick_Smooth"},{"x":-14,"y":0,"z":2,"name":"Soil_Dirt"},{"x":-14,"y":1,"z":2,"name":"Soil_Dirt"},{"x":-14,"y":2,"z":2,"name":"Soil_Dirt"},{"x":-14,"y":3,"z":2,"name":"Soil_Dirt"},{"x":-14,"y":4,"z":2,"name":"Soil_Dirt"},{"x":-14,"y":5,"z":2,"name":"Rock_Stone_Brick_Smooth"},{"x":-14,"y":0,"z":3,"name":"Soil_Dirt"},{"x":-14,"y":1,"z":3,"name":"Soil_Dirt"},{"x":-14,"y":2,"z":3,"name":"Soil_Dirt"},{"x":-14,"y":3,"z":3,"name":"Soil_Dirt"},{"x":-14,"y":4,"z":3,"name":"Soil_Dirt"},{"x":-14,"y":5,"z":3,"name":"Rock_Stone_Brick_Smooth"},{"x":-14,"y":0,"z":4,"name":"Soil_Dirt"},{"x":-14,"y":1,"z":4,"name":"Soil_Dirt"},{"x":-14,"y":2,"z":4,"name":"Soil_Dirt"},{"x":-14,"y":3,"z":4,"name":"Soil_Dirt"},{"x":-14,"y":4,"z":4,"name":"Soil_Dirt"},{"x":-14,"y":5,"z":4,"name":"Rock_Stone_Brick_Smooth"},{"x":-14,"y":0,"z":5,"name":"Soil_Dirt"},{"x":-14,"y":1,"z":5,"name":"Soil_Dirt"},{"x":-14,"y":2,"z":5,"name":"Soil_Dirt"},{"x":-14,"y":3,"z":5,"name":"Soil_Dirt"},{"x":-14,"y":4,"z":5,"name":"Soil_Dirt"},{"x":-14,"y":5,"z":5,"name":"Rock_Stone_Brick_Smooth"},{"x":-14,"y":0,"z":6,"name":"Soil_Dirt"},{"x":-14,"y":1,"z":6,"name":"Soil_Dirt"},{"x":-14,"y":2,"z":6,"name":"Soil_Dirt"},{"x":-14,"y":3,"z":6,"name":"Soil_Dirt"},{"x":-14,"y":4,"z":6,"name":"Soil_Dirt"},{"x":-14,"y":5,"z":6,"name":"Rock_Stone_Brick_Smooth"},{"x":-14,"y":0,"z":7,"name":"Soil_Dirt"},{"x":-14,"y":1,"z":7,"name":"Soil_Dirt"},{"x":-14,"y":2,"z":7,"name":"Soil_Dirt"},{"x":-14,"y":3,"z":7,"name":"Soil_Dirt"},{"x":-14,"y":4,"z":7,"name":"Soil_Dirt"},{"x":-14,"y":5,"z":7,"name":"Rock_Stone_Brick_Smooth"},{"x":-14,"y":0,"z":8,"name":"Soil_Dirt"},{"x":-14,"y":1,"z":8,"name":"Soil_Dirt"},{"x":-14,"y":2,"z":8,"name":"Soil_Dirt"},{"x":-14,"y":3,"z":8,"name":"Soil_Dirt"},{"x":-14,"y":4,"z":8,"name":"Soil_Dirt"},{"x":-14,"y":5,"z":8,"name":"Rock_Stone_Brick_Smooth"},{"x":-14,"y":0,"z":9,"name":"Soil_Dirt"},{"x":-14,"y":1,"z":9,"name":"Soil_Dirt"},{"x":-14,"y":2,"z":9,"name":"Soil_Dirt"},{"x":-14,"y":3,"z":9,"name":"Soil_Dirt"},{"x":-14,"y":4,"z":9,"name":"Soil_Dirt"},{"x":-14,"y":5,"z":9,"name":"Rock_Stone_Brick_Smooth"},{"x":-14,"y":0,"z":10,"name":"Soil_Dirt"},{"x":-14,"y":1,"z":10,"name":"Soil_Dirt"},{"x":-14,"y":2,"z":10,"name":"Soil_Dirt"},{"x":-14,"y":3,"z":10,"name":"Soil_Dirt"},{"x":-14,"y":4,"z":10,"name":"Soil_Dirt"},{"x":-14,"y":5,"z":10,"name":"Rock_Stone_Brick_Smooth"},{"x":-14,"y":0,"z":11,"name":"Soil_Dirt"},{"x":-14,"y":1,"z":11,"name":"Soil_Dirt"},{"x":-14,"y":2,"z":11,"name":"Soil_Dirt"},{"x":-14,"y":3,"z":11,"name":"Soil_Dirt"},{"x":-14,"y":4,"z":11,"name":"Soil_Dirt"},{"x":-14,"y":5,"z":11,"name":"Rock_Stone_Brick_Smooth"},{"x":-14,"y":0,"z":12,"name":"Soil_Dirt"},{"x":-14,"y":1,"z":12,"name":"Soil_Dirt"},{"x":-14,"y":2,"z":12,"name":"Soil_Dirt"},{"x":-14,"y":3,"z":12,"name":"Soil_Dirt"},{"x":-14,"y":4,"z":12,"name":"Soil_Dirt"},{"x":-14,"y":5,"z":12,"name":"Rock_Stone_Brick_Smooth"},{"x":-14,"y":0,"z":13,"name":"Soil_Dirt"},{"x":-14,"y":1,"z":13,"name":"Soil_Dirt"},{"x":-14,"y":2,"z":13,"name":"Soil_Dirt"},{"x":-14,"y":3,"z":13,"name":"Soil_Dirt"},{"x":-14,"y":4,"z":13,"name":"Soil_Dirt"},{"x":-14,"y":5,"z":13,"name":"Rock_Stone_Brick_Smooth"},{"x":-14,"y":0,"z":14,"name":"Soil_Dirt"},{"x":-14,"y":1,"z":14,"name":"Soil_Dirt"},{"x":-14,"y":2,"z":14,"name":"Soil_Dirt"},{"x":-14,"y":3,"z":14,"name":"Soil_Dirt"},{"x":-14,"y":4,"z":14,"name":"Soil_Dirt"},{"x":-14,"y":5,"z":14,"name":"Rock_Stone_Brick_Smooth"},{"x":-14,"y":0,"z":15,"name":"Soil_Dirt"},{"x":-14,"y":1,"z":15,"name":"Soil_Dirt"},{"x":-14,"y":2,"z":15,"name":"Soil_Dirt"},{"x":-14,"y":3,"z":15,"name":"Soil_Dirt"},{"x":-14,"y":4,"z":15,"name":"Soil_Dirt"},{"x":-14,"y":5,"z":15,"name":"Rock_Stone_Brick_Smooth"},{"x":-13,"y":0,"z":-14,"name":"Soil_Dirt"},{"x":-13,"y":1,"z":-14,"name":"Soil_Dirt"},{"x":-13,"y":2,"z":-14,"name":"Soil_Dirt"},{"x":-13,"y":3,"z":-14,"name":"Soil_Dirt"},{"x":-13,"y":4,"z":-14,"name":"Soil_Dirt"},{"x":-13,"y":5,"z":-14,"name":"Rock_Stone_Brick_Smooth"},{"x":-13,"y":0,"z":-13,"name":"Soil_Dirt"},{"x":-13,"y":1,"z":-13,"name":"Soil_Dirt"},{"x":-13,"y":2,"z":-13,"name":"Soil_Dirt"},{"x":-13,"y":3,"z":-13,"name":"Soil_Dirt"},{"x":-13,"y":4,"z":-13,"name":"Soil_Dirt"},{"x":-13,"y":5,"z":-13,"name":"Rock_Stone_Cobble_Mossy"},{"x":-13,"y":6,"z":-13,"name":"Rock_Stone_Brick_Decorative","rotation":2},{"x":-13,"y":0,"z":-12,"name":"Soil_Dirt"},{"x":-13,"y":1,"z":-12,"name":"Soil_Dirt"},{"x":-13,"y":2,"z":-12,"name":"Soil_Dirt"},{"x":-13,"y":3,"z":-12,"name":"Soil_Dirt"},{"x":-13,"y":4,"z":-12,"name":"Soil_Dirt"},{"x":-13,"y":5,"z":-12,"name":"Rock_Stone_Cobble"},{"x":-13,"y":6,"z":-12,"name":"Rock_Stone_Brick_Stairs","rotation":35},{"x":-13,"y":0,"z":-11,"name":"Soil_Dirt"},{"x":-13,"y":1,"z":-11,"name":"Soil_Dirt"},{"x":-13,"y":2,"z":-11,"name":"Soil_Dirt"},{"x":-13,"y":3,"z":-11,"name":"Soil_Dirt"},{"x":-13,"y":4,"z":-11,"name":"Soil_Dirt"},{"x":-13,"y":5,"z":-11,"name":"Rock_Stone_Cobble_Mossy"},{"x":-13,"y":6,"z":-11,"name":"Rock_Stone_Brick_Stairs","rotation":35},{"x":-13,"y":0,"z":-10,"name":"Soil_Dirt"},{"x":-13,"y":1,"z":-10,"name":"Soil_Dirt"},{"x":-13,"y":2,"z":-10,"name":"Soil_Dirt"},{"x":-13,"y":3,"z":-10,"name":"Soil_Dirt"},{"x":-13,"y":4,"z":-10,"name":"Soil_Dirt"},{"x":-13,"y":5,"z":-10,"name":"Rock_Stone_Cobble"},{"x":-13,"y":6,"z":-10,"name":"Rock_Stone_Brick_Decorative","rotation":2},{"x":-13,"y":0,"z":-9,"name":"Soil_Dirt"},{"x":-13,"y":1,"z":-9,"name":"Soil_Dirt"},{"x":-13,"y":2,"z":-9,"name":"Soil_Dirt"},{"x":-13,"y":3,"z":-9,"name":"Soil_Dirt"},{"x":-13,"y":4,"z":-9,"name":"Soil_Dirt"},{"x":-13,"y":5,"z":-9,"name":"Rock_Stone_Cobble"},{"x":-13,"y":0,"z":-8,"name":"Soil_Dirt"},{"x":-13,"y":1,"z":-8,"name":"Soil_Dirt"},{"x":-13,"y":2,"z":-8,"name":"Soil_Dirt"},{"x":-13,"y":3,"z":-8,"name":"Soil_Dirt"},{"x":-13,"y":4,"z":-8,"name":"Soil_Dirt"},{"x":-13,"y":5,"z":-8,"name":"Rock_Stone_Cobble"},{"x":-13,"y":0,"z":-7,"name":"Soil_Dirt"},{"x":-13,"y":1,"z":-7,"name":"Soil_Dirt"},{"x":-13,"y":2,"z":-7,"name":"Soil_Dirt"},{"x":-13,"y":3,"z":-7,"name":"Soil_Dirt"},{"x":-13,"y":4,"z":-7,"name":"Soil_Dirt"},{"x":-13,"y":5,"z":-7,"name":"Rock_Stone_Cobble"},{"x":-13,"y":0,"z":-6,"name":"Soil_Dirt"},{"x":-13,"y":1,"z":-6,"name":"Soil_Dirt"},{"x":-13,"y":2,"z":-6,"name":"Soil_Dirt"},{"x":-13,"y":3,"z":-6,"name":"Soil_Dirt"},{"x":-13,"y":4,"z":-6,"name":"Soil_Dirt"},{"x":-13,"y":5,"z":-6,"name":"Rock_Stone_Cobble_Mossy"},{"x":-13,"y":0,"z":-5,"name":"Soil_Dirt"},{"x":-13,"y":1,"z":-5,"name":"Soil_Dirt"},{"x":-13,"y":2,"z":-5,"name":"Soil_Dirt"},{"x":-13,"y":3,"z":-5,"name":"Soil_Dirt"},{"x":-13,"y":4,"z":-5,"name":"Soil_Dirt"},{"x":-13,"y":5,"z":-5,"name":"Rock_Stone_Cobble"},{"x":-13,"y":0,"z":-4,"name":"Soil_Dirt"},{"x":-13,"y":1,"z":-4,"name":"Soil_Dirt"},{"x":-13,"y":2,"z":-4,"name":"Soil_Dirt"},{"x":-13,"y":3,"z":-4,"name":"Soil_Dirt"},{"x":-13,"y":4,"z":-4,"name":"Soil_Dirt"},{"x":-13,"y":5,"z":-4,"name":"Rock_Stone_Cobble_Mossy"},{"x":-13,"y":0,"z":-3,"name":"Soil_Dirt"},{"x":-13,"y":1,"z":-3,"name":"Soil_Dirt"},{"x":-13,"y":2,"z":-3,"name":"Soil_Dirt"},{"x":-13,"y":3,"z":-3,"name":"Soil_Dirt"},{"x":-13,"y":4,"z":-3,"name":"Soil_Dirt"},{"x":-13,"y":5,"z":-3,"name":"Rock_Stone_Cobble_Mossy"},{"x":-13,"y":0,"z":-2,"name":"Soil_Dirt"},{"x":-13,"y":1,"z":-2,"name":"Soil_Dirt"},{"x":-13,"y":2,"z":-2,"name":"Soil_Dirt"},{"x":-13,"y":3,"z":-2,"name":"Soil_Dirt"},{"x":-13,"y":4,"z":-2,"name":"Soil_Dirt"},{"x":-13,"y":5,"z":-2,"name":"Rock_Stone_Cobble"},{"x":-13,"y":0,"z":-1,"name":"Soil_Dirt"},{"x":-13,"y":1,"z":-1,"name":"Soil_Dirt"},{"x":-13,"y":2,"z":-1,"name":"Soil_Dirt"},{"x":-13,"y":3,"z":-1,"name":"Soil_Dirt"},{"x":-13,"y":4,"z":-1,"name":"Soil_Dirt"},{"x":-13,"y":5,"z":-1,"name":"Rock_Stone_Cobble"},{"x":-13,"y":0,"z":0,"name":"Soil_Dirt"},{"x":-13,"y":1,"z":0,"name":"Soil_Dirt"},{"x":-13,"y":2,"z":0,"name":"Soil_Dirt"},{"x":-13,"y":3,"z":0,"name":"Soil_Dirt"},{"x":-13,"y":4,"z":0,"name":"Soil_Dirt"},{"x":-13,"y":5,"z":0,"name":"Rock_Stone_Cobble"},{"x":-13,"y":0,"z":1,"name":"Soil_Dirt"},{"x":-13,"y":1,"z":1,"name":"Soil_Dirt"},{"x":-13,"y":2,"z":1,"name":"Soil_Dirt"},{"x":-13,"y":3,"z":1,"name":"Soil_Dirt"},{"x":-13,"y":4,"z":1,"name":"Soil_Dirt"},{"x":-13,"y":5,"z":1,"name":"Rock_Stone_Cobble"},{"x":-13,"y":0,"z":2,"name":"Soil_Dirt"},{"x":-13,"y":1,"z":2,"name":"Soil_Dirt"},{"x":-13,"y":2,"z":2,"name":"Soil_Dirt"},{"x":-13,"y":3,"z":2,"name":"Soil_Dirt"},{"x":-13,"y":4,"z":2,"name":"Soil_Dirt"},{"x":-13,"y":5,"z":2,"name":"Rock_Stone_Cobble"},{"x":-13,"y":0,"z":3,"name":"Soil_Dirt"},{"x":-13,"y":1,"z":3,"name":"Soil_Dirt"},{"x":-13,"y":2,"z":3,"name":"Soil_Dirt"},{"x":-13,"y":3,"z":3,"name":"Soil_Dirt"},{"x":-13,"y":4,"z":3,"name":"Soil_Dirt"},{"x":-13,"y":5,"z":3,"name":"Rock_Stone_Cobble_Mossy"},{"x":-13,"y":0,"z":4,"name":"Soil_Dirt"},{"x":-13,"y":1,"z":4,"name":"Soil_Dirt"},{"x":-13,"y":2,"z":4,"name":"Soil_Dirt"},{"x":-13,"y":3,"z":4,"name":"Soil_Dirt"},{"x":-13,"y":4,"z":4,"name":"Soil_Dirt"},{"x":-13,"y":5,"z":4,"name":"Rock_Stone_Cobble"},{"x":-13,"y":0,"z":5,"name":"Soil_Dirt"},{"x":-13,"y":1,"z":5,"name":"Soil_Dirt"},{"x":-13,"y":2,"z":5,"name":"Soil_Dirt"},{"x":-13,"y":3,"z":5,"name":"Soil_Dirt"},{"x":-13,"y":4,"z":5,"name":"Soil_Dirt"},{"x":-13,"y":5,"z":5,"name":"Rock_Stone_Cobble"},{"x":-13,"y":0,"z":6,"name":"Soil_Dirt"},{"x":-13,"y":1,"z":6,"name":"Soil_Dirt"},{"x":-13,"y":2,"z":6,"name":"Soil_Dirt"},{"x":-13,"y":3,"z":6,"name":"Soil_Dirt"},{"x":-13,"y":4,"z":6,"name":"Soil_Dirt"},{"x":-13,"y":5,"z":6,"name":"Rock_Stone_Cobble"},{"x":-13,"y":0,"z":7,"name":"Soil_Dirt"},{"x":-13,"y":1,"z":7,"name":"Soil_Dirt"},{"x":-13,"y":2,"z":7,"name":"Soil_Dirt"},{"x":-13,"y":3,"z":7,"name":"Soil_Dirt"},{"x":-13,"y":4,"z":7,"name":"Soil_Dirt"},{"x":-13,"y":5,"z":7,"name":"Rock_Stone_Cobble"},{"x":-13,"y":0,"z":8,"name":"Soil_Dirt"},{"x":-13,"y":1,"z":8,"name":"Soil_Dirt"},{"x":-13,"y":2,"z":8,"name":"Soil_Dirt"},{"x":-13,"y":3,"z":8,"name":"Soil_Dirt"},{"x":-13,"y":4,"z":8,"name":"Soil_Dirt"},{"x":-13,"y":5,"z":8,"name":"Rock_Stone_Cobble"},{"x":-13,"y":0,"z":9,"name":"Soil_Dirt"},{"x":-13,"y":1,"z":9,"name":"Soil_Dirt"},{"x":-13,"y":2,"z":9,"name":"Soil_Dirt"},{"x":-13,"y":3,"z":9,"name":"Soil_Dirt"},{"x":-13,"y":4,"z":9,"name":"Soil_Dirt"},{"x":-13,"y":5,"z":9,"name":"Rock_Stone_Cobble"},{"x":-13,"y":0,"z":10,"name":"Soil_Dirt"},{"x":-13,"y":1,"z":10,"name":"Soil_Dirt"},{"x":-13,"y":2,"z":10,"name":"Soil_Dirt"},{"x":-13,"y":3,"z":10,"name":"Soil_Dirt"},{"x":-13,"y":4,"z":10,"name":"Soil_Dirt"},{"x":-13,"y":5,"z":10,"name":"Rock_Stone_Cobble"},{"x":-13,"y":0,"z":11,"name":"Soil_Dirt"},{"x":-13,"y":1,"z":11,"name":"Soil_Dirt"},{"x":-13,"y":2,"z":11,"name":"Soil_Dirt"},{"x":-13,"y":3,"z":11,"name":"Soil_Dirt"},{"x":-13,"y":4,"z":11,"name":"Soil_Dirt"},{"x":-13,"y":5,"z":11,"name":"Rock_Stone_Cobble_Mossy"},{"x":-13,"y":6,"z":11,"name":"Rock_Stone_Brick_Decorative","rotation":3},{"x":-13,"y":0,"z":12,"name":"Soil_Dirt"},{"x":-13,"y":1,"z":12,"name":"Soil_Dirt"},{"x":-13,"y":2,"z":12,"name":"Soil_Dirt"},{"x":-13,"y":3,"z":12,"name":"Soil_Dirt"},{"x":-13,"y":4,"z":12,"name":"Soil_Dirt"},{"x":-13,"y":5,"z":12,"name":"Rock_Stone_Cobble"},{"x":-13,"y":6,"z":12,"name":"Rock_Stone_Brick_Stairs","rotation":35},{"x":-13,"y":0,"z":13,"name":"Soil_Dirt"},{"x":-13,"y":1,"z":13,"name":"Soil_Dirt"},{"x":-13,"y":2,"z":13,"name":"Soil_Dirt"},{"x":-13,"y":3,"z":13,"name":"Soil_Dirt"},{"x":-13,"y":4,"z":13,"name":"Soil_Dirt"},{"x":-13,"y":5,"z":13,"name":"Rock_Stone_Cobble"},{"x":-13,"y":6,"z":13,"name":"Rock_Stone_Brick_Stairs","rotation":35},{"x":-13,"y":0,"z":14,"name":"Soil_Dirt"},{"x":-13,"y":1,"z":14,"name":"Soil_Dirt"},{"x":-13,"y":2,"z":14,"name":"Soil_Dirt"},{"x":-13,"y":3,"z":14,"name":"Soil_Dirt"},{"x":-13,"y":4,"z":14,"name":"Soil_Dirt"},{"x":-13,"y":5,"z":14,"name":"Rock_Stone_Cobble"},{"x":-13,"y":6,"z":14,"name":"Rock_Stone_Brick_Decorative","rotation":3},{"x":-13,"y":0,"z":15,"name":"Soil_Dirt"},{"x":-13,"y":1,"z":15,"name":"Soil_Dirt"},{"x":-13,"y":2,"z":15,"name":"Soil_Dirt"},{"x":-13,"y":3,"z":15,"name":"Soil_Dirt"},{"x":-13,"y":4,"z":15,"name":"Soil_Dirt"},{"x":-13,"y":5,"z":15,"name":"Rock_Stone_Brick_Smooth"},{"x":-12,"y":0,"z":-14,"name":"Soil_Dirt"},{"x":-12,"y":1,"z":-14,"name":"Soil_Dirt"},{"x":-12,"y":2,"z":-14,"name":"Soil_Dirt"},{"x":-12,"y":3,"z":-14,"name":"Soil_Dirt"},{"x":-12,"y":4,"z":-14,"name":"Soil_Dirt"},{"x":-12,"y":5,"z":-14,"name":"Rock_Stone_Brick_Smooth"},{"x":-12,"y":0,"z":-13,"name":"Soil_Dirt"},{"x":-12,"y":1,"z":-13,"name":"Soil_Dirt"},{"x":-12,"y":2,"z":-13,"name":"Soil_Dirt"},{"x":-12,"y":3,"z":-13,"name":"Soil_Dirt"},{"x":-12,"y":4,"z":-13,"name":"Soil_Dirt"},{"x":-12,"y":5,"z":-13,"name":"Rock_Stone_Cobble"},{"x":-12,"y":6,"z":-13,"name":"Rock_Stone_Brick_Stairs","rotation":34},{"x":-12,"y":0,"z":-12,"name":"Soil_Dirt"},{"x":-12,"y":1,"z":-12,"name":"Soil_Dirt"},{"x":-12,"y":2,"z":-12,"name":"Soil_Dirt"},{"x":-12,"y":3,"z":-12,"name":"Soil_Dirt"},{"x":-12,"y":4,"z":-12,"name":"Soil_Dirt"},{"x":-12,"y":5,"z":-12,"name":"Rock_Stone_Cobble_Mossy"},{"x":-12,"y":6,"z":-12,"name":"Rock_Stone_Brick_Smooth"},{"x":-12,"y":0,"z":-11,"name":"Soil_Dirt"},{"x":-12,"y":1,"z":-11,"name":"Soil_Dirt"},{"x":-12,"y":2,"z":-11,"name":"Soil_Dirt"},{"x":-12,"y":3,"z":-11,"name":"Soil_Dirt"},{"x":-12,"y":4,"z":-11,"name":"Soil_Dirt"},{"x":-12,"y":5,"z":-11,"name":"Rock_Stone_Cobble"},{"x":-12,"y":6,"z":-11,"name":"Rock_Stone_Brick_Smooth"},{"x":-12,"y":0,"z":-10,"name":"Soil_Dirt"},{"x":-12,"y":1,"z":-10,"name":"Soil_Dirt"},{"x":-12,"y":2,"z":-10,"name":"Soil_Dirt"},{"x":-12,"y":3,"z":-10,"name":"Soil_Dirt"},{"x":-12,"y":4,"z":-10,"name":"Soil_Dirt"},{"x":-12,"y":5,"z":-10,"name":"Rock_Stone_Cobble"},{"x":-12,"y":6,"z":-10,"name":"Rock_Stone_Brick_Stairs","rotation":32},{"x":-12,"y":0,"z":-9,"name":"Soil_Dirt"},{"x":-12,"y":1,"z":-9,"name":"Soil_Dirt"},{"x":-12,"y":2,"z":-9,"name":"Soil_Dirt"},{"x":-12,"y":3,"z":-9,"name":"Soil_Dirt"},{"x":-12,"y":4,"z":-9,"name":"Soil_Dirt"},{"x":-12,"y":5,"z":-9,"name":"Rock_Stone_Cobble_Mossy"},{"x":-12,"y":0,"z":-8,"name":"Soil_Dirt"},{"x":-12,"y":1,"z":-8,"name":"Soil_Dirt"},{"x":-12,"y":2,"z":-8,"name":"Soil_Dirt"},{"x":-12,"y":3,"z":-8,"name":"Soil_Dirt"},{"x":-12,"y":4,"z":-8,"name":"Soil_Dirt"},{"x":-12,"y":5,"z":-8,"name":"Rock_Stone_Cobble"},{"x":-12,"y":0,"z":-7,"name":"Soil_Dirt"},{"x":-12,"y":1,"z":-7,"name":"Soil_Dirt"},{"x":-12,"y":2,"z":-7,"name":"Soil_Dirt"},{"x":-12,"y":3,"z":-7,"name":"Soil_Dirt"},{"x":-12,"y":4,"z":-7,"name":"Soil_Dirt"},{"x":-12,"y":5,"z":-7,"name":"Rock_Stone_Cobble"},{"x":-12,"y":0,"z":-6,"name":"Soil_Dirt"},{"x":-12,"y":1,"z":-6,"name":"Soil_Dirt"},{"x":-12,"y":2,"z":-6,"name":"Soil_Dirt"},{"x":-12,"y":3,"z":-6,"name":"Soil_Dirt"},{"x":-12,"y":4,"z":-6,"name":"Soil_Dirt"},{"x":-12,"y":5,"z":-6,"name":"Rock_Stone_Cobble"},{"x":-12,"y":0,"z":-5,"name":"Soil_Dirt"},{"x":-12,"y":1,"z":-5,"name":"Soil_Dirt"},{"x":-12,"y":2,"z":-5,"name":"Soil_Dirt"},{"x":-12,"y":3,"z":-5,"name":"Soil_Dirt"},{"x":-12,"y":4,"z":-5,"name":"Soil_Dirt"},{"x":-12,"y":5,"z":-5,"name":"Rock_Stone_Cobble"},{"x":-12,"y":0,"z":-4,"name":"Soil_Dirt"},{"x":-12,"y":1,"z":-4,"name":"Soil_Dirt"},{"x":-12,"y":2,"z":-4,"name":"Soil_Dirt"},{"x":-12,"y":3,"z":-4,"name":"Soil_Dirt"},{"x":-12,"y":4,"z":-4,"name":"Soil_Dirt"},{"x":-12,"y":5,"z":-4,"name":"Rock_Stone_Cobble"},{"x":-12,"y":0,"z":-3,"name":"Soil_Dirt"},{"x":-12,"y":1,"z":-3,"name":"Soil_Dirt"},{"x":-12,"y":2,"z":-3,"name":"Soil_Dirt"},{"x":-12,"y":3,"z":-3,"name":"Soil_Dirt"},{"x":-12,"y":4,"z":-3,"name":"Soil_Dirt"},{"x":-12,"y":5,"z":-3,"name":"Rock_Stone_Cobble"},{"x":-12,"y":0,"z":-2,"name":"Soil_Dirt"},{"x":-12,"y":1,"z":-2,"name":"Soil_Dirt"},{"x":-12,"y":2,"z":-2,"name":"Soil_Dirt"},{"x":-12,"y":3,"z":-2,"name":"Soil_Dirt"},{"x":-12,"y":4,"z":-2,"name":"Soil_Dirt"},{"x":-12,"y":5,"z":-2,"name":"Rock_Stone_Cobble"},{"x":-12,"y":0,"z":-1,"name":"Soil_Dirt"},{"x":-12,"y":1,"z":-1,"name":"Soil_Dirt"},{"x":-12,"y":2,"z":-1,"name":"Soil_Dirt"},{"x":-12,"y":3,"z":-1,"name":"Soil_Dirt"},{"x":-12,"y":4,"z":-1,"name":"Soil_Dirt"},{"x":-12,"y":5,"z":-1,"name":"Rock_Stone_Cobble"},{"x":-12,"y":0,"z":0,"name":"Soil_Dirt"},{"x":-12,"y":1,"z":0,"name":"Soil_Dirt"},{"x":-12,"y":2,"z":0,"name":"Soil_Dirt"},{"x":-12,"y":3,"z":0,"name":"Soil_Dirt"},{"x":-12,"y":4,"z":0,"name":"Soil_Dirt"},{"x":-12,"y":5,"z":0,"name":"Rock_Stone_Cobble"},{"x":-12,"y":0,"z":1,"name":"Soil_Dirt"},{"x":-12,"y":1,"z":1,"name":"Soil_Dirt"},{"x":-12,"y":2,"z":1,"name":"Soil_Dirt"},{"x":-12,"y":3,"z":1,"name":"Soil_Dirt"},{"x":-12,"y":4,"z":1,"name":"Soil_Dirt"},{"x":-12,"y":5,"z":1,"name":"Rock_Stone_Cobble"},{"x":-12,"y":0,"z":2,"name":"Soil_Dirt"},{"x":-12,"y":1,"z":2,"name":"Soil_Dirt"},{"x":-12,"y":2,"z":2,"name":"Soil_Dirt"},{"x":-12,"y":3,"z":2,"name":"Soil_Dirt"},{"x":-12,"y":4,"z":2,"name":"Soil_Dirt"},{"x":-12,"y":5,"z":2,"name":"Rock_Stone_Cobble_Mossy"},{"x":-12,"y":0,"z":3,"name":"Soil_Dirt"},{"x":-12,"y":1,"z":3,"name":"Soil_Dirt"},{"x":-12,"y":2,"z":3,"name":"Soil_Dirt"},{"x":-12,"y":3,"z":3,"name":"Soil_Dirt"},{"x":-12,"y":4,"z":3,"name":"Soil_Dirt"},{"x":-12,"y":5,"z":3,"name":"Rock_Stone_Cobble"},{"x":-12,"y":0,"z":4,"name":"Soil_Dirt"},{"x":-12,"y":1,"z":4,"name":"Soil_Dirt"},{"x":-12,"y":2,"z":4,"name":"Soil_Dirt"},{"x":-12,"y":3,"z":4,"name":"Soil_Dirt"},{"x":-12,"y":4,"z":4,"name":"Soil_Dirt"},{"x":-12,"y":5,"z":4,"name":"Rock_Stone_Cobble_Mossy"},{"x":-12,"y":0,"z":5,"name":"Soil_Dirt"},{"x":-12,"y":1,"z":5,"name":"Soil_Dirt"},{"x":-12,"y":2,"z":5,"name":"Soil_Dirt"},{"x":-12,"y":3,"z":5,"name":"Soil_Dirt"},{"x":-12,"y":4,"z":5,"name":"Soil_Dirt"},{"x":-12,"y":5,"z":5,"name":"Rock_Stone_Cobble_Mossy"},{"x":-12,"y":0,"z":6,"name":"Soil_Dirt"},{"x":-12,"y":1,"z":6,"name":"Soil_Dirt"},{"x":-12,"y":2,"z":6,"name":"Soil_Dirt"},{"x":-12,"y":3,"z":6,"name":"Soil_Dirt"},{"x":-12,"y":4,"z":6,"name":"Soil_Dirt"},{"x":-12,"y":5,"z":6,"name":"Rock_Stone_Cobble"},{"x":-12,"y":0,"z":7,"name":"Soil_Dirt"},{"x":-12,"y":1,"z":7,"name":"Soil_Dirt"},{"x":-12,"y":2,"z":7,"name":"Soil_Dirt"},{"x":-12,"y":3,"z":7,"name":"Soil_Dirt"},{"x":-12,"y":4,"z":7,"name":"Soil_Dirt"},{"x":-12,"y":5,"z":7,"name":"Rock_Stone_Cobble"},{"x":-12,"y":0,"z":8,"name":"Soil_Dirt"},{"x":-12,"y":1,"z":8,"name":"Soil_Dirt"},{"x":-12,"y":2,"z":8,"name":"Soil_Dirt"},{"x":-12,"y":3,"z":8,"name":"Soil_Dirt"},{"x":-12,"y":4,"z":8,"name":"Soil_Dirt"},{"x":-12,"y":5,"z":8,"name":"Rock_Stone_Cobble"},{"x":-12,"y":0,"z":9,"name":"Soil_Dirt"},{"x":-12,"y":1,"z":9,"name":"Soil_Dirt"},{"x":-12,"y":2,"z":9,"name":"Soil_Dirt"},{"x":-12,"y":3,"z":9,"name":"Soil_Dirt"},{"x":-12,"y":4,"z":9,"name":"Soil_Dirt"},{"x":-12,"y":5,"z":9,"name":"Rock_Stone_Cobble_Mossy"},{"x":-12,"y":0,"z":10,"name":"Soil_Dirt"},{"x":-12,"y":1,"z":10,"name":"Soil_Dirt"},{"x":-12,"y":2,"z":10,"name":"Soil_Dirt"},{"x":-12,"y":3,"z":10,"name":"Soil_Dirt"},{"x":-12,"y":4,"z":10,"name":"Soil_Dirt"},{"x":-12,"y":5,"z":10,"name":"Rock_Stone_Cobble"},{"x":-12,"y":0,"z":11,"name":"Soil_Dirt"},{"x":-12,"y":1,"z":11,"name":"Soil_Dirt"},{"x":-12,"y":2,"z":11,"name":"Soil_Dirt"},{"x":-12,"y":3,"z":11,"name":"Soil_Dirt"},{"x":-12,"y":4,"z":11,"name":"Soil_Dirt"},{"x":-12,"y":5,"z":11,"name":"Rock_Stone_Cobble_Mossy"},{"x":-12,"y":6,"z":11,"name":"Rock_Stone_Brick_Stairs","rotation":34},{"x":-12,"y":0,"z":12,"name":"Soil_Dirt"},{"x":-12,"y":1,"z":12,"name":"Soil_Dirt"},{"x":-12,"y":2,"z":12,"name":"Soil_Dirt"},{"x":-12,"y":3,"z":12,"name":"Soil_Dirt"},{"x":-12,"y":4,"z":12,"name":"Soil_Dirt"},{"x":-12,"y":5,"z":12,"name":"Rock_Stone_Cobble"},{"x":-12,"y":6,"z":12,"name":"Rock_Stone_Brick_Smooth"},{"x":-12,"y":0,"z":13,"name":"Soil_Dirt"},{"x":-12,"y":1,"z":13,"name":"Soil_Dirt"},{"x":-12,"y":2,"z":13,"name":"Soil_Dirt"},{"x":-12,"y":3,"z":13,"name":"Soil_Dirt"},{"x":-12,"y":4,"z":13,"name":"Soil_Dirt"},{"x":-12,"y":5,"z":13,"name":"Rock_Stone_Cobble"},{"x":-12,"y":6,"z":13,"name":"Rock_Stone_Brick_Smooth"},{"x":-12,"y":0,"z":14,"name":"Soil_Dirt"},{"x":-12,"y":1,"z":14,"name":"Soil_Dirt"},{"x":-12,"y":2,"z":14,"name":"Soil_Dirt"},{"x":-12,"y":3,"z":14,"name":"Soil_Dirt"},{"x":-12,"y":4,"z":14,"name":"Soil_Dirt"},{"x":-12,"y":5,"z":14,"name":"Rock_Stone_Cobble"},{"x":-12,"y":6,"z":14,"name":"Rock_Stone_Brick_Stairs","rotation":32},{"x":-12,"y":0,"z":15,"name":"Soil_Dirt"},{"x":-12,"y":1,"z":15,"name":"Soil_Dirt"},{"x":-12,"y":2,"z":15,"name":"Soil_Dirt"},{"x":-12,"y":3,"z":15,"name":"Soil_Dirt"},{"x":-12,"y":4,"z":15,"name":"Soil_Dirt"},{"x":-12,"y":5,"z":15,"name":"Rock_Stone_Brick_Smooth"},{"x":-11,"y":0,"z":-14,"name":"Soil_Dirt"},{"x":-11,"y":1,"z":-14,"name":"Soil_Dirt"},{"x":-11,"y":2,"z":-14,"name":"Soil_Dirt"},{"x":-11,"y":3,"z":-14,"name":"Soil_Dirt"},{"x":-11,"y":4,"z":-14,"name":"Soil_Dirt"},{"x":-11,"y":5,"z":-14,"name":"Rock_Stone_Brick_Smooth"},{"x":-11,"y":0,"z":-13,"name":"Soil_Dirt"},{"x":-11,"y":1,"z":-13,"name":"Soil_Dirt"},{"x":-11,"y":2,"z":-13,"name":"Soil_Dirt"},{"x":-11,"y":3,"z":-13,"name":"Soil_Dirt"},{"x":-11,"y":4,"z":-13,"name":"Soil_Dirt"},{"x":-11,"y":5,"z":-13,"name":"Rock_Stone_Cobble"},{"x":-11,"y":6,"z":-13,"name":"Rock_Stone_Brick_Stairs","rotation":34},{"x":-11,"y":0,"z":-12,"name":"Soil_Dirt"},{"x":-11,"y":1,"z":-12,"name":"Soil_Dirt"},{"x":-11,"y":2,"z":-12,"name":"Soil_Dirt"},{"x":-11,"y":3,"z":-12,"name":"Soil_Dirt"},{"x":-11,"y":4,"z":-12,"name":"Soil_Dirt"},{"x":-11,"y":5,"z":-12,"name":"Rock_Stone_Cobble"},{"x":-11,"y":6,"z":-12,"name":"Rock_Stone_Brick_Smooth"},{"x":-11,"y":0,"z":-11,"name":"Soil_Dirt"},{"x":-11,"y":1,"z":-11,"name":"Soil_Dirt"},{"x":-11,"y":2,"z":-11,"name":"Soil_Dirt"},{"x":-11,"y":3,"z":-11,"name":"Soil_Dirt"},{"x":-11,"y":4,"z":-11,"name":"Soil_Dirt"},{"x":-11,"y":5,"z":-11,"name":"Rock_Stone_Cobble"},{"x":-11,"y":6,"z":-11,"name":"Rock_Stone_Brick_Smooth"},{"x":-11,"y":0,"z":-10,"name":"Soil_Dirt"},{"x":-11,"y":1,"z":-10,"name":"Soil_Dirt"},{"x":-11,"y":2,"z":-10,"name":"Soil_Dirt"},{"x":-11,"y":3,"z":-10,"name":"Soil_Dirt"},{"x":-11,"y":4,"z":-10,"name":"Soil_Dirt"},{"x":-11,"y":5,"z":-10,"name":"Rock_Stone_Cobble"},{"x":-11,"y":6,"z":-10,"name":"Rock_Stone_Brick_Stairs","rotation":32},{"x":-11,"y":0,"z":-9,"name":"Soil_Dirt"},{"x":-11,"y":1,"z":-9,"name":"Soil_Dirt"},{"x":-11,"y":2,"z":-9,"name":"Soil_Dirt"},{"x":-11,"y":3,"z":-9,"name":"Soil_Dirt"},{"x":-11,"y":4,"z":-9,"name":"Soil_Dirt"},{"x":-11,"y":5,"z":-9,"name":"Rock_Stone_Cobble_Mossy"},{"x":-11,"y":0,"z":-8,"name":"Soil_Dirt"},{"x":-11,"y":1,"z":-8,"name":"Soil_Dirt"},{"x":-11,"y":2,"z":-8,"name":"Soil_Dirt"},{"x":-11,"y":3,"z":-8,"name":"Soil_Dirt"},{"x":-11,"y":4,"z":-8,"name":"Soil_Dirt"},{"x":-11,"y":5,"z":-8,"name":"Rock_Stone_Cobble"},{"x":-11,"y":0,"z":-7,"name":"Soil_Dirt"},{"x":-11,"y":1,"z":-7,"name":"Soil_Dirt"},{"x":-11,"y":2,"z":-7,"name":"Soil_Dirt"},{"x":-11,"y":3,"z":-7,"name":"Soil_Dirt"},{"x":-11,"y":4,"z":-7,"name":"Soil_Dirt"},{"x":-11,"y":5,"z":-7,"name":"Rock_Stone_Cobble_Mossy"},{"x":-11,"y":0,"z":-6,"name":"Soil_Dirt"},{"x":-11,"y":1,"z":-6,"name":"Soil_Dirt"},{"x":-11,"y":2,"z":-6,"name":"Soil_Dirt"},{"x":-11,"y":3,"z":-6,"name":"Soil_Dirt"},{"x":-11,"y":4,"z":-6,"name":"Soil_Dirt"},{"x":-11,"y":5,"z":-6,"name":"Rock_Stone_Cobble"},{"x":-11,"y":0,"z":-5,"name":"Soil_Dirt"},{"x":-11,"y":1,"z":-5,"name":"Soil_Dirt"},{"x":-11,"y":2,"z":-5,"name":"Soil_Dirt"},{"x":-11,"y":3,"z":-5,"name":"Soil_Dirt"},{"x":-11,"y":4,"z":-5,"name":"Soil_Dirt"},{"x":-11,"y":5,"z":-5,"name":"Rock_Stone_Cobble_Mossy"},{"x":-11,"y":0,"z":-4,"name":"Soil_Dirt"},{"x":-11,"y":1,"z":-4,"name":"Soil_Dirt"},{"x":-11,"y":2,"z":-4,"name":"Soil_Dirt"},{"x":-11,"y":3,"z":-4,"name":"Soil_Dirt"},{"x":-11,"y":4,"z":-4,"name":"Soil_Dirt"},{"x":-11,"y":5,"z":-4,"name":"Rock_Stone_Cobble"},{"x":-11,"y":0,"z":-3,"name":"Soil_Dirt"},{"x":-11,"y":1,"z":-3,"name":"Soil_Dirt"},{"x":-11,"y":2,"z":-3,"name":"Soil_Dirt"},{"x":-11,"y":3,"z":-3,"name":"Soil_Dirt"},{"x":-11,"y":4,"z":-3,"name":"Soil_Dirt"},{"x":-11,"y":5,"z":-3,"name":"Rock_Stone_Cobble"},{"x":-11,"y":0,"z":-2,"name":"Soil_Dirt"},{"x":-11,"y":1,"z":-2,"name":"Soil_Dirt"},{"x":-11,"y":2,"z":-2,"name":"Soil_Dirt"},{"x":-11,"y":3,"z":-2,"name":"Soil_Dirt"},{"x":-11,"y":4,"z":-2,"name":"Soil_Dirt"},{"x":-11,"y":5,"z":-2,"name":"Rock_Stone_Cobble"},{"x":-11,"y":0,"z":-1,"name":"Soil_Dirt"},{"x":-11,"y":1,"z":-1,"name":"Soil_Dirt"},{"x":-11,"y":2,"z":-1,"name":"Soil_Dirt"},{"x":-11,"y":3,"z":-1,"name":"Soil_Dirt"},{"x":-11,"y":4,"z":-1,"name":"Soil_Dirt"},{"x":-11,"y":5,"z":-1,"name":"Rock_Stone_Cobble"},{"x":-11,"y":0,"z":0,"name":"Soil_Dirt"},{"x":-11,"y":1,"z":0,"name":"Soil_Dirt"},{"x":-11,"y":2,"z":0,"name":"Soil_Dirt"},{"x":-11,"y":3,"z":0,"name":"Soil_Dirt"},{"x":-11,"y":4,"z":0,"name":"Soil_Dirt"},{"x":-11,"y":5,"z":0,"name":"Rock_Stone_Cobble_Mossy"},{"x":-11,"y":0,"z":1,"name":"Soil_Dirt"},{"x":-11,"y":1,"z":1,"name":"Soil_Dirt"},{"x":-11,"y":2,"z":1,"name":"Soil_Dirt"},{"x":-11,"y":3,"z":1,"name":"Soil_Dirt"},{"x":-11,"y":4,"z":1,"name":"Soil_Dirt"},{"x":-11,"y":5,"z":1,"name":"Rock_Stone_Cobble"},{"x":-11,"y":0,"z":2,"name":"Soil_Dirt"},{"x":-11,"y":1,"z":2,"name":"Soil_Dirt"},{"x":-11,"y":2,"z":2,"name":"Soil_Dirt"},{"x":-11,"y":3,"z":2,"name":"Soil_Dirt"},{"x":-11,"y":4,"z":2,"name":"Soil_Dirt"},{"x":-11,"y":5,"z":2,"name":"Rock_Stone_Cobble"},{"x":-11,"y":0,"z":3,"name":"Soil_Dirt"},{"x":-11,"y":1,"z":3,"name":"Soil_Dirt"},{"x":-11,"y":2,"z":3,"name":"Soil_Dirt"},{"x":-11,"y":3,"z":3,"name":"Soil_Dirt"},{"x":-11,"y":4,"z":3,"name":"Soil_Dirt"},{"x":-11,"y":5,"z":3,"name":"Rock_Stone_Cobble_Mossy"},{"x":-11,"y":0,"z":4,"name":"Soil_Dirt"},{"x":-11,"y":1,"z":4,"name":"Soil_Dirt"},{"x":-11,"y":2,"z":4,"name":"Soil_Dirt"},{"x":-11,"y":3,"z":4,"name":"Soil_Dirt"},{"x":-11,"y":4,"z":4,"name":"Soil_Dirt"},{"x":-11,"y":5,"z":4,"name":"Rock_Stone_Cobble"},{"x":-11,"y":0,"z":5,"name":"Soil_Dirt"},{"x":-11,"y":1,"z":5,"name":"Soil_Dirt"},{"x":-11,"y":2,"z":5,"name":"Soil_Dirt"},{"x":-11,"y":3,"z":5,"name":"Soil_Dirt"},{"x":-11,"y":4,"z":5,"name":"Soil_Dirt"},{"x":-11,"y":5,"z":5,"name":"Rock_Stone_Cobble"},{"x":-11,"y":0,"z":6,"name":"Soil_Dirt"},{"x":-11,"y":1,"z":6,"name":"Soil_Dirt"},{"x":-11,"y":2,"z":6,"name":"Soil_Dirt"},{"x":-11,"y":3,"z":6,"name":"Soil_Dirt"},{"x":-11,"y":4,"z":6,"name":"Soil_Dirt"},{"x":-11,"y":5,"z":6,"name":"Rock_Stone_Cobble"},{"x":-11,"y":0,"z":7,"name":"Soil_Dirt"},{"x":-11,"y":1,"z":7,"name":"Soil_Dirt"},{"x":-11,"y":2,"z":7,"name":"Soil_Dirt"},{"x":-11,"y":3,"z":7,"name":"Soil_Dirt"},{"x":-11,"y":4,"z":7,"name":"Soil_Dirt"},{"x":-11,"y":5,"z":7,"name":"Rock_Stone_Cobble"},{"x":-11,"y":0,"z":8,"name":"Soil_Dirt"},{"x":-11,"y":1,"z":8,"name":"Soil_Dirt"},{"x":-11,"y":2,"z":8,"name":"Soil_Dirt"},{"x":-11,"y":3,"z":8,"name":"Soil_Dirt"},{"x":-11,"y":4,"z":8,"name":"Soil_Dirt"},{"x":-11,"y":5,"z":8,"name":"Rock_Stone_Cobble"},{"x":-11,"y":0,"z":9,"name":"Soil_Dirt"},{"x":-11,"y":1,"z":9,"name":"Soil_Dirt"},{"x":-11,"y":2,"z":9,"name":"Soil_Dirt"},{"x":-11,"y":3,"z":9,"name":"Soil_Dirt"},{"x":-11,"y":4,"z":9,"name":"Soil_Dirt"},{"x":-11,"y":5,"z":9,"name":"Rock_Stone_Cobble"},{"x":-11,"y":0,"z":10,"name":"Soil_Dirt"},{"x":-11,"y":1,"z":10,"name":"Soil_Dirt"},{"x":-11,"y":2,"z":10,"name":"Soil_Dirt"},{"x":-11,"y":3,"z":10,"name":"Soil_Dirt"},{"x":-11,"y":4,"z":10,"name":"Soil_Dirt"},{"x":-11,"y":5,"z":10,"name":"Rock_Stone_Cobble"},{"x":-11,"y":0,"z":11,"name":"Soil_Dirt"},{"x":-11,"y":1,"z":11,"name":"Soil_Dirt"},{"x":-11,"y":2,"z":11,"name":"Soil_Dirt"},{"x":-11,"y":3,"z":11,"name":"Soil_Dirt"},{"x":-11,"y":4,"z":11,"name":"Soil_Dirt"},{"x":-11,"y":5,"z":11,"name":"Rock_Stone_Cobble_Mossy"},{"x":-11,"y":6,"z":11,"name":"Rock_Stone_Brick_Stairs","rotation":34},{"x":-11,"y":0,"z":12,"name":"Soil_Dirt"},{"x":-11,"y":1,"z":12,"name":"Soil_Dirt"},{"x":-11,"y":2,"z":12,"name":"Soil_Dirt"},{"x":-11,"y":3,"z":12,"name":"Soil_Dirt"},{"x":-11,"y":4,"z":12,"name":"Soil_Dirt"},{"x":-11,"y":5,"z":12,"name":"Rock_Stone_Cobble"},{"x":-11,"y":6,"z":12,"name":"Rock_Stone_Brick_Smooth"},{"x":-11,"y":0,"z":13,"name":"Soil_Dirt"},{"x":-11,"y":1,"z":13,"name":"Soil_Dirt"},{"x":-11,"y":2,"z":13,"name":"Soil_Dirt"},{"x":-11,"y":3,"z":13,"name":"Soil_Dirt"},{"x":-11,"y":4,"z":13,"name":"Soil_Dirt"},{"x":-11,"y":5,"z":13,"name":"Rock_Stone_Cobble_Mossy"},{"x":-11,"y":6,"z":13,"name":"Rock_Stone_Brick_Smooth"},{"x":-11,"y":0,"z":14,"name":"Soil_Dirt"},{"x":-11,"y":1,"z":14,"name":"Soil_Dirt"},{"x":-11,"y":2,"z":14,"name":"Soil_Dirt"},{"x":-11,"y":3,"z":14,"name":"Soil_Dirt"},{"x":-11,"y":4,"z":14,"name":"Soil_Dirt"},{"x":-11,"y":5,"z":14,"name":"Rock_Stone_Cobble"},{"x":-11,"y":6,"z":14,"name":"Rock_Stone_Brick_Stairs","rotation":32},{"x":-11,"y":0,"z":15,"name":"Soil_Dirt"},{"x":-11,"y":1,"z":15,"name":"Soil_Dirt"},{"x":-11,"y":2,"z":15,"name":"Soil_Dirt"},{"x":-11,"y":3,"z":15,"name":"Soil_Dirt"},{"x":-11,"y":4,"z":15,"name":"Soil_Dirt"},{"x":-11,"y":5,"z":15,"name":"Rock_Stone_Brick_Smooth"},{"x":-10,"y":0,"z":-14,"name":"Soil_Dirt"},{"x":-10,"y":1,"z":-14,"name":"Soil_Dirt"},{"x":-10,"y":2,"z":-14,"name":"Soil_Dirt"},{"x":-10,"y":3,"z":-14,"name":"Soil_Dirt"},{"x":-10,"y":4,"z":-14,"name":"Soil_Dirt"},{"x":-10,"y":5,"z":-14,"name":"Rock_Stone_Brick_Smooth"},{"x":-10,"y":0,"z":-13,"name":"Soil_Dirt"},{"x":-10,"y":1,"z":-13,"name":"Soil_Dirt"},{"x":-10,"y":2,"z":-13,"name":"Soil_Dirt"},{"x":-10,"y":3,"z":-13,"name":"Soil_Dirt"},{"x":-10,"y":4,"z":-13,"name":"Soil_Dirt"},{"x":-10,"y":5,"z":-13,"name":"Rock_Stone_Cobble"},{"x":-10,"y":6,"z":-13,"name":"Rock_Stone_Brick_Decorative","rotation":2},{"x":-10,"y":0,"z":-12,"name":"Soil_Dirt"},{"x":-10,"y":1,"z":-12,"name":"Soil_Dirt"},{"x":-10,"y":2,"z":-12,"name":"Soil_Dirt"},{"x":-10,"y":3,"z":-12,"name":"Soil_Dirt"},{"x":-10,"y":4,"z":-12,"name":"Soil_Dirt"},{"x":-10,"y":5,"z":-12,"name":"Rock_Stone_Cobble"},{"x":-10,"y":6,"z":-12,"name":"Rock_Stone_Brick_Stairs","rotation":33},{"x":-10,"y":0,"z":-11,"name":"Soil_Dirt"},{"x":-10,"y":1,"z":-11,"name":"Soil_Dirt"},{"x":-10,"y":2,"z":-11,"name":"Soil_Dirt"},{"x":-10,"y":3,"z":-11,"name":"Soil_Dirt"},{"x":-10,"y":4,"z":-11,"name":"Soil_Dirt"},{"x":-10,"y":5,"z":-11,"name":"Rock_Stone_Cobble"},{"x":-10,"y":6,"z":-11,"name":"Rock_Stone_Brick_Stairs","rotation":33},{"x":-10,"y":0,"z":-10,"name":"Soil_Dirt"},{"x":-10,"y":1,"z":-10,"name":"Soil_Dirt"},{"x":-10,"y":2,"z":-10,"name":"Soil_Dirt"},{"x":-10,"y":3,"z":-10,"name":"Soil_Dirt"},{"x":-10,"y":4,"z":-10,"name":"Soil_Dirt"},{"x":-10,"y":5,"z":-10,"name":"Rock_Stone_Cobble_Mossy"},{"x":-10,"y":6,"z":-10,"name":"Rock_Stone_Brick_Decorative","rotation":2},{"x":-10,"y":0,"z":-9,"name":"Soil_Dirt"},{"x":-10,"y":1,"z":-9,"name":"Soil_Dirt"},{"x":-10,"y":2,"z":-9,"name":"Soil_Dirt"},{"x":-10,"y":3,"z":-9,"name":"Soil_Dirt"},{"x":-10,"y":4,"z":-9,"name":"Soil_Dirt"},{"x":-10,"y":5,"z":-9,"name":"Rock_Stone_Cobble"},{"x":-10,"y":0,"z":-8,"name":"Soil_Dirt"},{"x":-10,"y":1,"z":-8,"name":"Soil_Dirt"},{"x":-10,"y":2,"z":-8,"name":"Soil_Dirt"},{"x":-10,"y":3,"z":-8,"name":"Soil_Dirt"},{"x":-10,"y":4,"z":-8,"name":"Soil_Dirt"},{"x":-10,"y":5,"z":-8,"name":"Rock_Stone_Cobble"},{"x":-10,"y":0,"z":-7,"name":"Soil_Dirt"},{"x":-10,"y":1,"z":-7,"name":"Soil_Dirt"},{"x":-10,"y":2,"z":-7,"name":"Soil_Dirt"},{"x":-10,"y":3,"z":-7,"name":"Soil_Dirt"},{"x":-10,"y":4,"z":-7,"name":"Soil_Dirt"},{"x":-10,"y":5,"z":-7,"name":"Rock_Stone_Cobble"},{"x":-10,"y":0,"z":-6,"name":"Soil_Dirt"},{"x":-10,"y":1,"z":-6,"name":"Soil_Dirt"},{"x":-10,"y":2,"z":-6,"name":"Soil_Dirt"},{"x":-10,"y":3,"z":-6,"name":"Soil_Dirt"},{"x":-10,"y":4,"z":-6,"name":"Soil_Dirt"},{"x":-10,"y":5,"z":-6,"name":"Rock_Stone_Cobble"},{"x":-10,"y":0,"z":-5,"name":"Soil_Dirt"},{"x":-10,"y":1,"z":-5,"name":"Soil_Dirt"},{"x":-10,"y":2,"z":-5,"name":"Soil_Dirt"},{"x":-10,"y":3,"z":-5,"name":"Soil_Dirt"},{"x":-10,"y":4,"z":-5,"name":"Soil_Dirt"},{"x":-10,"y":5,"z":-5,"name":"Rock_Stone_Cobble"},{"x":-10,"y":0,"z":-4,"name":"Soil_Dirt"},{"x":-10,"y":1,"z":-4,"name":"Soil_Dirt"},{"x":-10,"y":2,"z":-4,"name":"Soil_Dirt"},{"x":-10,"y":3,"z":-4,"name":"Soil_Dirt"},{"x":-10,"y":4,"z":-4,"name":"Soil_Dirt"},{"x":-10,"y":5,"z":-4,"name":"Rock_Stone_Cobble"},{"x":-10,"y":0,"z":-3,"name":"Soil_Dirt"},{"x":-10,"y":1,"z":-3,"name":"Soil_Dirt"},{"x":-10,"y":2,"z":-3,"name":"Soil_Dirt"},{"x":-10,"y":3,"z":-3,"name":"Soil_Dirt"},{"x":-10,"y":4,"z":-3,"name":"Soil_Dirt"},{"x":-10,"y":5,"z":-3,"name":"Rock_Stone_Cobble"},{"x":-10,"y":0,"z":-2,"name":"Soil_Dirt"},{"x":-10,"y":1,"z":-2,"name":"Soil_Dirt"},{"x":-10,"y":2,"z":-2,"name":"Soil_Dirt"},{"x":-10,"y":3,"z":-2,"name":"Soil_Dirt"},{"x":-10,"y":4,"z":-2,"name":"Soil_Dirt"},{"x":-10,"y":5,"z":-2,"name":"Rock_Stone_Cobble"},{"x":-10,"y":0,"z":-1,"name":"Soil_Dirt"},{"x":-10,"y":1,"z":-1,"name":"Soil_Dirt"},{"x":-10,"y":2,"z":-1,"name":"Soil_Dirt"},{"x":-10,"y":3,"z":-1,"name":"Soil_Dirt"},{"x":-10,"y":4,"z":-1,"name":"Soil_Dirt"},{"x":-10,"y":5,"z":-1,"name":"Rock_Stone_Cobble"},{"x":-10,"y":0,"z":0,"name":"Soil_Dirt"},{"x":-10,"y":1,"z":0,"name":"Soil_Dirt"},{"x":-10,"y":2,"z":0,"name":"Soil_Dirt"},{"x":-10,"y":3,"z":0,"name":"Soil_Dirt"},{"x":-10,"y":4,"z":0,"name":"Soil_Dirt"},{"x":-10,"y":5,"z":0,"name":"Rock_Stone_Cobble_Mossy"},{"x":-10,"y":0,"z":1,"name":"Soil_Dirt"},{"x":-10,"y":1,"z":1,"name":"Soil_Dirt"},{"x":-10,"y":2,"z":1,"name":"Soil_Dirt"},{"x":-10,"y":3,"z":1,"name":"Soil_Dirt"},{"x":-10,"y":4,"z":1,"name":"Soil_Dirt"},{"x":-10,"y":5,"z":1,"name":"Rock_Stone_Cobble_Mossy"},{"x":-10,"y":0,"z":2,"name":"Soil_Dirt"},{"x":-10,"y":1,"z":2,"name":"Soil_Dirt"},{"x":-10,"y":2,"z":2,"name":"Soil_Dirt"},{"x":-10,"y":3,"z":2,"name":"Soil_Dirt"},{"x":-10,"y":4,"z":2,"name":"Soil_Dirt"},{"x":-10,"y":5,"z":2,"name":"Rock_Stone_Cobble"},{"x":-10,"y":0,"z":3,"name":"Soil_Dirt"},{"x":-10,"y":1,"z":3,"name":"Soil_Dirt"},{"x":-10,"y":2,"z":3,"name":"Soil_Dirt"},{"x":-10,"y":3,"z":3,"name":"Soil_Dirt"},{"x":-10,"y":4,"z":3,"name":"Soil_Dirt"},{"x":-10,"y":5,"z":3,"name":"Rock_Stone_Cobble"},{"x":-10,"y":0,"z":4,"name":"Soil_Dirt"},{"x":-10,"y":1,"z":4,"name":"Soil_Dirt"},{"x":-10,"y":2,"z":4,"name":"Soil_Dirt"},{"x":-10,"y":3,"z":4,"name":"Soil_Dirt"},{"x":-10,"y":4,"z":4,"name":"Soil_Dirt"},{"x":-10,"y":5,"z":4,"name":"Rock_Stone_Cobble"},{"x":-10,"y":0,"z":5,"name":"Soil_Dirt"},{"x":-10,"y":1,"z":5,"name":"Soil_Dirt"},{"x":-10,"y":2,"z":5,"name":"Soil_Dirt"},{"x":-10,"y":3,"z":5,"name":"Soil_Dirt"},{"x":-10,"y":4,"z":5,"name":"Soil_Dirt"},{"x":-10,"y":5,"z":5,"name":"Rock_Stone_Cobble_Mossy"},{"x":-10,"y":0,"z":6,"name":"Soil_Dirt"},{"x":-10,"y":1,"z":6,"name":"Soil_Dirt"},{"x":-10,"y":2,"z":6,"name":"Soil_Dirt"},{"x":-10,"y":3,"z":6,"name":"Soil_Dirt"},{"x":-10,"y":4,"z":6,"name":"Soil_Dirt"},{"x":-10,"y":5,"z":6,"name":"Rock_Stone_Cobble"},{"x":-10,"y":0,"z":7,"name":"Soil_Dirt"},{"x":-10,"y":1,"z":7,"name":"Soil_Dirt"},{"x":-10,"y":2,"z":7,"name":"Soil_Dirt"},{"x":-10,"y":3,"z":7,"name":"Soil_Dirt"},{"x":-10,"y":4,"z":7,"name":"Soil_Dirt"},{"x":-10,"y":5,"z":7,"name":"Rock_Stone_Cobble"},{"x":-10,"y":0,"z":8,"name":"Soil_Dirt"},{"x":-10,"y":1,"z":8,"name":"Soil_Dirt"},{"x":-10,"y":2,"z":8,"name":"Soil_Dirt"},{"x":-10,"y":3,"z":8,"name":"Soil_Dirt"},{"x":-10,"y":4,"z":8,"name":"Soil_Dirt"},{"x":-10,"y":5,"z":8,"name":"Rock_Stone_Cobble","support":15},{"x":-10,"y":0,"z":9,"name":"Soil_Dirt"},{"x":-10,"y":1,"z":9,"name":"Soil_Dirt"},{"x":-10,"y":2,"z":9,"name":"Soil_Dirt"},{"x":-10,"y":3,"z":9,"name":"Soil_Dirt"},{"x":-10,"y":4,"z":9,"name":"Soil_Dirt"},{"x":-10,"y":5,"z":9,"name":"Rock_Stone_Cobble","support":15},{"x":-10,"y":0,"z":10,"name":"Soil_Dirt"},{"x":-10,"y":1,"z":10,"name":"Soil_Dirt"},{"x":-10,"y":2,"z":10,"name":"Soil_Dirt"},{"x":-10,"y":3,"z":10,"name":"Soil_Dirt"},{"x":-10,"y":4,"z":10,"name":"Soil_Dirt"},{"x":-10,"y":5,"z":10,"name":"Rock_Stone_Cobble"},{"x":-10,"y":0,"z":11,"name":"Soil_Dirt"},{"x":-10,"y":1,"z":11,"name":"Soil_Dirt"},{"x":-10,"y":2,"z":11,"name":"Soil_Dirt"},{"x":-10,"y":3,"z":11,"name":"Soil_Dirt"},{"x":-10,"y":4,"z":11,"name":"Soil_Dirt"},{"x":-10,"y":5,"z":11,"name":"Rock_Stone_Cobble_Mossy"},{"x":-10,"y":6,"z":11,"name":"Rock_Stone_Brick_Decorative","rotation":3},{"x":-10,"y":0,"z":12,"name":"Soil_Dirt"},{"x":-10,"y":1,"z":12,"name":"Soil_Dirt"},{"x":-10,"y":2,"z":12,"name":"Soil_Dirt"},{"x":-10,"y":3,"z":12,"name":"Soil_Dirt"},{"x":-10,"y":4,"z":12,"name":"Soil_Dirt"},{"x":-10,"y":5,"z":12,"name":"Rock_Stone_Cobble"},{"x":-10,"y":6,"z":12,"name":"Rock_Stone_Brick_Stairs","rotation":33},{"x":-10,"y":0,"z":13,"name":"Soil_Dirt"},{"x":-10,"y":1,"z":13,"name":"Soil_Dirt"},{"x":-10,"y":2,"z":13,"name":"Soil_Dirt"},{"x":-10,"y":3,"z":13,"name":"Soil_Dirt"},{"x":-10,"y":4,"z":13,"name":"Soil_Dirt"},{"x":-10,"y":5,"z":13,"name":"Rock_Stone_Cobble_Mossy"},{"x":-10,"y":6,"z":13,"name":"Rock_Stone_Brick_Stairs","rotation":33},{"x":-10,"y":0,"z":14,"name":"Soil_Dirt"},{"x":-10,"y":1,"z":14,"name":"Soil_Dirt"},{"x":-10,"y":2,"z":14,"name":"Soil_Dirt"},{"x":-10,"y":3,"z":14,"name":"Soil_Dirt"},{"x":-10,"y":4,"z":14,"name":"Soil_Dirt"},{"x":-10,"y":5,"z":14,"name":"Rock_Stone_Cobble_Mossy"},{"x":-10,"y":6,"z":14,"name":"Rock_Stone_Brick_Decorative","rotation":3},{"x":-10,"y":0,"z":15,"name":"Soil_Dirt"},{"x":-10,"y":1,"z":15,"name":"Soil_Dirt"},{"x":-10,"y":2,"z":15,"name":"Soil_Dirt"},{"x":-10,"y":3,"z":15,"name":"Soil_Dirt"},{"x":-10,"y":4,"z":15,"name":"Soil_Dirt"},{"x":-10,"y":5,"z":15,"name":"Rock_Stone_Brick_Smooth"},{"x":-9,"y":0,"z":-14,"name":"Soil_Dirt"},{"x":-9,"y":1,"z":-14,"name":"Soil_Dirt"},{"x":-9,"y":2,"z":-14,"name":"Soil_Dirt"},{"x":-9,"y":3,"z":-14,"name":"Soil_Dirt"},{"x":-9,"y":4,"z":-14,"name":"Soil_Dirt"},{"x":-9,"y":5,"z":-14,"name":"Rock_Stone_Brick_Smooth"},{"x":-9,"y":0,"z":-13,"name":"Soil_Dirt"},{"x":-9,"y":1,"z":-13,"name":"Soil_Dirt"},{"x":-9,"y":2,"z":-13,"name":"Soil_Dirt"},{"x":-9,"y":3,"z":-13,"name":"Soil_Dirt"},{"x":-9,"y":4,"z":-13,"name":"Soil_Dirt"},{"x":-9,"y":5,"z":-13,"name":"Rock_Stone_Cobble"},{"x":-9,"y":0,"z":-12,"name":"Soil_Dirt"},{"x":-9,"y":1,"z":-12,"name":"Soil_Dirt"},{"x":-9,"y":2,"z":-12,"name":"Soil_Dirt"},{"x":-9,"y":3,"z":-12,"name":"Soil_Dirt"},{"x":-9,"y":4,"z":-12,"name":"Soil_Dirt"},{"x":-9,"y":5,"z":-12,"name":"Rock_Stone_Cobble"},{"x":-9,"y":0,"z":-11,"name":"Soil_Dirt"},{"x":-9,"y":1,"z":-11,"name":"Soil_Dirt"},{"x":-9,"y":2,"z":-11,"name":"Soil_Dirt"},{"x":-9,"y":3,"z":-11,"name":"Soil_Dirt"},{"x":-9,"y":4,"z":-11,"name":"Soil_Dirt"},{"x":-9,"y":5,"z":-11,"name":"Rock_Stone_Cobble"},{"x":-9,"y":0,"z":-10,"name":"Soil_Dirt"},{"x":-9,"y":1,"z":-10,"name":"Soil_Dirt"},{"x":-9,"y":2,"z":-10,"name":"Soil_Dirt"},{"x":-9,"y":3,"z":-10,"name":"Soil_Dirt"},{"x":-9,"y":4,"z":-10,"name":"Soil_Dirt"},{"x":-9,"y":5,"z":-10,"name":"Rock_Stone_Cobble"},{"x":-9,"y":0,"z":-9,"name":"Soil_Dirt"},{"x":-9,"y":1,"z":-9,"name":"Soil_Dirt"},{"x":-9,"y":2,"z":-9,"name":"Soil_Dirt"},{"x":-9,"y":3,"z":-9,"name":"Soil_Dirt"},{"x":-9,"y":4,"z":-9,"name":"Soil_Dirt"},{"x":-9,"y":5,"z":-9,"name":"Rock_Stone_Cobble"},{"x":-9,"y":0,"z":-8,"name":"Soil_Dirt"},{"x":-9,"y":1,"z":-8,"name":"Soil_Dirt"},{"x":-9,"y":2,"z":-8,"name":"Soil_Dirt"},{"x":-9,"y":3,"z":-8,"name":"Soil_Dirt"},{"x":-9,"y":4,"z":-8,"name":"Soil_Dirt"},{"x":-9,"y":5,"z":-8,"name":"Rock_Stone_Cobble"},{"x":-9,"y":0,"z":-7,"name":"Soil_Dirt"},{"x":-9,"y":1,"z":-7,"name":"Soil_Dirt"},{"x":-9,"y":2,"z":-7,"name":"Soil_Dirt"},{"x":-9,"y":3,"z":-7,"name":"Soil_Dirt"},{"x":-9,"y":4,"z":-7,"name":"Soil_Dirt"},{"x":-9,"y":5,"z":-7,"name":"Rock_Stone_Cobble"},{"x":-9,"y":0,"z":-6,"name":"Soil_Dirt"},{"x":-9,"y":1,"z":-6,"name":"Soil_Dirt"},{"x":-9,"y":2,"z":-6,"name":"Soil_Dirt"},{"x":-9,"y":3,"z":-6,"name":"Soil_Dirt"},{"x":-9,"y":4,"z":-6,"name":"Soil_Dirt"},{"x":-9,"y":5,"z":-6,"name":"Rock_Stone_Cobble"},{"x":-9,"y":0,"z":-5,"name":"Soil_Dirt"},{"x":-9,"y":1,"z":-5,"name":"Soil_Dirt"},{"x":-9,"y":2,"z":-5,"name":"Soil_Dirt"},{"x":-9,"y":3,"z":-5,"name":"Soil_Dirt"},{"x":-9,"y":4,"z":-5,"name":"Soil_Dirt"},{"x":-9,"y":5,"z":-5,"name":"Rock_Stone_Cobble"},{"x":-9,"y":0,"z":-4,"name":"Soil_Dirt"},{"x":-9,"y":1,"z":-4,"name":"Soil_Dirt"},{"x":-9,"y":2,"z":-4,"name":"Soil_Dirt"},{"x":-9,"y":3,"z":-4,"name":"Soil_Dirt"},{"x":-9,"y":4,"z":-4,"name":"Soil_Dirt"},{"x":-9,"y":5,"z":-4,"name":"Rock_Stone_Cobble"},{"x":-9,"y":0,"z":-3,"name":"Soil_Dirt"},{"x":-9,"y":1,"z":-3,"name":"Soil_Dirt"},{"x":-9,"y":2,"z":-3,"name":"Soil_Dirt"},{"x":-9,"y":3,"z":-3,"name":"Soil_Dirt"},{"x":-9,"y":4,"z":-3,"name":"Soil_Dirt"},{"x":-9,"y":5,"z":-3,"name":"Rock_Stone_Cobble"},{"x":-9,"y":0,"z":-2,"name":"Soil_Dirt"},{"x":-9,"y":1,"z":-2,"name":"Soil_Dirt"},{"x":-9,"y":2,"z":-2,"name":"Soil_Dirt"},{"x":-9,"y":3,"z":-2,"name":"Soil_Dirt"},{"x":-9,"y":4,"z":-2,"name":"Soil_Dirt"},{"x":-9,"y":5,"z":-2,"name":"Rock_Stone_Brick_Decorative","support":15},{"x":-9,"y":0,"z":-1,"name":"Soil_Dirt"},{"x":-9,"y":1,"z":-1,"name":"Soil_Dirt"},{"x":-9,"y":2,"z":-1,"name":"Soil_Dirt"},{"x":-9,"y":3,"z":-1,"name":"Soil_Dirt"},{"x":-9,"y":4,"z":-1,"name":"Soil_Dirt"},{"x":-9,"y":5,"z":-1,"name":"Rock_Stone_Brick_Decorative","support":15},{"x":-9,"y":0,"z":0,"name":"Soil_Dirt"},{"x":-9,"y":1,"z":0,"name":"Soil_Dirt"},{"x":-9,"y":2,"z":0,"name":"Soil_Dirt"},{"x":-9,"y":3,"z":0,"name":"Soil_Dirt"},{"x":-9,"y":4,"z":0,"name":"Soil_Dirt"},{"x":-9,"y":5,"z":0,"name":"Rock_Stone_Brick_Decorative","support":15},{"x":-9,"y":0,"z":1,"name":"Soil_Dirt"},{"x":-9,"y":1,"z":1,"name":"Soil_Dirt"},{"x":-9,"y":2,"z":1,"name":"Soil_Dirt"},{"x":-9,"y":3,"z":1,"name":"Soil_Dirt"},{"x":-9,"y":4,"z":1,"name":"Soil_Dirt"},{"x":-9,"y":5,"z":1,"name":"Rock_Stone_Brick_Decorative","support":15},{"x":-9,"y":0,"z":2,"name":"Soil_Dirt"},{"x":-9,"y":1,"z":2,"name":"Soil_Dirt"},{"x":-9,"y":2,"z":2,"name":"Soil_Dirt"},{"x":-9,"y":3,"z":2,"name":"Soil_Dirt"},{"x":-9,"y":4,"z":2,"name":"Soil_Dirt"},{"x":-9,"y":5,"z":2,"name":"Rock_Stone_Brick_Decorative","support":15},{"x":-9,"y":0,"z":3,"name":"Soil_Dirt"},{"x":-9,"y":1,"z":3,"name":"Soil_Dirt"},{"x":-9,"y":2,"z":3,"name":"Soil_Dirt"},{"x":-9,"y":3,"z":3,"name":"Soil_Dirt"},{"x":-9,"y":4,"z":3,"name":"Soil_Dirt"},{"x":-9,"y":5,"z":3,"name":"Rock_Stone_Brick_Decorative","support":15},{"x":-9,"y":0,"z":4,"name":"Soil_Dirt"},{"x":-9,"y":1,"z":4,"name":"Soil_Dirt"},{"x":-9,"y":2,"z":4,"name":"Soil_Dirt"},{"x":-9,"y":3,"z":4,"name":"Soil_Dirt"},{"x":-9,"y":4,"z":4,"name":"Soil_Dirt"},{"x":-9,"y":5,"z":4,"name":"Rock_Stone_Cobble"},{"x":-9,"y":0,"z":5,"name":"Soil_Dirt"},{"x":-9,"y":1,"z":5,"name":"Soil_Dirt"},{"x":-9,"y":2,"z":5,"name":"Soil_Dirt"},{"x":-9,"y":3,"z":5,"name":"Soil_Dirt"},{"x":-9,"y":4,"z":5,"name":"Soil_Dirt"},{"x":-9,"y":5,"z":5,"name":"Rock_Stone_Cobble"},{"x":-9,"y":0,"z":6,"name":"Soil_Dirt"},{"x":-9,"y":1,"z":6,"name":"Soil_Dirt"},{"x":-9,"y":2,"z":6,"name":"Soil_Dirt"},{"x":-9,"y":3,"z":6,"name":"Soil_Dirt"},{"x":-9,"y":4,"z":6,"name":"Soil_Dirt"},{"x":-9,"y":5,"z":6,"name":"Rock_Stone_Cobble"},{"x":-9,"y":0,"z":7,"name":"Soil_Dirt"},{"x":-9,"y":1,"z":7,"name":"Soil_Dirt"},{"x":-9,"y":2,"z":7,"name":"Soil_Dirt"},{"x":-9,"y":3,"z":7,"name":"Soil_Dirt"},{"x":-9,"y":4,"z":7,"name":"Soil_Dirt"},{"x":-9,"y":5,"z":7,"name":"Rock_Stone_Cobble"},{"x":-9,"y":0,"z":8,"name":"Soil_Dirt"},{"x":-9,"y":1,"z":8,"name":"Soil_Dirt"},{"x":-9,"y":2,"z":8,"name":"Soil_Dirt"},{"x":-9,"y":3,"z":8,"name":"Soil_Dirt"},{"x":-9,"y":4,"z":8,"name":"Soil_Dirt"},{"x":-9,"y":5,"z":8,"name":"Rock_Stone_Cobble"},{"x":-9,"y":0,"z":9,"name":"Soil_Dirt"},{"x":-9,"y":1,"z":9,"name":"Soil_Dirt"},{"x":-9,"y":2,"z":9,"name":"Soil_Dirt"},{"x":-9,"y":3,"z":9,"name":"Soil_Dirt"},{"x":-9,"y":4,"z":9,"name":"Soil_Dirt"},{"x":-9,"y":5,"z":9,"name":"Rock_Stone_Cobble"},{"x":-9,"y":0,"z":10,"name":"Soil_Dirt"},{"x":-9,"y":1,"z":10,"name":"Soil_Dirt"},{"x":-9,"y":2,"z":10,"name":"Soil_Dirt"},{"x":-9,"y":3,"z":10,"name":"Soil_Dirt"},{"x":-9,"y":4,"z":10,"name":"Soil_Dirt"},{"x":-9,"y":5,"z":10,"name":"Rock_Stone_Cobble"},{"x":-9,"y":0,"z":11,"name":"Soil_Dirt"},{"x":-9,"y":1,"z":11,"name":"Soil_Dirt"},{"x":-9,"y":2,"z":11,"name":"Soil_Dirt"},{"x":-9,"y":3,"z":11,"name":"Soil_Dirt"},{"x":-9,"y":4,"z":11,"name":"Soil_Dirt"},{"x":-9,"y":5,"z":11,"name":"Rock_Stone_Cobble"},{"x":-9,"y":0,"z":12,"name":"Soil_Dirt"},{"x":-9,"y":1,"z":12,"name":"Soil_Dirt"},{"x":-9,"y":2,"z":12,"name":"Soil_Dirt"},{"x":-9,"y":3,"z":12,"name":"Soil_Dirt"},{"x":-9,"y":4,"z":12,"name":"Soil_Dirt"},{"x":-9,"y":5,"z":12,"name":"Rock_Stone_Cobble"},{"x":-9,"y":0,"z":13,"name":"Soil_Dirt"},{"x":-9,"y":1,"z":13,"name":"Soil_Dirt"},{"x":-9,"y":2,"z":13,"name":"Soil_Dirt"},{"x":-9,"y":3,"z":13,"name":"Soil_Dirt"},{"x":-9,"y":4,"z":13,"name":"Soil_Dirt"},{"x":-9,"y":5,"z":13,"name":"Rock_Stone_Cobble"},{"x":-9,"y":0,"z":14,"name":"Soil_Dirt"},{"x":-9,"y":1,"z":14,"name":"Soil_Dirt"},{"x":-9,"y":2,"z":14,"name":"Soil_Dirt"},{"x":-9,"y":3,"z":14,"name":"Soil_Dirt"},{"x":-9,"y":4,"z":14,"name":"Soil_Dirt"},{"x":-9,"y":5,"z":14,"name":"Rock_Stone_Cobble"},{"x":-9,"y":0,"z":15,"name":"Soil_Dirt"},{"x":-9,"y":1,"z":15,"name":"Soil_Dirt"},{"x":-9,"y":2,"z":15,"name":"Soil_Dirt"},{"x":-9,"y":3,"z":15,"name":"Soil_Dirt"},{"x":-9,"y":4,"z":15,"name":"Soil_Dirt"},{"x":-9,"y":5,"z":15,"name":"Rock_Stone_Brick_Smooth"},{"x":-8,"y":0,"z":-14,"name":"Soil_Dirt"},{"x":-8,"y":1,"z":-14,"name":"Soil_Dirt"},{"x":-8,"y":2,"z":-14,"name":"Soil_Dirt"},{"x":-8,"y":3,"z":-14,"name":"Soil_Dirt"},{"x":-8,"y":4,"z":-14,"name":"Soil_Dirt"},{"x":-8,"y":5,"z":-14,"name":"Rock_Stone_Brick_Smooth"},{"x":-8,"y":0,"z":-13,"name":"Soil_Dirt"},{"x":-8,"y":1,"z":-13,"name":"Soil_Dirt"},{"x":-8,"y":2,"z":-13,"name":"Soil_Dirt"},{"x":-8,"y":3,"z":-13,"name":"Soil_Dirt"},{"x":-8,"y":4,"z":-13,"name":"Soil_Dirt"},{"x":-8,"y":5,"z":-13,"name":"Rock_Stone_Cobble"},{"x":-8,"y":0,"z":-12,"name":"Soil_Dirt"},{"x":-8,"y":1,"z":-12,"name":"Soil_Dirt"},{"x":-8,"y":2,"z":-12,"name":"Soil_Dirt"},{"x":-8,"y":3,"z":-12,"name":"Soil_Dirt"},{"x":-8,"y":4,"z":-12,"name":"Soil_Dirt"},{"x":-8,"y":5,"z":-12,"name":"Rock_Stone_Cobble"},{"x":-8,"y":0,"z":-11,"name":"Soil_Dirt"},{"x":-8,"y":1,"z":-11,"name":"Soil_Dirt"},{"x":-8,"y":2,"z":-11,"name":"Soil_Dirt"},{"x":-8,"y":3,"z":-11,"name":"Soil_Dirt"},{"x":-8,"y":4,"z":-11,"name":"Soil_Dirt"},{"x":-8,"y":5,"z":-11,"name":"Rock_Stone_Cobble_Mossy"},{"x":-8,"y":0,"z":-10,"name":"Soil_Dirt"},{"x":-8,"y":1,"z":-10,"name":"Soil_Dirt"},{"x":-8,"y":2,"z":-10,"name":"Soil_Dirt"},{"x":-8,"y":3,"z":-10,"name":"Soil_Dirt"},{"x":-8,"y":4,"z":-10,"name":"Soil_Dirt"},{"x":-8,"y":5,"z":-10,"name":"Rock_Stone_Cobble"},{"x":-8,"y":0,"z":-9,"name":"Soil_Dirt"},{"x":-8,"y":1,"z":-9,"name":"Soil_Dirt"},{"x":-8,"y":2,"z":-9,"name":"Soil_Dirt"},{"x":-8,"y":3,"z":-9,"name":"Soil_Dirt"},{"x":-8,"y":4,"z":-9,"name":"Soil_Dirt"},{"x":-8,"y":5,"z":-9,"name":"Rock_Stone_Cobble_Mossy"},{"x":-8,"y":0,"z":-8,"name":"Soil_Dirt"},{"x":-8,"y":1,"z":-8,"name":"Soil_Dirt"},{"x":-8,"y":2,"z":-8,"name":"Soil_Dirt"},{"x":-8,"y":3,"z":-8,"name":"Soil_Dirt"},{"x":-8,"y":4,"z":-8,"name":"Soil_Dirt"},{"x":-8,"y":5,"z":-8,"name":"Rock_Stone_Cobble"},{"x":-8,"y":0,"z":-7,"name":"Soil_Dirt"},{"x":-8,"y":1,"z":-7,"name":"Soil_Dirt"},{"x":-8,"y":2,"z":-7,"name":"Soil_Dirt"},{"x":-8,"y":3,"z":-7,"name":"Soil_Dirt"},{"x":-8,"y":4,"z":-7,"name":"Soil_Dirt"},{"x":-8,"y":5,"z":-7,"name":"Rock_Stone_Cobble"},{"x":-8,"y":0,"z":-6,"name":"Soil_Dirt"},{"x":-8,"y":1,"z":-6,"name":"Soil_Dirt"},{"x":-8,"y":2,"z":-6,"name":"Soil_Dirt"},{"x":-8,"y":3,"z":-6,"name":"Soil_Dirt"},{"x":-8,"y":4,"z":-6,"name":"Soil_Dirt"},{"x":-8,"y":5,"z":-6,"name":"Rock_Stone_Cobble"},{"x":-8,"y":0,"z":-5,"name":"Soil_Dirt"},{"x":-8,"y":1,"z":-5,"name":"Soil_Dirt"},{"x":-8,"y":2,"z":-5,"name":"Soil_Dirt"},{"x":-8,"y":3,"z":-5,"name":"Soil_Dirt"},{"x":-8,"y":4,"z":-5,"name":"Soil_Dirt"},{"x":-8,"y":5,"z":-5,"name":"Rock_Stone_Cobble_Mossy"},{"x":-8,"y":0,"z":-4,"name":"Soil_Dirt"},{"x":-8,"y":1,"z":-4,"name":"Soil_Dirt"},{"x":-8,"y":2,"z":-4,"name":"Soil_Dirt"},{"x":-8,"y":3,"z":-4,"name":"Soil_Dirt"},{"x":-8,"y":4,"z":-4,"name":"Soil_Dirt"},{"x":-8,"y":5,"z":-4,"name":"Rock_Stone_Brick_Decorative","support":15},{"x":-8,"y":0,"z":-3,"name":"Soil_Dirt"},{"x":-8,"y":1,"z":-3,"name":"Soil_Dirt"},{"x":-8,"y":2,"z":-3,"name":"Soil_Dirt"},{"x":-8,"y":3,"z":-3,"name":"Soil_Dirt"},{"x":-8,"y":4,"z":-3,"name":"Soil_Dirt"},{"x":-8,"y":5,"z":-3,"name":"Rock_Stone_Brick_Decorative"},{"x":-8,"y":0,"z":-2,"name":"Soil_Dirt"},{"x":-8,"y":1,"z":-2,"name":"Soil_Dirt"},{"x":-8,"y":2,"z":-2,"name":"Soil_Dirt"},{"x":-8,"y":3,"z":-2,"name":"Soil_Dirt"},{"x":-8,"y":4,"z":-2,"name":"Soil_Dirt"},{"x":-8,"y":5,"z":-2,"name":"Rock_Stone_Brick_Decorative","support":15},{"x":-8,"y":0,"z":-1,"name":"Soil_Dirt"},{"x":-8,"y":1,"z":-1,"name":"Soil_Dirt"},{"x":-8,"y":2,"z":-1,"name":"Soil_Dirt"},{"x":-8,"y":3,"z":-1,"name":"Soil_Dirt"},{"x":-8,"y":4,"z":-1,"name":"Soil_Dirt"},{"x":-8,"y":5,"z":-1,"name":"Rock_Stone_Brick_Decorative","support":15},{"x":-8,"y":6,"z":-1,"name":"Aetherhaven_Management_Block","components":{"Components":{"AetherhavenManagementBlock":{"PlotId":"","TownId":""},"PlacedByInteraction":{"WhoPlacedUuid":{"$binary":"v7RyWIT/TYKnXA2XcxdQtw==","$type":"04"}}}},"support":15,"rotation":3},{"x":-8,"y":0,"z":0,"name":"Soil_Dirt"},{"x":-8,"y":1,"z":0,"name":"Soil_Dirt"},{"x":-8,"y":2,"z":0,"name":"Soil_Dirt"},{"x":-8,"y":3,"z":0,"name":"Soil_Dirt"},{"x":-8,"y":4,"z":0,"name":"Soil_Dirt"},{"x":-8,"y":5,"z":0,"name":"Rock_Stone_Brick_Decorative"},{"x":-8,"y":6,"z":0,"name":"Furniture_Castle_Bench","support":15,"filler":992,"rotation":3},{"x":-8,"y":0,"z":1,"name":"Soil_Dirt"},{"x":-8,"y":1,"z":1,"name":"Soil_Dirt"},{"x":-8,"y":2,"z":1,"name":"Soil_Dirt"},{"x":-8,"y":3,"z":1,"name":"Soil_Dirt"},{"x":-8,"y":4,"z":1,"name":"Soil_Dirt"},{"x":-8,"y":5,"z":1,"name":"Rock_Stone_Brick_Decorative"},{"x":-8,"y":6,"z":1,"name":"Furniture_Castle_Bench","components":{"Components":{}},"support":15,"rotation":3},{"x":-8,"y":0,"z":2,"name":"Soil_Dirt"},{"x":-8,"y":1,"z":2,"name":"Soil_Dirt"},{"x":-8,"y":2,"z":2,"name":"Soil_Dirt"},{"x":-8,"y":3,"z":2,"name":"Soil_Dirt"},{"x":-8,"y":4,"z":2,"name":"Soil_Dirt"},{"x":-8,"y":5,"z":2,"name":"Rock_Stone_Brick_Decorative","support":15},{"x":-8,"y":0,"z":3,"name":"Soil_Dirt"},{"x":-8,"y":1,"z":3,"name":"Soil_Dirt"},{"x":-8,"y":2,"z":3,"name":"Soil_Dirt"},{"x":-8,"y":3,"z":3,"name":"Soil_Dirt"},{"x":-8,"y":4,"z":3,"name":"Soil_Dirt"},{"x":-8,"y":5,"z":3,"name":"Rock_Stone_Brick_Decorative","support":15},{"x":-8,"y":0,"z":4,"name":"Soil_Dirt"},{"x":-8,"y":1,"z":4,"name":"Soil_Dirt"},{"x":-8,"y":2,"z":4,"name":"Soil_Dirt"},{"x":-8,"y":3,"z":4,"name":"Soil_Dirt"},{"x":-8,"y":4,"z":4,"name":"Soil_Dirt"},{"x":-8,"y":5,"z":4,"name":"Rock_Stone_Brick_Decorative","support":15},{"x":-8,"y":0,"z":5,"name":"Soil_Dirt"},{"x":-8,"y":1,"z":5,"name":"Soil_Dirt"},{"x":-8,"y":2,"z":5,"name":"Soil_Dirt"},{"x":-8,"y":3,"z":5,"name":"Soil_Dirt"},{"x":-8,"y":4,"z":5,"name":"Soil_Dirt"},{"x":-8,"y":5,"z":5,"name":"Rock_Stone_Brick_Decorative","support":15},{"x":-8,"y":0,"z":6,"name":"Soil_Dirt"},{"x":-8,"y":1,"z":6,"name":"Soil_Dirt"},{"x":-8,"y":2,"z":6,"name":"Soil_Dirt"},{"x":-8,"y":3,"z":6,"name":"Soil_Dirt"},{"x":-8,"y":4,"z":6,"name":"Soil_Dirt"},{"x":-8,"y":5,"z":6,"name":"Rock_Stone_Cobble"},{"x":-8,"y":0,"z":7,"name":"Soil_Dirt"},{"x":-8,"y":1,"z":7,"name":"Soil_Dirt"},{"x":-8,"y":2,"z":7,"name":"Soil_Dirt"},{"x":-8,"y":3,"z":7,"name":"Soil_Dirt"},{"x":-8,"y":4,"z":7,"name":"Soil_Dirt"},{"x":-8,"y":5,"z":7,"name":"Rock_Stone_Cobble"},{"x":-8,"y":0,"z":8,"name":"Soil_Dirt"},{"x":-8,"y":1,"z":8,"name":"Soil_Dirt"},{"x":-8,"y":2,"z":8,"name":"Soil_Dirt"},{"x":-8,"y":3,"z":8,"name":"Soil_Dirt"},{"x":-8,"y":4,"z":8,"name":"Soil_Dirt"},{"x":-8,"y":5,"z":8,"name":"Rock_Stone_Cobble"},{"x":-8,"y":0,"z":9,"name":"Soil_Dirt"},{"x":-8,"y":1,"z":9,"name":"Soil_Dirt"},{"x":-8,"y":2,"z":9,"name":"Soil_Dirt"},{"x":-8,"y":3,"z":9,"name":"Soil_Dirt"},{"x":-8,"y":4,"z":9,"name":"Soil_Dirt"},{"x":-8,"y":5,"z":9,"name":"Rock_Stone_Cobble"},{"x":-8,"y":0,"z":10,"name":"Soil_Dirt"},{"x":-8,"y":1,"z":10,"name":"Soil_Dirt"},{"x":-8,"y":2,"z":10,"name":"Soil_Dirt"},{"x":-8,"y":3,"z":10,"name":"Soil_Dirt"},{"x":-8,"y":4,"z":10,"name":"Soil_Dirt"},{"x":-8,"y":5,"z":10,"name":"Rock_Stone_Cobble"},{"x":-8,"y":0,"z":11,"name":"Soil_Dirt"},{"x":-8,"y":1,"z":11,"name":"Soil_Dirt"},{"x":-8,"y":2,"z":11,"name":"Soil_Dirt"},{"x":-8,"y":3,"z":11,"name":"Soil_Dirt"},{"x":-8,"y":4,"z":11,"name":"Soil_Dirt"},{"x":-8,"y":5,"z":11,"name":"Rock_Stone_Cobble"},{"x":-8,"y":0,"z":12,"name":"Soil_Dirt"},{"x":-8,"y":1,"z":12,"name":"Soil_Dirt"},{"x":-8,"y":2,"z":12,"name":"Soil_Dirt"},{"x":-8,"y":3,"z":12,"name":"Soil_Dirt"},{"x":-8,"y":4,"z":12,"name":"Soil_Dirt"},{"x":-8,"y":5,"z":12,"name":"Rock_Stone_Cobble"},{"x":-8,"y":0,"z":13,"name":"Soil_Dirt"},{"x":-8,"y":1,"z":13,"name":"Soil_Dirt"},{"x":-8,"y":2,"z":13,"name":"Soil_Dirt"},{"x":-8,"y":3,"z":13,"name":"Soil_Dirt"},{"x":-8,"y":4,"z":13,"name":"Soil_Dirt"},{"x":-8,"y":5,"z":13,"name":"Rock_Stone_Cobble"},{"x":-8,"y":0,"z":14,"name":"Soil_Dirt"},{"x":-8,"y":1,"z":14,"name":"Soil_Dirt"},{"x":-8,"y":2,"z":14,"name":"Soil_Dirt"},{"x":-8,"y":3,"z":14,"name":"Soil_Dirt"},{"x":-8,"y":4,"z":14,"name":"Soil_Dirt"},{"x":-8,"y":5,"z":14,"name":"Rock_Stone_Cobble"},{"x":-8,"y":0,"z":15,"name":"Soil_Dirt"},{"x":-8,"y":1,"z":15,"name":"Soil_Dirt"},{"x":-8,"y":2,"z":15,"name":"Soil_Dirt"},{"x":-8,"y":3,"z":15,"name":"Soil_Dirt"},{"x":-8,"y":4,"z":15,"name":"Soil_Dirt"},{"x":-8,"y":5,"z":15,"name":"Rock_Stone_Brick_Smooth"},{"x":-7,"y":0,"z":-14,"name":"Soil_Dirt"},{"x":-7,"y":1,"z":-14,"name":"Soil_Dirt"},{"x":-7,"y":2,"z":-14,"name":"Soil_Dirt"},{"x":-7,"y":3,"z":-14,"name":"Soil_Dirt"},{"x":-7,"y":4,"z":-14,"name":"Soil_Dirt"},{"x":-7,"y":5,"z":-14,"name":"Rock_Stone_Brick_Smooth"},{"x":-7,"y":0,"z":-13,"name":"Soil_Dirt"},{"x":-7,"y":1,"z":-13,"name":"Soil_Dirt"},{"x":-7,"y":2,"z":-13,"name":"Soil_Dirt"},{"x":-7,"y":3,"z":-13,"name":"Soil_Dirt"},{"x":-7,"y":4,"z":-13,"name":"Soil_Dirt"},{"x":-7,"y":5,"z":-13,"name":"Rock_Stone_Cobble"},{"x":-7,"y":0,"z":-12,"name":"Soil_Dirt"},{"x":-7,"y":1,"z":-12,"name":"Soil_Dirt"},{"x":-7,"y":2,"z":-12,"name":"Soil_Dirt"},{"x":-7,"y":3,"z":-12,"name":"Soil_Dirt"},{"x":-7,"y":4,"z":-12,"name":"Soil_Dirt"},{"x":-7,"y":5,"z":-12,"name":"Rock_Stone_Cobble_Mossy"},{"x":-7,"y":0,"z":-11,"name":"Soil_Dirt"},{"x":-7,"y":1,"z":-11,"name":"Soil_Dirt"},{"x":-7,"y":2,"z":-11,"name":"Soil_Dirt"},{"x":-7,"y":3,"z":-11,"name":"Soil_Dirt"},{"x":-7,"y":4,"z":-11,"name":"Soil_Dirt"},{"x":-7,"y":5,"z":-11,"name":"Rock_Stone_Cobble"},{"x":-7,"y":0,"z":-10,"name":"Soil_Dirt"},{"x":-7,"y":1,"z":-10,"name":"Soil_Dirt"},{"x":-7,"y":2,"z":-10,"name":"Soil_Dirt"},{"x":-7,"y":3,"z":-10,"name":"Soil_Dirt"},{"x":-7,"y":4,"z":-10,"name":"Soil_Dirt"},{"x":-7,"y":5,"z":-10,"name":"Rock_Stone_Cobble"},{"x":-7,"y":0,"z":-9,"name":"Soil_Dirt"},{"x":-7,"y":1,"z":-9,"name":"Soil_Dirt"},{"x":-7,"y":2,"z":-9,"name":"Soil_Dirt"},{"x":-7,"y":3,"z":-9,"name":"Soil_Dirt"},{"x":-7,"y":4,"z":-9,"name":"Soil_Dirt"},{"x":-7,"y":5,"z":-9,"name":"Rock_Stone_Cobble_Mossy"},{"x":-7,"y":0,"z":-8,"name":"Soil_Dirt"},{"x":-7,"y":1,"z":-8,"name":"Soil_Dirt"},{"x":-7,"y":2,"z":-8,"name":"Soil_Dirt"},{"x":-7,"y":3,"z":-8,"name":"Soil_Dirt"},{"x":-7,"y":4,"z":-8,"name":"Soil_Dirt"},{"x":-7,"y":5,"z":-8,"name":"Rock_Stone_Cobble"},{"x":-7,"y":0,"z":-7,"name":"Soil_Dirt"},{"x":-7,"y":1,"z":-7,"name":"Soil_Dirt"},{"x":-7,"y":2,"z":-7,"name":"Soil_Dirt"},{"x":-7,"y":3,"z":-7,"name":"Soil_Dirt"},{"x":-7,"y":4,"z":-7,"name":"Soil_Dirt"},{"x":-7,"y":5,"z":-7,"name":"Rock_Stone_Cobble"},{"x":-7,"y":0,"z":-6,"name":"Soil_Dirt"},{"x":-7,"y":1,"z":-6,"name":"Soil_Dirt"},{"x":-7,"y":2,"z":-6,"name":"Soil_Dirt"},{"x":-7,"y":3,"z":-6,"name":"Soil_Dirt"},{"x":-7,"y":4,"z":-6,"name":"Soil_Dirt"},{"x":-7,"y":5,"z":-6,"name":"Rock_Stone_Cobble_Mossy"},{"x":-7,"y":0,"z":-5,"name":"Soil_Dirt"},{"x":-7,"y":1,"z":-5,"name":"Soil_Dirt"},{"x":-7,"y":2,"z":-5,"name":"Soil_Dirt"},{"x":-7,"y":3,"z":-5,"name":"Soil_Dirt"},{"x":-7,"y":4,"z":-5,"name":"Soil_Dirt"},{"x":-7,"y":5,"z":-5,"name":"Rock_Stone_Brick_Decorative","support":15},{"x":-7,"y":0,"z":-4,"name":"Soil_Dirt"},{"x":-7,"y":1,"z":-4,"name":"Soil_Dirt"},{"x":-7,"y":2,"z":-4,"name":"Soil_Dirt"},{"x":-7,"y":3,"z":-4,"name":"Soil_Dirt"},{"x":-7,"y":4,"z":-4,"name":"Soil_Dirt"},{"x":-7,"y":5,"z":-4,"name":"Rock_Stone_Brick_Decorative","support":15},{"x":-7,"y":0,"z":-3,"name":"Soil_Dirt"},{"x":-7,"y":1,"z":-3,"name":"Soil_Dirt"},{"x":-7,"y":2,"z":-3,"name":"Soil_Dirt"},{"x":-7,"y":3,"z":-3,"name":"Soil_Dirt"},{"x":-7,"y":4,"z":-3,"name":"Soil_Dirt"},{"x":-7,"y":5,"z":-3,"name":"Rock_Stone_Brick_Decorative","support":15},{"x":-7,"y":6,"z":-3,"name":"Furniture_Tavern_Planter","support":15},{"x":-7,"y":7,"z":-3,"name":"Plant_Flower_Flax_Yellow","support":15},{"x":-7,"y":0,"z":-2,"name":"Soil_Dirt"},{"x":-7,"y":1,"z":-2,"name":"Soil_Dirt"},{"x":-7,"y":2,"z":-2,"name":"Soil_Dirt"},{"x":-7,"y":3,"z":-2,"name":"Soil_Dirt"},{"x":-7,"y":4,"z":-2,"name":"Soil_Dirt"},{"x":-7,"y":5,"z":-2,"name":"Rock_Stone_Cobble"},{"x":-7,"y":6,"z":-2,"name":"Rock_Stone_Brick_Mossy","support":15},{"x":-7,"y":0,"z":-1,"name":"Soil_Dirt"},{"x":-7,"y":1,"z":-1,"name":"Soil_Dirt"},{"x":-7,"y":2,"z":-1,"name":"Soil_Dirt"},{"x":-7,"y":3,"z":-1,"name":"Soil_Dirt"},{"x":-7,"y":4,"z":-1,"name":"Soil_Dirt"},{"x":-7,"y":5,"z":-1,"name":"Rock_Stone_Cobble"},{"x":-7,"y":6,"z":-1,"name":"Rock_Stone_Brick_Decorative","support":15},{"x":-7,"y":0,"z":0,"name":"Soil_Dirt"},{"x":-7,"y":1,"z":0,"name":"Soil_Dirt"},{"x":-7,"y":2,"z":0,"name":"Soil_Dirt"},{"x":-7,"y":3,"z":0,"name":"Soil_Dirt"},{"x":-7,"y":4,"z":0,"name":"Soil_Dirt"},{"x":-7,"y":5,"z":0,"name":"Rock_Stone_Cobble_Mossy"},{"x":-7,"y":6,"z":0,"name":"Rock_Stone_Brick","support":15},{"x":-7,"y":0,"z":1,"name":"Soil_Dirt"},{"x":-7,"y":1,"z":1,"name":"Soil_Dirt"},{"x":-7,"y":2,"z":1,"name":"Soil_Dirt"},{"x":-7,"y":3,"z":1,"name":"Soil_Dirt"},{"x":-7,"y":4,"z":1,"name":"Soil_Dirt"},{"x":-7,"y":5,"z":1,"name":"Rock_Stone_Cobble"},{"x":-7,"y":6,"z":1,"name":"Rock_Stone_Brick","support":15},{"x":-7,"y":0,"z":2,"name":"Soil_Dirt"},{"x":-7,"y":1,"z":2,"name":"Soil_Dirt"},{"x":-7,"y":2,"z":2,"name":"Soil_Dirt"},{"x":-7,"y":3,"z":2,"name":"Soil_Dirt"},{"x":-7,"y":4,"z":2,"name":"Soil_Dirt"},{"x":-7,"y":5,"z":2,"name":"Rock_Stone_Cobble"},{"x":-7,"y":6,"z":2,"name":"Rock_Stone_Brick_Decorative","support":15},{"x":-7,"y":0,"z":3,"name":"Soil_Dirt"},{"x":-7,"y":1,"z":3,"name":"Soil_Dirt"},{"x":-7,"y":2,"z":3,"name":"Soil_Dirt"},{"x":-7,"y":3,"z":3,"name":"Soil_Dirt"},{"x":-7,"y":4,"z":3,"name":"Soil_Dirt"},{"x":-7,"y":5,"z":3,"name":"Rock_Stone_Cobble_Mossy"},{"x":-7,"y":6,"z":3,"name":"Rock_Stone_Brick","support":15},{"x":-7,"y":0,"z":4,"name":"Soil_Dirt"},{"x":-7,"y":1,"z":4,"name":"Soil_Dirt"},{"x":-7,"y":2,"z":4,"name":"Soil_Dirt"},{"x":-7,"y":3,"z":4,"name":"Soil_Dirt"},{"x":-7,"y":4,"z":4,"name":"Soil_Dirt"},{"x":-7,"y":5,"z":4,"name":"Rock_Stone_Brick_Decorative","support":15},{"x":-7,"y":6,"z":4,"name":"Furniture_Tavern_Planter","support":15},{"x":-7,"y":7,"z":4,"name":"Plant_Flower_Common_Cyan2","support":15},{"x":-7,"y":0,"z":5,"name":"Soil_Dirt"},{"x":-7,"y":1,"z":5,"name":"Soil_Dirt"},{"x":-7,"y":2,"z":5,"name":"Soil_Dirt"},{"x":-7,"y":3,"z":5,"name":"Soil_Dirt"},{"x":-7,"y":4,"z":5,"name":"Soil_Dirt"},{"x":-7,"y":5,"z":5,"name":"Rock_Stone_Brick_Decorative"},{"x":-7,"y":0,"z":6,"name":"Soil_Dirt"},{"x":-7,"y":1,"z":6,"name":"Soil_Dirt"},{"x":-7,"y":2,"z":6,"name":"Soil_Dirt"},{"x":-7,"y":3,"z":6,"name":"Soil_Dirt"},{"x":-7,"y":4,"z":6,"name":"Soil_Dirt"},{"x":-7,"y":5,"z":6,"name":"Rock_Stone_Brick_Decorative","support":15},{"x":-7,"y":0,"z":7,"name":"Soil_Dirt"},{"x":-7,"y":1,"z":7,"name":"Soil_Dirt"},{"x":-7,"y":2,"z":7,"name":"Soil_Dirt"},{"x":-7,"y":3,"z":7,"name":"Soil_Dirt"},{"x":-7,"y":4,"z":7,"name":"Soil_Dirt"},{"x":-7,"y":5,"z":7,"name":"Rock_Stone_Cobble"},{"x":-7,"y":0,"z":8,"name":"Soil_Dirt"},{"x":-7,"y":1,"z":8,"name":"Soil_Dirt"},{"x":-7,"y":2,"z":8,"name":"Soil_Dirt"},{"x":-7,"y":3,"z":8,"name":"Soil_Dirt"},{"x":-7,"y":4,"z":8,"name":"Soil_Dirt"},{"x":-7,"y":5,"z":8,"name":"Rock_Stone_Cobble"},{"x":-7,"y":0,"z":9,"name":"Soil_Dirt"},{"x":-7,"y":1,"z":9,"name":"Soil_Dirt"},{"x":-7,"y":2,"z":9,"name":"Soil_Dirt"},{"x":-7,"y":3,"z":9,"name":"Soil_Dirt"},{"x":-7,"y":4,"z":9,"name":"Soil_Dirt"},{"x":-7,"y":5,"z":9,"name":"Rock_Stone_Cobble"},{"x":-7,"y":0,"z":10,"name":"Soil_Dirt"},{"x":-7,"y":1,"z":10,"name":"Soil_Dirt"},{"x":-7,"y":2,"z":10,"name":"Soil_Dirt"},{"x":-7,"y":3,"z":10,"name":"Soil_Dirt"},{"x":-7,"y":4,"z":10,"name":"Soil_Dirt"},{"x":-7,"y":5,"z":10,"name":"Rock_Stone_Cobble"},{"x":-7,"y":0,"z":11,"name":"Soil_Dirt"},{"x":-7,"y":1,"z":11,"name":"Soil_Dirt"},{"x":-7,"y":2,"z":11,"name":"Soil_Dirt"},{"x":-7,"y":3,"z":11,"name":"Soil_Dirt"},{"x":-7,"y":4,"z":11,"name":"Soil_Dirt"},{"x":-7,"y":5,"z":11,"name":"Rock_Stone_Cobble"},{"x":-7,"y":0,"z":12,"name":"Soil_Dirt"},{"x":-7,"y":1,"z":12,"name":"Soil_Dirt"},{"x":-7,"y":2,"z":12,"name":"Soil_Dirt"},{"x":-7,"y":3,"z":12,"name":"Soil_Dirt"},{"x":-7,"y":4,"z":12,"name":"Soil_Dirt"},{"x":-7,"y":5,"z":12,"name":"Rock_Stone_Cobble"},{"x":-7,"y":0,"z":13,"name":"Soil_Dirt"},{"x":-7,"y":1,"z":13,"name":"Soil_Dirt"},{"x":-7,"y":2,"z":13,"name":"Soil_Dirt"},{"x":-7,"y":3,"z":13,"name":"Soil_Dirt"},{"x":-7,"y":4,"z":13,"name":"Soil_Dirt"},{"x":-7,"y":5,"z":13,"name":"Rock_Stone_Cobble"},{"x":-7,"y":0,"z":14,"name":"Soil_Dirt"},{"x":-7,"y":1,"z":14,"name":"Soil_Dirt"},{"x":-7,"y":2,"z":14,"name":"Soil_Dirt"},{"x":-7,"y":3,"z":14,"name":"Soil_Dirt"},{"x":-7,"y":4,"z":14,"name":"Soil_Dirt"},{"x":-7,"y":5,"z":14,"name":"Rock_Stone_Cobble_Mossy"},{"x":-7,"y":0,"z":15,"name":"Soil_Dirt"},{"x":-7,"y":1,"z":15,"name":"Soil_Dirt"},{"x":-7,"y":2,"z":15,"name":"Soil_Dirt"},{"x":-7,"y":3,"z":15,"name":"Soil_Dirt"},{"x":-7,"y":4,"z":15,"name":"Soil_Dirt"},{"x":-7,"y":5,"z":15,"name":"Rock_Stone_Brick_Smooth"},{"x":-6,"y":0,"z":-14,"name":"Soil_Dirt"},{"x":-6,"y":1,"z":-14,"name":"Soil_Dirt"},{"x":-6,"y":2,"z":-14,"name":"Soil_Dirt"},{"x":-6,"y":3,"z":-14,"name":"Soil_Dirt"},{"x":-6,"y":4,"z":-14,"name":"Soil_Dirt"},{"x":-6,"y":5,"z":-14,"name":"Rock_Stone_Brick_Smooth"},{"x":-6,"y":0,"z":-13,"name":"Soil_Dirt"},{"x":-6,"y":1,"z":-13,"name":"Soil_Dirt"},{"x":-6,"y":2,"z":-13,"name":"Soil_Dirt"},{"x":-6,"y":3,"z":-13,"name":"Soil_Dirt"},{"x":-6,"y":4,"z":-13,"name":"Soil_Dirt"},{"x":-6,"y":5,"z":-13,"name":"Rock_Stone_Cobble"},{"x":-6,"y":0,"z":-12,"name":"Soil_Dirt"},{"x":-6,"y":1,"z":-12,"name":"Soil_Dirt"},{"x":-6,"y":2,"z":-12,"name":"Soil_Dirt"},{"x":-6,"y":3,"z":-12,"name":"Soil_Dirt"},{"x":-6,"y":4,"z":-12,"name":"Soil_Dirt"},{"x":-6,"y":5,"z":-12,"name":"Rock_Stone_Cobble"},{"x":-6,"y":0,"z":-11,"name":"Soil_Dirt"},{"x":-6,"y":1,"z":-11,"name":"Soil_Dirt"},{"x":-6,"y":2,"z":-11,"name":"Soil_Dirt"},{"x":-6,"y":3,"z":-11,"name":"Soil_Dirt"},{"x":-6,"y":4,"z":-11,"name":"Soil_Dirt"},{"x":-6,"y":5,"z":-11,"name":"Rock_Stone_Cobble"},{"x":-6,"y":0,"z":-10,"name":"Soil_Dirt"},{"x":-6,"y":1,"z":-10,"name":"Soil_Dirt"},{"x":-6,"y":2,"z":-10,"name":"Soil_Dirt"},{"x":-6,"y":3,"z":-10,"name":"Soil_Dirt"},{"x":-6,"y":4,"z":-10,"name":"Soil_Dirt"},{"x":-6,"y":5,"z":-10,"name":"Rock_Stone_Cobble_Mossy"},{"x":-6,"y":0,"z":-9,"name":"Soil_Dirt"},{"x":-6,"y":1,"z":-9,"name":"Soil_Dirt"},{"x":-6,"y":2,"z":-9,"name":"Soil_Dirt"},{"x":-6,"y":3,"z":-9,"name":"Soil_Dirt"},{"x":-6,"y":4,"z":-9,"name":"Soil_Dirt"},{"x":-6,"y":5,"z":-9,"name":"Rock_Stone_Cobble"},{"x":-6,"y":0,"z":-8,"name":"Soil_Dirt"},{"x":-6,"y":1,"z":-8,"name":"Soil_Dirt"},{"x":-6,"y":2,"z":-8,"name":"Soil_Dirt"},{"x":-6,"y":3,"z":-8,"name":"Soil_Dirt"},{"x":-6,"y":4,"z":-8,"name":"Soil_Dirt"},{"x":-6,"y":5,"z":-8,"name":"Rock_Stone_Cobble"},{"x":-6,"y":0,"z":-7,"name":"Soil_Dirt"},{"x":-6,"y":1,"z":-7,"name":"Soil_Dirt"},{"x":-6,"y":2,"z":-7,"name":"Soil_Dirt"},{"x":-6,"y":3,"z":-7,"name":"Soil_Dirt"},{"x":-6,"y":4,"z":-7,"name":"Soil_Dirt"},{"x":-6,"y":5,"z":-7,"name":"Rock_Stone_Cobble"},{"x":-6,"y":0,"z":-6,"name":"Soil_Dirt"},{"x":-6,"y":1,"z":-6,"name":"Soil_Dirt"},{"x":-6,"y":2,"z":-6,"name":"Soil_Dirt"},{"x":-6,"y":3,"z":-6,"name":"Soil_Dirt"},{"x":-6,"y":4,"z":-6,"name":"Soil_Dirt"},{"x":-6,"y":5,"z":-6,"name":"Rock_Stone_Brick_Decorative","support":15},{"x":-6,"y":0,"z":-5,"name":"Soil_Dirt"},{"x":-6,"y":1,"z":-5,"name":"Soil_Dirt"},{"x":-6,"y":2,"z":-5,"name":"Soil_Dirt"},{"x":-6,"y":3,"z":-5,"name":"Soil_Dirt"},{"x":-6,"y":4,"z":-5,"name":"Soil_Dirt"},{"x":-6,"y":5,"z":-5,"name":"Rock_Stone_Brick_Decorative","support":15},{"x":-6,"y":0,"z":-4,"name":"Soil_Dirt"},{"x":-6,"y":1,"z":-4,"name":"Soil_Dirt"},{"x":-6,"y":2,"z":-4,"name":"Soil_Dirt"},{"x":-6,"y":3,"z":-4,"name":"Soil_Dirt"},{"x":-6,"y":4,"z":-4,"name":"Soil_Dirt"},{"x":-6,"y":5,"z":-4,"name":"Rock_Stone_Cobble"},{"x":-6,"y":6,"z":-4,"name":"Rock_Stone_Brick_Decorative","support":15},{"x":-6,"y":0,"z":-3,"name":"Soil_Dirt"},{"x":-6,"y":1,"z":-3,"name":"Soil_Dirt"},{"x":-6,"y":2,"z":-3,"name":"Soil_Dirt"},{"x":-6,"y":3,"z":-3,"name":"Soil_Dirt"},{"x":-6,"y":4,"z":-3,"name":"Soil_Dirt"},{"x":-6,"y":5,"z":-3,"name":"Rock_Stone_Cobble_Mossy"},{"x":-6,"y":6,"z":-3,"name":"Rock_Stone_Brick_Decorative","support":15},{"x":-6,"y":0,"z":-2,"name":"Soil_Dirt"},{"x":-6,"y":1,"z":-2,"name":"Soil_Dirt"},{"x":-6,"y":2,"z":-2,"name":"Soil_Dirt"},{"x":-6,"y":3,"z":-2,"name":"Soil_Dirt"},{"x":-6,"y":4,"z":-2,"name":"Soil_Dirt"},{"x":-6,"y":5,"z":-2,"name":"Rock_Stone_Brick_Mossy"},{"x":-6,"y":0,"z":-1,"name":"Soil_Dirt"},{"x":-6,"y":1,"z":-1,"name":"Soil_Dirt"},{"x":-6,"y":2,"z":-1,"name":"Soil_Dirt"},{"x":-6,"y":3,"z":-1,"name":"Soil_Dirt"},{"x":-6,"y":4,"z":-1,"name":"Soil_Dirt"},{"x":-6,"y":5,"z":-1,"name":"Rock_Stone_Brick"},{"x":-6,"y":0,"z":0,"name":"Soil_Dirt"},{"x":-6,"y":1,"z":0,"name":"Soil_Dirt"},{"x":-6,"y":2,"z":0,"name":"Soil_Dirt"},{"x":-6,"y":3,"z":0,"name":"Soil_Dirt"},{"x":-6,"y":4,"z":0,"name":"Soil_Dirt"},{"x":-6,"y":5,"z":0,"name":"Rock_Stone_Brick"},{"x":-6,"y":0,"z":1,"name":"Soil_Dirt"},{"x":-6,"y":1,"z":1,"name":"Soil_Dirt"},{"x":-6,"y":2,"z":1,"name":"Soil_Dirt"},{"x":-6,"y":3,"z":1,"name":"Soil_Dirt"},{"x":-6,"y":4,"z":1,"name":"Soil_Dirt"},{"x":-6,"y":5,"z":1,"name":"Rock_Stone_Brick"},{"x":-6,"y":0,"z":2,"name":"Soil_Dirt"},{"x":-6,"y":1,"z":2,"name":"Soil_Dirt"},{"x":-6,"y":2,"z":2,"name":"Soil_Dirt"},{"x":-6,"y":3,"z":2,"name":"Soil_Dirt"},{"x":-6,"y":4,"z":2,"name":"Soil_Dirt"},{"x":-6,"y":5,"z":2,"name":"Rock_Stone_Brick_Decorative"},{"x":-6,"y":0,"z":3,"name":"Soil_Dirt"},{"x":-6,"y":1,"z":3,"name":"Soil_Dirt"},{"x":-6,"y":2,"z":3,"name":"Soil_Dirt"},{"x":-6,"y":3,"z":3,"name":"Soil_Dirt"},{"x":-6,"y":4,"z":3,"name":"Soil_Dirt"},{"x":-6,"y":5,"z":3,"name":"Rock_Stone_Brick_Decorative"},{"x":-6,"y":0,"z":4,"name":"Soil_Dirt"},{"x":-6,"y":1,"z":4,"name":"Soil_Dirt"},{"x":-6,"y":2,"z":4,"name":"Soil_Dirt"},{"x":-6,"y":3,"z":4,"name":"Soil_Dirt"},{"x":-6,"y":4,"z":4,"name":"Soil_Dirt"},{"x":-6,"y":5,"z":4,"name":"Rock_Stone_Cobble"},{"x":-6,"y":6,"z":4,"name":"Rock_Stone_Brick_Decorative","support":15},{"x":-6,"y":0,"z":5,"name":"Soil_Dirt"},{"x":-6,"y":1,"z":5,"name":"Soil_Dirt"},{"x":-6,"y":2,"z":5,"name":"Soil_Dirt"},{"x":-6,"y":3,"z":5,"name":"Soil_Dirt"},{"x":-6,"y":4,"z":5,"name":"Soil_Dirt"},{"x":-6,"y":5,"z":5,"name":"Rock_Stone_Cobble"},{"x":-6,"y":6,"z":5,"name":"Rock_Stone_Brick_Mossy","support":15},{"x":-6,"y":0,"z":6,"name":"Soil_Dirt"},{"x":-6,"y":1,"z":6,"name":"Soil_Dirt"},{"x":-6,"y":2,"z":6,"name":"Soil_Dirt"},{"x":-6,"y":3,"z":6,"name":"Soil_Dirt"},{"x":-6,"y":4,"z":6,"name":"Soil_Dirt"},{"x":-6,"y":5,"z":6,"name":"Rock_Stone_Brick_Decorative","support":15},{"x":-6,"y":0,"z":7,"name":"Soil_Dirt"},{"x":-6,"y":1,"z":7,"name":"Soil_Dirt"},{"x":-6,"y":2,"z":7,"name":"Soil_Dirt"},{"x":-6,"y":3,"z":7,"name":"Soil_Dirt"},{"x":-6,"y":4,"z":7,"name":"Soil_Dirt"},{"x":-6,"y":5,"z":7,"name":"Rock_Stone_Brick_Decorative","support":15},{"x":-6,"y":0,"z":8,"name":"Soil_Dirt"},{"x":-6,"y":1,"z":8,"name":"Soil_Dirt"},{"x":-6,"y":2,"z":8,"name":"Soil_Dirt"},{"x":-6,"y":3,"z":8,"name":"Soil_Dirt"},{"x":-6,"y":4,"z":8,"name":"Soil_Dirt"},{"x":-6,"y":5,"z":8,"name":"Rock_Stone_Cobble"},{"x":-6,"y":0,"z":9,"name":"Soil_Dirt"},{"x":-6,"y":1,"z":9,"name":"Soil_Dirt"},{"x":-6,"y":2,"z":9,"name":"Soil_Dirt"},{"x":-6,"y":3,"z":9,"name":"Soil_Dirt"},{"x":-6,"y":4,"z":9,"name":"Soil_Dirt"},{"x":-6,"y":5,"z":9,"name":"Rock_Stone_Cobble"},{"x":-6,"y":0,"z":10,"name":"Soil_Dirt"},{"x":-6,"y":1,"z":10,"name":"Soil_Dirt"},{"x":-6,"y":2,"z":10,"name":"Soil_Dirt"},{"x":-6,"y":3,"z":10,"name":"Soil_Dirt"},{"x":-6,"y":4,"z":10,"name":"Soil_Dirt"},{"x":-6,"y":5,"z":10,"name":"Rock_Stone_Cobble"},{"x":-6,"y":0,"z":11,"name":"Soil_Dirt"},{"x":-6,"y":1,"z":11,"name":"Soil_Dirt"},{"x":-6,"y":2,"z":11,"name":"Soil_Dirt"},{"x":-6,"y":3,"z":11,"name":"Soil_Dirt"},{"x":-6,"y":4,"z":11,"name":"Soil_Dirt"},{"x":-6,"y":5,"z":11,"name":"Rock_Stone_Cobble"},{"x":-6,"y":0,"z":12,"name":"Soil_Dirt"},{"x":-6,"y":1,"z":12,"name":"Soil_Dirt"},{"x":-6,"y":2,"z":12,"name":"Soil_Dirt"},{"x":-6,"y":3,"z":12,"name":"Soil_Dirt"},{"x":-6,"y":4,"z":12,"name":"Soil_Dirt"},{"x":-6,"y":5,"z":12,"name":"Rock_Stone_Cobble"},{"x":-6,"y":0,"z":13,"name":"Soil_Dirt"},{"x":-6,"y":1,"z":13,"name":"Soil_Dirt"},{"x":-6,"y":2,"z":13,"name":"Soil_Dirt"},{"x":-6,"y":3,"z":13,"name":"Soil_Dirt"},{"x":-6,"y":4,"z":13,"name":"Soil_Dirt"},{"x":-6,"y":5,"z":13,"name":"Rock_Stone_Cobble"},{"x":-6,"y":0,"z":14,"name":"Soil_Dirt"},{"x":-6,"y":1,"z":14,"name":"Soil_Dirt"},{"x":-6,"y":2,"z":14,"name":"Soil_Dirt"},{"x":-6,"y":3,"z":14,"name":"Soil_Dirt"},{"x":-6,"y":4,"z":14,"name":"Soil_Dirt"},{"x":-6,"y":5,"z":14,"name":"Rock_Stone_Cobble"},{"x":-6,"y":0,"z":15,"name":"Soil_Dirt"},{"x":-6,"y":1,"z":15,"name":"Soil_Dirt"},{"x":-6,"y":2,"z":15,"name":"Soil_Dirt"},{"x":-6,"y":3,"z":15,"name":"Soil_Dirt"},{"x":-6,"y":4,"z":15,"name":"Soil_Dirt"},{"x":-6,"y":5,"z":15,"name":"Rock_Stone_Brick_Smooth"},{"x":-5,"y":0,"z":-14,"name":"Soil_Dirt"},{"x":-5,"y":1,"z":-14,"name":"Soil_Dirt"},{"x":-5,"y":2,"z":-14,"name":"Soil_Dirt"},{"x":-5,"y":3,"z":-14,"name":"Soil_Dirt"},{"x":-5,"y":4,"z":-14,"name":"Soil_Dirt"},{"x":-5,"y":5,"z":-14,"name":"Rock_Stone_Brick_Smooth"},{"x":-5,"y":0,"z":-13,"name":"Soil_Dirt"},{"x":-5,"y":1,"z":-13,"name":"Soil_Dirt"},{"x":-5,"y":2,"z":-13,"name":"Soil_Dirt"},{"x":-5,"y":3,"z":-13,"name":"Soil_Dirt"},{"x":-5,"y":4,"z":-13,"name":"Soil_Dirt"},{"x":-5,"y":5,"z":-13,"name":"Rock_Stone_Cobble_Mossy"},{"x":-5,"y":0,"z":-12,"name":"Soil_Dirt"},{"x":-5,"y":1,"z":-12,"name":"Soil_Dirt"},{"x":-5,"y":2,"z":-12,"name":"Soil_Dirt"},{"x":-5,"y":3,"z":-12,"name":"Soil_Dirt"},{"x":-5,"y":4,"z":-12,"name":"Soil_Dirt"},{"x":-5,"y":5,"z":-12,"name":"Rock_Stone_Cobble"},{"x":-5,"y":0,"z":-11,"name":"Soil_Dirt"},{"x":-5,"y":1,"z":-11,"name":"Soil_Dirt"},{"x":-5,"y":2,"z":-11,"name":"Soil_Dirt"},{"x":-5,"y":3,"z":-11,"name":"Soil_Dirt"},{"x":-5,"y":4,"z":-11,"name":"Soil_Dirt"},{"x":-5,"y":5,"z":-11,"name":"Rock_Stone_Cobble_Mossy"},{"x":-5,"y":0,"z":-10,"name":"Soil_Dirt"},{"x":-5,"y":1,"z":-10,"name":"Soil_Dirt"},{"x":-5,"y":2,"z":-10,"name":"Soil_Dirt"},{"x":-5,"y":3,"z":-10,"name":"Soil_Dirt"},{"x":-5,"y":4,"z":-10,"name":"Soil_Dirt"},{"x":-5,"y":5,"z":-10,"name":"Rock_Stone_Cobble_Mossy"},{"x":-5,"y":0,"z":-9,"name":"Soil_Dirt"},{"x":-5,"y":1,"z":-9,"name":"Soil_Dirt"},{"x":-5,"y":2,"z":-9,"name":"Soil_Dirt"},{"x":-5,"y":3,"z":-9,"name":"Soil_Dirt"},{"x":-5,"y":4,"z":-9,"name":"Soil_Dirt"},{"x":-5,"y":5,"z":-9,"name":"Rock_Stone_Cobble_Mossy"},{"x":-5,"y":0,"z":-8,"name":"Soil_Dirt"},{"x":-5,"y":1,"z":-8,"name":"Soil_Dirt"},{"x":-5,"y":2,"z":-8,"name":"Soil_Dirt"},{"x":-5,"y":3,"z":-8,"name":"Soil_Dirt"},{"x":-5,"y":4,"z":-8,"name":"Soil_Dirt"},{"x":-5,"y":5,"z":-8,"name":"Rock_Stone_Cobble"},{"x":-5,"y":0,"z":-7,"name":"Soil_Dirt"},{"x":-5,"y":1,"z":-7,"name":"Soil_Dirt"},{"x":-5,"y":2,"z":-7,"name":"Soil_Dirt"},{"x":-5,"y":3,"z":-7,"name":"Soil_Dirt"},{"x":-5,"y":4,"z":-7,"name":"Soil_Dirt"},{"x":-5,"y":5,"z":-7,"name":"Rock_Stone_Brick_Decorative","support":15},{"x":-5,"y":0,"z":-6,"name":"Soil_Dirt"},{"x":-5,"y":1,"z":-6,"name":"Soil_Dirt"},{"x":-5,"y":2,"z":-6,"name":"Soil_Dirt"},{"x":-5,"y":3,"z":-6,"name":"Soil_Dirt"},{"x":-5,"y":4,"z":-6,"name":"Soil_Dirt"},{"x":-5,"y":5,"z":-6,"name":"Rock_Stone_Brick_Decorative","support":15},{"x":-5,"y":0,"z":-5,"name":"Soil_Dirt"},{"x":-5,"y":1,"z":-5,"name":"Soil_Dirt"},{"x":-5,"y":2,"z":-5,"name":"Soil_Dirt"},{"x":-5,"y":3,"z":-5,"name":"Soil_Dirt"},{"x":-5,"y":4,"z":-5,"name":"Soil_Dirt"},{"x":-5,"y":5,"z":-5,"name":"Rock_Stone_Cobble"},{"x":-5,"y":6,"z":-5,"name":"Rock_Stone_Brick","support":15},{"x":-5,"y":0,"z":-4,"name":"Soil_Dirt"},{"x":-5,"y":1,"z":-4,"name":"Soil_Dirt"},{"x":-5,"y":2,"z":-4,"name":"Soil_Dirt"},{"x":-5,"y":3,"z":-4,"name":"Soil_Dirt"},{"x":-5,"y":4,"z":-4,"name":"Soil_Dirt"},{"x":-5,"y":5,"z":-4,"name":"Rock_Stone_Brick","support":15},{"x":-5,"y":0,"z":-3,"name":"Soil_Dirt"},{"x":-5,"y":1,"z":-3,"name":"Soil_Dirt"},{"x":-5,"y":2,"z":-3,"name":"Soil_Dirt"},{"x":-5,"y":3,"z":-3,"name":"Soil_Dirt"},{"x":-5,"y":4,"z":-3,"name":"Soil_Dirt"},{"x":-5,"y":5,"z":-3,"name":"Rock_Stone_Brick","support":15},{"x":-5,"y":0,"z":-2,"name":"Soil_Dirt"},{"x":-5,"y":1,"z":-2,"name":"Soil_Dirt"},{"x":-5,"y":2,"z":-2,"name":"Soil_Dirt"},{"x":-5,"y":3,"z":-2,"name":"Soil_Dirt"},{"x":-5,"y":4,"z":-2,"name":"Soil_Dirt"},{"x":-5,"y":5,"z":-2,"name":"Rock_Stone_Brick_Ornate","support":15},{"x":-5,"y":0,"z":-1,"name":"Soil_Dirt"},{"x":-5,"y":1,"z":-1,"name":"Soil_Dirt"},{"x":-5,"y":2,"z":-1,"name":"Soil_Dirt"},{"x":-5,"y":3,"z":-1,"name":"Soil_Dirt"},{"x":-5,"y":4,"z":-1,"name":"Soil_Dirt"},{"x":-5,"y":5,"z":-1,"name":"Rock_Stone_Brick_Ornate","support":15},{"x":-5,"y":0,"z":0,"name":"Soil_Dirt"},{"x":-5,"y":1,"z":0,"name":"Soil_Dirt"},{"x":-5,"y":2,"z":0,"name":"Soil_Dirt"},{"x":-5,"y":3,"z":0,"name":"Soil_Dirt"},{"x":-5,"y":4,"z":0,"name":"Soil_Dirt"},{"x":-5,"y":5,"z":0,"name":"Rock_Stone_Brick_Ornate","support":15},{"x":-5,"y":0,"z":1,"name":"Soil_Dirt"},{"x":-5,"y":1,"z":1,"name":"Soil_Dirt"},{"x":-5,"y":2,"z":1,"name":"Soil_Dirt"},{"x":-5,"y":3,"z":1,"name":"Soil_Dirt"},{"x":-5,"y":4,"z":1,"name":"Soil_Dirt"},{"x":-5,"y":5,"z":1,"name":"Rock_Stone_Brick_Ornate","support":15},{"x":-5,"y":0,"z":2,"name":"Soil_Dirt"},{"x":-5,"y":1,"z":2,"name":"Soil_Dirt"},{"x":-5,"y":2,"z":2,"name":"Soil_Dirt"},{"x":-5,"y":3,"z":2,"name":"Soil_Dirt"},{"x":-5,"y":4,"z":2,"name":"Soil_Dirt"},{"x":-5,"y":5,"z":2,"name":"Rock_Stone_Brick_Ornate","support":15},{"x":-5,"y":0,"z":3,"name":"Soil_Dirt"},{"x":-5,"y":1,"z":3,"name":"Soil_Dirt"},{"x":-5,"y":2,"z":3,"name":"Soil_Dirt"},{"x":-5,"y":3,"z":3,"name":"Soil_Dirt"},{"x":-5,"y":4,"z":3,"name":"Soil_Dirt"},{"x":-5,"y":5,"z":3,"name":"Rock_Stone_Brick_Ornate","support":15},{"x":-5,"y":0,"z":4,"name":"Soil_Dirt"},{"x":-5,"y":1,"z":4,"name":"Soil_Dirt"},{"x":-5,"y":2,"z":4,"name":"Soil_Dirt"},{"x":-5,"y":3,"z":4,"name":"Soil_Dirt"},{"x":-5,"y":4,"z":4,"name":"Soil_Dirt"},{"x":-5,"y":5,"z":4,"name":"Rock_Stone_Brick","support":15},{"x":-5,"y":0,"z":5,"name":"Soil_Dirt"},{"x":-5,"y":1,"z":5,"name":"Soil_Dirt"},{"x":-5,"y":2,"z":5,"name":"Soil_Dirt"},{"x":-5,"y":3,"z":5,"name":"Soil_Dirt"},{"x":-5,"y":4,"z":5,"name":"Soil_Dirt"},{"x":-5,"y":5,"z":5,"name":"Rock_Stone_Brick_Decorative","support":15},{"x":-5,"y":0,"z":6,"name":"Soil_Dirt"},{"x":-5,"y":1,"z":6,"name":"Soil_Dirt"},{"x":-5,"y":2,"z":6,"name":"Soil_Dirt"},{"x":-5,"y":3,"z":6,"name":"Soil_Dirt"},{"x":-5,"y":4,"z":6,"name":"Soil_Dirt"},{"x":-5,"y":5,"z":6,"name":"Rock_Stone_Cobble"},{"x":-5,"y":6,"z":6,"name":"Rock_Stone_Brick","support":15},{"x":-5,"y":0,"z":7,"name":"Soil_Dirt"},{"x":-5,"y":1,"z":7,"name":"Soil_Dirt"},{"x":-5,"y":2,"z":7,"name":"Soil_Dirt"},{"x":-5,"y":3,"z":7,"name":"Soil_Dirt"},{"x":-5,"y":4,"z":7,"name":"Soil_Dirt"},{"x":-5,"y":5,"z":7,"name":"Rock_Stone_Brick_Decorative","support":15},{"x":-5,"y":0,"z":8,"name":"Soil_Dirt"},{"x":-5,"y":1,"z":8,"name":"Soil_Dirt"},{"x":-5,"y":2,"z":8,"name":"Soil_Dirt"},{"x":-5,"y":3,"z":8,"name":"Soil_Dirt"},{"x":-5,"y":4,"z":8,"name":"Soil_Dirt"},{"x":-5,"y":5,"z":8,"name":"Rock_Stone_Brick_Decorative","support":15},{"x":-5,"y":0,"z":9,"name":"Soil_Dirt"},{"x":-5,"y":1,"z":9,"name":"Soil_Dirt"},{"x":-5,"y":2,"z":9,"name":"Soil_Dirt"},{"x":-5,"y":3,"z":9,"name":"Soil_Dirt"},{"x":-5,"y":4,"z":9,"name":"Soil_Dirt"},{"x":-5,"y":5,"z":9,"name":"Rock_Stone_Cobble"},{"x":-5,"y":0,"z":10,"name":"Soil_Dirt"},{"x":-5,"y":1,"z":10,"name":"Soil_Dirt"},{"x":-5,"y":2,"z":10,"name":"Soil_Dirt"},{"x":-5,"y":3,"z":10,"name":"Soil_Dirt"},{"x":-5,"y":4,"z":10,"name":"Soil_Dirt"},{"x":-5,"y":5,"z":10,"name":"Rock_Stone_Cobble"},{"x":-5,"y":0,"z":11,"name":"Soil_Dirt"},{"x":-5,"y":1,"z":11,"name":"Soil_Dirt"},{"x":-5,"y":2,"z":11,"name":"Soil_Dirt"},{"x":-5,"y":3,"z":11,"name":"Soil_Dirt"},{"x":-5,"y":4,"z":11,"name":"Soil_Dirt"},{"x":-5,"y":5,"z":11,"name":"Rock_Stone_Cobble"},{"x":-5,"y":0,"z":12,"name":"Soil_Dirt"},{"x":-5,"y":1,"z":12,"name":"Soil_Dirt"},{"x":-5,"y":2,"z":12,"name":"Soil_Dirt"},{"x":-5,"y":3,"z":12,"name":"Soil_Dirt"},{"x":-5,"y":4,"z":12,"name":"Soil_Dirt"},{"x":-5,"y":5,"z":12,"name":"Rock_Stone_Cobble"},{"x":-5,"y":0,"z":13,"name":"Soil_Dirt"},{"x":-5,"y":1,"z":13,"name":"Soil_Dirt"},{"x":-5,"y":2,"z":13,"name":"Soil_Dirt"},{"x":-5,"y":3,"z":13,"name":"Soil_Dirt"},{"x":-5,"y":4,"z":13,"name":"Soil_Dirt"},{"x":-5,"y":5,"z":13,"name":"Rock_Stone_Cobble"},{"x":-5,"y":0,"z":14,"name":"Soil_Dirt"},{"x":-5,"y":1,"z":14,"name":"Soil_Dirt"},{"x":-5,"y":2,"z":14,"name":"Soil_Dirt"},{"x":-5,"y":3,"z":14,"name":"Soil_Dirt"},{"x":-5,"y":4,"z":14,"name":"Soil_Dirt"},{"x":-5,"y":5,"z":14,"name":"Rock_Stone_Cobble"},{"x":-5,"y":0,"z":15,"name":"Soil_Dirt"},{"x":-5,"y":1,"z":15,"name":"Soil_Dirt"},{"x":-5,"y":2,"z":15,"name":"Soil_Dirt"},{"x":-5,"y":3,"z":15,"name":"Soil_Dirt"},{"x":-5,"y":4,"z":15,"name":"Soil_Dirt"},{"x":-5,"y":5,"z":15,"name":"Rock_Stone_Brick_Smooth"},{"x":-4,"y":0,"z":-14,"name":"Soil_Dirt"},{"x":-4,"y":1,"z":-14,"name":"Soil_Dirt"},{"x":-4,"y":2,"z":-14,"name":"Soil_Dirt"},{"x":-4,"y":3,"z":-14,"name":"Soil_Dirt"},{"x":-4,"y":4,"z":-14,"name":"Soil_Dirt"},{"x":-4,"y":5,"z":-14,"name":"Rock_Stone_Brick_Smooth"},{"x":-4,"y":0,"z":-13,"name":"Soil_Dirt"},{"x":-4,"y":1,"z":-13,"name":"Soil_Dirt"},{"x":-4,"y":2,"z":-13,"name":"Soil_Dirt"},{"x":-4,"y":3,"z":-13,"name":"Soil_Dirt"},{"x":-4,"y":4,"z":-13,"name":"Soil_Dirt"},{"x":-4,"y":5,"z":-13,"name":"Rock_Stone_Cobble"},{"x":-4,"y":0,"z":-12,"name":"Soil_Dirt"},{"x":-4,"y":1,"z":-12,"name":"Soil_Dirt"},{"x":-4,"y":2,"z":-12,"name":"Soil_Dirt"},{"x":-4,"y":3,"z":-12,"name":"Soil_Dirt"},{"x":-4,"y":4,"z":-12,"name":"Soil_Dirt"},{"x":-4,"y":5,"z":-12,"name":"Rock_Stone_Cobble"},{"x":-4,"y":0,"z":-11,"name":"Soil_Dirt"},{"x":-4,"y":1,"z":-11,"name":"Soil_Dirt"},{"x":-4,"y":2,"z":-11,"name":"Soil_Dirt"},{"x":-4,"y":3,"z":-11,"name":"Soil_Dirt"},{"x":-4,"y":4,"z":-11,"name":"Soil_Dirt"},{"x":-4,"y":5,"z":-11,"name":"Rock_Stone_Cobble"},{"x":-4,"y":0,"z":-10,"name":"Soil_Dirt"},{"x":-4,"y":1,"z":-10,"name":"Soil_Dirt"},{"x":-4,"y":2,"z":-10,"name":"Soil_Dirt"},{"x":-4,"y":3,"z":-10,"name":"Soil_Dirt"},{"x":-4,"y":4,"z":-10,"name":"Soil_Dirt"},{"x":-4,"y":5,"z":-10,"name":"Rock_Stone_Cobble"},{"x":-4,"y":0,"z":-9,"name":"Soil_Dirt"},{"x":-4,"y":1,"z":-9,"name":"Soil_Dirt"},{"x":-4,"y":2,"z":-9,"name":"Soil_Dirt"},{"x":-4,"y":3,"z":-9,"name":"Soil_Dirt"},{"x":-4,"y":4,"z":-9,"name":"Soil_Dirt"},{"x":-4,"y":5,"z":-9,"name":"Rock_Stone_Cobble_Mossy"},{"x":-4,"y":0,"z":-8,"name":"Soil_Dirt"},{"x":-4,"y":1,"z":-8,"name":"Soil_Dirt"},{"x":-4,"y":2,"z":-8,"name":"Soil_Dirt"},{"x":-4,"y":3,"z":-8,"name":"Soil_Dirt"},{"x":-4,"y":4,"z":-8,"name":"Soil_Dirt"},{"x":-4,"y":5,"z":-8,"name":"Rock_Stone_Brick_Decorative","support":15},{"x":-4,"y":0,"z":-7,"name":"Soil_Dirt"},{"x":-4,"y":1,"z":-7,"name":"Soil_Dirt"},{"x":-4,"y":2,"z":-7,"name":"Soil_Dirt"},{"x":-4,"y":3,"z":-7,"name":"Soil_Dirt"},{"x":-4,"y":4,"z":-7,"name":"Soil_Dirt"},{"x":-4,"y":5,"z":-7,"name":"Rock_Stone_Brick_Decorative","support":15},{"x":-4,"y":0,"z":-6,"name":"Soil_Dirt"},{"x":-4,"y":1,"z":-6,"name":"Soil_Dirt"},{"x":-4,"y":2,"z":-6,"name":"Soil_Dirt"},{"x":-4,"y":3,"z":-6,"name":"Soil_Dirt"},{"x":-4,"y":4,"z":-6,"name":"Soil_Dirt"},{"x":-4,"y":5,"z":-6,"name":"Rock_Stone_Cobble"},{"x":-4,"y":6,"z":-6,"name":"Rock_Stone_Brick_Decorative","support":15},{"x":-4,"y":0,"z":-5,"name":"Soil_Dirt"},{"x":-4,"y":1,"z":-5,"name":"Soil_Dirt"},{"x":-4,"y":2,"z":-5,"name":"Soil_Dirt"},{"x":-4,"y":3,"z":-5,"name":"Soil_Dirt"},{"x":-4,"y":4,"z":-5,"name":"Soil_Dirt"},{"x":-4,"y":5,"z":-5,"name":"Rock_Stone_Brick","support":15},{"x":-4,"y":0,"z":-4,"name":"Soil_Dirt"},{"x":-4,"y":1,"z":-4,"name":"Soil_Dirt"},{"x":-4,"y":2,"z":-4,"name":"Soil_Dirt"},{"x":-4,"y":3,"z":-4,"name":"Soil_Dirt"},{"x":-4,"y":4,"z":-4,"name":"Soil_Dirt"},{"x":-4,"y":5,"z":-4,"name":"Rock_Stone_Brick_Ornate","support":15},{"x":-4,"y":0,"z":-3,"name":"Soil_Dirt"},{"x":-4,"y":1,"z":-3,"name":"Soil_Dirt"},{"x":-4,"y":2,"z":-3,"name":"Soil_Dirt"},{"x":-4,"y":3,"z":-3,"name":"Soil_Dirt"},{"x":-4,"y":4,"z":-3,"name":"Soil_Dirt"},{"x":-4,"y":5,"z":-3,"name":"Rock_Stone_Brick_Ornate","support":15},{"x":-4,"y":0,"z":-2,"name":"Soil_Dirt"},{"x":-4,"y":1,"z":-2,"name":"Soil_Dirt"},{"x":-4,"y":2,"z":-2,"name":"Soil_Dirt"},{"x":-4,"y":3,"z":-2,"name":"Soil_Dirt"},{"x":-4,"y":4,"z":-2,"name":"Soil_Dirt"},{"x":-4,"y":5,"z":-2,"name":"Rock_Stone_Brick"},{"x":-4,"y":8,"z":-2,"name":"*Rock_Stone_Brick_Stairs_State_Definitions_Corner_Left","rotation":9},{"x":-4,"y":9,"z":-2,"name":"Rock_Stone_Brick_Smooth_Half"},{"x":-4,"y":0,"z":-1,"name":"Soil_Dirt"},{"x":-4,"y":1,"z":-1,"name":"Soil_Dirt"},{"x":-4,"y":2,"z":-1,"name":"Soil_Dirt"},{"x":-4,"y":3,"z":-1,"name":"Soil_Dirt"},{"x":-4,"y":4,"z":-1,"name":"Soil_Dirt"},{"x":-4,"y":5,"z":-1,"name":"Rock_Stone_Brick_Mossy"},{"x":-4,"y":0,"z":0,"name":"Soil_Dirt"},{"x":-4,"y":1,"z":0,"name":"Soil_Dirt"},{"x":-4,"y":2,"z":0,"name":"Soil_Dirt"},{"x":-4,"y":3,"z":0,"name":"Soil_Dirt"},{"x":-4,"y":4,"z":0,"name":"Soil_Dirt"},{"x":-4,"y":5,"z":0,"name":"Rock_Stone_Brick"},{"x":-4,"y":0,"z":1,"name":"Soil_Dirt"},{"x":-4,"y":1,"z":1,"name":"Soil_Dirt"},{"x":-4,"y":2,"z":1,"name":"Soil_Dirt"},{"x":-4,"y":3,"z":1,"name":"Soil_Dirt"},{"x":-4,"y":4,"z":1,"name":"Soil_Dirt"},{"x":-4,"y":5,"z":1,"name":"Rock_Stone_Brick"},{"x":-4,"y":0,"z":2,"name":"Soil_Dirt"},{"x":-4,"y":1,"z":2,"name":"Soil_Dirt"},{"x":-4,"y":2,"z":2,"name":"Soil_Dirt"},{"x":-4,"y":3,"z":2,"name":"Soil_Dirt"},{"x":-4,"y":4,"z":2,"name":"Soil_Dirt"},{"x":-4,"y":5,"z":2,"name":"Rock_Stone_Brick_Mossy"},{"x":-4,"y":0,"z":3,"name":"Soil_Dirt"},{"x":-4,"y":1,"z":3,"name":"Soil_Dirt"},{"x":-4,"y":2,"z":3,"name":"Soil_Dirt"},{"x":-4,"y":3,"z":3,"name":"Soil_Dirt"},{"x":-4,"y":4,"z":3,"name":"Soil_Dirt"},{"x":-4,"y":5,"z":3,"name":"Rock_Stone_Brick_Mossy"},{"x":-4,"y":8,"z":3,"name":"Rock_Stone_Brick_Stairs","rotation":10},{"x":-4,"y":9,"z":3,"name":"Rock_Stone_Brick_Smooth_Half"},{"x":-4,"y":0,"z":4,"name":"Soil_Dirt"},{"x":-4,"y":1,"z":4,"name":"Soil_Dirt"},{"x":-4,"y":2,"z":4,"name":"Soil_Dirt"},{"x":-4,"y":3,"z":4,"name":"Soil_Dirt"},{"x":-4,"y":4,"z":4,"name":"Soil_Dirt"},{"x":-4,"y":5,"z":4,"name":"Rock_Stone_Brick_Ornate","support":15},{"x":-4,"y":0,"z":5,"name":"Soil_Dirt"},{"x":-4,"y":1,"z":5,"name":"Soil_Dirt"},{"x":-4,"y":2,"z":5,"name":"Soil_Dirt"},{"x":-4,"y":3,"z":5,"name":"Soil_Dirt"},{"x":-4,"y":4,"z":5,"name":"Soil_Dirt"},{"x":-4,"y":5,"z":5,"name":"Rock_Stone_Brick_Ornate","support":15},{"x":-4,"y":0,"z":6,"name":"Soil_Dirt"},{"x":-4,"y":1,"z":6,"name":"Soil_Dirt"},{"x":-4,"y":2,"z":6,"name":"Soil_Dirt"},{"x":-4,"y":3,"z":6,"name":"Soil_Dirt"},{"x":-4,"y":4,"z":6,"name":"Soil_Dirt"},{"x":-4,"y":5,"z":6,"name":"Rock_Stone_Brick_Decorative","support":15},{"x":-4,"y":0,"z":7,"name":"Soil_Dirt"},{"x":-4,"y":1,"z":7,"name":"Soil_Dirt"},{"x":-4,"y":2,"z":7,"name":"Soil_Dirt"},{"x":-4,"y":3,"z":7,"name":"Soil_Dirt"},{"x":-4,"y":4,"z":7,"name":"Soil_Dirt"},{"x":-4,"y":5,"z":7,"name":"Rock_Stone_Cobble"},{"x":-4,"y":6,"z":7,"name":"Rock_Stone_Brick_Decorative","support":15},{"x":-4,"y":0,"z":8,"name":"Soil_Dirt"},{"x":-4,"y":1,"z":8,"name":"Soil_Dirt"},{"x":-4,"y":2,"z":8,"name":"Soil_Dirt"},{"x":-4,"y":3,"z":8,"name":"Soil_Dirt"},{"x":-4,"y":4,"z":8,"name":"Soil_Dirt"},{"x":-4,"y":5,"z":8,"name":"Rock_Stone_Brick_Decorative","support":15},{"x":-4,"y":0,"z":9,"name":"Soil_Dirt"},{"x":-4,"y":1,"z":9,"name":"Soil_Dirt"},{"x":-4,"y":2,"z":9,"name":"Soil_Dirt"},{"x":-4,"y":3,"z":9,"name":"Soil_Dirt"},{"x":-4,"y":4,"z":9,"name":"Soil_Dirt"},{"x":-4,"y":5,"z":9,"name":"Rock_Stone_Brick_Decorative","support":15},{"x":-4,"y":0,"z":10,"name":"Soil_Dirt"},{"x":-4,"y":1,"z":10,"name":"Soil_Dirt"},{"x":-4,"y":2,"z":10,"name":"Soil_Dirt"},{"x":-4,"y":3,"z":10,"name":"Soil_Dirt"},{"x":-4,"y":4,"z":10,"name":"Soil_Dirt"},{"x":-4,"y":5,"z":10,"name":"Rock_Stone_Cobble_Mossy"},{"x":-4,"y":0,"z":11,"name":"Soil_Dirt"},{"x":-4,"y":1,"z":11,"name":"Soil_Dirt"},{"x":-4,"y":2,"z":11,"name":"Soil_Dirt"},{"x":-4,"y":3,"z":11,"name":"Soil_Dirt"},{"x":-4,"y":4,"z":11,"name":"Soil_Dirt"},{"x":-4,"y":5,"z":11,"name":"Rock_Stone_Cobble_Mossy"},{"x":-4,"y":0,"z":12,"name":"Soil_Dirt"},{"x":-4,"y":1,"z":12,"name":"Soil_Dirt"},{"x":-4,"y":2,"z":12,"name":"Soil_Dirt"},{"x":-4,"y":3,"z":12,"name":"Soil_Dirt"},{"x":-4,"y":4,"z":12,"name":"Soil_Dirt"},{"x":-4,"y":5,"z":12,"name":"Rock_Stone_Cobble_Mossy"},{"x":-4,"y":0,"z":13,"name":"Soil_Dirt"},{"x":-4,"y":1,"z":13,"name":"Soil_Dirt"},{"x":-4,"y":2,"z":13,"name":"Soil_Dirt"},{"x":-4,"y":3,"z":13,"name":"Soil_Dirt"},{"x":-4,"y":4,"z":13,"name":"Soil_Dirt"},{"x":-4,"y":5,"z":13,"name":"Rock_Stone_Cobble_Mossy"},{"x":-4,"y":0,"z":14,"name":"Soil_Dirt"},{"x":-4,"y":1,"z":14,"name":"Soil_Dirt"},{"x":-4,"y":2,"z":14,"name":"Soil_Dirt"},{"x":-4,"y":3,"z":14,"name":"Soil_Dirt"},{"x":-4,"y":4,"z":14,"name":"Soil_Dirt"},{"x":-4,"y":5,"z":14,"name":"Rock_Stone_Cobble"},{"x":-4,"y":0,"z":15,"name":"Soil_Dirt"},{"x":-4,"y":1,"z":15,"name":"Soil_Dirt"},{"x":-4,"y":2,"z":15,"name":"Soil_Dirt"},{"x":-4,"y":3,"z":15,"name":"Soil_Dirt"},{"x":-4,"y":4,"z":15,"name":"Soil_Dirt"},{"x":-4,"y":5,"z":15,"name":"Rock_Stone_Brick_Smooth"},{"x":-3,"y":0,"z":-14,"name":"Soil_Dirt"},{"x":-3,"y":1,"z":-14,"name":"Soil_Dirt"},{"x":-3,"y":2,"z":-14,"name":"Soil_Dirt"},{"x":-3,"y":3,"z":-14,"name":"Soil_Dirt"},{"x":-3,"y":4,"z":-14,"name":"Soil_Dirt"},{"x":-3,"y":5,"z":-14,"name":"Rock_Stone_Brick_Smooth"},{"x":-3,"y":0,"z":-13,"name":"Soil_Dirt"},{"x":-3,"y":1,"z":-13,"name":"Soil_Dirt"},{"x":-3,"y":2,"z":-13,"name":"Soil_Dirt"},{"x":-3,"y":3,"z":-13,"name":"Soil_Dirt"},{"x":-3,"y":4,"z":-13,"name":"Soil_Dirt"},{"x":-3,"y":5,"z":-13,"name":"Rock_Stone_Cobble"},{"x":-3,"y":0,"z":-12,"name":"Soil_Dirt"},{"x":-3,"y":1,"z":-12,"name":"Soil_Dirt"},{"x":-3,"y":2,"z":-12,"name":"Soil_Dirt"},{"x":-3,"y":3,"z":-12,"name":"Soil_Dirt"},{"x":-3,"y":4,"z":-12,"name":"Soil_Dirt"},{"x":-3,"y":5,"z":-12,"name":"Rock_Stone_Cobble_Mossy"},{"x":-3,"y":0,"z":-11,"name":"Soil_Dirt"},{"x":-3,"y":1,"z":-11,"name":"Soil_Dirt"},{"x":-3,"y":2,"z":-11,"name":"Soil_Dirt"},{"x":-3,"y":3,"z":-11,"name":"Soil_Dirt"},{"x":-3,"y":4,"z":-11,"name":"Soil_Dirt"},{"x":-3,"y":5,"z":-11,"name":"Rock_Stone_Cobble"},{"x":-3,"y":0,"z":-10,"name":"Soil_Dirt"},{"x":-3,"y":1,"z":-10,"name":"Soil_Dirt"},{"x":-3,"y":2,"z":-10,"name":"Soil_Dirt"},{"x":-3,"y":3,"z":-10,"name":"Soil_Dirt"},{"x":-3,"y":4,"z":-10,"name":"Soil_Dirt"},{"x":-3,"y":5,"z":-10,"name":"Rock_Stone_Cobble"},{"x":-3,"y":0,"z":-9,"name":"Soil_Dirt"},{"x":-3,"y":1,"z":-9,"name":"Soil_Dirt"},{"x":-3,"y":2,"z":-9,"name":"Soil_Dirt"},{"x":-3,"y":3,"z":-9,"name":"Soil_Dirt"},{"x":-3,"y":4,"z":-9,"name":"Soil_Dirt"},{"x":-3,"y":5,"z":-9,"name":"Rock_Stone_Cobble"},{"x":-3,"y":0,"z":-8,"name":"Soil_Dirt"},{"x":-3,"y":1,"z":-8,"name":"Soil_Dirt"},{"x":-3,"y":2,"z":-8,"name":"Soil_Dirt"},{"x":-3,"y":3,"z":-8,"name":"Soil_Dirt"},{"x":-3,"y":4,"z":-8,"name":"Soil_Dirt"},{"x":-3,"y":5,"z":-8,"name":"Rock_Stone_Brick_Decorative"},{"x":-3,"y":0,"z":-7,"name":"Soil_Dirt"},{"x":-3,"y":1,"z":-7,"name":"Soil_Dirt"},{"x":-3,"y":2,"z":-7,"name":"Soil_Dirt"},{"x":-3,"y":3,"z":-7,"name":"Soil_Dirt"},{"x":-3,"y":4,"z":-7,"name":"Soil_Dirt"},{"x":-3,"y":5,"z":-7,"name":"Rock_Stone_Brick_Decorative","support":15},{"x":-3,"y":6,"z":-7,"name":"Furniture_Tavern_Planter","support":15},{"x":-3,"y":7,"z":-7,"name":"Plant_Flower_Flax_Pink","support":15},{"x":-3,"y":0,"z":-6,"name":"Soil_Dirt"},{"x":-3,"y":1,"z":-6,"name":"Soil_Dirt"},{"x":-3,"y":2,"z":-6,"name":"Soil_Dirt"},{"x":-3,"y":3,"z":-6,"name":"Soil_Dirt"},{"x":-3,"y":4,"z":-6,"name":"Soil_Dirt"},{"x":-3,"y":5,"z":-6,"name":"Rock_Stone_Cobble_Mossy"},{"x":-3,"y":6,"z":-6,"name":"Rock_Stone_Brick","support":15},{"x":-3,"y":0,"z":-5,"name":"Soil_Dirt"},{"x":-3,"y":1,"z":-5,"name":"Soil_Dirt"},{"x":-3,"y":2,"z":-5,"name":"Soil_Dirt"},{"x":-3,"y":3,"z":-5,"name":"Soil_Dirt"},{"x":-3,"y":4,"z":-5,"name":"Soil_Dirt"},{"x":-3,"y":5,"z":-5,"name":"Rock_Stone_Brick_Mossy","support":15},{"x":-3,"y":0,"z":-4,"name":"Soil_Dirt"},{"x":-3,"y":1,"z":-4,"name":"Soil_Dirt"},{"x":-3,"y":2,"z":-4,"name":"Soil_Dirt"},{"x":-3,"y":3,"z":-4,"name":"Soil_Dirt"},{"x":-3,"y":4,"z":-4,"name":"Soil_Dirt"},{"x":-3,"y":5,"z":-4,"name":"Rock_Stone_Brick_Ornate","support":15},{"x":-3,"y":0,"z":-3,"name":"Soil_Dirt"},{"x":-3,"y":1,"z":-3,"name":"Soil_Dirt"},{"x":-3,"y":2,"z":-3,"name":"Soil_Dirt"},{"x":-3,"y":3,"z":-3,"name":"Soil_Dirt"},{"x":-3,"y":4,"z":-3,"name":"Soil_Dirt"},{"x":-3,"y":5,"z":-3,"name":"Rock_Stone_Brick","support":15},{"x":-3,"y":8,"z":-3,"name":"*Rock_Stone_Brick_Stairs_State_Definitions_Corner_Left","rotation":9},{"x":-3,"y":9,"z":-3,"name":"Rock_Stone_Brick_Smooth_Half"},{"x":-3,"y":0,"z":-2,"name":"Soil_Dirt"},{"x":-3,"y":1,"z":-2,"name":"Soil_Dirt"},{"x":-3,"y":2,"z":-2,"name":"Soil_Dirt"},{"x":-3,"y":3,"z":-2,"name":"Soil_Dirt"},{"x":-3,"y":4,"z":-2,"name":"Soil_Dirt"},{"x":-3,"y":5,"z":-2,"name":"Rock_Stone_Brick"},{"x":-3,"y":8,"z":-2,"name":"*Rock_Stone_Brick_Stairs_State_Definitions_Inverted_Corner_Right","rotation":8},{"x":-3,"y":0,"z":-1,"name":"Soil_Dirt"},{"x":-3,"y":1,"z":-1,"name":"Soil_Dirt"},{"x":-3,"y":2,"z":-1,"name":"Soil_Dirt"},{"x":-3,"y":3,"z":-1,"name":"Soil_Dirt"},{"x":-3,"y":4,"z":-1,"name":"Soil_Dirt"},{"x":-3,"y":5,"z":-1,"name":"Rock_Stone_Brick"},{"x":-3,"y":8,"z":-1,"name":"Rock_Stone_Brick","support":15},{"x":-3,"y":0,"z":0,"name":"Soil_Dirt"},{"x":-3,"y":1,"z":0,"name":"Soil_Dirt"},{"x":-3,"y":2,"z":0,"name":"Soil_Dirt"},{"x":-3,"y":3,"z":0,"name":"Soil_Dirt"},{"x":-3,"y":4,"z":0,"name":"Soil_Dirt"},{"x":-3,"y":5,"z":0,"name":"Rock_Stone_Brick"},{"x":-3,"y":8,"z":0,"name":"Rock_Stone_Brick","support":15},{"x":-3,"y":0,"z":1,"name":"Soil_Dirt"},{"x":-3,"y":1,"z":1,"name":"Soil_Dirt"},{"x":-3,"y":2,"z":1,"name":"Soil_Dirt"},{"x":-3,"y":3,"z":1,"name":"Soil_Dirt"},{"x":-3,"y":4,"z":1,"name":"Soil_Dirt"},{"x":-3,"y":5,"z":1,"name":"Rock_Stone_Brick_Mossy"},{"x":-3,"y":8,"z":1,"name":"Rock_Stone_Brick","support":15},{"x":-3,"y":0,"z":2,"name":"Soil_Dirt"},{"x":-3,"y":1,"z":2,"name":"Soil_Dirt"},{"x":-3,"y":2,"z":2,"name":"Soil_Dirt"},{"x":-3,"y":3,"z":2,"name":"Soil_Dirt"},{"x":-3,"y":4,"z":2,"name":"Soil_Dirt"},{"x":-3,"y":5,"z":2,"name":"Rock_Stone_Brick_Mossy"},{"x":-3,"y":8,"z":2,"name":"Rock_Stone_Brick","support":15},{"x":-3,"y":0,"z":3,"name":"Soil_Dirt"},{"x":-3,"y":1,"z":3,"name":"Soil_Dirt"},{"x":-3,"y":2,"z":3,"name":"Soil_Dirt"},{"x":-3,"y":3,"z":3,"name":"Soil_Dirt"},{"x":-3,"y":4,"z":3,"name":"Soil_Dirt"},{"x":-3,"y":5,"z":3,"name":"Rock_Stone_Brick_Decorative"},{"x":-3,"y":8,"z":3,"name":"*Rock_Stone_Brick_Stairs_State_Definitions_Inverted_Corner_Right","rotation":9},{"x":-3,"y":0,"z":4,"name":"Soil_Dirt"},{"x":-3,"y":1,"z":4,"name":"Soil_Dirt"},{"x":-3,"y":2,"z":4,"name":"Soil_Dirt"},{"x":-3,"y":3,"z":4,"name":"Soil_Dirt"},{"x":-3,"y":4,"z":4,"name":"Soil_Dirt"},{"x":-3,"y":5,"z":4,"name":"Rock_Stone_Brick_Mossy","support":15},{"x":-3,"y":8,"z":4,"name":"*Rock_Stone_Brick_Stairs_State_Definitions_Corner_Left","rotation":10},{"x":-3,"y":9,"z":4,"name":"Rock_Stone_Brick_Smooth_Half"},{"x":-3,"y":0,"z":5,"name":"Soil_Dirt"},{"x":-3,"y":1,"z":5,"name":"Soil_Dirt"},{"x":-3,"y":2,"z":5,"name":"Soil_Dirt"},{"x":-3,"y":3,"z":5,"name":"Soil_Dirt"},{"x":-3,"y":4,"z":5,"name":"Soil_Dirt"},{"x":-3,"y":5,"z":5,"name":"Rock_Stone_Brick_Ornate","support":15},{"x":-3,"y":0,"z":6,"name":"Soil_Dirt"},{"x":-3,"y":1,"z":6,"name":"Soil_Dirt"},{"x":-3,"y":2,"z":6,"name":"Soil_Dirt"},{"x":-3,"y":3,"z":6,"name":"Soil_Dirt"},{"x":-3,"y":4,"z":6,"name":"Soil_Dirt"},{"x":-3,"y":5,"z":6,"name":"Rock_Stone_Brick_Decorative","support":15},{"x":-3,"y":0,"z":7,"name":"Soil_Dirt"},{"x":-3,"y":1,"z":7,"name":"Soil_Dirt"},{"x":-3,"y":2,"z":7,"name":"Soil_Dirt"},{"x":-3,"y":3,"z":7,"name":"Soil_Dirt"},{"x":-3,"y":4,"z":7,"name":"Soil_Dirt"},{"x":-3,"y":5,"z":7,"name":"Rock_Stone_Cobble"},{"x":-3,"y":6,"z":7,"name":"Rock_Stone_Brick_Decorative","support":15},{"x":-3,"y":0,"z":8,"name":"Soil_Dirt"},{"x":-3,"y":1,"z":8,"name":"Soil_Dirt"},{"x":-3,"y":2,"z":8,"name":"Soil_Dirt"},{"x":-3,"y":3,"z":8,"name":"Soil_Dirt"},{"x":-3,"y":4,"z":8,"name":"Soil_Dirt"},{"x":-3,"y":5,"z":8,"name":"Rock_Stone_Brick_Decorative","support":15},{"x":-3,"y":6,"z":8,"name":"Furniture_Tavern_Planter","support":15},{"x":-3,"y":7,"z":8,"name":"Plant_Flower_Common_Grey","support":15},{"x":-3,"y":0,"z":9,"name":"Soil_Dirt"},{"x":-3,"y":1,"z":9,"name":"Soil_Dirt"},{"x":-3,"y":2,"z":9,"name":"Soil_Dirt"},{"x":-3,"y":3,"z":9,"name":"Soil_Dirt"},{"x":-3,"y":4,"z":9,"name":"Soil_Dirt"},{"x":-3,"y":5,"z":9,"name":"Rock_Stone_Brick_Decorative"},{"x":-3,"y":0,"z":10,"name":"Soil_Dirt"},{"x":-3,"y":1,"z":10,"name":"Soil_Dirt"},{"x":-3,"y":2,"z":10,"name":"Soil_Dirt"},{"x":-3,"y":3,"z":10,"name":"Soil_Dirt"},{"x":-3,"y":4,"z":10,"name":"Soil_Dirt"},{"x":-3,"y":5,"z":10,"name":"Rock_Stone_Cobble_Mossy"},{"x":-3,"y":0,"z":11,"name":"Soil_Dirt"},{"x":-3,"y":1,"z":11,"name":"Soil_Dirt"},{"x":-3,"y":2,"z":11,"name":"Soil_Dirt"},{"x":-3,"y":3,"z":11,"name":"Soil_Dirt"},{"x":-3,"y":4,"z":11,"name":"Soil_Dirt"},{"x":-3,"y":5,"z":11,"name":"Rock_Stone_Cobble"},{"x":-3,"y":0,"z":12,"name":"Soil_Dirt"},{"x":-3,"y":1,"z":12,"name":"Soil_Dirt"},{"x":-3,"y":2,"z":12,"name":"Soil_Dirt"},{"x":-3,"y":3,"z":12,"name":"Soil_Dirt"},{"x":-3,"y":4,"z":12,"name":"Soil_Dirt"},{"x":-3,"y":5,"z":12,"name":"Rock_Stone_Cobble"},{"x":-3,"y":0,"z":13,"name":"Soil_Dirt"},{"x":-3,"y":1,"z":13,"name":"Soil_Dirt"},{"x":-3,"y":2,"z":13,"name":"Soil_Dirt"},{"x":-3,"y":3,"z":13,"name":"Soil_Dirt"},{"x":-3,"y":4,"z":13,"name":"Soil_Dirt"},{"x":-3,"y":5,"z":13,"name":"Rock_Stone_Cobble"},{"x":-3,"y":0,"z":14,"name":"Soil_Dirt"},{"x":-3,"y":1,"z":14,"name":"Soil_Dirt"},{"x":-3,"y":2,"z":14,"name":"Soil_Dirt"},{"x":-3,"y":3,"z":14,"name":"Soil_Dirt"},{"x":-3,"y":4,"z":14,"name":"Soil_Dirt"},{"x":-3,"y":5,"z":14,"name":"Rock_Stone_Cobble"},{"x":-3,"y":0,"z":15,"name":"Soil_Dirt"},{"x":-3,"y":1,"z":15,"name":"Soil_Dirt"},{"x":-3,"y":2,"z":15,"name":"Soil_Dirt"},{"x":-3,"y":3,"z":15,"name":"Soil_Dirt"},{"x":-3,"y":4,"z":15,"name":"Soil_Dirt"},{"x":-3,"y":5,"z":15,"name":"Rock_Stone_Brick_Smooth"},{"x":-2,"y":0,"z":-14,"name":"Soil_Dirt"},{"x":-2,"y":1,"z":-14,"name":"Soil_Dirt"},{"x":-2,"y":2,"z":-14,"name":"Soil_Dirt"},{"x":-2,"y":3,"z":-14,"name":"Soil_Dirt"},{"x":-2,"y":4,"z":-14,"name":"Soil_Dirt"},{"x":-2,"y":5,"z":-14,"name":"Rock_Stone_Brick_Smooth"},{"x":-2,"y":0,"z":-13,"name":"Soil_Dirt"},{"x":-2,"y":1,"z":-13,"name":"Soil_Dirt"},{"x":-2,"y":2,"z":-13,"name":"Soil_Dirt"},{"x":-2,"y":3,"z":-13,"name":"Soil_Dirt"},{"x":-2,"y":4,"z":-13,"name":"Soil_Dirt"},{"x":-2,"y":5,"z":-13,"name":"Rock_Stone_Cobble_Mossy"},{"x":-2,"y":0,"z":-12,"name":"Soil_Dirt"},{"x":-2,"y":1,"z":-12,"name":"Soil_Dirt"},{"x":-2,"y":2,"z":-12,"name":"Soil_Dirt"},{"x":-2,"y":3,"z":-12,"name":"Soil_Dirt"},{"x":-2,"y":4,"z":-12,"name":"Soil_Dirt"},