{"version":8,"blockIdVersion":11,"anchorX":0,"anchorY":0,"anchorZ":0,"blocks":[{"x":-14,"y":0,"z":-14,"name":"Soil_Dirt"},{"x":-14,"y":1,"z":-14,"name":"Soil_Dirt"},{"x":-14,"y":2,"z":-14,"name":"Soil_Dirt"},{"x":-14,"y":3,"z":-14,"name":"Soil_Dirt"},{"x":-14,"y":4,"z":-14,"name":"Soil_Dirt"},{"x":-14,"y":5,"z":-14,"name":"Rock_Stone_Brick_Smooth"},{"x":-14,"y":0,"z":-13,"name":"Soil_Dirt"},{"x":-14,"y":1,"z":-13,"name":"Soil_Dirt"},{"x":-14,"y":2,"z":-13,"name":"Soil_Dirt"},{"x":-14,"y":3,"z":-13,"name":"Soil_Dirt"},{"x":-14,"y":4,"z":-13,"name":"Soil_Dirt"},{"x":-14,"y":5,"z":-13,"name":"Rock_Stone_Brick_Smooth"},{"x":-14,"y":0,"z":-12,"name":"Soil_Dirt"},{"x":-14,"y":1,"z":-12,"name":"Soil_Dirt"},{"x":-14,"y":2,"z":-12,"name":"Soil_Dirt"},{"x":-14,"y":3,"z":-12,"name":"Soil_Dirt"},{"x":-14,"y":4,"z":-12,"name":"Soil_Dirt"},{"x":-14,"y":5,"z":-12,"name":"Rock_Stone_Brick_Smooth"},{"x":-14,"y":0,"z":-11,"name":"Soil_Dirt"},{"x":-14,"y":1,"z":-11,"name":"Soil_Dirt"},{"x":-14,"y":2,"z":-11,"name":"Soil_Dirt"},{"x":-14,"y":3,"z":-11,"name":"Soil_Dirt"},{"x":-14,"y":4,"z":-11,"name":"Soil_Dirt"},{"x":-14,"y":5,"z":-11,"name":"Rock_Stone_Brick_Smooth"},{"x":-14,"y":0,"z":-10,"name":"Soil_Dirt"},{"x":-14,"y":1,"z":-10,"name":"Soil_Dirt"},{"x":-14,"y":2,"z":-10,"name":"Soil_Dirt"},{"x":-14,"y":3,"z":-10,"name":"Soil_Dirt"},{"x":-14,"y":4,"z":-10,"name":"Soil_Dirt"},{"x":-14,"y":5,"z":-10,"name":"Rock_Stone_Brick_Smooth"},{"x":-14,"y":0,"z":-9,"name":"Soil_Dirt"},{"x":-14,"y":1,"z":-9,"name":"Soil_Dirt"},{"x":-14,"y":2,"z":-9,"name":"Soil_Dirt"},{"x":-14,"y":3,"z":-9,"name":"Soil_Dirt"},{"x":-14,"y":4,"z":-9,"name":"Soil_Dirt"},{"x":-14,"y":5,"z":-9,"name":"Rock_Stone_Brick_Smooth"},{"x":-14,"y":0,"z":-8,"name":"Soil_Dirt"},{"x":-14,"y":1,"z":-8,"name":"Soil_Dirt"},{"x":-14,"y":2,"z":-8,"name":"Soil_Dirt"},{"x":-14,"y":3,"z":-8,"name":"Soil_Dirt"},{"x":-14,"y":4,"z":-8,"name":"Soil_Dirt"},{"x":-14,"y":5,"z":-8,"name":"Rock_Stone_Brick_Smooth"},{"x":-14,"y":0,"z":-7,"name":"Soil_Dirt"},{"x":-14,"y":1,"z":-7,"name":"Soil_Dirt"},{"x":-14,"y":2,"z":-7,"name":"Soil_Dirt"},{"x":-14,"y":3,"z":-7,"name":"Soil_Dirt"},{"x":-14,"y":4,"z":-7,"name":"Soil_Dirt"},{"x":-14,"y":5,"z":-7,"name":"Rock_Stone_Brick_Smooth"},{"x":-14,"y":0,"z":-6,"name":"Soil_Dirt"},{"x":-14,"y":1,"z":-6,"name":"Soil_Dirt"},{"x":-14,"y":2,"z":-6,"name":"Soil_Dirt"},{"x":-14,"y":3,"z":-6,"name":"Soil_Dirt"},{"x":-14,"y":4,"z":-6,"name":"Soil_Dirt"},{"x":-14,"y":5,"z":-6,"name":"Rock_Stone_Brick_Smooth"},{"x":-14,"y":0,"z":-5,"name":"Soil_Dirt"},{"x":-14,"y":1,"z":-5,"name":"Soil_Dirt"},{"x":-14,"y":2,"z":-5,"name":"Soil_Dirt"},{"x":-14,"y":3,"z":-5,"name":"Soil_Dirt"},{"x":-14,"y":4,"z":-5,"name":"Soil_Dirt"},{"x":-14,"y":5,"z":-5,"name":"Rock_Stone_Brick_Smooth"},{"x":-14,"y":0,"z":-4,"name":"Soil_Dirt"},{"x":-14,"y":1,"z":-4,"name":"Soil_Dirt"},{"x":-14,"y":2,"z":-4,"name":"Soil_Dirt"},{"x":-14,"y":3,"z":-4,"name":"Soil_Dirt"},{"x":-14,"y":4,"z":-4,"name":"Soil_Dirt"},{"x":-14,"y":5,"z":-4,"name":"Rock_Stone_Brick_Smooth"},{"x":-14,"y":0,"z":-3,"name":"Soil_Dirt"},{"x":-14,"y":1,"z":-3,"name":"Soil_Dirt"},{"x":-14,"y":2,"z":-3,"name":"Soil_Dirt"},{"x":-14,"y":3,"z":-3,"name":"Soil_Dirt"},{"x":-14,"y":4,"z":-3,"name":"Soil_Dirt"},{"x":-14,"y":5,"z":-3,"name":"Rock_Stone_Brick_Smooth"},{"x":-14,"y":0,"z":-2,"name":"Soil_Dirt"},{"x":-14,"y":1,"z":-2,"name":"Soil_Dirt"},{"x":-14,"y":2,"z":-2,"name":"Soil_Dirt"},{"x":-14,"y":3,"z":-2,"name":"Soil_Dirt"},{"x":-14,"y":4,"z":-2,"name":"Soil_Dirt"},{"x":-14,"y":5,"z":-2,"name":"Rock_Stone_Brick_Smooth"},{"x":-14,"y":0,"z":-1,"name":"Soil_Dirt"},{"x":-14,"y":1,"z":-1,"name":"Soil_Dirt"},{"x":-14,"y":2,"z":-1,"name":"Soil_Dirt"},{"x":-14,"y":3,"z":-1,"name":"Soil_Dirt"},{"x":-14,"y":4,"z":-1,"name":"Soil_Dirt"},{"x":-14,"y":5,"z":-1,"name":"Rock_Stone_Brick_Smooth"},{"x":-14,"y":0,"z":0,"name":"Soil_Dirt"},{"x":-14,"y":1,"z":0,"name":"Soil_Dirt"},{"x":-14,"y":2,"z":0,"name":"Soil_Dirt"},{"x":-14,"y":3,"z":0,"name":"Soil_Dirt"},{"x":-14,"y":4,"z":0,"name":"Soil_Dirt"},{"x":-14,"y":5,"z":0,"name":"Rock_Stone_Brick_Smooth"},{"x":-14,"y":0,"z":1,"name":"Soil_Dirt"},{"x":-14,"y":1,"z":1,"name":"Soil_Dirt"},{"x":-14,"y":2,"z":1,"name":"Soil_Dirt"},{"x":-14,"y":3,"z":1,"name":"Soil_Dirt"},{"x":-14,"y":4,"z":1,"name":"Soil_Dirt"},{"x":-14,"y":5,"z":1,"name":"Rock_Stone_Brick_Smooth"},{"x":-14,"y":0,"z":2,"name":"Soil_Dirt"},{"x":-14,"y":1,"z":2,"name":"Soil_Dirt"},{"x":-14,"y":2,"z":2,"name":"Soil_Dirt"},{"x":-14,"y":3,"z":2,"name":"Soil_Dirt"},{"x":-14,"y":4,"z":2,"name":"Soil_Dirt"},{"x":-14,"y":5,"z":2,"name":"Rock_Stone_Brick_Smooth"},{"x":-14,"y":0,"z":3,"name":"Soil_Dirt"},{"x":-14,"y":1,"z":3,"name":"Soil_Dirt"},{"x":-14,"y":2,"z":3,"name":"Soil_Dirt"},{"x":-14,"y":3,"z":3,"name":"Soil_Dirt"},{"x":-14,"y":4,"z":3,"name":"Soil_Dirt"},{"x":-14,"y":5,"z":3,"name":"Rock_Stone_Brick_Smooth"},{"x":-14,"y":0,"z":4,"name":"Soil_Dirt"},{"x":-14,"y":1,"z":4,"name":"Soil_Dirt"},{"x":-14,"y":2,"z":4,"name":"Soil_Dirt"},{"x":-14,"y":3,"z":4,"name":"Soil_Dirt"},{"x":-14,"y":4,"z":4,"name":"Soil_Dirt"},{"x":-14,"y":5,"z":4,"name":"Rock_Stone_Brick_Smooth"},{"x":-14,"y":0,"z":5,"name":"Soil_Dirt"},{"x":-14,"y":1,"z":5,"name":"Soil_Dirt"},{"x":-14,"y":2,"z":5,"name":"Soil_Dirt"},{"x":-14,"y":3,"z":5,"name":"Soil_Dirt"},{"x":-14,"y":4,"z":5,"name":"Soil_Dirt"},{"x":-14,"y":5,"z":5,"name":"Rock_Stone_Brick_Smooth"},{"x":-14,"y":0,"z":6,"name":"Soil_Dirt"},{"x":-14,"y":1,"z":6,"name":"Soil_Dirt"},{"x":-14,"y":2,"z":6,"name":"Soil_Dirt"},{"x":-14,"y":3,"z":6,"name":"Soil_Dirt"},{"x":-14,"y":4,"z":6,"name":"Soil_Dirt"},{"x":-14,"y":5,"z":6,"name":"Rock_Stone_Brick_Smooth"},{"x":-14,"y":0,"z":7,"name":"Soil_Dirt"},{"x":-14,"y":1,"z":7,"name":"Soil_Dirt"},{"x":-14,"y":2,"z":7,"name":"Soil_Dirt"},{"x":-14,"y":3,"z":7,"name":"Soil_Dirt"},{"x":-14,"y":4,"z":7,"name":"Soil_Dirt"},{"x":-14,"y":5,"z":7,"name":"Rock_Stone_Brick_Smooth"},{"x":-14,"y":0,"z":8,"name":"Soil_Dirt"},{"x":-14,"y":1,"z":8,"name":"Soil_Dirt"},{"x":-14,"y":2,"z":8,"name":"Soil_Dirt"},{"x":-14,"y":3,"z":8,"name":"Soil_Dirt"},{"x":-14,"y":4,"z":8,"name":"Soil_Dirt"},{"x":-14,"y":5,"z":8,"name":"Rock_Stone_Brick_Smooth"},{"x":-14,"y":0,"z":9,"name":"Soil_Dirt"},{"x":-14,"y":1,"z":9,"name":"Soil_Dirt"},{"x":-14,"y":2,"z":9,"name":"Soil_Dirt"},{"x":-14,"y":3,"z":9,"name":"Soil_Dirt"},{"x":-14,"y":4,"z":9,"name":"Soil_Dirt"},{"x":-14,"y":5,"z":9,"name":"Rock_Stone_Brick_Smooth"},{"x":-14,"y":0,"z":10,"name":"Soil_Dirt"},{"x":-14,"y":1,"z":10,"name":"Soil_Dirt"},{"x":-14,"y":2,"z":10,"name":"Soil_Dirt"},{"x":-14,"y":3,"z":10,"name":"Soil_Dirt"},{"x":-14,"y":4,"z":10,"name":"Soil_Dirt"},{"x":-14,"y":5,"z":10,"name":"Rock_Stone_Brick_Smooth"},{"x":-14,"y":0,"z":11,"name":"Soil_Dirt"},{"x":-14,"y":1,"z":11,"name":"Soil_Dirt"},{"x":-14,"y":2,"z":11,"name":"Soil_Dirt"},{"x":-14,"y":3,"z":11,"name":"Soil_Dirt"},{"x":-14,"y":4,"z":11,"name":"Soil_Dirt"},{"x":-14,"y":5,"z":11,"name":"Rock_Stone_Brick_Smooth"},{"x":-14,"y":0,"z":12,"name":"Soil_Dirt"},{"x":-14,"y":1,"z":12,"name":"Soil_Dirt"},{"x":-14,"y":2,"z":12,"name":"Soil_Dirt"},{"x":-14,"y":3,"z":12,"name":"Soil_Dirt"},{"x":-14,"y":4,"z":12,"name":"Soil_Dirt"},{"x":-14,"y":5,"z":12,"name":"Rock_Stone_Brick_Smooth"},{"x":-14,"y":0,"z":13,"name":"Soil_Dirt"},{"x":-14,"y":1,"z":13,"name":"Soil_Dirt"},{"x":-14,"y":2,"z":13,"name":"Soil_Dirt"},{"x":-14,"y":3,"z":13,"name":"Soil_Dirt"},{"x":-14,"y":4,"z":13,"name":"Soil_Dirt"},{"x":-14,"y":5,"z":13,"name":"Rock_Stone_Brick_Smooth"},{"x":-14,"y":0,"z":14,"name":"Soil_Dirt"},{"x":-14,"y":1,"z":14,"name":"Soil_Dirt"},{"x":-14,"y":2,"z":14,"name":"Soil_Dirt"},{"x":-14,"y":3,"z":14,"name":"Soil_Dirt"},{"x":-14,"y":4,"z":14,"name":"Soil_Dirt"},{"x":-14,"y":5,"z":14,"name":"Rock_Stone_Brick_Smooth"},{"x":-14,"y":0,"z":15,"name":"Soil_Dirt"},{"x":-14,"y":1,"z":15,"name":"Soil_Dirt"},{"x":-14,"y":2,"z":15,"name":"Soil_Dirt"},{"x":-14,"y":3,"z":15,"name":"Soil_Dirt"},{"x":-14,"y":4,"z":15,"name":"Soil_Dirt"},{"x":-14,"y":5,"z":15,"name":"Rock_Stone_Brick_Smooth"},{"x":-13,"y":0,"z":-14,"name":"Soil_Dirt"},{"x":-13,"y":1,"z":-14,"name":"Soil_Dirt"},{"x":-13,"y":2,"z":-14,"name":"Soil_Dirt"},{"x":-13,"y":3,"z":-14,"name":"Soil_Dirt"},{"x":-13,"y":4,"z":-14,"name":"Soil_Dirt"},{"x":-13,"y":5,"z":-14,"name":"Rock_Stone_Brick_Smooth"},{"x":-13,"y":0,"z":-13,"name":"Soil_Dirt"},{"x":-13,"y":1,"z":-13,"name":"Soil_Dirt"},{"x":-13,"y":2,"z":-13,"name":"Soil_Dirt"},{"x":-13,"y":3,"z":-13,"name":"Soil_Dirt"},{"x":-13,"y":4,"z":-13,"name":"Soil_Dirt"},{"x":-13,"y":5,"z":-13,"name":"Soil_Snow"},{"x":-13,"y":0,"z":-12,"name":"Soil_Dirt"},{"x":-13,"y":1,"z":-12,"name":"Soil_Dirt"},{"x":-13,"y":2,"z":-12,"name":"Soil_Dirt"},{"x":-13,"y":3,"z":-12,"name":"Soil_Dirt"},{"x":-13,"y":4,"z":-12,"name":"Soil_Dirt"},{"x":-13,"y":5,"z":-12,"name":"Soil_Snow"},{"x":-13,"y":0,"z":-11,"name":"Soil_Dirt"},{"x":-13,"y":1,"z":-11,"name":"Soil_Dirt"},{"x":-13,"y":2,"z":-11,"name":"Soil_Dirt"},{"x":-13,"y":3,"z":-11,"name":"Soil_Dirt"},{"x":-13,"y":4,"z":-11,"name":"Soil_Dirt"},{"x":-13,"y":5,"z":-11,"name":"Soil_Snow"},{"x":-13,"y":0,"z":-10,"name":"Soil_Dirt"},{"x":-13,"y":1,"z":-10,"name":"Soil_Dirt"},{"x":-13,"y":2,"z":-10,"name":"Soil_Dirt"},{"x":-13,"y":3,"z":-10,"name":"Soil_Dirt"},{"x":-13,"y":4,"z":-10,"name":"Soil_Dirt"},{"x":-13,"y":5,"z":-10,"name":"Soil_Snow"},{"x":-13,"y":0,"z":-9,"name":"Soil_Dirt"},{"x":-13,"y":1,"z":-9,"name":"Soil_Dirt"},{"x":-13,"y":2,"z":-9,"name":"Soil_Dirt"},{"x":-13,"y":3,"z":-9,"name":"Soil_Dirt"},{"x":-13,"y":4,"z":-9,"name":"Soil_Dirt"},{"x":-13,"y":5,"z":-9,"name":"Soil_Snow"},{"x":-13,"y":0,"z":-8,"name":"Soil_Dirt"},{"x":-13,"y":1,"z":-8,"name":"Soil_Dirt"},{"x":-13,"y":2,"z":-8,"name":"Soil_Dirt"},{"x":-13,"y":3,"z":-8,"name":"Soil_Dirt"},{"x":-13,"y":4,"z":-8,"name":"Soil_Dirt"},{"x":-13,"y":5,"z":-8,"name":"Soil_Snow"},{"x":-13,"y":0,"z":-7,"name":"Soil_Dirt"},{"x":-13,"y":1,"z":-7,"name":"Soil_Dirt"},{"x":-13,"y":2,"z":-7,"name":"Soil_Dirt"},{"x":-13,"y":3,"z":-7,"name":"Soil_Dirt"},{"x":-13,"y":4,"z":-7,"name":"Soil_Dirt"},{"x":-13,"y":5,"z":-7,"name":"Soil_Snow"},{"x":-13,"y":0,"z":-6,"name":"Soil_Dirt"},{"x":-13,"y":1,"z":-6,"name":"Soil_Dirt"},{"x":-13,"y":2,"z":-6,"name":"Soil_Dirt"},{"x":-13,"y":3,"z":-6,"name":"Soil_Dirt"},{"x":-13,"y":4,"z":-6,"name":"Soil_Dirt"},{"x":-13,"y":5,"z":-6,"name":"Soil_Snow"},{"x":-13,"y":0,"z":-5,"name":"Soil_Dirt"},{"x":-13,"y":1,"z":-5,"name":"Soil_Dirt"},{"x":-13,"y":2,"z":-5,"name":"Soil_Dirt"},{"x":-13,"y":3,"z":-5,"name":"Soil_Dirt"},{"x":-13,"y":4,"z":-5,"name":"Soil_Dirt"},{"x":-13,"y":5,"z":-5,"name":"Soil_Snow"},{"x":-13,"y":0,"z":-4,"name":"Soil_Dirt"},{"x":-13,"y":1,"z":-4,"name":"Soil_Dirt"},{"x":-13,"y":2,"z":-4,"name":"Soil_Dirt"},{"x":-13,"y":3,"z":-4,"name":"Soil_Dirt"},{"x":-13,"y":4,"z":-4,"name":"Soil_Dirt"},{"x":-13,"y":5,"z":-4,"name":"Soil_Snow"},{"x":-13,"y":0,"z":-3,"name":"Soil_Dirt"},{"x":-13,"y":1,"z":-3,"name":"Soil_Dirt"},{"x":-13,"y":2,"z":-3,"name":"Soil_Dirt"},{"x":-13,"y":3,"z":-3,"name":"Soil_Dirt"},{"x":-13,"y":4,"z":-3,"name":"Soil_Dirt"},{"x":-13,"y":5,"z":-3,"name":"Soil_Snow"},{"x":-13,"y":0,"z":-2,"name":"Soil_Dirt"},{"x":-13,"y":1,"z":-2,"name":"Soil_Dirt"},{"x":-13,"y":2,"z":-2,"name":"Soil_Dirt"},{"x":-13,"y":3,"z":-2,"name":"Soil_Dirt"},{"x":-13,"y":4,"z":-2,"name":"Soil_Dirt"},{"x":-13,"y":5,"z":-2,"name":"Soil_Snow"},{"x":-13,"y":0,"z":-1,"name":"Soil_Dirt"},{"x":-13,"y":1,"z":-1,"name":"Soil_Dirt"},{"x":-13,"y":2,"z":-1,"name":"Soil_Dirt"},{"x":-13,"y":3,"z":-1,"name":"Soil_Dirt"},{"x":-13,"y":4,"z":-1,"name":"Soil_Dirt"},{"x":-13,"y":5,"z":-1,"name":"Soil_Snow"},{"x":-13,"y":0,"z":0,"name":"Soil_Dirt"},{"x":-13,"y":1,"z":0,"name":"Soil_Dirt"},{"x":-13,"y":2,"z":0,"name":"Soil_Dirt"},{"x":-13,"y":3,"z":0,"name":"Soil_Dirt"},{"x":-13,"y":4,"z":0,"name":"Soil_Dirt"},{"x":-13,"y":5,"z":0,"name":"Soil_Snow"},{"x":-13,"y":0,"z":1,"name":"Soil_Dirt"},{"x":-13,"y":1,"z":1,"name":"Soil_Dirt"},{"x":-13,"y":2,"z":1,"name":"Soil_Dirt"},{"x":-13,"y":3,"z":1,"name":"Soil_Dirt"},{"x":-13,"y":4,"z":1,"name":"Soil_Dirt"},{"x":-13,"y":5,"z":1,"name":"Soil_Snow"},{"x":-13,"y":0,"z":2,"name":"Soil_Dirt"},{"x":-13,"y":1,"z":2,"name":"Soil_Dirt"},{"x":-13,"y":2,"z":2,"name":"Soil_Dirt"},{"x":-13,"y":3,"z":2,"name":"Soil_Dirt"},{"x":-13,"y":4,"z":2,"name":"Soil_Dirt"},{"x":-13,"y":5,"z":2,"name":"Soil_Snow"},{"x":-13,"y":0,"z":3,"name":"Soil_Dirt"},{"x":-13,"y":1,"z":3,"name":"Soil_Dirt"},{"x":-13,"y":2,"z":3,"name":"Soil_Dirt"},{"x":-13,"y":3,"z":3,"name":"Soil_Dirt"},{"x":-13,"y":4,"z":3,"name":"Soil_Dirt"},{"x":-13,"y":5,"z":3,"name":"Soil_Snow"},{"x":-13,"y":0,"z":4,"name":"Soil_Dirt"},{"x":-13,"y":1,"z":4,"name":"Soil_Dirt"},{"x":-13,"y":2,"z":4,"name":"Soil_Dirt"},{"x":-13,"y":3,"z":4,"name":"Soil_Dirt"},{"x":-13,"y":4,"z":4,"name":"Soil_Dirt"},{"x":-13,"y":5,"z":4,"name":"Soil_Snow"},{"x":-13,"y":0,"z":5,"name":"Soil_Dirt"},{"x":-13,"y":1,"z":5,"name":"Soil_Dirt"},{"x":-13,"y":2,"z":5,"name":"Soil_Dirt"},{"x":-13,"y":3,"z":5,"name":"Soil_Dirt"},{"x":-13,"y":4,"z":5,"name":"Soil_Dirt"},{"x":-13,"y":5,"z":5,"name":"Soil_Snow"},{"x":-13,"y":0,"z":6,"name":"Soil_Dirt"},{"x":-13,"y":1,"z":6,"name":"Soil_Dirt"},{"x":-13,"y":2,"z":6,"name":"Soil_Dirt"},{"x":-13,"y":3,"z":6,"name":"Soil_Dirt"},{"x":-13,"y":4,"z":6,"name":"Soil_Dirt"},{"x":-13,"y":5,"z":6,"name":"Soil_Snow"},{"x":-13,"y":0,"z":7,"name":"Soil_Dirt"},{"x":-13,"y":1,"z":7,"name":"Soil_Dirt"},{"x":-13,"y":2,"z":7,"name":"Soil_Dirt"},{"x":-13,"y":3,"z":7,"name":"Soil_Dirt"},{"x":-13,"y":4,"z":7,"name":"Soil_Dirt"},{"x":-13,"y":5,"z":7,"name":"Soil_Snow"},{"x":-13,"y":0,"z":8,"name":"Soil_Dirt"},{"x":-13,"y":1,"z":8,"name":"Soil_Dirt"},{"x":-13,"y":2,"z":8,"name":"Soil_Dirt"},{"x":-13,"y":3,"z":8,"name":"Soil_Dirt"},{"x":-13,"y":4,"z":8,"name":"Soil_Dirt"},{"x":-13,"y":5,"z":8,"name":"Soil_Snow"},{"x":-13,"y":0,"z":9,"name":"Soil_Dirt"},{"x":-13,"y":1,"z":9,"name":"Soil_Dirt"},{"x":-13,"y":2,"z":9,"name":"Soil_Dirt"},{"x":-13,"y":3,"z":9,"name":"Soil_Dirt"},{"x":-13,"y":4,"z":9,"name":"Soil_Dirt"},{"x":-13,"y":5,"z":9,"name":"Soil_Snow"},{"x":-13,"y":0,"z":10,"name":"Soil_Dirt"},{"x":-13,"y":1,"z":10,"name":"Soil_Dirt"},{"x":-13,"y":2,"z":10,"name":"Soil_Dirt"},{"x":-13,"y":3,"z":10,"name":"Soil_Dirt"},{"x":-13,"y":4,"z":10,"name":"Soil_Dirt"},{"x":-13,"y":5,"z":10,"name":"Soil_Snow"},{"x":-13,"y":0,"z":11,"name":"Soil_Dirt"},{"x":-13,"y":1,"z":11,"name":"Soil_Dirt"},{"x":-13,"y":2,"z":11,"name":"Soil_Dirt"},{"x":-13,"y":3,"z":11,"name":"Soil_Dirt"},{"x":-13,"y":4,"z":11,"name":"Soil_Dirt"},{"x":-13,"y":5,"z":11,"name":"Soil_Snow"},{"x":-13,"y":0,"z":12,"name":"Soil_Dirt"},{"x":-13,"y":1,"z":12,"name":"Soil_Dirt"},{"x":-13,"y":2,"z":12,"name":"Soil_Dirt"},{"x":-13,"y":3,"z":12,"name":"Soil_Dirt"},{"x":-13,"y":4,"z":12,"name":"Soil_Dirt"},{"x":-13,"y":5,"z":12,"name":"Soil_Snow"},{"x":-13,"y":0,"z":13,"name":"Soil_Dirt"},{"x":-13,"y":1,"z":13,"name":"Soil_Dirt"},{"x":-13,"y":2,"z":13,"name":"Soil_Dirt"},{"x":-13,"y":3,"z":13,"name":"Soil_Dirt"},{"x":-13,"y":4,"z":13,"name":"Soil_Dirt"},{"x":-13,"y":5,"z":13,"name":"Soil_Snow"},{"x":-13,"y":0,"z":14,"name":"Soil_Dirt"},{"x":-13,"y":1,"z":14,"name":"Soil_Dirt"},{"x":-13,"y":2,"z":14,"name":"Soil_Dirt"},{"x":-13,"y":3,"z":14,"name":"Soil_Dirt"},{"x":-13,"y":4,"z":14,"name":"Soil_Dirt"},{"x":-13,"y":5,"z":14,"name":"Soil_Snow"},{"x":-13,"y":0,"z":15,"name":"Soil_Dirt"},{"x":-13,"y":1,"z":15,"name":"Soil_Dirt"},{"x":-13,"y":2,"z":15,"name":"Soil_Dirt"},{"x":-13,"y":3,"z":15,"name":"Soil_Dirt"},{"x":-13,"y":4,"z":15,"name":"Soil_Dirt"},{"x":-13,"y":5,"z":15,"name":"Rock_Stone_Brick_Smooth"},{"x":-12,"y":0,"z":-14,"name":"Soil_Dirt"},{"x":-12,"y":1,"z":-14,"name":"Soil_Dirt"},{"x":-12,"y":2,"z":-14,"name":"Soil_Dirt"},{"x":-12,"y":3,"z":-14,"name":"Soil_Dirt"},{"x":-12,"y":4,"z":-14,"name":"Soil_Dirt"},{"x":-12,"y":5,"z":-14,"name":"Rock_Stone_Brick_Smooth"},{"x":-12,"y":0,"z":-13,"name":"Soil_Dirt"},{"x":-12,"y":1,"z":-13,"name":"Soil_Dirt"},{"x":-12,"y":2,"z":-13,"name":"Soil_Dirt"},{"x":-12,"y":3,"z":-13,"name":"Soil_Dirt"},{"x":-12,"y":4,"z":-13,"name":"Soil_Dirt"},{"x":-12,"y":5,"z":-13,"name":"Soil_Snow"},{"x":-12,"y":0,"z":-12,"name":"Soil_Dirt"},{"x":-12,"y":1,"z":-12,"name":"Soil_Dirt"},{"x":-12,"y":2,"z":-12,"name":"Soil_Dirt"},{"x":-12,"y":3,"z":-12,"name":"Soil_Dirt"},{"x":-12,"y":4,"z":-12,"name":"Soil_Dirt"},{"x":-12,"y":5,"z":-12,"name":"Soil_Snow"},{"x":-12,"y":0,"z":-11,"name":"Soil_Dirt"},{"x":-12,"y":1,"z":-11,"name":"Soil_Dirt"},{"x":-12,"y":2,"z":-11,"name":"Soil_Dirt"},{"x":-12,"y":3,"z":-11,"name":"Soil_Dirt"},{"x":-12,"y":4,"z":-11,"name":"Soil_Dirt"},{"x":-12,"y":5,"z":-11,"name":"Soil_Snow"},{"x":-12,"y":0,"z":-10,"name":"Soil_Dirt"},{"x":-12,"y":1,"z":-10,"name":"Soil_Dirt"},{"x":-12,"y":2,"z":-10,"name":"Soil_Dirt"},{"x":-12,"y":3,"z":-10,"name":"Soil_Dirt"},{"x":-12,"y":4,"z":-10,"name":"Soil_Dirt"},{"x":-12,"y":5,"z":-10,"name":"Soil_Snow"},{"x":-12,"y":0,"z":-9,"name":"Soil_Dirt"},{"x":-12,"y":1,"z":-9,"name":"Soil_Dirt"},{"x":-12,"y":2,"z":-9,"name":"Soil_Dirt"},{"x":-12,"y":3,"z":-9,"name":"Soil_Dirt"},{"x":-12,"y":4,"z":-9,"name":"Soil_Dirt"},{"x":-12,"y":5,"z":-9,"name":"Soil_Snow"},{"x":-12,"y":0,"z":-8,"name":"Soil_Dirt"},{"x":-12,"y":1,"z":-8,"name":"Soil_Dirt"},{"x":-12,"y":2,"z":-8,"name":"Soil_Dirt"},{"x":-12,"y":3,"z":-8,"name":"Soil_Dirt"},{"x":-12,"y":4,"z":-8,"name":"Soil_Dirt"},{"x":-12,"y":5,"z":-8,"name":"Soil_Snow"},{"x":-12,"y":0,"z":-7,"name":"Soil_Dirt"},{"x":-12,"y":1,"z":-7,"name":"Soil_Dirt"},{"x":-12,"y":2,"z":-7,"name":"Soil_Dirt"},{"x":-12,"y":3,"z":-7,"name":"Soil_Dirt"},{"x":-12,"y":4,"z":-7,"name":"Soil_Dirt"},{"x":-12,"y":5,"z":-7,"name":"Soil_Snow"},{"x":-12,"y":0,"z":-6,"name":"Soil_Dirt"},{"x":-12,"y":1,"z":-6,"name":"Soil_Dirt"},{"x":-12,"y":2,"z":-6,"name":"Soil_Dirt"},{"x":-12,"y":3,"z":-6,"name":"Soil_Dirt"},{"x":-12,"y":4,"z":-6,"name":"Soil_Dirt"},{"x":-12,"y":5,"z":-6,"name":"Soil_Snow"},{"x":-12,"y":6,"z":-6,"name":"Soil_Snow_Half","support":15},{"x":-12,"y":0,"z":-5,"name":"Soil_Dirt"},{"x":-12,"y":1,"z":-5,"name":"Soil_Dirt"},{"x":-12,"y":2,"z":-5,"name":"Soil_Dirt"},{"x":-12,"y":3,"z":-5,"name":"Soil_Dirt"},{"x":-12,"y":4,"z":-5,"name":"Soil_Dirt"},{"x":-12,"y":5,"z":-5,"name":"Soil_Snow"},{"x":-12,"y":6,"z":-5,"name":"Soil_Snow_Half","support":15},{"x":-12,"y":0,"z":-4,"name":"Soil_Dirt"},{"x":-12,"y":1,"z":-4,"name":"Soil_Dirt"},{"x":-12,"y":2,"z":-4,"name":"Soil_Dirt"},{"x":-12,"y":3,"z":-4,"name":"Soil_Dirt"},{"x":-12,"y":4,"z":-4,"name":"Soil_Dirt"},{"x":-12,"y":5,"z":-4,"name":"Soil_Snow"},{"x":-12,"y":0,"z":-3,"name":"Soil_Dirt"},{"x":-12,"y":1,"z":-3,"name":"Soil_Dirt"},{"x":-12,"y":2,"z":-3,"name":"Soil_Dirt"},{"x":-12,"y":3,"z":-3,"name":"Soil_Dirt"},{"x":-12,"y":4,"z":-3,"name":"Soil_Dirt"},{"x":-12,"y":5,"z":-3,"name":"Soil_Snow"},{"x":-12,"y":0,"z":-2,"name":"Soil_Dirt"},{"x":-12,"y":1,"z":-2,"name":"Soil_Dirt"},{"x":-12,"y":2,"z":-2,"name":"Soil_Dirt"},{"x":-12,"y":3,"z":-2,"name":"Soil_Dirt"},{"x":-12,"y":4,"z":-2,"name":"Soil_Dirt"},{"x":-12,"y":5,"z":-2,"name":"Soil_Snow"},{"x":-12,"y":0,"z":-1,"name":"Soil_Dirt"},{"x":-12,"y":1,"z":-1,"name":"Soil_Dirt"},{"x":-12,"y":2,"z":-1,"name":"Soil_Dirt"},{"x":-12,"y":3,"z":-1,"name":"Soil_Dirt"},{"x":-12,"y":4,"z":-1,"name":"Soil_Dirt"},{"x":-12,"y":5,"z":-1,"name":"Soil_Snow"},{"x":-12,"y":0,"z":0,"name":"Soil_Dirt"},{"x":-12,"y":1,"z":0,"name":"Soil_Dirt"},{"x":-12,"y":2,"z":0,"name":"Soil_Dirt"},{"x":-12,"y":3,"z":0,"name":"Soil_Dirt"},{"x":-12,"y":4,"z":0,"name":"Soil_Dirt"},{"x":-12,"y":5,"z":0,"name":"Soil_Snow"},{"x":-12,"y":6,"z":0,"name":"Soil_Snow_Half","support":15},{"x":-12,"y":0,"z":1,"name":"Soil_Dirt"},{"x":-12,"y":1,"z":1,"name":"Soil_Dirt"},{"x":-12,"y":2,"z":1,"name":"Soil_Dirt"},{"x":-12,"y":3,"z":1,"name":"Soil_Dirt"},{"x":-12,"y":4,"z":1,"name":"Soil_Dirt"},{"x":-12,"y":5,"z":1,"name":"Soil_Snow"},{"x":-12,"y":0,"z":2,"name":"Soil_Dirt"},{"x":-12,"y":1,"z":2,"name":"Soil_Dirt"},{"x":-12,"y":2,"z":2,"name":"Soil_Dirt"},{"x":-12,"y":3,"z":2,"name":"Soil_Dirt"},{"x":-12,"y":4,"z":2,"name":"Soil_Dirt"},{"x":-12,"y":5,"z":2,"name":"Soil_Snow"},{"x":-12,"y":0,"z":3,"name":"Soil_Dirt"},{"x":-12,"y":1,"z":3,"name":"Soil_Dirt"},{"x":-12,"y":2,"z":3,"name":"Soil_Dirt"},{"x":-12,"y":3,"z":3,"name":"Soil_Dirt"},{"x":-12,"y":4,"z":3,"name":"Soil_Dirt"},{"x":-12,"y":5,"z":3,"name":"Soil_Snow"},{"x":-12,"y":0,"z":4,"name":"Soil_Dirt"},{"x":-12,"y":1,"z":4,"name":"Soil_Dirt"},{"x":-12,"y":2,"z":4,"name":"Soil_Dirt"},{"x":-12,"y":3,"z":4,"name":"Soil_Dirt"},{"x":-12,"y":4,"z":4,"name":"Soil_Dirt"},{"x":-12,"y":5,"z":4,"name":"Soil_Snow"},{"x":-12,"y":0,"z":5,"name":"Soil_Dirt"},{"x":-12,"y":1,"z":5,"name":"Soil_Dirt"},{"x":-12,"y":2,"z":5,"name":"Soil_Dirt"},{"x":-12,"y":3,"z":5,"name":"Soil_Dirt"},{"x":-12,"y":4,"z":5,"name":"Soil_Dirt"},{"x":-12,"y":5,"z":5,"name":"Soil_Snow"},{"x":-12,"y":0,"z":6,"name":"Soil_Dirt"},{"x":-12,"y":1,"z":6,"name":"Soil_Dirt"},{"x":-12,"y":2,"z":6,"name":"Soil_Dirt"},{"x":-12,"y":3,"z":6,"name":"Soil_Dirt"},{"x":-12,"y":4,"z":6,"name":"Soil_Dirt"},{"x":-12,"y":5,"z":6,"name":"Soil_Snow"},{"x":-12,"y":0,"z":7,"name":"Soil_Dirt"},{"x":-12,"y":1,"z":7,"name":"Soil_Dirt"},{"x":-12,"y":2,"z":7,"name":"Soil_Dirt"},{"x":-12,"y":3,"z":7,"name":"Soil_Dirt"},{"x":-12,"y":4,"z":7,"name":"Soil_Dirt"},{"x":-12,"y":5,"z":7,"name":"Soil_Snow"},{"x":-12,"y":0,"z":8,"name":"Soil_Dirt"},{"x":-12,"y":1,"z":8,"name":"Soil_Dirt"},{"x":-12,"y":2,"z":8,"name":"Soil_Dirt"},{"x":-12,"y":3,"z":8,"name":"Soil_Dirt"},{"x":-12,"y":4,"z":8,"name":"Soil_Dirt"},{"x":-12,"y":5,"z":8,"name":"Soil_Snow"},{"x":-12,"y":0,"z":9,"name":"Soil_Dirt"},{"x":-12,"y":1,"z":9,"name":"Soil_Dirt"},{"x":-12,"y":2,"z":9,"name":"Soil_Dirt"},{"x":-12,"y":3,"z":9,"name":"Soil_Dirt"},{"x":-12,"y":4,"z":9,"name":"Soil_Dirt"},{"x":-12,"y":5,"z":9,"name":"Soil_Snow"},{"x":-12,"y":0,"z":10,"name":"Soil_Dirt"},{"x":-12,"y":1,"z":10,"name":"Soil_Dirt"},{"x":-12,"y":2,"z":10,"name":"Soil_Dirt"},{"x":-12,"y":3,"z":10,"name":"Soil_Dirt"},{"x":-12,"y":4,"z":10,"name":"Soil_Dirt"},{"x":-12,"y":5,"z":10,"name":"Soil_Snow"},{"x":-12,"y":0,"z":11,"name":"Soil_Dirt"},{"x":-12,"y":1,"z":11,"name":"Soil_Dirt"},{"x":-12,"y":2,"z":11,"name":"Soil_Dirt"},{"x":-12,"y":3,"z":11,"name":"Soil_Dirt"},{"x":-12,"y":4,"z":11,"name":"Soil_Dirt"},{"x":-12,"y":5,"z":11,"name":"Soil_Snow"},{"x":-12,"y":0,"z":12,"name":"Soil_Dirt"},{"x":-12,"y":1,"z":12,"name":"Soil_Dirt"},{"x":-12,"y":2,"z":12,"name":"Soil_Dirt"},{"x":-12,"y":3,"z":12,"name":"Soil_Dirt"},{"x":-12,"y":4,"z":12,"name":"Soil_Dirt"},{"x":-12,"y":5,"z":12,"name":"Soil_Snow"},{"x":-12,"y":0,"z":13,"name":"Soil_Dirt"},{"x":-12,"y":1,"z":13,"name":"Soil_Dirt"},{"x":-12,"y":2,"z":13,"name":"Soil_Dirt"},{"x":-12,"y":3,"z":13,"name":"Soil_Dirt"},{"x":-12,"y":4,"z":13,"name":"Soil_Dirt"},{"x":-12,"y":5,"z":13,"name":"Soil_Snow"},{"x":-12,"y":0,"z":14,"name":"Soil_Dirt"},{"x":-12,"y":1,"z":14,"name":"Soil_Dirt"},{"x":-12,"y":2,"z":14,"name":"Soil_Dirt"},{"x":-12,"y":3,"z":14,"name":"Soil_Dirt"},{"x":-12,"y":4,"z":14,"name":"Soil_Dirt"},{"x":-12,"y":5,"z":14,"name":"Soil_Snow"},{"x":-12,"y":0,"z":15,"name":"Soil_Dirt"},{"x":-12,"y":1,"z":15,"name":"Soil_Dirt"},{"x":-12,"y":2,"z":15,"name":"Soil_Dirt"},{"x":-12,"y":3,"z":15,"name":"Soil_Dirt"},{"x":-12,"y":4,"z":15,"name":"Soil_Dirt"},{"x":-12,"y":5,"z":15,"name":"Rock_Stone_Brick_Smooth"},{"x":-11,"y":0,"z":-14,"name":"Soil_Dirt"},{"x":-11,"y":1,"z":-14,"name":"Soil_Dirt"},{"x":-11,"y":2,"z":-14,"name":"Soil_Dirt"},{"x":-11,"y":3,"z":-14,"name":"Soil_Dirt"},{"x":-11,"y":4,"z":-14,"name":"Soil_Dirt"},{"x":-11,"y":5,"z":-14,"name":"Rock_Stone_Brick_Smooth"},{"x":-11,"y":0,"z":-13,"name":"Soil_Dirt"},{"x":-11,"y":1,"z":-13,"name":"Soil_Dirt"},{"x":-11,"y":2,"z":-13,"name":"Soil_Dirt"},{"x":-11,"y":3,"z":-13,"name":"Soil_Dirt"},{"x":-11,"y":4,"z":-13,"name":"Soil_Dirt"},{"x":-11,"y":5,"z":-13,"name":"Soil_Snow"},{"x":-11,"y":0,"z":-12,"name":"Soil_Dirt"},{"x":-11,"y":1,"z":-12,"name":"Soil_Dirt"},{"x":-11,"y":2,"z":-12,"name":"Soil_Dirt"},{"x":-11,"y":3,"z":-12,"name":"Soil_Dirt"},{"x":-11,"y":4,"z":-12,"name":"Soil_Dirt"},{"x":-11,"y":5,"z":-12,"name":"Soil_Snow"},{"x":-11,"y":0,"z":-11,"name":"Soil_Dirt"},{"x":-11,"y":1,"z":-11,"name":"Soil_Dirt"},{"x":-11,"y":2,"z":-11,"name":"Soil_Dirt"},{"x":-11,"y":3,"z":-11,"name":"Soil_Dirt"},{"x":-11,"y":4,"z":-11,"name":"Soil_Dirt"},{"x":-11,"y":5,"z":-11,"name":"Soil_Snow"},{"x":-11,"y":6,"z":-11,"name":"WinterHoliday_Snowman","support":15,"rotation":1},{"x":-11,"y":7,"z":-11,"name":"WinterHoliday_Snowman","filler":1024,"rotation":1},{"x":-11,"y":0,"z":-10,"name":"Soil_Dirt"},{"x":-11,"y":1,"z":-10,"name":"Soil_Dirt"},{"x":-11,"y":2,"z":-10,"name":"Soil_Dirt"},{"x":-11,"y":3,"z":-10,"name":"Soil_Dirt"},{"x":-11,"y":4,"z":-10,"name":"Soil_Dirt"},{"x":-11,"y":5,"z":-10,"name":"Soil_Snow"},{"x":-11,"y":0,"z":-9,"name":"Soil_Dirt"},{"x":-11,"y":1,"z":-9,"name":"Soil_Dirt"},{"x":-11,"y":2,"z":-9,"name":"Soil_Dirt"},{"x":-11,"y":3,"z":-9,"name":"Soil_Dirt"},{"x":-11,"y":4,"z":-9,"name":"Soil_Dirt"},{"x":-11,"y":5,"z":-9,"name":"Soil_Snow"},{"x":-11,"y":0,"z":-8,"name":"Soil_Dirt"},{"x":-11,"y":1,"z":-8,"name":"Soil_Dirt"},{"x":-11,"y":2,"z":-8,"name":"Soil_Dirt"},{"x":-11,"y":3,"z":-8,"name":"Soil_Dirt"},{"x":-11,"y":4,"z":-8,"name":"Soil_Dirt"},{"x":-11,"y":5,"z":-8,"name":"Soil_Snow"},{"x":-11,"y":0,"z":-7,"name":"Soil_Dirt"},{"x":-11,"y":1,"z":-7,"name":"Soil_Dirt"},{"x":-11,"y":2,"z":-7,"name":"Soil_Dirt"},{"x":-11,"y":3,"z":-7,"name":"Soil_Dirt"},{"x":-11,"y":4,"z":-7,"name":"Soil_Dirt"},{"x":-11,"y":5,"z":-7,"name":"Soil_Snow"},{"x":-11,"y":6,"z":-7,"name":"Soil_Snow_Half","support":15},{"x":-11,"y":0,"z":-6,"name":"Soil_Dirt"},{"x":-11,"y":1,"z":-6,"name":"Soil_Dirt"},{"x":-11,"y":2,"z":-6,"name":"Soil_Dirt"},{"x":-11,"y":3,"z":-6,"name":"Soil_Dirt"},{"x":-11,"y":4,"z":-6,"name":"Soil_Dirt"},{"x":-11,"y":5,"z":-6,"name":"Soil_Snow"},{"x":-11,"y":6,"z":-6,"name":"Soil_Snow_Half","support":15},{"x":-11,"y":0,"z":-5,"name":"Soil_Dirt"},{"x":-11,"y":1,"z":-5,"name":"Soil_Dirt"},{"x":-11,"y":2,"z":-5,"name":"Soil_Dirt"},{"x":-11,"y":3,"z":-5,"name":"Soil_Dirt"},{"x":-11,"y":4,"z":-5,"name":"Soil_Dirt"},{"x":-11,"y":5,"z":-5,"name":"Soil_Snow"},{"x":-11,"y":6,"z":-5,"name":"Soil_Snow_Half","support":15},{"x":-11,"y":0,"z":-4,"name":"Soil_Dirt"},{"x":-11,"y":1,"z":-4,"name":"Soil_Dirt"},{"x":-11,"y":2,"z":-4,"name":"Soil_Dirt"},{"x":-11,"y":3,"z":-4,"name":"Soil_Dirt"},{"x":-11,"y":4,"z":-4,"name":"Soil_Dirt"},{"x":-11,"y":5,"z":-4,"name":"Soil_Snow"},{"x":-11,"y":6,"z":-4,"name":"Furniture_Frozen_Castle_Secondary_Lamp","support":15},{"x":-11,"y":0,"z":-3,"name":"Soil_Dirt"},{"x":-11,"y":1,"z":-3,"name":"Soil_Dirt"},{"x":-11,"y":2,"z":-3,"name":"Soil_Dirt"},{"x":-11,"y":3,"z":-3,"name":"Soil_Dirt"},{"x":-11,"y":4,"z":-3,"name":"Soil_Dirt"},{"x":-11,"y":5,"z":-3,"name":"Soil_Snow"},{"x":-11,"y":0,"z":-2,"name":"Soil_Dirt"},{"x":-11,"y":1,"z":-2,"name":"Soil_Dirt"},{"x":-11,"y":2,"z":-2,"name":"Soil_Dirt"},{"x":-11,"y":3,"z":-2,"name":"Soil_Dirt"},{"x":-11,"y":4,"z":-2,"name":"Soil_Dirt"},{"x":-11,"y":5,"z":-2,"name":"Soil_Snow"},{"x":-11,"y":0,"z":-1,"name":"Soil_Dirt"},{"x":-11,"y":1,"z":-1,"name":"Soil_Dirt"},{"x":-11,"y":2,"z":-1,"name":"Soil_Dirt"},{"x":-11,"y":3,"z":-1,"name":"Soil_Dirt"},{"x":-11,"y":4,"z":-1,"name":"Soil_Dirt"},{"x":-11,"y":5,"z":-1,"name":"Soil_Snow"},{"x":-11,"y":6,"z":-1,"name":"Soil_Snow_Half","support":15},{"x":-11,"y":0,"z":0,"name":"Soil_Dirt"},{"x":-11,"y":1,"z":0,"name":"Soil_Dirt"},{"x":-11,"y":2,"z":0,"name":"Soil_Dirt"},{"x":-11,"y":3,"z":0,"name":"Soil_Dirt"},{"x":-11,"y":4,"z":0,"name":"Soil_Dirt"},{"x":-11,"y":5,"z":0,"name":"Soil_Snow"},{"x":-11,"y":6,"z":0,"name":"*Soil_Snow_Half_State_Definitions_Block"},{"x":-11,"y":0,"z":1,"name":"Soil_Dirt"},{"x":-11,"y":1,"z":1,"name":"Soil_Dirt"},{"x":-11,"y":2,"z":1,"name":"Soil_Dirt"},{"x":-11,"y":3,"z":1,"name":"Soil_Dirt"},{"x":-11,"y":4,"z":1,"name":"Soil_Dirt"},{"x":-11,"y":5,"z":1,"name":"Soil_Snow"},{"x":-11,"y":6,"z":1,"name":"Soil_Snow_Half","support":15},{"x":-11,"y":0,"z":2,"name":"Soil_Dirt"},{"x":-11,"y":1,"z":2,"name":"Soil_Dirt"},{"x":-11,"y":2,"z":2,"name":"Soil_Dirt"},{"x":-11,"y":3,"z":2,"name":"Soil_Dirt"},{"x":-11,"y":4,"z":2,"name":"Soil_Dirt"},{"x":-11,"y":5,"z":2,"name":"Soil_Snow"},{"x":-11,"y":0,"z":3,"name":"Soil_Dirt"},{"x":-11,"y":1,"z":3,"name":"Soil_Dirt"},{"x":-11,"y":2,"z":3,"name":"Soil_Dirt"},{"x":-11,"y":3,"z":3,"name":"Soil_Dirt"},{"x":-11,"y":4,"z":3,"name":"Soil_Dirt"},{"x":-11,"y":5,"z":3,"name":"Soil_Snow"},{"x":-11,"y":0,"z":4,"name":"Soil_Dirt"},{"x":-11,"y":1,"z":4,"name":"Soil_Dirt"},{"x":-11,"y":2,"z":4,"name":"Soil_Dirt"},{"x":-11,"y":3,"z":4,"name":"Soil_Dirt"},{"x":-11,"y":4,"z":4,"name":"Soil_Dirt"},{"x":-11,"y":5,"z":4,"name":"Soil_Snow"},{"x":-11,"y":0,"z":5,"name":"Soil_Dirt"},{"x":-11,"y":1,"z":5,"name":"Soil_Dirt"},{"x":-11,"y":2,"z":5,"name":"Soil_Dirt"},{"x":-11,"y":3,"z":5,"name":"Soil_Dirt"},{"x":-11,"y":4,"z":5,"name":"Soil_Dirt"},{"x":-11,"y":5,"z":5,"name":"Soil_Snow"},{"x":-11,"y":0,"z":6,"name":"Soil_Dirt"},{"x":-11,"y":1,"z":6,"name":"Soil_Dirt"},{"x":-11,"y":2,"z":6,"name":"Soil_Dirt"},{"x":-11,"y":3,"z":6,"name":"Soil_Dirt"},{"x":-11,"y":4,"z":6,"name":"Soil_Dirt"},{"x":-11,"y":5,"z":6,"name":"Soil_Snow"},{"x":-11,"y":6,"z":6,"name":"WinterHoliday_Snowflake","support":15,"rotation":1},{"x":-11,"y":0,"z":7,"name":"Soil_Dirt"},{"x":-11,"y":1,"z":7,"name":"Soil_Dirt"},{"x":-11,"y":2,"z":7,"name":"Soil_Dirt"},{"x":-11,"y":3,"z":7,"name":"Soil_Dirt"},{"x":-11,"y":4,"z":7,"name":"Soil_Dirt"},{"x":-11,"y":5,"z":7,"name":"Soil_Snow"},{"x":-11,"y":0,"z":8,"name":"Soil_Dirt"},{"x":-11,"y":1,"z":8,"name":"Soil_Dirt"},{"x":-11,"y":2,"z":8,"name":"Soil_Dirt"},{"x":-11,"y":3,"z":8,"name":"Soil_Dirt"},{"x":-11,"y":4,"z":8,"name":"Soil_Dirt"},{"x":-11,"y":5,"z":8,"name":"Soil_Snow"},{"x":-11,"y":0,"z":9,"name":"Soil_Dirt"},{"x":-11,"y":1,"z":9,"name":"Soil_Dirt"},{"x":-11,"y":2,"z":9,"name":"Soil_Dirt"},{"x":-11,"y":3,"z":9,"name":"Soil_Dirt"},{"x":-11,"y":4,"z":9,"name":"Soil_Dirt"},{"x":-11,"y":5,"z":9,"name":"Soil_Snow"},{"x":-11,"y":0,"z":10,"name":"Soil_Dirt"},{"x":-11,"y":1,"z":10,"name":"Soil_Dirt"},{"x":-11,"y":2,"z":10,"name":"Soil_Dirt"},{"x":-11,"y":3,"z":10,"name":"Soil_Dirt"},{"x":-11,"y":4,"z":10,"name":"Soil_Dirt"},{"x":-11,"y":5,"z":10,"name":"Soil_Snow"},{"x":-11,"y":0,"z":11,"name":"Soil_Dirt"},{"x":-11,"y":1,"z":11,"name":"Soil_Dirt"},{"x":-11,"y":2,"z":11,"name":"Soil_Dirt"},{"x":-11,"y":3,"z":11,"name":"Soil_Dirt"},{"x":-11,"y":4,"z":11,"name":"Soil_Dirt"},{"x":-11,"y":5,"z":11,"name":"Soil_Snow"},{"x":-11,"y":0,"z":12,"name":"Soil_Dirt"},{"x":-11,"y":1,"z":12,"name":"Soil_Dirt"},{"x":-11,"y":2,"z":12,"name":"Soil_Dirt"},{"x":-11,"y":3,"z":12,"name":"Soil_Dirt"},{"x":-11,"y":4,"z":12,"name":"Soil_Dirt"},{"x":-11,"y":5,"z":12,"name":"Soil_Snow"},{"x":-11,"y":0,"z":13,"name":"Soil_Dirt"},{"x":-11,"y":1,"z":13,"name":"Soil_Dirt"},{"x":-11,"y":2,"z":13,"name":"Soil_Dirt"},{"x":-11,"y":3,"z":13,"name":"Soil_Dirt"},{"x":-11,"y":4,"z":13,"name":"Soil_Dirt"},{"x":-11,"y":5,"z":13,"name":"Soil_Snow"},{"x":-11,"y":6,"z":13,"name":"Rock_Ice_Stalactite_Large","support":15},{"x":-11,"y":7,"z":13,"name":"Rock_Ice_Stalactite_Large","filler":1024},{"x":-11,"y":0,"z":14,"name":"Soil_Dirt"},{"x":-11,"y":1,"z":14,"name":"Soil_Dirt"},{"x":-11,"y":2,"z":14,"name":"Soil_Dirt"},{"x":-11,"y":3,"z":14,"name":"Soil_Dirt"},{"x":-11,"y":4,"z":14,"name":"Soil_Dirt"},{"x":-11,"y":5,"z":14,"name":"Soil_Snow"},{"x":-11,"y":0,"z":15,"name":"Soil_Dirt"},{"x":-11,"y":1,"z":15,"name":"Soil_Dirt"},{"x":-11,"y":2,"z":15,"name":"Soil_Dirt"},{"x":-11,"y":3,"z":15,"name":"Soil_Dirt"},{"x":-11,"y":4,"z":15,"name":"Soil_Dirt"},{"x":-11,"y":5,"z":15,"name":"Rock_Stone_Brick_Smooth"},{"x":-10,"y":0,"z":-14,"name":"Soil_Dirt"},{"x":-10,"y":1,"z":-14,"name":"Soil_Dirt"},{"x":-10,"y":2,"z":-14,"name":"Soil_Dirt"},{"x":-10,"y":3,"z":-14,"name":"Soil_Dirt"},{"x":-10,"y":4,"z":-14,"name":"Soil_Dirt"},{"x":-10,"y":5,"z":-14,"name":"Rock_Stone_Brick_Smooth"},{"x":-10,"y":0,"z":-13,"name":"Soil_Dirt"},{"x":-10,"y":1,"z":-13,"name":"Soil_Dirt"},{"x":-10,"y":2,"z":-13,"name":"Soil_Dirt"},{"x":-10,"y":3,"z":-13,"name":"Soil_Dirt"},{"x":-10,"y":4,"z":-13,"name":"Soil_Dirt"},{"x":-10,"y":5,"z":-13,"name":"Soil_Snow"},{"x":-10,"y":0,"z":-12,"name":"Soil_Dirt"},{"x":-10,"y":1,"z":-12,"name":"Soil_Dirt"},{"x":-10,"y":2,"z":-12,"name":"Soil_Dirt"},{"x":-10,"y":3,"z":-12,"name":"Soil_Dirt"},{"x":-10,"y":4,"z":-12,"name":"Soil_Dirt"},{"x":-10,"y":5,"z":-12,"name":"Soil_Snow"},{"x":-10,"y":0,"z":-11,"name":"Soil_Dirt"},{"x":-10,"y":1,"z":-11,"name":"Soil_Dirt"},{"x":-10,"y":2,"z":-11,"name":"Soil_Dirt"},{"x":-10,"y":3,"z":-11,"name":"Soil_Dirt"},{"x":-10,"y":4,"z":-11,"name":"Soil_Dirt"},{"x":-10,"y":5,"z":-11,"name":"Soil_Snow"},{"x":-10,"y":0,"z":-10,"name":"Soil_Dirt"},{"x":-10,"y":1,"z":-10,"name":"Soil_Dirt"},{"x":-10,"y":2,"z":-10,"name":"Soil_Dirt"},{"x":-10,"y":3,"z":-10,"name":"Soil_Dirt"},{"x":-10,"y":4,"z":-10,"name":"Soil_Dirt"},{"x":-10,"y":5,"z":-10,"name":"Soil_Snow"},{"x":-10,"y":6,"z":-10,"name":"Furniture_Frozen_Castle_Secondary_Lamp","support":15},{"x":-10,"y":0,"z":-9,"name":"Soil_Dirt"},{"x":-10,"y":1,"z":-9,"name":"Soil_Dirt"},{"x":-10,"y":2,"z":-9,"name":"Soil_Dirt"},{"x":-10,"y":3,"z":-9,"name":"Soil_Dirt"},{"x":-10,"y":4,"z":-9,"name":"Soil_Dirt"},{"x":-10,"y":5,"z":-9,"name":"Soil_Snow"},{"x":-10,"y":6,"z":-9,"name":"Plant_Bush_Winter_Snow","support":15},{"x":-10,"y":0,"z":-8,"name":"Soil_Dirt"},{"x":-10,"y":1,"z":-8,"name":"Soil_Dirt"},{"x":-10,"y":2,"z":-8,"name":"Soil_Dirt"},{"x":-10,"y":3,"z":-8,"name":"Soil_Dirt"},{"x":-10,"y":4,"z":-8,"name":"Soil_Dirt"},{"x":-10,"y":5,"z":-8,"name":"Soil_Snow"},{"x":-10,"y":0,"z":-7,"name":"Soil_Dirt"},{"x":-10,"y":1,"z":-7,"name":"Soil_Dirt"},{"x":-10,"y":2,"z":-7,"name":"Soil_Dirt"},{"x":-10,"y":3,"z":-7,"name":"Soil_Dirt"},{"x":-10,"y":4,"z":-7,"name":"Soil_Dirt"},{"x":-10,"y":5,"z":-7,"name":"Soil_Snow"},{"x":-10,"y":6,"z":-7,"name":"WinterHoliday_Snowflake","support":15,"rotation":1},{"x":-10,"y":0,"z":-6,"name":"Soil_Dirt"},{"x":-10,"y":1,"z":-6,"name":"Soil_Dirt"},{"x":-10,"y":2,"z":-6,"name":"Soil_Dirt"},{"x":-10,"y":3,"z":-6,"name":"Soil_Dirt"},{"x":-10,"y":4,"z":-6,"name":"Soil_Dirt"},{"x":-10,"y":5,"z":-6,"name":"Soil_Snow"},{"x":-10,"y":6,"z":-6,"name":"Soil_Snow_Half","support":15},{"x":-10,"y":0,"z":-5,"name":"Soil_Dirt"},{"x":-10,"y":1,"z":-5,"name":"Soil_Dirt"},{"x":-10,"y":2,"z":-5,"name":"Soil_Dirt"},{"x":-10,"y":3,"z":-5,"name":"Soil_Dirt"},{"x":-10,"y":4,"z":-5,"name":"Soil_Dirt"},{"x":-10,"y":5,"z":-5,"name":"Soil_Snow"},{"x":-10,"y":6,"z":-5,"name":"Soil_Snow_Half","support":15},{"x":-10,"y":0,"z":-4,"name":"Soil_Dirt"},{"x":-10,"y":1,"z":-4,"name":"Soil_Dirt"},{"x":-10,"y":2,"z":-4,"name":"Soil_Dirt"},{"x":-10,"y":3,"z":-4,"name":"Soil_Dirt"},{"x":-10,"y":4,"z":-4,"name":"Soil_Dirt"},{"x":-10,"y":5,"z":-4,"name":"Soil_Snow"},{"x":-10,"y":0,"z":-3,"name":"Soil_Dirt"},{"x":-10,"y":1,"z":-3,"name":"Soil_Dirt"},{"x":-10,"y":2,"z":-3,"name":"Soil_Dirt"},{"x":-10,"y":3,"z":-3,"name":"Soil_Dirt"},{"x":-10,"y":4,"z":-3,"name":"Soil_Dirt"},{"x":-10,"y":5,"z":-3,"name":"Soil_Snow"},{"x":-10,"y":0,"z":-2,"name":"Soil_Dirt"},{"x":-10,"y":1,"z":-2,"name":"Soil_Dirt"},{"x":-10,"y":2,"z":-2,"name":"Soil_Dirt"},{"x":-10,"y":3,"z":-2,"name":"Soil_Dirt"},{"x":-10,"y":4,"z":-2,"name":"Soil_Dirt"},{"x":-10,"y":5,"z":-2,"name":"Soil_Snow"},{"x":-10,"y":6,"z":-2,"name":"Soil_Snow_Half","support":15},{"x":-10,"y":0,"z":-1,"name":"Soil_Dirt"},{"x":-10,"y":1,"z":-1,"name":"Soil_Dirt"},{"x":-10,"y":2,"z":-1,"name":"Soil_Dirt"},{"x":-10,"y":3,"z":-1,"name":"Soil_Dirt"},{"x":-10,"y":4,"z":-1,"name":"Soil_Dirt"},{"x":-10,"y":5,"z":-1,"name":"Soil_Snow"},{"x":-10,"y":6,"z":-1,"name":"*Soil_Snow_Half_State_Definitions_Block"},{"x":-10,"y":0,"z":0,"name":"Soil_Dirt"},{"x":-10,"y":1,"z":0,"name":"Soil_Dirt"},{"x":-10,"y":2,"z":0,"name":"Soil_Dirt"},{"x":-10,"y":3,"z":0,"name":"Soil_Dirt"},{"x":-10,"y":4,"z":0,"name":"Soil_Dirt"},{"x":-10,"y":5,"z":0,"name":"Soil_Snow"},{"x":-10,"y":6,"z":0,"name":"*Soil_Snow_Half_State_Definitions_Block"},{"x":-10,"y":0,"z":1,"name":"Soil_Dirt"},{"x":-10,"y":1,"z":1,"name":"Soil_Dirt"},{"x":-10,"y":2,"z":1,"name":"Soil_Dirt"},{"x":-10,"y":3,"z":1,"name":"Soil_Dirt"},{"x":-10,"y":4,"z":1,"name":"Soil_Dirt"},{"x":-10,"y":5,"z":1,"name":"Soil_Snow"},{"x":-10,"y":6,"z":1,"name":"*Soil_Snow_Half_State_Definitions_Block"},{"x":-10,"y":0,"z":2,"name":"Soil_Dirt"},{"x":-10,"y":1,"z":2,"name":"Soil_Dirt"},{"x":-10,"y":2,"z":2,"name":"Soil_Dirt"},{"x":-10,"y":3,"z":2,"name":"Soil_Dirt"},{"x":-10,"y":4,"z":2,"name":"Soil_Dirt"},{"x":-10,"y":5,"z":2,"name":"Soil_Snow"},{"x":-10,"y":6,"z":2,"name":"Soil_Snow_Half","support":15},{"x":-10,"y":0,"z":3,"name":"Soil_Dirt"},{"x":-10,"y":1,"z":3,"name":"Soil_Dirt"},{"x":-10,"y":2,"z":3,"name":"Soil_Dirt"},{"x":-10,"y":3,"z":3,"name":"Soil_Dirt"},{"x":-10,"y":4,"z":3,"name":"Soil_Dirt"},{"x":-10,"y":5,"z":3,"name":"Soil_Snow"},{"x":-10,"y":0,"z":4,"name":"Soil_Dirt"},{"x":-10,"y":1,"z":4,"name":"Soil_Dirt"},{"x":-10,"y":2,"z":4,"name":"Soil_Dirt"},{"x":-10,"y":3,"z":4,"name":"Soil_Dirt"},{"x":-10,"y":4,"z":4,"name":"Soil_Dirt"},{"x":-10,"y":5,"z":4,"name":"Soil_Snow"},{"x":-10,"y":0,"z":5,"name":"Soil_Dirt"},{"x":-10,"y":1,"z":5,"name":"Soil_Dirt"},{"x":-10,"y":2,"z":5,"name":"Soil_Dirt"},{"x":-10,"y":3,"z":5,"name":"Soil_Dirt"},{"x":-10,"y":4,"z":5,"name":"Soil_Dirt"},{"x":-10,"y":5,"z":5,"name":"Soil_Snow"},{"x":-10,"y":0,"z":6,"name":"Soil_Dirt"},{"x":-10,"y":1,"z":6,"name":"Soil_Dirt"},{"x":-10,"y":2,"z":6,"name":"Soil_Dirt"},{"x":-10,"y":3,"z":6,"name":"Soil_Dirt"},{"x":-10,"y":4,"z":6,"name":"Soil_Dirt"},{"x":-10,"y":5,"z":6,"name":"Soil_Snow"},{"x":-10,"y":0,"z":7,"name":"Soil_Dirt"},{"x":-10,"y":1,"z":7,"name":"Soil_Dirt"},{"x":-10,"y":2,"z":7,"name":"Soil_Dirt"},{"x":-10,"y":3,"z":7,"name":"Soil_Dirt"},{"x":-10,"y":4,"z":7,"name":"Soil_Dirt"},{"x":-10,"y":5,"z":7,"name":"Soil_Snow"},{"x":-10,"y":0,"z":8,"name":"Soil_Dirt"},{"x":-10,"y":1,"z":8,"name":"Soil_Dirt"},{"x":-10,"y":2,"z":8,"name":"Soil_Dirt"},{"x":-10,"y":3,"z":8,"name":"Soil_Dirt"},{"x":-10,"y":4,"z":8,"name":"Soil_Dirt"},{"x":-10,"y":5,"z":8,"name":"Soil_Snow","support":15},{"x":-10,"y":6,"z":8,"name":"Plant_Bush_Winter_Snow","support":15},{"x":-10,"y":0,"z":9,"name":"Soil_Dirt"},{"x":-10,"y":1,"z":9,"name":"Soil_Dirt"},{"x":-10,"y":2,"z":9,"name":"Soil_Dirt"},{"x":-10,"y":3,"z":9,"name":"Soil_Dirt"},{"x":-10,"y":4,"z":9,"name":"Soil_Dirt"},{"x":-10,"y":5,"z":9,"name":"Soil_Snow","support":15},{"x":-10,"y":0,"z":10,"name":"Soil_Dirt"},{"x":-10,"y":1,"z":10,"name":"Soil_Dirt"},{"x":-10,"y":2,"z":10,"name":"Soil_Dirt"},{"x":-10,"y":3,"z":10,"name":"Soil_Dirt"},{"x":-10,"y":4,"z":10,"name":"Soil_Dirt"},{"x":-10,"y":5,"z":10,"name":"Soil_Snow"},{"x":-10,"y":0,"z":11,"name":"Soil_Dirt"},{"x":-10,"y":1,"z":11,"name":"Soil_Dirt"},{"x":-10,"y":2,"z":11,"name":"Soil_Dirt"},{"x":-10,"y":3,"z":11,"name":"Soil_Dirt"},{"x":-10,"y":4,"z":11,"name":"Soil_Dirt"},{"x":-10,"y":5,"z":11,"name":"Soil_Snow"},{"x":-10,"y":0,"z":12,"name":"Soil_Dirt"},{"x":-10,"y":1,"z":12,"name":"Soil_Dirt"},{"x":-10,"y":2,"z":12,"name":"Soil_Dirt"},{"x":-10,"y":3,"z":12,"name":"Soil_Dirt"},{"x":-10,"y":4,"z":12,"name":"Soil_Dirt"},{"x":-10,"y":5,"z":12,"name":"Soil_Snow"},{"x":-10,"y":0,"z":13,"name":"Soil_Dirt"},{"x":-10,"y":1,"z":13,"name":"Soil_Dirt"},{"x":-10,"y":2,"z":13,"name":"Soil_Dirt"},{"x":-10,"y":3,"z":13,"name":"Soil_Dirt"},{"x":-10,"y":4,"z":13,"name":"Soil_Dirt"},{"x":-10,"y":5,"z":13,"name":"Soil_Snow"},{"x":-10,"y":0,"z":14,"name":"Soil_Dirt"},{"x":-10,"y":1,"z":14,"name":"Soil_Dirt"},{"x":-10,"y":2,"z":14,"name":"Soil_Dirt"},{"x":-10,"y":3,"z":14,"name":"Soil_Dirt"},{"x":-10,"y":4,"z":14,"name":"Soil_Dirt"},{"x":-10,"y":5,"z":14,"name":"Soil_Snow"},{"x":-10,"y":0,"z":15,"name":"Soil_Dirt"},{"x":-10,"y":1,"z":15,"name":"Soil_Dirt"},{"x":-10,"y":2,"z":15,"name":"Soil_Dirt"},{"x":-10,"y":3,"z":15,"name":"Soil_Dirt"},{"x":-10,"y":4,"z":15,"name":"Soil_Dirt"},{"x":-10,"y":5,"z":15,"name":"Rock_Stone_Brick_Smooth"},{"x":-9,"y":0,"z":-14,"name":"Soil_Dirt"},{"x":-9,"y":1,"z":-14,"name":"Soil_Dirt"},{"x":-9,"y":2,"z":-14,"name":"Soil_Dirt"},{"x":-9,"y":3,"z":-14,"name":"Soil_Dirt"},{"x":-9,"y":4,"z":-14,"name":"Soil_Dirt"},{"x":-9,"y":5,"z":-14,"name":"Rock_Stone_Brick_Smooth"},{"x":-9,"y":0,"z":-13,"name":"Soil_Dirt"},{"x":-9,"y":1,"z":-13,"name":"Soil_Dirt"},{"x":-9,"y":2,"z":-13,"name":"Soil_Dirt"},{"x":-9,"y":3,"z":-13,"name":"Soil_Dirt"},{"x":-9,"y":4,"z":-13,"name":"Soil_Dirt"},{"x":-9,"y":5,"z":-13,"name":"Soil_Snow"},{"x":-9,"y":0,"z":-12,"name":"Soil_Dirt"},{"x":-9,"y":1,"z":-12,"name":"Soil_Dirt"},{"x":-9,"y":2,"z":-12,"name":"Soil_Dirt"},{"x":-9,"y":3,"z":-12,"name":"Soil_Dirt"},{"x":-9,"y":4,"z":-12,"name":"Soil_Dirt"},{"x":-9,"y":5,"z":-12,"name":"Soil_Snow"},{"x":-9,"y":0,"z":-11,"name":"Soil_Dirt"},{"x":-9,"y":1,"z":-11,"name":"Soil_Dirt"},{"x":-9,"y":2,"z":-11,"name":"Soil_Dirt"},{"x":-9,"y":3,"z":-11,"name":"Soil_Dirt"},{"x":-9,"y":4,"z":-11,"name":"Soil_Dirt"},{"x":-9,"y":5,"z":-11,"name":"Soil_Snow"},{"x":-9,"y":0,"z":-10,"name":"Soil_Dirt"},{"x":-9,"y":1,"z":-10,"name":"Soil_Dirt"},{"x":-9,"y":2,"z":-10,"name":"Soil_Dirt"},{"x":-9,"y":3,"z":-10,"name":"Soil_Dirt"},{"x":-9,"y":4,"z":-10,"name":"Soil_Dirt"},{"x":-9,"y":5,"z":-10,"name":"Soil_Snow"},{"x":-9,"y":0,"z":-9,"name":"Soil_Dirt"},{"x":-9,"y":1,"z":-9,"name":"Soil_Dirt"},{"x":-9,"y":2,"z":-9,"name":"Soil_Dirt"},{"x":-9,"y":3,"z":-9,"name":"Soil_Dirt"},{"x":-9,"y":4,"z":-9,"name":"Soil_Dirt"},{"x":-9,"y":5,"z":-9,"name":"Soil_Snow"},{"x":-9,"y":0,"z":-8,"name":"Soil_Dirt"},{"x":-9,"y":1,"z":-8,"name":"Soil_Dirt"},{"x":-9,"y":2,"z":-8,"name":"Soil_Dirt"},{"x":-9,"y":3,"z":-8,"name":"Soil_Dirt"},{"x":-9,"y":4,"z":-8,"name":"Soil_Dirt"},{"x":-9,"y":5,"z":-8,"name":"Soil_Snow"},{"x":-9,"y":0,"z":-7,"name":"Soil_Dirt"},{"x":-9,"y":1,"z":-7,"name":"Soil_Dirt"},{"x":-9,"y":2,"z":-7,"name":"Soil_Dirt"},{"x":-9,"y":3,"z":-7,"name":"Soil_Dirt"},{"x":-9,"y":4,"z":-7,"name":"Soil_Dirt"},{"x":-9,"y":5,"z":-7,"name":"Soil_Snow"},{"x":-9,"y":0,"z":-6,"name":"Soil_Dirt"},{"x":-9,"y":1,"z":-6,"name":"Soil_Dirt"},{"x":-9,"y":2,"z":-6,"name":"Soil_Dirt"},{"x":-9,"y":3,"z":-6,"name":"Soil_Dirt"},{"x":-9,"y":4,"z":-6,"name":"Soil_Dirt"},{"x":-9,"y":5,"z":-6,"name":"Soil_Snow"},{"x":-9,"y":0,"z":-5,"name":"Soil_Dirt"},{"x":-9,"y":1,"z":-5,"name":"Soil_Dirt"},{"x":-9,"y":2,"z":-5,"name":"Soil_Dirt"},{"x":-9,"y":3,"z":-5,"name":"Soil_Dirt"},{"x":-9,"y":4,"z":-5,"name":"Soil_Dirt"},{"x":-9,"y":5,"z":-5,"name":"Soil_Snow"},{"x":-9,"y":0,"z":-4,"name":"Soil_Dirt"},{"x":-9,"y":1,"z":-4,"name":"Soil_Dirt"},{"x":-9,"y":2,"z":-4,"name":"Soil_Dirt"},{"x":-9,"y":3,"z":-4,"name":"Soil_Dirt"},{"x":-9,"y":4,"z":-4,"name":"Soil_Dirt"},{"x":-9,"y":5,"z":-4,"name":"Soil_Snow"},{"x":-9,"y":0,"z":-3,"name":"Soil_Dirt"},{"x":-9,"y":1,"z":-3,"name":"Soil_Dirt"},{"x":-9,"y":2,"z":-3,"name":"Soil_Dirt"},{"x":-9,"y":3,"z":-3,"name":"Soil_Dirt"},{"x":-9,"y":4,"z":-3,"name":"Soil_Dirt"},{"x":-9,"y":5,"z":-3,"name":"Soil_Snow"},{"x":-9,"y":0,"z":-2,"name":"Soil_Dirt"},{"x":-9,"y":1,"z":-2,"name":"Soil_Dirt"},{"x":-9,"y":2,"z":-2,"name":"Soil_Dirt"},{"x":-9,"y":3,"z":-2,"name":"Soil_Dirt"},{"x":-9,"y":4,"z":-2,"name":"Soil_Dirt"},{"x":-9,"y":5,"z":-2,"name":"Soil_Snow"},{"x":-9,"y":0,"z":-1,"name":"Soil_Dirt"},{"x":-9,"y":1,"z":-1,"name":"Soil_Dirt"},{"x":-9,"y":2,"z":-1,"name":"Soil_Dirt"},{"x":-9,"y":3,"z":-1,"name":"Soil_Dirt"},{"x":-9,"y":4,"z":-1,"name":"Soil_Dirt"},{"x":-9,"y":5,"z":-1,"name":"Soil_Snow"},{"x":-9,"y":6,"z":-1,"name":"Soil_Snow_Half","support":15},{"x":-9,"y":0,"z":0,"name":"Soil_Dirt"},{"x":-9,"y":1,"z":0,"name":"Soil_Dirt"},{"x":-9,"y":2,"z":0,"name":"Soil_Dirt"},{"x":-9,"y":3,"z":0,"name":"Soil_Dirt"},{"x":-9,"y":4,"z":0,"name":"Soil_Dirt"},{"x":-9,"y":5,"z":0,"name":"Soil_Snow"},{"x":-9,"y":6,"z":0,"name":"*Soil_Snow_Half_State_Definitions_Block"},{"x":-9,"y":0,"z":1,"name":"Soil_Dirt"},{"x":-9,"y":1,"z":1,"name":"Soil_Dirt"},{"x":-9,"y":2,"z":1,"name":"Soil_Dirt"},{"x":-9,"y":3,"z":1,"name":"Soil_Dirt"},{"x":-9,"y":4,"z":1,"name":"Soil_Dirt"},{"x":-9,"y":5,"z":1,"name":"Soil_Snow"},{"x":-9,"y":6,"z":1,"name":"*Soil_Snow_Half_State_Definitions_Block"},{"x":-9,"y":0,"z":2,"name":"Soil_Dirt"},{"x":-9,"y":1,"z":2,"name":"Soil_Dirt"},{"x":-9,"y":2,"z":2,"name":"Soil_Dirt"},{"x":-9,"y":3,"z":2,"name":"Soil_Dirt"},{"x":-9,"y":4,"z":2,"name":"Soil_Dirt"},{"x":-9,"y":5,"z":2,"name":"Soil_Snow"},{"x":-9,"y":6,"z":2,"name":"Soil_Snow_Half","support":15},{"x":-9,"y":0,"z":3,"name":"Soil_Dirt"},{"x":-9,"y":1,"z":3,"name":"Soil_Dirt"},{"x":-9,"y":2,"z":3,"name":"Soil_Dirt"},{"x":-9,"y":3,"z":3,"name":"Soil_Dirt"},{"x":-9,"y":4,"z":3,"name":"Soil_Dirt"},{"x":-9,"y":5,"z":3,"name":"Soil_Snow"},{"x":-9,"y":0,"z":4,"name":"Soil_Dirt"},{"x":-9,"y":1,"z":4,"name":"Soil_Dirt"},{"x":-9,"y":2,"z":4,"name":"Soil_Dirt"},{"x":-9,"y":3,"z":4,"name":"Soil_Dirt"},{"x":-9,"y":4,"z":4,"name":"Soil_Dirt"},{"x":-9,"y":5,"z":4,"name":"Soil_Snow"},{"x":-9,"y":0,"z":5,"name":"Soil_Dirt"},{"x":-9,"y":1,"z":5,"name":"Soil_Dirt"},{"x":-9,"y":2,"z":5,"name":"Soil_Dirt"},{"x":-9,"y":3,"z":5,"name":"Soil_Dirt"},{"x":-9,"y":4,"z":5,"name":"Soil_Dirt"},{"x":-9,"y":5,"z":5,"name":"Soil_Snow"},{"x":-9,"y":0,"z":6,"name":"Soil_Dirt"},{"x":-9,"y":1,"z":6,"name":"Soil_Dirt"},{"x":-9,"y":2,"z":6,"name":"Soil_Dirt"},{"x":-9,"y":3,"z":6,"name":"Soil_Dirt"},{"x":-9,"y":4,"z":6,"name":"Soil_Dirt"},{"x":-9,"y":5,"z":6,"name":"Soil_Snow"},{"x":-9,"y":0,"z":7,"name":"Soil_Dirt"},{"x":-9,"y":1,"z":7,"name":"Soil_Dirt"},{"x":-9,"y":2,"z":7,"name":"Soil_Dirt"},{"x":-9,"y":3,"z":7,"name":"Soil_Dirt"},{"x":-9,"y":4,"z":7,"name":"Soil_Dirt"},{"x":-9,"y":5,"z":7,"name":"Soil_Snow"},{"x":-9,"y":0,"z":8,"name":"Soil_Dirt"},{"x":-9,"y":1,"z":8,"name":"Soil_Dirt"},{"x":-9,"y":2,"z":8,"name":"Soil_Dirt"},{"x":-9,"y":3,"z":8,"name":"Soil_Dirt"},{"x":-9,"y":4,"z":8,"name":"Soil_Dirt"},{"x":-9,"y":5,"z":8,"name":"Soil_Snow"},{"x":-9,"y":0,"z":9,"name":"Soil_Dirt"},{"x":-9,"y":1,"z":9,"name":"Soil_Dirt"},{"x":-9,"y":2,"z":9,"name":"Soil_Dirt"},{"x":-9,"y":3,"z":9,"name":"Soil_Dirt"},{"x":-9,"y":4,"z":9,"name":"Soil_Dirt"},{"x":-9,"y":5,"z":9,"name":"Soil_Snow"},{"x":-9,"y":0,"z":10,"name":"Soil_Dirt"},{"x":-9,"y":1,"z":10,"name":"Soil_Dirt"},{"x":-9,"y":2,"z":10,"name":"Soil_Dirt"},{"x":-9,"y":3,"z":10,"name":"Soil_Dirt"},{"x":-9,"y":4,"z":10,"name":"Soil_Dirt"},{"x":-9,"y":5,"z":10,"name":"Soil_Snow"},{"x":-9,"y":0,"z":11,"name":"Soil_Dirt"},{"x":-9,"y":1,"z":11,"name":"Soil_Dirt"},{"x":-9,"y":2,"z":11,"name":"Soil_Dirt"},{"x":-9,"y":3,"z":11,"name":"Soil_Dirt"},{"x":-9,"y":4,"z":11,"name":"Soil_Dirt"},{"x":-9,"y":5,"z":11,"name":"Soil_Snow"},{"x":-9,"y":6,"z":11,"name":"Furniture_Frozen_Castle_Secondary_Lamp","support":15},{"x":-9,"y":0,"z":12,"name":"Soil_Dirt"},{"x":-9,"y":1,"z":12,"name":"Soil_Dirt"},{"x":-9,"y":2,"z":12,"name":"Soil_Dirt"},{"x":-9,"y":3,"z":12,"name":"Soil_Dirt"},{"x":-9,"y":4,"z":12,"name":"Soil_Dirt"},{"x":-9,"y":5,"z":12,"name":"Soil_Snow"},{"x":-9,"y":0,"z":13,"name":"Soil_Dirt"},{"x":-9,"y":1,"z":13,"name":"Soil_Dirt"},{"x":-9,"y":2,"z":13,"name":"Soil_Dirt"},{"x":-9,"y":3,"z":13,"name":"Soil_Dirt"},{"x":-9,"y":4,"z":13,"name":"Soil_Dirt"},{"x":-9,"y":5,"z":13,"name":"Soil_Snow"},{"x":-9,"y":0,"z":14,"name":"Soil_Dirt"},{"x":-9,"y":1,"z":14,"name":"Soil_Dirt"},{"x":-9,"y":2,"z":14,"name":"Soil_Dirt"},{"x":-9,"y":3,"z":14,"name":"Soil_Dirt"},{"x":-9,"y":4,"z":14,"name":"Soil_Dirt"},{"x":-9,"y":5,"z":14,"name":"Soil_Snow"},{"x":-9,"y":0,"z":15,"name":"Soil_Dirt"},{"x":-9,"y":1,"z":15,"name":"Soil_Dirt"},{"x":-9,"y":2,"z":15,"name":"Soil_Dirt"},{"x":-9,"y":3,"z":15,"name":"Soil_Dirt"},{"x":-9,"y":4,"z":15,"name":"Soil_Dirt"},{"x":-9,"y":5,"z":15,"name":"Rock_Stone_Brick_Smooth"},{"x":-8,"y":0,"z":-14,"name":"Soil_Dirt"},{"x":-8,"y":1,"z":-14,"name":"Soil_Dirt"},{"x":-8,"y":2,"z":-14,"name":"Soil_Dirt"},{"x":-8,"y":3,"z":-14,"name":"Soil_Dirt"},{"x":-8,"y":4,"z":-14,"name":"Soil_Dirt"},{"x":-8,"y":5,"z":-14,"name":"Rock_Stone_Brick_Smooth"},{"x":-8,"y":0,"z":-13,"name":"Soil_Dirt"},{"x":-8,"y":1,"z":-13,"name":"Soil_Dirt"},{"x":-8,"y":2,"z":-13,"name":"Soil_Dirt"},{"x":-8,"y":3,"z":-13,"name":"Soil_Dirt"},{"x":-8,"y":4,"z":-13,"name":"Soil_Dirt"},{"x":-8,"y":5,"z":-13,"name":"Soil_Snow"},{"x":-8,"y":0,"z":-12,"name":"Soil_Dirt"},{"x":-8,"y":1,"z":-12,"name":"Soil_Dirt"},{"x":-8,"y":2,"z":-12,"name":"Soil_Dirt"},{"x":-8,"y":3,"z":-12,"name":"Soil_Dirt"},{"x":-8,"y":4,"z":-12,"name":"Soil_Dirt"},{"x":-8,"y":5,"z":-12,"name":"Soil_Snow"},{"x":-8,"y":0,"z":-11,"name":"Soil_Dirt"},{"x":-8,"y":1,"z":-11,"name":"Soil_Dirt"},{"x":-8,"y":2,"z":-11,"name":"Soil_Dirt"},{"x":-8,"y":3,"z":-11,"name":"Soil_Dirt"},{"x":-8,"y":4,"z":-11,"name":"Soil_Dirt"},{"x":-8,"y":5,"z":-11,"name":"*Soil_Snow_Half_State_Definitions_Block"},{"x":-8,"y":6,"z":-11,"name":"Soil_Snow_Half","support":15},{"x":-8,"y":0,"z":-10,"name":"Soil_Dirt"},{"x":-8,"y":1,"z":-10,"name":"Soil_Dirt"},{"x":-8,"y":2,"z":-10,"name":"Soil_Dirt"},{"x":-8,"y":3,"z":-10,"name":"Soil_Dirt"},{"x":-8,"y":4,"z":-10,"name":"Soil_Dirt"},{"x":-8,"y":5,"z":-10,"name":"Soil_Snow"},{"x":-8,"y":6,"z":-10,"name":"Soil_Snow_Half","support":15},{"x":-8,"y":0,"z":-9,"name":"Soil_Dirt"},{"x":-8,"y":1,"z":-9,"name":"Soil_Dirt"},{"x":-8,"y":2,"z":-9,"name":"Soil_Dirt"},{"x":-8,"y":3,"z":-9,"name":"Soil_Dirt"},{"x":-8,"y":4,"z":-9,"name":"Soil_Dirt"},{"x":-8,"y":5,"z":-9,"name":"Soil_Snow"},{"x":-8,"y":0,"z":-8,"name":"Soil_Dirt"},{"x":-8,"y":1,"z":-8,"name":"Soil_Dirt"},{"x":-8,"y":2,"z":-8,"name":"Soil_Dirt"},{"x":-8,"y":3,"z":-8,"name":"Soil_Dirt"},{"x":-8,"y":4,"z":-8,"name":"Soil_Dirt"},{"x":-8,"y":5,"z":-8,"name":"Soil_Snow"},{"x":-8,"y":6,"z":-8,"name":"Rock_Ice_Stalactite_Large","support":15},{"x":-8,"y":7,"z":-8,"name":"Rock_Ice_Stalactite_Large","filler":1024},{"x":-8,"y":0,"z":-7,"name":"Soil_Dirt"},{"x":-8,"y":1,"z":-7,"name":"Soil_Dirt"},{"x":-8,"y":2,"z":-7,"name":"Soil_Dirt"},{"x":-8,"y":3,"z":-7,"name":"Soil_Dirt"},{"x":-8,"y":4,"z":-7,"name":"Soil_Dirt"},{"x":-8,"y":5,"z":-7,"name":"Soil_Snow"},{"x":-8,"y":0,"z":-6,"name":"Soil_Dirt"},{"x":-8,"y":1,"z":-6,"name":"Soil_Dirt"},{"x":-8,"y":2,"z":-6,"name":"Soil_Dirt"},{"x":-8,"y":3,"z":-6,"name":"Soil_Dirt"},{"x":-8,"y":4,"z":-6,"name":"Soil_Dirt"},{"x":-8,"y":5,"z":-6,"name":"Soil_Snow"},{"x":-8,"y":0,"z":-5,"name":"Soil_Dirt"},{"x":-8,"y":1,"z":-5,"name":"Soil_Dirt"},{"x":-8,"y":2,"z":-5,"name":"Soil_Dirt"},{"x":-8,"y":3,"z":-5,"name":"Soil_Dirt"},{"x":-8,"y":4,"z":-5,"name":"Soil_Dirt"},{"x":-8,"y":5,"z":-5,"name":"Soil_Snow"},{"x":-8,"y":0,"z":-4,"name":"Soil_Dirt"},{"x":-8,"y":1,"z":-4,"name":"Soil_Dirt"},{"x":-8,"y":2,"z":-4,"name":"Soil_Dirt"},{"x":-8,"y":3,"z":-4,"name":"Soil_Dirt"},{"x":-8,"y":4,"z":-4,"name":"Soil_Dirt"},{"x":-8,"y":5,"z":-4,"name":"Soil_Snow"},{"x":-8,"y":0,"z":-3,"name":"Soil_Dirt"},{"x":-8,"y":1,"z":-3,"name":"Soil_Dirt"},{"x":-8,"y":2,"z":-3,"name":"Soil_Dirt"},{"x":-8,"y":3,"z":-3,"name":"Soil_Dirt"},{"x":-8,"y":4,"z":-3,"name":"Soil_Dirt"},{"x":-8,"y":5,"z":-3,"name":"Soil_Snow"},{"x":-8,"y":6,"z":-3,"name":"Plant_Bush_Winter_Snow","support":15},{"x":-8,"y":0,"z":-2,"name":"Soil_Dirt"},{"x":-8,"y":1,"z":-2,"name":"Soil_Dirt"},{"x":-8,"y":2,"z":-2,"name":"Soil_Dirt"},{"x":-8,"y":3,"z":-2,"name":"Soil_Dirt"},{"x":-8,"y":4,"z":-2,"name":"Soil_Dirt"},{"x":-8,"y":5,"z":-2,"name":"Soil_Snow"},{"x":-8,"y":0,"z":-1,"name":"Soil_Dirt"},{"x":-8,"y":1,"z":-1,"name":"Soil_Dirt"},{"x":-8,"y":2,"z":-1,"name":"Soil_Dirt"},{"x":-8,"y":3,"z":-1,"name":"Soil_Dirt"},{"x":-8,"y":4,"z":-1,"name":"Soil_Dirt"},{"x":-8,"y":5,"z":-1,"name":"Soil_Snow"},{"x":-8,"y":0,"z":0,"name":"Soil_Dirt"},{"x":-8,"y":1,"z":0,"name":"Soil_Dirt"},{"x":-8,"y":2,"z":0,"name":"Soil_Dirt"},{"x":-8,"y":3,"z":0,"name":"Soil_Dirt"},{"x":-8,"y":4,"z":0,"name":"Soil_Dirt"},{"x":-8,"y":5,"z":0,"name":"Soil_Snow"},{"x":-8,"y":6,"z":0,"name":"Soil_Snow_Half","support":15},{"x":-8,"y":0,"z":1,"name":"Soil_Dirt"},{"x":-8,"y":1,"z":1,"name":"Soil_Dirt"},{"x":-8,"y":2,"z":1,"name":"Soil_Dirt"},{"x":-8,"y":3,"z":1,"name":"Soil_Dirt"},{"x":-8,"y":4,"z":1,"name":"Soil_Dirt"},{"x":-8,"y":5,"z":1,"name":"Soil_Snow"},{"x":-8,"y":6,"z":1,"name":"Soil_Snow_Half","support":15},{"x":-8,"y":0,"z":2,"name":"Soil_Dirt"},{"x":-8,"y":1,"z":2,"name":"Soil_Dirt"},{"x":-8,"y":2,"z":2,"name":"Soil_Dirt"},{"x":-8,"y":3,"z":2,"name":"Soil_Dirt"},{"x":-8,"y":4,"z":2,"name":"Soil_Dirt"},{"x":-8,"y":5,"z":2,"name":"Soil_Snow"},{"x":-8,"y":0,"z":3,"name":"Soil_Dirt"},{"x":-8,"y":1,"z":3,"name":"Soil_Dirt"},{"x":-8,"y":2,"z":3,"name":"Soil_Dirt"},{"x":-8,"y":3,"z":3,"name":"Soil_Dirt"},{"x":-8,"y":4,"z":3,"name":"Soil_Dirt"},{"x":-8,"y":5,"z":3,"name":"Soil_Snow"},{"x":-8,"y":0,"z":4,"name":"Soil_Dirt"},{"x":-8,"y":1,"z":4,"name":"Soil_Dirt"},{"x":-8,"y":2,"z":4,"name":"Soil_Dirt"},{"x":-8,"y":3,"z":4,"name":"Soil_Dirt"},{"x":-8,"y":4,"z":4,"name":"Soil_Dirt"},{"x":-8,"y":5,"z":4,"name":"Soil_Snow"},{"x":-8,"y":6,"z":4,"name":"Rock_Ice_Stalactite_Large","support":15},{"x":-8,"y":7,"z":4,"name":"Rock_Ice_Stalactite_Large","filler":1024},{"x":-8,"y":0,"z":5,"name":"Soil_Dirt"},{"x":-8,"y":1,"z":5,"name":"Soil_Dirt"},{"x":-8,"y":2,"z":5,"name":"Soil_Dirt"},{"x":-8,"y":3,"z":5,"name":"Soil_Dirt"},{"x":-8,"y":4,"z":5,"name":"Soil_Dirt"},{"x":-8,"y":5,"z":5,"name":"Soil_Snow"},{"x":-8,"y":0,"z":6,"name":"Soil_Dirt"},{"x":-8,"y":1,"z":6,"name":"Soil_Dirt"},{"x":-8,"y":2,"z":6,"name":"Soil_Dirt"},{"x":-8,"y":3,"z":6,"name":"Soil_Dirt"},{"x":-8,"y":4,"z":6,"name":"Soil_Dirt"},{"x":-8,"y":5,"z":6,"name":"Soil_Snow"},{"x":-8,"y":0,"z":7,"name":"Soil_Dirt"},{"x":-8,"y":1,"z":7,"name":"Soil_Dirt"},{"x":-8,"y":2,"z":7,"name":"Soil_Dirt"},{"x":-8,"y":3,"z":7,"name":"Soil_Dirt"},{"x":-8,"y":4,"z":7,"name":"Soil_Dirt"},{"x":-8,"y":5,"z":7,"name":"Soil_Snow"},{"x":-8,"y":0,"z":8,"name":"Soil_Dirt"},{"x":-8,"y":1,"z":8,"name":"Soil_Dirt"},{"x":-8,"y":2,"z":8,"name":"Soil_Dirt"},{"x":-8,"y":3,"z":8,"name":"Soil_Dirt"},{"x":-8,"y":4,"z":8,"name":"Soil_Dirt"},{"x":-8,"y":5,"z":8,"name":"Soil_Snow"},{"x":-8,"y":0,"z":9,"name":"Soil_Dirt"},{"x":-8,"y":1,"z":9,"name":"Soil_Dirt"},{"x":-8,"y":2,"z":9,"name":"Soil_Dirt"},{"x":-8,"y":3,"z":9,"name":"Soil_Dirt"},{"x":-8,"y":4,"z":9,"name":"Soil_Dirt"},{"x":-8,"y":5,"z":9,"name":"Soil_Snow"},{"x":-8,"y":0,"z":10,"name":"Soil_Dirt"},{"x":-8,"y":1,"z":10,"name":"Soil_Dirt"},{"x":-8,"y":2,"z":10,"name":"Soil_Dirt"},{"x":-8,"y":3,"z":10,"name":"Soil_Dirt"},{"x":-8,"y":4,"z":10,"name":"Soil_Dirt"},{"x":-8,"y":5,"z":10,"name":"Soil_Snow"},{"x":-8,"y":0,"z":11,"name":"Soil_Dirt"},{"x":-8,"y":1,"z":11,"name":"Soil_Dirt"},{"x":-8,"y":2,"z":11,"name":"Soil_Dirt"},{"x":-8,"y":3,"z":11,"name":"Soil_Dirt"},{"x":-8,"y":4,"z":11,"name":"Soil_Dirt"},{"x":-8,"y":5,"z":11,"name":"Soil_Snow"},{"x":-8,"y":0,"z":12,"name":"Soil_Dirt"},{"x":-8,"y":1,"z":12,"name":"Soil_Dirt"},{"x":-8,"y":2,"z":12,"name":"Soil_Dirt"},{"x":-8,"y":3,"z":12,"name":"Soil_Dirt"},{"x":-8,"y":4,"z":12,"name":"Soil_Dirt"},{"x":-8,"y":5,"z":12,"name":"Soil_Snow"},{"x":-8,"y":0,"z":13,"name":"Soil_Dirt"},{"x":-8,"y":1,"z":13,"name":"Soil_Dirt"},{"x":-8,"y":2,"z":13,"name":"Soil_Dirt"},{"x":-8,"y":3,"z":13,"name":"Soil_Dirt"},{"x":-8,"y":4,"z":13,"name":"Soil_Dirt"},{"x":-8,"y":5,"z":13,"name":"Soil_Snow"},{"x":-8,"y":0,"z":14,"name":"Soil_Dirt"},{"x":-8,"y":1,"z":14,"name":"Soil_Dirt"},{"x":-8,"y":2,"z":14,"name":"Soil_Dirt"},{"x":-8,"y":3,"z":14,"name":"Soil_Dirt"},{"x":-8,"y":4,"z":14,"name":"Soil_Dirt"},{"x":-8,"y":5,"z":14,"name":"Soil_Snow"},{"x":-8,"y":0,"z":15,"name":"Soil_Dirt"},{"x":-8,"y":1,"z":15,"name":"Soil_Dirt"},{"x":-8,"y":2,"z":15,"name":"Soil_Dirt"},{"x":-8,"y":3,"z":15,"name":"Soil_Dirt"},{"x":-8,"y":4,"z":15,"name":"Soil_Dirt"},{"x":-8,"y":5,"z":15,"name":"Rock_Stone_Brick_Smooth"},{"x":-7,"y":0,"z":-14,"name":"Soil_Dirt"},{"x":-7,"y":1,"z":-14,"name":"Soil_Dirt"},{"x":-7,"y":2,"z":-14,"name":"Soil_Dirt"},{"x":-7,"y":3,"z":-14,"name":"Soil_Dirt"},{"x":-7,"y":4,"z":-14,"name":"Soil_Dirt"},{"x":-7,"y":5,"z":-14,"name":"Rock_Stone_Brick_Smooth"},{"x":-7,"y":0,"z":-13,"name":"Soil_Dirt"},{"x":-7,"y":1,"z":-13,"name":"Soil_Dirt"},{"x":-7,"y":2,"z":-13,"name":"Soil_Dirt"},{"x":-7,"y":3,"z":-13,"name":"Soil_Dirt"},{"x":-7,"y":4,"z":-13,"name":"Soil_Dirt"},{"x":-7,"y":5,"z":-13,"name":"Soil_Snow"},{"x":-7,"y":0,"z":-12,"name":"Soil_Dirt"},{"x":-7,"y":1,"z":-12,"name":"Soil_Dirt"},{"x":-7,"y":2,"z":-12,"name":"Soil_Dirt"},{"x":-7,"y":3,"z":-12,"name":"Soil_Dirt"},{"x":-7,"y":4,"z":-12,"name":"Soil_Dirt"},{"x":-7,"y":5,"z":-12,"name":"Soil_Snow"},{"x":-7,"y":6,"z":-12,"name":"Soil_Snow_Half","support":15},{"x":-7,"y":0,"z":-11,"name":"Soil_Dirt"},{"x":-7,"y":1,"z":-11,"name":"Soil_Dirt"},{"x":-7,"y":2,"z":-11,"name":"Soil_Dirt"},{"x":-7,"y":3,"z":-11,"name":"Soil_Dirt"},{"x":-7,"y":4,"z":-11,"name":"Soil_Dirt"},{"x":-7,"y":5,"z":-11,"name":"Soil_Snow"},{"x":-7,"y":6,"z":-11,"name":"*Soil_Snow_Half_State_Definitions_Block"},{"x":-7,"y":0,"z":-10,"name":"Soil_Dirt"},{"x":-7,"y":1,"z":-10,"name":"Soil_Dirt"},{"x":-7,"y":2,"z":-10,"name":"Soil_Dirt"},{"x":-7,"y":3,"z":-10,"name":"Soil_Dirt"},{"x":-7,"y":4,"z":-10,"name":"Soil_Dirt"},{"x":-7,"y":5,"z":-10,"name":"*Soil_Snow_Half_State_Definitions_Block"},{"x":-7,"y":6,"z":-10,"name":"Soil_Snow_Half","support":15},{"x":-7,"y":0,"z":-9,"name":"Soil_Dirt"},{"x":-7,"y":1,"z":-9,"name":"Soil_Dirt"},{"x":-7,"y":2,"z":-9,"name":"Soil_Dirt"},{"x":-7,"y":3,"z":-9,"name":"Soil_Dirt"},{"x":-7,"y":4,"z":-9,"name":"Soil_Dirt"},{"x":-7,"y":5,"z":-9,"name":"Soil_Snow"},{"x":-7,"y":0,"z":-8,"name":"Soil_Dirt"},{"x":-7,"y":1,"z":-8,"name":"Soil_Dirt"},{"x":-7,"y":2,"z":-8,"name":"Soil_Dirt"},{"x":-7,"y":3,"z":-8,"name":"Soil_Dirt"},{"x":-7,"y":4,"z":-8,"name":"Soil_Dirt"},{"x":-7,"y":5,"z":-8,"name":"Soil_Snow"},{"x":-7,"y":0,"z":-7,"name":"Soil_Dirt"},{"x":-7,"y":1,"z":-7,"name":"Soil_Dirt"},{"x":-7,"y":2,"z":-7,"name":"Soil_Dirt"},{"x":-7,"y":3,"z":-7,"name":"Soil_Dirt"},{"x":-7,"y":4,"z":-7,"name":"Soil_Dirt"},{"x":-7,"y":5,"z":-7,"name":"Soil_Snow"},{"x":-7,"y":0,"z":-6,"name":"Soil_Dirt"},{"x":-7,"y":1,"z":-6,"name":"Soil_Dirt"},{"x":-7,"y":2,"z":-6,"name":"Soil_Dirt"},{"x":-7,"y":3,"z":-6,"name":"Soil_Dirt"},{"x":-7,"y":4,"z":-6,"name":"Soil_Dirt"},{"x":-7,"y":5,"z":-6,"name":"Soil_Snow"},{"x":-7,"y":0,"z":-5,"name":"Soil_Dirt"},{"x":-7,"y":1,"z":-5,"name":"Soil_Dirt"},{"x":-7,"y":2,"z":-5,"name":"Soil_Dirt"},{"x":-7,"y":3,"z":-5,"name":"Soil_Dirt"},{"x":-7,"y":4,"z":-5,"name":"Soil_Dirt"},{"x":-7,"y":5,"z":-5,"name":"Soil_Snow"},{"x":-7,"y":0,"z":-4,"name":"Soil_Dirt"},{"x":-7,"y":1,"z":-4,"name":"Soil_Dirt"},{"x":-7,"y":2,"z":-4,"name":"Soil_Dirt"},{"x":-7,"y":3,"z":-4,"name":"Soil_Dirt"},{"x":-7,"y":4,"z":-4,"name":"Soil_Dirt"},{"x":-7,"y":5,"z":-4,"name":"Soil_Snow"},{"x":-7,"y":0,"z":-3,"name":"Soil_Dirt"},{"x":-7,"y":1,"z":-3,"name":"Soil_Dirt"},{"x":-7,"y":2,"z":-3,"name":"Soil_Dirt"},{"x":-7,"y":3,"z":-3,"name":"Soil_Dirt"},{"x":-7,"y":4,"z":-3,"name":"Soil_Dirt"},{"x":-7,"y":5,"z":-3,"name":"Soil_Snow"},{"x":-7,"y":0,"z":-2,"name":"Soil_Dirt"},{"x":-7,"y":1,"z":-2,"name":"Soil_Dirt"},{"x":-7,"y":2,"z":-2,"name":"Soil_Dirt"},{"x":-7,"y":3,"z":-2,"name":"Soil_Dirt"},{"x":-7,"y":4,"z":-2,"name":"Soil_Dirt"},{"x":-7,"y":5,"z":-2,"name":"Soil_Snow"},{"x":-7,"y":0,"z":-1,"name":"Soil_Dirt"},{"x":-7,"y":1,"z":-1,"name":"Soil_Dirt"},{"x":-7,"y":2,"z":-1,"name":"Soil_Dirt"},{"x":-7,"y":3,"z":-1,"name":"Soil_Dirt"},{"x":-7,"y":4,"z":-1,"name":"Soil_Dirt"},{"x":-7,"y":5,"z":-1,"name":"Soil_Snow"},{"x":-7,"y":0,"z":0,"name":"Soil_Dirt"},{"x":-7,"y":1,"z":0,"name":"Soil_Dirt"},{"x":-7,"y":2,"z":0,"name":"Soil_Dirt"},{"x":-7,"y":3,"z":0,"name":"Soil_Dirt"},{"x":-7,"y":4,"z":0,"name":"Soil_Dirt"},{"x":-7,"y":5,"z":0,"name":"Soil_Snow"},{"x":-7,"y":0,"z":1,"name":"Soil_Dirt"},{"x":-7,"y":1,"z":1,"name":"Soil_Dirt"},{"x":-7,"y":2,"z":1,"name":"Soil_Dirt"},{"x":-7,"y":3,"z":1,"name":"Soil_Dirt"},{"x":-7,"y":4,"z":1,"name":"Soil_Dirt"},{"x":-7,"y":5,"z":1,"name":"Soil_Snow"},{"x":-7,"y":0,"z":2,"name":"Soil_Dirt"},{"x":-7,"y":1,"z":2,"name":"Soil_Dirt"},{"x":-7,"y":2,"z":2,"name":"Soil_Dirt"},{"x":-7,"y":3,"z":2,"name":"Soil_Dirt"},{"x":-7,"y":4,"z":2,"name":"Soil_Dirt"},{"x":-7,"y":5,"z":2,"name":"Soil_Snow"},{"x":-7,"y":0,"z":3,"name":"Soil_Dirt"},{"x":-7,"y":1,"z":3,"name":"Soil_Dirt"},{"x":-7,"y":2,"z":3,"name":"Soil_Dirt"},{"x":-7,"y":3,"z":3,"name":"Soil_Dirt"},{"x":-7,"y":4,"z":3,"name":"Soil_Dirt"},{"x":-7,"y":5,"z":3,"name":"Rock_Ice_Permafrost","support":15},{"x":-7,"y":0,"z":4,"name":"Soil_Dirt"},{"x":-7,"y":1,"z":4,"name":"Soil_Dirt"},{"x":-7,"y":2,"z":4,"name":"Soil_Dirt"},{"x":-7,"y":3,"z":4,"name":"Soil_Dirt"},{"x":-7,"y":4,"z":4,"name":"Soil_Dirt"},{"x":-7,"y":5,"z":4,"name":"Rock_Ice_Permafrost","support":15},{"x":-7,"y":0,"z":5,"name":"Soil_Dirt"},{"x":-7,"y":1,"z":5,"name":"Soil_Dirt"},{"x":-7,"y":2,"z":5,"name":"Soil_Dirt"},{"x":-7,"y":3,"z":5,"name":"Soil_Dirt"},{"x":-7,"y":4,"z":5,"name":"Soil_Dirt"},{"x":-7,"y":5,"z":5,"name":"Soil_Snow"},{"x":-7,"y":0,"z":6,"name":"Soil_Dirt"},{"x":-7,"y":1,"z":6,"name":"Soil_Dirt"},{"x":-7,"y":2,"z":6,"name":"Soil_Dirt"},{"x":-7,"y":3,"z":6,"name":"Soil_Dirt"},{"x":-7,"y":4,"z":6,"name":"Soil_Dirt"},{"x":-7,"y":5,"z":6,"name":"Soil_Snow"},{"x":-7,"y":0,"z":7,"name":"Soil_Dirt"},{"x":-7,"y":1,"z":7,"name":"Soil_Dirt"},{"x":-7,"y":2,"z":7,"name":"Soil_Dirt"},{"x":-7,"y":3,"z":7,"name":"Soil_Dirt"},{"x":-7,"y":4,"z":7,"name":"Soil_Dirt"},{"x":-7,"y":5,"z":7,"name":"Soil_Snow"},{"x":-7,"y":0,"z":8,"name":"Soil_Dirt"},{"x":-7,"y":1,"z":8,"name":"Soil_Dirt"},{"x":-7,"y":2,"z":8,"name":"Soil_Dirt"},{"x":-7,"y":3,"z":8,"name":"Soil_Dirt"},{"x":-7,"y":4,"z":8,"name":"Soil_Dirt"},{"x":-7,"y":5,"z":8,"name":"Soil_Snow"},{"x":-7,"y":0,"z":9,"name":"Soil_Dirt"},{"x":-7,"y":1,"z":9,"name":"Soil_Dirt"},{"x":-7,"y":2,"z":9,"name":"Soil_Dirt"},{"x":-7,"y":3,"z":9,"name":"Soil_Dirt"},{"x":-7,"y":4,"z":9,"name":"Soil_Dirt"},{"x":-7,"y":5,"z":9,"name":"Soil_Snow"},{"x":-7,"y":0,"z":10,"name":"Soil_Dirt"},{"x":-7,"y":1,"z":10,"name":"Soil_Dirt"},{"x":-7,"y":2,"z":10,"name":"Soil_Dirt"},{"x":-7,"y":3,"z":10,"name":"Soil_Dirt"},{"x":-7,"y":4,"z":10,"name":"Soil_Dirt"},{"x":-7,"y":5,"z":10,"name":"Soil_Snow"},{"x":-7,"y":0,"z":11,"name":"Soil_Dirt"},{"x":-7,"y":1,"z":11,"name":"Soil_Dirt"},{"x":-7,"y":2,"z":11,"name":"Soil_Dirt"},{"x":-7,"y":3,"z":11,"name":"Soil_Dirt"},{"x":-7,"y":4,"z":11,"name":"Soil_Dirt"},{"x":-7,"y":5,"z":11,"name":"Soil_Snow"},{"x":-7,"y":0,"z":12,"name":"Soil_Dirt"},{"x":-7,"y":1,"z":12,"name":"Soil_Dirt"},{"x":-7,"y":2,"z":12,"name":"Soil_Dirt"},{"x":-7,"y":3,"z":12,"name":"Soil_Dirt"},{"x":-7,"y":4,"z":12,"name":"Soil_Dirt"},{"x":-7,"y":5,"z":12,"name":"Soil_Snow"},{"x":-7,"y":0,"z":13,"name":"Soil_Dirt"},{"x":-7,"y":1,"z":13,"name":"Soil_Dirt"},{"x":-7,"y":2,"z":13,"name":"Soil_Dirt"},{"x":-7,"y":3,"z":13,"name":"Soil_Dirt"},{"x":-7,"y":4,"z":13,"name":"Soil_Dirt"},{"x":-7,"y":5,"z":13,"name":"Soil_Snow"},{"x":-7,"y":0,"z":14,"name":"Soil_Dirt"},{"x":-7,"y":1,"z":14,"name":"Soil_Dirt"},{"x":-7,"y":2,"z":14,"name":"Soil_Dirt"},{"x":-7,"y":3,"z":14,"name":"Soil_Dirt"},{"x":-7,"y":4,"z":14,"name":"Soil_Dirt"},{"x":-7,"y":5,"z":14,"name":"Soil_Snow"},{"x":-7,"y":0,"z":15,"name":"Soil_Dirt"},{"x":-7,"y":1,"z":15,"name":"Soil_Dirt"},{"x":-7,"y":2,"z":15,"name":"Soil_Dirt"},{"x":-7,"y":3,"z":15,"name":"Soil_Dirt"},{"x":-7,"y":4,"z":15,"name":"Soil_Dirt"},{"x":-7,"y":5,"z":15,"name":"Rock_Stone_Brick_Smooth"},{"x":-6,"y":0,"z":-14,"name":"Soil_Dirt"},{"x":-6,"y":1,"z":-14,"name":"Soil_Dirt"},{"x":-6,"y":2,"z":-14,"name":"Soil_Dirt"},{"x":-6,"y":3,"z":-14,"name":"Soil_Dirt"},{"x":-6,"y":4,"z":-14,"name":"Soil_Dirt"},{"x":-6,"y":5,"z":-14,"name":"Rock_Stone_Brick_Smooth"},{"x":-6,"y":0,"z":-13,"name":"Soil_Dirt"},{"x":-6,"y":1,"z":-13,"name":"Soil_Dirt"},{"x":-6,"y":2,"z":-13,"name":"Soil_Dirt"},{"x":-6,"y":3,"z":-13,"name":"Soil_Dirt"},{"x":-6,"y":4,"z":-13,"name":"Soil_Dirt"},{"x":-6,"y":5,"z":-13,"name":"Soil_Snow"},{"x":-6,"y":0,"z":-12,"name":"Soil_Dirt"},{"x":-6,"y":1,"z":-12,"name":"Soil_Dirt"},{"x":-6,"y":2,"z":-12,"name":"Soil_Dirt"},{"x":-6,"y":3,"z":-12,"name":"Soil_Dirt"},{"x":-6,"y":4,"z":-12,"name":"Soil_Dirt"},{"x":-6,"y":5,"z":-12,"name":"Soil_Snow"},{"x":-6,"y":6,"z":-12,"name":"Soil_Snow_Half","support":15},{"x":-6,"y":0,"z":-11,"name":"Soil_Dirt"},{"x":-6,"y":1,"z":-11,"name":"Soil_Dirt"},{"x":-6,"y":2,"z":-11,"name":"Soil_Dirt"},{"x":-6,"y":3,"z":-11,"name":"Soil_Dirt"},{"x":-6,"y":4,"z":-11,"name":"Soil_Dirt"},{"x":-6,"y":5,"z":-11,"name":"Soil_Snow"},{"x":-6,"y":6,"z":-11,"name":"*Soil_Snow_Half_State_Definitions_Block"},{"x":-6,"y":0,"z":-10,"name":"Soil_Dirt"},{"x":-6,"y":1,"z":-10,"name":"Soil_Dirt"},{"x":-6,"y":2,"z":-10,"name":"Soil_Dirt"},{"x":-6,"y":3,"z":-10,"name":"Soil_Dirt"},{"x":-6,"y":4,"z":-10,"name":"Soil_Dirt"},{"x":-6,"y":5,"z":-10,"name":"Soil_Snow"},{"x":-6,"y":6,"z":-10,"name":"Soil_Snow_Half","support":15},{"x":-6,"y":0,"z":-9,"name":"Soil_Dirt"},{"x":-6,"y":1,"z":-9,"name":"Soil_Dirt"},{"x":-6,"y":2,"z":-9,"name":"Soil_Dirt"},{"x":-6,"y":3,"z":-9,"name":"Soil_Dirt"},{"x":-6,"y":4,"z":-9,"name":"Soil_Dirt"},{"x":-6,"y":5,"z":-9,"name":"Soil_Snow"},{"x":-6,"y":0,"z":-8,"name":"Soil_Dirt"},{"x":-6,"y":1,"z":-8,"name":"Soil_Dirt"},{"x":-6,"y":2,"z":-8,"name":"Soil_Dirt"},{"x":-6,"y":3,"z":-8,"name":"Soil_Dirt"},{"x":-6,"y":4,"z":-8,"name":"Soil_Dirt"},{"x":-6,"y":5,"z":-8,"name":"Soil_Snow"},{"x":-6,"y":0,"z":-7,"name":"Soil_Dirt"},{"x":-6,"y":1,"z":-7,"name":"Soil_Dirt"},{"x":-6,"y":2,"z":-7,"name":"Soil_Dirt"},{"x":-6,"y":3,"z":-7,"name":"Soil_Dirt"},{"x":-6,"y":4,"z":-7,"name":"Soil_Dirt"},{"x":-6,"y":5,"z":-7,"name":"Soil_Snow"},{"x":-6,"y":0,"z":-6,"name":"Soil_Dirt"},{"x":-6,"y":1,"z":-6,"name":"Soil_Dirt"},{"x":-6,"y":2,"z":-6,"name":"Soil_Dirt"},{"x":-6,"y":3,"z":-6,"name":"Soil_Dirt"},{"x":-6,"y":4,"z":-6,"name":"Soil_Dirt"},{"x":-6,"y":5,"z":-6,"name":"Soil_Snow"},{"x":-6,"y":0,"z":-5,"name":"Soil_Dirt"},{"x":-6,"y":1,"z":-5,"name":"Soil_Dirt"},{"x":-6,"y":2,"z":-5,"name":"Soil_Dirt"},{"x":-6,"y":3,"z":-5,"name":"Soil_Dirt"},{"x":-6,"y":4,"z":-5,"name":"Soil_Dirt"},{"x":-6,"y":5,"z":-5,"name":"Soil_Snow"},{"x":-6,"y":0,"z":-4,"name":"Soil_Dirt"},{"x":-6,"y":1,"z":-4,"name":"Soil_Dirt"},{"x":-6,"y":2,"z":-4,"name":"Soil_Dirt"},{"x":-6,"y":3,"z":-4,"name":"Soil_Dirt"},{"x":-6,"y":4,"z":-4,"name":"Soil_Dirt"},{"x":-6,"y":5,"z":-4,"name":"Soil_Snow"},{"x":-6,"y":0,"z":-3,"name":"Soil_Dirt"},{"x":-6,"y":1,"z":-3,"name":"Soil_Dirt"},{"x":-6,"y":2,"z":-3,"name":"Soil_Dirt"},{"x":-6,"y":3,"z":-3,"name":"Soil_Dirt"},{"x":-6,"y":4,"z":-3,"name":"Soil_Dirt"},{"x":-6,"y":5,"z":-3,"name":"Soil_Snow"},{"x":-6,"y":0,"z":-2,"name":"Soil_Dirt"},{"x":-6,"y":1,"z":-2,"name":"Soil_Dirt"},{"x":-6,"y":2,"z":-2,"name":"Soil_Dirt"},{"x":-6,"y":3,"z":-2,"name":"Soil_Dirt"},{"x":-6,"y":4,"z":-2,"name":"Soil_Dirt"},{"x":-6,"y":5,"z":-2,"name":"Soil_Snow"},{"x":-6,"y":0,"z":-1,"name":"Soil_Dirt"},{"x":-6,"y":1,"z":-1,"name":"Soil_Dirt"},{"x":-6,"y":2,"z":-1,"name":"Soil_Dirt"},{"x":-6,"y":3,"z":-1,"name":"Soil_Dirt"},{"x":-6,"y":4,"z":-1,"name":"Soil_Dirt"},{"x":-6,"y":5,"z":-1,"name":"Soil_Snow"},{"x":-6,"y":0,"z":0,"name":"Soil_Dirt"},{"x":-6,"y":1,"z":0,"name":"Soil_Dirt"},{"x":-6,"y":2,"z":0,"name":"Soil_Dirt"},{"x":-6,"y":3,"z":0,"name":"Soil_Dirt"},{"x":-6,"y":4,"z":0,"name":"Soil_Dirt"},{"x":-6,"y":5,"z":0,"name":"Soil_Snow"},{"x":-6,"y":0,"z":1,"name":"Soil_Dirt"},{"x":-6,"y":1,"z":1,"name":"Soil_Dirt"},{"x":-6,"y":2,"z":1,"name":"Soil_Dirt"},{"x":-6,"y":3,"z":1,"name":"Soil_Dirt"},{"x":-6,"y":4,"z":1,"name":"Soil_Dirt"},{"x":-6,"y":5,"z":1,"name":"Soil_Snow"},{"x":-6,"y":0,"z":2,"name":"Soil_Dirt"},{"x":-6,"y":1,"z":2,"name":"Soil_Dirt"},{"x":-6,"y":2,"z":2,"name":"Soil_Dirt"},{"x":-6,"y":3,"z":2,"name":"Soil_Dirt"},{"x":-6,"y":4,"z":2,"name":"Soil_Dirt"},{"x":-6,"y":5,"z":2,"name":"Rock_Ice_Permafrost","support":15},{"x":-6,"y":0,"z":3,"name":"Soil_Dirt"},{"x":-6,"y":1,"z":3,"name":"Soil_Dirt"},{"x":-6,"y":2,"z":3,"name":"Soil_Dirt"},{"x":-6,"y":3,"z":3,"name":"Soil_Dirt"},{"x":-6,"y":4,"z":3,"name":"Soil_Dirt"},{"x":-6,"y":5,"z":3,"name":"Rock_Ice_Permafrost","support":15},{"x":-6,"y":0,"z":4,"name":"Soil_Dirt"},{"x":-6,"y":1,"z":4,"name":"Soil_Dirt"},{"x":-6,"y":2,"z":4,"name":"Soil_Dirt"},{"x":-6,"y":3,"z":4,"name":"Soil_Dirt"},{"x":-6,"y":4,"z":4,"name":"Soil_Dirt"},{"x":-6,"y":0,"z":5,"name":"Soil_Dirt"},{"x":-6,"y":1,"z":5,"name":"Soil_Dirt"},{"x":-6,"y":2,"z":5,"name":"Soil_Dirt"},{"x":-6,"y":3,"z":5,"name":"Soil_Dirt"},{"x":-6,"y":4,"z":5,"name":"Soil_Dirt"},{"x":-6,"y":5,"z":5,"name":"Rock_Ice_Permafrost","support":15},{"x":-6,"y":0,"z":6,"name":"Soil_Dirt"},{"x":-6,"y":1,"z":6,"name":"Soil_Dirt"},{"x":-6,"y":2,"z":6,"name":"Soil_Dirt"},{"x":-6,"y":3,"z":6,"name":"Soil_Dirt"},{"x":-6,"y":4,"z":6,"name":"Soil_Dirt"},{"x":-6,"y":5,"z":6,"name":"Soil_Snow"},{"x":-6,"y":0,"z":7,"name":"Soil_Dirt"},{"x":-6,"y":1,"z":7,"name":"Soil_Dirt"},{"x":-6,"y":2,"z":7,"name":"Soil_Dirt"},{"x":-6,"y":3,"z":7,"name":"Soil_Dirt"},{"x":-6,"y":4,"z":7,"name":"Soil_Dirt"},{"x":-6,"y":5,"z":7,"name":"Soil_Snow"},{"x":-6,"y":0,"z":8,"name":"Soil_Dirt"},{"x":-6,"y":1,"z":8,"name":"Soil_Dirt"},{"x":-6,"y":2,"z":8,"name":"Soil_Dirt"},{"x":-6,"y":3,"z":8,"name":"Soil_Dirt"},{"x":-6,"y":4,"z":8,"name":"Soil_Dirt"},{"x":-6,"y":5,"z":8,"name":"Soil_Snow"},{"x":-6,"y":0,"z":9,"name":"Soil_Dirt"},{"x":-6,"y":1,"z":9,"name":"Soil_Dirt"},{"x":-6,"y":2,"z":9,"name":"Soil_Dirt"},{"x":-6,"y":3,"z":9,"name":"Soil_Dirt"},{"x":-6,"y":4,"z":9,"name":"Soil_Dirt"},{"x":-6,"y":5,"z":9,"name":"Soil_Snow"},{"x":-6,"y":6,"z":9,"name":"Soil_Snow_Half","support":15},{"x":-6,"y":0,"z":10,"name":"Soil_Dirt"},{"x":-6,"y":1,"z":10,"name":"Soil_Dirt"},{"x":-6,"y":2,"z":10,"name":"Soil_Dirt"},{"x":-6,"y":3,"z":10,"name":"Soil_Dirt"},{"x":-6,"y":4,"z":10,"name":"Soil_Dirt"},{"x":-6,"y":5,"z":10,"name":"Soil_Snow"},{"x":-6,"y":6,"z":10,"name":"Soil_Snow_Half","support":15},{"x":-6,"y":0,"z":11,"name":"Soil_Dirt"},{"x":-6,"y":1,"z":11,"name":"Soil_Dirt"},{"x":-6,"y":2,"z":11,"name":"Soil_Dirt"},{"x":-6,"y":3,"z":11,"name":"Soil_Dirt"},{"x":-6,"y":4,"z":11,"name":"Soil_Dirt"},{"x":-6,"y":5,"z":11,"name":"Soil_Snow"},{"x":-6,"y":6,"z":11,"name":"Soil_Snow_Half","support":15},{"x":-6,"y":0,"z":12,"name":"Soil_Dirt"},{"x":-6,"y":1,"z":12,"name":"Soil_Dirt"},{"x":-6,"y":2,"z":12,"name":"Soil_Dirt"},{"x":-6,"y":3,"z":12,"name":"Soil_Dirt"},{"x":-6,"y":4,"z":12,"name":"Soil_Dirt"},{"x":-6,"y":5,"z":12,"name":"Soil_Snow"},{"x":-6,"y":0,"z":13,"name":"Soil_Dirt"},{"x":-6,"y":1,"z":13,"name":"Soil_Dirt"},{"x":-6,"y":2,"z":13,"name":"Soil_Dirt"},{"x":-6,"y":3,"z":13,"name":"Soil_Dirt"},{"x":-6,"y":4,"z":13,"name":"Soil_Dirt"},{"x":-6,"y":5,"z":13,"name":"Soil_Snow"},{"x":-6,"y":0,"z":14,"name":"Soil_Dirt"},{"x":-6,"y":1,"z":14,"name":"Soil_Dirt"},{"x":-6,"y":2,"z":14,"name":"Soil_Dirt"},{"x":-6,"y":3,"z":14,"name":"Soil_Dirt"},{"x":-6,"y":4,"z":14,"name":"Soil_Dirt"},{"x":-6,"y":5,"z":14,"name":"Soil_Snow"},{"x":-6,"y":0,"z":15,"name":"Soil_Dirt"},{"x":-6,"y":1,"z":15,"name":"Soil_Dirt"},{"x":-6,"y":2,"z":15,"name":"Soil_Dirt"},{"x":-6,"y":3,"z":15,"name":"Soil_Dirt"},{"x":-6,"y":4,"z":15,"name":"Soil_Dirt"},{"x":-6,"y":5,"z":15,"name":"Rock_Stone_Brick_Smooth"},{"x":-5,"y":0,"z":-14,"name":"Soil_Dirt"},{"x":-5,"y":1,"z":-14,"name":"Soil_Dirt"},{"x":-5,"y":2,"z":-14,"name":"Soil_Dirt"},{"x":-5,"y":3,"z":-14,"name":"Soil_Dirt"},{"x":-5,"y":4,"z":-14,"name":"Soil_Dirt"},{"x":-5,"y":5,"z":-14,"name":"Rock_Stone_Brick_Smooth"},{"x":-5,"y":0,"z":-13,"name":"Soil_Dirt"},{"x":-5,"y":1,"z":-13,"name":"Soil_Dirt"},{"x":-5,"y":2,"z":-13,"name":"Soil_Dirt"},{"x":-5,"y":3,"z":-13,"name":"Soil_Dirt"},{"x":-5,"y":4,"z":-13,"name":"Soil_Dirt"},{"x":-5,"y":5,"z":-13,"name":"Soil_Snow"},{"x":-5,"y":0,"z":-12,"name":"Soil_Dirt"},{"x":-5,"y":1,"z":-12,"name":"Soil_Dirt"},{"x":-5,"y":2,"z":-12,"name":"Soil_Dirt"},{"x":-5,"y":3,"z":-12,"name":"Soil_Dirt"},{"x":-5,"y":4,"z":-12,"name":"Soil_Dirt"},{"x":-5,"y":5,"z":-12,"name":"Soil_Snow"},{"x":-5,"y":0,"z":-11,"name":"Soil_Dirt"},{"x":-5,"y":1,"z":-11,"name":"Soil_Dirt"},{"x":-5,"y":2,"z":-11,"name":"Soil_Dirt"},{"x":-5,"y":3,"z":-11,"name":"Soil_Dirt"},{"x":-5,"y":4,"z":-11,"name":"Soil_Dirt"},{"x":-5,"y":5,"z":-11,"name":"Soil_Snow"},{"x":-5,"y":6,"z":-11,"name":"Soil_Snow_Half","support":15},{"x":-5,"y":0,"z":-10,"name":"Soil_Dirt"},{"x":-5,"y":1,"z":-10,"name":"Soil_Dirt"},{"x":-5,"y":2,"z":-10,"name":"Soil_Dirt"},{"x":-5,"y":3,"z":-10,"name":"Soil_Dirt"},{"x":-5,"y":4,"z":-10,"name":"Soil_Dirt"},{"x":-5,"y":5,"z":-10,"name":"Soil_Snow"},{"x":-5,"y":6,"z":-10,"name":"Furniture_Frozen_Castle_Secondary_Lamp","support":15},{"x":-5,"y":0,"z":-9,"name":"Soil_Dirt"},{"x":-5,"y":1,"z":-9,"name":"Soil_Dirt"},{"x":-5,"y":2,"z":-9,"name":"Soil_Dirt"},{"x":-5,"y":3,"z":-9,"name":"Soil_Dirt"},{"x":-5,"y":4,"z":-9,"name":"Soil_Dirt"},{"x":-5,"y":5,"z":-9,"name":"Soil_Snow"},{"x":-5,"y":0,"z":-8,"name":"Soil_Dirt"},{"x":-5,"y":1,"z":-8,"name":"Soil_Dirt"},{"x":-5,"y":2,"z":-8,"name":"Soil_Dirt"},{"x":-5,"y":3,"z":-8,"name":"Soil_Dirt"},{"x":-5,"y":4,"z":-8,"name":"Soil_Dirt"},{"x":-5,"y":5,"z":-8,"name":"Soil_Snow"},{"x":-5,"y":0,"z":-7,"name":"Soil_Dirt"},{"x":-5,"y":1,"z":-7,"name":"Soil_Dirt"},{"x":-5,"y":2,"z":-7,"name":"Soil_Dirt"},{"x":-5,"y":3,"z":-7,"name":"Soil_Dirt"},{"x":-5,"y":4,"z":-7,"name":"Soil_Dirt"},{"x":-5,"y":5,"z":-7,"name":"Soil_Snow"},{"x":-5,"y":0,"z":-6,"name":"Soil_Dirt"},{"x":-5,"y":1,"z":-6,"name":"Soil_Dirt"},{"x":-5,"y":2,"z":-6,"name":"Soil_Dirt"},{"x":-5,"y":3,"z":-6,"name":"Soil_Dirt"},{"x":-5,"y":4,"z":-6,"name":"Soil_Dirt"},{"x":-5,"y":5,"z":-6,"name":"Soil_Snow"},{"x":-5,"y":0,"z":-5,"name":"Soil_Dirt"},{"x":-5,"y":1,"z":-5,"name":"Soil_Dirt"},{"x":-5,"y":2,"z":-5,"name":"Soil_Dirt"},{"x":-5,"y":3,"z":-5,"name":"Soil_Dirt"},{"x":-5,"y":4,"z":-5,"name":"Soil_Dirt"},{"x":-5,"y":5,"z":-5,"name":"Soil_Snow"},{"x":-5,"y":0,"z":-4,"name":"Soil_Dirt"},{"x":-5,"y":1,"z":-4,"name":"Soil_Dirt"},{"x":-5,"y":2,"z":-4,"name":"Soil_Dirt"},{"x":-5,"y":3,"z":-4,"name":"Soil_Dirt"},{"x":-5,"y":4,"z":-4,"name":"Soil_Dirt"},{"x":-5,"y":5,"z":-4,"name":"Soil_Snow"},{"x":-5,"y":0,"z":-3,"name":"Soil_Dirt"},{"x":-5,"y":1,"z":-3,"name":"Soil_Dirt"},{"x":-5,"y":2,"z":-3,"name":"Soil_Dirt"},{"x":-5,"y":3,"z":-3,"name":"Soil_Dirt"},{"x":-5,"y":4,"z":-3,"name":"Soil_Dirt"},{"x":-5,"y":5,"z":-3,"name":"Soil_Snow"},{"x":-5,"y":0,"z":-2,"name":"Soil_Dirt"},{"x":-5,"y":1,"z":-2,"name":"Soil_Dirt"},{"x":-5,"y":2,"z":-2,"name":"Soil_Dirt"},{"x":-5,"y":3,"z":-2,"name":"Soil_Dirt"},{"x":-5,"y":4,"z":-2,"name":"Soil_Dirt"},{"x":-5,"y":5,"z":-2,"name":"Soil_Snow"},{"x":-5,"y":16,"z":-2,"name":"Plant_Leaves_Frostwood"},{"x":-5,"y":18,"z":-2,"name":"Plant_Leaves_Frostwood"},{"x":-5,"y":20,"z":-2,"name":"Plant_Leaves_Frostwood"},{"x":-5,"y":21,"z":-2,"name":"Plant_Leaves_Frostwood"},{"x":-5,"y":0,"z":-1,"name":"Soil_Dirt"},{"x":-5,"y":1,"z":-1,"name":"Soil_Dirt"},{"x":-5,"y":2,"z":-1,"name":"Soil_Dirt"},{"x":-5,"y":3,"z":-1,"name":"Soil_Dirt"},{"x":-5,"y":4,"z":-1,"name":"Soil_Dirt"},{"x":-5,"y":5,"z":-1,"name":"Soil_Snow"},{"x":-5,"y":0,"z":0,"name":"Soil_Dirt"},{"x":-5,"y":1,"z":0,"name":"Soil_Dirt"},{"x":-5,"y":2,"z":0,"name":"Soil_Dirt"},{"x":-5,"y":3,"z":0,"name":"Soil_Dirt"},{"x":-5,"y":4,"z":0,"name":"Soil_Dirt"},{"x":-5,"y":5,"z":0,"name":"Soil_Snow"},{"x":-5,"y":0,"z":1,"name":"Soil_Dirt"},{"x":-5,"y":1,"z":1,"name":"Soil_Dirt"},{"x":-5,"y":2,"z":1,"name":"Soil_Dirt"},{"x":-5,"y":3,"z":1,"name":"Soil_Dirt"},{"x":-5,"y":4,"z":1,"name":"Soil_Dirt"},{"x":-5,"y":5,"z":1,"name":"Soil_Snow"},{"x":-5,"y":0,"z":2,"name":"Soil_Dirt"},{"x":-5,"y":1,"z":2,"name":"Soil_Dirt"},{"x":-5,"y":2,"z":2,"name":"Soil_Dirt"},{"x":-5,"y":3,"z":2,"name":"Soil_Dirt"},{"x":-5,"y":4,"z":2,"name":"Soil_Dirt"},{"x":-5,"y":5,"z":2,"name":"Rock_Ice_Permafrost","support":15},{"x":-5,"y":0,"z":3,"name":"Soil_Dirt"},{"x":-5,"y":1,"z":3,"name":"Soil_Dirt"},{"x":-5,"y":2,"z":3,"name":"Soil_Dirt"},{"x":-5,"y":3,"z":3,"name":"Soil_Dirt"},{"x":-5,"y":4,"z":3,"name":"Soil_Dirt"},{"x":-5,"y":17,"z":3,"name":"Plant_Leaves_Frostwood"},{"x":-5,"y":0,"z":4,"name":"Soil_Dirt"},{"x":-5,"y":1,"z":4,"name":"Soil_Dirt"},{"x":-5,"y":2,"z":4,"name":"Soil_Dirt"},{"x":-5,"y":3,"z":4,"name":"Soil_Dirt"},{"x":-5,"y":4,"z":4,"name":"Soil_Dirt"},{"x":-5,"y":18,"z":4,"name":"Plant_Leaves_Frostwood"},{"x":-5,"y":0,"z":5,"name":"Soil_Dirt"},{"x":-5,"y":1,"z":5,"name":"Soil_Dirt"},{"x":-5,"y":2,"z":5,"name":"Soil_Dirt"},{"x":-5,"y":3,"z":5,"name":"Soil_Dirt"},{"x":-5,"y":4,"z":5,"name":"Soil_Dirt"},{"x":-5,"y":17,"z":5,"name":"Plant_Leaves_Frostwood"},{"x":-5,"y":19,"z":5,"name":"Plant_Leaves_Frostwood"},{"x":-5,"y":0,"z":6,"name":"Soil_Dirt"},{"x":-5,"y":1,"z":6,"name":"Soil_Dirt"},{"x":-5,"y":2,"z":6,"name":"Soil_Dirt"},{"x":-5,"y":3,"z":6,"name":"Soil_Dirt"},{"x":-5,"y":4,"z":6,"name":"Soil_Dirt"},{"x":-5,"y":5,"z":6,"name":"Rock_Ice_Permafrost","support":15},{"x":-5,"y":19,"z":6,"name":"Plant_Leaves_Frostwood"},{"x":-5,"y":0,"z":7,"name":"Soil_Dirt"},{"x":-5,"y":1,"z":7,"name":"Soil_Dirt"},{"x":-5,"y":2,"z":7,"name":"Soil_Dirt"},{"x":-5,"y":3,"z":7,"name":"Soil_Dirt"},{"x":-5,"y":4,"z":7,"name":"Soil_Dirt"},{"x":-5,"y":5,"z":7,"name":"Soil_Snow"},{"x":-5,"y":0,"z":8,"name":"Soil_Dirt"},{"x":-5,"y":1,"z":8,"name":"Soil_Dirt"},{"x":-5,"y":2,"z":8,"name":"Soil_Dirt"},{"x":-5,"y":3,"z":8,"name":"Soil_Dirt"},{"x":-5,"y":4,"z":8,"name":"Soil_Dirt"},{"x":-5,"y":5,"z":8,"name":"Soil_Snow"},{"x":-5,"y":0,"z":9,"name":"Soil_Dirt"},{"x":-5,"y":1,"z":9,"name":"Soil_Dirt"},{"x":-5,"y":2,"z":9,"name":"Soil_Dirt"},{"x":-5,"y":3,"z":9,"name":"Soil_Dirt"},{"x":-5,"y":4,"z":9,"name":"Soil_Dirt"},{"x":-5,"y":5,"z":9,"name":"Soil_Snow"},{"x":-5,"y":6,"z":9,"name":"Soil_Snow_Half","support":15},{"x":-5,"y":0,"z":10,"name":"Soil_Dirt"},{"x":-5,"y":1,"z":10,"name":"Soil_Dirt"},{"x":-5,"y":2,"z":10,"name":"Soil_Dirt"},{"x":-5,"y":3,"z":10,"name":"Soil_Dirt"},{"x":-5,"y":4,"z":10,"name":"Soil_Dirt"},{"x":-5,"y":5,"z":10,"name":"Soil_Snow"},{"x":-5,"y":6,"z":10,"name":"*Soil_Snow_Half_State_Definitions_Block"},{"x":-5,"y":0,"z":11,"name":"Soil_Dirt"},{"x":-5,"y":1,"z":11,"name":"Soil_Dirt"},{"x":-5,"y":2,"z":11,"name":"Soil_Dirt"},{"x":-5,"y":3,"z":11,"name":"Soil_Dirt"},{"x":-5,"y":4,"z":11,"name":"Soil_Dirt"},{"x":-5,"y":5,"z":11,"name":"Soil_Snow"},{"x":-5,"y":6,"z":11,"name":"Soil_Snow_Half","support":15},{"x":-5,"y":0,"z":12,"name":"Soil_Dirt"},{"x":-5,"y":1,"z":12,"name":"Soil_Dirt"},{"x":-5,"y":2,"z":12,"name":"Soil_Dirt"},{"x":-5,"y":3,"z":12,"name":"Soil_Dirt"},{"x":-5,"y":4,"z":12,"name":"Soil_Dirt"},{"x":-5,"y":5,"z":12,"name":"Soil_Snow"},{"x":-5,"y":0,"z":13,"name":"Soil_Dirt"},{"x":-5,"y":1,"z":13,"name":"Soil_Dirt"},{"x":-5,"y":2,"z":13,"name":"Soil_Dirt"},{"x":-5,"y":3,"z":13,"name":"Soil_Dirt"},{"x":-5,"y":4,"z":13,"name":"Soil_Dirt"},{"x":-5,"y":5,"z":13,"name":"Soil_Snow"},{"x":-5,"y":0,"z":14,"name":"Soil_Dirt"},{"x":-5,"y":1,"z":14,"name":"Soil_Dirt"},{"x":-5,"y":2,"z":14,"name":"Soil_Dirt"},{"x":-5,"y":3,"z":14,"name":"Soil_Dirt"},{"x":-5,"y":4,"z":14,"name":"Soil_Dirt"},{"x":-5,"y":5,"z":14,"name":"Soil_Snow"},{"x":-5,"y":0,"z":15,"name":"Soil_Dirt"},{"x":-5,"y":1,"z":15,"name":"Soil_Dirt"},{"x":-5,"y":2,"z":15,"name":"Soil_Dirt"},{"x":-5,"y":3,"z":15,"name":"Soil_Dirt"},{"x":-5,"y":4,"z":15,"name":"Soil_Dirt"},{"x":-5,"y":5,"z":15,"name":"Rock_Stone_Brick_Smooth"},{"x":-4,"y":0,"z":-14,"name":"Soil_Dirt"},{"x":-4,"y":1,"z":-14,"name":"Soil_Dirt"},{"x":-4,"y":2,"z":-14,"name":"Soil_Dirt"},{"x":-4,"y":3,"z":-14,"name":"Soil_Dirt"},{"x":-4,"y":4,"z":-14,"name":"Soil_Dirt"},{"x":-4,"y":5,"z":-14,"name":"Rock_Stone_Brick_Smooth"},{"x":-4,"y":0,"z":-13,"name":"Soil_Dirt"},{"x":-4,"y":1,"z":-13,"name":"Soil_Dirt"},{"x":-4,"y":2,"z":-13,"name":"Soil_Dirt"},{"x":-4,"y":3,"z":-13,"name":"Soil_Dirt"},{"x":-4,"y":4,"z":-13,"name":"Soil_Dirt"},{"x":-4,"y":5,"z":-13,"name":"Soil_Snow"},{"x":-4,"y":0,"z":-12,"name":"Soil_Dirt"},{"x":-4,"y":1,"z":-12,"name":"Soil_Dirt"},{"x":-4,"y":2,"z":-12,"name":"Soil_Dirt"},{"x":-4,"y":3,"z":-12,"name":"Soil_Dirt"},{"x":-4,"y":4,"z":-12,"name":"Soil_Dirt"},{"x":-4,"y":5,"z":-12,"name":"Soil_Snow"},{"x":-4,"y":0,"z":-11,"name":"Soil_Dirt"},{"x":-4,"y":1,"z":-11,"name":"Soil_Dirt"},{"x":-4,"y":2,"z":-11,"name":"Soil_Dirt"},{"x":-4,"y":3,"z":-11,"name":"Soil_Dirt"},{"x":-4,"y":4,"z":-11,"name":"Soil_Dirt"},{"x":-4,"y":5,"z":-11,"name":"Soil_Snow"},{"x":-4,"y":0,"z":-10,"name":"Soil_Dirt"},{"x":-4,"y":1,"z":-10,"name":"Soil_Dirt"},{"x":-4,"y":2,"z":-10,"name":"Soil_Dirt"},{"x":-4,"y":3,"z":-10,"name":"Soil_Dirt"},{"x":-4,"y":4,"z":-10,"name":"Soil_Dirt"},{"x":-4,"y":5,"z":-10,"name":"Soil_Snow"},{"x":-4,"y":0,"z":-9,"name":"Soil_Dirt"},{"x":-4,"y":1,"z":-9,"name":"Soil_Dirt"},{"x":-4,"y":2,"z":-9,"name":"Soil_Dirt"},{"x":-4,"y":3,"z":-9,"name":"Soil_Dirt"},{"x":-4,"y":4,"z":-9,"name":"Soil_Dirt"},{"x":-4,"y":5,"z":-9,"name":"Soil_Snow"},{"x":-4,"y":0,"z":-8,"name":"Soil_Dirt"},{"x":-4,"y":1,"z":-8,"name":"Soil_Dirt"},{"x":-4,"y":2,"z":-8,"name":"Soil_Dirt"},{"x":-4,"y":3,"z":-8,"name":"Soil_Dirt"},{"x":-4,"y":4,"z":-8,"name":"Soil_Dirt"},{"x":-4,"y":5,"z":-8,"name":"Soil_Snow"},{"x":-4,"y":0,"z":-7,"name":"Soil_Dirt"},{"x":-4,"y":1,"z":-7,"name":"Soil_Dirt"},{"x":-4,"y":2,"z":-7,"name":"Soil_Dirt"},{"x":-4,"y":3,"z":-7,"name":"Soil_Dirt"},{"x":-4,"y":4,"z":-7,"name":"Soil_Dirt"},{"x":-4,"y":5,"z":-7,"name":"Soil_Snow"},{"x":-4,"y":0,"z":-6,"name":"Soil_Dirt"},{"x":-4,"y":1,"z":-6,"name":"Soil_Dirt"},{"x":-4,"y":2,"z":-6,"name":"Soil_Dirt"},{"x":-4,"y":3,"z":-6,"name":"Soil_Dirt"},{"x":-4,"y":4,"z":-6,"name":"Soil_Dirt"},{"x":-4,"y":5,"z":-6,"name":"Soil_Snow"},{"x":-4,"y":0,"z":-5,"name":"Soil_Dirt"},{"x":-4,"y":1,"z":-5,"name":"Soil_Dirt"},{"x":-4,"y":2,"z":-5,"name":"Soil_Dirt"},{"x":-4,"y":3,"z":-5,"name":"Soil_Dirt"},{"x":-4,"y":4,"z":-5,"name":"Soil_Dirt"},{"x":-4,"y":5,"z":-5,"name":"Soil_Snow"},{"x":-4,"y":0,"z":-4,"name":"Soil_Dirt"},{"x":-4,"y":1,"z":-4,"name":"Soil_Dirt"},{"x":-4,"y":2,"z":-4,"name":"Soil_Dirt"},{"x":-4,"y":3,"z":-4,"name":"Soil_Dirt"},{"x":-4,"y":4,"z":-4,"name":"Soil_Dirt"},{"x":-4,"y":5,"z":-4,"name":"Soil_Snow"},{"x":-4,"y":0,"z":-3,"name":"Soil_Dirt"},{"x":-4,"y":1,"z":-3,"name":"Soil_Dirt"},{"x":-4,"y":2,"z":-3,"name":"Soil_Dirt"},{"x":-4,"y":3,"z":-3,"name":"Soil_Dirt"},{"x":-4,"y":4,"z":-3,"name":"Soil_Dirt"},{"x":-4,"y":5,"z":-3,"name":"Soil_Snow"},{"x":-4,"y":18,"z":-3,"name":"Plant_Leaves_Frostwood"},{"x":-4,"y":19,"z":-3,"name":"Plant_Leaves_Frostwood"},{"x":-4,"y":0,"z":-2,"name":"Soil_Dirt"},{"x":-4,"y":1,"z":-2,"name":"Soil_Dirt"},{"x":-4,"y":2,"z":-2,"name":"Soil_Dirt"},{"x":-4,"y":3,"z":-2,"name":"Soil_Dirt"},{"x":-4,"y":4,"z":-2,"name":"Soil_Dirt"},{"x":-4,"y":5,"z":-2,"name":"Soil_Snow"},{"x":-4,"y":6,"z":-2,"name":"Furniture_Frozen_Castle_Secondary_Lamp","support":15},{"x":-4,"y":15,"z":-2,"name":"Plant_Leaves_Frostwood"},{"x":-4,"y":16,"z":-2,"name":"Plant_Leaves_Frostwood"},{"x":-4,"y":17,"z":-2,"name":"Plant_Leaves_Frostwood"},{"x":-4,"y":18,"z":-2,"name":"Wood_Ice_Branch_Corner","rotation":3},{"x":-4,"y":19,"z":-2,"name":"Wood_Ice_Branch_Long"},{"x":-4,"y":20,"z":-2,"name":"Plant_Leaves_Frostwood"},{"x":-4,"y":0,"z":-1,"name":"Soil_Dirt"},{"x":-4,"y":1,"z":-1,"name":"Soil_Dirt"},{"x":-4,"y":2,"z":-1,"name":"Soil_Dirt"},{"x":-4,"y":3,"z":-1,"name":"Soil_Dirt"},{"x":-4,"y":4,"z":-1,"name":"Soil_Dirt"},{"x":-4,"y":5,"z":-1,"name":"Soil_Snow"},{"x":-4,"y":6,"z":-1,"name":"Rubble_Ice","support":15},{"x":-4,"y":17,"z":-1,"name":"Plant_Leaves_Frostwood"},{"x":-4,"y":19,"z":-1,"name":"Plant_Leaves_Frostwood"},{"x":-4,"y":0,"z":0,"name":"Soil_Dirt"},{"x":-4,"y":1,"z":0,"name":"Soil_Dirt"},{"x":-4,"y":2,"z":0,"name":"Soil_Dirt"},{"x":-4,"y":3,"z":0,"name":"Soil_Dirt"},{"x":-4,"y":4,"z":0,"name":"Soil_Dirt"},{"x":-4,"y":5,"z":0,"name":"Soil_Snow"},{"x":-4,"y":6,"z":0,"name":"Plant_Grass_Snowy","support":15},{"x":-4,"y":0,"z":1,"name":"Soil_Dirt"},{"x":-4,"y":1,"z":1,"name":"Soil_Dirt"},{"x":-4,"y":2,"z":1,"name":"Soil_Dirt"},{"x":-4,"y":3,"z":1,"name":"Soil_Dirt"},{"x":-4,"y":4,"z":1,"name":"Soil_Dirt"},{"x":-4,"y":5,"z":1,"name":"Soil_Snow"},{"x":-4,"y":0,"z":2,"name":"Soil_Dirt"},{"x":-4,"y":1,"z":2,"name":"Soil_Dirt"},{"x":-4,"y":2,"z":2,"name":"Soil_Dirt"},{"x":-4,"y":3,"z":2,"name":"Soil_Dirt"},{"x":-4,"y":4,"z":2,"name":"Soil_Dirt"},{"x":-4,"y":5,"z":2,"name":"Soil_Snow"},{"x":-4,"y":17,"z":2,"name":"Plant_Leaves_Frostwood"},{"x":-4,"y":0,"z":3,"name":"Soil_Dirt"},{"x":-4,"y":1,"z":3,"name":"Soil_Dirt"},{"x":-4,"y":2,"z":3,"name":"Soil_Dirt"},{"x":-4,"y":3,"z":3,"name":"Soil_Dirt"},{"x":-4,"y":4,"z":3,"name":"Soil_Dirt"},{"x":-4,"y":5,"z":3,"name":"Rock_Ice_Permafrost","support":15},{"x":-4,"y":17,"z":3,"name":"Plant_Leaves_Frostwood"},{"x":-4,"y":18,"z":3,"name":"Plant_Leaves_Frostwood"},{"x":-4,"y":19,"z":3,"name":"Plant_Leaves_Frostwood"},{"x":-4,"y":0,"z":4,"name":"Soil_Dirt"},{"x":-4,"y":1,"z":4,"name":"Soil_Dirt"},{"x":-4,"y":2,"z":4,"name":"Soil_Dirt"},{"x":-4,"y":3,"z":4,"name":"Soil_Dirt"},{"x":-4,"y":4,"z":4,"name":"Soil_Dirt"},{"x":-4,"y":17,"z":4,"name":"Wood_Ice_Branch_Corner","rotation":3},{"x":-4,"y":18,"z":4,"name":"Wood_Ice_Branch_Corner","rotation":8},{"x":-4,"y":19,"z":4,"name":"Plant_Leaves_Frostwood"},{"x":-4,"y":0,"z":5,"name":"Soil_Dirt"},{"x":-4,"y":1,"z":5,"name":"Soil_Dirt"},{"x":-4,"y":2,"z":5,"name":"Soil_Dirt"},{"x":-4,"y":3,"z":5,"name":"Soil_Dirt"},{"x":-4,"y":4,"z":5,"name":"Soil_Dirt"},{"x":-4,"y":17,"z":5,"name":"Plant_Leaves_Frostwood"},{"x":-4,"y":18,"z":5,"name":"Wood_Ice_Branch_Corner"},{"x":-4,"y":19,"z":5,"name":"Wood_Ice_Branch_Long"},{"x":-4,"y":20,"z":5,"name":"Plant_Leaves_Frostwood"},{"x":-4,"y":0,"z":6,"name":"Soil_Dirt"},{"x":-4,"y":1,"z":6,"name":"Soil_Dirt"},{"x":-4,"y":2,"z":6,"name":"Soil_Dirt"},{"x":-4,"y":3,"z":6,"name":"Soil_Dirt"},{"x":-4,"y":4,"z":6,"name":"Soil_Dirt"},{"x":-4,"y":5,"z":6,"name":"Rock_Ice_Permafrost","support":15},{"x":-4,"y":17,"z":6,"name":"Plant_Leaves_Frostwood"},{"x":-4,"y":18,"z":6,"name":"Plant_Leaves_Frostwood"},{"x":-4,"y":19,"z":6,"name":"Plant_Leaves_Frostwood"},{"x":-4,"y":20,"z":6,"name":"Plant_Leaves_Frostwood"},{"x":-4,"y":21,"z":6,"name":"Plant_Leaves_Frostwood"},{"x":-4,"y":0,"z":7,"name":"Soil_Dirt"},{"x":-4,"y":1,"z":7,"name":"Soil_Dirt"},{"x":-4,"y":2,"z":7,"name":"Soil_Dirt"},{"x":-4,"y":3,"z":7,"name":"Soil_Dirt"},{"x":-4,"y":4,"z":7,"name":"Soil_Dirt"},{"x":-4,"y":5,"z":7,"name":"Soil_Snow"},{"x":-4,"y":0,"z":8,"name":"Soil_Dirt"},{"x":-4,"y":1,"z":8,"name":"Soil_Dirt"},{"x":-4,"y":2,"z":8,"name":"Soil_Dirt"},{"x":-4,"y":3,"z":8,"name":"Soil_Dirt"},{"x":-4,"y":4,"z":8,"name":"Soil_Dirt"},{"x":-4,"y":5,"z":8,"name":"Soil_Snow"},{"x":-4,"y":6,"z":8,"name":"Soil_Snow_Half","support":15},{"x":-4,"y":0,"z":9,"name":"Soil_Dirt"},{"x":-4,"y":1,"z":9,"name":"Soil_Dirt"},{"x":-4,"y":2,"z":9,"name":"Soil_Dirt"},{"x":-4,"y":3,"z":9,"name":"Soil_Dirt"},{"x":-4,"y":4,"z":9,"name":"Soil_Dirt"},{"x":-4,"y":5,"z":9,"name":"Soil_Snow"},{"x":-4,"y":6,"z":9,"name":"Soil_Snow_Half","support":15},{"x":-4,"y":0,"z":10,"name":"Soil_Dirt"},{"x":-4,"y":1,"z":10,"name":"Soil_Dirt"},{"x":-4,"y":2,"z":10,"name":"Soil_Dirt"},{"x":-4,"y":3,"z":10,"name":"Soil_Dirt"},{"x":-4,"y":4,"z":10,"name":"Soil_Dirt"},{"x":-4,"y":5,"z":10,"name":"Soil_Snow"},{"x":-4,"y":6,"z":10,"name":"*Soil_Snow_Half_State_Definitions_Block"},{"x":-4,"y":0,"z":11,"name":"Soil_Dirt"},{"x":-4,"y":1,"z":11,"name":"Soil_Dirt"},{"x":-4,"y":2,"z":11,"name":"Soil_Dirt"},{"x":-4,"y":3,"z":11,"name":"Soil_Dirt"},{"x":-4,"y":4,"z":11,"name":"Soil_Dirt"},{"x":-4,"y":5,"z":11,"name":"Soil_Snow"},{"x":-4,"y":6,"z":11,"name":"Soil_Snow_Half","support":15},{"x":-4,"y":0,"z":12,"name":"Soil_Dirt"},{"x":-4,"y":1,"z":12,"name":"Soil_Dirt"},{"x":-4,"y":2,"z":12,"name":"Soil_Dirt"},{"x":-4,"y":3,"z":12,"name":"Soil_Dirt"},{"x":-4,"y":4,"z":12,"name":"Soil_Dirt"},{"x":-4,"y":5,"z":12,"name":"Soil_Snow"},{"x":-4,"y":0,"z":13,"name":"Soil_Dirt"},{"x":-4,"y":1,"z":13,"name":"Soil_Dirt"},{"x":-4,"y":2,"z":13,"name":"Soil_Dirt"},{"x":-4,"y":3,"z":13,"name":"Soil_Dirt"},{"x":-4,"y":4,"z":13,"name":"Soil_Dirt"},{"x":-4,"y":5,"z":13,"name":"Soil_Snow"},{"x":-4,"y":0,"z":14,"name":"Soil_Dirt"},{"x":-4,"y":1,"z":14,"name":"Soil_Dirt"},{"x":-4,"y":2,"z":14,"name":"Soil_Dirt"},{"x":-4,"y":3,"z":14,"name":"Soil_Dirt"},{"x":-4,"y":4,"z":14,"name":"Soil_Dirt"},{"x":-4,"y":5,"z":14,"name":"Soil_Snow"},{"x":-4,"y":0,"z":15,"name":"Soil_Dirt"},{"x":-4,"y":1,"z":15,"name":"Soil_Dirt"},{"x":-4,"y":2,"z":15,"name":"Soil_Dirt"},{"x":-4,"y":3,"z":15,"name":"Soil_Dirt"},{"x":-4,"y":4,"z":15,"name":"Soil_Dirt"},{"x":-4,"y":5,"z":15,"name":"Rock_Stone_Brick_Smooth"},{"x":-3,"y":0,"z":-14,"name":"Soil_Dirt"},{"x":-3,"y":1,"z":-14,"name":"Soil_Dirt"},{"x":-3,"y":2,"z":-14,"name":"Soil_Dirt"},{"x":-3,"y":3,"z":-14,"name":"Soil_Dirt"},{"x":-3,"y":4,"z":-14,"name":"Soil_Dirt"},{"x":-3,"y":5,"z":-14,"name":"Rock_Stone_Brick_Smooth"},{"x":-3,"y":0,"z":-13,"name":"Soil_Dirt"},{"x":-3,"y":1,"z":-13,"name":"Soil_Dirt"},{"x":-3,"y":2,"z":-13,"name":"Soil_Dirt"},{"x":-3,"y":3,"z":-13,"name":"Soil_Dirt"},{"x":-3,"y":4,"z":-13,"name":"Soil_Dirt"},{"x":-3,"y":5,"z":-13,"name":"Soil_Snow"},{"x":-3,"y":0,"z":-12,"name":"Soil_Dirt"},{"x":-3,"y":1,"z":-12,"name":"Soil_Dirt"},{"x":-3,"y":2,"z":-12,"name":"Soil_Dirt"},{"x":-3,"y":3,"z":-12,"name":"Soil_Dirt"},{"x":-3,"y":4,"z":-12,"name":"Soil_Dirt"},{"x":-3,"y":5,"z":-12,"name":"Soil_Snow"},{"x":-3,"y":6,"z":-12,"name":"Plant_Bush_Winter_Snow","support":15},{"x":-3,"y":0,"z":-11,"name":"Soil_Dirt"},{"x":-3,"y":1,"z":-11,"name":"Soil_Dirt"},{"x":-3,"y":2,"z":-11,"name":"Soil_Dirt"},{"x":-3,"y":3,"z":-11,"name":"Soil_Dirt"},{"x":-3,"y":4,"z":-11,"name":"Soil_Dirt"},{"x":-3,"y":5,"z":-11,"name":"Soil_Snow"},{"x":-3,"y":0,"z":-10,"name":"Soil_Dirt"},{"x":-3,"y":1,"z":-10,"name":"Soil_Dirt"},{"x":-3,"y":2,"z":-10,"name":"Soil_Dirt"},{"x":-3,"y":3,"z":-10,"name":"Soil_Dirt"},{"x":-3,"y":4,"z":-10,"name":"Soil_Dirt"},{"x":-3,"y":5,"z":-10,"name":"Soil_Snow"},{"x":-3,"y":0,"z":-9,"name":"Soil_Dirt"},{"x":-3,"y":1,"z":-9,"name":"Soil_Dirt"},{"x":-3,"y":2,"z":-9,"name":"Soil_Dirt"},{"x":-3,"y":3,"z":-9,"name":"Soil_Dirt"},{"x":-3,"y":4,"z":-9,"name":"Soil_Dirt"},{"x":-3,"y":5,"z":-9,"name":"Soil_Snow"},{"x":-3,"y":0,"z":-8,"name":"Soil_Dirt"},{"x":-3,"y":1,"z":-8,"name":"Soil_Dirt"},{"x":-3,"y":2,"z":-8,"name":"Soil_Dirt"},{"x":-3,"y":3,"z":-8,"name":"Soil_Dirt"},{"x":-3,"y":4,"z":-8,"name":"Soil_Dirt"},{"x":-3,"y":5,"z":-8,"name":"Soil_Snow"},{"x":-3,"y":0,"z":-7,"name":"Soil_Dirt"},{"x":-3,"y":1,"z":-7,"name":"Soil_Dirt"},{"x":-3,"y":2,"z":-7,"name":"Soil_Dirt"},{"x":-3,"y":3,"z":-7,"name":"Soil_Dirt"},{"x":-3,"y":4,"z":-7,"name":"Soil_Dirt"},{"x":-3,"y":5,"z":-7,"name":"Soil_Snow"},{"x":-3,"y":0,"z":-6,"name":"Soil_Dirt"},{"x":-3,"y":1,"z":-6,"name":"Soil_Dirt"},{"x":-3,"y":2,"z":-6,"name":"Soil_Dirt"},{"x":-3,"y":3,"z":-6,"name":"Soil_Dirt"},{"x":-3,"y":4,"z":-6,"name":"Soil_Dirt"},{"x":-3,"y":5,"z":-6,"name":"Soil_Snow"},{"x":-3,"y":0,"z":-5,"name":"Soil_Dirt"},{"x":-3,"y":1,"z":-5,"name":"Soil_Dirt"},{"x":-3,"y":2,"z":-5,"name":"Soil_Dirt"},{"x":-3,"y":3,"z":-5,"name":"Soil_Dirt"},{"x":-3,"y":4,"z":-5,"name":"Soil_Dirt"},{"x":-3,"y":5,"z":-5,"name":"Soil_Snow"},{"x":-3,"y":0,"z":-4,"name":"Soil_Dirt"},{"x":-3,"y":1,"z":-4,"name":"Soil_Dirt"},{"x":-3,"y":2,"z":-4,"name":"Soil_Dirt"},{"x":-3,"y":3,"z":-4,"name":"Soil_Dirt"},{"x":-3,"y":4,"z":-4,"name":"Soil_Dirt"},{"x":-3,"y":5,"z":-4,"name":"Soil_Snow"},{"x":-3,"y":17,"z":-4,"name":"Plant_Leaves_Frostwood"},{"x":-3,"y":0,"z":-3,"name":"Soil_Dirt"},{"x":-3,"y":1,"z":-3,"name":"Soil_Dirt"},{"x":-3,"y":2,"z":-3,"name":"Soil_Dirt"},{"x":-3,"y":3,"z":-3,"name":"Soil_Dirt"},{"x":-3,"y":4,"z":-3,"name":"Soil_Dirt"},{"x":-3,"y":5,"z":-3,"name":"Soil_Snow"},{"x":-3,"y":17,"z":-3,"name":"Plant_Leaves_Frostwood"},{"x":-3,"y":18,"z":-3,"name":"Plant_Leaves_Frostwood"},{"x":-3,"y":0,"z":-2,"name":"Soil_Dirt"},{"x":-3,"y":1,"z":-2,"name":"Soil_Dirt"},{"x":-3,"y":2,"z":-2,"name":"Soil_Dirt"},{"x":-3,"y":3,"z":-2,"name":"Soil_Dirt"},{"x":-3,"y":4,"z":-2,"name":"Soil_Dirt"},{"x":-3,"y":5,"z":-2,"name":"Soil_Snow"},{"x":-3,"y":16,"z":-2,"name":"Wood_Ice_Branch_Corner","rotation":3},{"x":-3,"y":17,"z":-2,"name":"Wood_Ice_Branch_Long"},{"x":-3,"y":18,"z":-2,"name":"Wood_Ice_Branch_Corner","rotation":11},{"x":-3,"y":19,"z":-2,"name":"Plant_Leaves_Frostwood"},{"x":-3,"y":0,"z":-1,"name":"Soil_Dirt"},{"x":-3,"y":1,"z":-1,"name":"Soil_Dirt"},{"x":-3,"y":2,"z":-1,"name":"Soil_Dirt"},{"x":-3,"y":3,"z":-1,"name":"Soil_Dirt"},{"x":-3,"y":4,"z":-1,"name":"Soil_Dirt"},{"x":-3,"y":5,"z":-1,"name":"Soil_Snow"},{"x":-3,"y":6,"z":-1,"name":"Wood_Ice_Trunk_Full"},{"x":-3,"y":7,"z":-1,"name":"Wood_Ice_Trunk"},{"x":-3,"y":8,"z":-1,"name":"Wood_Ice_Trunk_Full"},{"x":-3,"y":16,"z":-1,"name":"Plant_Leaves_Frostwood"},{"x":-3,"y":17,"z":-1,"name":"Plant_Leaves_Frostwood"},{"x":-3,"y":18,"z":-1,"name":"Plant_Leaves_Frostwood"},{"x":-3,"y":23,"z":-1,"name":"Plant_Leaves_Frostwood"},{"x":-3,"y":0,"z":0,"name":"Soil_Dirt"},{"x":-3,"y":1,"z":0,"name":"Soil_Dirt"},{"x":-3,"y":2,"z":0,"name":"Soil_Dirt"},{"x":-3,"y":3,"z":0,"name":"Soil_Dirt"},{"x":-3,"y":4,"z":0,"name":"Soil_Dirt"},{"x":-3,"y":5,"z":0,"name":"Soil_Snow"},{"x":-3,"y":8,"z":0,"name":"Wood_Ice_Trunk_Full","support":1},{"x":-3,"y":9,"z":0,"name":"Wood_Ice_Trunk_Full"},{"x":-3,"y":23,"z":0,"name":"Plant_Leaves_Frostwood"},{"x":-3,"y":24,"z":0,"name":"Plant_Leaves_Frostwood"},{"x":-3,"y":0,"z":1,"name":"Soil_Dirt"},{"x":-3,"y":1,"z":1,"name":"Soil_Dirt"},{"x":-3,"y":2,"z":1,"name":"Soil_Dirt"},{"x":-3,"y":3,"z":1,"name":"Soil_Dirt"},{"x":-3,"y":4,"z":1,"name":"Soil_Dirt"},{"x":-3,"y":5,"z":1,"name":"Soil_Snow"},{"x":-3,"y":6,"z":1,"name":"WinterHoliday_Snowman","support":15,"rotation":3},{"x":-3,"y":7,"z":1,"name":"WinterHoliday_Snowman","filler":1024,"rotation":3},{"x":-3,"y":0,"z":2,"name":"Soil_Dirt"},{"x":-3,"y":1,"z":2,"name":"Soil_Dirt"},{"x":-3,"y":2,"z":2,"name":"Soil_Dirt"},{"x":-3,"y":3,"z":2,"name":"Soil_Dirt"},{"x":-3,"y":4,"z":2,"name":"Soil_Dirt"},{"x":-3,"y":5,"z":2,"name":"Soil_Snow"},{"x":-3,"y":0,"z":3,"name":"Soil_Dirt"},{"x":-3,"y":1,"z":3,"name":"Soil_Dirt"},{"x":-3,"y":2,"z":3,"name":"Soil_Dirt"},{"x":-3,"y":3,"z":3,"name":"Soil_Dirt"},{"x":-3,"y":4,"z":3,"name":"Soil_Dirt"},{"x":-3,"y":5,"z":3,"name":"Rock_Ice_Permafrost","support":15},{"x":-3,"y":13,"z":3,"name":"Rock_Ice_Icicles","support":15,"rotation":8},{"x":-3,"y":14,"z":3,"name":"Wood_Ice_Trunk_Full","support":2},{"x":-3,"y":16,"z":3,"name":"Plant_Leaves_Frostwood"},{"x":-3,"y":0,"z":4,"name":"Soil_Dirt"},{"x":-3,"y":1,"z":4,"name":"Soil_Dirt"},{"x":-3,"y":2,"z":4,"name":"Soil_Dirt"},{"x":-3,"y":3,"z":4,"name":"Soil_Dirt"},{"x":-3,"y":4,"z":4,"name":"Soil_Dirt"},{"x":-3,"y":5,"z":4,"name":"Rock_Ice_Permafrost","support":15},{"x":-3,"y":13,"z":4,"name":"Furniture_Frozen_Castle_Secondary_Lamp","rotation":8},{"x":-3,"y":14,"z":4,"name":"Wood_Ice_Trunk_Full","support":3},{"x":-3,"y":15,"z":4,"name":"Wood_Ice_Trunk_Full"},{"x":-3,"y":16,"z":4,"name":"Wood_Ice_Branch_Long"},{"x":-3,"y":17,"z":4,"name":"Wood_Ice_Branch_Corner","rotation":11},{"x":-3,"y":18,"z":4,"name":"Plant_Leaves_Frostwood"},{"x":-3,"y":0,"z":5,"name":"Soil_Dirt"},{"x":-3,"y":1,"z":5,"name":"Soil_Dirt"},{"x":-3,"y":2,"z":5,"name":"Soil_Dirt"},{"x":-3,"y":3,"z":5,"name":"Soil_Dirt"},{"x":-3,"y":4,"z":5,"name":"Soil_Dirt"},{"x":-3,"y":17,"z":5,"name":"Plant_Leaves_Frostwood"},{"x":-3,"y":19,"z":5,"name":"Plant_Leaves_Frostwood"},{"x":-3,"y":0,"z":6,"name":"Soil_Dirt"},{"x":-3,"y":1,"z":6,"name":"Soil_Dirt"},{"x":-3,"y":2,"z":6,"name":"Soil_Dirt"},{"x":-3,"y":3,"z":6,"name":"Soil_Dirt"},{"x":-3,"y":4,"z":6,"name":"Soil_Dirt"},{"x":-3,"y":5,"z":6,"name":"Rock_Ice_Permafrost","support":15},{"x":-3,"y":17,"z":6,"name":"Plant_Leaves_Frostwood"},{"x":-3,"y":0,"z":7,"name":"Soil_Dirt"},{"x":-3,"y":1,"z":7,"name":"Soil_Dirt"},{"x":-3,"y":2,"z":7,"name":"Soil_Dirt"},{"x":-3,"y":3,"z":7,"name":"Soil_Dirt"},{"x":-3,"y":4,"z":7,"name":"Soil_Dirt"},{"x":-3,"y":5,"z":7,"name":"Soil_Snow"},{"x":-3,"y":0,"z":8,"name":"Soil_Dirt"},{"x":-3,"y":1,"z":8,"name":"Soil_Dirt"},{"x":-3,"y":2,"z":8,"name":"Soil_Dirt"},{"x":-3,"y":3,"z":8,"name":"Soil_Dirt"},{"x":-3,"y":4,"z":8,"name":"Soil_Dirt"},{"x":-3,"y":5,"z":8,"name":"Soil_Snow"},{"x":-3,"y":0,"z":9,"name":"Soil_Dirt"},{"x":-3,"y":1,"z":9,"name":"Soil_Dirt"},{"x":-3,"y":2,"z":9,"name":"Soil_Dirt"},{"x":-3,"y":3,"z":9,"name":"Soil_Dirt"},{"x":-3,"y":4,"z":9,"name":"Soil_Dirt"},{"x":-3,"y":5,"z":9,"name":"Soil_Snow"},{"x":-3,"y":6,"z":9,"name":"Soil_Snow_Half","support":15},{"x":-3,"y":0,"z":10,"name":"Soil_Dirt"},{"x":-3,"y":1,"z":10,"name":"Soil_Dirt"},{"x":-3,"y":2,"z":10,"name":"Soil_Dirt"},{"x":-3,"y":3,"z":10,"name":"Soil_Dirt"},{"x":-3,"y":4,"z":10,"name":"Soil_Dirt"},{"x":-3,"y":5,"z":10,"name":"Soil_Snow"},{"x":-3,"y":6,"z":10,"name":"*Soil_Snow_Half_State_Definitions_Block"},{"x":-3,"y":0,"z":11,"name":"Soil_Dirt"},{"x":-3,"y":1,"z":11,"name":"Soil_Dirt"},{"x":-3,"y":2,"z":11,"name":"Soil_Dirt"},{"x":-3,"y":3,"z":11,"name":"Soil_Dirt"},{"x":-3,"y":4,"z":11,"name":"Soil_Dirt"},{"x":-3,"y":5,"z":11,"name":"Soil_Snow"},{"x":-3,"y":6,"z":11,"name":"Soil_Snow_Half","support":15},{"x":-3,"y":0,"z":12,"name":"Soil_Dirt"},{"x":-3,"y":1,"z":12,"name":"Soil_Dirt"},{"x":-3,"y":2,"z":12,"name":"Soil_Dirt"},{"x":-3,"y":3,"z":12,"name":"Soil_Dirt"},{"x":-3,"y":4,"z":12,"name":"Soil_Dirt"},{"x":-3,"y":5,"z":12,"name":"Soil_Snow"},{"x":-3,"y":0,"z":13,"name":"Soil_Dirt"},{"x":-3,"y":1,"z":13,"name":"Soil_Dirt"},{"x":-3,"y":2,"z":13,"name":"Soil_Dirt"},{"x":-3,"y":3,"z":13,"name":"Soil_Dirt"},{"x":-3,"y":4,"z":13,"name":"Soil_Dirt"},{"x":-3,"y":5,"z":13,"name":"Soil_Snow"},{"x":-3,"y":0,"z":14,"name":"Soil_Dirt"},{"x":-3,"y":1,"z":14,"name":"Soil_Dirt"},{"x":-3,"y":2,"z":14,"name":"Soil_Dirt"},{"x":-3,"y":3,"z":14,"name":"Soil_Dirt"},{"x":-3,"y":4,"z":14,"name":"Soil_Dirt"},{"x":-3,"y":5,"z":14,"name":"Soil_Snow"},{"x":-3,"y":0,"z":15,"name":"Soil_Dirt"},{"x":-3,"y":1,"z":15,"name":"Soil_Dirt"},{"x":-3,"y":2,"z":15,"name":"Soil_Dirt"},{"x":-3,"y":3,"z":15,"name":"Soil_Dirt"},{"x":-3,"y":4,"z":15,"name":"Soil_Dirt"},{"x":-3,"y":5,"z":15,"name":"Rock_Stone_Brick_Smooth"},{"x":-2,"y":0,"z":-14,"name":"Soil_Dirt"},{"x":-2,"y":1,"z":-14,"name":"Soil_Dirt"},{"x":-2,"y":2,"z":-14,"name":"Soil_Dirt"},{"x":-2,"y":3,"z":-14,"name":"Soil_Dirt"},{"x":-2,"y":4,"z":-14,"name":"Soil_Dirt"},{"x":-2,"y":5,"z":-14,"name":"Rock_Stone_Brick_Smooth"},{"x":-2,"y":0,"z":-13,"name":"Soil_Dirt"},{"x":-2,"y":1,"z":-13,"name":"Soil_Dirt"},{"x":-2,"y":2,"z":-13,"name":"Soil_Dirt"},{"x":-2,"y":3,"z":-13,"name":"Soil_Dirt"},{"x":-2,"y":4,"z":-13,"name":"Soil_Dirt"},{"x":-2,"y":5,"z":-13,"name":"Soil_Snow"},{"x":-2,"y":0,"z":-12,"name":"Soil_Dirt"},{"x":-2,"y":1,"z":-12,"name":"Soil_Dirt"},{"x":-2,"y":2,"z":-12,"name":"Soil_Dirt"},{"x":-2,"y":3,"z":-12,"name":"Soil_Dirt"},{"x":-2,"y":4,"z":-12,"name":"Soil_Dirt"},{"x":-2,"y":5,"z":-12,"name":"Soil_Snow"},{"x":-2,"y":0,"z":-11,"name":"Soil_Dirt"},{"x":-2,"y":1,"z":-11,"name":"Soil_Dirt"},{"x":-2,"y":2,"z":-11,"name":"Soil_Dirt"},{"x":-2,"y":3,"z":-11,"name":"Soil_Dirt"},{"x":-2,"y":4,"z":-11,"name":"Soil_Dirt"},{"x":-2,"y":5,"z":-11,"name":"Soil_Snow"},{"x":-2,"y":0,"z":-10,"name":"Soil_Dirt"},{"x":-2,"y":1,"z":-10,"name":"Soil_Dirt"},{"x":-2,"y":2,"z":-10,"name":"Soil_Dirt"},{"x":-2,"y":3,"z":-10,"name":"Soil_Dirt"},{"x":-2,"y":4,"z":-10,"name":"Soil_Dirt"},{"x":-2,"y":5,"z":-10,"name":"Soil_Snow"},{"x":-2,"y":0,"z":-9,"name":"Soil_Dirt"},{"x":-2,"y":1,"z":-9,"name":"Soil_Dirt"},{"x":-2,"y":2,"z":-9,"name":"Soil_Dirt"},{"x":-2,"y":3,"z":-9,"name":"Soil_Dirt"},{"x":-2,"y":4,"z":-9,"name":"Soil_Dirt"},{"x":-2,"y":5,"z":-9,"name":"Soil_Snow"},{"x":-2,"y":0,"z":-8,"name":"Soil_Dirt"},{"x":-2,"y":1,"z":-8,"name":"Soil_Dirt"},{"x":-2,"y":2,"z":-8,"name":"Soil_Dirt"},{"x":-2,"y":3,"z":-8,"name":"Soil_Dirt"},{"x":-2,"y":4,"z":-8,"name":"Soil_Dirt"},{"x":-2,"y":5,"z":-8,"name":"Soil_Snow"},{"x":-2,"y":0,"z":-7,"name":"Soil_Dirt"},{"x":-2,"y":1,"z":-7,"name":"Soil_Dirt"},{"x":-2,"y":2,"z":-7,"name":"Soil_Dirt"},