{"version":8,"blockIdVersion":11,"anchorX":0,"anchorY":0,"anchorZ":0,"blocks":[{"x":-14,"y":0,"z":-14,"name":"Soil_Dirt"},{"x":-14,"y":1,"z":-14,"name":"Soil_Dirt"},{"x":-14,"y":2,"z":-14,"name":"Soil_Dirt"},{"x":-14,"y":3,"z":-14,"name":"Soil_Dirt"},{"x":-14,"y":4,"z":-14,"name":"Soil_Dirt"},{"x":-14,"y":5,"z":-14,"name":"Rock_Stone_Brick_Smooth"},{"x":-14,"y":0,"z":-13,"name":"Soil_Dirt"},{"x":-14,"y":1,"z":-13,"name":"Soil_Dirt"},{"x":-14,"y":2,"z":-13,"name":"Soil_Dirt"},{"x":-14,"y":3,"z":-13,"name":"Soil_Dirt"},{"x":-14,"y":4,"z":-13,"name":"Soil_Dirt"},{"x":-14,"y":5,"z":-13,"name":"Rock_Stone_Brick_Smooth"},{"x":-14,"y":0,"z":-12,"name":"Soil_Dirt"},{"x":-14,"y":1,"z":-12,"name":"Soil_Dirt"},{"x":-14,"y":2,"z":-12,"name":"Soil_Dirt"},{"x":-14,"y":3,"z":-12,"name":"Soil_Dirt"},{"x":-14,"y":4,"z":-12,"name":"Soil_Dirt"},{"x":-14,"y":5,"z":-12,"name":"Rock_Stone_Brick_Smooth"},{"x":-14,"y":0,"z":-11,"name":"Soil_Dirt"},{"x":-14,"y":1,"z":-11,"name":"Soil_Dirt"},{"x":-14,"y":2,"z":-11,"name":"Soil_Dirt"},{"x":-14,"y":3,"z":-11,"name":"Soil_Dirt"},{"x":-14,"y":4,"z":-11,"name":"Soil_Dirt"},{"x":-14,"y":5,"z":-11,"name":"Rock_Stone_Brick_Smooth"},{"x":-14,"y":0,"z":-10,"name":"Soil_Dirt"},{"x":-14,"y":1,"z":-10,"name":"Soil_Dirt"},{"x":-14,"y":2,"z":-10,"name":"Soil_Dirt"},{"x":-14,"y":3,"z":-10,"name":"Soil_Dirt"},{"x":-14,"y":4,"z":-10,"name":"Soil_Dirt"},{"x":-14,"y":5,"z":-10,"name":"Rock_Stone_Brick_Smooth"},{"x":-14,"y":0,"z":-9,"name":"Soil_Dirt"},{"x":-14,"y":1,"z":-9,"name":"Soil_Dirt"},{"x":-14,"y":2,"z":-9,"name":"Soil_Dirt"},{"x":-14,"y":3,"z":-9,"name":"Soil_Dirt"},{"x":-14,"y":4,"z":-9,"name":"Soil_Dirt"},{"x":-14,"y":5,"z":-9,"name":"Rock_Stone_Brick_Smooth"},{"x":-14,"y":0,"z":-8,"name":"Soil_Dirt"},{"x":-14,"y":1,"z":-8,"name":"Soil_Dirt"},{"x":-14,"y":2,"z":-8,"name":"Soil_Dirt"},{"x":-14,"y":3,"z":-8,"name":"Soil_Dirt"},{"x":-14,"y":4,"z":-8,"name":"Soil_Dirt"},{"x":-14,"y":5,"z":-8,"name":"Rock_Stone_Brick_Smooth"},{"x":-14,"y":0,"z":-7,"name":"Soil_Dirt"},{"x":-14,"y":1,"z":-7,"name":"Soil_Dirt"},{"x":-14,"y":2,"z":-7,"name":"Soil_Dirt"},{"x":-14,"y":3,"z":-7,"name":"Soil_Dirt"},{"x":-14,"y":4,"z":-7,"name":"Soil_Dirt"},{"x":-14,"y":5,"z":-7,"name":"Rock_Stone_Brick_Smooth"},{"x":-14,"y":0,"z":-6,"name":"Soil_Dirt"},{"x":-14,"y":1,"z":-6,"name":"Soil_Dirt"},{"x":-14,"y":2,"z":-6,"name":"Soil_Dirt"},{"x":-14,"y":3,"z":-6,"name":"Soil_Dirt"},{"x":-14,"y":4,"z":-6,"name":"Soil_Dirt"},{"x":-14,"y":5,"z":-6,"name":"Rock_Stone_Brick_Smooth"},{"x":-14,"y":0,"z":-5,"name":"Soil_Dirt"},{"x":-14,"y":1,"z":-5,"name":"Soil_Dirt"},{"x":-14,"y":2,"z":-5,"name":"Soil_Dirt"},{"x":-14,"y":3,"z":-5,"name":"Soil_Dirt"},{"x":-14,"y":4,"z":-5,"name":"Soil_Dirt"},{"x":-14,"y":5,"z":-5,"name":"Rock_Stone_Brick_Smooth"},{"x":-14,"y":0,"z":-4,"name":"Soil_Dirt"},{"x":-14,"y":1,"z":-4,"name":"Soil_Dirt"},{"x":-14,"y":2,"z":-4,"name":"Soil_Dirt"},{"x":-14,"y":3,"z":-4,"name":"Soil_Dirt"},{"x":-14,"y":4,"z":-4,"name":"Soil_Dirt"},{"x":-14,"y":5,"z":-4,"name":"Rock_Stone_Brick_Smooth"},{"x":-14,"y":0,"z":-3,"name":"Soil_Dirt"},{"x":-14,"y":1,"z":-3,"name":"Soil_Dirt"},{"x":-14,"y":2,"z":-3,"name":"Soil_Dirt"},{"x":-14,"y":3,"z":-3,"name":"Soil_Dirt"},{"x":-14,"y":4,"z":-3,"name":"Soil_Dirt"},{"x":-14,"y":5,"z":-3,"name":"Rock_Stone_Brick_Smooth"},{"x":-14,"y":0,"z":-2,"name":"Soil_Dirt"},{"x":-14,"y":1,"z":-2,"name":"Soil_Dirt"},{"x":-14,"y":2,"z":-2,"name":"Soil_Dirt"},{"x":-14,"y":3,"z":-2,"name":"Soil_Dirt"},{"x":-14,"y":4,"z":-2,"name":"Soil_Dirt"},{"x":-14,"y":5,"z":-2,"name":"Rock_Stone_Brick_Smooth"},{"x":-14,"y":0,"z":-1,"name":"Soil_Dirt"},{"x":-14,"y":1,"z":-1,"name":"Soil_Dirt"},{"x":-14,"y":2,"z":-1,"name":"Soil_Dirt"},{"x":-14,"y":3,"z":-1,"name":"Soil_Dirt"},{"x":-14,"y":4,"z":-1,"name":"Soil_Dirt"},{"x":-14,"y":5,"z":-1,"name":"Rock_Stone_Brick_Smooth"},{"x":-14,"y":0,"z":0,"name":"Soil_Dirt"},{"x":-14,"y":1,"z":0,"name":"Soil_Dirt"},{"x":-14,"y":2,"z":0,"name":"Soil_Dirt"},{"x":-14,"y":3,"z":0,"name":"Soil_Dirt"},{"x":-14,"y":4,"z":0,"name":"Soil_Dirt"},{"x":-14,"y":5,"z":0,"name":"Rock_Stone_Brick_Smooth"},{"x":-14,"y":0,"z":1,"name":"Soil_Dirt"},{"x":-14,"y":1,"z":1,"name":"Soil_Dirt"},{"x":-14,"y":2,"z":1,"name":"Soil_Dirt"},{"x":-14,"y":3,"z":1,"name":"Soil_Dirt"},{"x":-14,"y":4,"z":1,"name":"Soil_Dirt"},{"x":-14,"y":5,"z":1,"name":"Rock_Stone_Brick_Smooth"},{"x":-14,"y":0,"z":2,"name":"Soil_Dirt"},{"x":-14,"y":1,"z":2,"name":"Soil_Dirt"},{"x":-14,"y":2,"z":2,"name":"Soil_Dirt"},{"x":-14,"y":3,"z":2,"name":"Soil_Dirt"},{"x":-14,"y":4,"z":2,"name":"Soil_Dirt"},{"x":-14,"y":5,"z":2,"name":"Rock_Stone_Brick_Smooth"},{"x":-14,"y":0,"z":3,"name":"Soil_Dirt"},{"x":-14,"y":1,"z":3,"name":"Soil_Dirt"},{"x":-14,"y":2,"z":3,"name":"Soil_Dirt"},{"x":-14,"y":3,"z":3,"name":"Soil_Dirt"},{"x":-14,"y":4,"z":3,"name":"Soil_Dirt"},{"x":-14,"y":5,"z":3,"name":"Rock_Stone_Brick_Smooth"},{"x":-14,"y":0,"z":4,"name":"Soil_Dirt"},{"x":-14,"y":1,"z":4,"name":"Soil_Dirt"},{"x":-14,"y":2,"z":4,"name":"Soil_Dirt"},{"x":-14,"y":3,"z":4,"name":"Soil_Dirt"},{"x":-14,"y":4,"z":4,"name":"Soil_Dirt"},{"x":-14,"y":5,"z":4,"name":"Rock_Stone_Brick_Smooth"},{"x":-14,"y":0,"z":5,"name":"Soil_Dirt"},{"x":-14,"y":1,"z":5,"name":"Soil_Dirt"},{"x":-14,"y":2,"z":5,"name":"Soil_Dirt"},{"x":-14,"y":3,"z":5,"name":"Soil_Dirt"},{"x":-14,"y":4,"z":5,"name":"Soil_Dirt"},{"x":-14,"y":5,"z":5,"name":"Rock_Stone_Brick_Smooth"},{"x":-14,"y":0,"z":6,"name":"Soil_Dirt"},{"x":-14,"y":1,"z":6,"name":"Soil_Dirt"},{"x":-14,"y":2,"z":6,"name":"Soil_Dirt"},{"x":-14,"y":3,"z":6,"name":"Soil_Dirt"},{"x":-14,"y":4,"z":6,"name":"Soil_Dirt"},{"x":-14,"y":5,"z":6,"name":"Rock_Stone_Brick_Smooth"},{"x":-14,"y":0,"z":7,"name":"Soil_Dirt"},{"x":-14,"y":1,"z":7,"name":"Soil_Dirt"},{"x":-14,"y":2,"z":7,"name":"Soil_Dirt"},{"x":-14,"y":3,"z":7,"name":"Soil_Dirt"},{"x":-14,"y":4,"z":7,"name":"Soil_Dirt"},{"x":-14,"y":5,"z":7,"name":"Rock_Stone_Brick_Smooth"},{"x":-14,"y":0,"z":8,"name":"Soil_Dirt"},{"x":-14,"y":1,"z":8,"name":"Soil_Dirt"},{"x":-14,"y":2,"z":8,"name":"Soil_Dirt"},{"x":-14,"y":3,"z":8,"name":"Soil_Dirt"},{"x":-14,"y":4,"z":8,"name":"Soil_Dirt"},{"x":-14,"y":5,"z":8,"name":"Rock_Stone_Brick_Smooth"},{"x":-14,"y":0,"z":9,"name":"Soil_Dirt"},{"x":-14,"y":1,"z":9,"name":"Soil_Dirt"},{"x":-14,"y":2,"z":9,"name":"Soil_Dirt"},{"x":-14,"y":3,"z":9,"name":"Soil_Dirt"},{"x":-14,"y":4,"z":9,"name":"Soil_Dirt"},{"x":-14,"y":5,"z":9,"name":"Rock_Stone_Brick_Smooth"},{"x":-14,"y":0,"z":10,"name":"Soil_Dirt"},{"x":-14,"y":1,"z":10,"name":"Soil_Dirt"},{"x":-14,"y":2,"z":10,"name":"Soil_Dirt"},{"x":-14,"y":3,"z":10,"name":"Soil_Dirt"},{"x":-14,"y":4,"z":10,"name":"Soil_Dirt"},{"x":-14,"y":5,"z":10,"name":"Rock_Stone_Brick_Smooth"},{"x":-14,"y":0,"z":11,"name":"Soil_Dirt"},{"x":-14,"y":1,"z":11,"name":"Soil_Dirt"},{"x":-14,"y":2,"z":11,"name":"Soil_Dirt"},{"x":-14,"y":3,"z":11,"name":"Soil_Dirt"},{"x":-14,"y":4,"z":11,"name":"Soil_Dirt"},{"x":-14,"y":5,"z":11,"name":"Rock_Stone_Brick_Smooth"},{"x":-14,"y":0,"z":12,"name":"Soil_Dirt"},{"x":-14,"y":1,"z":12,"name":"Soil_Dirt"},{"x":-14,"y":2,"z":12,"name":"Soil_Dirt"},{"x":-14,"y":3,"z":12,"name":"Soil_Dirt"},{"x":-14,"y":4,"z":12,"name":"Soil_Dirt"},{"x":-14,"y":5,"z":12,"name":"Rock_Stone_Brick_Smooth"},{"x":-14,"y":0,"z":13,"name":"Soil_Dirt"},{"x":-14,"y":1,"z":13,"name":"Soil_Dirt"},{"x":-14,"y":2,"z":13,"name":"Soil_Dirt"},{"x":-14,"y":3,"z":13,"name":"Soil_Dirt"},{"x":-14,"y":4,"z":13,"name":"Soil_Dirt"},{"x":-14,"y":5,"z":13,"name":"Rock_Stone_Brick_Smooth"},{"x":-14,"y":0,"z":14,"name":"Soil_Dirt"},{"x":-14,"y":1,"z":14,"name":"Soil_Dirt"},{"x":-14,"y":2,"z":14,"name":"Soil_Dirt"},{"x":-14,"y":3,"z":14,"name":"Soil_Dirt"},{"x":-14,"y":4,"z":14,"name":"Soil_Dirt"},{"x":-14,"y":5,"z":14,"name":"Rock_Stone_Brick_Smooth"},{"x":-14,"y":0,"z":15,"name":"Soil_Dirt"},{"x":-14,"y":1,"z":15,"name":"Soil_Dirt"},{"x":-14,"y":2,"z":15,"name":"Soil_Dirt"},{"x":-14,"y":3,"z":15,"name":"Soil_Dirt"},{"x":-14,"y":4,"z":15,"name":"Soil_Dirt"},{"x":-14,"y":5,"z":15,"name":"Rock_Stone_Brick_Smooth"},{"x":-13,"y":0,"z":-14,"name":"Soil_Dirt"},{"x":-13,"y":1,"z":-14,"name":"Soil_Dirt"},{"x":-13,"y":2,"z":-14,"name":"Soil_Dirt"},{"x":-13,"y":3,"z":-14,"name":"Soil_Dirt"},{"x":-13,"y":4,"z":-14,"name":"Soil_Dirt"},{"x":-13,"y":5,"z":-14,"name":"Rock_Stone_Brick_Smooth"},{"x":-13,"y":0,"z":-13,"name":"Soil_Dirt"},{"x":-13,"y":1,"z":-13,"name":"Soil_Dirt"},{"x":-13,"y":2,"z":-13,"name":"Soil_Dirt"},{"x":-13,"y":3,"z":-13,"name":"Soil_Dirt"},{"x":-13,"y":4,"z":-13,"name":"Soil_Dirt"},{"x":-13,"y":5,"z":-13,"name":"Rock_Stone_Cobble_Mossy"},{"x":-13,"y":0,"z":-12,"name":"Soil_Dirt"},{"x":-13,"y":1,"z":-12,"name":"Soil_Dirt"},{"x":-13,"y":2,"z":-12,"name":"Soil_Dirt"},{"x":-13,"y":3,"z":-12,"name":"Soil_Dirt"},{"x":-13,"y":4,"z":-12,"name":"Soil_Dirt"},{"x":-13,"y":5,"z":-12,"name":"Rock_Stone_Cobble"},{"x":-13,"y":8,"z":-12,"name":"Cloth_Modern_DarkGreen_Roof_Vertical_Flap","rotation":3},{"x":-13,"y":9,"z":-12,"name":"Cloth_Modern_DarkGreen_Roof_Vertical","rotation":3},{"x":-13,"y":0,"z":-11,"name":"Soil_Dirt"},{"x":-13,"y":1,"z":-11,"name":"Soil_Dirt"},{"x":-13,"y":2,"z":-11,"name":"Soil_Dirt"},{"x":-13,"y":3,"z":-11,"name":"Soil_Dirt"},{"x":-13,"y":4,"z":-11,"name":"Soil_Dirt"},{"x":-13,"y":5,"z":-11,"name":"Rock_Stone_Cobble_Mossy"},{"x":-13,"y":0,"z":-10,"name":"Soil_Dirt"},{"x":-13,"y":1,"z":-10,"name":"Soil_Dirt"},{"x":-13,"y":2,"z":-10,"name":"Soil_Dirt"},{"x":-13,"y":3,"z":-10,"name":"Soil_Dirt"},{"x":-13,"y":4,"z":-10,"name":"Soil_Dirt"},{"x":-13,"y":5,"z":-10,"name":"Rock_Stone_Cobble"},{"x":-13,"y":0,"z":-9,"name":"Soil_Dirt"},{"x":-13,"y":1,"z":-9,"name":"Soil_Dirt"},{"x":-13,"y":2,"z":-9,"name":"Soil_Dirt"},{"x":-13,"y":3,"z":-9,"name":"Soil_Dirt"},{"x":-13,"y":4,"z":-9,"name":"Soil_Dirt"},{"x":-13,"y":5,"z":-9,"name":"Rock_Stone_Cobble"},{"x":-13,"y":0,"z":-8,"name":"Soil_Dirt"},{"x":-13,"y":1,"z":-8,"name":"Soil_Dirt"},{"x":-13,"y":2,"z":-8,"name":"Soil_Dirt"},{"x":-13,"y":3,"z":-8,"name":"Soil_Dirt"},{"x":-13,"y":4,"z":-8,"name":"Soil_Dirt"},{"x":-13,"y":5,"z":-8,"name":"Rock_Stone_Cobble"},{"x":-13,"y":0,"z":-7,"name":"Soil_Dirt"},{"x":-13,"y":1,"z":-7,"name":"Soil_Dirt"},{"x":-13,"y":2,"z":-7,"name":"Soil_Dirt"},{"x":-13,"y":3,"z":-7,"name":"Soil_Dirt"},{"x":-13,"y":4,"z":-7,"name":"Soil_Dirt"},{"x":-13,"y":5,"z":-7,"name":"Rock_Stone_Cobble"},{"x":-13,"y":0,"z":-6,"name":"Soil_Dirt"},{"x":-13,"y":1,"z":-6,"name":"Soil_Dirt"},{"x":-13,"y":2,"z":-6,"name":"Soil_Dirt"},{"x":-13,"y":3,"z":-6,"name":"Soil_Dirt"},{"x":-13,"y":4,"z":-6,"name":"Soil_Dirt"},{"x":-13,"y":5,"z":-6,"name":"Rock_Stone_Cobble_Mossy"},{"x":-13,"y":0,"z":-5,"name":"Soil_Dirt"},{"x":-13,"y":1,"z":-5,"name":"Soil_Dirt"},{"x":-13,"y":2,"z":-5,"name":"Soil_Dirt"},{"x":-13,"y":3,"z":-5,"name":"Soil_Dirt"},{"x":-13,"y":4,"z":-5,"name":"Soil_Dirt"},{"x":-13,"y":5,"z":-5,"name":"Rock_Stone_Cobble"},{"x":-13,"y":0,"z":-4,"name":"Soil_Dirt"},{"x":-13,"y":1,"z":-4,"name":"Soil_Dirt"},{"x":-13,"y":2,"z":-4,"name":"Soil_Dirt"},{"x":-13,"y":3,"z":-4,"name":"Soil_Dirt"},{"x":-13,"y":4,"z":-4,"name":"Soil_Dirt"},{"x":-13,"y":5,"z":-4,"name":"Rock_Stone_Cobble_Mossy"},{"x":-13,"y":0,"z":-3,"name":"Soil_Dirt"},{"x":-13,"y":1,"z":-3,"name":"Soil_Dirt"},{"x":-13,"y":2,"z":-3,"name":"Soil_Dirt"},{"x":-13,"y":3,"z":-3,"name":"Soil_Dirt"},{"x":-13,"y":4,"z":-3,"name":"Soil_Dirt"},{"x":-13,"y":5,"z":-3,"name":"Rock_Stone_Cobble_Mossy"},{"x":-13,"y":0,"z":-2,"name":"Soil_Dirt"},{"x":-13,"y":1,"z":-2,"name":"Soil_Dirt"},{"x":-13,"y":2,"z":-2,"name":"Soil_Dirt"},{"x":-13,"y":3,"z":-2,"name":"Soil_Dirt"},{"x":-13,"y":4,"z":-2,"name":"Soil_Dirt"},{"x":-13,"y":5,"z":-2,"name":"Rock_Stone_Cobble"},{"x":-13,"y":0,"z":-1,"name":"Soil_Dirt"},{"x":-13,"y":1,"z":-1,"name":"Soil_Dirt"},{"x":-13,"y":2,"z":-1,"name":"Soil_Dirt"},{"x":-13,"y":3,"z":-1,"name":"Soil_Dirt"},{"x":-13,"y":4,"z":-1,"name":"Soil_Dirt"},{"x":-13,"y":5,"z":-1,"name":"Rock_Stone_Cobble"},{"x":-13,"y":0,"z":0,"name":"Soil_Dirt"},{"x":-13,"y":1,"z":0,"name":"Soil_Dirt"},{"x":-13,"y":2,"z":0,"name":"Soil_Dirt"},{"x":-13,"y":3,"z":0,"name":"Soil_Dirt"},{"x":-13,"y":4,"z":0,"name":"Soil_Dirt"},{"x":-13,"y":5,"z":0,"name":"Rock_Stone_Cobble"},{"x":-13,"y":0,"z":1,"name":"Soil_Dirt"},{"x":-13,"y":1,"z":1,"name":"Soil_Dirt"},{"x":-13,"y":2,"z":1,"name":"Soil_Dirt"},{"x":-13,"y":3,"z":1,"name":"Soil_Dirt"},{"x":-13,"y":4,"z":1,"name":"Soil_Dirt"},{"x":-13,"y":5,"z":1,"name":"Rock_Stone_Cobble"},{"x":-13,"y":0,"z":2,"name":"Soil_Dirt"},{"x":-13,"y":1,"z":2,"name":"Soil_Dirt"},{"x":-13,"y":2,"z":2,"name":"Soil_Dirt"},{"x":-13,"y":3,"z":2,"name":"Soil_Dirt"},{"x":-13,"y":4,"z":2,"name":"Soil_Dirt"},{"x":-13,"y":5,"z":2,"name":"Rock_Stone_Cobble"},{"x":-13,"y":0,"z":3,"name":"Soil_Dirt"},{"x":-13,"y":1,"z":3,"name":"Soil_Dirt"},{"x":-13,"y":2,"z":3,"name":"Soil_Dirt"},{"x":-13,"y":3,"z":3,"name":"Soil_Dirt"},{"x":-13,"y":4,"z":3,"name":"Soil_Dirt"},{"x":-13,"y":5,"z":3,"name":"Rock_Stone_Cobble_Mossy"},{"x":-13,"y":0,"z":4,"name":"Soil_Dirt"},{"x":-13,"y":1,"z":4,"name":"Soil_Dirt"},{"x":-13,"y":2,"z":4,"name":"Soil_Dirt"},{"x":-13,"y":3,"z":4,"name":"Soil_Dirt"},{"x":-13,"y":4,"z":4,"name":"Soil_Dirt"},{"x":-13,"y":5,"z":4,"name":"Rock_Stone_Cobble"},{"x":-13,"y":0,"z":5,"name":"Soil_Dirt"},{"x":-13,"y":1,"z":5,"name":"Soil_Dirt"},{"x":-13,"y":2,"z":5,"name":"Soil_Dirt"},{"x":-13,"y":3,"z":5,"name":"Soil_Dirt"},{"x":-13,"y":4,"z":5,"name":"Soil_Dirt"},{"x":-13,"y":5,"z":5,"name":"Rock_Stone_Cobble"},{"x":-13,"y":0,"z":6,"name":"Soil_Dirt"},{"x":-13,"y":1,"z":6,"name":"Soil_Dirt"},{"x":-13,"y":2,"z":6,"name":"Soil_Dirt"},{"x":-13,"y":3,"z":6,"name":"Soil_Dirt"},{"x":-13,"y":4,"z":6,"name":"Soil_Dirt"},{"x":-13,"y":5,"z":6,"name":"Rock_Stone_Cobble"},{"x":-13,"y":0,"z":7,"name":"Soil_Dirt"},{"x":-13,"y":1,"z":7,"name":"Soil_Dirt"},{"x":-13,"y":2,"z":7,"name":"Soil_Dirt"},{"x":-13,"y":3,"z":7,"name":"Soil_Dirt"},{"x":-13,"y":4,"z":7,"name":"Soil_Dirt"},{"x":-13,"y":5,"z":7,"name":"Rock_Stone_Cobble"},{"x":-13,"y":0,"z":8,"name":"Soil_Dirt"},{"x":-13,"y":1,"z":8,"name":"Soil_Dirt"},{"x":-13,"y":2,"z":8,"name":"Soil_Dirt"},{"x":-13,"y":3,"z":8,"name":"Soil_Dirt"},{"x":-13,"y":4,"z":8,"name":"Soil_Dirt"},{"x":-13,"y":5,"z":8,"name":"Rock_Stone_Cobble"},{"x":-13,"y":0,"z":9,"name":"Soil_Dirt"},{"x":-13,"y":1,"z":9,"name":"Soil_Dirt"},{"x":-13,"y":2,"z":9,"name":"Soil_Dirt"},{"x":-13,"y":3,"z":9,"name":"Soil_Dirt"},{"x":-13,"y":4,"z":9,"name":"Soil_Dirt"},{"x":-13,"y":5,"z":9,"name":"Rock_Stone_Cobble"},{"x":-13,"y":0,"z":10,"name":"Soil_Dirt"},{"x":-13,"y":1,"z":10,"name":"Soil_Dirt"},{"x":-13,"y":2,"z":10,"name":"Soil_Dirt"},{"x":-13,"y":3,"z":10,"name":"Soil_Dirt"},{"x":-13,"y":4,"z":10,"name":"Soil_Dirt"},{"x":-13,"y":5,"z":10,"name":"Rock_Stone_Cobble"},{"x":-13,"y":0,"z":11,"name":"Soil_Dirt"},{"x":-13,"y":1,"z":11,"name":"Soil_Dirt"},{"x":-13,"y":2,"z":11,"name":"Soil_Dirt"},{"x":-13,"y":3,"z":11,"name":"Soil_Dirt"},{"x":-13,"y":4,"z":11,"name":"Soil_Dirt"},{"x":-13,"y":5,"z":11,"name":"Rock_Stone_Cobble_Mossy"},{"x":-13,"y":0,"z":12,"name":"Soil_Dirt"},{"x":-13,"y":1,"z":12,"name":"Soil_Dirt"},{"x":-13,"y":2,"z":12,"name":"Soil_Dirt"},{"x":-13,"y":3,"z":12,"name":"Soil_Dirt"},{"x":-13,"y":4,"z":12,"name":"Soil_Dirt"},{"x":-13,"y":5,"z":12,"name":"Rock_Stone_Cobble"},{"x":-13,"y":0,"z":13,"name":"Soil_Dirt"},{"x":-13,"y":1,"z":13,"name":"Soil_Dirt"},{"x":-13,"y":2,"z":13,"name":"Soil_Dirt"},{"x":-13,"y":3,"z":13,"name":"Soil_Dirt"},{"x":-13,"y":4,"z":13,"name":"Soil_Dirt"},{"x":-13,"y":5,"z":13,"name":"Rock_Stone_Cobble"},{"x":-13,"y":8,"z":13,"name":"Cloth_Modern_DarkGreen_Roof_Vertical_Flap","rotation":3},{"x":-13,"y":9,"z":13,"name":"Cloth_Modern_DarkGreen_Roof_Vertical","rotation":3},{"x":-13,"y":0,"z":14,"name":"Soil_Dirt"},{"x":-13,"y":1,"z":14,"name":"Soil_Dirt"},{"x":-13,"y":2,"z":14,"name":"Soil_Dirt"},{"x":-13,"y":3,"z":14,"name":"Soil_Dirt"},{"x":-13,"y":4,"z":14,"name":"Soil_Dirt"},{"x":-13,"y":5,"z":14,"name":"Rock_Stone_Cobble"},{"x":-13,"y":0,"z":15,"name":"Soil_Dirt"},{"x":-13,"y":1,"z":15,"name":"Soil_Dirt"},{"x":-13,"y":2,"z":15,"name":"Soil_Dirt"},{"x":-13,"y":3,"z":15,"name":"Soil_Dirt"},{"x":-13,"y":4,"z":15,"name":"Soil_Dirt"},{"x":-13,"y":5,"z":15,"name":"Rock_Stone_Brick_Smooth"},{"x":-12,"y":0,"z":-14,"name":"Soil_Dirt"},{"x":-12,"y":1,"z":-14,"name":"Soil_Dirt"},{"x":-12,"y":2,"z":-14,"name":"Soil_Dirt"},{"x":-12,"y":3,"z":-14,"name":"Soil_Dirt"},{"x":-12,"y":4,"z":-14,"name":"Soil_Dirt"},{"x":-12,"y":5,"z":-14,"name":"Rock_Stone_Brick_Smooth"},{"x":-12,"y":0,"z":-13,"name":"Soil_Dirt"},{"x":-12,"y":1,"z":-13,"name":"Soil_Dirt"},{"x":-12,"y":2,"z":-13,"name":"Soil_Dirt"},{"x":-12,"y":3,"z":-13,"name":"Soil_Dirt"},{"x":-12,"y":4,"z":-13,"name":"Soil_Dirt"},{"x":-12,"y":5,"z":-13,"name":"Rock_Stone_Cobble"},{"x":-12,"y":8,"z":-13,"name":"Cloth_Modern_DarkGreen_Roof_Vertical_Flap","rotation":2},{"x":-12,"y":9,"z":-13,"name":"Cloth_Modern_DarkGreen_Roof_Vertical","rotation":2},{"x":-12,"y":0,"z":-12,"name":"Soil_Dirt"},{"x":-12,"y":1,"z":-12,"name":"Soil_Dirt"},{"x":-12,"y":2,"z":-12,"name":"Soil_Dirt"},{"x":-12,"y":3,"z":-12,"name":"Soil_Dirt"},{"x":-12,"y":4,"z":-12,"name":"Soil_Dirt"},{"x":-12,"y":5,"z":-12,"name":"Rock_Stone_Cobble_Mossy"},{"x":-12,"y":6,"z":-12,"name":"Wood_Bamboo_Branch_Long","support":15},{"x":-12,"y":7,"z":-12,"name":"Wood_Bamboo_Branch_Long","support":15},{"x":-12,"y":8,"z":-12,"name":"Wood_Bamboo_Branch_Long","support":15},{"x":-12,"y":9,"z":-12,"name":"Rock_Crystal_Green_Block"},{"x":-12,"y":10,"z":-12,"name":"Wood_Tropicalwood_Roof_Flat","rotation":2},{"x":-12,"y":0,"z":-11,"name":"Soil_Dirt"},{"x":-12,"y":1,"z":-11,"name":"Soil_Dirt"},{"x":-12,"y":2,"z":-11,"name":"Soil_Dirt"},{"x":-12,"y":3,"z":-11,"name":"Soil_Dirt"},{"x":-12,"y":4,"z":-11,"name":"Soil_Dirt"},{"x":-12,"y":5,"z":-11,"name":"Rock_Stone_Cobble"},{"x":-12,"y":8,"z":-11,"name":"Cloth_Modern_DarkGreen_Roof_Vertical_Flap"},{"x":-12,"y":9,"z":-11,"name":"Cloth_Modern_DarkGreen_Roof_Vertical"},{"x":-12,"y":0,"z":-10,"name":"Soil_Dirt"},{"x":-12,"y":1,"z":-10,"name":"Soil_Dirt"},{"x":-12,"y":2,"z":-10,"name":"Soil_Dirt"},{"x":-12,"y":3,"z":-10,"name":"Soil_Dirt"},{"x":-12,"y":4,"z":-10,"name":"Soil_Dirt"},{"x":-12,"y":5,"z":-10,"name":"Rock_Stone_Cobble"},{"x":-12,"y":0,"z":-9,"name":"Soil_Dirt"},{"x":-12,"y":1,"z":-9,"name":"Soil_Dirt"},{"x":-12,"y":2,"z":-9,"name":"Soil_Dirt"},{"x":-12,"y":3,"z":-9,"name":"Soil_Dirt"},{"x":-12,"y":4,"z":-9,"name":"Soil_Dirt"},{"x":-12,"y":5,"z":-9,"name":"Rock_Stone_Cobble_Mossy"},{"x":-12,"y":0,"z":-8,"name":"Soil_Dirt"},{"x":-12,"y":1,"z":-8,"name":"Soil_Dirt"},{"x":-12,"y":2,"z":-8,"name":"Soil_Dirt"},{"x":-12,"y":3,"z":-8,"name":"Soil_Dirt"},{"x":-12,"y":4,"z":-8,"name":"Soil_Dirt"},{"x":-12,"y":5,"z":-8,"name":"Rock_Stone_Cobble"},{"x":-12,"y":0,"z":-7,"name":"Soil_Dirt"},{"x":-12,"y":1,"z":-7,"name":"Soil_Dirt"},{"x":-12,"y":2,"z":-7,"name":"Soil_Dirt"},{"x":-12,"y":3,"z":-7,"name":"Soil_Dirt"},{"x":-12,"y":4,"z":-7,"name":"Soil_Dirt"},{"x":-12,"y":5,"z":-7,"name":"Rock_Stone_Cobble"},{"x":-12,"y":0,"z":-6,"name":"Soil_Dirt"},{"x":-12,"y":1,"z":-6,"name":"Soil_Dirt"},{"x":-12,"y":2,"z":-6,"name":"Soil_Dirt"},{"x":-12,"y":3,"z":-6,"name":"Soil_Dirt"},{"x":-12,"y":4,"z":-6,"name":"Soil_Dirt"},{"x":-12,"y":5,"z":-6,"name":"Rock_Stone_Cobble"},{"x":-12,"y":0,"z":-5,"name":"Soil_Dirt"},{"x":-12,"y":1,"z":-5,"name":"Soil_Dirt"},{"x":-12,"y":2,"z":-5,"name":"Soil_Dirt"},{"x":-12,"y":3,"z":-5,"name":"Soil_Dirt"},{"x":-12,"y":4,"z":-5,"name":"Soil_Dirt"},{"x":-12,"y":5,"z":-5,"name":"Rock_Stone_Cobble"},{"x":-12,"y":0,"z":-4,"name":"Soil_Dirt"},{"x":-12,"y":1,"z":-4,"name":"Soil_Dirt"},{"x":-12,"y":2,"z":-4,"name":"Soil_Dirt"},{"x":-12,"y":3,"z":-4,"name":"Soil_Dirt"},{"x":-12,"y":4,"z":-4,"name":"Soil_Dirt"},{"x":-12,"y":5,"z":-4,"name":"Rock_Stone_Cobble"},{"x":-12,"y":0,"z":-3,"name":"Soil_Dirt"},{"x":-12,"y":1,"z":-3,"name":"Soil_Dirt"},{"x":-12,"y":2,"z":-3,"name":"Soil_Dirt"},{"x":-12,"y":3,"z":-3,"name":"Soil_Dirt"},{"x":-12,"y":4,"z":-3,"name":"Soil_Dirt"},{"x":-12,"y":5,"z":-3,"name":"Rock_Stone_Cobble"},{"x":-12,"y":0,"z":-2,"name":"Soil_Dirt"},{"x":-12,"y":1,"z":-2,"name":"Soil_Dirt"},{"x":-12,"y":2,"z":-2,"name":"Soil_Dirt"},{"x":-12,"y":3,"z":-2,"name":"Soil_Dirt"},{"x":-12,"y":4,"z":-2,"name":"Soil_Dirt"},{"x":-12,"y":5,"z":-2,"name":"Rock_Stone_Cobble"},{"x":-12,"y":0,"z":-1,"name":"Soil_Dirt"},{"x":-12,"y":1,"z":-1,"name":"Soil_Dirt"},{"x":-12,"y":2,"z":-1,"name":"Soil_Dirt"},{"x":-12,"y":3,"z":-1,"name":"Soil_Dirt"},{"x":-12,"y":4,"z":-1,"name":"Soil_Dirt"},{"x":-12,"y":5,"z":-1,"name":"Rock_Stone_Cobble"},{"x":-12,"y":0,"z":0,"name":"Soil_Dirt"},{"x":-12,"y":1,"z":0,"name":"Soil_Dirt"},{"x":-12,"y":2,"z":0,"name":"Soil_Dirt"},{"x":-12,"y":3,"z":0,"name":"Soil_Dirt"},{"x":-12,"y":4,"z":0,"name":"Soil_Dirt"},{"x":-12,"y":5,"z":0,"name":"Rock_Stone_Cobble"},{"x":-12,"y":42,"z":0,"name":"Plant_Leaves_Jungle"},{"x":-12,"y":43,"z":0,"name":"Plant_Leaves_Jungle"},{"x":-12,"y":44,"z":0,"name":"Plant_Leaves_Jungle"},{"x":-12,"y":0,"z":1,"name":"Soil_Dirt"},{"x":-12,"y":1,"z":1,"name":"Soil_Dirt"},{"x":-12,"y":2,"z":1,"name":"Soil_Dirt"},{"x":-12,"y":3,"z":1,"name":"Soil_Dirt"},{"x":-12,"y":4,"z":1,"name":"Soil_Dirt"},{"x":-12,"y":5,"z":1,"name":"Rock_Stone_Cobble"},{"x":-12,"y":42,"z":1,"name":"Plant_Leaves_Jungle"},{"x":-12,"y":43,"z":1,"name":"Plant_Leaves_Jungle"},{"x":-12,"y":44,"z":1,"name":"Plant_Leaves_Jungle"},{"x":-12,"y":0,"z":2,"name":"Soil_Dirt"},{"x":-12,"y":1,"z":2,"name":"Soil_Dirt"},{"x":-12,"y":2,"z":2,"name":"Soil_Dirt"},{"x":-12,"y":3,"z":2,"name":"Soil_Dirt"},{"x":-12,"y":4,"z":2,"name":"Soil_Dirt"},{"x":-12,"y":5,"z":2,"name":"Rock_Stone_Cobble_Mossy"},{"x":-12,"y":42,"z":2,"name":"Plant_Leaves_Jungle"},{"x":-12,"y":43,"z":2,"name":"Plant_Leaves_Jungle"},{"x":-12,"y":44,"z":2,"name":"Plant_Leaves_Jungle"},{"x":-12,"y":0,"z":3,"name":"Soil_Dirt"},{"x":-12,"y":1,"z":3,"name":"Soil_Dirt"},{"x":-12,"y":2,"z":3,"name":"Soil_Dirt"},{"x":-12,"y":3,"z":3,"name":"Soil_Dirt"},{"x":-12,"y":4,"z":3,"name":"Soil_Dirt"},{"x":-12,"y":5,"z":3,"name":"Rock_Stone_Cobble"},{"x":-12,"y":42,"z":3,"name":"Plant_Leaves_Jungle"},{"x":-12,"y":43,"z":3,"name":"Plant_Leaves_Jungle"},{"x":-12,"y":44,"z":3,"name":"Plant_Leaves_Jungle"},{"x":-12,"y":0,"z":4,"name":"Soil_Dirt"},{"x":-12,"y":1,"z":4,"name":"Soil_Dirt"},{"x":-12,"y":2,"z":4,"name":"Soil_Dirt"},{"x":-12,"y":3,"z":4,"name":"Soil_Dirt"},{"x":-12,"y":4,"z":4,"name":"Soil_Dirt"},{"x":-12,"y":5,"z":4,"name":"Rock_Stone_Cobble_Mossy"},{"x":-12,"y":0,"z":5,"name":"Soil_Dirt"},{"x":-12,"y":1,"z":5,"name":"Soil_Dirt"},{"x":-12,"y":2,"z":5,"name":"Soil_Dirt"},{"x":-12,"y":3,"z":5,"name":"Soil_Dirt"},{"x":-12,"y":4,"z":5,"name":"Soil_Dirt"},{"x":-12,"y":5,"z":5,"name":"Rock_Stone_Cobble_Mossy"},{"x":-12,"y":0,"z":6,"name":"Soil_Dirt"},{"x":-12,"y":1,"z":6,"name":"Soil_Dirt"},{"x":-12,"y":2,"z":6,"name":"Soil_Dirt"},{"x":-12,"y":3,"z":6,"name":"Soil_Dirt"},{"x":-12,"y":4,"z":6,"name":"Soil_Dirt"},{"x":-12,"y":5,"z":6,"name":"Rock_Stone_Cobble"},{"x":-12,"y":0,"z":7,"name":"Soil_Dirt"},{"x":-12,"y":1,"z":7,"name":"Soil_Dirt"},{"x":-12,"y":2,"z":7,"name":"Soil_Dirt"},{"x":-12,"y":3,"z":7,"name":"Soil_Dirt"},{"x":-12,"y":4,"z":7,"name":"Soil_Dirt"},{"x":-12,"y":5,"z":7,"name":"Rock_Stone_Cobble"},{"x":-12,"y":0,"z":8,"name":"Soil_Dirt"},{"x":-12,"y":1,"z":8,"name":"Soil_Dirt"},{"x":-12,"y":2,"z":8,"name":"Soil_Dirt"},{"x":-12,"y":3,"z":8,"name":"Soil_Dirt"},{"x":-12,"y":4,"z":8,"name":"Soil_Dirt"},{"x":-12,"y":5,"z":8,"name":"Rock_Stone_Cobble"},{"x":-12,"y":0,"z":9,"name":"Soil_Dirt"},{"x":-12,"y":1,"z":9,"name":"Soil_Dirt"},{"x":-12,"y":2,"z":9,"name":"Soil_Dirt"},{"x":-12,"y":3,"z":9,"name":"Soil_Dirt"},{"x":-12,"y":4,"z":9,"name":"Soil_Dirt"},{"x":-12,"y":5,"z":9,"name":"Rock_Stone_Cobble_Mossy"},{"x":-12,"y":0,"z":10,"name":"Soil_Dirt"},{"x":-12,"y":1,"z":10,"name":"Soil_Dirt"},{"x":-12,"y":2,"z":10,"name":"Soil_Dirt"},{"x":-12,"y":3,"z":10,"name":"Soil_Dirt"},{"x":-12,"y":4,"z":10,"name":"Soil_Dirt"},{"x":-12,"y":5,"z":10,"name":"Rock_Stone_Cobble"},{"x":-12,"y":0,"z":11,"name":"Soil_Dirt"},{"x":-12,"y":1,"z":11,"name":"Soil_Dirt"},{"x":-12,"y":2,"z":11,"name":"Soil_Dirt"},{"x":-12,"y":3,"z":11,"name":"Soil_Dirt"},{"x":-12,"y":4,"z":11,"name":"Soil_Dirt"},{"x":-12,"y":5,"z":11,"name":"Rock_Stone_Cobble_Mossy"},{"x":-12,"y":0,"z":12,"name":"Soil_Dirt"},{"x":-12,"y":1,"z":12,"name":"Soil_Dirt"},{"x":-12,"y":2,"z":12,"name":"Soil_Dirt"},{"x":-12,"y":3,"z":12,"name":"Soil_Dirt"},{"x":-12,"y":4,"z":12,"name":"Soil_Dirt"},{"x":-12,"y":5,"z":12,"name":"Rock_Stone_Cobble"},{"x":-12,"y":8,"z":12,"name":"Cloth_Modern_DarkGreen_Roof_Vertical_Flap","rotation":2},{"x":-12,"y":9,"z":12,"name":"Cloth_Modern_DarkGreen_Roof_Vertical","rotation":2},{"x":-12,"y":0,"z":13,"name":"Soil_Dirt"},{"x":-12,"y":1,"z":13,"name":"Soil_Dirt"},{"x":-12,"y":2,"z":13,"name":"Soil_Dirt"},{"x":-12,"y":3,"z":13,"name":"Soil_Dirt"},{"x":-12,"y":4,"z":13,"name":"Soil_Dirt"},{"x":-12,"y":5,"z":13,"name":"Rock_Stone_Cobble"},{"x":-12,"y":6,"z":13,"name":"Wood_Bamboo_Branch_Long","support":15},{"x":-12,"y":7,"z":13,"name":"Wood_Bamboo_Branch_Long","support":15},{"x":-12,"y":8,"z":13,"name":"Wood_Bamboo_Branch_Long","support":15},{"x":-12,"y":9,"z":13,"name":"Rock_Crystal_Green_Block"},{"x":-12,"y":10,"z":13,"name":"Wood_Tropicalwood_Roof_Flat","rotation":2},{"x":-12,"y":0,"z":14,"name":"Soil_Dirt"},{"x":-12,"y":1,"z":14,"name":"Soil_Dirt"},{"x":-12,"y":2,"z":14,"name":"Soil_Dirt"},{"x":-12,"y":3,"z":14,"name":"Soil_Dirt"},{"x":-12,"y":4,"z":14,"name":"Soil_Dirt"},{"x":-12,"y":5,"z":14,"name":"Rock_Stone_Cobble"},{"x":-12,"y":8,"z":14,"name":"Cloth_Modern_DarkGreen_Roof_Vertical_Flap"},{"x":-12,"y":9,"z":14,"name":"Cloth_Modern_DarkGreen_Roof_Vertical"},{"x":-12,"y":0,"z":15,"name":"Soil_Dirt"},{"x":-12,"y":1,"z":15,"name":"Soil_Dirt"},{"x":-12,"y":2,"z":15,"name":"Soil_Dirt"},{"x":-12,"y":3,"z":15,"name":"Soil_Dirt"},{"x":-12,"y":4,"z":15,"name":"Soil_Dirt"},{"x":-12,"y":5,"z":15,"name":"Rock_Stone_Brick_Smooth"},{"x":-11,"y":0,"z":-14,"name":"Soil_Dirt"},{"x":-11,"y":1,"z":-14,"name":"Soil_Dirt"},{"x":-11,"y":2,"z":-14,"name":"Soil_Dirt"},{"x":-11,"y":3,"z":-14,"name":"Soil_Dirt"},{"x":-11,"y":4,"z":-14,"name":"Soil_Dirt"},{"x":-11,"y":5,"z":-14,"name":"Rock_Stone_Brick_Smooth"},{"x":-11,"y":0,"z":-13,"name":"Soil_Dirt"},{"x":-11,"y":1,"z":-13,"name":"Soil_Dirt"},{"x":-11,"y":2,"z":-13,"name":"Soil_Dirt"},{"x":-11,"y":3,"z":-13,"name":"Soil_Dirt"},{"x":-11,"y":4,"z":-13,"name":"Soil_Dirt"},{"x":-11,"y":5,"z":-13,"name":"Rock_Stone_Cobble"},{"x":-11,"y":0,"z":-12,"name":"Soil_Dirt"},{"x":-11,"y":1,"z":-12,"name":"Soil_Dirt"},{"x":-11,"y":2,"z":-12,"name":"Soil_Dirt"},{"x":-11,"y":3,"z":-12,"name":"Soil_Dirt"},{"x":-11,"y":4,"z":-12,"name":"Soil_Dirt"},{"x":-11,"y":5,"z":-12,"name":"Rock_Stone_Cobble"},{"x":-11,"y":8,"z":-12,"name":"Cloth_Modern_DarkGreen_Roof_Vertical_Flap","rotation":1},{"x":-11,"y":9,"z":-12,"name":"Cloth_Modern_DarkGreen_Roof_Vertical","rotation":1},{"x":-11,"y":0,"z":-11,"name":"Soil_Dirt"},{"x":-11,"y":1,"z":-11,"name":"Soil_Dirt"},{"x":-11,"y":2,"z":-11,"name":"Soil_Dirt"},{"x":-11,"y":3,"z":-11,"name":"Soil_Dirt"},{"x":-11,"y":4,"z":-11,"name":"Soil_Dirt"},{"x":-11,"y":5,"z":-11,"name":"Rock_Stone_Cobble"},{"x":-11,"y":0,"z":-10,"name":"Soil_Dirt"},{"x":-11,"y":1,"z":-10,"name":"Soil_Dirt"},{"x":-11,"y":2,"z":-10,"name":"Soil_Dirt"},{"x":-11,"y":3,"z":-10,"name":"Soil_Dirt"},{"x":-11,"y":4,"z":-10,"name":"Soil_Dirt"},{"x":-11,"y":5,"z":-10,"name":"Rock_Stone_Cobble"},{"x":-11,"y":0,"z":-9,"name":"Soil_Dirt"},{"x":-11,"y":1,"z":-9,"name":"Soil_Dirt"},{"x":-11,"y":2,"z":-9,"name":"Soil_Dirt"},{"x":-11,"y":3,"z":-9,"name":"Soil_Dirt"},{"x":-11,"y":4,"z":-9,"name":"Soil_Dirt"},{"x":-11,"y":5,"z":-9,"name":"Rock_Stone_Cobble_Mossy"},{"x":-11,"y":0,"z":-8,"name":"Soil_Dirt"},{"x":-11,"y":1,"z":-8,"name":"Soil_Dirt"},{"x":-11,"y":2,"z":-8,"name":"Soil_Dirt"},{"x":-11,"y":3,"z":-8,"name":"Soil_Dirt"},{"x":-11,"y":4,"z":-8,"name":"Soil_Dirt"},{"x":-11,"y":5,"z":-8,"name":"Rock_Stone_Cobble"},{"x":-11,"y":0,"z":-7,"name":"Soil_Dirt"},{"x":-11,"y":1,"z":-7,"name":"Soil_Dirt"},{"x":-11,"y":2,"z":-7,"name":"Soil_Dirt"},{"x":-11,"y":3,"z":-7,"name":"Soil_Dirt"},{"x":-11,"y":4,"z":-7,"name":"Soil_Dirt"},{"x":-11,"y":5,"z":-7,"name":"Rock_Stone_Cobble_Mossy"},{"x":-11,"y":0,"z":-6,"name":"Soil_Dirt"},{"x":-11,"y":1,"z":-6,"name":"Soil_Dirt"},{"x":-11,"y":2,"z":-6,"name":"Soil_Dirt"},{"x":-11,"y":3,"z":-6,"name":"Soil_Dirt"},{"x":-11,"y":4,"z":-6,"name":"Soil_Dirt"},{"x":-11,"y":5,"z":-6,"name":"Rock_Stone_Cobble"},{"x":-11,"y":0,"z":-5,"name":"Soil_Dirt"},{"x":-11,"y":1,"z":-5,"name":"Soil_Dirt"},{"x":-11,"y":2,"z":-5,"name":"Soil_Dirt"},{"x":-11,"y":3,"z":-5,"name":"Soil_Dirt"},{"x":-11,"y":4,"z":-5,"name":"Soil_Dirt"},{"x":-11,"y":5,"z":-5,"name":"Rock_Stone_Cobble_Mossy"},{"x":-11,"y":0,"z":-4,"name":"Soil_Dirt"},{"x":-11,"y":1,"z":-4,"name":"Soil_Dirt"},{"x":-11,"y":2,"z":-4,"name":"Soil_Dirt"},{"x":-11,"y":3,"z":-4,"name":"Soil_Dirt"},{"x":-11,"y":4,"z":-4,"name":"Soil_Dirt"},{"x":-11,"y":5,"z":-4,"name":"Rock_Stone_Cobble"},{"x":-11,"y":0,"z":-3,"name":"Soil_Dirt"},{"x":-11,"y":1,"z":-3,"name":"Soil_Dirt"},{"x":-11,"y":2,"z":-3,"name":"Soil_Dirt"},{"x":-11,"y":3,"z":-3,"name":"Soil_Dirt"},{"x":-11,"y":4,"z":-3,"name":"Soil_Dirt"},{"x":-11,"y":5,"z":-3,"name":"Rock_Stone_Cobble"},{"x":-11,"y":0,"z":-2,"name":"Soil_Dirt"},{"x":-11,"y":1,"z":-2,"name":"Soil_Dirt"},{"x":-11,"y":2,"z":-2,"name":"Soil_Dirt"},{"x":-11,"y":3,"z":-2,"name":"Soil_Dirt"},{"x":-11,"y":4,"z":-2,"name":"Soil_Dirt"},{"x":-11,"y":5,"z":-2,"name":"Rock_Stone_Cobble"},{"x":-11,"y":0,"z":-1,"name":"Soil_Dirt"},{"x":-11,"y":1,"z":-1,"name":"Soil_Dirt"},{"x":-11,"y":2,"z":-1,"name":"Soil_Dirt"},{"x":-11,"y":3,"z":-1,"name":"Soil_Dirt"},{"x":-11,"y":4,"z":-1,"name":"Soil_Dirt"},{"x":-11,"y":5,"z":-1,"name":"Rock_Stone_Cobble"},{"x":-11,"y":42,"z":-1,"name":"Plant_Leaves_Jungle","support":2},{"x":-11,"y":43,"z":-1,"name":"Plant_Leaves_Jungle","support":2},{"x":-11,"y":44,"z":-1,"name":"Plant_Leaves_Jungle","support":2},{"x":-11,"y":0,"z":0,"name":"Soil_Dirt"},{"x":-11,"y":1,"z":0,"name":"Soil_Dirt"},{"x":-11,"y":2,"z":0,"name":"Soil_Dirt"},{"x":-11,"y":3,"z":0,"name":"Soil_Dirt"},{"x":-11,"y":4,"z":0,"name":"Soil_Dirt"},{"x":-11,"y":5,"z":0,"name":"Soil_Mud_Dry"},{"x":-11,"y":42,"z":0,"name":"Plant_Leaves_Jungle","support":1},{"x":-11,"y":43,"z":0,"name":"Plant_Leaves_Jungle","support":1},{"x":-11,"y":44,"z":0,"name":"Plant_Leaves_Jungle","support":1},{"x":-11,"y":0,"z":1,"name":"Soil_Dirt"},{"x":-11,"y":1,"z":1,"name":"Soil_Dirt"},{"x":-11,"y":2,"z":1,"name":"Soil_Dirt"},{"x":-11,"y":3,"z":1,"name":"Soil_Dirt"},{"x":-11,"y":4,"z":1,"name":"Soil_Dirt"},{"x":-11,"y":5,"z":1,"name":"Soil_Grass_Sunny"},{"x":-11,"y":41,"z":1,"name":"Plant_Leaves_Jungle","support":2},{"x":-11,"y":42,"z":1,"name":"Plant_Leaves_Jungle","support":1},{"x":-11,"y":43,"z":1,"name":"Plant_Leaves_Jungle","support":1},{"x":-11,"y":44,"z":1,"name":"Plant_Leaves_Jungle","support":1},{"x":-11,"y":45,"z":1,"name":"Plant_Leaves_Jungle","support":2},{"x":-11,"y":0,"z":2,"name":"Soil_Dirt"},{"x":-11,"y":1,"z":2,"name":"Soil_Dirt"},{"x":-11,"y":2,"z":2,"name":"Soil_Dirt"},{"x":-11,"y":3,"z":2,"name":"Soil_Dirt"},{"x":-11,"y":4,"z":2,"name":"Soil_Dirt"},{"x":-11,"y":5,"z":2,"name":"Soil_Grass_Deep"},{"x":-11,"y":41,"z":2,"name":"Plant_Leaves_Jungle","support":2},{"x":-11,"y":42,"z":2,"name":"Plant_Leaves_Jungle","support":1},{"x":-11,"y":43,"z":2,"name":"Plant_Leaves_Jungle","support":1},{"x":-11,"y":44,"z":2,"name":"Plant_Leaves_Jungle","support":1},{"x":-11,"y":45,"z":2,"name":"Plant_Leaves_Jungle","support":2},{"x":-11,"y":0,"z":3,"name":"Soil_Dirt"},{"x":-11,"y":1,"z":3,"name":"Soil_Dirt"},{"x":-11,"y":2,"z":3,"name":"Soil_Dirt"},{"x":-11,"y":3,"z":3,"name":"Soil_Dirt"},{"x":-11,"y":4,"z":3,"name":"Soil_Dirt"},{"x":-11,"y":5,"z":3,"name":"Rock_Stone_Cobble_Mossy"},{"x":-11,"y":39,"z":3,"name":"Plant_Leaves_Jungle"},{"x":-11,"y":42,"z":3,"name":"Plant_Leaves_Jungle","support":1},{"x":-11,"y":43,"z":3,"name":"Plant_Leaves_Jungle","support":1},{"x":-11,"y":44,"z":3,"name":"Plant_Leaves_Jungle","support":1},{"x":-11,"y":0,"z":4,"name":"Soil_Dirt"},{"x":-11,"y":1,"z":4,"name":"Soil_Dirt"},{"x":-11,"y":2,"z":4,"name":"Soil_Dirt"},{"x":-11,"y":3,"z":4,"name":"Soil_Dirt"},{"x":-11,"y":4,"z":4,"name":"Soil_Dirt"},{"x":-11,"y":5,"z":4,"name":"Soil_Mud_Dry"},{"x":-11,"y":42,"z":4,"name":"Plant_Leaves_Jungle","support":2},{"x":-11,"y":43,"z":4,"name":"Plant_Leaves_Jungle","support":2},{"x":-11,"y":44,"z":4,"name":"Plant_Leaves_Jungle","support":2},{"x":-11,"y":0,"z":5,"name":"Soil_Dirt"},{"x":-11,"y":1,"z":5,"name":"Soil_Dirt"},{"x":-11,"y":2,"z":5,"name":"Soil_Dirt"},{"x":-11,"y":3,"z":5,"name":"Soil_Dirt"},{"x":-11,"y":4,"z":5,"name":"Soil_Dirt"},{"x":-11,"y":5,"z":5,"name":"Soil_Mud_Dry"},{"x":-11,"y":42,"z":5,"name":"Plant_Leaves_Jungle","support":3},{"x":-11,"y":43,"z":5,"name":"Plant_Leaves_Jungle","support":3},{"x":-11,"y":44,"z":5,"name":"Plant_Leaves_Jungle","support":3},{"x":-11,"y":0,"z":6,"name":"Soil_Dirt"},{"x":-11,"y":1,"z":6,"name":"Soil_Dirt"},{"x":-11,"y":2,"z":6,"name":"Soil_Dirt"},{"x":-11,"y":3,"z":6,"name":"Soil_Dirt"},{"x":-11,"y":4,"z":6,"name":"Soil_Dirt"},{"x":-11,"y":5,"z":6,"name":"Soil_Grass_Deep"},{"x":-11,"y":42,"z":6,"name":"Plant_Leaves_Jungle","support":4},{"x":-11,"y":43,"z":6,"name":"Plant_Leaves_Jungle","support":4},{"x":-11,"y":44,"z":6,"name":"Plant_Leaves_Jungle","support":4},{"x":-11,"y":0,"z":7,"name":"Soil_Dirt"},{"x":-11,"y":1,"z":7,"name":"Soil_Dirt"},{"x":-11,"y":2,"z":7,"name":"Soil_Dirt"},{"x":-11,"y":3,"z":7,"name":"Soil_Dirt"},{"x":-11,"y":4,"z":7,"name":"Soil_Dirt"},{"x":-11,"y":5,"z":7,"name":"Rock_Stone_Cobble"},{"x":-11,"y":0,"z":8,"name":"Soil_Dirt"},{"x":-11,"y":1,"z":8,"name":"Soil_Dirt"},{"x":-11,"y":2,"z":8,"name":"Soil_Dirt"},{"x":-11,"y":3,"z":8,"name":"Soil_Dirt"},{"x":-11,"y":4,"z":8,"name":"Soil_Dirt"},{"x":-11,"y":5,"z":8,"name":"Rock_Stone_Cobble"},{"x":-11,"y":0,"z":9,"name":"Soil_Dirt"},{"x":-11,"y":1,"z":9,"name":"Soil_Dirt"},{"x":-11,"y":2,"z":9,"name":"Soil_Dirt"},{"x":-11,"y":3,"z":9,"name":"Soil_Dirt"},{"x":-11,"y":4,"z":9,"name":"Soil_Dirt"},{"x":-11,"y":5,"z":9,"name":"Rock_Stone_Cobble"},{"x":-11,"y":0,"z":10,"name":"Soil_Dirt"},{"x":-11,"y":1,"z":10,"name":"Soil_Dirt"},{"x":-11,"y":2,"z":10,"name":"Soil_Dirt"},{"x":-11,"y":3,"z":10,"name":"Soil_Dirt"},{"x":-11,"y":4,"z":10,"name":"Soil_Dirt"},{"x":-11,"y":5,"z":10,"name":"Rock_Stone_Cobble"},{"x":-11,"y":0,"z":11,"name":"Soil_Dirt"},{"x":-11,"y":1,"z":11,"name":"Soil_Dirt"},{"x":-11,"y":2,"z":11,"name":"Soil_Dirt"},{"x":-11,"y":3,"z":11,"name":"Soil_Dirt"},{"x":-11,"y":4,"z":11,"name":"Soil_Dirt"},{"x":-11,"y":5,"z":11,"name":"Rock_Stone_Cobble_Mossy"},{"x":-11,"y":0,"z":12,"name":"Soil_Dirt"},{"x":-11,"y":1,"z":12,"name":"Soil_Dirt"},{"x":-11,"y":2,"z":12,"name":"Soil_Dirt"},{"x":-11,"y":3,"z":12,"name":"Soil_Dirt"},{"x":-11,"y":4,"z":12,"name":"Soil_Dirt"},{"x":-11,"y":5,"z":12,"name":"Rock_Stone_Cobble"},{"x":-11,"y":0,"z":13,"name":"Soil_Dirt"},{"x":-11,"y":1,"z":13,"name":"Soil_Dirt"},{"x":-11,"y":2,"z":13,"name":"Soil_Dirt"},{"x":-11,"y":3,"z":13,"name":"Soil_Dirt"},{"x":-11,"y":4,"z":13,"name":"Soil_Dirt"},{"x":-11,"y":5,"z":13,"name":"Rock_Stone_Cobble_Mossy"},{"x":-11,"y":8,"z":13,"name":"Cloth_Modern_DarkGreen_Roof_Vertical_Flap","rotation":1},{"x":-11,"y":9,"z":13,"name":"Cloth_Modern_DarkGreen_Roof_Vertical","rotation":1},{"x":-11,"y":0,"z":14,"name":"Soil_Dirt"},{"x":-11,"y":1,"z":14,"name":"Soil_Dirt"},{"x":-11,"y":2,"z":14,"name":"Soil_Dirt"},{"x":-11,"y":3,"z":14,"name":"Soil_Dirt"},{"x":-11,"y":4,"z":14,"name":"Soil_Dirt"},{"x":-11,"y":5,"z":14,"name":"Rock_Stone_Cobble"},{"x":-11,"y":0,"z":15,"name":"Soil_Dirt"},{"x":-11,"y":1,"z":15,"name":"Soil_Dirt"},{"x":-11,"y":2,"z":15,"name":"Soil_Dirt"},{"x":-11,"y":3,"z":15,"name":"Soil_Dirt"},{"x":-11,"y":4,"z":15,"name":"Soil_Dirt"},{"x":-11,"y":5,"z":15,"name":"Rock_Stone_Brick_Smooth"},{"x":-10,"y":0,"z":-14,"name":"Soil_Dirt"},{"x":-10,"y":1,"z":-14,"name":"Soil_Dirt"},{"x":-10,"y":2,"z":-14,"name":"Soil_Dirt"},{"x":-10,"y":3,"z":-14,"name":"Soil_Dirt"},{"x":-10,"y":4,"z":-14,"name":"Soil_Dirt"},{"x":-10,"y":5,"z":-14,"name":"Rock_Stone_Brick_Smooth"},{"x":-10,"y":0,"z":-13,"name":"Soil_Dirt"},{"x":-10,"y":1,"z":-13,"name":"Soil_Dirt"},{"x":-10,"y":2,"z":-13,"name":"Soil_Dirt"},{"x":-10,"y":3,"z":-13,"name":"Soil_Dirt"},{"x":-10,"y":4,"z":-13,"name":"Soil_Dirt"},{"x":-10,"y":5,"z":-13,"name":"Rock_Stone_Cobble"},{"x":-10,"y":0,"z":-12,"name":"Soil_Dirt"},{"x":-10,"y":1,"z":-12,"name":"Soil_Dirt"},{"x":-10,"y":2,"z":-12,"name":"Soil_Dirt"},{"x":-10,"y":3,"z":-12,"name":"Soil_Dirt"},{"x":-10,"y":4,"z":-12,"name":"Soil_Dirt"},{"x":-10,"y":5,"z":-12,"name":"Rock_Stone_Cobble"},{"x":-10,"y":0,"z":-11,"name":"Soil_Dirt"},{"x":-10,"y":1,"z":-11,"name":"Soil_Dirt"},{"x":-10,"y":2,"z":-11,"name":"Soil_Dirt"},{"x":-10,"y":3,"z":-11,"name":"Soil_Dirt"},{"x":-10,"y":4,"z":-11,"name":"Soil_Dirt"},{"x":-10,"y":5,"z":-11,"name":"Rock_Stone_Cobble"},{"x":-10,"y":0,"z":-10,"name":"Soil_Dirt"},{"x":-10,"y":1,"z":-10,"name":"Soil_Dirt"},{"x":-10,"y":2,"z":-10,"name":"Soil_Dirt"},{"x":-10,"y":3,"z":-10,"name":"Soil_Dirt"},{"x":-10,"y":4,"z":-10,"name":"Soil_Dirt"},{"x":-10,"y":5,"z":-10,"name":"Rock_Stone_Cobble_Mossy"},{"x":-10,"y":0,"z":-9,"name":"Soil_Dirt"},{"x":-10,"y":1,"z":-9,"name":"Soil_Dirt"},{"x":-10,"y":2,"z":-9,"name":"Soil_Dirt"},{"x":-10,"y":3,"z":-9,"name":"Soil_Dirt"},{"x":-10,"y":4,"z":-9,"name":"Soil_Dirt"},{"x":-10,"y":5,"z":-9,"name":"Rock_Stone_Cobble"},{"x":-10,"y":0,"z":-8,"name":"Soil_Dirt"},{"x":-10,"y":1,"z":-8,"name":"Soil_Dirt"},{"x":-10,"y":2,"z":-8,"name":"Soil_Dirt"},{"x":-10,"y":3,"z":-8,"name":"Soil_Dirt"},{"x":-10,"y":4,"z":-8,"name":"Soil_Dirt"},{"x":-10,"y":5,"z":-8,"name":"Rock_Stone_Cobble"},{"x":-10,"y":0,"z":-7,"name":"Soil_Dirt"},{"x":-10,"y":1,"z":-7,"name":"Soil_Dirt"},{"x":-10,"y":2,"z":-7,"name":"Soil_Dirt"},{"x":-10,"y":3,"z":-7,"name":"Soil_Dirt"},{"x":-10,"y":4,"z":-7,"name":"Soil_Dirt"},{"x":-10,"y":5,"z":-7,"name":"Soil_Mud_Dry"},{"x":-10,"y":0,"z":-6,"name":"Soil_Dirt"},{"x":-10,"y":1,"z":-6,"name":"Soil_Dirt"},{"x":-10,"y":2,"z":-6,"name":"Soil_Dirt"},{"x":-10,"y":3,"z":-6,"name":"Soil_Dirt"},{"x":-10,"y":4,"z":-6,"name":"Soil_Dirt"},{"x":-10,"y":5,"z":-6,"name":"Soil_Grass_Sunny"},{"x":-10,"y":0,"z":-5,"name":"Soil_Dirt"},{"x":-10,"y":1,"z":-5,"name":"Soil_Dirt"},{"x":-10,"y":2,"z":-5,"name":"Soil_Dirt"},{"x":-10,"y":3,"z":-5,"name":"Soil_Dirt"},{"x":-10,"y":4,"z":-5,"name":"Soil_Dirt"},{"x":-10,"y":5,"z":-5,"name":"Soil_Grass_Deep"},{"x":-10,"y":0,"z":-4,"name":"Soil_Dirt"},{"x":-10,"y":1,"z":-4,"name":"Soil_Dirt"},{"x":-10,"y":2,"z":-4,"name":"Soil_Dirt"},{"x":-10,"y":3,"z":-4,"name":"Soil_Dirt"},{"x":-10,"y":4,"z":-4,"name":"Soil_Dirt"},{"x":-10,"y":5,"z":-4,"name":"Soil_Grass_Deep"},{"x":-10,"y":0,"z":-3,"name":"Soil_Dirt"},{"x":-10,"y":1,"z":-3,"name":"Soil_Dirt"},{"x":-10,"y":2,"z":-3,"name":"Soil_Dirt"},{"x":-10,"y":3,"z":-3,"name":"Soil_Dirt"},{"x":-10,"y":4,"z":-3,"name":"Soil_Dirt"},{"x":-10,"y":5,"z":-3,"name":"Soil_Grass_Deep"},{"x":-10,"y":0,"z":-2,"name":"Soil_Dirt"},{"x":-10,"y":1,"z":-2,"name":"Soil_Dirt"},{"x":-10,"y":2,"z":-2,"name":"Soil_Dirt"},{"x":-10,"y":3,"z":-2,"name":"Soil_Dirt"},{"x":-10,"y":4,"z":-2,"name":"Soil_Dirt"},{"x":-10,"y":5,"z":-2,"name":"Soil_Mud_Dry"},{"x":-10,"y":0,"z":-1,"name":"Soil_Dirt"},{"x":-10,"y":1,"z":-1,"name":"Soil_Dirt"},{"x":-10,"y":2,"z":-1,"name":"Soil_Dirt"},{"x":-10,"y":3,"z":-1,"name":"Soil_Dirt"},{"x":-10,"y":4,"z":-1,"name":"Soil_Dirt"},{"x":-10,"y":5,"z":-1,"name":"Soil_Grass_Deep"},{"x":-10,"y":42,"z":-1,"name":"Plant_Leaves_Jungle","support":3},{"x":-10,"y":43,"z":-1,"name":"Plant_Leaves_Jungle","support":3},{"x":-10,"y":44,"z":-1,"name":"Plant_Leaves_Jungle","support":3},{"x":-10,"y":0,"z":0,"name":"Soil_Dirt"},{"x":-10,"y":1,"z":0,"name":"Soil_Dirt"},{"x":-10,"y":2,"z":0,"name":"Soil_Dirt"},{"x":-10,"y":3,"z":0,"name":"Soil_Dirt"},{"x":-10,"y":4,"z":0,"name":"Soil_Dirt"},{"x":-10,"y":5,"z":0,"name":"Soil_Grass_Deep"},{"x":-10,"y":41,"z":0,"name":"Plant_Leaves_Jungle","support":3},{"x":-10,"y":42,"z":0,"name":"Plant_Leaves_Jungle","support":2},{"x":-10,"y":43,"z":0,"name":"Plant_Leaves_Jungle","support":2},{"x":-10,"y":44,"z":0,"name":"Plant_Leaves_Jungle","support":2},{"x":-10,"y":45,"z":0,"name":"Plant_Leaves_Jungle","support":3},{"x":-10,"y":0,"z":1,"name":"Soil_Dirt"},{"x":-10,"y":1,"z":1,"name":"Soil_Dirt"},{"x":-10,"y":2,"z":1,"name":"Soil_Dirt"},{"x":-10,"y":3,"z":1,"name":"Soil_Dirt"},{"x":-10,"y":4,"z":1,"name":"Soil_Dirt"},{"x":-10,"y":5,"z":1,"name":"Soil_Grass_Deep"},{"x":-10,"y":37,"z":1,"name":"Plant_Leaves_Jungle"},{"x":-10,"y":39,"z":1,"name":"Plant_Leaves_Jungle"},{"x":-10,"y":41,"z":1,"name":"Plant_Leaves_Jungle","support":3},{"x":-10,"y":42,"z":1,"name":"Plant_Leaves_Jungle","support":2},{"x":-10,"y":43,"z":1,"name":"Plant_Leaves_Jungle","support":2},{"x":-10,"y":44,"z":1,"name":"Plant_Leaves_Jungle","support":2},{"x":-10,"y":45,"z":1,"name":"Plant_Leaves_Jungle","support":3},{"x":-10,"y":0,"z":2,"name":"Soil_Dirt"},{"x":-10,"y":1,"z":2,"name":"Soil_Dirt"},{"x":-10,"y":2,"z":2,"name":"Soil_Dirt"},{"x":-10,"y":3,"z":2,"name":"Soil_Dirt"},{"x":-10,"y":4,"z":2,"name":"Soil_Dirt"},{"x":-10,"y":5,"z":2,"name":"Soil_Grass_Sunny"},{"x":-10,"y":39,"z":2,"name":"Plant_Leaves_Jungle"},{"x":-10,"y":41,"z":2,"name":"Plant_Leaves_Jungle","support":3},{"x":-10,"y":42,"z":2,"name":"Plant_Leaves_Jungle","support":2},{"x":-10,"y":43,"z":2,"name":"Plant_Leaves_Jungle","support":2},{"x":-10,"y":44,"z":2,"name":"Plant_Leaves_Jungle","support":2},{"x":-10,"y":45,"z":2,"name":"Plant_Leaves_Jungle","support":3},{"x":-10,"y":0,"z":3,"name":"Soil_Dirt"},{"x":-10,"y":1,"z":3,"name":"Soil_Dirt"},{"x":-10,"y":2,"z":3,"name":"Soil_Dirt"},{"x":-10,"y":3,"z":3,"name":"Soil_Dirt"},{"x":-10,"y":4,"z":3,"name":"Soil_Dirt"},{"x":-10,"y":5,"z":3,"name":"Soil_Grass_Deep"},{"x":-10,"y":36,"z":3,"name":"Plant_Leaves_Jungle"},{"x":-10,"y":38,"z":3,"name":"Plant_Leaves_Jungle"},{"x":-10,"y":39,"z":3,"name":"Plant_Leaves_Jungle"},{"x":-10,"y":40,"z":3,"name":"Plant_Leaves_Jungle","support":4},{"x":-10,"y":41,"z":3,"name":"Plant_Leaves_Jungle","support":3},{"x":-10,"y":42,"z":3,"name":"Plant_Leaves_Jungle","support":2},{"x":-10,"y":43,"z":3,"name":"Plant_Leaves_Jungle","support":2},{"x":-10,"y":44,"z":3,"name":"Plant_Leaves_Jungle","support":2},{"x":-10,"y":45,"z":3,"name":"Plant_Leaves_Jungle","support":3},{"x":-10,"y":0,"z":4,"name":"Soil_Dirt"},{"x":-10,"y":1,"z":4,"name":"Soil_Dirt"},{"x":-10,"y":2,"z":4,"name":"Soil_Dirt"},{"x":-10,"y":3,"z":4,"name":"Soil_Dirt"},{"x":-10,"y":4,"z":4,"name":"Soil_Dirt"},{"x":-10,"y":5,"z":4,"name":"Soil_Grass_Deep"},{"x":-10,"y":6,"z":4,"name":"Wood_Sticks","support":15},{"x":-10,"y":39,"z":4,"name":"Plant_Leaves_Jungle"},{"x":-10,"y":41,"z":4,"name":"Plant_Leaves_Jungle","support":4},{"x":-10,"y":42,"z":4,"name":"Plant_Leaves_Jungle","support":3},{"x":-10,"y":43,"z":4,"name":"Plant_Leaves_Jungle","support":3},{"x":-10,"y":44,"z":4,"name":"Plant_Leaves_Jungle","support":3},{"x":-10,"y":0,"z":5,"name":"Soil_Dirt"},{"x":-10,"y":1,"z":5,"name":"Soil_Dirt"},{"x":-10,"y":2,"z":5,"name":"Soil_Dirt"},{"x":-10,"y":3,"z":5,"name":"Soil_Dirt"},{"x":-10,"y":4,"z":5,"name":"Soil_Dirt"},{"x":-10,"y":5,"z":5,"name":"Soil_Grass_Deep"},{"x":-10,"y":41,"z":5,"name":"Plant_Leaves_Jungle"},{"x":-10,"y":42,"z":5,"name":"Plant_Leaves_Jungle","support":4},{"x":-10,"y":43,"z":5,"name":"Plant_Leaves_Jungle","support":4},{"x":-10,"y":44,"z":5,"name":"Plant_Leaves_Jungle","support":4},{"x":-10,"y":0,"z":6,"name":"Soil_Dirt"},{"x":-10,"y":1,"z":6,"name":"Soil_Dirt"},{"x":-10,"y":2,"z":6,"name":"Soil_Dirt"},{"x":-10,"y":3,"z":6,"name":"Soil_Dirt"},{"x":-10,"y":4,"z":6,"name":"Soil_Dirt"},{"x":-10,"y":5,"z":6,"name":"Soil_Grass_Sunny"},{"x":-10,"y":41,"z":6,"name":"Plant_Leaves_Jungle"},{"x":-10,"y":42,"z":6,"name":"Plant_Leaves_Jungle"},{"x":-10,"y":43,"z":6,"name":"Plant_Leaves_Jungle"},{"x":-10,"y":0,"z":7,"name":"Soil_Dirt"},{"x":-10,"y":1,"z":7,"name":"Soil_Dirt"},{"x":-10,"y":2,"z":7,"name":"Soil_Dirt"},{"x":-10,"y":3,"z":7,"name":"Soil_Dirt"},{"x":-10,"y":4,"z":7,"name":"Soil_Dirt"},{"x":-10,"y":5,"z":7,"name":"Soil_Grass_Sunny"},{"x":-10,"y":41,"z":7,"name":"Plant_Leaves_Jungle"},{"x":-10,"y":42,"z":7,"name":"Plant_Leaves_Jungle"},{"x":-10,"y":43,"z":7,"name":"Plant_Leaves_Jungle"},{"x":-10,"y":0,"z":8,"name":"Soil_Dirt"},{"x":-10,"y":1,"z":8,"name":"Soil_Dirt"},{"x":-10,"y":2,"z":8,"name":"Soil_Dirt"},{"x":-10,"y":3,"z":8,"name":"Soil_Dirt"},{"x":-10,"y":4,"z":8,"name":"Soil_Dirt"},{"x":-10,"y":5,"z":8,"name":"Soil_Grass_Deep","support":15},{"x":-10,"y":0,"z":9,"name":"Soil_Dirt"},{"x":-10,"y":1,"z":9,"name":"Soil_Dirt"},{"x":-10,"y":2,"z":9,"name":"Soil_Dirt"},{"x":-10,"y":3,"z":9,"name":"Soil_Dirt"},{"x":-10,"y":4,"z":9,"name":"Soil_Dirt"},{"x":-10,"y":5,"z":9,"name":"Rock_Stone_Cobble","support":15},{"x":-10,"y":0,"z":10,"name":"Soil_Dirt"},{"x":-10,"y":1,"z":10,"name":"Soil_Dirt"},{"x":-10,"y":2,"z":10,"name":"Soil_Dirt"},{"x":-10,"y":3,"z":10,"name":"Soil_Dirt"},{"x":-10,"y":4,"z":10,"name":"Soil_Dirt"},{"x":-10,"y":5,"z":10,"name":"Rock_Stone_Cobble"},{"x":-10,"y":0,"z":11,"name":"Soil_Dirt"},{"x":-10,"y":1,"z":11,"name":"Soil_Dirt"},{"x":-10,"y":2,"z":11,"name":"Soil_Dirt"},{"x":-10,"y":3,"z":11,"name":"Soil_Dirt"},{"x":-10,"y":4,"z":11,"name":"Soil_Dirt"},{"x":-10,"y":5,"z":11,"name":"Rock_Stone_Cobble_Mossy"},{"x":-10,"y":0,"z":12,"name":"Soil_Dirt"},{"x":-10,"y":1,"z":12,"name":"Soil_Dirt"},{"x":-10,"y":2,"z":12,"name":"Soil_Dirt"},{"x":-10,"y":3,"z":12,"name":"Soil_Dirt"},{"x":-10,"y":4,"z":12,"name":"Soil_Dirt"},{"x":-10,"y":5,"z":12,"name":"Rock_Stone_Cobble"},{"x":-10,"y":0,"z":13,"name":"Soil_Dirt"},{"x":-10,"y":1,"z":13,"name":"Soil_Dirt"},{"x":-10,"y":2,"z":13,"name":"Soil_Dirt"},{"x":-10,"y":3,"z":13,"name":"Soil_Dirt"},{"x":-10,"y":4,"z":13,"name":"Soil_Dirt"},{"x":-10,"y":5,"z":13,"name":"Rock_Stone_Cobble_Mossy"},{"x":-10,"y":0,"z":14,"name":"Soil_Dirt"},{"x":-10,"y":1,"z":14,"name":"Soil_Dirt"},{"x":-10,"y":2,"z":14,"name":"Soil_Dirt"},{"x":-10,"y":3,"z":14,"name":"Soil_Dirt"},{"x":-10,"y":4,"z":14,"name":"Soil_Dirt"},{"x":-10,"y":5,"z":14,"name":"Rock_Stone_Cobble_Mossy"},{"x":-10,"y":0,"z":15,"name":"Soil_Dirt"},{"x":-10,"y":1,"z":15,"name":"Soil_Dirt"},{"x":-10,"y":2,"z":15,"name":"Soil_Dirt"},{"x":-10,"y":3,"z":15,"name":"Soil_Dirt"},{"x":-10,"y":4,"z":15,"name":"Soil_Dirt"},{"x":-10,"y":5,"z":15,"name":"Rock_Stone_Brick_Smooth"},{"x":-9,"y":0,"z":-14,"name":"Soil_Dirt"},{"x":-9,"y":1,"z":-14,"name":"Soil_Dirt"},{"x":-9,"y":2,"z":-14,"name":"Soil_Dirt"},{"x":-9,"y":3,"z":-14,"name":"Soil_Dirt"},{"x":-9,"y":4,"z":-14,"name":"Soil_Dirt"},{"x":-9,"y":5,"z":-14,"name":"Rock_Stone_Brick_Smooth"},{"x":-9,"y":0,"z":-13,"name":"Soil_Dirt"},{"x":-9,"y":1,"z":-13,"name":"Soil_Dirt"},{"x":-9,"y":2,"z":-13,"name":"Soil_Dirt"},{"x":-9,"y":3,"z":-13,"name":"Soil_Dirt"},{"x":-9,"y":4,"z":-13,"name":"Soil_Dirt"},{"x":-9,"y":5,"z":-13,"name":"Rock_Stone_Cobble"},{"x":-9,"y":0,"z":-12,"name":"Soil_Dirt"},{"x":-9,"y":1,"z":-12,"name":"Soil_Dirt"},{"x":-9,"y":2,"z":-12,"name":"Soil_Dirt"},{"x":-9,"y":3,"z":-12,"name":"Soil_Dirt"},{"x":-9,"y":4,"z":-12,"name":"Soil_Dirt"},{"x":-9,"y":5,"z":-12,"name":"Rock_Stone_Cobble"},{"x":-9,"y":0,"z":-11,"name":"Soil_Dirt"},{"x":-9,"y":1,"z":-11,"name":"Soil_Dirt"},{"x":-9,"y":2,"z":-11,"name":"Soil_Dirt"},{"x":-9,"y":3,"z":-11,"name":"Soil_Dirt"},{"x":-9,"y":4,"z":-11,"name":"Soil_Dirt"},{"x":-9,"y":5,"z":-11,"name":"Rock_Stone_Cobble"},{"x":-9,"y":0,"z":-10,"name":"Soil_Dirt"},{"x":-9,"y":1,"z":-10,"name":"Soil_Dirt"},{"x":-9,"y":2,"z":-10,"name":"Soil_Dirt"},{"x":-9,"y":3,"z":-10,"name":"Soil_Dirt"},{"x":-9,"y":4,"z":-10,"name":"Soil_Dirt"},{"x":-9,"y":5,"z":-10,"name":"Rock_Stone_Cobble"},{"x":-9,"y":0,"z":-9,"name":"Soil_Dirt"},{"x":-9,"y":1,"z":-9,"name":"Soil_Dirt"},{"x":-9,"y":2,"z":-9,"name":"Soil_Dirt"},{"x":-9,"y":3,"z":-9,"name":"Soil_Dirt"},{"x":-9,"y":4,"z":-9,"name":"Soil_Dirt"},{"x":-9,"y":5,"z":-9,"name":"Rock_Stone_Cobble"},{"x":-9,"y":0,"z":-8,"name":"Soil_Dirt"},{"x":-9,"y":1,"z":-8,"name":"Soil_Dirt"},{"x":-9,"y":2,"z":-8,"name":"Soil_Dirt"},{"x":-9,"y":3,"z":-8,"name":"Soil_Dirt"},{"x":-9,"y":4,"z":-8,"name":"Soil_Dirt"},{"x":-9,"y":5,"z":-8,"name":"Soil_Grass_Deep"},{"x":-9,"y":0,"z":-7,"name":"Soil_Dirt"},{"x":-9,"y":1,"z":-7,"name":"Soil_Dirt"},{"x":-9,"y":2,"z":-7,"name":"Soil_Dirt"},{"x":-9,"y":3,"z":-7,"name":"Soil_Dirt"},{"x":-9,"y":4,"z":-7,"name":"Soil_Dirt"},{"x":-9,"y":5,"z":-7,"name":"Soil_Mud_Dry"},{"x":-9,"y":0,"z":-6,"name":"Soil_Dirt"},{"x":-9,"y":1,"z":-6,"name":"Soil_Dirt"},{"x":-9,"y":2,"z":-6,"name":"Soil_Dirt"},{"x":-9,"y":3,"z":-6,"name":"Soil_Dirt"},{"x":-9,"y":4,"z":-6,"name":"Soil_Dirt"},{"x":-9,"y":5,"z":-6,"name":"Soil_Mud_Dry"},{"x":-9,"y":0,"z":-5,"name":"Soil_Dirt"},{"x":-9,"y":1,"z":-5,"name":"Soil_Dirt"},{"x":-9,"y":2,"z":-5,"name":"Soil_Dirt"},{"x":-9,"y":3,"z":-5,"name":"Soil_Dirt"},{"x":-9,"y":4,"z":-5,"name":"Soil_Dirt"},{"x":-9,"y":5,"z":-5,"name":"Soil_Grass_Deep"},{"x":-9,"y":0,"z":-4,"name":"Soil_Dirt"},{"x":-9,"y":1,"z":-4,"name":"Soil_Dirt"},{"x":-9,"y":2,"z":-4,"name":"Soil_Dirt"},{"x":-9,"y":3,"z":-4,"name":"Soil_Dirt"},{"x":-9,"y":4,"z":-4,"name":"Soil_Dirt"},{"x":-9,"y":5,"z":-4,"name":"Soil_Grass_Deep"},{"x":-9,"y":6,"z":-4,"name":"Wood_Sticks","support":15},{"x":-9,"y":40,"z":-4,"name":"Plant_Leaves_Jungle"},{"x":-9,"y":41,"z":-4,"name":"Plant_Leaves_Jungle"},{"x":-9,"y":42,"z":-4,"name":"Plant_Leaves_Jungle"},{"x":-9,"y":0,"z":-3,"name":"Soil_Dirt"},{"x":-9,"y":1,"z":-3,"name":"Soil_Dirt"},{"x":-9,"y":2,"z":-3,"name":"Soil_Dirt"},{"x":-9,"y":3,"z":-3,"name":"Soil_Dirt"},{"x":-9,"y":4,"z":-3,"name":"Soil_Dirt"},{"x":-9,"y":5,"z":-3,"name":"Soil_Grass_Deep"},{"x":-9,"y":40,"z":-3,"name":"Plant_Leaves_Jungle"},{"x":-9,"y":41,"z":-3,"name":"Plant_Leaves_Jungle"},{"x":-9,"y":42,"z":-3,"name":"Plant_Leaves_Jungle"},{"x":-9,"y":0,"z":-2,"name":"Soil_Dirt"},{"x":-9,"y":1,"z":-2,"name":"Soil_Dirt"},{"x":-9,"y":2,"z":-2,"name":"Soil_Dirt"},{"x":-9,"y":3,"z":-2,"name":"Soil_Dirt"},{"x":-9,"y":4,"z":-2,"name":"Soil_Dirt"},{"x":-9,"y":5,"z":-2,"name":"Soil_Grass_Deep"},{"x":-9,"y":6,"z":-2,"name":"Plant_Leaves_Jungle_Floor","support":15},{"x":-9,"y":40,"z":-2,"name":"Plant_Leaves_Jungle"},{"x":-9,"y":41,"z":-2,"name":"Plant_Leaves_Jungle"},{"x":-9,"y":42,"z":-2,"name":"Plant_Leaves_Jungle"},{"x":-9,"y":0,"z":-1,"name":"Soil_Dirt"},{"x":-9,"y":1,"z":-1,"name":"Soil_Dirt"},{"x":-9,"y":2,"z":-1,"name":"Soil_Dirt"},{"x":-9,"y":3,"z":-1,"name":"Soil_Dirt"},{"x":-9,"y":4,"z":-1,"name":"Soil_Dirt"},{"x":-9,"y":5,"z":-1,"name":"Soil_Grass_Deep"},{"x":-9,"y":40,"z":-1,"name":"Plant_Leaves_Jungle"},{"x":-9,"y":41,"z":-1,"name":"Plant_Leaves_Jungle"},{"x":-9,"y":42,"z":-1,"name":"Plant_Leaves_Jungle","support":4},{"x":-9,"y":43,"z":-1,"name":"Plant_Leaves_Jungle","support":4},{"x":-9,"y":44,"z":-1,"name":"Plant_Leaves_Jungle","support":4},{"x":-9,"y":0,"z":0,"name":"Soil_Dirt"},{"x":-9,"y":1,"z":0,"name":"Soil_Dirt"},{"x":-9,"y":2,"z":0,"name":"Soil_Dirt"},{"x":-9,"y":3,"z":0,"name":"Soil_Dirt"},{"x":-9,"y":4,"z":0,"name":"Soil_Dirt"},{"x":-9,"y":5,"z":0,"name":"Soil_Grass_Deep"},{"x":-9,"y":6,"z":0,"name":"Plant_Leaves_Jungle_Floor","support":15},{"x":-9,"y":37,"z":0,"name":"Plant_Leaves_Jungle"},{"x":-9,"y":39,"z":0,"name":"Plant_Leaves_Jungle"},{"x":-9,"y":40,"z":0,"name":"Plant_Leaves_Jungle"},{"x":-9,"y":41,"z":0,"name":"Plant_Leaves_Jungle","support":4},{"x":-9,"y":42,"z":0,"name":"Plant_Leaves_Jungle","support":3},{"x":-9,"y":43,"z":0,"name":"Plant_Leaves_Jungle","support":3},{"x":-9,"y":44,"z":0,"name":"Plant_Leaves_Jungle","support":3},{"x":-9,"y":45,"z":0,"name":"Plant_Leaves_Jungle","support":4},{"x":-9,"y":0,"z":1,"name":"Soil_Dirt"},{"x":-9,"y":1,"z":1,"name":"Soil_Dirt"},{"x":-9,"y":2,"z":1,"name":"Soil_Dirt"},{"x":-9,"y":3,"z":1,"name":"Soil_Dirt"},{"x":-9,"y":4,"z":1,"name":"Soil_Dirt"},{"x":-9,"y":5,"z":1,"name":"Soil_Grass_Deep"},{"x":-9,"y":6,"z":1,"name":"Plant_Leaves_Jungle_Floor","support":15},{"x":-9,"y":36,"z":1,"name":"Plant_Leaves_Jungle"},{"x":-9,"y":37,"z":1,"name":"Plant_Leaves_Jungle"},{"x":-9,"y":38,"z":1,"name":"Plant_Leaves_Jungle"},{"x":-9,"y":39,"z":1,"name":"Plant_Leaves_Jungle"},{"x":-9,"y":40,"z":1,"name":"Plant_Leaves_Jungle"},{"x":-9,"y":41,"z":1,"name":"Plant_Leaves_Jungle","support":4},{"x":-9,"y":42,"z":1,"name":"Plant_Leaves_Jungle","support":3},{"x":-9,"y":43,"z":1,"name":"Plant_Leaves_Jungle","support":3},{"x":-9,"y":44,"z":1,"name":"Plant_Leaves_Jungle","support":3},{"x":-9,"y":45,"z":1,"name":"Plant_Leaves_Jungle","support":4},{"x":-9,"y":0,"z":2,"name":"Soil_Dirt"},{"x":-9,"y":1,"z":2,"name":"Soil_Dirt"},{"x":-9,"y":2,"z":2,"name":"Soil_Dirt"},{"x":-9,"y":3,"z":2,"name":"Soil_Dirt"},{"x":-9,"y":4,"z":2,"name":"Soil_Dirt"},{"x":-9,"y":5,"z":2,"name":"Soil_Grass_Deep"},{"x":-9,"y":6,"z":2,"name":"Plant_Leaves_Jungle_Floor","support":15},{"x":-9,"y":36,"z":2,"name":"Plant_Leaves_Jungle"},{"x":-9,"y":37,"z":2,"name":"Plant_Leaves_Jungle"},{"x":-9,"y":38,"z":2,"name":"Plant_Leaves_Jungle"},{"x":-9,"y":39,"z":2,"name":"Plant_Leaves_Jungle"},{"x":-9,"y":40,"z":2,"name":"Plant_Leaves_Jungle"},{"x":-9,"y":41,"z":2,"name":"Plant_Leaves_Jungle","support":4},{"x":-9,"y":42,"z":2,"name":"Plant_Leaves_Jungle","support":3},{"x":-9,"y":43,"z":2,"name":"Plant_Leaves_Jungle","support":3},{"x":-9,"y":44,"z":2,"name":"Plant_Leaves_Jungle","support":3},{"x":-9,"y":45,"z":2,"name":"Plant_Leaves_Jungle","support":4},{"x":-9,"y":0,"z":3,"name":"Soil_Dirt"},{"x":-9,"y":1,"z":3,"name":"Soil_Dirt"},{"x":-9,"y":2,"z":3,"name":"Soil_Dirt"},{"x":-9,"y":3,"z":3,"name":"Soil_Dirt"},{"x":-9,"y":4,"z":3,"name":"Soil_Dirt"},{"x":-9,"y":5,"z":3,"name":"Soil_Grass_Deep"},{"x":-9,"y":35,"z":3,"name":"Plant_Leaves_Jungle"},{"x":-9,"y":36,"z":3,"name":"Plant_Leaves_Jungle"},{"x":-9,"y":37,"z":3,"name":"Plant_Leaves_Jungle"},{"x":-9,"y":38,"z":3,"name":"Plant_Leaves_Jungle"},{"x":-9,"y":39,"z":3,"name":"Plant_Leaves_Jungle"},{"x":-9,"y":40,"z":3,"name":"Plant_Leaves_Jungle"},{"x":-9,"y":41,"z":3,"name":"Plant_Leaves_Jungle","support":4},{"x":-9,"y":42,"z":3,"name":"Plant_Leaves_Jungle","support":3},{"x":-9,"y":43,"z":3,"name":"Plant_Leaves_Jungle","support":3},{"x":-9,"y":44,"z":3,"name":"Plant_Leaves_Jungle","support":3},{"x":-9,"y":45,"z":3,"name":"Plant_Leaves_Jungle","support":4},{"x":-9,"y":0,"z":4,"name":"Soil_Dirt"},{"x":-9,"y":1,"z":4,"name":"Soil_Dirt"},{"x":-9,"y":2,"z":4,"name":"Soil_Dirt"},{"x":-9,"y":3,"z":4,"name":"Soil_Dirt"},{"x":-9,"y":4,"z":4,"name":"Soil_Dirt"},{"x":-9,"y":5,"z":4,"name":"Soil_Grass_Deep"},{"x":-9,"y":36,"z":4,"name":"Plant_Leaves_Jungle"},{"x":-9,"y":38,"z":4,"name":"Plant_Leaves_Jungle"},{"x":-9,"y":40,"z":4,"name":"Plant_Leaves_Jungle"},{"x":-9,"y":41,"z":4,"name":"Plant_Leaves_Jungle"},{"x":-9,"y":42,"z":4,"name":"Plant_Leaves_Jungle","support":4},{"x":-9,"y":43,"z":4,"name":"Plant_Leaves_Jungle","support":4},{"x":-9,"y":44,"z":4,"name":"Plant_Leaves_Jungle","support":3},{"x":-9,"y":45,"z":4,"name":"Plant_Leaves_Jungle","support":4},{"x":-9,"y":0,"z":5,"name":"Soil_Dirt"},{"x":-9,"y":1,"z":5,"name":"Soil_Dirt"},{"x":-9,"y":2,"z":5,"name":"Soil_Dirt"},{"x":-9,"y":3,"z":5,"name":"Soil_Dirt"},{"x":-9,"y":4,"z":5,"name":"Soil_Dirt"},{"x":-9,"y":5,"z":5,"name":"Soil_Mud_Dry"},{"x":-9,"y":40,"z":5,"name":"Plant_Leaves_Jungle"},{"x":-9,"y":41,"z":5,"name":"Plant_Leaves_Jungle"},{"x":-9,"y":42,"z":5,"name":"Plant_Leaves_Jungle"},{"x":-9,"y":43,"z":5,"name":"Plant_Leaves_Jungle","support":4},{"x":-9,"y":44,"z":5,"name":"Plant_Leaves_Jungle","support":3},{"x":-9,"y":45,"z":5,"name":"Plant_Leaves_Jungle","support":4},{"x":-9,"y":0,"z":6,"name":"Soil_Dirt"},{"x":-9,"y":1,"z":6,"name":"Soil_Dirt"},{"x":-9,"y":2,"z":6,"name":"Soil_Dirt"},{"x":-9,"y":3,"z":6,"name":"Soil_Dirt"},{"x":-9,"y":4,"z":6,"name":"Soil_Dirt"},{"x":-9,"y":5,"z":6,"name":"Soil_Grass_Deep"},{"x":-9,"y":40,"z":6,"name":"Plant_Leaves_Jungle"},{"x":-9,"y":41,"z":6,"name":"Plant_Leaves_Jungle"},{"x":-9,"y":42,"z":6,"name":"Plant_Leaves_Jungle"},{"x":-9,"y":43,"z":6,"name":"Plant_Leaves_Jungle"},{"x":-9,"y":44,"z":6,"name":"Plant_Leaves_Jungle","support":4},{"x":-9,"y":0,"z":7,"name":"Soil_Dirt"},{"x":-9,"y":1,"z":7,"name":"Soil_Dirt"},{"x":-9,"y":2,"z":7,"name":"Soil_Dirt"},{"x":-9,"y":3,"z":7,"name":"Soil_Dirt"},{"x":-9,"y":4,"z":7,"name":"Soil_Dirt"},{"x":-9,"y":5,"z":7,"name":"Soil_Grass_Sunny"},{"x":-9,"y":41,"z":7,"name":"Plant_Leaves_Jungle"},{"x":-9,"y":42,"z":7,"name":"Plant_Leaves_Jungle"},{"x":-9,"y":43,"z":7,"name":"Plant_Leaves_Jungle"},{"x":-9,"y":0,"z":8,"name":"Soil_Dirt"},{"x":-9,"y":1,"z":8,"name":"Soil_Dirt"},{"x":-9,"y":2,"z":8,"name":"Soil_Dirt"},{"x":-9,"y":3,"z":8,"name":"Soil_Dirt"},{"x":-9,"y":4,"z":8,"name":"Soil_Dirt"},{"x":-9,"y":5,"z":8,"name":"Soil_Grass_Sunny"},{"x":-9,"y":41,"z":8,"name":"Plant_Leaves_Jungle"},{"x":-9,"y":42,"z":8,"name":"Plant_Leaves_Jungle"},{"x":-9,"y":43,"z":8,"name":"Plant_Leaves_Jungle"},{"x":-9,"y":0,"z":9,"name":"Soil_Dirt"},{"x":-9,"y":1,"z":9,"name":"Soil_Dirt"},{"x":-9,"y":2,"z":9,"name":"Soil_Dirt"},{"x":-9,"y":3,"z":9,"name":"Soil_Dirt"},{"x":-9,"y":4,"z":9,"name":"Soil_Dirt"},{"x":-9,"y":5,"z":9,"name":"Soil_Grass_Sunny"},{"x":-9,"y":0,"z":10,"name":"Soil_Dirt"},{"x":-9,"y":1,"z":10,"name":"Soil_Dirt"},{"x":-9,"y":2,"z":10,"name":"Soil_Dirt"},{"x":-9,"y":3,"z":10,"name":"Soil_Dirt"},{"x":-9,"y":4,"z":10,"name":"Soil_Dirt"},{"x":-9,"y":5,"z":10,"name":"Soil_Mud_Dry"},{"x":-9,"y":0,"z":11,"name":"Soil_Dirt"},{"x":-9,"y":1,"z":11,"name":"Soil_Dirt"},{"x":-9,"y":2,"z":11,"name":"Soil_Dirt"},{"x":-9,"y":3,"z":11,"name":"Soil_Dirt"},{"x":-9,"y":4,"z":11,"name":"Soil_Dirt"},{"x":-9,"y":5,"z":11,"name":"Rock_Stone_Cobble"},{"x":-9,"y":0,"z":12,"name":"Soil_Dirt"},{"x":-9,"y":1,"z":12,"name":"Soil_Dirt"},{"x":-9,"y":2,"z":12,"name":"Soil_Dirt"},{"x":-9,"y":3,"z":12,"name":"Soil_Dirt"},{"x":-9,"y":4,"z":12,"name":"Soil_Dirt"},{"x":-9,"y":5,"z":12,"name":"Rock_Stone_Cobble"},{"x":-9,"y":0,"z":13,"name":"Soil_Dirt"},{"x":-9,"y":1,"z":13,"name":"Soil_Dirt"},{"x":-9,"y":2,"z":13,"name":"Soil_Dirt"},{"x":-9,"y":3,"z":13,"name":"Soil_Dirt"},{"x":-9,"y":4,"z":13,"name":"Soil_Dirt"},{"x":-9,"y":5,"z":13,"name":"Rock_Stone_Cobble"},{"x":-9,"y":0,"z":14,"name":"Soil_Dirt"},{"x":-9,"y":1,"z":14,"name":"Soil_Dirt"},{"x":-9,"y":2,"z":14,"name":"Soil_Dirt"},{"x":-9,"y":3,"z":14,"name":"Soil_Dirt"},{"x":-9,"y":4,"z":14,"name":"Soil_Dirt"},{"x":-9,"y":5,"z":14,"name":"Rock_Stone_Cobble"},{"x":-9,"y":0,"z":15,"name":"Soil_Dirt"},{"x":-9,"y":1,"z":15,"name":"Soil_Dirt"},{"x":-9,"y":2,"z":15,"name":"Soil_Dirt"},{"x":-9,"y":3,"z":15,"name":"Soil_Dirt"},{"x":-9,"y":4,"z":15,"name":"Soil_Dirt"},{"x":-9,"y":5,"z":15,"name":"Rock_Stone_Brick_Smooth"},{"x":-8,"y":0,"z":-14,"name":"Soil_Dirt"},{"x":-8,"y":1,"z":-14,"name":"Soil_Dirt"},{"x":-8,"y":2,"z":-14,"name":"Soil_Dirt"},{"x":-8,"y":3,"z":-14,"name":"Soil_Dirt"},{"x":-8,"y":4,"z":-14,"name":"Soil_Dirt"},{"x":-8,"y":5,"z":-14,"name":"Rock_Stone_Brick_Smooth"},{"x":-8,"y":0,"z":-13,"name":"Soil_Dirt"},{"x":-8,"y":1,"z":-13,"name":"Soil_Dirt"},{"x":-8,"y":2,"z":-13,"name":"Soil_Dirt"},{"x":-8,"y":3,"z":-13,"name":"Soil_Dirt"},{"x":-8,"y":4,"z":-13,"name":"Soil_Dirt"},{"x":-8,"y":5,"z":-13,"name":"Rock_Stone_Cobble"},{"x":-8,"y":0,"z":-12,"name":"Soil_Dirt"},{"x":-8,"y":1,"z":-12,"name":"Soil_Dirt"},{"x":-8,"y":2,"z":-12,"name":"Soil_Dirt"},{"x":-8,"y":3,"z":-12,"name":"Soil_Dirt"},{"x":-8,"y":4,"z":-12,"name":"Soil_Dirt"},{"x":-8,"y":5,"z":-12,"name":"Rock_Stone_Cobble"},{"x":-8,"y":0,"z":-11,"name":"Soil_Dirt"},{"x":-8,"y":1,"z":-11,"name":"Soil_Dirt"},{"x":-8,"y":2,"z":-11,"name":"Soil_Dirt"},{"x":-8,"y":3,"z":-11,"name":"Soil_Dirt"},{"x":-8,"y":4,"z":-11,"name":"Soil_Dirt"},{"x":-8,"y":5,"z":-11,"name":"Rock_Stone_Cobble_Mossy"},{"x":-8,"y":0,"z":-10,"name":"Soil_Dirt"},{"x":-8,"y":1,"z":-10,"name":"Soil_Dirt"},{"x":-8,"y":2,"z":-10,"name":"Soil_Dirt"},{"x":-8,"y":3,"z":-10,"name":"Soil_Dirt"},{"x":-8,"y":4,"z":-10,"name":"Soil_Dirt"},{"x":-8,"y":5,"z":-10,"name":"Rock_Stone_Cobble"},{"x":-8,"y":0,"z":-9,"name":"Soil_Dirt"},{"x":-8,"y":1,"z":-9,"name":"Soil_Dirt"},{"x":-8,"y":2,"z":-9,"name":"Soil_Dirt"},{"x":-8,"y":3,"z":-9,"name":"Soil_Dirt"},{"x":-8,"y":4,"z":-9,"name":"Soil_Dirt"},{"x":-8,"y":5,"z":-9,"name":"Soil_Grass_Deep"},{"x":-8,"y":33,"z":-9,"name":"Plant_Leaves_Jungle"},{"x":-8,"y":0,"z":-8,"name":"Soil_Dirt"},{"x":-8,"y":1,"z":-8,"name":"Soil_Dirt"},{"x":-8,"y":2,"z":-8,"name":"Soil_Dirt"},{"x":-8,"y":3,"z":-8,"name":"Soil_Dirt"},{"x":-8,"y":4,"z":-8,"name":"Soil_Dirt"},{"x":-8,"y":5,"z":-8,"name":"Soil_Grass_Deep"},{"x":-8,"y":34,"z":-8,"name":"Plant_Leaves_Jungle"},{"x":-8,"y":36,"z":-8,"name":"Plant_Leaves_Jungle"},{"x":-8,"y":40,"z":-8,"name":"Plant_Leaves_Jungle"},{"x":-8,"y":41,"z":-8,"name":"Plant_Leaves_Jungle"},{"x":-8,"y":42,"z":-8,"name":"Plant_Leaves_Jungle"},{"x":-8,"y":0,"z":-7,"name":"Soil_Dirt"},{"x":-8,"y":1,"z":-7,"name":"Soil_Dirt"},{"x":-8,"y":2,"z":-7,"name":"Soil_Dirt"},{"x":-8,"y":3,"z":-7,"name":"Soil_Dirt"},{"x":-8,"y":4,"z":-7,"name":"Soil_Dirt"},{"x":-8,"y":5,"z":-7,"name":"Soil_Mud_Dry"},{"x":-8,"y":37,"z":-7,"name":"Plant_Leaves_Jungle"},{"x":-8,"y":40,"z":-7,"name":"Plant_Leaves_Jungle"},{"x":-8,"y":41,"z":-7,"name":"Plant_Leaves_Jungle"},{"x":-8,"y":42,"z":-7,"name":"Plant_Leaves_Jungle"},{"x":-8,"y":0,"z":-6,"name":"Soil_Dirt"},{"x":-8,"y":1,"z":-6,"name":"Soil_Dirt"},{"x":-8,"y":2,"z":-6,"name":"Soil_Dirt"},{"x":-8,"y":3,"z":-6,"name":"Soil_Dirt"},{"x":-8,"y":4,"z":-6,"name":"Soil_Dirt"},{"x":-8,"y":5,"z":-6,"name":"Soil_Grass_Sunny"},{"x":-8,"y":38,"z":-6,"name":"Plant_Leaves_Jungle"},{"x":-8,"y":40,"z":-6,"name":"Plant_Leaves_Jungle"},{"x":-8,"y":41,"z":-6,"name":"Plant_Leaves_Jungle"},{"x":-8,"y":42,"z":-6,"name":"Plant_Leaves_Jungle"},{"x":-8,"y":0,"z":-5,"name":"Soil_Dirt"},{"x":-8,"y":1,"z":-5,"name":"Soil_Dirt"},{"x":-8,"y":2,"z":-5,"name":"Soil_Dirt"},{"x":-8,"y":3,"z":-5,"name":"Soil_Dirt"},{"x":-8,"y":4,"z":-5,"name":"Soil_Dirt"},{"x":-8,"y":5,"z":-5,"name":"Soil_Mud_Dry"},{"x":-8,"y":40,"z":-5,"name":"Plant_Leaves_Jungle"},{"x":-8,"y":41,"z":-5,"name":"Plant_Leaves_Jungle"},{"x":-8,"y":42,"z":-5,"name":"Plant_Leaves_Jungle"},{"x":-8,"y":0,"z":-4,"name":"Soil_Dirt"},{"x":-8,"y":1,"z":-4,"name":"Soil_Dirt"},{"x":-8,"y":2,"z":-4,"name":"Soil_Dirt"},{"x":-8,"y":3,"z":-4,"name":"Soil_Dirt"},{"x":-8,"y":4,"z":-4,"name":"Soil_Dirt"},{"x":-8,"y":5,"z":-4,"name":"Soil_Grass_Sunny"},{"x":-8,"y":6,"z":-4,"name":"Plant_Leaves_Jungle_Floor","support":15},{"x":-8,"y":20,"z":-4,"name":"Wood_Jungle_Trunk","support":15,"rotation":5},{"x":-8,"y":40,"z":-4,"name":"Plant_Leaves_Jungle"},{"x":-8,"y":41,"z":-4,"name":"Plant_Leaves_Jungle"},{"x":-8,"y":42,"z":-4,"name":"Plant_Leaves_Jungle"},{"x":-8,"y":0,"z":-3,"name":"Soil_Dirt"},{"x":-8,"y":1,"z":-3,"name":"Soil_Dirt"},{"x":-8,"y":2,"z":-3,"name":"Soil_Dirt"},{"x":-8,"y":3,"z":-3,"name":"Soil_Dirt"},{"x":-8,"y":4,"z":-3,"name":"Soil_Dirt"},{"x":-8,"y":5,"z":-3,"name":"Soil_Grass_Deep"},{"x":-8,"y":6,"z":-3,"name":"Plant_Leaves_Jungle_Floor","support":15},{"x":-8,"y":19,"z":-3,"name":"Wood_Jungle_Trunk","support":15,"rotation":5},{"x":-8,"y":20,"z":-3,"name":"Wood_Jungle_Trunk","support":15,"rotation":5},{"x":-8,"y":21,"z":-3,"name":"Wood_Jungle_Trunk","support":15,"rotation":5},{"x":-8,"y":39,"z":-3,"name":"Plant_Leaves_Jungle"},{"x":-8,"y":40,"z":-3,"name":"Plant_Leaves_Jungle"},{"x":-8,"y":41,"z":-3,"name":"Plant_Leaves_Jungle"},{"x":-8,"y":42,"z":-3,"name":"Plant_Leaves_Jungle"},{"x":-8,"y":43,"z":-3,"name":"Plant_Leaves_Jungle"},{"x":-8,"y":0,"z":-2,"name":"Soil_Dirt"},{"x":-8,"y":1,"z":-2,"name":"Soil_Dirt"},{"x":-8,"y":2,"z":-2,"name":"Soil_Dirt"},{"x":-8,"y":3,"z":-2,"name":"Soil_Dirt"},{"x":-8,"y":4,"z":-2,"name":"Soil_Dirt"},{"x":-8,"y":5,"z":-2,"name":"Soil_Grass_Sunny"},{"x":-8,"y":20,"z":-2,"name":"Wood_Jungle_Trunk","support":15,"rotation":5},{"x":-8,"y":39,"z":-2,"name":"Plant_Leaves_Jungle"},{"x":-8,"y":40,"z":-2,"name":"Plant_Leaves_Jungle"},{"x":-8,"y":41,"z":-2,"name":"Plant_Leaves_Jungle"},{"x":-8,"y":42,"z":-2,"name":"Plant_Leaves_Jungle"},{"x":-8,"y":43,"z":-2,"name":"Plant_Leaves_Jungle"},{"x":-8,"y":0,"z":-1,"name":"Soil_Dirt"},{"x":-8,"y":1,"z":-1,"name":"Soil_Dirt"},{"x":-8,"y":2,"z":-1,"name":"Soil_Dirt"},{"x":-8,"y":3,"z":-1,"name":"Soil_Dirt"},{"x":-8,"y":4,"z":-1,"name":"Soil_Dirt"},{"x":-8,"y":5,"z":-1,"name":"Soil_Grass_Deep"},{"x":-8,"y":20,"z":-1,"name":"Plant_Vine_Jungle","support":15,"rotation":3},{"x":-8,"y":40,"z":-1,"name":"Plant_Leaves_Jungle"},{"x":-8,"y":41,"z":-1,"name":"Plant_Leaves_Jungle"},{"x":-8,"y":42,"z":-1,"name":"Plant_Leaves_Jungle"},{"x":-8,"y":44,"z":-1,"name":"Plant_Leaves_Jungle","support":4},{"x":-8,"y":0,"z":0,"name":"Soil_Dirt"},{"x":-8,"y":1,"z":0,"name":"Soil_Dirt"},{"x":-8,"y":2,"z":0,"name":"Soil_Dirt"},{"x":-8,"y":3,"z":0,"name":"Soil_Dirt"},{"x":-8,"y":4,"z":0,"name":"Soil_Dirt"},{"x":-8,"y":5,"z":0,"name":"Soil_Mud_Dry"},{"x":-8,"y":6,"z":0,"name":"Plant_Leaves_Jungle_Floor","support":15},{"x":-8,"y":39,"z":0,"name":"Plant_Leaves_Jungle"},{"x":-8,"y":40,"z":0,"name":"Plant_Leaves_Jungle"},{"x":-8,"y":41,"z":0,"name":"Plant_Leaves_Jungle"},{"x":-8,"y":42,"z":0,"name":"Plant_Leaves_Jungle","support":4},{"x":-8,"y":43,"z":0,"name":"Plant_Leaves_Jungle","support":4},{"x":-8,"y":44,"z":0,"name":"Plant_Leaves_Jungle","support":3},{"x":-8,"y":0,"z":1,"name":"Soil_Dirt"},{"x":-8,"y":1,"z":1,"name":"Soil_Dirt"},{"x":-8,"y":2,"z":1,"name":"Soil_Dirt"},{"x":-8,"y":3,"z":1,"name":"Soil_Dirt"},{"x":-8,"y":4,"z":1,"name":"Soil_Dirt"},{"x":-8,"y":5,"z":1,"name":"Soil_Mud_Dry"},{"x":-8,"y":6,"z":1,"name":"Plant_Leaves_Jungle_Floor","support":15},{"x":-8,"y":37,"z":1,"name":"Plant_Leaves_Jungle"},{"x":-8,"y":39,"z":1,"name":"Plant_Leaves_Jungle"},{"x":-8,"y":40,"z":1,"name":"Plant_Leaves_Jungle"},{"x":-8,"y":41,"z":1,"name":"Plant_Leaves_Jungle"},{"x":-8,"y":42,"z":1,"name":"Plant_Leaves_Jungle","support":4},{"x":-8,"y":43,"z":1,"name":"Plant_Leaves_Jungle","support":3},{"x":-8,"y":44,"z":1,"name":"Plant_Leaves_Jungle","support":2},{"x":-8,"y":45,"z":1,"name":"Plant_Leaves_Jungle","support":3},{"x":-8,"y":0,"z":2,"name":"Soil_Dirt"},{"x":-8,"y":1,"z":2,"name":"Soil_Dirt"},{"x":-8,"y":2,"z":2,"name":"Soil_Dirt"},{"x":-8,"y":3,"z":2,"name":"Soil_Dirt"},{"x":-8,"y":4,"z":2,"name":"Soil_Dirt"},{"x":-8,"y":5,"z":2,"name":"Soil_Mud_Dry"},{"x":-8,"y":6,"z":2,"name":"Plant_Leaves_Jungle_Floor","support":15},{"x":-8,"y":40,"z":2,"name":"Plant_Leaves_Jungle"},{"x":-8,"y":41,"z":2,"name":"Plant_Leaves_Jungle"},{"x":-8,"y":42,"z":2,"name":"Plant_Leaves_Jungle","support":4},{"x":-8,"y":43,"z":2,"name":"Plant_Leaves_Jungle","support":3},{"x":-8,"y":44,"z":2,"name":"Plant_Leaves_Jungle","support":2},{"x":-8,"y":45,"z":2,"name":"Plant_Leaves_Jungle","support":3},{"x":-8,"y":0,"z":3,"name":"Soil_Dirt"},{"x":-8,"y":1,"z":3,"name":"Soil_Dirt"},{"x":-8,"y":2,"z":3,"name":"Soil_Dirt"},{"x":-8,"y":3,"z":3,"name":"Soil_Dirt"},{"x":-8,"y":4,"z":3,"name":"Soil_Dirt"},{"x":-8,"y":5,"z":3,"name":"Soil_Grass_Deep"},{"x":-8,"y":6,"z":3,"name":"Plant_Leaves_Jungle_Floor","support":15},{"x":-8,"y":36,"z":3,"name":"Plant_Leaves_Jungle"},{"x":-8,"y":38,"z":3,"name":"Plant_Leaves_Jungle"},{"x":-8,"y":40,"z":3,"name":"Plant_Leaves_Jungle"},{"x":-8,"y":41,"z":3,"name":"Plant_Leaves_Jungle"},{"x":-8,"y":42,"z":3,"name":"Plant_Leaves_Jungle","support":4},{"x":-8,"y":43,"z":3,"name":"Plant_Leaves_Jungle","support":3},{"x":-8,"y":44,"z":3,"name":"Plant_Leaves_Jungle","support":2},{"x":-8,"y":0,"z":4,"name":"Soil_Dirt"},{"x":-8,"y":1,"z":4,"name":"Soil_Dirt"},{"x":-8,"y":2,"z":4,"name":"Soil_Dirt"},{"x":-8,"y":3,"z":4,"name":"Soil_Dirt"},{"x":-8,"y":4,"z":4,"name":"Soil_Dirt"},{"x":-8,"y":5,"z":4,"name":"Soil_Grass_Deep"},{"x":-8,"y":40,"z":4,"name":"Plant_Leaves_Jungle"},{"x":-8,"y":41,"z":4,"name":"Plant_Leaves_Jungle"},{"x":-8,"y":42,"z":4,"name":"Plant_Leaves_Jungle","support":4},{"x":-8,"y":43,"z":4,"name":"Plant_Leaves_Jungle","support":3},{"x":-8,"y":44,"z":4,"name":"Plant_Leaves_Jungle","support":2},{"x":-8,"y":45,"z":4,"name":"Plant_Leaves_Jungle","support":3},{"x":-8,"y":0,"z":5,"name":"Soil_Dirt"},{"x":-8,"y":1,"z":5,"name":"Soil_Dirt"},{"x":-8,"y":2,"z":5,"name":"Soil_Dirt"},{"x":-8,"y":3,"z":5,"name":"Soil_Dirt"},{"x":-8,"y":4,"z":5,"name":"Soil_Dirt"},{"x":-8,"y":5,"z":5,"name":"Soil_Clay_Green"},{"x":-8,"y":40,"z":5,"name":"Plant_Leaves_Jungle"},{"x":-8,"y":41,"z":5,"name":"Plant_Leaves_Jungle"},{"x":-8,"y":42,"z":5,"name":"Plant_Leaves_Jungle","support":4},{"x":-8,"y":43,"z":5,"name":"Plant_Leaves_Jungle","support":3},{"x":-8,"y":44,"z":5,"name":"Plant_Leaves_Jungle","support":2},{"x":-8,"y":45,"z":5,"name":"Plant_Leaves_Jungle","support":3},{"x":-8,"y":0,"z":6,"name":"Soil_Dirt"},{"x":-8,"y":1,"z":6,"name":"Soil_Dirt"},{"x":-8,"y":2,"z":6,"name":"Soil_Dirt"},{"x":-8,"y":3,"z":6,"name":"Soil_Dirt"},{"x":-8,"y":4,"z":6,"name":"Soil_Dirt"},{"x":-8,"y":5,"z":6,"name":"Soil_Clay_Green"},{"x":-8,"y":40,"z":6,"name":"Plant_Leaves_Jungle"},{"x":-8,"y":41,"z":6,"name":"Plant_Leaves_Jungle"},{"x":-8,"y":42,"z":6,"name":"Plant_Leaves_Jungle"},{"x":-8,"y":43,"z":6,"name":"Plant_Leaves_Jungle","support":4},{"x":-8,"y":44,"z":6,"name":"Plant_Leaves_Jungle","support":3},{"x":-8,"y":45,"z":6,"name":"Plant_Leaves_Jungle","support":4},{"x":-8,"y":0,"z":7,"name":"Soil_Dirt"},{"x":-8,"y":1,"z":7,"name":"Soil_Dirt"},{"x":-8,"y":2,"z":7,"name":"Soil_Dirt"},{"x":-8,"y":3,"z":7,"name":"Soil_Dirt"},{"x":-8,"y":4,"z":7,"name":"Soil_Dirt"},{"x":-8,"y":5,"z":7,"name":"Soil_Clay_Green"},{"x":-8,"y":40,"z":7,"name":"Plant_Leaves_Jungle"},{"x":-8,"y":41,"z":7,"name":"Plant_Leaves_Jungle"},{"x":-8,"y":42,"z":7,"name":"Plant_Leaves_Jungle"},{"x":-8,"y":43,"z":7,"name":"Plant_Leaves_Jungle"},{"x":-8,"y":44,"z":7,"name":"Plant_Leaves_Jungle","support":4},{"x":-8,"y":0,"z":8,"name":"Soil_Dirt"},{"x":-8,"y":1,"z":8,"name":"Soil_Dirt"},{"x":-8,"y":2,"z":8,"name":"Soil_Dirt"},{"x":-8,"y":3,"z":8,"name":"Soil_Dirt"},{"x":-8,"y":4,"z":8,"name":"Soil_Dirt"},{"x":-8,"y":5,"z":8,"name":"Soil_Grass_Deep"},{"x":-8,"y":6,"z":8,"name":"Plant_Leaves_Jungle_Floor","support":15},{"x":-8,"y":41,"z":8,"name":"Plant_Leaves_Jungle"},{"x":-8,"y":42,"z":8,"name":"Plant_Leaves_Jungle"},{"x":-8,"y":43,"z":8,"name":"Plant_Leaves_Jungle"},{"x":-8,"y":0,"z":9,"name":"Soil_Dirt"},{"x":-8,"y":1,"z":9,"name":"Soil_Dirt"},{"x":-8,"y":2,"z":9,"name":"Soil_Dirt"},{"x":-8,"y":3,"z":9,"name":"Soil_Dirt"},{"x":-8,"y":4,"z":9,"name":"Soil_Dirt"},{"x":-8,"y":5,"z":9,"name":"Soil_Mud_Dry"},{"x":-8,"y":6,"z":9,"name":"Plant_Leaves_Jungle_Floor","support":15},{"x":-8,"y":40,"z":9,"name":"Plant_Leaves_Jungle"},{"x":-8,"y":0,"z":10,"name":"Soil_Dirt"},{"x":-8,"y":1,"z":10,"name":"Soil_Dirt"},{"x":-8,"y":2,"z":10,"name":"Soil_Dirt"},{"x":-8,"y":3,"z":10,"name":"Soil_Dirt"},{"x":-8,"y":4,"z":10,"name":"Soil_Dirt"},{"x":-8,"y":5,"z":10,"name":"Soil_Mud_Dry"},{"x":-8,"y":0,"z":11,"name":"Soil_Dirt"},{"x":-8,"y":1,"z":11,"name":"Soil_Dirt"},{"x":-8,"y":2,"z":11,"name":"Soil_Dirt"},{"x":-8,"y":3,"z":11,"name":"Soil_Dirt"},{"x":-8,"y":4,"z":11,"name":"Soil_Dirt"},{"x":-8,"y":5,"z":11,"name":"Soil_Grass_Deep"},{"x":-8,"y":0,"z":12,"name":"Soil_Dirt"},{"x":-8,"y":1,"z":12,"name":"Soil_Dirt"},{"x":-8,"y":2,"z":12,"name":"Soil_Dirt"},{"x":-8,"y":3,"z":12,"name":"Soil_Dirt"},{"x":-8,"y":4,"z":12,"name":"Soil_Dirt"},{"x":-8,"y":5,"z":12,"name":"Rock_Stone_Cobble"},{"x":-8,"y":0,"z":13,"name":"Soil_Dirt"},{"x":-8,"y":1,"z":13,"name":"Soil_Dirt"},{"x":-8,"y":2,"z":13,"name":"Soil_Dirt"},{"x":-8,"y":3,"z":13,"name":"Soil_Dirt"},{"x":-8,"y":4,"z":13,"name":"Soil_Dirt"},{"x":-8,"y":5,"z":13,"name":"Rock_Stone_Cobble"},{"x":-8,"y":0,"z":14,"name":"Soil_Dirt"},{"x":-8,"y":1,"z":14,"name":"Soil_Dirt"},{"x":-8,"y":2,"z":14,"name":"Soil_Dirt"},{"x":-8,"y":3,"z":14,"name":"Soil_Dirt"},{"x":-8,"y":4,"z":14,"name":"Soil_Dirt"},{"x":-8,"y":5,"z":14,"name":"Rock_Stone_Cobble"},{"x":-8,"y":0,"z":15,"name":"Soil_Dirt"},{"x":-8,"y":1,"z":15,"name":"Soil_Dirt"},{"x":-8,"y":2,"z":15,"name":"Soil_Dirt"},{"x":-8,"y":3,"z":15,"name":"Soil_Dirt"},{"x":-8,"y":4,"z":15,"name":"Soil_Dirt"},{"x":-8,"y":5,"z":15,"name":"Rock_Stone_Brick_Smooth"},{"x":-7,"y":0,"z":-14,"name":"Soil_Dirt"},{"x":-7,"y":1,"z":-14,"name":"Soil_Dirt"},{"x":-7,"y":2,"z":-14,"name":"Soil_Dirt"},{"x":-7,"y":3,"z":-14,"name":"Soil_Dirt"},{"x":-7,"y":4,"z":-14,"name":"Soil_Dirt"},{"x":-7,"y":5,"z":-14,"name":"Rock_Stone_Brick_Smooth"},{"x":-7,"y":0,"z":-13,"name":"Soil_Dirt"},{"x":-7,"y":1,"z":-13,"name":"Soil_Dirt"},{"x":-7,"y":2,"z":-13,"name":"Soil_Dirt"},{"x":-7,"y":3,"z":-13,"name":"Soil_Dirt"},{"x":-7,"y":4,"z":-13,"name":"Soil_Dirt"},{"x":-7,"y":5,"z":-13,"name":"Rock_Stone_Cobble"},{"x":-7,"y":0,"z":-12,"name":"Soil_Dirt"},{"x":-7,"y":1,"z":-12,"name":"Soil_Dirt"},{"x":-7,"y":2,"z":-12,"name":"Soil_Dirt"},{"x":-7,"y":3,"z":-12,"name":"Soil_Dirt"},{"x":-7,"y":4,"z":-12,"name":"Soil_Dirt"},{"x":-7,"y":5,"z":-12,"name":"Rock_Stone_Cobble_Mossy"},{"x":-7,"y":0,"z":-11,"name":"Soil_Dirt"},{"x":-7,"y":1,"z":-11,"name":"Soil_Dirt"},{"x":-7,"y":2,"z":-11,"name":"Soil_Dirt"},{"x":-7,"y":3,"z":-11,"name":"Soil_Dirt"},{"x":-7,"y":4,"z":-11,"name":"Soil_Dirt"},{"x":-7,"y":5,"z":-11,"name":"Rock_Stone_Cobble"},{"x":-7,"y":0,"z":-10,"name":"Soil_Dirt"},{"x":-7,"y":1,"z":-10,"name":"Soil_Dirt"},{"x":-7,"y":2,"z":-10,"name":"Soil_Dirt"},{"x":-7,"y":3,"z":-10,"name":"Soil_Dirt"},{"x":-7,"y":4,"z":-10,"name":"Soil_Dirt"},{"x":-7,"y":5,"z":-10,"name":"Rock_Stone_Cobble"},{"x":-7,"y":33,"z":-10,"name":"Plant_Leaves_Jungle"},{"x":-7,"y":0,"z":-9,"name":"Soil_Dirt"},{"x":-7,"y":1,"z":-9,"name":"Soil_Dirt"},{"x":-7,"y":2,"z":-9,"name":"Soil_Dirt"},{"x":-7,"y":3,"z":-9,"name":"Soil_Dirt"},{"x":-7,"y":4,"z":-9,"name":"Soil_Dirt"},{"x":-7,"y":5,"z":-9,"name":"Soil_Grass_Deep"},{"x":-7,"y":32,"z":-9,"name":"Plant_Leaves_Jungle"},{"x":-7,"y":33,"z":-9,"name":"Plant_Leaves_Jungle"},{"x":-7,"y":34,"z":-9,"name":"Plant_Leaves_Jungle"},{"x":-7,"y":36,"z":-9,"name":"Plant_Leaves_Jungle"},{"x":-7,"y":40,"z":-9,"name":"Plant_Leaves_Jungle"},{"x":-7,"y":41,"z":-9,"name":"Plant_Leaves_Jungle"},{"x":-7,"y":42,"z":-9,"name":"Plant_Leaves_Jungle"},{"x":-7,"y":0,"z":-8,"name":"Soil_Dirt"},{"x":-7,"y":1,"z":-8,"name":"Soil_Dirt"},{"x":-7,"y":2,"z":-8,"name":"Soil_Dirt"},{"x":-7,"y":3,"z":-8,"name":"Soil_Dirt"},{"x":-7,"y":4,"z":-8,"name":"Soil_Dirt"},{"x":-7,"y":5,"z":-8,"name":"Soil_Grass_Sunny"},{"x":-7,"y":33,"z":-8,"name":"Plant_Leaves_Jungle"},{"x":-7,"y":34,"z":-8,"name":"Plant_Leaves_Jungle"},{"x":-7,"y":35,"z":-8,"name":"Plant_Leaves_Jungle"},{"x":-7,"y":36,"z":-8,"name":"Plant_Leaves_Jungle"},{"x":-7,"y":37,"z":-8,"name":"Plant_Leaves_Jungle"},{"x":-7,"y":40,"z":-8,"name":"Plant_Leaves_Jungle"},{"x":-7,"y":41,"z":-8,"name":"Plant_Leaves_Jungle"},{"x":-7,"y":42,"z":-8,"name":"Plant_Leaves_Jungle"},{"x":-7,"y":0,"z":-7,"name":"Soil_Dirt"},{"x":-7,"y":1,"z":-7,"name":"Soil_Dirt"},{"x":-7,"y":2,"z":-7,"name":"Soil_Dirt"},{"x":-7,"y":3,"z":-7,"name":"Soil_Dirt"},{"x":-7,"y":4,"z":-7,"name":"Soil_Dirt"},{"x":-7,"y":5,"z":-7,"name":"Soil_Grass_Deep"},{"x":-7,"y":34,"z":-7,"name":"Plant_Leaves_Jungle"},{"x":-7,"y":36,"z":-7,"name":"Plant_Leaves_Jungle"},{"x":-7,"y":37,"z":-7,"name":"Plant_Leaves_Jungle"},{"x":-7,"y":38,"z":-7,"name":"Plant_Leaves_Jungle"},{"x":-7,"y":39,"z":-7,"name":"Plant_Leaves_Jungle","support":4},{"x":-7,"y":40,"z":-7,"name":"Plant_Leaves_Jungle"},{"x":-7,"y":41,"z":-7,"name":"Plant_Leaves_Jungle"},{"x":-7,"y":42,"z":-7,"name":"Plant_Leaves_Jungle"},{"x":-7,"y":43,"z":-7,"name":"Plant_Leaves_Jungle"},{"x":-7,"y":0,"z":-6,"name":"Soil_Dirt"},{"x":-7,"y":1,"z":-6,"name":"Soil_Dirt"},{"x":-7,"y":2,"z":-6,"name":"Soil_Dirt"},{"x":-7,"y":3,"z":-6,"name":"Soil_Dirt"},{"x":-7,"y":4,"z":-6,"name":"Soil_Dirt"},{"x":-7,"y":5,"z":-6,"name":"Soil_Grass_Deep"},{"x":-7,"y":6,"z":-6,"name":"Plant_Leaves_Jungle_Floor","support":15},{"x":-7,"y":37,"z":-6,"name":"Plant_Leaves_Jungle"},{"x":-7,"y":38,"z":-6,"name":"Plant_Leaves_Jungle"},{"x":-7,"y":39,"z":-6,"name":"Plant_Leaves_Jungle","support":4},{"x":-7,"y":40,"z":-6,"name":"Plant_Leaves_Jungle"},{"x":-7,"y":41,"z":-6,"name":"Plant_Leaves_Jungle"},{"x":-7,"y":42,"z":-6,"name":"Plant_Leaves_Jungle"},{"x":-7,"y":43,"z":-6,"name":"Plant_Leaves_Jungle"},{"x":-7,"y":0,"z":-5,"name":"Soil_Dirt"},{"x":-7,"y":1,"z":-5,"name":"Soil_Dirt"},{"x":-7,"y":2,"z":-5,"name":"Soil_Dirt"},{"x":-7,"y":3,"z":-5,"name":"Soil_Dirt"},{"x":-7,"y":4,"z":-5,"name":"Soil_Dirt"},{"x":-7,"y":5,"z":-5,"name":"Soil_Grass_Deep"},{"x":-7,"y":20,"z":-5,"name":"Wood_Jungle_Trunk_Full","support":1},{"x":-7,"y":38,"z":-5,"name":"Plant_Leaves_Jungle"},{"x":-7,"y":39,"z":-5,"name":"Plant_Leaves_Jungle","support":4},{"x":-7,"y":40,"z":-5,"name":"Plant_Leaves_Jungle"},{"x":-7,"y":41,"z":-5,"name":"Plant_Leaves_Jungle"},{"x":-7,"y":42,"z":-5,"name":"Plant_Leaves_Jungle"},{"x":-7,"y":43,"z":-5,"name":"Plant_Leaves_Jungle"},{"x":-7,"y":44,"z":-5,"name":"Plant_Leaves_Jungle"},{"x":-7,"y":0,"z":-4,"name":"Soil_Dirt"},{"x":-7,"y":1,"z":-4,"name":"Soil_Dirt"},{"x":-7,"y":2,"z":-4,"name":"Soil_Dirt"},{"x":-7,"y":3,"z":-4,"name":"Soil_Dirt"},{"x":-7,"y":4,"z":-4,"name":"Soil_Dirt"},{"x":-7,"y":5,"z":-4,"name":"Soil_Grass_Deep"},{"x":-7,"y":19,"z":-4,"name":"Wood_Jungle_Trunk_Full","support":1},{"x":-7,"y":20,"z":-4,"name":"Wood_Jungle_Trunk_Full"},{"x":-7,"y":21,"z":-4,"name":"Wood_Jungle_Trunk_Full"},{"x":-7,"y":22,"z":-4,"name":"Plant_Vine_Jungle","support":15,"rotation":2},{"x":-7,"y":39,"z":-4,"name":"Plant_Leaves_Jungle","support":4},{"x":-7,"y":40,"z":-4,"name":"Plant_Leaves_Jungle"},{"x":-7,"y":41,"z":-4,"name":"Plant_Leaves_Jungle"},{"x":-7,"y":42,"z":-4,"name":"Plant_Leaves_Jungle"},{"x":-7,"y":43,"z":-4,"name":"Plant_Leaves_Jungle"},{"x":-7,"y":44,"z":-4,"name":"Plant_Leaves_Jungle"},{"x":-7,"y":0,"z":-3,"name":"Soil_Dirt"},{"x":-7,"y":1,"z":-3,"name":"Soil_Dirt"},{"x":-7,"y":2,"z":-3,"name":"Soil_Dirt"},{"x":-7,"y":3,"z":-3,"name":"Soil_Dirt"},{"x":-7,"y":4,"z":-3,"name":"Soil_Dirt"},{"x":-7,"y":5,"z":-3,"name":"Soil_Grass_Deep"},{"x":-7,"y":8,"z":-3,"name":"Cloth_Modern_DarkGreen_Roof_Vertical_Flap","rotation":3},{"x":-7,"y":19,"z":-3,"name":"Wood_Jungle_Trunk_Full","support":2},{"x":-7,"y":20,"z":-3,"name":"Wood_Jungle_Trunk_Full"},{"x":-7,"y":21,"z":-3,"name":"Wood_Jungle_Trunk_Full"},{"x":-7,"y":22,"z":-3,"name":"Wood_Jungle_Trunk_Full"},{"x":-7,"y":39,"z":-3,"name":"Plant_Leaves_Jungle","support":4},{"x":-7,"y":40,"z":-3,"name":"Plant_Leaves_Jungle"},{"x":-7,"y":41,"z":-3,"name":"Plant_Leaves_Jungle"},{"x":-7,"y":42,"z":-3,"name":"Plant_Leaves_Jungle"},{"x":-7,"y":43,"z":-3,"name":"Plant_Leaves_Jungle"},{"x":-7,"y":44,"z":-3,"name":"Plant_Leaves_Jungle"},{"x":-7,"y":0,"z":-2,"name":"Soil_Dirt"},{"x":-7,"y":1,"z":-2,"name":"Soil_Dirt"},{"x":-7,"y":2,"z":-2,"name":"Soil_Dirt"},{"x":-7,"y":3,"z":-2,"name":"Soil_Dirt"},{"x":-7,"y":4,"z":-2,"name":"Soil_Dirt"},{"x":-7,"y":5,"z":-2,"name":"Soil_Grass_Sunny"},{"x":-7,"y":6,"z":-2,"name":"Wood_Sticks","support":15},{"x":-7,"y":8,"z":-2,"name":"Cloth_Modern_DarkGreen_Roof_Vertical_Flap","rotation":3},{"x":-7,"y":19,"z":-2,"name":"Wood_Jungle_Trunk_Full","support":2},{"x":-7,"y":20,"z":-2,"name":"Wood_Jungle_Trunk_Full"},{"x":-7,"y":21,"z":-2,"name":"Wood_Jungle_Trunk_Full"},{"x":-7,"y":22,"z":-2,"name":"Plant_Vine_Jungle","support":15,"rotation":3},{"x":-7,"y":39,"z":-2,"name":"Plant_Leaves_Jungle","support":4},{"x":-7,"y":40,"z":-2,"name":"Plant_Leaves_Jungle"},{"x":-7,"y":41,"z":-2,"name":"Plant_Leaves_Jungle"},{"x":-7,"y":42,"z":-2,"name":"Plant_Leaves_Jungle"},{"x":-7,"y":43,"z":-2,"name":"Plant_Leaves_Jungle"},{"x":-7,"y":44,"z":-2,"name":"Plant_Leaves_Jungle","support":4},{"x":-7,"y":0,"z":-1,"name":"Soil_Dirt"},{"x":-7,"y":1,"z":-1,"name":"Soil_Dirt"},{"x":-7,"y":2,"z":-1,"name":"Soil_Dirt"},{"x":-7,"y":3,"z":-1,"name":"Soil_Dirt"},{"x":-7,"y":4,"z":-1,"name":"Soil_Dirt"},{"x":-7,"y":5,"z":-1,"name":"Soil_Grass_Deep"},{"x":-7,"y":8,"z":-1,"name":"Cloth_Modern_DarkGreen_Roof_Vertical_Flap","rotation":3},{"x":-7,"y":19,"z":-1,"name":"Wood_Jungle_Trunk_Full","support":3},{"x":-7,"y":20,"z":-1,"name":"Wood_Jungle_Trunk_Full"},{"x":-7,"y":21,"z":-1,"name":"Wood_Jungle_Trunk_Full"},{"x":-7,"y":39,"z":-1,"name":"Plant_Leaves_Jungle"},{"x":-7,"y":40,"z":-1,"name":"Plant_Leaves_Jungle"},{"x":-7,"y":41,"z":-1,"name":"Plant_Leaves_Jungle"},{"x":-7,"y":42,"z":-1,"name":"Plant_Leaves_Jungle"},{"x":-7,"y":43,"z":-1,"name":"Plant_Leaves_Jungle","support":4},{"x":-7,"y":0,"z":0,"name":"Soil_Dirt"},{"x":-7,"y":1,"z":0,"name":"Soil_Dirt"},{"x":-7,"y":2,"z":0,"name":"Soil_Dirt"},{"x":-7,"y":3,"z":0,"name":"Soil_Dirt"},{"x":-7,"y":4,"z":0,"name":"Soil_Dirt"},{"x":-7,"y":5,"z":0,"name":"Soil_Grass_Sunny"},{"x":-7,"y":8,"z":0,"name":"Cloth_Modern_DarkGreen_Roof_Vertical_Flap","rotation":3},{"x":-7,"y":19,"z":0,"name":"Wood_Jungle_Trunk_Full","support":4},{"x":-7,"y":20,"z":0,"name":"Wood_Jungle_Trunk_Full"},{"x":-7,"y":21,"z":0,"name":"Wood_Jungle_Trunk_Full"},{"x":-7,"y":39,"z":0,"name":"Plant_Leaves_Jungle"},{"x":-7,"y":40,"z":0,"name":"Plant_Leaves_Jungle"},{"x":-7,"y":41,"z":0,"name":"Plant_Leaves_Jungle"},{"x":-7,"y":42,"z":0,"name":"Plant_Leaves_Jungle","support":4},{"x":-7,"y":43,"z":0,"name":"Plant_Leaves_Jungle","support":3},{"x":-7,"y":44,"z":0,"name":"Plant_Leaves_Jungle","support":2},{"x":-7,"y":0,"z":1,"name":"Soil_Dirt"},{"x":-7,"y":1,"z":1,"name":"Soil_Dirt"},{"x":-7,"y":2,"z":1,"name":"Soil_Dirt"},{"x":-7,"y":3,"z":1,"name":"Soil_Dirt"},{"x":-7,"y":4,"z":1,"name":"Soil_Dirt"},{"x":-7,"y":5,"z":1,"name":"Soil_Grass_Deep"},{"x":-7,"y":8,"z":1,"name":"Cloth_Modern_DarkGreen_Roof_Vertical_Flap","rotation":3},{"x":-7,"y":20,"z":1,"name":"Wood_Jungle_Trunk_Full","support":1},{"x":-7,"y":21,"z":1,"name":"Plant_Crop_Mushroom_Block_Green"},{"x":-7,"y":39,"z":1,"name":"Plant_Leaves_Jungle"},{"x":-7,"y":40,"z":1,"name":"Plant_Leaves_Jungle"},{"x":-7,"y":41,"z":1,"name":"Plant_Leaves_Jungle","support":4},{"x":-7,"y":42,"z":1,"name":"Plant_Leaves_Jungle","support":3},{"x":-7,"y":43,"z":1,"name":"Plant_Leaves_Jungle","support":2},{"x":-7,"y":44,"z":1,"name":"Plant_Leaves_Jungle","support":1},{"x":-7,"y":0,"z":2,"name":"Soil_Dirt"},{"x":-7,"y":1,"z":2,"name":"Soil_Dirt"},{"x":-7,"y":2,"z":2,"name":"Soil_Dirt"},{"x":-7,"y":3,"z":2,"name":"Soil_Dirt"},{"x":-7,"y":4,"z":2,"name":"Soil_Dirt"},{"x":-7,"y":5,"z":2,"name":"Soil_Mud_Dry"},{"x":-7,"y":6,"z":2,"name":"Plant_Leaves_Jungle_Floor","support":15},{"x":-7,"y":20,"z":2,"name":"Plant_Crop_Mushroom_Block_Green_Mycelium","rotation":8},{"x":-7,"y":21,"z":2,"name":"Plant_Crop_Mushroom_Block_Green"},{"x":-7,"y":39,"z":2,"name":"Plant_Leaves_Jungle"},{"x":-7,"y":40,"z":2,"name":"Plant_Leaves_Jungle"},{"x":-7,"y":41,"z":2,"name":"Plant_Leaves_Jungle","support":4},{"x":-7,"y":42,"z":2,"name":"Plant_Leaves_Jungle","support":3},{"x":-7,"y":43,"z":2,"name":"Plant_Leaves_Jungle","support":2},{"x":-7,"y":44,"z":2,"name":"Plant_Leaves_Jungle","support":1},{"x":-7,"y":0,"z":3,"name":"Soil_Dirt"},{"x":-7,"y":1,"z":3,"name":"Soil_Dirt"},{"x":-7,"y":2,"z":3,"name":"Soil_Dirt"},{"x":-7,"y":3,"z":3,"name":"Soil_Dirt"},{"x":-7,"y":4,"z":3,"name":"Soil_Dirt"},{"x":-7,"y":5,"z":3,"name":"Soil_Grass_Deep"},{"x":-7,"y":6,"z":3,"name":"Plant_Leaves_Jungle_Floor","support":15},{"x":-7,"y":20,"z":3,"name":"Plant_Crop_Mushroom_Block_Green_Mycelium","rotation":8},{"x":-7,"y":21,"z":3,"name":"Plant_Crop_Mushroom_Block_Green"},{"x":-7,"y":40,"z":3,"name":"Plant_Leaves_Jungle"},{"x":-7,"y":41,"z":3,"name":"Plant_Leaves_Jungle","support":4},{"x":-7,"y":42,"z":3,"name":"Plant_Leaves_Jungle","support":3},{"x":-7,"y":43,"z":3,"name":"Plant_Leaves_Jungle","support":2},{"x":-7,"y":44,"z":3,"name":"Plant_Leaves_Jungle","support":1},{"x":-7,"y":0,"z":4,"name":"Soil_Dirt"},{"x":-7,"y":1,"z":4,"name":"Soil_Dirt"},{"x":-7,"y":2,"z":4,"name":"Soil_Dirt"},{"x":-7,"y":3,"z":4,"name":"Soil_Dirt"},{"x":-7,"y":4,"z":4,"name":"Soil_Dirt"},{"x":-7,"y":5,"z":4,"name":"Soil_Grass_Deep"},{"x":-7,"y":40,"z":4,"name":"Plant_Leaves_Jungle"},{"x":-7,"y":41,"z":4,"name":"Plant_Leaves_Jungle","support":4},{"x":-7,"y":42,"z":4,"name":"Plant_Leaves_Jungle","support":3},{"x":-7,"y":43,"z":4,"name":"Plant_Leaves_Jungle","support":2},{"x":-7,"y":44,"z":4,"name":"Plant_Leaves_Jungle","support":1},{"x":-7,"y":0,"z":5,"name":"Soil_Dirt"},{"x":-7,"y":1,"z":5,"name":"Soil_Dirt"},{"x":-7,"y":2,"z":5,"name":"Soil_Dirt"},{"x":-7,"y":3,"z":5,"name":"Soil_Dirt"},{"x":-7,"y":4,"z":5,"name":"Soil_Dirt"},{"x":-7,"y":5,"z":5,"name":"Soil_Clay_Green"},{"x":-7,"y":40,"z":5,"name":"Plant_Leaves_Jungle"},{"x":-7,"y":41,"z":5,"name":"Plant_Leaves_Jungle","support":4},{"x":-7,"y":42,"z":5,"name":"Plant_Leaves_Jungle","support":3},{"x":-7,"y":43,"z":5,"name":"Plant_Leaves_Jungle","support":2},{"x":-7,"y":44,"z":5,"name":"Plant_Leaves_Jungle","support":1},{"x":-7,"y":45,"z":5,"name":"Plant_Leaves_Jungle","support":2},{"x":-7,"y":0,"z":6,"name":"Soil_Dirt"},{"x":-7,"y":1,"z":6,"name":"Soil_Dirt"},{"x":-7,"y":2,"z":6,"name":"Soil_Dirt"},{"x":-7,"y":3,"z":6,"name":"Soil_Dirt"},{"x":-7,"y":4,"z":6,"name":"Soil_Dirt"},{"x":-7,"y":5,"z":6,"name":"Rock_Crystal_Green_Block"},{"x":-7,"y":40,"z":6,"name":"Plant_Leaves_Jungle"},{"x":-7,"y":41,"z":6,"name":"Plant_Leaves_Jungle"},{"x":-7,"y":42,"z":6,"name":"Plant_Leaves_Jungle","support":4},{"x":-7,"y":43,"z":6,"name":"Plant_Leaves_Jungle","support":3},{"x":-7,"y":44,"z":6,"name":"Plant_Leaves_Jungle","support":2},{"x":-7,"y":45,"z":6,"name":"Plant_Leaves_Jungle","support":3},{"x":-7,"y":0,"z":7,"name":"Soil_Dirt"},{"x":-7,"y":1,"z":7,"name":"Soil_Dirt"},{"x":-7,"y":2,"z":7,"name":"Soil_Dirt"},{"x":-7,"y":3,"z":7,"name":"Soil_Dirt"},{"x":-7,"y":4,"z":7,"name":"Soil_Dirt"},{"x":-7,"y":5,"z":7,"name":"Soil_Clay_Green"},{"x":-7,"y":40,"z":7,"name":"Plant_Leaves_Jungle"},{"x":-7,"y":41,"z":7,"name":"Plant_Leaves_Jungle"},{"x":-7,"y":42,"z":7,"name":"Plant_Leaves_Jungle"},{"x":-7,"y":43,"z":7,"name":"Plant_Leaves_Jungle","support":4},{"x":-7,"y":44,"z":7,"name":"Plant_Leaves_Jungle","support":3},{"x":-7,"y":45,"z":7,"name":"Plant_Leaves_Jungle","support":4},{"x":-7,"y":0,"z":8,"name":"Soil_Dirt"},{"x":-7,"y":1,"z":8,"name":"Soil_Dirt"},{"x":-7,"y":2,"z":8,"name":"Soil_Dirt"},{"x":-7,"y":3,"z":8,"name":"Soil_Dirt"},{"x":-7,"y":4,"z":8,"name":"Soil_Dirt"},{"x":-7,"y":5,"z":8,"name":"Soil_Mud_Dry"},{"x":-7,"y":40,"z":8,"name":"Plant_Leaves_Jungle"},{"x":-7,"y":41,"z":8,"name":"Plant_Leaves_Jungle"},{"x":-7,"y":42,"z":8,"name":"Plant_Leaves_Jungle"},{"x":-7,"y":43,"z":8,"name":"Plant_Leaves_Jungle"},{"x":-7,"y":44,"z":8,"name":"Plant_Leaves_Jungle","support":4},{"x":-7,"y":0,"z":9,"name":"Soil_Dirt"},{"x":-7,"y":1,"z":9,"name":"Soil_Dirt"},{"x":-7,"y":2,"z":9,"name":"Soil_Dirt"},{"x":-7,"y":3,"z":9,"name":"Soil_Dirt"},{"x":-7,"y":4,"z":9,"name":"Soil_Dirt"},{"x":-7,"y":5,"z":9,"name":"Soil_Grass_Deep"},{"x":-7,"y":6,"z":9,"name":"Plant_Leaves_Jungle_Floor","support":15},{"x":-7,"y":39,"z":9,"name":"Plant_Leaves_Jungle"},{"x":-7,"y":40,"z":9,"name":"Plant_Leaves_Jungle"},{"x":-7,"y":41,"z":9,"name":"Plant_Leaves_Jungle"},{"x":-7,"y":42,"z":9,"name":"Plant_Leaves_Jungle"},{"x":-7,"y":43,"z":9,"name":"Plant_Leaves_Jungle"},{"x":-7,"y":0,"z":10,"name":"Soil_Dirt"},{"x":-7,"y":1,"z":10,"name":"Soil_Dirt"},{"x":-7,"y":2,"z":10,"name":"Soil_Dirt"},{"x":-7,"y":3,"z":10,"name":"Soil_Dirt"},{"x":-7,"y":4,"z":10,"name":"Soil_Dirt"},{"x":-7,"y":5,"z":10,"name":"Soil_Grass_Deep"},{"x":-7,"y":37,"z":10,"name":"Plant_Leaves_Jungle"},{"x":-7,"y":40,"z":10,"name":"Plant_Leaves_Jungle"},{"x":-7,"y":41,"z":10,"name":"Plant_Leaves_Jungle"},{"x":-7,"y":42,"z":10,"name":"Plant_Leaves_Jungle"},{"x":-7,"y":43,"z":10,"name":"Plant_Leaves_Jungle"},{"x":-7,"y":0,"z":11,"name":"Soil_Dirt"},{"x":-7,"y":1,"z":11,"name":"Soil_Dirt"},{"x":-7,"y":2,"z":11,"name":"Soil_Dirt"},{"x":-7,"y":3,"z":11,"name":"Soil_Dirt"},{"x":-7,"y":4,"z":11,"name":"Soil_Dirt"},{"x":-7,"y":5,"z":11,"name":"Soil_Grass_Deep"},{"x":-7,"y":0,"z":12,"name":"Soil_Dirt"},{"x":-7,"y":1,"z":12,"name":"Soil_Dirt"},{"x":-7,"y":2,"z":12,"name":"Soil_Dirt"},{"x":-7,"y":3,"z":12,"name":"Soil_Dirt"},{"x":-7,"y":4,"z":12,"name":"Soil_Dirt"},{"x":-7,"y":5,"z":12,"name":"Rock_Stone_Cobble"},{"x":-7,"y":0,"z":13,"name":"Soil_Dirt"},{"x":-7,"y":1,"z":13,"name":"Soil_Dirt"},{"x":-7,"y":2,"z":13,"name":"Soil_Dirt"},{"x":-7,"y":3,"z":13,"name":"Soil_Dirt"},{"x":-7,"y":4,"z":13,"name":"Soil_Dirt"},{"x":-7,"y":5,"z":13,"name":"Rock_Stone_Cobble"},{"x":-7,"y":0,"z":14,"name":"Soil_Dirt"},{"x":-7,"y":1,"z":14,"name":"Soil_Dirt"},{"x":-7,"y":2,"z":14,"name":"Soil_Dirt"},{"x":-7,"y":3,"z":14,"name":"Soil_Dirt"},{"x":-7,"y":4,"z":14,"name":"Soil_Dirt"},{"x":-7,"y":5,"z":14,"name":"Rock_Stone_Cobble_Mossy"},{"x":-7,"y":0,"z":15,"name":"Soil_Dirt"},{"x":-7,"y":1,"z":15,"name":"Soil_Dirt"},{"x":-7,"y":2,"z":15,"name":"Soil_Dirt"},{"x":-7,"y":3,"z":15,"name":"Soil_Dirt"},{"x":-7,"y":4,"z":15,"name":"Soil_Dirt"},{"x":-7,"y":5,"z":15,"name":"Rock_Stone_Brick_Smooth"},{"x":-6,"y":0,"z":-14,"name":"Soil_Dirt"},{"x":-6,"y":1,"z":-14,"name":"Soil_Dirt"},{"x":-6,"y":2,"z":-14,"name":"Soil_Dirt"},{"x":-6,"y":3,"z":-14,"name":"Soil_Dirt"},{"x":-6,"y":4,"z":-14,"name":"Soil_Dirt"},{"x":-6,"y":5,"z":-14,"name":"Rock_Stone_Brick_Smooth"},{"x":-6,"y":0,"z":-13,"name":"Soil_Dirt"},{"x":-6,"y":1,"z":-13,"name":"Soil_Dirt"},{"x":-6,"y":2,"z":-13,"name":"Soil_Dirt"},{"x":-6,"y":3,"z":-13,"name":"Soil_Dirt"},{"x":-6,"y":4,"z":-13,"name":"Soil_Dirt"},{"x":-6,"y":5,"z":-13,"name":"Rock_Stone_Cobble"},{"x":-6,"y":0,"z":-12,"name":"Soil_Dirt"},{"x":-6,"y":1,"z":-12,"name":"Soil_Dirt"},{"x":-6,"y":2,"z":-12,"name":"Soil_Dirt"},{"x":-6,"y":3,"z":-12,"name":"Soil_Dirt"},{"x":-6,"y":4,"z":-12,"name":"Soil_Dirt"},{"x":-6,"y":5,"z":-12,"name":"Rock_Stone_Cobble"},{"x":-6,"y":0,"z":-11,"name":"Soil_Dirt"},{"x":-6,"y":1,"z":-11,"name":"Soil_Dirt"},{"x":-6,"y":2,"z":-11,"name":"Soil_Dirt"},{"x":-6,"y":3,"z":-11,"name":"Soil_Dirt"},{"x":-6,"y":4,"z":-11,"name":"Soil_Dirt"},{"x":-6,"y":5,"z":-11,"name":"Rock_Stone_Cobble"},{"x":-6,"y":0,"z":-10,"name":"Soil_Dirt"},{"x":-6,"y":1,"z":-10,"name":"Soil_Dirt"},{"x":-6,"y":2,"z":-10,"name":"Soil_Dirt"},{"x":-6,"y":3,"z":-10,"name":"Soil_Dirt"},{"x":-6,"y":4,"z":-10,"name":"Soil_Dirt"},{"x":-6,"y":5,"z":-10,"name":"Soil_Grass_Deep"},{"x":-6,"y":34,"z":-10,"name":"Plant_Leaves_Jungle"},{"x":-6,"y":0,"z":-9,"name":"Soil_Dirt"},{"x":-6,"y":1,"z":-9,"name":"Soil_Dirt"},{"x":-6,"y":2,"z":-9,"name":"Soil_Dirt"},{"x":-6,"y":3,"z":-9,"name":"Soil_Dirt"},{"x":-6,"y":4,"z":-9,"name":"Soil_Dirt"},{"x":-6,"y":5,"z":-9,"name":"Soil_Grass_Deep"},{"x":-6,"y":33,"z":-9,"name":"Plant_Leaves_Jungle"},{"x":-6,"y":34,"z":-9,"name":"Plant_Leaves_Jungle"},{"x":-6,"y":35,"z":-9,"name":"Plant_Leaves_Jungle"},{"x":-6,"y":37,"z":-9,"name":"Plant_Leaves_Jungle"},{"x":-6,"y":40,"z":-9,"name":"Plant_Leaves_Jungle"},{"x":-6,"y":41,"z":-9,"name":"Plant_Leaves_Jungle"},{"x":-6,"y":42,"z":-9,"name":"Plant_Leaves_Jungle"},{"x":-6,"y":0,"z":-8,"name":"Soil_Dirt"},{"x":-6,"y":1,"z":-8,"name":"Soil_Dirt"},{"x":-6,"y":2,"z":-8,"name":"Soil_Dirt"},{"x":-6,"y":3,"z":-8,"name":"Soil_Dirt"},{"x":-6,"y":4,"z":-8,"name":"Soil_Dirt"},{"x":-6,"y":5,"z":-8,"name":"Soil_Mud_Dry"},{"x":-6,"y":6,"z":-8,"name":"Wood_Sticks","support":15},{"x":-6,"y":34,"z":-8,"name":"Plant_Leaves_Jungle"},{"x":-6,"y":35,"z":-8,"name":"Plant_Leaves_Jungle"},{"x":-6,"y":36,"z":-8,"name":"Plant_Leaves_Jungle"},{"x":-6,"y":37,"z":-8,"name":"Plant_Leaves_Jungle"},{"x":-6,"y":39,"z":-8,"name":"Plant_Leaves_Jungle","support":4},{"x":-6,"y":40,"z":-8,"name":"Plant_Leaves_Jungle"},{"x":-6,"y":41,"z":-8,"name":"Plant_Leaves_Jungle"},{"x":-6,"y":42,"z":-8,"name":"Plant_Leaves_Jungle"},{"x":-6,"y":43,"z":-8,"name":"Plant_Leaves_Jungle"},{"x":-6,"y":0,"z":-7,"name":"Soil_Dirt"},{"x":-6,"y":1,"z":-7,"name":"Soil_Dirt"},{"x":-6,"y":2,"z":-7,"name":"Soil_Dirt"},{"x":-6,"y":3,"z":-7,"name":"Soil_Dirt"},{"x":-6,"y":4,"z":-7,"name":"Soil_Dirt"},{"x":-6,"y":5,"z":-7,"name":"Soil_Grass_Deep"},{"x":-6,"y":35,"z":-7,"name":"Plant_Leaves_Jungle"},{"x":-6,"y":36,"z":-7,"name":"Plant_Leaves_Jungle"},{"x":-6,"y":37,"z":-7,"name":"Plant_Leaves_Jungle"},{"x":-6,"y":38,"z":-7,"name":"Plant_Leaves_Jungle"},{"x":-6,"y":39,"z":-7,"name":"Plant_Leaves_Jungle","support":4},{"x":-6,"y":40,"z":-7,"name":"Plant_Leaves_Jungle","support":4},{"x":-6,"y":41,"z":-7,"name":"Plant_Leaves_Jungle"},{"x":-6,"y":42,"z":-7,"name":"Plant_Leaves_Jungle"},{"x":-6,"y":43,"z":-7,"name":"Plant_Leaves_Jungle"},{"x":-6,"y":0,"z":-6,"name":"Soil_Dirt"},{"x":-6,"y":1,"z":-6,"name":"Soil_Dirt"},{"x":-6,"y":2,"z":-6,"name":"Soil_Dirt"},{"x":-6,"y":3,"z":-6,"name":"Soil_Dirt"},{"x":-6,"y":4,"z":-6,"name":"Soil_Dirt"},{"x":-6,"y":5,"z":-6,"name":"Soil_Grass_Deep"},{"x":-6,"y":20,"z":-6,"name":"Wood_Jungle_Trunk_Full","support":1},{"x":-6,"y":21,"z":-6,"name":"Plant_Vine_Jungle","support":15,"rotation":2},{"x":-6,"y":37,"z":-6,"name":"Plant_Leaves_Jungle"},{"x":-6,"y":38,"z":-6,"name":"Plant_Leaves_Jungle","support":4},{"x":-6,"y":39,"z":-6,"name":"Plant_Leaves_Jungle","support":3},{"x":-6,"y":40,"z":-6,"name":"Plant_Leaves_Jungle","support":4},{"x":-6,"y":41,"z":-6,"name":"Plant_Leaves_Jungle"},{"x":-6,"y":42,"z":-6,"name":"Plant_Leaves_Jungle"},{"x":-6,"y":43,"z":-6,"name":"Plant_Leaves_Jungle"},{"x":-6,"y":44,"z":-6,"name":"Plant_Leaves_Jungle"},{"x":-6,"y":0,"z":-5,"name":"Soil_Dirt"},{"x":-6,"y":1,"z":-5,"name":"Soil_Dirt"},{"x":-6,"y":2,"z":-5,"name":"Soil_Dirt"},{"x":-6,"y":3,"z":-5,"name":"Soil_Dirt"},{"x":-6,"y":4,"z":-5,"name":"Soil_Dirt"},{"x":-6,"y":5,"z":-5,"name":"Soil_Grass_Deep"},{"x":-6,"y":18,"z":-5,"name":"Plant_Vine_Hanging","support":15,"rotation":2},{"x":-6,"y":19,"z":-5,"name":"Wood_Jungle_Trunk_Full","support":1},{"x":-6,"y":20,"z":-5,"name":"Wood_Jungle_Trunk_Full"},{"x":-6,"y":21,"z":-5,"name":"Wood_Jungle_Trunk_Full"},{"x":-6,"y":39,"z":-5,"name":"Plant_Leaves_Jungle","support":3},{"x":-6,"y":40,"z":-5,"name":"Plant_Leaves_Jungle","support":4},{"x":-6,"y":41,"z":-5,"name":"Plant_Leaves_Jungle"},{"x":-6,"y":42,"z":-5,"name":"Plant_Leaves_Jungle"},{"x":-6,"y":43,"z":-5,"name":"Plant_Leaves_Jungle"},{"x":-6,"y":44,"z":-5,"name":"Plant_Leaves_Jungle"},{"x":-6,"y":0,"z":-4,"name":"Soil_Dirt"},{"x":-6,"y":1,"z":-4,"name":"Soil_Dirt"},{"x":-6,"y":2,"z":-4,"name":"Soil_Dirt"},{"x":-6,"y":3,"z":-4,"name":"Soil_Dirt"},{"x":-6,"y":4,"z":-4,"name":"Soil_Dirt"},{"x":-6,"y":5,"z":-4,"name":"Soil_Mud_Dry"},{"x":-6,"y":8,"z":-4,"name":"Cloth_Modern_DarkGreen_Roof_Vertical_Flap","rotation":2},{"x":-6,"y":18,"z":-4,"name":"Wood_Jungle_Trunk_Full","support":4},{"x":-6,"y":19,"z":-4,"name":"Wood_Jungle_Trunk_Full"},{"x":-6,"y":20,"z":-4,"name":"Wood_Jungle_Trunk_Full"},{"x":-6,"y":21,"z":-4,"name":"Wood_Jungle_Trunk_Full"},{"x":-6,"y":22,"z":-4,"name":"Wood_Jungle_Trunk_Full"},{"x":-6,"y":39,"z":-4,"name":"Plant_Leaves_Jungle","support":3},{"x":-6,"y":40,"z":-4,"name":"Plant_Leaves_Jungle","support":4},{"x":-6,"y":41,"z":-4,"name":"Plant_Leaves_Jungle"},{"x":-6,"y":42,"z":-4,"name":"Plant_Leaves_Jungle"},{"x":-6,"y":43,"z":-4,"name":"Plant_Leaves_Jungle"},{"x":-6,"y":44,"z":-4,"name":"Plant_Leaves_Jungle"},{"x":-6,"y":45,"z":-4,"name":"Plant_Leaves_Jungle"},{"x":-6,"y":0,"z":-3,"name":"Soil_Dirt"},{"x":-6,"y":1,"z":-3,"name":"Soil_Dirt"},{"x":-6,"y":2,"z":-3,"name":"Soil_Dirt"},{"x":-6,"y":3,"z":-3,"name":"Soil_Dirt"},{"x":-6,"y":4,"z":-3,"name":"Soil_Dirt"},{"x":-6,"y":5,"z":-3,"name":"Soil_Dirt"},{"x":-6,"y":6,"z":-3,"name":"Wood_Bamboo_Trunk_Full","support":15},{"x":-6,"y":7,"z":-3,"name":"Wood_Bamboo_Branch_Long","support":15},{"x":-6,"y":8,"z":-3,"name":"Wood_Bamboo_Branch_Long","support":15},{"x":-6,"y":9,"z":-3,"name":"*Cloth_Modern_DarkGreen_Roof_State_Definitions_Corner_Right","rotation":3},{"x":-6,"y":18,"z":-3,"name":"Wood_Jungle_Trunk_Full","support":5},{"x":-6,"y":19,"z":-3,"name":"Wood_Jungle_Trunk_Full"},{"x":-6,"y":20,"z":-3,"name":"Wood_Jungle_Trunk_Full"},{"x":-6,"y":21,"z":-3,"name":"Wood_Jungle_Trunk_Full"},{"x":-6,"y":22,"z":-3,"name":"Wood_Jungle_Trunk_Full"},{"x":-6,"y":39,"z":-3,"name":"Plant_Leaves_Jungle","support":3},{"x":-6,"y":40,"z":-3,"name":"Plant_Leaves_Jungle","support":4},{"x":-6,"y":41,"z":-3,"name":"Plant_Leaves_Jungle"},{"x":-6,"y":42,"z":-3,"name":"Plant_Leaves_Jungle"},{"x":-6,"y":43,"z":-3,"name":"Plant_Leaves_Jungle"},{"x":-6,"y":44,"z":-3,"name":"Plant_Leaves_Jungle","support":4},{"x":-6,"y":45,"z":-3,"name":"Plant_Leaves_Jungle"},{"x":-6,"y":0,"z":-2,"name":"Soil_Dirt"},{"x":-6,"y":1,"z":-2,"name":"Soil_Dirt"},{"x":-6,"y":2,"z":-2,"name":"Soil_Dirt"},{"x":-6,"y":3,"z":-2,"name":"Soil_Dirt"},{"x":-6,"y":4,"z":-2,"name":"Soil_Dirt"},{"x":-6,"y":5,"z":-2,"name":"Soil_Grass_Deep"},{"x":-6,"y":6,"z":-2,"name":"Furniture_Jungle_Platform"},{"x":-6,"y":9,"z":-2,"name":"Cloth_Modern_DarkGreen_Roof","rotation":3},{"x":-6,"y":18,"z":-2,"name":"Plant_Vine_Hanging","support":15,"rotation":3},{"x":-6,"y":19,"z":-2,"name":"Wood_Jungle_Trunk_Full","support":1},{"x":-6,"y":20,"z":-2,"name":"Wood_Jungle_Trunk_Full"},{"x":-6,"y":21,"z":-2,"name":"Wood_Jungle_Trunk_Full"},{"x":-6,"y":22,"z":-2,"name":"Wood_Jungle_Trunk_Full"},{"x":-6,"y":23,"z":-2,"name":"Plant_Vine_Jungle","support":15,"rotation":3},{"x":-6,"y":39,"z":-2,"name":"Plant_Leaves_Jungle","support":3},{"x":-6,"y":40,"z":-2,"name":"Plant_Leaves_Jungle","support":4},{"x":-6,"y":41,"z":-2,"name":"Plant_Leaves_Jungle"},{"x":-6,"y":42,"z":-2,"name":"Plant_Leaves_Jungle"},{"x":-6,"y":43,"z":-2,"name":"Plant_Leaves_Jungle","support":4},{"x":-6,"y":44,"z":-2,"name":"Plant_Leaves_Jungle","support":3},{"x":-6,"y":0,"z":-1,"name":"Soil_Dirt"},{"x":-6,"y":1,"z":-1,"name":"Soil_Dirt"},{"x":-6,"y":2,"z":-1,"name":"Soil_Dirt"},{"x":-6,"y":3,"z":-1,"name":"Soil_Dirt"},{"x":-6,"y":4,"z":-1,"name":"Soil_Dirt"},{"x":-6,"y":5,"z":-1,"name":"Soil_Grass_Deep"},{"x":-6,"y":6,"z":-1,"name":"Furniture_Jungle_Platform"},{"x":-6,"y":9,"z":-1,"name":"Cloth_Modern_DarkGreen_Roof","rotation":3},{"x":-6,"y":19,"z":-1,"name":"Wood_Jungle_Trunk_Full","support":2},{"x":-6,"y":20,"z":-1,"name":"Wood_Jungle_Trunk_Full"},{"x":-6,"y":21,"z":-1,"name":"Wood_Jungle_Trunk_Full"},{"x":-6,"y":22,"z":-1,"name":"Wood_Jungle_Trunk_Full"},{"x":-6,"y":23,"z":-1,"name":"Wood_Jungle_Trunk_Full"},{"x":-6,"y":39,"z":-1,"name":"Plant_Leaves_Jungle","support":4},{"x":-6,"y":40,"z":-1,"name":"Plant_Leaves_Jungle"},{"x":-6,"y":41,"z":-1,"name":"Plant_Leaves_Jungle"},{"x":-6,"y":42,"z":-1,"name":"Plant_Leaves_Jungle","support":4},{"x":-6,"y":43,"z":-1,"name":"Plant_Leaves_Jungle","support":3},{"x":-6,"y":44,"z":-1,"name":"Plant_Leaves_Jungle","support":2},{"x":-6,"y":0,"z":0,"name":"Soil_Dirt"},{"x":-6,"y":1,"z":0,"name":"Soil_Dirt"},{"x":-6,"y":2,"z":0,"name":"Soil_Dirt"},{"x":-6,"y":3,"z":0,"name":"Soil_Dirt"},{"x":-6,"y":4,"z":0,"name":"Soil_Dirt"},{"x":-6,"y":5,"z":0,"name":"Soil_Grass_Sunny"},{"x":-6,"y":6,"z":0,"name":"Furniture_Jungle_Platform","rotation":1},{"x":-6,"y":9,"z":0,"name":"Cloth_Modern_DarkGreen_Roof","rotation":3},{"x":-6,"y":19,"z":0,"name":"Wood_Jungle_Trunk_Full","support":3},{"x":-6,"y":20,"z":0,"name":"Wood_Jungle_Trunk_Full"},{"x":-6,"y":21,"z":0,"name":"Wood_Jungle_Trunk_Full"},{"x":-6,"y":22,"z":0,"name":"Wood_Jungle_Trunk_Full"},{"x":-6,"y":23,"z":0,"name":"Plant_Vine_Jungle","support":15,"rotation":3},{"x":-6,"y":39,"z":0,"name":"Plant_Leaves_Jungle"},{"x":-6,"y":40,"z":0,"name":"Plant_Leaves_Jungle"},{"x":-6,"y":41,"z":0,"name":"Plant_Leaves_Jungle","support":4},{"x":-6,"y":42,"z":0,"name":"Plant_Leaves_Jungle","support":3},{"x":-6,"y":43,"z":0,"name":"Plant_Leaves_Jungle","support":2},{"x":-6,"y":44,"z":0,"name":"Plant_Leaves_Jungle","support":1},{"x":-6,"y":0,"z":1,"name":"Soil_Dirt"},{"x":-6,"y":1,"z":1,"name":"Soil_Dirt"},{"x":-6,"y":2,"z":1,"name":"Soil_Dirt"},{"x":-6,"y":3,"z":1,"name":"Soil_Dirt"},{"x":-6,"y":4,"z":1,"name":"Soil_Dirt"},{"x":-6,"y":5,"z":1,"name":"Soil_Mud_Dry"},{"x":-6,"y":6,"z":1,"name":"Wood_Bamboo_Trunk_Full","support":15},{"x":-6,"y":7,"z":1,"name":"Wood_Bamboo_Branch_Long","support":15},{"x":-6,"y":8,"z":1,"name":"Wood_Bamboo_Branch_Long","support":15},