{"version":8,"blockIdVersion":11,"anchorX":0,"anchorY":0,"anchorZ":0,"blocks":[{"x":-14,"y":0,"z":-14,"name":"Soil_Dirt"},{"x":-14,"y":1,"z":-14,"name":"Soil_Dirt"},{"x":-14,"y":2,"z":-14,"name":"Soil_Dirt"},{"x":-14,"y":3,"z":-14,"name":"Soil_Dirt"},{"x":-14,"y":4,"z":-14,"name":"Soil_Dirt"},{"x":-14,"y":5,"z":-14,"name":"Rock_Stone_Brick_Smooth","support":15},{"x":-14,"y":0,"z":-13,"name":"Soil_Dirt"},{"x":-14,"y":1,"z":-13,"name":"Soil_Dirt"},{"x":-14,"y":2,"z":-13,"name":"Soil_Dirt"},{"x":-14,"y":3,"z":-13,"name":"Soil_Dirt"},{"x":-14,"y":4,"z":-13,"name":"Soil_Dirt"},{"x":-14,"y":5,"z":-13,"name":"Rock_Stone_Brick_Smooth","support":15},{"x":-14,"y":9,"z":-13,"name":"Cloth_Modern_Red_Roof_Vertical_Flap","support":15,"rotation":3},{"x":-14,"y":0,"z":-12,"name":"Soil_Dirt"},{"x":-14,"y":1,"z":-12,"name":"Soil_Dirt"},{"x":-14,"y":2,"z":-12,"name":"Soil_Dirt"},{"x":-14,"y":3,"z":-12,"name":"Soil_Dirt"},{"x":-14,"y":4,"z":-12,"name":"Soil_Dirt"},{"x":-14,"y":5,"z":-12,"name":"Rock_Stone_Brick_Smooth","support":15},{"x":-14,"y":0,"z":-11,"name":"Soil_Dirt"},{"x":-14,"y":1,"z":-11,"name":"Soil_Dirt"},{"x":-14,"y":2,"z":-11,"name":"Soil_Dirt"},{"x":-14,"y":3,"z":-11,"name":"Soil_Dirt"},{"x":-14,"y":4,"z":-11,"name":"Soil_Dirt"},{"x":-14,"y":5,"z":-11,"name":"Rock_Stone_Brick_Smooth","support":15},{"x":-14,"y":0,"z":-10,"name":"Soil_Dirt"},{"x":-14,"y":1,"z":-10,"name":"Soil_Dirt"},{"x":-14,"y":2,"z":-10,"name":"Soil_Dirt"},{"x":-14,"y":3,"z":-10,"name":"Soil_Dirt"},{"x":-14,"y":4,"z":-10,"name":"Soil_Dirt"},{"x":-14,"y":5,"z":-10,"name":"Rock_Stone_Brick_Smooth","support":15},{"x":-14,"y":0,"z":-9,"name":"Soil_Dirt"},{"x":-14,"y":1,"z":-9,"name":"Soil_Dirt"},{"x":-14,"y":2,"z":-9,"name":"Soil_Dirt"},{"x":-14,"y":3,"z":-9,"name":"Soil_Dirt"},{"x":-14,"y":4,"z":-9,"name":"Soil_Dirt"},{"x":-14,"y":5,"z":-9,"name":"Rock_Stone_Brick_Smooth","support":15},{"x":-14,"y":0,"z":-8,"name":"Soil_Dirt"},{"x":-14,"y":1,"z":-8,"name":"Soil_Dirt"},{"x":-14,"y":2,"z":-8,"name":"Soil_Dirt"},{"x":-14,"y":3,"z":-8,"name":"Soil_Dirt"},{"x":-14,"y":4,"z":-8,"name":"Soil_Dirt"},{"x":-14,"y":5,"z":-8,"name":"Rock_Stone_Brick_Smooth","support":15},{"x":-14,"y":0,"z":-7,"name":"Soil_Dirt"},{"x":-14,"y":1,"z":-7,"name":"Soil_Dirt"},{"x":-14,"y":2,"z":-7,"name":"Soil_Dirt"},{"x":-14,"y":3,"z":-7,"name":"Soil_Dirt"},{"x":-14,"y":4,"z":-7,"name":"Soil_Dirt"},{"x":-14,"y":5,"z":-7,"name":"Rock_Stone_Brick_Smooth","support":15},{"x":-14,"y":0,"z":-6,"name":"Soil_Dirt"},{"x":-14,"y":1,"z":-6,"name":"Soil_Dirt"},{"x":-14,"y":2,"z":-6,"name":"Soil_Dirt"},{"x":-14,"y":3,"z":-6,"name":"Soil_Dirt"},{"x":-14,"y":4,"z":-6,"name":"Soil_Dirt"},{"x":-14,"y":5,"z":-6,"name":"Rock_Stone_Brick_Smooth","support":15},{"x":-14,"y":0,"z":-5,"name":"Soil_Dirt"},{"x":-14,"y":1,"z":-5,"name":"Soil_Dirt"},{"x":-14,"y":2,"z":-5,"name":"Soil_Dirt"},{"x":-14,"y":3,"z":-5,"name":"Soil_Dirt"},{"x":-14,"y":4,"z":-5,"name":"Soil_Dirt"},{"x":-14,"y":5,"z":-5,"name":"Rock_Stone_Brick_Smooth","support":15},{"x":-14,"y":0,"z":-4,"name":"Soil_Dirt"},{"x":-14,"y":1,"z":-4,"name":"Soil_Dirt"},{"x":-14,"y":2,"z":-4,"name":"Soil_Dirt"},{"x":-14,"y":3,"z":-4,"name":"Soil_Dirt"},{"x":-14,"y":4,"z":-4,"name":"Soil_Dirt"},{"x":-14,"y":5,"z":-4,"name":"Rock_Stone_Brick_Smooth","support":15},{"x":-14,"y":9,"z":-4,"name":"Cloth_Modern_Red_Roof_Vertical_Flap","support":15,"rotation":3},{"x":-14,"y":0,"z":-3,"name":"Soil_Dirt"},{"x":-14,"y":1,"z":-3,"name":"Soil_Dirt"},{"x":-14,"y":2,"z":-3,"name":"Soil_Dirt"},{"x":-14,"y":3,"z":-3,"name":"Soil_Dirt"},{"x":-14,"y":4,"z":-3,"name":"Soil_Dirt"},{"x":-14,"y":5,"z":-3,"name":"Rock_Stone_Brick_Smooth","support":15},{"x":-14,"y":0,"z":-2,"name":"Soil_Dirt"},{"x":-14,"y":1,"z":-2,"name":"Soil_Dirt"},{"x":-14,"y":2,"z":-2,"name":"Soil_Dirt"},{"x":-14,"y":3,"z":-2,"name":"Soil_Dirt"},{"x":-14,"y":4,"z":-2,"name":"Soil_Dirt"},{"x":-14,"y":5,"z":-2,"name":"Rock_Stone_Brick_Smooth","support":15},{"x":-14,"y":0,"z":-1,"name":"Soil_Dirt"},{"x":-14,"y":1,"z":-1,"name":"Soil_Dirt"},{"x":-14,"y":2,"z":-1,"name":"Soil_Dirt"},{"x":-14,"y":3,"z":-1,"name":"Soil_Dirt"},{"x":-14,"y":4,"z":-1,"name":"Soil_Dirt"},{"x":-14,"y":5,"z":-1,"name":"Rock_Stone_Brick_Smooth","support":15},{"x":-14,"y":0,"z":0,"name":"Soil_Dirt"},{"x":-14,"y":1,"z":0,"name":"Soil_Dirt"},{"x":-14,"y":2,"z":0,"name":"Soil_Dirt"},{"x":-14,"y":3,"z":0,"name":"Soil_Dirt"},{"x":-14,"y":4,"z":0,"name":"Soil_Dirt"},{"x":-14,"y":5,"z":0,"name":"Rock_Stone_Brick_Smooth","support":15},{"x":-14,"y":0,"z":1,"name":"Soil_Dirt"},{"x":-14,"y":1,"z":1,"name":"Soil_Dirt"},{"x":-14,"y":2,"z":1,"name":"Soil_Dirt"},{"x":-14,"y":3,"z":1,"name":"Soil_Dirt"},{"x":-14,"y":4,"z":1,"name":"Soil_Dirt"},{"x":-14,"y":5,"z":1,"name":"Rock_Stone_Brick_Smooth","support":15},{"x":-14,"y":0,"z":2,"name":"Soil_Dirt"},{"x":-14,"y":1,"z":2,"name":"Soil_Dirt"},{"x":-14,"y":2,"z":2,"name":"Soil_Dirt"},{"x":-14,"y":3,"z":2,"name":"Soil_Dirt"},{"x":-14,"y":4,"z":2,"name":"Soil_Dirt"},{"x":-14,"y":5,"z":2,"name":"Rock_Stone_Brick_Smooth","support":15},{"x":-14,"y":0,"z":3,"name":"Soil_Dirt"},{"x":-14,"y":1,"z":3,"name":"Soil_Dirt"},{"x":-14,"y":2,"z":3,"name":"Soil_Dirt"},{"x":-14,"y":3,"z":3,"name":"Soil_Dirt"},{"x":-14,"y":4,"z":3,"name":"Soil_Dirt"},{"x":-14,"y":5,"z":3,"name":"Rock_Stone_Brick_Smooth","support":15},{"x":-14,"y":0,"z":4,"name":"Soil_Dirt"},{"x":-14,"y":1,"z":4,"name":"Soil_Dirt"},{"x":-14,"y":2,"z":4,"name":"Soil_Dirt"},{"x":-14,"y":3,"z":4,"name":"Soil_Dirt"},{"x":-14,"y":4,"z":4,"name":"Soil_Dirt"},{"x":-14,"y":5,"z":4,"name":"Rock_Stone_Brick_Smooth","support":15},{"x":-14,"y":0,"z":5,"name":"Soil_Dirt"},{"x":-14,"y":1,"z":5,"name":"Soil_Dirt"},{"x":-14,"y":2,"z":5,"name":"Soil_Dirt"},{"x":-14,"y":3,"z":5,"name":"Soil_Dirt"},{"x":-14,"y":4,"z":5,"name":"Soil_Dirt"},{"x":-14,"y":5,"z":5,"name":"Rock_Stone_Brick_Smooth","support":15},{"x":-14,"y":9,"z":5,"name":"Cloth_Modern_Red_Roof_Vertical_Flap","support":15,"rotation":3},{"x":-14,"y":0,"z":6,"name":"Soil_Dirt"},{"x":-14,"y":1,"z":6,"name":"Soil_Dirt"},{"x":-14,"y":2,"z":6,"name":"Soil_Dirt"},{"x":-14,"y":3,"z":6,"name":"Soil_Dirt"},{"x":-14,"y":4,"z":6,"name":"Soil_Dirt"},{"x":-14,"y":5,"z":6,"name":"Rock_Stone_Brick_Smooth","support":15},{"x":-14,"y":0,"z":7,"name":"Soil_Dirt"},{"x":-14,"y":1,"z":7,"name":"Soil_Dirt"},{"x":-14,"y":2,"z":7,"name":"Soil_Dirt"},{"x":-14,"y":3,"z":7,"name":"Soil_Dirt"},{"x":-14,"y":4,"z":7,"name":"Soil_Dirt"},{"x":-14,"y":5,"z":7,"name":"Rock_Stone_Brick_Smooth","support":15},{"x":-14,"y":0,"z":8,"name":"Soil_Dirt"},{"x":-14,"y":1,"z":8,"name":"Soil_Dirt"},{"x":-14,"y":2,"z":8,"name":"Soil_Dirt"},{"x":-14,"y":3,"z":8,"name":"Soil_Dirt"},{"x":-14,"y":4,"z":8,"name":"Soil_Dirt"},{"x":-14,"y":5,"z":8,"name":"Rock_Stone_Brick_Smooth","support":15},{"x":-14,"y":0,"z":9,"name":"Soil_Dirt"},{"x":-14,"y":1,"z":9,"name":"Soil_Dirt"},{"x":-14,"y":2,"z":9,"name":"Soil_Dirt"},{"x":-14,"y":3,"z":9,"name":"Soil_Dirt"},{"x":-14,"y":4,"z":9,"name":"Soil_Dirt"},{"x":-14,"y":5,"z":9,"name":"Rock_Stone_Brick_Smooth","support":15},{"x":-14,"y":0,"z":10,"name":"Soil_Dirt"},{"x":-14,"y":1,"z":10,"name":"Soil_Dirt"},{"x":-14,"y":2,"z":10,"name":"Soil_Dirt"},{"x":-14,"y":3,"z":10,"name":"Soil_Dirt"},{"x":-14,"y":4,"z":10,"name":"Soil_Dirt"},{"x":-14,"y":5,"z":10,"name":"Rock_Stone_Brick_Smooth","support":15},{"x":-14,"y":0,"z":11,"name":"Soil_Dirt"},{"x":-14,"y":1,"z":11,"name":"Soil_Dirt"},{"x":-14,"y":2,"z":11,"name":"Soil_Dirt"},{"x":-14,"y":3,"z":11,"name":"Soil_Dirt"},{"x":-14,"y":4,"z":11,"name":"Soil_Dirt"},{"x":-14,"y":5,"z":11,"name":"Rock_Stone_Brick_Smooth","support":15},{"x":-14,"y":0,"z":12,"name":"Soil_Dirt"},{"x":-14,"y":1,"z":12,"name":"Soil_Dirt"},{"x":-14,"y":2,"z":12,"name":"Soil_Dirt"},{"x":-14,"y":3,"z":12,"name":"Soil_Dirt"},{"x":-14,"y":4,"z":12,"name":"Soil_Dirt"},{"x":-14,"y":5,"z":12,"name":"Rock_Stone_Brick_Smooth","support":15},{"x":-14,"y":0,"z":13,"name":"Soil_Dirt"},{"x":-14,"y":1,"z":13,"name":"Soil_Dirt"},{"x":-14,"y":2,"z":13,"name":"Soil_Dirt"},{"x":-14,"y":3,"z":13,"name":"Soil_Dirt"},{"x":-14,"y":4,"z":13,"name":"Soil_Dirt"},{"x":-14,"y":5,"z":13,"name":"Rock_Stone_Brick_Smooth","support":15},{"x":-14,"y":0,"z":14,"name":"Soil_Dirt"},{"x":-14,"y":1,"z":14,"name":"Soil_Dirt"},{"x":-14,"y":2,"z":14,"name":"Soil_Dirt"},{"x":-14,"y":3,"z":14,"name":"Soil_Dirt"},{"x":-14,"y":4,"z":14,"name":"Soil_Dirt"},{"x":-14,"y":5,"z":14,"name":"Rock_Stone_Brick_Smooth","support":15},{"x":-14,"y":9,"z":14,"name":"Cloth_Modern_Red_Roof_Vertical_Flap","support":15,"rotation":3},{"x":-14,"y":0,"z":15,"name":"Soil_Dirt"},{"x":-14,"y":1,"z":15,"name":"Soil_Dirt"},{"x":-14,"y":2,"z":15,"name":"Soil_Dirt"},{"x":-14,"y":3,"z":15,"name":"Soil_Dirt"},{"x":-14,"y":4,"z":15,"name":"Soil_Dirt"},{"x":-14,"y":5,"z":15,"name":"Rock_Stone_Brick_Smooth","support":15},{"x":-13,"y":0,"z":-14,"name":"Soil_Dirt"},{"x":-13,"y":1,"z":-14,"name":"Soil_Dirt"},{"x":-13,"y":2,"z":-14,"name":"Soil_Dirt"},{"x":-13,"y":3,"z":-14,"name":"Soil_Dirt"},{"x":-13,"y":4,"z":-14,"name":"Soil_Dirt"},{"x":-13,"y":5,"z":-14,"name":"Rock_Stone_Brick_Smooth","support":15},{"x":-13,"y":9,"z":-14,"name":"Cloth_Modern_Red_Roof_Vertical_Flap","support":15,"rotation":2},{"x":-13,"y":0,"z":-13,"name":"Soil_Dirt"},{"x":-13,"y":1,"z":-13,"name":"Soil_Dirt"},{"x":-13,"y":2,"z":-13,"name":"Soil_Dirt"},{"x":-13,"y":3,"z":-13,"name":"Soil_Dirt"},{"x":-13,"y":4,"z":-13,"name":"Soil_Dirt"},{"x":-13,"y":5,"z":-13,"name":"Rock_Stone_Cobble_Mossy"},{"x":-13,"y":6,"z":-13,"name":"Wood_Softwood_Beam","support":15,"rotation":3},{"x":-13,"y":7,"z":-13,"name":"Wood_Softwood_Beam","support":15,"rotation":3},{"x":-13,"y":8,"z":-13,"name":"Wood_Softwood_Beam","support":15,"rotation":3},{"x":-13,"y":9,"z":-13,"name":"Wood_Softwood_Beam","support":15,"rotation":3},{"x":-13,"y":10,"z":-13,"name":"Wood_Redwood_Planks_Half","support":15},{"x":-13,"y":0,"z":-12,"name":"Soil_Dirt"},{"x":-13,"y":1,"z":-12,"name":"Soil_Dirt"},{"x":-13,"y":2,"z":-12,"name":"Soil_Dirt"},{"x":-13,"y":3,"z":-12,"name":"Soil_Dirt"},{"x":-13,"y":4,"z":-12,"name":"Soil_Dirt"},{"x":-13,"y":5,"z":-12,"name":"Rock_Stone_Cobble"},{"x":-13,"y":6,"z":-12,"name":"Furniture_Village_Crate","support":15},{"x":-13,"y":7,"z":-12,"name":"Furniture_Tavern_Barrel","support":15},{"x":-13,"y":0,"z":-11,"name":"Soil_Dirt"},{"x":-13,"y":1,"z":-11,"name":"Soil_Dirt"},{"x":-13,"y":2,"z":-11,"name":"Soil_Dirt"},{"x":-13,"y":3,"z":-11,"name":"Soil_Dirt"},{"x":-13,"y":4,"z":-11,"name":"Soil_Dirt"},{"x":-13,"y":5,"z":-11,"name":"Rock_Stone_Cobble_Mossy"},{"x":-13,"y":0,"z":-10,"name":"Soil_Dirt"},{"x":-13,"y":1,"z":-10,"name":"Soil_Dirt"},{"x":-13,"y":2,"z":-10,"name":"Soil_Dirt"},{"x":-13,"y":3,"z":-10,"name":"Soil_Dirt"},{"x":-13,"y":4,"z":-10,"name":"Soil_Dirt"},{"x":-13,"y":5,"z":-10,"name":"Rock_Stone_Cobble"},{"x":-13,"y":0,"z":-9,"name":"Soil_Dirt"},{"x":-13,"y":1,"z":-9,"name":"Soil_Dirt"},{"x":-13,"y":2,"z":-9,"name":"Soil_Dirt"},{"x":-13,"y":3,"z":-9,"name":"Soil_Dirt"},{"x":-13,"y":4,"z":-9,"name":"Soil_Dirt"},{"x":-13,"y":5,"z":-9,"name":"Rock_Stone_Cobble"},{"x":-13,"y":6,"z":-9,"name":"Furniture_Tavern_Bench","filler":992,"rotation":3},{"x":-13,"y":0,"z":-8,"name":"Soil_Dirt"},{"x":-13,"y":1,"z":-8,"name":"Soil_Dirt"},{"x":-13,"y":2,"z":-8,"name":"Soil_Dirt"},{"x":-13,"y":3,"z":-8,"name":"Soil_Dirt"},{"x":-13,"y":4,"z":-8,"name":"Soil_Dirt"},{"x":-13,"y":5,"z":-8,"name":"Rock_Stone_Cobble"},{"x":-13,"y":6,"z":-8,"name":"Furniture_Tavern_Bench","support":15,"rotation":3},{"x":-13,"y":0,"z":-7,"name":"Soil_Dirt"},{"x":-13,"y":1,"z":-7,"name":"Soil_Dirt"},{"x":-13,"y":2,"z":-7,"name":"Soil_Dirt"},{"x":-13,"y":3,"z":-7,"name":"Soil_Dirt"},{"x":-13,"y":4,"z":-7,"name":"Soil_Dirt"},{"x":-13,"y":5,"z":-7,"name":"Rock_Stone_Cobble"},{"x":-13,"y":0,"z":-6,"name":"Soil_Dirt"},{"x":-13,"y":1,"z":-6,"name":"Soil_Dirt"},{"x":-13,"y":2,"z":-6,"name":"Soil_Dirt"},{"x":-13,"y":3,"z":-6,"name":"Soil_Dirt"},{"x":-13,"y":4,"z":-6,"name":"Soil_Dirt"},{"x":-13,"y":5,"z":-6,"name":"Rock_Stone_Cobble_Mossy"},{"x":-13,"y":0,"z":-5,"name":"Soil_Dirt"},{"x":-13,"y":1,"z":-5,"name":"Soil_Dirt"},{"x":-13,"y":2,"z":-5,"name":"Soil_Dirt"},{"x":-13,"y":3,"z":-5,"name":"Soil_Dirt"},{"x":-13,"y":4,"z":-5,"name":"Soil_Dirt"},{"x":-13,"y":5,"z":-5,"name":"Rock_Stone_Cobble"},{"x":-13,"y":6,"z":-5,"name":"Furniture_Tavern_Planter","support":15},{"x":-13,"y":7,"z":-5,"name":"Plant_Flower_Common_Red2","support":15},{"x":-13,"y":0,"z":-4,"name":"Soil_Dirt"},{"x":-13,"y":1,"z":-4,"name":"Soil_Dirt"},{"x":-13,"y":2,"z":-4,"name":"Soil_Dirt"},{"x":-13,"y":3,"z":-4,"name":"Soil_Dirt"},{"x":-13,"y":4,"z":-4,"name":"Soil_Dirt"},{"x":-13,"y":5,"z":-4,"name":"Rock_Stone_Cobble_Mossy"},{"x":-13,"y":6,"z":-4,"name":"Wood_Softwood_Beam","support":15,"rotation":3},{"x":-13,"y":7,"z":-4,"name":"Wood_Softwood_Beam","support":15,"rotation":3},{"x":-13,"y":8,"z":-4,"name":"Wood_Softwood_Beam","support":15,"rotation":3},{"x":-13,"y":9,"z":-4,"name":"Wood_Softwood_Beam","support":15,"rotation":3},{"x":-13,"y":10,"z":-4,"name":"Wood_Redwood_Planks_Half","support":15},{"x":-13,"y":0,"z":-3,"name":"Soil_Dirt"},{"x":-13,"y":1,"z":-3,"name":"Soil_Dirt"},{"x":-13,"y":2,"z":-3,"name":"Soil_Dirt"},{"x":-13,"y":3,"z":-3,"name":"Soil_Dirt"},{"x":-13,"y":4,"z":-3,"name":"Soil_Dirt"},{"x":-13,"y":5,"z":-3,"name":"Rock_Stone_Cobble_Mossy"},{"x":-13,"y":6,"z":-3,"name":"Furniture_Tavern_Planter","support":15},{"x":-13,"y":7,"z":-3,"name":"Plant_Flower_Common_Yellow2","support":15},{"x":-13,"y":0,"z":-2,"name":"Soil_Dirt"},{"x":-13,"y":1,"z":-2,"name":"Soil_Dirt"},{"x":-13,"y":2,"z":-2,"name":"Soil_Dirt"},{"x":-13,"y":3,"z":-2,"name":"Soil_Dirt"},{"x":-13,"y":4,"z":-2,"name":"Soil_Dirt"},{"x":-13,"y":5,"z":-2,"name":"Rock_Stone_Cobble"},{"x":-13,"y":0,"z":-1,"name":"Soil_Dirt"},{"x":-13,"y":1,"z":-1,"name":"Soil_Dirt"},{"x":-13,"y":2,"z":-1,"name":"Soil_Dirt"},{"x":-13,"y":3,"z":-1,"name":"Soil_Dirt"},{"x":-13,"y":4,"z":-1,"name":"Soil_Dirt"},{"x":-13,"y":5,"z":-1,"name":"Rock_Stone_Cobble"},{"x":-13,"y":0,"z":0,"name":"Soil_Dirt"},{"x":-13,"y":1,"z":0,"name":"Soil_Dirt"},{"x":-13,"y":2,"z":0,"name":"Soil_Dirt"},{"x":-13,"y":3,"z":0,"name":"Soil_Dirt"},{"x":-13,"y":4,"z":0,"name":"Soil_Dirt"},{"x":-13,"y":5,"z":0,"name":"Rock_Stone_Cobble"},{"x":-13,"y":0,"z":1,"name":"Soil_Dirt"},{"x":-13,"y":1,"z":1,"name":"Soil_Dirt"},{"x":-13,"y":2,"z":1,"name":"Soil_Dirt"},{"x":-13,"y":3,"z":1,"name":"Soil_Dirt"},{"x":-13,"y":4,"z":1,"name":"Soil_Dirt"},{"x":-13,"y":5,"z":1,"name":"Rock_Stone_Cobble"},{"x":-13,"y":0,"z":2,"name":"Soil_Dirt"},{"x":-13,"y":1,"z":2,"name":"Soil_Dirt"},{"x":-13,"y":2,"z":2,"name":"Soil_Dirt"},{"x":-13,"y":3,"z":2,"name":"Soil_Dirt"},{"x":-13,"y":4,"z":2,"name":"Soil_Dirt"},{"x":-13,"y":5,"z":2,"name":"Rock_Stone_Cobble"},{"x":-13,"y":0,"z":3,"name":"Soil_Dirt"},{"x":-13,"y":1,"z":3,"name":"Soil_Dirt"},{"x":-13,"y":2,"z":3,"name":"Soil_Dirt"},{"x":-13,"y":3,"z":3,"name":"Soil_Dirt"},{"x":-13,"y":4,"z":3,"name":"Soil_Dirt"},{"x":-13,"y":5,"z":3,"name":"Rock_Stone_Cobble_Mossy"},{"x":-13,"y":0,"z":4,"name":"Soil_Dirt"},{"x":-13,"y":1,"z":4,"name":"Soil_Dirt"},{"x":-13,"y":2,"z":4,"name":"Soil_Dirt"},{"x":-13,"y":3,"z":4,"name":"Soil_Dirt"},{"x":-13,"y":4,"z":4,"name":"Soil_Dirt"},{"x":-13,"y":5,"z":4,"name":"Rock_Stone_Cobble"},{"x":-13,"y":6,"z":4,"name":"Furniture_Tavern_Planter","support":15},{"x":-13,"y":7,"z":4,"name":"Plant_Flower_Common_Red2","support":15},{"x":-13,"y":0,"z":5,"name":"Soil_Dirt"},{"x":-13,"y":1,"z":5,"name":"Soil_Dirt"},{"x":-13,"y":2,"z":5,"name":"Soil_Dirt"},{"x":-13,"y":3,"z":5,"name":"Soil_Dirt"},{"x":-13,"y":4,"z":5,"name":"Soil_Dirt"},{"x":-13,"y":5,"z":5,"name":"Rock_Stone_Cobble"},{"x":-13,"y":6,"z":5,"name":"Wood_Softwood_Beam","support":15,"rotation":3},{"x":-13,"y":7,"z":5,"name":"Wood_Softwood_Beam","support":15,"rotation":3},{"x":-13,"y":8,"z":5,"name":"Wood_Softwood_Beam","support":15,"rotation":3},{"x":-13,"y":9,"z":5,"name":"Wood_Softwood_Beam","support":15,"rotation":3},{"x":-13,"y":10,"z":5,"name":"Wood_Redwood_Planks_Half","support":15},{"x":-13,"y":0,"z":6,"name":"Soil_Dirt"},{"x":-13,"y":1,"z":6,"name":"Soil_Dirt"},{"x":-13,"y":2,"z":6,"name":"Soil_Dirt"},{"x":-13,"y":3,"z":6,"name":"Soil_Dirt"},{"x":-13,"y":4,"z":6,"name":"Soil_Dirt"},{"x":-13,"y":5,"z":6,"name":"Rock_Stone_Cobble"},{"x":-13,"y":6,"z":6,"name":"Furniture_Tavern_Planter","support":15},{"x":-13,"y":7,"z":6,"name":"Plant_Flower_Tall_Yellow","support":15},{"x":-13,"y":0,"z":7,"name":"Soil_Dirt"},{"x":-13,"y":1,"z":7,"name":"Soil_Dirt"},{"x":-13,"y":2,"z":7,"name":"Soil_Dirt"},{"x":-13,"y":3,"z":7,"name":"Soil_Dirt"},{"x":-13,"y":4,"z":7,"name":"Soil_Dirt"},{"x":-13,"y":5,"z":7,"name":"Rock_Stone_Cobble"},{"x":-13,"y":0,"z":8,"name":"Soil_Dirt"},{"x":-13,"y":1,"z":8,"name":"Soil_Dirt"},{"x":-13,"y":2,"z":8,"name":"Soil_Dirt"},{"x":-13,"y":3,"z":8,"name":"Soil_Dirt"},{"x":-13,"y":4,"z":8,"name":"Soil_Dirt"},{"x":-13,"y":5,"z":8,"name":"Rock_Stone_Cobble"},{"x":-13,"y":0,"z":9,"name":"Soil_Dirt"},{"x":-13,"y":1,"z":9,"name":"Soil_Dirt"},{"x":-13,"y":2,"z":9,"name":"Soil_Dirt"},{"x":-13,"y":3,"z":9,"name":"Soil_Dirt"},{"x":-13,"y":4,"z":9,"name":"Soil_Dirt"},{"x":-13,"y":5,"z":9,"name":"Rock_Stone_Cobble"},{"x":-13,"y":6,"z":9,"name":"Furniture_Tavern_Bench","filler":992,"rotation":3},{"x":-13,"y":0,"z":10,"name":"Soil_Dirt"},{"x":-13,"y":1,"z":10,"name":"Soil_Dirt"},{"x":-13,"y":2,"z":10,"name":"Soil_Dirt"},{"x":-13,"y":3,"z":10,"name":"Soil_Dirt"},{"x":-13,"y":4,"z":10,"name":"Soil_Dirt"},{"x":-13,"y":5,"z":10,"name":"Rock_Stone_Cobble"},{"x":-13,"y":6,"z":10,"name":"Furniture_Tavern_Bench","support":15,"rotation":3},{"x":-13,"y":0,"z":11,"name":"Soil_Dirt"},{"x":-13,"y":1,"z":11,"name":"Soil_Dirt"},{"x":-13,"y":2,"z":11,"name":"Soil_Dirt"},{"x":-13,"y":3,"z":11,"name":"Soil_Dirt"},{"x":-13,"y":4,"z":11,"name":"Soil_Dirt"},{"x":-13,"y":5,"z":11,"name":"Rock_Stone_Cobble_Mossy"},{"x":-13,"y":0,"z":12,"name":"Soil_Dirt"},{"x":-13,"y":1,"z":12,"name":"Soil_Dirt"},{"x":-13,"y":2,"z":12,"name":"Soil_Dirt"},{"x":-13,"y":3,"z":12,"name":"Soil_Dirt"},{"x":-13,"y":4,"z":12,"name":"Soil_Dirt"},{"x":-13,"y":5,"z":12,"name":"Rock_Stone_Cobble"},{"x":-13,"y":0,"z":13,"name":"Soil_Dirt"},{"x":-13,"y":1,"z":13,"name":"Soil_Dirt"},{"x":-13,"y":2,"z":13,"name":"Soil_Dirt"},{"x":-13,"y":3,"z":13,"name":"Soil_Dirt"},{"x":-13,"y":4,"z":13,"name":"Soil_Dirt"},{"x":-13,"y":5,"z":13,"name":"Rock_Stone_Cobble"},{"x":-13,"y":6,"z":13,"name":"Furniture_Village_Crate","support":15},{"x":-13,"y":0,"z":14,"name":"Soil_Dirt"},{"x":-13,"y":1,"z":14,"name":"Soil_Dirt"},{"x":-13,"y":2,"z":14,"name":"Soil_Dirt"},{"x":-13,"y":3,"z":14,"name":"Soil_Dirt"},{"x":-13,"y":4,"z":14,"name":"Soil_Dirt"},{"x":-13,"y":5,"z":14,"name":"Rock_Stone_Cobble"},{"x":-13,"y":6,"z":14,"name":"Wood_Softwood_Beam","support":15,"rotation":3},{"x":-13,"y":7,"z":14,"name":"Wood_Softwood_Beam","support":15,"rotation":3},{"x":-13,"y":8,"z":14,"name":"Wood_Softwood_Beam","support":15,"rotation":3},{"x":-13,"y":9,"z":14,"name":"Wood_Softwood_Beam","support":15,"rotation":3},{"x":-13,"y":10,"z":14,"name":"Wood_Redwood_Planks_Half","support":15},{"x":-13,"y":0,"z":15,"name":"Soil_Dirt"},{"x":-13,"y":1,"z":15,"name":"Soil_Dirt"},{"x":-13,"y":2,"z":15,"name":"Soil_Dirt"},{"x":-13,"y":3,"z":15,"name":"Soil_Dirt"},{"x":-13,"y":4,"z":15,"name":"Soil_Dirt"},{"x":-13,"y":5,"z":15,"name":"Rock_Stone_Brick_Smooth","support":15},{"x":-13,"y":9,"z":15,"name":"Cloth_Modern_Red_Roof_Vertical_Flap","support":15},{"x":-12,"y":0,"z":-14,"name":"Soil_Dirt"},{"x":-12,"y":1,"z":-14,"name":"Soil_Dirt"},{"x":-12,"y":2,"z":-14,"name":"Soil_Dirt"},{"x":-12,"y":3,"z":-14,"name":"Soil_Dirt"},{"x":-12,"y":4,"z":-14,"name":"Soil_Dirt"},{"x":-12,"y":5,"z":-14,"name":"Rock_Stone_Brick_Smooth","support":15},{"x":-12,"y":0,"z":-13,"name":"Soil_Dirt"},{"x":-12,"y":1,"z":-13,"name":"Soil_Dirt"},{"x":-12,"y":2,"z":-13,"name":"Soil_Dirt"},{"x":-12,"y":3,"z":-13,"name":"Soil_Dirt"},{"x":-12,"y":4,"z":-13,"name":"Soil_Dirt"},{"x":-12,"y":5,"z":-13,"name":"Rock_Stone_Cobble"},{"x":-12,"y":6,"z":-13,"name":"Furniture_Village_Crate","support":15},{"x":-12,"y":0,"z":-12,"name":"Soil_Dirt"},{"x":-12,"y":1,"z":-12,"name":"Soil_Dirt"},{"x":-12,"y":2,"z":-12,"name":"Soil_Dirt"},{"x":-12,"y":3,"z":-12,"name":"Soil_Dirt"},{"x":-12,"y":4,"z":-12,"name":"Soil_Dirt"},{"x":-12,"y":5,"z":-12,"name":"Rock_Stone_Cobble_Mossy"},{"x":-12,"y":0,"z":-11,"name":"Soil_Dirt"},{"x":-12,"y":1,"z":-11,"name":"Soil_Dirt"},{"x":-12,"y":2,"z":-11,"name":"Soil_Dirt"},{"x":-12,"y":3,"z":-11,"name":"Soil_Dirt"},{"x":-12,"y":4,"z":-11,"name":"Soil_Dirt"},{"x":-12,"y":5,"z":-11,"name":"Rock_Stone_Cobble"},{"x":-12,"y":0,"z":-10,"name":"Soil_Dirt"},{"x":-12,"y":1,"z":-10,"name":"Soil_Dirt"},{"x":-12,"y":2,"z":-10,"name":"Soil_Dirt"},{"x":-12,"y":3,"z":-10,"name":"Soil_Dirt"},{"x":-12,"y":4,"z":-10,"name":"Soil_Dirt"},{"x":-12,"y":5,"z":-10,"name":"Rock_Stone_Cobble"},{"x":-12,"y":0,"z":-9,"name":"Soil_Dirt"},{"x":-12,"y":1,"z":-9,"name":"Soil_Dirt"},{"x":-12,"y":2,"z":-9,"name":"Soil_Dirt"},{"x":-12,"y":3,"z":-9,"name":"Soil_Dirt"},{"x":-12,"y":4,"z":-9,"name":"Soil_Dirt"},{"x":-12,"y":5,"z":-9,"name":"Rock_Stone_Cobble_Mossy"},{"x":-12,"y":0,"z":-8,"name":"Soil_Dirt"},{"x":-12,"y":1,"z":-8,"name":"Soil_Dirt"},{"x":-12,"y":2,"z":-8,"name":"Soil_Dirt"},{"x":-12,"y":3,"z":-8,"name":"Soil_Dirt"},{"x":-12,"y":4,"z":-8,"name":"Soil_Dirt"},{"x":-12,"y":5,"z":-8,"name":"Rock_Stone_Cobble"},{"x":-12,"y":0,"z":-7,"name":"Soil_Dirt"},{"x":-12,"y":1,"z":-7,"name":"Soil_Dirt"},{"x":-12,"y":2,"z":-7,"name":"Soil_Dirt"},{"x":-12,"y":3,"z":-7,"name":"Soil_Dirt"},{"x":-12,"y":4,"z":-7,"name":"Soil_Dirt"},{"x":-12,"y":5,"z":-7,"name":"Rock_Stone_Cobble"},{"x":-12,"y":0,"z":-6,"name":"Soil_Dirt"},{"x":-12,"y":1,"z":-6,"name":"Soil_Dirt"},{"x":-12,"y":2,"z":-6,"name":"Soil_Dirt"},{"x":-12,"y":3,"z":-6,"name":"Soil_Dirt"},{"x":-12,"y":4,"z":-6,"name":"Soil_Dirt"},{"x":-12,"y":5,"z":-6,"name":"Rock_Stone_Cobble"},{"x":-12,"y":0,"z":-5,"name":"Soil_Dirt"},{"x":-12,"y":1,"z":-5,"name":"Soil_Dirt"},{"x":-12,"y":2,"z":-5,"name":"Soil_Dirt"},{"x":-12,"y":3,"z":-5,"name":"Soil_Dirt"},{"x":-12,"y":4,"z":-5,"name":"Soil_Dirt"},{"x":-12,"y":5,"z":-5,"name":"Rock_Stone_Cobble"},{"x":-12,"y":0,"z":-4,"name":"Soil_Dirt"},{"x":-12,"y":1,"z":-4,"name":"Soil_Dirt"},{"x":-12,"y":2,"z":-4,"name":"Soil_Dirt"},{"x":-12,"y":3,"z":-4,"name":"Soil_Dirt"},{"x":-12,"y":4,"z":-4,"name":"Soil_Dirt"},{"x":-12,"y":5,"z":-4,"name":"Rock_Stone_Cobble"},{"x":-12,"y":9,"z":-4,"name":"Cloth_Modern_Red_Roof_Vertical_Flap","support":15,"rotation":1},{"x":-12,"y":0,"z":-3,"name":"Soil_Dirt"},{"x":-12,"y":1,"z":-3,"name":"Soil_Dirt"},{"x":-12,"y":2,"z":-3,"name":"Soil_Dirt"},{"x":-12,"y":3,"z":-3,"name":"Soil_Dirt"},{"x":-12,"y":4,"z":-3,"name":"Soil_Dirt"},{"x":-12,"y":5,"z":-3,"name":"Rock_Stone_Cobble"},{"x":-12,"y":0,"z":-2,"name":"Soil_Dirt"},{"x":-12,"y":1,"z":-2,"name":"Soil_Dirt"},{"x":-12,"y":2,"z":-2,"name":"Soil_Dirt"},{"x":-12,"y":3,"z":-2,"name":"Soil_Dirt"},{"x":-12,"y":4,"z":-2,"name":"Soil_Dirt"},{"x":-12,"y":5,"z":-2,"name":"Rock_Stone_Cobble"},{"x":-12,"y":0,"z":-1,"name":"Soil_Dirt"},{"x":-12,"y":1,"z":-1,"name":"Soil_Dirt"},{"x":-12,"y":2,"z":-1,"name":"Soil_Dirt"},{"x":-12,"y":3,"z":-1,"name":"Soil_Dirt"},{"x":-12,"y":4,"z":-1,"name":"Soil_Dirt"},{"x":-12,"y":5,"z":-1,"name":"Rock_Stone_Cobble"},{"x":-12,"y":0,"z":0,"name":"Soil_Dirt"},{"x":-12,"y":1,"z":0,"name":"Soil_Dirt"},{"x":-12,"y":2,"z":0,"name":"Soil_Dirt"},{"x":-12,"y":3,"z":0,"name":"Soil_Dirt"},{"x":-12,"y":4,"z":0,"name":"Soil_Dirt"},{"x":-12,"y":5,"z":0,"name":"Rock_Stone_Cobble"},{"x":-12,"y":0,"z":1,"name":"Soil_Dirt"},{"x":-12,"y":1,"z":1,"name":"Soil_Dirt"},{"x":-12,"y":2,"z":1,"name":"Soil_Dirt"},{"x":-12,"y":3,"z":1,"name":"Soil_Dirt"},{"x":-12,"y":4,"z":1,"name":"Soil_Dirt"},{"x":-12,"y":5,"z":1,"name":"Rock_Stone_Cobble"},{"x":-12,"y":0,"z":2,"name":"Soil_Dirt"},{"x":-12,"y":1,"z":2,"name":"Soil_Dirt"},{"x":-12,"y":2,"z":2,"name":"Soil_Dirt"},{"x":-12,"y":3,"z":2,"name":"Soil_Dirt"},{"x":-12,"y":4,"z":2,"name":"Soil_Dirt"},{"x":-12,"y":5,"z":2,"name":"Rock_Stone_Cobble_Mossy"},{"x":-12,"y":0,"z":3,"name":"Soil_Dirt"},{"x":-12,"y":1,"z":3,"name":"Soil_Dirt"},{"x":-12,"y":2,"z":3,"name":"Soil_Dirt"},{"x":-12,"y":3,"z":3,"name":"Soil_Dirt"},{"x":-12,"y":4,"z":3,"name":"Soil_Dirt"},{"x":-12,"y":5,"z":3,"name":"Rock_Stone_Cobble"},{"x":-12,"y":0,"z":4,"name":"Soil_Dirt"},{"x":-12,"y":1,"z":4,"name":"Soil_Dirt"},{"x":-12,"y":2,"z":4,"name":"Soil_Dirt"},{"x":-12,"y":3,"z":4,"name":"Soil_Dirt"},{"x":-12,"y":4,"z":4,"name":"Soil_Dirt"},{"x":-12,"y":5,"z":4,"name":"Rock_Stone_Cobble_Mossy"},{"x":-12,"y":0,"z":5,"name":"Soil_Dirt"},{"x":-12,"y":1,"z":5,"name":"Soil_Dirt"},{"x":-12,"y":2,"z":5,"name":"Soil_Dirt"},{"x":-12,"y":3,"z":5,"name":"Soil_Dirt"},{"x":-12,"y":4,"z":5,"name":"Soil_Dirt"},{"x":-12,"y":5,"z":5,"name":"Rock_Stone_Cobble_Mossy"},{"x":-12,"y":9,"z":5,"name":"Cloth_Modern_Red_Roof_Vertical_Flap","support":15,"rotation":1},{"x":-12,"y":0,"z":6,"name":"Soil_Dirt"},{"x":-12,"y":1,"z":6,"name":"Soil_Dirt"},{"x":-12,"y":2,"z":6,"name":"Soil_Dirt"},{"x":-12,"y":3,"z":6,"name":"Soil_Dirt"},{"x":-12,"y":4,"z":6,"name":"Soil_Dirt"},{"x":-12,"y":5,"z":6,"name":"Rock_Stone_Cobble"},{"x":-12,"y":0,"z":7,"name":"Soil_Dirt"},{"x":-12,"y":1,"z":7,"name":"Soil_Dirt"},{"x":-12,"y":2,"z":7,"name":"Soil_Dirt"},{"x":-12,"y":3,"z":7,"name":"Soil_Dirt"},{"x":-12,"y":4,"z":7,"name":"Soil_Dirt"},{"x":-12,"y":5,"z":7,"name":"Rock_Stone_Cobble","support":15},{"x":-12,"y":0,"z":8,"name":"Soil_Dirt"},{"x":-12,"y":1,"z":8,"name":"Soil_Dirt"},{"x":-12,"y":2,"z":8,"name":"Soil_Dirt"},{"x":-12,"y":3,"z":8,"name":"Soil_Dirt"},{"x":-12,"y":4,"z":8,"name":"Soil_Dirt"},{"x":-12,"y":5,"z":8,"name":"Rock_Stone_Cobble"},{"x":-12,"y":0,"z":9,"name":"Soil_Dirt"},{"x":-12,"y":1,"z":9,"name":"Soil_Dirt"},{"x":-12,"y":2,"z":9,"name":"Soil_Dirt"},{"x":-12,"y":3,"z":9,"name":"Soil_Dirt"},{"x":-12,"y":4,"z":9,"name":"Soil_Dirt"},{"x":-12,"y":5,"z":9,"name":"Rock_Stone_Cobble_Mossy"},{"x":-12,"y":0,"z":10,"name":"Soil_Dirt"},{"x":-12,"y":1,"z":10,"name":"Soil_Dirt"},{"x":-12,"y":2,"z":10,"name":"Soil_Dirt"},{"x":-12,"y":3,"z":10,"name":"Soil_Dirt"},{"x":-12,"y":4,"z":10,"name":"Soil_Dirt"},{"x":-12,"y":5,"z":10,"name":"Rock_Stone_Cobble"},{"x":-12,"y":0,"z":11,"name":"Soil_Dirt"},{"x":-12,"y":1,"z":11,"name":"Soil_Dirt"},{"x":-12,"y":2,"z":11,"name":"Soil_Dirt"},{"x":-12,"y":3,"z":11,"name":"Soil_Dirt"},{"x":-12,"y":4,"z":11,"name":"Soil_Dirt"},{"x":-12,"y":5,"z":11,"name":"Rock_Stone_Cobble_Mossy"},{"x":-12,"y":0,"z":12,"name":"Soil_Dirt"},{"x":-12,"y":1,"z":12,"name":"Soil_Dirt"},{"x":-12,"y":2,"z":12,"name":"Soil_Dirt"},{"x":-12,"y":3,"z":12,"name":"Soil_Dirt"},{"x":-12,"y":4,"z":12,"name":"Soil_Dirt"},{"x":-12,"y":5,"z":12,"name":"Rock_Stone_Cobble"},{"x":-12,"y":0,"z":13,"name":"Soil_Dirt"},{"x":-12,"y":1,"z":13,"name":"Soil_Dirt"},{"x":-12,"y":2,"z":13,"name":"Soil_Dirt"},{"x":-12,"y":3,"z":13,"name":"Soil_Dirt"},{"x":-12,"y":4,"z":13,"name":"Soil_Dirt"},{"x":-12,"y":5,"z":13,"name":"Rock_Stone_Cobble"},{"x":-12,"y":0,"z":14,"name":"Soil_Dirt"},{"x":-12,"y":1,"z":14,"name":"Soil_Dirt"},{"x":-12,"y":2,"z":14,"name":"Soil_Dirt"},{"x":-12,"y":3,"z":14,"name":"Soil_Dirt"},{"x":-12,"y":4,"z":14,"name":"Soil_Dirt"},{"x":-12,"y":5,"z":14,"name":"Rock_Stone_Cobble"},{"x":-12,"y":6,"z":14,"name":"Furniture_Tavern_Barrel","support":15},{"x":-12,"y":0,"z":15,"name":"Soil_Dirt"},{"x":-12,"y":1,"z":15,"name":"Soil_Dirt"},{"x":-12,"y":2,"z":15,"name":"Soil_Dirt"},{"x":-12,"y":3,"z":15,"name":"Soil_Dirt"},{"x":-12,"y":4,"z":15,"name":"Soil_Dirt"},{"x":-12,"y":5,"z":15,"name":"Rock_Stone_Brick_Smooth","support":15},{"x":-11,"y":0,"z":-14,"name":"Soil_Dirt"},{"x":-11,"y":1,"z":-14,"name":"Soil_Dirt"},{"x":-11,"y":2,"z":-14,"name":"Soil_Dirt"},{"x":-11,"y":3,"z":-14,"name":"Soil_Dirt"},{"x":-11,"y":4,"z":-14,"name":"Soil_Dirt"},{"x":-11,"y":5,"z":-14,"name":"Rock_Stone_Brick_Smooth","support":15},{"x":-11,"y":0,"z":-13,"name":"Soil_Dirt"},{"x":-11,"y":1,"z":-13,"name":"Soil_Dirt"},{"x":-11,"y":2,"z":-13,"name":"Soil_Dirt"},{"x":-11,"y":3,"z":-13,"name":"Soil_Dirt"},{"x":-11,"y":4,"z":-13,"name":"Soil_Dirt"},{"x":-11,"y":5,"z":-13,"name":"Rock_Stone_Cobble"},{"x":-11,"y":0,"z":-12,"name":"Soil_Dirt"},{"x":-11,"y":1,"z":-12,"name":"Soil_Dirt"},{"x":-11,"y":2,"z":-12,"name":"Soil_Dirt"},{"x":-11,"y":3,"z":-12,"name":"Soil_Dirt"},{"x":-11,"y":4,"z":-12,"name":"Soil_Dirt"},{"x":-11,"y":5,"z":-12,"name":"Rock_Stone_Cobble"},{"x":-11,"y":0,"z":-11,"name":"Soil_Dirt"},{"x":-11,"y":1,"z":-11,"name":"Soil_Dirt"},{"x":-11,"y":2,"z":-11,"name":"Soil_Dirt"},{"x":-11,"y":3,"z":-11,"name":"Soil_Dirt"},{"x":-11,"y":4,"z":-11,"name":"Soil_Dirt"},{"x":-11,"y":5,"z":-11,"name":"Rock_Stone_Cobble"},{"x":-11,"y":0,"z":-10,"name":"Soil_Dirt"},{"x":-11,"y":1,"z":-10,"name":"Soil_Dirt"},{"x":-11,"y":2,"z":-10,"name":"Soil_Dirt"},{"x":-11,"y":3,"z":-10,"name":"Soil_Dirt"},{"x":-11,"y":4,"z":-10,"name":"Soil_Dirt"},{"x":-11,"y":5,"z":-10,"name":"Rock_Stone_Cobble"},{"x":-11,"y":0,"z":-9,"name":"Soil_Dirt"},{"x":-11,"y":1,"z":-9,"name":"Soil_Dirt"},{"x":-11,"y":2,"z":-9,"name":"Soil_Dirt"},{"x":-11,"y":3,"z":-9,"name":"Soil_Dirt"},{"x":-11,"y":4,"z":-9,"name":"Soil_Dirt"},{"x":-11,"y":5,"z":-9,"name":"Rock_Stone_Cobble_Mossy"},{"x":-11,"y":0,"z":-8,"name":"Soil_Dirt"},{"x":-11,"y":1,"z":-8,"name":"Soil_Dirt"},{"x":-11,"y":2,"z":-8,"name":"Soil_Dirt"},{"x":-11,"y":3,"z":-8,"name":"Soil_Dirt"},{"x":-11,"y":4,"z":-8,"name":"Soil_Dirt"},{"x":-11,"y":5,"z":-8,"name":"Rock_Stone_Cobble"},{"x":-11,"y":0,"z":-7,"name":"Soil_Dirt"},{"x":-11,"y":1,"z":-7,"name":"Soil_Dirt"},{"x":-11,"y":2,"z":-7,"name":"Soil_Dirt"},{"x":-11,"y":3,"z":-7,"name":"Soil_Dirt"},{"x":-11,"y":4,"z":-7,"name":"Soil_Dirt"},{"x":-11,"y":5,"z":-7,"name":"Soil_Pathway"},{"x":-11,"y":0,"z":-6,"name":"Soil_Dirt"},{"x":-11,"y":1,"z":-6,"name":"Soil_Dirt"},{"x":-11,"y":2,"z":-6,"name":"Soil_Dirt"},{"x":-11,"y":3,"z":-6,"name":"Soil_Dirt"},{"x":-11,"y":4,"z":-6,"name":"Soil_Dirt"},{"x":-11,"y":5,"z":-6,"name":"Soil_Pathway"},{"x":-11,"y":0,"z":-5,"name":"Soil_Dirt"},{"x":-11,"y":1,"z":-5,"name":"Soil_Dirt"},{"x":-11,"y":2,"z":-5,"name":"Soil_Dirt"},{"x":-11,"y":3,"z":-5,"name":"Soil_Dirt"},{"x":-11,"y":4,"z":-5,"name":"Soil_Dirt"},{"x":-11,"y":5,"z":-5,"name":"Soil_Pathway"},{"x":-11,"y":0,"z":-4,"name":"Soil_Dirt"},{"x":-11,"y":1,"z":-4,"name":"Soil_Dirt"},{"x":-11,"y":2,"z":-4,"name":"Soil_Dirt"},{"x":-11,"y":3,"z":-4,"name":"Soil_Dirt"},{"x":-11,"y":4,"z":-4,"name":"Soil_Dirt"},{"x":-11,"y":5,"z":-4,"name":"Soil_Pathway"},{"x":-11,"y":0,"z":-3,"name":"Soil_Dirt"},{"x":-11,"y":1,"z":-3,"name":"Soil_Dirt"},{"x":-11,"y":2,"z":-3,"name":"Soil_Dirt"},{"x":-11,"y":3,"z":-3,"name":"Soil_Dirt"},{"x":-11,"y":4,"z":-3,"name":"Soil_Dirt"},{"x":-11,"y":5,"z":-3,"name":"Soil_Dirt"},{"x":-11,"y":0,"z":-2,"name":"Soil_Dirt"},{"x":-11,"y":1,"z":-2,"name":"Soil_Dirt"},{"x":-11,"y":2,"z":-2,"name":"Soil_Dirt"},{"x":-11,"y":3,"z":-2,"name":"Soil_Dirt"},{"x":-11,"y":4,"z":-2,"name":"Soil_Dirt"},{"x":-11,"y":5,"z":-2,"name":"Soil_Mud"},{"x":-11,"y":0,"z":-1,"name":"Soil_Dirt"},{"x":-11,"y":1,"z":-1,"name":"Soil_Dirt"},{"x":-11,"y":2,"z":-1,"name":"Soil_Dirt"},{"x":-11,"y":3,"z":-1,"name":"Soil_Dirt"},{"x":-11,"y":4,"z":-1,"name":"Soil_Dirt"},{"x":-11,"y":5,"z":-1,"name":"Rock_Stone_Cobble"},{"x":-11,"y":0,"z":0,"name":"Soil_Dirt"},{"x":-11,"y":1,"z":0,"name":"Soil_Dirt"},{"x":-11,"y":2,"z":0,"name":"Soil_Dirt"},{"x":-11,"y":3,"z":0,"name":"Soil_Dirt"},{"x":-11,"y":4,"z":0,"name":"Soil_Dirt"},{"x":-11,"y":5,"z":0,"name":"Rock_Stone_Cobble_Mossy"},{"x":-11,"y":0,"z":1,"name":"Soil_Dirt"},{"x":-11,"y":1,"z":1,"name":"Soil_Dirt"},{"x":-11,"y":2,"z":1,"name":"Soil_Dirt"},{"x":-11,"y":3,"z":1,"name":"Soil_Dirt"},{"x":-11,"y":4,"z":1,"name":"Soil_Dirt"},{"x":-11,"y":5,"z":1,"name":"Rock_Stone_Cobble"},{"x":-11,"y":0,"z":2,"name":"Soil_Dirt"},{"x":-11,"y":1,"z":2,"name":"Soil_Dirt"},{"x":-11,"y":2,"z":2,"name":"Soil_Dirt"},{"x":-11,"y":3,"z":2,"name":"Soil_Dirt"},{"x":-11,"y":4,"z":2,"name":"Soil_Dirt"},{"x":-11,"y":5,"z":2,"name":"Rock_Stone_Cobble"},{"x":-11,"y":0,"z":3,"name":"Soil_Dirt"},{"x":-11,"y":1,"z":3,"name":"Soil_Dirt"},{"x":-11,"y":2,"z":3,"name":"Soil_Dirt"},{"x":-11,"y":3,"z":3,"name":"Soil_Dirt"},{"x":-11,"y":4,"z":3,"name":"Soil_Dirt"},{"x":-11,"y":5,"z":3,"name":"Rock_Stone_Cobble_Mossy"},{"x":-11,"y":0,"z":4,"name":"Soil_Dirt"},{"x":-11,"y":1,"z":4,"name":"Soil_Dirt"},{"x":-11,"y":2,"z":4,"name":"Soil_Dirt"},{"x":-11,"y":3,"z":4,"name":"Soil_Dirt"},{"x":-11,"y":4,"z":4,"name":"Soil_Dirt"},{"x":-11,"y":5,"z":4,"name":"Soil_Mud"},{"x":-11,"y":0,"z":5,"name":"Soil_Dirt"},{"x":-11,"y":1,"z":5,"name":"Soil_Dirt"},{"x":-11,"y":2,"z":5,"name":"Soil_Dirt"},{"x":-11,"y":3,"z":5,"name":"Soil_Dirt"},{"x":-11,"y":4,"z":5,"name":"Soil_Dirt"},{"x":-11,"y":5,"z":5,"name":"Soil_Dirt"},{"x":-11,"y":0,"z":6,"name":"Soil_Dirt"},{"x":-11,"y":1,"z":6,"name":"Soil_Dirt"},{"x":-11,"y":2,"z":6,"name":"Soil_Dirt"},{"x":-11,"y":3,"z":6,"name":"Soil_Dirt"},{"x":-11,"y":4,"z":6,"name":"Soil_Dirt"},{"x":-11,"y":5,"z":6,"name":"Soil_Pathway","support":15},{"x":-11,"y":0,"z":7,"name":"Soil_Dirt"},{"x":-11,"y":1,"z":7,"name":"Soil_Dirt"},{"x":-11,"y":2,"z":7,"name":"Soil_Dirt"},{"x":-11,"y":3,"z":7,"name":"Soil_Dirt"},{"x":-11,"y":4,"z":7,"name":"Soil_Dirt"},{"x":-11,"y":5,"z":7,"name":"Soil_Mud"},{"x":-11,"y":0,"z":8,"name":"Soil_Dirt"},{"x":-11,"y":1,"z":8,"name":"Soil_Dirt"},{"x":-11,"y":2,"z":8,"name":"Soil_Dirt"},{"x":-11,"y":3,"z":8,"name":"Soil_Dirt"},{"x":-11,"y":4,"z":8,"name":"Soil_Dirt"},{"x":-11,"y":5,"z":8,"name":"Soil_Pathway"},{"x":-11,"y":0,"z":9,"name":"Soil_Dirt"},{"x":-11,"y":1,"z":9,"name":"Soil_Dirt"},{"x":-11,"y":2,"z":9,"name":"Soil_Dirt"},{"x":-11,"y":3,"z":9,"name":"Soil_Dirt"},{"x":-11,"y":4,"z":9,"name":"Soil_Dirt"},{"x":-11,"y":5,"z":9,"name":"Soil_Pathway"},{"x":-11,"y":0,"z":10,"name":"Soil_Dirt"},{"x":-11,"y":1,"z":10,"name":"Soil_Dirt"},{"x":-11,"y":2,"z":10,"name":"Soil_Dirt"},{"x":-11,"y":3,"z":10,"name":"Soil_Dirt"},{"x":-11,"y":4,"z":10,"name":"Soil_Dirt"},{"x":-11,"y":5,"z":10,"name":"Soil_Pathway"},{"x":-11,"y":0,"z":11,"name":"Soil_Dirt"},{"x":-11,"y":1,"z":11,"name":"Soil_Dirt"},{"x":-11,"y":2,"z":11,"name":"Soil_Dirt"},{"x":-11,"y":3,"z":11,"name":"Soil_Dirt"},{"x":-11,"y":4,"z":11,"name":"Soil_Dirt"},{"x":-11,"y":5,"z":11,"name":"Soil_Pathway"},{"x":-11,"y":0,"z":12,"name":"Soil_Dirt"},{"x":-11,"y":1,"z":12,"name":"Soil_Dirt"},{"x":-11,"y":2,"z":12,"name":"Soil_Dirt"},{"x":-11,"y":3,"z":12,"name":"Soil_Dirt"},{"x":-11,"y":4,"z":12,"name":"Soil_Dirt"},{"x":-11,"y":5,"z":12,"name":"Rock_Stone_Cobble"},{"x":-11,"y":0,"z":13,"name":"Soil_Dirt"},{"x":-11,"y":1,"z":13,"name":"Soil_Dirt"},{"x":-11,"y":2,"z":13,"name":"Soil_Dirt"},{"x":-11,"y":3,"z":13,"name":"Soil_Dirt"},{"x":-11,"y":4,"z":13,"name":"Soil_Dirt"},{"x":-11,"y":5,"z":13,"name":"Rock_Stone_Cobble_Mossy"},{"x":-11,"y":0,"z":14,"name":"Soil_Dirt"},{"x":-11,"y":1,"z":14,"name":"Soil_Dirt"},{"x":-11,"y":2,"z":14,"name":"Soil_Dirt"},{"x":-11,"y":3,"z":14,"name":"Soil_Dirt"},{"x":-11,"y":4,"z":14,"name":"Soil_Dirt"},{"x":-11,"y":5,"z":14,"name":"Rock_Stone_Cobble"},{"x":-11,"y":0,"z":15,"name":"Soil_Dirt"},{"x":-11,"y":1,"z":15,"name":"Soil_Dirt"},{"x":-11,"y":2,"z":15,"name":"Soil_Dirt"},{"x":-11,"y":3,"z":15,"name":"Soil_Dirt"},{"x":-11,"y":4,"z":15,"name":"Soil_Dirt"},{"x":-11,"y":5,"z":15,"name":"Rock_Stone_Brick_Smooth","support":15},{"x":-10,"y":0,"z":-14,"name":"Soil_Dirt"},{"x":-10,"y":1,"z":-14,"name":"Soil_Dirt"},{"x":-10,"y":2,"z":-14,"name":"Soil_Dirt"},{"x":-10,"y":3,"z":-14,"name":"Soil_Dirt"},{"x":-10,"y":4,"z":-14,"name":"Soil_Dirt"},{"x":-10,"y":5,"z":-14,"name":"Rock_Stone_Brick_Smooth","support":15},{"x":-10,"y":0,"z":-13,"name":"Soil_Dirt"},{"x":-10,"y":1,"z":-13,"name":"Soil_Dirt"},{"x":-10,"y":2,"z":-13,"name":"Soil_Dirt"},{"x":-10,"y":3,"z":-13,"name":"Soil_Dirt"},{"x":-10,"y":4,"z":-13,"name":"Soil_Dirt"},{"x":-10,"y":5,"z":-13,"name":"Rock_Stone_Cobble"},{"x":-10,"y":0,"z":-12,"name":"Soil_Dirt"},{"x":-10,"y":1,"z":-12,"name":"Soil_Dirt"},{"x":-10,"y":2,"z":-12,"name":"Soil_Dirt"},{"x":-10,"y":3,"z":-12,"name":"Soil_Dirt"},{"x":-10,"y":4,"z":-12,"name":"Soil_Dirt"},{"x":-10,"y":5,"z":-12,"name":"Rock_Stone_Cobble"},{"x":-10,"y":0,"z":-11,"name":"Soil_Dirt"},{"x":-10,"y":1,"z":-11,"name":"Soil_Dirt"},{"x":-10,"y":2,"z":-11,"name":"Soil_Dirt"},{"x":-10,"y":3,"z":-11,"name":"Soil_Dirt"},{"x":-10,"y":4,"z":-11,"name":"Soil_Dirt"},{"x":-10,"y":5,"z":-11,"name":"Rock_Stone_Cobble"},{"x":-10,"y":0,"z":-10,"name":"Soil_Dirt"},{"x":-10,"y":1,"z":-10,"name":"Soil_Dirt"},{"x":-10,"y":2,"z":-10,"name":"Soil_Dirt"},{"x":-10,"y":3,"z":-10,"name":"Soil_Dirt"},{"x":-10,"y":4,"z":-10,"name":"Soil_Dirt"},{"x":-10,"y":5,"z":-10,"name":"Rock_Stone_Cobble_Mossy"},{"x":-10,"y":0,"z":-9,"name":"Soil_Dirt"},{"x":-10,"y":1,"z":-9,"name":"Soil_Dirt"},{"x":-10,"y":2,"z":-9,"name":"Soil_Dirt"},{"x":-10,"y":3,"z":-9,"name":"Soil_Dirt"},{"x":-10,"y":4,"z":-9,"name":"Soil_Dirt"},{"x":-10,"y":5,"z":-9,"name":"Soil_Mud"},{"x":-10,"y":0,"z":-8,"name":"Soil_Dirt"},{"x":-10,"y":1,"z":-8,"name":"Soil_Dirt"},{"x":-10,"y":2,"z":-8,"name":"Soil_Dirt"},{"x":-10,"y":3,"z":-8,"name":"Soil_Dirt"},{"x":-10,"y":4,"z":-8,"name":"Soil_Dirt"},{"x":-10,"y":5,"z":-8,"name":"Soil_Dirt"},{"x":-10,"y":0,"z":-7,"name":"Soil_Dirt"},{"x":-10,"y":1,"z":-7,"name":"Soil_Dirt"},{"x":-10,"y":2,"z":-7,"name":"Soil_Dirt"},{"x":-10,"y":3,"z":-7,"name":"Soil_Dirt"},{"x":-10,"y":4,"z":-7,"name":"Soil_Dirt"},{"x":-10,"y":5,"z":-7,"name":"Soil_Pathway"},{"x":-10,"y":0,"z":-6,"name":"Soil_Dirt"},{"x":-10,"y":1,"z":-6,"name":"Soil_Dirt"},{"x":-10,"y":2,"z":-6,"name":"Soil_Dirt"},{"x":-10,"y":3,"z":-6,"name":"Soil_Dirt"},{"x":-10,"y":4,"z":-6,"name":"Soil_Dirt"},{"x":-10,"y":5,"z":-6,"name":"Soil_Pathway"},{"x":-10,"y":0,"z":-5,"name":"Soil_Dirt"},{"x":-10,"y":1,"z":-5,"name":"Soil_Dirt"},{"x":-10,"y":2,"z":-5,"name":"Soil_Dirt"},{"x":-10,"y":3,"z":-5,"name":"Soil_Dirt"},{"x":-10,"y":4,"z":-5,"name":"Soil_Dirt"},{"x":-10,"y":5,"z":-5,"name":"Soil_Pathway"},{"x":-10,"y":0,"z":-4,"name":"Soil_Dirt"},{"x":-10,"y":1,"z":-4,"name":"Soil_Dirt"},{"x":-10,"y":2,"z":-4,"name":"Soil_Dirt"},{"x":-10,"y":3,"z":-4,"name":"Soil_Dirt"},{"x":-10,"y":4,"z":-4,"name":"Soil_Dirt"},{"x":-10,"y":5,"z":-4,"name":"Soil_Dirt"},{"x":-10,"y":0,"z":-3,"name":"Soil_Dirt"},{"x":-10,"y":1,"z":-3,"name":"Soil_Dirt"},{"x":-10,"y":2,"z":-3,"name":"Soil_Dirt"},{"x":-10,"y":3,"z":-3,"name":"Soil_Dirt"},{"x":-10,"y":4,"z":-3,"name":"Soil_Dirt"},{"x":-10,"y":5,"z":-3,"name":"Soil_Dirt"},{"x":-10,"y":0,"z":-2,"name":"Soil_Dirt"},{"x":-10,"y":1,"z":-2,"name":"Soil_Dirt"},{"x":-10,"y":2,"z":-2,"name":"Soil_Dirt"},{"x":-10,"y":3,"z":-2,"name":"Soil_Dirt"},{"x":-10,"y":4,"z":-2,"name":"Soil_Dirt"},{"x":-10,"y":5,"z":-2,"name":"Soil_Pathway"},{"x":-10,"y":0,"z":-1,"name":"Soil_Dirt"},{"x":-10,"y":1,"z":-1,"name":"Soil_Dirt"},{"x":-10,"y":2,"z":-1,"name":"Soil_Dirt"},{"x":-10,"y":3,"z":-1,"name":"Soil_Dirt"},{"x":-10,"y":4,"z":-1,"name":"Soil_Dirt"},{"x":-10,"y":5,"z":-1,"name":"Soil_Mud"},{"x":-10,"y":0,"z":0,"name":"Soil_Dirt"},{"x":-10,"y":1,"z":0,"name":"Soil_Dirt"},{"x":-10,"y":2,"z":0,"name":"Soil_Dirt"},{"x":-10,"y":3,"z":0,"name":"Soil_Dirt"},{"x":-10,"y":4,"z":0,"name":"Soil_Dirt"},{"x":-10,"y":5,"z":0,"name":"Soil_Mud"},{"x":-10,"y":0,"z":1,"name":"Soil_Dirt"},{"x":-10,"y":1,"z":1,"name":"Soil_Dirt"},{"x":-10,"y":2,"z":1,"name":"Soil_Dirt"},{"x":-10,"y":3,"z":1,"name":"Soil_Dirt"},{"x":-10,"y":4,"z":1,"name":"Soil_Dirt"},{"x":-10,"y":5,"z":1,"name":"Soil_Pathway"},{"x":-10,"y":0,"z":2,"name":"Soil_Dirt"},{"x":-10,"y":1,"z":2,"name":"Soil_Dirt"},{"x":-10,"y":2,"z":2,"name":"Soil_Dirt"},{"x":-10,"y":3,"z":2,"name":"Soil_Dirt"},{"x":-10,"y":4,"z":2,"name":"Soil_Dirt"},{"x":-10,"y":5,"z":2,"name":"Soil_Pathway"},{"x":-10,"y":0,"z":3,"name":"Soil_Dirt"},{"x":-10,"y":1,"z":3,"name":"Soil_Dirt"},{"x":-10,"y":2,"z":3,"name":"Soil_Dirt"},{"x":-10,"y":3,"z":3,"name":"Soil_Dirt"},{"x":-10,"y":4,"z":3,"name":"Soil_Dirt"},{"x":-10,"y":5,"z":3,"name":"Soil_Pathway"},{"x":-10,"y":0,"z":4,"name":"Soil_Dirt"},{"x":-10,"y":1,"z":4,"name":"Soil_Dirt"},{"x":-10,"y":2,"z":4,"name":"Soil_Dirt"},{"x":-10,"y":3,"z":4,"name":"Soil_Dirt"},{"x":-10,"y":4,"z":4,"name":"Soil_Dirt"},{"x":-10,"y":5,"z":4,"name":"Soil_Dirt"},{"x":-10,"y":0,"z":5,"name":"Soil_Dirt"},{"x":-10,"y":1,"z":5,"name":"Soil_Dirt"},{"x":-10,"y":2,"z":5,"name":"Soil_Dirt"},{"x":-10,"y":3,"z":5,"name":"Soil_Dirt"},{"x":-10,"y":4,"z":5,"name":"Soil_Dirt"},{"x":-10,"y":5,"z":5,"name":"Soil_Pathway"},{"x":-10,"y":0,"z":6,"name":"Soil_Dirt"},{"x":-10,"y":1,"z":6,"name":"Soil_Dirt"},{"x":-10,"y":2,"z":6,"name":"Soil_Dirt"},{"x":-10,"y":3,"z":6,"name":"Soil_Dirt"},{"x":-10,"y":4,"z":6,"name":"Soil_Dirt"},{"x":-10,"y":5,"z":6,"name":"Soil_Dirt"},{"x":-10,"y":0,"z":7,"name":"Soil_Dirt"},{"x":-10,"y":1,"z":7,"name":"Soil_Dirt"},{"x":-10,"y":2,"z":7,"name":"Soil_Dirt"},{"x":-10,"y":3,"z":7,"name":"Soil_Dirt"},{"x":-10,"y":4,"z":7,"name":"Soil_Dirt"},{"x":-10,"y":5,"z":7,"name":"Soil_Mud"},{"x":-10,"y":0,"z":8,"name":"Soil_Dirt"},{"x":-10,"y":1,"z":8,"name":"Soil_Dirt"},{"x":-10,"y":2,"z":8,"name":"Soil_Dirt"},{"x":-10,"y":3,"z":8,"name":"Soil_Dirt"},{"x":-10,"y":4,"z":8,"name":"Soil_Dirt"},{"x":-10,"y":5,"z":8,"name":"Soil_Dirt","support":15},{"x":-10,"y":0,"z":9,"name":"Soil_Dirt"},{"x":-10,"y":1,"z":9,"name":"Soil_Dirt"},{"x":-10,"y":2,"z":9,"name":"Soil_Dirt"},{"x":-10,"y":3,"z":9,"name":"Soil_Dirt"},{"x":-10,"y":4,"z":9,"name":"Soil_Dirt"},{"x":-10,"y":5,"z":9,"name":"Soil_Dirt","support":15},{"x":-10,"y":0,"z":10,"name":"Soil_Dirt"},{"x":-10,"y":1,"z":10,"name":"Soil_Dirt"},{"x":-10,"y":2,"z":10,"name":"Soil_Dirt"},{"x":-10,"y":3,"z":10,"name":"Soil_Dirt"},{"x":-10,"y":4,"z":10,"name":"Soil_Dirt"},{"x":-10,"y":5,"z":10,"name":"Soil_Dirt"},{"x":-10,"y":0,"z":11,"name":"Soil_Dirt"},{"x":-10,"y":1,"z":11,"name":"Soil_Dirt"},{"x":-10,"y":2,"z":11,"name":"Soil_Dirt"},{"x":-10,"y":3,"z":11,"name":"Soil_Dirt"},{"x":-10,"y":4,"z":11,"name":"Soil_Dirt"},{"x":-10,"y":5,"z":11,"name":"Soil_Pathway"},{"x":-10,"y":0,"z":12,"name":"Soil_Dirt"},{"x":-10,"y":1,"z":12,"name":"Soil_Dirt"},{"x":-10,"y":2,"z":12,"name":"Soil_Dirt"},{"x":-10,"y":3,"z":12,"name":"Soil_Dirt"},{"x":-10,"y":4,"z":12,"name":"Soil_Dirt"},{"x":-10,"y":5,"z":12,"name":"Soil_Dirt"},{"x":-10,"y":0,"z":13,"name":"Soil_Dirt"},{"x":-10,"y":1,"z":13,"name":"Soil_Dirt"},{"x":-10,"y":2,"z":13,"name":"Soil_Dirt"},{"x":-10,"y":3,"z":13,"name":"Soil_Dirt"},{"x":-10,"y":4,"z":13,"name":"Soil_Dirt"},{"x":-10,"y":5,"z":13,"name":"Rock_Stone_Cobble_Mossy"},{"x":-10,"y":0,"z":14,"name":"Soil_Dirt"},{"x":-10,"y":1,"z":14,"name":"Soil_Dirt"},{"x":-10,"y":2,"z":14,"name":"Soil_Dirt"},{"x":-10,"y":3,"z":14,"name":"Soil_Dirt"},{"x":-10,"y":4,"z":14,"name":"Soil_Dirt"},{"x":-10,"y":5,"z":14,"name":"Rock_Stone_Cobble_Mossy"},{"x":-10,"y":0,"z":15,"name":"Soil_Dirt"},{"x":-10,"y":1,"z":15,"name":"Soil_Dirt"},{"x":-10,"y":2,"z":15,"name":"Soil_Dirt"},{"x":-10,"y":3,"z":15,"name":"Soil_Dirt"},{"x":-10,"y":4,"z":15,"name":"Soil_Dirt"},{"x":-10,"y":5,"z":15,"name":"Rock_Stone_Brick_Smooth","support":15},{"x":-9,"y":0,"z":-14,"name":"Soil_Dirt"},{"x":-9,"y":1,"z":-14,"name":"Soil_Dirt"},{"x":-9,"y":2,"z":-14,"name":"Soil_Dirt"},{"x":-9,"y":3,"z":-14,"name":"Soil_Dirt"},{"x":-9,"y":4,"z":-14,"name":"Soil_Dirt"},{"x":-9,"y":5,"z":-14,"name":"Rock_Stone_Brick_Smooth","support":15},{"x":-9,"y":0,"z":-13,"name":"Soil_Dirt"},{"x":-9,"y":1,"z":-13,"name":"Soil_Dirt"},{"x":-9,"y":2,"z":-13,"name":"Soil_Dirt"},{"x":-9,"y":3,"z":-13,"name":"Soil_Dirt"},{"x":-9,"y":4,"z":-13,"name":"Soil_Dirt"},{"x":-9,"y":5,"z":-13,"name":"Rock_Stone_Cobble"},{"x":-9,"y":6,"z":-13,"name":"Furniture_Tavern_Bench","support":15,"rotation":2},{"x":-9,"y":0,"z":-12,"name":"Soil_Dirt"},{"x":-9,"y":1,"z":-12,"name":"Soil_Dirt"},{"x":-9,"y":2,"z":-12,"name":"Soil_Dirt"},{"x":-9,"y":3,"z":-12,"name":"Soil_Dirt"},{"x":-9,"y":4,"z":-12,"name":"Soil_Dirt"},{"x":-9,"y":5,"z":-12,"name":"Rock_Stone_Cobble"},{"x":-9,"y":0,"z":-11,"name":"Soil_Dirt"},{"x":-9,"y":1,"z":-11,"name":"Soil_Dirt"},{"x":-9,"y":2,"z":-11,"name":"Soil_Dirt"},{"x":-9,"y":3,"z":-11,"name":"Soil_Dirt"},{"x":-9,"y":4,"z":-11,"name":"Soil_Dirt"},{"x":-9,"y":5,"z":-11,"name":"Rock_Stone_Cobble"},{"x":-9,"y":0,"z":-10,"name":"Soil_Dirt"},{"x":-9,"y":1,"z":-10,"name":"Soil_Dirt"},{"x":-9,"y":2,"z":-10,"name":"Soil_Dirt"},{"x":-9,"y":3,"z":-10,"name":"Soil_Dirt"},{"x":-9,"y":4,"z":-10,"name":"Soil_Dirt"},{"x":-9,"y":5,"z":-10,"name":"Soil_Mud"},{"x":-9,"y":0,"z":-9,"name":"Soil_Dirt"},{"x":-9,"y":1,"z":-9,"name":"Soil_Dirt"},{"x":-9,"y":2,"z":-9,"name":"Soil_Dirt"},{"x":-9,"y":3,"z":-9,"name":"Soil_Dirt"},{"x":-9,"y":4,"z":-9,"name":"Soil_Dirt"},{"x":-9,"y":5,"z":-9,"name":"Soil_Pathway"},{"x":-9,"y":6,"z":-9,"name":"*Wood_Redwood_Fence_State_Definitions_Corner","rotation":1},{"x":-9,"y":7,"z":-9,"name":"Wood_Redwood_Beam","support":15},{"x":-9,"y":8,"z":-9,"name":"Deco_Lantern","support":15},{"x":-9,"y":0,"z":-8,"name":"Soil_Dirt"},{"x":-9,"y":1,"z":-8,"name":"Soil_Dirt"},{"x":-9,"y":2,"z":-8,"name":"Soil_Dirt"},{"x":-9,"y":3,"z":-8,"name":"Soil_Dirt"},{"x":-9,"y":4,"z":-8,"name":"Soil_Dirt"},{"x":-9,"y":5,"z":-8,"name":"Soil_Mud"},{"x":-9,"y":6,"z":-8,"name":"Wood_Redwood_Fence","support":15,"rotation":3},{"x":-9,"y":0,"z":-7,"name":"Soil_Dirt"},{"x":-9,"y":1,"z":-7,"name":"Soil_Dirt"},{"x":-9,"y":2,"z":-7,"name":"Soil_Dirt"},{"x":-9,"y":3,"z":-7,"name":"Soil_Dirt"},{"x":-9,"y":4,"z":-7,"name":"Soil_Dirt"},{"x":-9,"y":5,"z":-7,"name":"Soil_Dirt"},{"x":-9,"y":6,"z":-7,"name":"Wood_Redwood_Fence","support":15,"rotation":3},{"x":-9,"y":0,"z":-6,"name":"Soil_Dirt"},{"x":-9,"y":1,"z":-6,"name":"Soil_Dirt"},{"x":-9,"y":2,"z":-6,"name":"Soil_Dirt"},{"x":-9,"y":3,"z":-6,"name":"Soil_Dirt"},{"x":-9,"y":4,"z":-6,"name":"Soil_Dirt"},{"x":-9,"y":5,"z":-6,"name":"Soil_Pathway"},{"x":-9,"y":6,"z":-6,"name":"Wood_Redwood_Fence","support":15,"rotation":3},{"x":-9,"y":0,"z":-5,"name":"Soil_Dirt"},{"x":-9,"y":1,"z":-5,"name":"Soil_Dirt"},{"x":-9,"y":2,"z":-5,"name":"Soil_Dirt"},{"x":-9,"y":3,"z":-5,"name":"Soil_Dirt"},{"x":-9,"y":4,"z":-5,"name":"Soil_Dirt"},{"x":-9,"y":5,"z":-5,"name":"Soil_Mud"},{"x":-9,"y":6,"z":-5,"name":"Wood_Redwood_Fence","support":15,"rotation":3},{"x":-9,"y":0,"z":-4,"name":"Soil_Dirt"},{"x":-9,"y":1,"z":-4,"name":"Soil_Dirt"},{"x":-9,"y":2,"z":-4,"name":"Soil_Dirt"},{"x":-9,"y":3,"z":-4,"name":"Soil_Dirt"},{"x":-9,"y":4,"z":-4,"name":"Soil_Dirt"},{"x":-9,"y":5,"z":-4,"name":"Soil_Mud"},{"x":-9,"y":6,"z":-4,"name":"Wood_Redwood_Fence","support":15,"rotation":3},{"x":-9,"y":0,"z":-3,"name":"Soil_Dirt"},{"x":-9,"y":1,"z":-3,"name":"Soil_Dirt"},{"x":-9,"y":2,"z":-3,"name":"Soil_Dirt"},{"x":-9,"y":3,"z":-3,"name":"Soil_Dirt"},{"x":-9,"y":4,"z":-3,"name":"Soil_Dirt"},{"x":-9,"y":5,"z":-3,"name":"Soil_Mud"},{"x":-9,"y":6,"z":-3,"name":"Wood_Redwood_Fence","support":15,"rotation":3},{"x":-9,"y":9,"z":-3,"name":"Cloth_Modern_Red_Roof_Vertical_Flap","support":15,"rotation":2},{"x":-9,"y":0,"z":-2,"name":"Soil_Dirt"},{"x":-9,"y":1,"z":-2,"name":"Soil_Dirt"},{"x":-9,"y":2,"z":-2,"name":"Soil_Dirt"},{"x":-9,"y":3,"z":-2,"name":"Soil_Dirt"},{"x":-9,"y":4,"z":-2,"name":"Soil_Dirt"},{"x":-9,"y":5,"z":-2,"name":"Soil_Pathway"},{"x":-9,"y":6,"z":-2,"name":"Wood_Redwood_Trunk_Full","support":15},{"x":-9,"y":7,"z":-2,"name":"Wood_Redwood_Beam","support":15},{"x":-9,"y":8,"z":-2,"name":"Wood_Redwood_Beam","support":15},{"x":-9,"y":9,"z":-2,"name":"Wood_Redwood_Beam","support":15},{"x":-9,"y":10,"z":-2,"name":"Wood_Redwood_Planks_Half","support":15},{"x":-9,"y":0,"z":-1,"name":"Soil_Dirt"},{"x":-9,"y":1,"z":-1,"name":"Soil_Dirt"},{"x":-9,"y":2,"z":-1,"name":"Soil_Dirt"},{"x":-9,"y":3,"z":-1,"name":"Soil_Dirt"},{"x":-9,"y":4,"z":-1,"name":"Soil_Dirt"},{"x":-9,"y":5,"z":-1,"name":"Soil_Pathway"},{"x":-9,"y":6,"z":-1,"name":"Wood_Redwood_Fence","support":15,"rotation":3},{"x":-9,"y":9,"z":-1,"name":"Cloth_Modern_Red_Roof_Vertical_Flap","support":15},{"x":-9,"y":0,"z":0,"name":"Soil_Dirt"},{"x":-9,"y":1,"z":0,"name":"Soil_Dirt"},{"x":-9,"y":2,"z":0,"name":"Soil_Dirt"},{"x":-9,"y":3,"z":0,"name":"Soil_Dirt"},{"x":-9,"y":4,"z":0,"name":"Soil_Dirt"},{"x":-9,"y":5,"z":0,"name":"Soil_Dirt"},{"x":-9,"y":6,"z":0,"name":"Wood_Redwood_Fence","support":15,"rotation":3},{"x":-9,"y":0,"z":1,"name":"Soil_Dirt"},{"x":-9,"y":1,"z":1,"name":"Soil_Dirt"},{"x":-9,"y":2,"z":1,"name":"Soil_Dirt"},{"x":-9,"y":3,"z":1,"name":"Soil_Dirt"},{"x":-9,"y":4,"z":1,"name":"Soil_Dirt"},{"x":-9,"y":5,"z":1,"name":"Soil_Dirt"},{"x":-9,"y":6,"z":1,"name":"Wood_Redwood_Fence","support":15,"rotation":3},{"x":-9,"y":0,"z":2,"name":"Soil_Dirt"},{"x":-9,"y":1,"z":2,"name":"Soil_Dirt"},{"x":-9,"y":2,"z":2,"name":"Soil_Dirt"},{"x":-9,"y":3,"z":2,"name":"Soil_Dirt"},{"x":-9,"y":4,"z":2,"name":"Soil_Dirt"},{"x":-9,"y":5,"z":2,"name":"Soil_Pathway"},{"x":-9,"y":6,"z":2,"name":"Wood_Redwood_Fence","support":15,"rotation":3},{"x":-9,"y":9,"z":2,"name":"Cloth_Modern_Red_Roof_Vertical_Flap","support":15,"rotation":2},{"x":-9,"y":0,"z":3,"name":"Soil_Dirt"},{"x":-9,"y":1,"z":3,"name":"Soil_Dirt"},{"x":-9,"y":2,"z":3,"name":"Soil_Dirt"},{"x":-9,"y":3,"z":3,"name":"Soil_Dirt"},{"x":-9,"y":4,"z":3,"name":"Soil_Dirt"},{"x":-9,"y":5,"z":3,"name":"Soil_Pathway"},{"x":-9,"y":6,"z":3,"name":"Wood_Redwood_Trunk_Full","support":15},{"x":-9,"y":7,"z":3,"name":"Wood_Redwood_Beam","support":15},{"x":-9,"y":8,"z":3,"name":"Wood_Redwood_Beam","support":15},{"x":-9,"y":9,"z":3,"name":"Wood_Redwood_Beam","support":15},{"x":-9,"y":10,"z":3,"name":"Wood_Redwood_Planks_Half","support":15},{"x":-9,"y":0,"z":4,"name":"Soil_Dirt"},{"x":-9,"y":1,"z":4,"name":"Soil_Dirt"},{"x":-9,"y":2,"z":4,"name":"Soil_Dirt"},{"x":-9,"y":3,"z":4,"name":"Soil_Dirt"},{"x":-9,"y":4,"z":4,"name":"Soil_Dirt"},{"x":-9,"y":5,"z":4,"name":"Soil_Mud"},{"x":-9,"y":6,"z":4,"name":"Wood_Redwood_Fence","support":15,"rotation":3},{"x":-9,"y":9,"z":4,"name":"Cloth_Modern_Red_Roof_Vertical_Flap","support":15},{"x":-9,"y":0,"z":5,"name":"Soil_Dirt"},{"x":-9,"y":1,"z":5,"name":"Soil_Dirt"},{"x":-9,"y":2,"z":5,"name":"Soil_Dirt"},{"x":-9,"y":3,"z":5,"name":"Soil_Dirt"},{"x":-9,"y":4,"z":5,"name":"Soil_Dirt"},{"x":-9,"y":5,"z":5,"name":"Soil_Mud"},{"x":-9,"y":6,"z":5,"name":"Wood_Redwood_Fence","support":15,"rotation":3},{"x":-9,"y":0,"z":6,"name":"Soil_Dirt"},{"x":-9,"y":1,"z":6,"name":"Soil_Dirt"},{"x":-9,"y":2,"z":6,"name":"Soil_Dirt"},{"x":-9,"y":3,"z":6,"name":"Soil_Dirt"},{"x":-9,"y":4,"z":6,"name":"Soil_Dirt"},{"x":-9,"y":5,"z":6,"name":"Soil_Mud"},{"x":-9,"y":6,"z":6,"name":"Wood_Redwood_Fence","support":15,"rotation":3},{"x":-9,"y":0,"z":7,"name":"Soil_Dirt"},{"x":-9,"y":1,"z":7,"name":"Soil_Dirt"},{"x":-9,"y":2,"z":7,"name":"Soil_Dirt"},{"x":-9,"y":3,"z":7,"name":"Soil_Dirt"},{"x":-9,"y":4,"z":7,"name":"Soil_Dirt"},{"x":-9,"y":5,"z":7,"name":"Soil_Pathway"},{"x":-9,"y":6,"z":7,"name":"Wood_Redwood_Fence","support":15,"rotation":3},{"x":-9,"y":0,"z":8,"name":"Soil_Dirt"},{"x":-9,"y":1,"z":8,"name":"Soil_Dirt"},{"x":-9,"y":2,"z":8,"name":"Soil_Dirt"},{"x":-9,"y":3,"z":8,"name":"Soil_Dirt"},{"x":-9,"y":4,"z":8,"name":"Soil_Dirt"},{"x":-9,"y":5,"z":8,"name":"Soil_Dirt"},{"x":-9,"y":6,"z":8,"name":"Wood_Redwood_Fence","support":15,"rotation":3},{"x":-9,"y":0,"z":9,"name":"Soil_Dirt"},{"x":-9,"y":1,"z":9,"name":"Soil_Dirt"},{"x":-9,"y":2,"z":9,"name":"Soil_Dirt"},{"x":-9,"y":3,"z":9,"name":"Soil_Dirt"},{"x":-9,"y":4,"z":9,"name":"Soil_Dirt"},{"x":-9,"y":5,"z":9,"name":"Soil_Pathway"},{"x":-9,"y":6,"z":9,"name":"Wood_Redwood_Fence","support":15,"rotation":3},{"x":-9,"y":0,"z":10,"name":"Soil_Dirt"},{"x":-9,"y":1,"z":10,"name":"Soil_Dirt"},{"x":-9,"y":2,"z":10,"name":"Soil_Dirt"},{"x":-9,"y":3,"z":10,"name":"Soil_Dirt"},{"x":-9,"y":4,"z":10,"name":"Soil_Dirt"},{"x":-9,"y":5,"z":10,"name":"Soil_Mud"},{"x":-9,"y":6,"z":10,"name":"*Wood_Redwood_Fence_State_Definitions_Corner","rotation":2},{"x":-9,"y":7,"z":10,"name":"Wood_Redwood_Beam","support":15},{"x":-9,"y":8,"z":10,"name":"Deco_Lantern","support":15},{"x":-9,"y":0,"z":11,"name":"Soil_Dirt"},{"x":-9,"y":1,"z":11,"name":"Soil_Dirt"},{"x":-9,"y":2,"z":11,"name":"Soil_Dirt"},{"x":-9,"y":3,"z":11,"name":"Soil_Dirt"},{"x":-9,"y":4,"z":11,"name":"Soil_Dirt"},{"x":-9,"y":5,"z":11,"name":"Soil_Pathway"},{"x":-9,"y":0,"z":12,"name":"Soil_Dirt"},{"x":-9,"y":1,"z":12,"name":"Soil_Dirt"},{"x":-9,"y":2,"z":12,"name":"Soil_Dirt"},{"x":-9,"y":3,"z":12,"name":"Soil_Dirt"},{"x":-9,"y":4,"z":12,"name":"Soil_Dirt"},{"x":-9,"y":5,"z":12,"name":"Soil_Dirt"},{"x":-9,"y":0,"z":13,"name":"Soil_Dirt"},{"x":-9,"y":1,"z":13,"name":"Soil_Dirt"},{"x":-9,"y":2,"z":13,"name":"Soil_Dirt"},{"x":-9,"y":3,"z":13,"name":"Soil_Dirt"},{"x":-9,"y":4,"z":13,"name":"Soil_Dirt"},{"x":-9,"y":5,"z":13,"name":"Rock_Stone_Cobble"},{"x":-9,"y":0,"z":14,"name":"Soil_Dirt"},{"x":-9,"y":1,"z":14,"name":"Soil_Dirt"},{"x":-9,"y":2,"z":14,"name":"Soil_Dirt"},{"x":-9,"y":3,"z":14,"name":"Soil_Dirt"},{"x":-9,"y":4,"z":14,"name":"Soil_Dirt"},{"x":-9,"y":5,"z":14,"name":"Rock_Stone_Cobble"},{"x":-9,"y":6,"z":14,"name":"Furniture_Tavern_Bench","support":15,"rotation":2},{"x":-9,"y":0,"z":15,"name":"Soil_Dirt"},{"x":-9,"y":1,"z":15,"name":"Soil_Dirt"},{"x":-9,"y":2,"z":15,"name":"Soil_Dirt"},{"x":-9,"y":3,"z":15,"name":"Soil_Dirt"},{"x":-9,"y":4,"z":15,"name":"Soil_Dirt"},{"x":-9,"y":5,"z":15,"name":"Rock_Stone_Brick_Smooth","support":15},{"x":-8,"y":0,"z":-14,"name":"Soil_Dirt"},{"x":-8,"y":1,"z":-14,"name":"Soil_Dirt"},{"x":-8,"y":2,"z":-14,"name":"Soil_Dirt"},{"x":-8,"y":3,"z":-14,"name":"Soil_Dirt"},{"x":-8,"y":4,"z":-14,"name":"Soil_Dirt"},{"x":-8,"y":5,"z":-14,"name":"Rock_Stone_Brick_Smooth","support":15},{"x":-8,"y":0,"z":-13,"name":"Soil_Dirt"},{"x":-8,"y":1,"z":-13,"name":"Soil_Dirt"},{"x":-8,"y":2,"z":-13,"name":"Soil_Dirt"},{"x":-8,"y":3,"z":-13,"name":"Soil_Dirt"},{"x":-8,"y":4,"z":-13,"name":"Soil_Dirt"},{"x":-8,"y":5,"z":-13,"name":"Rock_Stone_Cobble"},{"x":-8,"y":6,"z":-13,"name":"Furniture_Tavern_Bench","filler":1,"rotation":2},{"x":-8,"y":0,"z":-12,"name":"Soil_Dirt"},{"x":-8,"y":1,"z":-12,"name":"Soil_Dirt"},{"x":-8,"y":2,"z":-12,"name":"Soil_Dirt"},{"x":-8,"y":3,"z":-12,"name":"Soil_Dirt"},{"x":-8,"y":4,"z":-12,"name":"Soil_Dirt"},{"x":-8,"y":5,"z":-12,"name":"Rock_Stone_Cobble"},{"x":-8,"y":0,"z":-11,"name":"Soil_Dirt"},{"x":-8,"y":1,"z":-11,"name":"Soil_Dirt"},{"x":-8,"y":2,"z":-11,"name":"Soil_Dirt"},{"x":-8,"y":3,"z":-11,"name":"Soil_Dirt"},{"x":-8,"y":4,"z":-11,"name":"Soil_Dirt"},{"x":-8,"y":5,"z":-11,"name":"Soil_Pathway"},{"x":-8,"y":0,"z":-10,"name":"Soil_Dirt"},{"x":-8,"y":1,"z":-10,"name":"Soil_Dirt"},{"x":-8,"y":2,"z":-10,"name":"Soil_Dirt"},{"x":-8,"y":3,"z":-10,"name":"Soil_Dirt"},{"x":-8,"y":4,"z":-10,"name":"Soil_Dirt"},{"x":-8,"y":5,"z":-10,"name":"Soil_Pathway"},{"x":-8,"y":0,"z":-9,"name":"Soil_Dirt"},{"x":-8,"y":1,"z":-9,"name":"Soil_Dirt"},{"x":-8,"y":2,"z":-9,"name":"Soil_Dirt"},{"x":-8,"y":3,"z":-9,"name":"Soil_Dirt"},{"x":-8,"y":4,"z":-9,"name":"Soil_Dirt"},{"x":-8,"y":5,"z":-9,"name":"Soil_Pathway"},{"x":-8,"y":6,"z":-9,"name":"Wood_Redwood_Fence","support":15,"rotation":2},{"x":-8,"y":0,"z":-8,"name":"Soil_Dirt"},{"x":-8,"y":1,"z":-8,"name":"Soil_Dirt"},{"x":-8,"y":2,"z":-8,"name":"Soil_Dirt"},{"x":-8,"y":3,"z":-8,"name":"Soil_Dirt"},{"x":-8,"y":4,"z":-8,"name":"Soil_Dirt"},{"x":-8,"y":5,"z":-8,"name":"Soil_Dirt"},{"x":-8,"y":0,"z":-7,"name":"Soil_Dirt"},{"x":-8,"y":1,"z":-7,"name":"Soil_Dirt"},{"x":-8,"y":2,"z":-7,"name":"Soil_Dirt"},{"x":-8,"y":3,"z":-7,"name":"Soil_Dirt"},{"x":-8,"y":4,"z":-7,"name":"Soil_Dirt"},{"x":-8,"y":5,"z":-7,"name":"Soil_Pathway"},{"x":-8,"y":0,"z":-6,"name":"Soil_Dirt"},{"x":-8,"y":1,"z":-6,"name":"Soil_Dirt"},{"x":-8,"y":2,"z":-6,"name":"Soil_Dirt"},{"x":-8,"y":3,"z":-6,"name":"Soil_Dirt"},{"x":-8,"y":4,"z":-6,"name":"Soil_Dirt"},{"x":-8,"y":5,"z":-6,"name":"Cloth_Block_Wool_Green","support":15},{"x":-8,"y":0,"z":-5,"name":"Soil_Dirt"},{"x":-8,"y":1,"z":-5,"name":"Soil_Dirt"},{"x":-8,"y":2,"z":-5,"name":"Soil_Dirt"},{"x":-8,"y":3,"z":-5,"name":"Soil_Dirt"},{"x":-8,"y":4,"z":-5,"name":"Soil_Dirt"},{"x":-8,"y":5,"z":-5,"name":"Soil_Pathway"},{"x":-8,"y":0,"z":-4,"name":"Soil_Dirt"},{"x":-8,"y":1,"z":-4,"name":"Soil_Dirt"},{"x":-8,"y":2,"z":-4,"name":"Soil_Dirt"},{"x":-8,"y":3,"z":-4,"name":"Soil_Dirt"},{"x":-8,"y":4,"z":-4,"name":"Soil_Dirt"},{"x":-8,"y":5,"z":-4,"name":"Soil_Dirt"},{"x":-8,"y":0,"z":-3,"name":"Soil_Dirt"},{"x":-8,"y":1,"z":-3,"name":"Soil_Dirt"},{"x":-8,"y":2,"z":-3,"name":"Soil_Dirt"},{"x":-8,"y":3,"z":-3,"name":"Soil_Dirt"},{"x":-8,"y":4,"z":-3,"name":"Soil_Dirt"},{"x":-8,"y":5,"z":-3,"name":"Soil_Pathway"},{"x":-8,"y":0,"z":-2,"name":"Soil_Dirt"},{"x":-8,"y":1,"z":-2,"name":"Soil_Dirt"},{"x":-8,"y":2,"z":-2,"name":"Soil_Dirt"},{"x":-8,"y":3,"z":-2,"name":"Soil_Dirt"},{"x":-8,"y":4,"z":-2,"name":"Soil_Dirt"},{"x":-8,"y":5,"z":-2,"name":"Soil_Mud"},{"x":-8,"y":0,"z":-1,"name":"Soil_Dirt"},{"x":-8,"y":1,"z":-1,"name":"Soil_Dirt"},{"x":-8,"y":2,"z":-1,"name":"Soil_Dirt"},{"x":-8,"y":3,"z":-1,"name":"Soil_Dirt"},{"x":-8,"y":4,"z":-1,"name":"Soil_Dirt"},{"x":-8,"y":5,"z":-1,"name":"Soil_Pathway"},{"x":-8,"y":0,"z":0,"name":"Soil_Dirt"},{"x":-8,"y":1,"z":0,"name":"Soil_Dirt"},{"x":-8,"y":2,"z":0,"name":"Soil_Dirt"},{"x":-8,"y":3,"z":0,"name":"Soil_Dirt"},{"x":-8,"y":4,"z":0,"name":"Soil_Dirt"},{"x":-8,"y":5,"z":0,"name":"Soil_Mud"},{"x":-8,"y":0,"z":1,"name":"Soil_Dirt"},{"x":-8,"y":1,"z":1,"name":"Soil_Dirt"},{"x":-8,"y":2,"z":1,"name":"Soil_Dirt"},{"x":-8,"y":3,"z":1,"name":"Soil_Dirt"},{"x":-8,"y":4,"z":1,"name":"Soil_Dirt"},{"x":-8,"y":5,"z":1,"name":"Soil_Pathway"},{"x":-8,"y":0,"z":2,"name":"Soil_Dirt"},{"x":-8,"y":1,"z":2,"name":"Soil_Dirt"},{"x":-8,"y":2,"z":2,"name":"Soil_Dirt"},{"x":-8,"y":3,"z":2,"name":"Soil_Dirt"},{"x":-8,"y":4,"z":2,"name":"Soil_Dirt"},{"x":-8,"y":5,"z":2,"name":"Soil_Pathway"},{"x":-8,"y":0,"z":3,"name":"Soil_Dirt"},{"x":-8,"y":1,"z":3,"name":"Soil_Dirt"},{"x":-8,"y":2,"z":3,"name":"Soil_Dirt"},{"x":-8,"y":3,"z":3,"name":"Soil_Dirt"},{"x":-8,"y":4,"z":3,"name":"Soil_Dirt"},{"x":-8,"y":5,"z":3,"name":"Soil_Pathway"},{"x":-8,"y":0,"z":4,"name":"Soil_Dirt"},{"x":-8,"y":1,"z":4,"name":"Soil_Dirt"},{"x":-8,"y":2,"z":4,"name":"Soil_Dirt"},{"x":-8,"y":3,"z":4,"name":"Soil_Dirt"},{"x":-8,"y":4,"z":4,"name":"Soil_Dirt"},{"x":-8,"y":5,"z":4,"name":"Soil_Mud"},{"x":-8,"y":0,"z":5,"name":"Soil_Dirt"},{"x":-8,"y":1,"z":5,"name":"Soil_Dirt"},{"x":-8,"y":2,"z":5,"name":"Soil_Dirt"},{"x":-8,"y":3,"z":5,"name":"Soil_Dirt"},{"x":-8,"y":4,"z":5,"name":"Soil_Dirt"},{"x":-8,"y":5,"z":5,"name":"Soil_Mud"},{"x":-8,"y":0,"z":6,"name":"Soil_Dirt"},{"x":-8,"y":1,"z":6,"name":"Soil_Dirt"},{"x":-8,"y":2,"z":6,"name":"Soil_Dirt"},{"x":-8,"y":3,"z":6,"name":"Soil_Dirt"},{"x":-8,"y":4,"z":6,"name":"Soil_Dirt"},{"x":-8,"y":5,"z":6,"name":"Soil_Mud"},{"x":-8,"y":0,"z":7,"name":"Soil_Dirt"},{"x":-8,"y":1,"z":7,"name":"Soil_Dirt"},{"x":-8,"y":2,"z":7,"name":"Soil_Dirt"},{"x":-8,"y":3,"z":7,"name":"Soil_Dirt"},{"x":-8,"y":4,"z":7,"name":"Soil_Dirt"},{"x":-8,"y":5,"z":7,"name":"Soil_Mud"},{"x":-8,"y":0,"z":8,"name":"Soil_Dirt"},{"x":-8,"y":1,"z":8,"name":"Soil_Dirt"},{"x":-8,"y":2,"z":8,"name":"Soil_Dirt"},{"x":-8,"y":3,"z":8,"name":"Soil_Dirt"},{"x":-8,"y":4,"z":8,"name":"Soil_Dirt"},{"x":-8,"y":5,"z":8,"name":"Cloth_Block_Wool_Black","support":15},{"x":-8,"y":0,"z":9,"name":"Soil_Dirt"},{"x":-8,"y":1,"z":9,"name":"Soil_Dirt"},{"x":-8,"y":2,"z":9,"name":"Soil_Dirt"},{"x":-8,"y":3,"z":9,"name":"Soil_Dirt"},{"x":-8,"y":4,"z":9,"name":"Soil_Dirt"},{"x":-8,"y":5,"z":9,"name":"Cloth_Block_Wool_White","support":15},{"x":-8,"y":0,"z":10,"name":"Soil_Dirt"},{"x":-8,"y":1,"z":10,"name":"Soil_Dirt"},{"x":-8,"y":2,"z":10,"name":"Soil_Dirt"},{"x":-8,"y":3,"z":10,"name":"Soil_Dirt"},{"x":-8,"y":4,"z":10,"name":"Soil_Dirt"},{"x":-8,"y":5,"z":10,"name":"Soil_Pathway"},{"x":-8,"y":6,"z":10,"name":"Wood_Redwood_Fence","support":15},{"x":-8,"y":0,"z":11,"name":"Soil_Dirt"},{"x":-8,"y":1,"z":11,"name":"Soil_Dirt"},{"x":-8,"y":2,"z":11,"name":"Soil_Dirt"},{"x":-8,"y":3,"z":11,"name":"Soil_Dirt"},{"x":-8,"y":4,"z":11,"name":"Soil_Dirt"},{"x":-8,"y":5,"z":11,"name":"Soil_Dirt"},{"x":-8,"y":0,"z":12,"name":"Soil_Dirt"},{"x":-8,"y":1,"z":12,"name":"Soil_Dirt"},{"x":-8,"y":2,"z":12,"name":"Soil_Dirt"},{"x":-8,"y":3,"z":12,"name":"Soil_Dirt"},{"x":-8,"y":4,"z":12,"name":"Soil_Dirt"},{"x":-8,"y":5,"z":12,"name":"Soil_Pathway"},{"x":-8,"y":0,"z":13,"name":"Soil_Dirt"},{"x":-8,"y":1,"z":13,"name":"Soil_Dirt"},{"x":-8,"y":2,"z":13,"name":"Soil_Dirt"},{"x":-8,"y":3,"z":13,"name":"Soil_Dirt"},{"x":-8,"y":4,"z":13,"name":"Soil_Dirt"},{"x":-8,"y":5,"z":13,"name":"Rock_Stone_Cobble"},{"x":-8,"y":0,"z":14,"name":"Soil_Dirt"},{"x":-8,"y":1,"z":14,"name":"Soil_Dirt"},{"x":-8,"y":2,"z":14,"name":"Soil_Dirt"},{"x":-8,"y":3,"z":14,"name":"Soil_Dirt"},{"x":-8,"y":4,"z":14,"name":"Soil_Dirt"},{"x":-8,"y":5,"z":14,"name":"Rock_Stone_Cobble"},{"x":-8,"y":6,"z":14,"name":"Furniture_Tavern_Bench","filler":1,"rotation":2},{"x":-8,"y":0,"z":15,"name":"Soil_Dirt"},{"x":-8,"y":1,"z":15,"name":"Soil_Dirt"},{"x":-8,"y":2,"z":15,"name":"Soil_Dirt"},{"x":-8,"y":3,"z":15,"name":"Soil_Dirt"},{"x":-8,"y":4,"z":15,"name":"Soil_Dirt"},{"x":-8,"y":5,"z":15,"name":"Rock_Stone_Brick_Smooth","support":15},{"x":-7,"y":0,"z":-14,"name":"Soil_Dirt"},{"x":-7,"y":1,"z":-14,"name":"Soil_Dirt"},{"x":-7,"y":2,"z":-14,"name":"Soil_Dirt"},{"x":-7,"y":3,"z":-14,"name":"Soil_Dirt"},{"x":-7,"y":4,"z":-14,"name":"Soil_Dirt"},{"x":-7,"y":5,"z":-14,"name":"Rock_Stone_Brick_Smooth","support":15},{"x":-7,"y":0,"z":-13,"name":"Soil_Dirt"},{"x":-7,"y":1,"z":-13,"name":"Soil_Dirt"},{"x":-7,"y":2,"z":-13,"name":"Soil_Dirt"},{"x":-7,"y":3,"z":-13,"name":"Soil_Dirt"},{"x":-7,"y":4,"z":-13,"name":"Soil_Dirt"},{"x":-7,"y":5,"z":-13,"name":"Rock_Stone_Cobble"},{"x":-7,"y":0,"z":-12,"name":"Soil_Dirt"},{"x":-7,"y":1,"z":-12,"name":"Soil_Dirt"},{"x":-7,"y":2,"z":-12,"name":"Soil_Dirt"},{"x":-7,"y":3,"z":-12,"name":"Soil_Dirt"},{"x":-7,"y":4,"z":-12,"name":"Soil_Dirt"},{"x":-7,"y":5,"z":-12,"name":"Rock_Stone_Cobble_Mossy"},{"x":-7,"y":0,"z":-11,"name":"Soil_Dirt"},{"x":-7,"y":1,"z":-11,"name":"Soil_Dirt"},{"x":-7,"y":2,"z":-11,"name":"Soil_Dirt"},{"x":-7,"y":3,"z":-11,"name":"Soil_Dirt"},{"x":-7,"y":4,"z":-11,"name":"Soil_Dirt"},{"x":-7,"y":5,"z":-11,"name":"Soil_Pathway"},{"x":-7,"y":0,"z":-10,"name":"Soil_Dirt"},{"x":-7,"y":1,"z":-10,"name":"Soil_Dirt"},{"x":-7,"y":2,"z":-10,"name":"Soil_Dirt"},{"x":-7,"y":3,"z":-10,"name":"Soil_Dirt"},{"x":-7,"y":4,"z":-10,"name":"Soil_Dirt"},{"x":-7,"y":5,"z":-10,"name":"Soil_Mud"},{"x":-7,"y":0,"z":-9,"name":"Soil_Dirt"},{"x":-7,"y":1,"z":-9,"name":"Soil_Dirt"},{"x":-7,"y":2,"z":-9,"name":"Soil_Dirt"},{"x":-7,"y":3,"z":-9,"name":"Soil_Dirt"},{"x":-7,"y":4,"z":-9,"name":"Soil_Dirt"},{"x":-7,"y":5,"z":-9,"name":"Soil_Mud"},{"x":-7,"y":6,"z":-9,"name":"Wood_Redwood_Fence","support":15,"rotation":2},{"x":-7,"y":0,"z":-8,"name":"Soil_Dirt"},{"x":-7,"y":1,"z":-8,"name":"Soil_Dirt"},{"x":-7,"y":2,"z":-8,"name":"Soil_Dirt"},{"x":-7,"y":3,"z":-8,"name":"Soil_Dirt"},{"x":-7,"y":4,"z":-8,"name":"Soil_Dirt"},{"x":-7,"y":5,"z":-8,"name":"Soil_Pathway"},{"x":-7,"y":0,"z":-7,"name":"Soil_Dirt"},{"x":-7,"y":1,"z":-7,"name":"Soil_Dirt"},{"x":-7,"y":2,"z":-7,"name":"Soil_Dirt"},{"x":-7,"y":3,"z":-7,"name":"Soil_Dirt"},{"x":-7,"y":4,"z":-7,"name":"Soil_Dirt"},{"x":-7,"y":5,"z":-7,"name":"Soil_Pathway"},{"x":-7,"y":0,"z":-6,"name":"Soil_Dirt"},{"x":-7,"y":1,"z":-6,"name":"Soil_Dirt"},{"x":-7,"y":2,"z":-6,"name":"Soil_Dirt"},{"x":-7,"y":3,"z":-6,"name":"Soil_Dirt"},{"x":-7,"y":4,"z":-6,"name":"Soil_Dirt"},{"x":-7,"y":5,"z":-6,"name":"Cloth_Block_Wool_Green","support":15},{"x":-7,"y":0,"z":-5,"name":"Soil_Dirt"},{"x":-7,"y":1,"z":-5,"name":"Soil_Dirt"},{"x":-7,"y":2,"z":-5,"name":"Soil_Dirt"},{"x":-7,"y":3,"z":-5,"name":"Soil_Dirt"},{"x":-7,"y":4,"z":-5,"name":"Soil_Dirt"},{"x":-7,"y":5,"z":-5,"name":"Soil_Pathway"},{"x":-7,"y":0,"z":-4,"name":"Soil_Dirt"},{"x":-7,"y":1,"z":-4,"name":"Soil_Dirt"},{"x":-7,"y":2,"z":-4,"name":"Soil_Dirt"},{"x":-7,"y":3,"z":-4,"name":"Soil_Dirt"},{"x":-7,"y":4,"z":-4,"name":"Soil_Dirt"},{"x":-7,"y":5,"z":-4,"name":"Soil_Pathway"},{"x":-7,"y":0,"z":-3,"name":"Soil_Dirt"},{"x":-7,"y":1,"z":-3,"name":"Soil_Dirt"},{"x":-7,"y":2,"z":-3,"name":"Soil_Dirt"},{"x":-7,"y":3,"z":-3,"name":"Soil_Dirt"},{"x":-7,"y":4,"z":-3,"name":"Soil_Dirt"},{"x":-7,"y":5,"z":-3,"name":"Soil_Mud"},{"x":-7,"y":0,"z":-2,"name":"Soil_Dirt"},{"x":-7,"y":1,"z":-2,"name":"Soil_Dirt"},{"x":-7,"y":2,"z":-2,"name":"Soil_Dirt"},{"x":-7,"y":3,"z":-2,"name":"Soil_Dirt"},{"x":-7,"y":4,"z":-2,"name":"Soil_Dirt"},{"x":-7,"y":5,"z":-2,"name":"Soil_Mud"},{"x":-7,"y":0,"z":-1,"name":"Soil_Dirt"},{"x":-7,"y":1,"z":-1,"name":"Soil_Dirt"},{"x":-7,"y":2,"z":-1,"name":"Soil_Dirt"},{"x":-7,"y":3,"z":-1,"name":"Soil_Dirt"},{"x":-7,"y":4,"z":-1,"name":"Soil_Dirt"},{"x":-7,"y":5,"z":-1,"name":"Soil_Pathway"},{"x":-7,"y":0,"z":0,"name":"Soil_Dirt"},{"x":-7,"y":1,"z":0,"name":"Soil_Dirt"},{"x":-7,"y":2,"z":0,"name":"Soil_Dirt"},{"x":-7,"y":3,"z":0,"name":"Soil_Dirt"},{"x":-7,"y":4,"z":0,"name":"Soil_Dirt"},{"x":-7,"y":5,"z":0,"name":"Soil_Dirt"},{"x":-7,"y":0,"z":1,"name":"Soil_Dirt"},{"x":-7,"y":1,"z":1,"name":"Soil_Dirt"},{"x":-7,"y":2,"z":1,"name":"Soil_Dirt"},{"x":-7,"y":3,"z":1,"name":"Soil_Dirt"},{"x":-7,"y":4,"z":1,"name":"Soil_Dirt"},{"x":-7,"y":5,"z":1,"name":"Soil_Mud"},{"x":-7,"y":0,"z":2,"name":"Soil_Dirt"},{"x":-7,"y":1,"z":2,"name":"Soil_Dirt"},{"x":-7,"y":2,"z":2,"name":"Soil_Dirt"},{"x":-7,"y":3,"z":2,"name":"Soil_Dirt"},{"x":-7,"y":4,"z":2,"name":"Soil_Dirt"},{"x":-7,"y":5,"z":2,"name":"Soil_Mud"},{"x":-7,"y":0,"z":3,"name":"Soil_Dirt"},{"x":-7,"y":1,"z":3,"name":"Soil_Dirt"},{"x":-7,"y":2,"z":3,"name":"Soil_Dirt"},{"x":-7,"y":3,"z":3,"name":"Soil_Dirt"},{"x":-7,"y":4,"z":3,"name":"Soil_Dirt"},{"x":-7,"y":5,"z":3,"name":"Soil_Dirt"},{"x":-7,"y":0,"z":4,"name":"Soil_Dirt"},{"x":-7,"y":1,"z":4,"name":"Soil_Dirt"},{"x":-7,"y":2,"z":4,"name":"Soil_Dirt"},{"x":-7,"y":3,"z":4,"name":"Soil_Dirt"},{"x":-7,"y":4,"z":4,"name":"Soil_Dirt"},{"x":-7,"y":5,"z":4,"name":"Soil_Dirt"},{"x":-7,"y":0,"z":5,"name":"Soil_Dirt"},{"x":-7,"y":1,"z":5,"name":"Soil_Dirt"},{"x":-7,"y":2,"z":5,"name":"Soil_Dirt"},{"x":-7,"y":3,"z":5,"name":"Soil_Dirt"},{"x":-7,"y":4,"z":5,"name":"Soil_Dirt"},{"x":-7,"y":5,"z":5,"name":"Soil_Mud"},{"x":-7,"y":0,"z":6,"name":"Soil_Dirt"},{"x":-7,"y":1,"z":6,"name":"Soil_Dirt"},{"x":-7,"y":2,"z":6,"name":"Soil_Dirt"},{"x":-7,"y":3,"z":6,"name":"Soil_Dirt"},{"x":-7,"y":4,"z":6,"name":"Soil_Dirt"},{"x":-7,"y":5,"z":6,"name":"Soil_Pathway"},{"x":-7,"y":0,"z":7,"name":"Soil_Dirt"},{"x":-7,"y":1,"z":7,"name":"Soil_Dirt"},{"x":-7,"y":2,"z":7,"name":"Soil_Dirt"},{"x":-7,"y":3,"z":7,"name":"Soil_Dirt"},{"x":-7,"y":4,"z":7,"name":"Soil_Dirt"},{"x":-7,"y":5,"z":7,"name":"Soil_Pathway"},{"x":-7,"y":0,"z":8,"name":"Soil_Dirt"},{"x":-7,"y":1,"z":8,"name":"Soil_Dirt"},{"x":-7,"y":2,"z":8,"name":"Soil_Dirt"},{"x":-7,"y":3,"z":8,"name":"Soil_Dirt"},{"x":-7,"y":4,"z":8,"name":"Soil_Dirt"},{"x":-7,"y":5,"z":8,"name":"Cloth_Block_Wool_White","support":15},{"x":-7,"y":0,"z":9,"name":"Soil_Dirt"},{"x":-7,"y":1,"z":9,"name":"Soil_Dirt"},{"x":-7,"y":2,"z":9,"name":"Soil_Dirt"},{"x":-7,"y":3,"z":9,"name":"Soil_Dirt"},{"x":-7,"y":4,"z":9,"name":"Soil_Dirt"},{"x":-7,"y":5,"z":9,"name":"Cloth_Block_Wool_Black","support":15},{"x":-7,"y":0,"z":10,"name":"Soil_Dirt"},{"x":-7,"y":1,"z":10,"name":"Soil_Dirt"},{"x":-7,"y":2,"z":10,"name":"Soil_Dirt"},{"x":-7,"y":3,"z":10,"name":"Soil_Dirt"},{"x":-7,"y":4,"z":10,"name":"Soil_Dirt"},{"x":-7,"y":5,"z":10,"name":"Soil_Dirt"},{"x":-7,"y":6,"z":10,"name":"Wood_Redwood_Fence","support":15},{"x":-7,"y":0,"z":11,"name":"Soil_Dirt"},{"x":-7,"y":1,"z":11,"name":"Soil_Dirt"},{"x":-7,"y":2,"z":11,"name":"Soil_Dirt"},{"x":-7,"y":3,"z":11,"name":"Soil_Dirt"},{"x":-7,"y":4,"z":11,"name":"Soil_Dirt"},{"x":-7,"y":5,"z":11,"name":"Soil_Mud"},{"x":-7,"y":0,"z":12,"name":"Soil_Dirt"},{"x":-7,"y":1,"z":12,"name":"Soil_Dirt"},{"x":-7,"y":2,"z":12,"name":"Soil_Dirt"},{"x":-7,"y":3,"z":12,"name":"Soil_Dirt"},{"x":-7,"y":4,"z":12,"name":"Soil_Dirt"},{"x":-7,"y":5,"z":12,"name":"Soil_Pathway"},{"x":-7,"y":0,"z":13,"name":"Soil_Dirt"},{"x":-7,"y":1,"z":13,"name":"Soil_Dirt"},{"x":-7,"y":2,"z":13,"name":"Soil_Dirt"},{"x":-7,"y":3,"z":13,"name":"Soil_Dirt"},{"x":-7,"y":4,"z":13,"name":"Soil_Dirt"},{"x":-7,"y":5,"z":13,"name":"Rock_Stone_Cobble"},{"x":-7,"y":0,"z":14,"name":"Soil_Dirt"},{"x":-7,"y":1,"z":14,"name":"Soil_Dirt"},{"x":-7,"y":2,"z":14,"name":"Soil_Dirt"},{"x":-7,"y":3,"z":14,"name":"Soil_Dirt"},{"x":-7,"y":4,"z":14,"name":"Soil_Dirt"},{"x":-7,"y":5,"z":14,"name":"Rock_Stone_Cobble_Mossy"},{"x":-7,"y":0,"z":15,"name":"Soil_Dirt"},{"x":-7,"y":1,"z":15,"name":"Soil_Dirt"},{"x":-7,"y":2,"z":15,"name":"Soil_Dirt"},{"x":-7,"y":3,"z":15,"name":"Soil_Dirt","support":15},{"x":-7,"y":4,"z":15,"name":"Soil_Dirt","support":15},{"x":-7,"y":5,"z":15,"name":"Rock_Stone_Brick_Smooth","support":15},{"x":-6,"y":0,"z":-14,"name":"Soil_Dirt"},{"x":-6,"y":1,"z":-14,"name":"Soil_Dirt"},{"x":-6,"y":2,"z":-14,"name":"Soil_Dirt"},{"x":-6,"y":3,"z":-14,"name":"Soil_Dirt"},{"x":-6,"y":4,"z":-14,"name":"Soil_Dirt"},{"x":-6,"y":5,"z":-14,"name":"Rock_Stone_Brick_Smooth","support":15},{"x":-6,"y":0,"z":-13,"name":"Soil_Dirt"},{"x":-6,"y":1,"z":-13,"name":"Soil_Dirt"},{"x":-6,"y":2,"z":-13,"name":"Soil_Dirt"},{"x":-6,"y":3,"z":-13,"name":"Soil_Dirt"},{"x":-6,"y":4,"z":-13,"name":"Soil_Dirt"},{"x":-6,"y":5,"z":-13,"name":"Rock_Stone_Cobble"},{"x":-6,"y":0,"z":-12,"name":"Soil_Dirt"},{"x":-6,"y":1,"z":-12,"name":"Soil_Dirt"},{"x":-6,"y":2,"z":-12,"name":"Soil_Dirt"},{"x":-6,"y":3,"z":-12,"name":"Soil_Dirt"},{"x":-6,"y":4,"z":-12,"name":"Soil_Dirt"},{"x":-6,"y":5,"z":-12,"name":"Rock_Stone_Cobble"},{"x":-6,"y":0,"z":-11,"name":"Soil_Dirt"},{"x":-6,"y":1,"z":-11,"name":"Soil_Dirt"},{"x":-6,"y":2,"z":-11,"name":"Soil_Dirt"},{"x":-6,"y":3,"z":-11,"name":"Soil_Dirt"},{"x":-6,"y":4,"z":-11,"name":"Soil_Dirt"},{"x":-6,"y":5,"z":-11,"name":"Soil_Pathway"},{"x":-6,"y":0,"z":-10,"name":"Soil_Dirt"},{"x":-6,"y":1,"z":-10,"name":"Soil_Dirt"},{"x":-6,"y":2,"z":-10,"name":"Soil_Dirt"},{"x":-6,"y":3,"z":-10,"name":"Soil_Dirt"},{"x":-6,"y":4,"z":-10,"name":"Soil_Dirt"},{"x":-6,"y":5,"z":-10,"name":"Soil_Pathway"},{"x":-6,"y":0,"z":-9,"name":"Soil_Dirt"},{"x":-6,"y":1,"z":-9,"name":"Soil_Dirt"},{"x":-6,"y":2,"z":-9,"name":"Soil_Dirt"},{"x":-6,"y":3,"z":-9,"name":"Soil_Dirt"},{"x":-6,"y":4,"z":-9,"name":"Soil_Dirt"},{"x":-6,"y":5,"z":-9,"name":"Soil_Pathway"},{"x":-6,"y":6,"z":-9,"name":"Wood_Redwood_Fence","support":15,"rotation":2},{"x":-6,"y":0,"z":-8,"name":"Soil_Dirt"},{"x":-6,"y":1,"z":-8,"name":"Soil_Dirt"},{"x":-6,"y":2,"z":-8,"name":"Soil_Dirt"},{"x":-6,"y":3,"z":-8,"name":"Soil_Dirt"},{"x":-6,"y":4,"z":-8,"name":"Soil_Dirt"},{"x":-6,"y":5,"z":-8,"name":"Soil_Pathway"},{"x":-6,"y":0,"z":-7,"name":"Soil_Dirt"},{"x":-6,"y":1,"z":-7,"name":"Soil_Dirt"},{"x":-6,"y":2,"z":-7,"name":"Soil_Dirt"},{"x":-6,"y":3,"z":-7,"name":"Soil_Dirt"},{"x":-6,"y":4,"z":-7,"name":"Soil_Dirt"},{"x":-6,"y":5,"z":-7,"name":"Soil_Pathway"},{"x":-6,"y":0,"z":-6,"name":"Soil_Dirt"},{"x":-6,"y":1,"z":-6,"name":"Soil_Dirt"},{"x":-6,"y":2,"z":-6,"name":"Soil_Dirt"},{"x":-6,"y":3,"z":-6,"name":"Soil_Dirt"},{"x":-6,"y":4,"z":-6,"name":"Soil_Dirt"},{"x":-6,"y":5,"z":-6,"name":"Cloth_Block_Wool_Green","support":15},{"x":-6,"y":0,"z":-5,"name":"Soil_Dirt"},{"x":-6,"y":1,"z":-5,"name":"Soil_Dirt"},{"x":-6,"y":2,"z":-5,"name":"Soil_Dirt"},{"x":-6,"y":3,"z":-5,"name":"Soil_Dirt"},{"x":-6,"y":4,"z":-5,"name":"Soil_Dirt"},{"x":-6,"y":5,"z":-5,"name":"Soil_Dirt"},{"x":-6,"y":0,"z":-4,"name":"Soil_Dirt"},{"x":-6,"y":1,"z":-4,"name":"Soil_Dirt"},{"x":-6,"y":2,"z":-4,"name":"Soil_Dirt"},{"x":-6,"y":3,"z":-4,"name":"Soil_Dirt"},{"x":-6,"y":4,"z":-4,"name":"Soil_Dirt"},{"x":-6,"y":5,"z":-4,"name":"Soil_Pathway"},{"x":-6,"y":7,"z":-4,"name":"Cloth_Modern_Red_Roof_Vertical_Flap","support":15,"rotation":3},{"x":-6,"y":8,"z":-4,"name":"Cloth_Modern_Red_Roof_Vertical","support":15,"rotation":3},{"x":-6,"y":0,"z":-3,"name":"Soil_Dirt"},{"x":-6,"y":1,"z":-3,"name":"Soil_Dirt"},{"x":-6,"y":2,"z":-3,"name":"Soil_Dirt"},{"x":-6,"y":3,"z":-3,"name":"Soil_Dirt"},{"x":-6,"y":4,"z":-3,"name":"Soil_Dirt"},{"x":-6,"y":5,"z":-3,"name":"Soil_Dirt"},{"x":-6,"y":0,"z":-2,"name":"Soil_Dirt"},{"x":-6,"y":1,"z":-2,"name":"Soil_Dirt"},{"x":-6,"y":2,"z":-2,"name":"Soil_Dirt"},{"x":-6,"y":3,"z":-2,"name":"Soil_Dirt"},{"x":-6,"y":4,"z":-2,"name":"Soil_Dirt"},{"x":-6,"y":5,"z":-2,"name":"Soil_Pathway"},{"x":-6,"y":0,"z":-1,"name":"Soil_Dirt"},{"x":-6,"y":1,"z":-1,"name":"Soil_Dirt"},{"x":-6,"y":2,"z":-1,"name":"Soil_Dirt"},{"x":-6,"y":3,"z":-1,"name":"Soil_Dirt"},{"x":-6,"y":4,"z":-1,"name":"Soil_Dirt"},{"x":-6,"y":5,"z":-1,"name":"Soil_Mud"},{"x":-6,"y":0,"z":0,"name":"Soil_Dirt"},{"x":-6,"y":1,"z":0,"name":"Soil_Dirt"},{"x":-6,"y":2,"z":0,"name":"Soil_Dirt"},{"x":-6,"y":3,"z":0,"name":"Soil_Dirt"},{"x":-6,"y":4,"z":0,"name":"Soil_Dirt"},{"x":-6,"y":5,"z":0,"name":"Soil_Pathway"},{"x":-6,"y":0,"z":1,"name":"Soil_Dirt"},{"x":-6,"y":1,"z":1,"name":"Soil_Dirt"},{"x":-6,"y":2,"z":1,"name":"Soil_Dirt"},{"x":-6,"y":3,"z":1,"name":"Soil_Dirt"},{"x":-6,"y":4,"z":1,"name":"Soil_Dirt"},{"x":-6,"y":5,"z":1,"name":"Soil_Mud"},{"x":-6,"y":0,"z":2,"name":"Soil_Dirt"},{"x":-6,"y":1,"z":2,"name":"Soil_Dirt"},{"x":-6,"y":2,"z":2,"name":"Soil_Dirt"},{"x":-6,"y":3,"z":2,"name":"Soil_Dirt"},{"x":-6,"y":4,"z":2,"name":"Soil_Dirt"},{"x":-6,"y":5,"z":2,"name":"Soil_Pathway"},{"x":-6,"y":0,"z":3,"name":"Soil_Dirt"},{"x":-6,"y":1,"z":3,"name":"Soil_Dirt"},{"x":-6,"y":2,"z":3,"name":"Soil_Dirt"},{"x":-6,"y":3,"z":3,"name":"Soil_Dirt"},{"x":-6,"y":4,"z":3,"name":"Soil_Dirt"},{"x":-6,"y":5,"z":3,"name":"Soil_Mud"},{"x":-6,"y":0,"z":4,"name":"Soil_Dirt"},{"x":-6,"y":1,"z":4,"name":"Soil_Dirt"},{"x":-6,"y":2,"z":4,"name":"Soil_Dirt"},{"x":-6,"y":3,"z":4,"name":"Soil_Dirt"},{"x":-6,"y":4,"z":4,"name":"Soil_Dirt"},{"x":-6,"y":5,"z":4,"name":"Soil_Dirt"},{"x":-6,"y":0,"z":5,"name":"Soil_Dirt"},{"x":-6,"y":1,"z":5,"name":"Soil_Dirt"},{"x":-6,"y":2,"z":5,"name":"Soil_Dirt"},{"x":-6,"y":3,"z":5,"name":"Soil_Dirt"},{"x":-6,"y":4,"z":5,"name":"Soil_Dirt"},{"x":-6,"y":5,"z":5,"name":"Soil_Pathway"},{"x":-6,"y":7,"z":5,"name":"Cloth_Modern_Red_Roof_Vertical_Flap","support":15,"rotation":3},{"x":-6,"y":8,"z":5,"name":"Cloth_Modern_Red_Roof_Vertical","support":15,"rotation":3},{"x":-6,"y":0,"z":6,"name":"Soil_Dirt"},{"x":-6,"y":1,"z":6,"name":"Soil_Dirt"},{"x":-6,"y":2,"z":6,"name":"Soil_Dirt"},{"x":-6,"y":3,"z":6,"name":"Soil_Dirt"},{"x":-6,"y":4,"z":6,"name":"Soil_Dirt"},{"x":-6,"y":5,"z":6,"name":"Soil_Pathway"},{"x":-6,"y":0,"z":7,"name":"Soil_Dirt"},{"x":-6,"y":1,"z":7,"name":"Soil_Dirt"},{"x":-6,"y":2,"z":7,"name":"Soil_Dirt"},{"x":-6,"y":3,"z":7,"name":"Soil_Dirt"},{"x":-6,"y":4,"z":7,"name":"Soil_Dirt"},{"x":-6,"y":5,"z":7,"name":"Soil_Pathway"},{"x":-6,"y":0,"z":8,"name":"Soil_Dirt"},{"x":-6,"y":1,"z":8,"name":"Soil_Dirt"},{"x":-6,"y":2,"z":8,"name":"Soil_Dirt"},{"x":-6,"y":3,"z":8,"name":"Soil_Dirt"},{"x":-6,"y":4,"z":8,"name":"Soil_Dirt"},{"x":-6,"y":5,"z":8,"name":"Cloth_Block_Wool_Black","support":15},{"x":-6,"y":0,"z":9,"name":"Soil_Dirt"},{"x":-6,"y":1,"z":9,"name":"Soil_Dirt"},{"x":-6,"y":2,"z":9,"name":"Soil_Dirt"},{"x":-6,"y":3,"z":9,"name":"Soil_Dirt"},{"x":-6,"y":4,"z":9,"name":"Soil_Dirt"},{"x":-6,"y":5,"z":9,"name":"Cloth_Block_Wool_White","support":15},{"x":-6,"y":0,"z":10,"name":"Soil_Dirt"},{"x":-6,"y":1,"z":10,"name":"Soil_Dirt"},{"x":-6,"y":2,"z":10,"name":"Soil_Dirt"},{"x":-6,"y":3,"z":10,"name":"Soil_Dirt"},{"x":-6,"y":4,"z":10,"name":"Soil_Dirt"},{"x":-6,"y":5,"z":10,"name":"Soil_Pathway"},{"x":-6,"y":6,"z":10,"name":"Wood_Redwood_Fence","rotation":2},{"x":-6,"y":0,"z":11,"name":"Soil_Dirt"},{"x":-6,"y":1,"z":11,"name":"Soil_Dirt"},{"x":-6,"y":2,"z":11,"name":"Soil_Dirt"},{"x":-6,"y":3,"z":11,"name":"Soil_Dirt"},{"x":-6,"y":4,"z":11,"name":"Soil_Dirt"},{"x":-6,"y":5,"z":11,"name":"Soil_Dirt"},{"x":-6,"y":0,"z":12,"name":"Soil_Dirt"},{"x":-6,"y":1,"z":12,"name":"Soil_Dirt"},{"x":-6,"y":2,"z":12,"name":"Soil_Dirt"},{"x":-6,"y":3,"z":12,"name":"Soil_Dirt"},{"x":-6,"y":4,"z":12,"name":"Soil_Dirt"},{"x":-6,"y":5,"z":12,"name":"Soil_Mud"},{"x":-6,"y":0,"z":13,"name":"Soil_Dirt"},{"x":-6,"y":1,"z":13,"name":"Soil_Dirt"},{"x":-6,"y":2,"z":13,"name":"Soil_Dirt"},{"x":-6,"y":3,"z":13,"name":"Soil_Dirt"},{"x":-6,"y":4,"z":13,"name":"Soil_Dirt"},{"x":-6,"y":5,"z":13,"name":"Rock_Stone_Cobble"},{"x":-6,"y":0,"z":14,"name":"Soil_Dirt"},{"x":-6,"y":1,"z":14,"name":"Soil_Dirt"},{"x":-6,"y":2,"z":14,"name":"Soil_Dirt"},{"x":-6,"y":3,"z":14,"name":"Soil_Dirt"},{"x":-6,"y":4,"z":14,"name":"Soil_Dirt"},{"x":-6,"y":5,"z":14,"name":"Rock_Stone_Cobble"},{"x":-6,"y":0,"z":15,"name":"Soil_Dirt"},{"x":-6,"y":1,"z":15,"name":"Soil_Dirt"},{"x":-6,"y":2,"z":15,"name":"Soil_Dirt"},{"x":-6,"y":3,"z":15,"name":"Soil_Dirt"},{"x":-6,"y":4,"z":15,"name":"Soil_Dirt"},{"x":-6,"y":5,"z":15,"name":"Rock_Stone_Brick_Smooth","support":15},{"x":-5,"y":0,"z":-14,"name":"Soil_Dirt"},{"x":-5,"y":1,"z":-14,"name":"Soil_Dirt"},{"x":-5,"y":2,"z":-14,"name":"Soil_Dirt"},{"x":-5,"y":3,"z":-14,"name":"Soil_Dirt"},{"x":-5,"y":4,"z":-14,"name":"Soil_Dirt"},{"x":-5,"y":5,"z":-14,"name":"Rock_Stone_Brick_Smooth","support":15},{"x":-5,"y":0,"z":-13,"name":"Soil_Dirt"},{"x":-5,"y":1,"z":-13,"name":"Soil_Dirt"},{"x":-5,"y":2,"z":-13,"name":"Soil_Dirt"},{"x":-5,"y":3,"z":-13,"name":"Soil_Dirt"},{"x":-5,"y":4,"z":-13,"name":"Soil_Dirt"},{"x":-5,"y":5,"z":-13,"name":"Rock_Stone_Cobble_Mossy"},{"x":-5,"y":6,"z":-13,"name":"Furniture_Tavern_Planter","support":15},{"x":-5,"y":7,"z":-13,"name":"Plant_Flower_Tall_Yellow","support":15},{"x":-5,"y":0,"z":-12,"name":"Soil_Dirt"},{"x":-5,"y":1,"z":-12,"name":"Soil_Dirt"},{"x":-5,"y":2,"z":-12,"name":"Soil_Dirt"},{"x":-5,"y":3,"z":-12,"name":"Soil_Dirt"},{"x":-5,"y":4,"z":-12,"name":"Soil_Dirt"},{"x":-5,"y":5,"z":-12,"name":"Rock_Stone_Cobble"},{"x":-5,"y":0,"z":-11,"name":"Soil_Dirt"},{"x":-5,"y":1,"z":-11,"name":"Soil_Dirt"},{"x":-5,"y":2,"z":-11,"name":"Soil_Dirt"},{"x":-5,"y":3,"z":-11,"name":"Soil_Dirt"},{"x":-5,"y":4,"z":-11,"name":"Soil_Dirt"},{"x":-5,"y":5,"z":-11,"name":"Soil_Mud"},{"x":-5,"y":0,"z":-10,"name":"Soil_Dirt"},{"x":-5,"y":1,"z":-10,"name":"Soil_Dirt"},{"x":-5,"y":2,"z":-10,"name":"Soil_Dirt"},{"x":-5,"y":3,"z":-10,"name":"Soil_Dirt"},{"x":-5,"y":4,"z":-10,"name":"Soil_Dirt"},{"x":-5,"y":5,"z":-10,"name":"Soil_Pathway"},{"x":-5,"y":0,"z":-9,"name":"Soil_Dirt"},{"x":-5,"y":1,"z":-9,"name":"Soil_Dirt"},{"x":-5,"y":2,"z":-9,"name":"Soil_Dirt"},{"x":-5,"y":3,"z":-9,"name":"Soil_Dirt"},{"x":-5,"y":4,"z":-9,"name":"Soil_Dirt"},{"x":-5,"y":5,"z":-9,"name":"Soil_Mud"},{"x":-5,"y":6,"z":-9,"name":"*Wood_Redwood_Fence_State_Definitions_T"},{"x":-5,"y":0,"z":-8,"name":"Soil_Dirt"},{"x":-5,"y":1,"z":-8,"name":"Soil_Dirt"},{"x":-5,"y":2,"z":-8,"name":"Soil_Dirt"},{"x":-5,"y":3,"z":-8,"name":"Soil_Dirt"},{"x":-5,"y":4,"z":-8,"name":"Soil_Dirt"},{"x":-5,"y":5,"z":-8,"name":"Soil_Pathway"},{"x":-5,"y":6,"z":-8,"name":"Wood_Redwood_Fence","support":15,"rotation":1},{"x":-5,"y":0,"z":-7,"name":"Soil_Dirt"},{"x":-5,"y":1,"z":-7,"name":"Soil_Dirt"},{"x":-5,"y":2,"z":-7,"name":"Soil_Dirt"},{"x":-5,"y":3,"z":-7,"name":"Soil_Dirt"},{"x":-5,"y":4,"z":-7,"name":"Soil_Dirt"},{"x":-5,"y":5,"z":-7,"name":"Soil_Pathway"},{"x":-5,"y":6,"z":-7,"name":"Wood_Redwood_Fence","support":15,"rotation":1},{"x":-5,"y":0,"z":-6,"name":"Soil_Dirt"},{"x":-5,"y":1,"z":-6,"name":"Soil_Dirt"},{"x":-5,"y":2,"z":-6,"name":"Soil_Dirt"},{"x":-5,"y":3,"z":-6,"name":"Soil_Dirt"},{"x":-5,"y":4,"z":-6,"name":"Soil_Dirt"},{"x":-5,"y":5,"z":-6,"name":"Soil_Dirt"},{"x":-5,"y":6,"z":-6,"name":"Wood_Redwood_Fence","support":15,"rotation":1},{"x":-5,"y":0,"z":-5,"name":"Soil_Dirt"},{"x":-5,"y":1,"z":-5,"name":"Soil_Dirt"},{"x":-5,"y":2,"z":-5,"name":"Soil_Dirt"},{"x":-5,"y":3,"z":-5,"name":"Soil_Dirt"},{"x":-5,"y":4,"z":-5,"name":"Soil_Dirt"},{"x":-5,"y":5,"z":-5,"name":"Soil_Mud"},{"x":-5,"y":6,"z":-5,"name":"Wood_Redwood_Fence","support":15,"rotation":1},{"x":-5,"y":0,"z":-4,"name":"Soil_Dirt"},{"x":-5,"y":1,"z":-4,"name":"Soil_Dirt"},{"x":-5,"y":2,"z":-4,"name":"Soil_Dirt"},{"x":-5,"y":3,"z":-4,"name":"Soil_Dirt"},{"x":-5,"y":4,"z":-4,"name":"Soil_Dirt"},{"x":-5,"y":5,"z":-4,"name":"Soil_Pathway"},{"x":-5,"y":6,"z":-4,"name":"Wood_Redwood_Trunk_Full","support":15},{"x":-5,"y":7,"z":-4,"name":"Wood_Redwood_Beam","support":15},{"x":-5,"y":8,"z":-4,"name":"Wood_Redwood_Beam","support":15},{"x":-5,"y":9,"z":-4,"name":"Wood_Redwood_Planks_Half","support":15},{"x":-5,"y":0,"z":-3,"name":"Soil_Dirt"},{"x":-5,"y":1,"z":-3,"name":"Soil_Dirt"},{"x":-5,"y":2,"z":-3,"name":"Soil_Dirt"},{"x":-5,"y":3,"z":-3,"name":"Soil_Dirt"},{"x":-5,"y":4,"z":-3,"name":"Soil_Dirt"},{"x":-5,"y":5,"z":-3,"name":"Soil_Dirt"},{"x":-5,"y":6,"z":-3,"name":"Wood_Redwood_Fence","support":15,"rotation":1},{"x":-5,"y":0,"z":-2,"name":"Soil_Dirt"},{"x":-5,"y":1,"z":-2,"name":"Soil_Dirt"},{"x":-5,"y":2,"z":-2,"name":"Soil_Dirt"},{"x":-5,"y":3,"z":-2,"name":"Soil_Dirt"},{"x":-5,"y":4,"z":-2,"name":"Soil_Dirt"},{"x":-5,"y":5,"z":-2,"name":"Soil_Pathway"},{"x":-5,"y":6,"z":-2,"name":"Wood_Redwood_Fence","support":15,"rotation":1},{"x":-5,"y":0,"z":-1,"name":"Soil_Dirt"},{"x":-5,"y":1,"z":-1,"name":"Soil_Dirt"},{"x":-5,"y":2,"z":-1,"name":"Soil_Dirt"},{"x":-5,"y":3,"z":-1,"name":"Soil_Dirt"},{"x":-5,"y":4,"z":-1,"name":"Soil_Dirt"},{"x":-5,"y":5,"z":-1,"name":"Soil_Mud"},{"x":-5,"y":6,"z":-1,"name":"Wood_Redwood_Fence","support":15,"rotation":1},{"x":-5,"y":0,"z":0,"name":"Soil_Dirt"},{"x":-5,"y":1,"z":0,"name":"Soil_Dirt"},{"x":-5,"y":2,"z":0,"name":"Soil_Dirt"},{"x":-5,"y":3,"z":0,"name":"Soil_Dirt"},{"x":-5,"y":4,"z":0,"name":"Soil_Dirt"},{"x":-5,"y":5,"z":0,"name":"Soil_Mud"},{"x":-5,"y":6,"z":0,"name":"Wood_Redwood_Fence","support":15,"rotation":1},{"x":-5,"y":0,"z":1,"name":"Soil_Dirt"},{"x":-5,"y":1,"z":1,"name":"Soil_Dirt"},{"x":-5,"y":2,"z":1,"name":"Soil_Dirt"},{"x":-5,"y":3,"z":1,"name":"Soil_Dirt"},{"x":-5,"y":4,"z":1,"name":"Soil_Dirt"},{"x":-5,"y":5,"z":1,"name":"Soil_Dirt"},{"x":-5,"y":6,"z":1,"name":"Wood_Redwood_Fence","support":15,"rotation":1},{"x":-5,"y":0,"z":2,"name":"Soil_Dirt"},{"x":-5,"y":1,"z":2,"name":"Soil_Dirt"},{"x":-5,"y":2,"z":2,"name":"Soil_Dirt"},{"x":-5,"y":3,"z":2,"name":"Soil_Dirt"},{"x":-5,"y":4,"z":2,"name":"Soil_Dirt"},{"x":-5,"y":5,"z":2,"name":"Soil_Pathway"},{"x":-5,"y":6,"z":2,"name":"Wood_Redwood_Fence","support":15,"rotation":1},{"x":-5,"y":0,"z":3,"name":"Soil_Dirt"},{"x":-5,"y":1,"z":3,"name":"Soil_Dirt"},{"x":-5,"y":2,"z":3,"name":"Soil_Dirt"},{"x":-5,"y":3,"z":3,"name":"Soil_Dirt"},{"x":-5,"y":4,"z":3,"name":"Soil_Dirt"},{"x":-5,"y":5,"z":3,"name":"Soil_Mud"},{"x":-5,"y":6,"z":3,"name":"Wood_Redwood_Fence","support":15,"rotation":1},{"x":-5,"y":0,"z":4,"name":"Soil_Dirt"},{"x":-5,"y":1,"z":4,"name":"Soil_Dirt"},{"x":-5,"y":2,"z":4,"name":"Soil_Dirt"},{"x":-5,"y":3,"z":4,"name":"Soil_Dirt"},{"x":-5,"y":4,"z":4,"name":"Soil_Dirt"},{"x":-5,"y":5,"z":4,"name":"Soil_Pathway"},{"x":-5,"y":6,"z":4,"name":"Wood_Redwood_Fence","support":15,"rotation":1},{"x":-5,"y":0,"z":5,"name":"Soil_Dirt"},{"x":-5,"y":1,"z":5,"name":"Soil_Dirt"},{"x":-5,"y":2,"z":5,"name":"Soil_Dirt"},{"x":-5,"y":3,"z":5,"name":"Soil_Dirt"},{"x":-5,"y":4,"z":5,"name":"Soil_Dirt"},{"x":-5,"y":5,"z":5,"name":"Soil_Pathway"},{"x":-5,"y":6,"z":5,"name":"Wood_Redwood_Trunk_Full","support":15},{"x":-5,"y":7,"z":5,"name":"Wood_Redwood_Beam","support":15},{"x":-5,"y":8,"z":5,"name":"Wood_Redwood_Beam","support":15},{"x":-5,"y":9,"z":5,"name":"Wood_Redwood_Planks_Half","support":15},{"x":-5,"y":0,"z":6,"name":"Soil_Dirt"},{"x":-5,"y":1,"z":6,"name":"Soil_Dirt"},{"x":-5,"y":2,"z":6,"name":"Soil_Dirt"},{"x":-5,"y":3,"z":6,"name":"Soil_Dirt"},{"x":-5,"y":4,"z":6,"name":"Soil_Dirt"},{"x":-5,"y":5,"z":6,"name":"Soil_Dirt"},{"x":-5,"y":6,"z":6,"name":"Wood_Redwood_Fence","support":15,"rotation":1},{"x":-5,"y":0,"z":7,"name":"Soil_Dirt"},{"x":-5,"y":1,"z":7,"name":"Soil_Dirt"},{"x":-5,"y":2,"z":7,"name":"Soil_Dirt"},{"x":-5,"y":3,"z":7,"name":"Soil_Dirt"},{"x":-5,"y":4,"z":7,"name":"Soil_Dirt"},{"x":-5,"y":5,"z":7,"name":"Soil_Pathway"},{"x":-5,"y":6,"z":7,"name":"Wood_Redwood_Fence","support":15,"rotation":1},{"x":-5,"y":0,"z":8,"name":"Soil_Dirt"},{"x":-5,"y":1,"z":8,"name":"Soil_Dirt"},{"x":-5,"y":2,"z":8,"name":"Soil_Dirt"},{"x":-5,"y":3,"z":8,"name":"Soil_Dirt"},{"x":-5,"y":4,"z":8,"name":"Soil_Dirt"},{"x":-5,"y":5,"z":8,"name":"Soil_Pathway"},{"x":-5,"y":6,"z":8,"name":"Wood_Redwood_Fence","support":15,"rotation":1},{"x":-5,"y":0,"z":9,"name":"Soil_Dirt"},{"x":-5,"y":1,"z":9,"name":"Soil_Dirt"},{"x":-5,"y":2,"z":9,"name":"Soil_Dirt"},{"x":-5,"y":3,"z":9,"name":"Soil_Dirt"},{"x":-5,"y":4,"z":9,"name":"Soil_Dirt"},{"x":-5,"y":5,"z":9,"name":"Soil_Pathway"},{"x":-5,"y":6,"z":9,"name":"Wood_Redwood_Fence","support":15,"rotation":1},{"x":-5,"y":0,"z":10,"name":"Soil_Dirt"},{"x":-5,"y":1,"z":10,"name":"Soil_Dirt"},{"x":-5,"y":2,"z":10,"name":"Soil_Dirt"},{"x":-5,"y":3,"z":10,"name":"Soil_Dirt"},{"x":-5,"y":4,"z":10,"name":"Soil_Dirt"},{"x":-5,"y":5,"z":10,"name":"Soil_Pathway"},{"x":-5,"y":6,"z":10,"name":"*Wood_Redwood_Fence_State_Definitions_T","rotation":2},{"x":-5,"y":0,"z":11,"name":"Soil_Dirt"},{"x":-5,"y":1,"z":11,"name":"Soil_Dirt"},{"x":-5,"y":2,"z":11,"name":"Soil_Dirt"},{"x":-5,"y":3,"z":11,"name":"Soil_Dirt"},{"x":-5,"y":4,"z":11,"name":"Soil_Dirt"},{"x":-5,"y":5,"z":11,"name":"Soil_Pathway"},{"x":-5,"y":0,"z":12,"name":"Soil_Dirt"},{"x":-5,"y":1,"z":12,"name":"Soil_Dirt"},{"x":-5,"y":2,"z":12,"name":"Soil_Dirt"},{"x":-5,"y":3,"z":12,"name":"Soil_Dirt"},{"x":-5,"y":4,"z":12,"name":"Soil_Dirt"},{"x":-5,"y":5,"z":12,"name":"Soil_Pathway"},{"x":-5,"y":0,"z":13,"name":"Soil_Dirt"},{"x":-5,"y":1,"z":13,"name":"Soil_Dirt"},{"x":-5,"y":2,"z":13,"name":"Soil_Dirt"},{"x":-5,"y":3,"z":13,"name":"Soil_Dirt"},{"x":-5,"y":4,"z":13,"name":"Soil_Dirt"},{"x":-5,"y":5,"z":13,"name":"Soil_Dirt"},{"x":-5,"y":0,"z":14,"name":"Soil_Dirt"},{"x":-5,"y":1,"z":14,"name":"Soil_Dirt"},{"x":-5,"y":2,"z":14,"name":"Soil_Dirt"},{"x":-5,"y":3,"z":14,"name":"Soil_Dirt"},{"x":-5,"y":4,"z":14,"name":"Soil_Dirt"},{"x":-5,"y":5,"z":14,"name":"Rock_Stone_Cobble"},{"x":-5,"y":6,"z":14,"name":"Furniture_Tavern_Planter","support":15},{"x":-5,"y":7,"z":14,"name":"Plant_Flower_Common_Red2","support":15},{"x":-5,"y":0,"z":15,"name":"Soil_Dirt"},{"x":-5,"y":1,"z":15,"name":"Soil_Dirt"},{"x":-5,"y":2,"z":15,"name":"Soil_Dirt"},{"x":-5,"y":3,"z":15,"name":"Soil_Dirt"},{"x":-5,"y":4,"z":15,"name":"Soil_Dirt"},{"x":-5,"y":5,"z":15,"name":"Rock_Stone_Brick_Smooth","support":15},{"x":-4,"y":0,"z":-14,"name":"Soil_Dirt"},{"x":-4,"y":1,"z":-14,"name":"Soil_Dirt"},{"x":-4,"y":2,"z":-14,"name":"Soil_Dirt"},{"x":-4,"y":3,"z":-14,"name":"Soil_Dirt"},{"x":-4,"y":4,"z":-14,"name":"Soil_Dirt"},{"x":-4,"y":5,"z":-14,"name":"Rock_Stone_Brick_Smooth","support":15},{"x":-4,"y":9,"z":-14,"name":"Cloth_Modern_Red_Roof_Vertical_Flap","support":15,"rotation":2},{"x":-4,"y":0,"z":-13,"name":"Soil_Dirt"},{"x":-4,"y":1,"z":-13,"name":"Soil_Dirt"},{"x":-4,"y":2,"z":-13,"name":"Soil_Dirt"},{"x":-4,"y":3,"z":-13,"name":"Soil_Dirt"},{"x":-4,"y":4,"z":-13,"name":"Soil_Dirt"},{"x":-4,"y":5,"z":-13,"name":"Rock_Stone_Cobble"},{"x":-4,"y":6,"z":-13,"name":"Wood_Softwood_Beam","support":15,"rotation":2},{"x":-4,"y":7,"z":-13,"name":"Wood_Softwood_Beam","support":15,"rotation":2},{"x":-4,"y":8,"z":-13,"name":"Wood_Softwood_Beam","support":15,"rotation":2},{"x":-4,"y":9,"z":-13,"name":"Wood_Softwood_Beam","support":15,"rotation":2},{"x":-4,"y":10,"z":-13,"name":"Wood_Redwood_Planks_Half","support":15},{"x":-4,"y":0,"z":-12,"name":"Soil_Dirt"},{"x":-4,"y":1,"z":-12,"name":"Soil_Dirt"},{"x":-4,"y":2,"z":-12,"name":"Soil_Dirt"},{"x":-4,"y":3,"z":-12,"name":"Soil_Dirt"},{"x":-4,"y":4,"z":-12,"name":"Soil_Dirt"},{"x":-4,"y":5,"z":-12,"name":"Rock_Stone_Cobble"},{"x":-4,"y":9,"z":-12,"name":"Cloth_Modern_Red_Roof_Vertical_Flap","support":15},{"x":-4,"y":0,"z":-11,"name":"Soil_Dirt"},{"x":-4,"y":1,"z":-11,"name":"Soil_Dirt"},{"x":-4,"y":2,"z":-11,"name":"Soil_Dirt"},{"x":-4,"y":3,"z":-11,"name":"Soil_Dirt"},{"x":-4,"y":4,"z":-11,"name":"Soil_Dirt"},{"x":-4,"y":5,"z":-11,"name":"Soil_Dirt"},{"x":-4,"y":0,"z":-10,"name":"Soil_Dirt"},{"x":-4,"y":1,"z":-10,"name":"Soil_Dirt"},{"x":-4,"y":2,"z":-10,"name":"Soil_Dirt"},{"x":-4,"y":3,"z":-10,"name":"Soil_Dirt"},{"x":-4,"y":4,"z":-10,"name":"Soil_Dirt"},{"x":-4,"y":5,"z":-10,"name":"Soil_Mud"},{"x":-4,"y":0,"z":-9,"name":"Soil_Dirt"},{"x":-4,"y":1,"z":-9,"name":"Soil_Dirt"},{"x":-4,"y":2,"z":-9,"name":"Soil_Dirt"},{"x":-4,"y":3,"z":-9,"name":"Soil_Dirt"},{"x":-4,"y":4,"z":-9,"name":"Soil_Dirt"},{"x":-4,"y":5,"z":-9,"name":"Soil_Pathway"},{"x":-4,"y":6,"z":-9,"name":"Wood_Redwood_Fence","support":15,"rotation":2},{"x":-4,"y":0,"z":-8,"name":"Soil_Dirt"},{"x":-4,"y":1,"z":-8,"name":"Soil_Dirt"},{"x":-4,"y":2,"z":-8,"name":"Soil_Dirt"},{"x":-4,"y":3,"z":-8,"name":"Soil_Dirt"},{"x":-4,"y":4,"z":-8,"name":"Soil_Dirt"},{"x":-4,"y":5,"z":-8,"name":"Soil_Pathway"},{"x":-4,"y":0,"z":-7,"name":"Soil_Dirt"},{"x":-4,"y":1,"z":-7,"name":"Soil_Dirt"},{"x":-4,"y":2,"z":-7,"name":"Soil_Dirt"},{"x":-4,"y":3,"z":-7,"name":"Soil_Dirt"},{"x":-4,"y":4,"z":-7,"name":"Soil_Dirt"},{"x":-4,"y":5,"z":-7,"name":"Soil_Mud"},{"x":-4,"y":0,"z":-6,"name":"Soil_Dirt"},{"x":-4,"y":1,"z":-6,"name":"Soil_Dirt"},{"x":-4,"y":2,"z":-6,"name":"Soil_Dirt"},{"x":-4,"y":3,"z":-6,"name":"Soil_Dirt"},{"x":-4,"y":4,"z":-6,"name":"Soil_Dirt"},{"x":-4,"y":5,"z":-6,"name":"Cloth_Block_Wool_Green","support":15},{"x":-4,"y":0,"z":-5,"name":"Soil_Dirt"},{"x":-4,"y":1,"z":-5,"name":"Soil_Dirt"},{"x":-4,"y":2,"z":-5,"name":"Soil_Dirt"},{"x":-4,"y":3,"z":-5,"name":"Soil_Dirt"},{"x":-4,"y":4,"z":-5,"name":"Soil_Dirt"},{"x":-4,"y":5,"z":-5,"name":"Soil_Pathway"},{"x":-4,"y":0,"z":-4,"name":"Soil_Dirt"},{"x":-4,"y":1,"z":-4,"name":"Soil_Dirt"},{"x":-4,"y":2,"z":-4,"name":"Soil_Dirt"},{"x":-4,"y":3,"z":-4,"name":"Soil_Dirt"},{"x":-4,"y":4,"z":-4,"name":"Soil_Dirt"},{"x":-4,"y":5,"z":-4,"name":"Soil_Pathway"},{"x":-4,"y":7,"z":-4,"name":"Cloth_Modern_Red_Roof_Vertical_Flap","support":15,"rotation":1},{"x":-4,"y":8,"z":-4,"name":"Cloth_Modern_Red_Roof_Vertical","support":15,"rotation":1},{"x":-4,"y":0,"z":-3,"name":"Soil_Dirt"},{"x":-4,"y":1,"z":-3,"name":"Soil_Dirt"},{"x":-4,"y":2,"z":-3,"name":"Soil_Dirt"},{"x":-4,"y":3,"z":-3,"name":"Soil_Dirt"},{"x":-4,"y":4,"z":-3,"name":"Soil_Dirt"},{"x":-4,"y":5,"z":-3,"name":"Soil_Pathway"},{"x":-4,"y":0,"z":-2,"name":"Soil_Dirt"},{"x":-4,"y":1,"z":-2,"name":"Soil_Dirt"},{"x":-4,"y":2,"z":-2,"name":"Soil_Dirt"},{"x":-4,"y":3,"z":-2,"name":"Soil_Dirt"},{"x":-4,"y":4,"z":-2,"name":"Soil_Dirt"},{"x":-4,"y":5,"z":-2,"name":"Soil_Pathway"},{"x":-4,"y":0,"z":-1,"name":"Soil_Dirt"},{"x":-4,"y":1,"z":-1,"name":"Soil_Dirt"},{"x":-4,"y":2,"z":-1,"name":"Soil_Dirt"},{"x":-4,"y":3,"z":-1,"name":"Soil_Dirt"},{"x":-4,"y":4,"z":-1,"name":"Soil_Dirt"},{"x":-4,"y":5,"z":-1,"name":"Soil_Mud"},{"x":-4,"y":0,"z":0,"name":"Soil_Dirt"},{"x":-4,"y":1,"z":0,"name":"Soil_Dirt"},{"x":-4,"y":2,"z":0,"name":"Soil_Dirt"},{"x":-4,"y":3,"z":0,"name":"Soil_Dirt"},{"x":-4,"y":4,"z":0,"name":"Soil_Dirt"},{"x":-4,"y":5,"z":0,"name":"Soil_Dirt"},{"x":-4,"y":0,"z":1,"name":"Soil_Dirt"},{"x":-4,"y":1,"z":1,"name":"Soil_Dirt"},{"x":-4,"y":2,"z":1,"name":"Soil_Dirt"},{"x":-4,"y":3,"z":1,"name":"Soil_Dirt"},{"x":-4,"y":4,"z":1,"name":"Soil_Dirt"},{"x":-4,"y":5,"z":1,"name":"Soil_Pathway"},{"x":-4,"y":0,"z":2,"name":"Soil_Dirt"},{"x":-4,"y":1,"z":2,"name":"Soil_Dirt"},{"x":-4,"y":2,"z":2,"name":"Soil_Dirt"},{"x":-4,"y":3,"z":2,"name":"Soil_Dirt"},{"x":-4,"y":4,"z":2,"name":"Soil_Dirt"},{"x":-4,"y":5,"z":2,"name":"Soil_Pathway"},{"x":-4,"y":0,"z":3,"name":"Soil_Dirt"},{"x":-4,"y":1,"z":3,"name":"Soil_Dirt"},{"x":-4,"y":2,"z":3,"name":"Soil_Dirt"},{"x":-4,"y":3,"z":3,"name":"Soil_Dirt"},{"x":-4,"y":4,"z":3,"name":"Soil_Dirt"},{"x":-4,"y":5,"z":3,"name":"Soil_Pathway"},{"x":-4,"y":0,"z":4,"name":"Soil_Dirt"},{"x":-4,"y":1,"z":4,"name":"Soil_Dirt"},{"x":-4,"y":2,"z":4,"name":"Soil_Dirt"},{"x":-4,"y":3,"z":4,"name":"Soil_Dirt"},{"x":-4,"y":4,"z":4,"name":"Soil_Dirt"},{"x":-4,"y":5,"z":4,"name":"Soil_Pathway"},{"x":-4,"y":0,"z":5,"name":"Soil_Dirt"},{"x":-4,"y":1,"z":5,"name":"Soil_Dirt"},{"x":-4,"y":2,"z":5,"name":"Soil_Dirt"},{"x":-4,"y":3,"z":5,"name":"Soil_Dirt"},{"x":-4,"y":4,"z":5,"name":"Soil_Dirt"},{"x":-4,"y":5,"z":5,"name":"Soil_Dirt"},{"x":-4,"y":7,"z":5,"name":"Cloth_Modern_Red_Roof_Vertical_Flap","support":15,"rotation":1},{"x":-4,"y":8,"z":5,"name":"Cloth_Modern_Red_Roof_Vertical","support":15,"rotation":1},{"x":-4,"y":0,"z":6,"name":"Soil_Dirt"},{"x":-4,"y":1,"z":6,"name":"Soil_Dirt"},{"x":-4,"y":2,"z":6,"name":"Soil_Dirt"},{"x":-4,"y":3,"z":6,"name":"Soil_Dirt"},{"x":-4,"y":4,"z":6,"name":"Soil_Dirt"},{"x":-4,"y":5,"z":6,"name":"Soil_Mud"},{"x":-4,"y":0,"z":7,"name":"Soil_Dirt"},{"x":-4,"y":1,"z":7,"name":"Soil_Dirt"},{"x":-4,"y":2,"z":7,"name":"Soil_Dirt"},{"x":-4,"y":3,"z":7,"name":"Soil_Dirt"},{"x":-4,"y":4,"z":7,"name":"Soil_Dirt"},{"x":-4,"y":5,"z":7,"name":"Soil_Dirt"},{"x":-4,"y":0,"z":8,"name":"Soil_Dirt"},{"x":-4,"y":1,"z":8,"name":"Soil_Dirt"},{"x":-4,"y":2,"z":8,"name":"Soil_Dirt"},{"x":-4,"y":3,"z":8,"name":"Soil_Dirt"},{"x":-4,"y":4,"z":8,"name":"Soil_Dirt"},{"x":-4,"y":5,"z":8,"name":"Cloth_Block_Wool_White","support":15},{"x":-4,"y":0,"z":9,"name":"Soil_Dirt"},{"x":-4,"y":1,"z":9,"name":"Soil_Dirt"},{"x":-4,"y":2,"z":9,"name":"Soil_Dirt"},{"x":-4,"y":3,"z":9,"name":"Soil_Dirt"},{"x":-4,"y":4,"z":9,"name":"Soil_Dirt"},{"x":-4,"y":5,"z":9,"name":"Cloth_Block_Wool_Black","support":15},{"x":-4,"y":0,"z":10,"name":"Soil_Dirt"},{"x":-4,"y":1,"z":10,"name":"Soil_Dirt"},{"x":-4,"y":2,"z":10,"name":"Soil_Dirt"},{"x":-4,"y":3,"z":10,"name":"Soil_Dirt"},{"x":-4,"y":4,"z":10,"name":"Soil_Dirt"},{"x":-4,"y":5,"z":10,"name":"Soil_Pathway"},{"x":-4,"y":6,"z":10,"name":"Wood_Redwood_Fence","support":15},{"x":-4,"y":0,"z":11,"name":"Soil_Dirt"},{"x":-4,"y":1,"z":11,"name":"Soil_Dirt"},{"x":-4,"y":2,"z":11,"name":"Soil_Dirt"},{"x":-4,"y":3,"z":11,"name":"Soil_Dirt"},{"x":-4,"y":4,"z":11,"name":"Soil_Dirt"},{"x":-4,"y":5,"z":11,"name":"Soil_Dirt"},{"x":-4,"y":0,"z":12,"name":"Soil_Dirt"},{"x":-4,"y":1,"z":12,"name":"Soil_Dirt"},{"x":-4,"y":2,"z":12,"name":"Soil_Dirt"},{"x":-4,"y":3,"z":12,"name":"Soil_Dirt"},{"x":-4,"y":4,"z":12,"name":"Soil_Dirt"},{"x":-4,"y":5,"z":12,"name":"Soil_Mud"},{"x":-4,"y":0,"z":13,"name":"Soil_Dirt"},{"x":-4,"y":1,"z":13,"name":"Soil_Dirt"},{"x":-4,"y":2,"z":13,"name":"Soil_Dirt"},{"x":-4,"y":3,"z":13,"name":"Soil_Dirt"},{"x":-4,"y":4,"z":13,"name":"Soil_Dirt"},{"x":-4,"y":5,"z":13,"name":"Soil_Dirt"},{"x":-4,"y":9,"z":13,"name":"Cloth_Modern_Red_Roof_Vertical_Flap","support":15,"rotation":2},{"x":-4,"y":0,"z":14,"name":"Soil_Dirt"},{"x":-4,"y":1,"z":14,"name":"Soil_Dirt"},{"x":-4,"y":2,"z":14,"name":"Soil_Dirt"},{"x":-4,"y":3,"z":14,"name":"Soil_Dirt"},{"x":-4,"y":4,"z":14,"name":"Soil_Dirt"},{"x":-4,"y":5,"z":14,"name":"Rock_Stone_Cobble"},{"x":-4,"y":6,"z":14,"name":"Wood_Softwood_Beam","support":15},{"x":-4,"y":7,"z":14,"name":"Wood_Softwood_Beam","support":15},{"x":-4,"y":8,"z":14,"name":"Wood_Softwood_Beam","support":15},{"x":-4,"y":9,"z":14,"name":"Wood_Softwood_Beam","support":15},{"x":-4,"y":10,"z":14,"name":"Wood_Redwood_Planks_Half","support":15},{"x":-4,"y":0,"z":15,"name":"Soil_Dirt"},{"x":-4,"y":1,"z":15,"name":"Soil_Dirt"},{"x":-4,"y":2,"z":15,"name":"Soil_Dirt"},{"x":-4,"y":3,"z":15,"name":"Soil_Dirt"},{"x":-4,"y":4,"z":15,"name":"Soil_Dirt"},{"x":-4,"y":5,"z":15,"name":"Rock_Stone_Brick_Smooth","support":15},{"x":-4,"y":9,"z":15,"name":"Cloth_Modern_Red_Roof_Vertical_Flap","support":15},{"x":-3,"y":0,"z":-14,"name":"Soil_Dirt"},{"x":-3,"y":1,"z":-14,"name":"Soil_Dirt"},{"x":-3,"y":2,"z":-14,"name":"Soil_Dirt"},{"x":-3,"y":3,"z":-14,"name":"Soil_Dirt"},{"x":-3,"y":4,"z":-14,"name":"Soil_Dirt"},{"x":-3,"y":5,"z":-14,"name":"Rock_Stone_Brick_Smooth","support":15},{"x":-3,"y":0,"z":-13,"name":"Soil_Dirt"},{"x":-3,"y":1,"z":-13,"name":"Soil_Dirt"},{"x":-3,"y":2,"z":-13,"name":"Soil_Dirt"},{"x":-3,"y":3,"z":-13,"name":"Soil_Dirt"},{"x":-3,"y":4,"z":-13,"name":"Soil_Dirt"},{"x":-3,"y":5,"z":-13,"name":"Rock_Stone_Cobble"},{"x":-3,"y":6,"z":-13,"name":"Furniture_Tavern_Planter","support":15},{"x":-3,"y":7,"z":-13,"name":"Plant_Flower_Common_Red2","support":15},{"x":-3,"y":0,"z":-12,"name":"Soil_Dirt"},{"x":-3,"y":1,"z":-12,"name":"Soil_Dirt"},{"x":-3,"y":2,"z":-12,"name":"Soil_Dirt"},{"x":-3,"y":3,"z":-12,"name":"Soil_Dirt"},{"x":-3,"y":4,"z":-12,"name":"Soil_Dirt"},{"x":-3,"y":5,"z":-12,"name":"Rock_Stone_Cobble_Mossy"},{"x":-3,"y":0,"z":-11,"name":"Soil_Dirt"},{"x":-3,"y":1,"z":-11,"name":"Soil_Dirt"},{"x":-3,"y":2,"z":-11,"name":"Soil_Dirt"},{"x":-3,"y":3,"z":-11,"name":"Soil_Dirt"},{"x":-3,"y":4,"z":-11,"name":"Soil_Dirt"},{"x":-3,"y":5,"z":-11,"name":"Rock_Stone_Cobble"},{"x":-3,"y":0,"z":-10,"name":"Soil_Dirt"},{"x":-3,"y":1,"z":-10,"name":"Soil_Dirt"},{"x":-3,"y":2,"z":-10,"name":"Soil_Dirt"},{"x":-3,"y":3,"z":-10,"name":"Soil_Dirt"},{"x":-3,"y":4,"z":-10,"name":"Soil_Dirt"},{"x":-3,"y":5,"z":-10,"name":"Soil_Dirt"},{"x":-3,"y":0,"z":-9,"name":"Soil_Dirt"},{"x":-3,"y":1,"z":-9,"name":"Soil_Dirt"},{"x":-3,"y":2,"z":-9,"name":"Soil_Dirt"},{"x":-3,"y":3,"z":-9,"name":"Soil_Dirt"},{"x":-3,"y":4,"z":-9,"name":"Soil_Dirt"},{"x":-3,"y":5,"z":-9,"name":"Soil_Dirt"},{"x":-3,"y":6,"z":-9,"name":"Wood_Redwood_Fence","support":15,"rotation":2},{"x":-3,"y":0,"z":-8,"name":"Soil_Dirt"},{"x":-3,"y":1,"z":-8,"name":"Soil_Dirt"},{"x":-3,"y":2,"z":-8,"name":"Soil_Dirt"},{"x":-3,"y":3,"z":-8,"name":"Soil_Dirt"},{"x":-3,"y":4,"z":-8,"name":"Soil_Dirt"},{"x":-3,"y":5,"z":-8,"name":"Soil_Pathway"},{"x":-3,"y":0,"z":-7,"name":"Soil_Dirt"},{"x":-3,"y":1,"z":-7,"name":"Soil_Dirt"},{"x":-3,"y":2,"z":-7,"name":"Soil_Dirt"},{"x":-3,"y":3,"z":-7,"name":"Soil_Dirt"},{"x":-3,"y":4,"z":-7,"name":"Soil_Dirt"},{"x":-3,"y":5,"z":-7,"name":"Soil_Pathway"},{"x":-3,"y":0,"z":-6,"name":"Soil_Dirt"},{"x":-3,"y":1,"z":-6,"name":"Soil_Dirt"},{"x":-3,"y":2,"z":-6,"name":"Soil_Dirt"},{"x":-3,"y":3,"z":-6,"name":"Soil_Dirt"},{"x":-3,"y":4,"z":-6,"name":"Soil_Dirt"},{"x":-3,"y":5,"z":-6,"name":"Cloth_Block_Wool_Green","support":15},{"x":-3,"y":0,"z":-5,"name":"Soil_Dirt"},{"x":-3,"y":1,"z":-5,"name":"Soil_Dirt"},{"x":-3,"y":2,"z":-5,"name":"Soil_Dirt"},{"x":-3,"y":3,"z":-5,"name":"Soil_Dirt"},{"x":-3,"y":4,"z":-5,"name":"Soil_Dirt"},{"x":-3,"y":5,"z":-5,"name":"Soil_Pathway"},{"x":-3,"y":0,"z":-4,"name":"Soil_Dirt"},{"x":-3,"y":1,"z":-4,"name":"Soil_Dirt"},{"x":-3,"y":2,"z":-4,"name":"Soil_Dirt"},{"x":-3,"y":3,"z":-4,"name":"Soil_Dirt"},{"x":-3,"y":4,"z":-4,"name":"Soil_Dirt"},{"x":-3,"y":5,"z":-4,"name":"Soil_Dirt"},{"x":-3,"y":0,"z":-3,"name":"Soil_Dirt"},{"x":-3,"y":1,"z":-3,"name":"Soil_Dirt"},{"x":-3,"y":2,"z":-3,"name":"Soil_Dirt"},{"x":-3,"y":3,"z":-3,"name":"Soil_Dirt"},{"x":-3,"y":4,"z":-3,"name":"Soil_Dirt"},{"x":-3,"y":5,"z":-3,"name":"Soil_Dirt"},{"x":-3,"y":0,"z":-2,"name":"Soil_Dirt"},{"x":-3,"y":1,"z":-2,"name":"Soil_Dirt"},{"x":-3,"y":2,"z":-2,"name":"Soil_Dirt"},{"x":-3,"y":3,"z":-2,"name":"Soil_Dirt"},{"x":-3,"y":4,"z":-2,"name":"Soil_Dirt"},{"x":-3,"y":5,"z":-2,"name":"Soil_Pathway"},{"x":-3,"y":0,"z":-1,"name":"Soil_Dirt"},{"x":-3,"y":1,"z":-1,"name":"Soil_Dirt"},{"x":-3,"y":2,"z":-1,"name":"Soil_Dirt"},{"x":-3,"y":3,"z":-1,"name":"Soil_Dirt"},{"x":-3,"y":4,"z":-1,"name":"Soil_Dirt"},{"x":-3,"y":5,"z":-1,"name":"Soil_Pathway"},{"x":-3,"y":0,"z":0,"name":"Soil_Dirt"},{"x":-3,"y":1,"z":0,"name":"Soil_Dirt"},{"x":-3,"y":2,"z":0,"name":"Soil_Dirt"},{"x":-3,"y":3,"z":0,"name":"Soil_Dirt"},{"x":-3,"y":4,"z":0,"name":"Soil_Dirt"},{"x":-3,"y":5,"z":0,"name":"Soil_Pathway"},{"x":-3,"y":0,"z":1,"name":"Soil_Dirt"},{"x":-3,"y":1,"z":1,"name":"Soil_Dirt"},{"x":-3,"y":2,"z":1,"name":"Soil_Dirt"},{"x":-3,"y":3,"z":1,"name":"Soil_Dirt"},{"x":-3,"y":4,"z":1,"name":"Soil_Dirt"},{"x":-3,"y":5,"z":1,"name":"Soil_Dirt"},{"x":-3,"y":0,"z":2,"name":"Soil_Dirt"},{"x":-3,"y":1,"z":2,"name":"Soil_Dirt"},