{
  "version": 8,
  "blockIdVersion": 11,
  "anchorX": 0,
  "anchorY": 0,
  "anchorZ": 0,
  "blocks": [
    {
      "x": -14,
      "y": 0,
      "z": -14,
      "name": "Soil_Dirt"
    },
    {
      "x": -14,
      "y": 1,
      "z": -14,
      "name": "Soil_Dirt"
    },
    {
      "x": -14,
      "y": 2,
      "z": -14,
      "name": "Soil_Dirt"
    },
    {
      "x": -14,
      "y": 3,
      "z": -14,
      "name": "Soil_Dirt"
    },
    {
      "x": -14,
      "y": 4,
      "z": -14,
      "name": "Soil_Dirt"
    },
    {
      "x": -14,
      "y": 5,
      "z": -14,
      "name": "Rock_Stone_Brick_Smooth"
    },
    {
      "x": -14,
      "y": 0,
      "z": -13,
      "name": "Soil_Dirt"
    },
    {
      "x": -14,
      "y": 1,
      "z": -13,
      "name": "Soil_Dirt"
    },
    {
      "x": -14,
      "y": 2,
      "z": -13,
      "name": "Soil_Dirt"
    },
    {
      "x": -14,
      "y": 3,
      "z": -13,
      "name": "Soil_Dirt"
    },
    {
      "x": -14,
      "y": 4,
      "z": -13,
      "name": "Soil_Dirt"
    },
    {
      "x": -14,
      "y": 5,
      "z": -13,
      "name": "Rock_Stone_Brick_Smooth"
    },
    {
      "x": -14,
      "y": 0,
      "z": -12,
      "name": "Soil_Dirt"
    },
    {
      "x": -14,
      "y": 1,
      "z": -12,
      "name": "Soil_Dirt"
    },
    {
      "x": -14,
      "y": 2,
      "z": -12,
      "name": "Soil_Dirt"
    },
    {
      "x": -14,
      "y": 3,
      "z": -12,
      "name": "Soil_Dirt"
    },
    {
      "x": -14,
      "y": 4,
      "z": -12,
      "name": "Soil_Dirt"
    },
    {
      "x": -14,
      "y": 5,
      "z": -12,
      "name": "Rock_Stone_Brick_Smooth"
    },
    {
      "x": -14,
      "y": 0,
      "z": -11,
      "name": "Soil_Dirt"
    },
    {
      "x": -14,
      "y": 1,
      "z": -11,
      "name": "Soil_Dirt"
    },
    {
      "x": -14,
      "y": 2,
      "z": -11,
      "name": "Soil_Dirt"
    },
    {
      "x": -14,
      "y": 3,
      "z": -11,
      "name": "Soil_Dirt"
    },
    {
      "x": -14,
      "y": 4,
      "z": -11,
      "name": "Soil_Dirt"
    },
    {
      "x": -14,
      "y": 5,
      "z": -11,
      "name": "Rock_Stone_Brick_Smooth"
    },
    {
      "x": -14,
      "y": 0,
      "z": -10,
      "name": "Soil_Dirt"
    },
    {
      "x": -14,
      "y": 1,
      "z": -10,
      "name": "Soil_Dirt"
    },
    {
      "x": -14,
      "y": 2,
      "z": -10,
      "name": "Soil_Dirt"
    },
    {
      "x": -14,
      "y": 3,
      "z": -10,
      "name": "Soil_Dirt"
    },
    {
      "x": -14,
      "y": 4,
      "z": -10,
      "name": "Soil_Dirt"
    },
    {
      "x": -14,
      "y": 5,
      "z": -10,
      "name": "Rock_Stone_Brick_Smooth"
    },
    {
      "x": -14,
      "y": 0,
      "z": -9,
      "name": "Soil_Dirt"
    },
    {
      "x": -14,
      "y": 1,
      "z": -9,
      "name": "Soil_Dirt"
    },
    {
      "x": -14,
      "y": 2,
      "z": -9,
      "name": "Soil_Dirt"
    },
    {
      "x": -14,
      "y": 3,
      "z": -9,
      "name": "Soil_Dirt"
    },
    {
      "x": -14,
      "y": 4,
      "z": -9,
      "name": "Soil_Dirt"
    },
    {
      "x": -14,
      "y": 5,
      "z": -9,
      "name": "Rock_Stone_Brick_Smooth"
    },
    {
      "x": -14,
      "y": 0,
      "z": -8,
      "name": "Soil_Dirt"
    },
    {
      "x": -14,
      "y": 1,
      "z": -8,
      "name": "Soil_Dirt"
    },
    {
      "x": -14,
      "y": 2,
      "z": -8,
      "name": "Soil_Dirt"
    },
    {
      "x": -14,
      "y": 3,
      "z": -8,
      "name": "Soil_Dirt"
    },
    {
      "x": -14,
      "y": 4,
      "z": -8,
      "name": "Soil_Dirt"
    },
    {
      "x": -14,
      "y": 5,
      "z": -8,
      "name": "Rock_Stone_Brick_Smooth"
    },
    {
      "x": -14,
      "y": 0,
      "z": -7,
      "name": "Soil_Dirt"
    },
    {
      "x": -14,
      "y": 1,
      "z": -7,
      "name": "Soil_Dirt"
    },
    {
      "x": -14,
      "y": 2,
      "z": -7,
      "name": "Soil_Dirt"
    },
    {
      "x": -14,
      "y": 3,
      "z": -7,
      "name": "Soil_Dirt"
    },
    {
      "x": -14,
      "y": 4,
      "z": -7,
      "name": "Soil_Dirt"
    },
    {
      "x": -14,
      "y": 5,
      "z": -7,
      "name": "Rock_Stone_Brick_Smooth"
    },
    {
      "x": -14,
      "y": 0,
      "z": -6,
      "name": "Soil_Dirt"
    },
    {
      "x": -14,
      "y": 1,
      "z": -6,
      "name": "Soil_Dirt"
    },
    {
      "x": -14,
      "y": 2,
      "z": -6,
      "name": "Soil_Dirt"
    },
    {
      "x": -14,
      "y": 3,
      "z": -6,
      "name": "Soil_Dirt"
    },
    {
      "x": -14,
      "y": 4,
      "z": -6,
      "name": "Soil_Dirt"
    },
    {
      "x": -14,
      "y": 5,
      "z": -6,
      "name": "Rock_Stone_Brick_Smooth"
    },
    {
      "x": -14,
      "y": 0,
      "z": -5,
      "name": "Soil_Dirt"
    },
    {
      "x": -14,
      "y": 1,
      "z": -5,
      "name": "Soil_Dirt"
    },
    {
      "x": -14,
      "y": 2,
      "z": -5,
      "name": "Soil_Dirt"
    },
    {
      "x": -14,
      "y": 3,
      "z": -5,
      "name": "Soil_Dirt"
    },
    {
      "x": -14,
      "y": 4,
      "z": -5,
      "name": "Soil_Dirt"
    },
    {
      "x": -14,
      "y": 5,
      "z": -5,
      "name": "Rock_Stone_Brick_Smooth"
    },
    {
      "x": -14,
      "y": 0,
      "z": -4,
      "name": "Soil_Dirt"
    },
    {
      "x": -14,
      "y": 1,
      "z": -4,
      "name": "Soil_Dirt"
    },
    {
      "x": -14,
      "y": 2,
      "z": -4,
      "name": "Soil_Dirt"
    },
    {
      "x": -14,
      "y": 3,
      "z": -4,
      "name": "Soil_Dirt"
    },
    {
      "x": -14,
      "y": 4,
      "z": -4,
      "name": "Soil_Dirt"
    },
    {
      "x": -14,
      "y": 5,
      "z": -4,
      "name": "Rock_Stone_Brick_Smooth"
    },
    {
      "x": -14,
      "y": 0,
      "z": -3,
      "name": "Soil_Dirt"
    },
    {
      "x": -14,
      "y": 1,
      "z": -3,
      "name": "Soil_Dirt"
    },
    {
      "x": -14,
      "y": 2,
      "z": -3,
      "name": "Soil_Dirt"
    },
    {
      "x": -14,
      "y": 3,
      "z": -3,
      "name": "Soil_Dirt"
    },
    {
      "x": -14,
      "y": 4,
      "z": -3,
      "name": "Soil_Dirt"
    },
    {
      "x": -14,
      "y": 5,
      "z": -3,
      "name": "Rock_Stone_Brick_Smooth"
    },
    {
      "x": -14,
      "y": 0,
      "z": -2,
      "name": "Soil_Dirt"
    },
    {
      "x": -14,
      "y": 1,
      "z": -2,
      "name": "Soil_Dirt"
    },
    {
      "x": -14,
      "y": 2,
      "z": -2,
      "name": "Soil_Dirt"
    },
    {
      "x": -14,
      "y": 3,
      "z": -2,
      "name": "Soil_Dirt"
    },
    {
      "x": -14,
      "y": 4,
      "z": -2,
      "name": "Soil_Dirt"
    },
    {
      "x": -14,
      "y": 5,
      "z": -2,
      "name": "Rock_Stone_Brick_Smooth"
    },
    {
      "x": -14,
      "y": 0,
      "z": -1,
      "name": "Soil_Dirt"
    },
    {
      "x": -14,
      "y": 1,
      "z": -1,
      "name": "Soil_Dirt"
    },
    {
      "x": -14,
      "y": 2,
      "z": -1,
      "name": "Soil_Dirt"
    },
    {
      "x": -14,
      "y": 3,
      "z": -1,
      "name": "Soil_Dirt"
    },
    {
      "x": -14,
      "y": 4,
      "z": -1,
      "name": "Soil_Dirt"
    },
    {
      "x": -14,
      "y": 5,
      "z": -1,
      "name": "Rock_Stone_Brick_Smooth"
    },
    {
      "x": -14,
      "y": 0,
      "z": 0,
      "name": "Soil_Dirt"
    },
    {
      "x": -14,
      "y": 1,
      "z": 0,
      "name": "Soil_Dirt"
    },
    {
      "x": -14,
      "y": 2,
      "z": 0,
      "name": "Soil_Dirt"
    },
    {
      "x": -14,
      "y": 3,
      "z": 0,
      "name": "Soil_Dirt"
    },
    {
      "x": -14,
      "y": 4,
      "z": 0,
      "name": "Soil_Dirt"
    },
    {
      "x": -14,
      "y": 5,
      "z": 0,
      "name": "Rock_Stone_Brick_Smooth"
    },
    {
      "x": -14,
      "y": 0,
      "z": 1,
      "name": "Soil_Dirt"
    },
    {
      "x": -14,
      "y": 1,
      "z": 1,
      "name": "Soil_Dirt"
    },
    {
      "x": -14,
      "y": 2,
      "z": 1,
      "name": "Soil_Dirt"
    },
    {
      "x": -14,
      "y": 3,
      "z": 1,
      "name": "Soil_Dirt"
    },
    {
      "x": -14,
      "y": 4,
      "z": 1,
      "name": "Soil_Dirt"
    },
    {
      "x": -14,
      "y": 5,
      "z": 1,
      "name": "Rock_Stone_Brick_Smooth"
    },
    {
      "x": -14,
      "y": 0,
      "z": 2,
      "name": "Soil_Dirt"
    },
    {
      "x": -14,
      "y": 1,
      "z": 2,
      "name": "Soil_Dirt"
    },
    {
      "x": -14,
      "y": 2,
      "z": 2,
      "name": "Soil_Dirt"
    },
    {
      "x": -14,
      "y": 3,
      "z": 2,
      "name": "Soil_Dirt"
    },
    {
      "x": -14,
      "y": 4,
      "z": 2,
      "name": "Soil_Dirt"
    },
    {
      "x": -14,
      "y": 5,
      "z": 2,
      "name": "Rock_Stone_Brick_Smooth"
    },
    {
      "x": -14,
      "y": 0,
      "z": 3,
      "name": "Soil_Dirt"
    },
    {
      "x": -14,
      "y": 1,
      "z": 3,
      "name": "Soil_Dirt"
    },
    {
      "x": -14,
      "y": 2,
      "z": 3,
      "name": "Soil_Dirt"
    },
    {
      "x": -14,
      "y": 3,
      "z": 3,
      "name": "Soil_Dirt"
    },
    {
      "x": -14,
      "y": 4,
      "z": 3,
      "name": "Soil_Dirt"
    },
    {
      "x": -14,
      "y": 5,
      "z": 3,
      "name": "Rock_Stone_Brick_Smooth"
    },
    {
      "x": -14,
      "y": 0,
      "z": 4,
      "name": "Soil_Dirt"
    },
    {
      "x": -14,
      "y": 1,
      "z": 4,
      "name": "Soil_Dirt"
    },
    {
      "x": -14,
      "y": 2,
      "z": 4,
      "name": "Soil_Dirt"
    },
    {
      "x": -14,
      "y": 3,
      "z": 4,
      "name": "Soil_Dirt"
    },
    {
      "x": -14,
      "y": 4,
      "z": 4,
      "name": "Soil_Dirt"
    },
    {
      "x": -14,
      "y": 5,
      "z": 4,
      "name": "Rock_Stone_Brick_Smooth"
    },
    {
      "x": -14,
      "y": 0,
      "z": 5,
      "name": "Soil_Dirt"
    },
    {
      "x": -14,
      "y": 1,
      "z": 5,
      "name": "Soil_Dirt"
    },
    {
      "x": -14,
      "y": 2,
      "z": 5,
      "name": "Soil_Dirt"
    },
    {
      "x": -14,
      "y": 3,
      "z": 5,
      "name": "Soil_Dirt"
    },
    {
      "x": -14,
      "y": 4,
      "z": 5,
      "name": "Soil_Dirt"
    },
    {
      "x": -14,
      "y": 5,
      "z": 5,
      "name": "Rock_Stone_Brick_Smooth"
    },
    {
      "x": -14,
      "y": 0,
      "z": 6,
      "name": "Soil_Dirt"
    },
    {
      "x": -14,
      "y": 1,
      "z": 6,
      "name": "Soil_Dirt"
    },
    {
      "x": -14,
      "y": 2,
      "z": 6,
      "name": "Soil_Dirt"
    },
    {
      "x": -14,
      "y": 3,
      "z": 6,
      "name": "Soil_Dirt"
    },
    {
      "x": -14,
      "y": 4,
      "z": 6,
      "name": "Soil_Dirt"
    },
    {
      "x": -14,
      "y": 5,
      "z": 6,
      "name": "Rock_Stone_Brick_Smooth"
    },
    {
      "x": -14,
      "y": 0,
      "z": 7,
      "name": "Soil_Dirt"
    },
    {
      "x": -14,
      "y": 1,
      "z": 7,
      "name": "Soil_Dirt"
    },
    {
      "x": -14,
      "y": 2,
      "z": 7,
      "name": "Soil_Dirt"
    },
    {
      "x": -14,
      "y": 3,
      "z": 7,
      "name": "Soil_Dirt"
    },
    {
      "x": -14,
      "y": 4,
      "z": 7,
      "name": "Soil_Dirt"
    },
    {
      "x": -14,
      "y": 5,
      "z": 7,
      "name": "Rock_Stone_Brick_Smooth"
    },
    {
      "x": -14,
      "y": 0,
      "z": 8,
      "name": "Soil_Dirt"
    },
    {
      "x": -14,
      "y": 1,
      "z": 8,
      "name": "Soil_Dirt"
    },
    {
      "x": -14,
      "y": 2,
      "z": 8,
      "name": "Soil_Dirt"
    },
    {
      "x": -14,
      "y": 3,
      "z": 8,
      "name": "Soil_Dirt"
    },
    {
      "x": -14,
      "y": 4,
      "z": 8,
      "name": "Soil_Dirt"
    },
    {
      "x": -14,
      "y": 5,
      "z": 8,
      "name": "Rock_Stone_Brick_Smooth"
    },
    {
      "x": -14,
      "y": 0,
      "z": 9,
      "name": "Soil_Dirt"
    },
    {
      "x": -14,
      "y": 1,
      "z": 9,
      "name": "Soil_Dirt"
    },
    {
      "x": -14,
      "y": 2,
      "z": 9,
      "name": "Soil_Dirt"
    },
    {
      "x": -14,
      "y": 3,
      "z": 9,
      "name": "Soil_Dirt"
    },
    {
      "x": -14,
      "y": 4,
      "z": 9,
      "name": "Soil_Dirt"
    },
    {
      "x": -14,
      "y": 5,
      "z": 9,
      "name": "Rock_Stone_Brick_Smooth"
    },
    {
      "x": -14,
      "y": 0,
      "z": 10,
      "name": "Soil_Dirt"
    },
    {
      "x": -14,
      "y": 1,
      "z": 10,
      "name": "Soil_Dirt"
    },
    {
      "x": -14,
      "y": 2,
      "z": 10,
      "name": "Soil_Dirt"
    },
    {
      "x": -14,
      "y": 3,
      "z": 10,
      "name": "Soil_Dirt"
    },
    {
      "x": -14,
      "y": 4,
      "z": 10,
      "name": "Soil_Dirt"
    },
    {
      "x": -14,
      "y": 5,
      "z": 10,
      "name": "Rock_Stone_Brick_Smooth"
    },
    {
      "x": -14,
      "y": 0,
      "z": 11,
      "name": "Soil_Dirt"
    },
    {
      "x": -14,
      "y": 1,
      "z": 11,
      "name": "Soil_Dirt"
    },
    {
      "x": -14,
      "y": 2,
      "z": 11,
      "name": "Soil_Dirt"
    },
    {
      "x": -14,
      "y": 3,
      "z": 11,
      "name": "Soil_Dirt"
    },
    {
      "x": -14,
      "y": 4,
      "z": 11,
      "name": "Soil_Dirt"
    },
    {
      "x": -14,
      "y": 5,
      "z": 11,
      "name": "Rock_Stone_Brick_Smooth"
    },
    {
      "x": -14,
      "y": 0,
      "z": 12,
      "name": "Soil_Dirt"
    },
    {
      "x": -14,
      "y": 1,
      "z": 12,
      "name": "Soil_Dirt"
    },
    {
      "x": -14,
      "y": 2,
      "z": 12,
      "name": "Soil_Dirt"
    },
    {
      "x": -14,
      "y": 3,
      "z": 12,
      "name": "Soil_Dirt"
    },
    {
      "x": -14,
      "y": 4,
      "z": 12,
      "name": "Soil_Dirt"
    },
    {
      "x": -14,
      "y": 5,
      "z": 12,
      "name": "Rock_Stone_Brick_Smooth"
    },
    {
      "x": -14,
      "y": 0,
      "z": 13,
      "name": "Soil_Dirt"
    },
    {
      "x": -14,
      "y": 1,
      "z": 13,
      "name": "Soil_Dirt"
    },
    {
      "x": -14,
      "y": 2,
      "z": 13,
      "name": "Soil_Dirt"
    },
    {
      "x": -14,
      "y": 3,
      "z": 13,
      "name": "Soil_Dirt"
    },
    {
      "x": -14,
      "y": 4,
      "z": 13,
      "name": "Soil_Dirt"
    },
    {
      "x": -14,
      "y": 5,
      "z": 13,
      "name": "Rock_Stone_Brick_Smooth"
    },
    {
      "x": -14,
      "y": 0,
      "z": 14,
      "name": "Soil_Dirt"
    },
    {
      "x": -14,
      "y": 1,
      "z": 14,
      "name": "Soil_Dirt"
    },
    {
      "x": -14,
      "y": 2,
      "z": 14,
      "name": "Soil_Dirt"
    },
    {
      "x": -14,
      "y": 3,
      "z": 14,
      "name": "Soil_Dirt"
    },
    {
      "x": -14,
      "y": 4,
      "z": 14,
      "name": "Soil_Dirt"
    },
    {
      "x": -14,
      "y": 5,
      "z": 14,
      "name": "Rock_Stone_Brick_Smooth"
    },
    {
      "x": -14,
      "y": 0,
      "z": 15,
      "name": "Soil_Dirt"
    },
    {
      "x": -14,
      "y": 1,
      "z": 15,
      "name": "Soil_Dirt"
    },
    {
      "x": -14,
      "y": 2,
      "z": 15,
      "name": "Soil_Dirt"
    },
    {
      "x": -14,
      "y": 3,
      "z": 15,
      "name": "Soil_Dirt"
    },
    {
      "x": -14,
      "y": 4,
      "z": 15,
      "name": "Soil_Dirt"
    },
    {
      "x": -14,
      "y": 5,
      "z": 15,
      "name": "Rock_Stone_Brick_Smooth"
    },
    {
      "x": -13,
      "y": 0,
      "z": -14,
      "name": "Soil_Dirt"
    },
    {
      "x": -13,
      "y": 1,
      "z": -14,
      "name": "Soil_Dirt"
    },
    {
      "x": -13,
      "y": 2,
      "z": -14,
      "name": "Soil_Dirt"
    },
    {
      "x": -13,
      "y": 3,
      "z": -14,
      "name": "Soil_Dirt"
    },
    {
      "x": -13,
      "y": 4,
      "z": -14,
      "name": "Soil_Dirt"
    },
    {
      "x": -13,
      "y": 5,
      "z": -14,
      "name": "Rock_Stone_Brick_Smooth"
    },
    {
      "x": -13,
      "y": 0,
      "z": -13,
      "name": "Soil_Dirt"
    },
    {
      "x": -13,
      "y": 1,
      "z": -13,
      "name": "Soil_Dirt"
    },
    {
      "x": -13,
      "y": 2,
      "z": -13,
      "name": "Soil_Dirt"
    },
    {
      "x": -13,
      "y": 3,
      "z": -13,
      "name": "Soil_Dirt"
    },
    {
      "x": -13,
      "y": 4,
      "z": -13,
      "name": "Soil_Dirt"
    },
    {
      "x": -13,
      "y": 5,
      "z": -13,
      "name": "Soil_Grass_Sunny",
      "support": 15
    },
    {
      "x": -13,
      "y": 6,
      "z": -13,
      "name": "Plant_Grass_Sharp",
      "support": 15
    },
    {
      "x": -13,
      "y": 0,
      "z": -12,
      "name": "Soil_Dirt"
    },
    {
      "x": -13,
      "y": 1,
      "z": -12,
      "name": "Soil_Dirt"
    },
    {
      "x": -13,
      "y": 2,
      "z": -12,
      "name": "Soil_Dirt"
    },
    {
      "x": -13,
      "y": 3,
      "z": -12,
      "name": "Soil_Dirt"
    },
    {
      "x": -13,
      "y": 4,
      "z": -12,
      "name": "Soil_Dirt"
    },
    {
      "x": -13,
      "y": 5,
      "z": -12,
      "name": "Soil_Grass_Sunny",
      "support": 15
    },
    {
      "x": -13,
      "y": 6,
      "z": -12,
      "name": "Plant_Grass_Sharp_Short",
      "support": 15
    },
    {
      "x": -13,
      "y": 0,
      "z": -11,
      "name": "Soil_Dirt"
    },
    {
      "x": -13,
      "y": 1,
      "z": -11,
      "name": "Soil_Dirt"
    },
    {
      "x": -13,
      "y": 2,
      "z": -11,
      "name": "Soil_Dirt"
    },
    {
      "x": -13,
      "y": 3,
      "z": -11,
      "name": "Soil_Dirt"
    },
    {
      "x": -13,
      "y": 4,
      "z": -11,
      "name": "Soil_Dirt"
    },
    {
      "x": -13,
      "y": 5,
      "z": -11,
      "name": "Soil_Grass_Sunny",
      "support": 15
    },
    {
      "x": -13,
      "y": 6,
      "z": -11,
      "name": "Plant_Grass_Sharp_Short",
      "support": 15
    },
    {
      "x": -13,
      "y": 0,
      "z": -10,
      "name": "Soil_Dirt"
    },
    {
      "x": -13,
      "y": 1,
      "z": -10,
      "name": "Soil_Dirt"
    },
    {
      "x": -13,
      "y": 2,
      "z": -10,
      "name": "Soil_Dirt"
    },
    {
      "x": -13,
      "y": 3,
      "z": -10,
      "name": "Soil_Dirt"
    },
    {
      "x": -13,
      "y": 4,
      "z": -10,
      "name": "Soil_Dirt"
    },
    {
      "x": -13,
      "y": 5,
      "z": -10,
      "name": "Soil_Grass_Sunny",
      "support": 15
    },
    {
      "x": -13,
      "y": 6,
      "z": -10,
      "name": "Plant_Grass_Sharp_Short",
      "support": 15
    },
    {
      "x": -13,
      "y": 0,
      "z": -9,
      "name": "Soil_Dirt"
    },
    {
      "x": -13,
      "y": 1,
      "z": -9,
      "name": "Soil_Dirt"
    },
    {
      "x": -13,
      "y": 2,
      "z": -9,
      "name": "Soil_Dirt"
    },
    {
      "x": -13,
      "y": 3,
      "z": -9,
      "name": "Soil_Dirt"
    },
    {
      "x": -13,
      "y": 4,
      "z": -9,
      "name": "Soil_Dirt"
    },
    {
      "x": -13,
      "y": 5,
      "z": -9,
      "name": "Soil_Grass_Sunny",
      "support": 15
    },
    {
      "x": -13,
      "y": 6,
      "z": -9,
      "name": "Plant_Grass_Sharp_Short",
      "support": 15
    },
    {
      "x": -13,
      "y": 0,
      "z": -8,
      "name": "Soil_Dirt"
    },
    {
      "x": -13,
      "y": 1,
      "z": -8,
      "name": "Soil_Dirt"
    },
    {
      "x": -13,
      "y": 2,
      "z": -8,
      "name": "Soil_Dirt"
    },
    {
      "x": -13,
      "y": 3,
      "z": -8,
      "name": "Soil_Dirt"
    },
    {
      "x": -13,
      "y": 4,
      "z": -8,
      "name": "Soil_Dirt"
    },
    {
      "x": -13,
      "y": 5,
      "z": -8,
      "name": "Soil_Grass_Sunny",
      "support": 15
    },
    {
      "x": -13,
      "y": 6,
      "z": -8,
      "name": "Plant_Grass_Sharp",
      "support": 15
    },
    {
      "x": -13,
      "y": 0,
      "z": -7,
      "name": "Soil_Dirt"
    },
    {
      "x": -13,
      "y": 1,
      "z": -7,
      "name": "Soil_Dirt"
    },
    {
      "x": -13,
      "y": 2,
      "z": -7,
      "name": "Soil_Dirt"
    },
    {
      "x": -13,
      "y": 3,
      "z": -7,
      "name": "Soil_Dirt"
    },
    {
      "x": -13,
      "y": 4,
      "z": -7,
      "name": "Soil_Dirt"
    },
    {
      "x": -13,
      "y": 5,
      "z": -7,
      "name": "Soil_Grass_Sunny",
      "support": 15
    },
    {
      "x": -13,
      "y": 6,
      "z": -7,
      "name": "Plant_Grass_Sharp_Short",
      "support": 15
    },
    {
      "x": -13,
      "y": 0,
      "z": -6,
      "name": "Soil_Dirt"
    },
    {
      "x": -13,
      "y": 1,
      "z": -6,
      "name": "Soil_Dirt"
    },
    {
      "x": -13,
      "y": 2,
      "z": -6,
      "name": "Soil_Dirt"
    },
    {
      "x": -13,
      "y": 3,
      "z": -6,
      "name": "Soil_Dirt"
    },
    {
      "x": -13,
      "y": 4,
      "z": -6,
      "name": "Soil_Dirt"
    },
    {
      "x": -13,
      "y": 5,
      "z": -6,
      "name": "Soil_Grass_Sunny",
      "support": 15
    },
    {
      "x": -13,
      "y": 6,
      "z": -6,
      "name": "Plant_Grass_Sharp_Short",
      "support": 15
    },
    {
      "x": -13,
      "y": 0,
      "z": -5,
      "name": "Soil_Dirt"
    },
    {
      "x": -13,
      "y": 1,
      "z": -5,
      "name": "Soil_Dirt"
    },
    {
      "x": -13,
      "y": 2,
      "z": -5,
      "name": "Soil_Dirt"
    },
    {
      "x": -13,
      "y": 3,
      "z": -5,
      "name": "Soil_Dirt"
    },
    {
      "x": -13,
      "y": 4,
      "z": -5,
      "name": "Soil_Dirt"
    },
    {
      "x": -13,
      "y": 5,
      "z": -5,
      "name": "Soil_Grass_Sunny",
      "support": 15
    },
    {
      "x": -13,
      "y": 0,
      "z": -4,
      "name": "Soil_Dirt"
    },
    {
      "x": -13,
      "y": 1,
      "z": -4,
      "name": "Soil_Dirt"
    },
    {
      "x": -13,
      "y": 2,
      "z": -4,
      "name": "Soil_Dirt"
    },
    {
      "x": -13,
      "y": 3,
      "z": -4,
      "name": "Soil_Dirt"
    },
    {
      "x": -13,
      "y": 4,
      "z": -4,
      "name": "Soil_Dirt"
    },
    {
      "x": -13,
      "y": 5,
      "z": -4,
      "name": "Soil_Grass_Sunny",
      "support": 15
    },
    {
      "x": -13,
      "y": 0,
      "z": -3,
      "name": "Soil_Dirt"
    },
    {
      "x": -13,
      "y": 1,
      "z": -3,
      "name": "Soil_Dirt"
    },
    {
      "x": -13,
      "y": 2,
      "z": -3,
      "name": "Soil_Dirt"
    },
    {
      "x": -13,
      "y": 3,
      "z": -3,
      "name": "Soil_Dirt"
    },
    {
      "x": -13,
      "y": 4,
      "z": -3,
      "name": "Soil_Dirt"
    },
    {
      "x": -13,
      "y": 5,
      "z": -3,
      "name": "Soil_Grass_Sunny",
      "support": 15
    },
    {
      "x": -13,
      "y": 0,
      "z": -2,
      "name": "Soil_Dirt"
    },
    {
      "x": -13,
      "y": 1,
      "z": -2,
      "name": "Soil_Dirt"
    },
    {
      "x": -13,
      "y": 2,
      "z": -2,
      "name": "Soil_Dirt"
    },
    {
      "x": -13,
      "y": 3,
      "z": -2,
      "name": "Soil_Dirt"
    },
    {
      "x": -13,
      "y": 4,
      "z": -2,
      "name": "Soil_Dirt"
    },
    {
      "x": -13,
      "y": 5,
      "z": -2,
      "name": "Soil_Grass_Sunny",
      "support": 15
    },
    {
      "x": -13,
      "y": 0,
      "z": -1,
      "name": "Soil_Dirt"
    },
    {
      "x": -13,
      "y": 1,
      "z": -1,
      "name": "Soil_Dirt"
    },
    {
      "x": -13,
      "y": 2,
      "z": -1,
      "name": "Soil_Dirt"
    },
    {
      "x": -13,
      "y": 3,
      "z": -1,
      "name": "Soil_Dirt"
    },
    {
      "x": -13,
      "y": 4,
      "z": -1,
      "name": "Soil_Dirt"
    },
    {
      "x": -13,
      "y": 5,
      "z": -1,
      "name": "Soil_Grass_Sunny",
      "support": 15
    },
    {
      "x": -13,
      "y": 0,
      "z": 0,
      "name": "Soil_Dirt"
    },
    {
      "x": -13,
      "y": 1,
      "z": 0,
      "name": "Soil_Dirt"
    },
    {
      "x": -13,
      "y": 2,
      "z": 0,
      "name": "Soil_Dirt"
    },
    {
      "x": -13,
      "y": 3,
      "z": 0,
      "name": "Soil_Dirt"
    },
    {
      "x": -13,
      "y": 4,
      "z": 0,
      "name": "Soil_Dirt"
    },
    {
      "x": -13,
      "y": 5,
      "z": 0,
      "name": "Soil_Grass_Sunny",
      "support": 15
    },
    {
      "x": -13,
      "y": 6,
      "z": 0,
      "name": "Plant_Grass_Sharp_Short",
      "support": 15
    },
    {
      "x": -13,
      "y": 0,
      "z": 1,
      "name": "Soil_Dirt"
    },
    {
      "x": -13,
      "y": 1,
      "z": 1,
      "name": "Soil_Dirt"
    },
    {
      "x": -13,
      "y": 2,
      "z": 1,
      "name": "Soil_Dirt"
    },
    {
      "x": -13,
      "y": 3,
      "z": 1,
      "name": "Soil_Dirt"
    },
    {
      "x": -13,
      "y": 4,
      "z": 1,
      "name": "Soil_Dirt"
    },
    {
      "x": -13,
      "y": 5,
      "z": 1,
      "name": "Soil_Grass_Sunny",
      "support": 15
    },
    {
      "x": -13,
      "y": 6,
      "z": 1,
      "name": "Plant_Crop_Mushroom_Common_Brown",
      "components": {
        "Components": {
          "FarmingBlock": {
            "LastTickGameTime": "0001-03-23T20:49:21.248895326Z",
            "SpreadRate": 0.5
          }
        }
      },
      "support": 15
    },
    {
      "x": -13,
      "y": 0,
      "z": 2,
      "name": "Soil_Dirt"
    },
    {
      "x": -13,
      "y": 1,
      "z": 2,
      "name": "Soil_Dirt"
    },
    {
      "x": -13,
      "y": 2,
      "z": 2,
      "name": "Soil_Dirt"
    },
    {
      "x": -13,
      "y": 3,
      "z": 2,
      "name": "Soil_Dirt"
    },
    {
      "x": -13,
      "y": 4,
      "z": 2,
      "name": "Soil_Dirt"
    },
    {
      "x": -13,
      "y": 5,
      "z": 2,
      "name": "Soil_Grass_Sunny",
      "support": 15
    },
    {
      "x": -13,
      "y": 6,
      "z": 2,
      "name": "Plant_Grass_Sharp",
      "support": 15
    },
    {
      "x": -13,
      "y": 0,
      "z": 3,
      "name": "Soil_Dirt"
    },
    {
      "x": -13,
      "y": 1,
      "z": 3,
      "name": "Soil_Dirt"
    },
    {
      "x": -13,
      "y": 2,
      "z": 3,
      "name": "Soil_Dirt"
    },
    {
      "x": -13,
      "y": 3,
      "z": 3,
      "name": "Soil_Dirt"
    },
    {
      "x": -13,
      "y": 4,
      "z": 3,
      "name": "Soil_Dirt"
    },
    {
      "x": -13,
      "y": 5,
      "z": 3,
      "name": "Soil_Grass_Sunny",
      "support": 15
    },
    {
      "x": -13,
      "y": 6,
      "z": 3,
      "name": "Plant_Grass_Sharp",
      "support": 15
    },
    {
      "x": -13,
      "y": 0,
      "z": 4,
      "name": "Soil_Dirt"
    },
    {
      "x": -13,
      "y": 1,
      "z": 4,
      "name": "Soil_Dirt"
    },
    {
      "x": -13,
      "y": 2,
      "z": 4,
      "name": "Soil_Dirt"
    },
    {
      "x": -13,
      "y": 3,
      "z": 4,
      "name": "Soil_Dirt"
    },
    {
      "x": -13,
      "y": 4,
      "z": 4,
      "name": "Soil_Dirt"
    },
    {
      "x": -13,
      "y": 5,
      "z": 4,
      "name": "Soil_Grass_Sunny",
      "support": 15
    },
    {
      "x": -13,
      "y": 6,
      "z": 4,
      "name": "Plant_Grass_Sharp_Short",
      "support": 15
    },
    {
      "x": -13,
      "y": 0,
      "z": 5,
      "name": "Soil_Dirt"
    },
    {
      "x": -13,
      "y": 1,
      "z": 5,
      "name": "Soil_Dirt"
    },
    {
      "x": -13,
      "y": 2,
      "z": 5,
      "name": "Soil_Dirt"
    },
    {
      "x": -13,
      "y": 3,
      "z": 5,
      "name": "Soil_Dirt"
    },
    {
      "x": -13,
      "y": 4,
      "z": 5,
      "name": "Soil_Dirt"
    },
    {
      "x": -13,
      "y": 5,
      "z": 5,
      "name": "Soil_Grass_Sunny",
      "support": 15
    },
    {
      "x": -13,
      "y": 6,
      "z": 5,
      "name": "Plant_Crop_Mushroom_Common_Brown",
      "components": {
        "Components": {
          "FarmingBlock": {
            "GrowthProgress": 1.0000965595245361,
            "LastTickGameTime": "0001-03-23T20:49:21.248895326Z",
            "Generation": 1,
            "Executions": 1
          }
        }
      },
      "support": 15
    },
    {
      "x": -13,
      "y": 0,
      "z": 6,
      "name": "Soil_Dirt"
    },
    {
      "x": -13,
      "y": 1,
      "z": 6,
      "name": "Soil_Dirt"
    },
    {
      "x": -13,
      "y": 2,
      "z": 6,
      "name": "Soil_Dirt"
    },
    {
      "x": -13,
      "y": 3,
      "z": 6,
      "name": "Soil_Dirt",
      "support": 15
    },
    {
      "x": -13,
      "y": 4,
      "z": 6,
      "name": "Soil_Dirt"
    },
    {
      "x": -13,
      "y": 5,
      "z": 6,
      "name": "Soil_Grass_Sunny",
      "support": 15
    },
    {
      "x": -13,
      "y": 0,
      "z": 7,
      "name": "Soil_Dirt"
    },
    {
      "x": -13,
      "y": 1,
      "z": 7,
      "name": "Soil_Dirt"
    },
    {
      "x": -13,
      "y": 2,
      "z": 7,
      "name": "Soil_Dirt"
    },
    {
      "x": -13,
      "y": 3,
      "z": 7,
      "name": "Soil_Dirt"
    },
    {
      "x": -13,
      "y": 4,
      "z": 7,
      "name": "Soil_Dirt",
      "support": 15
    },
    {
      "x": -13,
      "y": 5,
      "z": 7,
      "name": "Soil_Grass_Sunny",
      "support": 15
    },
    {
      "x": -13,
      "y": 0,
      "z": 8,
      "name": "Soil_Dirt"
    },
    {
      "x": -13,
      "y": 1,
      "z": 8,
      "name": "Soil_Dirt"
    },
    {
      "x": -13,
      "y": 2,
      "z": 8,
      "name": "Soil_Dirt"
    },
    {
      "x": -13,
      "y": 3,
      "z": 8,
      "name": "Soil_Dirt"
    },
    {
      "x": -13,
      "y": 4,
      "z": 8,
      "name": "Soil_Dirt"
    },
    {
      "x": -13,
      "y": 5,
      "z": 8,
      "name": "Soil_Grass_Sunny",
      "support": 15
    },
    {
      "x": -13,
      "y": 0,
      "z": 9,
      "name": "Soil_Dirt"
    },
    {
      "x": -13,
      "y": 1,
      "z": 9,
      "name": "Soil_Dirt"
    },
    {
      "x": -13,
      "y": 2,
      "z": 9,
      "name": "Soil_Dirt"
    },
    {
      "x": -13,
      "y": 3,
      "z": 9,
      "name": "Soil_Dirt"
    },
    {
      "x": -13,
      "y": 4,
      "z": 9,
      "name": "Soil_Dirt"
    },
    {
      "x": -13,
      "y": 5,
      "z": 9,
      "name": "Soil_Grass_Sunny",
      "support": 15
    },
    {
      "x": -13,
      "y": 0,
      "z": 10,
      "name": "Soil_Dirt"
    },
    {
      "x": -13,
      "y": 1,
      "z": 10,
      "name": "Soil_Dirt"
    },
    {
      "x": -13,
      "y": 2,
      "z": 10,
      "name": "Soil_Dirt"
    },
    {
      "x": -13,
      "y": 3,
      "z": 10,
      "name": "Soil_Dirt"
    },
    {
      "x": -13,
      "y": 4,
      "z": 10,
      "name": "Soil_Dirt"
    },
    {
      "x": -13,
      "y": 5,
      "z": 10,
      "name": "Soil_Grass_Sunny",
      "support": 15
    },
    {
      "x": -13,
      "y": 0,
      "z": 11,
      "name": "Soil_Dirt"
    },
    {
      "x": -13,
      "y": 1,
      "z": 11,
      "name": "Soil_Dirt"
    },
    {
      "x": -13,
      "y": 2,
      "z": 11,
      "name": "Soil_Dirt"
    },
    {
      "x": -13,
      "y": 3,
      "z": 11,
      "name": "Soil_Dirt"
    },
    {
      "x": -13,
      "y": 4,
      "z": 11,
      "name": "Soil_Dirt"
    },
    {
      "x": -13,
      "y": 5,
      "z": 11,
      "name": "Soil_Grass_Sunny",
      "support": 15
    },
    {
      "x": -13,
      "y": 6,
      "z": 11,
      "name": "Plant_Grass_Sharp_Short",
      "support": 15
    },
    {
      "x": -13,
      "y": 0,
      "z": 12,
      "name": "Soil_Dirt"
    },
    {
      "x": -13,
      "y": 1,
      "z": 12,
      "name": "Soil_Dirt"
    },
    {
      "x": -13,
      "y": 2,
      "z": 12,
      "name": "Soil_Dirt"
    },
    {
      "x": -13,
      "y": 3,
      "z": 12,
      "name": "Soil_Dirt"
    },
    {
      "x": -13,
      "y": 4,
      "z": 12,
      "name": "Soil_Dirt"
    },
    {
      "x": -13,
      "y": 5,
      "z": 12,
      "name": "Soil_Grass_Sunny",
      "support": 15
    },
    {
      "x": -13,
      "y": 6,
      "z": 12,
      "name": "Plant_Grass_Sharp_Short",
      "support": 15
    },
    {
      "x": -13,
      "y": 0,
      "z": 13,
      "name": "Soil_Dirt"
    },
    {
      "x": -13,
      "y": 1,
      "z": 13,
      "name": "Soil_Dirt"
    },
    {
      "x": -13,
      "y": 2,
      "z": 13,
      "name": "Soil_Dirt"
    },
    {
      "x": -13,
      "y": 3,
      "z": 13,
      "name": "Soil_Dirt"
    },
    {
      "x": -13,
      "y": 4,
      "z": 13,
      "name": "Soil_Dirt"
    },
    {
      "x": -13,
      "y": 5,
      "z": 13,
      "name": "Soil_Grass_Sunny",
      "support": 15
    },
    {
      "x": -13,
      "y": 6,
      "z": 13,
      "name": "Plant_Grass_Sharp_Short",
      "support": 15
    },
    {
      "x": -13,
      "y": 0,
      "z": 14,
      "name": "Soil_Dirt"
    },
    {
      "x": -13,
      "y": 1,
      "z": 14,
      "name": "Soil_Dirt"
    },
    {
      "x": -13,
      "y": 2,
      "z": 14,
      "name": "Soil_Dirt"
    },
    {
      "x": -13,
      "y": 3,
      "z": 14,
      "name": "Soil_Dirt"
    },
    {
      "x": -13,
      "y": 4,
      "z": 14,
      "name": "Soil_Dirt"
    },
    {
      "x": -13,
      "y": 5,
      "z": 14,
      "name": "Soil_Grass_Sunny",
      "support": 15
    },
    {
      "x": -13,
      "y": 6,
      "z": 14,
      "name": "Plant_Flower_Common_Red2",
      "support": 15
    },
    {
      "x": -13,
      "y": 0,
      "z": 15,
      "name": "Soil_Dirt"
    },
    {
      "x": -13,
      "y": 1,
      "z": 15,
      "name": "Soil_Dirt"
    },
    {
      "x": -13,
      "y": 2,
      "z": 15,
      "name": "Soil_Dirt"
    },
    {
      "x": -13,
      "y": 3,
      "z": 15,
      "name": "Soil_Dirt"
    },
    {
      "x": -13,
      "y": 4,
      "z": 15,
      "name": "Soil_Dirt"
    },
    {
      "x": -13,
      "y": 5,
      "z": 15,
      "name": "Rock_Stone_Brick_Smooth"
    },
    {
      "x": -12,
      "y": 0,
      "z": -14,
      "name": "Soil_Dirt"
    },
    {
      "x": -12,
      "y": 1,
      "z": -14,
      "name": "Soil_Dirt"
    },
    {
      "x": -12,
      "y": 2,
      "z": -14,
      "name": "Soil_Dirt"
    },
    {
      "x": -12,
      "y": 3,
      "z": -14,
      "name": "Soil_Dirt"
    },
    {
      "x": -12,
      "y": 4,
      "z": -14,
      "name": "Soil_Dirt"
    },
    {
      "x": -12,
      "y": 5,
      "z": -14,
      "name": "Rock_Stone_Brick_Smooth"
    },
    {
      "x": -12,
      "y": 0,
      "z": -13,
      "name": "Soil_Dirt"
    },
    {
      "x": -12,
      "y": 1,
      "z": -13,
      "name": "Soil_Dirt"
    },
    {
      "x": -12,
      "y": 2,
      "z": -13,
      "name": "Soil_Dirt"
    },
    {
      "x": -12,
      "y": 3,
      "z": -13,
      "name": "Soil_Dirt"
    },
    {
      "x": -12,
      "y": 4,
      "z": -13,
      "name": "Soil_Dirt"
    },
    {
      "x": -12,
      "y": 5,
      "z": -13,
      "name": "Soil_Grass_Sunny",
      "support": 15
    },
    {
      "x": -12,
      "y": 6,
      "z": -13,
      "name": "Plant_Grass_Sharp_Short",
      "support": 15
    },
    {
      "x": -12,
      "y": 0,
      "z": -12,
      "name": "Soil_Dirt"
    },
    {
      "x": -12,
      "y": 1,
      "z": -12,
      "name": "Soil_Dirt"
    },
    {
      "x": -12,
      "y": 2,
      "z": -12,
      "name": "Soil_Dirt"
    },
    {
      "x": -12,
      "y": 3,
      "z": -12,
      "name": "Soil_Dirt"
    },
    {
      "x": -12,
      "y": 4,
      "z": -12,
      "name": "Soil_Dirt"
    },
    {
      "x": -12,
      "y": 5,
      "z": -12,
      "name": "Soil_Grass_Sunny",
      "support": 15
    },
    {
      "x": -12,
      "y": 6,
      "z": -12,
      "name": "Plant_Grass_Sharp_Short",
      "support": 15
    },
    {
      "x": -12,
      "y": 0,
      "z": -11,
      "name": "Soil_Dirt"
    },
    {
      "x": -12,
      "y": 1,
      "z": -11,
      "name": "Soil_Dirt"
    },
    {
      "x": -12,
      "y": 2,
      "z": -11,
      "name": "Soil_Dirt"
    },
    {
      "x": -12,
      "y": 3,
      "z": -11,
      "name": "Soil_Dirt"
    },
    {
      "x": -12,
      "y": 4,
      "z": -11,
      "name": "Soil_Dirt"
    },
    {
      "x": -12,
      "y": 5,
      "z": -11,
      "name": "Soil_Pathway"
    },
    {
      "x": -12,
      "y": 0,
      "z": -10,
      "name": "Soil_Dirt"
    },
    {
      "x": -12,
      "y": 1,
      "z": -10,
      "name": "Soil_Dirt"
    },
    {
      "x": -12,
      "y": 2,
      "z": -10,
      "name": "Soil_Dirt"
    },
    {
      "x": -12,
      "y": 3,
      "z": -10,
      "name": "Soil_Dirt"
    },
    {
      "x": -12,
      "y": 4,
      "z": -10,
      "name": "Soil_Dirt"
    },
    {
      "x": -12,
      "y": 5,
      "z": -10,
      "name": "Soil_Pathway"
    },
    {
      "x": -12,
      "y": 0,
      "z": -9,
      "name": "Soil_Dirt"
    },
    {
      "x": -12,
      "y": 1,
      "z": -9,
      "name": "Soil_Dirt"
    },
    {
      "x": -12,
      "y": 2,
      "z": -9,
      "name": "Soil_Dirt"
    },
    {
      "x": -12,
      "y": 3,
      "z": -9,
      "name": "Soil_Dirt"
    },
    {
      "x": -12,
      "y": 4,
      "z": -9,
      "name": "Soil_Dirt"
    },
    {
      "x": -12,
      "y": 5,
      "z": -9,
      "name": "Soil_Pathway"
    },
    {
      "x": -12,
      "y": 6,
      "z": -9,
      "name": "Plant_Flower_Common_Red2",
      "support": 15
    },
    {
      "x": -12,
      "y": 0,
      "z": -8,
      "name": "Soil_Dirt"
    },
    {
      "x": -12,
      "y": 1,
      "z": -8,
      "name": "Soil_Dirt"
    },
    {
      "x": -12,
      "y": 2,
      "z": -8,
      "name": "Soil_Dirt"
    },
    {
      "x": -12,
      "y": 3,
      "z": -8,
      "name": "Soil_Dirt"
    },
    {
      "x": -12,
      "y": 4,
      "z": -8,
      "name": "Soil_Dirt"
    },
    {
      "x": -12,
      "y": 5,
      "z": -8,
      "name": "Soil_Grass_Sunny"
    },
    {
      "x": -12,
      "y": 6,
      "z": -8,
      "name": "Plant_Grass_Sharp_Short",
      "support": 15
    },
    {
      "x": -12,
      "y": 0,
      "z": -7,
      "name": "Soil_Dirt"
    },
    {
      "x": -12,
      "y": 1,
      "z": -7,
      "name": "Soil_Dirt"
    },
    {
      "x": -12,
      "y": 2,
      "z": -7,
      "name": "Soil_Dirt"
    },
    {
      "x": -12,
      "y": 3,
      "z": -7,
      "name": "Soil_Dirt"
    },
    {
      "x": -12,
      "y": 4,
      "z": -7,
      "name": "Soil_Dirt"
    },
    {
      "x": -12,
      "y": 5,
      "z": -7,
      "name": "Soil_Clay"
    },
    {
      "x": -12,
      "y": 0,
      "z": -6,
      "name": "Soil_Dirt"
    },
    {
      "x": -12,
      "y": 1,
      "z": -6,
      "name": "Soil_Dirt"
    },
    {
      "x": -12,
      "y": 2,
      "z": -6,
      "name": "Soil_Dirt"
    },
    {
      "x": -12,
      "y": 3,
      "z": -6,
      "name": "Soil_Dirt"
    },
    {
      "x": -12,
      "y": 4,
      "z": -6,
      "name": "Soil_Dirt"
    },
    {
      "x": -12,
      "y": 5,
      "z": -6,
      "name": "Soil_Pathway"
    },
    {
      "x": -12,
      "y": 0,
      "z": -5,
      "name": "Soil_Dirt"
    },
    {
      "x": -12,
      "y": 1,
      "z": -5,
      "name": "Soil_Dirt"
    },
    {
      "x": -12,
      "y": 2,
      "z": -5,
      "name": "Soil_Dirt"
    },
    {
      "x": -12,
      "y": 3,
      "z": -5,
      "name": "Soil_Dirt"
    },
    {
      "x": -12,
      "y": 4,
      "z": -5,
      "name": "Soil_Dirt"
    },
    {
      "x": -12,
      "y": 5,
      "z": -5,
      "name": "Soil_Clay"
    },
    {
      "x": -12,
      "y": 0,
      "z": -4,
      "name": "Soil_Dirt"
    },
    {
      "x": -12,
      "y": 1,
      "z": -4,
      "name": "Soil_Dirt"
    },
    {
      "x": -12,
      "y": 2,
      "z": -4,
      "name": "Soil_Dirt"
    },
    {
      "x": -12,
      "y": 3,
      "z": -4,
      "name": "Soil_Dirt"
    },
    {
      "x": -12,
      "y": 4,
      "z": -4,
      "name": "Soil_Dirt"
    },
    {
      "x": -12,
      "y": 5,
      "z": -4,
      "name": "Soil_Pathway"
    },
    {
      "x": -12,
      "y": 0,
      "z": -3,
      "name": "Soil_Dirt"
    },
    {
      "x": -12,
      "y": 1,
      "z": -3,
      "name": "Soil_Dirt"
    },
    {
      "x": -12,
      "y": 2,
      "z": -3,
      "name": "Soil_Dirt"
    },
    {
      "x": -12,
      "y": 3,
      "z": -3,
      "name": "Soil_Dirt"
    },
    {
      "x": -12,
      "y": 4,
      "z": -3,
      "name": "Soil_Dirt"
    },
    {
      "x": -12,
      "y": 5,
      "z": -3,
      "name": "Soil_Pathway"
    },
    {
      "x": -12,
      "y": 0,
      "z": -2,
      "name": "Soil_Dirt"
    },
    {
      "x": -12,
      "y": 1,
      "z": -2,
      "name": "Soil_Dirt"
    },
    {
      "x": -12,
      "y": 2,
      "z": -2,
      "name": "Soil_Dirt"
    },
    {
      "x": -12,
      "y": 3,
      "z": -2,
      "name": "Soil_Dirt"
    },
    {
      "x": -12,
      "y": 4,
      "z": -2,
      "name": "Soil_Dirt"
    },
    {
      "x": -12,
      "y": 5,
      "z": -2,
      "name": "Soil_Pathway"
    },
    {
      "x": -12,
      "y": 0,
      "z": -1,
      "name": "Soil_Dirt"
    },
    {
      "x": -12,
      "y": 1,
      "z": -1,
      "name": "Soil_Dirt"
    },
    {
      "x": -12,
      "y": 2,
      "z": -1,
      "name": "Soil_Dirt"
    },
    {
      "x": -12,
      "y": 3,
      "z": -1,
      "name": "Soil_Dirt"
    },
    {
      "x": -12,
      "y": 4,
      "z": -1,
      "name": "Soil_Dirt"
    },
    {
      "x": -12,
      "y": 5,
      "z": -1,
      "name": "Soil_Pathway"
    },
    {
      "x": -12,
      "y": 0,
      "z": 0,
      "name": "Soil_Dirt"
    },
    {
      "x": -12,
      "y": 1,
      "z": 0,
      "name": "Soil_Dirt"
    },
    {
      "x": -12,
      "y": 2,
      "z": 0,
      "name": "Soil_Dirt"
    },
    {
      "x": -12,
      "y": 3,
      "z": 0,
      "name": "Soil_Dirt"
    },
    {
      "x": -12,
      "y": 4,
      "z": 0,
      "name": "Soil_Dirt"
    },
    {
      "x": -12,
      "y": 5,
      "z": 0,
      "name": "Soil_Grass_Sunny",
      "support": 15
    },
    {
      "x": -12,
      "y": 0,
      "z": 1,
      "name": "Soil_Dirt"
    },
    {
      "x": -12,
      "y": 1,
      "z": 1,
      "name": "Soil_Dirt"
    },
    {
      "x": -12,
      "y": 2,
      "z": 1,
      "name": "Soil_Dirt"
    },
    {
      "x": -12,
      "y": 3,
      "z": 1,
      "name": "Soil_Dirt"
    },
    {
      "x": -12,
      "y": 4,
      "z": 1,
      "name": "Soil_Dirt"
    },
    {
      "x": -12,
      "y": 5,
      "z": 1,
      "name": "Soil_Grass_Sunny",
      "support": 15
    },
    {
      "x": -12,
      "y": 6,
      "z": 1,
      "name": "Plant_Grass_Sharp_Short",
      "support": 15
    },
    {
      "x": -12,
      "y": 0,
      "z": 2,
      "name": "Soil_Dirt"
    },
    {
      "x": -12,
      "y": 1,
      "z": 2,
      "name": "Soil_Dirt"
    },
    {
      "x": -12,
      "y": 2,
      "z": 2,
      "name": "Soil_Dirt"
    },
    {
      "x": -12,
      "y": 3,
      "z": 2,
      "name": "Soil_Dirt"
    },
    {
      "x": -12,
      "y": 4,
      "z": 2,
      "name": "Soil_Dirt"
    },
    {
      "x": -12,
      "y": 5,
      "z": 2,
      "name": "Soil_Grass_Sunny",
      "support": 15
    },
    {
      "x": -12,
      "y": 6,
      "z": 2,
      "name": "Plant_Grass_Sharp",
      "support": 15
    },
    {
      "x": -12,
      "y": 0,
      "z": 3,
      "name": "Soil_Dirt"
    },
    {
      "x": -12,
      "y": 1,
      "z": 3,
      "name": "Soil_Dirt"
    },
    {
      "x": -12,
      "y": 2,
      "z": 3,
      "name": "Soil_Dirt"
    },
    {
      "x": -12,
      "y": 3,
      "z": 3,
      "name": "Soil_Dirt",
      "support": 15
    },
    {
      "x": -12,
      "y": 4,
      "z": 3,
      "name": "Soil_Dirt"
    },
    {
      "x": -12,
      "y": 5,
      "z": 3,
      "name": "Soil_Grass_Sunny",
      "support": 15
    },
    {
      "x": -12,
      "y": 6,
      "z": 3,
      "name": "Plant_Grass_Sharp_Short",
      "support": 15
    },
    {
      "x": -12,
      "y": 15,
      "z": 3,
      "name": "Plant_Leaves_Maple",
      "support": 15,
      "rotation": 2
    },
    {
      "x": -12,
      "y": 16,
      "z": 3,
      "name": "Plant_Leaves_Maple",
      "support": 15,
      "rotation": 2
    },
    {
      "x": -12,
      "y": 0,
      "z": 4,
      "name": "Soil_Dirt"
    },
    {
      "x": -12,
      "y": 2,
      "z": 4,
      "name": "Soil_Dirt"
    },
    {
      "x": -12,
      "y": 3,
      "z": 4,
      "name": "Soil_Dirt",
      "support": 15
    },
    {
      "x": -12,
      "y": 4,
      "z": 4,
      "name": "Soil_Grass_Sunny",
      "support": 15
    },
    {
      "x": -12,
      "y": 5,
      "z": 4,
      "name": "Plant_Grass_Sharp_Short",
      "support": 15
    },
    {
      "x": -12,
      "y": 15,
      "z": 4,
      "name": "Plant_Leaves_Maple",
      "support": 15,
      "rotation": 2
    },
    {
      "x": -12,
      "y": 16,
      "z": 4,
      "name": "Plant_Leaves_Maple",
      "support": 15,
      "rotation": 2
    },
    {
      "x": -12,
      "y": 17,
      "z": 4,
      "name": "Plant_Leaves_Maple",
      "support": 15,
      "rotation": 2
    },
    {
      "x": -12,
      "y": 0,
      "z": 5,
      "name": "Soil_Dirt"
    },
    {
      "x": -12,
      "y": 2,
      "z": 5,
      "name": "Soil_Pathway",
      "support": 15
    },
    {
      "x": -12,
      "y": 3,
      "z": 5,
      "name": "Soil_Dirt",
      "support": 15
    },
    {
      "x": -12,
      "y": 4,
      "z": 5,
      "name": "Soil_Grass_Sunny",
      "support": 15
    },
    {
      "x": -12,
      "y": 5,
      "z": 5,
      "name": "Plant_Reeds_Marsh",
      "support": 15
    },
    {
      "x": -12,
      "y": 15,
      "z": 5,
      "name": "Plant_Leaves_Maple",
      "support": 15,
      "rotation": 2
    },
    {
      "x": -12,
      "y": 16,
      "z": 5,
      "name": "Plant_Leaves_Maple",
      "support": 15,
      "rotation": 2
    },
    {
      "x": -12,
      "y": 17,
      "z": 5,
      "name": "Plant_Leaves_Maple",
      "support": 15,
      "rotation": 2
    },
    {
      "x": -12,
      "y": 0,
      "z": 6,
      "name": "Soil_Dirt"
    },
    {
      "x": -12,
      "y": 2,
      "z": 6,
      "name": "Soil_Dirt",
      "support": 15
    },
    {
      "x": -12,
      "y": 3,
      "z": 6,
      "name": "Soil_Dirt",
      "support": 15
    },
    {
      "x": -12,
      "y": 4,
      "z": 6,
      "name": "Soil_Grass_Sunny",
      "support": 15
    },
    {
      "x": -12,
      "y": 15,
      "z": 6,
      "name": "Plant_Leaves_Maple",
      "support": 15,
      "rotation": 2
    },
    {
      "x": -12,
      "y": 16,
      "z": 6,
      "name": "Plant_Leaves_Maple",
      "support": 15,
      "rotation": 2
    },
    {
      "x": -12,
      "y": 17,
      "z": 6,
      "name": "Plant_Leaves_Maple",
      "support": 15,
      "rotation": 2
    },
    {
      "x": -12,
      "y": 0,
      "z": 7,
      "name": "Soil_Dirt"
    },
    {
      "x": -12,
      "y": 1,
      "z": 7,
      "name": "Soil_Dirt"
    },
    {
      "x": -12,
      "y": 2,
      "z": 7,
      "name": "Soil_Dirt",
      "support": 15
    },
    {
      "x": -12,
      "y": 3,
      "z": 7,
      "name": "Soil_Dirt",
      "support": 15
    },
    {
      "x": -12,
      "y": 4,
      "z": 7,
      "name": "Soil_Grass_Sunny",
      "support": 15
    },
    {
      "x": -12,
      "y": 16,
      "z": 7,
      "name": "Plant_Leaves_Maple",
      "support": 15,
      "rotation": 2
    },
    {
      "x": -12,
      "y": 0,
      "z": 8,
      "name": "Soil_Dirt"
    },
    {
      "x": -12,
      "y": 2,
      "z": 8,
      "name": "Soil_Pathway",
      "support": 15
    },
    {
      "x": -12,
      "y": 3,
      "z": 8,
      "name": "Soil_Dirt",
      "support": 15
    },
    {
      "x": -12,
      "y": 4,
      "z": 8,
      "name": "Soil_Dirt"
    },
    {
      "x": -12,
      "y": 5,
      "z": 8,
      "name": "Soil_Grass_Sunny",
      "support": 15
    },
    {
      "x": -12,
      "y": 0,
      "z": 9,
      "name": "Soil_Dirt"
    },
    {
      "x": -12,
      "y": 1,
      "z": 9,
      "name": "Soil_Dirt"
    },
    {
      "x": -12,
      "y": 2,
      "z": 9,
      "name": "Soil_Dirt"
    },
    {
      "x": -12,
      "y": 3,
      "z": 9,
      "name": "Soil_Dirt"
    },
    {
      "x": -12,
      "y": 4,
      "z": 9,
      "name": "Soil_Dirt"
    },
    {
      "x": -12,
      "y": 5,
      "z": 9,
      "name": "Soil_Grass_Sunny",
      "support": 15
    },
    {
      "x": -12,
      "y": 6,
      "z": 9,
      "name": "Plant_Crop_Mushroom_Common_Brown",
      "support": 15
    },
    {
      "x": -12,
      "y": 0,
      "z": 10,
      "name": "Soil_Dirt"
    },
    {
      "x": -12,
      "y": 1,
      "z": 10,
      "name": "Soil_Dirt"
    },
    {
      "x": -12,
      "y": 2,
      "z": 10,
      "name": "Soil_Dirt"
    },
    {
      "x": -12,
      "y": 3,
      "z": 10,
      "name": "Soil_Dirt"
    },
    {
      "x": -12,
      "y": 4,
      "z": 10,
      "name": "Soil_Dirt"
    },
    {
      "x": -12,
      "y": 5,
      "z": 10,
      "name": "Soil_Grass_Sunny",
      "support": 15
    },
    {
      "x": -12,
      "y": 6,
      "z": 10,
      "name": "Plant_Grass_Sharp_Short",
      "support": 15
    },
    {
      "x": -12,
      "y": 0,
      "z": 11,
      "name": "Soil_Dirt"
    },
    {
      "x": -12,
      "y": 1,
      "z": 11,
      "name": "Soil_Dirt"
    },
    {
      "x": -12,
      "y": 2,
      "z": 11,
      "name": "Soil_Dirt"
    },
    {
      "x": -12,
      "y": 3,
      "z": 11,
      "name": "Soil_Dirt"
    },
    {
      "x": -12,
      "y": 4,
      "z": 11,
      "name": "Soil_Dirt"
    },
    {
      "x": -12,
      "y": 5,
      "z": 11,
      "name": "Soil_Grass_Sunny",
      "support": 15
    },
    {
      "x": -12,
      "y": 0,
      "z": 12,
      "name": "Soil_Dirt"
    },
    {
      "x": -12,
      "y": 1,
      "z": 12,
      "name": "Soil_Dirt"
    },
    {
      "x": -12,
      "y": 2,
      "z": 12,
      "name": "Soil_Dirt"
    },
    {
      "x": -12,
      "y": 3,
      "z": 12,
      "name": "Soil_Dirt"
    },
    {
      "x": -12,
      "y": 4,
      "z": 12,
      "name": "Soil_Dirt"
    },
    {
      "x": -12,
      "y": 5,
      "z": 12,
      "name": "Soil_Grass_Sunny",
      "support": 15
    },
    {
      "x": -12,
      "y": 6,
      "z": 12,
      "name": "Plant_Grass_Sharp",
      "support": 15
    },
    {
      "x": -12,
      "y": 0,
      "z": 13,
      "name": "Soil_Dirt"
    },
    {
      "x": -12,
      "y": 1,
      "z": 13,
      "name": "Soil_Dirt"
    },
    {
      "x": -12,
      "y": 2,
      "z": 13,
      "name": "Soil_Dirt"
    },
    {
      "x": -12,
      "y": 3,
      "z": 13,
      "name": "Soil_Dirt"
    },
    {
      "x": -12,
      "y": 4,
      "z": 13,
      "name": "Soil_Dirt"
    },
    {
      "x": -12,
      "y": 5,
      "z": 13,
      "name": "Soil_Grass_Sunny",
      "support": 15
    },
    {
      "x": -12,
      "y": 6,
      "z": 13,
      "name": "Plant_Grass_Sharp_Short",
      "support": 15
    },
    {
      "x": -12,
      "y": 0,
      "z": 14,
      "name": "Soil_Dirt"
    },
    {
      "x": -12,
      "y": 1,
      "z": 14,
      "name": "Soil_Dirt"
    },
    {
      "x": -12,
      "y": 2,
      "z": 14,
      "name": "Soil_Dirt"
    },
    {
      "x": -12,
      "y": 3,
      "z": 14,
      "name": "Soil_Dirt"
    },
    {
      "x": -12,
      "y": 4,
      "z": 14,
      "name": "Soil_Dirt"
    },
    {
      "x": -12,
      "y": 5,
      "z": 14,
      "name": "Soil_Grass_Sunny",
      "support": 15
    },
    {
      "x": -12,
      "y": 6,
      "z": 14,
      "name": "Plant_Grass_Sharp_Short",
      "support": 15
    },
    {
      "x": -12,
      "y": 0,
      "z": 15,
      "name": "Soil_Dirt"
    },
    {
      "x": -12,
      "y": 1,
      "z": 15,
      "name": "Soil_Dirt"
    },
    {
      "x": -12,
      "y": 2,
      "z": 15,
      "name": "Soil_Dirt"
    },
    {
      "x": -12,
      "y": 3,
      "z": 15,
      "name": "Soil_Dirt"
    },
    {
      "x": -12,
      "y": 4,
      "z": 15,
      "name": "Soil_Dirt"
    },
    {
      "x": -12,
      "y": 5,
      "z": 15,
      "name": "Rock_Stone_Brick_Smooth"
    },
    {
      "x": -11,
      "y": 0,
      "z": -14,
      "name": "Soil_Dirt"
    },
    {
      "x": -11,
      "y": 1,
      "z": -14,
      "name": "Soil_Dirt"
    },
    {
      "x": -11,
      "y": 2,
      "z": -14,
      "name": "Soil_Dirt"
    },
    {
      "x": -11,
      "y": 3,
      "z": -14,
      "name": "Soil_Dirt"
    },
    {
      "x": -11,
      "y": 4,
      "z": -14,
      "name": "Soil_Dirt"
    },
    {
      "x": -11,
      "y": 5,
      "z": -14,
      "name": "Rock_Stone_Brick_Smooth"
    },
    {
      "x": -11,
      "y": 0,
      "z": -13,
      "name": "Soil_Dirt"
    },
    {
      "x": -11,
      "y": 1,
      "z": -13,
      "name": "Soil_Dirt"
    },
    {
      "x": -11,
      "y": 2,
      "z": -13,
      "name": "Soil_Dirt"
    },
    {
      "x": -11,
      "y": 3,
      "z": -13,
      "name": "Soil_Dirt"
    },
    {
      "x": -11,
      "y": 4,
      "z": -13,
      "name": "Soil_Dirt"
    },
    {
      "x": -11,
      "y": 5,
      "z": -13,
      "name": "Soil_Grass_Sunny",
      "support": 15
    },
    {
      "x": -11,
      "y": 6,
      "z": -13,
      "name": "Plant_Flower_Common_Yellow2",
      "support": 15
    },
    {
      "x": -11,
      "y": 0,
      "z": -12,
      "name": "Soil_Dirt"
    },
    {
      "x": -11,
      "y": 1,
      "z": -12,
      "name": "Soil_Dirt"
    },
    {
      "x": -11,
      "y": 2,
      "z": -12,
      "name": "Soil_Dirt"
    },
    {
      "x": -11,
      "y": 3,
      "z": -12,
      "name": "Soil_Dirt"
    },
    {
      "x": -11,
      "y": 4,
      "z": -12,
      "name": "Soil_Dirt"
    },
    {
      "x": -11,
      "y": 5,
      "z": -12,
      "name": "Soil_Pathway"
    },
    {
      "x": -11,
      "y": 6,
      "z": -12,
      "name": "Wood_Hardwood_Decorative"
    },
    {
      "x": -11,
      "y": 7,
      "z": -12,
      "name": "Wood_Hardwood_Planks"
    },
    {
      "x": -11,
      "y": 8,
      "z": -12,
      "name": "Wood_Hardwood_Planks"
    },
    {
      "x": -11,
      "y": 9,
      "z": -12,
      "name": "Wood_Hardwood_Planks"
    },
    {
      "x": -11,
      "y": 10,
      "z": -12,
      "name": "Wood_Hardwood_Stairs",
      "rotation": 3
    },
    {
      "x": -11,
      "y": 0,
      "z": -11,
      "name": "Soil_Dirt"
    },
    {
      "x": -11,
      "y": 1,
      "z": -11,
      "name": "Soil_Dirt"
    },
    {
      "x": -11,
      "y": 2,
      "z": -11,
      "name": "Soil_Dirt"
    },
    {
      "x": -11,
      "y": 3,
      "z": -11,
      "name": "Soil_Dirt"
    },
    {
      "x": -11,
      "y": 4,
      "z": -11,
      "name": "Soil_Dirt"
    },
    {
      "x": -11,
      "y": 5,
      "z": -11,
      "name": "Soil_Pathway"
    },
    {
      "x": -11,
      "y": 6,
      "z": -11,
      "name": "Wood_Hardwood_Decorative"
    },
    {
      "x": -11,
      "y": 7,
      "z": -11,
      "name": "Wood_Hardwood_Planks"
    },
    {
      "x": -11,
      "y": 8,
      "z": -11,
      "name": "Wood_Hardwood_Planks"
    },
    {
      "x": -11,
      "y": 10,
      "z": -11,
      "name": "Cloth_Modern_Orange_Roof",
      "rotation": 3
    },
    {
      "x": -11,
      "y": 0,
      "z": -10,
      "name": "Soil_Dirt"
    },
    {
      "x": -11,
      "y": 1,
      "z": -10,
      "name": "Soil_Dirt"
    },
    {
      "x": -11,
      "y": 2,
      "z": -10,
      "name": "Soil_Dirt"
    },
    {
      "x": -11,
      "y": 3,
      "z": -10,
      "name": "Soil_Dirt"
    },
    {
      "x": -11,
      "y": 4,
      "z": -10,
      "name": "Soil_Dirt"
    },
    {
      "x": -11,
      "y": 5,
      "z": -10,
      "name": "Soil_Dirt"
    },
    {
      "x": -11,
      "y": 6,
      "z": -10,
      "name": "Wood_Hardwood_Decorative"
    },
    {
      "x": -11,
      "y": 7,
      "z": -10,
      "name": "Wood_Hardwood_Planks"
    },
    {
      "x": -11,
      "y": 10,
      "z": -10,
      "name": "Cloth_Modern_Orange_Roof",
      "rotation": 3
    },
    {
      "x": -11,
      "y": 0,
      "z": -9,
      "name": "Soil_Dirt"
    },
    {
      "x": -11,
      "y": 1,
      "z": -9,
      "name": "Soil_Dirt"
    },
    {
      "x": -11,
      "y": 2,
      "z": -9,
      "name": "Soil_Dirt"
    },
    {
      "x": -11,
      "y": 3,
      "z": -9,
      "name": "Soil_Dirt"
    },
    {
      "x": -11,
      "y": 4,
      "z": -9,
      "name": "Soil_Dirt"
    },
    {
      "x": -11,
      "y": 5,
      "z": -9,
      "name": "Soil_Dirt"
    },
    {
      "x": -11,
      "y": 6,
      "z": -9,
      "name": "Wood_Hardwood_Decorative"
    },
    {
      "x": -11,
      "y": 7,
      "z": -9,
      "name": "Wood_Hardwood_Beam"
    },
    {
      "x": -11,
      "y": 8,
      "z": -9,
      "name": "Wood_Hardwood_Beam"
    },
    {
      "x": -11,
      "y": 9,
      "z": -9,
      "name": "Wood_Hardwood_Beam"
    },
    {
      "x": -11,
      "y": 10,
      "z": -9,
      "name": "*Cloth_Modern_Orange_Roof_State_Definitions_Corner_Right"
    },
    {
      "x": -11,
      "y": 0,
      "z": -8,
      "name": "Soil_Dirt"
    },
    {
      "x": -11,
      "y": 1,
      "z": -8,
      "name": "Soil_Dirt"
    },
    {
      "x": -11,
      "y": 2,
      "z": -8,
      "name": "Soil_Dirt"
    },
    {
      "x": -11,
      "y": 3,
      "z": -8,
      "name": "Soil_Dirt"
    },
    {
      "x": -11,
      "y": 4,
      "z": -8,
      "name": "Soil_Dirt"
    },
    {
      "x": -11,
      "y": 5,
      "z": -8,
      "name": "Soil_Pathway"
    },
    {
      "x": -11,
      "y": 0,
      "z": -7,
      "name": "Soil_Dirt"
    },
    {
      "x": -11,
      "y": 1,
      "z": -7,
      "name": "Soil_Dirt"
    },
    {
      "x": -11,
      "y": 2,
      "z": -7,
      "name": "Soil_Dirt"
    },
    {
      "x": -11,
      "y": 3,
      "z": -7,
      "name": "Soil_Dirt"
    },
    {
      "x": -11,
      "y": 4,
      "z": -7,
      "name": "Soil_Dirt"
    },
    {
      "x": -11,
      "y": 5,
      "z": -7,
      "name": "Soil_Grass_Sunny"
    },
    {
      "x": -11,
      "y": 0,
      "z": -6,
      "name": "Soil_Dirt"
    },
    {
      "x": -11,
      "y": 1,
      "z": -6,
      "name": "Soil_Dirt"
    },
    {
      "x": -11,
      "y": 2,
      "z": -6,
      "name": "Soil_Dirt"
    },
    {
      "x": -11,
      "y": 3,
      "z": -6,
      "name": "Soil_Dirt"
    },
    {
      "x": -11,
      "y": 4,
      "z": -6,
      "name": "Soil_Dirt"
    },
    {
      "x": -11,
      "y": 5,
      "z": -6,
      "name": "Soil_Pathway"
    },
    {
      "x": -11,
      "y": 0,
      "z": -5,
      "name": "Soil_Dirt"
    },
    {
      "x": -11,
      "y": 1,
      "z": -5,
      "name": "Soil_Dirt"
    },
    {
      "x": -11,
      "y": 2,
      "z": -5,
      "name": "Soil_Dirt"
    },
    {
      "x": -11,
      "y": 3,
      "z": -5,
      "name": "Soil_Dirt"
    },
    {
      "x": -11,
      "y": 4,
      "z": -5,
      "name": "Soil_Dirt"
    },
    {
      "x": -11,
      "y": 5,
      "z": -5,
      "name": "Soil_Pathway"
    },
    {
      "x": -11,
      "y": 0,
      "z": -4,
      "name": "Soil_Dirt"
    },
    {
      "x": -11,
      "y": 1,
      "z": -4,
      "name": "Soil_Dirt"
    },
    {
      "x": -11,
      "y": 2,
      "z": -4,
      "name": "Soil_Dirt"
    },
    {
      "x": -11,
      "y": 3,
      "z": -4,
      "name": "Soil_Dirt"
    },
    {
      "x": -11,
      "y": 4,
      "z": -4,
      "name": "Soil_Dirt"
    },
    {
      "x": -11,
      "y": 5,
      "z": -4,
      "name": "Soil_Pathway"
    },
    {
      "x": -11,
      "y": 0,
      "z": -3,
      "name": "Soil_Dirt"
    },
    {
      "x": -11,
      "y": 1,
      "z": -3,
      "name": "Soil_Dirt"
    },
    {
      "x": -11,
      "y": 2,
      "z": -3,
      "name": "Soil_Dirt"
    },
    {
      "x": -11,
      "y": 3,
      "z": -3,
      "name": "Soil_Dirt"
    },
    {
      "x": -11,
      "y": 4,
      "z": -3,
      "name": "Soil_Dirt"
    },
    {
      "x": -11,
      "y": 5,
      "z": -3,
      "name": "Soil_Clay"
    },
    {
      "x": -11,
      "y": 0,
      "z": -2,
      "name": "Soil_Dirt"
    },
    {
      "x": -11,
      "y": 1,
      "z": -2,
      "name": "Soil_Dirt"
    },
    {
      "x": -11,
      "y": 2,
      "z": -2,
      "name": "Soil_Dirt"
    },
    {
      "x": -11,
      "y": 3,
      "z": -2,
      "name": "Soil_Dirt"
    },
    {
      "x": -11,
      "y": 4,
      "z": -2,
      "name": "Soil_Dirt"
    },
    {
      "x": -11,
      "y": 5,
      "z": -2,
      "name": "Soil_Dirt"
    },
    {
      "x": -11,
      "y": 0,
      "z": -1,
      "name": "Soil_Dirt"
    },
    {
      "x": -11,
      "y": 1,
      "z": -1,
      "name": "Soil_Dirt"
    },
    {
      "x": -11,
      "y": 2,
      "z": -1,
      "name": "Soil_Dirt"
    },
    {
      "x": -11,
      "y": 3,
      "z": -1,
      "name": "Soil_Dirt"
    },
    {
      "x": -11,
      "y": 4,
      "z": -1,
      "name": "Soil_Dirt"
    },
    {
      "x": -11,
      "y": 5,
      "z": -1,
      "name": "Soil_Clay"
    },
    {
      "x": -11,
      "y": 0,
      "z": 0,
      "name": "Soil_Dirt"
    },
    {
      "x": -11,
      "y": 1,
      "z": 0,
      "name": "Soil_Dirt"
    },
    {
      "x": -11,
      "y": 2,
      "z": 0,
      "name": "Soil_Dirt"
    },
    {
      "x": -11,
      "y": 3,
      "z": 0,
      "name": "Soil_Dirt"
    },
    {
      "x": -11,
      "y": 4,
      "z": 0,
      "name": "Soil_Dirt"
    },
    {
      "x": -11,
      "y": 5,
      "z": 0,
      "name": "Soil_Pathway"
    },
    {
      "x": -11,
      "y": 0,
      "z": 1,
      "name": "Soil_Dirt"
    },
    {
      "x": -11,
      "y": 1,
      "z": 1,
      "name": "Soil_Dirt"
    },
    {
      "x": -11,
      "y": 2,
      "z": 1,
      "name": "Soil_Dirt"
    },
    {
      "x": -11,
      "y": 3,
      "z": 1,
      "name": "Soil_Dirt"
    },
    {
      "x": -11,
      "y": 4,
      "z": 1,
      "name": "Soil_Dirt"
    },
    {
      "x": -11,
      "y": 5,
      "z": 1,
      "name": "Soil_Grass_Sunny",
      "support": 15
    },
    {
      "x": -11,
      "y": 6,
      "z": 1,
      "name": "Plant_Grass_Sharp_Short",
      "support": 15
    },
    {
      "x": -11,
      "y": 0,
      "z": 2,
      "name": "Soil_Dirt"
    },
    {
      "x": -11,
      "y": 1,
      "z": 2,
      "name": "Soil_Dirt"
    },
    {
      "x": -11,
      "y": 2,
      "z": 2,
      "name": "Soil_Dirt"
    },
    {
      "x": -11,
      "y": 3,
      "z": 2,
      "name": "Soil_Dirt"
    },
    {
      "x": -11,
      "y": 4,
      "z": 2,
      "name": "Soil_Dirt"
    },
    {
      "x": -11,
      "y": 5,
      "z": 2,
      "name": "Soil_Grass_Sunny",
      "support": 15
    },
    {
      "x": -11,
      "y": 6,
      "z": 2,
      "name": "Plant_Grass_Sharp_Short",
      "support": 15
    },
    {
      "x": -11,
      "y": 14,
      "z": 2,
      "name": "Plant_Leaves_Maple",
      "support": 15,
      "rotation": 2
    },
    {
      "x": -11,
      "y": 15,
      "z": 2,
      "name": "Plant_Leaves_Maple",
      "support": 15,
      "rotation": 2
    },
    {
      "x": -11,
      "y": 16,
      "z": 2,
      "name": "Plant_Leaves_Maple",
      "support": 15,
      "rotation": 2
    },
    {
      "x": -11,
      "y": 17,
      "z": 2,
      "name": "Plant_Leaves_Maple",
      "support": 15,
      "rotation": 2
    },
    {
      "x": -11,
      "y": 0,
      "z": 3,
      "name": "Soil_Dirt"
    },
    {
      "x": -11,
      "y": 1,
      "z": 3,
      "name": "Soil_Dirt"
    },
    {
      "x": -11,
      "y": 2,
      "z": 3,
      "name": "Soil_Dirt"
    },
    {
      "x": -11,
      "y": 3,
      "z": 3,
      "name": "Soil_Dirt",
      "support": 15
    },
    {
      "x": -11,
      "y": 4,
      "z": 3,
      "name": "Soil_Dirt",
      "support": 15
    },
    {
      "x": -11,
      "y": 5,
      "z": 3,
      "name": "Soil_Grass_Sunny",
      "support": 15
    },
    {
      "x": -11,
      "y": 6,
      "z": 3,
      "name": "Plant_Grass_Sharp_Short",
      "support": 15
    },
    {
      "x": -11,
      "y": 14,
      "z": 3,
      "name": "Plant_Leaves_Maple",
      "support": 15,
      "rotation": 2
    },
    {
      "x": -11,
      "y": 15,
      "z": 3,
      "name": "Plant_Leaves_Maple",
      "support": 15,
      "rotation": 2
    },
    {
      "x": -11,
      "y": 17,
      "z": 3,
      "name": "Plant_Leaves_Maple",
      "support": 15,
      "rotation": 2
    },
    {
      "x": -11,
      "y": 0,
      "z": 4,
      "name": "Soil_Dirt"
    },
    {
      "x": -11,
      "y": 2,
      "z": 4,
      "name": "Soil_Pathway",
      "support": 15
    },
    {
      "x": -11,
      "y": 3,
      "z": 4,
      "name": "Soil_Dirt",
      "support": 15
    },
    {
      "x": -11,
      "y": 4,
      "z": 4,
      "name": "Soil_Grass_Sunny",
      "support": 15
    },
    {
      "x": -11,
      "y": 6,
      "z": 4,
      "name": "Plant_Flower_Water_White",
      "support": 15
    },
    {
      "x": -11,
      "y": 14,
      "z": 4,
      "name": "Plant_Leaves_Maple",
      "support": 15,
      "rotation": 2
    },
    {
      "x": -11,
      "y": 16,
      "z": 4,
      "name": "Wood_Oak_Branch_Long",
      "support": 15,
      "rotation": 7
    },
    {
      "x": -11,
      "y": 17,
      "z": 4,
      "name": "Plant_Leaves_Maple",
      "support": 15,
      "rotation": 2
    },
    {
      "x": -11,
      "y": 0,
      "z": 5,
      "name": "Soil_Dirt"
    },
    {
      "x": -11,
      "y": 1,
      "z": 5,
      "name": "Soil_Dirt"
    },
    {
      "x": -11,
      "y": 2,
      "z": 5,
      "name": "Soil_Pathway",
      "support": 15
    },
    {
      "x": -11,
      "y": 3,
      "z": 5,
      "name": "Soil_Grass_Sunny",
      "support": 15
    },
    {
      "x": -11,
      "y": 15,
      "z": 5,
      "name": "Plant_Leaves_Maple",
      "support": 15,
      "rotation": 2
    },
    {
      "x": -11,
      "y": 16,
      "z": 5,
      "name": "Plant_Leaves_Maple",
      "support": 15,
      "rotation": 2
    },
    {
      "x": -11,
      "y": 17,
      "z": 5,
      "name": "Plant_Leaves_Maple",
      "support": 15,
      "rotation": 2
    },
    {
      "x": -11,
      "y": 18,
      "z": 5,
      "name": "Plant_Leaves_Maple",
      "support": 15,
      "rotation": 2
    },
    {
      "x": -11,
      "y": 0,
      "z": 6,
      "name": "Soil_Dirt"
    },
    {
      "x": -11,
      "y": 1,
      "z": 6,
      "name": "Soil_Dirt"
    },
    {
      "x": -11,
      "y": 2,
      "z": 6,
      "name": "Soil_Pathway",
      "support": 15
    },
    {
      "x": -11,
      "y": 3,
      "z": 6,
      "name": "Soil_Grass_Sunny",
      "support": 15
    },
    {
      "x": -11,
      "y": 15,
      "z": 6,
      "name": "Plant_Leaves_Maple",
      "support": 15,
      "rotation": 2
    },
    {
      "x": -11,
      "y": 16,
      "z": 6,
      "name": "Plant_Leaves_Maple",
      "support": 15,
      "rotation": 2
    },
    {
      "x": -11,
      "y": 17,
      "z": 6,
      "name": "Plant_Leaves_Maple",
      "support": 15,
      "rotation": 2
    },
    {
      "x": -11,
      "y": 0,
      "z": 7,
      "name": "Soil_Dirt"
    },
    {
      "x": -11,
      "y": 1,
      "z": 7,
      "name": "Soil_Dirt"
    },
    {
      "x": -11,
      "y": 2,
      "z": 7,
      "name": "Soil_Dirt",
      "support": 15
    },
    {
      "x": -11,
      "y": 3,
      "z": 7,
      "name": "Soil_Dirt",
      "support": 15
    },
    {
      "x": -11,
      "y": 4,
      "z": 7,
      "name": "Rock_Crystal_Cyan_Small",
      "support": 15
    },
    {
      "x": -11,
      "y": 16,
      "z": 7,
      "name": "Plant_Leaves_Maple",
      "support": 15,
      "rotation": 2
    },
    {
      "x": -11,
      "y": 17,
      "z": 7,
      "name": "Plant_Leaves_Maple",
      "support": 15,
      "rotation": 2
    },
    {
      "x": -11,
      "y": 18,
      "z": 7,
      "name": "Plant_Leaves_Maple",
      "support": 15,
      "rotation": 2
    },
    {
      "x": -11,
      "y": 0,
      "z": 8,
      "name": "Soil_Dirt"
    },
    {
      "x": -11,
      "y": 2,
      "z": 8,
      "name": "Soil_Dirt",
      "support": 15
    },
    {
      "x": -11,
      "y": 3,
      "z": 8,
      "name": "Soil_Dirt",
      "support": 15
    },
    {
      "x": -11,
      "y": 4,
      "z": 8,
      "name": "Soil_Grass_Sunny",
      "support": 15
    },
    {
      "x": -11,
      "y": 15,
      "z": 8,
      "name": "Plant_Leaves_Maple",
      "support": 15,
      "rotation": 2
    },
    {
      "x": -11,
      "y": 16,
      "z": 8,
      "name": "Plant_Leaves_Maple",
      "support": 15,
      "rotation": 2
    },
    {
      "x": -11,
      "y": 17,
      "z": 8,
      "name": "Plant_Leaves_Maple",
      "support": 15,
      "rotation": 2
    },
    {
      "x": -11,
      "y": 18,
      "z": 8,
      "name": "Plant_Leaves_Maple",
      "support": 15,
      "rotation": 2
    },
    {
      "x": -11,
      "y": 0,
      "z": 9,
      "name": "Soil_Dirt"
    },
    {
      "x": -11,
      "y": 1,
      "z": 9,
      "name": "Soil_Dirt"
    },
    {
      "x": -11,
      "y": 3,
      "z": 9,
      "name": "Soil_Dirt",
      "support": 15
    },
    {
      "x": -11,
      "y": 4,
      "z": 9,
      "name": "Soil_Grass_Sunny"
    },
    {
      "x": -11,
      "y": 5,
      "z": 9,
      "name": "Plant_Crop_Mushroom_Cap_Red",
      "components": {
        "Components": {
          "FarmingBlock": {
            "LastTickGameTime": "0001-03-23T21:28:09.490776242Z",
            "SpreadRate": 0.0
          }
        }
      },
      "support": 15
    },
    {
      "x": -11,
      "y": 16,
      "z": 9,
      "name": "Plant_Leaves_Maple",
      "support": 15,
      "rotation": 2
    },
    {
      "x": -11,
      "y": 17,
      "z": 9,
      "name": "Plant_Leaves_Maple",
      "support": 15,
      "rotation": 2
    },
    {
      "x": -11,
      "y": 0,
      "z": 10,
      "name": "Soil_Dirt"
    },
    {
      "x": -11,
      "y": 1,
      "z": 10,
      "name": "Soil_Dirt"
    },
    {
      "x": -11,
      "y": 2,
      "z": 10,
      "name": "Soil_Dirt"
    },
    {
      "x": -11,
      "y": 3,
      "z": 10,
      "name": "Soil_Dirt"
    },
    {
      "x": -11,
      "y": 4,
      "z": 10,
      "name": "Soil_Dirt"
    },
    {
      "x": -11,
      "y": 5,
      "z": 10,
      "name": "Soil_Grass_Sunny",
      "support": 15
    },
    {
      "x": -11,
      "y": 6,
      "z": 10,
      "name": "Plant_Grass_Sharp_Short",
      "support": 15
    },
    {
      "x": -11,
      "y": 16,
      "z": 10,
      "name": "Plant_Leaves_Maple",
      "support": 15,
      "rotation": 2
    },
    {
      "x": -11,
      "y": 0,
      "z": 11,
      "name": "Soil_Dirt"
    },
    {
      "x": -11,
      "y": 1,
      "z": 11,
      "name": "Soil_Dirt"
    },
    {
      "x": -11,
      "y": 2,
      "z": 11,
      "name": "Soil_Dirt"
    },
    {
      "x": -11,
      "y": 3,
      "z": 11,
      "name": "Soil_Dirt"
    },
    {
      "x": -11,
      "y": 4,
      "z": 11,
      "name": "Soil_Dirt"
    },
    {
      "x": -11,
      "y": 5,
      "z": 11,
      "name": "Soil_Grass_Sunny",
      "support": 15
    },
    {
      "x": -11,
      "y": 6,
      "z": 11,
      "name": "Plant_Grass_Sharp",
      "support": 15
    },
    {
      "x": -11,
      "y": 0,
      "z": 12,
      "name": "Soil_Dirt"
    },
    {
      "x": -11,
      "y": 1,
      "z": 12,
      "name": "Soil_Dirt"
    },
    {
      "x": -11,
      "y": 2,
      "z": 12,
      "name": "Soil_Dirt"
    },
    {
      "x": -11,
      "y": 3,
      "z": 12,
      "name": "Soil_Dirt"
    },
    {
      "x": -11,
      "y": 4,
      "z": 12,
      "name": "Soil_Dirt"
    },
    {
      "x": -11,
      "y": 5,
      "z": 12,
      "name": "Soil_Grass_Sunny",
      "support": 15
    },
    {
      "x": -11,
      "y": 6,
      "z": 12,
      "name": "Plant_Grass_Sharp_Short",
      "support": 15
    },
    {
      "x": -11,
      "y": 0,
      "z": 13,
      "name": "Soil_Dirt"
    },
    {
      "x": -11,
      "y": 1,
      "z": 13,
      "name": "Soil_Dirt"
    },
    {
      "x": -11,
      "y": 2,
      "z": 13,
      "name": "Soil_Dirt"
    },
    {
      "x": -11,
      "y": 3,
      "z": 13,
      "name": "Soil_Dirt"
    },
    {
      "x": -11,
      "y": 4,
      "z": 13,
      "name": "Soil_Dirt"
    },
    {
      "x": -11,
      "y": 5,
      "z": 13,
      "name": "Soil_Grass_Sunny",
      "support": 15
    },
    {
      "x": -11,
      "y": 6,
      "z": 13,
      "name": "Plant_Grass_Sharp",
      "support": 15
    },
    {
      "x": -11,
      "y": 0,
      "z": 14,
      "name": "Soil_Dirt"
    },
    {
      "x": -11,
      "y": 1,
      "z": 14,
      "name": "Soil_Dirt"
    },
    {
      "x": -11,
      "y": 2,
      "z": 14,
      "name": "Soil_Dirt"
    },
    {
      "x": -11,
      "y": 3,
      "z": 14,
      "name": "Soil_Dirt"
    },
    {
      "x": -11,
      "y": 4,
      "z": 14,
      "name": "Soil_Dirt"
    },
    {
      "x": -11,
      "y": 5,
      "z": 14,
      "name": "Soil_Grass_Sunny",
      "support": 15
    },
    {
      "x": -11,
      "y": 6,
      "z": 14,
      "name": "Plant_Crop_Mushroom_Cap_Red",
      "support": 15
    },
    {
      "x": -11,
      "y": 0,
      "z": 15,
      "name": "Soil_Dirt"
    },
    {
      "x": -11,
      "y": 1,
      "z": 15,
      "name": "Soil_Dirt"
    },
    {
      "x": -11,
      "y": 2,
      "z": 15,
      "name": "Soil_Dirt"
    },
    {
      "x": -11,
      "y": 3,
      "z": 15,
      "name": "Soil_Dirt"
    },
    {
      "x": -11,
      "y": 4,
      "z": 15,
      "name": "Soil_Dirt"
    },
    {
      "x": -11,
      "y": 5,
      "z": 15,
      "name": "Rock_Stone_Brick_Smooth"
    },
    {
      "x": -10,
      "y": 0,
      "z": -14,
      "name": "Soil_Dirt"
    },
    {
      "x": -10,
      "y": 1,
      "z": -14,
      "name": "Soil_Dirt"
    },
    {
      "x": -10,
      "y": 2,
      "z": -14,
      "name": "Soil_Dirt"
    },
    {
      "x": -10,
      "y": 3,
      "z": -14,
      "name": "Soil_Dirt"
    },
    {
      "x": -10,
      "y": 4,
      "z": -14,
      "name": "Soil_Dirt"
    },
    {
      "x": -10,
      "y": 5,
      "z": -14,
      "name": "Rock_Stone_Brick_Smooth"
    },
    {
      "x": -10,
      "y": 0,
      "z": -13,
      "name": "Soil_Dirt"
    },
    {
      "x": -10,
      "y": 1,
      "z": -13,
      "name": "Soil_Dirt"
    },
    {
      "x": -10,
      "y": 2,
      "z": -13,
      "name": "Soil_Dirt"
    },
    {
      "x": -10,
      "y": 3,
      "z": -13,
      "name": "Soil_Dirt"
    },
    {
      "x": -10,
      "y": 4,
      "z": -13,
      "name": "Soil_Dirt"
    },
    {
      "x": -10,
      "y": 5,
      "z": -13,
      "name": "Soil_Grass_Sunny",
      "support": 15
    },
    {
      "x": -10,
      "y": 0,
      "z": -12,
      "name": "Soil_Dirt"
    },
    {
      "x": -10,
      "y": 1,
      "z": -12,
      "name": "Soil_Dirt"
    },
    {
      "x": -10,
      "y": 2,
      "z": -12,
      "name": "Soil_Dirt"
    },
    {
      "x": -10,
      "y": 3,
      "z": -12,
      "name": "Soil_Dirt"
    },
    {
      "x": -10,
      "y": 4,
      "z": -12,
      "name": "Soil_Dirt"
    },
    {
      "x": -10,
      "y": 5,
      "z": -12,
      "name": "Soil_Pathway"
    },
    {
      "x": -10,
      "y": 6,
      "z": -12,
      "name": "Wood_Hardwood_Decorative"
    },
    {
      "x": -10,
      "y": 7,
      "z": -12,
      "name": "Wood_Hardwood_Planks"
    },
    {
      "x": -10,
      "y": 8,
      "z": -12,
      "name": "Wood_Hardwood_Planks"
    },
    {
      "x": -10,
      "y": 9,
      "z": -12,
      "name": "Wood_Hardwood_Planks"
    },
    {
      "x": -10,
      "y": 10,
      "z": -12,
      "name": "Wood_Hardwood_Planks"
    },
    {
      "x": -10,
      "y": 0,
      "z": -11,
      "name": "Soil_Dirt"
    },
    {
      "x": -10,
      "y": 1,
      "z": -11,
      "name": "Soil_Dirt"
    },
    {
      "x": -10,
      "y": 2,
      "z": -11,
      "name": "Soil_Dirt"
    },
    {
      "x": -10,
      "y": 3,
      "z": -11,
      "name": "Soil_Dirt"
    },
    {
      "x": -10,
      "y": 4,
      "z": -11,
      "name": "Soil_Dirt"
    },
    {
      "x": -10,
      "y": 5,
      "z": -11,
      "name": "Soil_Pathway"
    },
    {
      "x": -10,
      "y": 6,
      "z": -11,
      "name": "Wood_Hardwood_Decorative"
    },
    {
      "x": -10,
      "y": 7,
      "z": -11,
      "name": "Wood_Hardwood_Planks"
    },
    {
      "x": -10,
      "y": 8,
      "z": -11,
      "name": "Wood_Hardwood_Decorative"
    },
    {
      "x": -10,
      "y": 11,
      "z": -11,
      "name": "Cloth_Modern_Orange_Roof_Flat"
    },
    {
      "x": -10,
      "y": 0,
      "z": -10,
      "name": "Soil_Dirt"
    },
    {
      "x": -10,
      "y": 1,
      "z": -10,
      "name": "Soil_Dirt"
    },
    {
      "x": -10,
      "y": 2,
      "z": -10,
      "name": "Soil_Dirt"
    },
    {
      "x": -10,
      "y": 3,
      "z": -10,
      "name": "Soil_Dirt"
    },
    {
      "x": -10,
      "y": 4,
      "z": -10,
      "name": "Soil_Dirt"
    },
    {
      "x": -10,
      "y": 5,
      "z": -10,
      "name": "Soil_Dirt"
    },
    {
      "x": -10,
      "y": 6,
      "z": -10,
      "name": "Wood_Hardwood_Decorative"
    },
    {
      "x": -10,
      "y": 7,
      "z": -10,
      "name": "Wood_Hardwood_Decorative"
    },
    {
      "x": -10,
      "y": 11,
      "z": -10,
      "name": "Cloth_Modern_Orange_Roof_Flat"
    },
    {
      "x": -10,
      "y": 0,
      "z": -9,
      "name": "Soil_Dirt"
    },
    {
      "x": -10,
      "y": 1,
      "z": -9,
      "name": "Soil_Dirt"
    },
    {
      "x": -10,
      "y": 2,
      "z": -9,
      "name": "Soil_Dirt"
    },
    {
      "x": -10,
      "y": 3,
      "z": -9,
      "name": "Soil_Dirt"
    },
    {
      "x": -10,
      "y": 4,
      "z": -9,
      "name": "Soil_Dirt"
    },
    {
      "x": -10,
      "y": 5,
      "z": -9,
      "name": "Soil_Pathway"
    },
    {
      "x": -10,
      "y": 6,
      "z": -9,
      "name": "Wood_Hardwood_Decorative"
    },
    {
      "x": -10,
      "y": 10,
      "z": -9,
      "name": "Cloth_Modern_Orange_Roof"
    },
    {
      "x": -10,
      "y": 0,
      "z": -8,
      "name": "Soil_Dirt"
    },
    {
      "x": -10,
      "y": 1,
      "z": -8,
      "name": "Soil_Dirt"
    },
    {
      "x": -10,
      "y": 2,
      "z": -8,
      "name": "Soil_Dirt"
    },
    {
      "x": -10,
      "y": 3,
      "z": -8,
      "name": "Soil_Dirt"
    },
    {
      "x": -10,
      "y": 4,
      "z": -8,
      "name": "Soil_Dirt"
    },
    {
      "x": -10,
      "y": 5,
      "z": -8,
      "name": "Soil_Pathway"
    },
    {
      "x": -10,
      "y": 0,
      "z": -7,
      "name": "Soil_Dirt"
    },
    {
      "x": -10,
      "y": 1,
      "z": -7,
      "name": "Soil_Dirt"
    },
    {
      "x": -10,
      "y": 2,
      "z": -7,
      "name": "Soil_Dirt"
    },
    {
      "x": -10,
      "y": 3,
      "z": -7,
      "name": "Soil_Dirt"
    },
    {
      "x": -10,
      "y": 4,
      "z": -7,
      "name": "Soil_Dirt"
    },
    {
      "x": -10,
      "y": 5,
      "z": -7,
      "name": "Soil_Pathway"
    },
    {
      "x": -10,
      "y": 0,
      "z": -6,
      "name": "Soil_Dirt"
    },
    {
      "x": -10,
      "y": 1,
      "z": -6,
      "name": "Soil_Dirt"
    },
    {
      "x": -10,
      "y": 2,
      "z": -6,
      "name": "Soil_Dirt"
    },
    {
      "x": -10,
      "y": 3,
      "z": -6,
      "name": "Soil_Dirt"
    },
    {
      "x": -10,
      "y": 4,
      "z": -6,
      "name": "Soil_Dirt"
    },
    {
      "x": -10,
      "y": 5,
      "z": -6,
      "name": "Soil_Clay"
    },
    {
      "x": -10,
      "y": 0,
      "z": -5,
      "name": "Soil_Dirt"
    },
    {
      "x": -10,
      "y": 1,
      "z": -5,
      "name": "Soil_Dirt"
    },
    {
      "x": -10,
      "y": 2,
      "z": -5,
      "name": "Soil_Dirt"
    },
    {
      "x": -10,
      "y": 3,
      "z": -5,
      "name": "Soil_Dirt"
    },
    {
      "x": -10,
      "y": 4,
      "z": -5,
      "name": "Soil_Dirt"
    },
    {
      "x": -10,
      "y": 5,
      "z": -5,
      "name": "Soil_Pathway"
    },
    {
      "x": -10,
      "y": 0,
      "z": -4,
      "name": "Soil_Dirt"
    },
    {
      "x": -10,
      "y": 1,
      "z": -4,
      "name": "Soil_Dirt"
    },
    {
      "x": -10,
      "y": 2,
      "z": -4,
      "name": "Soil_Dirt"
    },
    {
      "x": -10,
      "y": 3,
      "z": -4,
      "name": "Soil_Dirt"
    },
    {
      "x": -10,
      "y": 4,
      "z": -4,
      "name": "Soil_Dirt"
    },
    {
      "x": -10,
      "y": 5,
      "z": -4,
      "name": "Soil_Pathway"
    },
    {
      "x": -10,
      "y": 0,
      "z": -3,
      "name": "Soil_Dirt"
    },
    {
      "x": -10,
      "y": 1,
      "z": -3,
      "name": "Soil_Dirt"
    },
    {
      "x": -10,
      "y": 2,
      "z": -3,
      "name": "Soil_Dirt"
    },
    {
      "x": -10,
      "y": 3,
      "z": -3,
      "name": "Soil_Dirt"
    },
    {
      "x": -10,
      "y": 4,
      "z": -3,
      "name": "Soil_Dirt"
    },
    {
      "x": -10,
      "y": 5,
      "z": -3,
      "name": "Soil_Dirt"
    },
    {
      "x": -10,
      "y": 0,
      "z": -2,
      "name": "Soil_Dirt"
    },
    {
      "x": -10,
      "y": 1,
      "z": -2,
      "name": "Soil_Dirt"
    },
    {
      "x": -10,
      "y": 2,
      "z": -2,
      "name": "Soil_Dirt"
    },
    {
      "x": -10,
      "y": 3,
      "z": -2,
      "name": "Soil_Dirt"
    },
    {
      "x": -10,
      "y": 4,
      "z": -2,
      "name": "Soil_Dirt"
    },
    {
      "x": -10,
      "y": 5,
      "z": -2,
      "name": "Soil_Pathway"
    },
    {
      "x": -10,
      "y": 0,
      "z": -1,
      "name": "Soil_Dirt"
    },
    {
      "x": -10,
      "y": 1,
      "z": -1,
      "name": "Soil_Dirt"
    },
    {
      "x": -10,
      "y": 2,
      "z": -1,
      "name": "Soil_Dirt"
    },
    {
      "x": -10,
      "y": 3,
      "z": -1,
      "name": "Soil_Dirt"
    },
    {
      "x": -10,
      "y": 4,
      "z": -1,
      "name": "Soil_Dirt"
    },
    {
      "x": -10,
      "y": 5,
      "z": -1,
      "name": "Soil_Pathway"
    },
    {
      "x": -10,
      "y": 0,
      "z": 0,
      "name": "Soil_Dirt"
    },
    {
      "x": -10,
      "y": 1,
      "z": 0,
      "name": "Soil_Dirt"
    },
    {
      "x": -10,
      "y": 2,
      "z": 0,
      "name": "Soil_Dirt"
    },
    {
      "x": -10,
      "y": 3,
      "z": 0,
      "name": "Soil_Dirt"
    },
    {
      "x": -10,
      "y": 4,
      "z": 0,
      "name": "Soil_Dirt"
    },
    {
      "x": -10,
      "y": 5,
      "z": 0,
      "name": "Soil_Pathway"
    },
    {
      "x": -10,
      "y": 6,
      "z": 0,
      "name": "Plant_Crop_Mushroom_Cap_Red",
      "support": 15
    },
    {
      "x": -10,
      "y": 0,
      "z": 1,
      "name": "Soil_Dirt"
    },
    {
      "x": -10,
      "y": 1,
      "z": 1,
      "name": "Soil_Dirt"
    },
    {
      "x": -10,
      "y": 2,
      "z": 1,
      "name": "Soil_Dirt"
    },
    {
      "x": -10,
      "y": 3,
      "z": 1,
      "name": "Soil_Dirt"
    },
    {
      "x": -10,
      "y": 4,
      "z": 1,
      "name": "Soil_Dirt"
    },
    {
      "x": -10,
      "y": 5,
      "z": 1,
      "name": "Soil_Grass_Sunny",
      "support": 15
    },
    {
      "x": -10,
      "y": 14,
      "z": 1,
      "name": "Plant_Leaves_Maple",
      "support": 15,
      "rotation": 2
    },
    {
      "x": -10,
      "y": 15,
      "z": 1,
      "name": "Plant_Leaves_Maple",
      "support": 15,
      "rotation": 2
    },
    {
      "x": -10,
      "y": 16,
      "z": 1,
      "name": "Plant_Leaves_Maple",
      "support": 15,
      "rotation": 2
    },
    {
      "x": -10,
      "y": 0,
      "z": 2,
      "name": "Soil_Dirt"
    },
    {
      "x": -10,
      "y": 1,
      "z": 2,
      "name": "Soil_Dirt"
    },
    {
      "x": -10,
      "y": 2,
      "z": 2,
      "name": "Soil_Dirt"
    },
    {
      "x": -10,
      "y": 3,
      "z": 2,
      "name": "Soil_Dirt",
      "support": 15
    },
    {
      "x": -10,
      "y": 4,
      "z": 2,
      "name": "Soil_Dirt",
      "support": 15
    },
    {
      "x": -10,
      "y": 5,
      "z": 2,
      "name": "Soil_Grass_Sunny",
      "support": 15
    },
    {
      "x": -10,
      "y": 6,
      "z": 2,
      "name": "Plant_Flower_Common_Yellow2",
      "support": 15
    },
    {
      "x": -10,
      "y": 14,
      "z": 2,
      "name": "Plant_Leaves_Maple",
      "support": 15,
      "rotation": 2
    },
    {
      "x": -10,
      "y": 16,
      "z": 2,
      "name": "Plant_Leaves_Maple",
      "support": 15,
      "rotation": 2
    },
    {
      "x": -10,
      "y": 17,
      "z": 2,
      "name": "Plant_Leaves_Maple",
      "support": 15,
      "rotation": 2
    },
    {
      "x": -10,
      "y": 0,
      "z": 3,
      "name": "Soil_Dirt"
    },
    {
      "x": -10,
      "y": 2,
      "z": 3,
      "name": "Soil_Pathway",
      "support": 15
    },
    {
      "x": -10,
      "y": 3,
      "z": 3,
      "name": "Soil_Dirt",
      "support": 15
    },
    {
      "x": -10,
      "y": 4,
      "z": 3,
      "name": "Soil_Grass_Sunny",
      "support": 15
    },
    {
      "x": -10,
      "y": 19,
      "z": 3,
      "name": "Plant_Leaves_Maple",
      "support": 15,
      "rotation": 2
    },
    {
      "x": -10,
      "y": 20,
      "z": 3,
      "name": "Plant_Leaves_Maple",
      "support": 15,
      "rotation": 2
    },
    {
      "x": -10,
      "y": 0,
      "z": 4,
      "name": "Soil_Dirt"
    },
    {
      "x": -10,
      "y": 1,
      "z": 4,
      "name": "Soil_Dirt"
    },
    {
      "x": -10,
      "y": 2,
      "z": 4,
      "name": "Soil_Dirt",
      "support": 15
    },
    {
      "x": -10,
      "y": 3,
      "z": 4,
      "name": "Soil_Grass_Sunny",
      "support": 15
    },
    {
      "x": -10,
      "y": 16,
      "z": 4,
      "name": "Wood_Maple_Trunk_Full",
      "support": 15,
      "rotation": 2
    },
    {
      "x": -10,
      "y": 19,
      "z": 4,
      "name": "Plant_Leaves_Maple",
      "support": 15,
      "rotation": 2
    },
    {
      "x": -10,
      "y": 21,
      "z": 4,
      "name": "Plant_Leaves_Maple",
      "support": 15,
      "rotation": 2
    },
    {
      "x": -10,
      "y": 0,
      "z": 5,
      "name": "Soil_Dirt"
    },
    {
      "x": -10,
      "y": 2,
      "z": 5,
      "name": "Soil_Dirt",
      "support": 15
    },
    {
      "x": -10,
      "y": 3,
      "z": 5,
      "name": "Soil_Grass_Sunny",
      "support": 15
    },
    {
      "x": -10,
      "y": 4,
      "z": 5,
      "name": "Plant_Crop_Mushroom_Common_Brown",
      "components": {
        "Components": {
          "FarmingBlock": {
            "LastTickGameTime": "0001-03-23T21:15:17.691770252Z",
            "SpreadRate": 0.5
          }
        }
      },
      "support": 15
    },
    {
      "x": -10,
      "y": 19,
      "z": 5,
      "name": "Plant_Leaves_Maple",
      "support": 15,
      "rotation": 2
    },
    {
      "x": -10,
      "y": 0,
      "z": 6,
      "name": "Soil_Dirt"
    },
    {
      "x": -10,
      "y": 1,
      "z": 6,
      "name": "Soil_Dirt"
    },
    {
      "x": -10,
      "y": 2,
      "z": 6,
      "name": "Soil_Dirt",
      "support": 15
    },
    {
      "x": -10,
      "y": 3,
      "z": 6,
      "name": "Soil_Grass_Sunny",
      "support": 15
    },
    {
      "x": -10,
      "y": 18,
      "z": 6,
      "name": "Plant_Leaves_Maple",
      "support": 15,
      "rotation": 2
    },
    {
      "x": -10,
      "y": 0,
      "z": 7,
      "name": "Soil_Dirt"
    },
    {
      "x": -10,
      "y": 1,
      "z": 7,
      "name": "Soil_Dirt"
    },
    {
      "x": -10,
      "y": 2,
      "z": 7,
      "name": "Soil_Dirt",
      "support": 15
    },
    {
      "x": -10,
      "y": 3,
      "z": 7,
      "name": "Soil_Grass_Sunny",
      "support": 15
    },
    {
      "x": -10,
      "y": 4,
      "z": 7,
      "name": "Plant_Crop_Mushroom_Common_Brown",
      "components": {
        "Components": {
          "FarmingBlock": {
            "LastTickGameTime": "0001-03-23T21:12:06.143674979Z",
            "SpreadRate": 0.5
          }
        }
      },
      "support": 15
    },
    {
      "x": -10,
      "y": 17,
      "z": 7,
      "name": "Plant_Leaves_Maple",
      "support": 15,
      "rotation": 2
    },
    {
      "x": -10,
      "y": 18,
      "z": 7,
      "name": "Plant_Leaves_Maple",
      "support": 15,
      "rotation": 2
    },
    {
      "x": -10,
      "y": 0,
      "z": 8,
      "name": "Soil_Dirt"
    },
    {
      "x": -10,
      "y": 1,
      "z": 8,
      "name": "Soil_Dirt"
    },
    {
      "x": -10,
      "y": 2,
      "z": 8,
      "name": "Soil_Dirt",
      "support": 15
    },
    {
      "x": -10,
      "y": 3,
      "z": 8,
      "name": "Soil_Grass_Sunny",
      "support": 15
    },
    {
      "x": -10,
      "y": 4,
      "z": 8,
      "name": "Plant_Crop_Mushroom_Common_Brown",
      "support": 15
    },
    {
      "x": -10,
      "y": 6,
      "z": 8,
      "name": "Plant_Flower_Water_Green",
      "support": 15
    },
    {
      "x": -10,
      "y": 16,
      "z": 8,
      "name": "Wood_Maple_Branch_Long",
      "support": 15,
      "rotation": 7
    },
    {
      "x": -10,
      "y": 17,
      "z": 8,
      "name": "Plant_Leaves_Maple",
      "support": 15,
      "rotation": 2
    },
    {
      "x": -10,
      "y": 18,
      "z": 8,
      "name": "Plant_Leaves_Maple",
      "support": 15,
      "rotation": 2
    },
    {
      "x": -10,
      "y": 19,
      "z": 8,
      "name": "Plant_Leaves_Maple",
      "support": 15,
      "rotation": 2
    },
    {
      "x": -10,
      "y": 0,
      "z": 9,
      "name": "Soil_Dirt"
    },
    {
      "x": -10,
      "y": 1,
      "z": 9,
      "name": "Soil_Dirt"
    },
    {
      "x": -10,
      "y": 2,
      "z": 9,
      "name": "Soil_Pathway",
      "support": 15
    },
    {
      "x": -10,
      "y": 3,
      "z": 9,
      "name": "Soil_Dirt",
      "support": 15
    },
    {
      "x": -10,
      "y": 4,
      "z": 9,
      "name": "Soil_Grass_Sunny",
      "support": 15
    },
    {
      "x": -10,
      "y": 14,
      "z": 9,
      "name": "Plant_Leaves_Maple",
      "support": 15,
      "rotation": 2
    },
    {
      "x": -10,
      "y": 15,
      "z": 9,
      "name": "Plant_Leaves_Maple",
      "support": 15,
      "rotation": 2
    },
    {
      "x": -10,
      "y": 16,
      "z": 9,
      "name": "Plant_Leaves_Maple",
      "support": 15,
      "rotation": 2
    },
    {
      "x": -10,
      "y": 17,
      "z": 9,
      "name": "Plant_Leaves_Maple",
      "support": 15,
      "rotation": 2
    },
    {
      "x": -10,
      "y": 18,
      "z": 9,
      "name": "Plant_Leaves_Maple",
      "support": 15,
      "rotation": 2
    },
    {
      "x": -10,
      "y": 0,
      "z": 10,
      "name": "Soil_Dirt"
    },
    {
      "x": -10,
      "y": 1,
      "z": 10,
      "name": "Soil_Dirt"
    },
    {
      "x": -10,
      "y": 2,
      "z": 10,
      "name": "Soil_Dirt"
    },
    {
      "x": -10,
      "y": 3,
      "z": 10,
      "name": "Plant_Grass_Sharp_Short",
      "support": 15
    },
    {
      "x": -10,
      "y": 4,
      "z": 10,
      "name": "Soil_Dirt"
    },
    {
      "x": -10,
      "y": 5,
      "z": 10,
      "name": "Soil_Grass_Sunny",
      "support": 15
    },
    {
      "x": -10,
      "y": 6,
      "z": 10,
      "name": "Plant_Grass_Sharp_Short",
      "support": 15
    },
    {
      "x": -10,
      "y": 16,
      "z": 10,
      "name": "Plant_Leaves_Maple",
      "support": 15,
      "rotation": 2
    },
    {
      "x": -10,
      "y": 17,
      "z": 10,
      "name": "Plant_Leaves_Maple",
      "support": 15,
      "rotation": 2
    },
    {
      "x": -10,
      "y": 0,
      "z": 11,
      "name": "Soil_Dirt"
    },
    {
      "x": -10,
      "y": 1,
      "z": 11,
      "name": "Soil_Dirt"
    },
    {
      "x": -10,
      "y": 2,
      "z": 11,
      "name": "Soil_Dirt"
    },
    {
      "x": -10,
      "y": 3,
      "z": 11,
      "name": "Soil_Dirt"
    },
    {
      "x": -10,
      "y": 4,
      "z": 11,
      "name": "Soil_Dirt"
    },
    {
      "x": -10,
      "y": 5,
      "z": 11,
      "name": "Soil_Grass_Sunny",
      "support": 15
    },
    {
      "x": -10,
      "y": 6,
      "z": 11,
      "name": "Plant_Grass_Sharp_Short",
      "support": 15
    },
    {
      "x": -10,
      "y": 0,
      "z": 12,
      "name": "Soil_Dirt"
    },
    {
      "x": -10,
      "y": 1,
      "z": 12,
      "name": "Soil_Dirt"
    },
    {
      "x": -10,
      "y": 2,
      "z": 12,
      "name": "Soil_Dirt"
    },
    {
      "x": -10,
      "y": 3,
      "z": 12,
      "name": "Soil_Dirt"
    },
    {
      "x": -10,
      "y": 4,
      "z": 12,
      "name": "Soil_Dirt"
    },
    {
      "x": -10,
      "y": 5,
      "z": 12,
      "name": "Soil_Grass_Sunny",
      "support": 15
    },
    {
      "x": -10,
      "y": 6,
      "z": 12,
      "name": "Plant_Grass_Sharp",
      "support": 15
    },
    {
      "x": -10,
      "y": 0,
      "z": 13,
      "name": "Soil_Dirt"
    },
    {
      "x": -10,
      "y": 1,
      "z": 13,
      "name": "Soil_Dirt"
    },
    {
      "x": -10,
      "y": 2,
      "z": 13,
      "name": "Soil_Dirt"
    },
    {
      "x": -10,
      "y": 3,
      "z": 13,
      "name": "Soil_Dirt"
    },
    {
      "x": -10,
      "y": 4,
      "z": 13,
      "name": "Soil_Dirt"
    },
    {
      "x": -10,
      "y": 5,
      "z": 13,
      "name": "Soil_Grass_Sunny",
      "support": 15
    },
    {
      "x": -10,
      "y": 6,
      "z": 13,
      "name": "Plant_Grass_Sharp_Short",
      "support": 15
    },
    {
      "x": -10,
      "y": 0,
      "z": 14,
      "name": "Soil_Dirt"
    },
    {
      "x": -10,
      "y": 1,
      "z": 14,
      "name": "Soil_Dirt"
    },
    {
      "x": -10,
      "y": 2,
      "z": 14,
      "name": "Soil_Dirt"
    },
    {
      "x": -10,
      "y": 3,
      "z": 14,
      "name": "Soil_Dirt"
    },
    {
      "x": -10,
      "y": 4,
      "z": 14,
      "name": "Soil_Dirt"
    },
    {
      "x": -10,
      "y": 5,
      "z": 14,
      "name": "Soil_Grass_Sunny",
      "support": 15
    },
    {
      "x": -10,
      "y": 6,
      "z": 14,
      "name": "Plant_Grass_Sharp_Short",
      "support": 15
    },
    {
      "x": -10,
      "y": 0,
      "z": 15,
      "name": "Soil_Dirt"
    },
    {
      "x": -10,
      "y": 1,
      "z": 15,
      "name": "Soil_Dirt"
    },
    {
      "x": -10,
      "y": 2,
      "z": 15,
      "name": "Soil_Dirt"
    },
    {
      "x": -10,
      "y": 3,
      "z": 15,
      "name": "Soil_Dirt"
    },
    {
      "x": -10,
      "y": 4,
      "z": 15,
      "name": "Soil_Dirt"
    },
    {
      "x": -10,
      "y": 5,
      "z": 15,
      "name": "Rock_Stone_Brick_Smooth"
    },
    {
      "x": -9,
      "y": 0,
      "z": -14,
      "name": "Soil_Dirt"
    },
    {
      "x": -9,
      "y": 1,
      "z": -14,
      "name": "Soil_Dirt"
    },
    {
      "x": -9,
      "y": 2,
      "z": -14,
      "name": "Soil_Dirt"
    },
    {
      "x": -9,
      "y": 3,
      "z": -14,
      "name": "Soil_Dirt"
    },
    {
      "x": -9,
      "y": 4,
      "z": -14,
      "name": "Soil_Dirt"
    },
    {
      "x": -9,
      "y": 5,
      "z": -14,
      "name": "Rock_Stone_Brick_Smooth"
    },
    {
      "x": -9,
      "y": 0,
      "z": -13,
      "name": "Soil_Dirt"
    },
    {
      "x": -9,
      "y": 1,
      "z": -13,
      "name": "Soil_Dirt"
    },
    {
      "x": -9,
      "y": 2,
      "z": -13,
      "name": "Soil_Dirt"
    },
    {
      "x": -9,
      "y": 3,
      "z": -13,
      "name": "Soil_Dirt"
    },
    {
      "x": -9,
      "y": 4,
      "z": -13,
      "name": "Soil_Dirt"
    },
    {
      "x": -9,
      "y": 5,
      "z": -13,
      "name": "Soil_Grass_Sunny",
      "support": 15
    },
    {
      "x": -9,
      "y": 0,
      "z": -12,
      "name": "Soil_Dirt"
    },
    {
      "x": -9,
      "y": 1,
      "z": -12,
      "name": "Soil_Dirt"
    },
    {
      "x": -9,
      "y": 2,
      "z": -12,
      "name": "Soil_Dirt"
    },
    {
      "x": -9,
      "y": 3,
      "z": -12,
      "name": "Soil_Dirt"
    },
    {
      "x": -9,
      "y": 4,
      "z": -12,
      "name": "Soil_Dirt"
    },
    {
      "x": -9,
      "y": 5,
      "z": -12,
      "name": "Soil_Pathway"
    },
    {
      "x": -9,
      "y": 6,
      "z": -12,
      "name": "Wood_Hardwood_Decorative"
    },
    {
      "x": -9,
      "y": 7,
      "z": -12,
      "name": "Wood_Hardwood_Planks"
    },
    {
      "x": -9,
      "y": 8,
      "z": -12,
      "name": "Wood_Hardwood_Planks"
    },
    {
      "x": -9,
      "y": 9,
      "z": -12,
      "name": "Wood_Hardwood_Planks"
    },
    {
      "x": -9,
      "y": 10,
      "z": -12,
      "name": "Wood_Hardwood_Planks"
    },
    {
      "x": -9,
      "y": 0,
      "z": -11,
      "name": "Soil_Dirt"
    },
    {
      "x": -9,
      "y": 1,
      "z": -11,
      "name": "Soil_Dirt"
    },
    {
      "x": -9,
      "y": 2,
      "z": -11,
      "name": "Soil_Dirt"
    },
    {
      "x": -9,
      "y": 3,
      "z": -11,
      "name": "Soil_Dirt"
    },
    {
      "x": -9,
      "y": 4,
      "z": -11,
      "name": "Soil_Dirt"
    },
    {
      "x": -9,
      "y": 5,
      "z": -11,
      "name": "Soil_Dirt"
    },
    {
      "x": -9,
      "y": 6,
      "z": -11,
      "name": "Wood_Hardwood_Decorative"
    },
    {
      "x": -9,
      "y": 7,
      "z": -11,
      "name": "Wood_Hardwood_Planks"
    },
    {
      "x": -9,
      "y": 8,
      "z": -11,
      "name": "Wood_Hardwood_Decorative"
    },
    {
      "x": -9,
      "y": 11,
      "z": -11,
      "name": "Cloth_Modern_Orange_Roof_Flat"
    },
    {
      "x": -9,
      "y": 0,
      "z": -10,
      "name": "Soil_Dirt"
    },
    {
      "x": -9,
      "y": 1,
      "z": -10,
      "name": "Soil_Dirt"
    },
    {
      "x": -9,
      "y": 2,
      "z": -10,
      "name": "Soil_Dirt"
    },
    {
      "x": -9,
      "y": 3,
      "z": -10,
      "name": "Soil_Dirt"
    },
    {
      "x": -9,
      "y": 4,
      "z": -10,
      "name": "Soil_Dirt"
    },
    {
      "x": -9,
      "y": 5,
      "z": -10,
      "name": "Soil_Pathway"
    },
    {
      "x": -9,
      "y": 6,
      "z": -10,
      "name": "Wood_Hardwood_Decorative"
    },
    {
      "x": -9,
      "y": 7,
      "z": -10,
      "name": "Wood_Hardwood_Decorative"
    },
    {
      "x": -9,
      "y": 11,
      "z": -10,
      "name": "Cloth_Modern_Orange_Roof_Flat"
    },
    {
      "x": -9,
      "y": 0,
      "z": -9,
      "name": "Soil_Dirt"
    },
    {
      "x": -9,
      "y": 1,
      "z": -9,
      "name": "Soil_Dirt"
    },
    {
      "x": -9,
      "y": 2,
      "z": -9,
      "name": "Soil_Dirt"
    },
    {
      "x": -9,
      "y": 3,
      "z": -9,
      "name": "Soil_Dirt"
    },
    {
      "x": -9,
      "y": 4,
      "z": -9,
      "name": "Soil_Dirt"
    },
    {
      "x": -9,
      "y": 5,
      "z": -9,
      "name": "Soil_Pathway"
    },
    {
      "x": -9,
