{
  "version": 8,
  "blockIdVersion": 11,
  "anchorX": 0,
  "anchorY": 0,
  "anchorZ": 0,
  "blocks": [
    {
      "x": 1,
      "y": 1,
      "z": -29,
      "name": "Editor_Empty"
    },
    {
      "x": 1,
      "y": 2,
      "z": -29,
      "name": "Editor_Empty"
    },
    {
      "x": 1,
      "y": 3,
      "z": -29,
      "name": "Editor_Empty"
    },
    {
      "x": 1,
      "y": 4,
      "z": -29,
      "name": "Editor_Empty"
    },
    {
      "x": 1,
      "y": 5,
      "z": -29,
      "name": "Editor_Empty"
    },
    {
      "x": 1,
      "y": 6,
      "z": -29,
      "name": "Editor_Empty"
    },
    {
      "x": 1,
      "y": 7,
      "z": -29,
      "name": "Editor_Empty"
    },
    {
      "x": 1,
      "y": 8,
      "z": -29,
      "name": "Editor_Empty"
    },
    {
      "x": 1,
      "y": 9,
      "z": -29,
      "name": "Editor_Empty"
    },
    {
      "x": 1,
      "y": 10,
      "z": -29,
      "name": "Editor_Empty"
    },
    {
      "x": 1,
      "y": 11,
      "z": -29,
      "name": "Editor_Empty"
    },
    {
      "x": 1,
      "y": 12,
      "z": -29,
      "name": "Editor_Empty"
    },
    {
      "x": 1,
      "y": 1,
      "z": -28,
      "name": "Editor_Empty"
    },
    {
      "x": 1,
      "y": 2,
      "z": -28,
      "name": "Editor_Empty"
    },
    {
      "x": 1,
      "y": 3,
      "z": -28,
      "name": "Editor_Empty"
    },
    {
      "x": 1,
      "y": 4,
      "z": -28,
      "name": "Editor_Empty"
    },
    {
      "x": 1,
      "y": 5,
      "z": -28,
      "name": "Editor_Empty"
    },
    {
      "x": 1,
      "y": 6,
      "z": -28,
      "name": "Editor_Empty"
    },
    {
      "x": 1,
      "y": 7,
      "z": -28,
      "name": "Editor_Empty"
    },
    {
      "x": 1,
      "y": 8,
      "z": -28,
      "name": "Editor_Empty"
    },
    {
      "x": 1,
      "y": 9,
      "z": -28,
      "name": "Editor_Empty"
    },
    {
      "x": 1,
      "y": 10,
      "z": -28,
      "name": "Editor_Empty"
    },
    {
      "x": 1,
      "y": 11,
      "z": -28,
      "name": "Editor_Empty"
    },
    {
      "x": 1,
      "y": 12,
      "z": -28,
      "name": "Editor_Empty"
    },
    {
      "x": 1,
      "y": 1,
      "z": -27,
      "name": "Editor_Empty"
    },
    {
      "x": 1,
      "y": 2,
      "z": -27,
      "name": "Editor_Empty"
    },
    {
      "x": 1,
      "y": 3,
      "z": -27,
      "name": "Editor_Empty"
    },
    {
      "x": 1,
      "y": 4,
      "z": -27,
      "name": "Editor_Empty"
    },
    {
      "x": 1,
      "y": 5,
      "z": -27,
      "name": "Editor_Empty"
    },
    {
      "x": 1,
      "y": 6,
      "z": -27,
      "name": "Editor_Empty"
    },
    {
      "x": 1,
      "y": 7,
      "z": -27,
      "name": "Editor_Empty"
    },
    {
      "x": 1,
      "y": 8,
      "z": -27,
      "name": "Editor_Empty"
    },
    {
      "x": 1,
      "y": 9,
      "z": -27,
      "name": "Editor_Empty"
    },
    {
      "x": 1,
      "y": 10,
      "z": -27,
      "name": "Editor_Empty"
    },
    {
      "x": 1,
      "y": 11,
      "z": -27,
      "name": "Editor_Empty"
    },
    {
      "x": 1,
      "y": 12,
      "z": -27,
      "name": "Editor_Empty"
    },
    {
      "x": 1,
      "y": 1,
      "z": -26,
      "name": "Editor_Empty"
    },
    {
      "x": 1,
      "y": 2,
      "z": -26,
      "name": "Editor_Empty"
    },
    {
      "x": 1,
      "y": 3,
      "z": -26,
      "name": "Editor_Empty"
    },
    {
      "x": 1,
      "y": 4,
      "z": -26,
      "name": "Editor_Empty"
    },
    {
      "x": 1,
      "y": 5,
      "z": -26,
      "name": "Editor_Empty"
    },
    {
      "x": 1,
      "y": 6,
      "z": -26,
      "name": "Editor_Empty"
    },
    {
      "x": 1,
      "y": 7,
      "z": -26,
      "name": "Editor_Empty"
    },
    {
      "x": 1,
      "y": 8,
      "z": -26,
      "name": "Editor_Empty"
    },
    {
      "x": 1,
      "y": 9,
      "z": -26,
      "name": "Editor_Empty"
    },
    {
      "x": 1,
      "y": 10,
      "z": -26,
      "name": "Editor_Empty"
    },
    {
      "x": 1,
      "y": 11,
      "z": -26,
      "name": "Editor_Empty"
    },
    {
      "x": 1,
      "y": 12,
      "z": -26,
      "name": "Editor_Empty"
    },
    {
      "x": 1,
      "y": 1,
      "z": -25,
      "name": "Editor_Empty"
    },
    {
      "x": 1,
      "y": 2,
      "z": -25,
      "name": "Editor_Empty"
    },
    {
      "x": 1,
      "y": 3,
      "z": -25,
      "name": "Editor_Empty"
    },
    {
      "x": 1,
      "y": 4,
      "z": -25,
      "name": "Editor_Empty"
    },
    {
      "x": 1,
      "y": 5,
      "z": -25,
      "name": "Editor_Empty"
    },
    {
      "x": 1,
      "y": 6,
      "z": -25,
      "name": "Editor_Empty"
    },
    {
      "x": 1,
      "y": 7,
      "z": -25,
      "name": "Editor_Empty"
    },
    {
      "x": 1,
      "y": 8,
      "z": -25,
      "name": "Editor_Empty"
    },
    {
      "x": 1,
      "y": 9,
      "z": -25,
      "name": "Editor_Empty"
    },
    {
      "x": 1,
      "y": 10,
      "z": -25,
      "name": "Editor_Empty"
    },
    {
      "x": 1,
      "y": 11,
      "z": -25,
      "name": "Editor_Empty"
    },
    {
      "x": 1,
      "y": 12,
      "z": -25,
      "name": "Editor_Empty"
    },
    {
      "x": 1,
      "y": 1,
      "z": -24,
      "name": "Editor_Empty"
    },
    {
      "x": 1,
      "y": 2,
      "z": -24,
      "name": "Editor_Empty"
    },
    {
      "x": 1,
      "y": 3,
      "z": -24,
      "name": "Editor_Empty"
    },
    {
      "x": 1,
      "y": 4,
      "z": -24,
      "name": "Editor_Empty"
    },
    {
      "x": 1,
      "y": 5,
      "z": -24,
      "name": "Editor_Empty"
    },
    {
      "x": 1,
      "y": 6,
      "z": -24,
      "name": "Editor_Empty"
    },
    {
      "x": 1,
      "y": 7,
      "z": -24,
      "name": "Editor_Empty"
    },
    {
      "x": 1,
      "y": 8,
      "z": -24,
      "name": "Editor_Empty"
    },
    {
      "x": 1,
      "y": 9,
      "z": -24,
      "name": "Editor_Empty"
    },
    {
      "x": 1,
      "y": 10,
      "z": -24,
      "name": "Editor_Empty"
    },
    {
      "x": 1,
      "y": 11,
      "z": -24,
      "name": "Editor_Empty"
    },
    {
      "x": 1,
      "y": 12,
      "z": -24,
      "name": "Editor_Empty"
    },
    {
      "x": 1,
      "y": 1,
      "z": -23,
      "name": "Editor_Empty"
    },
    {
      "x": 1,
      "y": 2,
      "z": -23,
      "name": "Editor_Empty"
    },
    {
      "x": 1,
      "y": 3,
      "z": -23,
      "name": "Editor_Empty"
    },
    {
      "x": 1,
      "y": 4,
      "z": -23,
      "name": "Editor_Empty"
    },
    {
      "x": 1,
      "y": 5,
      "z": -23,
      "name": "Editor_Empty"
    },
    {
      "x": 1,
      "y": 6,
      "z": -23,
      "name": "Editor_Empty"
    },
    {
      "x": 1,
      "y": 7,
      "z": -23,
      "name": "Editor_Empty"
    },
    {
      "x": 1,
      "y": 8,
      "z": -23,
      "name": "Editor_Empty"
    },
    {
      "x": 1,
      "y": 9,
      "z": -23,
      "name": "Editor_Empty"
    },
    {
      "x": 1,
      "y": 10,
      "z": -23,
      "name": "Editor_Empty"
    },
    {
      "x": 1,
      "y": 11,
      "z": -23,
      "name": "Editor_Empty"
    },
    {
      "x": 1,
      "y": 12,
      "z": -23,
      "name": "Editor_Empty"
    },
    {
      "x": 1,
      "y": 1,
      "z": -22,
      "name": "Editor_Empty"
    },
    {
      "x": 1,
      "y": 2,
      "z": -22,
      "name": "Editor_Empty"
    },
    {
      "x": 1,
      "y": 3,
      "z": -22,
      "name": "Editor_Empty"
    },
    {
      "x": 1,
      "y": 4,
      "z": -22,
      "name": "Editor_Empty"
    },
    {
      "x": 1,
      "y": 5,
      "z": -22,
      "name": "Editor_Empty"
    },
    {
      "x": 1,
      "y": 6,
      "z": -22,
      "name": "Editor_Empty"
    },
    {
      "x": 1,
      "y": 7,
      "z": -22,
      "name": "Editor_Empty"
    },
    {
      "x": 1,
      "y": 8,
      "z": -22,
      "name": "Editor_Empty"
    },
    {
      "x": 1,
      "y": 9,
      "z": -22,
      "name": "Editor_Empty"
    },
    {
      "x": 1,
      "y": 10,
      "z": -22,
      "name": "Editor_Empty"
    },
    {
      "x": 1,
      "y": 11,
      "z": -22,
      "name": "Editor_Empty"
    },
    {
      "x": 1,
      "y": 12,
      "z": -22,
      "name": "Editor_Empty"
    },
    {
      "x": 1,
      "y": 1,
      "z": -21,
      "name": "Editor_Empty"
    },
    {
      "x": 1,
      "y": 2,
      "z": -21,
      "name": "Editor_Empty"
    },
    {
      "x": 1,
      "y": 3,
      "z": -21,
      "name": "Editor_Empty"
    },
    {
      "x": 1,
      "y": 4,
      "z": -21,
      "name": "Editor_Empty"
    },
    {
      "x": 1,
      "y": 5,
      "z": -21,
      "name": "Editor_Empty"
    },
    {
      "x": 1,
      "y": 6,
      "z": -21,
      "name": "Editor_Empty"
    },
    {
      "x": 1,
      "y": 7,
      "z": -21,
      "name": "Editor_Empty"
    },
    {
      "x": 1,
      "y": 8,
      "z": -21,
      "name": "Editor_Empty"
    },
    {
      "x": 1,
      "y": 9,
      "z": -21,
      "name": "Editor_Empty"
    },
    {
      "x": 1,
      "y": 10,
      "z": -21,
      "name": "Editor_Empty"
    },
    {
      "x": 1,
      "y": 11,
      "z": -21,
      "name": "Editor_Empty"
    },
    {
      "x": 1,
      "y": 12,
      "z": -21,
      "name": "Editor_Empty"
    },
    {
      "x": 1,
      "y": 1,
      "z": -20,
      "name": "Editor_Empty"
    },
    {
      "x": 1,
      "y": 2,
      "z": -20,
      "name": "Editor_Empty"
    },
    {
      "x": 1,
      "y": 3,
      "z": -20,
      "name": "Editor_Empty"
    },
    {
      "x": 1,
      "y": 4,
      "z": -20,
      "name": "Editor_Empty"
    },
    {
      "x": 1,
      "y": 5,
      "z": -20,
      "name": "Editor_Empty"
    },
    {
      "x": 1,
      "y": 6,
      "z": -20,
      "name": "Editor_Empty"
    },
    {
      "x": 1,
      "y": 7,
      "z": -20,
      "name": "Editor_Empty"
    },
    {
      "x": 1,
      "y": 8,
      "z": -20,
      "name": "Editor_Empty"
    },
    {
      "x": 1,
      "y": 9,
      "z": -20,
      "name": "Editor_Empty"
    },
    {
      "x": 1,
      "y": 10,
      "z": -20,
      "name": "Editor_Empty"
    },
    {
      "x": 1,
      "y": 11,
      "z": -20,
      "name": "Editor_Empty"
    },
    {
      "x": 1,
      "y": 12,
      "z": -20,
      "name": "Editor_Empty"
    },
    {
      "x": 1,
      "y": 1,
      "z": -19,
      "name": "Editor_Empty"
    },
    {
      "x": 1,
      "y": 2,
      "z": -19,
      "name": "Editor_Empty"
    },
    {
      "x": 1,
      "y": 3,
      "z": -19,
      "name": "Editor_Empty"
    },
    {
      "x": 1,
      "y": 4,
      "z": -19,
      "name": "Editor_Empty"
    },
    {
      "x": 1,
      "y": 5,
      "z": -19,
      "name": "Editor_Empty"
    },
    {
      "x": 1,
      "y": 6,
      "z": -19,
      "name": "Editor_Empty"
    },
    {
      "x": 1,
      "y": 7,
      "z": -19,
      "name": "Editor_Empty"
    },
    {
      "x": 1,
      "y": 8,
      "z": -19,
      "name": "Editor_Empty"
    },
    {
      "x": 1,
      "y": 9,
      "z": -19,
      "name": "Editor_Empty"
    },
    {
      "x": 1,
      "y": 10,
      "z": -19,
      "name": "Editor_Empty"
    },
    {
      "x": 1,
      "y": 11,
      "z": -19,
      "name": "Editor_Empty"
    },
    {
      "x": 1,
      "y": 12,
      "z": -19,
      "name": "Editor_Empty"
    },
    {
      "x": 1,
      "y": 0,
      "z": -18,
      "name": "Rock_Stone_Cobble_Mossy"
    },
    {
      "x": 1,
      "y": 1,
      "z": -18,
      "name": "Rock_Stone_Cobble"
    },
    {
      "x": 1,
      "y": 2,
      "z": -18,
      "name": "Rock_Stone"
    },
    {
      "x": 1,
      "y": 3,
      "z": -18,
      "name": "Rock_Stone"
    },
    {
      "x": 1,
      "y": 4,
      "z": -18,
      "name": "Editor_Empty"
    },
    {
      "x": 1,
      "y": 5,
      "z": -18,
      "name": "Editor_Empty"
    },
    {
      "x": 1,
      "y": 6,
      "z": -18,
      "name": "Editor_Empty"
    },
    {
      "x": 1,
      "y": 7,
      "z": -18,
      "name": "Editor_Empty"
    },
    {
      "x": 1,
      "y": 8,
      "z": -18,
      "name": "Editor_Empty"
    },
    {
      "x": 1,
      "y": 9,
      "z": -18,
      "name": "Editor_Empty"
    },
    {
      "x": 1,
      "y": 10,
      "z": -18,
      "name": "Editor_Empty"
    },
    {
      "x": 1,
      "y": 11,
      "z": -18,
      "name": "Editor_Empty"
    },
    {
      "x": 1,
      "y": 12,
      "z": -18,
      "name": "Editor_Empty"
    },
    {
      "x": 1,
      "y": 0,
      "z": -17,
      "name": "Rock_Stone_Cobble"
    },
    {
      "x": 1,
      "y": 1,
      "z": -17,
      "name": "Rock_Stone"
    },
    {
      "x": 1,
      "y": 2,
      "z": -17,
      "name": "Rock_Stone_Cobble"
    },
    {
      "x": 1,
      "y": 3,
      "z": -17,
      "name": "Rock_Stone_Cobble_Mossy"
    },
    {
      "x": 1,
      "y": 4,
      "z": -17,
      "name": "Editor_Empty"
    },
    {
      "x": 1,
      "y": 5,
      "z": -17,
      "name": "Editor_Empty"
    },
    {
      "x": 1,
      "y": 6,
      "z": -17,
      "name": "Editor_Empty"
    },
    {
      "x": 1,
      "y": 7,
      "z": -17,
      "name": "Editor_Empty"
    },
    {
      "x": 1,
      "y": 8,
      "z": -17,
      "name": "Editor_Empty"
    },
    {
      "x": 1,
      "y": 9,
      "z": -17,
      "name": "Editor_Empty"
    },
    {
      "x": 1,
      "y": 10,
      "z": -17,
      "name": "Editor_Empty"
    },
    {
      "x": 1,
      "y": 11,
      "z": -17,
      "name": "Editor_Empty"
    },
    {
      "x": 1,
      "y": 12,
      "z": -17,
      "name": "Editor_Empty"
    },
    {
      "x": 1,
      "y": 0,
      "z": -16,
      "name": "Rock_Stone"
    },
    {
      "x": 1,
      "y": 1,
      "z": -16,
      "name": "Rock_Stone_Cobble_Mossy"
    },
    {
      "x": 1,
      "y": 2,
      "z": -16,
      "name": "Rock_Stone"
    },
    {
      "x": 1,
      "y": 3,
      "z": -16,
      "name": "Rock_Stone"
    },
    {
      "x": 1,
      "y": 4,
      "z": -16,
      "name": "Editor_Empty"
    },
    {
      "x": 1,
      "y": 5,
      "z": -16,
      "name": "Editor_Empty"
    },
    {
      "x": 1,
      "y": 6,
      "z": -16,
      "name": "Editor_Empty"
    },
    {
      "x": 1,
      "y": 7,
      "z": -16,
      "name": "Editor_Empty"
    },
    {
      "x": 1,
      "y": 8,
      "z": -16,
      "name": "Editor_Empty"
    },
    {
      "x": 1,
      "y": 9,
      "z": -16,
      "name": "Editor_Empty"
    },
    {
      "x": 1,
      "y": 10,
      "z": -16,
      "name": "Editor_Empty"
    },
    {
      "x": 1,
      "y": 11,
      "z": -16,
      "name": "Editor_Empty"
    },
    {
      "x": 1,
      "y": 12,
      "z": -16,
      "name": "Editor_Empty"
    },
    {
      "x": 1,
      "y": 0,
      "z": -15,
      "name": "Rock_Stone"
    },
    {
      "x": 1,
      "y": 1,
      "z": -15,
      "name": "Rock_Stone_Cobble"
    },
    {
      "x": 1,
      "y": 2,
      "z": -15,
      "name": "Rock_Stone"
    },
    {
      "x": 1,
      "y": 3,
      "z": -15,
      "name": "Rock_Stone"
    },
    {
      "x": 1,
      "y": 4,
      "z": -15,
      "name": "Editor_Empty"
    },
    {
      "x": 1,
      "y": 5,
      "z": -15,
      "name": "Editor_Empty"
    },
    {
      "x": 1,
      "y": 6,
      "z": -15,
      "name": "Editor_Empty"
    },
    {
      "x": 1,
      "y": 7,
      "z": -15,
      "name": "Editor_Empty"
    },
    {
      "x": 1,
      "y": 8,
      "z": -15,
      "name": "Editor_Empty"
    },
    {
      "x": 1,
      "y": 9,
      "z": -15,
      "name": "Editor_Empty"
    },
    {
      "x": 1,
      "y": 10,
      "z": -15,
      "name": "Editor_Empty"
    },
    {
      "x": 1,
      "y": 11,
      "z": -15,
      "name": "Editor_Empty"
    },
    {
      "x": 1,
      "y": 12,
      "z": -15,
      "name": "Editor_Empty"
    },
    {
      "x": 1,
      "y": 1,
      "z": -14,
      "name": "Editor_Empty"
    },
    {
      "x": 1,
      "y": 2,
      "z": -14,
      "name": "Editor_Empty"
    },
    {
      "x": 1,
      "y": 3,
      "z": -14,
      "name": "Editor_Empty"
    },
    {
      "x": 1,
      "y": 4,
      "z": -14,
      "name": "Editor_Empty"
    },
    {
      "x": 1,
      "y": 5,
      "z": -14,
      "name": "Editor_Empty"
    },
    {
      "x": 1,
      "y": 6,
      "z": -14,
      "name": "Editor_Empty"
    },
    {
      "x": 1,
      "y": 7,
      "z": -14,
      "name": "Editor_Empty"
    },
    {
      "x": 1,
      "y": 8,
      "z": -14,
      "name": "Editor_Empty"
    },
    {
      "x": 1,
      "y": 9,
      "z": -14,
      "name": "Editor_Empty"
    },
    {
      "x": 1,
      "y": 10,
      "z": -14,
      "name": "Editor_Empty"
    },
    {
      "x": 1,
      "y": 11,
      "z": -14,
      "name": "Editor_Empty"
    },
    {
      "x": 1,
      "y": 12,
      "z": -14,
      "name": "Editor_Empty"
    },
    {
      "x": 1,
      "y": 1,
      "z": -13,
      "name": "Editor_Empty"
    },
    {
      "x": 1,
      "y": 2,
      "z": -13,
      "name": "Editor_Empty"
    },
    {
      "x": 1,
      "y": 3,
      "z": -13,
      "name": "Editor_Empty"
    },
    {
      "x": 1,
      "y": 4,
      "z": -13,
      "name": "Editor_Empty"
    },
    {
      "x": 1,
      "y": 5,
      "z": -13,
      "name": "Editor_Empty"
    },
    {
      "x": 1,
      "y": 6,
      "z": -13,
      "name": "Editor_Empty"
    },
    {
      "x": 1,
      "y": 7,
      "z": -13,
      "name": "Editor_Empty"
    },
    {
      "x": 1,
      "y": 8,
      "z": -13,
      "name": "Editor_Empty"
    },
    {
      "x": 1,
      "y": 9,
      "z": -13,
      "name": "Editor_Empty"
    },
    {
      "x": 1,
      "y": 10,
      "z": -13,
      "name": "Editor_Empty"
    },
    {
      "x": 1,
      "y": 11,
      "z": -13,
      "name": "Editor_Empty"
    },
    {
      "x": 1,
      "y": 12,
      "z": -13,
      "name": "Editor_Empty"
    },
    {
      "x": 1,
      "y": 1,
      "z": -12,
      "name": "Editor_Empty"
    },
    {
      "x": 1,
      "y": 2,
      "z": -12,
      "name": "Editor_Empty"
    },
    {
      "x": 1,
      "y": 3,
      "z": -12,
      "name": "Editor_Empty"
    },
    {
      "x": 1,
      "y": 4,
      "z": -12,
      "name": "Editor_Empty"
    },
    {
      "x": 1,
      "y": 5,
      "z": -12,
      "name": "Editor_Empty"
    },
    {
      "x": 1,
      "y": 6,
      "z": -12,
      "name": "Editor_Empty"
    },
    {
      "x": 1,
      "y": 7,
      "z": -12,
      "name": "Editor_Empty"
    },
    {
      "x": 1,
      "y": 8,
      "z": -12,
      "name": "Editor_Empty"
    },
    {
      "x": 1,
      "y": 9,
      "z": -12,
      "name": "Editor_Empty"
    },
    {
      "x": 1,
      "y": 10,
      "z": -12,
      "name": "Editor_Empty"
    },
    {
      "x": 1,
      "y": 11,
      "z": -12,
      "name": "Editor_Empty"
    },
    {
      "x": 1,
      "y": 12,
      "z": -12,
      "name": "Editor_Empty"
    },
    {
      "x": 1,
      "y": 1,
      "z": -11,
      "name": "Editor_Empty"
    },
    {
      "x": 1,
      "y": 2,
      "z": -11,
      "name": "Editor_Empty"
    },
    {
      "x": 1,
      "y": 3,
      "z": -11,
      "name": "Editor_Empty"
    },
    {
      "x": 1,
      "y": 4,
      "z": -11,
      "name": "Editor_Empty"
    },
    {
      "x": 1,
      "y": 5,
      "z": -11,
      "name": "Editor_Empty"
    },
    {
      "x": 1,
      "y": 6,
      "z": -11,
      "name": "Editor_Empty"
    },
    {
      "x": 1,
      "y": 7,
      "z": -11,
      "name": "Editor_Empty"
    },
    {
      "x": 1,
      "y": 8,
      "z": -11,
      "name": "Editor_Empty"
    },
    {
      "x": 1,
      "y": 9,
      "z": -11,
      "name": "Editor_Empty"
    },
    {
      "x": 1,
      "y": 10,
      "z": -11,
      "name": "Editor_Empty"
    },
    {
      "x": 1,
      "y": 11,
      "z": -11,
      "name": "Editor_Empty"
    },
    {
      "x": 1,
      "y": 12,
      "z": -11,
      "name": "Editor_Empty"
    },
    {
      "x": 1,
      "y": 1,
      "z": -10,
      "name": "Editor_Empty"
    },
    {
      "x": 1,
      "y": 2,
      "z": -10,
      "name": "Editor_Empty"
    },
    {
      "x": 1,
      "y": 3,
      "z": -10,
      "name": "Editor_Empty"
    },
    {
      "x": 1,
      "y": 4,
      "z": -10,
      "name": "Editor_Empty"
    },
    {
      "x": 1,
      "y": 5,
      "z": -10,
      "name": "Editor_Empty"
    },
    {
      "x": 1,
      "y": 6,
      "z": -10,
      "name": "Editor_Empty"
    },
    {
      "x": 1,
      "y": 7,
      "z": -10,
      "name": "Editor_Empty"
    },
    {
      "x": 1,
      "y": 8,
      "z": -10,
      "name": "Editor_Empty"
    },
    {
      "x": 1,
      "y": 9,
      "z": -10,
      "name": "Editor_Empty"
    },
    {
      "x": 1,
      "y": 10,
      "z": -10,
      "name": "Editor_Empty"
    },
    {
      "x": 1,
      "y": 11,
      "z": -10,
      "name": "Editor_Empty"
    },
    {
      "x": 1,
      "y": 12,
      "z": -10,
      "name": "Editor_Empty"
    },
    {
      "x": 1,
      "y": 1,
      "z": -9,
      "name": "Editor_Empty"
    },
    {
      "x": 1,
      "y": 2,
      "z": -9,
      "name": "Editor_Empty"
    },
    {
      "x": 1,
      "y": 3,
      "z": -9,
      "name": "Editor_Empty"
    },
    {
      "x": 1,
      "y": 4,
      "z": -9,
      "name": "Editor_Empty"
    },
    {
      "x": 1,
      "y": 5,
      "z": -9,
      "name": "Editor_Empty"
    },
    {
      "x": 1,
      "y": 6,
      "z": -9,
      "name": "Editor_Empty"
    },
    {
      "x": 1,
      "y": 7,
      "z": -9,
      "name": "Editor_Empty"
    },
    {
      "x": 1,
      "y": 8,
      "z": -9,
      "name": "Editor_Empty"
    },
    {
      "x": 1,
      "y": 9,
      "z": -9,
      "name": "Editor_Empty"
    },
    {
      "x": 1,
      "y": 10,
      "z": -9,
      "name": "Editor_Empty"
    },
    {
      "x": 1,
      "y": 11,
      "z": -9,
      "name": "Editor_Empty"
    },
    {
      "x": 1,
      "y": 12,
      "z": -9,
      "name": "Editor_Empty"
    },
    {
      "x": 1,
      "y": 1,
      "z": -8,
      "name": "Editor_Empty"
    },
    {
      "x": 1,
      "y": 2,
      "z": -8,
      "name": "Editor_Empty"
    },
    {
      "x": 1,
      "y": 3,
      "z": -8,
      "name": "Editor_Empty"
    },
    {
      "x": 1,
      "y": 4,
      "z": -8,
      "name": "Editor_Empty"
    },
    {
      "x": 1,
      "y": 5,
      "z": -8,
      "name": "Editor_Empty"
    },
    {
      "x": 1,
      "y": 6,
      "z": -8,
      "name": "Editor_Empty"
    },
    {
      "x": 1,
      "y": 7,
      "z": -8,
      "name": "Editor_Empty"
    },
    {
      "x": 1,
      "y": 8,
      "z": -8,
      "name": "Editor_Empty"
    },
    {
      "x": 1,
      "y": 9,
      "z": -8,
      "name": "Editor_Empty"
    },
    {
      "x": 1,
      "y": 10,
      "z": -8,
      "name": "Editor_Empty"
    },
    {
      "x": 1,
      "y": 11,
      "z": -8,
      "name": "Editor_Empty"
    },
    {
      "x": 1,
      "y": 12,
      "z": -8,
      "name": "Editor_Empty"
    },
    {
      "x": 1,
      "y": 1,
      "z": -7,
      "name": "Editor_Empty"
    },
    {
      "x": 1,
      "y": 2,
      "z": -7,
      "name": "Editor_Empty"
    },
    {
      "x": 1,
      "y": 3,
      "z": -7,
      "name": "Editor_Empty"
    },
    {
      "x": 1,
      "y": 4,
      "z": -7,
      "name": "Editor_Empty"
    },
    {
      "x": 1,
      "y": 5,
      "z": -7,
      "name": "Editor_Empty"
    },
    {
      "x": 1,
      "y": 6,
      "z": -7,
      "name": "Editor_Empty"
    },
    {
      "x": 1,
      "y": 7,
      "z": -7,
      "name": "Editor_Empty"
    },
    {
      "x": 1,
      "y": 8,
      "z": -7,
      "name": "Editor_Empty"
    },
    {
      "x": 1,
      "y": 9,
      "z": -7,
      "name": "Editor_Empty"
    },
    {
      "x": 1,
      "y": 10,
      "z": -7,
      "name": "Editor_Empty"
    },
    {
      "x": 1,
      "y": 11,
      "z": -7,
      "name": "Editor_Empty"
    },
    {
      "x": 1,
      "y": 12,
      "z": -7,
      "name": "Editor_Empty"
    },
    {
      "x": 1,
      "y": 1,
      "z": -6,
      "name": "Editor_Empty"
    },
    {
      "x": 1,
      "y": 2,
      "z": -6,
      "name": "Editor_Empty"
    },
    {
      "x": 1,
      "y": 3,
      "z": -6,
      "name": "Editor_Empty"
    },
    {
      "x": 1,
      "y": 4,
      "z": -6,
      "name": "Editor_Empty"
    },
    {
      "x": 1,
      "y": 5,
      "z": -6,
      "name": "Editor_Empty"
    },
    {
      "x": 1,
      "y": 6,
      "z": -6,
      "name": "Editor_Empty"
    },
    {
      "x": 1,
      "y": 7,
      "z": -6,
      "name": "Editor_Empty"
    },
    {
      "x": 1,
      "y": 8,
      "z": -6,
      "name": "Editor_Empty"
    },
    {
      "x": 1,
      "y": 9,
      "z": -6,
      "name": "Editor_Empty"
    },
    {
      "x": 1,
      "y": 10,
      "z": -6,
      "name": "Editor_Empty"
    },
    {
      "x": 1,
      "y": 11,
      "z": -6,
      "name": "Editor_Empty"
    },
    {
      "x": 1,
      "y": 12,
      "z": -6,
      "name": "Editor_Empty"
    },
    {
      "x": 1,
      "y": 1,
      "z": -5,
      "name": "Editor_Empty"
    },
    {
      "x": 1,
      "y": 2,
      "z": -5,
      "name": "Editor_Empty"
    },
    {
      "x": 1,
      "y": 3,
      "z": -5,
      "name": "Editor_Empty"
    },
    {
      "x": 1,
      "y": 4,
      "z": -5,
      "name": "Editor_Empty"
    },
    {
      "x": 1,
      "y": 5,
      "z": -5,
      "name": "Editor_Empty"
    },
    {
      "x": 1,
      "y": 6,
      "z": -5,
      "name": "Editor_Empty"
    },
    {
      "x": 1,
      "y": 7,
      "z": -5,
      "name": "Editor_Empty"
    },
    {
      "x": 1,
      "y": 8,
      "z": -5,
      "name": "Editor_Empty"
    },
    {
      "x": 1,
      "y": 9,
      "z": -5,
      "name": "Editor_Empty"
    },
    {
      "x": 1,
      "y": 10,
      "z": -5,
      "name": "Editor_Empty"
    },
    {
      "x": 1,
      "y": 11,
      "z": -5,
      "name": "Editor_Empty"
    },
    {
      "x": 1,
      "y": 12,
      "z": -5,
      "name": "Editor_Empty"
    },
    {
      "x": 1,
      "y": 1,
      "z": -4,
      "name": "Editor_Empty"
    },
    {
      "x": 1,
      "y": 2,
      "z": -4,
      "name": "Editor_Empty"
    },
    {
      "x": 1,
      "y": 3,
      "z": -4,
      "name": "Editor_Empty"
    },
    {
      "x": 1,
      "y": 4,
      "z": -4,
      "name": "Editor_Empty"
    },
    {
      "x": 1,
      "y": 5,
      "z": -4,
      "name": "Editor_Empty"
    },
    {
      "x": 1,
      "y": 6,
      "z": -4,
      "name": "Editor_Empty"
    },
    {
      "x": 1,
      "y": 7,
      "z": -4,
      "name": "Editor_Empty"
    },
    {
      "x": 1,
      "y": 8,
      "z": -4,
      "name": "Editor_Empty"
    },
    {
      "x": 1,
      "y": 9,
      "z": -4,
      "name": "Editor_Empty"
    },
    {
      "x": 1,
      "y": 10,
      "z": -4,
      "name": "Editor_Empty"
    },
    {
      "x": 1,
      "y": 11,
      "z": -4,
      "name": "Editor_Empty"
    },
    {
      "x": 1,
      "y": 12,
      "z": -4,
      "name": "Editor_Empty"
    },
    {
      "x": 1,
      "y": 1,
      "z": -3,
      "name": "Editor_Empty"
    },
    {
      "x": 1,
      "y": 2,
      "z": -3,
      "name": "Editor_Empty"
    },
    {
      "x": 1,
      "y": 3,
      "z": -3,
      "name": "Editor_Empty"
    },
    {
      "x": 1,
      "y": 4,
      "z": -3,
      "name": "Editor_Empty"
    },
    {
      "x": 1,
      "y": 5,
      "z": -3,
      "name": "Editor_Empty"
    },
    {
      "x": 1,
      "y": 6,
      "z": -3,
      "name": "Editor_Empty"
    },
    {
      "x": 1,
      "y": 7,
      "z": -3,
      "name": "Editor_Empty"
    },
    {
      "x": 1,
      "y": 8,
      "z": -3,
      "name": "Editor_Empty"
    },
    {
      "x": 1,
      "y": 9,
      "z": -3,
      "name": "Editor_Empty"
    },
    {
      "x": 1,
      "y": 10,
      "z": -3,
      "name": "Editor_Empty"
    },
    {
      "x": 1,
      "y": 11,
      "z": -3,
      "name": "Editor_Empty"
    },
    {
      "x": 1,
      "y": 12,
      "z": -3,
      "name": "Editor_Empty"
    },
    {
      "x": 1,
      "y": 1,
      "z": -2,
      "name": "Editor_Empty"
    },
    {
      "x": 1,
      "y": 2,
      "z": -2,
      "name": "Editor_Empty"
    },
    {
      "x": 1,
      "y": 3,
      "z": -2,
      "name": "Editor_Empty"
    },
    {
      "x": 1,
      "y": 4,
      "z": -2,
      "name": "Editor_Empty"
    },
    {
      "x": 1,
      "y": 5,
      "z": -2,
      "name": "Editor_Empty"
    },
    {
      "x": 1,
      "y": 6,
      "z": -2,
      "name": "Editor_Empty"
    },
    {
      "x": 1,
      "y": 7,
      "z": -2,
      "name": "Editor_Empty"
    },
    {
      "x": 1,
      "y": 8,
      "z": -2,
      "name": "Editor_Empty"
    },
    {
      "x": 1,
      "y": 9,
      "z": -2,
      "name": "Editor_Empty"
    },
    {
      "x": 1,
      "y": 10,
      "z": -2,
      "name": "Editor_Empty"
    },
    {
      "x": 1,
      "y": 11,
      "z": -2,
      "name": "Editor_Empty"
    },
    {
      "x": 1,
      "y": 12,
      "z": -2,
      "name": "Editor_Empty"
    },
    {
      "x": 1,
      "y": 1,
      "z": -1,
      "name": "Editor_Empty"
    },
    {
      "x": 1,
      "y": 2,
      "z": -1,
      "name": "Editor_Empty"
    },
    {
      "x": 1,
      "y": 3,
      "z": -1,
      "name": "Editor_Empty"
    },
    {
      "x": 1,
      "y": 4,
      "z": -1,
      "name": "Editor_Empty"
    },
    {
      "x": 1,
      "y": 5,
      "z": -1,
      "name": "Editor_Empty"
    },
    {
      "x": 1,
      "y": 6,
      "z": -1,
      "name": "Editor_Empty"
    },
    {
      "x": 1,
      "y": 7,
      "z": -1,
      "name": "Editor_Empty"
    },
    {
      "x": 1,
      "y": 8,
      "z": -1,
      "name": "Editor_Empty"
    },
    {
      "x": 1,
      "y": 9,
      "z": -1,
      "name": "Editor_Empty"
    },
    {
      "x": 1,
      "y": 10,
      "z": -1,
      "name": "Editor_Empty"
    },
    {
      "x": 1,
      "y": 11,
      "z": -1,
      "name": "Editor_Empty"
    },
    {
      "x": 1,
      "y": 12,
      "z": -1,
      "name": "Editor_Empty"
    },
    {
      "x": 2,
      "y": 1,
      "z": -29,
      "name": "Editor_Empty"
    },
    {
      "x": 2,
      "y": 2,
      "z": -29,
      "name": "Editor_Empty"
    },
    {
      "x": 2,
      "y": 3,
      "z": -29,
      "name": "Editor_Empty"
    },
    {
      "x": 2,
      "y": 4,
      "z": -29,
      "name": "Editor_Empty"
    },
    {
      "x": 2,
      "y": 5,
      "z": -29,
      "name": "Editor_Empty"
    },
    {
      "x": 2,
      "y": 6,
      "z": -29,
      "name": "Editor_Empty"
    },
    {
      "x": 2,
      "y": 7,
      "z": -29,
      "name": "Editor_Empty"
    },
    {
      "x": 2,
      "y": 8,
      "z": -29,
      "name": "Editor_Empty"
    },
    {
      "x": 2,
      "y": 9,
      "z": -29,
      "name": "Editor_Empty"
    },
    {
      "x": 2,
      "y": 10,
      "z": -29,
      "name": "Editor_Empty"
    },
    {
      "x": 2,
      "y": 11,
      "z": -29,
      "name": "Editor_Empty"
    },
    {
      "x": 2,
      "y": 12,
      "z": -29,
      "name": "Editor_Empty"
    },
    {
      "x": 2,
      "y": 1,
      "z": -28,
      "name": "Editor_Empty"
    },
    {
      "x": 2,
      "y": 2,
      "z": -28,
      "name": "Editor_Empty"
    },
    {
      "x": 2,
      "y": 3,
      "z": -28,
      "name": "Editor_Empty"
    },
    {
      "x": 2,
      "y": 4,
      "z": -28,
      "name": "Editor_Empty"
    },
    {
      "x": 2,
      "y": 5,
      "z": -28,
      "name": "Editor_Empty"
    },
    {
      "x": 2,
      "y": 6,
      "z": -28,
      "name": "Editor_Empty"
    },
    {
      "x": 2,
      "y": 7,
      "z": -28,
      "name": "Editor_Empty"
    },
    {
      "x": 2,
      "y": 8,
      "z": -28,
      "name": "Editor_Empty"
    },
    {
      "x": 2,
      "y": 9,
      "z": -28,
      "name": "Editor_Empty"
    },
    {
      "x": 2,
      "y": 10,
      "z": -28,
      "name": "Editor_Empty"
    },
    {
      "x": 2,
      "y": 11,
      "z": -28,
      "name": "Editor_Empty"
    },
    {
      "x": 2,
      "y": 12,
      "z": -28,
      "name": "Editor_Empty"
    },
    {
      "x": 2,
      "y": 1,
      "z": -27,
      "name": "Editor_Empty"
    },
    {
      "x": 2,
      "y": 2,
      "z": -27,
      "name": "Editor_Empty"
    },
    {
      "x": 2,
      "y": 3,
      "z": -27,
      "name": "Editor_Empty"
    },
    {
      "x": 2,
      "y": 4,
      "z": -27,
      "name": "Editor_Empty"
    },
    {
      "x": 2,
      "y": 5,
      "z": -27,
      "name": "Editor_Empty"
    },
    {
      "x": 2,
      "y": 6,
      "z": -27,
      "name": "Editor_Empty"
    },
    {
      "x": 2,
      "y": 7,
      "z": -27,
      "name": "Editor_Empty"
    },
    {
      "x": 2,
      "y": 8,
      "z": -27,
      "name": "Editor_Empty"
    },
    {
      "x": 2,
      "y": 9,
      "z": -27,
      "name": "Editor_Empty"
    },
    {
      "x": 2,
      "y": 10,
      "z": -27,
      "name": "Editor_Empty"
    },
    {
      "x": 2,
      "y": 11,
      "z": -27,
      "name": "Editor_Empty"
    },
    {
      "x": 2,
      "y": 12,
      "z": -27,
      "name": "Editor_Empty"
    },
    {
      "x": 2,
      "y": 1,
      "z": -26,
      "name": "Editor_Empty"
    },
    {
      "x": 2,
      "y": 2,
      "z": -26,
      "name": "Editor_Empty"
    },
    {
      "x": 2,
      "y": 3,
      "z": -26,
      "name": "Editor_Empty"
    },
    {
      "x": 2,
      "y": 4,
      "z": -26,
      "name": "Editor_Empty"
    },
    {
      "x": 2,
      "y": 5,
      "z": -26,
      "name": "Editor_Empty"
    },
    {
      "x": 2,
      "y": 6,
      "z": -26,
      "name": "Editor_Empty"
    },
    {
      "x": 2,
      "y": 7,
      "z": -26,
      "name": "Editor_Empty"
    },
    {
      "x": 2,
      "y": 8,
      "z": -26,
      "name": "Editor_Empty"
    },
    {
      "x": 2,
      "y": 9,
      "z": -26,
      "name": "Editor_Empty"
    },
    {
      "x": 2,
      "y": 10,
      "z": -26,
      "name": "Editor_Empty"
    },
    {
      "x": 2,
      "y": 11,
      "z": -26,
      "name": "Editor_Empty"
    },
    {
      "x": 2,
      "y": 12,
      "z": -26,
      "name": "Editor_Empty"
    },
    {
      "x": 2,
      "y": 1,
      "z": -25,
      "name": "Editor_Empty"
    },
    {
      "x": 2,
      "y": 2,
      "z": -25,
      "name": "Editor_Empty"
    },
    {
      "x": 2,
      "y": 3,
      "z": -25,
      "name": "Editor_Empty"
    },
    {
      "x": 2,
      "y": 4,
      "z": -25,
      "name": "Editor_Empty"
    },
    {
      "x": 2,
      "y": 5,
      "z": -25,
      "name": "Editor_Empty"
    },
    {
      "x": 2,
      "y": 6,
      "z": -25,
      "name": "Editor_Empty"
    },
    {
      "x": 2,
      "y": 7,
      "z": -25,
      "name": "Editor_Empty"
    },
    {
      "x": 2,
      "y": 8,
      "z": -25,
      "name": "Editor_Empty"
    },
    {
      "x": 2,
      "y": 9,
      "z": -25,
      "name": "Editor_Empty"
    },
    {
      "x": 2,
      "y": 10,
      "z": -25,
      "name": "Editor_Empty"
    },
    {
      "x": 2,
      "y": 11,
      "z": -25,
      "name": "Editor_Empty"
    },
    {
      "x": 2,
      "y": 12,
      "z": -25,
      "name": "Editor_Empty"
    },
    {
      "x": 2,
      "y": 1,
      "z": -24,
      "name": "Editor_Empty"
    },
    {
      "x": 2,
      "y": 2,
      "z": -24,
      "name": "Editor_Empty"
    },
    {
      "x": 2,
      "y": 3,
      "z": -24,
      "name": "Editor_Empty"
    },
    {
      "x": 2,
      "y": 4,
      "z": -24,
      "name": "Editor_Empty"
    },
    {
      "x": 2,
      "y": 5,
      "z": -24,
      "name": "Editor_Empty"
    },
    {
      "x": 2,
      "y": 6,
      "z": -24,
      "name": "Editor_Empty"
    },
    {
      "x": 2,
      "y": 7,
      "z": -24,
      "name": "Editor_Empty"
    },
    {
      "x": 2,
      "y": 8,
      "z": -24,
      "name": "Editor_Empty"
    },
    {
      "x": 2,
      "y": 9,
      "z": -24,
      "name": "Editor_Empty"
    },
    {
      "x": 2,
      "y": 10,
      "z": -24,
      "name": "Editor_Empty"
    },
    {
      "x": 2,
      "y": 11,
      "z": -24,
      "name": "Editor_Empty"
    },
    {
      "x": 2,
      "y": 12,
      "z": -24,
      "name": "Editor_Empty"
    },
    {
      "x": 2,
      "y": 1,
      "z": -23,
      "name": "Editor_Empty"
    },
    {
      "x": 2,
      "y": 2,
      "z": -23,
      "name": "Editor_Empty"
    },
    {
      "x": 2,
      "y": 3,
      "z": -23,
      "name": "Editor_Empty"
    },
    {
      "x": 2,
      "y": 4,
      "z": -23,
      "name": "Editor_Empty"
    },
    {
      "x": 2,
      "y": 5,
      "z": -23,
      "name": "Editor_Empty"
    },
    {
      "x": 2,
      "y": 6,
      "z": -23,
      "name": "Editor_Empty"
    },
    {
      "x": 2,
      "y": 7,
      "z": -23,
      "name": "Editor_Empty"
    },
    {
      "x": 2,
      "y": 8,
      "z": -23,
      "name": "Editor_Empty"
    },
    {
      "x": 2,
      "y": 9,
      "z": -23,
      "name": "Editor_Empty"
    },
    {
      "x": 2,
      "y": 10,
      "z": -23,
      "name": "Editor_Empty"
    },
    {
      "x": 2,
      "y": 11,
      "z": -23,
      "name": "Editor_Empty"
    },
    {
      "x": 2,
      "y": 12,
      "z": -23,
      "name": "Editor_Empty"
    },
    {
      "x": 2,
      "y": 1,
      "z": -22,
      "name": "Editor_Empty"
    },
    {
      "x": 2,
      "y": 2,
      "z": -22,
      "name": "Editor_Empty"
    },
    {
      "x": 2,
      "y": 3,
      "z": -22,
      "name": "Editor_Empty"
    },
    {
      "x": 2,
      "y": 4,
      "z": -22,
      "name": "Editor_Empty"
    },
    {
      "x": 2,
      "y": 5,
      "z": -22,
      "name": "Editor_Empty"
    },
    {
      "x": 2,
      "y": 6,
      "z": -22,
      "name": "Editor_Empty"
    },
    {
      "x": 2,
      "y": 7,
      "z": -22,
      "name": "Editor_Empty"
    },
    {
      "x": 2,
      "y": 8,
      "z": -22,
      "name": "Editor_Empty"
    },
    {
      "x": 2,
      "y": 9,
      "z": -22,
      "name": "Editor_Empty"
    },
    {
      "x": 2,
      "y": 10,
      "z": -22,
      "name": "Editor_Empty"
    },
    {
      "x": 2,
      "y": 11,
      "z": -22,
      "name": "Editor_Empty"
    },
    {
      "x": 2,
      "y": 12,
      "z": -22,
      "name": "Editor_Empty"
    },
    {
      "x": 2,
      "y": 1,
      "z": -21,
      "name": "Editor_Empty"
    },
    {
      "x": 2,
      "y": 2,
      "z": -21,
      "name": "Editor_Empty"
    },
    {
      "x": 2,
      "y": 3,
      "z": -21,
      "name": "Editor_Empty"
    },
    {
      "x": 2,
      "y": 4,
      "z": -21,
      "name": "Editor_Empty"
    },
    {
      "x": 2,
      "y": 5,
      "z": -21,
      "name": "Editor_Empty"
    },
    {
      "x": 2,
      "y": 6,
      "z": -21,
      "name": "Editor_Empty"
    },
    {
      "x": 2,
      "y": 7,
      "z": -21,
      "name": "Editor_Empty"
    },
    {
      "x": 2,
      "y": 8,
      "z": -21,
      "name": "Editor_Empty"
    },
    {
      "x": 2,
      "y": 9,
      "z": -21,
      "name": "Editor_Empty"
    },
    {
      "x": 2,
      "y": 10,
      "z": -21,
      "name": "Editor_Empty"
    },
    {
      "x": 2,
      "y": 11,
      "z": -21,
      "name": "Editor_Empty"
    },
    {
      "x": 2,
      "y": 12,
      "z": -21,
      "name": "Editor_Empty"
    },
    {
      "x": 2,
      "y": 1,
      "z": -20,
      "name": "Editor_Empty"
    },
    {
      "x": 2,
      "y": 2,
      "z": -20,
      "name": "Editor_Empty"
    },
    {
      "x": 2,
      "y": 3,
      "z": -20,
      "name": "Editor_Empty"
    },
    {
      "x": 2,
      "y": 4,
      "z": -20,
      "name": "Editor_Empty"
    },
    {
      "x": 2,
      "y": 5,
      "z": -20,
      "name": "Editor_Empty"
    },
    {
      "x": 2,
      "y": 6,
      "z": -20,
      "name": "Editor_Empty"
    },
    {
      "x": 2,
      "y": 7,
      "z": -20,
      "name": "Editor_Empty"
    },
    {
      "x": 2,
      "y": 8,
      "z": -20,
      "name": "Editor_Empty"
    },
    {
      "x": 2,
      "y": 9,
      "z": -20,
      "name": "Editor_Empty"
    },
    {
      "x": 2,
      "y": 10,
      "z": -20,
      "name": "Editor_Empty"
    },
    {
      "x": 2,
      "y": 11,
      "z": -20,
      "name": "Editor_Empty"
    },
    {
      "x": 2,
      "y": 12,
      "z": -20,
      "name": "Editor_Empty"
    },
    {
      "x": 2,
      "y": 0,
      "z": -19,
      "name": "Rock_Stone"
    },
    {
      "x": 2,
      "y": 1,
      "z": -19,
      "name": "Rock_Stone_Cobble"
    },
    {
      "x": 2,
      "y": 2,
      "z": -19,
      "name": "Rock_Stone"
    },
    {
      "x": 2,
      "y": 3,
      "z": -19,
      "name": "Rock_Stone_Cobble_Mossy"
    },
    {
      "x": 2,
      "y": 4,
      "z": -19,
      "name": "Editor_Empty"
    },
    {
      "x": 2,
      "y": 5,
      "z": -19,
      "name": "Editor_Empty"
    },
    {
      "x": 2,
      "y": 6,
      "z": -19,
      "name": "Editor_Empty"
    },
    {
      "x": 2,
      "y": 7,
      "z": -19,
      "name": "Editor_Empty"
    },
    {
      "x": 2,
      "y": 8,
      "z": -19,
      "name": "Editor_Empty"
    },
    {
      "x": 2,
      "y": 9,
      "z": -19,
      "name": "Editor_Empty"
    },
    {
      "x": 2,
      "y": 10,
      "z": -19,
      "name": "Editor_Empty"
    },
    {
      "x": 2,
      "y": 11,
      "z": -19,
      "name": "Editor_Empty"
    },
    {
      "x": 2,
      "y": 12,
      "z": -19,
      "name": "Editor_Empty"
    },
    {
      "x": 2,
      "y": 0,
      "z": -18,
      "name": "Rock_Stone"
    },
    {
      "x": 2,
      "y": 1,
      "z": -18,
      "name": "Rock_Stone_Cobble_Mossy"
    },
    {
      "x": 2,
      "y": 2,
      "z": -18,
      "name": "Rock_Stone_Cobble"
    },
    {
      "x": 2,
      "y": 3,
      "z": -18,
      "name": "Rock_Stone"
    },
    {
      "x": 2,
      "y": 4,
      "z": -18,
      "name": "Rock_Stone_Cobble"
    },
    {
      "x": 2,
      "y": 5,
      "z": -18,
      "name": "Rock_Stone_Cobble"
    },
    {
      "x": 2,
      "y": 6,
      "z": -18,
      "name": "Rock_Stone"
    },
    {
      "x": 2,
      "y": 7,
      "z": -18,
      "name": "Editor_Empty"
    },
    {
      "x": 2,
      "y": 8,
      "z": -18,
      "name": "Editor_Empty"
    },
    {
      "x": 2,
      "y": 9,
      "z": -18,
      "name": "Editor_Empty"
    },
    {
      "x": 2,
      "y": 10,
      "z": -18,
      "name": "Editor_Empty"
    },
    {
      "x": 2,
      "y": 11,
      "z": -18,
      "name": "Editor_Empty"
    },
    {
      "x": 2,
      "y": 12,
      "z": -18,
      "name": "Editor_Empty"
    },
    {
      "x": 2,
      "y": 0,
      "z": -17,
      "name": "Rock_Stone_Cobble"
    },
    {
      "x": 2,
      "y": 1,
      "z": -17,
      "name": "Rock_Stone"
    },
    {
      "x": 2,
      "y": 2,
      "z": -17,
      "name": "Rock_Stone"
    },
    {
      "x": 2,
      "y": 3,
      "z": -17,
      "name": "Rock_Stone_Cobble_Mossy"
    },
    {
      "x": 2,
      "y": 4,
      "z": -17,
      "name": "Rock_Stone_Cobble"
    },
    {
      "x": 2,
      "y": 5,
      "z": -17,
      "name": "Rock_Stone_Cobble_Mossy"
    },
    {
      "x": 2,
      "y": 6,
      "z": -17,
      "name": "Rock_Stone"
    },
    {
      "x": 2,
      "y": 7,
      "z": -17,
      "name": "Editor_Empty"
    },
    {
      "x": 2,
      "y": 8,
      "z": -17,
      "name": "Editor_Empty"
    },
    {
      "x": 2,
      "y": 9,
      "z": -17,
      "name": "Editor_Empty"
    },
    {
      "x": 2,
      "y": 10,
      "z": -17,
      "name": "Editor_Empty"
    },
    {
      "x": 2,
      "y": 11,
      "z": -17,
      "name": "Editor_Empty"
    },
    {
      "x": 2,
      "y": 12,
      "z": -17,
      "name": "Editor_Empty"
    },
    {
      "x": 2,
      "y": 0,
      "z": -16,
      "name": "Rock_Stone_Cobble"
    },
    {
      "x": 2,
      "y": 1,
      "z": -16,
      "name": "Rock_Stone_Cobble_Mossy"
    },
    {
      "x": 2,
      "y": 2,
      "z": -16,
      "name": "Rock_Stone_Cobble"
    },
    {
      "x": 2,
      "y": 3,
      "z": -16,
      "name": "Rock_Stone_Cobble_Mossy"
    },
    {
      "x": 2,
      "y": 4,
      "z": -16,
      "name": "Rock_Stone_Cobble"
    },
    {
      "x": 2,
      "y": 5,
      "z": -16,
      "name": "Rock_Stone"
    },
    {
      "x": 2,
      "y": 6,
      "z": -16,
      "name": "Rock_Stone_Cobble"
    },
    {
      "x": 2,
      "y": 7,
      "z": -16,
      "name": "Editor_Empty"
    },
    {
      "x": 2,
      "y": 8,
      "z": -16,
      "name": "Editor_Empty"
    },
    {
      "x": 2,
      "y": 9,
      "z": -16,
      "name": "Editor_Empty"
    },
    {
      "x": 2,
      "y": 10,
      "z": -16,
      "name": "Editor_Empty"
    },
    {
      "x": 2,
      "y": 11,
      "z": -16,
      "name": "Editor_Empty"
    },
    {
      "x": 2,
      "y": 12,
      "z": -16,
      "name": "Editor_Empty"
    },
    {
      "x": 2,
      "y": 0,
      "z": -15,
      "name": "Rock_Stone_Cobble_Mossy"
    },
    {
      "x": 2,
      "y": 1,
      "z": -15,
      "name": "Rock_Stone_Cobble_Mossy"
    },
    {
      "x": 2,
      "y": 2,
      "z": -15,
      "name": "Rock_Stone_Cobble"
    },
    {
      "x": 2,
      "y": 3,
      "z": -15,
      "name": "Rock_Stone_Cobble"
    },
    {
      "x": 2,
      "y": 4,
      "z": -15,
      "name": "Rock_Stone_Cobble"
    },
    {
      "x": 2,
      "y": 5,
      "z": -15,
      "name": "Rock_Stone"
    },
    {
      "x": 2,
      "y": 6,
      "z": -15,
      "name": "Rock_Stone_Cobble"
    },
    {
      "x": 2,
      "y": 7,
      "z": -15,
      "name": "Editor_Empty"
    },
    {
      "x": 2,
      "y": 8,
      "z": -15,
      "name": "Editor_Empty"
    },
    {
      "x": 2,
      "y": 9,
      "z": -15,
      "name": "Editor_Empty"
    },
    {
      "x": 2,
      "y": 10,
      "z": -15,
      "name": "Editor_Empty"
    },
    {
      "x": 2,
      "y": 11,
      "z": -15,
      "name": "Editor_Empty"
    },
    {
      "x": 2,
      "y": 12,
      "z": -15,
      "name": "Editor_Empty"
    },
    {
      "x": 2,
      "y": 0,
      "z": -14,
      "name": "Rock_Stone"
    },
    {
      "x": 2,
      "y": 1,
      "z": -14,
      "name": "Rock_Stone"
    },
    {
      "x": 2,
      "y": 2,
      "z": -14,
      "name": "Rock_Stone_Cobble"
    },
    {
      "x": 2,
      "y": 3,
      "z": -14,
      "name": "Rock_Stone_Cobble_Mossy"
    },
    {
      "x": 2,
      "y": 4,
      "z": -14,
      "name": "Editor_Empty"
    },
    {
      "x": 2,
      "y": 5,
      "z": -14,
      "name": "Editor_Empty"
    },
    {
      "x": 2,
      "y": 6,
      "z": -14,
      "name": "Editor_Empty"
    },
    {
      "x": 2,
      "y": 7,
      "z": -14,
      "name": "Editor_Empty"
    },
    {
      "x": 2,
      "y": 8,
      "z": -14,
      "name": "Editor_Empty"
    },
    {
      "x": 2,
      "y": 9,
      "z": -14,
      "name": "Editor_Empty"
    },
    {
      "x": 2,
      "y": 10,
      "z": -14,
      "name": "Editor_Empty"
    },
    {
      "x": 2,
      "y": 11,
      "z": -14,
      "name": "Editor_Empty"
    },
    {
      "x": 2,
      "y": 12,
      "z": -14,
      "name": "Editor_Empty"
    },
    {
      "x": 2,
      "y": 0,
      "z": -13,
      "name": "Rock_Stone_Cobble_Mossy"
    },
    {
      "x": 2,
      "y": 1,
      "z": -13,
      "name": "Rock_Stone"
    },
    {
      "x": 2,
      "y": 2,
      "z": -13,
      "name": "Rock_Stone"
    },
    {
      "x": 2,
      "y": 3,
      "z": -13,
      "name": "Editor_Empty"
    },
    {
      "x": 2,
      "y": 4,
      "z": -13,
      "name": "Editor_Empty"
    },
    {
      "x": 2,
      "y": 5,
      "z": -13,
      "name": "Editor_Empty"
    },
    {
      "x": 2,
      "y": 6,
      "z": -13,
      "name": "Editor_Empty"
    },
    {
      "x": 2,
      "y": 7,
      "z": -13,
      "name": "Editor_Empty"
    },
    {
      "x": 2,
      "y": 8,
      "z": -13,
      "name": "Editor_Empty"
    },
    {
      "x": 2,
      "y": 9,
      "z": -13,
      "name": "Editor_Empty"
    },
    {
      "x": 2,
      "y": 10,
      "z": -13,
      "name": "Editor_Empty"
    },
    {
      "x": 2,
      "y": 11,
      "z": -13,
      "name": "Editor_Empty"
    },
    {
      "x": 2,
      "y": 12,
      "z": -13,
      "name": "Editor_Empty"
    },
    {
      "x": 2,
      "y": 0,
      "z": -12,
      "name": "Rock_Stone_Cobble"
    },
    {
      "x": 2,
      "y": 1,
      "z": -12,
      "name": "Rock_Stone"
    },
    {
      "x": 2,
      "y": 2,
      "z": -12,
      "name": "Rock_Stone_Cobble"
    },
    {
      "x": 2,
      "y": 3,
      "z": -12,
      "name": "Editor_Empty"
    },
    {
      "x": 2,
      "y": 4,
      "z": -12,
      "name": "Editor_Empty"
    },
    {
      "x": 2,
      "y": 5,
      "z": -12,
      "name": "Editor_Empty"
    },
    {
      "x": 2,
      "y": 6,
      "z": -12,
      "name": "Editor_Empty"
    },
    {
      "x": 2,
      "y": 7,
      "z": -12,
      "name": "Editor_Empty"
    },
    {
      "x": 2,
      "y": 8,
      "z": -12,
      "name": "Editor_Empty"
    },
    {
      "x": 2,
      "y": 9,
      "z": -12,
      "name": "Editor_Empty"
    },
    {
      "x": 2,
      "y": 10,
      "z": -12,
      "name": "Editor_Empty"
    },
    {
      "x": 2,
      "y": 11,
      "z": -12,
      "name": "Editor_Empty"
    },
    {
      "x": 2,
      "y": 12,
      "z": -12,
      "name": "Editor_Empty"
    },
    {
      "x": 2,
      "y": 1,
      "z": -11,
      "name": "Editor_Empty"
    },
    {
      "x": 2,
      "y": 2,
      "z": -11,
      "name": "Editor_Empty"
    },
    {
      "x": 2,
      "y": 3,
      "z": -11,
      "name": "Editor_Empty"
    },
    {
      "x": 2,
      "y": 4,
      "z": -11,
      "name": "Editor_Empty"
    },
    {
      "x": 2,
      "y": 5,
      "z": -11,
      "name": "Editor_Empty"
    },
    {
      "x": 2,
      "y": 6,
      "z": -11,
      "name": "Editor_Empty"
    },
    {
      "x": 2,
      "y": 7,
      "z": -11,
      "name": "Editor_Empty"
    },
    {
      "x": 2,
      "y": 8,
      "z": -11,
      "name": "Editor_Empty"
    },
    {
      "x": 2,
      "y": 9,
      "z": -11,
      "name": "Editor_Empty"
    },
    {
      "x": 2,
      "y": 10,
      "z": -11,
      "name": "Editor_Empty"
    },
    {
      "x": 2,
      "y": 11,
      "z": -11,
      "name": "Editor_Empty"
    },
    {
      "x": 2,
      "y": 12,
      "z": -11,
      "name": "Editor_Empty"
    },
    {
      "x": 2,
      "y": 1,
      "z": -10,
      "name": "Editor_Empty"
    },
    {
      "x": 2,
      "y": 2,
      "z": -10,
      "name": "Editor_Empty"
    },
    {
      "x": 2,
      "y": 3,
      "z": -10,
      "name": "Editor_Empty"
    },
    {
      "x": 2,
      "y": 4,
      "z": -10,
      "name": "Editor_Empty"
    },
    {
      "x": 2,
      "y": 5,
      "z": -10,
      "name": "Editor_Empty"
    },
    {
      "x": 2,
      "y": 6,
      "z": -10,
      "name": "Editor_Empty"
    },
    {
      "x": 2,
      "y": 7,
      "z": -10,
      "name": "Editor_Empty"
    },
    {
      "x": 2,
      "y": 8,
      "z": -10,
      "name": "Editor_Empty"
    },
    {
      "x": 2,
      "y": 9,
      "z": -10,
      "name": "Editor_Empty"
    },
    {
      "x": 2,
      "y": 10,
      "z": -10,
      "name": "Editor_Empty"
    },
    {
      "x": 2,
      "y": 11,
      "z": -10,
      "name": "Editor_Empty"
    },
    {
      "x": 2,
      "y": 12,
      "z": -10,
      "name": "Editor_Empty"
    },
    {
      "x": 2,
      "y": 1,
      "z": -9,
      "name": "Editor_Empty"
    },
    {
      "x": 2,
      "y": 2,
      "z": -9,
      "name": "Editor_Empty"
    },
    {
      "x": 2,
      "y": 3,
      "z": -9,
      "name": "Editor_Empty"
    },
    {
      "x": 2,
      "y": 4,
      "z": -9,
      "name": "Editor_Empty"
    },
    {
      "x": 2,
      "y": 5,
      "z": -9,
      "name": "Editor_Empty"
    },
    {
      "x": 2,
      "y": 6,
      "z": -9,
      "name": "Editor_Empty"
    },
    {
      "x": 2,
      "y": 7,
      "z": -9,
      "name": "Editor_Empty"
    },
    {
      "x": 2,
      "y": 8,
      "z": -9,
      "name": "Editor_Empty"
    },
    {
      "x": 2,
      "y": 9,
      "z": -9,
      "name": "Editor_Empty"
    },
    {
      "x": 2,
      "y": 10,
      "z": -9,
      "name": "Editor_Empty"
    },
    {
      "x": 2,
      "y": 11,
      "z": -9,
      "name": "Editor_Empty"
    },
    {
      "x": 2,
      "y": 12,
      "z": -9,
      "name": "Editor_Empty"
    },
    {
      "x": 2,
      "y": 0,
      "z": -8,
      "name": "Rock_Stone"
    },
    {
      "x": 2,
      "y": 1,
      "z": -8,
      "name": "Rock_Stone"
    },
    {
      "x": 2,
      "y": 2,
      "z": -8,
      "name": "Rock_Stone_Cobble_Mossy"
    },
    {
      "x": 2,
      "y": 3,
      "z": -8,
      "name": "Editor_Empty"
    },
    {
      "x": 2,
      "y": 4,
      "z": -8,
      "name": "Editor_Empty"
    },
    {
      "x": 2,
      "y": 5,
      "z": -8,
      "name": "Editor_Empty"
    },
    {
      "x": 2,
      "y": 6,
      "z": -8,
      "name": "Editor_Empty"
    },
    {
      "x": 2,
      "y": 7,
      "z": -8,
      "name": "Editor_Empty"
    },
    {
      "x": 2,
      "y": 8,
      "z": -8,
      "name": "Editor_Empty"
    },
    {
      "x": 2,
      "y": 9,
      "z": -8,
      "name": "Editor_Empty"
    },
    {
      "x": 2,
      "y": 10,
      "z": -8,
      "name": "Editor_Empty"
    },
    {
      "x": 2,
      "y": 11,
      "z": -8,
      "name": "Editor_Empty"
    },
    {
      "x": 2,
      "y": 12,
      "z": -8,
      "name": "Editor_Empty"
    },
    {
      "x": 2,
      "y": 0,
      "z": -7,
      "name": "Rock_Stone"
    },
    {
      "x": 2,
      "y": 1,
      "z": -7,
      "name": "Rock_Stone_Cobble_Mossy"
    },
    {
      "x": 2,
      "y": 2,
      "z": -7,
      "name": "Rock_Stone"
    },
    {
      "x": 2,
      "y": 3,
      "z": -7,
      "name": "Editor_Empty"
    },
    {
      "x": 2,
      "y": 4,
      "z": -7,
      "name": "Editor_Empty"
    },
    {
      "x": 2,
      "y": 5,
      "z": -7,
      "name": "Editor_Empty"
    },
    {
      "x": 2,
      "y": 6,
      "z": -7,
      "name": "Editor_Empty"
    },
    {
      "x": 2,
      "y": 7,
      "z": -7,
      "name": "Editor_Empty"
    },
    {
      "x": 2,
      "y": 8,
      "z": -7,
      "name": "Editor_Empty"
    },
    {
      "x": 2,
      "y": 9,
      "z": -7,
      "name": "Editor_Empty"
    },
    {
      "x": 2,
      "y": 10,
      "z": -7,
      "name": "Editor_Empty"
    },
    {
      "x": 2,
      "y": 11,
      "z": -7,
      "name": "Editor_Empty"
    },
    {
      "x": 2,
      "y": 12,
      "z": -7,
      "name": "Editor_Empty"
    },
    {
      "x": 2,
      "y": 0,
      "z": -6,
      "name": "Rock_Stone"
    },
    {
      "x": 2,
      "y": 1,
      "z": -6,
      "name": "Rock_Stone_Cobble_Mossy"
    },
    {
      "x": 2,
      "y": 2,
      "z": -6,
      "name": "Rock_Stone_Cobble_Mossy"
    },
    {
      "x": 2,
      "y": 3,
      "z": -6,
      "name": "Editor_Empty"
    },
    {
      "x": 2,
      "y": 4,
      "z": -6,
      "name": "Editor_Empty"
    },
    {
      "x": 2,
      "y": 5,
      "z": -6,
      "name": "Editor_Empty"
    },
    {
      "x": 2,
      "y": 6,
      "z": -6,
      "name": "Editor_Empty"
    },
    {
      "x": 2,
      "y": 7,
      "z": -6,
      "name": "Editor_Empty"
    },
    {
      "x": 2,
      "y": 8,
      "z": -6,
      "name": "Editor_Empty"
    },
    {
      "x": 2,
      "y": 9,
      "z": -6,
      "name": "Editor_Empty"
    },
    {
      "x": 2,
      "y": 10,
      "z": -6,
      "name": "Editor_Empty"
    },
    {
      "x": 2,
      "y": 11,
      "z": -6,
      "name": "Editor_Empty"
    },
    {
      "x": 2,
      "y": 12,
      "z": -6,
      "name": "Editor_Empty"
    },
    {
      "x": 2,
      "y": 0,
      "z": -5,
      "name": "Rock_Stone_Cobble"
    },
    {
      "x": 2,
      "y": 1,
      "z": -5,
      "name": "Rock_Stone_Cobble"
    },
    {
      "x": 2,
      "y": 2,
      "z": -5,
      "name": "Rock_Stone_Cobble"
    },
    {
      "x": 2,
      "y": 3,
      "z": -5,
      "name": "Editor_Empty"
    },
    {
      "x": 2,
      "y": 4,
      "z": -5,
      "name": "Editor_Empty"
    },
    {
      "x": 2,
      "y": 5,
      "z": -5,
      "name": "Editor_Empty"
    },
    {
      "x": 2,
      "y": 6,
      "z": -5,
      "name": "Editor_Empty"
    },
    {
      "x": 2,
      "y": 7,
      "z": -5,
      "name": "Editor_Empty"
    },
    {
      "x": 2,
      "y": 8,
      "z": -5,
      "name": "Editor_Empty"
    },
    {
      "x": 2,
      "y": 9,
      "z": -5,
      "name": "Editor_Empty"
    },
    {
      "x": 2,
      "y": 10,
      "z": -5,
      "name": "Editor_Empty"
    },
    {
      "x": 2,
      "y": 11,
      "z": -5,
      "name": "Editor_Empty"
    },
    {
      "x": 2,
      "y": 12,
      "z": -5,
      "name": "Editor_Empty"
    },
    {
      "x": 2,
      "y": 1,
      "z": -4,
      "name": "Editor_Empty"
    },
    {
      "x": 2,
      "y": 2,
      "z": -4,
      "name": "Editor_Empty"
    },
    {
      "x": 2,
      "y": 3,
      "z": -4,
      "name": "Editor_Empty"
    },
    {
      "x": 2,
      "y": 4,
      "z": -4,
      "name": "Editor_Empty"
    },
    {
      "x": 2,
      "y": 5,
      "z": -4,
      "name": "Editor_Empty"
    },
    {
      "x": 2,
      "y": 6,
      "z": -4,
      "name": "Editor_Empty"
    },
    {
      "x": 2,
      "y": 7,
      "z": -4,
      "name": "Editor_Empty"
    },
    {
      "x": 2,
      "y": 8,
      "z": -4,
      "name": "Editor_Empty"
    },
    {
      "x": 2,
      "y": 9,
      "z": -4,
      "name": "Editor_Empty"
    },
    {
      "x": 2,
      "y": 10,
      "z": -4,
      "name": "Editor_Empty"
    },
    {
      "x": 2,
      "y": 11,
      "z": -4,
      "name": "Editor_Empty"
    },
    {
      "x": 2,
      "y": 12,
      "z": -4,
      "name": "Editor_Empty"
    },
    {
      "x": 2,
      "y": 1,
      "z": -3,
      "name": "Editor_Empty"
    },
    {
      "x": 2,
      "y": 2,
      "z": -3,
      "name": "Editor_Empty"
    },
    {
      "x": 2,
      "y": 3,
      "z": -3,
      "name": "Editor_Empty"
    },
    {
      "x": 2,
      "y": 4,
      "z": -3,
      "name": "Editor_Empty"
    },
    {
      "x": 2,
      "y": 5,
      "z": -3,
      "name": "Editor_Empty"
    },
    {
      "x": 2,
      "y": 6,
      "z": -3,
      "name": "Editor_Empty"
    },
    {
      "x": 2,
      "y": 7,
      "z": -3,
      "name": "Editor_Empty"
    },
    {
      "x": 2,
      "y": 8,
      "z": -3,
      "name": "Editor_Empty"
    },
    {
      "x": 2,
      "y": 9,
      "z": -3,
      "name": "Editor_Empty"
    },
    {
      "x": 2,
      "y": 10,
      "z": -3,
      "name": "Editor_Empty"
    },
    {
      "x": 2,
      "y": 11,
      "z": -3,
      "name": "Editor_Empty"
    },
    {
      "x": 2,
      "y": 12,
      "z": -3,
      "name": "Editor_Empty"
    },
    {
      "x": 2,
      "y": 1,
      "z": -2,
      "name": "Editor_Empty"
    },
    {
      "x": 2,
      "y": 2,
      "z": -2,
      "name": "Editor_Empty"
    },
    {
      "x": 2,
      "y": 3,
      "z": -2,
      "name": "Editor_Empty"
    },
    {
      "x": 2,
      "y": 4,
      "z": -2,
      "name": "Editor_Empty"
    },
    {
      "x": 2,
      "y": 5,
      "z": -2,
      "name": "Editor_Empty"
    },
    {
      "x": 2,
      "y": 6,
      "z": -2,
      "name": "Editor_Empty"
    },
    {
      "x": 2,
      "y": 7,
      "z": -2,
      "name": "Editor_Empty"
    },
    {
      "x": 2,
      "y": 8,
      "z": -2,
      "name": "Editor_Empty"
    },
    {
      "x": 2,
      "y": 9,
      "z": -2,
      "name": "Editor_Empty"
    },
    {
      "x": 2,
      "y": 10,
      "z": -2,
      "name": "Editor_Empty"
    },
    {
      "x": 2,
      "y": 11,
      "z": -2,
      "name": "Editor_Empty"
    },
    {
      "x": 2,
      "y": 12,
      "z": -2,
      "name": "Editor_Empty"
    },
    {
      "x": 2,
      "y": 1,
      "z": -1,
      "name": "Editor_Empty"
    },
    {
      "x": 2,
      "y": 2,
      "z": -1,
      "name": "Editor_Empty"
    },
    {
      "x": 2,
      "y": 3,
      "z": -1,
      "name": "Editor_Empty"
    },
    {
      "x": 2,
      "y": 4,
      "z": -1,
      "name": "Editor_Empty"
    },
    {
      "x": 2,
      "y": 5,
      "z": -1,
      "name": "Editor_Empty"
    },
    {
      "x": 2,
      "y": 6,
      "z": -1,
      "name": "Editor_Empty"
    },
    {
      "x": 2,
      "y": 7,
      "z": -1,
      "name": "Editor_Empty"
    },
    {
      "x": 2,
      "y": 8,
      "z": -1,
      "name": "Editor_Empty"
    },
    {
      "x": 2,
      "y": 9,
      "z": -1,
      "name": "Editor_Empty"
    },
    {
      "x": 2,
      "y": 10,
      "z": -1,
      "name": "Editor_Empty"
    },
    {
      "x": 2,
      "y": 11,
      "z": -1,
      "name": "Editor_Empty"
    },
    {
      "x": 2,
      "y": 12,
      "z": -1,
      "name": "Editor_Empty"
    },
    {
      "x": 3,
      "y": 1,
      "z": -29,
      "name": "Editor_Empty"
    },
    {
      "x": 3,
      "y": 2,
      "z": -29,
      "name": "Editor_Empty"
    },
    {
      "x": 3,
      "y": 3,
      "z": -29,
      "name": "Editor_Empty"
    },
    {
      "x": 3,
      "y": 4,
      "z": -29,
      "name": "Editor_Empty"
    },
    {
      "x": 3,
      "y": 5,
      "z": -29,
      "name": "Editor_Empty"
    },
    {
      "x": 3,
      "y": 6,
      "z": -29,
      "name": "Editor_Empty"
    },
    {
      "x": 3,
      "y": 7,
      "z": -29,
      "name": "Editor_Empty"
    },
    {
      "x": 3,
      "y": 8,
      "z": -29,
      "name": "Editor_Empty"
    },
    {
      "x": 3,
      "y": 9,
      "z": -29,
      "name": "Editor_Empty"
    },
    {
      "x": 3,
      "y": 10,
      "z": -29,
      "name": "Editor_Empty"
    },
    {
      "x": 3,
      "y": 11,
      "z": -29,
      "name": "Editor_Empty"
    },
    {
      "x": 3,
      "y": 12,
      "z": -29,
      "name": "Editor_Empty"
    },
    {
      "x": 3,
      "y": 1,
      "z": -28,
      "name": "Editor_Empty"
    },
    {
      "x": 3,
      "y": 2,
      "z": -28,
      "name": "Editor_Empty"
    },
    {
      "x": 3,
      "y": 3,
      "z": -28,
      "name": "Editor_Empty"
    },
    {
      "x": 3,
      "y": 4,
      "z": -28,
      "name": "Editor_Empty"
    },
    {
      "x": 3,
      "y": 5,
      "z": -28,
      "name": "Editor_Empty"
    },
    {
      "x": 3,
      "y": 6,
      "z": -28,
      "name": "Editor_Empty"
    },
    {
      "x": 3,
      "y": 7,
      "z": -28,
      "name": "Editor_Empty"
    },
    {
      "x": 3,
      "y": 8,
      "z": -28,
      "name": "Editor_Empty"
    },
    {
      "x": 3,
      "y": 9,
      "z": -28,
      "name": "Editor_Empty"
    },
    {
      "x": 3,
      "y": 10,
      "z": -28,
      "name": "Editor_Empty"
    },
    {
      "x": 3,
      "y": 11,
      "z": -28,
      "name": "Editor_Empty"
    },
    {
      "x": 3,
      "y": 12,
      "z": -28,
      "name": "Editor_Empty"
    },
    {
      "x": 3,
      "y": 1,
      "z": -27,
      "name": "Editor_Empty"
    },
    {
      "x": 3,
      "y": 2,
      "z": -27,
      "name": "Editor_Empty"
    },
    {
      "x": 3,
      "y": 3,
      "z": -27,
      "name": "Editor_Empty"
    },
    {
      "x": 3,
      "y": 4,
      "z": -27,
      "name": "Editor_Empty"
    },
    {
      "x": 3,
      "y": 5,
      "z": -27,
      "name": "Editor_Empty"
    },
    {
      "x": 3,
      "y": 6,
      "z": -27,
      "name": "Editor_Empty"
    },
    {
      "x": 3,
      "y": 7,
      "z": -27,
      "name": "Editor_Empty"
    },
    {
      "x": 3,
      "y": 8,
      "z": -27,
      "name": "Editor_Empty"
    },
    {
      "x": 3,
      "y": 9,
      "z": -27,
      "name": "Editor_Empty"
    },
    {
      "x": 3,
      "y": 10,
      "z": -27,
      "name": "Editor_Empty"
    },
    {
      "x": 3,
      "y": 11,
      "z": -27,
      "name": "Editor_Empty"
    },
    {
      "x": 3,
      "y": 12,
      "z": -27,
      "name": "Editor_Empty"
    },
    {
      "x": 3,
      "y": 1,
      "z": -26,
      "name": "Editor_Empty"
    },
    {
      "x": 3,
      "y": 2,
      "z": -26,
      "name": "Editor_Empty"
    },
    {
      "x": 3,
      "y": 3,
      "z": -26,
      "name": "Editor_Empty"
    },
    {
      "x": 3,
      "y": 4,
      "z": -26,
      "name": "Editor_Empty"
    },
    {
      "x": 3,
      "y": 5,
      "z": -26,
      "name": "Editor_Empty"
    },
    {
      "x": 3,
      "y": 6,
      "z": -26,
      "name": "Editor_Empty"
    },
    {
      "x": 3,
      "y": 7,
      "z": -26,
      "name": "Editor_Empty"
    },
    {
      "x": 3,
      "y": 8,
      "z": -26,
      "name": "Editor_Empty"
    },
    {
      "x": 3,
      "y": 9,
      "z": -26,
      "name": "Editor_Empty"
    },
    {
      "x": 3,
      "y": 10,
      "z": -26,
      "name": "Editor_Empty"
    },
    {
      "x": 3,
      "y": 11,
      "z": -26,
      "name": "Editor_Empty"
    },
    {
      "x": 3,
      "y": 12,
      "z": -26,
      "name": "Editor_Empty"
    },
    {
      "x": 3,
      "y": 1,
      "z": -25,
      "name": "Editor_Empty"
    },
    {
      "x": 3,
      "y": 2,
      "z": -25,
      "name": "Editor_Empty"
    },
    {
      "x": 3,
      "y": 3,
      "z": -25,
      "name": "Editor_Empty"
    },
    {
      "x": 3,
      "y": 4,
      "z": -25,
      "name": "Editor_Empty"
    },
    {
      "x": 3,
      "y": 5,
      "z": -25,
      "name": "Editor_Empty"
    },
    {
      "x": 3,
      "y": 6,
      "z": -25,
      "name": "Editor_Empty"
    },
    {
      "x": 3,
      "y": 7,
      "z": -25,
      "name": "Editor_Empty"
    },
    {
      "x": 3,
      "y": 8,
      "z": -25,
      "name": "Editor_Empty"
    },
    {
      "x": 3,
      "y": 9,
      "z": -25,
      "name": "Editor_Empty"
    },
    {
      "x": 3,
      "y": 10,
      "z": -25,
      "name": "Editor_Empty"
    },
    {
      "x": 3,
      "y": 11,
      "z": -25,
      "name": "Editor_Empty"
    },
    {
      "x": 3,
      "y": 12,
      "z": -25,
      "name": "Editor_Empty"
    },
    {
      "x": 3,
      "y": 1,
      "z": -24,
      "name": "Editor_Empty"
    },
    {
      "x": 3,
      "y": 2,
      "z": -24,
      "name": "Editor_Empty"
    },
    {
      "x": 3,
      "y": 3,
      "z": -24,
      "name": "Editor_Empty"
    },
    {
      "x": 3,
      "y": 4,
      "z": -24,
      "name": "Editor_Empty"
    },
    {
      "x": 3,
      "y": 5,
      "z": -24,
      "name": "Editor_Empty"
    },
    {
      "x": 3,
      "y": 6,
      "z": -24,
      "name": "Editor_Empty"
    },
    {
      "x": 3,
      "y": 7,
      "z": -24,
      "name": "Editor_Empty"
    },
    {
      "x": 3,
      "y": 8,
      "z": -24,
      "name": "Editor_Empty"
    },
    {
      "x": 3,
      "y": 9,
      "z": -24,
      "name": "Editor_Empty"
    },
    {
      "x": 3,
      "y": 10,
      "z": -24,
      "name": "Editor_Empty"
    },
    {
      "x": 3,
      "y": 11,
      "z": -24,
      "name": "Editor_Empty"
    },
    {
      "x": 3,
      "y": 12,
      "z": -24,
      "name": "Editor_Empty"
    },
    {
      "x": 3,
      "y": 1,
      "z": -23,
      "name": "Editor_Empty"
    },
    {
      "x": 3,
      "y": 2,
      "z": -23,
      "name": "Editor_Empty"
    },
    {
      "x": 3,
      "y": 3,
      "z": -23,
      "name": "Editor_Empty"
    },
    {
      "x": 3,
      "y": 4,
      "z": -23,
      "name": "Editor_Empty"
    },
    {
      "x": 3,
      "y": 5,
      "z": -23,
      "name": "Editor_Empty"
    },
    {
      "x": 3,
      "y": 6,
      "z": -23,
      "name": "Editor_Empty"
    },
    {
      "x": 3,
      "y": 7,
      "z": -23,
      "name": "Editor_Empty"
    },
    {
      "x": 3,
      "y": 8,
      "z": -23,
      "name": "Editor_Empty"
    },
    {
      "x": 3,
      "y": 9,
      "z": -23,
      "name": "Editor_Empty"
    },
    {
      "x": 3,
      "y": 10,
      "z": -23,
      "name": "Editor_Empty"
    },
    {
      "x": 3,
      "y": 11,
      "z": -23,
      "name": "Editor_Empty"
    },
    {
      "x": 3,
      "y": 12,
      "z": -23,
      "name": "Editor_Empty"
    },
    {
      "x": 3,
      "y": 1,
      "z": -22,
      "name": "Editor_Empty"
    },
    {
      "x": 3,
      "y": 2,
      "z": -22,
      "name": "Editor_Empty"
    },
    {
      "x": 3,
      "y": 3,
      "z": -22,
      "name": "Editor_Empty"
    },
    {
      "x": 3,
      "y": 4,
      "z": -22,
      "name": "Editor_Empty"
    },
    {
      "x": 3,
      "y": 5,
      "z": -22,
      "name": "Editor_Empty"
    },
    {
      "x": 3,
      "y": 6,
      "z": -22,
      "name": "Editor_Empty"
    },
    {
      "x": 3,
      "y": 7,
      "z": -22,
      "name": "Editor_Empty"
    },
    {
      "x": 3,
      "y": 8,
      "z": -22,
      "name": "Editor_Empty"
    },
    {
      "x": 3,
      "y": 9,
      "z": -22,
      "name": "Editor_Empty"
    },
    {
      "x": 3,
      "y": 10,
      "z": -22,
      "name": "Editor_Empty"
    },
    {
      "x": 3,
      "y": 11,
      "z": -22,
      "name": "Editor_Empty"
    },
    {
      "x": 3,
      "y": 12,
      "z": -22,
      "name": "Editor_Empty"
    },
    {
      "x": 3,
      "y": 0,
      "z": -21,
      "name": "Rock_Stone_Cobble_Mossy"
    },
    {
      "x": 3,
      "y": 1,
      "z": -21,
      "name": "Rock_Stone_Cobble_Mossy"
    },
    {
      "x": 3,
      "y": 2,
      "z": -21,
      "name": "Rock_Stone"
    },
    {
      "x": 3,
      "y": 3,
      "z": -21,
      "name": "Rock_Stone_Cobble_Mossy"
    },
    {
      "x": 3,
      "y": 4,
      "z": -21,
      "name": "Editor_Empty"
    },
    {
      "x": 3,
      "y": 5,
      "z": -21,
      "name": "Editor_Empty"
    },
    {
      "x": 3,
      "y": 6,
      "z": -21,
      "name": "Editor_Empty"
    },
    {
      "x": 3,
      "y": 7,
      "z": -21,
      "name": "Editor_Empty"
    },
    {
      "x": 3,
      "y": 8,
      "z": -21,
      "name": "Editor_Empty"
    },
    {
      "x": 3,
      "y": 9,
      "z": -21,
      "name": "Editor_Empty"
    },
    {
      "x": 3,
      "y": 10,
      "z": -21,
      "name": "Editor_Empty"
    },
    {
      "x": 3,
      "y": 11,
      "z": -21,
      "name": "Editor_Empty"
    },
    {
      "x": 3,
      "y": 12,
      "z": -21,
      "name": "Editor_Empty"
    },
    {
      "x": 3,
      "y": 0,
      "z": -20,
      "name": "Rock_Stone"
    },
    {
      "x": 3,
      "y": 1,
      "z": -20,
      "name": "Rock_Stone"
    },
    {
      "x": 3,
      "y": 2,
      "z": -20,
      "name": "Rock_Stone"
    },
    {
      "x": 3,
      "y": 3,
      "z": -20,
      "name": "Rock_Stone"
    },
    {
      "x": 3,
      "y": 4,
      "z": -20,
      "name": "Editor_Empty"
    },
    {
      "x": 3,
      "y": 5,
      "z": -20,
      "name": "Editor_Empty"
    },
    {
      "x": 3,
      "y": 6,
      "z": -20,
      "name": "Editor_Empty"
    },
    {
      "x": 3,
      "y": 7,
      "z": -20,
      "name": "Editor_Empty"
    },
    {
      "x": 3,
      "y": 8,
      "z": -20,
      "name": "Editor_Empty"
    },
    {
      "x": 3,
      "y": 9,
      "z": -20,
      "name": "Editor_Empty"
    },
    {
      "x": 3,
      "y": 10,
      "z": -20,
      "name": "Editor_Empty"
    },
    {
      "x": 3,
      "y": 11,
      "z": -20,
      "name": "Editor_Empty"
    },
    {
      "x": 3,
      "y": 12,
      "z": -20,
      "name": "Editor_Empty"
    },
    {
      "x": 3,
      "y": 0,
      "z": -19,
      "name": "Rock_Stone_Cobble"
    },
    {
      "x": 3,
      "y": 1,
      "z": -19,
      "name": "Rock_Stone"
    },
    {
      "x": 3,
      "y": 2,
      "z": -19,
      "name": "Rock_Stone_Cobble"
    },
    {
      "x": 3,
      "y": 3,
      "z": -19,
      "name": "Rock_Stone_Cobble_Mossy"
    },
    {
      "x": 3,
      "y": 4,
      "z": -19,
      "name": "Rock_Stone"
    },
    {
      "x": 3,
      "y": 5,
      "z": -19,
      "name": "Rock_Stone_Cobble_Mossy"
    },
    {
      "x": 3,
      "y": 6,
      "z": -19,
      "name": "Rock_Stone"
    },
    {
      "x": 3,
      "y": 7,
      "z": -19,
      "name": "Editor_Empty"
    },
    {
      "x": 3,
      "y": 8,
      "z": -19,
      "name": "Editor_Empty"
    },
    {
      "x": 3,
      "y": 9,
      "z": -19,
      "name": "Editor_Empty"
    },
    {
      "x": 3,
      "y": 10,
      "z": -19,
      "name": "Editor_Empty"
    },
    {
      "x": 3,
      "y": 11,
      "z": -19,
      "name": "Editor_Empty"
    },
    {
      "x": 3,
      "y": 12,
      "z": -19,
      "name": "Editor_Empty"
    },
    {
      "x": 3,
      "y": 0,
      "z": -18,
      "name": "Rock_Stone_Cobble"
    },
    {
      "x": 3,
      "y": 1,
      "z": -18,
      "name": "Rock_Stone_Cobble"
    },
    {
      "x": 3,
      "y": 2,
      "z": -18,
      "name": "Rock_Stone_Cobble"
    },
    {
      "x": 3,
      "y": 3,
      "z": -18,
      "name": "Rock_Stone_Cobble"
    },
    {
      "x": 3,
      "y": 4,
      "z": -18,
      "name": "Rock_Stone_Cobble_Mossy"
    },
    {
      "x": 3,
      "y": 5,
      "z": -18,
      "name": "Rock_Stone_Cobble_Mossy"
    },
    {
      "x": 3,
      "y": 6,
      "z": -18,
      "name": "Rock_Stone_Cobble_Mossy"
    },
    {
      "x": 3,
      "y": 7,
      "z": -18,
      "name": "Rock_Stone_Cobble"
    },
    {
      "x": 3,
      "y": 8,
      "z": -18,
      "name": "Editor_Empty"
    },
    {
      "x": 3,
      "y": 9,
      "z": -18,
      "name": "Editor_Empty"
    },
    {
      "x": 3,
      "y": 10,
      "z": -18,
      "name": "Editor_Empty"
    },
    {
      "x": 3,
      "y": 11,
      "z": -18,
      "name": "Editor_Empty"
    },
    {
      "x": 3,
      "y": 12,
      "z": -18,
      "name": "Editor_Empty"
    },
    {
      "x": 3,
      "y": 0,
      "z": -17,
      "name": "Rock_Stone_Cobble"
    },
    {
      "x": 3,
      "y": 1,
      "z": -17,
      "name": "Rock_Stone_Cobble_Mossy"
    },
    {
      "x": 3,
      "y": 2,
      "z": -17,
      "name": "Rock_Stone_Cobble"
    },
    {
      "x": 3,
      "y": 3,
      "z": -17,
      "name": "Rock_Stone"
    },
    {
      "x": 3,
      "y": 4,
      "z": -17,
      "name": "Rock_Stone_Cobble_Mossy"
    },
    {
      "x": 3,
      "y": 5,
      "z": -17,
      "name": "Rock_Stone_Cobble"
    },
    {
      "x": 3,
      "y": 6,
      "z": -17,
      "name": "Rock_Stone"
    },
    {
      "x": 3,
      "y": 7,
      "z": -17,
      "name": "Rock_Stone"
    },
    {
      "x": 3,
      "y": 8,
      "z": -17,
      "name": "Editor_Empty"
    },
    {
      "x": 3,
      "y": 9,
      "z": -17,
      "name": "Editor_Empty"
    },
    {
      "x": 3,
      "y": 10,
      "z": -17,
      "name": "Editor_Empty"
    },
    {
      "x": 3,
      "y": 11,
      "z": -17,
      "name": "Editor_Empty"
    },
    {
      "x": 3,
      "y": 12,
      "z": -17,
      "name": "Editor_Empty"
    },
    {
      "x": 3,
      "y": 0,
      "z": -16,
      "name": "Rock_Stone_Cobble_Mossy"
    },
    {
      "x": 3,
      "y": 1,
      "z": -16,
      "name": "Rock_Stone_Cobble"
    },
    {
      "x": 3,
      "y": 2,
      "z": -16,
      "name": "Rock_Stone_Cobble_Mossy"
    },
    {
      "x": 3,
      "y": 3,
      "z": -16,
      "name": "Rock_Stone_Cobble"
    },
    {
      "x": 3,
      "y": 4,
      "z": -16,
      "name": "Rock_Stone_Cobble_Mossy"
    },
    {
      "x": 3,
      "y": 5,
      "z": -16,
      "name": "Rock_Stone_Cobble"
    },
    {
      "x": 3,
      "y": 6,
      "z": -16,
      "name": "Rock_Stone_Cobble"
    },
    {
      "x": 3,
      "y": 7,
      "z": -16,
      "name": "Rock_Stone_Cobble"
    },
    {
      "x": 3,
      "y": 8,
      "z": -16,
      "name": "Editor_Empty"
    },
    {
      "x": 3,
      "y": 9,
      "z": -16,
      "name": "Editor_Empty"
    },
    {
      "x": 3,
      "y": 10,
      "z": -16,
      "name": "Editor_Empty"
    },
    {
      "x": 3,
      "y": 11,
      "z": -16,
      "name": "Editor_Empty"
    },
    {
      "x": 3,
      "y": 12,
      "z": -16,
      "name": "Editor_Empty"
    },
    {
      "x": 3,
      "y": 0,
      "z": -15,
      "name": "Rock_Stone"
    },
    {
      "x": 3,
      "y": 1,
      "z": -15,
      "name": "Rock_Stone_Cobble_Mossy"
    },
    {
      "x": 3,
      "y": 2,
      "z": -15,
      "name": "Rock_Stone_Cobble"
    },
    {
      "x": 3,
      "y": 3,
      "z": -15,
      "name": "Rock_Stone"
    },
    {
      "x": 3,
      "y": 4,
      "z": -15,
      "name": "Rock_Stone_Cobble_Mossy"
    },
    {
      "x": 3,
      "y": 5,
      "z": -15,
      "name": "Rock_Stone"
    },
    {
      "x": 3,
      "y": 6,
      "z": -15,
      "name": "Rock_Stone_Cobble"
    },
    {
      "x": 3,
      "y": 7,
      "z": -15,
      "name": "Rock_Stone"
    },
    {
      "x": 3,
      "y": 8,
      "z": -15,
      "name": "Editor_Empty"
    },
    {
      "x": 3,
      "y": 9,
      "z": -15,
      "name": "Editor_Empty"
    },
    {
      "x": 3,
      "y": 10,
      "z": -15,
      "name": "Editor_Empty"
    },
    {
      "x": 3,
      "y": 11,
      "z": -15,
      "name": "Editor_Empty"
    },
    {
      "x": 3,
      "y": 12,
      "z": -15,
      "name": "Editor_Empty"
    },
    {
      "x": 3,
      "y": 0,
      "z": -14,
      "name": "Rock_Stone_Cobble_Mossy"
    },
    {
      "x": 3,
      "y": 1,
      "z": -14,
      "name": "Rock_Stone_Cobble_Mossy"
    },
    {
      "x": 3,
      "y": 2,
      "z": -14,
      "name": "Rock_Stone"
    },
    {
      "x": 3,
      "y": 3,
      "z": -14,
      "name": "Rock_Stone"
    },
    {
      "x": 3,
      "y": 4,
      "z": -14,
      "name": "Rock_Stone"
    },
    {
      "x": 3,
      "y": 5,
      "z": -14,
      "name": "Rock_Stone_Cobble"
    },
    {
      "x": 3,
      "y": 6,
      "z": -14,
      "name": "Rock_Stone_Cobble"
    },
    {
      "x": 3,
      "y": 7,
      "z": -14,
      "name": "Editor_Empty"
    },
    {
      "x": 3,
      "y": 8,
      "z": -14,
      "name": "Editor_Empty"
    },
    {
      "x": 3,
      "y": 9,
      "z": -14,
      "name": "Editor_Empty"
    },
    {
      "x": 3,
      "y": 10,
      "z": -14,
      "name": "Editor_Empty"
    },
    {
      "x": 3,
      "y": 11,
      "z": -14,
      "name": "Editor_Empty"
    },
    {
      "x": 3,
      "y": 12,
      "z": -14,
      "name": "Editor_Empty"
    },
    {
      "x": 3,
      "y": 0,
      "z": -13,
      "name": "Rock_Stone"
    },
    {
      "x": 3,
      "y": 1,
      "z": -13,
      "name": "Rock_Stone"
    },
    {
      "x": 3,
      "y": 2,
      "z": -13,
      "name": "Rock_Stone"
    },
    {
      "x": 3,
      "y": 3,
      "z": -13,
      "name": "Rock_Stone_Cobble_Mossy"
    },
    {
      "x": 3,
      "y": 4,
      "z": -13,
      "name": "Editor_Empty"
    },
    {
      "x": 3,
      "y": 5,
      "z": -13,
      "name": "Editor_Empty"
    },
    {
      "x": 3,
      "y": 6,
      "z": -13,
      "name": "Editor_Empty"
    },
    {
      "x": 3,
      "y": 7,
      "z": -13,
      "name": "Editor_Empty"
    },
    {
      "x": 3,
      "y": 8,
      "z": -13,
      "name": "Editor_Empty"
    },
    {
      "x": 3,
      "y": 9,
      "z": -13,
      "name": "Editor_Empty"
    },
    {
      "x": 3,
      "y": 10,
      "z": -13,
      "name": "Editor_Empty"
    },
    {
      "x": 3,
      "y": 11,
      "z": -13,
      "name": "Editor_Empty"
    },
    {
      "x": 3,
      "y": 12,
      "z": -13,
      "name": "Editor_Empty"
    },
    {
      "x": 3,
      "y": 0,
      "z": -12,
      "name": "Rock_Stone"
    },
    {
      "x": 3,
      "y": 1,
      "z": -12,
      "name": "Rock_Stone_Cobble"
    },
    {
      "x": 3,
      "y": 2,
      "z": -12,
      "name": "Rock_Stone_Cobble"
    },
    {
      "x": 3,
      "y": 3,
      "z": -12,
      "name": "Rock_Stone"
    },
    {
      "x": 3,
      "y": 4,
      "z": -12,
      "name": "Editor_Empty"
    },
    {
      "x": 3,
      "y": 5,
      "z": -12,
      "name": "Editor_Empty"
    },
    {
      "x": 3,
      "y": 6,
      "z": -12,
      "name": "Editor_Empty"
    },
    {
      "x": 3,
      "y": 7,
      "z": -12,
      "name": "Editor_Empty"
    },
    {
      "x": 3,
      "y": 8,
      "z": -12,
      "name": "Editor_Empty"
    },
    {
      "x": 3,
      "y": 9,
      "z": -12,
      "name": "Editor_Empty"
    },
    {
      "x": 3,
      "y": 10,
      "z": -12,
      "name": "Editor_Empty"
    },
    {
      "x": 3,
      "y": 11,
      "z": -12,
      "name": "Editor_Empty"
    },
    {
      "x": 3,
      "y": 12,
      "z": -12,
      "name": "Editor_Empty"
    },
    {
      "x": 3,
      "y": 0,
      "z": -11,
      "name": "Rock_Stone_Cobble_Mossy"
    },
    {
      "x": 3,
      "y": 1,
      "z": -11,
      "name": "Rock_Stone"
    },
    {
      "x": 3,
      "y": 2,
      "z": -11,
      "name": "Rock_Stone"
    },
    {
      "x": 3,
      "y": 3,
      "z": -11,
      "name": "Editor_Empty"
    },
    {
      "x": 3,
      "y": 4,
      "z": -11,
      "name": "Editor_Empty"
    },
    {
      "x": 3,
      "y": 5,
      "z": -11,
      "name": "Editor_Empty"
    },
    {
      "x": 3,
      "y": 6,
      "z": -11,
      "name": "Editor_Empty"
    },
    {
      "x": 3,
      "y": 7,
      "z": -11,
      "name": "Editor_Empty"
    },
    {
      "x": 3,
      "y": 8,
      "z": -11,
      "name": "Editor_Empty"
    },
    {
      "x": 3,
      "y": 9,
      "z": -11,
      "name": "Editor_Empty"
    },
    {
      "x": 3,
      "y": 10,
      "z": -11,
      "name": "Editor_Empty"
    },
    {
      "x": 3,
      "y": 11,
      "z": -11,
      "name": "Editor_Empty"
    },
    {
      "x": 3,
      "y": 12,
      "z": -11,
      "name": "Editor_Empty"
    },
    {
      "x": 3,
      "y": 0,
      "z": -10,
      "name": "Rock_Stone_Cobble"
    },
    {
      "x": 3,
      "y": 1,
      "z": -10,
      "name": "Rock_Stone_Cobble"
    },
    {
      "x": 3,
      "y": 2,
      "z": -10,
      "name": "Rock_Stone_Cobble_Mossy"
    },
    {
      "x": 3,
      "y": 3,
      "z": -10,
      "name": "Editor_Empty"
    },
    {
      "x": 3,
      "y": 4,
      "z": -10,
      "name": "Editor_Empty"
    },
    {
      "x": 3,
      "y": 5,
      "z": -10,
      "name": "Editor_Empty"
    },
    {
      "x": 3,
      "y": 6,
      "z": -10,
      "name": "Editor_Empty"
    },
    {
      "x": 3,
      "y": 7,
      "z": -10,
      "name": "Editor_Empty"
    },
    {
      "x": 3,
      "y": 8,
      "z": -10,
      "name": "Editor_Empty"
    },
    {
      "x": 3,
      "y": 9,
      "z": -10,
      "name": "Editor_Empty"
    },
    {
      "x": 3,
      "y": 10,
      "z": -10,
      "name": "Editor_Empty"
    },
    {
      "x": 3,
      "y": 11,
      "z": -10,
      "name": "Editor_Empty"
    },
    {
      "x": 3,
      "y": 12,
      "z": -10,
      "name": "Editor_Empty"
    },
    {
      "x": 3,
      "y": 0,
      "z": -9,
      "name": "Rock_Stone"
    },
    {
      "x": 3,
      "y": 1,
      "z": -9,
      "name": "Rock_Stone_Cobble"
    },
    {
      "x": 3,
      "y": 2,
      "z": -9,
      "name": "Rock_Stone_Cobble"
    },
    {
      "x": 3,
      "y": 3,
      "z": -9,
      "name": "Editor_Empty"
    },
    {
      "x": 3,
      "y": 4,
      "z": -9,
      "name": "Editor_Empty"
    },
    {
      "x": 3,
      "y": 5,
      "z": -9,
      "name": "Editor_Empty"
    },
    {
      "x": 3,
      "y": 6,
      "z": -9,
      "name": "Editor_Empty"
    },
    {
      "x": 3,
      "y": 7,
      "z": -9,
      "name": "Editor_Empty"
    },
    {
      "x": 3,
      "y": 8,
      "z": -9,
      "name": "Editor_Empty"
    },
    {
      "x": 3,
      "y": 9,
      "z": -9,
      "name": "Editor_Empty"
    },
    {
      "x": 3,
      "y": 10,
      "z": -9,
      "name": "Editor_Empty"
    },
    {
      "x": 3,
      "y": 11,
      "z": -9,
      "name": "Editor_Empty"
    },
    {
      "x": 3,
      "y": 12,
      "z": -9,
      "name": "Editor_Empty"
    },
    {
      "x": 3,
      "y": 0,
      "z": -8,
      "name": "Rock_Stone"
    },
    {
      "x": 3,
      "y": 1,
      "z": -8,
      "name": "Rock_Stone_Cobble_Mossy"
    },
    {
      "x": 3,
      "y": 2,
      "z": -8,
      "name": "Rock_Stone_Cobble"
    },
    {
      "x": 3,
      "y": 3,
      "z": -8,
      "name": "Rock_Stone_Cobble"
    },
    {
      "x": 3,
      "y": 4,
      "z": -8,
      "name": "Editor_Empty"
    },
    {
      "x": 3,
      "y": 5,
      "z": -8,
      "name": "Editor_Empty"
    },
    {
      "x": 3,
      "y": 6,
      "z": -8,
      "name": "Editor_Empty"
    },
    {
      "x": 3,
      "y": 7,
      "z": -8,
      "name": "Editor_Empty"
    },
    {
      "x": 3,
      "y": 8,
      "z": -8,
      "name": "Editor_Empty"
    },
    {
      "x": 3,
      "y": 9,
      "z": -8,
      "name": "Editor_Empty"
    },
    {
      "x": 3,
      "y": 10,
      "z": -8,
      "name": "Editor_Empty"
    },
    {
      "x": 3,
      "y": 11,
      "z": -8,
      "name": "Editor_Empty"
    },
    {
      "x": 3,
      "y": 12,
      "z": -8,
      "name": "Editor_Empty"
    },
    {
      "x": 3,
      "y": 0,
      "z": -7,
      "name": "Rock_Stone"
    },
    {
      "x": 3,
      "y": 1,
      "z": -7,
      "name": "Rock_Stone_Cobble_Mossy"
    },
    {
      "x": 3,
      "y": 2,
      "z": -7,
      "name": "Rock_Stone_Cobble_Mossy"
    },
    {
      "x": 3,
      "y": 3,
      "z": -7,
      "name": "Rock_Stone"
    },
    {
      "x": 3,
      "y": 4,
      "z": -7,
      "name": "Editor_Empty"
    },
    {
      "x": 3,
      "y": 5,
      "z": -7,
      "name": "Editor_Empty"
    },
    {
      "x": 3,
      "y": 6,
      "z": -7,
      "name": "Editor_Empty"
    },
    {
      "x": 3,
      "y": 7,
      "z": -7,
      "name": "Editor_Empty"
    },
    {
      "x": 3,
      "y": 8,
      "z": -7,
      "name": "Editor_Empty"
    },
    {
      "x": 3,
      "y": 9,
      "z": -7,
      "name": "Editor_Empty"
    },
    {
      "x": 3,
      "y": 10,
      "z": -7,
      "name": "Editor_Empty"
    },
    {
      "x": 3,
      "y": 11,
      "z": -7,
      "name": "Editor_Empty"
    },
    {
      "x": 3,
      "y": 12,
      "z": -7,
      "name": "Editor_Empty"
    },
    {
      "x": 3,
      "y": 0,
      "z": -6,
      "name": "Rock_Stone_Cobble"
    },
    {
      "x": 3,
      "y": 1,
      "z": -6,
      "name": "Rock_Stone_Cobble"
    },
    {
      "x": 3,
      "y": 2,
      "z": -6,
      "name": "Rock_Stone_Cobble"
    },
    {
      "x": 3,
      "y": 3,
      "z": -6,
      "name": "Rock_Stone"
    },
    {
      "x": 3,
      "y": 4,
      "z": -6,
      "name": "Editor_Empty"
    },
    {
      "x": 3,
      "y": 5,
      "z": -6,
      "name": "Editor_Empty"
    },
    {
      "x": 3,
      "y": 6,
      "z": -6,
      "name": "Editor_Empty"
    },
    {
      "x": 3,
      "y": 7,
      "z": -6,
      "name": "Editor_Empty"
    },
    {
      "x": 3,
      "y": 8,
      "z": -6,
      "name": "Editor_Empty"
    },
    {
      "x": 3,
      "y": 9,
      "z": -6,
      "name": "Editor_Empty"
    },
    {
      "x": 3,
      "y": 10,
      "z": -6,
      "name": "Editor_Empty"
    },
    {
      "x": 3,
      "y": 11,
      "z": -6,
      "name": "Editor_Empty"
    },
    {
      "x": 3,
      "y": 12,
      "z": -6,
      "name": "Editor_Empty"
    },
    {
      "x": 3,
      "y": 0,
      "z": -5,
      "name": "Rock_Stone"
    },
    {
      "x": 3,
      "y": 1,
      "z": -5,
      "name": "Rock_Stone"
    },
    {
      "x": 3,
      "y": 2,
      "z": -5,
      "name": "Rock_Stone_Cobble_Mossy"
    },
    {
      "x": 3,
      "y": 3,
      "z": -5,
      "name": "Rock_Stone_Cobble"
    },
    {
      "x": 3,
      "y": 4,
      "z": -5,
      "name": "Editor_Empty"
    },
    {
      "x": 3,
      "y": 5,
      "z": -5,
      "name": "Editor_Empty"
    },
    {
      "x": 3,
      "y": 6,
      "z": -5,
      "name": "Editor_Empty"
    },
    {
      "x": 3,
      "y": 7,
      "z": -5,
      "name": "Editor_Empty"
    },
    {
      "x": 3,
      "y": 8,
      "z": -5,
      "name": "Editor_Empty"
    },
    {
      "x": 3,
      "y": 9,
      "z": -5,
      "name": "Editor_Empty"
    },
    {
      "x": 3,
      "y": 10,
      "z": -5,
      "name": "Editor_Empty"
    },
    {
      "x": 3,
      "y": 11,
      "z": -5,
      "name": "Editor_Empty"
    },
    {
      "x": 3,
      "y": 12,
      "z": -5,
      "name": "Editor_Empty"
    },
    {
      "x": 3,
      "y": 0,
      "z": -4,
      "name": "Rock_Stone_Cobble_Mossy"
    },
    {
      "x": 3,
      "y": 1,
      "z": -4,
      "name": "Rock_Stone"
    },
    {
      "x": 3,
      "y": 2,
      "z": -4,
      "name": "Rock_Stone_Cobble"
    },
    {
      "x": 3,
      "y": 3,
      "z": -4,
      "name": "Editor_Empty"
    },
    {
      "x": 3,
      "y": 4,
      "z": -4,
      "name": "Editor_Empty"
    },
    {
      "x": 3,
      "y": 5,
      "z": -4,
      "name": "Editor_Empty"
    },
    {
      "x": 3,
      "y": 6,
      "z": -4,
      "name": "Editor_Empty"
    },
    {
      "x": 3,
      "y": 7,
      "z": -4,
      "name": "Editor_Empty"
    },
    {
      "x": 3,
      "y": 8,
      "z": -4,
      "name": "Editor_Empty"
    },
    {
      "x": 3,
      "y": 9,
      "z": -4,
      "name": "Editor_Empty"
    },
    {
      "x": 3,
      "y": 10,
      "z": -4,
      "name": "Editor_Empty"
    },
    {
      "x": 3,
      "y": 11,
      "z": -4,
      "name": "Editor_Empty"
    },
    {
      "x": 3,
      "y": 12,
      "z": -4,
      "name": "Editor_Empty"
    },
    {
      "x": 3,
      "y": 1,
      "z": -3,
      "name": "Editor_Empty"
    },
    {
      "x": 3,
      "y": 2,
      "z": -3,
      "name": "Editor_Empty"
    },
    {
      "x": 3,
      "y": 3,
      "z": -3,
      "name": "Editor_Empty"
    },
    {
      "x": 3,
      "y": 4,
      "z": -3,
      "name": "Editor_Empty"
    },
    {
      "x": 3,
      "y": 5,
      "z": -3,
      "name": "Editor_Empty"
    },
    {
      "x": 3,
      "y": 6,
      "z": -3,
      "name": "Editor_Empty"
    },
    {
      "x": 3,
      "y": 7,
      "z": -3,
      "name": "Editor_Empty"
    },
    {
      "x": 3,
      "y": 8,
      "z": -3,
      "name": "Editor_Empty"
    },
    {
      "x": 3,
      "y": 9,
      "z": -3,
      "name": "Editor_Empty"
    },
    {
      "x": 3,
      "y": 10,
      "z": -3,
      "name": "Editor_Empty"
    },
    {
      "x": 3,
      "y": 11,
      "z": -3,
      "name": "Editor_Empty"
    },
    {
      "x": 3,
      "y": 12,
      "z": -3,
      "name": "Editor_Empty"
    },
    {
      "x": 3,
      "y": 1,
      "z": -2,
      "name": "Editor_Empty"
    },
    {
      "x": 3,
      "y": 2,
      "z": -2,
      "name": "Editor_Empty"
    },
    {
      "x": 3,
      "y": 3,
      "z": -2,
      "name": "Editor_Empty"
    },
    {
      "x": 3,
      "y": 4,
      "z": -2,
      "name": "Editor_Empty"
    },
    {
      "x": 3,
      "y": 5,
      "z": -2,
      "name": "Editor_Empty"
    },
    {
      "x": 3,
      "y": 6,
      "z": -2,
      "name": "Editor_Empty"
    },
    {
      "x": 3,
      "y": 7,
      "z": -2,
      "name": "Editor_Empty"
    },
    {
      "x": 3,
      "y": 8,
      "z": -2,
      "name": "Editor_Empty"
    },
    {
      "x": 3,
      "y": 9,
      "z": -2,
      "name": "Editor_Empty"
    },
    {
      "x": 3,
      "y": 10,
      "z": -2,
      "name": "Editor_Empty"
    },
    {
      "x": 3,
      "y": 11,
      "z": -2,
      "name": "Editor_Empty"
    },
    {
      "x": 3,
      "y": 12,
      "z": -2,
      "name": "Editor_Empty"
    },
    {
      "x": 3,
      "y": 1,
      "z": -1,
      "name": "Editor_Empty"
    },
    {
      "x": 3,
      "y": 2,
      "z": -1,
      "name": "Editor_Empty"
    },
    {
      "x": 3,
      "y": 3,
      "z": -1,
      "name": "Editor_Empty"
    },
    {
      "x": 3,
      "y": 4,
      "z": -1,
      "name": "Editor_Empty"
    },
    {
      "x": 3,
      "y": 5,
      "z": -1,
      "name": "Editor_Empty"
    },
    {
      "x": 3,
      "y": 6,
      "z": -1,
      "name": "Editor_Empty"
    },
    {
      "x": 3,
      "y": 7,
      "z": -1,
      "name": "Editor_Empty"
    },
    {
      "x": 3,
      "y": 8,
      "z": -1,
      "name": "Editor_Empty"
    },
    {
      "x": 3,
      "y": 9,
      "z": -1,
      "name": "Editor_Empty"
    },
    {
      "x": 3,
      "y": 10,
      "z": -1,
      "name": "Editor_Empty"
    },
    {
      "x": 3,
      "y": 11,
      "z": -1,
      "name": "Editor_Empty"
    },
    {
      "x": 3,
      "y": 12,
      "z": -1,
      "name": "Editor_Empty"
    },
    {
      "x": 4,
      "y": 1,
      "z": -29,
      "name": "Editor_Empty"
    },
    {
      "x": 4,
      "y": 2,
      "z": -29,
      "name": "Editor_Empty"
    },
    {
      "x": 4,
      "y": 3,
      "z": -29,
      "name": "Editor_Empty"
    },
    {
      "x": 4,
      "y": 4,
      "z": -29,
      "name": "Editor_Empty"
    },
    {
      "x": 4,
      "y": 5,
      "z": -29,
      "name": "Editor_Empty"
    },
    {
      "x": 4,
      "y": 6,
      "z": -29,
      "name": "Editor_Empty"
    },
    {
      "x": 4,
      "y": 7,
      "z": -29,
      "name": "Editor_Empty"
    },
    {
      "x": 4,
      "y": 8,
      "z": -29,
      "name": "Editor_Empty"
    },
    {
      "x": 4,
      "y": 9,
      "z": -29,
      "name": "Editor_Empty"
    },
    {
      "x": 4,
      "y": 10,
      "z": -29,
      "name": "Editor_Empty"
    },
    {
      "x": 4,
      "y": 11,
      "z": -29,
      "name": "Editor_Empty"
    },
    {
      "x": 4,
      "y": 12,
      "z": -29,
      "name": "Editor_Empty"
    },
    {
      "x": 4,
      "y": 1,
      "z": -28,
      "name": "Editor_Empty"
    },
    {
      "x": 4,
      "y": 2,
      "z": -28,
      "name": "Editor_Empty"
    },
    {
      "x": 4,
      "y": 3,
      "z": -28,
      "name": "Editor_Empty"
    },
    {
      "x": 4,
      "y": 4,
      "z": -28,
      "name": "Editor_Empty"
    },
    {
      "x": 4,
      "y": 5,
      "z": -28,
      "name": "Editor_Empty"
    },
    {
      "x": 4,
      "y": 6,
      "z": -28,
      "name": "Editor_Empty"
    },
    {
      "x": 4,
      "y": 7,
      "z": -28,
      "name": "Editor_Empty"
    },
    {
      "x": 4,
      "y": 8,
      "z": -28,
      "name": "Editor_Empty"
    },
    {
      "x": 4,
      "y": 9,
      "z": -28,
      "name": "Editor_Empty"
    },
    {
      "x": 4,
      "y": 10,
      "z": -28,
      "name": "Editor_Empty"
    },
    {
      "x": 4,
      "y": 11,
      "z": -28,
      "name": "Editor_Empty"
    },
    {
      "x": 4,
      "y": 12,
      "z": -28,
      "name": "Editor_Empty"
    },
    {
      "x": 4,
      "y": 1,
      "z": -27,
      "name": "Editor_Empty"
    },
    {
      "x": 4,
      "y": 2,
      "z": -27,
      "name": "Editor_Empty"
    },
    {
      "x": 4,
      "y": 3,
      "z": -27,
      "name": "Editor_Empty"
    },
    {
      "x": 4,
      "y": 4,
      "z": -27,
      "name": "Editor_Empty"
    },
    {
      "x": 4,
      "y": 5,
      "z": -27,
      "name": "Editor_Empty"
    },
    {
      "x": 4,
      "y": 6,
      "z": -27,
      "name": "Editor_Empty"
    },
    {
      "x": 4,
      "y": 7,
      "z": -27,
      "name": "Editor_Empty"
    },
    {
      "x": 4,
      "y": 8,
      "z": -27,
      "name": "Editor_Empty"
    },
    {
      "x": 4,
      "y": 9,
      "z": -27,
      "name": "Editor_Empty"
    },
    {
      "x": 4,
      "y": 10,
      "z": -27,
      "name": "Editor_Empty"
    },
    {
      "x": 4,
      "y": 11,
      "z": -27,
      "name": "Editor_Empty"
    },
    {
      "x": 4,
      "y": 12,
      "z": -27,
      "name": "Editor_Empty"
    },
    {
      "x": 4,
      "y": 1,
      "z": -26,
      "name": "Editor_Empty"
    },
    {
      "x": 4,
      "y": 2,
      "z": -26,
      "name": "Editor_Empty"
    },
    {
      "x": 4,
      "y": 3,
      "z": -26,
      "name": "Editor_Empty"
    },
    {
      "x": 4,
      "y": 4,
      "z": -26,
      "name": "Editor_Empty"
    },
    {
      "x": 4,
      "y": 5,
      "z": -26,
      "name": "Editor_Empty"
    },
    {
      "x": 4,
      "y": 6,
      "z": -26,
      "name": "Editor_Empty"
    },
    {
      "x": 4,
      "y": 7,
      "z": -26,
      "name": "Editor_Empty"
    },
    {
      "x": 4,
      "y": 8,
      "z": -26,
      "name": "Editor_Empty"
    },
    {
      "x": 4,
      "y": 9,
      "z": -26,
      "name": "Editor_Empty"
    },
    {
      "x": 4,
      "y": 10,
      "z": -26,
      "name": "Editor_Empty"
    },
    {
      "x": 4,
      "y": 11,
      "z": -26,
      "name": "Editor_Empty"
    },
    {
      "x": 4,
      "y": 12,
      "z": -26,
      "name": "Editor_Empty"
    },
    {
      "x": 4,
      "y": 1,
      "z": -25,
      "name": "Editor_Empty"
    },
    {
      "x": 4,
      "y": 2,
      "z": -25,
      "name": "Editor_Empty"
    },
    {
      "x": 4,
      "y": 3,
      "z": -25,
      "name": "Editor_Empty"
    },
    {
      "x": 4,
      "y": 4,
      "z": -25,
      "name": "Editor_Empty"
    },
    {
      "x": 4,
      "y": 5,
      "z": -25,
      "name": "Editor_Empty"
    },
    {
      "x": 4,
      "y": 6,
      "z": -25,
      "name": "Editor_Empty"
    },
    {
      "x": 4,
      "y": 7,
      "z": -25,
      "name": "Editor_Empty"
    },
    {
      "x": 4,
      "y": 8,
      "z": -25,
      "name": "Editor_Empty"
    },
    {
      "x": 4,
      "y": 9,
      "z": -25,
      "name": "Editor_Empty"
    },
    {
      "x": 4,
      "y": 10,
      "z": -25,
      "name": "Editor_Empty"
    },
    {
      "x": 4,
      "y": 11,
      "z": -25,
      "name": "Editor_Empty"
    },
    {
      "x": 4,
      "y": 12,
      "z": -25,
      "name": "Editor_Empty"
    },
    {
      "x": 4,
      "y": 1,
      "z": -24,
      "name": "Editor_Empty"
    },
    {
      "x": 4,
      "y": 2,
      "z": -24,
      "name": "Editor_Empty"
    },
    {
      "x": 4,
      "y": 3,
      "z": -24,
      "name": "Editor_Empty"
    },
    {
      "x": 4,
      "y": 4,
      "z": -24,
      "name": "Editor_Empty"
    },
    {
      "x": 4,
      "y": 5,
      "z": -24,
      "name": "Editor_Empty"
    },
    {
      "x": 4,
      "y": 6,
      "z": -24,
      "name": "Editor_Empty"
    },
    {
      "x": 4,
      "y": 7,
      "z": -24,
      "name": "Editor_Empty"
    },
    {
      "x": 4,
      "y": 8,
      "z": -24,
      "name": "Editor_Empty"
    },
    {
      "x": 4,
      "y": 9,
      "z": -24,
      "name": "Editor_Empty"
    },
    {
      "x": 4,
      "y": 10,
      "z": -24,
      "name": "Editor_Empty"
    },
    {
      "x": 4,
      "y": 11,
      "z": -24,
      "name": "Editor_Empty"
    },
    {
      "x": 4,
      "y": 12,
      "z": -24,
      "name": "Editor_Empty"
    },
    {
      "x": 4,
      "y": 0,
      "z": -23,
      "name": "Rock_Stone_Cobble"
    },
    {
      "x": 4,
      "y": 1,
      "z": -23,
      "name": "Editor_Empty"
    },
    {
      "x": 4,
      "y": 2,
      "z": -23,
      "name": "Editor_Empty"
    },
    {
      "x": 4,
      "y": 3,
      "z": -23,
      "name": "Editor_Empty"
    },
    {
      "x": 4,
      "y": 4,
      "z": -23,
      "name": "Editor_Empty"
