{
  "version": 8,
  "blockIdVersion": 11,
  "anchorX": 0,
  "anchorY": 0,
  "anchorZ": 0,
  "blocks": [
    {
      "x": 1,
      "y": 2,
      "z": -12,
      "name": "Editor_Empty"
    },
    {
      "x": 1,
      "y": 3,
      "z": -12,
      "name": "Editor_Empty"
    },
    {
      "x": 1,
      "y": 4,
      "z": -12,
      "name": "Editor_Empty"
    },
    {
      "x": 1,
      "y": 5,
      "z": -12,
      "name": "Editor_Empty"
    },
    {
      "x": 1,
      "y": 6,
      "z": -12,
      "name": "Editor_Empty"
    },
    {
      "x": 1,
      "y": 7,
      "z": -12,
      "name": "Editor_Empty"
    },
    {
      "x": 1,
      "y": 8,
      "z": -12,
      "name": "Editor_Empty"
    },
    {
      "x": 1,
      "y": 9,
      "z": -12,
      "name": "Editor_Empty"
    },
    {
      "x": 1,
      "y": 10,
      "z": -12,
      "name": "Editor_Empty"
    },
    {
      "x": 1,
      "y": 11,
      "z": -12,
      "name": "Editor_Empty"
    },
    {
      "x": 1,
      "y": 12,
      "z": -12,
      "name": "Editor_Empty"
    },
    {
      "x": 1,
      "y": 2,
      "z": -11,
      "name": "Editor_Empty"
    },
    {
      "x": 1,
      "y": 3,
      "z": -11,
      "name": "Editor_Empty"
    },
    {
      "x": 1,
      "y": 4,
      "z": -11,
      "name": "Editor_Empty"
    },
    {
      "x": 1,
      "y": 5,
      "z": -11,
      "name": "Editor_Empty"
    },
    {
      "x": 1,
      "y": 6,
      "z": -11,
      "name": "Editor_Empty"
    },
    {
      "x": 1,
      "y": 7,
      "z": -11,
      "name": "Editor_Empty"
    },
    {
      "x": 1,
      "y": 8,
      "z": -11,
      "name": "Editor_Empty"
    },
    {
      "x": 1,
      "y": 9,
      "z": -11,
      "name": "Editor_Empty"
    },
    {
      "x": 1,
      "y": 10,
      "z": -11,
      "name": "Editor_Empty"
    },
    {
      "x": 1,
      "y": 11,
      "z": -11,
      "name": "Editor_Empty"
    },
    {
      "x": 1,
      "y": 12,
      "z": -11,
      "name": "Editor_Empty"
    },
    {
      "x": 1,
      "y": 1,
      "z": -10,
      "name": "Rock_Stone_Brick_Smooth"
    },
    {
      "x": 1,
      "y": 2,
      "z": -10,
      "name": "Editor_Empty"
    },
    {
      "x": 1,
      "y": 3,
      "z": -10,
      "name": "Editor_Empty"
    },
    {
      "x": 1,
      "y": 4,
      "z": -10,
      "name": "Editor_Empty"
    },
    {
      "x": 1,
      "y": 5,
      "z": -10,
      "name": "Editor_Empty"
    },
    {
      "x": 1,
      "y": 6,
      "z": -10,
      "name": "Editor_Empty"
    },
    {
      "x": 1,
      "y": 7,
      "z": -10,
      "name": "Editor_Empty"
    },
    {
      "x": 1,
      "y": 8,
      "z": -10,
      "name": "Editor_Empty"
    },
    {
      "x": 1,
      "y": 9,
      "z": -10,
      "name": "Editor_Empty"
    },
    {
      "x": 1,
      "y": 10,
      "z": -10,
      "name": "Editor_Empty"
    },
    {
      "x": 1,
      "y": 11,
      "z": -10,
      "name": "Editor_Empty"
    },
    {
      "x": 1,
      "y": 12,
      "z": -10,
      "name": "Editor_Empty"
    },
    {
      "x": 1,
      "y": 1,
      "z": -9,
      "name": "Rock_Stone_Brick_Smooth"
    },
    {
      "x": 1,
      "y": 2,
      "z": -9,
      "name": "Editor_Empty"
    },
    {
      "x": 1,
      "y": 3,
      "z": -9,
      "name": "Editor_Empty"
    },
    {
      "x": 1,
      "y": 4,
      "z": -9,
      "name": "Editor_Empty"
    },
    {
      "x": 1,
      "y": 5,
      "z": -9,
      "name": "Editor_Empty"
    },
    {
      "x": 1,
      "y": 6,
      "z": -9,
      "name": "Editor_Empty"
    },
    {
      "x": 1,
      "y": 7,
      "z": -9,
      "name": "Editor_Empty"
    },
    {
      "x": 1,
      "y": 8,
      "z": -9,
      "name": "Editor_Empty"
    },
    {
      "x": 1,
      "y": 9,
      "z": -9,
      "name": "Editor_Empty"
    },
    {
      "x": 1,
      "y": 10,
      "z": -9,
      "name": "Editor_Empty"
    },
    {
      "x": 1,
      "y": 11,
      "z": -9,
      "name": "Editor_Empty"
    },
    {
      "x": 1,
      "y": 12,
      "z": -9,
      "name": "Editor_Empty"
    },
    {
      "x": 1,
      "y": 1,
      "z": -8,
      "name": "Rock_Stone_Brick_Smooth"
    },
    {
      "x": 1,
      "y": 2,
      "z": -8,
      "name": "Editor_Empty"
    },
    {
      "x": 1,
      "y": 3,
      "z": -8,
      "name": "Editor_Empty"
    },
    {
      "x": 1,
      "y": 4,
      "z": -8,
      "name": "Editor_Empty"
    },
    {
      "x": 1,
      "y": 5,
      "z": -8,
      "name": "Editor_Empty"
    },
    {
      "x": 1,
      "y": 6,
      "z": -8,
      "name": "Editor_Empty"
    },
    {
      "x": 1,
      "y": 7,
      "z": -8,
      "name": "Editor_Empty"
    },
    {
      "x": 1,
      "y": 8,
      "z": -8,
      "name": "Editor_Empty"
    },
    {
      "x": 1,
      "y": 9,
      "z": -8,
      "name": "Editor_Empty"
    },
    {
      "x": 1,
      "y": 10,
      "z": -8,
      "name": "Editor_Empty"
    },
    {
      "x": 1,
      "y": 11,
      "z": -8,
      "name": "Editor_Empty"
    },
    {
      "x": 1,
      "y": 12,
      "z": -8,
      "name": "Editor_Empty"
    },
    {
      "x": 1,
      "y": 1,
      "z": -7,
      "name": "Rock_Stone_Brick_Smooth"
    },
    {
      "x": 1,
      "y": 2,
      "z": -7,
      "name": "Editor_Empty"
    },
    {
      "x": 1,
      "y": 3,
      "z": -7,
      "name": "Editor_Empty"
    },
    {
      "x": 1,
      "y": 4,
      "z": -7,
      "name": "Editor_Empty"
    },
    {
      "x": 1,
      "y": 5,
      "z": -7,
      "name": "Editor_Empty"
    },
    {
      "x": 1,
      "y": 6,
      "z": -7,
      "name": "Editor_Empty"
    },
    {
      "x": 1,
      "y": 7,
      "z": -7,
      "name": "Editor_Empty"
    },
    {
      "x": 1,
      "y": 8,
      "z": -7,
      "name": "Editor_Empty"
    },
    {
      "x": 1,
      "y": 9,
      "z": -7,
      "name": "Editor_Empty"
    },
    {
      "x": 1,
      "y": 10,
      "z": -7,
      "name": "Editor_Empty"
    },
    {
      "x": 1,
      "y": 11,
      "z": -7,
      "name": "Editor_Empty"
    },
    {
      "x": 1,
      "y": 12,
      "z": -7,
      "name": "Editor_Empty"
    },
    {
      "x": 1,
      "y": 1,
      "z": -6,
      "name": "Rock_Stone_Brick_Smooth"
    },
    {
      "x": 1,
      "y": 2,
      "z": -6,
      "name": "Editor_Empty"
    },
    {
      "x": 1,
      "y": 3,
      "z": -6,
      "name": "Editor_Empty"
    },
    {
      "x": 1,
      "y": 4,
      "z": -6,
      "name": "Editor_Empty"
    },
    {
      "x": 1,
      "y": 5,
      "z": -6,
      "name": "Editor_Empty"
    },
    {
      "x": 1,
      "y": 6,
      "z": -6,
      "name": "Editor_Empty"
    },
    {
      "x": 1,
      "y": 7,
      "z": -6,
      "name": "Editor_Empty"
    },
    {
      "x": 1,
      "y": 8,
      "z": -6,
      "name": "Editor_Empty"
    },
    {
      "x": 1,
      "y": 9,
      "z": -6,
      "name": "Editor_Empty"
    },
    {
      "x": 1,
      "y": 10,
      "z": -6,
      "name": "Editor_Empty"
    },
    {
      "x": 1,
      "y": 11,
      "z": -6,
      "name": "Editor_Empty"
    },
    {
      "x": 1,
      "y": 12,
      "z": -6,
      "name": "Editor_Empty"
    },
    {
      "x": 1,
      "y": 1,
      "z": -5,
      "name": "Rock_Stone_Brick_Smooth"
    },
    {
      "x": 1,
      "y": 2,
      "z": -5,
      "name": "Editor_Empty"
    },
    {
      "x": 1,
      "y": 3,
      "z": -5,
      "name": "Editor_Empty"
    },
    {
      "x": 1,
      "y": 4,
      "z": -5,
      "name": "Editor_Empty"
    },
    {
      "x": 1,
      "y": 5,
      "z": -5,
      "name": "Editor_Empty"
    },
    {
      "x": 1,
      "y": 6,
      "z": -5,
      "name": "Editor_Empty"
    },
    {
      "x": 1,
      "y": 7,
      "z": -5,
      "name": "Editor_Empty"
    },
    {
      "x": 1,
      "y": 8,
      "z": -5,
      "name": "Editor_Empty"
    },
    {
      "x": 1,
      "y": 9,
      "z": -5,
      "name": "Editor_Empty"
    },
    {
      "x": 1,
      "y": 10,
      "z": -5,
      "name": "Editor_Empty"
    },
    {
      "x": 1,
      "y": 11,
      "z": -5,
      "name": "Editor_Empty"
    },
    {
      "x": 1,
      "y": 12,
      "z": -5,
      "name": "Editor_Empty"
    },
    {
      "x": 1,
      "y": 1,
      "z": -4,
      "name": "Rock_Stone_Brick_Smooth"
    },
    {
      "x": 1,
      "y": 2,
      "z": -4,
      "name": "Editor_Empty"
    },
    {
      "x": 1,
      "y": 3,
      "z": -4,
      "name": "Editor_Empty"
    },
    {
      "x": 1,
      "y": 4,
      "z": -4,
      "name": "Editor_Empty"
    },
    {
      "x": 1,
      "y": 5,
      "z": -4,
      "name": "Editor_Empty"
    },
    {
      "x": 1,
      "y": 6,
      "z": -4,
      "name": "Editor_Empty"
    },
    {
      "x": 1,
      "y": 7,
      "z": -4,
      "name": "Editor_Empty"
    },
    {
      "x": 1,
      "y": 8,
      "z": -4,
      "name": "Editor_Empty"
    },
    {
      "x": 1,
      "y": 9,
      "z": -4,
      "name": "Editor_Empty"
    },
    {
      "x": 1,
      "y": 10,
      "z": -4,
      "name": "Editor_Empty"
    },
    {
      "x": 1,
      "y": 11,
      "z": -4,
      "name": "Editor_Empty"
    },
    {
      "x": 1,
      "y": 12,
      "z": -4,
      "name": "Editor_Empty"
    },
    {
      "x": 1,
      "y": 1,
      "z": -3,
      "name": "Rock_Stone_Brick_Smooth"
    },
    {
      "x": 1,
      "y": 2,
      "z": -3,
      "name": "Editor_Empty"
    },
    {
      "x": 1,
      "y": 3,
      "z": -3,
      "name": "Editor_Empty"
    },
    {
      "x": 1,
      "y": 4,
      "z": -3,
      "name": "Editor_Empty"
    },
    {
      "x": 1,
      "y": 5,
      "z": -3,
      "name": "Editor_Empty"
    },
    {
      "x": 1,
      "y": 6,
      "z": -3,
      "name": "Editor_Empty"
    },
    {
      "x": 1,
      "y": 7,
      "z": -3,
      "name": "Editor_Empty"
    },
    {
      "x": 1,
      "y": 8,
      "z": -3,
      "name": "Editor_Empty"
    },
    {
      "x": 1,
      "y": 9,
      "z": -3,
      "name": "Editor_Empty"
    },
    {
      "x": 1,
      "y": 10,
      "z": -3,
      "name": "Editor_Empty"
    },
    {
      "x": 1,
      "y": 11,
      "z": -3,
      "name": "Editor_Empty"
    },
    {
      "x": 1,
      "y": 12,
      "z": -3,
      "name": "Editor_Empty"
    },
    {
      "x": 1,
      "y": 2,
      "z": -2,
      "name": "Editor_Empty"
    },
    {
      "x": 1,
      "y": 3,
      "z": -2,
      "name": "Editor_Empty"
    },
    {
      "x": 1,
      "y": 4,
      "z": -2,
      "name": "Editor_Empty"
    },
    {
      "x": 1,
      "y": 5,
      "z": -2,
      "name": "Editor_Empty"
    },
    {
      "x": 1,
      "y": 6,
      "z": -2,
      "name": "Editor_Empty"
    },
    {
      "x": 1,
      "y": 7,
      "z": -2,
      "name": "Editor_Empty"
    },
    {
      "x": 1,
      "y": 8,
      "z": -2,
      "name": "Editor_Empty"
    },
    {
      "x": 1,
      "y": 9,
      "z": -2,
      "name": "Editor_Empty"
    },
    {
      "x": 1,
      "y": 10,
      "z": -2,
      "name": "Editor_Empty"
    },
    {
      "x": 1,
      "y": 11,
      "z": -2,
      "name": "Editor_Empty"
    },
    {
      "x": 1,
      "y": 12,
      "z": -2,
      "name": "Editor_Empty"
    },
    {
      "x": 1,
      "y": 2,
      "z": -1,
      "name": "Editor_Empty"
    },
    {
      "x": 1,
      "y": 3,
      "z": -1,
      "name": "Editor_Empty"
    },
    {
      "x": 1,
      "y": 4,
      "z": -1,
      "name": "Editor_Empty"
    },
    {
      "x": 1,
      "y": 5,
      "z": -1,
      "name": "Editor_Empty"
    },
    {
      "x": 1,
      "y": 6,
      "z": -1,
      "name": "Editor_Empty"
    },
    {
      "x": 1,
      "y": 7,
      "z": -1,
      "name": "Editor_Empty"
    },
    {
      "x": 1,
      "y": 8,
      "z": -1,
      "name": "Editor_Empty"
    },
    {
      "x": 1,
      "y": 9,
      "z": -1,
      "name": "Editor_Empty"
    },
    {
      "x": 1,
      "y": 10,
      "z": -1,
      "name": "Editor_Empty"
    },
    {
      "x": 1,
      "y": 11,
      "z": -1,
      "name": "Editor_Empty"
    },
    {
      "x": 1,
      "y": 12,
      "z": -1,
      "name": "Editor_Empty"
    },
    {
      "x": 2,
      "y": 2,
      "z": -12,
      "name": "Editor_Empty"
    },
    {
      "x": 2,
      "y": 3,
      "z": -12,
      "name": "Editor_Empty"
    },
    {
      "x": 2,
      "y": 4,
      "z": -12,
      "name": "Editor_Empty"
    },
    {
      "x": 2,
      "y": 5,
      "z": -12,
      "name": "Editor_Empty"
    },
    {
      "x": 2,
      "y": 6,
      "z": -12,
      "name": "Editor_Empty"
    },
    {
      "x": 2,
      "y": 7,
      "z": -12,
      "name": "Editor_Empty"
    },
    {
      "x": 2,
      "y": 8,
      "z": -12,
      "name": "Editor_Empty"
    },
    {
      "x": 2,
      "y": 9,
      "z": -12,
      "name": "Editor_Empty"
    },
    {
      "x": 2,
      "y": 10,
      "z": -12,
      "name": "Editor_Empty"
    },
    {
      "x": 2,
      "y": 11,
      "z": -12,
      "name": "Editor_Empty"
    },
    {
      "x": 2,
      "y": 12,
      "z": -12,
      "name": "Editor_Empty"
    },
    {
      "x": 2,
      "y": 1,
      "z": -11,
      "name": "Rock_Stone_Brick_Smooth"
    },
    {
      "x": 2,
      "y": 2,
      "z": -11,
      "name": "Editor_Empty"
    },
    {
      "x": 2,
      "y": 3,
      "z": -11,
      "name": "Editor_Empty"
    },
    {
      "x": 2,
      "y": 4,
      "z": -11,
      "name": "Editor_Empty"
    },
    {
      "x": 2,
      "y": 5,
      "z": -11,
      "name": "Editor_Empty"
    },
    {
      "x": 2,
      "y": 6,
      "z": -11,
      "name": "Editor_Empty"
    },
    {
      "x": 2,
      "y": 7,
      "z": -11,
      "name": "Editor_Empty"
    },
    {
      "x": 2,
      "y": 8,
      "z": -11,
      "name": "Editor_Empty"
    },
    {
      "x": 2,
      "y": 9,
      "z": -11,
      "name": "Editor_Empty"
    },
    {
      "x": 2,
      "y": 10,
      "z": -11,
      "name": "Editor_Empty"
    },
    {
      "x": 2,
      "y": 11,
      "z": -11,
      "name": "Editor_Empty"
    },
    {
      "x": 2,
      "y": 12,
      "z": -11,
      "name": "Editor_Empty"
    },
    {
      "x": 2,
      "y": 1,
      "z": -10,
      "name": "Rock_Sandstone_Red_Cobble"
    },
    {
      "x": 2,
      "y": 2,
      "z": -10,
      "name": "Editor_Empty"
    },
    {
      "x": 2,
      "y": 3,
      "z": -10,
      "name": "Editor_Empty"
    },
    {
      "x": 2,
      "y": 4,
      "z": -10,
      "name": "Editor_Empty"
    },
    {
      "x": 2,
      "y": 5,
      "z": -10,
      "name": "Editor_Empty"
    },
    {
      "x": 2,
      "y": 6,
      "z": -10,
      "name": "Editor_Empty"
    },
    {
      "x": 2,
      "y": 7,
      "z": -10,
      "name": "Editor_Empty"
    },
    {
      "x": 2,
      "y": 8,
      "z": -10,
      "name": "Editor_Empty"
    },
    {
      "x": 2,
      "y": 9,
      "z": -10,
      "name": "Editor_Empty"
    },
    {
      "x": 2,
      "y": 10,
      "z": -10,
      "name": "Editor_Empty"
    },
    {
      "x": 2,
      "y": 11,
      "z": -10,
      "name": "Editor_Empty"
    },
    {
      "x": 2,
      "y": 12,
      "z": -10,
      "name": "Editor_Empty"
    },
    {
      "x": 2,
      "y": 1,
      "z": -9,
      "name": "Rock_Sandstone_Red_Cobble",
      "rotation": 2
    },
    {
      "x": 2,
      "y": 2,
      "z": -9,
      "name": "Editor_Empty"
    },
    {
      "x": 2,
      "y": 3,
      "z": -9,
      "name": "Editor_Empty"
    },
    {
      "x": 2,
      "y": 4,
      "z": -9,
      "name": "Editor_Empty"
    },
    {
      "x": 2,
      "y": 5,
      "z": -9,
      "name": "Editor_Empty"
    },
    {
      "x": 2,
      "y": 6,
      "z": -9,
      "name": "Editor_Empty"
    },
    {
      "x": 2,
      "y": 7,
      "z": -9,
      "name": "Editor_Empty"
    },
    {
      "x": 2,
      "y": 8,
      "z": -9,
      "name": "Editor_Empty"
    },
    {
      "x": 2,
      "y": 9,
      "z": -9,
      "name": "Editor_Empty"
    },
    {
      "x": 2,
      "y": 10,
      "z": -9,
      "name": "Editor_Empty"
    },
    {
      "x": 2,
      "y": 11,
      "z": -9,
      "name": "Editor_Empty"
    },
    {
      "x": 2,
      "y": 12,
      "z": -9,
      "name": "Editor_Empty"
    },
    {
      "x": 2,
      "y": 1,
      "z": -8,
      "name": "Rock_Sandstone_Red_Cobble",
      "rotation": 2
    },
    {
      "x": 2,
      "y": 2,
      "z": -8,
      "name": "Editor_Empty"
    },
    {
      "x": 2,
      "y": 3,
      "z": -8,
      "name": "Rock_Stone_Brick_Stairs",
      "rotation": 35
    },
    {
      "x": 2,
      "y": 4,
      "z": -8,
      "name": "Rock_Stone_Brick",
      "rotation": 2
    },
    {
      "x": 2,
      "y": 5,
      "z": -8,
      "name": "Rock_Stone_Brick",
      "rotation": 2
    },
    {
      "x": 2,
      "y": 6,
      "z": -8,
      "name": "Rock_Stone_Brick",
      "rotation": 2
    },
    {
      "x": 2,
      "y": 7,
      "z": -8,
      "name": "Rock_Stone_Brick",
      "rotation": 2
    },
    {
      "x": 2,
      "y": 8,
      "z": -8,
      "name": "Rock_Stone_Brick_Stairs",
      "rotation": 3
    },
    {
      "x": 2,
      "y": 9,
      "z": -8,
      "name": "Editor_Empty"
    },
    {
      "x": 2,
      "y": 10,
      "z": -8,
      "name": "Editor_Empty"
    },
    {
      "x": 2,
      "y": 11,
      "z": -8,
      "name": "Editor_Empty"
    },
    {
      "x": 2,
      "y": 12,
      "z": -8,
      "name": "Editor_Empty"
    },
    {
      "x": 2,
      "y": 1,
      "z": -7,
      "name": "Rock_Sandstone_Red_Cobble"
    },
    {
      "x": 2,
      "y": 2,
      "z": -7,
      "name": "Editor_Empty"
    },
    {
      "x": 2,
      "y": 3,
      "z": -7,
      "name": "Rock_Stone_Brick_Stairs",
      "rotation": 9
    },
    {
      "x": 2,
      "y": 4,
      "z": -7,
      "name": "Rock_Stone_Brick"
    },
    {
      "x": 2,
      "y": 5,
      "z": -7,
      "name": "Rock_Stone_Brick"
    },
    {
      "x": 2,
      "y": 6,
      "z": -7,
      "name": "Rock_Stone_Brick"
    },
    {
      "x": 2,
      "y": 7,
      "z": -7,
      "name": "Rock_Stone_Brick"
    },
    {
      "x": 2,
      "y": 8,
      "z": -7,
      "name": "Rock_Stone_Brick_Stairs",
      "rotation": 3
    },
    {
      "x": 2,
      "y": 9,
      "z": -7,
      "name": "Editor_Empty"
    },
    {
      "x": 2,
      "y": 10,
      "z": -7,
      "name": "Editor_Empty"
    },
    {
      "x": 2,
      "y": 11,
      "z": -7,
      "name": "Editor_Empty"
    },
    {
      "x": 2,
      "y": 12,
      "z": -7,
      "name": "Editor_Empty"
    },
    {
      "x": 2,
      "y": 1,
      "z": -6,
      "name": "Rock_Sandstone_Red_Cobble"
    },
    {
      "x": 2,
      "y": 2,
      "z": -6,
      "name": "Editor_Empty"
    },
    {
      "x": 2,
      "y": 3,
      "z": -6,
      "name": "Rock_Stone_Brick_Stairs",
      "rotation": 9
    },
    {
      "x": 2,
      "y": 4,
      "z": -6,
      "name": "Rock_Stone_Brick"
    },
    {
      "x": 2,
      "y": 5,
      "z": -6,
      "name": "Rock_Stone_Brick"
    },
    {
      "x": 2,
      "y": 6,
      "z": -6,
      "name": "Rock_Stone_Brick"
    },
    {
      "x": 2,
      "y": 7,
      "z": -6,
      "name": "Rock_Stone_Brick"
    },
    {
      "x": 2,
      "y": 8,
      "z": -6,
      "name": "Rock_Stone_Brick_Stairs",
      "rotation": 3
    },
    {
      "x": 2,
      "y": 9,
      "z": -6,
      "name": "Editor_Empty"
    },
    {
      "x": 2,
      "y": 10,
      "z": -6,
      "name": "Editor_Empty"
    },
    {
      "x": 2,
      "y": 11,
      "z": -6,
      "name": "Editor_Empty"
    },
    {
      "x": 2,
      "y": 12,
      "z": -6,
      "name": "Editor_Empty"
    },
    {
      "x": 2,
      "y": 1,
      "z": -5,
      "name": "Rock_Sandstone_Red_Cobble"
    },
    {
      "x": 2,
      "y": 2,
      "z": -5,
      "name": "Editor_Empty"
    },
    {
      "x": 2,
      "y": 3,
      "z": -5,
      "name": "Editor_Empty"
    },
    {
      "x": 2,
      "y": 4,
      "z": -5,
      "name": "Editor_Empty"
    },
    {
      "x": 2,
      "y": 5,
      "z": -5,
      "name": "Editor_Empty"
    },
    {
      "x": 2,
      "y": 6,
      "z": -5,
      "name": "Editor_Empty"
    },
    {
      "x": 2,
      "y": 7,
      "z": -5,
      "name": "Editor_Empty"
    },
    {
      "x": 2,
      "y": 8,
      "z": -5,
      "name": "Editor_Empty"
    },
    {
      "x": 2,
      "y": 9,
      "z": -5,
      "name": "Editor_Empty"
    },
    {
      "x": 2,
      "y": 10,
      "z": -5,
      "name": "Editor_Empty"
    },
    {
      "x": 2,
      "y": 11,
      "z": -5,
      "name": "Editor_Empty"
    },
    {
      "x": 2,
      "y": 12,
      "z": -5,
      "name": "Editor_Empty"
    },
    {
      "x": 2,
      "y": 1,
      "z": -4,
      "name": "Rock_Sandstone_Red_Cobble"
    },
    {
      "x": 2,
      "y": 2,
      "z": -4,
      "name": "Editor_Empty"
    },
    {
      "x": 2,
      "y": 3,
      "z": -4,
      "name": "Editor_Empty"
    },
    {
      "x": 2,
      "y": 4,
      "z": -4,
      "name": "Editor_Empty"
    },
    {
      "x": 2,
      "y": 5,
      "z": -4,
      "name": "Editor_Empty"
    },
    {
      "x": 2,
      "y": 6,
      "z": -4,
      "name": "Editor_Empty"
    },
    {
      "x": 2,
      "y": 7,
      "z": -4,
      "name": "Editor_Empty"
    },
    {
      "x": 2,
      "y": 8,
      "z": -4,
      "name": "Editor_Empty"
    },
    {
      "x": 2,
      "y": 9,
      "z": -4,
      "name": "Editor_Empty"
    },
    {
      "x": 2,
      "y": 10,
      "z": -4,
      "name": "Editor_Empty"
    },
    {
      "x": 2,
      "y": 11,
      "z": -4,
      "name": "Editor_Empty"
    },
    {
      "x": 2,
      "y": 12,
      "z": -4,
      "name": "Editor_Empty"
    },
    {
      "x": 2,
      "y": 1,
      "z": -3,
      "name": "Rock_Sandstone_Red_Cobble"
    },
    {
      "x": 2,
      "y": 2,
      "z": -3,
      "name": "Editor_Empty"
    },
    {
      "x": 2,
      "y": 3,
      "z": -3,
      "name": "Editor_Empty"
    },
    {
      "x": 2,
      "y": 4,
      "z": -3,
      "name": "Editor_Empty"
    },
    {
      "x": 2,
      "y": 5,
      "z": -3,
      "name": "Editor_Empty"
    },
    {
      "x": 2,
      "y": 6,
      "z": -3,
      "name": "Editor_Empty"
    },
    {
      "x": 2,
      "y": 7,
      "z": -3,
      "name": "Editor_Empty"
    },
    {
      "x": 2,
      "y": 8,
      "z": -3,
      "name": "Editor_Empty"
    },
    {
      "x": 2,
      "y": 9,
      "z": -3,
      "name": "Editor_Empty"
    },
    {
      "x": 2,
      "y": 10,
      "z": -3,
      "name": "Editor_Empty"
    },
    {
      "x": 2,
      "y": 11,
      "z": -3,
      "name": "Editor_Empty"
    },
    {
      "x": 2,
      "y": 12,
      "z": -3,
      "name": "Editor_Empty"
    },
    {
      "x": 2,
      "y": 1,
      "z": -2,
      "name": "Rock_Stone_Brick_Smooth"
    },
    {
      "x": 2,
      "y": 2,
      "z": -2,
      "name": "Editor_Empty"
    },
    {
      "x": 2,
      "y": 3,
      "z": -2,
      "name": "Editor_Empty"
    },
    {
      "x": 2,
      "y": 4,
      "z": -2,
      "name": "Editor_Empty"
    },
    {
      "x": 2,
      "y": 5,
      "z": -2,
      "name": "Editor_Empty"
    },
    {
      "x": 2,
      "y": 6,
      "z": -2,
      "name": "Editor_Empty"
    },
    {
      "x": 2,
      "y": 7,
      "z": -2,
      "name": "Editor_Empty"
    },
    {
      "x": 2,
      "y": 8,
      "z": -2,
      "name": "Editor_Empty"
    },
    {
      "x": 2,
      "y": 9,
      "z": -2,
      "name": "Editor_Empty"
    },
    {
      "x": 2,
      "y": 10,
      "z": -2,
      "name": "Editor_Empty"
    },
    {
      "x": 2,
      "y": 11,
      "z": -2,
      "name": "Editor_Empty"
    },
    {
      "x": 2,
      "y": 12,
      "z": -2,
      "name": "Editor_Empty"
    },
    {
      "x": 2,
      "y": 2,
      "z": -1,
      "name": "Editor_Empty"
    },
    {
      "x": 2,
      "y": 3,
      "z": -1,
      "name": "Editor_Empty"
    },
    {
      "x": 2,
      "y": 4,
      "z": -1,
      "name": "Editor_Empty"
    },
    {
      "x": 2,
      "y": 5,
      "z": -1,
      "name": "Editor_Empty"
    },
    {
      "x": 2,
      "y": 6,
      "z": -1,
      "name": "Editor_Empty"
    },
    {
      "x": 2,
      "y": 7,
      "z": -1,
      "name": "Editor_Empty"
    },
    {
      "x": 2,
      "y": 8,
      "z": -1,
      "name": "Editor_Empty"
    },
    {
      "x": 2,
      "y": 9,
      "z": -1,
      "name": "Editor_Empty"
    },
    {
      "x": 2,
      "y": 10,
      "z": -1,
      "name": "Editor_Empty"
    },
    {
      "x": 2,
      "y": 11,
      "z": -1,
      "name": "Editor_Empty"
    },
    {
      "x": 2,
      "y": 12,
      "z": -1,
      "name": "Editor_Empty"
    },
    {
      "x": 3,
      "y": 1,
      "z": -12,
      "name": "Rock_Stone_Brick_Smooth"
    },
    {
      "x": 3,
      "y": 2,
      "z": -12,
      "name": "Editor_Empty"
    },
    {
      "x": 3,
      "y": 3,
      "z": -12,
      "name": "Editor_Empty"
    },
    {
      "x": 3,
      "y": 4,
      "z": -12,
      "name": "Editor_Empty"
    },
    {
      "x": 3,
      "y": 5,
      "z": -12,
      "name": "Editor_Empty"
    },
    {
      "x": 3,
      "y": 6,
      "z": -12,
      "name": "Editor_Empty"
    },
    {
      "x": 3,
      "y": 7,
      "z": -12,
      "name": "Editor_Empty"
    },
    {
      "x": 3,
      "y": 8,
      "z": -12,
      "name": "Editor_Empty"
    },
    {
      "x": 3,
      "y": 9,
      "z": -12,
      "name": "Editor_Empty"
    },
    {
      "x": 3,
      "y": 10,
      "z": -12,
      "name": "Editor_Empty"
    },
    {
      "x": 3,
      "y": 11,
      "z": -12,
      "name": "Editor_Empty"
    },
    {
      "x": 3,
      "y": 12,
      "z": -12,
      "name": "Editor_Empty"
    },
    {
      "x": 3,
      "y": 1,
      "z": -11,
      "name": "Rock_Sandstone_Red_Cobble"
    },
    {
      "x": 3,
      "y": 2,
      "z": -11,
      "name": "Editor_Empty"
    },
    {
      "x": 3,
      "y": 3,
      "z": -11,
      "name": "Editor_Empty"
    },
    {
      "x": 3,
      "y": 4,
      "z": -11,
      "name": "Editor_Empty"
    },
    {
      "x": 3,
      "y": 5,
      "z": -11,
      "name": "Editor_Empty"
    },
    {
      "x": 3,
      "y": 6,
      "z": -11,
      "name": "Editor_Empty"
    },
    {
      "x": 3,
      "y": 7,
      "z": -11,
      "name": "Editor_Empty"
    },
    {
      "x": 3,
      "y": 8,
      "z": -11,
      "name": "Editor_Empty"
    },
    {
      "x": 3,
      "y": 9,
      "z": -11,
      "name": "Editor_Empty"
    },
    {
      "x": 3,
      "y": 10,
      "z": -11,
      "name": "Editor_Empty"
    },
    {
      "x": 3,
      "y": 11,
      "z": -11,
      "name": "Editor_Empty"
    },
    {
      "x": 3,
      "y": 12,
      "z": -11,
      "name": "Editor_Empty"
    },
    {
      "x": 3,
      "y": 1,
      "z": -10,
      "name": "Rock_Sandstone_Red_Cobble"
    },
    {
      "x": 3,
      "y": 2,
      "z": -10,
      "name": "Editor_Empty"
    },
    {
      "x": 3,
      "y": 3,
      "z": -10,
      "name": "Editor_Empty"
    },
    {
      "x": 3,
      "y": 4,
      "z": -10,
      "name": "Editor_Empty"
    },
    {
      "x": 3,
      "y": 5,
      "z": -10,
      "name": "Editor_Empty"
    },
    {
      "x": 3,
      "y": 6,
      "z": -10,
      "name": "Editor_Empty"
    },
    {
      "x": 3,
      "y": 7,
      "z": -10,
      "name": "Editor_Empty"
    },
    {
      "x": 3,
      "y": 8,
      "z": -10,
      "name": "Editor_Empty"
    },
    {
      "x": 3,
      "y": 9,
      "z": -10,
      "name": "Editor_Empty"
    },
    {
      "x": 3,
      "y": 10,
      "z": -10,
      "name": "Editor_Empty"
    },
    {
      "x": 3,
      "y": 11,
      "z": -10,
      "name": "Editor_Empty"
    },
    {
      "x": 3,
      "y": 12,
      "z": -10,
      "name": "Editor_Empty"
    },
    {
      "x": 3,
      "y": 1,
      "z": -9,
      "name": "Rock_Sandstone_Red_Cobble",
      "rotation": 2
    },
    {
      "x": 3,
      "y": 2,
      "z": -9,
      "name": "Editor_Empty"
    },
    {
      "x": 3,
      "y": 3,
      "z": -9,
      "name": "Editor_Empty"
    },
    {
      "x": 3,
      "y": 4,
      "z": -9,
      "name": "Editor_Empty"
    },
    {
      "x": 3,
      "y": 5,
      "z": -9,
      "name": "Editor_Empty"
    },
    {
      "x": 3,
      "y": 6,
      "z": -9,
      "name": "Editor_Empty"
    },
    {
      "x": 3,
      "y": 7,
      "z": -9,
      "name": "Editor_Empty"
    },
    {
      "x": 3,
      "y": 8,
      "z": -9,
      "name": "Editor_Empty"
    },
    {
      "x": 3,
      "y": 9,
      "z": -9,
      "name": "Editor_Empty"
    },
    {
      "x": 3,
      "y": 10,
      "z": -9,
      "name": "Editor_Empty"
    },
    {
      "x": 3,
      "y": 11,
      "z": -9,
      "name": "Editor_Empty"
    },
    {
      "x": 3,
      "y": 12,
      "z": -9,
      "name": "Editor_Empty"
    },
    {
      "x": 3,
      "y": 1,
      "z": -8,
      "name": "Rock_Sandstone_Red_Cobble",
      "rotation": 2
    },
    {
      "x": 3,
      "y": 2,
      "z": -8,
      "name": "Rock_Stone_Brick_Stairs",
      "rotation": 35
    },
    {
      "x": 3,
      "y": 3,
      "z": -8,
      "name": "Rock_Stone_Brick",
      "rotation": 2
    },
    {
      "x": 3,
      "y": 4,
      "z": -8,
      "name": "Rock_Crystal_Purple_Block",
      "rotation": 6
    },
    {
      "x": 3,
      "y": 5,
      "z": -8,
      "name": "Rock_Crystal_Purple_Block",
      "rotation": 6
    },
    {
      "x": 3,
      "y": 6,
      "z": -8,
      "name": "Rock_Crystal_Purple_Block",
      "rotation": 6
    },
    {
      "x": 3,
      "y": 7,
      "z": -8,
      "name": "Rock_Crystal_Purple_Block",
      "rotation": 6
    },
    {
      "x": 3,
      "y": 8,
      "z": -8,
      "name": "Rock_Stone_Brick",
      "rotation": 2
    },
    {
      "x": 3,
      "y": 9,
      "z": -8,
      "name": "Rock_Stone_Brick",
      "rotation": 2
    },
    {
      "x": 3,
      "y": 10,
      "z": -8,
      "name": "Rock_Stone_Brick_Stairs",
      "rotation": 3
    },
    {
      "x": 3,
      "y": 11,
      "z": -8,
      "name": "Editor_Empty"
    },
    {
      "x": 3,
      "y": 12,
      "z": -8,
      "name": "Editor_Empty"
    },
    {
      "x": 3,
      "y": 1,
      "z": -7,
      "name": "Rock_Sandstone_Red_Cobble"
    },
    {
      "x": 3,
      "y": 2,
      "z": -7,
      "name": "Rock_Stone_Brick_Stairs",
      "rotation": 9
    },
    {
      "x": 3,
      "y": 3,
      "z": -7,
      "name": "Rock_Stone_Brick"
    },
    {
      "x": 3,
      "y": 4,
      "z": -7,
      "name": "Rock_Stone_Brick"
    },
    {
      "x": 3,
      "y": 5,
      "z": -7,
      "name": "Rock_Stone_Brick"
    },
    {
      "x": 3,
      "y": 6,
      "z": -7,
      "name": "Rock_Stone_Brick"
    },
    {
      "x": 3,
      "y": 7,
      "z": -7,
      "name": "Rock_Stone_Brick"
    },
    {
      "x": 3,
      "y": 8,
      "z": -7,
      "name": "Rock_Stone_Brick"
    },
    {
      "x": 3,
      "y": 9,
      "z": -7,
      "name": "Rock_Stone_Brick"
    },
    {
      "x": 3,
      "y": 10,
      "z": -7,
      "name": "Rock_Stone_Brick_Stairs",
      "rotation": 3
    },
    {
      "x": 3,
      "y": 11,
      "z": -7,
      "name": "Editor_Empty"
    },
    {
      "x": 3,
      "y": 12,
      "z": -7,
      "name": "Editor_Empty"
    },
    {
      "x": 3,
      "y": 1,
      "z": -6,
      "name": "Rock_Sandstone_Red_Cobble"
    },
    {
      "x": 3,
      "y": 2,
      "z": -6,
      "name": "Rock_Stone_Brick_Stairs",
      "rotation": 9
    },
    {
      "x": 3,
      "y": 3,
      "z": -6,
      "name": "Rock_Stone_Brick"
    },
    {
      "x": 3,
      "y": 4,
      "z": -6,
      "name": "Rock_Crystal_Purple_Block",
      "rotation": 4
    },
    {
      "x": 3,
      "y": 5,
      "z": -6,
      "name": "Rock_Crystal_Purple_Block",
      "rotation": 4
    },
    {
      "x": 3,
      "y": 6,
      "z": -6,
      "name": "Rock_Crystal_Purple_Block",
      "rotation": 4
    },
    {
      "x": 3,
      "y": 7,
      "z": -6,
      "name": "Rock_Crystal_Purple_Block",
      "rotation": 4
    },
    {
      "x": 3,
      "y": 8,
      "z": -6,
      "name": "Rock_Stone_Brick"
    },
    {
      "x": 3,
      "y": 9,
      "z": -6,
      "name": "Rock_Stone_Brick"
    },
    {
      "x": 3,
      "y": 10,
      "z": -6,
      "name": "Rock_Stone_Brick_Stairs",
      "rotation": 3
    },
    {
      "x": 3,
      "y": 11,
      "z": -6,
      "name": "Editor_Empty"
    },
    {
      "x": 3,
      "y": 12,
      "z": -6,
      "name": "Editor_Empty"
    },
    {
      "x": 3,
      "y": 1,
      "z": -5,
      "name": "Rock_Sandstone_Red_Cobble"
    },
    {
      "x": 3,
      "y": 2,
      "z": -5,
      "name": "Editor_Empty"
    },
    {
      "x": 3,
      "y": 3,
      "z": -5,
      "name": "Editor_Empty"
    },
    {
      "x": 3,
      "y": 4,
      "z": -5,
      "name": "Editor_Empty"
    },
    {
      "x": 3,
      "y": 5,
      "z": -5,
      "name": "Editor_Empty"
    },
    {
      "x": 3,
      "y": 6,
      "z": -5,
      "name": "Editor_Empty"
    },
    {
      "x": 3,
      "y": 7,
      "z": -5,
      "name": "Editor_Empty"
    },
    {
      "x": 3,
      "y": 8,
      "z": -5,
      "name": "Editor_Empty"
    },
    {
      "x": 3,
      "y": 9,
      "z": -5,
      "name": "Editor_Empty"
    },
    {
      "x": 3,
      "y": 10,
      "z": -5,
      "name": "Editor_Empty"
    },
    {
      "x": 3,
      "y": 11,
      "z": -5,
      "name": "Editor_Empty"
    },
    {
      "x": 3,
      "y": 12,
      "z": -5,
      "name": "Editor_Empty"
    },
    {
      "x": 3,
      "y": 1,
      "z": -4,
      "name": "Rock_Sandstone_Red_Cobble"
    },
    {
      "x": 3,
      "y": 2,
      "z": -4,
      "name": "Editor_Empty"
    },
    {
      "x": 3,
      "y": 3,
      "z": -4,
      "name": "Editor_Empty"
    },
    {
      "x": 3,
      "y": 4,
      "z": -4,
      "name": "Editor_Empty"
    },
    {
      "x": 3,
      "y": 5,
      "z": -4,
      "name": "Editor_Empty"
    },
    {
      "x": 3,
      "y": 6,
      "z": -4,
      "name": "Editor_Empty"
    },
    {
      "x": 3,
      "y": 7,
      "z": -4,
      "name": "Editor_Empty"
    },
    {
      "x": 3,
      "y": 8,
      "z": -4,
      "name": "Editor_Empty"
    },
    {
      "x": 3,
      "y": 9,
      "z": -4,
      "name": "Editor_Empty"
    },
    {
      "x": 3,
      "y": 10,
      "z": -4,
      "name": "Editor_Empty"
    },
    {
      "x": 3,
      "y": 11,
      "z": -4,
      "name": "Editor_Empty"
    },
    {
      "x": 3,
      "y": 12,
      "z": -4,
      "name": "Editor_Empty"
    },
    {
      "x": 3,
      "y": 1,
      "z": -3,
      "name": "Rock_Sandstone_Red_Cobble"
    },
    {
      "x": 3,
      "y": 2,
      "z": -3,
      "name": "Editor_Empty"
    },
    {
      "x": 3,
      "y": 3,
      "z": -3,
      "name": "Editor_Empty"
    },
    {
      "x": 3,
      "y": 4,
      "z": -3,
      "name": "Editor_Empty"
    },
    {
      "x": 3,
      "y": 5,
      "z": -3,
      "name": "Editor_Empty"
    },
    {
      "x": 3,
      "y": 6,
      "z": -3,
      "name": "Editor_Empty"
    },
    {
      "x": 3,
      "y": 7,
      "z": -3,
      "name": "Editor_Empty"
    },
    {
      "x": 3,
      "y": 8,
      "z": -3,
      "name": "Editor_Empty"
    },
    {
      "x": 3,
      "y": 9,
      "z": -3,
      "name": "Editor_Empty"
    },
    {
      "x": 3,
      "y": 10,
      "z": -3,
      "name": "Editor_Empty"
    },
    {
      "x": 3,
      "y": 11,
      "z": -3,
      "name": "Editor_Empty"
    },
    {
      "x": 3,
      "y": 12,
      "z": -3,
      "name": "Editor_Empty"
    },
    {
      "x": 3,
      "y": 1,
      "z": -2,
      "name": "Rock_Sandstone_Red_Cobble"
    },
    {
      "x": 3,
      "y": 2,
      "z": -2,
      "name": "Editor_Empty"
    },
    {
      "x": 3,
      "y": 3,
      "z": -2,
      "name": "Editor_Empty"
    },
    {
      "x": 3,
      "y": 4,
      "z": -2,
      "name": "Editor_Empty"
    },
    {
      "x": 3,
      "y": 5,
      "z": -2,
      "name": "Editor_Empty"
    },
    {
      "x": 3,
      "y": 6,
      "z": -2,
      "name": "Editor_Empty"
    },
    {
      "x": 3,
      "y": 7,
      "z": -2,
      "name": "Editor_Empty"
    },
    {
      "x": 3,
      "y": 8,
      "z": -2,
      "name": "Editor_Empty"
    },
    {
      "x": 3,
      "y": 9,
      "z": -2,
      "name": "Editor_Empty"
    },
    {
      "x": 3,
      "y": 10,
      "z": -2,
      "name": "Editor_Empty"
    },
    {
      "x": 3,
      "y": 11,
      "z": -2,
      "name": "Editor_Empty"
    },
    {
      "x": 3,
      "y": 12,
      "z": -2,
      "name": "Editor_Empty"
    },
    {
      "x": 3,
      "y": 1,
      "z": -1,
      "name": "Rock_Stone_Brick_Smooth"
    },
    {
      "x": 3,
      "y": 2,
      "z": -1,
      "name": "Editor_Empty"
    },
    {
      "x": 3,
      "y": 3,
      "z": -1,
      "name": "Editor_Empty"
    },
    {
      "x": 3,
      "y": 4,
      "z": -1,
      "name": "Editor_Empty"
    },
    {
      "x": 3,
      "y": 5,
      "z": -1,
      "name": "Editor_Empty"
    },
    {
      "x": 3,
      "y": 6,
      "z": -1,
      "name": "Editor_Empty"
    },
    {
      "x": 3,
      "y": 7,
      "z": -1,
      "name": "Editor_Empty"
    },
    {
      "x": 3,
      "y": 8,
      "z": -1,
      "name": "Editor_Empty"
    },
    {
      "x": 3,
      "y": 9,
      "z": -1,
      "name": "Editor_Empty"
    },
    {
      "x": 3,
      "y": 10,
      "z": -1,
      "name": "Editor_Empty"
    },
    {
      "x": 3,
      "y": 11,
      "z": -1,
      "name": "Editor_Empty"
    },
    {
      "x": 3,
      "y": 12,
      "z": -1,
      "name": "Editor_Empty"
    },
    {
      "x": 4,
      "y": 1,
      "z": -12,
      "name": "Rock_Stone_Brick_Smooth"
    },
    {
      "x": 4,
      "y": 2,
      "z": -12,
      "name": "Editor_Empty"
    },
    {
      "x": 4,
      "y": 3,
      "z": -12,
      "name": "Editor_Empty"
    },
    {
      "x": 4,
      "y": 4,
      "z": -12,
      "name": "Editor_Empty"
    },
    {
      "x": 4,
      "y": 5,
      "z": -12,
      "name": "Editor_Empty"
    },
    {
      "x": 4,
      "y": 6,
      "z": -12,
      "name": "Editor_Empty"
    },
    {
      "x": 4,
      "y": 7,
      "z": -12,
      "name": "Editor_Empty"
    },
    {
      "x": 4,
      "y": 8,
      "z": -12,
      "name": "Editor_Empty"
    },
    {
      "x": 4,
      "y": 9,
      "z": -12,
      "name": "Editor_Empty"
    },
    {
      "x": 4,
      "y": 10,
      "z": -12,
      "name": "Editor_Empty"
    },
    {
      "x": 4,
      "y": 11,
      "z": -12,
      "name": "Editor_Empty"
    },
    {
      "x": 4,
      "y": 12,
      "z": -12,
      "name": "Editor_Empty"
    },
    {
      "x": 4,
      "y": 1,
      "z": -11,
      "name": "Rock_Sandstone_Red_Cobble"
    },
    {
      "x": 4,
      "y": 2,
      "z": -11,
      "name": "Editor_Empty"
    },
    {
      "x": 4,
      "y": 3,
      "z": -11,
      "name": "Editor_Empty"
    },
    {
      "x": 4,
      "y": 4,
      "z": -11,
      "name": "Editor_Empty"
    },
    {
      "x": 4,
      "y": 5,
      "z": -11,
      "name": "Editor_Empty"
    },
    {
      "x": 4,
      "y": 6,
      "z": -11,
      "name": "Editor_Empty"
    },
    {
      "x": 4,
      "y": 7,
      "z": -11,
      "name": "Editor_Empty"
    },
    {
      "x": 4,
      "y": 8,
      "z": -11,
      "name": "Editor_Empty"
    },
    {
      "x": 4,
      "y": 9,
      "z": -11,
      "name": "Editor_Empty"
    },
    {
      "x": 4,
      "y": 10,
      "z": -11,
      "name": "Editor_Empty"
    },
    {
      "x": 4,
      "y": 11,
      "z": -11,
      "name": "Editor_Empty"
    },
    {
      "x": 4,
      "y": 12,
      "z": -11,
      "name": "Editor_Empty"
    },
    {
      "x": 4,
      "y": 1,
      "z": -10,
      "name": "Rock_Sandstone_Red_Cobble"
    },
    {
      "x": 4,
      "y": 2,
      "z": -10,
      "name": "Editor_Empty"
    },
    {
      "x": 4,
      "y": 3,
      "z": -10,
      "name": "Editor_Empty"
    },
    {
      "x": 4,
      "y": 4,
      "z": -10,
      "name": "Editor_Empty"
    },
    {
      "x": 4,
      "y": 5,
      "z": -10,
      "name": "Editor_Empty"
    },
    {
      "x": 4,
      "y": 6,
      "z": -10,
      "name": "Editor_Empty"
    },
    {
      "x": 4,
      "y": 7,
      "z": -10,
      "name": "Editor_Empty"
    },
    {
      "x": 4,
      "y": 8,
      "z": -10,
      "name": "Editor_Empty"
    },
    {
      "x": 4,
      "y": 9,
      "z": -10,
      "name": "Editor_Empty"
    },
    {
      "x": 4,
      "y": 10,
      "z": -10,
      "name": "Editor_Empty"
    },
    {
      "x": 4,
      "y": 11,
      "z": -10,
      "name": "Editor_Empty"
    },
    {
      "x": 4,
      "y": 12,
      "z": -10,
      "name": "Editor_Empty"
    },
    {
      "x": 4,
      "y": 1,
      "z": -9,
      "name": "Rock_Sandstone_Red_Cobble",
      "rotation": 2
    },
    {
      "x": 4,
      "y": 2,
      "z": -9,
      "name": "Editor_Empty"
    },
    {
      "x": 4,
      "y": 3,
      "z": -9,
      "name": "Editor_Empty"
    },
    {
      "x": 4,
      "y": 4,
      "z": -9,
      "name": "Editor_Empty"
    },
    {
      "x": 4,
      "y": 5,
      "z": -9,
      "name": "Editor_Empty"
    },
    {
      "x": 4,
      "y": 6,
      "z": -9,
      "name": "Editor_Empty"
    },
    {
      "x": 4,
      "y": 7,
      "z": -9,
      "name": "Editor_Empty"
    },
    {
      "x": 4,
      "y": 8,
      "z": -9,
      "name": "Editor_Empty"
    },
    {
      "x": 4,
      "y": 9,
      "z": -9,
      "name": "Editor_Empty"
    },
    {
      "x": 4,
      "y": 10,
      "z": -9,
      "name": "Editor_Empty"
    },
    {
      "x": 4,
      "y": 11,
      "z": -9,
      "name": "Editor_Empty"
    },
    {
      "x": 4,
      "y": 12,
      "z": -9,
      "name": "Editor_Empty"
    },
    {
      "x": 4,
      "y": 1,
      "z": -8,
      "name": "Rock_Stone_Brick",
      "rotation": 2
    },
    {
      "x": 4,
      "y": 2,
      "z": -8,
      "name": "Rock_Stone_Brick",
      "rotation": 2
    },
    {
      "x": 4,
      "y": 3,
      "z": -8,
      "name": "Rock_Crystal_Purple_Block",
      "rotation": 6
    },
    {
      "x": 4,
      "y": 4,
      "z": -8,
      "name": "Rock_Stone_Brick",
      "rotation": 2
    },
    {
      "x": 4,
      "y": 5,
      "z": -8,
      "name": "Rock_Stone_Brick",
      "rotation": 2
    },
    {
      "x": 4,
      "y": 6,
      "z": -8,
      "name": "Rock_Stone_Brick",
      "rotation": 2
    },
    {
      "x": 4,
      "y": 7,
      "z": -8,
      "name": "Rock_Stone_Brick",
      "rotation": 2
    },
    {
      "x": 4,
      "y": 8,
      "z": -8,
      "name": "Rock_Crystal_Purple_Block",
      "rotation": 6
    },
    {
      "x": 4,
      "y": 9,
      "z": -8,
      "name": "Rock_Crystal_Purple_Block",
      "rotation": 6
    },
    {
      "x": 4,
      "y": 10,
      "z": -8,
      "name": "Rock_Stone_Brick",
      "rotation": 2
    },
    {
      "x": 4,
      "y": 11,
      "z": -8,
      "name": "Editor_Empty"
    },
    {
      "x": 4,
      "y": 12,
      "z": -8,
      "name": "Editor_Empty"
    },
    {
      "x": 4,
      "y": 1,
      "z": -7,
      "name": "Rock_Stone_Brick"
    },
    {
      "x": 4,
      "y": 2,
      "z": -7,
      "name": "Rock_Stone_Brick"
    },
    {
      "x": 4,
      "y": 3,
      "z": -7,
      "name": "Rock_Stone_Brick"
    },
    {
      "x": 4,
      "y": 4,
      "z": -7,
      "name": "Rock_Stone_Brick"
    },
    {
      "x": 4,
      "y": 5,
      "z": -7,
      "name": "Rock_Stone_Brick"
    },
    {
      "x": 4,
      "y": 6,
      "z": -7,
      "name": "Rock_Stone_Brick"
    },
    {
      "x": 4,
      "y": 7,
      "z": -7,
      "name": "Rock_Stone_Brick"
    },
    {
      "x": 4,
      "y": 8,
      "z": -7,
      "name": "Rock_Stone_Brick"
    },
    {
      "x": 4,
      "y": 9,
      "z": -7,
      "name": "Rock_Stone_Brick"
    },
    {
      "x": 4,
      "y": 10,
      "z": -7,
      "name": "Rock_Stone_Brick"
    },
    {
      "x": 4,
      "y": 11,
      "z": -7,
      "name": "Editor_Empty"
    },
    {
      "x": 4,
      "y": 12,
      "z": -7,
      "name": "Editor_Empty"
    },
    {
      "x": 4,
      "y": 1,
      "z": -6,
      "name": "Rock_Stone_Brick"
    },
    {
      "x": 4,
      "y": 2,
      "z": -6,
      "name": "Rock_Stone_Brick"
    },
    {
      "x": 4,
      "y": 3,
      "z": -6,
      "name": "Rock_Crystal_Purple_Block",
      "rotation": 4
    },
    {
      "x": 4,
      "y": 4,
      "z": -6,
      "name": "Rock_Stone_Brick"
    },
    {
      "x": 4,
      "y": 5,
      "z": -6,
      "name": "Rock_Stone_Brick"
    },
    {
      "x": 4,
      "y": 6,
      "z": -6,
      "name": "Rock_Stone_Brick"
    },
    {
      "x": 4,
      "y": 7,
      "z": -6,
      "name": "Rock_Stone_Brick"
    },
    {
      "x": 4,
      "y": 8,
      "z": -6,
      "name": "Rock_Crystal_Purple_Block",
      "rotation": 4
    },
    {
      "x": 4,
      "y": 9,
      "z": -6,
      "name": "Rock_Crystal_Purple_Block",
      "rotation": 4
    },
    {
      "x": 4,
      "y": 10,
      "z": -6,
      "name": "Rock_Stone_Brick"
    },
    {
      "x": 4,
      "y": 11,
      "z": -6,
      "name": "Editor_Empty"
    },
    {
      "x": 4,
      "y": 12,
      "z": -6,
      "name": "Editor_Empty"
    },
    {
      "x": 4,
      "y": 1,
      "z": -5,
      "name": "Rock_Sandstone_Red_Cobble"
    },
    {
      "x": 4,
      "y": 2,
      "z": -5,
      "name": "Aetherhaven_Management_Block",
      "components": {
        "Components": {
          "AetherhavenManagementBlock": {
            "PlotId": "",
            "TownId": ""
          },
          "PlacedByInteraction": {
            "WhoPlacedUuid": {
              "$binary": "v7RyWIT/TYKnXA2XcxdQtw==",
              "$type": "04"
            }
          }
        }
      },
      "support": 15
    },
    {
      "x": 4,
      "y": 3,
      "z": -5,
      "name": "Editor_Empty"
    },
    {
      "x": 4,
      "y": 4,
      "z": -5,
      "name": "Editor_Empty"
    },
    {
      "x": 4,
      "y": 5,
      "z": -5,
      "name": "Editor_Empty"
    },
    {
      "x": 4,
      "y": 6,
      "z": -5,
      "name": "Editor_Empty"
    },
    {
      "x": 4,
      "y": 7,
      "z": -5,
      "name": "Editor_Empty"
    },
    {
      "x": 4,
      "y": 8,
      "z": -5,
      "name": "Editor_Empty"
    },
    {
      "x": 4,
      "y": 9,
      "z": -5,
      "name": "Editor_Empty"
    },
    {
      "x": 4,
      "y": 10,
      "z": -5,
      "name": "Editor_Empty"
    },
    {
      "x": 4,
      "y": 11,
      "z": -5,
      "name": "Editor_Empty"
    },
    {
      "x": 4,
      "y": 12,
      "z": -5,
      "name": "Editor_Empty"
    },
    {
      "x": 4,
      "y": 1,
      "z": -4,
      "name": "Rock_Sandstone_Red_Cobble"
    },
    {
      "x": 4,
      "y": 2,
      "z": -4,
      "name": "Editor_Empty"
    },
    {
      "x": 4,
      "y": 3,
      "z": -4,
      "name": "Editor_Empty"
    },
    {
      "x": 4,
      "y": 4,
      "z": -4,
      "name": "Editor_Empty"
    },
    {
      "x": 4,
      "y": 5,
      "z": -4,
      "name": "Editor_Empty"
    },
    {
      "x": 4,
      "y": 6,
      "z": -4,
      "name": "Editor_Empty"
    },
    {
      "x": 4,
      "y": 7,
      "z": -4,
      "name": "Editor_Empty"
    },
    {
      "x": 4,
      "y": 8,
      "z": -4,
      "name": "Editor_Empty"
    },
    {
      "x": 4,
      "y": 9,
      "z": -4,
      "name": "Editor_Empty"
    },
    {
      "x": 4,
      "y": 10,
      "z": -4,
      "name": "Editor_Empty"
    },
    {
      "x": 4,
      "y": 11,
      "z": -4,
      "name": "Editor_Empty"
    },
    {
      "x": 4,
      "y": 12,
      "z": -4,
      "name": "Editor_Empty"
    },
    {
      "x": 4,
      "y": 1,
      "z": -3,
      "name": "Rock_Sandstone_Red_Cobble"
    },
    {
      "x": 4,
      "y": 2,
      "z": -3,
      "name": "Editor_Empty"
    },
    {
      "x": 4,
      "y": 3,
      "z": -3,
      "name": "Editor_Empty"
    },
    {
      "x": 4,
      "y": 4,
      "z": -3,
      "name": "Editor_Empty"
    },
    {
      "x": 4,
      "y": 5,
      "z": -3,
      "name": "Editor_Empty"
    },
    {
      "x": 4,
      "y": 6,
      "z": -3,
      "name": "Editor_Empty"
    },
    {
      "x": 4,
      "y": 7,
      "z": -3,
      "name": "Editor_Empty"
    },
    {
      "x": 4,
      "y": 8,
      "z": -3,
      "name": "Editor_Empty"
    },
    {
      "x": 4,
      "y": 9,
      "z": -3,
      "name": "Editor_Empty"
    },
    {
      "x": 4,
      "y": 10,
      "z": -3,
      "name": "Editor_Empty"
    },
    {
      "x": 4,
      "y": 11,
      "z": -3,
      "name": "Editor_Empty"
    },
    {
      "x": 4,
      "y": 12,
      "z": -3,
      "name": "Editor_Empty"
    },
    {
      "x": 4,
      "y": 1,
      "z": -2,
      "name": "Rock_Sandstone_Red_Cobble"
    },
    {
      "x": 4,
      "y": 2,
      "z": -2,
      "name": "Editor_Empty"
    },
    {
      "x": 4,
      "y": 3,
      "z": -2,
      "name": "Editor_Empty"
    },
    {
      "x": 4,
      "y": 4,
      "z": -2,
      "name": "Editor_Empty"
    },
    {
      "x": 4,
      "y": 5,
      "z": -2,
      "name": "Editor_Empty"
    },
    {
      "x": 4,
      "y": 6,
      "z": -2,
      "name": "Editor_Empty"
    },
    {
      "x": 4,
      "y": 7,
      "z": -2,
      "name": "Editor_Empty"
    },
    {
      "x": 4,
      "y": 8,
      "z": -2,
      "name": "Editor_Empty"
    },
    {
      "x": 4,
      "y": 9,
      "z": -2,
      "name": "Editor_Empty"
    },
    {
      "x": 4,
      "y": 10,
      "z": -2,
      "name": "Editor_Empty"
    },
    {
      "x": 4,
      "y": 11,
      "z": -2,
      "name": "Editor_Empty"
    },
    {
      "x": 4,
      "y": 12,
      "z": -2,
      "name": "Editor_Empty"
    },
    {
      "x": 4,
      "y": 1,
      "z": -1,
      "name": "Rock_Stone_Brick_Smooth"
    },
    {
      "x": 4,
      "y": 2,
      "z": -1,
      "name": "Editor_Empty"
    },
    {
      "x": 4,
      "y": 3,
      "z": -1,
      "name": "Editor_Empty"
    },
    {
      "x": 4,
      "y": 4,
      "z": -1,
      "name": "Editor_Empty"
    },
    {
      "x": 4,
      "y": 5,
      "z": -1,
      "name": "Editor_Empty"
    },
    {
      "x": 4,
      "y": 6,
      "z": -1,
      "name": "Editor_Empty"
    },
    {
      "x": 4,
      "y": 7,
      "z": -1,
      "name": "Editor_Empty"
    },
    {
      "x": 4,
      "y": 8,
      "z": -1,
      "name": "Editor_Empty"
    },
    {
      "x": 4,
      "y": 9,
      "z": -1,
      "name": "Editor_Empty"
    },
    {
      "x": 4,
      "y": 10,
      "z": -1,
      "name": "Editor_Empty"
    },
    {
      "x": 4,
      "y": 11,
      "z": -1,
      "name": "Editor_Empty"
    },
    {
      "x": 4,
      "y": 12,
      "z": -1,
      "name": "Editor_Empty"
    },
    {
      "x": 5,
      "y": 1,
      "z": -12,
      "name": "Rock_Stone_Brick_Smooth"
    },
    {
      "x": 5,
      "y": 2,
      "z": -12,
      "name": "Editor_Empty"
    },
    {
      "x": 5,
      "y": 3,
      "z": -12,
      "name": "Editor_Empty"
    },
    {
      "x": 5,
      "y": 4,
      "z": -12,
      "name": "Editor_Empty"
    },
    {
      "x": 5,
      "y": 5,
      "z": -12,
      "name": "Editor_Empty"
    },
    {
      "x": 5,
      "y": 6,
      "z": -12,
      "name": "Editor_Empty"
    },
    {
      "x": 5,
      "y": 7,
      "z": -12,
      "name": "Editor_Empty"
    },
    {
      "x": 5,
      "y": 8,
      "z": -12,
      "name": "Editor_Empty"
    },
    {
      "x": 5,
      "y": 9,
      "z": -12,
      "name": "Editor_Empty"
    },
    {
      "x": 5,
      "y": 10,
      "z": -12,
      "name": "Editor_Empty"
    },
    {
      "x": 5,
      "y": 11,
      "z": -12,
      "name": "Editor_Empty"
    },
    {
      "x": 5,
      "y": 12,
      "z": -12,
      "name": "Editor_Empty"
    },
    {
      "x": 5,
      "y": 1,
      "z": -11,
      "name": "Rock_Sandstone_Red_Cobble"
    },
    {
      "x": 5,
      "y": 2,
      "z": -11,
      "name": "Editor_Empty"
    },
    {
      "x": 5,
      "y": 3,
      "z": -11,
      "name": "Editor_Empty"
    },
    {
      "x": 5,
      "y": 4,
      "z": -11,
      "name": "Editor_Empty"
    },
    {
      "x": 5,
      "y": 5,
      "z": -11,
      "name": "Editor_Empty"
    },
    {
      "x": 5,
      "y": 6,
      "z": -11,
      "name": "Editor_Empty"
    },
    {
      "x": 5,
      "y": 7,
      "z": -11,
      "name": "Editor_Empty"
    },
    {
      "x": 5,
      "y": 8,
      "z": -11,
      "name": "Editor_Empty"
    },
    {
      "x": 5,
      "y": 9,
      "z": -11,
      "name": "Editor_Empty"
    },
    {
      "x": 5,
      "y": 10,
      "z": -11,
      "name": "Editor_Empty"
    },
    {
      "x": 5,
      "y": 11,
      "z": -11,
      "name": "Editor_Empty"
    },
    {
      "x": 5,
      "y": 12,
      "z": -11,
      "name": "Editor_Empty"
    },
    {
      "x": 5,
      "y": 1,
      "z": -10,
      "name": "Rock_Sandstone_Red_Cobble"
    },
    {
      "x": 5,
      "y": 2,
      "z": -10,
      "name": "Editor_Empty"
    },
    {
      "x": 5,
      "y": 3,
      "z": -10,
      "name": "Editor_Empty"
    },
    {
      "x": 5,
      "y": 4,
      "z": -10,
      "name": "Editor_Empty"
    },
    {
      "x": 5,
      "y": 5,
      "z": -10,
      "name": "Editor_Empty"
    },
    {
      "x": 5,
      "y": 6,
      "z": -10,
      "name": "Editor_Empty"
    },
    {
      "x": 5,
      "y": 7,
      "z": -10,
      "name": "Editor_Empty"
    },
    {
      "x": 5,
      "y": 8,
      "z": -10,
      "name": "Editor_Empty"
    },
    {
      "x": 5,
      "y": 9,
      "z": -10,
      "name": "Editor_Empty"
    },
    {
      "x": 5,
      "y": 10,
      "z": -10,
      "name": "Editor_Empty"
    },
    {
      "x": 5,
      "y": 11,
      "z": -10,
      "name": "Editor_Empty"
    },
    {
      "x": 5,
      "y": 12,
      "z": -10,
      "name": "Editor_Empty"
    },
    {
      "x": 5,
      "y": 1,
      "z": -9,
      "name": "Rock_Stone_Brick",
      "rotation": 2
    },
    {
      "x": 5,
      "y": 2,
      "z": -9,
      "name": "Rock_Stone_Brick_Smooth",
      "rotation": 2
    },
    {
      "x": 5,
      "y": 3,
      "z": -9,
      "name": "Furniture_Village_Brazier",
      "rotation": 2
    },
    {
      "x": 5,
      "y": 4,
      "z": -9,
      "name": "Editor_Empty"
    },
    {
      "x": 5,
      "y": 5,
      "z": -9,
      "name": "Editor_Empty"
    },
    {
      "x": 5,
      "y": 6,
      "z": -9,
      "name": "Editor_Empty"
    },
    {
      "x": 5,
      "y": 7,
      "z": -9,
      "name": "Editor_Empty"
    },
    {
      "x": 5,
      "y": 8,
      "z": -9,
      "name": "Editor_Empty"
    },
    {
      "x": 5,
      "y": 9,
      "z": -9,
      "name": "Editor_Empty"
    },
    {
      "x": 5,
      "y": 10,
      "z": -9,
      "name": "Editor_Empty"
    },
    {
      "x": 5,
      "y": 11,
      "z": -9,
      "name": "Editor_Empty"
    },
    {
      "x": 5,
      "y": 12,
      "z": -9,
      "name": "Editor_Empty"
    },
    {
      "x": 5,
      "y": 1,
      "z": -8,
      "name": "Rock_Stone_Brick",
      "rotation": 2
    },
    {
      "x": 5,
      "y": 2,
      "z": -8,
      "name": "Rock_Crystal_Purple_Block",
      "rotation": 2
    },
    {
      "x": 5,
      "y": 3,
      "z": -8,
      "name": "Rock_Stone_Brick",
      "rotation": 2
    },
    {
      "x": 5,
      "y": 4,
      "z": -8,
      "name": "Rock_Stone_Brick_Stairs",
      "rotation": 1
    },
    {
      "x": 5,
      "y": 5,
      "z": -8,
      "name": "Editor_Empty"
    },
    {
      "x": 5,
      "y": 6,
      "z": -8,
      "name": "Editor_Empty"
    },
    {
      "x": 5,
      "y": 7,
      "z": -8,
      "name": "Rock_Stone_Brick_Stairs",
      "rotation": 33
    },
    {
      "x": 5,
      "y": 8,
      "z": -8,
      "name": "Rock_Stone_Brick",
      "rotation": 2
    },
    {
      "x": 5,
      "y": 9,
      "z": -8,
      "name": "Rock_Crystal_Purple_Block",
      "rotation": 6
    },
    {
      "x": 5,
      "y": 10,
      "z": -8,
      "name": "Rock_Stone_Brick",
      "rotation": 2
    },
    {
      "x": 5,
      "y": 11,
      "z": -8,
      "name": "Rock_Stone_Brick_Stairs",
      "rotation": 3
    },
    {
      "x": 5,
      "y": 12,
      "z": -8,
      "name": "Editor_Empty"
    },
    {
      "x": 5,
      "y": 1,
      "z": -7,
      "name": "Rock_Stone_Brick"
    },
    {
      "x": 5,
      "y": 2,
      "z": -7,
      "name": "Rock_Stone_Brick"
    },
    {
      "x": 5,
      "y": 3,
      "z": -7,
      "name": "Rock_Stone_Brick"
    },
    {
      "x": 5,
      "y": 4,
      "z": -7,
      "name": "Rock_Stone_Brick_Stairs",
      "rotation": 1
    },
    {
      "x": 5,
      "y": 5,
      "z": -7,
      "name": "Editor_Empty"
    },
    {
      "x": 5,
      "y": 6,
      "z": -7,
      "name": "Editor_Empty"
    },
    {
      "x": 5,
      "y": 7,
      "z": -7,
      "name": "Rock_Stone_Brick_Stairs",
      "rotation": 11
    },
    {
      "x": 5,
      "y": 8,
      "z": -7,
      "name": "Rock_Stone_Brick"
    },
    {
      "x": 5,
      "y": 9,
      "z": -7,
      "name": "Rock_Crystal_Purple_Block"
    },
    {
      "x": 5,
      "y": 10,
      "z": -7,
      "name": "Rock_Stone_Brick"
    },
    {
      "x": 5,
      "y": 11,
      "z": -7,
      "name": "Rock_Stone_Brick_Stairs",
      "rotation": 3
    },
    {
      "x": 5,
      "y": 12,
      "z": -7,
      "name": "Editor_Empty"
    },
    {
      "x": 5,
      "y": 1,
      "z": -6,
      "name": "Rock_Stone_Brick"
    },
    {
      "x": 5,
      "y": 2,
      "z": -6,
      "name": "Rock_Crystal_Purple_Block"
    },
    {
      "x": 5,
      "y": 3,
      "z": -6,
      "name": "Rock_Stone_Brick"
    },
    {
      "x": 5,
      "y": 4,
      "z": -6,
      "name": "Rock_Stone_Brick_Stairs",
      "rotation": 1
    },
    {
      "x": 5,
      "y": 5,
      "z": -6,
      "name": "Editor_Empty"
    },
    {
      "x": 5,
      "y": 6,
      "z": -6,
      "name": "Editor_Empty"
    },
    {
      "x": 5,
      "y": 7,
      "z": -6,
      "name": "Rock_Stone_Brick_Stairs",
      "rotation": 11
    },
    {
      "x": 5,
      "y": 8,
      "z": -6,
      "name": "Rock_Stone_Brick"
    },
    {
      "x": 5,
      "y": 9,
      "z": -6,
      "name": "Rock_Crystal_Purple_Block",
      "rotation": 4
    },
    {
      "x": 5,
      "y": 10,
      "z": -6,
      "name": "Rock_Stone_Brick"
    },
    {
      "x": 5,
      "y": 11,
      "z": -6,
      "name": "Rock_Stone_Brick_Stairs",
      "rotation": 3
    },
    {
      "x": 5,
      "y": 12,
      "z": -6,
      "name": "Editor_Empty"
    },
    {
      "x": 5,
      "y": 1,
      "z": -5,
      "name": "Rock_Stone_Brick"
    },
    {
      "x": 5,
      "y": 2,
      "z": -5,
      "name": "Rock_Stone_Brick_Smooth"
    },
    {
      "x": 5,
      "y": 3,
      "z": -5,
      "name": "Furniture_Village_Brazier"
    },
    {
      "x": 5,
      "y": 4,
      "z": -5,
      "name": "Editor_Empty"
    },
    {
      "x": 5,
      "y": 5,
      "z": -5,
      "name": "Editor_Empty"
    },
    {
      "x": 5,
      "y": 6,
      "z": -5,
      "name": "Editor_Empty"
    },
    {
      "x": 5,
      "y": 7,
      "z": -5,
      "name": "Editor_Empty"
    },
    {
      "x": 5,
      "y": 8,
      "z": -5,
      "name": "Editor_Empty"
    },
    {
      "x": 5,
      "y": 9,
      "z": -5,
      "name": "Editor_Empty"
    },
    {
      "x": 5,
      "y": 10,
      "z": -5,
      "name": "Editor_Empty"
    },
    {
      "x": 5,
      "y": 11,
      "z": -5,
      "name": "Editor_Empty"
    },
    {
      "x": 5,
      "y": 12,
      "z": -5,
      "name": "Editor_Empty"
    },
    {
      "x": 5,
      "y": 1,
      "z": -4,
      "name": "Rock_Sandstone_Red_Cobble"
    },
    {
      "x": 5,
      "y": 2,
      "z": -4,
      "name": "Editor_Empty"
    },
    {
      "x": 5,
      "y": 3,
      "z": -4,
      "name": "Editor_Empty"
    },
    {
      "x": 5,
      "y": 4,
      "z": -4,
      "name": "Editor_Empty"
    },
    {
      "x": 5,
      "y": 5,
      "z": -4,
      "name": "Editor_Empty"
    },
    {
      "x": 5,
      "y": 6,
      "z": -4,
      "name": "Editor_Empty"
    },
    {
      "x": 5,
      "y": 7,
      "z": -4,
      "name": "Editor_Empty"
    },
    {
      "x": 5,
      "y": 8,
      "z": -4,
      "name": "Editor_Empty"
    },
    {
      "x": 5,
      "y": 9,
      "z": -4,
      "name": "Editor_Empty"
    },
    {
      "x": 5,
      "y": 10,
      "z": -4,
      "name": "Editor_Empty"
    },
    {
      "x": 5,
      "y": 11,
      "z": -4,
      "name": "Editor_Empty"
    },
    {
      "x": 5,
      "y": 12,
      "z": -4,
      "name": "Editor_Empty"
    },
    {
      "x": 5,
      "y": 1,
      "z": -3,
      "name": "Rock_Sandstone_Red_Cobble"
    },
    {
      "x": 5,
      "y": 2,
      "z": -3,
      "name": "Editor_Empty"
    },
    {
      "x": 5,
      "y": 3,
      "z": -3,
      "name": "Editor_Empty"
    },
    {
      "x": 5,
      "y": 4,
      "z": -3,
      "name": "Editor_Empty"
    },
    {
      "x": 5,
      "y": 5,
      "z": -3,
      "name": "Editor_Empty"
    },
    {
      "x": 5,
      "y": 6,
      "z": -3,
      "name": "Editor_Empty"
    },
    {
      "x": 5,
      "y": 7,
      "z": -3,
      "name": "Editor_Empty"
    },
    {
      "x": 5,
      "y": 8,
      "z": -3,
      "name": "Editor_Empty"
    },
    {
      "x": 5,
      "y": 9,
      "z": -3,
      "name": "Editor_Empty"
    },
    {
      "x": 5,
      "y": 10,
      "z": -3,
      "name": "Editor_Empty"
    },
    {
      "x": 5,
      "y": 11,
      "z": -3,
      "name": "Editor_Empty"
    },
    {
      "x": 5,
      "y": 12,
      "z": -3,
      "name": "Editor_Empty"
    },
    {
      "x": 5,
      "y": 1,
      "z": -2,
      "name": "Rock_Sandstone_Red_Cobble"
    },
    {
      "x": 5,
      "y": 2,
      "z": -2,
      "name": "Editor_Empty"
    },
    {
      "x": 5,
      "y": 3,
      "z": -2,
      "name": "Editor_Empty"
    },
    {
      "x": 5,
      "y": 4,
      "z": -2,
      "name": "Editor_Empty"
    },
    {
      "x": 5,
      "y": 5,
      "z": -2,
      "name": "Editor_Empty"
    },
    {
      "x": 5,
      "y": 6,
      "z": -2,
      "name": "Editor_Empty"
    },
    {
      "x": 5,
      "y": 7,
      "z": -2,
      "name": "Editor_Empty"
    },
    {
      "x": 5,
      "y": 8,
      "z": -2,
      "name": "Editor_Empty"
    },
    {
      "x": 5,
      "y": 9,
      "z": -2,
      "name": "Editor_Empty"
    },
    {
      "x": 5,
      "y": 10,
      "z": -2,
      "name": "Editor_Empty"
    },
    {
      "x": 5,
      "y": 11,
      "z": -2,
      "name": "Editor_Empty"
    },
    {
      "x": 5,
      "y": 12,
      "z": -2,
      "name": "Editor_Empty"
    },
    {
      "x": 5,
      "y": 1,
      "z": -1,
      "name": "Rock_Stone_Brick_Smooth"
    },
    {
      "x": 5,
      "y": 2,
      "z": -1,
      "name": "Editor_Empty"
    },
    {
      "x": 5,
      "y": 3,
      "z": -1,
      "name": "Editor_Empty"
    },
    {
      "x": 5,
      "y": 4,
      "z": -1,
      "name": "Editor_Empty"
    },
    {
      "x": 5,
      "y": 5,
      "z": -1,
      "name": "Editor_Empty"
    },
    {
      "x": 5,
      "y": 6,
      "z": -1,
      "name": "Editor_Empty"
    },
    {
      "x": 5,
      "y": 7,
      "z": -1,
      "name": "Editor_Empty"
    },
    {
      "x": 5,
      "y": 8,
      "z": -1,
      "name": "Editor_Empty"
    },
    {
      "x": 5,
      "y": 9,
      "z": -1,
      "name": "Editor_Empty"
    },
    {
      "x": 5,
      "y": 10,
      "z": -1,
      "name": "Editor_Empty"
    },
    {
      "x": 5,
      "y": 11,
      "z": -1,
      "name": "Editor_Empty"
    },
    {
      "x": 5,
      "y": 12,
      "z": -1,
      "name": "Editor_Empty"
    },
    {
      "x": 6,
      "y": 1,
      "z": -12,
      "name": "Rock_Stone_Brick_Smooth"
    },
    {
      "x": 6,
      "y": 2,
      "z": -12,
      "name": "Editor_Empty"
    },
    {
      "x": 6,
      "y": 3,
      "z": -12,
      "name": "Editor_Empty"
    },
    {
      "x": 6,
      "y": 4,
      "z": -12,
      "name": "Editor_Empty"
    },
    {
      "x": 6,
      "y": 5,
      "z": -12,
      "name": "Editor_Empty"
    },
    {
      "x": 6,
      "y": 6,
      "z": -12,
      "name": "Editor_Empty"
    },
    {
      "x": 6,
      "y": 7,
      "z": -12,
      "name": "Editor_Empty"
    },
    {
      "x": 6,
      "y": 8,
      "z": -12,
      "name": "Editor_Empty"
    },
    {
      "x": 6,
      "y": 9,
      "z": -12,
      "name": "Editor_Empty"
    },
    {
      "x": 6,
      "y": 10,
      "z": -12,
      "name": "Editor_Empty"
    },
    {
      "x": 6,
      "y": 11,
      "z": -12,
      "name": "Editor_Empty"
    },
    {
      "x": 6,
      "y": 12,
      "z": -12,
      "name": "Editor_Empty"
    },
    {
      "x": 6,
      "y": 1,
      "z": -11,
      "name": "Rock_Sandstone_Red_Cobble"
    },
    {
      "x": 6,
      "y": 2,
      "z": -11,
      "name": "Editor_Empty"
    },
    {
      "x": 6,
      "y": 3,
      "z": -11,
      "name": "Editor_Empty"
    },
    {
      "x": 6,
      "y": 4,
      "z": -11,
      "name": "Editor_Empty"
    },
    {
      "x": 6,
      "y": 5,
      "z": -11,
      "name": "Editor_Empty"
    },
    {
      "x": 6,
      "y": 6,
      "z": -11,
      "name": "Editor_Empty"
    },
    {
      "x": 6,
      "y": 7,
      "z": -11,
      "name": "Editor_Empty"
    },
    {
      "x": 6,
      "y": 8,
      "z": -11,
      "name": "Editor_Empty"
    },
    {
      "x": 6,
      "y": 9,
      "z": -11,
      "name": "Editor_Empty"
    },
    {
      "x": 6,
      "y": 10,
      "z": -11,
      "name": "Editor_Empty"
    },
    {
      "x": 6,
      "y": 11,
      "z": -11,
      "name": "Editor_Empty"
    },
    {
      "x": 6,
      "y": 12,
      "z": -11,
      "name": "Editor_Empty"
    },
    {
      "x": 6,
      "y": 1,
      "z": -10,
      "name": "Rock_Sandstone_Red_Cobble"
    },
    {
      "x": 6,
      "y": 2,
      "z": -10,
      "name": "Editor_Empty"
    },
    {
      "x": 6,
      "y": 3,
      "z": -10,
      "name": "Editor_Empty"
    },
    {
      "x": 6,
      "y": 4,
      "z": -10,
      "name": "Editor_Empty"
    },
    {
      "x": 6,
      "y": 5,
      "z": -10,
      "name": "Editor_Empty"
    },
    {
      "x": 6,
      "y": 6,
      "z": -10,
      "name": "Editor_Empty"
    },
    {
      "x": 6,
      "y": 7,
      "z": -10,
      "name": "Editor_Empty"
    },
    {
      "x": 6,
      "y": 8,
      "z": -10,
      "name": "Editor_Empty"
    },
    {
      "x": 6,
      "y": 9,
      "z": -10,
      "name": "Editor_Empty"
    },
    {
      "x": 6,
      "y": 10,
      "z": -10,
      "name": "Editor_Empty"
    },
    {
      "x": 6,
      "y": 11,
      "z": -10,
      "name": "Editor_Empty"
    },
    {
      "x": 6,
      "y": 12,
      "z": -10,
      "name": "Editor_Empty"
    },
    {
      "x": 6,
      "y": 1,
      "z": -9,
      "name": "Rock_Stone_Brick",
      "rotation": 2
    },
    {
      "x": 6,
      "y": 2,
      "z": -9,
      "name": "Editor_Empty"
    },
    {
      "x": 6,
      "y": 3,
      "z": -9,
      "name": "Editor_Empty"
    },
    {
      "x": 6,
      "y": 4,
      "z": -9,
      "name": "Editor_Empty"
    },
    {
      "x": 6,
      "y": 5,
      "z": -9,
      "name": "Editor_Empty"
    },
    {
      "x": 6,
      "y": 6,
      "z": -9,
      "name": "Editor_Empty"
    },
    {
      "x": 6,
      "y": 7,
      "z": -9,
      "name": "Editor_Empty"
    },
    {
      "x": 6,
      "y": 8,
      "z": -9,
      "name": "Editor_Empty"
    },
    {
      "x": 6,
      "y": 9,
      "z": -9,
      "name": "Editor_Empty"
    },
    {
      "x": 6,
      "y": 10,
      "z": -9,
      "name": "Editor_Empty"
    },
    {
      "x": 6,
      "y": 11,
      "z": -9,
      "name": "Editor_Empty"
    },
    {
      "x": 6,
      "y": 12,
      "z": -9,
      "name": "Editor_Empty"
    },
    {
      "x": 6,
      "y": 1,
      "z": -8,
      "name": "Rock_Stone_Brick",
      "rotation": 2
    },
    {
      "x": 6,
      "y": 2,
      "z": -8,
      "name": "Rock_Stone_Brick_Stairs",
      "rotation": 1
    },
    {
      "x": 6,
      "y": 3,
      "z": -8,
      "name": "Editor_Empty"
    },
    {
      "x": 6,
      "y": 4,
      "z": -8,
      "name": "Editor_Empty"
    },
    {
      "x": 6,
      "y": 5,
      "z": -8,
      "name": "Editor_Empty"
    },
    {
      "x": 6,
      "y": 6,
      "z": -8,
      "name": "Editor_Empty"
    },
    {
      "x": 6,
      "y": 7,
      "z": -8,
      "name": "Editor_Empty"
    },
    {
      "x": 6,
      "y": 8,
      "z": -8,
      "name": "Rock_Stone_Brick_Stairs",
      "rotation": 33
    },
    {
      "x": 6,
      "y": 9,
      "z": -8,
      "name": "Rock_Stone_Brick",
      "rotation": 2
    },
    {
      "x": 6,
      "y": 10,
      "z": -8,
      "name": "Rock_Crystal_Purple_Block",
      "rotation": 6
    },
    {
      "x": 6,
      "y": 11,
      "z": -8,
      "name": "Rock_Stone_Brick",
      "rotation": 2
    },
    {
      "x": 6,
      "y": 12,
      "z": -8,
      "name": "Editor_Empty"
    },
    {
      "x": 6,
      "y": 1,
      "z": -7,
      "name": "Rock_Stone_Brick"
    },
    {
      "x": 6,
      "y": 2,
      "z": -7,
      "name": "Rock_Stone_Brick_Stairs",
      "rotation": 1
    },
    {
      "x": 6,
      "y": 3,
      "z": -7,
      "name": "Editor_Empty"
    },
    {
      "x": 6,
      "y": 4,
      "z": -7,
      "name": "Editor_Empty"
    },
    {
      "x": 6,
      "y": 5,
      "z": -7,
      "name": "Editor_Empty"
    },
    {
      "x": 6,
      "y": 6,
      "z": -7,
      "name": "Editor_Empty"
    },
    {
      "x": 6,
      "y": 7,
      "z": -7,
      "name": "Editor_Empty"
    },
    {
      "x": 6,
      "y": 8,
      "z": -7,
      "name": "Rock_Stone_Brick_Stairs",
      "rotation": 11
    },
    {
      "x": 6,
      "y": 9,
      "z": -7,
      "name": "Rock_Stone_Brick"
    },
    {
      "x": 6,
      "y": 10,
      "z": -7,
      "name": "Rock_Stone_Brick"
    },
    {
      "x": 6,
      "y": 11,
      "z": -7,
      "name": "Rock_Stone_Brick"
    },
    {
      "x": 6,
      "y": 12,
      "z": -7,
      "name": "Editor_Empty"
    },
    {
      "x": 6,
      "y": 1,
      "z": -6,
      "name": "Rock_Stone_Brick"
    },
    {
      "x": 6,
      "y": 2,
      "z": -6,
      "name": "Rock_Stone_Brick_Stairs",
      "rotation": 1
    },
    {
      "x": 6,
      "y": 3,
      "z": -6,
      "name": "Editor_Empty"
    },
    {
      "x": 6,
      "y": 4,
      "z": -6,
      "name": "Editor_Empty"
    },
    {
      "x": 6,
      "y": 5,
      "z": -6,
      "name": "Editor_Empty"
    },
    {
      "x": 6,
      "y": 6,
      "z": -6,
      "name": "Editor_Empty"
    },
    {
      "x": 6,
      "y": 7,
      "z": -6,
      "name": "Editor_Empty"
    },
    {
      "x": 6,
      "y": 8,
      "z": -6,
      "name": "Rock_Stone_Brick_Stairs",
      "rotation": 11
    },
    {
      "x": 6,
      "y": 9,
      "z": -6,
      "name": "Rock_Stone_Brick"
    },
    {
      "x": 6,
      "y": 10,
      "z": -6,
      "name": "Rock_Crystal_Purple_Block",
      "rotation": 4
    },
    {
      "x": 6,
      "y": 11,
      "z": -6,
      "name": "Rock_Stone_Brick"
    },
    {
      "x": 6,
      "y": 12,
      "z": -6,
      "name": "Editor_Empty"
    },
    {
      "x": 6,
      "y": 1,
      "z": -5,
      "name": "Rock_Stone_Brick"
    },
    {
      "x": 6,
      "y": 2,
      "z": -5,
      "name": "Editor_Empty"
    },
    {
      "x": 6,
      "y": 3,
      "z": -5,
      "name": "Editor_Empty"
    },
    {
      "x": 6,
      "y": 4,
      "z": -5,
      "name": "Editor_Empty"
    },
    {
      "x": 6,
      "y": 5,
      "z": -5,
      "name": "Editor_Empty"
    },
    {
      "x": 6,
      "y": 6,
      "z": -5,
      "name": "Editor_Empty"
    },
    {
      "x": 6,
      "y": 7,
      "z": -5,
      "name": "Editor_Empty"
    },
    {
      "x": 6,
      "y": 8,
      "z": -5,
      "name": "Editor_Empty"
    },
    {
      "x": 6,
      "y": 9,
      "z": -5,
      "name": "Editor_Empty"
    },
    {
      "x": 6,
      "y": 10,
      "z": -5,
      "name": "Editor_Empty"
    },
    {
      "x": 6,
      "y": 11,
      "z": -5,
      "name": "Editor_Empty"
    },
    {
      "x": 6,
      "y": 12,
      "z": -5,
      "name": "Editor_Empty"
    },
    {
      "x": 6,
      "y": 1,
      "z": -4,
      "name": "Rock_Sandstone_Red_Cobble"
    },
    {
      "x": 6,
      "y": 2,
      "z": -4,
      "name": "Editor_Empty"
    },
    {
      "x": 6,
      "y": 3,
      "z": -4,
      "name": "Editor_Empty"
    },
    {
      "x": 6,
      "y": 4,
      "z": -4,
      "name": "Editor_Empty"
    },
    {
      "x": 6,
      "y": 5,
      "z": -4,
      "name": "Editor_Empty"
    },
    {
      "x": 6,
      "y": 6,
      "z": -4,
      "name": "Editor_Empty"
    },
    {
      "x": 6,
      "y": 7,
      "z": -4,
      "name": "Editor_Empty"
    },
    {
      "x": 6,
      "y": 8,
      "z": -4,
      "name": "Editor_Empty"
    },
    {
      "x": 6,
      "y": 9,
      "z": -4,
      "name": "Editor_Empty"
    },
    {
      "x": 6,
      "y": 10,
      "z": -4,
      "name": "Editor_Empty"
    },
    {
      "x": 6,
      "y": 11,
      "z": -4,
      "name": "Editor_Empty"
    },
    {
      "x": 6,
      "y": 12,
      "z": -4,
      "name": "Editor_Empty"
    },
    {
      "x": 6,
      "y": 1,
      "z": -3,
      "name": "Rock_Sandstone_Red_Cobble"
    },
    {
      "x": 6,
      "y": 2,
      "z": -3,
      "name": "Editor_Empty"
    },
    {
      "x": 6,
      "y": 3,
      "z": -3,
      "name": "Editor_Empty"
    },
    {
      "x": 6,
      "y": 4,
      "z": -3,
      "name": "Editor_Empty"
    },
    {
      "x": 6,
      "y": 5,
      "z": -3,
      "name": "Editor_Empty"
    },
    {
      "x": 6,
      "y": 6,
      "z": -3,
      "name": "Editor_Empty"
    },
    {
      "x": 6,
      "y": 7,
      "z": -3,
      "name": "Editor_Empty"
    },
    {
      "x": 6,
      "y": 8,
      "z": -3,
      "name": "Editor_Empty"
    },
    {
      "x": 6,
      "y": 9,
      "z": -3,
      "name": "Editor_Empty"
    },
    {
      "x": 6,
      "y": 10,
      "z": -3,
      "name": "Editor_Empty"
    },
    {
      "x": 6,
      "y": 11,
      "z": -3,
      "name": "Editor_Empty"
    },
    {
      "x": 6,
      "y": 12,
      "z": -3,
      "name": "Editor_Empty"
    },
    {
      "x": 6,
      "y": 1,
      "z": -2,
      "name": "Rock_Sandstone_Red_Cobble"
    },
    {
      "x": 6,
      "y": 2,
      "z": -2,
      "name": "Editor_Empty"
    },
    {
      "x": 6,
      "y": 3,
      "z": -2,
      "name": "Editor_Empty"
    },
    {
      "x": 6,
      "y": 4,
      "z": -2,
      "name": "Editor_Empty"
    },
    {
      "x": 6,
      "y": 5,
      "z": -2,
      "name": "Editor_Empty"
    },
    {
      "x": 6,
      "y": 6,
      "z": -2,
      "name": "Editor_Empty"
    },
    {
      "x": 6,
      "y": 7,
      "z": -2,
      "name": "Editor_Empty"
    },
    {
      "x": 6,
      "y": 8,
      "z": -2,
      "name": "Editor_Empty"
    },
    {
      "x": 6,
      "y": 9,
      "z": -2,
      "name": "Editor_Empty"
    },
    {
      "x": 6,
      "y": 10,
      "z": -2,
      "name": "Editor_Empty"
    },
    {
      "x": 6,
      "y": 11,
      "z": -2,
      "name": "Editor_Empty"
    },
    {
      "x": 6,
      "y": 12,
      "z": -2,
      "name": "Editor_Empty"
    },
    {
      "x": 6,
      "y": 1,
      "z": -1,
      "name": "Rock_Stone_Brick_Smooth"
    },
    {
      "x": 6,
      "y": 2,
      "z": -1,
      "name": "Editor_Empty"
    },
    {
      "x": 6,
      "y": 3,
      "z": -1,
      "name": "Editor_Empty"
    },
    {
      "x": 6,
      "y": 4,
      "z": -1,
      "name": "Editor_Empty"
    },
    {
      "x": 6,
      "y": 5,
      "z": -1,
      "name": "Editor_Empty"
    },
    {
      "x": 6,
      "y": 6,
      "z": -1,
      "name": "Editor_Empty"
    },
    {
      "x": 6,
      "y": 7,
      "z": -1,
      "name": "Editor_Empty"
    },
    {
      "x": 6,
      "y": 8,
      "z": -1,
      "name": "Editor_Empty"
    },
    {
      "x": 6,
      "y": 9,
      "z": -1,
      "name": "Editor_Empty"
    },
    {
      "x": 6,
      "y": 10,
      "z": -1,
      "name": "Editor_Empty"
    },
    {
      "x": 6,
      "y": 11,
      "z": -1,
      "name": "Editor_Empty"
    },
    {
      "x": 6,
      "y": 12,
      "z": -1,
      "name": "Editor_Empty"
    },
    {
      "x": 7,
      "y": 1,
      "z": -12,
      "name": "Rock_Stone_Brick_Smooth"
    },
    {
      "x": 7,
      "y": 2,
      "z": -12,
      "name": "Editor_Empty"
    },
    {
      "x": 7,
      "y": 3,
      "z": -12,
      "name": "Editor_Empty"
    },
    {
      "x": 7,
      "y": 4,
      "z": -12,
      "name": "Editor_Empty"
    },
    {
      "x": 7,
      "y": 5,
      "z": -12,
      "name": "Editor_Empty"
    },
    {
      "x": 7,
      "y": 6,
      "z": -12,
      "name": "Editor_Empty"
    },
    {
      "x": 7,
      "y": 7,
      "z": -12,
      "name": "Editor_Empty"
    },
    {
      "x": 7,
      "y": 8,
      "z": -12,
      "name": "Editor_Empty"
    },
    {
      "x": 7,
      "y": 9,
      "z": -12,
      "name": "Editor_Empty"
    },
    {
      "x": 7,
      "y": 10,
      "z": -12,
      "name": "Editor_Empty"
    },
    {
      "x": 7,
      "y": 11,
      "z": -12,
      "name": "Editor_Empty"
    },
    {
      "x": 7,
      "y": 12,
      "z": -12,
      "name": "Editor_Empty"
    },
    {
      "x": 7,
      "y": 1,
      "z": -11,
      "name": "Rock_Sandstone_Red_Cobble"
    },
    {
      "x": 7,
      "y": 2,
      "z": -11,
      "name": "Editor_Empty"
    },
    {
      "x": 7,
      "y": 3,
      "z": -11,
      "name": "Editor_Empty"
    },
    {
      "x": 7,
      "y": 4,
      "z": -11,
      "name": "Editor_Empty"
    },
    {
      "x": 7,
      "y": 5,
      "z": -11,
      "name": "Editor_Empty"
    },
    {
      "x": 7,
      "y": 6,
      "z": -11,
      "name": "Editor_Empty"
    },
    {
      "x": 7,
      "y": 7,
      "z": -11,
      "name": "Editor_Empty"
    },
    {
      "x": 7,
      "y": 8,
      "z": -11,
      "name": "Editor_Empty"
    },
    {
      "x": 7,
      "y": 9,
      "z": -11,
      "name": "Editor_Empty"
    },
    {
      "x": 7,
      "y": 10,
      "z": -11,
      "name": "Editor_Empty"
    },
    {
      "x": 7,
      "y": 11,
      "z": -11,
      "name": "Editor_Empty"
    },
    {
      "x": 7,
      "y": 12,
      "z": -11,
      "name": "Editor_Empty"
    },
    {
      "x": 7,
      "y": 1,
      "z": -10,
      "name": "Rock_Sandstone_Red_Cobble"
    },
    {
      "x": 7,
      "y": 2,
      "z": -10,
      "name": "Editor_Empty"
    },
    {
      "x": 7,
      "y": 3,
      "z": -10,
      "name": "Editor_Empty"
    },
    {
      "x": 7,
      "y": 4,
      "z": -10,
      "name": "Editor_Empty"
    },
    {
      "x": 7,
      "y": 5,
      "z": -10,
      "name": "Editor_Empty"
    },
    {
      "x": 7,
      "y": 6,
      "z": -10,
      "name": "Editor_Empty"
    },
    {
      "x": 7,
      "y": 7,
      "z": -10,
      "name": "Editor_Empty"
    },
    {
      "x": 7,
      "y": 8,
      "z": -10,
      "name": "Editor_Empty"
    },
    {
      "x": 7,
      "y": 9,
      "z": -10,
      "name": "Editor_Empty"
    },
    {
      "x": 7,
      "y": 10,
      "z": -10,
      "name": "Editor_Empty"
    },
    {
      "x": 7,
      "y": 11,
      "z": -10,
      "name": "Editor_Empty"
    },
    {
      "x": 7,
      "y": 12,
      "z": -10,
      "name": "Editor_Empty"
    },
    {
      "x": 7,
      "y": 1,
      "z": -9,
      "name": "Rock_Stone_Brick",
      "rotation": 2
    },
    {
      "x": 7,
      "y": 2,
      "z": -9,
      "name": "Editor_Empty"
    },
    {
      "x": 7,
      "y": 3,
      "z": -9,
      "name": "Editor_Empty"
    },
    {
      "x": 7,
      "y": 4,
      "z": -9,
      "name": "Editor_Empty"
    },
    {
      "x": 7,
      "y": 5,
      "z": -9,
      "name": "Editor_Empty"
    },
    {
      "x": 7,
      "y": 6,
      "z": -9,
      "name": "Editor_Empty"
    },
    {
      "x": 7,
      "y": 7,
      "z": -9,
      "name": "Editor_Empty"
    },
    {
      "x": 7,
      "y": 8,
      "z": -9,
      "name": "Editor_Empty"
    },
    {
      "x": 7,
      "y": 9,
      "z": -9,
      "name": "Editor_Empty"
    },
    {
      "x": 7,
      "y": 10,
      "z": -9,
      "name": "Editor_Empty"
    },
    {
      "x": 7,
      "y": 11,
      "z": -9,
      "name": "Editor_Empty"
    },
    {
      "x": 7,
      "y": 12,
      "z": -9,
      "name": "Editor_Empty"
    },
    {
      "x": 7,
      "y": 1,
      "z": -8,
      "name": "Rock_Stone_Brick",
      "rotation": 2
    },
    {
      "x": 7,
      "y": 2,
      "z": -8,
      "name": "Editor_Empty"
    },
    {
      "x": 7,
      "y": 3,
      "z": -8,
      "name": "Editor_Empty"
    },
    {
      "x": 7,
      "y": 4,
      "z": -8,
      "name": "Editor_Empty"
    },
    {
      "x": 7,
      "y": 5,
      "z": -8,
      "name": "Editor_Empty"
    },
    {
      "x": 7,
      "y": 6,
      "z": -8,
      "name": "Editor_Empty"
    },
    {
      "x": 7,
      "y": 7,
      "z": -8,
      "name": "Editor_Empty"
    },
    {
      "x": 7,
      "y": 8,
      "z": -8,
      "name": "Rock_Stone_Brick_Half",
      "rotation": 32
    },
    {
      "x": 7,
      "y": 9,
      "z": -8,
      "name": "Rock_Crystal_Purple_Block",
      "rotation": 6
    },
    {
      "x": 7,
      "y": 10,
      "z": -8,
      "name": "Rock_Volcanic_Brick_Smooth"
    },
    {
      "x": 7,
      "y": 11,
      "z": -8,
      "name": "Rock_Crystal_Purple_Block",
      "rotation": 6
    },
    {
      "x": 7,
      "y": 12,
      "z": -8,
      "name": "Rock_Stone_Brick_Half",
      "rotation": 2
    },
    {
      "x": 7,
      "y": 1,
      "z": -7,
      "name": "Rock_Stone_Brick"
    },
    {
      "x": 7,
      "y": 2,
      "z": -7,
      "name": "Aetherhaven_Tourist_Portal",
      "components": {
        "Components": {
          "AetherhavenTouristPortalBlock": {
            "PortalId": "ec4f46ba-9753-45ec-b951-4ba7fb39488f",
            "TownId": "",
            "PlotId": "",
            "Configured": true
          },
          "PlacedByInteraction": {
            "WhoPlacedUuid": {
              "$binary": "v7RyWIT/TYKnXA2XcxdQtw==",
              "$type": "04"
            }
          }
        }
      }
    },
    {
      "x": 7,
      "y": 3,
      "z": -7,
      "name": "Editor_Empty"
    },
    {
      "x": 7,
      "y": 4,
      "z": -7,
      "name": "Editor_Empty"
    },
    {
      "x": 7,
      "y": 5,
      "z": -7,
      "name": "Editor_Empty"
    },
    {
      "x": 7,
      "y": 6,
      "z": -7,
      "name": "Editor_Empty"
    },
    {
      "x": 7,
      "y": 7,
      "z": -7,
      "name": "Editor_Empty"
    },
    {
      "x": 7,
      "y": 8,
      "z": -7,
      "name": "Rock_Stone_Brick_Half",
      "rotation": 8
    },
    {
      "x": 7,
      "y": 9,
      "z": -7,
      "name": "Rock_Stone_Brick"
    },
    {
      "x": 7,
      "y": 10,
      "z": -7,
      "name": "Rock_Stone_Brick"
    },
    {
      "x": 7,
      "y": 11,
      "z": -7,
      "name": "Rock_Stone_Brick"
    },
    {
      "x": 7,
      "y": 12,
      "z": -7,
      "name": "Rock_Stone_Brick_Half"
    },
    {
      "x": 7,
      "y": 1,
      "z": -6,
      "name": "Rock_Stone_Brick"
    },
    {
      "x": 7,
      "y": 2,
      "z": -6,
      "name": "Editor_Empty"
    },
    {
      "x": 7,
      "y": 3,
      "z": -6,
      "name": "Editor_Empty"
    },
    {
      "x": 7,
      "y": 4,
      "z": -6,
      "name": "Editor_Empty"
    },
    {
      "x": 7,
      "y": 5,
      "z": -6,
      "name": "Editor_Empty"
    },
    {
      "x": 7,
      "y": 6,
      "z": -6,
      "name": "Editor_Empty"
    },
    {
      "x": 7,
      "y": 7,
      "z": -6,
      "name": "Editor_Empty"
    },
    {
      "x": 7,
      "y": 8,
      "z": -6,
      "name": "Rock_Stone_Brick_Half",
      "rotation": 8
    },
    {
      "x": 7,
      "y": 9,
      "z": -6,
      "name": "Rock_Crystal_Purple_Block",
      "rotation": 4
    },
    {
      "x": 7,
      "y": 10,
      "z": -6,
      "name": "Rock_Volcanic_Brick_Smooth"
    },
    {
      "x": 7,
      "y": 11,
      "z": -6,
      "name": "Rock_Crystal_Purple_Block",
      "rotation": 4
    },
    {
      "x": 7,
      "y": 12,
      "z": -6,
      "name": "Rock_Stone_Brick_Half"
    },
    {
      "x": 7,
      "y": 1,
      "z": -5,
      "name": "Rock_Stone_Brick"
    },
    {
      "x": 7,
      "y": 2,
      "z": -5,
      "name": "Editor_Empty"
    },
    {
      "x": 7,
      "y": 3,
      "z": -5,
      "name": "Editor_Empty"
    },
    {
      "x": 7,
      "y": 4,
      "z": -5,
      "name": "Editor_Empty"
    },
    {
      "x": 7,
      "y": 5,
      "z": -5,
      "name": "Editor_Empty"
    },
    {
      "x": 7,
      "y": 6,
      "z": -5,
      "name": "Editor_Empty"
    },
    {
      "x": 7,
      "y": 7,
      "z": -5,
      "name": "Editor_Empty"
    },
    {
      "x": 7,
      "y": 8,
      "z": -5,
      "name": "Editor_Empty"
    },
    {
      "x": 7,
      "y": 9,
      "z": -5,
      "name": "Editor_Empty"
    },
    {
      "x": 7,
      "y": 10,
      "z": -5,
      "name": "Editor_Empty"
    },
    {
      "x": 7,
      "y": 11,
      "z": -5,
      "name": "Editor_Empty"
    },
    {
      "x": 7,
      "y": 12,
      "z": -5,
      "name": "Editor_Empty"
    },
    {
      "x": 7,
      "y": 1,
      "z": -4,
      "name": "Rock_Sandstone_Red_Cobble"
    },
    {
      "x": 7,
      "y": 2,
      "z": -4,
      "name": "Editor_Empty"
    },
    {
      "x": 7,
      "y": 3,
      "z": -4,
      "name": "Editor_Empty"
    },
    {
      "x": 7,
      "y": 4,
      "z": -4,
      "name": "Editor_Empty"
    },
    {
      "x": 7,
      "y": 5,
      "z": -4,
      "name": "Editor_Empty"
    },
    {
      "x": 7,
      "y": 6,
      "z": -4,
      "name": "Editor_Empty"
    },
    {
      "x": 7,
      "y": 7,
      "z": -4,
      "name": "Editor_Empty"
    },
    {
      "x": 7,
      "y": 8,
      "z": -4,
      "name": "Editor_Empty"
    },
    {
      "x": 7,
      "y": 9,
      "z": -4,
      "name": "Editor_Empty"
    },
    {
      "x": 7,
      "y": 10,
      "z": -4,
      "name": "Editor_Empty"
    },
    {
      "x": 7,
      "y": 11,
      "z": -4,
      "name": "Editor_Empty"
    },
    {
      "x": 7,
      "y": 12,
      "z": -4,
      "name": "Editor_Empty"
    },
    {
      "x": 7,
      "y": 1,
      "z": -3,
      "name": "Rock_Sandstone_Red_Cobble"
    },
    {
      "x": 7,
      "y": 2,
      "z": -3,
      "name": "Editor_Empty"
    },
    {
      "x": 7,
      "y": 3,
      "z": -3,
      "name": "Editor_Empty"
    },
    {
      "x": 7,
      "y": 4,
      "z": -3,
      "name": "Editor_Empty"
    },
    {
      "x": 7,
      "y": 5,
      "z": -3,
      "name": "Editor_Empty"
    },
    {
      "x": 7,
      "y": 6,
      "z": -3,
      "name": "Editor_Empty"
    },
    {
      "x": 7,
      "y": 7,
      "z": -3,
      "name": "Editor_Empty"
    },
    {
      "x": 7,
      "y": 8,
      "z": -3,
      "name": "Editor_Empty"
    },
    {
      "x": 7,
      "y": 9,
      "z": -3,
      "name": "Editor_Empty"
    },
    {
      "x": 7,
      "y": 10,
      "z": -3,
      "name": "Editor_Empty"
    },
    {
      "x": 7,
      "y": 11,
      "z": -3,
      "name": "Editor_Empty"
    },
    {
      "x": 7,
      "y": 12,
      "z": -3,
      "name": "Editor_Empty"
    },
    {
      "x": 7,
      "y": 1,
      "z": -2,
      "name": "Rock_Sandstone_Red_Cobble"
    },
    {
      "x": 7,
      "y": 2,
      "z": -2,
      "name": "Editor_Empty"
    },
    {
      "x": 7,
      "y": 3,
      "z": -2,
      "name": "Editor_Empty"
    },
    {
      "x": 7,
      "y": 4,
      "z": -2,
      "name": "Editor_Empty"
    },
    {
      "x": 7,
      "y": 5,
      "z": -2,
      "name": "Editor_Empty"
    },
    {
      "x": 7,
      "y": 6,
      "z": -2,
      "name": "Editor_Empty"
    },
    {
      "x": 7,
      "y": 7,
      "z": -2,
      "name": "Editor_Empty"
    },
    {
      "x": 7,
      "y": 8,
      "z": -2,
      "name": "Editor_Empty"
    },
    {
      "x": 7,
      "y": 9,
      "z": -2,
      "name": "Editor_Empty"
    },
    {
      "x": 7,
      "y": 10,
      "z": -2,
      "name": "Editor_Empty"
    },
    {
      "x": 7,
      "y": 11,
      "z": -2,
      "name": "Editor_Empty"
    },
    {
      "x": 7,
      "y": 12,
      "z": -2,
      "name": "Editor_Empty"
    },
    {
      "x": 7,
      "y": 1,
      "z": -1,
      "name": "Rock_Stone_Brick_Smooth"
    },
    {
      "x": 7,
      "y": 2,
      "z": -1,
      "name": "Editor_Empty"
    },
    {
      "x": 7,
      "y": 3,
      "z": -1,
      "name": "Editor_Empty"
    },
    {
      "x": 7,
      "y": 4,
      "z": -1,
      "name": "Editor_Empty"
    },
    {
      "x": 7,
      "y": 5,
      "z": -1,
      "name": "Editor_Empty"
    },
    {
      "x": 7,
      "y": 6,
      "z": -1,
      "name": "Editor_Empty"
    },
    {
      "x": 7,
      "y": 7,
      "z": -1,
      "name": "Editor_Empty"
    },
    {
      "x": 7,
      "y": 8,
      "z": -1,
      "name": "Editor_Empty"
    },
    {
      "x": 7,
      "y": 9,
      "z": -1,
      "name": "Editor_Empty"
    },
    {
      "x": 7,
      "y": 10,
      "z": -1,
      "name": "Editor_Empty"
    },
    {
      "x": 7,
      "y": 11,
      "z": -1,
      "name": "Editor_Empty"
    },
    {
      "x": 7,
      "y": 12,
      "z": -1,
      "name": "Editor_Empty"
    },
    {
      "x": 8,
      "y": 1,
      "z": -12,
      "name": "Rock_Stone_Brick_Smooth"
    },
    {
      "x": 8,
      "y": 2,
      "z": -12,
      "name": "Editor_Empty"
    },
    {
      "x": 8,
      "y": 3,
      "z": -12,
      "name": "Editor_Empty"
    },
    {
      "x": 8,
      "y": 4,
      "z": -12,
      "name": "Editor_Empty"
    },
    {
      "x": 8,
      "y": 5,
      "z": -12,
      "name": "Editor_Empty"
    },
    {
      "x": 8,
      "y": 6,
      "z": -12,
      "name": "Editor_Empty"
    },
    {
      "x": 8,
      "y": 7,
      "z": -12,
      "name": "Editor_Empty"
    },
    {
      "x": 8,
      "y": 8,
      "z": -12,
      "name": "Editor_Empty"
    },
    {
      "x": 8,
      "y": 9,
      "z": -12,
      "name": "Editor_Empty"
    },
    {
      "x": 8,
      "y": 10,
      "z": -12,
      "name": "Editor_Empty"
    },
    {
      "x": 8,
      "y": 11,
      "z": -12,
      "name": "Editor_Empty"
    },
    {
      "x": 8,
      "y": 12,
      "z": -12,
      "name": "Editor_Empty"
    },
    {
      "x": 8,
      "y": 1,
      "z": -11,
      "name": "Rock_Sandstone_Red_Cobble"
    },
    {
      "x": 8,
      "y": 2,
      "z": -11,
      "name": "Editor_Empty"
    },
    {
      "x": 8,
      "y": 3,
      "z": -11,
      "name": "Editor_Empty"
    },
    {
      "x": 8,
      "y": 4,
      "z": -11,
      "name": "Editor_Empty"
    },
    {
      "x": 8,
      "y": 5,
      "z": -11,
      "name": "Editor_Empty"
    },
    {
      "x": 8,
      "y": 6,
      "z": -11,
      "name": "Editor_Empty"
    },
    {
      "x": 8,
      "y": 7,
      "z": -11,
      "name": "Editor_Empty"
    },
    {
      "x": 8,
      "y": 8,
      "z": -11,
      "name": "Editor_Empty"
    },
    {
      "x": 8,
      "y": 9,
      "z": -11,
      "name": "Editor_Empty"
    },
    {
      "x": 8,
      "y": 10,
      "z": -11,
      "name": "Editor_Empty"
    },
    {
      "x": 8,
      "y": 11,
      "z": -11,
      "name": "Editor_Empty"
    },
    {
      "x": 8,
      "y": 12,
      "z": -11,
      "name": "Editor_Empty"
    },
    {
      "x": 8,
      "y": 1,
      "z": -10,
      "name": "Rock_Sandstone_Red_Cobble"
    },
    {
      "x": 8,
      "y": 2,
      "z": -10,
      "name": "Editor_Empty"
    },
    {
      "x": 8,
      "y": 3,
      "z": -10,
      "name": "Editor_Empty"
    },
    {
      "x": 8,
      "y": 4,
      "z": -10,
      "name": "Editor_Empty"
    },
    {
      "x": 8,
      "y": 5,
      "z": -10,
      "name": "Editor_Empty"
    },
    {
      "x": 8,
      "y": 6,
      "z": -10,
      "name": "Editor_Empty"
    },
    {
      "x": 8,
      "y": 7,
      "z": -10,
      "name": "Editor_Empty"
    },
    {
      "x": 8,
      "y": 8,
      "z": -10,
      "name": "Editor_Empty"
    },
    {
      "x": 8,
      "y": 9,
      "z": -10,
      "name": "Editor_Empty"
    },
    {
      "x": 8,
      "y": 10,
      "z": -10,
      "name": "Editor_Empty"
    },
    {
      "x": 8,
      "y": 11,
      "z": -10,
      "name": "Editor_Empty"
    },
    {
      "x": 8,
      "y": 12,
      "z": -10,
      "name": "Editor_Empty"
    },
    {
      "x": 8,
      "y": 1,
      "z": -9,
      "name": "Rock_Stone_Brick",
      "rotation": 2
    },
    {
      "x": 8,
      "y": 2,
      "z": -9,
      "name": "Editor_Empty"
    },
    {
      "x": 8,
      "y": 3,
      "z": -9,
      "name": "Editor_Empty"
    },
    {
      "x": 8,
      "y": 4,
      "z": -9,
      "name": "Editor_Empty"
    },
    {
      "x": 8,
      "y": 5,
      "z": -9,
      "name": "Editor_Empty"
    },
    {
      "x": 8,
      "y": 6,
      "z": -9,
      "name": "Editor_Empty"
    },
    {
      "x": 8,
      "y": 7,
      "z": -9,
      "name": "Editor_Empty"
    },
    {
      "x": 8,
      "y": 8,
      "z": -9,
      "name": "Editor_Empty"
    },
    {
      "x": 8,
      "y": 9,
      "z": -9,
      "name": "Editor_Empty"
    },
    {
      "x": 8,
      "y": 10,
      "z": -9,
      "name": "Editor_Empty"
    },
    {
      "x": 8,
      "y": 11,
      "z": -9,
      "name": "Editor_Empty"
    },
    {
      "x": 8,
      "y": 12,
      "z": -9,
      "name": "Editor_Empty"
    },
    {
      "x": 8,
      "y": 1,
      "z": -8,
      "name": "Rock_Stone_Brick",
      "rotation": 2
    },
    {
      "x": 8,
      "y": 3,
      "z": -8,
      "name": "Editor_Empty"
    },
    {
      "x": 8,
      "y": 4,
      "z": -8,
      "name": "Editor_Empty"
    },
    {
      "x": 8,
      "y": 5,
      "z": -8,
      "name": "Editor_Empty"
    },
    {
      "x": 8,
      "y": 6,
      "z": -8,
      "name": "Editor_Empty"
    },
    {
      "x": 8,
      "y": 7,
      "z": -8,
      "name": "Editor_Empty"
    },
    {
      "x": 8,
      "y": 8,
      "z": -8,
      "name": "Rock_Stone_Brick_Half",
      "rotation": 32
    },
    {
      "x": 8,
      "y": 9,
      "z": -8,
      "name": "Rock_Crystal_Purple_Block",
      "rotation": 6
    },
    {
      "x": 8,
      "y": 10,
      "z": -8,
      "name": "Rock_Volcanic_Brick_Smooth"
    },
    {
      "x": 8,
      "y": 11,
      "z": -8,
      "name": "Rock_Crystal_Purple_Block",
      "rotation": 6
    },
    {
      "x": 8,
      "y": 12,
      "z": -8,
      "name": "Rock_Stone_Brick_Half",
      "rotation": 2
    },
    {
      "x": 8,
      "y": 1,
      "z": -7,
      "name": "Rock_Stone_Brick"
    },
    {
      "x": 8,
      "y": 2,
      "z": -7,
      "name": "Aetherhaven_Tourist_Portal",
      "filler": 1
    },
    {
      "x": 8,
      "y": 3,
      "z": -7,
      "name": "Editor_Empty"
    },
    {
      "x": 8,
      "y": 4,
      "z": -7,
      "name": "Editor_Empty"
    },
    {
      "x": 8,
      "y": 5,
      "z": -7,
      "name": "Editor_Empty"
    },
    {
      "x": 8,
      "y": 6,
      "z": -7,
      "name": "Editor_Empty"
    },
    {
      "x": 8,
      "y": 7,
      "z": -7,
      "name": "Editor_Empty"
    },
    {
      "x": 8,
      "y": 8,
      "z": -7,
      "name": "Rock_Stone_Brick_Half",
      "rotation": 8
    },
    {
      "x": 8,
      "y": 9,
      "z": -7,
      "name": "Rock_Stone_Brick"
    },
    {
      "x": 8,
      "y": 10,
      "z": -7,
      "name": "Rock_Stone_Brick"
    },
    {
      "x": 8,
      "y": 11,
      "z": -7,
      "name": "Rock_Stone_Brick"
    },
    {
      "x": 8,
      "y": 12,
      "z": -7,
      "name": "Rock_Stone_Brick_Half"
    },
    {
      "x": 8,
      "y": 1,
      "z": -6,
      "name": "Rock_Stone_Brick"
    },
    {
      "x": 8,
      "y": 2,
      "z": -6,
      "name": "Editor_Empty"
    },
    {
      "x": 8,
      "y": 3,
      "z": -6,
      "name": "Editor_Empty"
    },
    {
      "x": 8,
      "y": 4,
      "z": -6,
      "name": "Editor_Empty"
    },
    {
      "x": 8,
      "y": 5,
      "z": -6,
      "name": "Editor_Empty"
    },
    {
      "x": 8,
      "y": 6,
      "z": -6,
      "name": "Editor_Empty"
    },
    {
      "x": 8,
      "y": 7,
      "z": -6,
      "name": "Editor_Empty"
    },
    {
      "x": 8,
      "y": 8,
      "z": -6,
      "name": "Rock_Stone_Brick_Half",
      "rotation": 8
    },
    {
      "x": 8,
      "y": 9,
      "z": -6,
      "name": "Rock_Crystal_Purple_Block",
      "rotation": 4
    },
    {
      "x": 8,
      "y": 10,
      "z": -6,
      "name": "Rock_Volcanic_Brick_Smooth"
    },
    {
      "x": 8,
      "y": 11,
      "z": -6,
      "name": "Rock_Crystal_Purple_Block",
      "rotation": 4
    },
    {
      "x": 8,
      "y": 12,
      "z": -6,
      "name": "Rock_Stone_Brick_Half"
    },
    {
      "x": 8,
      "y": 1,
      "z": -5,
      "name": "Rock_Stone_Brick"
    },
    {
      "x": 8,
      "y": 2,
      "z": -5,
      "name": "Editor_Empty"
    },
    {
      "x": 8,
      "y": 3,
      "z": -5,
      "name": "Editor_Empty"
    },
    {
      "x": 8,
      "y": 4,
      "z": -5,
      "name": "Editor_Empty"
    },
    {
      "x": 8,
      "y": 5,
      "z": -5,
      "name": "Editor_Empty"
    },
    {
      "x": 8,
      "y": 6,
      "z": -5,
      "name": "Editor_Empty"
    },
    {
      "x": 8,
      "y": 7,
      "z": -5,
      "name": "Editor_Empty"
    },
    {
      "x": 8,
      "y": 8,
      "z": -5,
      "name": "Editor_Empty"
    },
    {
      "x": 8,
      "y": 9,
      "z": -5,
      "name": "Editor_Empty"
    },
    {
      "x": 8,
      "y": 10,
      "z": -5,
      "name": "Editor_Empty"
    },
    {
      "x": 8,
      "y": 11,
      "z": -5,
      "name": "Editor_Empty"
    },
    {
      "x": 8,
      "y": 12,
      "z": -5,
      "name": "Editor_Empty"
    },
    {
      "x": 8,
      "y": 1,
      "z": -4,
      "name": "Rock_Sandstone_Red_Cobble"
    },
    {
      "x": 8,
      "y": 2,
      "z": -4,
      "name": "Editor_Empty"
    },
    {
      "x": 8,
      "y": 3,
      "z": -4,
      "name": "Editor_Empty"
    },
    {
      "x": 8,
      "y": 4,
      "z": -4,
      "name": "Editor_Empty"
    },
    {
      "x": 8,
      "y": 5,
      "z": -4,
      "name": "Editor_Empty"
    },
    {
      "x": 8,
      "y": 6,
      "z": -4,
      "name": "Editor_Empty"
    },
    {
      "x": 8,
      "y": 7,
      "z": -4,
      "name": "Editor_Empty"
    },
    {
      "x": 8,
      "y": 8,
      "z": -4,
      "name": "Editor_Empty"
    },
    {
      "x": 8,
      "y": 9,
      "z": -4,
      "name": "Editor_Empty"
    },
    {
      "x": 8,
      "y": 10,
      "z": -4,
      "name": "Editor_Empty"
    },
    {
      "x": 8,
      "y": 11,
      "z": -4,
      "name": "Editor_Empty"
    },
    {
      "x": 8,
      "y": 12,
      "z": -4,
      "name": "Editor_Empty"
    },
    {
      "x": 8,
      "y": 1,
      "z": -3,
      "name": "Rock_Sandstone_Red_Cobble"
    },
    {
      "x": 8,
