{
  "version": 8,
  "blockIdVersion": 11,
  "anchorX": 0,
  "anchorY": 0,
  "anchorZ": 0,
  "blocks": [
    {
      "x": -1,
      "y": 0,
      "z": -4,
      "name": "*Wood_Tropicalwood_Roof_State_Definitions_Corner_Left",
      "rotation": 2
    },
    {
      "x": -1,
      "y": 0,
      "z": -3,
      "name": "Wood_Tropicalwood_Roof",
      "rotation": 3
    },
    {
      "x": -1,
      "y": 3,
      "z": -3,
      "name": "Plant_Vine",
      "support": 15,
      "rotation": 3
    },
    {
      "x": -1,
      "y": 0,
      "z": -2,
      "name": "*Wood_Tropicalwood_Roof_State_Definitions_Corner_Right"
    },
    {
      "x": -1,
      "y": 4,
      "z": -2,
      "name": "Plant_Vine_Wall",
      "support": 15,
      "rotation": 3
    },
    {
      "x": -1,
      "y": 5,
      "z": 1,
      "name": "Plant_Vine",
      "support": 15,
      "rotation": 3
    },
    {
      "x": -1,
      "y": 5,
      "z": 2,
      "name": "Plant_Vine_Wall",
      "support": 15,
      "rotation": 3
    },
    {
      "x": -1,
      "y": 0,
      "z": 3,
      "name": "*Wood_Tropicalwood_Roof_State_Definitions_Corner_Left",
      "rotation": 2
    },
    {
      "x": -1,
      "y": 0,
      "z": 4,
      "name": "Wood_Tropicalwood_Roof",
      "rotation": 3
    },
    {
      "x": -1,
      "y": 2,
      "z": 4,
      "name": "Plant_Vine_Wall",
      "support": 15,
      "rotation": 3
    },
    {
      "x": -1,
      "y": 3,
      "z": 4,
      "name": "Plant_Vine_Wall",
      "support": 15,
      "rotation": 3
    },
    {
      "x": -1,
      "y": 0,
      "z": 5,
      "name": "*Wood_Tropicalwood_Roof_State_Definitions_Corner_Right"
    },
    {
      "x": 0,
      "y": 0,
      "z": -4,
      "name": "Wood_Tropicalwood_Roof",
      "rotation": 2
    },
    {
      "x": 0,
      "y": 1,
      "z": -4,
      "name": "Plant_Vine_Wall",
      "support": 15,
      "rotation": 2
    },
    {
      "x": 0,
      "y": 2,
      "z": -4,
      "name": "Plant_Vine_Wall",
      "support": 15,
      "rotation": 2
    },
    {
      "x": 0,
      "y": 3,
      "z": -4,
      "name": "Plant_Vine_Wall",
      "support": 15,
      "rotation": 2
    },
    {
      "x": 0,
      "y": 0,
      "z": -3,
      "name": "Plant_Moss_Block_Green",
      "support": 15
    },
    {
      "x": 0,
      "y": 1,
      "z": -3,
      "name": "Soil_Clay_Smooth_GreenDark"
    },
    {
      "x": 0,
      "y": 2,
      "z": -3,
      "name": "Plant_Moss_Block_Green",
      "support": 15
    },
    {
      "x": 0,
      "y": 3,
      "z": -3,
      "name": "Plant_Moss_Block_Green_Dark",
      "support": 15
    },
    {
      "x": 0,
      "y": 4,
      "z": -3,
      "name": "Plant_Moss_Rug_Green",
      "support": 15
    },
    {
      "x": 0,
      "y": 0,
      "z": -2,
      "name": "Wood_Tropicalwood_Roof"
    },
    {
      "x": 0,
      "y": 2,
      "z": -2,
      "name": "Plant_Vine_Wall",
      "support": 15
    },
    {
      "x": 0,
      "y": 3,
      "z": -2,
      "name": "Soil_Clay_Smooth_GreenDark_Stairs",
      "rotation": 10
    },
    {
      "x": 0,
      "y": 4,
      "z": -2,
      "name": "Soil_Grass_Sunny_Full"
    },
    {
      "x": 0,
      "y": 5,
      "z": -2,
      "name": "Plant_Flower_Tall_Purple"
    },
    {
      "x": 0,
      "y": 4,
      "z": -1,
      "name": "Soil_Clay_Smooth_Lime_Stairs",
      "rotation": 10
    },
    {
      "x": 0,
      "y": 5,
      "z": -1,
      "name": "Soil_Grass_Full"
    },
    {
      "x": 0,
      "y": 6,
      "z": -1,
      "name": "Plant_Cactus_Flower"
    },
    {
      "x": 0,
      "y": 4,
      "z": 0,
      "name": "Plant_Moss_Cave_Green",
      "support": 15,
      "rotation": 8
    },
    {
      "x": 0,
      "y": 5,
      "z": 0,
      "name": "Plant_Moss_Block_Green_Dark",
      "support": 15
    },
    {
      "x": 0,
      "y": 6,
      "z": 0,
      "name": "Plant_Moss_Rug_Green",
      "support": 15
    },
    {
      "x": 0,
      "y": 5,
      "z": 1,
      "name": "Plant_Moss_Block_Green",
      "support": 15
    },
    {
      "x": 0,
      "y": 6,
      "z": 1,
      "name": "Plant_Moss_Rug_Green",
      "support": 15
    },
    {
      "x": 0,
      "y": 4,
      "z": 2,
      "name": "Soil_Clay_Smooth_GreenDark_Stairs",
      "rotation": 8
    },
    {
      "x": 0,
      "y": 5,
      "z": 2,
      "name": "Plant_Moss_Block_Green_Dark",
      "support": 15
    },
    {
      "x": 0,
      "y": 6,
      "z": 2,
      "name": "Plant_Moss_Rug_Green",
      "support": 15
    },
    {
      "x": 0,
      "y": 0,
      "z": 3,
      "name": "Wood_Tropicalwood_Roof",
      "rotation": 2
    },
    {
      "x": 0,
      "y": 2,
      "z": 3,
      "name": "Plant_Vine_Wall",
      "support": 15,
      "rotation": 2
    },
    {
      "x": 0,
      "y": 3,
      "z": 3,
      "name": "Soil_Clay_Smooth_GreenDark_Stairs",
      "rotation": 8
    },
    {
      "x": 0,
      "y": 4,
      "z": 3,
      "name": "Plant_Moss_Block_Green_Dark",
      "support": 15
    },
    {
      "x": 0,
      "y": 5,
      "z": 3,
      "name": "Plant_Moss_Rug_Green",
      "support": 15
    },
    {
      "x": 0,
      "y": 0,
      "z": 4,
      "name": "Plant_Moss_Block_Green",
      "support": 15
    },
    {
      "x": 0,
      "y": 1,
      "z": 4,
      "name": "Soil_Clay_Smooth_GreenDark"
    },
    {
      "x": 0,
      "y": 2,
      "z": 4,
      "name": "Plant_Moss_Block_Green_Dark",
      "support": 15
    },
    {
      "x": 0,
      "y": 3,
      "z": 4,
      "name": "Soil_Grass_Sunny_Full"
    },
    {
      "x": 0,
      "y": 4,
      "z": 4,
      "name": "Plant_Flower_Common_Poisoned2"
    },
    {
      "x": 0,
      "y": 0,
      "z": 5,
      "name": "Wood_Tropicalwood_Roof"
    },
    {
      "x": 0,
      "y": 2,
      "z": 5,
      "name": "Plant_Vine_Wall",
      "support": 15
    },
    {
      "x": 1,
      "y": 0,
      "z": -4,
      "name": "*Wood_Tropicalwood_Roof_State_Definitions_Corner_Left",
      "rotation": 1
    },
    {
      "x": 1,
      "y": 0,
      "z": -3,
      "name": "Wood_Tropicalwood_Roof",
      "rotation": 1
    },
    {
      "x": 1,
      "y": 2,
      "z": -3,
      "name": "Plant_Vine",
      "support": 15,
      "rotation": 1
    },
    {
      "x": 1,
      "y": 3,
      "z": -3,
      "name": "Plant_Vine",
      "support": 15,
      "rotation": 1
    },
    {
      "x": 1,
      "y": 0,
      "z": -2,
      "name": "*Wood_Tropicalwood_Roof_State_Definitions_Corner_Left"
    },
    {
      "x": 1,
      "y": 5,
      "z": 1,
      "name": "Plant_Vine",
      "support": 15,
      "rotation": 1
    },
    {
      "x": 1,
      "y": 5,
      "z": 2,
      "name": "Plant_Vine_Wall",
      "support": 15,
      "rotation": 1
    },
    {
      "x": 1,
      "y": 0,
      "z": 3,
      "name": "*Wood_Tropicalwood_Roof_State_Definitions_Corner_Left",
      "rotation": 1
    },
    {
      "x": 1,
      "y": 4,
      "z": 3,
      "name": "Plant_Vine",
      "support": 15,
      "rotation": 1
    },
    {
      "x": 1,
      "y": 0,
      "z": 4,
      "name": "Wood_Tropicalwood_Roof",
      "rotation": 1
    },
    {
      "x": 1,
      "y": 0,
      "z": 5,
      "name": "*Wood_Tropicalwood_Roof_State_Definitions_Corner_Left"
    }
  ],
  "fluids": [
    {
      "x": -1,
      "y": 0,
      "z": -4,
      "name": "Empty",
      "level": 0
    },
    {
      "x": -1,
      "y": 0,
      "z": -3,
      "name": "Empty",
      "level": 0
    },
    {
      "x": -1,
      "y": 3,
      "z": -3,
      "name": "Empty",
      "level": 0
    },
    {
      "x": -1,
      "y": 0,
      "z": -2,
      "name": "Empty",
      "level": 0
    },
    {
      "x": -1,
      "y": 4,
      "z": -2,
      "name": "Empty",
      "level": 0
    },
    {
      "x": -1,
      "y": 5,
      "z": 1,
      "name": "Empty",
      "level": 0
    },
    {
      "x": -1,
      "y": 5,
      "z": 2,
      "name": "Empty",
      "level": 0
    },
    {
      "x": -1,
      "y": 0,
      "z": 3,
      "name": "Empty",
      "level": 0
    },
    {
      "x": -1,
      "y": 0,
      "z": 4,
      "name": "Empty",
      "level": 0
    },
    {
      "x": -1,
      "y": 2,
      "z": 4,
      "name": "Empty",
      "level": 0
    },
    {
      "x": -1,
      "y": 3,
      "z": 4,
      "name": "Empty",
      "level": 0
    },
    {
      "x": -1,
      "y": 0,
      "z": 5,
      "name": "Empty",
      "level": 0
    },
    {
      "x": 0,
      "y": 0,
      "z": -4,
      "name": "Empty",
      "level": 0
    },
    {
      "x": 0,
      "y": 1,
      "z": -4,
      "name": "Empty",
      "level": 0
    },
    {
      "x": 0,
      "y": 2,
      "z": -4,
      "name": "Empty",
      "level": 0
    },
    {
      "x": 0,
      "y": 3,
      "z": -4,
      "name": "Empty",
      "level": 0
    },
    {
      "x": 0,
      "y": 0,
      "z": -3,
      "name": "Empty",
      "level": 0
    },
    {
      "x": 0,
      "y": 1,
      "z": -3,
      "name": "Empty",
      "level": 0
    },
    {
      "x": 0,
      "y": 2,
      "z": -3,
      "name": "Empty",
      "level": 0
    },
    {
      "x": 0,
      "y": 3,
      "z": -3,
      "name": "Empty",
      "level": 0
    },
    {
      "x": 0,
      "y": 4,
      "z": -3,
      "name": "Empty",
      "level": 0
    },
    {
      "x": 0,
      "y": 0,
      "z": -2,
      "name": "Empty",
      "level": 0
    },
    {
      "x": 0,
      "y": 2,
      "z": -2,
      "name": "Empty",
      "level": 0
    },
    {
      "x": 0,
      "y": 3,
      "z": -2,
      "name": "Empty",
      "level": 0
    },
    {
      "x": 0,
      "y": 4,
      "z": -2,
      "name": "Empty",
      "level": 0
    },
    {
      "x": 0,
      "y": 5,
      "z": -2,
      "name": "Empty",
      "level": 0
    },
    {
      "x": 0,
      "y": 4,
      "z": -1,
      "name": "Empty",
      "level": 0
    },
    {
      "x": 0,
      "y": 5,
      "z": -1,
      "name": "Empty",
      "level": 0
    },
    {
      "x": 0,
      "y": 6,
      "z": -1,
      "name": "Empty",
      "level": 0
    },
    {
      "x": 0,
      "y": 4,
      "z": 0,
      "name": "Empty",
      "level": 0
    },
    {
      "x": 0,
      "y": 5,
      "z": 0,
      "name": "Empty",
      "level": 0
    },
    {
      "x": 0,
      "y": 6,
      "z": 0,
      "name": "Empty",
      "level": 0
    },
    {
      "x": 0,
      "y": 5,
      "z": 1,
      "name": "Empty",
      "level": 0
    },
    {
      "x": 0,
      "y": 6,
      "z": 1,
      "name": "Empty",
      "level": 0
    },
    {
      "x": 0,
      "y": 4,
      "z": 2,
      "name": "Empty",
      "level": 0
    },
    {
      "x": 0,
      "y": 5,
      "z": 2,
      "name": "Empty",
      "level": 0
    },
    {
      "x": 0,
      "y": 6,
      "z": 2,
      "name": "Empty",
      "level": 0
    },
    {
      "x": 0,
      "y": 0,
      "z": 3,
      "name": "Empty",
      "level": 0
    },
    {
      "x": 0,
      "y": 2,
      "z": 3,
      "name": "Empty",
      "level": 0
    },
    {
      "x": 0,
      "y": 3,
      "z": 3,
      "name": "Empty",
      "level": 0
    },
    {
      "x": 0,
      "y": 4,
      "z": 3,
      "name": "Empty",
      "level": 0
    },
    {
      "x": 0,
      "y": 5,
      "z": 3,
      "name": "Empty",
      "level": 0
    },
    {
      "x": 0,
      "y": 0,
      "z": 4,
      "name": "Empty",
      "level": 0
    },
    {
      "x": 0,
      "y": 1,
      "z": 4,
      "name": "Empty",
      "level": 0
    },
    {
      "x": 0,
      "y": 2,
      "z": 4,
      "name": "Empty",
      "level": 0
    },
    {
      "x": 0,
      "y": 3,
      "z": 4,
      "name": "Empty",
      "level": 0
    },
    {
      "x": 0,
      "y": 4,
      "z": 4,
      "name": "Empty",
      "level": 0
    },
    {
      "x": 0,
      "y": 0,
      "z": 5,
      "name": "Empty",
      "level": 0
    },
    {
      "x": 0,
      "y": 2,
      "z": 5,
      "name": "Empty",
      "level": 0
    },
    {
      "x": 1,
      "y": 0,
      "z": -4,
      "name": "Empty",
      "level": 0
    },
    {
      "x": 1,
      "y": 0,
      "z": -3,
      "name": "Empty",
      "level": 0
    },
    {
      "x": 1,
      "y": 2,
      "z": -3,
      "name": "Empty",
      "level": 0
    },
    {
      "x": 1,
      "y": 3,
      "z": -3,
      "name": "Empty",
      "level": 0
    },
    {
      "x": 1,
      "y": 0,
      "z": -2,
      "name": "Empty",
      "level": 0
    },
    {
      "x": 1,
      "y": 5,
      "z": 1,
      "name": "Empty",
      "level": 0
    },
    {
      "x": 1,
      "y": 5,
      "z": 2,
      "name": "Empty",
      "level": 0
    },
    {
      "x": 1,
      "y": 0,
      "z": 3,
      "name": "Empty",
      "level": 0
    },
    {
      "x": 1,
      "y": 4,
      "z": 3,
      "name": "Empty",
      "level": 0
    },
    {
      "x": 1,
      "y": 0,
      "z": 4,
      "name": "Empty",
      "level": 0
    },
    {
      "x": 1,
      "y": 0,
      "z": 5,
      "name": "Empty",
      "level": 0
    }
  ],
  "entities": [
    {
      "Components": {
        "PreventItemMerging": {},
        "Prop": {},
        "Transform": {
          "Position": {
            "X": 0.525665283203125,
            "Y": 2.1511383056640625,
            "Z": 3.2139663696289062
          },
          "Rotation": {
            "Pitch": 0.0,
            "Yaw": 2.931155204772949,
            "Roll": 0.0
          }
        },
        "PreventPickup": {},
        "EntityScale": {
          "Scale": 2.5999999046325684
        },
        "Item": {
          "Item": {
            "Id": "Ingredient_Life_Essence",
            "Quantity": 1,
            "Durability": 0.0,
            "MaxDurability": 0.0,
            "OverrideDroppedItemAnimation": true
          },
          "StackDelay": 1.5,
          "PickupDelay": 0.5,
          "PickupThrottle": 0.0,
          "RemovedByPlayerPickup": false
        },
        "PrefabCopyable": {},
        "HeadRotation": {
          "Rotation": {
            "Pitch": 0.0,
            "Yaw": 2.931155204772949,
            "Roll": 0.0
          }
        }
      }
    },
    {
      "Components": {
        "PreventItemMerging": {},
        "Prop": {},
        "Transform": {
          "Position": {
            "X": 0.525665283203125,
            "Y": 2.1511383056640625,
            "Z": -1.3446369171142578
          },
          "Rotation": {
            "Pitch": 0.0,
            "Yaw": 2.931155204772949,
            "Roll": 0.0
          }
        },
        "PreventPickup": {},
        "EntityScale": {
          "Scale": 2.5999999046325684
        },
        "Item": {
          "Item": {
            "Id": "Ingredient_Life_Essence",
            "Quantity": 1,
            "Durability": 0.0,
            "MaxDurability": 0.0,
            "OverrideDroppedItemAnimation": true
          },
          "StackDelay": 1.5,
          "PickupDelay": 0.5,
          "PickupThrottle": 0.0,
          "RemovedByPlayerPickup": false
        },
        "PrefabCopyable": {},
        "HeadRotation": {
          "Rotation": {
            "Pitch": 0.0,
            "Yaw": 2.931155204772949,
            "Roll": 0.0
          }
        }
      }
    },
    {
      "Components": {
        "Transform": {
          "Position": {
            "X": -9.0,
            "Y": 6.5,
            "Z": 2.0
          },
          "Rotation": {
            "Pitch": 0.0,
            "Yaw": 0.0,
            "Roll": 0.0
          }
        },
        "TriggerVolume": {
          "Shape": {
            "Type": "Box",
            "Min": {
              "X": -14.0,
              "Y": -6.5,
              "Z": -14.0
            },
            "Max": {
              "X": 14.0,
              "Y": 6.5,
              "Z": 14.0
            }
          },
          "Effects": [
            {
              "Type": "SetMusic",
              "Event": "ENTER",
              "Interval": 0.0,
              "Delay": 0.0,
              "MusicContainer": "Track_Aetherhaven_FunkyLittleDudes",
              "ClearMusic": false
            },
            {
              "Type": "SetMusic",
              "Event": "EXIT",
              "Interval": 0.0,
              "Delay": 0.0,
              "MusicContainer": "",
              "ClearMusic": true
            },
            {
              "Type": "SetWeather",
              "Event": "ENTER",
              "Interval": 0.0,
              "Delay": 0.0,
              "Weather": "Zone1_Sunny_Fireflies",
              "PlayerOnly": true,
              "ResetWeather": false
            },
            {
              "Type": "SetWeather",
              "Event": "EXIT",
              "Interval": 0.0,
              "Delay": 0.0,
              "Weather": "",
              "PlayerOnly": true,
              "ResetWeather": true
            }
          ],
          "Enabled": true,
          "TargetTypes": [
            "Player"
          ],
          "KeepLoaded": false,
          "Color": {
            "X": 0.003921568859368563,
            "Y": 0.800000011920929,
            "Z": 0.0
          },
          "PrefabIndex": 0
        }
      }
    }
  ]
}