{
  "version": 8,
  "blockIdVersion": 11,
  "anchorX": 0,
  "anchorY": 0,
  "anchorZ": 0,
  "blocks": [
    {
      "x": 1,
      "y": -6,
      "z": 1,
      "name": "Soil_Dirt"
    },
    {
      "x": 1,
      "y": -5,
      "z": 1,
      "name": "Soil_Dirt"
    },
    {
      "x": 1,
      "y": -4,
      "z": 1,
      "name": "Soil_Dirt"
    },
    {
      "x": 1,
      "y": -3,
      "z": 1,
      "name": "Soil_Dirt"
    },
    {
      "x": 1,
      "y": -2,
      "z": 1,
      "name": "Soil_Dirt"
    },
    {
      "x": 1,
      "y": -1,
      "z": 1,
      "name": "Rock_Stone_Brick_Smooth"
    },
    {
      "x": 1,
      "y": -6,
      "z": 2,
      "name": "Soil_Dirt"
    },
    {
      "x": 1,
      "y": -5,
      "z": 2,
      "name": "Soil_Dirt"
    },
    {
      "x": 1,
      "y": -4,
      "z": 2,
      "name": "Soil_Dirt"
    },
    {
      "x": 1,
      "y": -3,
      "z": 2,
      "name": "Soil_Dirt"
    },
    {
      "x": 1,
      "y": -2,
      "z": 2,
      "name": "Soil_Dirt"
    },
    {
      "x": 1,
      "y": -1,
      "z": 2,
      "name": "Rock_Stone_Brick_Smooth"
    },
    {
      "x": 1,
      "y": -6,
      "z": 3,
      "name": "Soil_Dirt"
    },
    {
      "x": 1,
      "y": -5,
      "z": 3,
      "name": "Soil_Dirt"
    },
    {
      "x": 1,
      "y": -4,
      "z": 3,
      "name": "Soil_Dirt"
    },
    {
      "x": 1,
      "y": -3,
      "z": 3,
      "name": "Soil_Dirt"
    },
    {
      "x": 1,
      "y": -2,
      "z": 3,
      "name": "Soil_Dirt"
    },
    {
      "x": 1,
      "y": -1,
      "z": 3,
      "name": "Rock_Stone_Brick_Smooth"
    },
    {
      "x": 1,
      "y": -6,
      "z": 4,
      "name": "Soil_Dirt"
    },
    {
      "x": 1,
      "y": -5,
      "z": 4,
      "name": "Soil_Dirt"
    },
    {
      "x": 1,
      "y": -4,
      "z": 4,
      "name": "Soil_Dirt"
    },
    {
      "x": 1,
      "y": -3,
      "z": 4,
      "name": "Soil_Dirt"
    },
    {
      "x": 1,
      "y": -2,
      "z": 4,
      "name": "Soil_Dirt"
    },
    {
      "x": 1,
      "y": -1,
      "z": 4,
      "name": "Rock_Stone_Brick_Smooth"
    },
    {
      "x": 1,
      "y": -6,
      "z": 5,
      "name": "Soil_Dirt"
    },
    {
      "x": 1,
      "y": -5,
      "z": 5,
      "name": "Soil_Dirt"
    },
    {
      "x": 1,
      "y": -4,
      "z": 5,
      "name": "Soil_Dirt"
    },
    {
      "x": 1,
      "y": -3,
      "z": 5,
      "name": "Soil_Dirt"
    },
    {
      "x": 1,
      "y": -2,
      "z": 5,
      "name": "Soil_Dirt"
    },
    {
      "x": 1,
      "y": -1,
      "z": 5,
      "name": "Rock_Stone_Brick_Smooth"
    },
    {
      "x": 1,
      "y": -6,
      "z": 6,
      "name": "Soil_Dirt"
    },
    {
      "x": 1,
      "y": -5,
      "z": 6,
      "name": "Soil_Dirt"
    },
    {
      "x": 1,
      "y": -4,
      "z": 6,
      "name": "Soil_Dirt"
    },
    {
      "x": 1,
      "y": -3,
      "z": 6,
      "name": "Soil_Dirt"
    },
    {
      "x": 1,
      "y": -2,
      "z": 6,
      "name": "Soil_Dirt"
    },
    {
      "x": 1,
      "y": -1,
      "z": 6,
      "name": "Rock_Stone_Brick_Smooth"
    },
    {
      "x": 1,
      "y": -6,
      "z": 7,
      "name": "Soil_Dirt"
    },
    {
      "x": 1,
      "y": -5,
      "z": 7,
      "name": "Soil_Dirt"
    },
    {
      "x": 1,
      "y": -4,
      "z": 7,
      "name": "Soil_Dirt"
    },
    {
      "x": 1,
      "y": -3,
      "z": 7,
      "name": "Soil_Dirt"
    },
    {
      "x": 1,
      "y": -2,
      "z": 7,
      "name": "Soil_Dirt"
    },
    {
      "x": 1,
      "y": -1,
      "z": 7,
      "name": "Rock_Stone_Brick_Smooth"
    },
    {
      "x": 1,
      "y": -6,
      "z": 8,
      "name": "Soil_Dirt"
    },
    {
      "x": 1,
      "y": -5,
      "z": 8,
      "name": "Soil_Dirt"
    },
    {
      "x": 1,
      "y": -4,
      "z": 8,
      "name": "Soil_Dirt"
    },
    {
      "x": 1,
      "y": -3,
      "z": 8,
      "name": "Soil_Dirt"
    },
    {
      "x": 1,
      "y": -2,
      "z": 8,
      "name": "Soil_Dirt"
    },
    {
      "x": 1,
      "y": -1,
      "z": 8,
      "name": "Rock_Stone_Brick_Smooth"
    },
    {
      "x": 1,
      "y": -6,
      "z": 9,
      "name": "Soil_Dirt"
    },
    {
      "x": 1,
      "y": -5,
      "z": 9,
      "name": "Soil_Dirt"
    },
    {
      "x": 1,
      "y": -4,
      "z": 9,
      "name": "Soil_Dirt"
    },
    {
      "x": 1,
      "y": -3,
      "z": 9,
      "name": "Soil_Dirt"
    },
    {
      "x": 1,
      "y": -2,
      "z": 9,
      "name": "Soil_Dirt"
    },
    {
      "x": 1,
      "y": -1,
      "z": 9,
      "name": "Rock_Stone_Brick_Smooth"
    },
    {
      "x": 1,
      "y": -6,
      "z": 10,
      "name": "Soil_Dirt"
    },
    {
      "x": 1,
      "y": -5,
      "z": 10,
      "name": "Soil_Dirt"
    },
    {
      "x": 1,
      "y": -4,
      "z": 10,
      "name": "Soil_Dirt"
    },
    {
      "x": 1,
      "y": -3,
      "z": 10,
      "name": "Soil_Dirt"
    },
    {
      "x": 1,
      "y": -2,
      "z": 10,
      "name": "Soil_Dirt"
    },
    {
      "x": 1,
      "y": -1,
      "z": 10,
      "name": "Rock_Stone_Brick_Smooth"
    },
    {
      "x": 1,
      "y": -6,
      "z": 11,
      "name": "Soil_Dirt"
    },
    {
      "x": 1,
      "y": -5,
      "z": 11,
      "name": "Soil_Dirt"
    },
    {
      "x": 1,
      "y": -4,
      "z": 11,
      "name": "Soil_Dirt"
    },
    {
      "x": 1,
      "y": -3,
      "z": 11,
      "name": "Soil_Dirt"
    },
    {
      "x": 1,
      "y": -2,
      "z": 11,
      "name": "Soil_Dirt"
    },
    {
      "x": 1,
      "y": -1,
      "z": 11,
      "name": "Rock_Stone_Brick_Smooth"
    },
    {
      "x": 1,
      "y": -6,
      "z": 12,
      "name": "Soil_Dirt"
    },
    {
      "x": 1,
      "y": -5,
      "z": 12,
      "name": "Soil_Dirt"
    },
    {
      "x": 1,
      "y": -4,
      "z": 12,
      "name": "Soil_Dirt"
    },
    {
      "x": 1,
      "y": -3,
      "z": 12,
      "name": "Soil_Dirt"
    },
    {
      "x": 1,
      "y": -2,
      "z": 12,
      "name": "Soil_Dirt"
    },
    {
      "x": 1,
      "y": -1,
      "z": 12,
      "name": "Rock_Stone_Brick_Smooth"
    },
    {
      "x": 1,
      "y": -6,
      "z": 13,
      "name": "Soil_Dirt"
    },
    {
      "x": 1,
      "y": -5,
      "z": 13,
      "name": "Soil_Dirt"
    },
    {
      "x": 1,
      "y": -4,
      "z": 13,
      "name": "Soil_Dirt"
    },
    {
      "x": 1,
      "y": -3,
      "z": 13,
      "name": "Soil_Dirt"
    },
    {
      "x": 1,
      "y": -2,
      "z": 13,
      "name": "Soil_Dirt"
    },
    {
      "x": 1,
      "y": -1,
      "z": 13,
      "name": "Rock_Stone_Brick_Smooth"
    },
    {
      "x": 1,
      "y": -6,
      "z": 14,
      "name": "Soil_Dirt"
    },
    {
      "x": 1,
      "y": -5,
      "z": 14,
      "name": "Soil_Dirt"
    },
    {
      "x": 1,
      "y": -4,
      "z": 14,
      "name": "Soil_Dirt"
    },
    {
      "x": 1,
      "y": -3,
      "z": 14,
      "name": "Soil_Dirt"
    },
    {
      "x": 1,
      "y": -2,
      "z": 14,
      "name": "Soil_Dirt"
    },
    {
      "x": 1,
      "y": -1,
      "z": 14,
      "name": "Rock_Stone_Brick_Smooth"
    },
    {
      "x": 1,
      "y": -6,
      "z": 15,
      "name": "Soil_Dirt"
    },
    {
      "x": 1,
      "y": -5,
      "z": 15,
      "name": "Soil_Dirt"
    },
    {
      "x": 1,
      "y": -4,
      "z": 15,
      "name": "Soil_Dirt"
    },
    {
      "x": 1,
      "y": -3,
      "z": 15,
      "name": "Soil_Dirt"
    },
    {
      "x": 1,
      "y": -2,
      "z": 15,
      "name": "Soil_Dirt"
    },
    {
      "x": 1,
      "y": -1,
      "z": 15,
      "name": "Rock_Stone_Brick_Smooth"
    },
    {
      "x": 1,
      "y": -6,
      "z": 16,
      "name": "Soil_Dirt"
    },
    {
      "x": 1,
      "y": -5,
      "z": 16,
      "name": "Soil_Dirt"
    },
    {
      "x": 1,
      "y": -4,
      "z": 16,
      "name": "Soil_Dirt"
    },
    {
      "x": 1,
      "y": -3,
      "z": 16,
      "name": "Soil_Dirt"
    },
    {
      "x": 1,
      "y": -2,
      "z": 16,
      "name": "Soil_Dirt"
    },
    {
      "x": 1,
      "y": -1,
      "z": 16,
      "name": "Rock_Stone_Brick_Smooth"
    },
    {
      "x": 1,
      "y": -6,
      "z": 17,
      "name": "Soil_Dirt"
    },
    {
      "x": 1,
      "y": -5,
      "z": 17,
      "name": "Soil_Dirt"
    },
    {
      "x": 1,
      "y": -4,
      "z": 17,
      "name": "Soil_Dirt"
    },
    {
      "x": 1,
      "y": -3,
      "z": 17,
      "name": "Soil_Dirt"
    },
    {
      "x": 1,
      "y": -2,
      "z": 17,
      "name": "Soil_Dirt"
    },
    {
      "x": 1,
      "y": -1,
      "z": 17,
      "name": "Rock_Stone_Brick_Smooth"
    },
    {
      "x": 1,
      "y": -6,
      "z": 18,
      "name": "Soil_Dirt"
    },
    {
      "x": 1,
      "y": -5,
      "z": 18,
      "name": "Soil_Dirt"
    },
    {
      "x": 1,
      "y": -4,
      "z": 18,
      "name": "Soil_Dirt"
    },
    {
      "x": 1,
      "y": -3,
      "z": 18,
      "name": "Soil_Dirt"
    },
    {
      "x": 1,
      "y": -2,
      "z": 18,
      "name": "Soil_Dirt"
    },
    {
      "x": 1,
      "y": -1,
      "z": 18,
      "name": "Rock_Stone_Brick_Smooth"
    },
    {
      "x": 1,
      "y": -6,
      "z": 19,
      "name": "Soil_Dirt"
    },
    {
      "x": 1,
      "y": -5,
      "z": 19,
      "name": "Soil_Dirt"
    },
    {
      "x": 1,
      "y": -4,
      "z": 19,
      "name": "Soil_Dirt"
    },
    {
      "x": 1,
      "y": -3,
      "z": 19,
      "name": "Soil_Dirt"
    },
    {
      "x": 1,
      "y": -2,
      "z": 19,
      "name": "Soil_Dirt"
    },
    {
      "x": 1,
      "y": -1,
      "z": 19,
      "name": "Rock_Stone_Brick_Smooth"
    },
    {
      "x": 1,
      "y": -6,
      "z": 20,
      "name": "Soil_Dirt"
    },
    {
      "x": 1,
      "y": -5,
      "z": 20,
      "name": "Soil_Dirt"
    },
    {
      "x": 1,
      "y": -4,
      "z": 20,
      "name": "Soil_Dirt"
    },
    {
      "x": 1,
      "y": -3,
      "z": 20,
      "name": "Soil_Dirt"
    },
    {
      "x": 1,
      "y": -2,
      "z": 20,
      "name": "Soil_Dirt"
    },
    {
      "x": 1,
      "y": -1,
      "z": 20,
      "name": "Rock_Stone_Brick_Smooth"
    },
    {
      "x": 1,
      "y": -6,
      "z": 21,
      "name": "Soil_Dirt"
    },
    {
      "x": 1,
      "y": -5,
      "z": 21,
      "name": "Soil_Dirt"
    },
    {
      "x": 1,
      "y": -4,
      "z": 21,
      "name": "Soil_Dirt"
    },
    {
      "x": 1,
      "y": -3,
      "z": 21,
      "name": "Soil_Dirt"
    },
    {
      "x": 1,
      "y": -2,
      "z": 21,
      "name": "Soil_Dirt"
    },
    {
      "x": 1,
      "y": -1,
      "z": 21,
      "name": "Rock_Stone_Brick_Smooth"
    },
    {
      "x": 1,
      "y": -6,
      "z": 22,
      "name": "Soil_Dirt"
    },
    {
      "x": 1,
      "y": -5,
      "z": 22,
      "name": "Soil_Dirt"
    },
    {
      "x": 1,
      "y": -4,
      "z": 22,
      "name": "Soil_Dirt"
    },
    {
      "x": 1,
      "y": -3,
      "z": 22,
      "name": "Soil_Dirt"
    },
    {
      "x": 1,
      "y": -2,
      "z": 22,
      "name": "Soil_Dirt"
    },
    {
      "x": 1,
      "y": -1,
      "z": 22,
      "name": "Rock_Stone_Brick_Smooth"
    },
    {
      "x": 1,
      "y": -6,
      "z": 23,
      "name": "Soil_Dirt"
    },
    {
      "x": 1,
      "y": -5,
      "z": 23,
      "name": "Soil_Dirt"
    },
    {
      "x": 1,
      "y": -4,
      "z": 23,
      "name": "Soil_Dirt"
    },
    {
      "x": 1,
      "y": -3,
      "z": 23,
      "name": "Soil_Dirt"
    },
    {
      "x": 1,
      "y": -2,
      "z": 23,
      "name": "Soil_Dirt"
    },
    {
      "x": 1,
      "y": -1,
      "z": 23,
      "name": "Rock_Stone_Brick_Smooth"
    },
    {
      "x": 1,
      "y": -6,
      "z": 24,
      "name": "Soil_Dirt"
    },
    {
      "x": 1,
      "y": -5,
      "z": 24,
      "name": "Soil_Dirt"
    },
    {
      "x": 1,
      "y": -4,
      "z": 24,
      "name": "Soil_Dirt"
    },
    {
      "x": 1,
      "y": -3,
      "z": 24,
      "name": "Soil_Dirt"
    },
    {
      "x": 1,
      "y": -2,
      "z": 24,
      "name": "Soil_Dirt"
    },
    {
      "x": 1,
      "y": -1,
      "z": 24,
      "name": "Rock_Stone_Brick_Smooth"
    },
    {
      "x": 1,
      "y": -6,
      "z": 25,
      "name": "Soil_Dirt"
    },
    {
      "x": 1,
      "y": -5,
      "z": 25,
      "name": "Soil_Dirt"
    },
    {
      "x": 1,
      "y": -4,
      "z": 25,
      "name": "Soil_Dirt"
    },
    {
      "x": 1,
      "y": -3,
      "z": 25,
      "name": "Soil_Dirt"
    },
    {
      "x": 1,
      "y": -2,
      "z": 25,
      "name": "Soil_Dirt"
    },
    {
      "x": 1,
      "y": -1,
      "z": 25,
      "name": "Rock_Stone_Brick_Smooth"
    },
    {
      "x": 1,
      "y": -6,
      "z": 26,
      "name": "Soil_Dirt"
    },
    {
      "x": 1,
      "y": -5,
      "z": 26,
      "name": "Soil_Dirt"
    },
    {
      "x": 1,
      "y": -4,
      "z": 26,
      "name": "Soil_Dirt"
    },
    {
      "x": 1,
      "y": -3,
      "z": 26,
      "name": "Soil_Dirt"
    },
    {
      "x": 1,
      "y": -2,
      "z": 26,
      "name": "Soil_Dirt"
    },
    {
      "x": 1,
      "y": -1,
      "z": 26,
      "name": "Rock_Stone_Brick_Smooth"
    },
    {
      "x": 1,
      "y": -6,
      "z": 27,
      "name": "Soil_Dirt"
    },
    {
      "x": 1,
      "y": -5,
      "z": 27,
      "name": "Soil_Dirt"
    },
    {
      "x": 1,
      "y": -4,
      "z": 27,
      "name": "Soil_Dirt"
    },
    {
      "x": 1,
      "y": -3,
      "z": 27,
      "name": "Soil_Dirt"
    },
    {
      "x": 1,
      "y": -2,
      "z": 27,
      "name": "Soil_Dirt"
    },
    {
      "x": 1,
      "y": -1,
      "z": 27,
      "name": "Rock_Stone_Brick_Smooth"
    },
    {
      "x": 1,
      "y": -6,
      "z": 28,
      "name": "Soil_Dirt"
    },
    {
      "x": 1,
      "y": -5,
      "z": 28,
      "name": "Soil_Dirt"
    },
    {
      "x": 1,
      "y": -4,
      "z": 28,
      "name": "Soil_Dirt"
    },
    {
      "x": 1,
      "y": -3,
      "z": 28,
      "name": "Soil_Dirt"
    },
    {
      "x": 1,
      "y": -2,
      "z": 28,
      "name": "Soil_Dirt"
    },
    {
      "x": 1,
      "y": -1,
      "z": 28,
      "name": "Rock_Stone_Brick_Smooth"
    },
    {
      "x": 1,
      "y": -6,
      "z": 29,
      "name": "Soil_Dirt"
    },
    {
      "x": 1,
      "y": -5,
      "z": 29,
      "name": "Soil_Dirt"
    },
    {
      "x": 1,
      "y": -4,
      "z": 29,
      "name": "Soil_Dirt"
    },
    {
      "x": 1,
      "y": -3,
      "z": 29,
      "name": "Soil_Dirt"
    },
    {
      "x": 1,
      "y": -2,
      "z": 29,
      "name": "Soil_Dirt"
    },
    {
      "x": 1,
      "y": -1,
      "z": 29,
      "name": "Rock_Stone_Brick_Smooth"
    },
    {
      "x": 1,
      "y": -6,
      "z": 30,
      "name": "Soil_Dirt"
    },
    {
      "x": 1,
      "y": -5,
      "z": 30,
      "name": "Soil_Dirt"
    },
    {
      "x": 1,
      "y": -4,
      "z": 30,
      "name": "Soil_Dirt"
    },
    {
      "x": 1,
      "y": -3,
      "z": 30,
      "name": "Soil_Dirt"
    },
    {
      "x": 1,
      "y": -2,
      "z": 30,
      "name": "Soil_Dirt"
    },
    {
      "x": 1,
      "y": -1,
      "z": 30,
      "name": "Rock_Stone_Brick_Smooth"
    },
    {
      "x": 2,
      "y": -6,
      "z": 1,
      "name": "Soil_Dirt"
    },
    {
      "x": 2,
      "y": -5,
      "z": 1,
      "name": "Soil_Dirt"
    },
    {
      "x": 2,
      "y": -4,
      "z": 1,
      "name": "Soil_Dirt"
    },
    {
      "x": 2,
      "y": -3,
      "z": 1,
      "name": "Soil_Dirt"
    },
    {
      "x": 2,
      "y": -2,
      "z": 1,
      "name": "Soil_Dirt"
    },
    {
      "x": 2,
      "y": -1,
      "z": 1,
      "name": "Rock_Stone_Brick_Smooth"
    },
    {
      "x": 2,
      "y": -6,
      "z": 2,
      "name": "Soil_Dirt"
    },
    {
      "x": 2,
      "y": -5,
      "z": 2,
      "name": "Soil_Dirt"
    },
    {
      "x": 2,
      "y": -4,
      "z": 2,
      "name": "Soil_Dirt"
    },
    {
      "x": 2,
      "y": -3,
      "z": 2,
      "name": "Soil_Dirt"
    },
    {
      "x": 2,
      "y": -2,
      "z": 2,
      "name": "Soil_Dirt"
    },
    {
      "x": 2,
      "y": -1,
      "z": 2,
      "name": "Rock_Stone_Cobble_Mossy"
    },
    {
      "x": 2,
      "y": 0,
      "z": 2,
      "name": "Rock_Stone_Brick_Decorative",
      "rotation": 2
    },
    {
      "x": 2,
      "y": -6,
      "z": 3,
      "name": "Soil_Dirt"
    },
    {
      "x": 2,
      "y": -5,
      "z": 3,
      "name": "Soil_Dirt"
    },
    {
      "x": 2,
      "y": -4,
      "z": 3,
      "name": "Soil_Dirt"
    },
    {
      "x": 2,
      "y": -3,
      "z": 3,
      "name": "Soil_Dirt"
    },
    {
      "x": 2,
      "y": -2,
      "z": 3,
      "name": "Soil_Dirt"
    },
    {
      "x": 2,
      "y": -1,
      "z": 3,
      "name": "Rock_Stone_Cobble"
    },
    {
      "x": 2,
      "y": 0,
      "z": 3,
      "name": "Rock_Stone_Brick_Stairs",
      "rotation": 35
    },
    {
      "x": 2,
      "y": -6,
      "z": 4,
      "name": "Soil_Dirt"
    },
    {
      "x": 2,
      "y": -5,
      "z": 4,
      "name": "Soil_Dirt"
    },
    {
      "x": 2,
      "y": -4,
      "z": 4,
      "name": "Soil_Dirt"
    },
    {
      "x": 2,
      "y": -3,
      "z": 4,
      "name": "Soil_Dirt"
    },
    {
      "x": 2,
      "y": -2,
      "z": 4,
      "name": "Soil_Dirt"
    },
    {
      "x": 2,
      "y": -1,
      "z": 4,
      "name": "Rock_Stone_Cobble_Mossy"
    },
    {
      "x": 2,
      "y": 0,
      "z": 4,
      "name": "Rock_Stone_Brick_Stairs",
      "rotation": 35
    },
    {
      "x": 2,
      "y": -6,
      "z": 5,
      "name": "Soil_Dirt"
    },
    {
      "x": 2,
      "y": -5,
      "z": 5,
      "name": "Soil_Dirt"
    },
    {
      "x": 2,
      "y": -4,
      "z": 5,
      "name": "Soil_Dirt"
    },
    {
      "x": 2,
      "y": -3,
      "z": 5,
      "name": "Soil_Dirt"
    },
    {
      "x": 2,
      "y": -2,
      "z": 5,
      "name": "Soil_Dirt"
    },
    {
      "x": 2,
      "y": -1,
      "z": 5,
      "name": "Rock_Stone_Cobble"
    },
    {
      "x": 2,
      "y": 0,
      "z": 5,
      "name": "Rock_Stone_Brick_Decorative",
      "rotation": 2
    },
    {
      "x": 2,
      "y": -6,
      "z": 6,
      "name": "Soil_Dirt"
    },
    {
      "x": 2,
      "y": -5,
      "z": 6,
      "name": "Soil_Dirt"
    },
    {
      "x": 2,
      "y": -4,
      "z": 6,
      "name": "Soil_Dirt"
    },
    {
      "x": 2,
      "y": -3,
      "z": 6,
      "name": "Soil_Dirt"
    },
    {
      "x": 2,
      "y": -2,
      "z": 6,
      "name": "Soil_Dirt"
    },
    {
      "x": 2,
      "y": -1,
      "z": 6,
      "name": "Rock_Stone_Cobble"
    },
    {
      "x": 2,
      "y": -6,
      "z": 7,
      "name": "Soil_Dirt"
    },
    {
      "x": 2,
      "y": -5,
      "z": 7,
      "name": "Soil_Dirt"
    },
    {
      "x": 2,
      "y": -4,
      "z": 7,
      "name": "Soil_Dirt"
    },
    {
      "x": 2,
      "y": -3,
      "z": 7,
      "name": "Soil_Dirt"
    },
    {
      "x": 2,
      "y": -2,
      "z": 7,
      "name": "Soil_Dirt"
    },
    {
      "x": 2,
      "y": -1,
      "z": 7,
      "name": "Rock_Stone_Cobble"
    },
    {
      "x": 2,
      "y": -6,
      "z": 8,
      "name": "Soil_Dirt"
    },
    {
      "x": 2,
      "y": -5,
      "z": 8,
      "name": "Soil_Dirt"
    },
    {
      "x": 2,
      "y": -4,
      "z": 8,
      "name": "Soil_Dirt"
    },
    {
      "x": 2,
      "y": -3,
      "z": 8,
      "name": "Soil_Dirt"
    },
    {
      "x": 2,
      "y": -2,
      "z": 8,
      "name": "Soil_Dirt"
    },
    {
      "x": 2,
      "y": -1,
      "z": 8,
      "name": "Rock_Stone_Cobble"
    },
    {
      "x": 2,
      "y": -6,
      "z": 9,
      "name": "Soil_Dirt"
    },
    {
      "x": 2,
      "y": -5,
      "z": 9,
      "name": "Soil_Dirt"
    },
    {
      "x": 2,
      "y": -4,
      "z": 9,
      "name": "Soil_Dirt"
    },
    {
      "x": 2,
      "y": -3,
      "z": 9,
      "name": "Soil_Dirt"
    },
    {
      "x": 2,
      "y": -2,
      "z": 9,
      "name": "Soil_Dirt"
    },
    {
      "x": 2,
      "y": -1,
      "z": 9,
      "name": "Rock_Stone_Cobble_Mossy"
    },
    {
      "x": 2,
      "y": -6,
      "z": 10,
      "name": "Soil_Dirt"
    },
    {
      "x": 2,
      "y": -5,
      "z": 10,
      "name": "Soil_Dirt"
    },
    {
      "x": 2,
      "y": -4,
      "z": 10,
      "name": "Soil_Dirt"
    },
    {
      "x": 2,
      "y": -3,
      "z": 10,
      "name": "Soil_Dirt"
    },
    {
      "x": 2,
      "y": -2,
      "z": 10,
      "name": "Soil_Dirt"
    },
    {
      "x": 2,
      "y": -1,
      "z": 10,
      "name": "Rock_Stone_Cobble"
    },
    {
      "x": 2,
      "y": -6,
      "z": 11,
      "name": "Soil_Dirt"
    },
    {
      "x": 2,
      "y": -5,
      "z": 11,
      "name": "Soil_Dirt"
    },
    {
      "x": 2,
      "y": -4,
      "z": 11,
      "name": "Soil_Dirt"
    },
    {
      "x": 2,
      "y": -3,
      "z": 11,
      "name": "Soil_Dirt"
    },
    {
      "x": 2,
      "y": -2,
      "z": 11,
      "name": "Soil_Dirt"
    },
    {
      "x": 2,
      "y": -1,
      "z": 11,
      "name": "Rock_Stone_Cobble_Mossy"
    },
    {
      "x": 2,
      "y": -6,
      "z": 12,
      "name": "Soil_Dirt"
    },
    {
      "x": 2,
      "y": -5,
      "z": 12,
      "name": "Soil_Dirt"
    },
    {
      "x": 2,
      "y": -4,
      "z": 12,
      "name": "Soil_Dirt"
    },
    {
      "x": 2,
      "y": -3,
      "z": 12,
      "name": "Soil_Dirt"
    },
    {
      "x": 2,
      "y": -2,
      "z": 12,
      "name": "Soil_Dirt"
    },
    {
      "x": 2,
      "y": -1,
      "z": 12,
      "name": "Rock_Stone_Cobble_Mossy"
    },
    {
      "x": 2,
      "y": -6,
      "z": 13,
      "name": "Soil_Dirt"
    },
    {
      "x": 2,
      "y": -5,
      "z": 13,
      "name": "Soil_Dirt"
    },
    {
      "x": 2,
      "y": -4,
      "z": 13,
      "name": "Soil_Dirt"
    },
    {
      "x": 2,
      "y": -3,
      "z": 13,
      "name": "Soil_Dirt"
    },
    {
      "x": 2,
      "y": -2,
      "z": 13,
      "name": "Soil_Dirt"
    },
    {
      "x": 2,
      "y": -1,
      "z": 13,
      "name": "Rock_Stone_Cobble"
    },
    {
      "x": 2,
      "y": -6,
      "z": 14,
      "name": "Soil_Dirt"
    },
    {
      "x": 2,
      "y": -5,
      "z": 14,
      "name": "Soil_Dirt"
    },
    {
      "x": 2,
      "y": -4,
      "z": 14,
      "name": "Soil_Dirt"
    },
    {
      "x": 2,
      "y": -3,
      "z": 14,
      "name": "Soil_Dirt"
    },
    {
      "x": 2,
      "y": -2,
      "z": 14,
      "name": "Soil_Dirt"
    },
    {
      "x": 2,
      "y": -1,
      "z": 14,
      "name": "Rock_Stone_Cobble"
    },
    {
      "x": 2,
      "y": -6,
      "z": 15,
      "name": "Soil_Dirt"
    },
    {
      "x": 2,
      "y": -5,
      "z": 15,
      "name": "Soil_Dirt"
    },
    {
      "x": 2,
      "y": -4,
      "z": 15,
      "name": "Soil_Dirt"
    },
    {
      "x": 2,
      "y": -3,
      "z": 15,
      "name": "Soil_Dirt"
    },
    {
      "x": 2,
      "y": -2,
      "z": 15,
      "name": "Soil_Dirt"
    },
    {
      "x": 2,
      "y": -1,
      "z": 15,
      "name": "Rock_Stone_Cobble"
    },
    {
      "x": 2,
      "y": -6,
      "z": 16,
      "name": "Soil_Dirt"
    },
    {
      "x": 2,
      "y": -5,
      "z": 16,
      "name": "Soil_Dirt"
    },
    {
      "x": 2,
      "y": -4,
      "z": 16,
      "name": "Soil_Dirt"
    },
    {
      "x": 2,
      "y": -3,
      "z": 16,
      "name": "Soil_Dirt"
    },
    {
      "x": 2,
      "y": -2,
      "z": 16,
      "name": "Soil_Dirt"
    },
    {
      "x": 2,
      "y": -1,
      "z": 16,
      "name": "Rock_Stone_Cobble"
    },
    {
      "x": 2,
      "y": -6,
      "z": 17,
      "name": "Soil_Dirt"
    },
    {
      "x": 2,
      "y": -5,
      "z": 17,
      "name": "Soil_Dirt"
    },
    {
      "x": 2,
      "y": -4,
      "z": 17,
      "name": "Soil_Dirt"
    },
    {
      "x": 2,
      "y": -3,
      "z": 17,
      "name": "Soil_Dirt"
    },
    {
      "x": 2,
      "y": -2,
      "z": 17,
      "name": "Soil_Dirt"
    },
    {
      "x": 2,
      "y": -1,
      "z": 17,
      "name": "Rock_Stone_Cobble"
    },
    {
      "x": 2,
      "y": -6,
      "z": 18,
      "name": "Soil_Dirt"
    },
    {
      "x": 2,
      "y": -5,
      "z": 18,
      "name": "Soil_Dirt"
    },
    {
      "x": 2,
      "y": -4,
      "z": 18,
      "name": "Soil_Dirt"
    },
    {
      "x": 2,
      "y": -3,
      "z": 18,
      "name": "Soil_Dirt"
    },
    {
      "x": 2,
      "y": -2,
      "z": 18,
      "name": "Soil_Dirt"
    },
    {
      "x": 2,
      "y": -1,
      "z": 18,
      "name": "Rock_Stone_Cobble_Mossy"
    },
    {
      "x": 2,
      "y": -6,
      "z": 19,
      "name": "Soil_Dirt"
    },
    {
      "x": 2,
      "y": -5,
      "z": 19,
      "name": "Soil_Dirt"
    },
    {
      "x": 2,
      "y": -4,
      "z": 19,
      "name": "Soil_Dirt"
    },
    {
      "x": 2,
      "y": -3,
      "z": 19,
      "name": "Soil_Dirt"
    },
    {
      "x": 2,
      "y": -2,
      "z": 19,
      "name": "Soil_Dirt"
    },
    {
      "x": 2,
      "y": -1,
      "z": 19,
      "name": "Rock_Stone_Cobble"
    },
    {
      "x": 2,
      "y": -6,
      "z": 20,
      "name": "Soil_Dirt"
    },
    {
      "x": 2,
      "y": -5,
      "z": 20,
      "name": "Soil_Dirt"
    },
    {
      "x": 2,
      "y": -4,
      "z": 20,
      "name": "Soil_Dirt"
    },
    {
      "x": 2,
      "y": -3,
      "z": 20,
      "name": "Soil_Dirt"
    },
    {
      "x": 2,
      "y": -2,
      "z": 20,
      "name": "Soil_Dirt"
    },
    {
      "x": 2,
      "y": -1,
      "z": 20,
      "name": "Rock_Stone_Cobble"
    },
    {
      "x": 2,
      "y": -6,
      "z": 21,
      "name": "Soil_Dirt"
    },
    {
      "x": 2,
      "y": -5,
      "z": 21,
      "name": "Soil_Dirt"
    },
    {
      "x": 2,
      "y": -4,
      "z": 21,
      "name": "Soil_Dirt"
    },
    {
      "x": 2,
      "y": -3,
      "z": 21,
      "name": "Soil_Dirt"
    },
    {
      "x": 2,
      "y": -2,
      "z": 21,
      "name": "Soil_Dirt"
    },
    {
      "x": 2,
      "y": -1,
      "z": 21,
      "name": "Rock_Stone_Cobble"
    },
    {
      "x": 2,
      "y": -6,
      "z": 22,
      "name": "Soil_Dirt"
    },
    {
      "x": 2,
      "y": -5,
      "z": 22,
      "name": "Soil_Dirt"
    },
    {
      "x": 2,
      "y": -4,
      "z": 22,
      "name": "Soil_Dirt"
    },
    {
      "x": 2,
      "y": -3,
      "z": 22,
      "name": "Soil_Dirt"
    },
    {
      "x": 2,
      "y": -2,
      "z": 22,
      "name": "Soil_Dirt"
    },
    {
      "x": 2,
      "y": -1,
      "z": 22,
      "name": "Rock_Stone_Cobble"
    },
    {
      "x": 2,
      "y": -6,
      "z": 23,
      "name": "Soil_Dirt"
    },
    {
      "x": 2,
      "y": -5,
      "z": 23,
      "name": "Soil_Dirt"
    },
    {
      "x": 2,
      "y": -4,
      "z": 23,
      "name": "Soil_Dirt"
    },
    {
      "x": 2,
      "y": -3,
      "z": 23,
      "name": "Soil_Dirt"
    },
    {
      "x": 2,
      "y": -2,
      "z": 23,
      "name": "Soil_Dirt"
    },
    {
      "x": 2,
      "y": -1,
      "z": 23,
      "name": "Rock_Stone_Cobble"
    },
    {
      "x": 2,
      "y": -6,
      "z": 24,
      "name": "Soil_Dirt"
    },
    {
      "x": 2,
      "y": -5,
      "z": 24,
      "name": "Soil_Dirt"
    },
    {
      "x": 2,
      "y": -4,
      "z": 24,
      "name": "Soil_Dirt"
    },
    {
      "x": 2,
      "y": -3,
      "z": 24,
      "name": "Soil_Dirt"
    },
    {
      "x": 2,
      "y": -2,
      "z": 24,
      "name": "Soil_Dirt"
    },
    {
      "x": 2,
      "y": -1,
      "z": 24,
      "name": "Rock_Stone_Cobble"
    },
    {
      "x": 2,
      "y": -6,
      "z": 25,
      "name": "Soil_Dirt"
    },
    {
      "x": 2,
      "y": -5,
      "z": 25,
      "name": "Soil_Dirt"
    },
    {
      "x": 2,
      "y": -4,
      "z": 25,
      "name": "Soil_Dirt"
    },
    {
      "x": 2,
      "y": -3,
      "z": 25,
      "name": "Soil_Dirt"
    },
    {
      "x": 2,
      "y": -2,
      "z": 25,
      "name": "Soil_Dirt"
    },
    {
      "x": 2,
      "y": -1,
      "z": 25,
      "name": "Rock_Stone_Cobble"
    },
    {
      "x": 2,
      "y": -6,
      "z": 26,
      "name": "Soil_Dirt"
    },
    {
      "x": 2,
      "y": -5,
      "z": 26,
      "name": "Soil_Dirt"
    },
    {
      "x": 2,
      "y": -4,
      "z": 26,
      "name": "Soil_Dirt"
    },
    {
      "x": 2,
      "y": -3,
      "z": 26,
      "name": "Soil_Dirt"
    },
    {
      "x": 2,
      "y": -2,
      "z": 26,
      "name": "Soil_Dirt"
    },
    {
      "x": 2,
      "y": -1,
      "z": 26,
      "name": "Rock_Stone_Cobble_Mossy"
    },
    {
      "x": 2,
      "y": 0,
      "z": 26,
      "name": "Rock_Stone_Brick_Decorative",
      "rotation": 3
    },
    {
      "x": 2,
      "y": -6,
      "z": 27,
      "name": "Soil_Dirt"
    },
    {
      "x": 2,
      "y": -5,
      "z": 27,
      "name": "Soil_Dirt"
    },
    {
      "x": 2,
      "y": -4,
      "z": 27,
      "name": "Soil_Dirt"
    },
    {
      "x": 2,
      "y": -3,
      "z": 27,
      "name": "Soil_Dirt"
    },
    {
      "x": 2,
      "y": -2,
      "z": 27,
      "name": "Soil_Dirt"
    },
    {
      "x": 2,
      "y": -1,
      "z": 27,
      "name": "Rock_Stone_Cobble"
    },
    {
      "x": 2,
      "y": 0,
      "z": 27,
      "name": "Rock_Stone_Brick_Stairs",
      "rotation": 35
    },
    {
      "x": 2,
      "y": -6,
      "z": 28,
      "name": "Soil_Dirt"
    },
    {
      "x": 2,
      "y": -5,
      "z": 28,
      "name": "Soil_Dirt"
    },
    {
      "x": 2,
      "y": -4,
      "z": 28,
      "name": "Soil_Dirt"
    },
    {
      "x": 2,
      "y": -3,
      "z": 28,
      "name": "Soil_Dirt"
    },
    {
      "x": 2,
      "y": -2,
      "z": 28,
      "name": "Soil_Dirt"
    },
    {
      "x": 2,
      "y": -1,
      "z": 28,
      "name": "Rock_Stone_Cobble"
    },
    {
      "x": 2,
      "y": 0,
      "z": 28,
      "name": "Rock_Stone_Brick_Stairs",
      "rotation": 35
    },
    {
      "x": 2,
      "y": -6,
      "z": 29,
      "name": "Soil_Dirt"
    },
    {
      "x": 2,
      "y": -5,
      "z": 29,
      "name": "Soil_Dirt"
    },
    {
      "x": 2,
      "y": -4,
      "z": 29,
      "name": "Soil_Dirt"
    },
    {
      "x": 2,
      "y": -3,
      "z": 29,
      "name": "Soil_Dirt"
    },
    {
      "x": 2,
      "y": -2,
      "z": 29,
      "name": "Soil_Dirt"
    },
    {
      "x": 2,
      "y": -1,
      "z": 29,
      "name": "Rock_Stone_Cobble"
    },
    {
      "x": 2,
      "y": 0,
      "z": 29,
      "name": "Rock_Stone_Brick_Decorative",
      "rotation": 3
    },
    {
      "x": 2,
      "y": -6,
      "z": 30,
      "name": "Soil_Dirt"
    },
    {
      "x": 2,
      "y": -5,
      "z": 30,
      "name": "Soil_Dirt"
    },
    {
      "x": 2,
      "y": -4,
      "z": 30,
      "name": "Soil_Dirt"
    },
    {
      "x": 2,
      "y": -3,
      "z": 30,
      "name": "Soil_Dirt"
    },
    {
      "x": 2,
      "y": -2,
      "z": 30,
      "name": "Soil_Dirt"
    },
    {
      "x": 2,
      "y": -1,
      "z": 30,
      "name": "Rock_Stone_Brick_Smooth"
    },
    {
      "x": 3,
      "y": -6,
      "z": 1,
      "name": "Soil_Dirt"
    },
    {
      "x": 3,
      "y": -5,
      "z": 1,
      "name": "Soil_Dirt"
    },
    {
      "x": 3,
      "y": -4,
      "z": 1,
      "name": "Soil_Dirt"
    },
    {
      "x": 3,
      "y": -3,
      "z": 1,
      "name": "Soil_Dirt"
    },
    {
      "x": 3,
      "y": -2,
      "z": 1,
      "name": "Soil_Dirt"
    },
    {
      "x": 3,
      "y": -1,
      "z": 1,
      "name": "Rock_Stone_Brick_Smooth"
    },
    {
      "x": 3,
      "y": -6,
      "z": 2,
      "name": "Soil_Dirt"
    },
    {
      "x": 3,
      "y": -5,
      "z": 2,
      "name": "Soil_Dirt"
    },
    {
      "x": 3,
      "y": -4,
      "z": 2,
      "name": "Soil_Dirt"
    },
    {
      "x": 3,
      "y": -3,
      "z": 2,
      "name": "Soil_Dirt"
    },
    {
      "x": 3,
      "y": -2,
      "z": 2,
      "name": "Soil_Dirt"
    },
    {
      "x": 3,
      "y": -1,
      "z": 2,
      "name": "Rock_Stone_Cobble"
    },
    {
      "x": 3,
      "y": 0,
      "z": 2,
      "name": "Rock_Stone_Brick_Stairs",
      "rotation": 34
    },
    {
      "x": 3,
      "y": -6,
      "z": 3,
      "name": "Soil_Dirt"
    },
    {
      "x": 3,
      "y": -5,
      "z": 3,
      "name": "Soil_Dirt"
    },
    {
      "x": 3,
      "y": -4,
      "z": 3,
      "name": "Soil_Dirt"
    },
    {
      "x": 3,
      "y": -3,
      "z": 3,
      "name": "Soil_Dirt"
    },
    {
      "x": 3,
      "y": -2,
      "z": 3,
      "name": "Soil_Dirt"
    },
    {
      "x": 3,
      "y": -1,
      "z": 3,
      "name": "Rock_Stone_Cobble_Mossy"
    },
    {
      "x": 3,
      "y": 0,
      "z": 3,
      "name": "Rock_Stone_Brick_Smooth"
    },
    {
      "x": 3,
      "y": -6,
      "z": 4,
      "name": "Soil_Dirt"
    },
    {
      "x": 3,
      "y": -5,
      "z": 4,
      "name": "Soil_Dirt"
    },
    {
      "x": 3,
      "y": -4,
      "z": 4,
      "name": "Soil_Dirt"
    },
    {
      "x": 3,
      "y": -3,
      "z": 4,
      "name": "Soil_Dirt"
    },
    {
      "x": 3,
      "y": -2,
      "z": 4,
      "name": "Soil_Dirt"
    },
    {
      "x": 3,
      "y": -1,
      "z": 4,
      "name": "Rock_Stone_Cobble"
    },
    {
      "x": 3,
      "y": 0,
      "z": 4,
      "name": "Rock_Stone_Brick_Smooth"
    },
    {
      "x": 3,
      "y": -6,
      "z": 5,
      "name": "Soil_Dirt"
    },
    {
      "x": 3,
      "y": -5,
      "z": 5,
      "name": "Soil_Dirt"
    },
    {
      "x": 3,
      "y": -4,
      "z": 5,
      "name": "Soil_Dirt"
    },
    {
      "x": 3,
      "y": -3,
      "z": 5,
      "name": "Soil_Dirt"
    },
    {
      "x": 3,
      "y": -2,
      "z": 5,
      "name": "Soil_Dirt"
    },
    {
      "x": 3,
      "y": -1,
      "z": 5,
      "name": "Rock_Stone_Cobble"
    },
    {
      "x": 3,
      "y": 0,
      "z": 5,
      "name": "Rock_Stone_Brick_Stairs",
      "rotation": 32
    },
    {
      "x": 3,
      "y": -6,
      "z": 6,
      "name": "Soil_Dirt"
    },
    {
      "x": 3,
      "y": -5,
      "z": 6,
      "name": "Soil_Dirt"
    },
    {
      "x": 3,
      "y": -4,
      "z": 6,
      "name": "Soil_Dirt"
    },
    {
      "x": 3,
      "y": -3,
      "z": 6,
      "name": "Soil_Dirt"
    },
    {
      "x": 3,
      "y": -2,
      "z": 6,
      "name": "Soil_Dirt"
    },
    {
      "x": 3,
      "y": -1,
      "z": 6,
      "name": "Rock_Stone_Cobble_Mossy"
    },
    {
      "x": 3,
      "y": -6,
      "z": 7,
      "name": "Soil_Dirt"
    },
    {
      "x": 3,
      "y": -5,
      "z": 7,
      "name": "Soil_Dirt"
    },
    {
      "x": 3,
      "y": -4,
      "z": 7,
      "name": "Soil_Dirt"
    },
    {
      "x": 3,
      "y": -3,
      "z": 7,
      "name": "Soil_Dirt"
    },
    {
      "x": 3,
      "y": -2,
      "z": 7,
      "name": "Soil_Dirt"
    },
    {
      "x": 3,
      "y": -1,
      "z": 7,
      "name": "Rock_Stone_Cobble"
    },
    {
      "x": 3,
      "y": -6,
      "z": 8,
      "name": "Soil_Dirt"
    },
    {
      "x": 3,
      "y": -5,
      "z": 8,
      "name": "Soil_Dirt"
    },
    {
      "x": 3,
      "y": -4,
      "z": 8,
      "name": "Soil_Dirt"
    },
    {
      "x": 3,
      "y": -3,
      "z": 8,
      "name": "Soil_Dirt"
    },
    {
      "x": 3,
      "y": -2,
      "z": 8,
      "name": "Soil_Dirt"
    },
    {
      "x": 3,
      "y": -1,
      "z": 8,
      "name": "Rock_Stone_Cobble"
    },
    {
      "x": 3,
      "y": -6,
      "z": 9,
      "name": "Soil_Dirt"
    },
    {
      "x": 3,
      "y": -5,
      "z": 9,
      "name": "Soil_Dirt"
    },
    {
      "x": 3,
      "y": -4,
      "z": 9,
      "name": "Soil_Dirt"
    },
    {
      "x": 3,
      "y": -3,
      "z": 9,
      "name": "Soil_Dirt"
    },
    {
      "x": 3,
      "y": -2,
      "z": 9,
      "name": "Soil_Dirt"
    },
    {
      "x": 3,
      "y": -1,
      "z": 9,
      "name": "Rock_Stone_Cobble"
    },
    {
      "x": 3,
      "y": -6,
      "z": 10,
      "name": "Soil_Dirt"
    },
    {
      "x": 3,
      "y": -5,
      "z": 10,
      "name": "Soil_Dirt"
    },
    {
      "x": 3,
      "y": -4,
      "z": 10,
      "name": "Soil_Dirt"
    },
    {
      "x": 3,
      "y": -3,
      "z": 10,
      "name": "Soil_Dirt"
    },
    {
      "x": 3,
      "y": -2,
      "z": 10,
      "name": "Soil_Dirt"
    },
    {
      "x": 3,
      "y": -1,
      "z": 10,
      "name": "Rock_Stone_Cobble"
    },
    {
      "x": 3,
      "y": -6,
      "z": 11,
      "name": "Soil_Dirt"
    },
    {
      "x": 3,
      "y": -5,
      "z": 11,
      "name": "Soil_Dirt"
    },
    {
      "x": 3,
      "y": -4,
      "z": 11,
      "name": "Soil_Dirt"
    },
    {
      "x": 3,
      "y": -3,
      "z": 11,
      "name": "Soil_Dirt"
    },
    {
      "x": 3,
      "y": -2,
      "z": 11,
      "name": "Soil_Dirt"
    },
    {
      "x": 3,
      "y": -1,
      "z": 11,
      "name": "Rock_Stone_Cobble"
    },
    {
      "x": 3,
      "y": -6,
      "z": 12,
      "name": "Soil_Dirt"
    },
    {
      "x": 3,
      "y": -5,
      "z": 12,
      "name": "Soil_Dirt"
    },
    {
      "x": 3,
      "y": -4,
      "z": 12,
      "name": "Soil_Dirt"
    },
    {
      "x": 3,
      "y": -3,
      "z": 12,
      "name": "Soil_Dirt"
    },
    {
      "x": 3,
      "y": -2,
      "z": 12,
      "name": "Soil_Dirt"
    },
    {
      "x": 3,
      "y": -1,
      "z": 12,
      "name": "Rock_Stone_Cobble"
    },
    {
      "x": 3,
      "y": -6,
      "z": 13,
      "name": "Soil_Dirt"
    },
    {
      "x": 3,
      "y": -5,
      "z": 13,
      "name": "Soil_Dirt"
    },
    {
      "x": 3,
      "y": -4,
      "z": 13,
      "name": "Soil_Dirt"
    },
    {
      "x": 3,
      "y": -3,
      "z": 13,
      "name": "Soil_Dirt"
    },
    {
      "x": 3,
      "y": -2,
      "z": 13,
      "name": "Soil_Dirt"
    },
    {
      "x": 3,
      "y": -1,
      "z": 13,
      "name": "Rock_Stone_Cobble"
    },
    {
      "x": 3,
      "y": -6,
      "z": 14,
      "name": "Soil_Dirt"
    },
    {
      "x": 3,
      "y": -5,
      "z": 14,
      "name": "Soil_Dirt"
    },
    {
      "x": 3,
      "y": -4,
      "z": 14,
      "name": "Soil_Dirt"
    },
    {
      "x": 3,
      "y": -3,
      "z": 14,
      "name": "Soil_Dirt"
    },
    {
      "x": 3,
      "y": -2,
      "z": 14,
      "name": "Soil_Dirt"
    },
    {
      "x": 3,
      "y": -1,
      "z": 14,
      "name": "Rock_Stone_Cobble"
    },
    {
      "x": 3,
      "y": -6,
      "z": 15,
      "name": "Soil_Dirt"
    },
    {
      "x": 3,
      "y": -5,
      "z": 15,
      "name": "Soil_Dirt"
    },
    {
      "x": 3,
      "y": -4,
      "z": 15,
      "name": "Soil_Dirt"
    },
    {
      "x": 3,
      "y": -3,
      "z": 15,
      "name": "Soil_Dirt"
    },
    {
      "x": 3,
      "y": -2,
      "z": 15,
      "name": "Soil_Dirt"
    },
    {
      "x": 3,
      "y": -1,
      "z": 15,
      "name": "Rock_Stone_Cobble"
    },
    {
      "x": 3,
      "y": -6,
      "z": 16,
      "name": "Soil_Dirt"
    },
    {
      "x": 3,
      "y": -5,
      "z": 16,
      "name": "Soil_Dirt"
    },
    {
      "x": 3,
      "y": -4,
      "z": 16,
      "name": "Soil_Dirt"
    },
    {
      "x": 3,
      "y": -3,
      "z": 16,
      "name": "Soil_Dirt"
    },
    {
      "x": 3,
      "y": -2,
      "z": 16,
      "name": "Soil_Dirt"
    },
    {
      "x": 3,
      "y": -1,
      "z": 16,
      "name": "Rock_Stone_Cobble"
    },
    {
      "x": 3,
      "y": -6,
      "z": 17,
      "name": "Soil_Dirt"
    },
    {
      "x": 3,
      "y": -5,
      "z": 17,
      "name": "Soil_Dirt"
    },
    {
      "x": 3,
      "y": -4,
      "z": 17,
      "name": "Soil_Dirt"
    },
    {
      "x": 3,
      "y": -3,
      "z": 17,
      "name": "Soil_Dirt"
    },
    {
      "x": 3,
      "y": -2,
      "z": 17,
      "name": "Soil_Dirt"
    },
    {
      "x": 3,
      "y": -1,
      "z": 17,
      "name": "Rock_Stone_Cobble_Mossy"
    },
    {
      "x": 3,
      "y": -6,
      "z": 18,
      "name": "Soil_Dirt"
    },
    {
      "x": 3,
      "y": -5,
      "z": 18,
      "name": "Soil_Dirt"
    },
    {
      "x": 3,
      "y": -4,
      "z": 18,
      "name": "Soil_Dirt"
    },
    {
      "x": 3,
      "y": -3,
      "z": 18,
      "name": "Soil_Dirt"
    },
    {
      "x": 3,
      "y": -2,
      "z": 18,
      "name": "Soil_Dirt"
    },
    {
      "x": 3,
      "y": -1,
      "z": 18,
      "name": "Rock_Stone_Cobble"
    },
    {
      "x": 3,
      "y": -6,
      "z": 19,
      "name": "Soil_Dirt"
    },
    {
      "x": 3,
      "y": -5,
      "z": 19,
      "name": "Soil_Dirt"
    },
    {
      "x": 3,
      "y": -4,
      "z": 19,
      "name": "Soil_Dirt"
    },
    {
      "x": 3,
      "y": -3,
      "z": 19,
      "name": "Soil_Dirt"
    },
    {
      "x": 3,
      "y": -2,
      "z": 19,
      "name": "Soil_Dirt"
    },
    {
      "x": 3,
      "y": -1,
      "z": 19,
      "name": "Rock_Stone_Cobble_Mossy"
    },
    {
      "x": 3,
      "y": -6,
      "z": 20,
      "name": "Soil_Dirt"
    },
    {
      "x": 3,
      "y": -5,
      "z": 20,
      "name": "Soil_Dirt"
    },
    {
      "x": 3,
      "y": -4,
      "z": 20,
      "name": "Soil_Dirt"
    },
    {
      "x": 3,
      "y": -3,
      "z": 20,
      "name": "Soil_Dirt"
    },
    {
      "x": 3,
      "y": -2,
      "z": 20,
      "name": "Soil_Dirt"
    },
    {
      "x": 3,
      "y": -1,
      "z": 20,
      "name": "Rock_Stone_Cobble_Mossy"
    },
    {
      "x": 3,
      "y": -6,
      "z": 21,
      "name": "Soil_Dirt"
    },
    {
      "x": 3,
      "y": -5,
      "z": 21,
      "name": "Soil_Dirt"
    },
    {
      "x": 3,
      "y": -4,
      "z": 21,
      "name": "Soil_Dirt"
    },
    {
      "x": 3,
      "y": -3,
      "z": 21,
      "name": "Soil_Dirt"
    },
    {
      "x": 3,
      "y": -2,
      "z": 21,
      "name": "Soil_Dirt"
    },
    {
      "x": 3,
      "y": -1,
      "z": 21,
      "name": "Rock_Stone_Cobble"
    },
    {
      "x": 3,
      "y": -6,
      "z": 22,
      "name": "Soil_Dirt"
    },
    {
      "x": 3,
      "y": -5,
      "z": 22,
      "name": "Soil_Dirt"
    },
    {
      "x": 3,
      "y": -4,
      "z": 22,
      "name": "Soil_Dirt"
    },
    {
      "x": 3,
      "y": -3,
      "z": 22,
      "name": "Soil_Dirt"
    },
    {
      "x": 3,
      "y": -2,
      "z": 22,
      "name": "Soil_Dirt"
    },
    {
      "x": 3,
      "y": -1,
      "z": 22,
      "name": "Rock_Stone_Cobble"
    },
    {
      "x": 3,
      "y": -6,
      "z": 23,
      "name": "Soil_Dirt"
    },
    {
      "x": 3,
      "y": -5,
      "z": 23,
      "name": "Soil_Dirt"
    },
    {
      "x": 3,
      "y": -4,
      "z": 23,
      "name": "Soil_Dirt"
    },
    {
      "x": 3,
      "y": -3,
      "z": 23,
      "name": "Soil_Dirt"
    },
    {
      "x": 3,
      "y": -2,
      "z": 23,
      "name": "Soil_Dirt"
    },
    {
      "x": 3,
      "y": -1,
      "z": 23,
      "name": "Rock_Stone_Cobble"
    },
    {
      "x": 3,
      "y": -6,
      "z": 24,
      "name": "Soil_Dirt"
    },
    {
      "x": 3,
      "y": -5,
      "z": 24,
      "name": "Soil_Dirt"
    },
    {
      "x": 3,
      "y": -4,
      "z": 24,
      "name": "Soil_Dirt"
    },
    {
      "x": 3,
      "y": -3,
      "z": 24,
      "name": "Soil_Dirt"
    },
    {
      "x": 3,
      "y": -2,
      "z": 24,
      "name": "Soil_Dirt"
    },
    {
      "x": 3,
      "y": -1,
      "z": 24,
      "name": "Rock_Stone_Cobble_Mossy"
    },
    {
      "x": 3,
      "y": -6,
      "z": 25,
      "name": "Soil_Dirt"
    },
    {
      "x": 3,
      "y": -5,
      "z": 25,
      "name": "Soil_Dirt"
    },
    {
      "x": 3,
      "y": -4,
      "z": 25,
      "name": "Soil_Dirt"
    },
    {
      "x": 3,
      "y": -3,
      "z": 25,
      "name": "Soil_Dirt"
    },
    {
      "x": 3,
      "y": -2,
      "z": 25,
      "name": "Soil_Dirt"
    },
    {
      "x": 3,
      "y": -1,
      "z": 25,
      "name": "Rock_Stone_Cobble"
    },
    {
      "x": 3,
      "y": -6,
      "z": 26,
      "name": "Soil_Dirt"
    },
    {
      "x": 3,
      "y": -5,
      "z": 26,
      "name": "Soil_Dirt"
    },
    {
      "x": 3,
      "y": -4,
      "z": 26,
      "name": "Soil_Dirt"
    },
    {
      "x": 3,
      "y": -3,
      "z": 26,
      "name": "Soil_Dirt"
    },
    {
      "x": 3,
      "y": -2,
      "z": 26,
      "name": "Soil_Dirt"
    },
    {
      "x": 3,
      "y": -1,
      "z": 26,
      "name": "Rock_Stone_Cobble_Mossy"
    },
    {
      "x": 3,
      "y": 0,
      "z": 26,
      "name": "Rock_Stone_Brick_Stairs",
      "rotation": 34
    },
    {
      "x": 3,
      "y": -6,
      "z": 27,
      "name": "Soil_Dirt"
    },
    {
      "x": 3,
      "y": -5,
      "z": 27,
      "name": "Soil_Dirt"
    },
    {
      "x": 3,
      "y": -4,
      "z": 27,
      "name": "Soil_Dirt"
    },
    {
      "x": 3,
      "y": -3,
      "z": 27,
      "name": "Soil_Dirt"
    },
    {
      "x": 3,
      "y": -2,
      "z": 27,
      "name": "Soil_Dirt"
    },
    {
      "x": 3,
      "y": -1,
      "z": 27,
      "name": "Rock_Stone_Cobble"
    },
    {
      "x": 3,
      "y": 0,
      "z": 27,
      "name": "Rock_Stone_Brick_Smooth"
    },
    {
      "x": 3,
      "y": -6,
      "z": 28,
      "name": "Soil_Dirt"
    },
    {
      "x": 3,
      "y": -5,
      "z": 28,
      "name": "Soil_Dirt"
    },
    {
      "x": 3,
      "y": -4,
      "z": 28,
      "name": "Soil_Dirt"
    },
    {
      "x": 3,
      "y": -3,
      "z": 28,
      "name": "Soil_Dirt"
    },
    {
      "x": 3,
      "y": -2,
      "z": 28,
      "name": "Soil_Dirt"
    },
    {
      "x": 3,
      "y": -1,
      "z": 28,
      "name": "Rock_Stone_Cobble"
    },
    {
      "x": 3,
      "y": 0,
      "z": 28,
      "name": "Rock_Stone_Brick_Smooth"
    },
    {
      "x": 3,
      "y": -6,
      "z": 29,
      "name": "Soil_Dirt"
    },
    {
      "x": 3,
      "y": -5,
      "z": 29,
      "name": "Soil_Dirt"
    },
    {
      "x": 3,
      "y": -4,
      "z": 29,
      "name": "Soil_Dirt"
    },
    {
      "x": 3,
      "y": -3,
      "z": 29,
      "name": "Soil_Dirt"
    },
    {
      "x": 3,
      "y": -2,
      "z": 29,
      "name": "Soil_Dirt"
    },
    {
      "x": 3,
      "y": -1,
      "z": 29,
      "name": "Rock_Stone_Cobble"
    },
    {
      "x": 3,
      "y": 0,
      "z": 29,
      "name": "Rock_Stone_Brick_Stairs",
      "rotation": 32
    },
    {
      "x": 3,
      "y": -6,
      "z": 30,
      "name": "Soil_Dirt"
    },
    {
      "x": 3,
      "y": -5,
      "z": 30,
      "name": "Soil_Dirt"
    },
    {
      "x": 3,
      "y": -4,
      "z": 30,
      "name": "Soil_Dirt"
    },
    {
      "x": 3,
      "y": -3,
      "z": 30,
      "name": "Soil_Dirt"
    },
    {
      "x": 3,
      "y": -2,
      "z": 30,
      "name": "Soil_Dirt"
    },
    {
      "x": 3,
      "y": -1,
      "z": 30,
      "name": "Rock_Stone_Brick_Smooth"
    },
    {
      "x": 4,
      "y": -6,
      "z": 1,
      "name": "Soil_Dirt"
    },
    {
      "x": 4,
      "y": -5,
      "z": 1,
      "name": "Soil_Dirt"
    },
    {
      "x": 4,
      "y": -4,
      "z": 1,
      "name": "Soil_Dirt"
    },
    {
      "x": 4,
      "y": -3,
      "z": 1,
      "name": "Soil_Dirt"
    },
    {
      "x": 4,
      "y": -2,
      "z": 1,
      "name": "Soil_Dirt"
    },
    {
      "x": 4,
      "y": -1,
      "z": 1,
      "name": "Rock_Stone_Brick_Smooth"
    },
    {
      "x": 4,
      "y": -6,
      "z": 2,
      "name": "Soil_Dirt"
    },
    {
      "x": 4,
      "y": -5,
      "z": 2,
      "name": "Soil_Dirt"
    },
    {
      "x": 4,
      "y": -4,
      "z": 2,
      "name": "Soil_Dirt"
    },
    {
      "x": 4,
      "y": -3,
      "z": 2,
      "name": "Soil_Dirt"
    },
    {
      "x": 4,
      "y": -2,
      "z": 2,
      "name": "Soil_Dirt"
    },
    {
      "x": 4,
      "y": -1,
      "z": 2,
      "name": "Rock_Stone_Cobble"
    },
    {
      "x": 4,
      "y": 0,
      "z": 2,
      "name": "Rock_Stone_Brick_Stairs",
      "rotation": 34
    },
    {
      "x": 4,
      "y": -6,
      "z": 3,
      "name": "Soil_Dirt"
    },
    {
      "x": 4,
      "y": -5,
      "z": 3,
      "name": "Soil_Dirt"
    },
    {
      "x": 4,
      "y": -4,
      "z": 3,
      "name": "Soil_Dirt"
    },
    {
      "x": 4,
      "y": -3,
      "z": 3,
      "name": "Soil_Dirt"
    },
    {
      "x": 4,
      "y": -2,
      "z": 3,
      "name": "Soil_Dirt"
    },
    {
      "x": 4,
      "y": -1,
      "z": 3,
      "name": "Rock_Stone_Cobble"
    },
    {
      "x": 4,
      "y": 0,
      "z": 3,
      "name": "Rock_Stone_Brick_Smooth"
    },
    {
      "x": 4,
      "y": -6,
      "z": 4,
      "name": "Soil_Dirt"
    },
    {
      "x": 4,
      "y": -5,
      "z": 4,
      "name": "Soil_Dirt"
    },
    {
      "x": 4,
      "y": -4,
      "z": 4,
      "name": "Soil_Dirt"
    },
    {
      "x": 4,
      "y": -3,
      "z": 4,
      "name": "Soil_Dirt"
    },
    {
      "x": 4,
      "y": -2,
      "z": 4,
      "name": "Soil_Dirt"
    },
    {
      "x": 4,
      "y": -1,
      "z": 4,
      "name": "Rock_Stone_Cobble"
    },
    {
      "x": 4,
      "y": 0,
      "z": 4,
      "name": "Rock_Stone_Brick_Smooth"
    },
    {
      "x": 4,
      "y": -6,
      "z": 5,
      "name": "Soil_Dirt"
    },
    {
      "x": 4,
      "y": -5,
      "z": 5,
      "name": "Soil_Dirt"
    },
    {
      "x": 4,
      "y": -4,
      "z": 5,
      "name": "Soil_Dirt"
    },
    {
      "x": 4,
      "y": -3,
      "z": 5,
      "name": "Soil_Dirt"
    },
    {
      "x": 4,
      "y": -2,
      "z": 5,
      "name": "Soil_Dirt"
    },
    {
      "x": 4,
      "y": -1,
      "z": 5,
      "name": "Rock_Stone_Cobble"
    },
    {
      "x": 4,
      "y": 0,
      "z": 5,
      "name": "Rock_Stone_Brick_Stairs",
      "rotation": 32
    },
    {
      "x": 4,
      "y": -6,
      "z": 6,
      "name": "Soil_Dirt"
    },
    {
      "x": 4,
      "y": -5,
      "z": 6,
      "name": "Soil_Dirt"
    },
    {
      "x": 4,
      "y": -4,
      "z": 6,
      "name": "Soil_Dirt"
    },
    {
      "x": 4,
      "y": -3,
      "z": 6,
      "name": "Soil_Dirt"
    },
    {
      "x": 4,
      "y": -2,
      "z": 6,
      "name": "Soil_Dirt"
    },
    {
      "x": 4,
      "y": -1,
      "z": 6,
      "name": "Rock_Stone_Cobble_Mossy"
    },
    {
      "x": 4,
      "y": -6,
      "z": 7,
      "name": "Soil_Dirt"
    },
    {
      "x": 4,
      "y": -5,
      "z": 7,
      "name": "Soil_Dirt"
    },
    {
      "x": 4,
      "y": -4,
      "z": 7,
      "name": "Soil_Dirt"
    },
    {
      "x": 4,
      "y": -3,
      "z": 7,
      "name": "Soil_Dirt"
    },
    {
      "x": 4,
      "y": -2,
      "z": 7,
      "name": "Soil_Dirt"
    },
    {
      "x": 4,
      "y": -1,
      "z": 7,
      "name": "Rock_Stone_Cobble"
    },
    {
      "x": 4,
      "y": -6,
      "z": 8,
      "name": "Soil_Dirt"
    },
    {
      "x": 4,
      "y": -5,
      "z": 8,
      "name": "Soil_Dirt"
    },
    {
      "x": 4,
      "y": -4,
      "z": 8,
      "name": "Soil_Dirt"
    },
    {
      "x": 4,
      "y": -3,
      "z": 8,
      "name": "Soil_Dirt"
    },
    {
      "x": 4,
      "y": -2,
      "z": 8,
      "name": "Soil_Dirt"
    },
    {
      "x": 4,
      "y": -1,
      "z": 8,
      "name": "Rock_Stone_Cobble_Mossy"
    },
    {
      "x": 4,
      "y": -6,
      "z": 9,
      "name": "Soil_Dirt"
    },
    {
      "x": 4,
      "y": -5,
      "z": 9,
      "name": "Soil_Dirt"
    },
    {
      "x": 4,
      "y": -4,
      "z": 9,
      "name": "Soil_Dirt"
    },
    {
      "x": 4,
      "y": -3,
      "z": 9,
      "name": "Soil_Dirt"
    },
    {
      "x": 4,
      "y": -2,
      "z": 9,
      "name": "Soil_Dirt"
    },
    {
      "x": 4,
      "y": -1,
      "z": 9,
      "name": "Rock_Stone_Cobble"
    },
    {
      "x": 4,
      "y": -6,
      "z": 10,
      "name": "Soil_Dirt"
    },
    {
      "x": 4,
      "y": -5,
      "z": 10,
      "name": "Soil_Dirt"
    },
    {
      "x": 4,
      "y": -4,
      "z": 10,
      "name": "Soil_Dirt"
    },
    {
      "x": 4,
      "y": -3,
      "z": 10,
      "name": "Soil_Dirt"
    },
    {
      "x": 4,
      "y": -2,
      "z": 10,
      "name": "Soil_Dirt"
    },
    {
      "x": 4,
      "y": -1,
      "z": 10,
      "name": "Rock_Stone_Cobble_Mossy"
    },
    {
      "x": 4,
      "y": -6,
      "z": 11,
      "name": "Soil_Dirt"
    },
    {
      "x": 4,
      "y": -5,
      "z": 11,
      "name": "Soil_Dirt"
    },
    {
      "x": 4,
      "y": -4,
      "z": 11,
      "name": "Soil_Dirt"
    },
    {
      "x": 4,
      "y": -3,
      "z": 11,
      "name": "Soil_Dirt"
    },
    {
      "x": 4,
      "y": -2,
      "z": 11,
      "name": "Soil_Dirt"
    },
    {
      "x": 4,
      "y": -1,
      "z": 11,
      "name": "Rock_Stone_Cobble"
    },
    {
      "x": 4,
      "y": -6,
      "z": 12,
      "name": "Soil_Dirt"
    },
    {
      "x": 4,
      "y": -5,
      "z": 12,
      "name": "Soil_Dirt"
    },
    {
      "x": 4,
      "y": -4,
      "z": 12,
      "name": "Soil_Dirt"
    },
    {
      "x": 4,
      "y": -3,
      "z": 12,
      "name": "Soil_Dirt"
    },
    {
      "x": 4,
      "y": -2,
      "z": 12,
      "name": "Soil_Dirt"
    },
    {
      "x": 4,
      "y": -1,
      "z": 12,
      "name": "Rock_Stone_Cobble"
    },
    {
      "x": 4,
      "y": -6,
      "z": 13,
      "name": "Soil_Dirt"
    },
    {
      "x": 4,
      "y": -5,
      "z": 13,
      "name": "Soil_Dirt"
    },
    {
      "x": 4,
      "y": -4,
      "z": 13,
      "name": "Soil_Dirt"
    },
    {
      "x": 4,
      "y": -3,
      "z": 13,
      "name": "Soil_Dirt"
    },
    {
      "x": 4,
      "y": -2,
      "z": 13,
      "name": "Soil_Dirt"
    },
    {
      "x": 4,
      "y": -1,
      "z": 13,
      "name": "Rock_Stone_Cobble"
    },
    {
      "x": 4,
      "y": -6,
      "z": 14,
      "name": "Soil_Dirt"
    },
    {
      "x": 4,
      "y": -5,
      "z": 14,
      "name": "Soil_Dirt"
    },
    {
      "x": 4,
      "y": -4,
      "z": 14,
      "name": "Soil_Dirt"
    },
    {
      "x": 4,
      "y": -3,
      "z": 14,
      "name": "Soil_Dirt"
    },
    {
      "x": 4,
      "y": -2,
      "z": 14,
      "name": "Soil_Dirt"
    },
    {
      "x": 4,
      "y": -1,
      "z": 14,
      "name": "Rock_Stone_Cobble"
    },
    {
      "x": 4,
      "y": -6,
      "z": 15,
      "name": "Soil_Dirt"
    },
    {
      "x": 4,
      "y": -5,
      "z": 15,
      "name": "Soil_Dirt"
    },
    {
      "x": 4,
      "y": -4,
      "z": 15,
      "name": "Soil_Dirt"
    },
    {
      "x": 4,
      "y": -3,
      "z": 15,
      "name": "Soil_Dirt"
    },
    {
      "x": 4,
      "y": -2,
      "z": 15,
      "name": "Soil_Dirt"
    },
    {
      "x": 4,
      "y": -1,
      "z": 15,
      "name": "Rock_Stone_Cobble_Mossy"
    },
    {
      "x": 4,
      "y": -6,
      "z": 16,
      "name": "Soil_Dirt"
    },
    {
      "x": 4,
      "y": -5,
      "z": 16,
      "name": "Soil_Dirt"
    },
    {
      "x": 4,
      "y": -4,
      "z": 16,
      "name": "Soil_Dirt"
    },
    {
      "x": 4,
      "y": -3,
      "z": 16,
      "name": "Soil_Dirt"
    },
    {
      "x": 4,
      "y": -2,
      "z": 16,
      "name": "Soil_Dirt"
    },
    {
      "x": 4,
      "y": -1,
      "z": 16,
      "name": "Rock_Stone_Cobble"
    },
    {
      "x": 4,
      "y": -6,
      "z": 17,
      "name": "Soil_Dirt"
    },
    {
      "x": 4,
      "y": -5,
      "z": 17,
      "name": "Soil_Dirt"
    },
    {
      "x": 4,
      "y": -4,
      "z": 17,
      "name": "Soil_Dirt"
    },
    {
      "x": 4,
      "y": -3,
      "z": 17,
      "name": "Soil_Dirt"
    },
    {
      "x": 4,
      "y": -2,
      "z": 17,
      "name": "Soil_Dirt"
    },
    {
      "x": 4,
      "y": -1,
      "z": 17,
      "name": "Rock_Stone_Cobble"
    },
    {
      "x": 4,
      "y": -6,
      "z": 18,
      "name": "Soil_Dirt"
    },
    {
      "x": 4,
      "y": -5,
      "z": 18,
      "name": "Soil_Dirt"
    },
    {
      "x": 4,
      "y": -4,
      "z": 18,
      "name": "Soil_Dirt"
    },
    {
      "x": 4,
      "y": -3,
      "z": 18,
      "name": "Soil_Dirt"
    },
    {
      "x": 4,
      "y": -2,
      "z": 18,
      "name": "Soil_Dirt"
    },
    {
      "x": 4,
      "y": -1,
      "z": 18,
      "name": "Rock_Stone_Cobble_Mossy"
    },
    {
      "x": 4,
      "y": -6,
      "z": 19,
      "name": "Soil_Dirt"
    },
    {
      "x": 4,
      "y": -5,
      "z": 19,
      "name": "Soil_Dirt"
    },
    {
      "x": 4,
      "y": -4,
      "z": 19,
      "name": "Soil_Dirt"
    },
    {
      "x": 4,
      "y": -3,
      "z": 19,
      "name": "Soil_Dirt"
    },
    {
      "x": 4,
      "y": -2,
      "z": 19,
      "name": "Soil_Dirt"
    },
    {
      "x": 4,
      "y": -1,
      "z": 19,
      "name": "Rock_Stone_Cobble"
    },
    {
      "x": 4,
      "y": -6,
      "z": 20,
      "name": "Soil_Dirt"
    },
    {
      "x": 4,
      "y": -5,
      "z": 20,
      "name": "Soil_Dirt"
    },
    {
      "x": 4,
      "y": -4,
      "z": 20,
      "name": "Soil_Dirt"
    },
    {
      "x": 4,
      "y": -3,
      "z": 20,
      "name": "Soil_Dirt"
    },
    {
      "x": 4,
      "y": -2,
      "z": 20,
      "name": "Soil_Dirt"
    },
    {
      "x": 4,
      "y": -1,
      "z": 20,
      "name": "Rock_Stone_Cobble"
    },
    {
      "x": 4,
      "y": -6,
      "z": 21,
      "name": "Soil_Dirt"
    },
    {
      "x": 4,
      "y": -5,
      "z": 21,
      "name": "Soil_Dirt"
    },
    {
      "x": 4,
      "y": -4,
      "z": 21,
      "name": "Soil_Dirt"
    },
    {
      "x": 4,
      "y": -3,
      "z": 21,
      "name": "Soil_Dirt"
    },
    {
      "x": 4,
      "y": -2,
      "z": 21,
      "name": "Soil_Dirt"
    },
    {
      "x": 4,
      "y": -1,
      "z": 21,
      "name": "Rock_Stone_Cobble"
    },
    {
      "x": 4,
      "y": -6,
      "z": 22,
      "name": "Soil_Dirt"
    },
    {
      "x": 4,
      "y": -5,
      "z": 22,
      "name": "Soil_Dirt"
    },
    {
      "x": 4,
      "y": -4,
      "z": 22,
      "name": "Soil_Dirt"
    },
    {
      "x": 4,
      "y": -3,
      "z": 22,
      "name": "Soil_Dirt"
    },
    {
      "x": 4,
      "y": -2,
      "z": 22,
      "name": "Soil_Dirt"
    },
    {
      "x": 4,
      "y": -1,
      "z": 22,
      "name": "Rock_Stone_Cobble"
    },
    {
      "x": 4,
      "y": -6,
      "z": 23,
      "name": "Soil_Dirt"
    },
    {
      "x": 4,
      "y": -5,
      "z": 23,
      "name": "Soil_Dirt"
    },
    {
      "x": 4,
      "y": -4,
      "z": 23,
      "name": "Soil_Dirt"
    },
    {
      "x": 4,
      "y": -3,
      "z": 23,
      "name": "Soil_Dirt"
    },
    {
      "x": 4,
      "y": -2,
      "z": 23,
      "name": "Soil_Dirt"
    },
    {
      "x": 4,
      "y": -1,
      "z": 23,
      "name": "Rock_Stone_Cobble"
    },
    {
      "x": 4,
      "y": -6,
      "z": 24,
      "name": "Soil_Dirt"
    },
    {
      "x": 4,
      "y": -5,
      "z": 24,
      "name": "Soil_Dirt"
    },
    {
      "x": 4,
      "y": -4,
      "z": 24,
      "name": "Soil_Dirt"
    },
    {
      "x": 4,
      "y": -3,
      "z": 24,
      "name": "Soil_Dirt"
    },
    {
      "x": 4,
      "y": -2,
      "z": 24,
      "name": "Soil_Dirt"
    },
    {
      "x": 4,
      "y": -1,
      "z": 24,
      "name": "Rock_Stone_Cobble"
    },
    {
      "x": 4,
      "y": -6,
      "z": 25,
      "name": "Soil_Dirt"
    },
    {
      "x": 4,
      "y": -5,
      "z": 25,
      "name": "Soil_Dirt"
    },
    {
      "x": 4,
      "y": -4,
      "z": 25,
      "name": "Soil_Dirt"
    },
    {
      "x": 4,
      "y": -3,
      "z": 25,
      "name": "Soil_Dirt"
    },
    {
      "x": 4,
      "y": -2,
      "z": 25,
      "name": "Soil_Dirt"
    },
    {
      "x": 4,
      "y": -1,
      "z": 25,
      "name": "Rock_Stone_Cobble"
    },
    {
      "x": 4,
      "y": -6,
      "z": 26,
      "name": "Soil_Dirt"
    },
    {
      "x": 4,
      "y": -5,
      "z": 26,
      "name": "Soil_Dirt"
    },
    {
      "x": 4,
      "y": -4,
      "z": 26,
      "name": "Soil_Dirt"
    },
    {
      "x": 4,
      "y": -3,
      "z": 26,
      "name": "Soil_Dirt"
    },
    {
      "x": 4,
      "y": -2,
      "z": 26,
      "name": "Soil_Dirt"
    },
    {
      "x": 4,
      "y": -1,
      "z": 26,
      "name": "Rock_Stone_Cobble_Mossy"
    },
    {
      "x": 4,
      "y": 0,
      "z": 26,
      "name": "Rock_Stone_Brick_Stairs",
      "rotation": 34
    },
    {
      "x": 4,
      "y": -6,
      "z": 27,
      "name": "Soil_Dirt"
    },
    {
      "x": 4,
      "y": -5,
      "z": 27,
      "name": "Soil_Dirt"
    },
    {
      "x": 4,
      "y": -4,
      "z": 27,
      "name": "Soil_Dirt"
    },
    {
      "x": 4,
      "y": -3,
      "z": 27,
      "name": "Soil_Dirt"
    },
    {
      "x": 4,
      "y": -2,
      "z": 27,
      "name": "Soil_Dirt"
    },
    {
      "x": 4,
      "y": -1,
      "z": 27,
      "name": "Rock_Stone_Cobble"
    },
    {
      "x": 4,
      "y": 0,
      "z": 27,
      "name": "Rock_Stone_Brick_Smooth"
    },
    {
      "x": 4,
      "y": -6,
      "z": 28,
      "name": "Soil_Dirt"
    },
    {
      "x": 4,
      "y": -5,
      "z": 28,
      "name": "Soil_Dirt"
    },
    {
      "x": 4,
      "y": -4,
      "z": 28,
      "name": "Soil_Dirt"
    },
    {
      "x": 4,
      "y": -3,
      "z": 28,
      "name": "Soil_Dirt"
    },
    {
      "x": 4,
      "y": -2,
      "z": 28,
      "name": "Soil_Dirt"
    },
    {
      "x": 4,
      "y": -1,
      "z": 28,
      "name": "Rock_Stone_Cobble_Mossy"
    },
    {
      "x": 4,
      "y": 0,
      "z": 28,
      "name": "Rock_Stone_Brick_Smooth"
    },
    {
      "x": 4,
      "y": -6,
      "z": 29,
      "name": "Soil_Dirt"
    },
    {
      "x": 4,
      "y": -5,
      "z": 29,
      "name": "Soil_Dirt"
    },
    {
      "x": 4,
      "y": -4,
      "z": 29,
      "name": "Soil_Dirt"
    },
    {
      "x": 4,
      "y": -3,
      "z": 29,
      "name": "Soil_Dirt"
    },
    {
      "x": 4,
      "y": -2,
      "z": 29,
      "name": "Soil_Dirt"
    },
    {
      "x": 4,
      "y": -1,
      "z": 29,
      "name": "Rock_Stone_Cobble"
    },
    {
      "x": 4,
      "y": 0,
      "z": 29,
      "name": "Rock_Stone_Brick_Stairs",
      "rotation": 32
    },
    {
      "x": 4,
      "y": -6,
      "z": 30,
      "name": "Soil_Dirt"
    },
    {
      "x": 4,
      "y": -5,
      "z": 30,
      "name": "Soil_Dirt"
    },
    {
      "x": 4,
      "y": -4,
      "z": 30,
      "name": "Soil_Dirt"
    },
    {
      "x": 4,
      "y": -3,
      "z": 30,
      "name": "Soil_Dirt"
    },
    {
      "x": 4,
      "y": -2,
      "z": 30,
      "name": "Soil_Dirt"
    },
    {
      "x": 4,
      "y": -1,
      "z": 30,
      "name": "Rock_Stone_Brick_Smooth"
    },
    {
      "x": 5,
      "y": -6,
      "z": 1,
      "name": "Soil_Dirt"
    },
    {
      "x": 5,
      "y": -5,
      "z": 1,
      "name": "Soil_Dirt"
    },
    {
      "x": 5,
      "y": -4,
      "z": 1,
      "name": "Soil_Dirt"
    },
    {
      "x": 5,
      "y": -3,
      "z": 1,
      "name": "Soil_Dirt"
    },
    {
      "x": 5,
      "y": -2,
      "z": 1,
      "name": "Soil_Dirt"
    },
    {
      "x": 5,
      "y": -1,
      "z": 1,
      "name": "Rock_Stone_Brick_Smooth"
    },
    {
      "x": 5,
      "y": -6,
      "z": 2,
      "name": "Soil_Dirt"
    },
    {
      "x": 5,
      "y": -5,
      "z": 2,
      "name": "Soil_Dirt"
    },
    {
      "x": 5,
      "y": -4,
      "z": 2,
      "name": "Soil_Dirt"
    },
    {
      "x": 5,
      "y": -3,
      "z": 2,
      "name": "Soil_Dirt"
    },
    {
      "x": 5,
      "y": -2,
      "z": 2,
      "name": "Soil_Dirt"
    },
    {
      "x": 5,
      "y": -1,
      "z": 2,
      "name": "Rock_Stone_Cobble"
    },
    {
      "x": 5,
      "y": 0,
      "z": 2,
      "name": "Rock_Stone_Brick_Decorative",
      "rotation": 2
    },
    {
      "x": 5,
      "y": -6,
      "z": 3,
      "name": "Soil_Dirt"
    },
    {
      "x": 5,
      "y": -5,
      "z": 3,
      "name": "Soil_Dirt"
    },
    {
      "x": 5,
      "y": -4,
      "z": 3,
      "name": "Soil_Dirt"
    },
    {
      "x": 5,
      "y": -3,
      "z": 3,
      "name": "Soil_Dirt"
    },
    {
      "x": 5,
      "y": -2,
      "z": 3,
      "name": "Soil_Dirt"
    },
    {
      "x": 5,
      "y": -1,
      "z": 3,
      "name": "Rock_Stone_Cobble"
    },
    {
      "x": 5,
      "y": 0,
      "z": 3,
      "name": "Rock_Stone_Brick_Stairs",
      "rotation": 33
    },
    {
      "x": 5,
      "y": -6,
      "z": 4,
      "name": "Soil_Dirt"
    },
    {
      "x": 5,
      "y": -5,
      "z": 4,
      "name": "Soil_Dirt"
    },
    {
      "x": 5,
      "y": -4,
      "z": 4,
      "name": "Soil_Dirt"
    },
    {
      "x": 5,
      "y": -3,
      "z": 4,
      "name": "Soil_Dirt"
    },
    {
      "x": 5,
      "y": -2,
      "z": 4,
      "name": "Soil_Dirt"
    },
    {
      "x": 5,
      "y": -1,
      "z": 4,
      "name": "Rock_Stone_Cobble"
    },
    {
      "x": 5,
      "y": 0,
      "z": 4,
      "name": "Rock_Stone_Brick_Stairs",
      "rotation": 33
    },
    {
      "x": 5,
      "y": -6,
      "z": 5,
      "name": "Soil_Dirt"
    },
    {
      "x": 5,
      "y": -5,
      "z": 5,
      "name": "Soil_Dirt"
    },
    {
      "x": 5,
      "y": -4,
      "z": 5,
      "name": "Soil_Dirt"
    },
    {
      "x": 5,
      "y": -3,
      "z": 5,
      "name": "Soil_Dirt"
    },
    {
      "x": 5,
      "y": -2,
      "z": 5,
      "name": "Soil_Dirt"
    },
    {
      "x": 5,
      "y": -1,
      "z": 5,
      "name": "Rock_Stone_Cobble_Mossy"
    },
    {
      "x": 5,
      "y": 0,
      "z": 5,
      "name": "Rock_Stone_Brick_Decorative",
      "rotation": 2
    },
    {
      "x": 5,
      "y": -6,
      "z": 6,
      "name": "Soil_Dirt"
    },
    {
      "x": 5,
      "y": -5,
      "z": 6,
      "name": "Soil_Dirt"
    },
    {
      "x": 5,
      "y": -4,
      "z": 6,
      "name": "Soil_Dirt"
    },
    {
      "x": 5,
      "y": -3,
      "z": 6,
      "name": "Soil_Dirt"
    },
    {
      "x": 5,
      "y": -2,
      "z": 6,
      "name": "Soil_Dirt"
    },
    {
      "x": 5,
      "y": -1,
      "z": 6,
      "name": "Rock_Stone_Cobble"
    },
    {
      "x": 5,
      "y": -6,
      "z": 7,
      "name": "Soil_Dirt"
    },
    {
      "x": 5,
      "y": -5,
      "z": 7,
      "name": "Soil_Dirt"
    },
    {
      "x": 5,
      "y": -4,
      "z": 7,
      "name": "Soil_Dirt"
    },
    {
      "x": 5,
      "y": -3,
      "z": 7,
      "name": "Soil_Dirt"
    },
    {
      "x": 5,
      "y": -2,
      "z": 7,
      "name": "Soil_Dirt"
    },
    {
      "x": 5,
      "y": -1,
      "z": 7,
      "name": "Rock_Stone_Cobble"
    },
    {
      "x": 5,
      "y": -6,
      "z": 8,
      "name": "Soil_Dirt"
    },
    {
      "x": 5,
      "y": -5,
      "z": 8,
      "name": "Soil_Dirt"
    },
    {
      "x": 5,
      "y": -4,
      "z": 8,
      "name": "Soil_Dirt"
    },
    {
      "x": 5,
      "y": -3,
      "z": 8,
      "name": "Soil_Dirt"
    },
    {
      "x": 5,
      "y": -2,
      "z": 8,
      "name": "Soil_Dirt"
    },
    {
      "x": 5,
      "y": -1,
      "z": 8,
      "name": "Rock_Stone_Cobble"
    },
    {
      "x": 5,
      "y": -6,
      "z": 9,
      "name": "Soil_Dirt"
    },
    {
      "x": 5,
      "y": -5,
      "z": 9,
      "name": "Soil_Dirt"
    },
    {
      "x": 5,
      "y": -4,
      "z": 9,
      "name": "Soil_Dirt"
    },
    {
      "x": 5,
      "y": -3,
      "z": 9,
      "name": "Soil_Dirt"
    },
    {
      "x": 5,
      "y": -2,
      "z": 9,
      "name": "Soil_Dirt"
    },
    {
      "x": 5,
      "y": -1,
      "z": 9,
      "name": "Rock_Stone_Cobble"
    },
    {
      "x": 5,
      "y": -6,
      "z": 10,
      "name": "Soil_Dirt"
    },
    {
      "x": 5,
      "y": -5,
      "z": 10,
      "name": "Soil_Dirt"
    },
    {
      "x": 5,
      "y": -4,
      "z": 10,
      "name": "Soil_Dirt"
    },
    {
      "x": 5,
      "y": -3,
      "z": 10,
      "name": "Soil_Dirt"
    },
    {
      "x": 5,
      "y": -2,
      "z": 10,
      "name": "Soil_Dirt"
    },
    {
      "x": 5,
      "y": -1,
      "z": 10,
      "name": "Rock_Stone_Cobble"
    },
    {
      "x": 5,
      "y": -6,
      "z": 11,
      "name": "Soil_Dirt"
    },
    {
      "x": 5,
      "y": -5,
      "z": 11,
      "name": "Soil_Dirt"
    },
    {
      "x": 5,
      "y": -4,
      "z": 11,
      "name": "Soil_Dirt"
    },
    {
      "x": 5,
      "y": -3,
      "z": 11,
      "name": "Soil_Dirt"
    },
    {
      "x": 5,
      "y": -2,
      "z": 11,
      "name": "Soil_Dirt"
    },
    {
      "x": 5,
      "y": -1,
      "z": 11,
      "name": "Rock_Stone_Cobble"
    },
    {
      "x": 5,
      "y": -6,
      "z": 12,
      "name": "Soil_Dirt"
    },
    {
      "x": 5,
      "y": -5,
      "z": 12,
      "name": "Soil_Dirt"
    },
    {
      "x": 5,
      "y": -4,
      "z": 12,
      "name": "Soil_Dirt"
    },
    {
      "x": 5,
      "y": -3,
      "z": 12,
      "name": "Soil_Dirt"
    },
    {
      "x": 5,
      "y": -2,
      "z": 12,
      "name": "Soil_Dirt"
    },
    {
      "x": 5,
      "y": -1,
      "z": 12,
      "name": "Rock_Stone_Cobble"
    },
    {
      "x": 5,
      "y": -6,
      "z": 13,
      "name": "Soil_Dirt"
    },
    {
      "x": 5,
      "y": -5,
      "z": 13,
      "name": "Soil_Dirt"
    },
    {
      "x": 5,
      "y": -4,
      "z": 13,
      "name": "Soil_Dirt"
    },
    {
      "x": 5,
      "y": -3,
      "z": 13,
      "name": "Soil_Dirt"
    },
    {
      "x": 5,
      "y": -2,
      "z": 13,
      "name": "Soil_Dirt"
    },
    {
      "x": 5,
      "y": -1,
      "z": 13,
      "name": "Rock_Stone_Cobble"
    },
    {
      "x": 5,
      "y": -6,
      "z": 14,
      "name": "Soil_Dirt"
    },
    {
      "x": 5,
      "y": -5,
      "z": 14,
      "name": "Soil_Dirt"
    },
    {
      "x": 5,
      "y": -4,
      "z": 14,
      "name": "Soil_Dirt"
    },
    {
      "x": 5,
      "y": -3,
      "z": 14,
      "name": "Soil_Dirt"
    },
    {
      "x": 5,
      "y": -2,
      "z": 14,
      "name": "Soil_Dirt"
    },
    {
      "x": 5,
      "y": -1,
      "z": 14,
      "name": "Rock_Stone_Cobble"
    },
    {
      "x": 5,
      "y": -6,
      "z": 15,
      "name": "Soil_Dirt"
    },
    {
      "x": 5,
      "y": -5,
      "z": 15,
      "name": "Soil_Dirt"
    },
    {
      "x": 5,
      "y": -4,
      "z": 15,
      "name": "Soil_Dirt"
    },
    {
      "x": 5,
      "y": -3,
      "z": 15,
      "name": "Soil_Dirt"
    },
    {
      "x": 5,
      "y": -2,
      "z": 15,
      "name": "Soil_Dirt"
    },
    {
      "x": 5,
      "y": -1,
      "z": 15,
      "name": "Rock_Stone_Cobble_Mossy"
    },
    {
      "x": 5,
      "y": -6,
      "z": 16,
      "name": "Soil_Dirt"
    },
    {
      "x": 5,
      "y": -5,
      "z": 16,
      "name": "Soil_Dirt"
    },
    {
      "x": 5,
      "y": -4,
      "z": 16,
      "name": "Soil_Dirt"
    },
    {
      "x": 5,
      "y": -3,
      "z": 16,
      "name": "Soil_Dirt"
    },
    {
      "x": 5,
      "y": -2,
      "z": 16,
      "name": "Soil_Dirt"
    },
    {
      "x": 5,
      "y": -1,
      "z": 16,
      "name": "Rock_Stone_Cobble_Mossy"
    },
    {
      "x": 5,
      "y": -6,
      "z": 17,
      "name": "Soil_Dirt"
    },
    {
      "x": 5,
      "y": -5,
      "z": 17,
      "name": "Soil_Dirt"
    },
    {
      "x": 5,
      "y": -4,
      "z": 17,
      "name": "Soil_Dirt"
    },
    {
      "x": 5,
      "y": -3,
      "z": 17,
      "name": "Soil_Dirt"
    },
    {
      "x": 5,
      "y": -2,
      "z": 17,
      "name": "Soil_Dirt"
    },
    {
      "x": 5,
      "y": -1,
      "z": 17,
      "name": "Rock_Stone_Cobble"
    },
    {
      "x": 5,
      "y": -6,
      "z": 18,
      "name": "Soil_Dirt"
    },
    {
      "x": 5,
      "y": -5,
      "z": 18,
      "name": "Soil_Dirt"
    },
    {
      "x": 5,
      "y": -4,
      "z": 18,
      "name": "Soil_Dirt"
    },
    {
      "x": 5,
      "y": -3,
      "z": 18,
      "name": "Soil_Dirt"
    },
    {
      "x": 5,
      "y": -2,
      "z": 18,
      "name": "Soil_Dirt"
    },
    {
      "x": 5,
      "y": -1,
      "z": 18,
      "name": "Rock_Stone_Cobble"
    },
    {
      "x": 5,
      "y": -6,
      "z": 19,
      "name": "Soil_Dirt"
    },
    {
      "x": 5,
      "y": -5,
      "z": 19,
      "name": "Soil_Dirt"
    },
    {
      "x": 5,
      "y": -4,
      "z": 19,
      "name": "Soil_Dirt"
    },
    {
      "x": 5,
      "y": -3,
      "z": 19,
      "name": "Soil_Dirt"
    },
    {
      "x": 5,
      "y": -2,
      "z": 19,
      "name": "Soil_Dirt"
    },
    {
      "x": 5,
      "y": -1,
      "z": 19,
      "name": "Rock_Stone_Cobble"
    },
    {
      "x": 5,
      "y": -6,
      "z": 20,
      "name": "Soil_Dirt"
    },
    {
      "x": 5,
      "y": -5,
      "z": 20,
      "name": "Soil_Dirt"
    },
    {
      "x": 5,
      "y": -4,
      "z": 20,
      "name": "Soil_Dirt"
    },
    {
      "x": 5,
      "y": -3,
      "z": 20,
      "name": "Soil_Dirt"
    },
    {
      "x": 5,
      "y": -2,
      "z": 20,
      "name": "Soil_Dirt"
    },
    {
      "x": 5,
      "y": -1,
      "z": 20,
      "name": "Rock_Stone_Cobble_Mossy"
    },
    {
      "x": 5,
      "y": -6,
      "z": 21,
      "name": "Soil_Dirt"
    },
    {
      "x": 5,
      "y": -5,
      "z": 21,
      "name": "Soil_Dirt"
    },
    {
      "x": 5,
      "y": -4,
      "z": 21,
      "name": "Soil_Dirt"
    },
    {
      "x": 5,
      "y": -3,
      "z": 21,
      "name": "Soil_Dirt"
    },
    {
      "x": 5,
      "y": -2,
      "z": 21,
      "name": "Soil_Dirt"
    },
    {
      "x": 5,
      "y": -1,
      "z": 21,
      "name": "Rock_Stone_Cobble"
    },
    {
      "x": 5,
      "y": -6,
      "z": 22,
      "name": "Soil_Dirt"
    },
    {
      "x": 5,
      "y": -5,
      "z": 22,
      "name": "Soil_Dirt"
    },
    {
      "x": 5,
      "y": -4,
      "z": 22,
      "name": "Soil_Dirt"
    },
    {
      "x": 5,
      "y": -3,
      "z": 22,
      "name": "Soil_Dirt"
    },
    {
      "x": 5,
      "y": -2,
      "z": 22,
      "name": "Soil_Dirt"
    },
    {
      "x": 5,
      "y": -1,
      "z": 22,
      "name": "Rock_Stone_Cobble"
    },
    {
      "x": 5,
      "y": -6,
      "z": 23,
      "name": "Soil_Dirt"
    },
    {
      "x": 5,
      "y": -5,
      "z": 23,
      "name": "Soil_Dirt"
    },
    {
      "x": 5,
      "y": -4,
      "z": 23,
      "name": "Soil_Dirt"
    },
    {
      "x": 5,
      "y": -3,
      "z": 23,
      "name": "Soil_Dirt"
    },
    {
      "x": 5,
      "y": -2,
      "z": 23,
      "name": "Soil_Dirt"
    },
    {
      "x": 5,
      "y": -1,
      "z": 23,
      "name": "Rock_Stone_Cobble",
      "support": 15
    },
    {
      "x": 5,
      "y": -6,
      "z": 24,
      "name": "Soil_Dirt"
    },
    {
      "x": 5,
      "y": -5,
      "z": 24,
      "name": "Soil_Dirt"
    },
    {
      "x": 5,
      "y": -4,
      "z": 24,
      "name": "Soil_Dirt"
    },
    {
      "x": 5,
      "y": -3,
      "z": 24,
      "name": "Soil_Dirt"
    },
    {
      "x": 5,
      "y": -2,
      "z": 24,
      "name": "Soil_Dirt"
    },
    {
      "x": 5,
      "y": -1,
      "z": 24,
      "name": "Rock_Stone_Cobble",
      "support": 15
    },
    {
      "x": 5,
      "y": -6,
      "z": 25,
      "name": "Soil_Dirt"
    },
    {
      "x": 5,
      "y": -5,
      "z": 25,
      "name": "Soil_Dirt"
    },
    {
      "x": 5,
      "y": -4,
      "z": 25,
      "name": "Soil_Dirt"
    },
    {
      "x": 5,
      "y": -3,
      "z": 25,
      "name": "Soil_Dirt"
    },
    {
      "x": 5,
      "y": -2,
      "z": 25,
      "name": "Soil_Dirt"
    },
    {
      "x": 5,
      "y": -1,
      "z": 25,
      "name": "Rock_Stone_Cobble"
    },
    {
      "x": 5,
      "y": -6,
      "z": 26,
      "name": "Soil_Dirt"
    },
    {
      "x": 5,
      "y": -5,
      "z": 26,
      "name": "Soil_Dirt"
    },
    {
      "x": 5,
      "y": -4,
      "z": 26,
      "name": "Soil_Dirt"
    },
    {
      "x": 5,
      "y": -3,
      "z": 26,
      "name": "Soil_Dirt"
    },
    {
      "x": 5,
      "y": -2,
      "z": 26,
      "name": "Soil_Dirt"
    },
    {
      "x": 5,
      "y": -1,
      "z": 26,
      "name": "Rock_Stone_Cobble_Mossy"
    },
    {
      "x": 5,
      "y": 0,
      "z": 26,
      "name": "Rock_Stone_Brick_Decorative",
      "rotation": 3
    },
    {
      "x": 5,
      "y": -6,
      "z": 27,
      "name": "Soil_Dirt"
    },
    {
      "x": 5,
      "y": -5,
      "z": 27,
      "name": "Soil_Dirt"
    },
    {
      "x": 5,
      "y": -4,
      "z": 27,
      "name": "Soil_Dirt"
    },
    {
      "x": 5,
      "y": -3,
      "z": 27,
      "name": "Soil_Dirt"
    },
    {
      "x": 5,
      "y": -2,
      "z": 27,
      "name": "Soil_Dirt"
    },
    {
      "x": 5,
      "y": -1,
      "z": 27,
      "name": "Rock_Stone_Cobble"
    },
    {
      "x": 5,
      "y": 0,
      "z": 27,
      "name": "Rock_Stone_Brick_Stairs",
      "rotation": 33
    },
    {
      "x": 5,
      "y": -6,
      "z": 28,
      "name": "Soil_Dirt"
    },
    {
      "x": 5,
      "y": -5,
      "z": 28,
      "name": "Soil_Dirt"
    },
    {
      "x": 5,
      "y": -4,
      "z": 28,
      "name": "Soil_Dirt"
    },
    {
      "x": 5,
      "y": -3,
      "z": 28,
      "name": "Soil_Dirt"
    },
    {
      "x": 5,
      "y": -2,
      "z": 28,
      "name": "Soil_Dirt"
    },
    {
      "x": 5,
      "y": -1,
      "z": 28,
      "name": "Rock_Stone_Cobble_Mossy"
    },
    {
      "x": 5,
      "y": 0,
      "z": 28,
      "name": "Rock_Stone_Brick_Stairs",
      "rotation": 33
    },
    {
      "x": 5,
      "y": -6,
      "z": 29,
      "name": "Soil_Dirt"
    },
    {
      "x": 5,
      "y": -5,
      "z": 29,
      "name": "Soil_Dirt"
    },
    {
      "x": 5,
      "y": -4,
      "z": 29,
      "name": "Soil_Dirt"
    },
    {
      "x": 5,
      "y": -3,
      "z": 29,
      "name": "Soil_Dirt"
    },
    {
      "x": 5,
      "y": -2,
      "z": 29,
      "name": "Soil_Dirt"
    },
    {
      "x": 5,
      "y": -1,
      "z": 29,
      "name": "Rock_Stone_Cobble_Mossy"
    },
    {
      "x": 5,
      "y": 0,
      "z": 29,
      "name": "Rock_Stone_Brick_Decorative",
      "rotation": 3
    },
    {
      "x": 5,
      "y": -6,
      "z": 30,
      "name": "Soil_Dirt"
    },
    {
      "x": 5,
      "y": -5,
      "z": 30,
      "name": "Soil_Dirt"
    },
    {
      "x": 5,
      "y": -4,
      "z": 30,
      "name": "Soil_Dirt"
    },
    {
      "x": 5,
      "y": -3,
      "z": 30,
      "name": "Soil_Dirt"
    },
    {
      "x": 5,
      "y": -2,
      "z": 30,
      "name": "Soil_Dirt"
    },
    {
      "x": 5,
      "y": -1,
      "z": 30,
      "name": "Rock_Stone_Brick_Smooth"
    },
    {
      "x": 6,
      "y": -6,
      "z": 1,
      "name": "Soil_Dirt"
    },
    {
      "x": 6,
      "y": -5,
      "z": 1,
      "name": "Soil_Dirt"
    },
    {
      "x": 6,
      "y": -4,
      "z": 1,
      "name": "Soil_Dirt"
    },
    {
      "x": 6,
      "y": -3,
      "z": 1,
      "name": "Soil_Dirt"
    },
    {
      "x": 6,
      "y": -2,
      "z": 1,
      "name": "Soil_Dirt"
    },
    {
      "x": 6,
      "y": -1,
      "z": 1,
      "name": "Rock_Stone_Brick_Smooth"
    },
    {
      "x": 6,
      "y": -6,
      "z": 2,
      "name": "Soil_Dirt"
    },
    {
      "x": 6,
      "y": -5,
      "z": 2,
      "name": "Soil_Dirt"
    },
    {
      "x": 6,
      "y": -4,
      "z": 2,
      "name": "Soil_Dirt"
    },
    {
      "x": 6,
      "y": -3,
      "z": 2,
      "name": "Soil_Dirt"
    },
    {
      "x": 6,
      "y": -2,
      "z": 2,
      "name": "Soil_Dirt"
    },
    {
      "x": 6,
      "y": -1,
      "z": 2,
      "name": "Rock_Stone_Cobble"
    },
    {
      "x": 6,
      "y": -6,
      "z": 3,
      "name": "Soil_Dirt"
    },
    {
      "x": 6,
      "y": -5,
      "z": 3,
      "name": "Soil_Dirt"
    },
    {
      "x": 6,
      "y": -4,
      "z": 3,
      "name": "Soil_Dirt"
    },
    {
      "x": 6,
      "y": -3,
      "z": 3,
      "name": "Soil_Dirt"
    },
    {
      "x": 6,
      "y": -2,
      "z": 3,
      "name": "Soil_Dirt"
    },
    {
      "x": 6,
      "y": -1,
      "z": 3,
      "name": "Rock_Stone_Cobble"
    },
    {
      "x": 6,
      "y": -6,
      "z": 4,
      "name": "Soil_Dirt"
    },
    {
      "x": 6,
      "y": -5,
      "z": 4,
      "name": "Soil_Dirt"
    },
    {
      "x": 6,
      "y": -4,
      "z": 4,
      "name": "Soil_Dirt"
    },
    {
      "x": 6,
      "y": -3,
      "z": 4,
      "name": "Soil_Dirt"
    },
    {
      "x": 6,
      "y": -2,
      "z": 4,
      "name": "Soil_Dirt"
    },
    {
      "x": 6,
      "y": -1,
      "z": 4,
      "name": "Rock_Stone_Cobble"
    },
    {
      "x": 6,
      "y": -6,
      "z": 5,
      "name": "Soil_Dirt"
    },
    {
      "x": 6,
      "y": -5,
      "z": 5,
      "name": "Soil_Dirt"
    },
    {
      "x": 6,
      "y": -4,
      "z": 5,
      "name": "Soil_Dirt"
    },
    {
      "x": 6,
      "y": -3,
      "z": 5,
      "name": "Soil_Dirt"
    },
    {
      "x": 6,
      "y": -2,
      "z": 5,
      "name": "Soil_Dirt"
    },
    {
      "x": 6,
      "y": -1,
      "z": 5,
      "name": "Rock_Stone_Cobble"
    },
    {
      "x": 6,
      "y": -6,
      "z": 6,
      "name": "Soil_Dirt"
    },
    {
      "x": 6,
      "y": -5,
      "z": 6,
      "name": "Soil_Dirt"
    },
    {
      "x": 6,
      "y": -4,
      "z": 6,
      "name": "Soil_Dirt"
    },
    {
      "x": 6,
      "y": -3,
      "z": 6,
      "name": "Soil_Dirt"
    },
    {
      "x": 6,
      "y": -2,
      "z": 6,
      "name": "Soil_Dirt"
    },
    {
      "x": 6,
      "y": -1,
      "z": 6,
      "name": "Rock_Stone_Cobble"
    },
    {
      "x": 6,
      "y": -6,
      "z": 7,
      "name": "Soil_Dirt"
    },
    {
      "x": 6,
      "y": -5,
      "z": 7,
      "name": "Soil_Dirt"
    },
    {
      "x": 6,
      "y": -4,
      "z": 7,
      "name": "Soil_Dirt"
    },
    {
      "x": 6,
      "y": -3,
      "z": 7,
      "name": "Soil_Dirt"
    },
    {
      "x": 6,
      "y": -2,
      "z": 7,
      "name": "Soil_Dirt"
    },
    {
      "x": 6,
      "y": -1,
      "z": 7,
      "name": "Rock_Stone_Cobble"
    },
    {
      "x": 6,
      "y": -6,
      "z": 8,
      "name": "Soil_Dirt"
    },
    {
      "x": 6,
      "y": -5,
      "z": 8,
      "name": "Soil_Dirt"
    },
    {
      "x": 6,
      "y": -4,
      "z": 8,
      "name": "Soil_Dirt"
    },
    {
      "x": 6,
      "y": -3,
      "z": 8,
      "name": "Soil_Dirt"
    },
    {
      "x": 6,
      "y": -2,
      "z": 8,
      "name": "Soil_Dirt"
    },
    {
      "x": 6,
      "y": -1,
      "z": 8,
      "name": "Rock_Stone_Cobble"
    },
    {
      "x": 6,
      "y": -6,
      "z": 9,
      "name": "Soil_Dirt"
    },
    {
      "x": 6,
      "y": -5,
      "z": 9,
      "name": "Soil_Dirt"
    },
    {
      "x": 6,
      "y": -4,
      "z": 9,
      "name": "Soil_Dirt"
    },
    {
      "x": 6,
      "y": -3,
      "z": 9,
      "name": "Soil_Dirt"
    },
    {
      "x": 6,
      "y": -2,
      "z": 9,
      "name": "Soil_Dirt"
    },
    {
      "x": 6,
      "y": -1,
      "z": 9,
      "name": "Rock_Stone_Cobble"
    },
    {
      "x": 6,
      "y": -6,
      "z": 10,
      "name": "Soil_Dirt"
    },
    {
      "x": 6,
      "y": -5,
      "z": 10,
      "name": "Soil_Dirt"
    },
    {
      "x": 6,
      "y": -4,
      "z": 10,
      "name": "Soil_Dirt"
    },
    {
      "x": 6,
      "y": -3,
      "z": 10,
      "name": "Soil_Dirt"
    },
    {
      "x": 6,
      "y": -2,
      "z": 10,
      "name": "Soil_Dirt"
    },
    {
      "x": 6,
      "y": -1,
      "z": 10,
      "name": "Rock_Stone_Cobble"
    },
    {
      "x": 6,
      "y": -6,
      "z": 11,
      "name": "Soil_Dirt"
    },
    {
      "x": 6,
      "y": -5,
      "z": 11,
      "name": "Soil_Dirt"
    },
    {
      "x": 6,
      "y": -4,
      "z": 11,
      "name": "Soil_Dirt"
    },
    {
      "x": 6,
      "y": -3,
      "z": 11,
      "name": "Soil_Dirt"
    },
    {
      "x": 6,
      "y": -2,
      "z": 11,
      "name": "Soil_Dirt"
    },
    {
      "x": 6,
      "y": -1,
      "z": 11,
      "name": "Rock_Stone_Cobble"
    },
    {
      "x": 6,
      "y": -6,
      "z": 12,
      "name": "Soil_Dirt"
    },
    {
      "x": 6,
      "y": -5,
      "z": 12,
      "name": "Soil_Dirt"
    },
    {
      "x": 6,
      "y": -4,
      "z": 12,
      "name": "Soil_Dirt"
    },
    {
      "x": 6,
      "y": -3,
      "z": 12,
      "name": "Soil_Dirt"
    },
    {
      "x": 6,
      "y": -2,
      "z": 12,
      "name": "Soil_Dirt"
    },
    {
      "x": 6,
      "y": -1,
      "z": 12,
      "name": "Rock_Stone_Cobble"
    },
    {
      "x": 6,
      "y": -6,
      "z": 13,
      "name": "Soil_Dirt"
    },
    {
      "x": 6,
      "y": -5,
      "z": 13,
      "name": "Soil_Dirt"
    },
    {
      "x": 6,
      "y": -4,
      "z": 13,
      "name": "Soil_Dirt"
    },
    {
      "x": 6,
      "y": -3,
      "z": 13,
      "name": "Soil_Dirt"
    },
    {
      "x": 6,
      "y": -2,
      "z": 13,
      "name": "Soil_Dirt"
    },
    {
      "x": 6,
      "y": -1,
      "z": 13,
      "name": "Rock_Stone_Brick_Decorative",
      "support": 15
    },
    {
      "x": 6,
      "y": -6,
      "z": 14,
      "name": "Soil_Dirt"
    },
    {
      "x": 6,
      "y": -5,
      "z": 14,
      "name": "Soil_Dirt"
    },
    {
      "x": 6,
      "y": -4,
      "z": 14,
      "name": "Soil_Dirt"
    },
    {
      "x": 6,
      "y": -3,
      "z": 14,
      "name": "Soil_Dirt"
    },
    {
      "x": 6,
      "y": -2,
      "z": 14,
      "name": "Soil_Dirt"
    },
    {
      "x": 6,
      "y": -1,
      "z": 14,
      "name": "Rock_Stone_Brick_Decorative",
      "support": 15
    },
    {
      "x": 6,
      "y": -6,
      "z": 15,
      "name": "Soil_Dirt"
    },
    {
      "x": 6,
      "y": -5,
      "z": 15,
      "name": "Soil_Dirt"
    },
    {
      "x": 6,
      "y": -4,
      "z": 15,
      "name": "Soil_Dirt"
    },
    {
      "x": 6,
      "y": -3,
      "z": 15,
      "name": "Soil_Dirt"
    },
    {
      "x": 6,
      "y": -2,
      "z": 15,
      "name": "Soil_Dirt"
    },
    {
      "x": 6,
      "y": -1,
      "z": 15,
      "name": "Rock_Stone_Brick_Decorative",
      "support": 15
    },
    {
      "x": 6,
      "y": -6,
      "z": 16,
      "name": "Soil_Dirt"
    },
    {
      "x": 6,
      "y": -5,
      "z": 16,
      "name": "Soil_Dirt"
    },
    {
      "x": 6,
      "y": -4,
      "z": 16,
      "name": "Soil_Dirt"
    },
    {
      "x": 6,
      "y": -3,
      "z": 16,
      "name": "Soil_Dirt"
    },
    {
      "x": 6,
      "y": -2,
      "z": 16,
      "name": "Soil_Dirt"
    },
    {
      "x": 6,
      "y": -1,
      "z": 16,
      "name": "Rock_Stone_Brick_Decorative",
      "support": 15
    },
    {
      "x": 6,
      "y": -6,
      "z": 17,
      "name": "Soil_Dirt"
    },
    {
      "x": 6,
      "y": -5,
      "z": 17,
      "name": "Soil_Dirt"
    },
    {
      "x": 6,
      "y": -4,
      "z": 17,
      "name": "Soil_Dirt"
    },
    {
      "x": 6,
      "y": -3,
      "z": 17,
      "name": "Soil_Dirt"
    },
    {
      "x": 6,
      "y": -2,
      "z": 17,
      "name": "Soil_Dirt"
    },
    {
      "x": 6,
      "y": -1,
      "z": 17,
      "name": "Rock_Stone_Brick_Decorative",
      "support": 15
    },
    {
      "x": 6,
      "y": -6,
      "z": 18,
      "name": "Soil_Dirt"
    },
    {
      "x": 6,
      "y": -5,
      "z": 18,
      "name": "Soil_Dirt"
    },
    {
      "x": 6,
      "y": -4,
      "z": 18,
      "name": "Soil_Dirt"
    },
    {
      "x": 6,
      "y": -3,
      "z": 18,
      "name": "Soil_Dirt"
    },
    {
      "x": 6,
      "y": -2,
      "z": 18,
      "name": "Soil_Dirt"
    },
    {
      "x": 6,
      "y": -1,
      "z": 18,
      "name": "Rock_Stone_Brick_Decorative",
      "support": 15
    },
    {
      "x": 6,
      "y": -6,
      "z": 19,
      "name": "Soil_Dirt"
    },
    {
      "x": 6,
      "y": -5,
      "z": 19,
      "name": "Soil_Dirt"
    },
    {
      "x": 6,
      "y": -4,
      "z": 19,
      "name": "Soil_Dirt"
    },
    {
      "x": 6,
      "y": -3,
      "z": 19,
      "name": "Soil_Dirt"
    },
    {
      "x": 6,
      "y": -2,
      "z": 19,
      "name": "Soil_Dirt"
    },
    {
      "x": 6,
      "y": -1,
      "z": 19,
      "name": "Rock_Stone_Cobble"
    },
    {
      "x": 6,
      "y": -6,
      "z": 20,
      "name": "Soil_Dirt"
    },
    {
      "x": 6,
      "y": -5,
      "z": 20,
      "name": "Soil_Dirt"
    },
    {
      "x": 6,
      "y": -4,
      "z": 20,
      "name": "Soil_Dirt"
    },
    {
      "x": 6,
      "y": -3,
      "z": 20,
      "name": "Soil_Dirt"
    },
    {
      "x": 6,
      "y": -2,
      "z": 20,
      "name": "Soil_Dirt"
    },
    {
      "x": 6,
      "y": -1,
      "z": 20,
      "name": "Rock_Stone_Cobble"
    },
    {
      "x": 6,
      "y": -6,
      "z": 21,
      "name": "Soil_Dirt"
    },
    {
      "x": 6,
      "y": -5,
      "z": 21,
      "name": "Soil_Dirt"
    },
    {
      "x": 6,
      "y": -4,
      "z": 21,
      "name": "Soil_Dirt"
    },
    {
      "x": 6,
      "y": -3,
      "z": 21,
      "name": "Soil_Dirt"
    },
    {
      "x": 6,
      "y": -2,
      "z": 21,
      "name": "Soil_Dirt"
    },
    {
      "x": 6,
      "y": -1,
      "z": 21,
      "name": "Rock_Stone_Cobble"
    },
    {
      "x": 6,
      "y": -6,
      "z": 22,
      "name": "Soil_Dirt"
    },
    {
      "x": 6,
      "y": -5,
      "z": 22,
      "name": "Soil_Dirt"
    },
    {
      "x": 6,
      "y": -4,
      "z": 22,
      "name": "Soil_Dirt"
    },
    {
      "x": 6,
      "y": -3,
      "z": 22,
      "name": "Soil_Dirt"
    },
    {
      "x": 6,
      "y": -2,
      "z": 22,
      "name": "Soil_Dirt"
    },
    {
      "x": 6,
      "y": -1,
      "z": 22,
      "name": "Rock_Stone_Cobble"
    },
    {
      "x": 6,
      "y": -6,
      "z": 23,
      "name": "Soil_Dirt"
    },
    {
      "x": 6,
      "y": -5,
      "z": 23,
      "name": "Soil_Dirt"
    },
    {
      "x": 6,
      "y": -4,
      "z": 23,
      "name": "Soil_Dirt"
    },
    {
      "x": 6,
      "y": -3,
      "z": 23,
      "name": "Soil_Dirt"
    },
    {
      "x": 6,
      "y": -2,
      "z": 23,
      "name": "Soil_Dirt"
    },
    {
      "x": 6,
      "y": -1,
      "z": 23,
      "name": "Rock_Stone_Cobble"
    },
    {
      "x": 6,
      "y": -6,
      "z": 24,
      "name": "Soil_Dirt"
    },
    {
      "x": 6,
      "y": -5,
      "z": 24,
      "name": "Soil_Dirt"
    },
    {
      "x": 6,
      "y": -4,
      "z": 24,
      "name": "Soil_Dirt"
    },
    {
      "x": 6,
      "y": -3,
      "z": 24,
      "name": "Soil_Dirt"
    },
    {
      "x": 6,
      "y": -2,
      "z": 24,
      "name": "Soil_Dirt"
    },
    {
      "x": 6,
      "y": -1,
      "z": 24,
      "name": "Rock_Stone_Cobble"
    },
    {
      "x": 6,
      "y": -6,
      "z": 25,
      "name": "Soil_Dirt"
    },
    {
      "x": 6,
      "y": -5,
      "z": 25,
      "name": "Soil_Dirt"
    },
    {
      "x": 6,
      "y": -4,
      "z": 25,
      "name": "Soil_Dirt"
    },
    {
      "x": 6,
      "y": -3,
      "z": 25,
      "name": "Soil_Dirt"
    },
    {
      "x": 6,
      "y": -2,
      "z": 25,
      "name": "Soil_Dirt"
    },
    {
      "x": 6,
      "y": -1,
      "z": 25,
      "name": "Rock_Stone_Cobble"
    },
    {
      "x": 6,
      "y": -6,
      "z": 26,
      "name": "Soil_Dirt"
    },
    {
      "x": 6,
      "y": -5,
      "z": 26,
      "name": "Soil_Dirt"
    },
    {
      "x": 6,
      "y": -4,
      "z": 26,
      "name": "Soil_Dirt"
    },
    {
      "x": 6,
      "y": -3,
      "z": 26,
      "name": "Soil_Dirt"
    },
    {
      "x": 6,
      "y": -2,
      "z": 26,
      "name": "Soil_Dirt"
    },
    {
      "x": 6,
      "y": -1,
      "z": 26,
      "name": "Rock_Stone_Cobble"
    },
    {
      "x": 6,
      "y": -6,
      "z": 27,
      "name": "Soil_Dirt"
    },
    {
      "x": 6,
      "y": -5,
      "z": 27,
      "name": "Soil_Dirt"
    },
    {
      "x": 6,
      "y": -4,
      "z": 27,
      "name": "Soil_Dirt"
    },
    {
      "x": 6,
      "y": -3,
      "z": 27,
      "name": "Soil_Dirt"
    },
    {
      "x": 6,
      "y": -2,
      "z": 27,
      "name": "Soil_Dirt"
    },
    {
      "x": 6,
      "y": -1,
      "z": 27,
      "name": "Rock_Stone_Cobble"
    },
    {
      "x": 6,
      "y": -6,
      "z": 28,
      "name": "Soil_Dirt"
    },
    {
      "x": 6,
      "y": -5,
      "z": 28,
      "name": "Soil_Dirt"
    },
    {
      "x": 6,
      "y": -4,
      "z": 28,
      "name": "Soil_Dirt"
    },
    {
      "x": 6,
      "y": -3,
      "z": 28,
      "name": "Soil_Dirt"
    },
    {
      "x": 6,
      "y": -2,
      "z": 28,
      "name": "Soil_Dirt"
    },
    {
      "x": 6,
      "y": -1,
      "z": 28,
      "name": "Rock_Stone_Cobble"
    },
    {
      "x": 6,
      "y": -6,
      "z": 29,
      "name": "Soil_Dirt"
    },
    {
      "x": 6,
      "y": -5,
      "z": 29,
      "name": "Soil_Dirt"
    },
    {
      "x": 6,
      "y": -4,
      "z": 29,
      "name": "Soil_Dirt"
    },
    {
      "x": 6,
      "y": -3,
      "z": 29,
      "name": "Soil_Dirt"
    },
    {
      "x": 6,
      "y": -2,
      "z": 29,
      "name": "Soil_Dirt"
    },
    {
      "x": 6,
      "y": -1,
      "z": 29,
      "name": "Rock_Stone_Cobble"
    },
    {
      "x": 6,
      "y": -6,
      "z": 30,
      "name": "Soil_Dirt"
    },
    {
      "x": 6,
      "y": -5,
      "z": 30,
      "name": "Soil_Dirt"
    },
    {
      "x": 6,
      "y": -4,
      "z": 30,
      "name": "Soil_Dirt"
    },
    {
      "x": 6,
      "y": -3,
      "z": 30,
      "name": "Soil_Dirt"
    },
    {
      "x": 6,
      "y": -2,
      "z": 30,
      "name": "Soil_Dirt"
    },
    {
      "x": 6,
      "y": -1,
      "z": 30,
      "name": "Rock_Stone_Brick_Smooth"
    },
    {
      "x": 7,
      "y": -6,
      "z": 1,
      "name": "Soil_Dirt"
    },
    {
      "x": 7,
      "y": -5,
      "z": 1,
      "name": "Soil_Dirt"
    },
    {
      "x": 7,
      "y": -4,
      "z": 1,
      "name": "Soil_Dirt"
    },
    {
      "x": 7,
      "y": -3,
      "z": 1,
      "name": "Soil_Dirt"
    },
    {
      "x": 7,
      "y": -2,
      "z": 1,
      "name": "Soil_Dirt"
    },
    {
      "x": 7,
      "y": -1,
      "z": 1,
      "name": "Rock_Stone_Brick_Smooth"
    },
    {
      "x": 7,
      "y": -6,
      "z": 2,
      "name": "Soil_Dirt"
    },
    {
      "x": 7,
      "y": -5,
      "z": 2,
      "name": "Soil_Dirt"
    },
    {
      "x": 7,
      "y": -4,
      "z": 2,
      "name": "Soil_Dirt"
    },
    {
      "x": 7,
      "y": -3,
      "z": 2,
      "name": "Soil_Dirt"
    },
    {
      "x": 7,
      "y": -2,
      "z": 2,
      "name": "Soil_Dirt"
    },
    {
      "x": 7,
      "y": -1,
      "z": 2,
      "name": "Rock_Stone_Cobble"
    },
    {
      "x": 7,
      "y": -6,
      "z": 3,
      "name": "Soil_Dirt"
    },
    {
      "x": 7,
      "y": -5,
      "z": 3,
      "name": "Soil_Dirt"
    },
    {
      "x": 7,
      "y": -4,
      "z": 3,
      "name": "Soil_Dirt"
    },
    {
      "x": 7,
      "y": -3,
      "z": 3,
      "name": "Soil_Dirt"
    },
    {
      "x": 7,
      "y": -2,
      "z": 3,
      "name": "Soil_Dirt"
    },
    {
      "x": 7,
      "y": -1,
      "z": 3,
      "name": "Rock_Stone_Cobble"
    },
    {
      "x": 7,
      "y": -6,
      "z": 4,
      "name": "Soil_Dirt"
    },
    {
      "x": 7,
      "y": -5,
      "z": 4,
      "name": "Soil_Dirt"
    },
    {
      "x": 7,
      "y": -4,
      "z": 4,
      "name": "Soil_Dirt"
    },
    {
      "x": 7,
      "y": -3,
      "z": 4,
      "name": "Soil_Dirt"
    },
    {
      "x": 7,
      "y": -2,
      "z": 4,
      "name": "Soil_Dirt"
    },
    {
      "x": 7,
      "y": -1,
      "z": 4,
      "name": "Rock_Stone_Cobble_Mossy"
    },
    {
      "x": 7,
      "y": -6,
      "z": 5,
      "name": "Soil_Dirt"
    },
    {
      "x": 7,
      "y": -5,
      "z": 5,
      "name": "Soil_Dirt"
    },
    {
      "x": 7,
      "y": -4,
      "z": 5,
      "name": "Soil_Dirt"
    },
    {
      "x": 7,
      "y": -3,
      "z": 5,
      "name": "Soil_Dirt"
    },
    {
      "x": 7,
      "y": -2,
      "z": 5,
      "name": "Soil_Dirt"
    },
    {
      "x": 7,
      "y": -1,
      "z": 5,
      "name": "Rock_Stone_Cobble"
    },
    {
      "x": 7,
      "y": -6,
      "z": 6,
      "name": "Soil_Dirt"
    },
    {
      "x": 7,
      "y": -5,
      "z": 6,
      "name": "Soil_Dirt"
    },
    {
      "x": 7,
      "y": -4,
      "z": 6,
      "name": "Soil_Dirt"
    },
    {
      "x": 7,
      "y": -3,
      "z": 6,
      "name": "Soil_Dirt"
    },
    {
      "x": 7,
      "y": -2,
      "z": 6,
      "name": "Soil_Dirt"
    },
    {
      "x": 7,
      "y": -1,
      "z": 6,
      "name": "Rock_Stone_Cobble_Mossy"
    },
    {
      "x": 7,
      "y": -6,
      "z": 7,
      "name": "Soil_Dirt"
    },
    {
      "x": 7,
      "y": -5,
      "z": 7,
      "name": "Soil_Dirt"
    },
    {
      "x": 7,
      "y": -4,
      "z": 7,
      "name": "Soil_Dirt"
    },
    {
      "x": 7,
      "y": -3,
      "z": 7,
      "name": "Soil_Dirt"
    },
    {
      "x": 7,
      "y": -2,
      "z": 7,
      "name": "Soil_Dirt"
    },
    {
      "x": 7,
      "y": -1,
      "z": 7,
      "name": "Rock_Stone_Cobble"
    },
    {
      "x": 7,
      "y": -6,
      "z": 8,
      "name": "Soil_Dirt"
    },
    {
      "x": 7,
      "y": -5,
      "z": 8,
      "name": "Soil_Dirt"
    },
    {
      "x": 7,
      "y": -4,
      "z": 8,
      "name": "Soil_Dirt"
    },
    {
      "x": 7,
      "y": -3,
      "z": 8,
      "name": "Soil_Dirt"
    },
    {
      "x": 7,
      "y": -2,
      "z": 8,
      "name": "Soil_Dirt"
    },
    {
      "x": 7,
      "y": -1,
      "z": 8,
      "name": "Rock_Stone_Cobble"
    },
    {
      "x": 7,
      "y": -6,
      "z": 9,
      "name": "Soil_Dirt"
    },
    {
      "x": 7,
      "y": -5,
      "z": 9,
      "name": "Soil_Dirt"
    },
    {
      "x": 7,
      "y": -4,
      "z": 9,
      "name": "Soil_Dirt"
    },
    {
      "x": 7,
      "y": -3,
      "z": 9,
      "name": "Soil_Dirt"
    },
    {
      "x": 7,
      "y": -2,
      "z": 9,
      "name": "Soil_Dirt"
    },
    {
      "x": 7,
      "y": -1,
      "z": 9,
      "name": "Rock_Stone_Cobble"
    },
    {
      "x": 7,
      "y": -6,
      "z": 10,
      "name": "Soil_Dirt"
    },
    {
      "x": 7,
      "y": -5,
      "z": 10,
      "name": "Soil_Dirt"
    },
    {
      "x": 7,
      "y": -4,
      "z": 10,
      "name": "Soil_Dirt"
    },
    {
      "x": 7,
      "y": -3,
      "z": 10,
      "name": "Soil_Dirt"
    },
    {
      "x": 7,
      "y": -2,
