{
  "version": 8,
  "blockIdVersion": 11,
  "anchorX": 0,
  "anchorY": 0,
  "anchorZ": 0,
  "blocks": [
    {
      "x": -8,
      "y": 0,
      "z": -6,
      "name": "Rock_Stone_Cobble"
    },
    {
      "x": -8,
      "y": 4,
      "z": -6,
      "name": "*Wood_Softwood_Roof_Hollow_State_Definitions_Corner_Left",
      "rotation": 2
    },
    {
      "x": -8,
      "y": 0,
      "z": -5,
      "name": "Rock_Stone_Cobble"
    },
    {
      "x": -8,
      "y": 3,
      "z": -5,
      "name": "Wood_Beech_Branch_Corner",
      "support": 15,
      "rotation": 3
    },
    {
      "x": -8,
      "y": 4,
      "z": -5,
      "name": "Wood_Softwood_Roof",
      "rotation": 3
    },
    {
      "x": -8,
      "y": 0,
      "z": -4,
      "name": "Rock_Stone_Cobble"
    },
    {
      "x": -8,
      "y": 4,
      "z": -4,
      "name": "Wood_Softwood_Roof_Hollow",
      "rotation": 3
    },
    {
      "x": -8,
      "y": 0,
      "z": -3,
      "name": "Rock_Stone_Cobble"
    },
    {
      "x": -8,
      "y": 2,
      "z": -3,
      "name": "Plant_Vine_Wall",
      "support": 15,
      "rotation": 3
    },
    {
      "x": -8,
      "y": 3,
      "z": -3,
      "name": "Plant_Vine_Wall",
      "support": 15,
      "rotation": 3
    },
    {
      "x": -8,
      "y": 4,
      "z": -3,
      "name": "Wood_Softwood_Roof_Hollow",
      "rotation": 3
    },
    {
      "x": -8,
      "y": 0,
      "z": -2,
      "name": "Rock_Stone_Cobble"
    },
    {
      "x": -8,
      "y": 4,
      "z": -2,
      "name": "Wood_Softwood_Roof_Hollow",
      "rotation": 3
    },
    {
      "x": -8,
      "y": 0,
      "z": -1,
      "name": "Rock_Stone_Cobble_Mossy"
    },
    {
      "x": -8,
      "y": 1,
      "z": -1,
      "name": "Furniture_Tavern_Barrel",
      "support": 15
    },
    {
      "x": -8,
      "y": 4,
      "z": -1,
      "name": "Wood_Softwood_Roof_Hollow",
      "rotation": 3
    },
    {
      "x": -8,
      "y": 0,
      "z": 0,
      "name": "Rock_Stone_Cobble"
    },
    {
      "x": -8,
      "y": 2,
      "z": 0,
      "name": "Plant_Vine_Wall",
      "support": 15,
      "rotation": 3
    },
    {
      "x": -8,
      "y": 4,
      "z": 0,
      "name": "Wood_Softwood_Roof_Hollow",
      "rotation": 3
    },
    {
      "x": -8,
      "y": 0,
      "z": 1,
      "name": "Rock_Stone_Cobble"
    },
    {
      "x": -8,
      "y": 4,
      "z": 1,
      "name": "Wood_Softwood_Roof_Hollow",
      "rotation": 3
    },
    {
      "x": -8,
      "y": 0,
      "z": 2,
      "name": "Rock_Stone_Cobble"
    },
    {
      "x": -8,
      "y": 4,
      "z": 2,
      "name": "Wood_Softwood_Roof_Hollow",
      "rotation": 3
    },
    {
      "x": -8,
      "y": 0,
      "z": 3,
      "name": "Rock_Stone_Cobble"
    },
    {
      "x": -8,
      "y": 1,
      "z": 3,
      "name": "Furniture_Village_Crate"
    },
    {
      "x": -8,
      "y": 4,
      "z": 3,
      "name": "Wood_Softwood_Roof_Hollow",
      "rotation": 3
    },
    {
      "x": -8,
      "y": 0,
      "z": 4,
      "name": "Rock_Stone_Cobble"
    },
    {
      "x": -8,
      "y": 1,
      "z": 4,
      "name": "Furniture_Village_Crate"
    },
    {
      "x": -8,
      "y": 4,
      "z": 4,
      "name": "Wood_Softwood_Roof_Hollow",
      "rotation": 3
    },
    {
      "x": -8,
      "y": 0,
      "z": 5,
      "name": "Rock_Stone_Cobble"
    },
    {
      "x": -8,
      "y": 3,
      "z": 5,
      "name": "Plant_Vine_Wall",
      "support": 15,
      "rotation": 3
    },
    {
      "x": -8,
      "y": 4,
      "z": 5,
      "name": "Wood_Softwood_Roof_Hollow",
      "rotation": 3
    },
    {
      "x": -8,
      "y": 0,
      "z": 6,
      "name": "Rock_Stone_Cobble"
    },
    {
      "x": -8,
      "y": 3,
      "z": 6,
      "name": "Wood_Beech_Branch_Corner",
      "support": 15,
      "rotation": 3
    },
    {
      "x": -8,
      "y": 4,
      "z": 6,
      "name": "Wood_Softwood_Roof",
      "rotation": 3
    },
    {
      "x": -8,
      "y": 0,
      "z": 7,
      "name": "Rock_Stone_Cobble"
    },
    {
      "x": -8,
      "y": 4,
      "z": 7,
      "name": "Wood_Softwood_Roof_Hollow",
      "rotation": 3
    },
    {
      "x": -7,
      "y": 0,
      "z": -6,
      "name": "Rock_Stone_Cobble"
    },
    {
      "x": -7,
      "y": 1,
      "z": -6,
      "name": "Furniture_Tavern_Barrel",
      "support": 15
    },
    {
      "x": -7,
      "y": 2,
      "z": -6,
      "name": "Plant_Vine_Wall",
      "support": 15,
      "rotation": 2
    },
    {
      "x": -7,
      "y": 3,
      "z": -6,
      "name": "Wood_Beech_Branch_Corner",
      "support": 15,
      "rotation": 2
    },
    {
      "x": -7,
      "y": 4,
      "z": -6,
      "name": "Wood_Softwood_Roof",
      "rotation": 2
    },
    {
      "x": -7,
      "y": 0,
      "z": -5,
      "name": "Rock_Stone_Cobble_Mossy"
    },
    {
      "x": -7,
      "y": 1,
      "z": -5,
      "name": "Wood_Beech_Trunk",
      "support": 15
    },
    {
      "x": -7,
      "y": 2,
      "z": -5,
      "name": "Wood_Beech_Trunk",
      "support": 15
    },
    {
      "x": -7,
      "y": 3,
      "z": -5,
      "name": "Wood_Beech_Trunk",
      "support": 15
    },
    {
      "x": -7,
      "y": 4,
      "z": -5,
      "name": "Wood_Beech_Trunk",
      "support": 15
    },
    {
      "x": -7,
      "y": 5,
      "z": -5,
      "name": "*Wood_Softwood_Roof_State_Definitions_Corner_Right",
      "rotation": 3
    },
    {
      "x": -7,
      "y": 0,
      "z": -4,
      "name": "Rock_Stone_Cobble_Mossy"
    },
    {
      "x": -7,
      "y": 1,
      "z": -4,
      "name": "Rock_Stone_Brick"
    },
    {
      "x": -7,
      "y": 2,
      "z": -4,
      "name": "*Wood_Village_Wall_Full_State_Definitions_Bottom"
    },
    {
      "x": -7,
      "y": 3,
      "z": -4,
      "name": "*Wood_Village_Wall_Full_State_Definitions_Top"
    },
    {
      "x": -7,
      "y": 4,
      "z": -4,
      "name": "Wood_Beech_Trunk",
      "support": 15,
      "rotation": 4
    },
    {
      "x": -7,
      "y": 5,
      "z": -4,
      "name": "Wood_Softwood_Roof",
      "rotation": 3
    },
    {
      "x": -7,
      "y": 0,
      "z": -3,
      "name": "Rock_Stone_Cobble"
    },
    {
      "x": -7,
      "y": 1,
      "z": -3,
      "name": "Rock_Stone_Brick"
    },
    {
      "x": -7,
      "y": 2,
      "z": -3,
      "name": "*Wood_Village_Wall_Full_State_Definitions_Bottom"
    },
    {
      "x": -7,
      "y": 3,
      "z": -3,
      "name": "*Wood_Village_Wall_Full_State_Definitions_Top"
    },
    {
      "x": -7,
      "y": 4,
      "z": -3,
      "name": "Wood_Beech_Trunk",
      "support": 15,
      "rotation": 4
    },
    {
      "x": -7,
      "y": 5,
      "z": -3,
      "name": "Wood_Softwood_Roof",
      "rotation": 3
    },
    {
      "x": -7,
      "y": 0,
      "z": -2,
      "name": "Rock_Stone_Cobble"
    },
    {
      "x": -7,
      "y": 1,
      "z": -2,
      "name": "Rock_Stone_Brick"
    },
    {
      "x": -7,
      "y": 2,
      "z": -2,
      "name": "Furniture_Village_Window",
      "rotation": 1
    },
    {
      "x": -7,
      "y": 3,
      "z": -2,
      "name": "Furniture_Village_Window",
      "rotation": 1
    },
    {
      "x": -7,
      "y": 4,
      "z": -2,
      "name": "Wood_Beech_Trunk",
      "support": 15,
      "rotation": 4
    },
    {
      "x": -7,
      "y": 5,
      "z": -2,
      "name": "Wood_Softwood_Roof",
      "rotation": 3
    },
    {
      "x": -7,
      "y": 0,
      "z": -1,
      "name": "Rock_Stone_Cobble"
    },
    {
      "x": -7,
      "y": 1,
      "z": -1,
      "name": "Rock_Stone_Brick_Mossy"
    },
    {
      "x": -7,
      "y": 2,
      "z": -1,
      "name": "Furniture_Village_Window",
      "rotation": 1
    },
    {
      "x": -7,
      "y": 3,
      "z": -1,
      "name": "Furniture_Village_Window",
      "rotation": 1
    },
    {
      "x": -7,
      "y": 4,
      "z": -1,
      "name": "Wood_Beech_Trunk",
      "support": 15,
      "rotation": 4
    },
    {
      "x": -7,
      "y": 5,
      "z": -1,
      "name": "Wood_Softwood_Roof",
      "rotation": 3
    },
    {
      "x": -7,
      "y": 0,
      "z": 0,
      "name": "Rock_Stone_Cobble"
    },
    {
      "x": -7,
      "y": 1,
      "z": 0,
      "name": "Rock_Stone_Brick"
    },
    {
      "x": -7,
      "y": 2,
      "z": 0,
      "name": "*Wood_Village_Wall_Full_State_Definitions_Bottom"
    },
    {
      "x": -7,
      "y": 3,
      "z": 0,
      "name": "*Wood_Village_Wall_Full_State_Definitions_Top"
    },
    {
      "x": -7,
      "y": 4,
      "z": 0,
      "name": "Wood_Beech_Trunk",
      "support": 15,
      "rotation": 4
    },
    {
      "x": -7,
      "y": 5,
      "z": 0,
      "name": "Wood_Softwood_Roof",
      "rotation": 3
    },
    {
      "x": -7,
      "y": 0,
      "z": 1,
      "name": "Rock_Stone_Cobble_Mossy"
    },
    {
      "x": -7,
      "y": 1,
      "z": 1,
      "name": "Rock_Stone_Brick"
    },
    {
      "x": -7,
      "y": 2,
      "z": 1,
      "name": "*Wood_Village_Wall_Full_State_Definitions_Bottom"
    },
    {
      "x": -7,
      "y": 3,
      "z": 1,
      "name": "*Wood_Village_Wall_Full_State_Definitions_Top"
    },
    {
      "x": -7,
      "y": 4,
      "z": 1,
      "name": "Wood_Beech_Trunk",
      "support": 15,
      "rotation": 4
    },
    {
      "x": -7,
      "y": 5,
      "z": 1,
      "name": "Wood_Softwood_Roof",
      "rotation": 3
    },
    {
      "x": -7,
      "y": 0,
      "z": 2,
      "name": "Rock_Stone_Cobble"
    },
    {
      "x": -7,
      "y": 1,
      "z": 2,
      "name": "Rock_Stone_Brick"
    },
    {
      "x": -7,
      "y": 2,
      "z": 2,
      "name": "Furniture_Village_Window",
      "rotation": 1
    },
    {
      "x": -7,
      "y": 3,
      "z": 2,
      "name": "Furniture_Village_Window",
      "rotation": 1
    },
    {
      "x": -7,
      "y": 4,
      "z": 2,
      "name": "Wood_Beech_Trunk",
      "support": 15,
      "rotation": 4
    },
    {
      "x": -7,
      "y": 5,
      "z": 2,
      "name": "Wood_Softwood_Roof",
      "rotation": 3
    },
    {
      "x": -7,
      "y": 0,
      "z": 3,
      "name": "Rock_Stone_Cobble"
    },
    {
      "x": -7,
      "y": 1,
      "z": 3,
      "name": "Rock_Stone_Brick_Mossy"
    },
    {
      "x": -7,
      "y": 2,
      "z": 3,
      "name": "Furniture_Village_Window",
      "rotation": 1
    },
    {
      "x": -7,
      "y": 3,
      "z": 3,
      "name": "Furniture_Village_Window",
      "rotation": 1
    },
    {
      "x": -7,
      "y": 4,
      "z": 3,
      "name": "Wood_Beech_Trunk",
      "support": 15,
      "rotation": 4
    },
    {
      "x": -7,
      "y": 5,
      "z": 3,
      "name": "Wood_Softwood_Roof",
      "rotation": 3
    },
    {
      "x": -7,
      "y": 0,
      "z": 4,
      "name": "Rock_Stone_Cobble"
    },
    {
      "x": -7,
      "y": 1,
      "z": 4,
      "name": "Rock_Stone_Brick"
    },
    {
      "x": -7,
      "y": 2,
      "z": 4,
      "name": "*Wood_Village_Wall_Full_State_Definitions_Bottom"
    },
    {
      "x": -7,
      "y": 3,
      "z": 4,
      "name": "*Wood_Village_Wall_Full_State_Definitions_Top"
    },
    {
      "x": -7,
      "y": 4,
      "z": 4,
      "name": "Wood_Beech_Trunk",
      "support": 15,
      "rotation": 4
    },
    {
      "x": -7,
      "y": 5,
      "z": 4,
      "name": "Wood_Softwood_Roof",
      "rotation": 3
    },
    {
      "x": -7,
      "y": 0,
      "z": 5,
      "name": "Rock_Stone_Cobble_Mossy"
    },
    {
      "x": -7,
      "y": 1,
      "z": 5,
      "name": "Rock_Stone_Brick"
    },
    {
      "x": -7,
      "y": 2,
      "z": 5,
      "name": "*Wood_Village_Wall_Full_State_Definitions_Bottom"
    },
    {
      "x": -7,
      "y": 3,
      "z": 5,
      "name": "*Wood_Village_Wall_Full_State_Definitions_Top"
    },
    {
      "x": -7,
      "y": 4,
      "z": 5,
      "name": "Wood_Beech_Trunk",
      "support": 15,
      "rotation": 4
    },
    {
      "x": -7,
      "y": 5,
      "z": 5,
      "name": "Wood_Softwood_Roof",
      "rotation": 3
    },
    {
      "x": -7,
      "y": 0,
      "z": 6,
      "name": "Rock_Stone_Cobble"
    },
    {
      "x": -7,
      "y": 1,
      "z": 6,
      "name": "Wood_Beech_Trunk",
      "support": 15
    },
    {
      "x": -7,
      "y": 2,
      "z": 6,
      "name": "Wood_Beech_Trunk",
      "support": 15
    },
    {
      "x": -7,
      "y": 3,
      "z": 6,
      "name": "Wood_Beech_Trunk",
      "support": 15
    },
    {
      "x": -7,
      "y": 4,
      "z": 6,
      "name": "Wood_Beech_Trunk",
      "support": 15
    },
    {
      "x": -7,
      "y": 5,
      "z": 6,
      "name": "Wood_Softwood_Roof",
      "rotation": 3
    },
    {
      "x": -7,
      "y": 0,
      "z": 7,
      "name": "Rock_Stone_Cobble"
    },
    {
      "x": -7,
      "y": 3,
      "z": 7,
      "name": "Furniture_Village_Sign",
      "rotation": 1
    },
    {
      "x": -7,
      "y": 4,
      "z": 7,
      "name": "Wood_Beech_Branch_Corner",
      "support": 15
    },
    {
      "x": -7,
      "y": 5,
      "z": 7,
      "name": "Wood_Softwood_Roof",
      "rotation": 3
    },
    {
      "x": -6,
      "y": 0,
      "z": -6,
      "name": "Rock_Stone_Cobble"
    },
    {
      "x": -6,
      "y": 1,
      "z": -6,
      "name": "Furniture_Village_Crate"
    },
    {
      "x": -6,
      "y": 4,
      "z": -6,
      "name": "Wood_Softwood_Roof_Hollow",
      "rotation": 2
    },
    {
      "x": -6,
      "y": 0,
      "z": -5,
      "name": "Rock_Stone_Cobble"
    },
    {
      "x": -6,
      "y": 1,
      "z": -5,
      "name": "Rock_Stone_Brick"
    },
    {
      "x": -6,
      "y": 2,
      "z": -5,
      "name": "*Wood_Village_Wall_Full_State_Definitions_Bottom"
    },
    {
      "x": -6,
      "y": 3,
      "z": -5,
      "name": "*Wood_Village_Wall_Full_State_Definitions_Top"
    },
    {
      "x": -6,
      "y": 4,
      "z": -5,
      "name": "Wood_Beech_Trunk",
      "support": 15,
      "rotation": 5
    },
    {
      "x": -6,
      "y": 5,
      "z": -5,
      "name": "Wood_Softwood_Roof",
      "rotation": 2
    },
    {
      "x": -6,
      "y": 0,
      "z": -4,
      "name": "Wood_Softwood_Planks"
    },
    {
      "x": -6,
      "y": 1,
      "z": -4,
      "name": "Furniture_Village_Bookcase",
      "support": 15,
      "rotation": 1
    },
    {
      "x": -6,
      "y": 2,
      "z": -4,
      "name": "Furniture_Village_Bookcase",
      "support": 15,
      "rotation": 1
    },
    {
      "x": -6,
      "y": 3,
      "z": -4,
      "name": "Furniture_Village_Bookcase",
      "support": 15,
      "rotation": 1
    },
    {
      "x": -6,
      "y": 4,
      "z": -4,
      "name": "Wood_Softwood_Planks"
    },
    {
      "x": -6,
      "y": 5,
      "z": -4,
      "name": "*Wood_Softwood_Stairs_State_Definitions_Inverted_Corner_Left",
      "rotation": 11
    },
    {
      "x": -6,
      "y": 6,
      "z": -4,
      "name": "*Wood_Softwood_Roof_State_Definitions_Corner_Left",
      "rotation": 2
    },
    {
      "x": -6,
      "y": 0,
      "z": -3,
      "name": "Wood_Softwood_Planks"
    },
    {
      "x": -6,
      "y": 1,
      "z": -3,
      "name": "Furniture_Village_Bookcase",
      "support": 15,
      "rotation": 1
    },
    {
      "x": -6,
      "y": 2,
      "z": -3,
      "name": "Aetherhaven_Management_Block",
      "components": {
        "Components": {
          "AetherhavenManagementBlock": {
            "PlotId": "",
            "TownId": ""
          },
          "PlacedByInteraction": {
            "WhoPlacedUuid": {
              "$binary": "v7RyWIT/TYKnXA2XcxdQtw==",
              "$type": "04"
            }
          }
        }
      },
      "support": 15,
      "rotation": 1
    },
    {
      "x": -6,
      "y": 3,
      "z": -3,
      "name": "Furniture_Village_Bookcase",
      "support": 15,
      "rotation": 1
    },
    {
      "x": -6,
      "y": 4,
      "z": -3,
      "name": "Wood_Softwood_Planks"
    },
    {
      "x": -6,
      "y": 5,
      "z": -3,
      "name": "Wood_Softwood_Stairs",
      "rotation": 11
    },
    {
      "x": -6,
      "y": 6,
      "z": -3,
      "name": "Wood_Softwood_Roof",
      "rotation": 3
    },
    {
      "x": -6,
      "y": 0,
      "z": -2,
      "name": "Wood_Softwood_Planks"
    },
    {
      "x": -6,
      "y": 4,
      "z": -2,
      "name": "Wood_Softwood_Planks"
    },
    {
      "x": -6,
      "y": 5,
      "z": -2,
      "name": "Wood_Softwood_Stairs",
      "rotation": 11
    },
    {
      "x": -6,
      "y": 6,
      "z": -2,
      "name": "Wood_Softwood_Roof",
      "rotation": 3
    },
    {
      "x": -6,
      "y": 0,
      "z": -1,
      "name": "Wood_Softwood_Planks"
    },
    {
      "x": -6,
      "y": 4,
      "z": -1,
      "name": "Wood_Softwood_Planks"
    },
    {
      "x": -6,
      "y": 5,
      "z": -1,
      "name": "Wood_Softwood_Stairs",
      "rotation": 11
    },
    {
      "x": -6,
      "y": 6,
      "z": -1,
      "name": "Wood_Softwood_Roof",
      "rotation": 3
    },
    {
      "x": -6,
      "y": 0,
      "z": 0,
      "name": "Wood_Softwood_Planks"
    },
    {
      "x": -6,
      "y": 1,
      "z": 0,
      "name": "Wood_Softwood_Ornate"
    },
    {
      "x": -6,
      "y": 3,
      "z": 0,
      "name": "Wood_Softwood_Stairs",
      "rotation": 11
    },
    {
      "x": -6,
      "y": 4,
      "z": 0,
      "name": "Wood_Softwood_Stairs"
    },
    {
      "x": -6,
      "y": 5,
      "z": 0,
      "name": "Wood_Softwood_Stairs",
      "rotation": 11
    },
    {
      "x": -6,
      "y": 6,
      "z": 0,
      "name": "Wood_Softwood_Roof",
      "rotation": 3
    },
    {
      "x": -6,
      "y": 0,
      "z": 1,
      "name": "Wood_Softwood_Planks"
    },
    {
      "x": -6,
      "y": 5,
      "z": 1,
      "name": "Wood_Softwood_Stairs",
      "rotation": 11
    },
    {
      "x": -6,
      "y": 6,
      "z": 1,
      "name": "Wood_Softwood_Roof",
      "rotation": 3
    },
    {
      "x": -6,
      "y": 0,
      "z": 2,
      "name": "Wood_Softwood_Planks"
    },
    {
      "x": -6,
      "y": 5,
      "z": 2,
      "name": "Wood_Softwood_Stairs",
      "rotation": 11
    },
    {
      "x": -6,
      "y": 6,
      "z": 2,
      "name": "Wood_Softwood_Roof",
      "rotation": 3
    },
    {
      "x": -6,
      "y": 0,
      "z": 3,
      "name": "Wood_Softwood_Planks"
    },
    {
      "x": -6,
      "y": 5,
      "z": 3,
      "name": "Wood_Softwood_Stairs",
      "rotation": 11
    },
    {
      "x": -6,
      "y": 6,
      "z": 3,
      "name": "Wood_Softwood_Roof",
      "rotation": 3
    },
    {
      "x": -6,
      "y": 0,
      "z": 4,
      "name": "Wood_Softwood_Planks"
    },
    {
      "x": -6,
      "y": 5,
      "z": 4,
      "name": "Wood_Softwood_Stairs",
      "rotation": 11
    },
    {
      "x": -6,
      "y": 6,
      "z": 4,
      "name": "Wood_Softwood_Roof",
      "rotation": 3
    },
    {
      "x": -6,
      "y": 0,
      "z": 5,
      "name": "Wood_Softwood_Planks"
    },
    {
      "x": -6,
      "y": 1,
      "z": 5,
      "name": "Furniture_Temple_Dark_Candle",
      "support": 15
    },
    {
      "x": -6,
      "y": 2,
      "z": 5,
      "name": "Furniture_Temple_Dark_Candle",
      "support": 15,
      "filler": 1024
    },
    {
      "x": -6,
      "y": 5,
      "z": 5,
      "name": "Wood_Softwood_Stairs",
      "rotation": 11
    },
    {
      "x": -6,
      "y": 6,
      "z": 5,
      "name": "Wood_Softwood_Roof",
      "rotation": 3
    },
    {
      "x": -6,
      "y": 0,
      "z": 6,
      "name": "Rock_Stone_Cobble"
    },
    {
      "x": -6,
      "y": 1,
      "z": 6,
      "name": "Rock_Stone_Brick_Mossy"
    },
    {
      "x": -6,
      "y": 2,
      "z": 6,
      "name": "*Wood_Village_Wall_Full_State_Definitions_Bottom"
    },
    {
      "x": -6,
      "y": 3,
      "z": 6,
      "name": "*Wood_Village_Wall_Full_State_Definitions_Top"
    },
    {
      "x": -6,
      "y": 4,
      "z": 6,
      "name": "Wood_Beech_Trunk",
      "support": 15,
      "rotation": 5
    },
    {
      "x": -6,
      "y": 5,
      "z": 6,
      "name": "Wood_Village_Wall_Full"
    },
    {
      "x": -6,
      "y": 6,
      "z": 6,
      "name": "Wood_Softwood_Roof",
      "rotation": 3
    },
    {
      "x": -6,
      "y": 0,
      "z": 7,
      "name": "Rock_Stone_Cobble_Mossy"
    },
    {
      "x": -6,
      "y": 2,
      "z": 7,
      "name": "Plant_Vine_Wall",
      "support": 15
    },
    {
      "x": -6,
      "y": 5,
      "z": 7,
      "name": "Wood_Softwood_Stairs",
      "rotation": 11
    },
    {
      "x": -6,
      "y": 6,
      "z": 7,
      "name": "Wood_Softwood_Roof",
      "rotation": 3
    },
    {
      "x": -5,
      "y": 0,
      "z": -6,
      "name": "Rock_Stone_Cobble"
    },
    {
      "x": -5,
      "y": 1,
      "z": -6,
      "name": "Furniture_Village_Crate"
    },
    {
      "x": -5,
      "y": 4,
      "z": -6,
      "name": "Wood_Softwood_Roof_Hollow",
      "rotation": 2
    },
    {
      "x": -5,
      "y": 0,
      "z": -5,
      "name": "Rock_Stone_Cobble"
    },
    {
      "x": -5,
      "y": 1,
      "z": -5,
      "name": "Rock_Stone_Brick"
    },
    {
      "x": -5,
      "y": 2,
      "z": -5,
      "name": "Furniture_Village_Window"
    },
    {
      "x": -5,
      "y": 3,
      "z": -5,
      "name": "Furniture_Village_Window"
    },
    {
      "x": -5,
      "y": 4,
      "z": -5,
      "name": "Wood_Beech_Trunk",
      "support": 15,
      "rotation": 5
    },
    {
      "x": -5,
      "y": 5,
      "z": -5,
      "name": "Wood_Softwood_Roof",
      "rotation": 2
    },
    {
      "x": -5,
      "y": 0,
      "z": -4,
      "name": "Wood_Softwood_Planks"
    },
    {
      "x": -5,
      "y": 4,
      "z": -4,
      "name": "Wood_Softwood_Planks"
    },
    {
      "x": -5,
      "y": 5,
      "z": -4,
      "name": "Wood_Softwood_Stairs",
      "rotation": 10
    },
    {
      "x": -5,
      "y": 6,
      "z": -4,
      "name": "Wood_Softwood_Roof",
      "rotation": 2
    },
    {
      "x": -5,
      "y": 0,
      "z": -3,
      "name": "Wood_Softwood_Planks"
    },
    {
      "x": -5,
      "y": 4,
      "z": -3,
      "name": "Wood_Softwood_Planks"
    },
    {
      "x": -5,
      "y": 6,
      "z": -3,
      "name": "*Wood_Softwood_Stairs_State_Definitions_Inverted_Corner_Right",
      "rotation": 10
    },
    {
      "x": -5,
      "y": 7,
      "z": -3,
      "name": "Wood_Softwood_Roof_Flat",
      "rotation": 2
    },
    {
      "x": -5,
      "y": 0,
      "z": -2,
      "name": "Wood_Softwood_Planks"
    },
    {
      "x": -5,
      "y": 4,
      "z": -2,
      "name": "Wood_Softwood_Planks"
    },
    {
      "x": -5,
      "y": 6,
      "z": -2,
      "name": "Wood_Softwood_Stairs",
      "rotation": 11
    },
    {
      "x": -5,
      "y": 7,
      "z": -2,
      "name": "Wood_Softwood_Roof_Flat",
      "rotation": 2
    },
    {
      "x": -5,
      "y": 0,
      "z": -1,
      "name": "Wood_Softwood_Planks"
    },
    {
      "x": -5,
      "y": 4,
      "z": -1,
      "name": "Wood_Softwood_Planks"
    },
    {
      "x": -5,
      "y": 6,
      "z": -1,
      "name": "Wood_Softwood_Stairs",
      "rotation": 11
    },
    {
      "x": -5,
      "y": 7,
      "z": -1,
      "name": "Wood_Softwood_Roof_Flat",
      "rotation": 2
    },
    {
      "x": -5,
      "y": 0,
      "z": 0,
      "name": "Wood_Softwood_Planks"
    },
    {
      "x": -5,
      "y": 1,
      "z": 0,
      "name": "Wood_Softwood_Fence_Gate"
    },
    {
      "x": -5,
      "y": 3,
      "z": 0,
      "name": "Wood_Softwood_Stairs",
      "rotation": 9
    },
    {
      "x": -5,
      "y": 4,
      "z": 0,
      "name": "Wood_Softwood_Stairs"
    },
    {
      "x": -5,
      "y": 6,
      "z": 0,
      "name": "Wood_Softwood_Stairs",
      "rotation": 11
    },
    {
      "x": -5,
      "y": 7,
      "z": 0,
      "name": "Wood_Softwood_Roof_Flat",
      "rotation": 2
    },
    {
      "x": -5,
      "y": 0,
      "z": 1,
      "name": "Cloth_Block_Wool_Green",
      "support": 15
    },
    {
      "x": -5,
      "y": 6,
      "z": 1,
      "name": "Wood_Softwood_Stairs",
      "rotation": 11
    },
    {
      "x": -5,
      "y": 7,
      "z": 1,
      "name": "Wood_Softwood_Roof_Flat",
      "rotation": 2
    },
    {
      "x": -5,
      "y": 0,
      "z": 2,
      "name": "Cloth_Block_Wool_Green",
      "support": 15
    },
    {
      "x": -5,
      "y": 6,
      "z": 2,
      "name": "Wood_Softwood_Stairs",
      "rotation": 11
    },
    {
      "x": -5,
      "y": 7,
      "z": 2,
      "name": "Wood_Softwood_Roof_Flat"
    },
    {
      "x": -5,
      "y": 0,
      "z": 3,
      "name": "Cloth_Block_Wool_Green",
      "support": 15
    },
    {
      "x": -5,
      "y": 6,
      "z": 3,
      "name": "Wood_Softwood_Stairs",
      "rotation": 11
    },
    {
      "x": -5,
      "y": 7,
      "z": 3,
      "name": "Wood_Softwood_Roof_Flat"
    },
    {
      "x": -5,
      "y": 0,
      "z": 4,
      "name": "Cloth_Block_Wool_Green",
      "support": 15
    },
    {
      "x": -5,
      "y": 6,
      "z": 4,
      "name": "Wood_Softwood_Stairs",
      "rotation": 11
    },
    {
      "x": -5,
      "y": 7,
      "z": 4,
      "name": "Wood_Softwood_Roof_Flat"
    },
    {
      "x": -5,
      "y": 0,
      "z": 5,
      "name": "Cloth_Block_Wool_Green",
      "support": 15
    },
    {
      "x": -5,
      "y": 6,
      "z": 5,
      "name": "Wood_Softwood_Stairs",
      "rotation": 11
    },
    {
      "x": -5,
      "y": 7,
      "z": 5,
      "name": "Wood_Softwood_Roof_Flat"
    },
    {
      "x": -5,
      "y": 0,
      "z": 6,
      "name": "Wood_Softwood_Planks"
    },
    {
      "x": -5,
      "y": 1,
      "z": 6,
      "name": "*Furniture_Village_Door_State_Definitions_CloseDoorIn"
    },
    {
      "x": -5,
      "y": 2,
      "z": 6,
      "name": "*Furniture_Village_Door_State_Definitions_CloseDoorIn",
      "filler": 1024
    },
    {
      "x": -5,
      "y": 3,
      "z": 6,
      "name": "Wood_Village_Wall_Full"
    },
    {
      "x": -5,
      "y": 4,
      "z": 6,
      "name": "Wood_Beech_Trunk",
      "support": 15,
      "rotation": 5
    },
    {
      "x": -5,
      "y": 5,
      "z": 6,
      "name": "*Wood_Village_Wall_Full_State_Definitions_Bottom"
    },
    {
      "x": -5,
      "y": 6,
      "z": 6,
      "name": "*Wood_Village_Wall_Full_State_Definitions_Top"
    },
    {
      "x": -5,
      "y": 7,
      "z": 6,
      "name": "Wood_Softwood_Roof_Flat"
    },
    {
      "x": -5,
      "y": 0,
      "z": 7,
      "name": "Rock_Stone_Cobble"
    },
    {
      "x": -5,
      "y": 6,
      "z": 7,
      "name": "Wood_Softwood_Stairs",
      "rotation": 11
    },
    {
      "x": -5,
      "y": 7,
      "z": 7,
      "name": "Wood_Softwood_Roof_Flat"
    },
    {
      "x": -4,
      "y": 0,
      "z": -6,
      "name": "Rock_Stone_Cobble_Mossy"
    },
    {
      "x": -4,
      "y": 4,
      "z": -6,
      "name": "Wood_Softwood_Roof_Hollow",
      "rotation": 2
    },
    {
      "x": -4,
      "y": 0,
      "z": -5,
      "name": "Rock_Stone_Cobble_Mossy"
    },
    {
      "x": -4,
      "y": 1,
      "z": -5,
      "name": "Rock_Stone_Brick_Mossy"
    },
    {
      "x": -4,
      "y": 2,
      "z": -5,
      "name": "*Wood_Village_Wall_Full_State_Definitions_Bottom"
    },
    {
      "x": -4,
      "y": 3,
      "z": -5,
      "name": "*Wood_Village_Wall_Full_State_Definitions_Top"
    },
    {
      "x": -4,
      "y": 4,
      "z": -5,
      "name": "Wood_Beech_Trunk",
      "support": 15,
      "rotation": 5
    },
    {
      "x": -4,
      "y": 5,
      "z": -5,
      "name": "Wood_Softwood_Roof",
      "rotation": 2
    },
    {
      "x": -4,
      "y": 0,
      "z": -4,
      "name": "Wood_Softwood_Planks"
    },
    {
      "x": -4,
      "y": 1,
      "z": -4,
      "name": "Wood_Softwood_Ornate"
    },
    {
      "x": -4,
      "y": 3,
      "z": -4,
      "name": "Wood_Softwood_Stairs",
      "rotation": 10
    },
    {
      "x": -4,
      "y": 4,
      "z": -4,
      "name": "Wood_Softwood_Stairs",
      "rotation": 1
    },
    {
      "x": -4,
      "y": 5,
      "z": -4,
      "name": "Wood_Softwood_Stairs",
      "rotation": 10
    },
    {
      "x": -4,
      "y": 6,
      "z": -4,
      "name": "Wood_Softwood_Roof",
      "rotation": 2
    },
    {
      "x": -4,
      "y": 0,
      "z": -3,
      "name": "Wood_Softwood_Planks"
    },
    {
      "x": -4,
      "y": 1,
      "z": -3,
      "name": "Furniture_Village_Counter",
      "support": 15,
      "filler": 992,
      "rotation": 3
    },
    {
      "x": -4,
      "y": 4,
      "z": -3,
      "name": "Wood_Softwood_Stairs",
      "rotation": 1
    },
    {
      "x": -4,
      "y": 6,
      "z": -3,
      "name": "Wood_Softwood_Stairs",
      "rotation": 10
    },
    {
      "x": -4,
      "y": 7,
      "z": -3,
      "name": "Wood_Softwood_Roof_Flat",
      "rotation": 2
    },
    {
      "x": -4,
      "y": 0,
      "z": -2,
      "name": "Wood_Softwood_Planks"
    },
    {
      "x": -4,
      "y": 1,
      "z": -2,
      "name": "Furniture_Village_Counter",
      "support": 15,
      "rotation": 3
    },
    {
      "x": -4,
      "y": 4,
      "z": -2,
      "name": "Wood_Softwood_Stairs",
      "rotation": 1
    },
    {
      "x": -4,
      "y": 6,
      "z": -2,
      "name": "Wood_Softwood_Planks_Half",
      "rotation": 8
    },
    {
      "x": -4,
      "y": 7,
      "z": -2,
      "name": "Wood_Beech_Trunk",
      "support": 15
    },
    {
      "x": -4,
      "y": 8,
      "z": -2,
      "name": "Wood_Beech_Trunk",
      "support": 15
    },
    {
      "x": -4,
      "y": 9,
      "z": -2,
      "name": "Wood_Softwood_Roof",
      "rotation": 2
    },
    {
      "x": -4,
      "y": 0,
      "z": -1,
      "name": "Wood_Softwood_Planks"
    },
    {
      "x": -4,
      "y": 1,
      "z": -1,
      "name": "Wood_Softwood_Ornate"
    },
    {
      "x": -4,
      "y": 2,
      "z": -1,
      "name": "Furniture_Crude_Candle",
      "support": 15
    },
    {
      "x": -4,
      "y": 3,
      "z": -1,
      "name": "Wood_Softwood_Stairs",
      "rotation": 8
    },
    {
      "x": -4,
      "y": 4,
      "z": -1,
      "name": "Wood_Softwood_Stairs",
      "rotation": 1
    },
    {
      "x": -4,
      "y": 5,
      "z": -1,
      "name": "Deco_Lantern_Ceiling",
      "support": 15
    },
    {
      "x": -4,
      "y": 6,
      "z": -1,
      "name": "Deco_Iron_Chain_Small"
    },
    {
      "x": -4,
      "y": 7,
      "z": -1,
      "name": "Wood_Softwood_Planks"
    },
    {
      "x": -4,
      "y": 8,
      "z": -1,
      "name": "*Wood_Village_Wall_Full_State_Definitions_Bottom"
    },
    {
      "x": -4,
      "y": 9,
      "z": -1,
      "name": "*Wood_Village_Wall_Full_State_Definitions_Top"
    },
    {
      "x": -4,
      "y": 10,
      "z": -1,
      "name": "Wood_Softwood_Roof_Flat",
      "rotation": 3
    },
    {
      "x": -4,
      "y": 0,
      "z": 0,
      "name": "Wood_Softwood_Planks"
    },
    {
      "x": -4,
      "y": 1,
      "z": 0,
      "name": "Wood_Softwood_Ornate"
    },
    {
      "x": -4,
      "y": 2,
      "z": 0,
      "name": "Wood_Softwood_Planks"
    },
    {
      "x": -4,
      "y": 3,
      "z": 0,
      "name": "Wood_Softwood_Planks"
    },
    {
      "x": -4,
      "y": 4,
      "z": 0,
      "name": "*Wood_Softwood_Stairs_State_Definitions_Corner_Left"
    },
    {
      "x": -4,
      "y": 6,
      "z": 0,
      "name": "Wood_Softwood_Planks_Half",
      "rotation": 8
    },
    {
      "x": -4,
      "y": 7,
      "z": 0,
      "name": "Wood_Beech_Trunk",
      "support": 15
    },
    {
      "x": -4,
      "y": 8,
      "z": 0,
      "name": "Wood_Beech_Trunk",
      "support": 15
    },
    {
      "x": -4,
      "y": 9,
      "z": 0,
      "name": "Wood_Softwood_Roof"
    },
    {
      "x": -4,
      "y": 0,
      "z": 1,
      "name": "Cloth_Block_Wool_Green",
      "support": 15
    },
    {
      "x": -4,
      "y": 6,
      "z": 1,
      "name": "*Wood_Softwood_Stairs_State_Definitions_Corner_Right",
      "rotation": 8
    },
    {
      "x": -4,
      "y": 7,
      "z": 1,
      "name": "Wood_Softwood_Roof_Flat",
      "rotation": 2
    },
    {
      "x": -4,
      "y": 0,
      "z": 2,
      "name": "Cloth_Block_Wool_Green",
      "support": 15
    },
    {
      "x": -4,
      "y": 6,
      "z": 2,
      "name": "Wood_Softwood_Stairs",
      "rotation": 9
    },
    {
      "x": -4,
      "y": 7,
      "z": 2,
      "name": "Wood_Softwood_Roof_Flat"
    },
    {
      "x": -4,
      "y": 0,
      "z": 3,
      "name": "Cloth_Block_Wool_Green",
      "support": 15
    },
    {
      "x": -4,
      "y": 6,
      "z": 3,
      "name": "Wood_Softwood_Stairs",
      "rotation": 9
    },
    {
      "x": -4,
      "y": 7,
      "z": 3,
      "name": "Wood_Softwood_Roof_Flat"
    },
    {
      "x": -4,
      "y": 0,
      "z": 4,
      "name": "Cloth_Block_Wool_Green",
      "support": 15
    },
    {
      "x": -4,
      "y": 6,
      "z": 4,
      "name": "Wood_Softwood_Stairs",
      "rotation": 9
    },
    {
      "x": -4,
      "y": 7,
      "z": 4,
      "name": "Wood_Softwood_Roof_Flat"
    },
    {
      "x": -4,
      "y": 0,
      "z": 5,
      "name": "Cloth_Block_Wool_Green",
      "support": 15
    },
    {
      "x": -4,
      "y": 6,
      "z": 5,
      "name": "Wood_Softwood_Stairs",
      "rotation": 9
    },
    {
      "x": -4,
      "y": 7,
      "z": 5,
      "name": "Wood_Softwood_Roof_Flat"
    },
    {
      "x": -4,
      "y": 0,
      "z": 6,
      "name": "Wood_Softwood_Planks"
    },
    {
      "x": -4,
      "y": 1,
      "z": 6,
      "name": "*Furniture_Village_Door_State_Definitions_CloseDoorOut",
      "rotation": 2
    },
    {
      "x": -4,
      "y": 2,
      "z": 6,
      "name": "*Furniture_Village_Door_State_Definitions_CloseDoorOut",
      "filler": 1024,
      "rotation": 2
    },
    {
      "x": -4,
      "y": 3,
      "z": 6,
      "name": "Wood_Village_Wall_Full"
    },
    {
      "x": -4,
      "y": 4,
      "z": 6,
      "name": "Wood_Beech_Trunk",
      "support": 15,
      "rotation": 5
    },
    {
      "x": -4,
      "y": 5,
      "z": 6,
      "name": "*Wood_Village_Wall_Full_State_Definitions_Bottom"
    },
    {
      "x": -4,
      "y": 6,
      "z": 6,
      "name": "*Wood_Village_Wall_Full_State_Definitions_Top"
    },
    {
      "x": -4,
      "y": 7,
      "z": 6,
      "name": "Wood_Softwood_Roof_Flat"
    },
    {
      "x": -4,
      "y": 0,
      "z": 7,
      "name": "Rock_Stone_Cobble"
    },
    {
      "x": -4,
      "y": 6,
      "z": 7,
      "name": "Wood_Softwood_Stairs",
      "rotation": 9
    },
    {
      "x": -4,
      "y": 7,
      "z": 7,
      "name": "Wood_Softwood_Roof_Flat"
    },
    {
      "x": -3,
      "y": 0,
      "z": -6,
      "name": "Rock_Stone_Cobble"
    },
    {
      "x": -3,
      "y": 3,
      "z": -6,
      "name": "Plant_Vine_Wall",
      "support": 15,
      "rotation": 2
    },
    {
      "x": -3,
      "y": 4,
      "z": -6,
      "name": "Wood_Softwood_Roof_Hollow",
      "rotation": 2
    },
    {
      "x": -3,
      "y": 0,
      "z": -5,
      "name": "Rock_Stone_Cobble"
    },
    {
      "x": -3,
      "y": 1,
      "z": -5,
      "name": "Rock_Stone_Brick"
    },
    {
      "x": -3,
      "y": 2,
      "z": -5,
      "name": "*Wood_Village_Wall_Full_State_Definitions_Bottom"
    },
    {
      "x": -3,
      "y": 3,
      "z": -5,
      "name": "*Wood_Village_Wall_Full_State_Definitions_Top"
    },
    {
      "x": -3,
      "y": 4,
      "z": -5,
      "name": "Wood_Beech_Trunk",
      "support": 15,
      "rotation": 5
    },
    {
      "x": -3,
      "y": 5,
      "z": -5,
      "name": "Wood_Softwood_Roof",
      "rotation": 2
    },
    {
      "x": -3,
      "y": 0,
      "z": -4,
      "name": "Wood_Softwood_Planks"
    },
    {
      "x": -3,
      "y": 5,
      "z": -4,
      "name": "Wood_Softwood_Stairs",
      "rotation": 10
    },
    {
      "x": -3,
      "y": 6,
      "z": -4,
      "name": "Wood_Softwood_Roof",
      "rotation": 2
    },
    {
      "x": -3,
      "y": 0,
      "z": -3,
      "name": "Cloth_Block_Wool_Green",
      "support": 15
    },
    {
      "x": -3,
      "y": 6,
      "z": -3,
      "name": "Wood_Softwood_Stairs",
      "rotation": 10
    },
    {
      "x": -3,
      "y": 7,
      "z": -3,
      "name": "Wood_Softwood_Roof_Flat",
      "rotation": 2
    },
    {
      "x": -3,
      "y": 0,
      "z": -2,
      "name": "Cloth_Block_Wool_Green",
      "support": 15
    },
    {
      "x": -3,
      "y": 7,
      "z": -2,
      "name": "Wood_Softwood_Planks"
    },
    {
      "x": -3,
      "y": 8,
      "z": -2,
      "name": "Wood_Village_Wall_Full"
    },
    {
      "x": -3,
      "y": 9,
      "z": -2,
      "name": "Wood_Softwood_Roof",
      "rotation": 2
    },
    {
      "x": -3,
      "y": 0,
      "z": -1,
      "name": "Cloth_Block_Wool_Green",
      "support": 15
    },
    {
      "x": -3,
      "y": 9,
      "z": -1,
      "name": "Wood_Softwood_Planks"
    },
    {
      "x": -3,
      "y": 10,
      "z": -1,
      "name": "Wood_Softwood_Roof_Flat",
      "rotation": 3
    },
    {
      "x": -3,
      "y": 0,
      "z": 0,
      "name": "Cloth_Block_Wool_Green",
      "support": 15
    },
    {
      "x": -3,
      "y": 7,
      "z": 0,
      "name": "Wood_Softwood_Planks"
    },
    {
      "x": -3,
      "y": 8,
      "z": 0,
      "name": "Wood_Village_Wall_Full"
    },
    {
      "x": -3,
      "y": 9,
      "z": 0,
      "name": "Wood_Softwood_Roof"
    },
    {
      "x": -3,
      "y": 0,
      "z": 1,
      "name": "Cloth_Block_Wool_Green",
      "support": 15
    },
    {
      "x": -3,
      "y": 6,
      "z": 1,
      "name": "Wood_Softwood_Stairs",
      "rotation": 8
    },
    {
      "x": -3,
      "y": 7,
      "z": 1,
      "name": "Wood_Softwood_Roof_Flat",
      "rotation": 2
    },
    {
      "x": -3,
      "y": 0,
      "z": 2,
      "name": "Wood_Softwood_Planks"
    },
    {
      "x": -3,
      "y": 5,
      "z": 2,
      "name": "*Wood_Softwood_Stairs_State_Definitions_Corner_Right",
      "rotation": 8
    },
    {
      "x": -3,
      "y": 6,
      "z": 2,
      "name": "*Wood_Softwood_Roof_State_Definitions_Inverted_Corner_Right",
      "rotation": 1
    },
    {
      "x": -3,
      "y": 0,
      "z": 3,
      "name": "Wood_Softwood_Planks"
    },
    {
      "x": -3,
      "y": 5,
      "z": 3,
      "name": "Wood_Softwood_Stairs",
      "rotation": 9
    },
    {
      "x": -3,
      "y": 6,
      "z": 3,
      "name": "Wood_Softwood_Roof",
      "rotation": 1
    },
    {
      "x": -3,
      "y": 0,
      "z": 4,
      "name": "Wood_Softwood_Planks"
    },
    {
      "x": -3,
      "y": 5,
      "z": 4,
      "name": "Wood_Softwood_Stairs",
      "rotation": 9
    },
    {
      "x": -3,
      "y": 6,
      "z": 4,
      "name": "Wood_Softwood_Roof",
      "rotation": 1
    },
    {
      "x": -3,
      "y": 0,
      "z": 5,
      "name": "Wood_Softwood_Planks"
    },
    {
      "x": -3,
      "y": 1,
      "z": 5,
      "name": "Furniture_Temple_Dark_Candle",
      "support": 15
    },
    {
      "x": -3,
      "y": 2,
      "z": 5,
      "name": "Furniture_Temple_Dark_Candle",
      "support": 15,
      "filler": 1024
    },
    {
      "x": -3,
      "y": 5,
      "z": 5,
      "name": "Wood_Softwood_Stairs",
      "rotation": 9
    },
    {
      "x": -3,
      "y": 6,
      "z": 5,
      "name": "Wood_Softwood_Roof",
      "rotation": 1
    },
    {
      "x": -3,
      "y": 0,
      "z": 6,
      "name": "Rock_Stone_Cobble_Mossy"
    },
    {
      "x": -3,
      "y": 1,
      "z": 6,
      "name": "Rock_Stone_Brick"
    },
    {
      "x": -3,
      "y": 2,
      "z": 6,
      "name": "*Wood_Village_Wall_Full_State_Definitions_Bottom"
    },
    {
      "x": -3,
      "y": 3,
      "z": 6,
      "name": "*Wood_Village_Wall_Full_State_Definitions_Top"
    },
    {
      "x": -3,
      "y": 4,
      "z": 6,
      "name": "Wood_Beech_Trunk",
      "support": 15,
      "rotation": 5
    },
    {
      "x": -3,
      "y": 5,
      "z": 6,
      "name": "Wood_Village_Wall_Full"
    },
    {
      "x": -3,
      "y": 6,
      "z": 6,
      "name": "Wood_Softwood_Roof",
      "rotation": 1
    },
    {
      "x": -3,
      "y": 0,
      "z": 7,
      "name": "Rock_Stone_Cobble"
    },
    {
      "x": -3,
      "y": 4,
      "z": 7,
      "name": "Plant_Vine_Wall",
      "support": 15
    },
    {
      "x": -3,
      "y": 5,
      "z": 7,
      "name": "Wood_Softwood_Stairs",
      "rotation": 9
    },
    {
      "x": -3,
      "y": 6,
      "z": 7,
      "name": "Wood_Softwood_Roof",
      "rotation": 1
    },
    {
      "x": -2,
      "y": 0,
      "z": -6,
      "name": "Rock_Stone_Cobble"
    },
    {
      "x": -2,
      "y": 3,
      "z": -6,
      "name": "Wood_Beech_Branch_Corner",
      "support": 15,
      "rotation": 2
    },
    {
      "x": -2,
      "y": 4,
      "z": -6,
      "name": "Wood_Softwood_Roof",
      "rotation": 2
    },
    {
      "x": -2,
      "y": 0,
      "z": -5,
      "name": "Rock_Stone_Cobble"
    },
    {
      "x": -2,
      "y": 1,
      "z": -5,
      "name": "Wood_Beech_Trunk",
      "support": 15
    },
    {
      "x": -2,
      "y": 2,
      "z": -5,
      "name": "Wood_Beech_Trunk",
      "support": 15
    },
    {
      "x": -2,
      "y": 3,
      "z": -5,
      "name": "Wood_Beech_Trunk",
      "support": 15
    },
    {
      "x": -2,
      "y": 4,
      "z": -5,
      "name": "Wood_Beech_Trunk",
      "support": 15
    },
    {
      "x": -2,
      "y": 5,
      "z": -5,
      "name": "Wood_Softwood_Roof",
      "rotation": 2
    },
    {
      "x": -2,
      "y": 0,
      "z": -4,
      "name": "Wood_Softwood_Planks"
    },
    {
      "x": -2,
      "y": 5,
      "z": -4,
      "name": "Wood_Softwood_Stairs",
      "rotation": 10
    },
    {
      "x": -2,
      "y": 6,
      "z": -4,
      "name": "Wood_Softwood_Roof",
      "rotation": 2
    },
    {
      "x": -2,
      "y": 0,
      "z": -3,
      "name": "Cloth_Block_Wool_Green",
      "support": 15
    },
    {
      "x": -2,
      "y": 6,
      "z": -3,
      "name": "Wood_Softwood_Stairs",
      "rotation": 10
    },
    {
      "x": -2,
      "y": 7,
      "z": -3,
      "name": "Wood_Softwood_Roof_Flat",
      "rotation": 2
    },
    {
      "x": -2,
      "y": 0,
      "z": -2,
      "name": "Cloth_Block_Wool_Green",
      "support": 15
    },
    {
      "x": -2,
      "y": 7,
      "z": -2,
      "name": "Wood_Softwood_Planks"
    },
    {
      "x": -2,
      "y": 8,
      "z": -2,
      "name": "Furniture_Village_Window"
    },
    {
      "x": -2,
      "y": 9,
      "z": -2,
      "name": "Wood_Softwood_Roof",
      "rotation": 2
    },
    {
      "x": -2,
      "y": 0,
      "z": -1,
      "name": "Cloth_Block_Wool_Green",
      "support": 15
    },
    {
      "x": -2,
      "y": 9,
      "z": -1,
      "name": "Wood_Softwood_Planks"
    },
    {
      "x": -2,
      "y": 10,
      "z": -1,
      "name": "Wood_Softwood_Roof_Flat",
      "rotation": 3
    },
    {
      "x": -2,
      "y": 0,
      "z": 0,
      "name": "Cloth_Block_Wool_Green",
      "support": 15
    },
    {
      "x": -2,
      "y": 7,
      "z": 0,
      "name": "Wood_Softwood_Planks"
    },
    {
      "x": -2,
      "y": 8,
      "z": 0,
      "name": "Furniture_Village_Window"
    },
    {
      "x": -2,
      "y": 9,
      "z": 0,
      "name": "Wood_Softwood_Roof"
    },
    {
      "x": -2,
      "y": 0,
      "z": 1,
      "name": "Cloth_Block_Wool_Green",
      "support": 15
    },
    {
      "x": -2,
      "y": 6,
      "z": 1,
      "name": "Wood_Softwood_Stairs",
      "rotation": 8
    },
    {
      "x": -2,
      "y": 7,
      "z": 1,
      "name": "Wood_Softwood_Roof_Flat",
      "rotation": 2
    },
    {
      "x": -2,
      "y": 0,
      "z": 2,
      "name": "Wood_Softwood_Planks"
    },
    {
      "x": -2,
      "y": 5,
      "z": 2,
      "name": "Wood_Softwood_Stairs",
      "rotation": 8
    },
    {
      "x": -2,
      "y": 6,
      "z": 2,
      "name": "Wood_Softwood_Roof"
    },
    {
      "x": -2,
      "y": 0,
      "z": 3,
      "name": "Rock_Stone_Cobble"
    },
    {
      "x": -2,
      "y": 1,
      "z": 3,
      "name": "Wood_Beech_Trunk",
      "support": 15
    },
    {
      "x": -2,
      "y": 2,
      "z": 3,
      "name": "Wood_Beech_Trunk",
      "support": 15
    },
    {
      "x": -2,
      "y": 3,
      "z": 3,
      "name": "Wood_Beech_Trunk",
      "support": 15
    },
    {
      "x": -2,
      "y": 4,
      "z": 3,
      "name": "Wood_Beech_Trunk",
      "support": 15
    },
    {
      "x": -2,
      "y": 5,
      "z": 3,
      "name": "*Wood_Softwood_Roof_State_Definitions_Inverted_Corner_Right",
      "rotation": 1
    },
    {
      "x": -2,
      "y": 0,
      "z": 4,
      "name": "Rock_Stone_Cobble"
    },
    {
      "x": -2,
      "y": 1,
      "z": 4,
      "name": "Rock_Stone_Brick_Mossy"
    },
    {
      "x": -2,
      "y": 2,
      "z": 4,
      "name": "*Wood_Village_Wall_Full_State_Definitions_Bottom"
    },
    {
      "x": -2,
      "y": 3,
      "z": 4,
      "name": "*Wood_Village_Wall_Full_State_Definitions_Top"
    },
    {
      "x": -2,
      "y": 4,
      "z": 4,
      "name": "Wood_Beech_Trunk",
      "support": 15,
      "rotation": 4
    },
    {
      "x": -2,
      "y": 5,
      "z": 4,
      "name": "Wood_Softwood_Roof",
      "rotation": 1
    },
    {
      "x": -2,
      "y": 0,
      "z": 5,
      "name": "Rock_Stone_Cobble"
    },
    {
      "x": -2,
      "y": 1,
      "z": 5,
      "name": "Rock_Stone_Brick"
    },
    {
      "x": -2,
      "y": 2,
      "z": 5,
      "name": "*Wood_Village_Wall_Full_State_Definitions_Bottom"
    },
    {
      "x": -2,
      "y": 3,
      "z": 5,
      "name": "*Wood_Village_Wall_Full_State_Definitions_Top"
    },
    {
      "x": -2,
      "y": 4,
      "z": 5,
      "name": "Wood_Beech_Trunk",
      "support": 15,
      "rotation": 4
    },
    {
      "x": -2,
      "y": 5,
      "z": 5,
      "name": "Wood_Softwood_Roof",
      "rotation": 1
    },
    {
      "x": -2,
      "y": 0,
      "z": 6,
      "name": "Rock_Stone_Cobble"
    },
    {
      "x": -2,
      "y": 1,
      "z": 6,
      "name": "Wood_Beech_Trunk",
      "support": 15
    },
    {
      "x": -2,
      "y": 2,
      "z": 6,
      "name": "Wood_Beech_Trunk",
      "support": 15
    },
    {
      "x": -2,
      "y": 3,
      "z": 6,
      "name": "Wood_Beech_Trunk",
      "support": 15
    },
    {
      "x": -2,
      "y": 4,
      "z": 6,
      "name": "Wood_Beech_Trunk",
      "support": 15
    },
    {
      "x": -2,
      "y": 5,
      "z": 6,
      "name": "Wood_Softwood_Roof",
      "rotation": 1
    },
    {
      "x": -2,
      "y": 0,
      "z": 7,
      "name": "Rock_Stone_Cobble"
    },
    {
      "x": -2,
      "y": 4,
      "z": 7,
      "name": "Wood_Beech_Branch_Corner",
      "support": 15
    },
    {
      "x": -2,
      "y": 5,
      "z": 7,
      "name": "Wood_Softwood_Roof",
      "rotation": 1
    },
    {
      "x": -1,
      "y": 0,
      "z": -6,
      "name": "Rock_Stone_Cobble"
    },
    {
      "x": -1,
      "y": 4,
      "z": -6,
      "name": "Wood_Softwood_Roof_Hollow",
      "rotation": 2
    },
    {
      "x": -1,
      "y": 0,
      "z": -5,
      "name": "Rock_Stone_Cobble_Mossy"
    },
    {
      "x": -1,
      "y": 1,
      "z": -5,
      "name": "Rock_Stone_Brick"
    },
    {
      "x": -1,
      "y": 2,
      "z": -5,
      "name": "*Wood_Village_Wall_Full_State_Definitions_Bottom"
    },
    {
      "x": -1,
      "y": 3,
      "z": -5,
      "name": "*Wood_Village_Wall_Full_State_Definitions_Top"
    },
    {
      "x": -1,
      "y": 4,
      "z": -5,
      "name": "Wood_Beech_Trunk",
      "support": 15,
      "rotation": 5
    },
    {
      "x": -1,
      "y": 5,
      "z": -5,
      "name": "Wood_Softwood_Roof",
      "rotation": 2
    },
    {
      "x": -1,
      "y": 0,
      "z": -4,
      "name": "Wood_Softwood_Planks"
    },
    {
      "x": -1,
      "y": 1,
      "z": -4,
      "name": "Aetherhaven_Production_Storage",
      "support": 15,
      "filler": 31
    },
    {
      "x": -1,
      "y": 2,
      "z": -4,
      "name": "Aetherhaven_Production_Storage",
      "support": 15,
      "filler": 1055
    },
    {
      "x": -1,
      "y": 5,
      "z": -4,
      "name": "Wood_Softwood_Stairs",
      "rotation": 10
    },
    {
      "x": -1,
      "y": 6,
      "z": -4,
      "name": "Wood_Softwood_Roof",
      "rotation": 2
    },
    {
      "x": -1,
      "y": 0,
      "z": -3,
      "name": "Cloth_Block_Wool_Green"
    },
    {
      "x": -1,
      "y": 6,
      "z": -3,
      "name": "Wood_Softwood_Stairs",
      "rotation": 10
    },
    {
      "x": -1,
      "y": 7,
      "z": -3,
      "name": "Wood_Softwood_Roof_Flat",
      "rotation": 2
    },
    {
      "x": -1,
      "y": 0,
      "z": -2,
      "name": "Cloth_Block_Wool_Green"
    },
    {
      "x": -1,
      "y": 7,
      "z": -2,
      "name": "Wood_Softwood_Planks"
    },
    {
      "x": -1,
      "y": 8,
      "z": -2,
      "name": "Furniture_Village_Window"
    },
    {
      "x": -1,
      "y": 9,
      "z": -2,
      "name": "Wood_Softwood_Roof",
      "rotation": 2
    },
    {
      "x": -1,
      "y": 0,
      "z": -1,
      "name": "Cloth_Block_Wool_Green"
    },
    {
      "x": -1,
      "y": 9,
      "z": -1,
      "name": "Wood_Softwood_Planks"
    },
    {
      "x": -1,
      "y": 10,
      "z": -1,
      "name": "Wood_Softwood_Roof_Flat",
      "rotation": 3
    },
    {
      "x": -1,
      "y": 0,
      "z": 0,
      "name": "Cloth_Block_Wool_Green",
      "support": 15
    },
    {
      "x": -1,
      "y": 7,
      "z": 0,
      "name": "Wood_Softwood_Planks"
    },
    {
      "x": -1,
      "y": 8,
      "z": 0,
      "name": "Furniture_Village_Window"
    },
    {
      "x": -1,
      "y": 9,
      "z": 0,
      "name": "Wood_Softwood_Roof"
    },
    {
      "x": -1,
      "y": 0,
      "z": 1,
      "name": "Cloth_Block_Wool_Green",
      "support": 15
    },
    {
      "x": -1,
      "y": 6,
      "z": 1,
      "name": "Wood_Softwood_Stairs",
      "rotation": 8
    },
    {
      "x": -1,
      "y": 7,
      "z": 1,
      "name": "Wood_Softwood_Roof_Flat",
      "rotation": 2
    },
    {
      "x": -1,
      "y": 0,
      "z": 2,
      "name": "Wood_Softwood_Planks"
    },
    {
      "x": -1,
      "y": 5,
      "z": 2,
      "name": "Wood_Softwood_Stairs",
      "rotation": 8
    },
    {
      "x": -1,
      "y": 6,
      "z": 2,
      "name": "Wood_Softwood_Roof"
    },
    {
      "x": -1,
      "y": 0,
      "z": 3,
      "name": "Rock_Stone_Cobble_Mossy"
    },
    {
      "x": -1,
      "y": 1,
      "z": 3,
      "name": "Rock_Stone_Brick"
    },
    {
      "x": -1,
      "y": 2,
      "z": 3,
      "name": "*Wood_Village_Wall_Full_State_Definitions_Bottom"
    },
    {
      "x": -1,
      "y": 3,
      "z": 3,
      "name": "*Wood_Village_Wall_Full_State_Definitions_Top"
    },
    {
      "x": -1,
      "y": 4,
      "z": 3,
      "name": "Wood_Beech_Trunk",
      "support": 15,
      "rotation": 5
    },
    {
      "x": -1,
      "y": 5,
      "z": 3,
      "name": "Wood_Softwood_Roof"
    },
    {
      "x": -1,
      "y": 0,
      "z": 4,
      "name": "Rock_Stone_Cobble"
    },
    {
      "x": -1,
      "y": 1,
      "z": 4,
      "name": "Furniture_Village_Crate"
    },
    {
      "x": -1,
      "y": 2,
      "z": 4,
      "name": "Furniture_Village_Crate"
    },
    {
      "x": -1,
      "y": 4,
      "z": 4,
      "name": "*Wood_Softwood_Roof_Hollow_State_Definitions_Inverted_Corner_Right",
      "rotation": 1
    },
    {
      "x": -1,
      "y": 0,
      "z": 5,
      "name": "Rock_Stone_Cobble"
    },
    {
      "x": -1,
      "y": 1,
      "z": 5,
      "name": "Furniture_Tavern_Barrel",
      "support": 15
    },
    {
      "x": -1,
      "y": 4,
      "z": 5,
      "name": "Wood_Softwood_Roof_Hollow",
      "rotation": 1
    },
    {
      "x": -1,
      "y": 0,
      "z": 6,
      "name": "Rock_Stone_Cobble_Mossy"
    },
    {
      "x": -1,
      "y": 3,
      "z": 6,
      "name": "Wood_Beech_Branch_Corner",
      "support": 15,
      "rotation": 1
    },
    {
      "x": -1,
      "y": 4,
      "z": 6,
      "name": "Wood_Softwood_Roof",
      "rotation": 1
    },
    {
      "x": -1,
      "y": 0,
      "z": 7,
      "name": "Rock_Stone_Cobble"
    },
    {
      "x": -1,
      "y": 4,
      "z": 7,
      "name": "Wood_Softwood_Roof_Hollow",
      "rotation": 1
    },
    {
      "x": 0,
      "y": 0,
      "z": -6,
      "name": "Rock_Stone_Cobble"
    },
    {
      "x": 0,
      "y": 4,
      "z": -6,
      "name": "Wood_Softwood_Roof_Hollow",
      "rotation": 2
    },
    {
      "x": 0,
      "y": 0,
      "z": -5,
      "name": "Rock_Stone_Cobble"
    },
    {
      "x": 0,
      "y": 1,
      "z": -5,
      "name": "Rock_Stone_Brick"
    },
    {
      "x": 0,
      "y": 2,
      "z": -5,
      "name": "Furniture_Village_Window"
    },
    {
      "x": 0,
      "y": 3,
      "z": -5,
      "name": "Furniture_Village_Window"
    },
    {
      "x": 0,
      "y": 4,
      "z": -5,
      "name": "Wood_Beech_Trunk",
      "support": 15,
      "rotation": 5
    },
    {
      "x": 0,
      "y": 5,
      "z": -5,
      "name": "Wood_Softwood_Roof",
      "rotation": 2
    },
    {
      "x": 0,
      "y": 0,
      "z": -4,
      "name": "Wood_Softwood_Planks"
    },
    {
      "x": 0,
      "y": 1,
      "z": -4,
      "name": "Aetherhaven_Production_Storage",
      "support": 15
    },
    {
      "x": 0,
      "y": 2,
      "z": -4,
      "name": "Aetherhaven_Production_Storage",
      "support": 15,
      "filler": 1024
    },
    {
      "x": 0,
      "y": 5,
      "z": -4,
      "name": "Wood_Softwood_Stairs",
      "rotation": 10
    },
    {
      "x": 0,
      "y": 6,
      "z": -4,
      "name": "Wood_Softwood_Roof",
      "rotation": 2
    },
    {
      "x": 0,
      "y": 0,
      "z": -3,
      "name": "Cloth_Block_Wool_Green"
    },
    {
      "x": 0,
      "y": 6,
      "z": -3,
      "name": "Wood_Softwood_Stairs",
      "rotation": 10
    },
    {
      "x": 0,
      "y": 7,
      "z": -3,
      "name": "Wood_Softwood_Roof_Flat",
      "rotation": 2
    },
    {
      "x": 0,
      "y": 0,
      "z": -2,
      "name": "Cloth_Block_Wool_Green"
    },
    {
      "x": 0,
      "y": 7,
      "z": -2,
      "name": "Wood_Softwood_Planks"
    },
    {
      "x": 0,
      "y": 8,
      "z": -2,
      "name": "Wood_Village_Wall_Full"
    },
    {
      "x": 0,
      "y": 9,
      "z": -2,
      "name": "Wood_Softwood_Roof",
      "rotation": 2
    },
    {
      "x": 0,
      "y": 0,
      "z": -1,
      "name": "Cloth_Block_Wool_Green"
    },
    {
      "x": 0,
      "y": 5,
      "z": -1,
      "name": "Deco_Lantern_Ceiling",
      "support": 15
    },
    {
      "x": 0,
      "y": 6,
      "z": -1,
      "name": "Deco_Iron_Chain_Small"
    },
    {
      "x": 0,
      "y": 7,
      "z": -1,
      "name": "Deco_Iron_Chain_Small"
    },
    {
      "x": 0,
      "y": 8,
      "z": -1,
      "name": "Deco_Iron_Chain_Small"
    },
    {
      "x": 0,
      "y": 9,
      "z": -1,
      "name": "Wood_Softwood_Planks"
    },
    {
      "x": 0,
      "y": 10,
      "z": -1,
      "name": "Wood_Softwood_Roof_Flat",
      "rotation": 3
    },
    {
      "x": 0,
      "y": 0,
      "z": 0,
      "name": "Cloth_Block_Wool_Green",
      "support": 15
    },
    {
      "x": 0,
      "y": 7,
      "z": 0,
      "name": "Wood_Softwood_Planks"
    },
    {
      "x": 0,
      "y": 8,
      "z": 0,
      "name": "Wood_Village_Wall_Full"
    },
    {
      "x": 0,
      "y": 9,
      "z": 0,
      "name": "Wood_Softwood_Roof"
    },
    {
      "x": 0,
      "y": 0,
      "z": 1,
      "name": "Cloth_Block_Wool_Green",
      "support": 15
    },
    {
      "x": 0,
      "y": 1,
      "z": 1,
      "name": "Furniture_Tavern_Bed",
      "support": 15,
      "filler": 30,
      "rotation": 3
    },
    {
      "x": 0,
      "y": 2,
      "z": 1,
      "name": "Furniture_Tavern_Bed",
      "support": 15,
      "filler": 1054,
      "rotation": 3
    },
    {
      "x": 0,
      "y": 6,
      "z": 1,
      "name": "Wood_Softwood_Stairs",
      "rotation": 8
    },
    {
      "x": 0,
      "y": 7,
      "z": 1,
      "name": "Wood_Softwood_Roof_Flat",
      "rotation": 2
    },
    {
      "x": 0,
      "y": 0,
      "z": 2,
      "name": "Wood_Softwood_Planks"
    },
    {
      "x": 0,
      "y": 1,
      "z": 2,
      "name": "Furniture_Tavern_Bed",
      "support": 15,
      "filler": 62,
      "rotation": 3
    },
    {
      "x": 0,
      "y": 2,
      "z": 2,
      "name": "Furniture_Tavern_Bed",
      "support": 15,
      "filler": 1086,
      "rotation": 3
    },
    {
      "x": 0,
      "y": 5,
      "z": 2,
      "name": "Wood_Softwood_Stairs",
      "rotation": 8
    },
    {
      "x": 0,
      "y": 6,
      "z": 2,
      "name": "Wood_Softwood_Roof"
    },
    {
      "x": 0,
      "y": 0,
      "z": 3,
      "name": "Rock_Stone_Cobble"
    },
    {
      "x": 0,
      "y": 1,
      "z": 3,
      "name": "Rock_Stone_Brick"
    },
    {
      "x": 0,
      "y": 2,
      "z": 3,
      "name": "Furniture_Village_Window"
    },
    {
      "x": 0,
      "y": 3,
      "z": 3,
      "name": "Furniture_Village_Window"
    },
    {
      "x": 0,
      "y": 4,
      "z": 3,
      "name": "Wood_Beech_Trunk",
      "support": 15,
      "rotation": 5
    },
    {
      "x": 0,
      "y": 5,
      "z": 3,
      "name": "Wood_Softwood_Roof"
    },
    {
      "x": 0,
      "y": 0,
      "z": 4,
      "name": "Rock_Stone_Cobble"
    },
    {
      "x": 0,
      "y": 1,
      "z": 4,
      "name": "Furniture_Village_Crate"
    },
    {
      "x": 0,
      "y": 4,
      "z": 4,
      "name": "Wood_Softwood_Roof_Hollow"
    },
    {
      "x": 1,
      "y": 0,
      "z": -6,
      "name": "Rock_Stone_Cobble"
    },
    {
      "x": 1,
      "y": 1,
      "z": -6,
      "name": "Furniture_Tavern_Barrel",
      "support": 15
    },
    {
      "x": 1,
      "y": 4,
      "z": -6,
      "name": "Wood_Softwood_Roof_Hollow",
      "rotation": 2
    },
    {
      "x": 1,
      "y": 0,
      "z": -5,
      "name": "Rock_Stone_Cobble"
    },
    {
      "x": 1,
      "y": 1,
      "z": -5,
      "name": "Rock_Stone_Brick_Mossy"
    },
    {
      "x": 1,
      "y": 2,
      "z": -5,
      "name": "Furniture_Village_Window"
    },
    {
      "x": 1,
      "y": 3,
      "z": -5,
      "name": "Furniture_Village_Window"
    },
    {
      "x": 1,
      "y": 4,
      "z": -5,
      "name": "Wood_Beech_Trunk",
      "support": 15,
      "rotation": 5
    },
    {
      "x": 1,
      "y": 5,
      "z": -5,
      "name": "Wood_Softwood_Roof",
      "rotation": 2
    },
    {
      "x": 1,
      "y": 0,
      "z": -4,
      "name": "Wood_Softwood_Planks"
    },
    {
      "x": 1,
      "y": 1,
      "z": -4,
      "name": "Furniture_Human_Ruins_Chair",
      "components": {
        "Components": {}
      },
      "support": 15
    },
    {
      "x": 1,
      "y": 2,
      "z": -4,
      "name": "Furniture_Human_Ruins_Chair",
      "support": 15,
      "filler": 1024
    },
    {
      "x": 1,
      "y": 5,
      "z": -4,
      "name": "Wood_Softwood_Stairs",
      "rotation": 10
    },
    {
      "x": 1,
      "y": 6,
      "z": -4,
      "name": "Wood_Softwood_Roof",
      "rotation": 2
    },
    {
      "x": 1,
      "y": 0,
      "z": -3,
      "name": "Cloth_Block_Wool_Green",
      "support": 15
    },
    {
      "x": 1,
      "y": 6,
      "z": -3,
      "name": "Wood_Softwood_Stairs",
      "rotation": 10
    },
    {
      "x": 1,
      "y": 7,
      "z": -3,
      "name": "Wood_Softwood_Roof_Flat",
      "rotation": 2
    },
    {
      "x": 1,
      "y": 0,
      "z": -2,
      "name": "Cloth_Block_Wool_Green",
      "support": 15
    },
    {
      "x": 1,
      "y": 7,
      "z": -2,
      "name": "Wood_Softwood_Planks"
    },
    {
      "x": 1,
      "y": 8,
      "z": -2,
      "name": "Furniture_Village_Window"
    },
    {
      "x": 1,
      "y": 9,
      "z": -2,
      "name": "Wood_Softwood_Roof",
      "rotation": 2
    },
    {
      "x": 1,
      "y": 0,
      "z": -1,
      "name": "Cloth_Block_Wool_Green"
    },
    {
      "x": 1,
      "y": 9,
      "z": -1,
      "name": "Wood_Softwood_Planks"
    },
    {
      "x": 1,
      "y": 10,
      "z": -1,
      "name": "Wood_Softwood_Roof_Flat",
      "rotation": 3
    },
    {
      "x": 1,
      "y": 0,
      "z": 0,
      "name": "Cloth_Block_Wool_Green",
      "support": 15
    },
    {
      "x": 1,
      "y": 7,
      "z": 0,
      "name": "Wood_Softwood_Planks"
    },
    {
      "x": 1,
      "y": 8,
      "z": 0,
      "name": "Furniture_Village_Window"
    },
    {
      "x": 1,
      "y": 9,
      "z": 0,
      "name": "Wood_Softwood_Roof"
    },
    {
      "x": 1,
      "y": 0,
      "z": 1,
      "name": "Cloth_Block_Wool_Green",
      "support": 15
    },
    {
      "x": 1,
      "y": 1,
      "z": 1,
      "name": "Furniture_Tavern_Bed",
      "support": 15,
      "filler": 31,
      "rotation": 3
    },
    {
      "x": 1,
      "y": 2,
      "z": 1,
      "name": "Furniture_Tavern_Bed",
      "support": 15,
      "filler": 1055,
      "rotation": 3
    },
    {
      "x": 1,
      "y": 6,
      "z": 1,
      "name": "Wood_Softwood_Stairs",
      "rotation": 8
    },
    {
      "x": 1,
      "y": 7,
      "z": 1,
      "name": "Wood_Softwood_Roof_Flat",
      "rotation": 2
    },
    {
      "x": 1,
      "y": 0,
      "z": 2,
      "name": "Wood_Softwood_Planks"
    },
    {
      "x": 1,
      "y": 1,
      "z": 2,
      "name": "Furniture_Tavern_Bed",
      "support": 15,
      "filler": 63,
      "rotation": 3
    },
    {
      "x": 1,
      "y": 2,
      "z": 2,
      "name": "Furniture_Tavern_Bed",
      "support": 15,
      "filler": 1087,
      "rotation": 3
    },
    {
      "x": 1,
      "y": 5,
      "z": 2,
      "name": "Wood_Softwood_Stairs",
      "rotation": 8
    },
    {
      "x": 1,
      "y": 6,
      "z": 2,
      "name": "Wood_Softwood_Roof"
    },
    {
      "x": 1,
      "y": 0,
      "z": 3,
      "name": "Rock_Stone_Cobble"
    },
    {
      "x": 1,
      "y": 1,
      "z": 3,
      "name": "Rock_Stone_Brick_Mossy"
    },
    {
      "x": 1,
      "y": 2,
      "z": 3,
      "name": "Furniture_Village_Window"
    },
    {
      "x": 1,
      "y": 3,
      "z": 3,
      "name": "Furniture_Village_Window"
    },
    {
      "x": 1,
      "y": 4,
      "z": 3,
      "name": "Wood_Beech_Trunk",
      "support": 15,
      "rotation": 5
    },
    {
      "x": 1,
      "y": 5,
      "z": 3,
      "name": "Wood_Softwood_Roof"
    },
    {
      "x": 1,
      "y": 0,
      "z": 4,
      "name": "Rock_Stone_Cobble"
    },
    {
      "x": 1,
      "y": 4,
      "z": 4,
      "name": "Wood_Softwood_Roof_Hollow"
    },
    {
      "x": 2,
      "y": 0,
      "z": -6,
      "name": "Rock_Stone_Cobble"
    },
    {
      "x": 2,
      "y": 1,
      "z": -6,
      "name": "Furniture_Tavern_Barrel",
      "support": 15
    },
    {
      "x": 2,
      "y": 4,
      "z": -6,
      "name": "Wood_Softwood_Roof_Hollow",
      "rotation": 2
    },
    {
      "x": 2,
      "y": 0,
      "z": -5,
      "name": "Rock_Stone_Cobble"
    },
    {
      "x": 2,
      "y": 1,
      "z": -5,
      "name": "Rock_Stone_Brick_Mossy"
    },
    {
      "x": 2,
      "y": 2,
      "z": -5,
      "name": "*Wood_Village_Wall_Full_State_Definitions_Bottom"
    },
    {
      "x": 2,
      "y": 3,
      "z": -5,
      "name": "*Wood_Village_Wall_Full_State_Definitions_Top"
    },
    {
      "x": 2,
      "y": 4,
      "z": -5,
      "name": "Wood_Beech_Trunk",
      "support": 15,
      "rotation": 5
    },
    {
      "x": 2,
      "y": 5,
      "z": -5,
      "name": "Wood_Softwood_Roof",
      "rotation": 2
    },
    {
      "x": 2,
      "y": 0,
      "z": -4,
      "name": "Wood_Softwood_Planks"
    },
    {
      "x": 2,
      "y": 1,
      "z": -4,
      "name": "Furniture_Tavern_Chair",
      "components": {
        "Components": {}
      },
      "support": 15
    },
    {
      "x": 2,
      "y": 5,
      "z": -4,
      "name": "Wood_Softwood_Stairs",
      "rotation": 10
    },
    {
      "x": 2,
      "y": 6,
      "z": -4,
      "name": "Wood_Softwood_Roof",
      "rotation": 2
    },
    {
      "x": 2,
      "y": 0,
      "z": -3,
      "name": "Cloth_Block_Wool_Green",
      "support": 15
    },
    {
      "x": 2,
      "y": 6,
      "z": -3,
      "name": "Wood_Softwood_Stairs",
      "rotation": 10
    },
    {
      "x": 2,
      "y": 7,
      "z": -3,
      "name": "Wood_Softwood_Roof_Flat",
      "rotation": 2
    },
    {
      "x": 2,
      "y": 0,
      "z": -2,
      "name": "Cloth_Block_Wool_Green",
      "support": 15
    },
    {
      "x": 2,
      "y": 7,
      "z": -2,
      "name": "Wood_Softwood_Planks"
    },
    {
      "x": 2,
      "y": 8,
      "z": -2,
      "name": "Furniture_Village_Window"
    },
    {
      "x": 2,
      "y": 9,
      "z": -2,
      "name": "Wood_Softwood_Roof",
      "rotation": 2
    },
    {
      "x": 2,
      "y": 0,
      "z": -1,
      "name": "Cloth_Block_Wool_Green"
    },
    {
      "x": 2,
      "y": 9,
      "z": -1,
      "name": "Wood_Softwood_Planks"
    },
    {
      "x": 2,
      "y": 10,
      "z": -1,
      "name": "Wood_Softwood_Roof_Flat",
      "rotation": 3
    },
    {
      "x": 2,
      "y": 0,
      "z": 0,
      "name": "Cloth_Block_Wool_Green",
      "support": 15
    },
    {
      "x": 2,
      "y": 7,
      "z": 0,
      "name": "Wood_Softwood_Planks"
    },
    {
      "x": 2,
      "y": 8,
      "z": 0,
      "name": "Furniture_Village_Window"
    },
    {
      "x": 2,
      "y": 9,
      "z": 0,
      "name": "Wood_Softwood_Roof"
    },
    {
      "x": 2,
      "y": 0,
      "z": 1,
      "name": "Cloth_Block_Wool_Green",
      "support": 15
    },
    {
      "x": 2,
      "y": 1,
      "z": 1,
      "name": "Furniture_Tavern_Bed",
      "components": {
        "Components": {
          "PlacedByInteraction": {
            "WhoPlacedUuid": {
              "$binary": "v7RyWIT/TYKnXA2XcxdQtw==",
              "$type": "04"
            }
          },
          "RespawnBlock": {}
        }
      },
      "support": 15,
      "rotation": 3
    },
    {
      "x": 2,
      "y": 2,
      "z": 1,
      "name": "Furniture_Tavern_Bed",
      "support": 15,
      "filler": 1024,
      "rotation": 3
    },
    {
      "x": 2,
      "y": 6,
      "z": 1,
      "name": "Wood_Softwood_Stairs",
      "rotation": 8
    },
    {
      "x": 2,
      "y": 7,
      "z": 1,
      "name": "Wood_Softwood_Roof_Flat",
      "rotation": 2
    },
    {
      "x": 2,
      "y": 0,
      "z": 2,
      "name": "Wood_Softwood_Planks"
    },
    {
      "x": 2,
      "y": 1,
      "z": 2,
      "name": "Furniture_Tavern_Bed",
      "support": 15,
      "filler": 32,
      "rotation": 3
    },
    {
      "x": 2,
      "y": 2,
      "z": 2,
      "name": "Furniture_Tavern_Bed",
      "support": 15,
      "filler": 1056,
      "rotation": 3
    },
    {
      "x": 2,
      "y": 5,
      "z": 2,
      "name": "Wood_Softwood_Stairs",
      "rotation": 8
    },
    {
      "x": 2,
      "y": 6,
      "z": 2,
      "name": "Wood_Softwood_Roof"
    },
    {
      "x": 2,
      "y": 0,
      "z": 3,
      "name": "Rock_Stone_Cobble"
    },
    {
      "x": 2,
      "y": 1,
      "z": 3,
      "name": "Rock_Stone_Brick"
    },
    {
      "x": 2,
      "y": 2,
      "z": 3,
      "name": "*Wood_Village_Wall_Full_State_Definitions_Bottom"
    },
    {
      "x": 2,
      "y": 3,
      "z": 3,
      "name": "*Wood_Village_Wall_Full_State_Definitions_Top"
    },
    {
      "x": 2,
      "y": 4,
      "z": 3,
      "name": "Wood_Beech_Trunk",
      "support": 15,
      "rotation": 5
    },
    {
      "x": 2,
      "y": 5,
      "z": 3,
      "name": "Wood_Softwood_Roof"
    },
    {
      "x": 2,
      "y": 0,
      "z": 4,
      "name": "Rock_Stone_Cobble"
    },
    {
      "x": 2,
      "y": 3,
      "z": 4,
      "name": "Plant_Vine_Wall",
      "support": 15
    },
    {
      "x": 2,
      "y": 4,
      "z": 4,
      "name": "Wood_Softwood_Roof_Hollow"
    },
    {
      "x": 3,
      "y": 0,
      "z": -6,
      "name": "Rock_Stone_Cobble"
    },
    {
      "x": 3,
      "y": 2,
      "z": -6,
      "name": "Plant_Vine_Wall",
      "support": 15,
      "rotation": 2
    },
    {
      "x": 3,
      "y": 3,
      "z": -6,
      "name": "Plant_Vine_Wall",
      "support": 15,
      "rotation": 2
    },
    {
      "x": 3,
      "y": 4,
      "z": -6,
      "name": "Wood_Softwood_Roof_Hollow",
      "rotation": 2
    },
    {
      "x": 3,
      "y": 0,
      "z": -5,
      "name": "Rock_Stone_Cobble_Mossy"
    },
    {
      "x": 3,
      "y": 1,
      "z": -5,
      "name": "Rock_Stone_Brick"
    },
    {
      "x": 3,
      "y": 2,
      "z": -5,
      "name": "*Wood_Village_Wall_Full_State_Definitions_Bottom"
    },
    {
      "x": 3,
      "y": 3,
      "z": -5,
      "name": "*Wood_Village_Wall_Full_State_Definitions_Top"
    },
    {
      "x": 3,
      "y": 4,
      "z": -5,
      "name": "Wood_Beech_Trunk",
      "support": 15,
      "rotation": 5
    },
    {
      "x": 3,
      "y": 5,
      "z": -5,
      "name": "Wood_Softwood_Roof",
      "rotation": 2
    },
    {
      "x": 3,
      "y": 0,
      "z": -4,
      "name": "Wood_Softwood_Planks"
    },
    {
      "x": 3,
      "y": 1,
      "z": -4,
      "name": "Furniture_Lumberjack_Chair",
      "components": {
        "Components": {}
      },
      "support": 15
    },
    {
      "x": 3,
      "y": 5,
      "z": -4,
      "name": "Wood_Softwood_Stairs",
      "rotation": 10
    },
    {
      "x": 3,
      "y": 6,
      "z": -4,
      "name": "Wood_Softwood_Roof",
      "rotation": 2
    },
    {
      "x": 3,
      "y": 0,
      "z": -3,
      "name": "Cloth_Block_Wool_Green",
      "support": 15
    },
    {
      "x": 3,
      "y": 6,
      "z": -3,
      "name": "Wood_Softwood_Stairs",
      "rotation": 10
    },
    {
      "x": 3,
      "y": 7,
      "z": -3,
      "name": "Wood_Softwood_Roof_Flat",
      "rotation": 2
    },
    {
      "x": 3,
      "y": 0,
      "z": -2,
      "name": "Cloth_Block_Wool_Green",
      "support": 15
    },
    {
      "x": 3,
      "y": 7,
      "z": -2,
      "name": "Wood_Softwood_Planks"
    },
    {
      "x": 3,
      "y": 8,
      "z": -2,
      "name": "Wood_Village_Wall_Full"
    },
    {
      "x": 3,
      "y": 9,
      "z": -2,
      "name": "Wood_Softwood_Roof",
      "rotation": 2
    },
    {
      "x": 3,
      "y": 0,
      "z": -1,
      "name": "Cloth_Block_Wool_Green"
    },
    {
      "x": 3,
      "y": 5,
      "z": -1,
      "name": "Deco_Lantern_Ceiling",
      "support": 15
    },
    {
      "x": 3,
      "y": 6,
      "z": -1,
      "name": "Deco_Iron_Chain_Small"
    },
    {
      "x": 3,
      "y": 7,
      "z": -1,
      "name": "Deco_Iron_Chain_Small"
    },
    {
      "x": 3,
      "y": 8,
      "z": -1,
      "name": "Deco_Iron_Chain_Small"
    },
    {
      "x": 3,
      "y": 9,
      "z": -1,
      "name": "Wood_Softwood_Planks"
    },
    {
      "x": 3,
      "y": 10,
      "z": -1,
      "name": "Wood_Softwood_Roof_Flat",
      "rotation": 3
    },
    {
      "x": 3,
      "y": 0,
      "z": 0,
      "name": "Cloth_Block_Wool_Green",
      "support": 15
    },
    {
      "x": 3,
      "y": 7,
      "z": 0,
      "name": "Wood_Softwood_Planks"
    },
    {
      "x": 3,
      "y": 8,
      "z": 0,
      "name": "Wood_Village_Wall_Full"
    },
    {
      "x": 3,
      "y": 9,
      "z": 0,
      "name": "Wood_Softwood_Roof"
    },
    {
      "x": 3,
      "y": 0,
      "z": 1,
      "name": "Cloth_Block_Wool_Green",
      "support": 15
    },
    {
      "x": 3,
      "y": 1,
      "z": 1,
      "name": "Furniture_Village_Table",
      "support": 15,
      "filler": 1023,
      "rotation": 2
    },
    {
      "x": 3,
      "y": 6,
      "z": 1,
      "name": "Wood_Softwood_Stairs",
      "rotation": 8
    },
    {
      "x": 3,
      "y": 7,
      "z": 1,
      "name": "Wood_Softwood_Roof_Flat",
      "rotation": 2
    },
    {
      "x": 3,
      "y": 0,
      "z": 2,
      "name": "Wood_Softwood_Planks"
    },
    {
      "x": 3,
      "y": 1,
      "z": 2,
      "name": "Furniture_Village_Table",
      "support": 15,
      "filler": 31,
      "rotation": 2
    },
    {
      "x": 3,
      "y": 2,
      "z": 2,
      "name": "Furniture_Village_Stool",
      "support": 15,
      "rotation": 2
    },
    {
      "x": 3,
      "y": 5,
      "z": 2,
      "name": "Wood_Softwood_Stairs",
      "rotation": 8
    },
    {
      "x": 3,
      "y": 6,
      "z": 2,
      "name": "Wood_Softwood_Roof"
    },
    {
      "x": 3,
      "y": 0,
      "z": 3,
      "name": "Rock_Stone_Cobble"
    },
    {
      "x": 3,
      "y": 1,
      "z": 3,
      "name": "Rock_Stone_Brick"
    },
    {
      "x": 3,
      "y": 2,
      "z": 3,
      "name": "*Wood_Village_Wall_Full_State_Definitions_Bottom"
    },
    {
      "x": 3,
      "y": 3,
      "z": 3,
      "name": "*Wood_Village_Wall_Full_State_Definitions_Top"
    },
    {
      "x": 3,
      "y": 4,
      "z": 3,
      "name": "Wood_Beech_Trunk",
      "support": 15,
      "rotation": 5
    },
    {
      "x": 3,
      "y": 5,
      "z": 3,
      "name": "Wood_Softwood_Roof"
    },
    {
      "x": 3,
      "y": 0,
      "z": 4,
      "name": "Rock_Stone_Cobble"
    },
    {
      "x": 3,
      "y": 4,
      "z": 4,
      "name": "Wood_Softwood_Roof_Hollow"
    },
    {
      "x": 4,
      "y": 0,
      "z": -6,
      "name": "Rock_Stone_Cobble"
    },
    {
      "x": 4,
      "y": 4,
      "z": -6,
      "name": "Wood_Softwood_Roof_Hollow",
      "rotation": 2
    },
    {
      "x": 4,
      "y": 0,
      "z": -5,
      "name": "Rock_Stone_Cobble"
    },
    {
      "x": 4,
      "y": 1,
      "z": -5,
      "name": "Rock_Stone_Brick"
    },
    {
      "x": 4,
      "y": 2,
      "z": -5,
      "name": "*Wood_Village_Wall_Full_State_Definitions_Bottom"
    },
    {
      "x": 4,
      "y": 3,
      "z": -5,
      "name": "*Wood_Village_Wall_Full_State_Definitions_Top"
    },
    {
      "x": 4,
      "y": 4,
      "z": -5,
      "name": "Wood_Beech_Trunk",
      "support": 15,
      "rotation": 5
    },
    {
      "x": 4,
      "y": 5,
      "z": -5,
      "name": "Wood_Softwood_Roof",
      "rotation": 2
    },
    {
      "x": 4,
      "y": 0,
      "z": -4,
      "name": "Wood_Softwood_Planks"
    },
    {
      "x": 4,
      "y": 1,
      "z": -4,
      "name": "Furniture_Village_Chair",
      "components": {
        "Components": {}
      },
      "support": 15
    },
    {
      "x": 4,
      "y": 2,
      "z": -4,
      "name": "Furniture_Village_Chair",
      "support": 15,
      "filler": 1024
    },
    {
      "x": 4,
      "y": 5,
      "z": -4,
      "name": "Wood_Softwood_Stairs",
      "rotation": 10
    },
    {
      "x": 4,
      "y": 6,
      "z": -4,
      "name": "Wood_Softwood_Roof",
      "rotation": 2
    },
    {
      "x": 4,
      "y": 0,
      "z": -3,
      "name": "Cloth_Block_Wool_Green",
      "support": 15
    },
    {
      "x": 4,
      "y": 6,
      "z": -3,
      "name": "Wood_Softwood_Stairs",
      "rotation": 10
    },
    {
      "x": 4,
      "y": 7,
      "z": -3,
      "name": "Wood_Softwood_Roof_Flat",
      "rotation": 2
    },
    {
      "x": 4,
      "y": 0,
      "z": -2,
      "name": "Cloth_Block_Wool_Green",
      "support": 15
    },
    {
      "x": 4,
      "y": 7,
      "z": -2,
      "name": "Wood_Softwood_Planks"
    },
    {
      "x": 4,
      "y": 8,
      "z": -2,
      "name": "Furniture_Village_Window"
    },
    {
      "x": 4,
      "y": 9,
      "z": -2,
      "name": "Wood_Softwood_Roof",
      "rotation": 2
    },
    {
      "x": 4,
      "y": 0,
      "z": -1,
      "name": "Cloth_Block_Wool_Green"
    },
    {
      "x": 4,
      "y": 9,
      "z": -1,
      "name": "Wood_Softwood_Planks"
    },
    {
      "x": 4,
      "y": 10,
      "z": -1,
      "name": "Wood_Softwood_Roof_Flat",
      "rotation": 3
    },
    {
      "x": 4,
      "y": 0,
      "z": 0,
      "name": "Cloth_Block_Wool_Green",
      "support": 15
    },
    {
      "x": 4,
      "y": 7,
      "z": 0,
      "name": "Wood_Softwood_Planks"
    },
    {
      "x": 4,
      "y": 8,
      "z": 0,
      "name": "Furniture_Village_Window"
    },
    {
      "x": 4,
      "y": 9,
      "z": 0,
      "name": "Wood_Softwood_Roof"
    },
    {
      "x": 4,
      "y": 0,
      "z": 1,
      "name": "Cloth_Block_Wool_Green",
      "support": 15
    },
    {
      "x": 4,
      "y": 1,
      "z": 1,
      "name": "Furniture_Village_Table",
      "support": 15,
      "filler": 992,
      "rotation": 2
    },
    {
      "x": 4,
      "y": 6,
      "z": 1,
      "name": "Wood_Softwood_Stairs",
      "rotation": 8
    },
    {
      "x": 4,
      "y": 7,
      "z": 1,
      "name": "Wood_Softwood_Roof_Flat",
      "rotation": 2
    },
    {
      "x": 4,
      "y": 0,
      "z": 2,
      "name": "Wood_Softwood_Planks"
    },
    {
      "x": 4,
      "y": 1,
      "z": 2,
      "name": "Furniture_Village_Table",
      "support": 15,
      "rotation": 2
    },
    {
      "x": 4,
      "y": 5,
      "z": 2,
      "name": "Wood_Softwood_Stairs",
      "rotation": 8
    },
    {
      "x": 4,
      "y": 6,
      "z": 2,
      "name": "Wood_Softwood_Roof"
    },
    {
      "x": 4,
      "y": 0,
      "z": 3,
      "name": "Rock_Stone_Cobble"
    },
    {
      "x": 4,
      "y": 1,
      "z": 3,
      "name": "Rock_Stone_Brick"
    },
    {
      "x": 4,
      "y": 2,
      "z": 3,
      "name": "*Wood_Village_Wall_Full_State_Definitions_Bottom"
    },
    {
      "x": 4,
      "y": 3,
      "z": 3,
      "name": "*Wood_Village_Wall_Full_State_Definitions_Top"
    },
    {
      "x": 4,
      "y": 4,
      "z": 3,
      "name": "Wood_Beech_Trunk",
      "support": 15,
      "rotation": 5
    },
    {
      "x": 4,
      "y": 5,
      "z": 3,
      "name": "Wood_Softwood_Roof"
    },
    {
      "x": 4,
      "y": 0,
      "z": 4,
      "name": "Rock_Stone_Cobble"
    },
    {
      "x": 4,
      "y": 2,
      "z": 4,
      "name": "Plant_Vine_Wall",
      "support": 15
    },
    {
      "x": 4,
      "y": 4,
      "z": 4,
      "name": "Wood_Softwood_Roof_Hollow"
    },
    {
      "x": 5,
      "y": 0,
      "z": -6,
      "name": "Rock_Stone_Cobble_Mossy"
    },
    {
      "x": 5,
      "y": 4,
      "z": -6,
      "name": "Wood_Softwood_Roof_Hollow",
      "rotation": 2
    },
    {
      "x": 5,
      "y": 0,
      "z": -5,
      "name": "Rock_Stone_Cobble"
    },
    {
      "x": 5,
      "y": 1,
      "z": -5,
      "name": "Rock_Stone_Brick"
    },
    {
      "x": 5,
      "y": 2,
      "z": -5,
      "name": "Furniture_Village_Window"
    },
    {
      "x": 5,
      "y": 3,
      "z": -5,
      "name": "Furniture_Village_Window"
    },
    {
      "x": 5,
      "y": 4,
      "z": -5,
      "name": "Wood_Beech_Trunk",
      "support": 15,
      "rotation": 5
    },
    {
      "x": 5,
      "y": 5,
      "z": -5,
      "name": "Wood_Softwood_Roof",
      "rotation": 2
    },
    {
      "x": 5,
      "y": 0,
      "z": -4,
      "name": "Wood_Softwood_Planks"
    },
    {
      "x": 5,
      "y": 1,
      "z": -4,
      "name": "Furniture_Kweebec_Wardrobe",
      "support": 15,
      "filler": 31
    },
    {
      "x": 5,
      "y": 2,
      "z": -4,
      "name": "Furniture_Kweebec_Wardrobe",
      "support": 15,
      "filler": 1055
    },
    {
      "x": 5,
      "y": 5,
      "z": -4,
      "name": "Wood_Softwood_Stairs",
      "rotation": 10
    },
    {
      "x": 5,
      "y": 6,
      "z": -4,
      "name": "Wood_Softwood_Roof",
      "rotation": 2
    },
    {
      "x": 5,
      "y": 0,
      "z": -3,
      "name": "Cloth_Block_Wool_Green",
      "support": 15
    },
    {
      "x": 5,
      "y": 6,
      "z": -3,
      "name": "Wood_Softwood_Stairs",
      "rotation": 10
    },
    {
      "x": 5,
      "y": 7,
      "z": -3,
      "name": "Wood_Softwood_Roof_Flat",
      "rotation": 2
    },
    {
      "x": 5,
      "y": 0,
      "z": -2,
      "name": "Cloth_Block_Wool_Green",
      "support": 15
    },
    {
      "x": 5,
      "y": 7,
      "z": -2,
      "name": "Wood_Softwood_Planks"
    },
    {
      "x": 5,
      "y": 8,
      "z": -2,
      "name": "Furniture_Village_Window"
    },
    {
      "x": 5,
      "y": 9,
      "z": -2,
      "name": "Wood_Softwood_Roof",
      "rotation": 2
    },
    {
      "x": 5,
      "y": 0,
      "z": -1,
      "name": "Cloth_Block_Wool_Green"
    },
    {
      "x": 5,
      "y": 9,
      "z": -1,
      "name": "Wood_Softwood_Planks"
    },
    {
      "x": 5,
      "y": 10,
      "z": -1,
      "name": "Wood_Softwood_Roof_Flat",
      "rotation": 3
    },
    {
      "x": 5,
      "y": 0,
      "z": 0,
      "name": "Cloth_Block_Wool_Green",
      "support": 15
    },
    {
      "x": 5,
      "y": 7,
      "z": 0,
      "name": "Wood_Softwood_Planks"
    },
    {
      "x": 5,
      "y": 8,
      "z": 0,
      "name": "Furniture_Village_Window"
    },
    {
      "x": 5,
      "y": 9,
      "z": 0,
      "name": "Wood_Softwood_Roof"
    },
    {
      "x": 5,
      "y": 0,
      "z": 1,
      "name": "Cloth_Block_Wool_Green",
      "support": 15
    },
    {
      "x": 5,
      "y": 1,
      "z": 1,
      "name": "Furniture_Human_Ruins_Bed",
      "support": 15,
      "filler": 992,
      "rotation": 1
    },
    {
      "x": 5,
      "y": 2,
      "z": 1,
      "name": "Furniture_Human_Ruins_Bed",
      "support": 15,
      "filler": 2016,
      "rotation": 1
    },
    {
      "x": 5,
      "y": 6,
      "z": 1,
      "name": "Wood_Softwood_Stairs",
      "rotation": 8
    },
    {
      "x": 5,
      "y": 7,
      "z": 1,
      "name": "Wood_Softwood_Roof_Flat",
      "rotation": 2
    },
    {
      "x": 5,
      "y": 0,
      "z": 2,
      "name": "Wood_Softwood_Planks"
    },
    {
      "x": 5,
      "y": 1,
      "z": 2,
      "name": "Furniture_Human_Ruins_Bed",
      "components": {
        "Components": {
          "PlacedByInteraction": {
            "WhoPlacedUuid": {
              "$binary": "v7RyWIT/TYKnXA2XcxdQtw==",
              "$type": "04"
            }
          },
          "RespawnBlock": {}
        }
      },
      "support": 15,
      "rotation": 1
    },
    {
      "x": 5,
      "y": 2,
      "z": 2,
      "name": "Furniture_Human_Ruins_Bed",
      "support": 15,
      "filler": 1024,
      "rotation": 1
    },
    {
      "x": 5,
      "y": 5,
      "z": 2,
      "name": "Wood_Softwood_Stairs",
      "rotation": 8
    },
    {
      "x": 5,
      "y": 6,
      "z": 2,
      "name": "Wood_Softwood_Roof"
    },
    {
      "x": 5,
      "y": 0,
      "z": 3,
      "name": "Rock_Stone_Cobble"
    },
    {
      "x": 5,
      "y": 1,
      "z": 3,
      "name": "Rock_Stone_Brick_Mossy"
    },
    {
      "x": 5,
      "y": 2,
      "z": 3,
      "name": "Furniture_Village_Window"
    },
    {
      "x": 5,
      "y": 3,
      "z": 3,
      "name": "Furniture_Village_Window"
    },
    {
      "x": 5,
      "y": 4,
      "z": 3,
      "name": "Wood_Beech_Trunk",
      "support": 15,
      "rotation": 5
    },
    {
      "x": 5,
      "y": 5,
      "z": 3,
      "name": "Wood_Softwood_Roof"
    },
    {
      "x": 5,
      "y": 0,
      "z": 4,
      "name": "Rock_Stone_Cobble_Mossy"
    },
    {
      "x": 5,
      "y": 4,
      "z": 4,
      "name": "Wood_Softwood_Roof_Hollow"
    },
    {
      "x": 6,
      "y": 0,
      "z": -6,
      "name": "Rock_Stone_Cobble"
    },
    {
      "x": 6,
      "y": 4,
      "z": -6,
      "name": "Wood_Softwood_Roof_Hollow",
      "rotation": 2
    },
    {
      "x": 6,
      "y": 0,
      "z": -5,
      "name": "Rock_Stone_Cobble_Mossy"
    },
    {
      "x": 6,
      "y": 1,
      "z": -5,
      "name": "Rock_Stone_Brick_Mossy"
    },
    {
      "x": 6,
      "y": 2,
      "z": -5,
      "name": "Furniture_Village_Window"
    },
    {
      "x": 6,
      "y": 3,
      "z": -5,
      "name": "Furniture_Village_Window"
    },
    {
      "x": 6,
      "y": 4,
      "z": -5,
      "name": "Wood_Beech_Trunk",
      "support": 15,
      "rotation": 5
    },
    {
      "x": 6,
      "y": 5,
      "z": -5,
      "name": "Wood_Softwood_Roof",
      "rotation": 2
    },
    {
      "x": 6,
      "y": 0,
      "z": -4,
      "name": "Wood_Softwood_Planks"
    },
    {
      "x": 6,
      "y": 1,
      "z": -4,
      "name": "Furniture_Kweebec_Wardrobe",
      "support": 15
    },
    {
      "x": 6,
      "y": 2,
      "z": -4,
      "name": "Furniture_Kweebec_Wardrobe",
      "support": 15,
      "filler": 1024
    },
    {
      "x": 6,
      "y": 5,
      "z": -4,
      "name": "Wood_Softwood_Stairs",
      "rotation": 10
    },
    {
      "x": 6,
      "y": 6,
      "z": -4,
      "name": "Wood_Softwood_Roof",
      "rotation": 2
    },
    {
      "x": 6,
      "y": 0,
      "z": -3,
      "name": "Cloth_Block_Wool_Green",
      "support": 15
    },
    {
      "x": 6,
      "y": 6,
      "z": -3,
      "name": "Wood_Softwood_Stairs",
      "rotation": 10
    },
    {
      "x": 6,
      "y": 7,
      "z": -3,
      "name": "Wood_Softwood_Roof_Flat",
      "rotation": 2
    },
    {
      "x": 6,
      "y": 0,
      "z": -2,
      "name": "Cloth_Block_Wool_Green",
      "support": 15
    },
    {
      "x": 6,
      "y": 7,
      "z": -2,
      "name": "Wood_Softwood_Planks"
    },
    {
      "x": 6,
      "y": 8,
      "z": -2,
      "name": "Wood_Village_Wall_Full"
    },
    {
      "x": 6,
      "y": 9,
      "z": -2,
      "name": "Wood_Softwood_Roof",
      "rotation": 2
    },
    {
      "x": 6,
      "y": 0,
      "z": -1,
      "name": "Cloth_Block_Wool_Green",
      "support": 15
    },
    {
      "x": 6,
      "y": 9,
      "z": -1,
      "name": "Wood_Softwood_Planks"
    },
    {
      "x": 6,
      "y": 10,
      "z": -1,
      "name": "Wood_Softwood_Roof_Flat",
      "rotation": 3
    },
    {
      "x": 6,
      "y": 0,
      "z": 0,
      "name": "Cloth_Block_Wool_Green",
      "support": 15
    },
    {
      "x": 6,
      "y": 7,
      "z": 0,
      "name": "Wood_Softwood_Planks"
    },
    {
      "x": 6,
      "y": 8,
      "z": 0,
      "name": "Wood_Village_Wall_Full"
    },
    {
      "x": 6,
      "y": 9,
      "z": 0,
      "name": "Wood_Softwood_Roof"
    },
    {
      "x": 6,
      "y": 0,
      "z": 1,
      "name": "Cloth_Block_Wool_Green",
      "support": 15
    },
    {
      "x": 6,
      "y": 1,
      "z": 1,
      "name": "Furniture_Human_Ruins_Bed",
      "support": 15,
      "filler": 993,
      "rotation": 1
    },
    {
      "x": 6,
      "y": 2,
      "z": 1,
      "name": "Furniture_Human_Ruins_Bed",
      "support": 15,
      "filler": 2017,
      "rotation": 1
    },
    {
      "x": 6,
      "y": 6,
      "z": 1,
      "name": "Wood_Softwood_Stairs",
      "rotation": 8
    },
    {
      "x": 6,
      "y": 7,
      "z": 1,
      "name": "Wood_Softwood_Roof_Flat",
      "rotation": 2
    },
    {
      "x": 6,
      "y": 0,
      "z": 2,
      "name": "Wood_Softwood_Planks"
    },
    {
      "x": 6,
      "y": 1,
      "z": 2,
      "name": "Furniture_Human_Ruins_Bed",
      "support": 15,
      "filler": 1,
      "rotation": 1
    },
    {
      "x": 6,
      "y": 2,
      "z": 2,
      "name": "Furniture_Human_Ruins_Bed",
      "support": 15,
      "filler": 1025,
      "rotation": 1
    },
    {
      "x": 6,
      "y": 5,
      "z": 2,
      "name": "Wood_Softwood_Stairs",
      "rotation": 8
    },
    {
      "x": 6,
      "y": 6,
      "z": 2,
      "name": "Wood_Softwood_Roof"
    },
    {
      "x": 6,
      "y": 0,
      "z": 3,
      "name": "Rock_Stone_Cobble"
    },
    {
      "x": 6,
      "y": 1,
      "z": 3,
      "name": "Rock_Stone_Brick_Mossy"
    },
    {
      "x": 6,
      "y": 2,
      "z": 3,
      "name": "Furniture_Village_Window"
    },
    {
      "x": 6,
      "y": 3,
      "z": 3,
      "name": "Furniture_Village_Window"
    },
    {
      "x": 6,
      "y": 4,
      "z": 3,
      "name": "Wood_Beech_Trunk",
      "support": 15,
      "rotation": 5
    },
    {
      "x": 6,
      "y": 5,
      "z": 3,
      "name": "Wood_Softwood_Roof"
    },
    {
      "x": 6,
      "y": 0,
      "z": 4,
      "name": "Rock_Stone_Cobble"
    },
    {
      "x": 6,
      "y": 4,
      "z": 4,
      "name": "Wood_Softwood_Roof_Hollow"
    },
    {
      "x": 7,
      "y": 0,
      "z": -6,
      "name": "Rock_Stone_Cobble"
    },
    {
      "x": 7,
      "y": 3,
      "z": -6,
      "name": "Plant_Vine_Wall",
      "support": 15,
      "rotation": 2
    },
    {
      "x": 7,
      "y": 4,
      "z": -6,
      "name": "Wood_Softwood_Roof_Hollow",
      "rotation": 2
    },
    {
      "x": 7,
      "y": 0,
      "z": -5,
      "name": "Rock_Stone_Cobble_Mossy"
    },
    {
      "x": 7,
      "y": 1,
      "z": -5,
      "name": "Rock_Stone_Brick"
    },
    {
      "x": 7,
      "y": 2,
      "z": -5,
      "name": "*Wood_Village_Wall_Full_State_Definitions_Bottom"
    },
    {
      "x": 7,
      "y": 3,
      "z": -5,
      "name": "*Wood_Village_Wall_Full_State_Definitions_Top"
    },
    {
      "x": 7,
      "y": 4,
      "z": -5,
      "name": "Wood_Beech_Trunk",
      "support": 15,
      "rotation": 5
    },
    {
      "x": 7,
      "y": 5,
      "z": -5,
      "name": "Wood_Softwood_Roof",
      "rotation": 2
    },
    {
      "x": 7,
      "y": 0,
      "z": -4,
      "name": "Wood_Softwood_Planks"
    },
    {
      "x": 7,
      "y": 5,
      "z": -4,
      "name": "Wood_Softwood_Stairs",
      "rotation": 10
    },
    {
      "x": 7,
      "y": 6,
      "z": -4,
      "name": "Wood_Softwood_Roof",
      "rotation": 2
    },
    {
      "x": 7,
      "y": 0,
      "z": -3,
      "name": "Cloth_Block_Wool_Green",
      "support": 15
    },
    {
      "x": 7,
      "y": 1,
      "z": -3,
      "name": "Furniture_Village_Counter",
      "support": 15,
      "filler": 992,
      "rotation": 3
    },
    {
      "x": 7,
      "y": 6,
      "z": -3,
      "name": "Wood_Softwood_Stairs",
      "rotation": 10
    },
    {
      "x": 7,
      "y": 7,
      "z": -3,
      "name": "Wood_Softwood_Roof_Flat",
      "rotation": 2
    },
    {
      "x": 7,
      "y": 0,
      "z": -2,
      "name": "Cloth_Block_Wool_Green",
      "support": 15
    },
    {
      "x": 7,
      "y": 1,
      "z": -2,
      "name": "Furniture_Village_Counter",
      "support": 15,
      "rotation": 3
    },
    {
      "x": 7,
      "y": 2,
      "z": -2,
      "name": "Furniture_Village_Counter",
      "support": 15,
      "filler": 992,
      "rotation": 3
    },
    {
      "x": 7,
      "y": 6,
      "z": -2,
      "name": "Wood_Softwood_Planks_Half",
      "rotation": 8
    },
    {
      "x": 7,
      "y": 7,
      "z": -2,
      "name": "Wood_Beech_Trunk",
      "support": 15
    },
    {
      "x": 7,
      "y": 8,
      "z": -2,
      "name": "Wood_Beech_Trunk",
      "support": 15
    },
    {
      "x": 7,
      "y": 9,
      "z": -2,
      "name": "Wood_Softwood_Roof",
      "rotation": 2
    },
    {
      "x": 7,
      "y": 0,
      "z": -1,
      "name": "Cloth_Block_Wool_Green",
      "support": 15
    },
    {
      "x": 7,
      "y": 1,
      "z": -1,
      "name": "Furniture_Village_Counter",
      "support": 15,
      "filler": 992,
      "rotation": 3
    },
    {
      "x": 7,
      "y": 2,
      "z": -1,
      "name": "Furniture_Village_Counter",
      "support": 15,
      "rotation": 3
    },
    {
      "x": 7,
      "y": 5,
      "z": -1,
      "name": "Deco_Lantern_Ceiling",
      "support": 15
    },
    {
      "x": 7,
      "y": 6,
      "z": -1,
      "name": "Deco_Iron_Chain_Small"
    },
    {
      "x": 7,
      "y": 7,
      "z": -1,
      "name": "Wood_Softwood_Planks"
    },
    {
      "x": 7,
      "y": 8,
      "z": -1,
      "name": "*Wood_Village_Wall_Full_State_Definitions_Bottom"
    },
    {
      "x": 7,
      "y": 9,
      "z": -1,
      "name": "*Wood_Village_Wall_Full_State_Definitions_Top"
    },
    {
      "x": 7,
      "y": 10,
      "z": -1,
      "name": "Wood_Softwood_Roof_Flat",
      "rotation": 1
    },
    {
      "x": 7,
      "y": 0,
      "z": 0,
      "name": "Cloth_Block_Wool_Green",
      "support": 15
    },
    {
      "x": 7,
      "y": 1,
      "z": 0,
      "name": "Furniture_Village_Counter",
      "support": 15,
      "rotation": 3
    },
    {
      "x": 7,
      "y": 6,
      "z": 0,
      "name": "Wood_Softwood_Planks_Half",
      "rotation": 8
    },
    {
      "x": 7,
      "y": 7,
      "z": 0,
      "name": "Wood_Beech_Trunk",
      "support": 15
    },
    {
      "x": 7,
      "y": 8,
      "z": 0,
      "name": "Wood_Beech_Trunk",
      "support": 15
    },
    {
      "x": 7,
      "y": 9,
      "z": 0,
      "name": "Wood_Softwood_Roof"
    },
    {
      "x": 7,
      "y": 0,
      "z": 1,
      "name": "Cloth_Block_Wool_Green",
      "support": 15
    },
    {
      "x": 7,
      "y": 1,
      "z": 1,
      "name": "Furniture_Human_Ruins_Bed",
      "support": 15,
      "filler": 994,
      "rotation": 1
    },
    {
      "x": 7,
      "y": 2,
      "z": 1,
      "name": "Furniture_Human_Ruins_Bed",
      "support": 15,
      "filler": 2018,
      "rotation": 1
    },
    {
      "x": 7,
      "y": 6,
      "z": 1,
      "name": "Wood_Softwood_Stairs",
      "rotation": 8
    },
    {
      "x": 7,
      "y": 7,
      "z": 1,
      "name": "Wood_Softwood_Roof_Flat",
      "rotation": 2
    },
    {
      "x": 7,
      "y": 0,
      "z": 2,
      "name": "Wood_Softwood_Planks"
    },
    {
      "x": 7,
      "y": 1,
      "z": 2,
      "name": "Furniture_Human_Ruins_Bed",
      "support": 15,
      "filler": 2,
      "rotation": 1
    },
    {
      "x": 7,
      "y": 2,
      "z": 2,
      "name": "Furniture_Human_Ruins_Bed",
      "support": 15,
      "filler": 1026,
      "rotation": 1
    },
    {
      "x": 7,
      "y": 5,
      "z": 2,
      "name": "Wood_Softwood_Stairs",
      "rotation": 8
    },
    {
      "x": 7,
      "y": 6,
      "z": 2,
      "name": "Wood_Softwood_Roof"
    },
    {
      "x": 7,
      "y": 0,
      "z": 3,
      "name": "Rock_Stone_Cobble"
    },
    {
      "x": 7,
      "y": 1,
      "z": 3,
      "name": "Rock_Stone_Brick"
    },
    {
      "x": 7,
      "y": 2,
      "z": 3,
      "name": "*Wood_Village_Wall_Full_State_Definitions_Bottom"
    },
    {
      "x": 7,
      "y": 3,
      "z": 3,
      "name": "*Wood_Village_Wall_Full_State_Definitions_Top"
    },
    {
      "x": 7,
      "y": 4,
      "z": 3,
      "name": "Wood_Beech_Trunk",
      "support": 15,
      "rotation": 5
    },
    {
      "x": 7,
      "y": 5,
      "z": 3,
      "name": "Wood_Softwood_Roof"
    },
    {
      "x": 7,
      "y": 0,
      "z": 4,
      "name": "Rock_Stone_Cobble"
    },
    {
      "x": 7,
      "y": 4,
      "z": 4,
      "name": "Wood_Softwood_Roof_Hollow"
    },
    {
      "x": 8,
      "y": 0,
      "z": -6,
      "name": "Rock_Stone_Cobble"
    },
    {
      "x": 8,
      "y": 3,
      "z": -6,
      "name": "Wood_Beech_Branch_Corner",
      "support": 15,
      "rotation": 2
    },
    {
      "x": 8,
      "y": 4,
      "z": -6,
      "name": "Wood_Softwood_Roof",
      "rotation": 2
    },
    {
      "x": 8,
      "y": 0,
      "z": -5,
      "name": "Rock_Stone_Cobble"
    },
    {
      "x": 8,
      "y": 1,
      "z": -5,
      "name": "Wood_Beech_Trunk",
      "support": 15
    },
    {
      "x": 8,
      "y": 2,
      "z": -5,
      "name": "Wood_Beech_Trunk",
      "support": 15
    },
    {
      "x": 8,
      "y": 3,
      "z": -5,
      "name": "Wood_Beech_Trunk",
      "support": 15
    },
    {
      "x": 8,
      "y": 4,
      "z": -5,
      "name": "Wood_Beech_Trunk",
      "support": 15
    },
    {
      "x": 8,
      "y": 5,
      "z": -5,
      "name": "Wood_Softwood_Roof",
      "rotation": 2
    },
    {
      "x": 8,
      "y": 0,
      "z": -4,
      "name": "Rock_Stone_Cobble_Mossy"
    },
    {
      "x": 8,
      "y": 1,
      "z": -4,
      "name": "Rock_Stone_Brick"
    },
    {
      "x": 8,
      "y": 2,
      "z": -4,
      "name": "*Wood_Village_Wall_Full_State_Definitions_Bottom"
    },
    {
      "x": 8,
      "y": 3,
      "z": -4,
      "name": "*Wood_Village_Wall_Full_State_Definitions_Top"
    },
    {
      "x": 8,
      "y": 4,
      "z": -4,
      "name": "Wood_Beech_Trunk",
      "support": 15,
      "rotation": 4
    },
    {
      "x": 8,
      "y": 5,
      "z": -4,
      "name": "Wood_Village_Wall_Full"
    },
    {
      "x": 8,
      "y": 6,
      "z": -4,
      "name": "Wood_Softwood_Roof",
      "rotation": 2
    },
    {
      "x": 8,
      "y": 0,
      "z": -3,
      "name": "Rock_Stone_Cobble_Mossy"
    },
    {
      "x": 8,
      "y": 1,
      "z": -3,
      "name": "Rock_Stone_Brick_Mossy"
    },
    {
      "x": 8,
      "y": 2,
      "z": -3,
      "name": "Furniture_Village_Window",
      "rotation": 1
    },
    {
      "x": 8,
      "y": 3,
      "z": -3,
      "name": "Furniture_Village_Window",
      "rotation": 1
    },
    {
      "x": 8,
      "y": 4,
      "z": -3,
      "name": "Wood_Beech_Trunk",
      "support": 15,
      "rotation": 4
    },
    {
      "x": 8,
      "y": 5,
      "z": -3,
      "name": "*Wood_Village_Wall_Full_State_Definitions_Bottom"
    },
    {
      "x": 8,
      "y": 6,
      "z": -3,
      "name": "*Wood_Village_Wall_Full_State_Definitions_Top"
    },
    {
      "x": 8,
      "y": 7,
      "z": -3,
      "name": "Wood_Softwood_Roof_Flat",
      "rotation": 2
    },
    {
      "x": 8,
      "y": 0,
      "z": -2,
      "name": "Rock_Stone_Cobble"
    },
    {
      "x": 8,
      "y": 1,
      "z": -2,
      "name": "Rock_Stone_Brick"
    },
    {
      "x": 8,
      "y": 2,
      "z": -2,
      "name": "*Wood_Village_Wall_Full_State_Definitions_Bottom"
    },
    {
      "x": 8,
      "y": 3,
      "z": -2,
      "name": "*Wood_Village_Wall_Full_State_Definitions_Top"
    },
    {
      "x": 8,
      "y": 4,
      "z": -2,
      "name": "Wood_Beech_Trunk",
      "support": 15,
      "rotation": 4
    },
    {
      "x": 8,
      "y": 5,
      "z": -2,
      "name": "*Wood_Village_Wall_Full_State_Definitions_Bottom"
    },
    {
      "x": 8,
      "y": 6,
      "z": -2,
      "name": "*Wood_Village_Wall_Full_State_Definitions_Top"
    },
    {
      "x": 8,
      "y": 7,
      "z": -2,
      "name": "Wood_Softwood_Roof_Flat",
      "rotation": 2
    },
    {
      "x": 8,
      "y": 0,
      "z": -1,
      "name": "Rock_Stone_Cobble"
    },
    {
      "x": 8,
      "y": 1,
      "z": -1,
      "name": "Rock_Stone_Brick_Mossy"
    },
    {
      "x": 8,
      "y": 2,
      "z": -1,
      "name": "*Wood_Village_Wall_Full_State_Definitions_Bottom"
    },
    {
      "x": 8,
      "y": 3,
      "z": -1,
      "name": "*Wood_Village_Wall_Full_State_Definitions_Top"
    },
    {
      "x": 8,
      "y": 4,
      "z": -1,
      "name": "Wood_Beech_Trunk",
      "support": 15,
      "rotation": 4
    },
    {
      "x": 8,
      "y": 5,
      "z": -1,
      "name": "*Wood_Village_Wall_Full_State_Definitions_Bottom"
    },
    {
      "x": 8,
