{
  "version": 8,
  "blockIdVersion": 11,
  "anchorX": 0,
  "anchorY": 0,
  "anchorZ": 0,
  "blocks": [
    {
      "x": 0,
      "y": -1,
      "z": 0,
      "name": "Soil_Grass"
    },
    {
      "x": 0,
      "y": -1,
      "z": 1,
      "name": "Soil_Grass"
    },
    {
      "x": 0,
      "y": 0,
      "z": 1,
      "name": "Plant_Grass_Sharp",
      "support": 15
    },
    {
      "x": 0,
      "y": -1,
      "z": 2,
      "name": "Soil_Grass"
    },
    {
      "x": 0,
      "y": -1,
      "z": 3,
      "name": "Soil_Mud_Dry"
    },
    {
      "x": 0,
      "y": 5,
      "z": 3,
      "name": "Plant_Vine",
      "support": 15,
      "rotation": 3
    },
    {
      "x": 0,
      "y": -1,
      "z": 4,
      "name": "Soil_Pathway"
    },
    {
      "x": 0,
      "y": -1,
      "z": 5,
      "name": "Soil_Pathway"
    },
    {
      "x": 0,
      "y": -1,
      "z": 6,
      "name": "Soil_Pathway"
    },
    {
      "x": 0,
      "y": -1,
      "z": 7,
      "name": "Soil_Mud_Dry"
    },
    {
      "x": 0,
      "y": 0,
      "z": 7,
      "name": "Plant_Grass_Lush_Short",
      "support": 15
    },
    {
      "x": 0,
      "y": -1,
      "z": 8,
      "name": "Soil_Grass"
    },
    {
      "x": 0,
      "y": 0,
      "z": 8,
      "name": "Plant_Grass_Lush_Short",
      "support": 15
    },
    {
      "x": 0,
      "y": -1,
      "z": 9,
      "name": "Soil_Grass"
    },
    {
      "x": 0,
      "y": -1,
      "z": 10,
      "name": "Soil_Grass"
    },
    {
      "x": 1,
      "y": -1,
      "z": 0,
      "name": "Soil_Grass"
    },
    {
      "x": 1,
      "y": 0,
      "z": 0,
      "name": "Plant_Grass_Sharp",
      "support": 15
    },
    {
      "x": 1,
      "y": -1,
      "z": 1,
      "name": "Soil_Grass"
    },
    {
      "x": 1,
      "y": 0,
      "z": 1,
      "name": "Plant_Grass_Lush_Short",
      "support": 15
    },
    {
      "x": 1,
      "y": -1,
      "z": 2,
      "name": "Soil_Grass"
    },
    {
      "x": 1,
      "y": 0,
      "z": 2,
      "name": "Plant_Leaves_Oak",
      "support": 15
    },
    {
      "x": 1,
      "y": -1,
      "z": 3,
      "name": "Soil_Mud_Dry"
    },
    {
      "x": 1,
      "y": 0,
      "z": 3,
      "name": "Rock_Marble_Brick_Pillar_Base"
    },
    {
      "x": 1,
      "y": 1,
      "z": 3,
      "name": "Rock_Marble_Brick_Pillar_Middle"
    },
    {
      "x": 1,
      "y": 2,
      "z": 3,
      "name": "Rock_Marble_Brick_Pillar_Middle"
    },
    {
      "x": 1,
      "y": 3,
      "z": 3,
      "name": "Rock_Marble_Brick_Pillar_Middle"
    },
    {
      "x": 1,
      "y": 4,
      "z": 3,
      "name": "Rock_Marble_Brick_Pillar_Base",
      "rotation": 8
    },
    {
      "x": 1,
      "y": 5,
      "z": 3,
      "name": "Rock_Marble_Brick"
    },
    {
      "x": 1,
      "y": -1,
      "z": 4,
      "name": "Soil_Pathway"
    },
    {
      "x": 1,
      "y": 5,
      "z": 4,
      "name": "Rock_Marble_Brick"
    },
    {
      "x": 1,
      "y": -1,
      "z": 5,
      "name": "Soil_Pathway"
    },
    {
      "x": 1,
      "y": 5,
      "z": 5,
      "name": "Rock_Marble_Brick"
    },
    {
      "x": 1,
      "y": -1,
      "z": 6,
      "name": "Soil_Pathway"
    },
    {
      "x": 1,
      "y": 5,
      "z": 6,
      "name": "Rock_Marble_Brick"
    },
    {
      "x": 1,
      "y": -1,
      "z": 7,
      "name": "Soil_Pathway"
    },
    {
      "x": 1,
      "y": 0,
      "z": 7,
      "name": "Rock_Marble_Brick_Pillar_Base"
    },
    {
      "x": 1,
      "y": 1,
      "z": 7,
      "name": "Rock_Marble_Brick_Pillar_Middle"
    },
    {
      "x": 1,
      "y": 2,
      "z": 7,
      "name": "Rock_Marble_Brick_Pillar_Middle"
    },
    {
      "x": 1,
      "y": 3,
      "z": 7,
      "name": "Rock_Marble_Brick_Pillar_Middle"
    },
    {
      "x": 1,
      "y": 4,
      "z": 7,
      "name": "Rock_Marble_Brick_Pillar_Base",
      "rotation": 8
    },
    {
      "x": 1,
      "y": 5,
      "z": 7,
      "name": "Rock_Marble_Brick"
    },
    {
      "x": 1,
      "y": -1,
      "z": 8,
      "name": "Soil_Grass"
    },
    {
      "x": 1,
      "y": 0,
      "z": 8,
      "name": "Plant_Leaves_Oak",
      "support": 15
    },
    {
      "x": 1,
      "y": -1,
      "z": 9,
      "name": "Soil_Grass"
    },
    {
      "x": 1,
      "y": 0,
      "z": 9,
      "name": "Plant_Grass_Lush_Short",
      "support": 15
    },
    {
      "x": 1,
      "y": -1,
      "z": 10,
      "name": "Soil_Grass"
    },
    {
      "x": 2,
      "y": -1,
      "z": 0,
      "name": "Soil_Grass"
    },
    {
      "x": 2,
      "y": -1,
      "z": 1,
      "name": "Soil_Grass_Deep"
    },
    {
      "x": 2,
      "y": 0,
      "z": 1,
      "name": "Plant_Leaves_Oak",
      "support": 15
    },
    {
      "x": 2,
      "y": 5,
      "z": 1,
      "name": "Plant_Vine_Wall",
      "support": 15,
      "rotation": 2
    },
    {
      "x": 2,
      "y": -1,
      "z": 2,
      "name": "Soil_Grass_Deep"
    },
    {
      "x": 2,
      "y": 0,
      "z": 2,
      "name": "Plant_Leaves_Oak",
      "support": 15
    },
    {
      "x": 2,
      "y": 1,
      "z": 2,
      "name": "Plant_Leaves_Oak",
      "support": 15
    },
    {
      "x": 2,
      "y": 5,
      "z": 2,
      "name": "Rock_Marble_Brick"
    },
    {
      "x": 2,
      "y": -1,
      "z": 3,
      "name": "Soil_Pathway"
    },
    {
      "x": 2,
      "y": 0,
      "z": 3,
      "name": "Furniture_Temple_Emerald_Stool",
      "support": 15
    },
    {
      "x": 2,
      "y": 5,
      "z": 3,
      "name": "Rock_Marble_Brick"
    },
    {
      "x": 2,
      "y": 6,
      "z": 3,
      "name": "Plant_Leaves_Oak",
      "support": 15
    },
    {
      "x": 2,
      "y": -1,
      "z": 4,
      "name": "Soil_Pathway"
    },
    {
      "x": 2,
      "y": 6,
      "z": 4,
      "name": "Plant_Leaves_Oak",
      "support": 15
    },
    {
      "x": 2,
      "y": -1,
      "z": 5,
      "name": "Soil_Pathway"
    },
    {
      "x": 2,
      "y": 6,
      "z": 5,
      "name": "Plant_Leaves_Oak",
      "support": 15
    },
    {
      "x": 2,
      "y": -1,
      "z": 6,
      "name": "Soil_Mud_Dry"
    },
    {
      "x": 2,
      "y": 6,
      "z": 6,
      "name": "Plant_Leaves_Oak",
      "support": 15
    },
    {
      "x": 2,
      "y": -1,
      "z": 7,
      "name": "Soil_Pathway"
    },
    {
      "x": 2,
      "y": 5,
      "z": 7,
      "name": "Rock_Marble_Brick"
    },
    {
      "x": 2,
      "y": 6,
      "z": 7,
      "name": "Plant_Leaves_Oak",
      "support": 15
    },
    {
      "x": 2,
      "y": -1,
      "z": 8,
      "name": "Soil_Grass"
    },
    {
      "x": 2,
      "y": 0,
      "z": 8,
      "name": "Plant_Leaves_Oak",
      "support": 15
    },
    {
      "x": 2,
      "y": 1,
      "z": 8,
      "name": "Plant_Leaves_Oak",
      "support": 15
    },
    {
      "x": 2,
      "y": 5,
      "z": 8,
      "name": "Rock_Marble_Brick"
    },
    {
      "x": 2,
      "y": -1,
      "z": 9,
      "name": "Soil_Grass"
    },
    {
      "x": 2,
      "y": 0,
      "z": 9,
      "name": "Plant_Leaves_Oak",
      "support": 15
    },
    {
      "x": 2,
      "y": -1,
      "z": 10,
      "name": "Soil_Grass_Deep"
    },
    {
      "x": 3,
      "y": -1,
      "z": 0,
      "name": "Soil_Mud_Dry"
    },
    {
      "x": 3,
      "y": -1,
      "z": 1,
      "name": "Soil_Pathway"
    },
    {
      "x": 3,
      "y": 0,
      "z": 1,
      "name": "Rock_Marble_Brick_Pillar_Base"
    },
    {
      "x": 3,
      "y": 1,
      "z": 1,
      "name": "Rock_Marble_Brick_Pillar_Middle"
    },
    {
      "x": 3,
      "y": 2,
      "z": 1,
      "name": "Rock_Marble_Brick_Pillar_Middle"
    },
    {
      "x": 3,
      "y": 3,
      "z": 1,
      "name": "Rock_Marble_Brick_Pillar_Middle"
    },
    {
      "x": 3,
      "y": 4,
      "z": 1,
      "name": "Rock_Marble_Brick_Pillar_Base",
      "rotation": 8
    },
    {
      "x": 3,
      "y": 5,
      "z": 1,
      "name": "Rock_Marble_Brick"
    },
    {
      "x": 3,
      "y": -1,
      "z": 2,
      "name": "Soil_Mud_Dry"
    },
    {
      "x": 3,
      "y": 5,
      "z": 2,
      "name": "Rock_Marble_Brick"
    },
    {
      "x": 3,
      "y": 6,
      "z": 2,
      "name": "Plant_Leaves_Oak",
      "support": 15
    },
    {
      "x": 3,
      "y": -1,
      "z": 3,
      "name": "Soil_Mud_Dry"
    },
    {
      "x": 3,
      "y": 5,
      "z": 3,
      "name": "Plant_Leaves_Oak",
      "support": 15
    },
    {
      "x": 3,
      "y": 6,
      "z": 3,
      "name": "Plant_Leaves_Oak",
      "support": 15
    },
    {
      "x": 3,
      "y": -1,
      "z": 4,
      "name": "Soil_Pathway"
    },
    {
      "x": 3,
      "y": 6,
      "z": 4,
      "name": "Plant_Leaves_Oak",
      "support": 15
    },
    {
      "x": 3,
      "y": -1,
      "z": 5,
      "name": "Soil_Pathway"
    },
    {
      "x": 3,
      "y": -1,
      "z": 6,
      "name": "Soil_Mud_Dry"
    },
    {
      "x": 3,
      "y": 6,
      "z": 6,
      "name": "Plant_Leaves_Oak",
      "support": 15
    },
    {
      "x": 3,
      "y": -1,
      "z": 7,
      "name": "Soil_Pathway"
    },
    {
      "x": 3,
      "y": 5,
      "z": 7,
      "name": "Plant_Leaves_Oak",
      "support": 15
    },
    {
      "x": 3,
      "y": 6,
      "z": 7,
      "name": "Plant_Leaves_Oak",
      "support": 15
    },
    {
      "x": 3,
      "y": -1,
      "z": 8,
      "name": "Soil_Pathway"
    },
    {
      "x": 3,
      "y": 5,
      "z": 8,
      "name": "Rock_Marble_Brick"
    },
    {
      "x": 3,
      "y": 6,
      "z": 8,
      "name": "Plant_Leaves_Oak",
      "support": 15
    },
    {
      "x": 3,
      "y": -1,
      "z": 9,
      "name": "Soil_Grass_Deep"
    },
    {
      "x": 3,
      "y": 0,
      "z": 9,
      "name": "Rock_Marble_Brick_Pillar_Base"
    },
    {
      "x": 3,
      "y": 1,
      "z": 9,
      "name": "Rock_Marble_Brick_Pillar_Middle"
    },
    {
      "x": 3,
      "y": 2,
      "z": 9,
      "name": "Rock_Marble_Brick_Pillar_Middle"
    },
    {
      "x": 3,
      "y": 3,
      "z": 9,
      "name": "Rock_Marble_Brick_Pillar_Middle"
    },
    {
      "x": 3,
      "y": 4,
      "z": 9,
      "name": "Rock_Marble_Brick_Pillar_Base",
      "rotation": 8
    },
    {
      "x": 3,
      "y": 5,
      "z": 9,
      "name": "Rock_Marble_Brick"
    },
    {
      "x": 3,
      "y": -1,
      "z": 10,
      "name": "Soil_Mud_Dry"
    },
    {
      "x": 3,
      "y": 0,
      "z": 10,
      "name": "Plant_Grass_Sharp",
      "support": 15
    },
    {
      "x": 3,
      "y": 5,
      "z": 10,
      "name": "Plant_Vine",
      "support": 15
    },
    {
      "x": 4,
      "y": -1,
      "z": 0,
      "name": "Soil_Mud_Dry"
    },
    {
      "x": 4,
      "y": -1,
      "z": 1,
      "name": "Soil_Mud_Dry"
    },
    {
      "x": 4,
      "y": 5,
      "z": 1,
      "name": "Rock_Marble_Brick"
    },
    {
      "x": 4,
      "y": -1,
      "z": 2,
      "name": "Soil_Pathway"
    },
    {
      "x": 4,
      "y": 6,
      "z": 2,
      "name": "Plant_Leaves_Oak",
      "support": 15
    },
    {
      "x": 4,
      "y": -1,
      "z": 3,
      "name": "Soil_Pathway"
    },
    {
      "x": 4,
      "y": 6,
      "z": 3,
      "name": "Plant_Leaves_Oak",
      "support": 15
    },
    {
      "x": 4,
      "y": -1,
      "z": 4,
      "name": "Soil_Pathway"
    },
    {
      "x": 4,
      "y": -1,
      "z": 5,
      "name": "Soil_Pathway"
    },
    {
      "x": 4,
      "y": -1,
      "z": 6,
      "name": "Soil_Mud_Dry"
    },
    {
      "x": 4,
      "y": -1,
      "z": 7,
      "name": "Soil_Pathway"
    },
    {
      "x": 4,
      "y": 6,
      "z": 7,
      "name": "Plant_Leaves_Oak",
      "support": 15
    },
    {
      "x": 4,
      "y": -1,
      "z": 8,
      "name": "Soil_Mud_Dry"
    },
    {
      "x": 4,
      "y": 6,
      "z": 8,
      "name": "Plant_Leaves_Oak",
      "support": 15
    },
    {
      "x": 4,
      "y": -1,
      "z": 9,
      "name": "Soil_Pathway"
    },
    {
      "x": 4,
      "y": 5,
      "z": 9,
      "name": "Rock_Marble_Brick"
    },
    {
      "x": 4,
      "y": -1,
      "z": 10,
      "name": "Soil_Pathway"
    },
    {
      "x": 5,
      "y": -1,
      "z": 0,
      "name": "Soil_Mud_Dry"
    },
    {
      "x": 5,
      "y": -1,
      "z": 1,
      "name": "Soil_Pathway"
    },
    {
      "x": 5,
      "y": 5,
      "z": 1,
      "name": "Rock_Marble_Brick"
    },
    {
      "x": 5,
      "y": -1,
      "z": 2,
      "name": "Soil_Pathway"
    },
    {
      "x": 5,
      "y": 6,
      "z": 2,
      "name": "Plant_Leaves_Oak",
      "support": 15
    },
    {
      "x": 5,
      "y": -1,
      "z": 3,
      "name": "Soil_Pathway"
    },
    {
      "x": 5,
      "y": -1,
      "z": 4,
      "name": "Soil_Mud_Dry"
    },
    {
      "x": 5,
      "y": -1,
      "z": 5,
      "name": "Soil_Pathway"
    },
    {
      "x": 5,
      "y": 0,
      "z": 5,
      "name": "Rock_Marble_Brick"
    },
    {
      "x": 5,
      "y": 1,
      "z": 5,
      "name": "Aetherhaven_Statue_Of_Gaia",
      "components": {
        "Components": {
          "AetherhavenGaiaStatueBlock": {
            "PlotId": "",
            "TownId": ""
          }
        }
      },
      "support": 15,
      "rotation": 3
    },
    {
      "x": 5,
      "y": -1,
      "z": 6,
      "name": "Soil_Pathway"
    },
    {
      "x": 5,
      "y": -1,
      "z": 7,
      "name": "Soil_Pathway"
    },
    {
      "x": 5,
      "y": -1,
      "z": 8,
      "name": "Soil_Pathway"
    },
    {
      "x": 5,
      "y": 6,
      "z": 8,
      "name": "Plant_Leaves_Oak",
      "support": 15
    },
    {
      "x": 5,
      "y": -1,
      "z": 9,
      "name": "Soil_Mud_Dry"
    },
    {
      "x": 5,
      "y": 5,
      "z": 9,
      "name": "Rock_Marble_Brick"
    },
    {
      "x": 5,
      "y": -1,
      "z": 10,
      "name": "Soil_Mud_Dry"
    },
    {
      "x": 6,
      "y": -1,
      "z": 0,
      "name": "Soil_Pathway"
    },
    {
      "x": 6,
      "y": -1,
      "z": 1,
      "name": "Soil_Pathway"
    },
    {
      "x": 6,
      "y": 5,
      "z": 1,
      "name": "Rock_Marble_Brick"
    },
    {
      "x": 6,
      "y": -1,
      "z": 2,
      "name": "Soil_Mud_Dry"
    },
    {
      "x": 6,
      "y": 6,
      "z": 2,
      "name": "Plant_Leaves_Oak",
      "support": 15
    },
    {
      "x": 6,
      "y": -1,
      "z": 3,
      "name": "Soil_Pathway"
    },
    {
      "x": 6,
      "y": 6,
      "z": 3,
      "name": "Plant_Leaves_Oak",
      "support": 15
    },
    {
      "x": 6,
      "y": -1,
      "z": 4,
      "name": "Soil_Pathway"
    },
    {
      "x": 6,
      "y": -1,
      "z": 5,
      "name": "Soil_Mud_Dry"
    },
    {
      "x": 6,
      "y": -1,
      "z": 6,
      "name": "Soil_Pathway"
    },
    {
      "x": 6,
      "y": -1,
      "z": 7,
      "name": "Soil_Pathway"
    },
    {
      "x": 6,
      "y": 6,
      "z": 7,
      "name": "Plant_Leaves_Oak",
      "support": 15
    },
    {
      "x": 6,
      "y": -1,
      "z": 8,
      "name": "Soil_Pathway"
    },
    {
      "x": 6,
      "y": 6,
      "z": 8,
      "name": "Plant_Leaves_Oak",
      "support": 15
    },
    {
      "x": 6,
      "y": -1,
      "z": 9,
      "name": "Soil_Pathway"
    },
    {
      "x": 6,
      "y": 5,
      "z": 9,
      "name": "Rock_Marble_Brick"
    },
    {
      "x": 6,
      "y": -1,
      "z": 10,
      "name": "Soil_Pathway"
    },
    {
      "x": 7,
      "y": -1,
      "z": 0,
      "name": "Soil_Pathway"
    },
    {
      "x": 7,
      "y": -1,
      "z": 1,
      "name": "Soil_Mud_Dry"
    },
    {
      "x": 7,
      "y": 0,
      "z": 1,
      "name": "Rock_Marble_Brick_Pillar_Base"
    },
    {
      "x": 7,
      "y": 1,
      "z": 1,
      "name": "Rock_Marble_Brick_Pillar_Middle"
    },
    {
      "x": 7,
      "y": 2,
      "z": 1,
      "name": "Rock_Marble_Brick_Pillar_Middle"
    },
    {
      "x": 7,
      "y": 3,
      "z": 1,
      "name": "Rock_Marble_Brick_Pillar_Middle"
    },
    {
      "x": 7,
      "y": 4,
      "z": 1,
      "name": "Rock_Marble_Brick_Pillar_Base",
      "rotation": 8
    },
    {
      "x": 7,
      "y": 5,
      "z": 1,
      "name": "Rock_Marble_Brick"
    },
    {
      "x": 7,
      "y": -1,
      "z": 2,
      "name": "Soil_Pathway"
    },
    {
      "x": 7,
      "y": 5,
      "z": 2,
      "name": "Rock_Marble_Brick"
    },
    {
      "x": 7,
      "y": 6,
      "z": 2,
      "name": "Plant_Leaves_Oak",
      "support": 15
    },
    {
      "x": 7,
      "y": -1,
      "z": 3,
      "name": "Soil_Pathway"
    },
    {
      "x": 7,
      "y": 5,
      "z": 3,
      "name": "Plant_Leaves_Oak",
      "support": 15
    },
    {
      "x": 7,
      "y": 6,
      "z": 3,
      "name": "Plant_Leaves_Oak",
      "support": 15
    },
    {
      "x": 7,
      "y": -1,
      "z": 4,
      "name": "Soil_Mud_Dry"
    },
    {
      "x": 7,
      "y": 6,
      "z": 4,
      "name": "Plant_Leaves_Oak",
      "support": 15
    },
    {
      "x": 7,
      "y": -1,
      "z": 5,
      "name": "Soil_Pathway"
    },
    {
      "x": 7,
      "y": -1,
      "z": 6,
      "name": "Soil_Mud_Dry"
    },
    {
      "x": 7,
      "y": 6,
      "z": 6,
      "name": "Plant_Leaves_Oak",
      "support": 15
    },
    {
      "x": 7,
      "y": -1,
      "z": 7,
      "name": "Soil_Pathway"
    },
    {
      "x": 7,
      "y": 5,
      "z": 7,
      "name": "Plant_Leaves_Oak",
      "support": 15
    },
    {
      "x": 7,
      "y": 6,
      "z": 7,
      "name": "Plant_Leaves_Oak",
      "support": 15
    },
    {
      "x": 7,
      "y": -1,
      "z": 8,
      "name": "Soil_Pathway"
    },
    {
      "x": 7,
      "y": 0,
      "z": 8,
      "name": "Aetherhaven_Management_Block",
      "components": {
        "Components": {
          "AetherhavenManagementBlock": {
            "PlotId": "",
            "TownId": ""
          },
          "PlacedByInteraction": {
            "WhoPlacedUuid": {
              "$binary": "v7RyWIT/TYKnXA2XcxdQtw==",
              "$type": "04"
            }
          }
        }
      },
      "rotation": 2
    },
    {
      "x": 7,
      "y": 5,
      "z": 8,
      "name": "Rock_Marble_Brick"
    },
    {
      "x": 7,
      "y": 6,
      "z": 8,
      "name": "Plant_Leaves_Oak",
      "support": 15
    },
    {
      "x": 7,
      "y": -1,
      "z": 9,
      "name": "Soil_Grass"
    },
    {
      "x": 7,
      "y": 0,
      "z": 9,
      "name": "Rock_Marble_Brick_Pillar_Base"
    },
    {
      "x": 7,
      "y": 1,
      "z": 9,
      "name": "Rock_Marble_Brick_Pillar_Middle"
    },
    {
      "x": 7,
      "y": 2,
      "z": 9,
      "name": "Rock_Marble_Brick_Pillar_Middle"
    },
    {
      "x": 7,
      "y": 3,
      "z": 9,
      "name": "Rock_Marble_Brick_Pillar_Middle"
    },
    {
      "x": 7,
      "y": 4,
      "z": 9,
      "name": "Rock_Marble_Brick_Pillar_Base",
      "rotation": 8
    },
    {
      "x": 7,
      "y": 5,
      "z": 9,
      "name": "Rock_Marble_Brick"
    },
    {
      "x": 7,
      "y": -1,
      "z": 10,
      "name": "Soil_Mud_Dry"
    },
    {
      "x": 7,
      "y": 5,
      "z": 10,
      "name": "Plant_Vine",
      "support": 15
    },
    {
      "x": 8,
      "y": -1,
      "z": 0,
      "name": "Soil_Grass"
    },
    {
      "x": 8,
      "y": -1,
      "z": 1,
      "name": "Soil_Grass"
    },
    {
      "x": 8,
      "y": 0,
      "z": 1,
      "name": "Plant_Leaves_Oak",
      "support": 15
    },
    {
      "x": 8,
      "y": 5,
      "z": 1,
      "name": "Plant_Vine_Wall",
      "support": 15,
      "rotation": 1
    },
    {
      "x": 8,
      "y": -1,
      "z": 2,
      "name": "Soil_Grass_Deep"
    },
    {
      "x": 8,
      "y": 0,
      "z": 2,
      "name": "Plant_Leaves_Oak",
      "support": 15
    },
    {
      "x": 8,
      "y": 1,
      "z": 2,
      "name": "Plant_Leaves_Oak",
      "support": 15
    },
    {
      "x": 8,
      "y": 5,
      "z": 2,
      "name": "Rock_Marble_Brick"
    },
    {
      "x": 8,
      "y": -1,
      "z": 3,
      "name": "Soil_Pathway"
    },
    {
      "x": 8,
      "y": 5,
      "z": 3,
      "name": "Rock_Marble_Brick"
    },
    {
      "x": 8,
      "y": 6,
      "z": 3,
      "name": "Plant_Leaves_Oak",
      "support": 15
    },
    {
      "x": 8,
      "y": -1,
      "z": 4,
      "name": "Soil_Pathway"
    },
    {
      "x": 8,
      "y": 6,
      "z": 4,
      "name": "Plant_Leaves_Oak",
      "support": 15
    },
    {
      "x": 8,
      "y": -1,
      "z": 5,
      "name": "Soil_Pathway"
    },
    {
      "x": 8,
      "y": 6,
      "z": 5,
      "name": "Plant_Leaves_Oak",
      "support": 15
    },
    {
      "x": 8,
      "y": -1,
      "z": 6,
      "name": "Soil_Pathway"
    },
    {
      "x": 8,
      "y": 6,
      "z": 6,
      "name": "Plant_Leaves_Oak",
      "support": 15
    },
    {
      "x": 8,
      "y": -1,
      "z": 7,
      "name": "Soil_Mud_Dry"
    },
    {
      "x": 8,
      "y": 0,
      "z": 7,
      "name": "Furniture_Temple_Emerald_Stool",
      "support": 15,
      "rotation": 3
    },
    {
      "x": 8,
      "y": 5,
      "z": 7,
      "name": "Rock_Marble_Brick"
    },
    {
      "x": 8,
      "y": 6,
      "z": 7,
      "name": "Plant_Leaves_Oak",
      "support": 15
    },
    {
      "x": 8,
      "y": -1,
      "z": 8,
      "name": "Soil_Grass"
    },
    {
      "x": 8,
      "y": 0,
      "z": 8,
      "name": "Plant_Leaves_Oak",
      "support": 15
    },
    {
      "x": 8,
      "y": 1,
      "z": 8,
      "name": "Plant_Leaves_Oak",
      "support": 15
    },
    {
      "x": 8,
      "y": 5,
      "z": 8,
      "name": "Rock_Marble_Brick"
    },
    {
      "x": 8,
      "y": -1,
      "z": 9,
      "name": "Soil_Grass"
    },
    {
      "x": 8,
      "y": 0,
      "z": 9,
      "name": "Plant_Leaves_Oak",
      "support": 15
    },
    {
      "x": 8,
      "y": -1,
      "z": 10,
      "name": "Soil_Grass_Deep"
    },
    {
      "x": 9,
      "y": -1,
      "z": 0,
      "name": "Soil_Grass"
    },
    {
      "x": 9,
      "y": 0,
      "z": 0,
      "name": "Plant_Grass_Lush",
      "support": 15
    },
    {
      "x": 9,
      "y": -1,
      "z": 1,
      "name": "Soil_Grass"
    },
    {
      "x": 9,
      "y": 0,
      "z": 1,
      "name": "Plant_Grass_Sharp",
      "support": 15
    },
    {
      "x": 9,
      "y": -1,
      "z": 2,
      "name": "Soil_Grass"
    },
    {
      "x": 9,
      "y": 0,
      "z": 2,
      "name": "Plant_Leaves_Oak",
      "support": 15
    },
    {
      "x": 9,
      "y": -1,
      "z": 3,
      "name": "Soil_Mud_Dry"
    },
    {
      "x": 9,
      "y": 0,
      "z": 3,
      "name": "Rock_Marble_Brick_Pillar_Base"
    },
    {
      "x": 9,
      "y": 1,
      "z": 3,
      "name": "Rock_Marble_Brick_Pillar_Middle"
    },
    {
      "x": 9,
      "y": 2,
      "z": 3,
      "name": "Rock_Marble_Brick_Pillar_Middle"
    },
    {
      "x": 9,
      "y": 3,
      "z": 3,
      "name": "Rock_Marble_Brick_Pillar_Middle"
    },
    {
      "x": 9,
      "y": 4,
      "z": 3,
      "name": "Rock_Marble_Brick_Pillar_Base",
      "rotation": 8
    },
    {
      "x": 9,
      "y": 5,
      "z": 3,
      "name": "Rock_Marble_Brick"
    },
    {
      "x": 9,
      "y": -1,
      "z": 4,
      "name": "Soil_Pathway"
    },
    {
      "x": 9,
      "y": 5,
      "z": 4,
      "name": "Rock_Marble_Brick"
    },
    {
      "x": 9,
      "y": -1,
      "z": 5,
      "name": "Soil_Pathway"
    },
    {
      "x": 9,
      "y": 5,
      "z": 5,
      "name": "Rock_Marble_Brick"
    },
    {
      "x": 9,
      "y": -1,
      "z": 6,
      "name": "Soil_Pathway"
    },
    {
      "x": 9,
      "y": 5,
      "z": 6,
      "name": "Rock_Marble_Brick"
    },
    {
      "x": 9,
      "y": -1,
      "z": 7,
      "name": "Soil_Mud_Dry"
    },
    {
      "x": 9,
      "y": 0,
      "z": 7,
      "name": "Rock_Marble_Brick_Pillar_Base"
    },
    {
      "x": 9,
      "y": 1,
      "z": 7,
      "name": "Rock_Marble_Brick_Pillar_Middle"
    },
    {
      "x": 9,
      "y": 2,
      "z": 7,
      "name": "Rock_Marble_Brick_Pillar_Middle"
    },
    {
      "x": 9,
      "y": 3,
      "z": 7,
      "name": "Rock_Marble_Brick_Pillar_Middle"
    },
    {
      "x": 9,
      "y": 4,
      "z": 7,
      "name": "Rock_Marble_Brick_Pillar_Base",
      "rotation": 8
    },
    {
      "x": 9,
      "y": 5,
      "z": 7,
      "name": "Rock_Marble_Brick"
    },
    {
      "x": 9,
      "y": -1,
      "z": 8,
      "name": "Soil_Grass"
    },
    {
      "x": 9,
      "y": 0,
      "z": 8,
      "name": "Plant_Leaves_Oak",
      "support": 15
    },
    {
      "x": 9,
      "y": 5,
      "z": 8,
      "name": "Plant_Vine_Wall",
      "support": 15
    },
    {
      "x": 9,
      "y": -1,
      "z": 9,
      "name": "Soil_Grass"
    },
    {
      "x": 9,
      "y": -1,
      "z": 10,
      "name": "Soil_Grass"
    },
    {
      "x": 10,
      "y": -1,
      "z": 0,
      "name": "Soil_Grass"
    },
    {
      "x": 10,
      "y": -1,
      "z": 1,
      "name": "Soil_Grass"
    },
    {
      "x": 10,
      "y": 0,
      "z": 1,
      "name": "Plant_Grass_Sharp",
      "support": 15
    },
    {
      "x": 10,
      "y": -1,
      "z": 2,
      "name": "Soil_Grass_Deep"
    },
    {
      "x": 10,
      "y": 0,
      "z": 2,
      "name": "Plant_Grass_Lush_Short",
      "support": 15
    },
    {
      "x": 10,
      "y": -1,
      "z": 3,
      "name": "Soil_Pathway"
    },
    {
      "x": 10,
      "y": 5,
      "z": 3,
      "name": "Plant_Vine_Wall",
      "support": 15,
      "rotation": 1
    },
    {
      "x": 10,
      "y": -1,
      "z": 4,
      "name": "Soil_Pathway"
    },
    {
      "x": 10,
      "y": -1,
      "z": 5,
      "name": "Soil_Pathway"
    },
    {
      "x": 10,
      "y": -1,
      "z": 6,
      "name": "Soil_Mud_Dry"
    },
    {
      "x": 10,
      "y": 0,
      "z": 6,
      "name": "Plant_Grass_Lush_Short",
      "support": 15
    },
    {
      "x": 10,
      "y": 5,
      "z": 6,
      "name": "Plant_Vine",
      "support": 15,
      "rotation": 1
    },
    {
      "x": 10,
      "y": -1,
      "z": 7,
      "name": "Soil_Pathway"
    },
    {
      "x": 10,
      "y": -1,
      "z": 8,
      "name": "Soil_Grass"
    },
    {
      "x": 10,
      "y": 0,
      "z": 8,
      "name": "Plant_Grass_Lush",
      "support": 15
    },
    {
      "x": 10,
      "y": -1,
      "z": 9,
      "name": "Soil_Grass"
    },
    {
      "x": 10,
      "y": 0,
      "z": 9,
      "name": "Plant_Grass_Lush",
      "support": 15
    },
    {
      "x": 10,
      "y": -1,
      "z": 10,
      "name": "Soil_Grass"
    }
  ]
}