{
  "version": 8,
  "blockIdVersion": 11,
  "anchorX": 0,
  "anchorY": 0,
  "anchorZ": 0,
  "blocks": [
    {
      "x": -5,
      "y": -1,
      "z": -5,
      "name": "Soil_Grass"
    },
    {
      "x": -5,
      "y": -1,
      "z": -4,
      "name": "Soil_Grass"
    },
    {
      "x": -5,
      "y": 0,
      "z": -4,
      "name": "Plant_Grass_Sharp",
      "support": 15
    },
    {
      "x": -5,
      "y": -1,
      "z": -3,
      "name": "Soil_Grass"
    },
    {
      "x": -5,
      "y": -1,
      "z": -2,
      "name": "Soil_Mud_Dry"
    },
    {
      "x": -5,
      "y": 5,
      "z": -2,
      "name": "Plant_Vine",
      "support": 15,
      "rotation": 3
    },
    {
      "x": -5,
      "y": -1,
      "z": -1,
      "name": "Soil_Pathway"
    },
    {
      "x": -5,
      "y": -1,
      "z": 0,
      "name": "Soil_Pathway"
    },
    {
      "x": -5,
      "y": -1,
      "z": 1,
      "name": "Soil_Pathway"
    },
    {
      "x": -5,
      "y": -1,
      "z": 2,
      "name": "Soil_Mud_Dry"
    },
    {
      "x": -5,
      "y": 0,
      "z": 2,
      "name": "Plant_Grass_Lush_Short",
      "support": 15
    },
    {
      "x": -5,
      "y": -1,
      "z": 3,
      "name": "Soil_Grass"
    },
    {
      "x": -5,
      "y": 0,
      "z": 3,
      "name": "Plant_Grass_Lush_Short",
      "support": 15
    },
    {
      "x": -5,
      "y": -1,
      "z": 4,
      "name": "Soil_Grass"
    },
    {
      "x": -5,
      "y": -1,
      "z": 5,
      "name": "Soil_Grass"
    },
    {
      "x": -4,
      "y": -1,
      "z": -5,
      "name": "Soil_Grass"
    },
    {
      "x": -4,
      "y": 0,
      "z": -5,
      "name": "Plant_Grass_Sharp",
      "support": 15
    },
    {
      "x": -4,
      "y": -1,
      "z": -4,
      "name": "Soil_Grass"
    },
    {
      "x": -4,
      "y": 0,
      "z": -4,
      "name": "Plant_Grass_Lush_Short",
      "support": 15
    },
    {
      "x": -4,
      "y": -1,
      "z": -3,
      "name": "Soil_Grass"
    },
    {
      "x": -4,
      "y": 0,
      "z": -3,
      "name": "Plant_Leaves_Oak",
      "support": 15
    },
    {
      "x": -4,
      "y": -1,
      "z": -2,
      "name": "Soil_Mud_Dry"
    },
    {
      "x": -4,
      "y": 0,
      "z": -2,
      "name": "Rock_Marble_Brick_Pillar_Base"
    },
    {
      "x": -4,
      "y": 1,
      "z": -2,
      "name": "Rock_Marble_Brick_Pillar_Middle"
    },
    {
      "x": -4,
      "y": 2,
      "z": -2,
      "name": "Rock_Marble_Brick_Pillar_Middle"
    },
    {
      "x": -4,
      "y": 3,
      "z": -2,
      "name": "Rock_Marble_Brick_Pillar_Middle"
    },
    {
      "x": -4,
      "y": 4,
      "z": -2,
      "name": "Rock_Marble_Brick_Pillar_Base",
      "rotation": 8
    },
    {
      "x": -4,
      "y": 5,
      "z": -2,
      "name": "Rock_Marble_Brick"
    },
    {
      "x": -4,
      "y": -1,
      "z": -1,
      "name": "Soil_Pathway"
    },
    {
      "x": -4,
      "y": 5,
      "z": -1,
      "name": "Rock_Marble_Brick"
    },
    {
      "x": -4,
      "y": -1,
      "z": 0,
      "name": "Soil_Pathway"
    },
    {
      "x": -4,
      "y": 5,
      "z": 0,
      "name": "Rock_Marble_Brick"
    },
    {
      "x": -4,
      "y": -1,
      "z": 1,
      "name": "Soil_Pathway"
    },
    {
      "x": -4,
      "y": 5,
      "z": 1,
      "name": "Rock_Marble_Brick"
    },
    {
      "x": -4,
      "y": -1,
      "z": 2,
      "name": "Soil_Pathway"
    },
    {
      "x": -4,
      "y": 0,
      "z": 2,
      "name": "Rock_Marble_Brick_Pillar_Base"
    },
    {
      "x": -4,
      "y": 1,
      "z": 2,
      "name": "Rock_Marble_Brick_Pillar_Middle"
    },
    {
      "x": -4,
      "y": 2,
      "z": 2,
      "name": "Rock_Marble_Brick_Pillar_Middle"
    },
    {
      "x": -4,
      "y": 3,
      "z": 2,
      "name": "Rock_Marble_Brick_Pillar_Middle"
    },
    {
      "x": -4,
      "y": 4,
      "z": 2,
      "name": "Rock_Marble_Brick_Pillar_Base",
      "rotation": 8
    },
    {
      "x": -4,
      "y": 5,
      "z": 2,
      "name": "Rock_Marble_Brick"
    },
    {
      "x": -4,
      "y": -1,
      "z": 3,
      "name": "Soil_Grass"
    },
    {
      "x": -4,
      "y": 0,
      "z": 3,
      "name": "Plant_Leaves_Oak",
      "support": 15
    },
    {
      "x": -4,
      "y": -1,
      "z": 4,
      "name": "Soil_Grass"
    },
    {
      "x": -4,
      "y": 0,
      "z": 4,
      "name": "Plant_Grass_Lush_Short",
      "support": 15
    },
    {
      "x": -4,
      "y": -1,
      "z": 5,
      "name": "Soil_Grass"
    },
    {
      "x": -3,
      "y": -1,
      "z": -5,
      "name": "Soil_Grass"
    },
    {
      "x": -3,
      "y": -1,
      "z": -4,
      "name": "Soil_Grass_Deep"
    },
    {
      "x": -3,
      "y": 0,
      "z": -4,
      "name": "Plant_Leaves_Oak",
      "support": 15
    },
    {
      "x": -3,
      "y": 5,
      "z": -4,
      "name": "Plant_Vine_Wall",
      "support": 15,
      "rotation": 2
    },
    {
      "x": -3,
      "y": -1,
      "z": -3,
      "name": "Soil_Grass_Deep"
    },
    {
      "x": -3,
      "y": 0,
      "z": -3,
      "name": "Plant_Leaves_Oak",
      "support": 15
    },
    {
      "x": -3,
      "y": 1,
      "z": -3,
      "name": "Plant_Leaves_Oak",
      "support": 15
    },
    {
      "x": -3,
      "y": 5,
      "z": -3,
      "name": "Rock_Marble_Brick"
    },
    {
      "x": -3,
      "y": -1,
      "z": -2,
      "name": "Soil_Pathway"
    },
    {
      "x": -3,
      "y": 0,
      "z": -2,
      "name": "Furniture_Temple_Emerald_Stool",
      "support": 15
    },
    {
      "x": -3,
      "y": 5,
      "z": -2,
      "name": "Rock_Marble_Brick"
    },
    {
      "x": -3,
      "y": 6,
      "z": -2,
      "name": "Plant_Leaves_Oak",
      "support": 15
    },
    {
      "x": -3,
      "y": -1,
      "z": -1,
      "name": "Soil_Pathway"
    },
    {
      "x": -3,
      "y": 6,
      "z": -1,
      "name": "Plant_Leaves_Oak",
      "support": 15
    },
    {
      "x": -3,
      "y": -1,
      "z": 0,
      "name": "Soil_Pathway"
    },
    {
      "x": -3,
      "y": 6,
      "z": 0,
      "name": "Plant_Leaves_Oak",
      "support": 15
    },
    {
      "x": -3,
      "y": -1,
      "z": 1,
      "name": "Soil_Mud_Dry"
    },
    {
      "x": -3,
      "y": 6,
      "z": 1,
      "name": "Plant_Leaves_Oak",
      "support": 15
    },
    {
      "x": -3,
      "y": -1,
      "z": 2,
      "name": "Soil_Pathway"
    },
    {
      "x": -3,
      "y": 5,
      "z": 2,
      "name": "Rock_Marble_Brick"
    },
    {
      "x": -3,
      "y": 6,
      "z": 2,
      "name": "Plant_Leaves_Oak",
      "support": 15
    },
    {
      "x": -3,
      "y": -1,
      "z": 3,
      "name": "Soil_Grass"
    },
    {
      "x": -3,
      "y": 0,
      "z": 3,
      "name": "Plant_Leaves_Oak",
      "support": 15
    },
    {
      "x": -3,
      "y": 1,
      "z": 3,
      "name": "Plant_Leaves_Oak",
      "support": 15
    },
    {
      "x": -3,
      "y": 5,
      "z": 3,
      "name": "Rock_Marble_Brick"
    },
    {
      "x": -3,
      "y": -1,
      "z": 4,
      "name": "Soil_Grass"
    },
    {
      "x": -3,
      "y": 0,
      "z": 4,
      "name": "Plant_Leaves_Oak",
      "support": 15
    },
    {
      "x": -3,
      "y": -1,
      "z": 5,
      "name": "Soil_Grass_Deep"
    },
    {
      "x": -2,
      "y": -1,
      "z": -5,
      "name": "Soil_Mud_Dry"
    },
    {
      "x": -2,
      "y": -1,
      "z": -4,
      "name": "Soil_Pathway"
    },
    {
      "x": -2,
      "y": 0,
      "z": -4,
      "name": "Rock_Marble_Brick_Pillar_Base"
    },
    {
      "x": -2,
      "y": 1,
      "z": -4,
      "name": "Rock_Marble_Brick_Pillar_Middle"
    },
    {
      "x": -2,
      "y": 2,
      "z": -4,
      "name": "Rock_Marble_Brick_Pillar_Middle"
    },
    {
      "x": -2,
      "y": 3,
      "z": -4,
      "name": "Rock_Marble_Brick_Pillar_Middle"
    },
    {
      "x": -2,
      "y": 4,
      "z": -4,
      "name": "Rock_Marble_Brick_Pillar_Base",
      "rotation": 8
    },
    {
      "x": -2,
      "y": 5,
      "z": -4,
      "name": "Rock_Marble_Brick"
    },
    {
      "x": -2,
      "y": -1,
      "z": -3,
      "name": "Soil_Mud_Dry"
    },
    {
      "x": -2,
      "y": 5,
      "z": -3,
      "name": "Rock_Marble_Brick"
    },
    {
      "x": -2,
      "y": 6,
      "z": -3,
      "name": "Plant_Leaves_Oak",
      "support": 15
    },
    {
      "x": -2,
      "y": -1,
      "z": -2,
      "name": "Soil_Mud_Dry"
    },
    {
      "x": -2,
      "y": 5,
      "z": -2,
      "name": "Plant_Leaves_Oak",
      "support": 15
    },
    {
      "x": -2,
      "y": 6,
      "z": -2,
      "name": "Plant_Leaves_Oak",
      "support": 15
    },
    {
      "x": -2,
      "y": -1,
      "z": -1,
      "name": "Soil_Pathway"
    },
    {
      "x": -2,
      "y": 6,
      "z": -1,
      "name": "Plant_Leaves_Oak",
      "support": 15
    },
    {
      "x": -2,
      "y": -1,
      "z": 0,
      "name": "Soil_Pathway"
    },
    {
      "x": -2,
      "y": -1,
      "z": 1,
      "name": "Soil_Mud_Dry"
    },
    {
      "x": -2,
      "y": 6,
      "z": 1,
      "name": "Plant_Leaves_Oak",
      "support": 15
    },
    {
      "x": -2,
      "y": -1,
      "z": 2,
      "name": "Soil_Pathway"
    },
    {
      "x": -2,
      "y": 5,
      "z": 2,
      "name": "Plant_Leaves_Oak",
      "support": 15
    },
    {
      "x": -2,
      "y": 6,
      "z": 2,
      "name": "Plant_Leaves_Oak",
      "support": 15
    },
    {
      "x": -2,
      "y": -1,
      "z": 3,
      "name": "Soil_Pathway"
    },
    {
      "x": -2,
      "y": 5,
      "z": 3,
      "name": "Rock_Marble_Brick"
    },
    {
      "x": -2,
      "y": 6,
      "z": 3,
      "name": "Plant_Leaves_Oak",
      "support": 15
    },
    {
      "x": -2,
      "y": -1,
      "z": 4,
      "name": "Soil_Grass_Deep"
    },
    {
      "x": -2,
      "y": 0,
      "z": 4,
      "name": "Rock_Marble_Brick_Pillar_Base"
    },
    {
      "x": -2,
      "y": 1,
      "z": 4,
      "name": "Rock_Marble_Brick_Pillar_Middle"
    },
    {
      "x": -2,
      "y": 2,
      "z": 4,
      "name": "Rock_Marble_Brick_Pillar_Middle"
    },
    {
      "x": -2,
      "y": 3,
      "z": 4,
      "name": "Rock_Marble_Brick_Pillar_Middle"
    },
    {
      "x": -2,
      "y": 4,
      "z": 4,
      "name": "Rock_Marble_Brick_Pillar_Base",
      "rotation": 8
    },
    {
      "x": -2,
      "y": 5,
      "z": 4,
      "name": "Rock_Marble_Brick"
    },
    {
      "x": -2,
      "y": -1,
      "z": 5,
      "name": "Soil_Mud_Dry"
    },
    {
      "x": -2,
      "y": 0,
      "z": 5,
      "name": "Plant_Grass_Sharp",
      "support": 15
    },
    {
      "x": -2,
      "y": 5,
      "z": 5,
      "name": "Plant_Vine",
      "support": 15
    },
    {
      "x": -1,
      "y": -1,
      "z": -5,
      "name": "Soil_Mud_Dry"
    },
    {
      "x": -1,
      "y": -1,
      "z": -4,
      "name": "Soil_Mud_Dry"
    },
    {
      "x": -1,
      "y": 5,
      "z": -4,
      "name": "Rock_Marble_Brick"
    },
    {
      "x": -1,
      "y": -1,
      "z": -3,
      "name": "Soil_Pathway"
    },
    {
      "x": -1,
      "y": 6,
      "z": -3,
      "name": "Plant_Leaves_Oak",
      "support": 15
    },
    {
      "x": -1,
      "y": -1,
      "z": -2,
      "name": "Soil_Pathway"
    },
    {
      "x": -1,
      "y": 6,
      "z": -2,
      "name": "Plant_Leaves_Oak",
      "support": 15
    },
    {
      "x": -1,
      "y": -1,
      "z": -1,
      "name": "Soil_Pathway"
    },
    {
      "x": -1,
      "y": -1,
      "z": 0,
      "name": "Soil_Pathway"
    },
    {
      "x": -1,
      "y": -1,
      "z": 1,
      "name": "Soil_Mud_Dry"
    },
    {
      "x": -1,
      "y": -1,
      "z": 2,
      "name": "Soil_Pathway"
    },
    {
      "x": -1,
      "y": 6,
      "z": 2,
      "name": "Plant_Leaves_Oak",
      "support": 15
    },
    {
      "x": -1,
      "y": -1,
      "z": 3,
      "name": "Soil_Mud_Dry"
    },
    {
      "x": -1,
      "y": 6,
      "z": 3,
      "name": "Plant_Leaves_Oak",
      "support": 15
    },
    {
      "x": -1,
      "y": -1,
      "z": 4,
      "name": "Soil_Pathway"
    },
    {
      "x": -1,
      "y": 5,
      "z": 4,
      "name": "Rock_Marble_Brick"
    },
    {
      "x": -1,
      "y": -1,
      "z": 5,
      "name": "Soil_Pathway"
    },
    {
      "x": 0,
      "y": -1,
      "z": -5,
      "name": "Soil_Mud_Dry"
    },
    {
      "x": 0,
      "y": -1,
      "z": -4,
      "name": "Soil_Pathway"
    },
    {
      "x": 0,
      "y": 5,
      "z": -4,
      "name": "Rock_Marble_Brick"
    },
    {
      "x": 0,
      "y": -1,
      "z": -3,
      "name": "Soil_Pathway"
    },
    {
      "x": 0,
      "y": 6,
      "z": -3,
      "name": "Plant_Leaves_Oak",
      "support": 15
    },
    {
      "x": 0,
      "y": -1,
      "z": -2,
      "name": "Soil_Pathway"
    },
    {
      "x": 0,
      "y": -1,
      "z": -1,
      "name": "Soil_Mud_Dry"
    },
    {
      "x": 0,
      "y": -1,
      "z": 0,
      "name": "Soil_Pathway"
    },
    {
      "x": 0,
      "y": 0,
      "z": 0,
      "name": "Rock_Marble_Brick"
    },
    {
      "x": 0,
      "y": 1,
      "z": 0,
      "name": "Aetherhaven_Statue_Of_Gaia",
      "components": {
        "Components": {
          "AetherhavenGaiaStatueBlock": {
            "PlotId": "",
            "TownId": ""
          }
        }
      },
      "support": 15,
      "rotation": 3
    },
    {
      "x": 0,
      "y": -1,
      "z": 1,
      "name": "Soil_Pathway"
    },
    {
      "x": 0,
      "y": -1,
      "z": 2,
      "name": "Soil_Pathway"
    },
    {
      "x": 0,
      "y": -1,
      "z": 3,
      "name": "Soil_Pathway"
    },
    {
      "x": 0,
      "y": 6,
      "z": 3,
      "name": "Plant_Leaves_Oak",
      "support": 15
    },
    {
      "x": 0,
      "y": -1,
      "z": 4,
      "name": "Soil_Mud_Dry"
    },
    {
      "x": 0,
      "y": 5,
      "z": 4,
      "name": "Rock_Marble_Brick"
    },
    {
      "x": 0,
      "y": -1,
      "z": 5,
      "name": "Soil_Mud_Dry"
    },
    {
      "x": 1,
      "y": -1,
      "z": -5,
      "name": "Soil_Pathway"
    },
    {
      "x": 1,
      "y": -1,
      "z": -4,
      "name": "Soil_Pathway"
    },
    {
      "x": 1,
      "y": 5,
      "z": -4,
      "name": "Rock_Marble_Brick"
    },
    {
      "x": 1,
      "y": -1,
      "z": -3,
      "name": "Soil_Mud_Dry"
    },
    {
      "x": 1,
      "y": 6,
      "z": -3,
      "name": "Plant_Leaves_Oak",
      "support": 15
    },
    {
      "x": 1,
      "y": -1,
      "z": -2,
      "name": "Soil_Pathway"
    },
    {
      "x": 1,
      "y": 6,
      "z": -2,
      "name": "Plant_Leaves_Oak",
      "support": 15
    },
    {
      "x": 1,
      "y": -1,
      "z": -1,
      "name": "Soil_Pathway"
    },
    {
      "x": 1,
      "y": -1,
      "z": 0,
      "name": "Soil_Mud_Dry"
    },
    {
      "x": 1,
      "y": -1,
      "z": 1,
      "name": "Soil_Pathway"
    },
    {
      "x": 1,
      "y": -1,
      "z": 2,
      "name": "Soil_Pathway"
    },
    {
      "x": 1,
      "y": 6,
      "z": 2,
      "name": "Plant_Leaves_Oak",
      "support": 15
    },
    {
      "x": 1,
      "y": -1,
      "z": 3,
      "name": "Soil_Pathway"
    },
    {
      "x": 1,
      "y": 6,
      "z": 3,
      "name": "Plant_Leaves_Oak",
      "support": 15
    },
    {
      "x": 1,
      "y": -1,
      "z": 4,
      "name": "Soil_Pathway"
    },
    {
      "x": 1,
      "y": 5,
      "z": 4,
      "name": "Rock_Marble_Brick"
    },
    {
      "x": 1,
      "y": -1,
      "z": 5,
      "name": "Soil_Pathway"
    },
    {
      "x": 2,
      "y": -1,
      "z": -5,
      "name": "Soil_Pathway"
    },
    {
      "x": 2,
      "y": -1,
      "z": -4,
      "name": "Soil_Mud_Dry"
    },
    {
      "x": 2,
      "y": 0,
      "z": -4,
      "name": "Rock_Marble_Brick_Pillar_Base"
    },
    {
      "x": 2,
      "y": 1,
      "z": -4,
      "name": "Rock_Marble_Brick_Pillar_Middle"
    },
    {
      "x": 2,
      "y": 2,
      "z": -4,
      "name": "Rock_Marble_Brick_Pillar_Middle"
    },
    {
      "x": 2,
      "y": 3,
      "z": -4,
      "name": "Rock_Marble_Brick_Pillar_Middle"
    },
    {
      "x": 2,
      "y": 4,
      "z": -4,
      "name": "Rock_Marble_Brick_Pillar_Base",
      "rotation": 8
    },
    {
      "x": 2,
      "y": 5,
      "z": -4,
      "name": "Rock_Marble_Brick"
    },
    {
      "x": 2,
      "y": -1,
      "z": -3,
      "name": "Soil_Pathway"
    },
    {
      "x": 2,
      "y": 5,
      "z": -3,
      "name": "Rock_Marble_Brick"
    },
    {
      "x": 2,
      "y": 6,
      "z": -3,
      "name": "Plant_Leaves_Oak",
      "support": 15
    },
    {
      "x": 2,
      "y": -1,
      "z": -2,
      "name": "Soil_Pathway"
    },
    {
      "x": 2,
      "y": 5,
      "z": -2,
      "name": "Plant_Leaves_Oak",
      "support": 15
    },
    {
      "x": 2,
      "y": 6,
      "z": -2,
      "name": "Plant_Leaves_Oak",
      "support": 15
    },
    {
      "x": 2,
      "y": -1,
      "z": -1,
      "name": "Soil_Mud_Dry"
    },
    {
      "x": 2,
      "y": 6,
      "z": -1,
      "name": "Plant_Leaves_Oak",
      "support": 15
    },
    {
      "x": 2,
      "y": -1,
      "z": 0,
      "name": "Soil_Pathway"
    },
    {
      "x": 2,
      "y": -1,
      "z": 1,
      "name": "Soil_Mud_Dry"
    },
    {
      "x": 2,
      "y": 6,
      "z": 1,
      "name": "Plant_Leaves_Oak",
      "support": 15
    },
    {
      "x": 2,
      "y": -1,
      "z": 2,
      "name": "Soil_Pathway"
    },
    {
      "x": 2,
      "y": 5,
      "z": 2,
      "name": "Plant_Leaves_Oak",
      "support": 15
    },
    {
      "x": 2,
      "y": 6,
      "z": 2,
      "name": "Plant_Leaves_Oak",
      "support": 15
    },
    {
      "x": 2,
      "y": -1,
      "z": 3,
      "name": "Soil_Pathway"
    },
    {
      "x": 2,
      "y": 0,
      "z": 3,
      "name": "Aetherhaven_Management_Block",
      "components": {
        "Components": {
          "AetherhavenManagementBlock": {
            "PlotId": "",
            "TownId": ""
          },
          "PlacedByInteraction": {
            "WhoPlacedUuid": {
              "$binary": "v7RyWIT/TYKnXA2XcxdQtw==",
              "$type": "04"
            }
          }
        }
      },
      "rotation": 2
    },
    {
      "x": 2,
      "y": 5,
      "z": 3,
      "name": "Rock_Marble_Brick"
    },
    {
      "x": 2,
      "y": 6,
      "z": 3,
      "name": "Plant_Leaves_Oak",
      "support": 15
    },
    {
      "x": 2,
      "y": -1,
      "z": 4,
      "name": "Soil_Grass"
    },
    {
      "x": 2,
      "y": 0,
      "z": 4,
      "name": "Rock_Marble_Brick_Pillar_Base"
    },
    {
      "x": 2,
      "y": 1,
      "z": 4,
      "name": "Rock_Marble_Brick_Pillar_Middle"
    },
    {
      "x": 2,
      "y": 2,
      "z": 4,
      "name": "Rock_Marble_Brick_Pillar_Middle"
    },
    {
      "x": 2,
      "y": 3,
      "z": 4,
      "name": "Rock_Marble_Brick_Pillar_Middle"
    },
    {
      "x": 2,
      "y": 4,
      "z": 4,
      "name": "Rock_Marble_Brick_Pillar_Base",
      "rotation": 8
    },
    {
      "x": 2,
      "y": 5,
      "z": 4,
      "name": "Rock_Marble_Brick"
    },
    {
      "x": 2,
      "y": -1,
      "z": 5,
      "name": "Soil_Mud_Dry"
    },
    {
      "x": 2,
      "y": 5,
      "z": 5,
      "name": "Plant_Vine",
      "support": 15
    },
    {
      "x": 3,
      "y": -1,
      "z": -5,
      "name": "Soil_Grass"
    },
    {
      "x": 3,
      "y": -1,
      "z": -4,
      "name": "Soil_Grass"
    },
    {
      "x": 3,
      "y": 0,
      "z": -4,
      "name": "Plant_Leaves_Oak",
      "support": 15
    },
    {
      "x": 3,
      "y": 5,
      "z": -4,
      "name": "Plant_Vine_Wall",
      "support": 15,
      "rotation": 1
    },
    {
      "x": 3,
      "y": -1,
      "z": -3,
      "name": "Soil_Grass_Deep"
    },
    {
      "x": 3,
      "y": 0,
      "z": -3,
      "name": "Plant_Leaves_Oak",
      "support": 15
    },
    {
      "x": 3,
      "y": 1,
      "z": -3,
      "name": "Plant_Leaves_Oak",
      "support": 15
    },
    {
      "x": 3,
      "y": 5,
      "z": -3,
      "name": "Rock_Marble_Brick"
    },
    {
      "x": 3,
      "y": -1,
      "z": -2,
      "name": "Soil_Pathway"
    },
    {
      "x": 3,
      "y": 5,
      "z": -2,
      "name": "Rock_Marble_Brick"
    },
    {
      "x": 3,
      "y": 6,
      "z": -2,
      "name": "Plant_Leaves_Oak",
      "support": 15
    },
    {
      "x": 3,
      "y": -1,
      "z": -1,
      "name": "Soil_Pathway"
    },
    {
      "x": 3,
      "y": 6,
      "z": -1,
      "name": "Plant_Leaves_Oak",
      "support": 15
    },
    {
      "x": 3,
      "y": -1,
      "z": 0,
      "name": "Soil_Pathway"
    },
    {
      "x": 3,
      "y": 6,
      "z": 0,
      "name": "Plant_Leaves_Oak",
      "support": 15
    },
    {
      "x": 3,
      "y": -1,
      "z": 1,
      "name": "Soil_Pathway"
    },
    {
      "x": 3,
      "y": 6,
      "z": 1,
      "name": "Plant_Leaves_Oak",
      "support": 15
    },
    {
      "x": 3,
      "y": -1,
      "z": 2,
      "name": "Soil_Mud_Dry"
    },
    {
      "x": 3,
      "y": 0,
      "z": 2,
      "name": "Furniture_Temple_Emerald_Stool",
      "support": 15,
      "rotation": 3
    },
    {
      "x": 3,
      "y": 5,
      "z": 2,
      "name": "Rock_Marble_Brick"
    },
    {
      "x": 3,
      "y": 6,
      "z": 2,
      "name": "Plant_Leaves_Oak",
      "support": 15
    },
    {
      "x": 3,
      "y": -1,
      "z": 3,
      "name": "Soil_Grass"
    },
    {
      "x": 3,
      "y": 0,
      "z": 3,
      "name": "Plant_Leaves_Oak",
      "support": 15
    },
    {
      "x": 3,
      "y": 1,
      "z": 3,
      "name": "Plant_Leaves_Oak",
      "support": 15
    },
    {
      "x": 3,
      "y": 5,
      "z": 3,
      "name": "Rock_Marble_Brick"
    },
    {
      "x": 3,
      "y": -1,
      "z": 4,
      "name": "Soil_Grass"
    },
    {
      "x": 3,
      "y": 0,
      "z": 4,
      "name": "Plant_Leaves_Oak",
      "support": 15
    },
    {
      "x": 3,
      "y": -1,
      "z": 5,
      "name": "Soil_Grass_Deep"
    },
    {
      "x": 4,
      "y": -1,
      "z": -5,
      "name": "Soil_Grass"
    },
    {
      "x": 4,
      "y": 0,
      "z": -5,
      "name": "Plant_Grass_Lush",
      "support": 15
    },
    {
      "x": 4,
      "y": -1,
      "z": -4,
      "name": "Soil_Grass"
    },
    {
      "x": 4,
      "y": 0,
      "z": -4,
      "name": "Plant_Grass_Sharp",
      "support": 15
    },
    {
      "x": 4,
      "y": -1,
      "z": -3,
      "name": "Soil_Grass"
    },
    {
      "x": 4,
      "y": 0,
      "z": -3,
      "name": "Plant_Leaves_Oak",
      "support": 15
    },
    {
      "x": 4,
      "y": -1,
      "z": -2,
      "name": "Soil_Mud_Dry"
    },
    {
      "x": 4,
      "y": 0,
      "z": -2,
      "name": "Rock_Marble_Brick_Pillar_Base"
    },
    {
      "x": 4,
      "y": 1,
      "z": -2,
      "name": "Rock_Marble_Brick_Pillar_Middle"
    },
    {
      "x": 4,
      "y": 2,
      "z": -2,
      "name": "Rock_Marble_Brick_Pillar_Middle"
    },
    {
      "x": 4,
      "y": 3,
      "z": -2,
      "name": "Rock_Marble_Brick_Pillar_Middle"
    },
    {
      "x": 4,
      "y": 4,
      "z": -2,
      "name": "Rock_Marble_Brick_Pillar_Base",
      "rotation": 8
    },
    {
      "x": 4,
      "y": 5,
      "z": -2,
      "name": "Rock_Marble_Brick"
    },
    {
      "x": 4,
      "y": -1,
      "z": -1,
      "name": "Soil_Pathway"
    },
    {
      "x": 4,
      "y": 5,
      "z": -1,
      "name": "Rock_Marble_Brick"
    },
    {
      "x": 4,
      "y": -1,
      "z": 0,
      "name": "Soil_Pathway"
    },
    {
      "x": 4,
      "y": 5,
      "z": 0,
      "name": "Rock_Marble_Brick"
    },
    {
      "x": 4,
      "y": -1,
      "z": 1,
      "name": "Soil_Pathway"
    },
    {
      "x": 4,
      "y": 5,
      "z": 1,
      "name": "Rock_Marble_Brick"
    },
    {
      "x": 4,
      "y": -1,
      "z": 2,
      "name": "Soil_Mud_Dry"
    },
    {
      "x": 4,
      "y": 0,
      "z": 2,
      "name": "Rock_Marble_Brick_Pillar_Base"
    },
    {
      "x": 4,
      "y": 1,
      "z": 2,
      "name": "Rock_Marble_Brick_Pillar_Middle"
    },
    {
      "x": 4,
      "y": 2,
      "z": 2,
      "name": "Rock_Marble_Brick_Pillar_Middle"
    },
    {
      "x": 4,
      "y": 3,
      "z": 2,
      "name": "Rock_Marble_Brick_Pillar_Middle"
    },
    {
      "x": 4,
      "y": 4,
      "z": 2,
      "name": "Rock_Marble_Brick_Pillar_Base",
      "rotation": 8
    },
    {
      "x": 4,
      "y": 5,
      "z": 2,
      "name": "Rock_Marble_Brick"
    },
    {
      "x": 4,
      "y": -1,
      "z": 3,
      "name": "Soil_Grass"
    },
    {
      "x": 4,
      "y": 0,
      "z": 3,
      "name": "Plant_Leaves_Oak",
      "support": 15
    },
    {
      "x": 4,
      "y": 5,
      "z": 3,
      "name": "Plant_Vine_Wall",
      "support": 15
    },
    {
      "x": 4,
      "y": -1,
      "z": 4,
      "name": "Soil_Grass"
    },
    {
      "x": 4,
      "y": -1,
      "z": 5,
      "name": "Soil_Grass"
    },
    {
      "x": 5,
      "y": -1,
      "z": -5,
      "name": "Soil_Grass"
    },
    {
      "x": 5,
      "y": -1,
      "z": -4,
      "name": "Soil_Grass"
    },
    {
      "x": 5,
      "y": 0,
      "z": -4,
      "name": "Plant_Grass_Sharp",
      "support": 15
    },
    {
      "x": 5,
      "y": -1,
      "z": -3,
      "name": "Soil_Grass_Deep"
    },
    {
      "x": 5,
      "y": 0,
      "z": -3,
      "name": "Plant_Grass_Lush_Short",
      "support": 15
    },
    {
      "x": 5,
      "y": -1,
      "z": -2,
      "name": "Soil_Pathway"
    },
    {
      "x": 5,
      "y": 5,
      "z": -2,
      "name": "Plant_Vine_Wall",
      "support": 15,
      "rotation": 1
    },
    {
      "x": 5,
      "y": -1,
      "z": -1,
      "name": "Soil_Pathway"
    },
    {
      "x": 5,
      "y": -1,
      "z": 0,
      "name": "Soil_Pathway"
    },
    {
      "x": 5,
      "y": -1,
      "z": 1,
      "name": "Soil_Mud_Dry"
    },
    {
      "x": 5,
      "y": 0,
      "z": 1,
      "name": "Plant_Grass_Lush_Short",
      "support": 15
    },
    {
      "x": 5,
      "y": 5,
      "z": 1,
      "name": "Plant_Vine",
      "support": 15,
      "rotation": 1
    },
    {
      "x": 5,
      "y": -1,
      "z": 2,
      "name": "Soil_Pathway"
    },
    {
      "x": 5,
      "y": -1,
      "z": 3,
      "name": "Soil_Grass"
    },
    {
      "x": 5,
      "y": 0,
      "z": 3,
      "name": "Plant_Grass_Lush",
      "support": 15
    },
    {
      "x": 5,
      "y": -1,
      "z": 4,
      "name": "Soil_Grass"
    },
    {
      "x": 5,
      "y": 0,
      "z": 4,
      "name": "Plant_Grass_Lush",
      "support": 15
    },
    {
      "x": 5,
      "y": -1,
      "z": 5,
      "name": "Soil_Grass"
    }
  ]
}
