{
  "version": 8,
  "blockIdVersion": 11,
  "anchorX": 0,
  "anchorY": 0,
  "anchorZ": 0,
  "blocks": [
    {
      "x": 1,
      "y": -1,
      "z": 1,
      "name": "Rock_Stone_Cobble"
    },
    {
      "x": 1,
      "y": -1,
      "z": 2,
      "name": "Rock_Stone_Cobble"
    },
    {
      "x": 1,
      "y": -1,
      "z": 3,
      "name": "Rock_Stone_Cobble"
    },
    {
      "x": 1,
      "y": 3,
      "z": 3,
      "name": "Wood_Softwood_Roof_Hollow",
      "rotation": 2
    },
    {
      "x": 1,
      "y": -1,
      "z": 4,
      "name": "Rock_Stone_Cobble"
    },
    {
      "x": 1,
      "y": 3,
      "z": 4,
      "name": "Wood_Beech_Branch_Corner",
      "support": 15,
      "rotation": 3
    },
    {
      "x": 1,
      "y": 4,
      "z": 4,
      "name": "Wood_Softwood_Roof",
      "rotation": 2
    },
    {
      "x": 1,
      "y": -1,
      "z": 5,
      "name": "Rock_Stone_Cobble"
    },
    {
      "x": 1,
      "y": 3,
      "z": 5,
      "name": "Wood_Beech_Branch_Short",
      "support": 15,
      "rotation": 3
    },
    {
      "x": 1,
      "y": 4,
      "z": 5,
      "name": "Wood_Softwood_Planks_Half",
      "rotation": 8
    },
    {
      "x": 1,
      "y": 5,
      "z": 5,
      "name": "Wood_Softwood_Roof",
      "rotation": 2
    },
    {
      "x": 1,
      "y": -1,
      "z": 6,
      "name": "Rock_Stone_Cobble"
    },
    {
      "x": 1,
      "y": 2,
      "z": 6,
      "name": "Plant_Vine_Wall",
      "support": 15,
      "rotation": 3
    },
    {
      "x": 1,
      "y": 3,
      "z": 6,
      "name": "Plant_Vine",
      "support": 15,
      "rotation": 3
    },
    {
      "x": 1,
      "y": 5,
      "z": 6,
      "name": "Wood_Softwood_Planks_Half",
      "rotation": 8
    },
    {
      "x": 1,
      "y": 6,
      "z": 6,
      "name": "Wood_Softwood_Roof",
      "rotation": 2
    },
    {
      "x": 1,
      "y": -1,
      "z": 7,
      "name": "Rock_Stone_Cobble"
    },
    {
      "x": 1,
      "y": 3,
      "z": 7,
      "name": "Wood_Beech_Branch_Short",
      "support": 15,
      "rotation": 3
    },
    {
      "x": 1,
      "y": 6,
      "z": 7,
      "name": "Wood_Softwood_Planks_Half",
      "rotation": 8
    },
    {
      "x": 1,
      "y": 7,
      "z": 7,
      "name": "Wood_Softwood_Roof",
      "rotation": 2
    },
    {
      "x": 1,
      "y": -1,
      "z": 8,
      "name": "Rock_Stone_Cobble"
    },
    {
      "x": 1,
      "y": 6,
      "z": 8,
      "name": "Wood_Softwood_Planks_Half",
      "rotation": 8
    },
    {
      "x": 1,
      "y": 7,
      "z": 8,
      "name": "Wood_Softwood_Roof"
    },
    {
      "x": 1,
      "y": -1,
      "z": 9,
      "name": "Rock_Stone_Cobble"
    },
    {
      "x": 1,
      "y": 3,
      "z": 9,
      "name": "Wood_Beech_Branch_Short",
      "support": 15,
      "rotation": 3
    },
    {
      "x": 1,
      "y": 5,
      "z": 9,
      "name": "Wood_Softwood_Planks_Half",
      "rotation": 8
    },
    {
      "x": 1,
      "y": 6,
      "z": 9,
      "name": "Wood_Softwood_Roof"
    },
    {
      "x": 1,
      "y": -1,
      "z": 10,
      "name": "Rock_Stone_Cobble"
    },
    {
      "x": 1,
      "y": 1,
      "z": 10,
      "name": "Plant_Vine_Wall",
      "support": 15,
      "rotation": 3
    },
    {
      "x": 1,
      "y": 2,
      "z": 10,
      "name": "Plant_Vine",
      "support": 15,
      "rotation": 3
    },
    {
      "x": 1,
      "y": 4,
      "z": 10,
      "name": "Wood_Softwood_Planks_Half",
      "rotation": 8
    },
    {
      "x": 1,
      "y": 5,
      "z": 10,
      "name": "Wood_Softwood_Roof"
    },
    {
      "x": 1,
      "y": -1,
      "z": 11,
      "name": "Rock_Stone_Cobble"
    },
    {
      "x": 1,
      "y": 3,
      "z": 11,
      "name": "Wood_Beech_Branch_Corner",
      "support": 15,
      "rotation": 3
    },
    {
      "x": 1,
      "y": 4,
      "z": 11,
      "name": "Wood_Softwood_Roof"
    },
    {
      "x": 1,
      "y": -1,
      "z": 12,
      "name": "Rock_Stone_Cobble"
    },
    {
      "x": 1,
      "y": 3,
      "z": 12,
      "name": "Wood_Softwood_Roof_Hollow"
    },
    {
      "x": 2,
      "y": -1,
      "z": 1,
      "name": "Rock_Stone_Cobble"
    },
    {
      "x": 2,
      "y": -1,
      "z": 2,
      "name": "Rock_Stone_Cobble"
    },
    {
      "x": 2,
      "y": -1,
      "z": 3,
      "name": "Rock_Stone_Cobble"
    },
    {
      "x": 2,
      "y": 2,
      "z": 3,
      "name": "Wood_Beech_Branch_Corner",
      "support": 15,
      "rotation": 2
    },
    {
      "x": 2,
      "y": 3,
      "z": 3,
      "name": "Wood_Softwood_Roof",
      "rotation": 2
    },
    {
      "x": 2,
      "y": -1,
      "z": 4,
      "name": "Rock_Stone_Cobble"
    },
    {
      "x": 2,
      "y": 0,
      "z": 4,
      "name": "Wood_Beech_Trunk",
      "support": 15
    },
    {
      "x": 2,
      "y": 1,
      "z": 4,
      "name": "Wood_Beech_Trunk",
      "support": 15
    },
    {
      "x": 2,
      "y": 2,
      "z": 4,
      "name": "Wood_Beech_Trunk",
      "support": 15
    },
    {
      "x": 2,
      "y": 3,
      "z": 4,
      "name": "Wood_Beech_Trunk",
      "support": 15
    },
    {
      "x": 2,
      "y": 4,
      "z": 4,
      "name": "Wood_Softwood_Roof",
      "rotation": 2
    },
    {
      "x": 2,
      "y": -1,
      "z": 5,
      "name": "Rock_Stone_Cobble"
    },
    {
      "x": 2,
      "y": 0,
      "z": 5,
      "name": "Rock_Stone_Brick"
    },
    {
      "x": 2,
      "y": 1,
      "z": 5,
      "name": "*Wood_Village_Wall_Full_State_Definitions_Bottom"
    },
    {
      "x": 2,
      "y": 2,
      "z": 5,
      "name": "*Wood_Village_Wall_Full_State_Definitions_Top"
    },
    {
      "x": 2,
      "y": 3,
      "z": 5,
      "name": "Wood_Beech_Trunk",
      "support": 15,
      "rotation": 4
    },
    {
      "x": 2,
      "y": 4,
      "z": 5,
      "name": "Wood_Village_Wall_Full"
    },
    {
      "x": 2,
      "y": 5,
      "z": 5,
      "name": "Wood_Softwood_Roof",
      "rotation": 2
    },
    {
      "x": 2,
      "y": -1,
      "z": 6,
      "name": "Rock_Stone_Cobble"
    },
    {
      "x": 2,
      "y": 0,
      "z": 6,
      "name": "Rock_Stone_Brick"
    },
    {
      "x": 2,
      "y": 1,
      "z": 6,
      "name": "*Wood_Village_Wall_Full_State_Definitions_Bottom"
    },
    {
      "x": 2,
      "y": 2,
      "z": 6,
      "name": "*Wood_Village_Wall_Full_State_Definitions_Top"
    },
    {
      "x": 2,
      "y": 3,
      "z": 6,
      "name": "Wood_Beech_Trunk",
      "support": 15,
      "rotation": 4
    },
    {
      "x": 2,
      "y": 4,
      "z": 6,
      "name": "*Wood_Village_Wall_Full_State_Definitions_Bottom"
    },
    {
      "x": 2,
      "y": 5,
      "z": 6,
      "name": "*Wood_Village_Wall_Full_State_Definitions_Top"
    },
    {
      "x": 2,
      "y": 6,
      "z": 6,
      "name": "Wood_Softwood_Roof",
      "rotation": 2
    },
    {
      "x": 2,
      "y": -1,
      "z": 7,
      "name": "Rock_Stone_Cobble"
    },
    {
      "x": 2,
      "y": 0,
      "z": 7,
      "name": "Rock_Stone_Brick"
    },
    {
      "x": 2,
      "y": 1,
      "z": 7,
      "name": "*Wood_Village_Wall_Full_State_Definitions_Bottom"
    },
    {
      "x": 2,
      "y": 2,
      "z": 7,
      "name": "*Wood_Village_Wall_Full_State_Definitions_Top"
    },
    {
      "x": 2,
      "y": 3,
      "z": 7,
      "name": "Wood_Beech_Trunk",
      "support": 15,
      "rotation": 4
    },
    {
      "x": 2,
      "y": 4,
      "z": 7,
      "name": "Wood_Village_Wall_Full"
    },
    {
      "x": 2,
      "y": 5,
      "z": 7,
      "name": "Furniture_Village_Window",
      "rotation": 1
    },
    {
      "x": 2,
      "y": 6,
      "z": 7,
      "name": "Wood_Village_Wall_Full"
    },
    {
      "x": 2,
      "y": 7,
      "z": 7,
      "name": "Wood_Softwood_Roof",
      "rotation": 2
    },
    {
      "x": 2,
      "y": -1,
      "z": 8,
      "name": "Rock_Stone_Cobble"
    },
    {
      "x": 2,
      "y": 0,
      "z": 8,
      "name": "Rock_Stone_Brick"
    },
    {
      "x": 2,
      "y": 1,
      "z": 8,
      "name": "*Wood_Village_Wall_Full_State_Definitions_Bottom"
    },
    {
      "x": 2,
      "y": 2,
      "z": 8,
      "name": "*Wood_Village_Wall_Full_State_Definitions_Top"
    },
    {
      "x": 2,
      "y": 3,
      "z": 8,
      "name": "Wood_Beech_Trunk",
      "support": 15,
      "rotation": 4
    },
    {
      "x": 2,
      "y": 4,
      "z": 8,
      "name": "Wood_Village_Wall_Full"
    },
    {
      "x": 2,
      "y": 5,
      "z": 8,
      "name": "Furniture_Village_Window",
      "rotation": 1
    },
    {
      "x": 2,
      "y": 6,
      "z": 8,
      "name": "Wood_Village_Wall_Full"
    },
    {
      "x": 2,
      "y": 7,
      "z": 8,
      "name": "Wood_Softwood_Roof"
    },
    {
      "x": 2,
      "y": -1,
      "z": 9,
      "name": "Rock_Stone_Cobble"
    },
    {
      "x": 2,
      "y": 0,
      "z": 9,
      "name": "Rock_Stone_Brick"
    },
    {
      "x": 2,
      "y": 1,
      "z": 9,
      "name": "Furniture_Village_Window",
      "rotation": 1
    },
    {
      "x": 2,
      "y": 2,
      "z": 9,
      "name": "Furniture_Village_Window",
      "rotation": 1
    },
    {
      "x": 2,
      "y": 3,
      "z": 9,
      "name": "Wood_Beech_Trunk",
      "support": 15,
      "rotation": 4
    },
    {
      "x": 2,
      "y": 4,
      "z": 9,
      "name": "*Wood_Village_Wall_Full_State_Definitions_Bottom"
    },
    {
      "x": 2,
      "y": 5,
      "z": 9,
      "name": "*Wood_Village_Wall_Full_State_Definitions_Top"
    },
    {
      "x": 2,
      "y": 6,
      "z": 9,
      "name": "Wood_Softwood_Roof"
    },
    {
      "x": 2,
      "y": -1,
      "z": 10,
      "name": "Rock_Stone_Cobble"
    },
    {
      "x": 2,
      "y": 0,
      "z": 10,
      "name": "Rock_Stone_Brick"
    },
    {
      "x": 2,
      "y": 1,
      "z": 10,
      "name": "*Wood_Village_Wall_Full_State_Definitions_Bottom"
    },
    {
      "x": 2,
      "y": 2,
      "z": 10,
      "name": "*Wood_Village_Wall_Full_State_Definitions_Top"
    },
    {
      "x": 2,
      "y": 3,
      "z": 10,
      "name": "Wood_Beech_Trunk",
      "support": 15,
      "rotation": 4
    },
    {
      "x": 2,
      "y": 4,
      "z": 10,
      "name": "Wood_Village_Wall_Full"
    },
    {
      "x": 2,
      "y": 5,
      "z": 10,
      "name": "Wood_Softwood_Roof"
    },
    {
      "x": 2,
      "y": -1,
      "z": 11,
      "name": "Rock_Stone_Cobble"
    },
    {
      "x": 2,
      "y": 0,
      "z": 11,
      "name": "Wood_Beech_Trunk",
      "support": 15
    },
    {
      "x": 2,
      "y": 1,
      "z": 11,
      "name": "Wood_Beech_Trunk",
      "support": 15
    },
    {
      "x": 2,
      "y": 2,
      "z": 11,
      "name": "Wood_Beech_Trunk",
      "support": 15
    },
    {
      "x": 2,
      "y": 3,
      "z": 11,
      "name": "Wood_Beech_Trunk",
      "support": 15
    },
    {
      "x": 2,
      "y": 4,
      "z": 11,
      "name": "Wood_Softwood_Roof"
    },
    {
      "x": 2,
      "y": -1,
      "z": 12,
      "name": "Rock_Stone_Cobble"
    },
    {
      "x": 2,
      "y": 2,
      "z": 12,
      "name": "Wood_Beech_Branch_Corner",
      "support": 15
    },
    {
      "x": 2,
      "y": 3,
      "z": 12,
      "name": "Wood_Softwood_Roof"
    },
    {
      "x": 3,
      "y": -1,
      "z": 1,
      "name": "Rock_Stone_Cobble"
    },
    {
      "x": 3,
      "y": -1,
      "z": 2,
      "name": "Rock_Stone_Cobble"
    },
    {
      "x": 3,
      "y": -1,
      "z": 3,
      "name": "Rock_Stone_Cobble"
    },
    {
      "x": 3,
      "y": 1,
      "z": 3,
      "name": "Plant_Vine_Wall",
      "support": 15,
      "rotation": 2
    },
    {
      "x": 3,
      "y": 2,
      "z": 3,
      "name": "Plant_Vine",
      "support": 15,
      "rotation": 2
    },
    {
      "x": 3,
      "y": 3,
      "z": 3,
      "name": "Wood_Softwood_Roof_Hollow",
      "rotation": 2
    },
    {
      "x": 3,
      "y": -1,
      "z": 4,
      "name": "Rock_Stone_Cobble"
    },
    {
      "x": 3,
      "y": 0,
      "z": 4,
      "name": "Rock_Stone_Brick"
    },
    {
      "x": 3,
      "y": 1,
      "z": 4,
      "name": "*Wood_Village_Wall_Full_State_Definitions_Bottom"
    },
    {
      "x": 3,
      "y": 2,
      "z": 4,
      "name": "*Wood_Village_Wall_Full_State_Definitions_Top"
    },
    {
      "x": 3,
      "y": 3,
      "z": 4,
      "name": "Wood_Beech_Trunk",
      "support": 15,
      "rotation": 5
    },
    {
      "x": 3,
      "y": 4,
      "z": 4,
      "name": "Wood_Softwood_Roof",
      "rotation": 2
    },
    {
      "x": 3,
      "y": -1,
      "z": 5,
      "name": "Wood_Drywood_Planks"
    },
    {
      "x": 3,
      "y": 0,
      "z": 5,
      "name": "Furniture_Temple_Dark_Candle",
      "support": 15
    },
    {
      "x": 3,
      "y": 1,
      "z": 5,
      "name": "Furniture_Temple_Dark_Candle",
      "support": 15,
      "filler": 1024
    },
    {
      "x": 3,
      "y": 3,
      "z": 5,
      "name": "Furniture_Village_Platform",
      "support": 15,
      "rotation": 1
    },
    {
      "x": 3,
      "y": 4,
      "z": 5,
      "name": "Wood_Softwood_Stairs",
      "rotation": 10
    },
    {
      "x": 3,
      "y": 5,
      "z": 5,
      "name": "Wood_Softwood_Roof",
      "rotation": 2
    },
    {
      "x": 3,
      "y": -1,
      "z": 6,
      "name": "Wood_Drywood_Planks"
    },
    {
      "x": 3,
      "y": 3,
      "z": 6,
      "name": "Furniture_Village_Platform",
      "support": 15,
      "rotation": 1
    },
    {
      "x": 3,
      "y": 4,
      "z": 6,
      "name": "Furniture_Tavern_Barrel",
      "support": 15
    },
    {
      "x": 3,
      "y": 5,
      "z": 6,
      "name": "Wood_Softwood_Stairs",
      "rotation": 10
    },
    {
      "x": 3,
      "y": 6,
      "z": 6,
      "name": "Wood_Softwood_Roof",
      "rotation": 2
    },
    {
      "x": 3,
      "y": -1,
      "z": 7,
      "name": "Rock_Stone_Cobble"
    },
    {
      "x": 3,
      "y": 0,
      "z": 7,
      "name": "*Wood_Village_Wall_Full_State_Definitions_Bottom"
    },
    {
      "x": 3,
      "y": 1,
      "z": 7,
      "name": "*Wood_Village_Wall_Full_State_Definitions_Middle"
    },
    {
      "x": 3,
      "y": 2,
      "z": 7,
      "name": "*Wood_Village_Wall_Full_State_Definitions_Top"
    },
    {
      "x": 3,
      "y": 3,
      "z": 7,
      "name": "Wood_Beech_Trunk",
      "support": 15,
      "rotation": 5
    },
    {
      "x": 3,
      "y": 6,
      "z": 7,
      "name": "Wood_Softwood_Stairs",
      "rotation": 10
    },
    {
      "x": 3,
      "y": 7,
      "z": 7,
      "name": "Wood_Softwood_Roof",
      "rotation": 2
    },
    {
      "x": 3,
      "y": -1,
      "z": 8,
      "name": "Wood_Drywood_Planks"
    },
    {
      "x": 3,
      "y": 0,
      "z": 8,
      "name": "Furniture_Tavern_Candle",
      "support": 15
    },
    {
      "x": 3,
      "y": 3,
      "z": 8,
      "name": "Furniture_Village_Platform",
      "support": 15,
      "rotation": 1
    },
    {
      "x": 3,
      "y": 4,
      "z": 8,
      "name": "Furniture_Village_Crate"
    },
    {
      "x": 3,
      "y": 5,
      "z": 8,
      "name": "Furniture_Crude_Candle",
      "support": 15
    },
    {
      "x": 3,
      "y": 6,
      "z": 8,
      "name": "Wood_Softwood_Stairs",
      "rotation": 8
    },
    {
      "x": 3,
      "y": 7,
      "z": 8,
      "name": "Wood_Softwood_Roof"
    },
    {
      "x": 3,
      "y": -1,
      "z": 9,
      "name": "Wood_Drywood_Planks"
    },
    {
      "x": 3,
      "y": 0,
      "z": 9,
      "name": "Furniture_Village_Bed",
      "support": 15,
      "filler": 992,
      "rotation": 1
    },
    {
      "x": 3,
      "y": 1,
      "z": 9,
      "name": "Furniture_Village_Bed",
      "support": 15,
      "filler": 2016,
      "rotation": 1
    },
    {
      "x": 3,
      "y": 3,
      "z": 9,
      "name": "Furniture_Village_Platform",
      "support": 15,
      "rotation": 1
    },
    {
      "x": 3,
      "y": 4,
      "z": 9,
      "name": "Furniture_Village_Crate"
    },
    {
      "x": 3,
      "y": 5,
      "z": 9,
      "name": "Wood_Softwood_Stairs",
      "rotation": 8
    },
    {
      "x": 3,
      "y": 6,
      "z": 9,
      "name": "Wood_Softwood_Roof"
    },
    {
      "x": 3,
      "y": -1,
      "z": 10,
      "name": "Wood_Drywood_Planks"
    },
    {
      "x": 3,
      "y": 0,
      "z": 10,
      "name": "Furniture_Village_Bed",
      "components": {
        "Components": {
          "PlacedByInteraction": {
            "WhoPlacedUuid": {
              "$binary": "v7RyWIT/TYKnXA2XcxdQtw==",
              "$type": "04"
            }
          },
          "RespawnBlock": {}
        }
      },
      "support": 15,
      "rotation": 1
    },
    {
      "x": 3,
      "y": 1,
      "z": 10,
      "name": "Furniture_Village_Bed",
      "support": 15,
      "filler": 1024,
      "rotation": 1
    },
    {
      "x": 3,
      "y": 3,
      "z": 10,
      "name": "Furniture_Village_Platform",
      "support": 15,
      "rotation": 1
    },
    {
      "x": 3,
      "y": 4,
      "z": 10,
      "name": "Wood_Softwood_Stairs",
      "rotation": 8
    },
    {
      "x": 3,
      "y": 5,
      "z": 10,
      "name": "Wood_Softwood_Roof"
    },
    {
      "x": 3,
      "y": -1,
      "z": 11,
      "name": "Rock_Stone_Cobble"
    },
    {
      "x": 3,
      "y": 0,
      "z": 11,
      "name": "Rock_Stone_Brick"
    },
    {
      "x": 3,
      "y": 1,
      "z": 11,
      "name": "*Wood_Village_Wall_Full_State_Definitions_Bottom"
    },
    {
      "x": 3,
      "y": 2,
      "z": 11,
      "name": "*Wood_Village_Wall_Full_State_Definitions_Top"
    },
    {
      "x": 3,
      "y": 3,
      "z": 11,
      "name": "Wood_Beech_Trunk",
      "support": 15,
      "rotation": 5
    },
    {
      "x": 3,
      "y": 4,
      "z": 11,
      "name": "Wood_Softwood_Roof"
    },
    {
      "x": 3,
      "y": -1,
      "z": 12,
      "name": "Rock_Stone_Cobble"
    },
    {
      "x": 3,
      "y": 3,
      "z": 12,
      "name": "Wood_Softwood_Roof_Hollow"
    },
    {
      "x": 4,
      "y": -1,
      "z": 1,
      "name": "Rock_Stone_Cobble"
    },
    {
      "x": 4,
      "y": -1,
      "z": 2,
      "name": "Rock_Stone_Cobble"
    },
    {
      "x": 4,
      "y": -1,
      "z": 3,
      "name": "Rock_Stone_Cobble"
    },
    {
      "x": 4,
      "y": 3,
      "z": 3,
      "name": "Wood_Softwood_Roof_Hollow",
      "rotation": 2
    },
    {
      "x": 4,
      "y": -1,
      "z": 4,
      "name": "Rock_Stone_Cobble"
    },
    {
      "x": 4,
      "y": 0,
      "z": 4,
      "name": "Rock_Stone_Brick"
    },
    {
      "x": 4,
      "y": 1,
      "z": 4,
      "name": "*Wood_Village_Wall_Full_State_Definitions_Bottom"
    },
    {
      "x": 4,
      "y": 2,
      "z": 4,
      "name": "*Wood_Village_Wall_Full_State_Definitions_Top"
    },
    {
      "x": 4,
      "y": 3,
      "z": 4,
      "name": "Wood_Beech_Trunk",
      "support": 15,
      "rotation": 5
    },
    {
      "x": 4,
      "y": 4,
      "z": 4,
      "name": "Wood_Softwood_Roof",
      "rotation": 2
    },
    {
      "x": 4,
      "y": -1,
      "z": 5,
      "name": "Wood_Drywood_Planks"
    },
    {
      "x": 4,
      "y": 3,
      "z": 5,
      "name": "Furniture_Village_Platform",
      "support": 15,
      "rotation": 1
    },
    {
      "x": 4,
      "y": 4,
      "z": 5,
      "name": "Wood_Softwood_Stairs",
      "rotation": 10
    },
    {
      "x": 4,
      "y": 5,
      "z": 5,
      "name": "Wood_Softwood_Roof",
      "rotation": 2
    },
    {
      "x": 4,
      "y": -1,
      "z": 6,
      "name": "Wood_Drywood_Planks"
    },
    {
      "x": 4,
      "y": 3,
      "z": 6,
      "name": "Furniture_Village_Platform",
      "support": 15,
      "rotation": 1
    },
    {
      "x": 4,
      "y": 5,
      "z": 6,
      "name": "Wood_Softwood_Stairs",
      "rotation": 10
    },
    {
      "x": 4,
      "y": 6,
      "z": 6,
      "name": "Wood_Softwood_Roof",
      "rotation": 2
    },
    {
      "x": 4,
      "y": -1,
      "z": 7,
      "name": "Wood_Drywood_Planks"
    },
    {
      "x": 4,
      "y": 0,
      "z": 7,
      "name": "*Furniture_Village_Door_State_Definitions_CloseDoorOut",
      "rotation": 2
    },
    {
      "x": 4,
      "y": 1,
      "z": 7,
      "name": "*Furniture_Village_Door_State_Definitions_CloseDoorOut",
      "filler": 1024,
      "rotation": 2
    },
    {
      "x": 4,
      "y": 2,
      "z": 7,
      "name": "Wood_Village_Wall_Full"
    },
    {
      "x": 4,
      "y": 3,
      "z": 7,
      "name": "Wood_Beech_Trunk",
      "support": 15,
      "rotation": 5
    },
    {
      "x": 4,
      "y": 6,
      "z": 7,
      "name": "Wood_Softwood_Stairs",
      "rotation": 10
    },
    {
      "x": 4,
      "y": 7,
      "z": 7,
      "name": "Wood_Softwood_Roof",
      "rotation": 2
    },
    {
      "x": 4,
      "y": -1,
      "z": 8,
      "name": "Wood_Drywood_Planks"
    },
    {
      "x": 4,
      "y": 3,
      "z": 8,
      "name": "Furniture_Village_Platform",
      "support": 15,
      "rotation": 1
    },
    {
      "x": 4,
      "y": 6,
      "z": 8,
      "name": "Wood_Softwood_Stairs",
      "rotation": 8
    },
    {
      "x": 4,
      "y": 7,
      "z": 8,
      "name": "Wood_Softwood_Roof"
    },
    {
      "x": 4,
      "y": -1,
      "z": 9,
      "name": "Wood_Drywood_Planks"
    },
    {
      "x": 4,
      "y": 0,
      "z": 9,
      "name": "Furniture_Village_Bed",
      "support": 15,
      "filler": 993,
      "rotation": 1
    },
    {
      "x": 4,
      "y": 1,
      "z": 9,
      "name": "Furniture_Village_Bed",
      "support": 15,
      "filler": 2017,
      "rotation": 1
    },
    {
      "x": 4,
      "y": 3,
      "z": 9,
      "name": "Furniture_Village_Platform",
      "support": 15,
      "rotation": 1
    },
    {
      "x": 4,
      "y": 4,
      "z": 9,
      "name": "Furniture_Village_Crate"
    },
    {
      "x": 4,
      "y": 5,
      "z": 9,
      "name": "Wood_Softwood_Stairs",
      "rotation": 8
    },
    {
      "x": 4,
      "y": 6,
      "z": 9,
      "name": "Wood_Softwood_Roof"
    },
    {
      "x": 4,
      "y": -1,
      "z": 10,
      "name": "Wood_Drywood_Planks"
    },
    {
      "x": 4,
      "y": 0,
      "z": 10,
      "name": "Furniture_Village_Bed",
      "support": 15,
      "filler": 1,
      "rotation": 1
    },
    {
      "x": 4,
      "y": 1,
      "z": 10,
      "name": "Furniture_Village_Bed",
      "support": 15,
      "filler": 1025,
      "rotation": 1
    },
    {
      "x": 4,
      "y": 3,
      "z": 10,
      "name": "Furniture_Village_Platform",
      "support": 15,
      "rotation": 1
    },
    {
      "x": 4,
      "y": 4,
      "z": 10,
      "name": "Wood_Softwood_Stairs",
      "rotation": 8
    },
    {
      "x": 4,
      "y": 5,
      "z": 10,
      "name": "Wood_Softwood_Roof"
    },
    {
      "x": 4,
      "y": -1,
      "z": 11,
      "name": "Rock_Stone_Cobble"
    },
    {
      "x": 4,
      "y": 0,
      "z": 11,
      "name": "Rock_Stone_Brick"
    },
    {
      "x": 4,
      "y": 1,
      "z": 11,
      "name": "Furniture_Village_Window"
    },
    {
      "x": 4,
      "y": 2,
      "z": 11,
      "name": "Furniture_Village_Window"
    },
    {
      "x": 4,
      "y": 3,
      "z": 11,
      "name": "Wood_Beech_Trunk",
      "support": 15,
      "rotation": 5
    },
    {
      "x": 4,
      "y": 4,
      "z": 11,
      "name": "Wood_Softwood_Roof"
    },
    {
      "x": 4,
      "y": -1,
      "z": 12,
      "name": "Rock_Stone_Cobble"
    },
    {
      "x": 4,
      "y": 3,
      "z": 12,
      "name": "Wood_Softwood_Roof_Hollow"
    },
    {
      "x": 5,
      "y": -1,
      "z": 1,
      "name": "Rock_Stone_Cobble"
    },
    {
      "x": 5,
      "y": -1,
      "z": 2,
      "name": "Rock_Stone_Cobble"
    },
    {
      "x": 5,
      "y": -1,
      "z": 3,
      "name": "Rock_Stone_Cobble"
    },
    {
      "x": 5,
      "y": 3,
      "z": 3,
      "name": "Wood_Softwood_Roof_Hollow",
      "rotation": 2
    },
    {
      "x": 5,
      "y": -1,
      "z": 4,
      "name": "Rock_Stone_Cobble"
    },
    {
      "x": 5,
      "y": 0,
      "z": 4,
      "name": "Rock_Stone_Brick"
    },
    {
      "x": 5,
      "y": 1,
      "z": 4,
      "name": "Furniture_Village_Window"
    },
    {
      "x": 5,
      "y": 2,
      "z": 4,
      "name": "Furniture_Village_Window"
    },
    {
      "x": 5,
      "y": 3,
      "z": 4,
      "name": "Wood_Beech_Trunk",
      "support": 15,
      "rotation": 5
    },
    {
      "x": 5,
      "y": 4,
      "z": 4,
      "name": "Wood_Softwood_Roof",
      "rotation": 2
    },
    {
      "x": 5,
      "y": -1,
      "z": 5,
      "name": "Wood_Drywood_Planks"
    },
    {
      "x": 5,
      "y": 3,
      "z": 5,
      "name": "Furniture_Village_Platform",
      "support": 15,
      "rotation": 1
    },
    {
      "x": 5,
      "y": 4,
      "z": 5,
      "name": "Wood_Softwood_Stairs",
      "rotation": 10
    },
    {
      "x": 5,
      "y": 5,
      "z": 5,
      "name": "Wood_Softwood_Roof",
      "rotation": 2
    },
    {
      "x": 5,
      "y": -1,
      "z": 6,
      "name": "Wood_Drywood_Planks"
    },
    {
      "x": 5,
      "y": 3,
      "z": 6,
      "name": "Furniture_Village_Platform",
      "support": 15,
      "rotation": 1
    },
    {
      "x": 5,
      "y": 4,
      "z": 6,
      "name": "Furniture_Tavern_Barrel",
      "support": 15
    },
    {
      "x": 5,
      "y": 5,
      "z": 6,
      "name": "Wood_Softwood_Stairs",
      "rotation": 10
    },
    {
      "x": 5,
      "y": 6,
      "z": 6,
      "name": "Wood_Softwood_Roof",
      "rotation": 2
    },
    {
      "x": 5,
      "y": -1,
      "z": 7,
      "name": "Rock_Stone_Cobble"
    },
    {
      "x": 5,
      "y": 0,
      "z": 7,
      "name": "*Wood_Village_Wall_Full_State_Definitions_Bottom"
    },
    {
      "x": 5,
      "y": 1,
      "z": 7,
      "name": "*Wood_Village_Wall_Full_State_Definitions_Middle"
    },
    {
      "x": 5,
      "y": 2,
      "z": 7,
      "name": "*Wood_Village_Wall_Full_State_Definitions_Top"
    },
    {
      "x": 5,
      "y": 3,
      "z": 7,
      "name": "Wood_Beech_Trunk",
      "support": 15,
      "rotation": 5
    },
    {
      "x": 5,
      "y": 6,
      "z": 7,
      "name": "Wood_Softwood_Stairs",
      "rotation": 10
    },
    {
      "x": 5,
      "y": 7,
      "z": 7,
      "name": "Wood_Softwood_Roof",
      "rotation": 2
    },
    {
      "x": 5,
      "y": -1,
      "z": 8,
      "name": "Wood_Drywood_Planks"
    },
    {
      "x": 5,
      "y": 3,
      "z": 8,
      "name": "Furniture_Village_Platform",
      "support": 15,
      "rotation": 1
    },
    {
      "x": 5,
      "y": 6,
      "z": 8,
      "name": "Wood_Softwood_Stairs",
      "rotation": 8
    },
    {
      "x": 5,
      "y": 7,
      "z": 8,
      "name": "Wood_Softwood_Roof"
    },
    {
      "x": 5,
      "y": -1,
      "z": 9,
      "name": "Wood_Drywood_Planks"
    },
    {
      "x": 5,
      "y": 0,
      "z": 9,
      "name": "Furniture_Village_Bed",
      "support": 15,
      "filler": 994,
      "rotation": 1
    },
    {
      "x": 5,
      "y": 1,
      "z": 9,
      "name": "Furniture_Village_Bed",
      "support": 15,
      "filler": 2018,
      "rotation": 1
    },
    {
      "x": 5,
      "y": 3,
      "z": 9,
      "name": "Furniture_Village_Platform",
      "support": 15,
      "rotation": 1
    },
    {
      "x": 5,
      "y": 4,
      "z": 9,
      "name": "Furniture_Tavern_Barrel",
      "support": 15
    },
    {
      "x": 5,
      "y": 5,
      "z": 9,
      "name": "Wood_Softwood_Stairs",
      "rotation": 8
    },
    {
      "x": 5,
      "y": 6,
      "z": 9,
      "name": "Wood_Softwood_Roof"
    },
    {
      "x": 5,
      "y": -1,
      "z": 10,
      "name": "Wood_Drywood_Planks"
    },
    {
      "x": 5,
      "y": 0,
      "z": 10,
      "name": "Furniture_Village_Bed",
      "support": 15,
      "filler": 2,
      "rotation": 1
    },
    {
      "x": 5,
      "y": 1,
      "z": 10,
      "name": "Furniture_Village_Bed",
      "support": 15,
      "filler": 1026,
      "rotation": 1
    },
    {
      "x": 5,
      "y": 3,
      "z": 10,
      "name": "Furniture_Village_Platform",
      "support": 15,
      "rotation": 1
    },
    {
      "x": 5,
      "y": 4,
      "z": 10,
      "name": "Wood_Softwood_Stairs",
      "rotation": 8
    },
    {
      "x": 5,
      "y": 5,
      "z": 10,
      "name": "Wood_Softwood_Roof"
    },
    {
      "x": 5,
      "y": -1,
      "z": 11,
      "name": "Rock_Stone_Cobble"
    },
    {
      "x": 5,
      "y": 0,
      "z": 11,
      "name": "Rock_Stone_Brick"
    },
    {
      "x": 5,
      "y": 1,
      "z": 11,
      "name": "*Wood_Village_Wall_Full_State_Definitions_Bottom"
    },
    {
      "x": 5,
      "y": 2,
      "z": 11,
      "name": "*Wood_Village_Wall_Full_State_Definitions_Top"
    },
    {
      "x": 5,
      "y": 3,
      "z": 11,
      "name": "Wood_Beech_Trunk",
      "support": 15,
      "rotation": 5
    },
    {
      "x": 5,
      "y": 4,
      "z": 11,
      "name": "Wood_Softwood_Roof"
    },
    {
      "x": 5,
      "y": -1,
      "z": 12,
      "name": "Rock_Stone_Cobble"
    },
    {
      "x": 5,
      "y": 1,
      "z": 12,
      "name": "Plant_Vine_Wall",
      "support": 15
    },
    {
      "x": 5,
      "y": 2,
      "z": 12,
      "name": "Plant_Vine",
      "support": 15
    },
    {
      "x": 5,
      "y": 3,
      "z": 12,
      "name": "Wood_Softwood_Roof_Hollow"
    },
    {
      "x": 6,
      "y": -1,
      "z": 1,
      "name": "Rock_Stone_Cobble"
    },
    {
      "x": 6,
      "y": -1,
      "z": 2,
      "name": "Rock_Stone_Cobble"
    },
    {
      "x": 6,
      "y": -1,
      "z": 3,
      "name": "Rock_Stone_Cobble"
    },
    {
      "x": 6,
      "y": 0,
      "z": 3,
      "name": "Furniture_Tavern_Planter",
      "support": 15
    },
    {
      "x": 6,
      "y": 1,
      "z": 3,
      "name": "Plant_Flower_Common_Yellow2",
      "support": 15
    },
    {
      "x": 6,
      "y": 3,
      "z": 3,
      "name": "Wood_Softwood_Roof_Hollow",
      "rotation": 2
    },
    {
      "x": 6,
      "y": -1,
      "z": 4,
      "name": "Rock_Stone_Cobble"
    },
    {
      "x": 6,
      "y": 0,
      "z": 4,
      "name": "Rock_Stone_Brick"
    },
    {
      "x": 6,
      "y": 1,
      "z": 4,
      "name": "*Wood_Village_Wall_Full_State_Definitions_Bottom"
    },
    {
      "x": 6,
      "y": 2,
      "z": 4,
      "name": "*Wood_Village_Wall_Full_State_Definitions_Top"
    },
    {
      "x": 6,
      "y": 3,
      "z": 4,
      "name": "Wood_Beech_Trunk",
      "support": 15,
      "rotation": 5
    },
    {
      "x": 6,
      "y": 4,
      "z": 4,
      "name": "Wood_Softwood_Roof",
      "rotation": 2
    },
    {
      "x": 6,
      "y": -1,
      "z": 5,
      "name": "Wood_Drywood_Planks"
    },
    {
      "x": 6,
      "y": 3,
      "z": 5,
      "name": "Furniture_Village_Platform",
      "support": 15,
      "rotation": 1
    },
    {
      "x": 6,
      "y": 4,
      "z": 5,
      "name": "Wood_Softwood_Stairs",
      "rotation": 10
    },
    {
      "x": 6,
      "y": 5,
      "z": 5,
      "name": "Wood_Softwood_Roof",
      "rotation": 2
    },
    {
      "x": 6,
      "y": -1,
      "z": 6,
      "name": "Wood_Drywood_Planks"
    },
    {
      "x": 6,
      "y": 3,
      "z": 6,
      "name": "Furniture_Village_Platform",
      "support": 15,
      "rotation": 1
    },
    {
      "x": 6,
      "y": 4,
      "z": 6,
      "name": "Furniture_Village_Crate"
    },
    {
      "x": 6,
      "y": 5,
      "z": 6,
      "name": "Wood_Softwood_Stairs",
      "rotation": 10
    },
    {
      "x": 6,
      "y": 6,
      "z": 6,
      "name": "Wood_Softwood_Roof",
      "rotation": 2
    },
    {
      "x": 6,
      "y": -1,
      "z": 7,
      "name": "Rock_Stone_Cobble"
    },
    {
      "x": 6,
      "y": 0,
      "z": 7,
      "name": "Wood_Beech_Trunk",
      "support": 15
    },
    {
      "x": 6,
      "y": 1,
      "z": 7,
      "name": "Wood_Beech_Trunk",
      "support": 15
    },
    {
      "x": 6,
      "y": 2,
      "z": 7,
      "name": "Wood_Beech_Trunk",
      "support": 15
    },
    {
      "x": 6,
      "y": 3,
      "z": 7,
      "name": "Wood_Beech_Trunk",
      "support": 15,
      "rotation": 5
    },
    {
      "x": 6,
      "y": 6,
      "z": 7,
      "name": "Wood_Softwood_Stairs",
      "rotation": 10
    },
    {
      "x": 6,
      "y": 7,
      "z": 7,
      "name": "Wood_Softwood_Roof",
      "rotation": 2
    },
    {
      "x": 6,
      "y": -1,
      "z": 8,
      "name": "Rock_Stone_Cobble"
    },
    {
      "x": 6,
      "y": 0,
      "z": 8,
      "name": "*Wood_Village_Wall_Full_State_Definitions_Bottom"
    },
    {
      "x": 6,
      "y": 1,
      "z": 8,
      "name": "*Wood_Village_Wall_Full_State_Definitions_Middle"
    },
    {
      "x": 6,
      "y": 2,
      "z": 8,
      "name": "*Wood_Village_Wall_Full_State_Definitions_Top"
    },
    {
      "x": 6,
      "y": 3,
      "z": 8,
      "name": "Wood_Beech_Trunk",
      "support": 15,
      "rotation": 4
    },
    {
      "x": 6,
      "y": 6,
      "z": 8,
      "name": "Wood_Softwood_Stairs",
      "rotation": 8
    },
    {
      "x": 6,
      "y": 7,
      "z": 8,
      "name": "Wood_Softwood_Roof"
    },
    {
      "x": 6,
      "y": -1,
      "z": 9,
      "name": "Rock_Stone_Cobble"
    },
    {
      "x": 6,
      "y": 0,
      "z": 9,
      "name": "*Wood_Village_Wall_Full_State_Definitions_Bottom"
    },
    {
      "x": 6,
      "y": 1,
      "z": 9,
      "name": "*Wood_Village_Wall_Full_State_Definitions_Middle"
    },
    {
      "x": 6,
      "y": 2,
      "z": 9,
      "name": "*Wood_Village_Wall_Full_State_Definitions_Top"
    },
    {
      "x": 6,
      "y": 3,
      "z": 9,
      "name": "Wood_Beech_Trunk",
      "support": 15,
      "rotation": 4
    },
    {
      "x": 6,
      "y": 4,
      "z": 9,
      "name": "Furniture_Tavern_Barrel",
      "support": 15
    },
    {
      "x": 6,
      "y": 5,
      "z": 9,
      "name": "Wood_Softwood_Stairs",
      "rotation": 8
    },
    {
      "x": 6,
      "y": 6,
      "z": 9,
      "name": "Wood_Softwood_Roof"
    },
    {
      "x": 6,
      "y": -1,
      "z": 10,
      "name": "Rock_Stone_Cobble"
    },
    {
      "x": 6,
      "y": 0,
      "z": 10,
      "name": "*Wood_Village_Wall_Full_State_Definitions_Bottom"
    },
    {
      "x": 6,
      "y": 1,
      "z": 10,
      "name": "*Wood_Village_Wall_Full_State_Definitions_Middle"
    },
    {
      "x": 6,
      "y": 2,
      "z": 10,
      "name": "*Wood_Village_Wall_Full_State_Definitions_Top"
    },
    {
      "x": 6,
      "y": 3,
      "z": 10,
      "name": "Wood_Beech_Trunk",
      "support": 15,
      "rotation": 4
    },
    {
      "x": 6,
      "y": 4,
      "z": 10,
      "name": "Wood_Softwood_Stairs",
      "rotation": 8
    },
    {
      "x": 6,
      "y": 5,
      "z": 10,
      "name": "Wood_Softwood_Roof"
    },
    {
      "x": 6,
      "y": -1,
      "z": 11,
      "name": "Rock_Stone_Cobble"
    },
    {
      "x": 6,
      "y": 0,
      "z": 11,
      "name": "Wood_Beech_Trunk",
      "support": 15
    },
    {
      "x": 6,
      "y": 1,
      "z": 11,
      "name": "Wood_Beech_Trunk",
      "support": 15
    },
    {
      "x": 6,
      "y": 2,
      "z": 11,
      "name": "Wood_Beech_Trunk",
      "support": 15
    },
    {
      "x": 6,
      "y": 3,
      "z": 11,
      "name": "Wood_Beech_Trunk",
      "support": 15
    },
    {
      "x": 6,
      "y": 4,
      "z": 11,
      "name": "Wood_Softwood_Roof"
    },
    {
      "x": 6,
      "y": -1,
      "z": 12,
      "name": "Rock_Stone_Cobble"
    },
    {
      "x": 6,
      "y": 2,
      "z": 12,
      "name": "Wood_Beech_Branch_Corner",
      "support": 15
    },
    {
      "x": 6,
      "y": 3,
      "z": 12,
      "name": "Wood_Softwood_Roof"
    },
    {
      "x": 7,
      "y": -1,
      "z": 1,
      "name": "Rock_Stone_Cobble"
    },
    {
      "x": 7,
      "y": -1,
      "z": 2,
      "name": "Rock_Stone_Cobble"
    },
    {
      "x": 7,
      "y": -1,
      "z": 3,
      "name": "Rock_Stone_Cobble"
    },
    {
      "x": 7,
      "y": 3,
      "z": 3,
      "name": "Wood_Softwood_Roof_Hollow",
      "rotation": 2
    },
    {
      "x": 7,
      "y": -1,
      "z": 4,
      "name": "Rock_Stone_Cobble"
    },
    {
      "x": 7,
      "y": 0,
      "z": 4,
      "name": "Rock_Stone_Brick"
    },
    {
      "x": 7,
      "y": 1,
      "z": 4,
      "name": "Furniture_Village_Window"
    },
    {
      "x": 7,
      "y": 2,
      "z": 4,
      "name": "Furniture_Village_Window"
    },
    {
      "x": 7,
      "y": 3,
      "z": 4,
      "name": "Wood_Beech_Trunk",
      "support": 15,
      "rotation": 5
    },
    {
      "x": 7,
      "y": 4,
      "z": 4,
      "name": "Wood_Softwood_Roof",
      "rotation": 2
    },
    {
      "x": 7,
      "y": -1,
      "z": 5,
      "name": "Wood_Drywood_Planks"
    },
    {
      "x": 7,
      "y": 3,
      "z": 5,
      "name": "Furniture_Village_Platform",
      "support": 15,
      "rotation": 1
    },
    {
      "x": 7,
      "y": 4,
      "z": 5,
      "name": "Wood_Softwood_Stairs",
      "rotation": 10
    },
    {
      "x": 7,
      "y": 5,
      "z": 5,
      "name": "Wood_Softwood_Roof",
      "rotation": 2
    },
    {
      "x": 7,
      "y": -1,
      "z": 6,
      "name": "Wood_Drywood_Planks"
    },
    {
      "x": 7,
      "y": 3,
      "z": 6,
      "name": "Furniture_Village_Platform",
      "support": 15,
      "rotation": 1
    },
    {
      "x": 7,
      "y": 4,
      "z": 6,
      "name": "Furniture_Tavern_Barrel",
      "support": 15
    },
    {
      "x": 7,
      "y": 5,
      "z": 6,
      "name": "Wood_Softwood_Stairs",
      "rotation": 10
    },
    {
      "x": 7,
      "y": 6,
      "z": 6,
      "name": "Wood_Softwood_Roof",
      "rotation": 2
    },
    {
      "x": 7,
      "y": -1,
      "z": 7,
      "name": "Rock_Stone_Cobble"
    },
    {
      "x": 7,
      "y": 0,
      "z": 7,
      "name": "*Wood_Village_Wall_Full_State_Definitions_Bottom"
    },
    {
      "x": 7,
      "y": 1,
      "z": 7,
      "name": "*Wood_Village_Wall_Full_State_Definitions_Middle"
    },
    {
      "x": 7,
      "y": 2,
      "z": 7,
      "name": "*Wood_Village_Wall_Full_State_Definitions_Top"
    },
    {
      "x": 7,
      "y": 3,
      "z": 7,
      "name": "Wood_Beech_Trunk",
      "support": 15,
      "rotation": 5
    },
    {
      "x": 7,
      "y": 6,
      "z": 7,
      "name": "Wood_Softwood_Stairs",
      "rotation": 10
    },
    {
      "x": 7,
      "y": 7,
      "z": 7,
      "name": "Wood_Softwood_Roof",
      "rotation": 2
    },
    {
      "x": 7,
      "y": -1,
      "z": 8,
      "name": "Wood_Drywood_Planks"
    },
    {
      "x": 7,
      "y": 0,
      "z": 8,
      "name": "Furniture_Tavern_Candle",
      "support": 15
    },
    {
      "x": 7,
      "y": 3,
      "z": 8,
      "name": "Furniture_Village_Platform",
      "support": 15,
      "rotation": 1
    },
    {
      "x": 7,
      "y": 6,
      "z": 8,
      "name": "Wood_Softwood_Stairs",
      "rotation": 8
    },
    {
      "x": 7,
      "y": 7,
      "z": 8,
      "name": "Wood_Softwood_Roof"
    },
    {
      "x": 7,
      "y": -1,
      "z": 9,
      "name": "Wood_Drywood_Planks"
    },
    {
      "x": 7,
      "y": 0,
      "z": 9,
      "name": "Furniture_Village_Bed",
      "support": 15,
      "filler": 992,
      "rotation": 1
    },
    {
      "x": 7,
      "y": 1,
      "z": 9,
      "name": "Furniture_Village_Bed",
      "support": 15,
      "filler": 2016,
      "rotation": 1
    },
    {
      "x": 7,
      "y": 3,
      "z": 9,
      "name": "Furniture_Village_Platform",
      "support": 15,
      "rotation": 1
    },
    {
      "x": 7,
      "y": 4,
      "z": 9,
      "name": "Furniture_Village_Crate"
    },
    {
      "x": 7,
      "y": 5,
      "z": 9,
      "name": "Wood_Softwood_Stairs",
      "rotation": 8
    },
    {
      "x": 7,
      "y": 6,
      "z": 9,
      "name": "Wood_Softwood_Roof"
    },
    {
      "x": 7,
      "y": -1,
      "z": 10,
      "name": "Wood_Drywood_Planks"
    },
    {
      "x": 7,
      "y": 0,
      "z": 10,
      "name": "Furniture_Village_Bed",
      "components": {
        "Components": {
          "PlacedByInteraction": {
            "WhoPlacedUuid": {
              "$binary": "v7RyWIT/TYKnXA2XcxdQtw==",
              "$type": "04"
            }
          },
          "RespawnBlock": {}
        }
      },
      "support": 15,
      "rotation": 1
    },
    {
      "x": 7,
      "y": 1,
      "z": 10,
      "name": "Furniture_Village_Bed",
      "support": 15,
      "filler": 1024,
      "rotation": 1
    },
    {
      "x": 7,
      "y": 3,
      "z": 10,
      "name": "Furniture_Village_Platform",
      "support": 15,
      "rotation": 1
    },
    {
      "x": 7,
      "y": 4,
      "z": 10,
      "name": "Wood_Softwood_Stairs",
      "rotation": 8
    },
    {
      "x": 7,
      "y": 5,
      "z": 10,
      "name": "Wood_Softwood_Roof"
    },
    {
      "x": 7,
      "y": -1,
      "z": 11,
      "name": "Rock_Stone_Cobble"
    },
    {
      "x": 7,
      "y": 0,
      "z": 11,
      "name": "Rock_Stone_Brick"
    },
    {
      "x": 7,
      "y": 1,
      "z": 11,
      "name": "*Wood_Village_Wall_Full_State_Definitions_Bottom"
    },
    {
      "x": 7,
      "y": 2,
      "z": 11,
      "name": "*Wood_Village_Wall_Full_State_Definitions_Top"
    },
    {
      "x": 7,
      "y": 3,
      "z": 11,
      "name": "Wood_Beech_Trunk",
      "support": 15,
      "rotation": 5
    },
    {
      "x": 7,
      "y": 4,
      "z": 11,
      "name": "Wood_Softwood_Roof"
    },
    {
      "x": 7,
      "y": -1,
      "z": 12,
      "name": "Rock_Stone_Cobble"
    },
    {
      "x": 7,
      "y": 3,
      "z": 12,
      "name": "Wood_Softwood_Roof_Hollow"
    },
    {
      "x": 8,
      "y": -1,
      "z": 1,
      "name": "Rock_Stone_Cobble"
    },
    {
      "x": 8,
      "y": -1,
      "z": 2,
      "name": "Rock_Stone_Cobble"
    },
    {
      "x": 8,
      "y": -1,
      "z": 3,
      "name": "Rock_Stone_Cobble"
    },
    {
      "x": 8,
      "y": 1,
      "z": 3,
      "name": "Plant_Vine_Wall",
      "support": 15,
      "rotation": 2
    },
    {
      "x": 8,
      "y": 2,
      "z": 3,
      "name": "Plant_Vine",
      "support": 15,
      "rotation": 2
    },
    {
      "x": 8,
      "y": 3,
      "z": 3,
      "name": "Wood_Softwood_Roof_Hollow",
      "rotation": 2
    },
    {
      "x": 8,
      "y": -1,
      "z": 4,
      "name": "Rock_Stone_Cobble"
    },
    {
      "x": 8,
      "y": 0,
      "z": 4,
      "name": "Rock_Stone_Brick"
    },
    {
      "x": 8,
      "y": 1,
      "z": 4,
      "name": "*Wood_Village_Wall_Full_State_Definitions_Bottom"
    },
    {
      "x": 8,
      "y": 2,
      "z": 4,
      "name": "*Wood_Village_Wall_Full_State_Definitions_Top"
    },
    {
      "x": 8,
      "y": 3,
      "z": 4,
      "name": "Wood_Beech_Trunk",
      "support": 15,
      "rotation": 5
    },
    {
      "x": 8,
      "y": 4,
      "z": 4,
      "name": "Wood_Softwood_Roof",
      "rotation": 2
    },
    {
      "x": 8,
      "y": -1,
      "z": 5,
      "name": "Wood_Drywood_Planks"
    },
    {
      "x": 8,
      "y": 3,
      "z": 5,
      "name": "Furniture_Village_Platform",
      "support": 15,
      "rotation": 1
    },
    {
      "x": 8,
      "y": 4,
      "z": 5,
      "name": "Wood_Softwood_Stairs",
      "rotation": 10
    },
    {
      "x": 8,
      "y": 5,
      "z": 5,
      "name": "Wood_Softwood_Roof",
      "rotation": 2
    },
    {
      "x": 8,
      "y": -1,
      "z": 6,
      "name": "Wood_Drywood_Planks"
    },
    {
      "x": 8,
      "y": 3,
      "z": 6,
      "name": "Furniture_Village_Platform",
      "support": 15,
      "rotation": 1
    },
    {
      "x": 8,
      "y": 5,
      "z": 6,
      "name": "Wood_Softwood_Stairs",
      "rotation": 10
    },
    {
      "x": 8,
      "y": 6,
      "z": 6,
      "name": "Wood_Softwood_Roof",
      "rotation": 2
    },
    {
      "x": 8,
      "y": -1,
      "z": 7,
      "name": "Wood_Drywood_Planks"
    },
    {
      "x": 8,
      "y": 0,
      "z": 7,
      "name": "*Furniture_Village_Door_State_Definitions_CloseDoorIn",
      "rotation": 2
    },
    {
      "x": 8,
      "y": 1,
      "z": 7,
      "name": "*Furniture_Village_Door_State_Definitions_CloseDoorIn",
      "filler": 1024,
      "rotation": 2
    },
    {
      "x": 8,
      "y": 2,
      "z": 7,
      "name": "Wood_Village_Wall_Full"
    },
    {
      "x": 8,
      "y": 3,
      "z": 7,
      "name": "Wood_Beech_Trunk",
      "support": 15,
      "rotation": 5
    },
    {
      "x": 8,
      "y": 6,
      "z": 7,
      "name": "Wood_Softwood_Stairs",
      "rotation": 10
    },
    {
      "x": 8,
      "y": 7,
      "z": 7,
      "name": "Wood_Softwood_Roof",
      "rotation": 2
    },
    {
      "x": 8,
      "y": -1,
      "z": 8,
      "name": "Wood_Drywood_Planks"
    },
    {
      "x": 8,
      "y": 3,
      "z": 8,
      "name": "Furniture_Village_Platform",
      "support": 15,
      "rotation": 1
    },
    {
      "x": 8,
      "y": 6,
      "z": 8,
      "name": "Wood_Softwood_Stairs",
      "rotation": 8
    },
    {
      "x": 8,
      "y": 7,
      "z": 8,
      "name": "Wood_Softwood_Roof"
    },
    {
      "x": 8,
      "y": -1,
      "z": 9,
      "name": "Wood_Drywood_Planks"
    },
    {
      "x": 8,
      "y": 0,
      "z": 9,
      "name": "Furniture_Village_Bed",
      "support": 15,
      "filler": 993,
      "rotation": 1
    },
    {
      "x": 8,
      "y": 1,
      "z": 9,
      "name": "Furniture_Village_Bed",
      "support": 15,
      "filler": 2017,
      "rotation": 1
    },
    {
      "x": 8,
      "y": 3,
      "z": 9,
      "name": "Furniture_Village_Platform",
      "support": 15,
      "rotation": 1
    },
    {
      "x": 8,
      "y": 4,
      "z": 9,
      "name": "Furniture_Tavern_Barrel",
      "support": 15
    },
    {
      "x": 8,
      "y": 5,
      "z": 9,
      "name": "Wood_Softwood_Stairs",
      "rotation": 8
    },
    {
      "x": 8,
      "y": 6,
      "z": 9,
      "name": "Wood_Softwood_Roof"
    },
    {
      "x": 8,
      "y": -1,
      "z": 10,
      "name": "Wood_Drywood_Planks"
    },
    {
      "x": 8,
      "y": 0,
      "z": 10,
      "name": "Furniture_Village_Bed",
      "support": 15,
      "filler": 1,
      "rotation": 1
    },
    {
      "x": 8,
      "y": 1,
      "z": 10,
      "name": "Furniture_Village_Bed",
      "support": 15,
      "filler": 1025,
      "rotation": 1
    },
    {
      "x": 8,
      "y": 3,
      "z": 10,
      "name": "Furniture_Village_Platform",
      "support": 15,
      "rotation": 1
    },
    {
      "x": 8,
      "y": 4,
      "z": 10,
      "name": "Wood_Softwood_Stairs",
      "rotation": 8
    },
    {
      "x": 8,
      "y": 5,
      "z": 10,
      "name": "Wood_Softwood_Roof"
    },
    {
      "x": 8,
      "y": -1,
      "z": 11,
      "name": "Rock_Stone_Cobble"
    },
    {
      "x": 8,
      "y": 0,
      "z": 11,
      "name": "Rock_Stone_Brick"
    },
    {
      "x": 8,
      "y": 1,
      "z": 11,
      "name": "Furniture_Village_Window"
    },
    {
      "x": 8,
      "y": 2,
      "z": 11,
      "name": "Furniture_Village_Window"
    },
    {
      "x": 8,
      "y": 3,
      "z": 11,
      "name": "Wood_Beech_Trunk",
      "support": 15,
      "rotation": 5
    },
    {
      "x": 8,
      "y": 4,
      "z": 11,
      "name": "Wood_Softwood_Roof"
    },
    {
      "x": 8,
      "y": -1,
      "z": 12,
      "name": "Rock_Stone_Cobble"
    },
    {
      "x": 8,
      "y": 3,
      "z": 12,
      "name": "Wood_Softwood_Roof_Hollow"
    },
    {
      "x": 9,
      "y": -1,
      "z": 1,
      "name": "Rock_Stone_Cobble"
    },
    {
      "x": 9,
      "y": 3,
      "z": 1,
      "name": "Wood_Softwood_Roof_Hollow",
      "rotation": 3
    },
    {
      "x": 9,
      "y": -1,
      "z": 2,
      "name": "Rock_Stone_Cobble"
    },
    {
      "x": 9,
      "y": 2,
      "z": 2,
      "name": "Wood_Beech_Branch_Corner",
      "support": 15,
      "rotation": 3
    },
    {
      "x": 9,
      "y": 3,
      "z": 2,
      "name": "Wood_Softwood_Roof",
      "rotation": 3
    },
    {
      "x": 9,
      "y": -1,
      "z": 3,
      "name": "Rock_Stone_Cobble"
    },
    {
      "x": 9,
      "y": 0,
      "z": 3,
      "name": "Furniture_Tavern_Planter",
      "support": 15
    },
    {
      "x": 9,
      "y": 1,
      "z": 3,
      "name": "Plant_Flower_Common_Pink2",
      "support": 15
    },
    {
      "x": 9,
      "y": 3,
      "z": 3,
      "name": "*Wood_Softwood_Roof_Hollow_State_Definitions_Inverted_Corner_Right",
      "rotation": 3
    },
    {
      "x": 9,
      "y": -1,
      "z": 4,
      "name": "Rock_Stone_Cobble"
    },
    {
      "x": 9,
      "y": 0,
      "z": 4,
      "name": "Rock_Stone_Brick"
    },
    {
      "x": 9,
      "y": 1,
      "z": 4,
      "name": "*Wood_Village_Wall_Full_State_Definitions_Bottom"
    },
    {
      "x": 9,
      "y": 2,
      "z": 4,
      "name": "*Wood_Village_Wall_Full_State_Definitions_Top"
    },
    {
      "x": 9,
      "y": 3,
      "z": 4,
      "name": "Wood_Beech_Trunk",
      "support": 15,
      "rotation": 5
    },
    {
      "x": 9,
      "y": 4,
      "z": 4,
      "name": "Wood_Softwood_Roof",
      "rotation": 2
    },
    {
      "x": 9,
      "y": -1,
      "z": 5,
      "name": "Wood_Drywood_Planks"
    },
    {
      "x": 9,
      "y": 3,
      "z": 5,
      "name": "Furniture_Village_Platform",
      "support": 15,
      "rotation": 1
    },
    {
      "x": 9,
      "y": 4,
      "z": 5,
      "name": "Wood_Softwood_Stairs",
      "rotation": 10
    },
    {
      "x": 9,
      "y": 5,
      "z": 5,
      "name": "Wood_Softwood_Roof",
      "rotation": 2
    },
    {
      "x": 9,
      "y": -1,
      "z": 6,
      "name": "Wood_Drywood_Planks"
    },
    {
      "x": 9,
      "y": 3,
      "z": 6,
      "name": "Furniture_Village_Platform",
      "support": 15,
      "rotation": 1
    },
    {
      "x": 9,
      "y": 4,
      "z": 6,
      "name": "Furniture_Tavern_Barrel",
      "support": 15
    },
    {
      "x": 9,
      "y": 5,
      "z": 6,
      "name": "Wood_Softwood_Stairs",
      "rotation": 10
    },
    {
      "x": 9,
      "y": 6,
      "z": 6,
      "name": "Wood_Softwood_Roof",
      "rotation": 2
    },
    {
      "x": 9,
      "y": -1,
      "z": 7,
      "name": "Rock_Stone_Cobble"
    },
    {
      "x": 9,
      "y": 0,
      "z": 7,
      "name": "*Wood_Village_Wall_Full_State_Definitions_Bottom"
    },
    {
      "x": 9,
      "y": 1,
      "z": 7,
      "name": "*Wood_Village_Wall_Full_State_Definitions_Middle"
    },
    {
      "x": 9,
      "y": 2,
      "z": 7,
      "name": "*Wood_Village_Wall_Full_State_Definitions_Top"
    },
    {
      "x": 9,
      "y": 3,
      "z": 7,
      "name": "Wood_Beech_Trunk",
      "support": 15,
      "rotation": 5
    },
    {
      "x": 9,
      "y": 6,
      "z": 7,
      "name": "Wood_Softwood_Stairs",
      "rotation": 10
    },
    {
      "x": 9,
      "y": 7,
      "z": 7,
      "name": "Wood_Softwood_Roof",
      "rotation": 2
    },
    {
      "x": 9,
      "y": -1,
      "z": 8,
      "name": "Wood_Drywood_Planks"
    },
    {
      "x": 9,
      "y": 3,
      "z": 8,
      "name": "Furniture_Village_Platform",
      "support": 15,
      "rotation": 1
    },
    {
      "x": 9,
      "y": 6,
      "z": 8,
      "name": "Wood_Softwood_Stairs",
      "rotation": 8
    },
    {
      "x": 9,
      "y": 7,
      "z": 8,
      "name": "Wood_Softwood_Roof"
    },
    {
      "x": 9,
      "y": -1,
      "z": 9,
      "name": "Wood_Drywood_Planks"
    },
    {
      "x": 9,
      "y": 0,
      "z": 9,
      "name": "Furniture_Village_Bed",
      "support": 15,
      "filler": 994,
      "rotation": 1
    },
    {
      "x": 9,
      "y": 1,
      "z": 9,
      "name": "Furniture_Village_Bed",
      "support": 15,
      "filler": 2018,
      "rotation": 1
    },
    {
      "x": 9,
      "y": 3,
      "z": 9,
      "name": "Furniture_Village_Platform",
      "support": 15,
      "rotation": 1
    },
    {
      "x": 9,
      "y": 4,
      "z": 9,
      "name": "Furniture_Tavern_Barrel",
      "support": 15
    },
    {
      "x": 9,
      "y": 5,
      "z": 9,
      "name": "Wood_Softwood_Stairs",
      "rotation": 8
    },
    {
      "x": 9,
      "y": 6,
      "z": 9,
      "name": "Wood_Softwood_Roof"
    },
    {
      "x": 9,
      "y": -1,
      "z": 10,
      "name": "Wood_Drywood_Planks"
    },
    {
      "x": 9,
      "y": 0,
      "z": 10,
      "name": "Furniture_Village_Bed",
      "support": 15,
      "filler": 2,
      "rotation": 1
    },
    {
      "x": 9,
      "y": 1,
      "z": 10,
      "name": "Furniture_Village_Bed",
      "support": 15,
      "filler": 1026,
      "rotation": 1
    },
    {
      "x": 9,
      "y": 3,
      "z": 10,
      "name": "Furniture_Village_Platform",
      "support": 15,
      "rotation": 1
    },
    {
      "x": 9,
      "y": 4,
      "z": 10,
      "name": "Wood_Softwood_Stairs",
      "rotation": 8
    },
    {
      "x": 9,
      "y": 5,
      "z": 10,
      "name": "Wood_Softwood_Roof"
    },
    {
      "x": 9,
      "y": -1,
      "z": 11,
      "name": "Rock_Stone_Cobble"
    },
    {
      "x": 9,
      "y": 0,
      "z": 11,
      "name": "Rock_Stone_Brick"
    },
    {
      "x": 9,
      "y": 1,
      "z": 11,
      "name": "*Wood_Village_Wall_Full_State_Definitions_Bottom"
    },
    {
      "x": 9,
      "y": 2,
      "z": 11,
      "name": "*Wood_Village_Wall_Full_State_Definitions_Top"
    },
    {
      "x": 9,
      "y": 3,
      "z": 11,
      "name": "Wood_Beech_Trunk",
      "support": 15,
      "rotation": 5
    },
    {
      "x": 9,
      "y": 4,
      "z": 11,
      "name": "Wood_Softwood_Roof"
    },
    {
      "x": 9,
      "y": -1,
      "z": 12,
      "name": "Rock_Stone_Cobble"
    },
    {
      "x": 9,
      "y": 1,
      "z": 12,
      "name": "Plant_Vine_Wall",
      "support": 15
    },
    {
      "x": 9,
      "y": 3,
      "z": 12,
      "name": "Wood_Softwood_Roof_Hollow"
    },
    {
      "x": 10,
      "y": -1,
      "z": 1,
      "name": "Rock_Stone_Cobble"
    },
    {
      "x": 10,
      "y": 3,
      "z": 1,
      "name": "Wood_Beech_Branch_Corner",
      "support": 15,
      "rotation": 2
    },
    {
      "x": 10,
      "y": 4,
      "z": 1,
      "name": "Wood_Softwood_Roof",
      "rotation": 3
    },
    {
      "x": 10,
      "y": -1,
      "z": 2,
      "name": "Rock_Stone_Cobble"
    },
    {
      "x": 10,
      "y": 0,
      "z": 2,
      "name": "Wood_Beech_Trunk",
      "support": 15
    },
    {
      "x": 10,
      "y": 1,
      "z": 2,
      "name": "Wood_Beech_Trunk",
      "support": 15
    },
    {
      "x": 10,
      "y": 2,
      "z": 2,
      "name": "Wood_Beech_Trunk",
      "support": 15
    },
    {
      "x": 10,
      "y": 3,
      "z": 2,
      "name": "Wood_Beech_Trunk",
      "support": 15
    },
    {
      "x": 10,
      "y": 4,
      "z": 2,
      "name": "Wood_Softwood_Roof",
      "rotation": 3
    },
    {
      "x": 10,
      "y": -1,
      "z": 3,
      "name": "Rock_Stone_Cobble"
    },
    {
      "x": 10,
      "y": 0,
      "z": 3,
      "name": "Rock_Stone_Brick"
    },
    {
      "x": 10,
      "y": 1,
      "z": 3,
      "name": "*Wood_Village_Wall_Full_State_Definitions_Bottom"
    },
    {
      "x": 10,
      "y": 2,
      "z": 3,
      "name": "*Wood_Village_Wall_Full_State_Definitions_Top"
    },
    {
      "x": 10,
      "y": 3,
      "z": 3,
      "name": "Wood_Beech_Trunk",
      "support": 15,
      "rotation": 4
    },
    {
      "x": 10,
      "y": 4,
      "z": 3,
      "name": "Wood_Softwood_Roof",
      "rotation": 3
    },
    {
      "x": 10,
      "y": -1,
      "z": 4,
      "name": "Rock_Stone_Cobble"
    },
    {
      "x": 10,
      "y": 0,
      "z": 4,
      "name": "Wood_Beech_Trunk",
      "support": 15
    },
    {
      "x": 10,
      "y": 1,
      "z": 4,
      "name": "Wood_Beech_Trunk",
      "support": 15
    },
    {
      "x": 10,
      "y": 2,
      "z": 4,
      "name": "Wood_Beech_Trunk",
      "support": 15
    },
    {
      "x": 10,
      "y": 3,
      "z": 4,
      "name": "Wood_Beech_Trunk",
      "support": 15
    },
    {
      "x": 10,
      "y": 4,
      "z": 4,
      "name": "*Wood_Softwood_Roof_State_Definitions_Inverted_Corner_Right",
      "rotation": 3
    },
    {
      "x": 10,
      "y": -1,
      "z": 5,
      "name": "Wood_Drywood_Planks"
    },
    {
      "x": 10,
      "y": 3,
      "z": 5,
      "name": "Wood_Beech_Trunk",
      "support": 15,
      "rotation": 4
    },
    {
      "x": 10,
      "y": 4,
      "z": 5,
      "name": "Wood_Softwood_Stairs",
      "rotation": 10
    },
    {
      "x": 10,
      "y": 5,
      "z": 5,
      "name": "Wood_Softwood_Roof",
      "rotation": 2
    },
    {
      "x": 10,
      "y": -1,
      "z": 6,
      "name": "Wood_Drywood_Planks"
    },
    {
      "x": 10,
      "y": 3,
      "z": 6,
      "name": "Wood_Beech_Trunk",
      "support": 15,
      "rotation": 4
    },
    {
      "x": 10,
      "y": 5,
      "z": 6,
      "name": "Wood_Softwood_Stairs",
      "rotation": 10
    },
    {
      "x": 10,
      "y": 6,
      "z": 6,
      "name": "Wood_Softwood_Roof",
      "rotation": 2
    },
    {
      "x": 10,
      "y": -1,
      "z": 7,
      "name": "Rock_Stone_Cobble"
    },
    {
      "x": 10,
      "y": 0,
      "z": 7,
      "name": "Wood_Beech_Trunk",
      "support": 15
    },
    {
      "x": 10,
      "y": 1,
      "z": 7,
      "name": "Wood_Beech_Trunk",
      "support": 15
    },
    {
      "x": 10,
      "y": 2,
      "z": 7,
      "name": "Wood_Beech_Trunk",
      "support": 15
    },
    {
      "x": 10,
      "y": 3,
      "z": 7,
      "name": "Wood_Beech_Trunk",
      "support": 15
    },
    {
      "x": 10,
      "y": 6,
      "z": 7,
      "name": "Wood_Softwood_Stairs",
      "rotation": 10
    },
    {
      "x": 10,
      "y": 7,
      "z": 7,
      "name": "Wood_Softwood_Roof",
      "rotation": 2
    },
    {
      "x": 10,
      "y": -1,
      "z": 8,
      "name": "Rock_Stone_Cobble"
    },
    {
      "x": 10,
      "y": 0,
      "z": 8,
      "name": "*Wood_Village_Wall_Full_State_Definitions_Bottom"
    },
    {
      "x": 10,
      "y": 1,
      "z": 8,
      "name": "*Wood_Village_Wall_Full_State_Definitions_Middle"
    },
    {
      "x": 10,
      "y": 2,
      "z": 8,
      "name": "*Wood_Village_Wall_Full_State_Definitions_Top"
    },
    {
      "x": 10,
      "y": 3,
      "z": 8,
      "name": "Wood_Beech_Trunk",
      "support": 15,
      "rotation": 4
    },
    {
      "x": 10,
      "y": 6,
      "z": 8,
      "name": "Wood_Softwood_Stairs",
      "rotation": 8
    },
    {
      "x": 10,
      "y": 7,
      "z": 8,
      "name": "Wood_Softwood_Roof"
    },
    {
      "x": 10,
      "y": -1,
      "z": 9,
      "name": "Rock_Stone_Cobble"
    },
    {
      "x": 10,
      "y": 0,
      "z": 9,
      "name": "*Wood_Village_Wall_Full_State_Definitions_Bottom"
    },
    {
      "x": 10,
      "y": 1,
      "z": 9,
      "name": "*Wood_Village_Wall_Full_State_Definitions_Middle"
    },
    {
      "x": 10,
      "y": 2,
      "z": 9,
      "name": "*Wood_Village_Wall_Full_State_Definitions_Top"
    },
    {
      "x": 10,
      "y": 3,
      "z": 9,
      "name": "Wood_Beech_Trunk",
      "support": 15,
      "rotation": 4
    },
    {
      "x": 10,
      "y": 5,
      "z": 9,
      "name": "Wood_Softwood_Stairs",
      "rotation": 8
    },
    {
      "x": 10,
      "y": 6,
      "z": 9,
      "name": "Wood_Softwood_Roof"
    },
    {
      "x": 10,
      "y": -1,
      "z": 10,
      "name": "Rock_Stone_Cobble"
    },
    {
      "x": 10,
      "y": 0,
      "z": 10,
      "name": "*Wood_Village_Wall_Full_State_Definitions_Bottom"
    },
    {
      "x": 10,
      "y": 1,
      "z": 10,
      "name": "*Wood_Village_Wall_Full_State_Definitions_Middle"
    },
    {
      "x": 10,
      "y": 2,
      "z": 10,
      "name": "*Wood_Village_Wall_Full_State_Definitions_Top"
    },
    {
      "x": 10,
      "y": 3,
      "z": 10,
      "name": "Wood_Beech_Trunk",
      "support": 15,
      "rotation": 4
    },
    {
      "x": 10,
      "y": 4,
      "z": 10,
      "name": "Wood_Softwood_Stairs",
      "rotation": 8
    },
    {
      "x": 10,
      "y": 5,
      "z": 10,
      "name": "Wood_Softwood_Roof"
    },
    {
      "x": 10,
      "y": -1,
      "z": 11,
      "name": "Rock_Stone_Cobble"
    },
    {
      "x": 10,
      "y": 0,
      "z": 11,
      "name": "Wood_Beech_Trunk",
      "support": 15
    },
    {
      "x": 10,
      "y": 1,
      "z": 11,
      "name": "Wood_Beech_Trunk",
      "support": 15
    },
    {
      "x": 10,
      "y": 2,
      "z": 11,
      "name": "Wood_Beech_Trunk",
      "support": 15
    },
    {
      "x": 10,
      "y": 3,
      "z": 11,
      "name": "Wood_Beech_Trunk",
      "support": 15
    },
    {
      "x": 10,
      "y": 4,
      "z": 11,
      "name": "Wood_Softwood_Roof"
    },
    {
      "x": 10,
      "y": -1,
      "z": 12,
      "name": "Rock_Stone_Cobble"
    },
    {
      "x": 10,
      "y": 2,
      "z": 12,
      "name": "Wood_Beech_Branch_Corner",
      "support": 15
    },
    {
      "x": 10,
      "y": 3,
      "z": 12,
      "name": "Wood_Softwood_Roof"
    },
    {
      "x": 11,
      "y": -1,
      "z": 1,
      "name": "Rock_Stone_Cobble"
    },
    {
      "x": 11,
      "y": 3,
      "z": 1,
      "name": "Wood_Beech_Branch_Short",
      "support": 15,
      "rotation": 2
    },
    {
      "x": 11,
      "y": 4,
      "z": 1,
      "name": "Wood_Softwood_Planks_Half",
      "rotation": 8
    },
    {
      "x": 11,
      "y": 5,
      "z": 1,
      "name": "Wood_Softwood_Roof",
      "rotation": 3
    },
    {
      "x": 11,
      "y": -1,
      "z": 2,
      "name": "Rock_Stone_Cobble"
    },
    {
      "x": 11,
      "y": 0,
      "z": 2,
      "name": "Rock_Stone_Brick"
    },
    {
      "x": 11,
      "y": 1,
      "z": 2,
      "name": "*Wood_Village_Wall_Full_State_Definitions_Bottom"
    },
    {
      "x": 11,
      "y": 2,
      "z": 2,
      "name": "*Wood_Village_Wall_Full_State_Definitions_Top"
    },
    {
      "x": 11,
      "y": 3,
      "z": 2,
      "name": "Wood_Beech_Trunk",
      "support": 15,
      "rotation": 5
    },
    {
      "x": 11,
      "y": 4,
      "z": 2,
      "name": "Wood_Village_Wall_Full"
    },
    {
      "x": 11,
      "y": 5,
      "z": 2,
      "name": "Wood_Softwood_Roof",
      "rotation": 3
    },
    {
      "x": 11,
      "y": -1,
      "z": 3,
      "name": "Wood_Drywood_Planks"
    },
    {
      "x": 11,
      "y": 0,
      "z": 3,
      "name": "Furniture_Tavern_Candle",
      "support": 15
    },
    {
      "x": 11,
      "y": 4,
      "z": 3,
      "name": "Wood_Softwood_Stairs",
      "rotation": 11
    },
    {
      "x": 11,
      "y": 5,
      "z": 3,
      "name": "Wood_Softwood_Roof",
      "rotation": 3
    },
    {
      "x": 11,
      "y": -1,
      "z": 4,
      "name": "Wood_Drywood_Planks"
    },
    {
      "x": 11,
      "y": 4,
      "z": 4,
      "name": "Wood_Softwood_Stairs",
      "rotation": 11
    },
    {
      "x": 11,
      "y": 5,
      "z": 4,
      "name": "Wood_Softwood_Roof",
      "rotation": 3
    },
    {
      "x": 11,
      "y": -1,
      "z": 5,
      "name": "Wood_Drywood_Planks"
    },
    {
      "x": 11,
      "y": 4,
      "z": 5,
      "name": "*Wood_Softwood_Stairs_State_Definitions_Corner_Right",
      "rotation": 10
    },
    {
      "x": 11,
      "y": 5,
      "z": 5,
      "name": "*Wood_Softwood_Roof_State_Definitions_Inverted_Corner_Right",
      "rotation": 3
    },
    {
      "x": 11,
      "y": -1,
      "z": 6,
      "name": "Wood_Drywood_Planks"
    },
    {
      "x": 11,
      "y": 5,
      "z": 6,
      "name": "Wood_Softwood_Stairs",
      "rotation": 10
    },
    {
      "x": 11,
      "y": 6,
      "z": 6,
      "name": "Wood_Softwood_Roof",
      "rotation": 2
    },
    {
      "x": 11,
      "y": -1,
      "z": 7,
      "name": "Wood_Drywood_Planks"
    },
    {
      "x": 11,
      "y": 0,
      "z": 7,
      "name": "Furniture_Village_Ladder",
      "rotation": 1
    },
    {
      "x": 11,
      "y": 1,
      "z": 7,
      "name": "Furniture_Village_Ladder",
      "rotation": 1
    },
    {
      "x": 11,
      "y": 2,
      "z": 7,
      "name": "Furniture_Village_Ladder",
      "rotation": 1
    },
    {
      "x": 11,
      "y": 3,
      "z": 7,
      "name": "Furniture_Village_Ladder",
      "rotation": 1
    },
    {
      "x": 11,
      "y": 6,
      "z": 7,
      "name": "Wood_Softwood_Stairs",
      "rotation": 10
    },
    {
      "x": 11,
      "y": 7,
      "z": 7,
      "name": "Wood_Softwood_Roof",
      "rotation": 2
    },
    {
      "x": 11,
      "y": -1,
      "z": 8,
      "name": "Wood_Drywood_Planks"
    },
    {
      "x": 11,
      "y": 0,
      "z": 8,
      "name": "*Wood_Softwood_Fence_Gate_State_Definitions_CloseDoorOut",
      "rotation": 2
    },
    {
      "x": 11,
      "y": 6,
      "z": 8,
      "name": "Wood_Softwood_Stairs",
      "rotation": 8
    },
    {
      "x": 11,
      "y": 7,
      "z": 8,
      "name": "Wood_Softwood_Roof"
    },
    {
      "x": 11,
      "y": -1,
      "z": 9,
      "name": "Wood_Drywood_Planks"
    },
    {
      "x": 11,
      "y": 5,
      "z": 9,
      "name": "Wood_Softwood_Stairs",
      "rotation": 8
    },
    {
      "x": 11,
      "y": 6,
      "z": 9,
      "name": "Wood_Softwood_Roof"
    },
    {
      "x": 11,
      "y": -1,
      "z": 10,
      "name": "Wood_Drywood_Planks"
    },
    {
      "x": 11,
      "y": 4,
      "z": 10,
      "name": "Wood_Softwood_Stairs",
      "rotation": 8
    },
    {
      "x": 11,
      "y": 5,
      "z": 10,
      "name": "Wood_Softwood_Roof"
    },
    {
      "x": 11,
      "y": -1,
      "z": 11,
      "name": "Rock_Stone_Cobble"
    },
    {
      "x": 11,
      "y": 0,
      "z": 11,
      "name": "Rock_Stone_Brick"
    },
    {
      "x": 11,
      "y": 1,
      "z": 11,
      "name": "*Wood_Village_Wall_Full_State_Definitions_Bottom"
    },
    {
      "x": 11,
      "y": 2,
      "z": 11,
      "name": "*Wood_Village_Wall_Full_State_Definitions_Top"
    },
    {
      "x": 11,
      "y": 3,
      "z": 11,
      "name": "Wood_Beech_Trunk",
      "support": 15,
      "rotation": 5
    },
    {
      "x": 11,
      "y": 4,
      "z": 11,
      "name": "Wood_Softwood_Roof"
    },
    {
      "x": 11,
      "y": -1,
      "z": 12,
      "name": "Rock_Stone_Cobble"
    },
    {
      "x": 11,
      "y": 3,
      "z": 12,
      "name": "Wood_Softwood_Roof_Hollow"
    },
    {
      "x": 12,
      "y": -1,
      "z": 1,
      "name": "Rock_Stone_Cobble"
    },
    {
      "x": 12,
      "y": 0,
      "z": 1,
      "name": "Wood_Softwood_Beam"
    },
    {
      "x": 12,
      "y": 1,
      "z": 1,
      "name": "Wood_Softwood_Beam"
    },
    {
      "x": 12,
      "y": 2,
      "z": 1,
      "name": "*Wood_Softwood_Roof_State_Definitions_Corner_Right",
      "rotation": 3
    },
    {
      "x": 12,
      "y": 5,
      "z": 1,
      "name": "Wood_Softwood_Planks_Half",
      "rotation": 8
    },
    {
      "x": 12,
      "y": 6,
      "z": 1,
      "name": "Wood_Softwood_Roof",
      "rotation": 3
    },
    {
      "x": 12,
      "y": -1,
      "z": 2,
      "name": "Rock_Stone_Cobble"
    },
    {
      "x": 12,
      "y": 0,
      "z": 2,
      "name": "Rock_Stone_Brick"
    },
    {
      "x": 12,
      "y": 1,
      "z": 2,
      "name": "*Wood_Village_Wall_Full_State_Definitions_Bottom"
    },
    {
      "x": 12,
      "y": 2,
      "z": 2,
      "name": "*Wood_Village_Wall_Full_State_Definitions_Top"
    },
    {
      "x": 12,
      "y": 3,
      "z": 2,
      "name": "Wood_Beech_Trunk",
      "support": 15,
      "rotation": 5
    },
    {
      "x": 12,
      "y": 4,
      "z": 2,
      "name": "*Wood_Village_Wall_Full_State_Definitions_Bottom"
    },
    {
      "x": 12,
      "y": 5,
      "z": 2,
      "name": "*Wood_Village_Wall_Full_State_Definitions_Top"
    },
    {
      "x": 12,
      "y": 6,
      "z": 2,
      "name": "Wood_Softwood_Roof",
      "rotation": 3
    },
    {
      "x": 12,
      "y": -1,
      "z": 3,
      "name": "Wood_Drywood_Planks"
    },
    {
      "x": 12,
      "y": 5,
      "z": 3,
      "name": "Wood_Softwood_Stairs",
      "rotation": 11
    },
    {
      "x": 12,
      "y": 6,
      "z": 3,
      "name": "Wood_Softwood_Roof",
      "rotation": 3
    },
    {
      "x": 12,
      "y": -1,
      "z": 4,
      "name": "Wood_Drywood_Planks"
    },
    {
      "x": 12,
      "y": 0,
      "z": 4,
      "name": "Cloth_Roof_Leather_Flat"
    },
    {
      "x": 12,
      "y": 5,
      "z": 4,
      "name": "Wood_Softwood_Stairs",
      "rotation": 11
    },
    {
      "x": 12,
      "y": 6,
      "z": 4,
      "name": "Wood_Softwood_Roof",
      "rotation": 3
    },
    {
      "x": 12,
      "y": -1,
      "z": 5,
      "name": "Wood_Drywood_Planks"
    },
    {
      "x": 12,
      "y": 0,
      "z": 5,
      "name": "Cloth_Roof_Leather_Flat"
    },
    {
      "x": 12,
      "y": 5,
      "z": 5,
      "name": "Wood_Softwood_Stairs",
      "rotation": 11
    },
    {
      "x": 12,
      "y": 6,
      "z": 5,
      "name": "Wood_Softwood_Roof",
      "rotation": 3
    },
    {
      "x": 12,
      "y": -1,
      "z": 6,
      "name": "Wood_Drywood_Planks"
    },
    {
      "x": 12,
      "y": 0,
      "z": 6,
      "name": "Cloth_Roof_Leather_Flat"
    },
    {
      "x": 12,
      "y": 5,
      "z": 6,
      "name": "*Wood_Softwood_Stairs_State_Definitions_Corner_Right",
      "rotation": 10
    },
    {
      "x": 12,
      "y": 6,
      "z": 6,
      "name": "*Wood_Softwood_Roof_State_Definitions_Inverted_Corner_Right",
      "rotation": 3
    },
    {
      "x": 12,
      "y": -1,
      "z": 7,
      "name": "Wood_Drywood_Planks"
    },
    {
      "x": 12,
      "y": 6,
      "z": 7,
      "name": "Wood_Softwood_Stairs",
      "rotation": 10
    },
    {
      "x": 12,
      "y": 7,
      "z": 7,
      "name": "Wood_Softwood_Roof",
      "rotation": 2
    },
    {
      "x": 12,
      "y": -1,
      "z": 8,
      "name": "Wood_Drywood_Planks"
    },
    {
      "x": 12,
      "y": 0,
      "z": 8,
      "name": "Wood_Softwood_Planks"
    },
    {
      "x": 12,
      "y": 1,
      "z": 8,
      "name": "Aetherhaven_Inn_Bell",
      "support": 15
    },
    {
      "x": 12,
      "y": 6,
      "z": 8,
      "name": "Wood_Softwood_Stairs",
      "rotation": 8
    },
    {
      "x": 12,
      "y": 7,
      "z": 8,
      "name": "Wood_Softwood_Roof"
    },
    {
      "x": 12,
      "y": -1,
      "z": 9,
      "name": "Wood_Drywood_Planks"
    },
    {
      "x": 12,
      "y": 5,
      "z": 9,
      "name": "Wood_Softwood_Stairs",
      "rotation": 8
    },
    {
      "x": 12,
      "y": 6,
      "z": 9,
      "name": "Wood_Softwood_Roof"
    },
    {
      "x": 12,
      "y": -1,
      "z": 10,
      "name": "Wood_Drywood_Planks"
    },
    {
      "x": 12,
      "y": 4,
      "z": 10,
      "name": "Wood_Softwood_Stairs",
      "rotation": 8
    },
    {
      "x": 12,
      "y": 5,
      "z": 10,
      "name": "Wood_Softwood_Roof"
    },
    {
      "x": 12,
      "y": -1,
      "z": 11,
      "name": "Rock_Stone_Cobble"
    },
    {
      "x": 12,
      "y": 0,
      "z": 11,
      "name": "Rock_Stone_Brick"
    },
    {
      "x": 12,
      "y": 1,
      "z": 11,
      "name": "Furniture_Village_Window"
    },
    {
      "x": 12,
      "y": 2,
      "z": 11,
      "name": "Furniture_Village_Window"
    },
    {
      "x": 12,
      "y": 3,
      "z": 11,
      "name": "Wood_Beech_Trunk",
      "support": 15,
      "rotation": 5
    },
    {
      "x": 12,
      "y": 4,
      "z": 11,
      "name": "Wood_Softwood_Roof"
    },
    {
      "x": 12,
      "y": -1,
      "z": 12,
      "name": "Rock_Stone_Cobble"
    },
    {
      "x": 12,
      "y": 3,
      "z": 12,
      "name": "Wood_Softwood_Roof_Hollow"
    },
    {
      "x": 13,
      "y": -1,
      "z": 1,
      "name": "Rock_Stone_Cobble"
    },
    {
      "x": 13,
      "y": 2,
      "z": 1,
      "name": "Wood_Softwood_Roof_Hollow",
      "rotation": 2
    },
    {
      "x": 13,
      "y": 3,
      "z": 1,
      "name": "Wood_Beech_Branch_Short",
      "support": 15,
      "rotation": 2
    },
    {
      "x": 13,
      "y": 6,
      "z": 1,
      "name": "Wood_Beech_Trunk",
      "support": 15,
      "rotation": 4
    },
    {
      "x": 13,
      "y": 7,
      "z": 1,
      "name": "Wood_Softwood_Roof_Flat",
      "rotation": 2
    },
    {
      "x": 13,
      "y": -1,
      "z": 2,
      "name": "Rock_Stone_Cobble"
    },
    {
      "x": 13,
      "y": 0,
      "z": 2,
      "name": "*Furniture_Village_Door_State_Definitions_OpenDoorOut",
      "rotation": 2
    },
    {
      "x": 13,
      "y": 1,
      "z": 2,
      "name": "*Furniture_Village_Door_State_Definitions_OpenDoorOut",
      "filler": 1024,
      "rotation": 2
    },
    {
      "x": 13,
      "y": 2,
      "z": 2,
      "name": "Wood_Village_Wall_Full"
    },
    {
      "x": 13,
      "y": 3,
      "z": 2,
      "name": "Wood_Beech_Trunk",
      "support": 15,
      "rotation": 5
    },
    {
      "x": 13,
      "y": 4,
      "z": 2,
      "name": "Furniture_Village_Window"
    },
    {
      "x": 13,
      "y": 5,
      "z": 2,
      "name": "Wood_Beech_Trunk",
      "support": 15
    },
    {
      "x": 13,
      "y": 6,
      "z": 2,
      "name": "Wood_Beech_Trunk",
      "support": 15,
      "rotation": 4
    },
    {
      "x": 13,
      "y": 7,
      "z": 2,
      "name": "Wood_Softwood_Roof_Flat",
      "rotation": 2
    },
    {
      "x": 13,
      "y": -1,
      "z": 3,
      "name": "Wood_Drywood_Planks"
    },
    {
      "x": 13,
      "y": 0,
      "z": 3,
      "name": "*Furniture_Village_Door_State_Definitions_OpenDoorOut",
      "filler": 32,
      "rotation": 2
    },
    {
      "x": 13,
      "y": 1,
      "z": 3,
      "name": "*Furniture_Village_Door_State_Definitions_OpenDoorOut",
      "filler": 1056,
      "rotation": 2
    },
    {
      "x": 13,
      "y": 6,
      "z": 3,
      "name": "Wood_Beech_Trunk",
      "support": 15,
      "rotation": 4
    },
    {
      "x": 13,
      "y": 7,
      "z": 3,
      "name": "Wood_Softwood_Roof_Flat",
      "rotation": 1
    },
    {
      "x": 13,
      "y": -1,
      "z": 4,
      "name": "Wood_Drywood_Planks"
    },
    {
      "x": 13,
      "y": 0,
      "z": 4,
      "name": "Cloth_Roof_Leather_Flat"
    },
    {
      "x": 13,
      "y": 6,
      "z": 4,
      "name": "Wood_Beech_Trunk",
      "support": 15,
      "rotation": 4
    },
    {
      "x": 13,
      "y": 7,
      "z": 4,
      "name": "Wood_Softwood_Roof_Flat",
      "rotation": 3
    },
    {
      "x": 13,
      "y": -1,
      "z": 5,
      "name": "Wood_Drywood_Planks"
    },
    {
      "x": 13,
      "y": 0,
      "z": 5,
      "name": "Cloth_Roof_Leather_Flat"
    },
    {
      "x": 13,
      "y": 6,
      "z": 5,
      "name": "Wood_Beech_Trunk",
      "support": 15,
      "rotation": 4
    },
    {
      "x": 13,
      "y": 7,
      "z": 5,
      "name": "Wood_Softwood_Roof_Flat",
      "rotation": 1
    },
    {
      "x": 13,
      "y": -1,
      "z": 6,
      "name": "Wood_Drywood_Planks"
    },
    {
      "x": 13,
      "y": 0,
      "z": 6,
      "name": "Cloth_Roof_Leather_Flat"
    },
    {
      "x": 13,
      "y": 6,
      "z": 6,
      "name": "Wood_Beech_Trunk",
      "support": 15,
      "rotation": 4
    },
    {
      "x": 13,
      "y": 7,
      "z": 6,
      "name": "Wood_Softwood_Roof_Flat",
      "rotation": 3
    },
    {
      "x": 13,
      "y": -1,
      "z": 7,
      "name": "Wood_Drywood_Planks"
    },
    {
      "x": 13,
      "y": 3,
      "z": 7,
      "name": "Deco_Lantern_Ceiling",
      "support": 15
    },
    {
      "x": 13,
      "y": 4,
      "z": 7,
      "name": "Deco_Rope",
      "support": 15
    },
    {
      "x": 13,
      "y": 5,
      "z": 7,
      "name": "Deco_Rope",
      "support": 15
    },
    {
      "x": 13,
      "y": 6,
      "z": 7,
      "name": "Wood_Beech_Trunk",
      "support": 15,
      "rotation": 4
    },
    {
      "x": 13,
      "y": 7,
      "z": 7,
      "name": "*Wood_Softwood_Roof_State_Definitions_Corner_Left",
      "rotation": 1
    },
    {
      "x": 13,
      "y": -1,
      "z": 8,
      "name": "Wood_Drywood_Planks"
    },
    {
      "x": 13,
      "y": 0,
      "z": 8,
      "name": "Wood_Softwood_Planks_Half",
      "rotation": 8
    },
    {
      "x": 13,
      "y": 6,
      "z": 8,
      "name": "Wood_Beech_Trunk",
      "support": 15,
      "rotation": 4
    },
    {
      "x": 13,
      "y": 7,
      "z": 8,
      "name": "*Wood_Softwood_Roof_State_Definitions_Corner_Left"
    },
    {
      "x": 13,
      "y": -1,
      "z": 9,
      "name": "Wood_Drywood_Planks"
    },
    {
      "x": 13,
      "y": 5,
      "z": 9,
      "name": "Wood_Softwood_Stairs",
      "rotation": 8
    },
    {
      "x": 13,
      "y": 6,
      "z": 9,
      "name": "Wood_Softwood_Roof"
    },
    {
      "x": 13,
      "y": -1,
      "z": 10,
      "name": "Wood_Drywood_Planks"
    },
    {
      "x": 13,
      "y": 4,
      "z": 10,
      "name": "Wood_Softwood_Stairs",
      "rotation": 8
    },
    {
      "x": 13,
      "y": 5,
      "z": 10,
      "name": "Wood_Softwood_Roof"
    },
    {
      "x": 13,
      "y": -1,
      "z": 11,
      "name": "Rock_Stone_Cobble"
    },
    {
      "x": 13,
      "y": 0,
      "z": 11,
      "name": "Rock_Stone_Brick"
    },
    {
      "x": 13,
      "y": 1,
      "z": 11,
      "name": "Furniture_Village_Window"
    },
    {
      "x": 13,
      "y": 2,
      "z": 11,
      "name": "Furniture_Village_Window"
    },
    {
      "x": 13,
      "y": 3,
      "z": 11,
      "name": "Wood_Beech_Trunk",
      "support": 15,
      "rotation": 5
    },
    {
      "x": 13,
      "y": 4,
      "z": 11,
      "name": "Wood_Softwood_Roof"
    },
    {
      "x": 13,
      "y": -1,
      "z": 12,
      "name": "Rock_Stone_Cobble"
    },
    {
      "x": 13,
      "y": 3,
      "z": 12,
      "name": "Wood_Softwood_Roof_Hollow"
    },
    {
      "x": 14,
      "y": -1,
      "z": 1,
      "name": "Rock_Stone_Cobble"
    },
    {
      "x": 14,
      "y": 0,
      "z": 1,
      "name": "Wood_Softwood_Beam"
    },
    {
      "x": 14,
      "y": 1,
      "z": 1,
      "name": "Wood_Softwood_Beam"
    },
    {
      "x": 14,
      "y": 2,
      "z": 1,
      "name": "*Wood_Softwood_Roof_State_Definitions_Corner_Left",
      "rotation": 1
    },
    {
      "x": 14,
      "y": 5,
      "z": 1,
      "name": "Wood_Softwood_Planks_Half",
      "rotation": 8
    },
    {
      "x": 14,
      "y": 6,
      "z": 1,
      "name": "Wood_Softwood_Roof",
      "rotation": 1
    },
    {
      "x": 14,
      "y": -1,
      "z": 2,
      "name": "Rock_Stone_Cobble"
    },
    {
      "x": 14,
      "y": 0,
      "z": 2,
      "name": "Rock_Stone_Brick"
    },
    {
      "x": 14,
      "y": 1,
      "z": 2,
      "name": "*Wood_Village_Wall_Full_State_Definitions_Bottom"
    },
    {
      "x": 14,
      "y": 2,
      "z": 2,
      "name": "*Wood_Village_Wall_Full_State_Definitions_Top"
    },
    {
      "x": 14,
      "y": 3,
      "z": 2,
      "name": "Wood_Beech_Trunk",
      "support": 15,
      "rotation": 5
    },
    {
      "x": 14,
      "y": 4,
      "z": 2,
      "name": "*Wood_Village_Wall_Full_State_Definitions_Bottom"
    },
    {
      "x": 14,
      "y": 5,
      "z": 2,
      "name": "*Wood_Village_Wall_Full_State_Definitions_Top"
    },
    {
      "x": 14,
      "y": 6,
      "z": 2,
      "name": "Wood_Softwood_Roof",
      "rotation": 1
    },
    {
      "x": 14,
      "y": -1,
      "z": 3,
      "name": "Wood_Drywood_Planks"
    },
    {
      "x": 14,
      "y": 5,
      "z": 3,
      "name": "Wood_Softwood_Stairs",
      "rotation": 9
    },
    {
      "x": 14,
      "y": 6,
      "z": 3,
      "name": "Wood_Softwood_Roof",
      "rotation": 1
    },
    {
      "x": 14,
      "y": -1,
      "z": 4,
      "name": "Wood_Drywood_Planks"
    },
    {
      "x": 14,
      "y": 5,
      "z": 4,
      "name": "Wood_Softwood_Stairs",
      "rotation": 9
    },
    {
      "x": 14,
      "y": 6,
      "z": 4,
      "name": "Wood_Softwood_Roof",
      "rotation": 1
    },
    {
      "x": 14,
      "y": -1,
      "z": 5,
      "name": "Wood_Drywood_Planks"
    },
    {
      "x": 14,
      "y": 5,
      "z": 5,
      "name": "Wood_Softwood_Stairs",
      "rotation": 9
    },
    {
      "x": 14,
      "y": 6,
      "z": 5,
      "name": "Wood_Softwood_Roof",
      "rotation": 1
    },
    {
      "x": 14,
      "y": -1,
      "z": 6,
      "name": "Wood_Drywood_Planks"
    },
    {
      "x": 14,
      "y": 5,
      "z": 6,
      "name": "Wood_Softwood_Stairs",
      "rotation": 9
    },
    {
      "x": 14,
      "y": 6,
      "z": 6,
      "name": "Wood_Softwood_Roof",
      "rotation": 1
    },
    {
      "x": 14,
      "y": -1,
      "z": 7,
      "name": "Wood_Drywood_Planks"
    },
    {
      "x": 14,
      "y": 5,
      "z": 7,
      "name": "Wood_Softwood_Stairs",
      "rotation": 9
    },
    {
      "x": 14,
      "y": 6,
      "z": 7,
      "name": "Wood_Softwood_Roof",
      "rotation": 1
    },
    {
      "x": 14,
      "y": -1,
      "z": 8,
      "name": "Wood_Drywood_Planks"
    },
    {
      "x": 14,
      "y": 0,
      "z": 8,
      "name": "Wood_Softwood_Planks_Half",
      "rotation": 8
    },
    {
      "x": 14,
      "y": 5,
      "z": 8,
      "name": "Wood_Softwood_Stairs",
      "rotation": 9
    },
    {
      "x": 14,
      "y": 6,
      "z": 8,
      "name": "Wood_Softwood_Roof",
      "rotation": 1
    },
    {
      "x": 14,
      "y": -1,
      "z": 9,
      "name": "Wood_Drywood_Planks"
    },
    {
      "x": 14,
      "y": 5,
      "z": 9,
      "name": "*Wood_Softwood_Stairs_State_Definitions_Inverted_Corner_Right",
      "rotation": 8
    },
    {
      "x": 14,
      "y": 6,
      "z": 9,
      "name": "*Wood_Softwood_Roof_State_Definitions_Corner_Left"
    },
    {
      "x": 14,
      "y": -1,
      "z": 10,
      "name": "Wood_Drywood_Planks"
    },
    {
      "x": 14,
      "y": 4,
      "z": 10,
      "name": "Wood_Softwood_Stairs",
      "rotation": 8
    },
    {
      "x": 14,
      "y": 5,
      "z": 10,
      "name": "Wood_Softwood_Roof"
    },
    {
      "x": 14,
      "y": -1,
      "z": 11,
      "name": "Rock_Stone_Cobble"
    },
    {
      "x": 14,
      "y": 0,
      "z": 11,
      "name": "Rock_Stone_Brick"
    },
    {
      "x": 14,
      "y": 1,
      "z": 11,
      "name": "Furniture_Village_Window"
    },
    {
      "x": 14,
      "y": 2,
      "z": 11,
      "name": "Furniture_Village_Window"
    },
    {
      "x": 14,
      "y": 3,
      "z": 11,
      "name": "Wood_Beech_Trunk",
      "support": 15,
      "rotation": 5
    },
    {
      "x": 14,
      "y": 4,
      "z": 11,
      "name": "Wood_Softwood_Roof"
    },
    {
      "x": 14,
      "y": -1,
      "z": 12,
      "name": "Rock_Stone_Cobble"
    },
    {
      "x": 14,
      "y": 3,
      "z": 12,
      "name": "Wood_Softwood_Roof_Hollow"
    },
    {
      "x": 15,
      "y": -1,
      "z": 1,
      "name": "Rock_Stone_Cobble"
    },
    {
      "x": 15,
      "y": 1,
      "z": 1,
      "name": "Plant_Vine_Wall",
      "support": 15,
      "rotation": 2
    },
    {
      "x": 15,
      "y": 2,
      "z": 1,
      "name": "Plant_Vine",
      "support": 15,
      "rotation": 2
    },
    {
      "x": 15,
      "y": 3,
      "z": 1,
      "name": "Wood_Beech_Branch_Short",
      "support": 15,
      "rotation": 2
    },
    {
      "x": 15,
      "y": 4,
      "z": 1,
      "name": "Wood_Softwood_Planks_Half",
      "rotation": 8
    },
    {
      "x": 15,
      "y": 5,
      "z": 1,
      "name": "Wood_Softwood_Roof",
      "rotation": 1
    },
    {
      "x": 15,
      "y": -1,
      "z": 2,
      "name": "Rock_Stone_Cobble"
    },
    {
      "x": 15,
      "y": 0,
      "z": 2,
      "name": "Rock_Stone_Brick"
    },
    {
      "x": 15,
      "y": 1,
      "z": 2,
      "name": "*Wood_Village_Wall_Full_State_Definitions_Bottom"
    },
    {
      "x": 15,
      "y": 2,
      "z": 2,
      "name": "*Wood_Village_Wall_Full_State_Definitions_Top"
    },
    {
      "x": 15,
      "y": 3,
      "z": 2,
      "name": "Wood_Beech_Trunk",
      "support": 15,
      "rotation": 5
    },
    {
      "x": 15,
      "y": 4,
      "z": 2,
      "name": "Wood_Village_Wall_Full"
    },
    {
      "x": 15,
      "y": 5,
      "z": 2,
      "name": "Wood_Softwood_Roof",
      "rotation": 1
    },
    {
      "x": 15,
      "y": -1,
      "z": 3,
      "name": "Wood_Drywood_Planks"
    },
    {
      "x": 15,
      "y": 4,
      "z": 3,
      "name": "Wood_Softwood_Stairs",
      "rotation": 9
    },
    {
      "x": 15,
      "y": 5,
      "z": 3,
      "name": "Wood_Softwood_Roof",
      "rotation": 1
    },
    {
      "x": 15,
      "y": -1,
      "z": 4,
      "name": "Rock_Stone_Brick_Smooth"
    },
    {
      "x": 15,
      "y": 0,
      "z": 4,
      "name": "Rock_Stone_Brick_Beam"
    },
    {
      "x": 15,
      "y": 1,
      "z": 4,
      "name": "Rock_Stone_Brick_Beam"
    },
    {
      "x": 15,
      "y": 2,
      "z": 4,
      "name": "Rock_Stone_Brick_Stairs",
      "rotation": 3
    },
    {
      "x": 15,
      "y": 4,
      "z": 4,
      "name": "Wood_Softwood_Stairs",
      "rotation": 9
    },
    {
      "x": 15,
      "y": 5,
      "z": 4,
      "name": "Wood_Softwood_Roof",
      "rotation": 1
    },
    {
      "x": 15,
      "y": -1,
      "z": 5,
      "name": "Rock_Stone_Brick_Smooth"
    },
    {
      "x": 15,
      "y": 0,
      "z": 5,
      "name": "Deco_Iron_Bars",
      "rotation": 1
    },
    {
      "x": 15,
      "y": 1,
      "z": 5,
      "name": "Deco_Iron_Bars",
      "rotation": 1
    },
    {
      "x": 15,
      "y": 2,
      "z": 5,
      "name": "Rock_Stone_Brick_Stairs",
      "rotation": 3
    },
    {
      "x": 15,
      "y": 4,
      "z": 5,
      "name": "Rock_Stone_Brick_Stairs",
      "rotation": 9
    },
    {
      "x": 15,
      "y": 5,
      "z": 5,
      "name": "Wood_Softwood_Roof",
      "rotation": 1
    },
    {
      "x": 15,
      "y": -1,
      "z": 6,
      "name": "Rock_Stone_Brick_Smooth"
    },
    {
      "x": 15,
      "y": 0,
      "z": 6,
      "name": "Rock_Stone_Brick_Beam"
    },
    {
      "x": 15,
      "y": 1,
      "z": 6,
      "name": "Rock_Stone_Brick_Beam"
    },
    {
      "x": 15,
      "y": 2,
      "z": 6,
      "name": "Rock_Stone_Brick_Stairs",
      "rotation": 3
    },
    {
      "x": 15,
      "y": 4,
      "z": 6,
      "name": "Wood_Softwood_Stairs",
      "rotation": 9
    },
    {
      "x": 15,
      "y": 5,
      "z": 6,
      "name": "Wood_Softwood_Roof",
      "rotation": 1
    },
    {
      "x": 15,
      "y": -1,
      "z": 7,
      "name": "Wood_Drywood_Planks"
    },
    {
      "x": 15,
      "y": 4,
      "z": 7,
      "name": "Wood_Softwood_Stairs",
      "rotation": 9
    },
    {
      "x": 15,
      "y": 5,
      "z": 7,
      "name": "Wood_Softwood_Roof",
      "rotation": 1
    },
    {
      "x": 15,
      "y": -1,
      "z": 8,
      "name": "Wood_Drywood_Planks"
    },
    {
      "x": 15,
      "y": 0,
      "z": 8,
      "name": "Wood_Softwood_Planks"
    },
    {
      "x": 15,
      "y": 1,
      "z": 8,
      "name": "Furniture_Crude_Candle",
      "support": 15
    },
    {
      "x": 15,
      "y": 4,
      "z": 8,
      "name": "Wood_Softwood_Stairs",
      "rotation": 9
    },
    {
      "x": 15,
      "y": 5,
      "z": 8,
      "name": "Wood_Softwood_Roof",
      "rotation": 1
    },
    {
      "x": 15,
      "y": -1,
      "z": 9,
      "name": "Wood_Drywood_Planks"
    },
    {
      "x": 15,
      "y": 0,
      "z": 9,
      "name": "Furniture_Village_Counter",
      "support": 15,
      "filler": 992,
      "rotation": 3
    },
    {
      "x": 15,
      "y": 4,
      "z": 9,
      "name": "Wood_Softwood_Stairs",
      "rotation": 9
    },
    {
      "x": 15,
      "y": 5,
      "z": 9,
      "name": "Wood_Softwood_Roof",
      "rotation": 1
    },
    {
      "x": 15,
      "y": -1,
      "z": 10,
      "name": "Wood_Drywood_Planks"
    },
    {
      "x": 15,
      "y": 0,
      "z": 10,
      "name": "Furniture_Village_Counter",
      "support": 15,
      "rotation": 3
    },
    {
      "x": 15,
      "y": 1,
      "z": 10,
      "name": "Aetherhaven_Management_Block",
      "components": {
        "Components": {
          "AetherhavenManagementBlock": {
            "PlotId": "",
            "TownId": ""
          }
        }
      },
      "rotation": 3
    },
    {
      "x": 15,
      "y": 4,
      "z": 10,
      "name": "*Wood_Softwood_Stairs_State_Definitions_Inverted_Corner_Left",
      "rotation": 9
    },
    {
      "x": 15,
      "y": 5,
      "z": 10,
      "name": "*Wood_Softwood_Roof_State_Definitions_Corner_Right",
      "rotation": 1
    },
    {
      "x": 15,
      "y": -1,
      "z": 11,
      "name": "Rock_Stone_Cobble"
    },
    {
      "x": 15,
      "y": 0,
      "z": 11,
      "name": "Rock_Stone_Brick"
    },
    {
      "x": 15,
      "y": 1,
      "z": 11,
      "name": "*Wood_Village_Wall_Full_State_Definitions_Bottom"
    },
    {
      "x": 15,
      "y": 2,
      "z": 11,
      "name": "*Wood_Village_Wall_Full_State_Definitions_Top"
    },
    {
      "x": 15,
      "y": 3,
      "z": 11,
      "name": "Wood_Beech_Trunk",
      "support": 15,
      "rotation": 5
    },
    {
      "x": 15,
      "y": 4,
      "z": 11,
      "name": "Wood_Softwood_Roof"
    },
    {
      "x": 15,
      "y": -1,
      "z": 12,
      "name": "Rock_Stone_Cobble"
    },
    {
      "x": 15,
      "y": 1,
      "z": 12,
      "name": "Plant_Vine_Wall",
      "support": 15
    },
    {
      "x": 15,
      "y": 2,
      "z": 12,
      "name": "Plant_Vine",
      "support": 15
    },
    {
      "x": 15,
      "y": 3,
      "z": 12,
      "name": "Wood_Softwood_Roof_Hollow"
    },
    {
      "x": 16,
      "y": -1,
      "z": 1,
      "name": "Rock_Stone_Cobble"
    },
    {
      "x": 16,
      "y": 3,
      "z": 1,
      "name": "Wood_Beech_Branch_Corner",
      "support": 15,
      "rotation": 2
    },
    {
      "x": 16,
      "y": 4,
      "z": 1,
      "name": "Wood_Softwood_Roof",
      "rotation": 1
    },
    {
      "x": 16,
      "y": -1,
      "z": 2,
      "name": "Rock_Stone_Cobble"
    },
    {
      "x": 16,
      "y": 0,
      "z": 2,
      "name": "Wood_Beech_Trunk",
      "support": 15
    },
    {
      "x": 16,
      "y": 1,
      "z": 2,
      "name": "Wood_Beech_Trunk",
      "support": 15
    },
    {
      "x": 16,
      "y": 2,
      "z": 2,
      "name": "Wood_Beech_Trunk",
      "support": 15
    },
    {
      "x": 16,
      "y": 3,
      "z": 2,
      "name": "Wood_Beech_Trunk",
      "support": 15
    },
    {
      "x": 16,
      "y": 4,
      "z": 2,
      "name": "Wood_Softwood_Roof",
      "rotation": 1
    },
    {
      "x": 16,
      "y": -1,
      "z": 3,
      "name": "Rock_Stone_Cobble"
    },
    {
      "x": 16,
      "y": 0,
      "z": 3,
      "name": "Rock_Stone_Brick"
    },
    {
      "x": 16,
      "y": 1,
      "z": 3,
      "name": "*Wood_Village_Wall_Full_State_Definitions_Bottom"
    },
    {
      "x": 16,
      "y": 2,
      "z": 3,
      "name": "*Wood_Village_Wall_Full_State_Definitions_Top"
    },
    {
      "x": 16,
      "y": 3,
      "z": 3,
      "name": "Wood_Beech_Trunk",
      "support": 15,
      "rotation": 4
    },
    {
      "x": 16,
      "y": 4,
      "z": 3,
      "name": "Wood_Softwood_Roof",
      "rotation": 1
    },
    {
      "x": 16,
      "y": -1,
      "z": 4,
      "name": "Rock_Stone_Cobble"
    },
    {
      "x": 16,
      "y": 0,
      "z": 4,
      "name": "Rock_Stone_Brick"
    },
    {
      "x": 16,
      "y": 1,
      "z": 4,
      "name": "Rock_Stone_Brick"
    },
    {
      "x": 16,
      "y": 2,
      "z": 4,
      "name": "Wood_Village_Wall_Full"
    },
    {
      "x": 16,
      "y": 3,
      "z": 4,
      "name": "Rock_Stone_Brick"
    },
    {
      "x": 16,
      "y": 4,
      "z": 4,
      "name": "Wood_Softwood_Roof",
      "rotation": 1
    },
    {
      "x": 16,
      "y": -1,
      "z": 5,
      "name": "Soil_Ash"
    },
    {
      "x": 16,
      "y": 0,
      "z": 5,
      "name": "Furniture_Crude_Brazier",
      "support": 15
    },
    {
      "x": 16,
      "y": 3,
      "z": 5,
      "name": "Rock_Stone_Brick"
    },
    {
      "x": 16,
      "y": 4,
      "z": 5,
      "name": "Rock_Stone_Brick"
    },
    {
      "x": 16,
      "y": 5,
      "z": 5,
      "name": "Rock_Stone_Brick"
    },
    {
      "x": 16,
      "y": 6,
      "z": 5,
      "name": "Rock_Stone_Brick"
    },
    {
      "x": 16,
      "y": 7,
      "z": 5,
      "name": "Furniture_Village_Planter",
      "support": 15
    },
    {
      "x": 16,
      "y": 8,
      "z": 5,
      "name": "Rock_Stone_Brick_Roof_Flat",
      "rotation": 1
    },
    {
      "x": 16,
      "y": -1,
      "z": 6,
      "name": "Rock_Stone_Cobble"
    },
    {
      "x": 16,
      "y": 0,
      "z": 6,
      "name": "Rock_Stone_Brick"
    },
    {
      "x": 16,
      "y": 1,
      "z": 6,
      "name": "Rock_Stone_Brick"
    },
    {
      "x": 16,
      "y": 2,
      "z": 6,
      "name": "Wood_Village_Wall_Full"
    },
    {
      "x": 16,
      "y": 3,
      "z": 6,
      "name": "Rock_Stone_Brick"
    },
    {
      "x": 16,
      "y": 4,
      "z": 6,
      "name": "Wood_Softwood_Roof",
      "rotation": 1
    },
    {
      "x": 16,
      "y": -1,
      "z": 7,
      "name": "Rock_Stone_Cobble"
    },
    {
      "x": 16,
      "y": 0,
      "z": 7,
      "name": "Rock_Stone_Brick"
    },
    {
      "x": 16,
      "y": 1,
      "z": 7,
      "name": "*Wood_Village_Wall_Full_State_Definitions_Bottom"
    },
    {
      "x": 16,
      "y": 2,
      "z": 7,
      "name": "*Wood_Village_Wall_Full_State_Definitions_Top"
    },
    {
      "x": 16,
      "y": 3,
      "z": 7,
      "name": "Wood_Beech_Trunk",
      "support": 15,
      "rotation": 4
    },
    {
      "x": 16,
      "y": 4,
      "z": 7,
      "name": "Wood_Softwood_Roof",
      "rotation": 1
    },
    {
      "x": 16,
      "y": -1,
      "z": 8,
      "name": "Rock_Stone_Cobble"
    },
    {
      "x": 16,
      "y": 0,
      "z": 8,
      "name": "Rock_Stone_Brick"
    },
    {
      "x": 16,
      "y": 1,
      "z": 8,
      "name": "Furniture_Village_Window",
      "rotation": 1
    },
    {
      "x": 16,
      "y": 2,
      "z": 8,
      "name": "Furniture_Village_Window",
      "rotation": 1
    },
    {
      "x": 16,
      "y": 3,
      "z": 8,
      "name": "Wood_Beech_Trunk",
      "support": 15,
      "rotation": 4
    },
    {
      "x": 16,
      "y": 4,
      "z": 8,
      "name": "Wood_Softwood_Roof",
      "rotation": 1
    },
    {
      "x": 16,
      "y": -1,
      "z": 9,
      "name": "Rock_Stone_Cobble"
    },
    {
      "x": 16,
      "y": 0,
      "z": 9,
      "name": "Rock_Stone_Brick"
    },
    {
      "x": 16,
      "y": 1,
      "z": 9,
      "name": "*Wood_Village_Wall_Full_State_Definitions_Bottom"
    },
    {
      "x": 16,
      "y": 2,
      "z": 9,
      "name": "*Wood_Village_Wall_Full_State_Definitions_Top"
    },
    {
      "x": 16,
      "y": 3,
      "z": 9,
      "name": "Wood_Beech_Trunk",
      "support": 15,
      "rotation": 4
    },
    {
      "x": 16,
      "y": 4,
      "z": 9,
      "name": "Wood_Softwood_Roof",
      "rotation": 1
    },
    {
      "x": 16,
      "y": -1,
      "z": 10,
      "name": "Rock_Stone_Cobble"
    },
    {
      "x": 16,
      "y": 0,
      "z": 10,
      "name": "Rock_Stone_Brick"
    },
    {
      "x": 16,
      "y": 1,
      "z": 10,
      "name": "*Wood_Village_Wall_Full_State_Definitions_Bottom"
    },
    {
      "x": 16,
      "y": 2,
      "z": 10,
      "name": "*Wood_Village_Wall_Full_State_Definitions_Top"
    },
    {
      "x": 16,
      "y": 3,
      "z": 10,
      "name": "Wood_Beech_Trunk",
      "support": 15,
      "rotation": 4
    },
    {
      "x": 16,
      "y": 4,
      "z": 10,
      "name": "Wood_Softwood_Roof",
      "rotation": 1
    },
    {
      "x": 16,
      "y": -1,
      "z": 11,
      "name": "Rock_Stone_Cobble"
    },
    {
      "x": 16,
      "y": 0,
      "z": 11,
      "name": "Wood_Beech_Trunk",
      "support": 15
    },
    {
      "x": 16,
      "y": 1,
      "z": 11,
      "name": "Wood_Beech_Trunk",
      "support": 15
    },
    {
      "x": 16,
      "y": 2,
      "z": 11,
      "name": "Wood_Beech_Trunk",
      "support": 15
    },
    {
      "x": 16,
      "y": 3,
      "z": 11,
      "name": "Wood_Beech_Trunk",
      "support": 15
    },
    {
      "x": 16,
      "y": 4,
      "z": 11,
      "name": "*Wood_Softwood_Roof_State_Definitions_Corner_Right",
      "rotation": 1
    },
    {
      "x": 16,
      "y": -1,
      "z": 12,
      "name": "Rock_Stone_Cobble"
    },
    {
      "x": 16,
      "y": 2,
      "z": 12,
      "name": "Wood_Beech_Branch_Corner",
      "support": 15
    },
    {
      "x": 16,
      "y": 3,
      "z": 12,
      "name": "Wood_Softwood_Roof"
    },
    {
      "x": 17,
      "y": -1,
      "z": 1,
      "name": "Rock_Stone_Cobble"
    },
    {
      "x": 17,
      "y": 3,
      "z": 1,
      "name": "Wood_Softwood_Roof_Hollow",
      "rotation": 1
    },
    {
      "x": 17,
      "y": -1,
      "z": 2,
      "name": "Rock_Stone_Cobble"
    },
    {
      "x": 17,
      "y": 2,
      "z": 2,
      "name": "Wood_Beech_Branch_Corner",
      "support": 15,
      "rotation": 1
    },
    {
      "x": 17,
      "y": 3,
      "z": 2,
      "name": "Wood_Softwood_Roof",
      "rotation": 1
    },
    {
      "x": 17,
      "y": -1,
      "z": 3,
      "name": "Rock_Stone_Cobble"
    },
    {
      "x": 17,
      "y": 1,
      "z": 3,
      "name": "Plant_Vine_Wall",
      "support": 15,
      "rotation": 1
    },
    {
      "x": 17,
      "y": 2,
      "z": 3,
      "name": "Plant_Vine",
      "support": 15,
      "rotation": 1
    },
    {
      "x": 17,
      "y": 3,
      "z": 3,
      "name": "Wood_Softwood_Roof_Hollow",
      "rotation": 1
    },
    {
      "x": 17,
      "y": -1,
      "z": 4,
      "name": "Rock_Stone_Cobble"
    },
    {
      "x": 17,
      "y": 0,
      "z": 4,
      "name": "Rock_Stone_Brick_Stairs",
      "rotation": 2
    },
    {
      "x": 17,
      "y": 1,
      "z": 4,
      "name": "Rock_Stone_Brick_Half",
      "rotation": 6
    },
    {
      "x": 17,
      "y": 2,
      "z": 4,
      "name": "Rock_Stone_Brick_Half",
      "rotation": 6
    },
    {
      "x": 17,
      "y": 3,
      "z": 4,
      "name": "Wood_Softwood_Roof_Hollow",
      "rotation": 1
    },
    {
      "x": 17,
      "y": -1,
      "z": 5,
      "name": "Rock_Stone_Cobble"
    },
    {
      "x": 17,
      "y": 0,
      "z": 5,
      "name": "Rock_Stone_Brick"
    },
    {
      "x": 17,
      "y": 1,
      "z": 5,
      "name": "Rock_Stone_Brick"
    },
    {
      "x": 17,
      "y": 2,
      "z": 5,
