{
  "version": 8,
  "blockIdVersion": 11,
  "anchorX": 0,
  "anchorY": 0,
  "anchorZ": 0,
  "blocks": [
    {
      "x": -4,
      "y": 4,
      "z": -2,
      "name": "Wood_Softwood_Roof_Hollow",
      "rotation": 3
    },
    {
      "x": -4,
      "y": 4,
      "z": -1,
      "name": "Wood_Softwood_Roof_Hollow",
      "rotation": 3
    },
    {
      "x": -4,
      "y": 4,
      "z": 0,
      "name": "Wood_Softwood_Roof_Hollow",
      "rotation": 3
    },
    {
      "x": -4,
      "y": 4,
      "z": 1,
      "name": "Wood_Softwood_Roof_Hollow",
      "rotation": 3
    },
    {
      "x": -4,
      "y": 4,
      "z": 2,
      "name": "Wood_Softwood_Roof_Hollow",
      "rotation": 3
    },
    {
      "x": -4,
      "y": 4,
      "z": 3,
      "name": "Wood_Softwood_Roof_Hollow",
      "rotation": 3
    },
    {
      "x": -4,
      "y": 4,
      "z": 4,
      "name": "Wood_Softwood_Roof_Hollow",
      "rotation": 3
    },
    {
      "x": -3,
      "y": 0,
      "z": -2,
      "name": "Wood_Ash_Trunk",
      "support": 15
    },
    {
      "x": -3,
      "y": 1,
      "z": -2,
      "name": "Wood_Ash_Trunk",
      "support": 15
    },
    {
      "x": -3,
      "y": 2,
      "z": -2,
      "name": "Wood_Ash_Trunk",
      "support": 15
    },
    {
      "x": -3,
      "y": 3,
      "z": -2,
      "name": "Wood_Ash_Trunk",
      "support": 15
    },
    {
      "x": -3,
      "y": 4,
      "z": -2,
      "name": "Wood_Ash_Trunk",
      "support": 15
    },
    {
      "x": -3,
      "y": 5,
      "z": -2,
      "name": "Wood_Softwood_Roof_Shallow",
      "rotation": 3
    },
    {
      "x": -3,
      "y": 0,
      "z": -1,
      "name": "Rock_Stone_Cobble"
    },
    {
      "x": -3,
      "y": 1,
      "z": -1,
      "name": "Rock_Stone_Cobble"
    },
    {
      "x": -3,
      "y": 2,
      "z": -1,
      "name": "Wood_Softwood_Planks"
    },
    {
      "x": -3,
      "y": 3,
      "z": -1,
      "name": "Wood_Softwood_Planks"
    },
    {
      "x": -3,
      "y": 4,
      "z": -1,
      "name": "Wood_Softwood_Planks"
    },
    {
      "x": -3,
      "y": 5,
      "z": -1,
      "name": "Wood_Softwood_Roof_Shallow",
      "rotation": 3
    },
    {
      "x": -3,
      "y": 0,
      "z": 0,
      "name": "Rock_Stone_Cobble"
    },
    {
      "x": -3,
      "y": 1,
      "z": 0,
      "name": "Rock_Stone_Cobble"
    },
    {
      "x": -3,
      "y": 2,
      "z": 0,
      "name": "Wood_Softwood_Planks"
    },
    {
      "x": -3,
      "y": 3,
      "z": 0,
      "name": "Wood_Softwood_Planks"
    },
    {
      "x": -3,
      "y": 4,
      "z": 0,
      "name": "Wood_Softwood_Planks"
    },
    {
      "x": -3,
      "y": 5,
      "z": 0,
      "name": "Wood_Softwood_Roof_Shallow",
      "rotation": 3
    },
    {
      "x": -3,
      "y": 0,
      "z": 1,
      "name": "Rock_Stone_Cobble"
    },
    {
      "x": -3,
      "y": 1,
      "z": 1,
      "name": "Rock_Stone_Cobble"
    },
    {
      "x": -3,
      "y": 2,
      "z": 1,
      "name": "Furniture_Village_Window",
      "rotation": 1
    },
    {
      "x": -3,
      "y": 3,
      "z": 1,
      "name": "Furniture_Village_Window",
      "rotation": 1
    },
    {
      "x": -3,
      "y": 4,
      "z": 1,
      "name": "Wood_Softwood_Planks"
    },
    {
      "x": -3,
      "y": 5,
      "z": 1,
      "name": "Wood_Softwood_Roof_Shallow",
      "rotation": 3
    },
    {
      "x": -3,
      "y": 0,
      "z": 2,
      "name": "Rock_Stone_Cobble"
    },
    {
      "x": -3,
      "y": 1,
      "z": 2,
      "name": "Rock_Stone_Cobble"
    },
    {
      "x": -3,
      "y": 2,
      "z": 2,
      "name": "Wood_Softwood_Planks"
    },
    {
      "x": -3,
      "y": 3,
      "z": 2,
      "name": "Wood_Softwood_Planks"
    },
    {
      "x": -3,
      "y": 4,
      "z": 2,
      "name": "Wood_Softwood_Planks"
    },
    {
      "x": -3,
      "y": 5,
      "z": 2,
      "name": "Wood_Softwood_Roof_Shallow",
      "rotation": 3
    },
    {
      "x": -3,
      "y": 0,
      "z": 3,
      "name": "Rock_Stone_Cobble"
    },
    {
      "x": -3,
      "y": 1,
      "z": 3,
      "name": "Rock_Stone_Cobble"
    },
    {
      "x": -3,
      "y": 2,
      "z": 3,
      "name": "Wood_Softwood_Planks"
    },
    {
      "x": -3,
      "y": 3,
      "z": 3,
      "name": "Wood_Softwood_Planks"
    },
    {
      "x": -3,
      "y": 4,
      "z": 3,
      "name": "Wood_Softwood_Planks"
    },
    {
      "x": -3,
      "y": 5,
      "z": 3,
      "name": "Wood_Softwood_Roof_Shallow",
      "rotation": 3
    },
    {
      "x": -3,
      "y": 0,
      "z": 4,
      "name": "Wood_Ash_Trunk",
      "support": 15
    },
    {
      "x": -3,
      "y": 1,
      "z": 4,
      "name": "Wood_Ash_Trunk",
      "support": 15
    },
    {
      "x": -3,
      "y": 2,
      "z": 4,
      "name": "Wood_Ash_Trunk",
      "support": 15
    },
    {
      "x": -3,
      "y": 3,
      "z": 4,
      "name": "Wood_Ash_Trunk",
      "support": 15
    },
    {
      "x": -3,
      "y": 4,
      "z": 4,
      "name": "Wood_Ash_Trunk",
      "support": 15
    },
    {
      "x": -3,
      "y": 5,
      "z": 4,
      "name": "Wood_Softwood_Roof_Shallow",
      "rotation": 3
    },
    {
      "x": -2,
      "y": 0,
      "z": -2,
      "name": "Rock_Stone_Cobble"
    },
    {
      "x": -2,
      "y": 1,
      "z": -2,
      "name": "Rock_Stone_Cobble"
    },
    {
      "x": -2,
      "y": 2,
      "z": -2,
      "name": "Wood_Softwood_Planks"
    },
    {
      "x": -2,
      "y": 3,
      "z": -2,
      "name": "Wood_Softwood_Planks"
    },
    {
      "x": -2,
      "y": 4,
      "z": -2,
      "name": "Wood_Softwood_Planks"
    },
    {
      "x": -2,
      "y": 5,
      "z": -2,
      "name": "Wood_Softwood_Roof_Shallow",
      "filler": 1,
      "rotation": 3
    },
    {
      "x": -2,
      "y": 0,
      "z": -1,
      "name": "Wood_Softwood_Planks"
    },
    {
      "x": -2,
      "y": 4,
      "z": -1,
      "name": "Wood_Softwood_Planks"
    },
    {
      "x": -2,
      "y": 5,
      "z": -1,
      "name": "Wood_Softwood_Roof_Shallow",
      "filler": 1,
      "rotation": 3
    },
    {
      "x": -2,
      "y": 0,
      "z": 0,
      "name": "Wood_Softwood_Planks"
    },
    {
      "x": -2,
      "y": 1,
      "z": 0,
      "name": "Bench_Campfire",
      "components": {
        "Components": {
          "BenchBlock": {
            "TierLevel": 1,
            "UpgradeItems": []
          },
          "ProcessingBenchBlock": {
            "InputContainer": {
              "Id": "Simple",
              "Capacity": 2,
              "Items": {}
            },
            "FuelContainer": {
              "Id": "Simple",
              "Capacity": 1,
              "Items": {}
            },
            "OutputContainer": {
              "Id": "Simple",
              "Capacity": 4,
              "Items": {}
            },
            "Progress": 0.0,
            "FuelTime": 0.0,
            "Active": false,
            "NextExtra": 2,
            "LastTickGameTime": "0001-01-04T18:53:50.014969393Z"
          },
          "PlacedByInteraction": {
            "WhoPlacedUuid": {
              "$binary": "v7RyWIT/TYKnXA2XcxdQtw==",
              "$type": "04"
            }
          }
        }
      },
      "rotation": 1
    },
    {
      "x": -2,
      "y": 4,
      "z": 0,
      "name": "Wood_Softwood_Planks"
    },
    {
      "x": -2,
      "y": 5,
      "z": 0,
      "name": "Wood_Softwood_Roof_Shallow",
      "filler": 1,
      "rotation": 3
    },
    {
      "x": -2,
      "y": 0,
      "z": 1,
      "name": "Wood_Softwood_Planks"
    },
    {
      "x": -2,
      "y": 1,
      "z": 1,
      "name": "Furniture_Village_Bed",
      "filler": 991,
      "rotation": 2
    },
    {
      "x": -2,
      "y": 2,
      "z": 1,
      "name": "Furniture_Village_Bed",
      "filler": 2015,
      "rotation": 2
    },
    {
      "x": -2,
      "y": 4,
      "z": 1,
      "name": "Wood_Softwood_Planks"
    },
    {
      "x": -2,
      "y": 5,
      "z": 1,
      "name": "Wood_Softwood_Roof_Shallow",
      "filler": 1,
      "rotation": 3
    },
    {
      "x": -2,
      "y": 0,
      "z": 2,
      "name": "Wood_Softwood_Planks"
    },
    {
      "x": -2,
      "y": 1,
      "z": 2,
      "name": "Furniture_Village_Bed",
      "filler": 1023,
      "rotation": 2
    },
    {
      "x": -2,
      "y": 2,
      "z": 2,
      "name": "Furniture_Village_Bed",
      "filler": 2047,
      "rotation": 2
    },
    {
      "x": -2,
      "y": 3,
      "z": 2,
      "name": "Wood_Torch_Wall",
      "rotation": 1
    },
    {
      "x": -2,
      "y": 4,
      "z": 2,
      "name": "Wood_Softwood_Planks"
    },
    {
      "x": -2,
      "y": 5,
      "z": 2,
      "name": "Wood_Softwood_Roof_Shallow",
      "filler": 1,
      "rotation": 3
    },
    {
      "x": -2,
      "y": 0,
      "z": 3,
      "name": "Wood_Softwood_Planks"
    },
    {
      "x": -2,
      "y": 1,
      "z": 3,
      "name": "Furniture_Village_Bed",
      "filler": 31,
      "rotation": 2
    },
    {
      "x": -2,
      "y": 2,
      "z": 3,
      "name": "Furniture_Village_Bed",
      "filler": 1055,
      "rotation": 2
    },
    {
      "x": -2,
      "y": 4,
      "z": 3,
      "name": "Wood_Softwood_Planks"
    },
    {
      "x": -2,
      "y": 5,
      "z": 3,
      "name": "Wood_Softwood_Roof_Shallow",
      "filler": 1,
      "rotation": 3
    },
    {
      "x": -2,
      "y": 0,
      "z": 4,
      "name": "Rock_Stone_Cobble"
    },
    {
      "x": -2,
      "y": 1,
      "z": 4,
      "name": "Rock_Stone_Cobble"
    },
    {
      "x": -2,
      "y": 2,
      "z": 4,
      "name": "Wood_Softwood_Planks"
    },
    {
      "x": -2,
      "y": 3,
      "z": 4,
      "name": "Wood_Softwood_Planks"
    },
    {
      "x": -2,
      "y": 4,
      "z": 4,
      "name": "Wood_Softwood_Planks"
    },
    {
      "x": -2,
      "y": 5,
      "z": 4,
      "name": "Wood_Softwood_Roof_Shallow",
      "filler": 1,
      "rotation": 3
    },
    {
      "x": -1,
      "y": 0,
      "z": -2,
      "name": "Rock_Stone_Cobble"
    },
    {
      "x": -1,
      "y": 1,
      "z": -2,
      "name": "Rock_Stone_Cobble"
    },
    {
      "x": -1,
      "y": 2,
      "z": -2,
      "name": "Wood_Softwood_Planks"
    },
    {
      "x": -1,
      "y": 3,
      "z": -2,
      "name": "Wood_Softwood_Planks"
    },
    {
      "x": -1,
      "y": 4,
      "z": -2,
      "name": "Wood_Softwood_Planks"
    },
    {
      "x": -1,
      "y": 5,
      "z": -2,
      "name": "Wood_Softwood_Planks"
    },
    {
      "x": -1,
      "y": 6,
      "z": -2,
      "name": "Wood_Softwood_Roof",
      "rotation": 3
    },
    {
      "x": -1,
      "y": 0,
      "z": -1,
      "name": "Wood_Softwood_Planks"
    },
    {
      "x": -1,
      "y": 4,
      "z": -1,
      "name": "Wood_Softwood_Planks"
    },
    {
      "x": -1,
      "y": 5,
      "z": -1,
      "name": "Wood_Softwood_Planks"
    },
    {
      "x": -1,
      "y": 6,
      "z": -1,
      "name": "Wood_Softwood_Roof",
      "rotation": 3
    },
    {
      "x": -1,
      "y": 0,
      "z": 0,
      "name": "Wood_Softwood_Planks"
    },
    {
      "x": -1,
      "y": 4,
      "z": 0,
      "name": "Wood_Softwood_Planks"
    },
    {
      "x": -1,
      "y": 5,
      "z": 0,
      "name": "Wood_Softwood_Planks"
    },
    {
      "x": -1,
      "y": 6,
      "z": 0,
      "name": "Wood_Softwood_Roof",
      "rotation": 3
    },
    {
      "x": -1,
      "y": 0,
      "z": 1,
      "name": "Wood_Softwood_Planks"
    },
    {
      "x": -1,
      "y": 1,
      "z": 1,
      "name": "Furniture_Village_Bed",
      "filler": 960,
      "rotation": 2
    },
    {
      "x": -1,
      "y": 2,
      "z": 1,
      "name": "Furniture_Village_Bed",
      "filler": 1984,
      "rotation": 2
    },
    {
      "x": -1,
      "y": 4,
      "z": 1,
      "name": "Wood_Softwood_Planks"
    },
    {
      "x": -1,
      "y": 5,
      "z": 1,
      "name": "Wood_Softwood_Planks"
    },
    {
      "x": -1,
      "y": 6,
      "z": 1,
      "name": "Wood_Softwood_Roof",
      "rotation": 3
    },
    {
      "x": -1,
      "y": 0,
      "z": 2,
      "name": "Wood_Softwood_Planks"
    },
    {
      "x": -1,
      "y": 1,
      "z": 2,
      "name": "Furniture_Village_Bed",
      "filler": 992,
      "rotation": 2
    },
    {
      "x": -1,
      "y": 2,
      "z": 2,
      "name": "Furniture_Village_Bed",
      "filler": 2016,
      "rotation": 2
    },
    {
      "x": -1,
      "y": 4,
      "z": 2,
      "name": "Wood_Softwood_Planks"
    },
    {
      "x": -1,
      "y": 5,
      "z": 2,
      "name": "Wood_Softwood_Planks"
    },
    {
      "x": -1,
      "y": 6,
      "z": 2,
      "name": "Wood_Softwood_Roof",
      "rotation": 3
    },
    {
      "x": -1,
      "y": 0,
      "z": 3,
      "name": "Wood_Softwood_Planks"
    },
    {
      "x": -1,
      "y": 1,
      "z": 3,
      "name": "Furniture_Village_Bed",
      "components": {
        "Components": {
          "PlacedByInteraction": {
            "WhoPlacedUuid": {
              "$binary": "v7RyWIT/TYKnXA2XcxdQtw==",
              "$type": "04"
            }
          },
          "RespawnBlock": {}
        }
      },
      "rotation": 2
    },
    {
      "x": -1,
      "y": 2,
      "z": 3,
      "name": "Furniture_Village_Bed",
      "filler": 1024,
      "rotation": 2
    },
    {
      "x": -1,
      "y": 4,
      "z": 3,
      "name": "Wood_Softwood_Planks"
    },
    {
      "x": -1,
      "y": 5,
      "z": 3,
      "name": "Wood_Softwood_Planks"
    },
    {
      "x": -1,
      "y": 6,
      "z": 3,
      "name": "Wood_Softwood_Roof",
      "rotation": 3
    },
    {
      "x": -1,
      "y": 0,
      "z": 4,
      "name": "Rock_Stone_Cobble"
    },
    {
      "x": -1,
      "y": 1,
      "z": 4,
      "name": "Rock_Stone_Cobble"
    },
    {
      "x": -1,
      "y": 2,
      "z": 4,
      "name": "Wood_Softwood_Planks"
    },
    {
      "x": -1,
      "y": 3,
      "z": 4,
      "name": "Wood_Softwood_Planks"
    },
    {
      "x": -1,
      "y": 4,
      "z": 4,
      "name": "Wood_Softwood_Planks"
    },
    {
      "x": -1,
      "y": 5,
      "z": 4,
      "name": "Wood_Softwood_Planks"
    },
    {
      "x": -1,
      "y": 6,
      "z": 4,
      "name": "Wood_Softwood_Roof",
      "rotation": 3
    },
    {
      "x": 0,
      "y": 0,
      "z": -3,
      "name": "Rock_Stone_Cobble_Stairs",
      "rotation": 2
    },
    {
      "x": 0,
      "y": 0,
      "z": -2,
      "name": "Wood_Softwood_Planks"
    },
    {
      "x": 0,
      "y": 1,
      "z": -2,
      "name": "*Furniture_Village_Door_State_Definitions_CloseDoorIn",
      "rotation": 2
    },
    {
      "x": 0,
      "y": 2,
      "z": -2,
      "name": "*Furniture_Village_Door_State_Definitions_CloseDoorIn",
      "filler": 1024,
      "rotation": 2
    },
    {
      "x": 0,
      "y": 3,
      "z": -2,
      "name": "Wood_Softwood_Planks"
    },
    {
      "x": 0,
      "y": 4,
      "z": -2,
      "name": "Wood_Softwood_Planks"
    },
    {
      "x": 0,
      "y": 5,
      "z": -2,
      "name": "Wood_Softwood_Planks"
    },
    {
      "x": 0,
      "y": 6,
      "z": -2,
      "name": "Wood_Softwood_Planks"
    },
    {
      "x": 0,
      "y": 7,
      "z": -2,
      "name": "Wood_Softwood_Roof_Flat",
      "rotation": 2
    },
    {
      "x": 0,
      "y": 0,
      "z": -1,
      "name": "Wood_Softwood_Planks"
    },
    {
      "x": 0,
      "y": 4,
      "z": -1,
      "name": "Wood_Softwood_Planks"
    },
    {
      "x": 0,
      "y": 6,
      "z": -1,
      "name": "Wood_Softwood_Planks"
    },
    {
      "x": 0,
      "y": 7,
      "z": -1,
      "name": "Wood_Softwood_Roof_Flat",
      "rotation": 1
    },
    {
      "x": 0,
      "y": 0,
      "z": 0,
      "name": "Wood_Softwood_Planks"
    },
    {
      "x": 0,
      "y": 4,
      "z": 0,
      "name": "Wood_Softwood_Planks"
    },
    {
      "x": 0,
      "y": 6,
      "z": 0,
      "name": "Wood_Softwood_Planks"
    },
    {
      "x": 0,
      "y": 7,
      "z": 0,
      "name": "Wood_Softwood_Roof_Flat",
      "rotation": 1
    },
    {
      "x": 0,
      "y": 0,
      "z": 1,
      "name": "Wood_Softwood_Planks"
    },
    {
      "x": 0,
      "y": 4,
      "z": 1,
      "name": "Wood_Softwood_Planks"
    },
    {
      "x": 0,
      "y": 6,
      "z": 1,
      "name": "Wood_Softwood_Planks"
    },
    {
      "x": 0,
      "y": 7,
      "z": 1,
      "name": "Wood_Softwood_Roof_Flat",
      "rotation": 1
    },
    {
      "x": 0,
      "y": 0,
      "z": 2,
      "name": "Wood_Softwood_Planks"
    },
    {
      "x": 0,
      "y": 4,
      "z": 2,
      "name": "Wood_Softwood_Planks"
    },
    {
      "x": 0,
      "y": 6,
      "z": 2,
      "name": "Wood_Softwood_Planks"
    },
    {
      "x": 0,
      "y": 7,
      "z": 2,
      "name": "Wood_Softwood_Roof_Flat",
      "rotation": 1
    },
    {
      "x": 0,
      "y": 0,
      "z": 3,
      "name": "Wood_Softwood_Planks"
    },
    {
      "x": 0,
      "y": 4,
      "z": 3,
      "name": "Wood_Softwood_Planks"
    },
    {
      "x": 0,
      "y": 6,
      "z": 3,
      "name": "Wood_Softwood_Planks"
    },
    {
      "x": 0,
      "y": 7,
      "z": 3,
      "name": "Wood_Softwood_Roof_Flat",
      "rotation": 1
    },
    {
      "x": 0,
      "y": 0,
      "z": 4,
      "name": "Rock_Stone_Cobble"
    },
    {
      "x": 0,
      "y": 1,
      "z": 4,
      "name": "Rock_Stone_Cobble"
    },
    {
      "x": 0,
      "y": 2,
      "z": 4,
      "name": "Furniture_Village_Window"
    },
    {
      "x": 0,
      "y": 3,
      "z": 4,
      "name": "Furniture_Village_Window"
    },
    {
      "x": 0,
      "y": 4,
      "z": 4,
      "name": "Wood_Softwood_Planks"
    },
    {
      "x": 0,
      "y": 5,
      "z": 4,
      "name": "Wood_Softwood_Planks"
    },
    {
      "x": 0,
      "y": 6,
      "z": 4,
      "name": "Wood_Softwood_Planks"
    },
    {
      "x": 0,
      "y": 7,
      "z": 4,
      "name": "Wood_Softwood_Roof_Flat",
      "rotation": 1
    },
    {
      "x": 1,
      "y": 0,
      "z": -2,
      "name": "Rock_Stone_Cobble"
    },
    {
      "x": 1,
      "y": 1,
      "z": -2,
      "name": "Rock_Stone_Cobble"
    },
    {
      "x": 1,
      "y": 2,
      "z": -2,
      "name": "Wood_Softwood_Planks"
    },
    {
      "x": 1,
      "y": 3,
      "z": -2,
      "name": "Wood_Softwood_Planks"
    },
    {
      "x": 1,
      "y": 4,
      "z": -2,
      "name": "Wood_Softwood_Planks"
    },
    {
      "x": 1,
      "y": 5,
      "z": -2,
      "name": "Wood_Softwood_Planks"
    },
    {
      "x": 1,
      "y": 6,
      "z": -2,
      "name": "Wood_Softwood_Roof",
      "rotation": 1
    },
    {
      "x": 1,
      "y": 0,
      "z": -1,
      "name": "Wood_Softwood_Planks"
    },
    {
      "x": 1,
      "y": 4,
      "z": -1,
      "name": "Wood_Softwood_Planks"
    },
    {
      "x": 1,
      "y": 5,
      "z": -1,
      "name": "Wood_Softwood_Planks"
    },
    {
      "x": 1,
      "y": 6,
      "z": -1,
      "name": "Wood_Softwood_Roof",
      "rotation": 1
    },
    {
      "x": 1,
      "y": 0,
      "z": 0,
      "name": "Wood_Softwood_Planks"
    },
    {
      "x": 1,
      "y": 4,
      "z": 0,
      "name": "Wood_Softwood_Planks"
    },
    {
      "x": 1,
      "y": 5,
      "z": 0,
      "name": "Wood_Softwood_Planks"
    },
    {
      "x": 1,
      "y": 6,
      "z": 0,
      "name": "Wood_Softwood_Roof",
      "rotation": 1
    },
    {
      "x": 1,
      "y": 0,
      "z": 1,
      "name": "Wood_Softwood_Planks"
    },
    {
      "x": 1,
      "y": 4,
      "z": 1,
      "name": "Wood_Softwood_Planks"
    },
    {
      "x": 1,
      "y": 5,
      "z": 1,
      "name": "Wood_Softwood_Planks"
    },
    {
      "x": 1,
      "y": 6,
      "z": 1,
      "name": "Wood_Softwood_Roof",
      "rotation": 1
    },
    {
      "x": 1,
      "y": 0,
      "z": 2,
      "name": "Wood_Softwood_Planks"
    },
    {
      "x": 1,
      "y": 4,
      "z": 2,
      "name": "Wood_Softwood_Planks"
    },
    {
      "x": 1,
      "y": 5,
      "z": 2,
      "name": "Wood_Softwood_Planks"
    },
    {
      "x": 1,
      "y": 6,
      "z": 2,
      "name": "Wood_Softwood_Roof",
      "rotation": 1
    },
    {
      "x": 1,
      "y": 0,
      "z": 3,
      "name": "Wood_Softwood_Planks"
    },
    {
      "x": 1,
      "y": 2,
      "z": 3,
      "name": "Aetherhaven_Management_Block",
      "rotation": 2
    },
    {
      "x": 1,
      "y": 4,
      "z": 3,
      "name": "Wood_Softwood_Planks"
    },
    {
      "x": 1,
      "y": 5,
      "z": 3,
      "name": "Wood_Softwood_Planks"
    },
    {
      "x": 1,
      "y": 6,
      "z": 3,
      "name": "Wood_Softwood_Roof",
      "rotation": 1
    },
    {
      "x": 1,
      "y": 0,
      "z": 4,
      "name": "Rock_Stone_Cobble"
    },
    {
      "x": 1,
      "y": 1,
      "z": 4,
      "name": "Rock_Stone_Cobble"
    },
    {
      "x": 1,
      "y": 2,
      "z": 4,
      "name": "Wood_Softwood_Planks"
    },
    {
      "x": 1,
      "y": 3,
      "z": 4,
      "name": "Wood_Softwood_Planks"
    },
    {
      "x": 1,
      "y": 4,
      "z": 4,
      "name": "Wood_Softwood_Planks"
    },
    {
      "x": 1,
      "y": 5,
      "z": 4,
      "name": "Wood_Softwood_Planks"
    },
    {
      "x": 1,
      "y": 6,
      "z": 4,
      "name": "Wood_Softwood_Roof",
      "rotation": 1
    },
    {
      "x": 2,
      "y": 0,
      "z": -2,
      "name": "Rock_Stone_Cobble"
    },
    {
      "x": 2,
      "y": 1,
      "z": -2,
      "name": "Rock_Stone_Cobble"
    },
    {
      "x": 2,
      "y": 2,
      "z": -2,
      "name": "Wood_Softwood_Planks"
    },
    {
      "x": 2,
      "y": 3,
      "z": -2,
      "name": "Wood_Softwood_Planks"
    },
    {
      "x": 2,
      "y": 4,
      "z": -2,
      "name": "Wood_Softwood_Planks"
    },
    {
      "x": 2,
      "y": 5,
      "z": -2,
      "name": "Wood_Softwood_Roof_Shallow",
      "filler": 31,
      "rotation": 1
    },
    {
      "x": 2,
      "y": 0,
      "z": -1,
      "name": "Wood_Softwood_Planks"
    },
    {
      "x": 2,
      "y": 4,
      "z": -1,
      "name": "Wood_Softwood_Planks"
    },
    {
      "x": 2,
      "y": 5,
      "z": -1,
      "name": "Wood_Softwood_Roof_Shallow",
      "filler": 31,
      "rotation": 1
    },
    {
      "x": 2,
      "y": 0,
      "z": 0,
      "name": "Wood_Softwood_Planks"
    },
    {
      "x": 2,
      "y": 1,
      "z": 0,
      "name": "Furniture_Village_Chair",
      "components": {
        "Components": {}
      },
      "rotation": 3
    },
    {
      "x": 2,
      "y": 2,
      "z": 0,
      "name": "Furniture_Village_Chair",
      "filler": 1024,
      "rotation": 3
    },
    {
      "x": 2,
      "y": 4,
      "z": 0,
      "name": "Wood_Softwood_Planks"
    },
    {
      "x": 2,
      "y": 5,
      "z": 0,
      "name": "Wood_Softwood_Roof_Shallow",
      "filler": 31,
      "rotation": 1
    },
    {
      "x": 2,
      "y": 0,
      "z": 1,
      "name": "Wood_Softwood_Planks"
    },
    {
      "x": 2,
      "y": 4,
      "z": 1,
      "name": "Wood_Softwood_Planks"
    },
    {
      "x": 2,
      "y": 5,
      "z": 1,
      "name": "Wood_Softwood_Roof_Shallow",
      "filler": 31,
      "rotation": 1
    },
    {
      "x": 2,
      "y": 0,
      "z": 2,
      "name": "Wood_Softwood_Planks"
    },
    {
      "x": 2,
      "y": 3,
      "z": 2,
      "name": "Wood_Torch_Wall",
      "rotation": 3
    },
    {
      "x": 2,
      "y": 4,
      "z": 2,
      "name": "Wood_Softwood_Planks"
    },
    {
      "x": 2,
      "y": 5,
      "z": 2,
      "name": "Wood_Softwood_Roof_Shallow",
      "filler": 31,
      "rotation": 1
    },
    {
      "x": 2,
      "y": 0,
      "z": 3,
      "name": "Wood_Softwood_Planks"
    },
    {
      "x": 2,
      "y": 4,
      "z": 3,
      "name": "Wood_Softwood_Planks"
    },
    {
      "x": 2,
      "y": 5,
      "z": 3,
      "name": "Wood_Softwood_Roof_Shallow",
      "filler": 31,
      "rotation": 1
    },
    {
      "x": 2,
      "y": 0,
      "z": 4,
      "name": "Rock_Stone_Cobble"
    },
    {
      "x": 2,
      "y": 1,
      "z": 4,
      "name": "Rock_Stone_Cobble"
    },
    {
      "x": 2,
      "y": 2,
      "z": 4,
      "name": "Wood_Softwood_Planks"
    },
    {
      "x": 2,
      "y": 3,
      "z": 4,
      "name": "Wood_Softwood_Planks"
    },
    {
      "x": 2,
      "y": 4,
      "z": 4,
      "name": "Wood_Softwood_Planks"
    },
    {
      "x": 2,
      "y": 5,
      "z": 4,
      "name": "Wood_Softwood_Roof_Shallow",
      "filler": 31,
      "rotation": 1
    },
    {
      "x": 3,
      "y": 0,
      "z": -2,
      "name": "Wood_Ash_Trunk",
      "support": 15
    },
    {
      "x": 3,
      "y": 1,
      "z": -2,
      "name": "Wood_Ash_Trunk",
      "support": 15
    },
    {
      "x": 3,
      "y": 2,
      "z": -2,
      "name": "Wood_Ash_Trunk",
      "support": 15
    },
    {
      "x": 3,
      "y": 3,
      "z": -2,
      "name": "Wood_Ash_Trunk",
      "support": 15
    },
    {
      "x": 3,
      "y": 4,
      "z": -2,
      "name": "Wood_Ash_Trunk",
      "support": 15
    },
    {
      "x": 3,
      "y": 5,
      "z": -2,
      "name": "Wood_Softwood_Roof_Shallow",
      "rotation": 1
    },
    {
      "x": 3,
      "y": 0,
      "z": -1,
      "name": "Rock_Stone_Cobble"
    },
    {
      "x": 3,
      "y": 1,
      "z": -1,
      "name": "Rock_Stone_Cobble"
    },
    {
      "x": 3,
      "y": 2,
      "z": -1,
      "name": "Wood_Softwood_Planks"
    },
    {
      "x": 3,
      "y": 3,
      "z": -1,
      "name": "Wood_Softwood_Planks"
    },
    {
      "x": 3,
      "y": 4,
      "z": -1,
      "name": "Wood_Softwood_Planks"
    },
    {
      "x": 3,
      "y": 5,
      "z": -1,
      "name": "Wood_Softwood_Roof_Shallow",
      "rotation": 1
    },
    {
      "x": 3,
      "y": 0,
      "z": 0,
      "name": "Rock_Stone_Cobble"
    },
    {
      "x": 3,
      "y": 1,
      "z": 0,
      "name": "Rock_Stone_Cobble"
    },
    {
      "x": 3,
      "y": 2,
      "z": 0,
      "name": "Wood_Softwood_Planks"
    },
    {
      "x": 3,
      "y": 3,
      "z": 0,
      "name": "Wood_Softwood_Planks"
    },
    {
      "x": 3,
      "y": 4,
      "z": 0,
      "name": "Wood_Softwood_Planks"
    },
    {
      "x": 3,
      "y": 5,
      "z": 0,
      "name": "Wood_Softwood_Roof_Shallow",
      "rotation": 1
    },
    {
      "x": 3,
      "y": 0,
      "z": 1,
      "name": "Rock_Stone_Cobble"
    },
    {
      "x": 3,
      "y": 1,
      "z": 1,
      "name": "Rock_Stone_Cobble"
    },
    {
      "x": 3,
      "y": 2,
      "z": 1,
      "name": "Furniture_Village_Window",
      "rotation": 1
    },
    {
      "x": 3,
      "y": 3,
      "z": 1,
      "name": "Furniture_Village_Window",
      "rotation": 1
    },
    {
      "x": 3,
      "y": 4,
      "z": 1,
      "name": "Wood_Softwood_Planks"
    },
    {
      "x": 3,
      "y": 5,
      "z": 1,
      "name": "Wood_Softwood_Roof_Shallow",
      "rotation": 1
    },
    {
      "x": 3,
      "y": 0,
      "z": 2,
      "name": "Rock_Stone_Cobble"
    },
    {
      "x": 3,
      "y": 1,
      "z": 2,
      "name": "Rock_Stone_Cobble"
    },
    {
      "x": 3,
      "y": 2,
      "z": 2,
      "name": "Wood_Softwood_Planks"
    },
    {
      "x": 3,
      "y": 3,
      "z": 2,
      "name": "Wood_Softwood_Planks"
    },
    {
      "x": 3,
      "y": 4,
      "z": 2,
      "name": "Wood_Softwood_Planks"
    },
    {
      "x": 3,
      "y": 5,
      "z": 2,
      "name": "Wood_Softwood_Roof_Shallow",
      "rotation": 1
    },
    {
      "x": 3,
      "y": 0,
      "z": 3,
      "name": "Rock_Stone_Cobble"
    },
    {
      "x": 3,
      "y": 1,
      "z": 3,
      "name": "Rock_Stone_Cobble"
    },
    {
      "x": 3,
      "y": 2,
      "z": 3,
      "name": "Wood_Softwood_Planks"
    },
    {
      "x": 3,
      "y": 3,
      "z": 3,
      "name": "Wood_Softwood_Planks"
    },
    {
      "x": 3,
      "y": 4,
      "z": 3,
      "name": "Wood_Softwood_Planks"
    },
    {
      "x": 3,
      "y": 5,
      "z": 3,
      "name": "Wood_Softwood_Roof_Shallow",
      "rotation": 1
    },
    {
      "x": 3,
      "y": 0,
      "z": 4,
      "name": "Wood_Ash_Trunk",
      "support": 15
    },
    {
      "x": 3,
      "y": 1,
      "z": 4,
      "name": "Wood_Ash_Trunk",
      "support": 15
    },
    {
      "x": 3,
      "y": 2,
      "z": 4,
      "name": "Wood_Ash_Trunk",
      "support": 15
    },
    {
      "x": 3,
      "y": 3,
      "z": 4,
      "name": "Wood_Ash_Trunk",
      "support": 15
    },
    {
      "x": 3,
      "y": 4,
      "z": 4,
      "name": "Wood_Ash_Trunk",
      "support": 15
    },
    {
      "x": 3,
      "y": 5,
      "z": 4,
      "name": "Wood_Softwood_Roof_Shallow",
      "rotation": 1
    },
    {
      "x": 4,
      "y": 4,
      "z": -2,
      "name": "Wood_Softwood_Roof_Hollow",
      "rotation": 1
    },
    {
      "x": 4,
      "y": 4,
      "z": -1,
      "name": "Wood_Softwood_Roof_Hollow",
      "rotation": 1
    },
    {
      "x": 4,
      "y": 4,
      "z": 0,
      "name": "Wood_Softwood_Roof_Hollow",
      "rotation": 1
    },
    {
      "x": 4,
      "y": 4,
      "z": 1,
      "name": "Wood_Softwood_Roof_Hollow",
      "rotation": 1
    },
    {
      "x": 4,
      "y": 4,
      "z": 2,
      "name": "Wood_Softwood_Roof_Hollow",
      "rotation": 1
    },
    {
      "x": 4,
      "y": 4,
      "z": 3,
      "name": "Wood_Softwood_Roof_Hollow",
      "rotation": 1
    },
    {
      "x": 4,
      "y": 4,
      "z": 4,
      "name": "Wood_Softwood_Roof_Hollow",
      "rotation": 1
    }
  ],
  "fluids": [
    {
      "x": -4,
      "y": 4,
      "z": -2,
      "name": "Empty",
      "level": 0
    },
    {
      "x": -4,
      "y": 4,
      "z": -1,
      "name": "Empty",
      "level": 0
    },
    {
      "x": -4,
      "y": 4,
      "z": 0,
      "name": "Empty",
      "level": 0
    },
    {
      "x": -4,
      "y": 4,
      "z": 1,
      "name": "Empty",
      "level": 0
    },
    {
      "x": -4,
      "y": 4,
      "z": 2,
      "name": "Empty",
      "level": 0
    },
    {
      "x": -4,
      "y": 4,
      "z": 3,
      "name": "Empty",
      "level": 0
    },
    {
      "x": -4,
      "y": 4,
      "z": 4,
      "name": "Empty",
      "level": 0
    },
    {
      "x": -3,
      "y": 0,
      "z": -2,
      "name": "Empty",
      "level": 0
    },
    {
      "x": -3,
      "y": 1,
      "z": -2,
      "name": "Empty",
      "level": 0
    },
    {
      "x": -3,
      "y": 2,
      "z": -2,
      "name": "Empty",
      "level": 0
    },
    {
      "x": -3,
      "y": 3,
      "z": -2,
      "name": "Empty",
      "level": 0
    },
    {
      "x": -3,
      "y": 4,
      "z": -2,
      "name": "Empty",
      "level": 0
    },
    {
      "x": -3,
      "y": 5,
      "z": -2,
      "name": "Empty",
      "level": 0
    },
    {
      "x": -3,
      "y": 0,
      "z": -1,
      "name": "Empty",
      "level": 0
    },
    {
      "x": -3,
      "y": 1,
      "z": -1,
      "name": "Empty",
      "level": 0
    },
    {
      "x": -3,
      "y": 2,
      "z": -1,
      "name": "Empty",
      "level": 0
    },
    {
      "x": -3,
      "y": 3,
      "z": -1,
      "name": "Empty",
      "level": 0
    },
    {
      "x": -3,
      "y": 4,
      "z": -1,
      "name": "Empty",
      "level": 0
    },
    {
      "x": -3,
      "y": 5,
      "z": -1,
      "name": "Empty",
      "level": 0
    },
    {
      "x": -3,
      "y": 0,
      "z": 0,
      "name": "Empty",
      "level": 0
    },
    {
      "x": -3,
      "y": 1,
      "z": 0,
      "name": "Empty",
      "level": 0
    },
    {
      "x": -3,
      "y": 2,
      "z": 0,
      "name": "Empty",
      "level": 0
    },
    {
      "x": -3,
      "y": 3,
      "z": 0,
      "name": "Empty",
      "level": 0
    },
    {
      "x": -3,
      "y": 4,
      "z": 0,
      "name": "Empty",
      "level": 0
    },
    {
      "x": -3,
      "y": 5,
      "z": 0,
      "name": "Empty",
      "level": 0
    },
    {
      "x": -3,
      "y": 0,
      "z": 1,
      "name": "Empty",
      "level": 0
    },
    {
      "x": -3,
      "y": 1,
      "z": 1,
      "name": "Empty",
      "level": 0
    },
    {
      "x": -3,
      "y": 2,
      "z": 1,
      "name": "Empty",
      "level": 0
    },
    {
      "x": -3,
      "y": 3,
      "z": 1,
      "name": "Empty",
      "level": 0
    },
    {
      "x": -3,
      "y": 4,
      "z": 1,
      "name": "Empty",
      "level": 0
    },
    {
      "x": -3,
      "y": 5,
      "z": 1,
      "name": "Empty",
      "level": 0
    },
    {
      "x": -3,
      "y": 0,
      "z": 2,
      "name": "Empty",
      "level": 0
    },
    {
      "x": -3,
      "y": 1,
      "z": 2,
      "name": "Empty",
      "level": 0
    },
    {
      "x": -3,
      "y": 2,
      "z": 2,
      "name": "Empty",
      "level": 0
    },
    {
      "x": -3,
      "y": 3,
      "z": 2,
      "name": "Empty",
      "level": 0
    },
    {
      "x": -3,
      "y": 4,
      "z": 2,
      "name": "Empty",
      "level": 0
    },
    {
      "x": -3,
      "y": 5,
      "z": 2,
      "name": "Empty",
      "level": 0
    },
    {
      "x": -3,
      "y": 0,
      "z": 3,
      "name": "Empty",
      "level": 0
    },
    {
      "x": -3,
      "y": 1,
      "z": 3,
      "name": "Empty",
      "level": 0
    },
    {
      "x": -3,
      "y": 2,
      "z": 3,
      "name": "Empty",
      "level": 0
    },
    {
      "x": -3,
      "y": 3,
      "z": 3,
      "name": "Empty",
      "level": 0
    },
    {
      "x": -3,
      "y": 4,
      "z": 3,
      "name": "Empty",
      "level": 0
    },
    {
      "x": -3,
      "y": 5,
      "z": 3,
      "name": "Empty",
      "level": 0
    },
    {
      "x": -3,
      "y": 0,
      "z": 4,
      "name": "Empty",
      "level": 0
    },
    {
      "x": -3,
      "y": 1,
      "z": 4,
      "name": "Empty",
      "level": 0
    },
    {
      "x": -3,
      "y": 2,
      "z": 4,
      "name": "Empty",
      "level": 0
    },
    {
      "x": -3,
      "y": 3,
      "z": 4,
      "name": "Empty",
      "level": 0
    },
    {
      "x": -3,
      "y": 4,
      "z": 4,
      "name": "Empty",
      "level": 0
    },
    {
      "x": -3,
      "y": 5,
      "z": 4,
      "name": "Empty",
      "level": 0
    },
    {
      "x": -2,
      "y": 0,
      "z": -2,
      "name": "Empty",
      "level": 0
    },
    {
      "x": -2,
      "y": 1,
      "z": -2,
      "name": "Empty",
      "level": 0
    },
    {
      "x": -2,
      "y": 2,
      "z": -2,
      "name": "Empty",
      "level": 0
    },
    {
      "x": -2,
      "y": 3,
      "z": -2,
      "name": "Empty",
      "level": 0
    },
    {
      "x": -2,
      "y": 4,
      "z": -2,
      "name": "Empty",
      "level": 0
    },
    {
      "x": -2,
      "y": 5,
      "z": -2,
      "name": "Empty",
      "level": 0
    },
    {
      "x": -2,
      "y": 0,
      "z": -1,
      "name": "Empty",
      "level": 0
    },
    {
      "x": -2,
      "y": 4,
      "z": -1,
      "name": "Empty",
      "level": 0
    },
    {
      "x": -2,
      "y": 5,
      "z": -1,
      "name": "Empty",
      "level": 0
    },
    {
      "x": -2,
      "y": 0,
      "z": 0,
      "name": "Empty",
      "level": 0
    },
    {
      "x": -2,
      "y": 1,
      "z": 0,
      "name": "Empty",
      "level": 0
    },
    {
      "x": -2,
      "y": 4,
      "z": 0,
      "name": "Empty",
      "level": 0
    },
    {
      "x": -2,
      "y": 5,
      "z": 0,
      "name": "Empty",
      "level": 0
    },
    {
      "x": -2,
      "y": 0,
      "z": 1,
      "name": "Empty",
      "level": 0
    },
    {
      "x": -2,
      "y": 1,
      "z": 1,
      "name": "Empty",
      "level": 0
    },
    {
      "x": -2,
      "y": 2,
      "z": 1,
      "name": "Empty",
      "level": 0
    },
    {
      "x": -2,
      "y": 4,
      "z": 1,
      "name": "Empty",
      "level": 0
    },
    {
      "x": -2,
      "y": 5,
      "z": 1,
      "name": "Empty",
      "level": 0
    },
    {
      "x": -2,
      "y": 0,
      "z": 2,
      "name": "Empty",
      "level": 0
    },
    {
      "x": -2,
      "y": 1,
      "z": 2,
      "name": "Empty",
      "level": 0
    },
    {
      "x": -2,
      "y": 2,
      "z": 2,
      "name": "Empty",
      "level": 0
    },
    {
      "x": -2,
      "y": 3,
      "z": 2,
      "name": "Empty",
      "level": 0
    },
    {
      "x": -2,
      "y": 4,
      "z": 2,
      "name": "Empty",
      "level": 0
    },
    {
      "x": -2,
      "y": 5,
      "z": 2,
      "name": "Empty",
      "level": 0
    },
    {
      "x": -2,
      "y": 0,
      "z": 3,
      "name": "Empty",
      "level": 0
    },
    {
      "x": -2,
      "y": 1,
      "z": 3,
      "name": "Empty",
      "level": 0
    },
    {
      "x": -2,
      "y": 2,
      "z": 3,
      "name": "Empty",
      "level": 0
    },
    {
      "x": -2,
      "y": 4,
      "z": 3,
      "name": "Empty",
      "level": 0
    },
    {
      "x": -2,
      "y": 5,
      "z": 3,
      "name": "Empty",
      "level": 0
    },
    {
      "x": -2,
      "y": 0,
      "z": 4,
      "name": "Empty",
      "level": 0
    },
    {
      "x": -2,
      "y": 1,
      "z": 4,
      "name": "Empty",
      "level": 0
    },
    {
      "x": -2,
      "y": 2,
      "z": 4,
      "name": "Empty",
      "level": 0
    },
    {
      "x": -2,
      "y": 3,
      "z": 4,
      "name": "Empty",
      "level": 0
    },
    {
      "x": -2,
      "y": 4,
      "z": 4,
      "name": "Empty",
      "level": 0
    },
    {
      "x": -2,
      "y": 5,
      "z": 4,
      "name": "Empty",
      "level": 0
    },
    {
      "x": -1,
      "y": 0,
      "z": -2,
      "name": "Empty",
      "level": 0
    },
    {
      "x": -1,
      "y": 1,
      "z": -2,
      "name": "Empty",
      "level": 0
    },
    {
      "x": -1,
      "y": 2,
      "z": -2,
      "name": "Empty",
      "level": 0
    },
    {
      "x": -1,
      "y": 3,
      "z": -2,
      "name": "Empty",
      "level": 0
    },
    {
      "x": -1,
      "y": 4,
      "z": -2,
      "name": "Empty",
      "level": 0
    },
    {
      "x": -1,
      "y": 5,
      "z": -2,
      "name": "Empty",
      "level": 0
    },
    {
      "x": -1,
      "y": 6,
      "z": -2,
      "name": "Empty",
      "level": 0
    },
    {
      "x": -1,
      "y": 0,
      "z": -1,
      "name": "Empty",
      "level": 0
    },
    {
      "x": -1,
      "y": 4,
      "z": -1,
      "name": "Empty",
      "level": 0
    },
    {
      "x": -1,
      "y": 5,
      "z": -1,
      "name": "Empty",
      "level": 0
    },
    {
      "x": -1,
      "y": 6,
      "z": -1,
      "name": "Empty",
      "level": 0
    },
    {
      "x": -1,
      "y": 0,
      "z": 0,
      "name": "Empty",
      "level": 0
    },
    {
      "x": -1,
      "y": 4,
      "z": 0,
      "name": "Empty",
      "level": 0
    },
    {
      "x": -1,
      "y": 5,
      "z": 0,
      "name": "Empty",
      "level": 0
    },
    {
      "x": -1,
      "y": 6,
      "z": 0,
      "name": "Empty",
      "level": 0
    },
    {
      "x": -1,
      "y": 0,
      "z": 1,
      "name": "Empty",
      "level": 0
    },
    {
      "x": -1,
      "y": 1,
      "z": 1,
      "name": "Empty",
      "level": 0
    },
    {
      "x": -1,
      "y": 2,
      "z": 1,
      "name": "Empty",
      "level": 0
    },
    {
      "x": -1,
      "y": 4,
      "z": 1,
      "name": "Empty",
      "level": 0
    },
    {
      "x": -1,
      "y": 5,
      "z": 1,
      "name": "Empty",
      "level": 0
    },
    {
      "x": -1,
      "y": 6,
      "z": 1,
      "name": "Empty",
      "level": 0
    },
    {
      "x": -1,
      "y": 0,
      "z": 2,
      "name": "Empty",
      "level": 0
    },
    {
      "x": -1,
      "y": 1,
      "z": 2,
      "name": "Empty",
      "level": 0
    },
    {
      "x": -1,
      "y": 2,
      "z": 2,
      "name": "Empty",
      "level": 0
    },
    {
      "x": -1,
      "y": 4,
      "z": 2,
      "name": "Empty",
      "level": 0
    },
    {
      "x": -1,
      "y": 5,
      "z": 2,
      "name": "Empty",
      "level": 0
    },
    {
      "x": -1,
      "y": 6,
      "z": 2,
      "name": "Empty",
      "level": 0
    },
    {
      "x": -1,
      "y": 0,
      "z": 3,
      "name": "Empty",
      "level": 0
    },
    {
      "x": -1,
      "y": 1,
      "z": 3,
      "name": "Empty",
      "level": 0
    },
    {
      "x": -1,
      "y": 2,
      "z": 3,
      "name": "Empty",
      "level": 0
    },
    {
      "x": -1,
      "y": 4,
      "z": 3,
      "name": "Empty",
      "level": 0
    },
    {
      "x": -1,
      "y": 5,
      "z": 3,
      "name": "Empty",
      "level": 0
    },
    {
      "x": -1,
      "y": 6,
      "z": 3,
      "name": "Empty",
      "level": 0
    },
    {
      "x": -1,
      "y": 0,
      "z": 4,
      "name": "Empty",
      "level": 0
    },
    {
      "x": -1,
      "y": 1,
      "z": 4,
      "name": "Empty",
      "level": 0
    },
    {
      "x": -1,
      "y": 2,
      "z": 4,
      "name": "Empty",
      "level": 0
    },
    {
      "x": -1,
      "y": 3,
      "z": 4,
      "name": "Empty",
      "level": 0
    },
    {
      "x": -1,
      "y": 4,
      "z": 4,
      "name": "Empty",
      "level": 0
    },
    {
      "x": -1,
      "y": 5,
      "z": 4,
      "name": "Empty",
      "level": 0
    },
    {
      "x": -1,
      "y": 6,
      "z": 4,
      "name": "Empty",
      "level": 0
    },
    {
      "x": 0,
      "y": 0,
      "z": -3,
      "name": "Empty",
      "level": 0
    },
    {
      "x": 0,
      "y": 0,
      "z": -2,
      "name": "Empty",
      "level": 0
    },
    {
      "x": 0,
      "y": 1,
      "z": -2,
      "name": "Empty",
      "level": 0
    },
    {
      "x": 0,
      "y": 2,
      "z": -2,
      "name": "Empty",
      "level": 0
    },
    {
      "x": 0,
      "y": 3,
      "z": -2,
      "name": "Empty",
      "level": 0
    },
    {
      "x": 0,
      "y": 4,
      "z": -2,
      "name": "Empty",
      "level": 0
    },
    {
      "x": 0,
      "y": 5,
      "z": -2,
      "name": "Empty",
      "level": 0
    },
    {
      "x": 0,
      "y": 6,
      "z": -2,
      "name": "Empty",
      "level": 0
    },
    {
      "x": 0,
      "y": 7,
      "z": -2,
      "name": "Empty",
      "level": 0
    },
    {
      "x": 0,
      "y": 0,
      "z": -1,
      "name": "Empty",
      "level": 0
    },
    {
      "x": 0,
      "y": 4,
      "z": -1,
      "name": "Empty",
      "level": 0
    },
    {
      "x": 0,
      "y": 6,
      "z": -1,
      "name": "Empty",
      "level": 0
    },
    {
      "x": 0,
      "y": 7,
      "z": -1,
      "name": "Empty",
      "level": 0
    },
    {
      "x": 0,
      "y": 0,
      "z": 0,
      "name": "Empty",
      "level": 0
    },
    {
      "x": 0,
      "y": 4,
      "z": 0,
      "name": "Empty",
      "level": 0
    },
    {
      "x": 0,
      "y": 6,
      "z": 0,
      "name": "Empty",
      "level": 0
    },
    {
      "x": 0,
      "y": 7,
      "z": 0,
      "name": "Empty",
      "level": 0
    },
    {
      "x": 0,
      "y": 0,
      "z": 1,
      "name": "Empty",
      "level": 0
    },
    {
      "x": 0,
      "y": 4,
      "z": 1,
      "name": "Empty",
      "level": 0
    },
    {
      "x": 0,
      "y": 6,
      "z": 1,
      "name": "Empty",
      "level": 0
    },
    {
      "x": 0,
      "y": 7,
      "z": 1,
      "name": "Empty",
      "level": 0
    },
    {
      "x": 0,
      "y": 0,
      "z": 2,
      "name": "Empty",
      "level": 0
    },
    {
      "x": 0,
      "y": 4,
      "z": 2,
      "name": "Empty",
      "level": 0
    },
    {
      "x": 0,
      "y": 6,
      "z": 2,
      "name": "Empty",
      "level": 0
    },
    {
      "x": 0,
      "y": 7,
      "z": 2,
      "name": "Empty",
      "level": 0
    },
    {
      "x": 0,
      "y": 0,
      "z": 3,
      "name": "Empty",
      "level": 0
    },
    {
      "x": 0,
      "y": 4,
      "z": 3,
      "name": "Empty",
      "level": 0
    },
    {
      "x": 0,
      "y": 6,
      "z": 3,
      "name": "Empty",
      "level": 0
    },
    {
      "x": 0,
      "y": 7,
      "z": 3,
      "name": "Empty",
      "level": 0
    },
    {
      "x": 0,
      "y": 0,
      "z": 4,
      "name": "Empty",
      "level": 0
    },
    {
      "x": 0,
      "y": 1,
      "z": 4,
      "name": "Empty",
      "level": 0
    },
    {
      "x": 0,
      "y": 2,
      "z": 4,
      "name": "Empty",
      "level": 0
    },
    {
      "x": 0,
      "y": 3,
      "z": 4,
      "name": "Empty",
      "level": 0
    },
    {
      "x": 0,
      "y": 4,
      "z": 4,
      "name": "Empty",
      "level": 0
    },
    {
      "x": 0,
      "y": 5,
      "z": 4,
      "name": "Empty",
      "level": 0
    },
    {
      "x": 0,
      "y": 6,
      "z": 4,
      "name": "Empty",
      "level": 0
    },
    {
      "x": 0,
      "y": 7,
      "z": 4,
      "name": "Empty",
      "level": 0
    },
    {
      "x": 1,
      "y": 0,
      "z": -2,
      "name": "Empty",
      "level": 0
    },
    {
      "x": 1,
      "y": 1,
      "z": -2,
      "name": "Empty",
      "level": 0
    },
    {
      "x": 1,
      "y": 2,
      "z": -2,
      "name": "Empty",
      "level": 0
    },
    {
      "x": 1,
      "y": 3,
      "z": -2,
      "name": "Empty",
      "level": 0
    },
    {
      "x": 1,
      "y": 4,
      "z": -2,
      "name": "Empty",
      "level": 0
    },
    {
      "x": 1,
      "y": 5,
      "z": -2,
      "name": "Empty",
      "level": 0
    },
    {
      "x": 1,
      "y": 6,
      "z": -2,
      "name": "Empty",
      "level": 0
    },
    {
      "x": 1,
      "y": 0,
      "z": -1,
      "name": "Empty",
      "level": 0
    },
    {
      "x": 1,
      "y": 4,
      "z": -1,
      "name": "Empty",
      "level": 0
    },
    {
      "x": 1,
      "y": 5,
      "z": -1,
      "name": "Empty",
      "level": 0
    },
    {
      "x": 1,
      "y": 6,
      "z": -1,
      "name": "Empty",
      "level": 0
    },
    {
      "x": 1,
      "y": 0,
      "z": 0,
      "name": "Empty",
      "level": 0
    },
    {
      "x": 1,
      "y": 4,
      "z": 0,
      "name": "Empty",
      "level": 0
    },
    {
      "x": 1,
      "y": 5,
      "z": 0,
      "name": "Empty",
      "level": 0
    },
    {
      "x": 1,
      "y": 6,
      "z": 0,
      "name": "Empty",
      "level": 0
    },
    {
      "x": 1,
      "y": 0,
      "z": 1,
      "name": "Empty",
      "level": 0
    },
    {
      "x": 1,
      "y": 4,
      "z": 1,
      "name": "Empty",
      "level": 0
    },
    {
      "x": 1,
      "y": 5,
      "z": 1,
      "name": "Empty",
      "level": 0
    },
    {
      "x": 1,
      "y": 6,
      "z": 1,
      "name": "Empty",
      "level": 0
    },
    {
      "x": 1,
      "y": 0,
      "z": 2,
      "name": "Empty",
      "level": 0
    },
    {
      "x": 1,
      "y": 4,
      "z": 2,
      "name": "Empty",
      "level": 0
    },
    {
      "x": 1,
      "y": 5,
      "z": 2,
      "name": "Empty",
      "level": 0
    },
    {
      "x": 1,
      "y": 6,
      "z": 2,
      "name": "Empty",
      "level": 0
    },
    {
      "x": 1,
      "y": 0,
      "z": 3,
      "name": "Empty",
      "level": 0
    },
    {
      "x": 1,
      "y": 2,
      "z": 3,
      "name": "Empty",
      "level": 0
    },
    {
      "x": 1,
      "y": 4,
      "z": 3,
      "name": "Empty",
      "level": 0
    },
    {
      "x": 1,
      "y": 5,
      "z": 3,
      "name": "Empty",
      "level": 0
    },
    {
      "x": 1,
      "y": 6,
      "z": 3,
      "name": "Empty",
      "level": 0
    },
    {
      "x": 1,
      "y": 0,
      "z": 4,
      "name": "Empty",
      "level": 0
    },
    {
      "x": 1,
      "y": 1,
      "z": 4,
      "name": "Empty",
      "level": 0
    },
    {
      "x": 1,
      "y": 2,
      "z": 4,
      "name": "Empty",
      "level": 0
    },
    {
      "x": 1,
      "y": 3,
      "z": 4,
      "name": "Empty",
      "level": 0
    },
    {
      "x": 1,
      "y": 4,
      "z": 4,
      "name": "Empty",
      "level": 0
    },
    {
      "x": 1,
      "y": 5,
      "z": 4,
      "name": "Empty",
      "level": 0
    },
    {
      "x": 1,
      "y": 6,
      "z": 4,
      "name": "Empty",
      "level": 0
    },
    {
      "x": 2,
      "y": 0,
      "z": -2,
      "name": "Empty",
      "level": 0
    },
    {
      "x": 2,
      "y": 1,
      "z": -2,
      "name": "Empty",
      "level": 0
    },
    {
      "x": 2,
      "y": 2,
      "z": -2,
      "name": "Empty",
      "level": 0
    },
    {
      "x": 2,
      "y": 3,
      "z": -2,
      "name": "Empty",
      "level": 0
    },
    {
      "x": 2,
      "y": 4,
      "z": -2,
      "name": "Empty",
      "level": 0
    },
    {
      "x": 2,
      "y": 5,
      "z": -2,
      "name": "Empty",
      "level": 0
    },
    {
      "x": 2,
      "y": 0,
      "z": -1,
      "name": "Empty",
      "level": 0
    },
    {
      "x": 2,
      "y": 4,
      "z": -1,
      "name": "Empty",
      "level": 0
    },
    {
      "x": 2,
      "y": 5,
      "z": -1,
      "name": "Empty",
      "level": 0
    },
    {
      "x": 2,
      "y": 0,
      "z": 0,
      "name": "Empty",
      "level": 0
    },
    {
      "x": 2,
      "y": 1,
      "z": 0,
      "name": "Empty",
      "level": 0
    },
    {
      "x": 2,
      "y": 2,
      "z": 0,
      "name": "Empty",
      "level": 0
    },
    {
      "x": 2,
      "y": 4,
      "z": 0,
      "name": "Empty",
      "level": 0
    },
    {
      "x": 2,
      "y": 5,
      "z": 0,
      "name": "Empty",
      "level": 0
    },
    {
      "x": 2,
      "y": 0,
      "z": 1,
      "name": "Empty",
      "level": 0
    },
    {
      "x": 2,
      "y": 4,
      "z": 1,
      "name": "Empty",
      "level": 0
    },
    {
      "x": 2,
      "y": 5,
      "z": 1,
      "name": "Empty",
      "level": 0
    },
    {
      "x": 2,
      "y": 0,
      "z": 2,
      "name": "Empty",
      "level": 0
    },
    {
      "x": 2,
      "y": 3,
      "z": 2,
      "name": "Empty",
      "level": 0
    },
    {
      "x": 2,
      "y": 4,
      "z": 2,
      "name": "Empty",
      "level": 0
    },
    {
      "x": 2,
      "y": 5,
      "z": 2,
      "name": "Empty",
      "level": 0
    },
    {
      "x": 2,
      "y": 0,
      "z": 3,
      "name": "Empty",
      "level": 0
    },
    {
      "x": 2,
      "y": 4,
      "z": 3,
      "name": "Empty",
      "level": 0
    },
    {
      "x": 2,
      "y": 5,
      "z": 3,
      "name": "Empty",
      "level": 0
    },
    {
      "x": 2,
      "y": 0,
      "z": 4,
      "name": "Empty",
      "level": 0
    },
    {
      "x": 2,
      "y": 1,
      "z": 4,
      "name": "Empty",
      "level": 0
    },
    {
      "x": 2,
      "y": 2,
      "z": 4,
      "name": "Empty",
      "level": 0
    },
    {
      "x": 2,
      "y": 3,
      "z": 4,
      "name": "Empty",
      "level": 0
    },
    {
      "x": 2,
      "y": 4,
      "z": 4,
      "name": "Empty",
      "level": 0
    },
    {
      "x": 2,
      "y": 5,
      "z": 4,
      "name": "Empty",
      "level": 0
    },
    {
      "x": 3,
      "y": 0,
      "z": -2,
      "name": "Empty",
      "level": 0
    },
    {
      "x": 3,
      "y": 1,
      "z": -2,
      "name": "Empty",
      "level": 0
    },
    {
      "x": 3,
      "y": 2,
      "z": -2,
      "name": "Empty",
      "level": 0
    },
    {
      "x": 3,
      "y": 3,
      "z": -2,
      "name": "Empty",
      "level": 0
    },
    {
      "x": 3,
      "y": 4,
      "z": -2,
      "name": "Empty",
      "level": 0
    },
    {
      "x": 3,
      "y": 5,
      "z": -2,
      "name": "Empty",
      "level": 0
    },
    {
      "x": 3,
      "y": 0,
      "z": -1,
      "name": "Empty",
      "level": 0
    },
    {
      "x": 3,
      "y": 1,
      "z": -1,
      "name": "Empty",
      "level": 0
    },
    {
      "x": 3,
      "y": 2,
      "z": -1,
      "name": "Empty",
      "level": 0
    },
    {
      "x": 3,
      "y": 3,
      "z": -1,
      "name": "Empty",
      "level": 0
    },
    {
      "x": 3,
      "y": 4,
      "z": -1,
      "name": "Empty",
      "level": 0
    },
    {
      "x": 3,
      "y": 5,
      "z": -1,
      "name": "Empty",
      "level": 0
    },
    {
      "x": 3,
      "y": 0,
      "z": 0,
      "name": "Empty",
      "level": 0
    },
    {
      "x": 3,
      "y": 1,
      "z": 0,
      "name": "Empty",
      "level": 0
    },
    {
      "x": 3,
      "y": 2,
      "z": 0,
      "name": "Empty",
      "level": 0
    },
    {
      "x": 3,
      "y": 3,
      "z": 0,
      "name": "Empty",
      "level": 0
    },
    {
      "x": 3,
      "y": 4,
      "z": 0,
      "name": "Empty",
      "level": 0
    },
    {
      "x": 3,
      "y": 5,
      "z": 0,
      "name": "Empty",
      "level": 0
    },
    {
      "x": 3,
      "y": 0,
      "z": 1,
      "name": "Empty",
      "level": 0
    },
    {
      "x": 3,
      "y": 1,
      "z": 1,
      "name": "Empty",
      "level": 0
    },
    {
      "x": 3,
      "y": 2,
      "z": 1,
      "name": "Empty",
      "level": 0
    },
    {
      "x": 3,
      "y": 3,
      "z": 1,
      "name": "Empty",
      "level": 0
    },
    {
      "x": 3,
      "y": 4,
      "z": 1,
      "name": "Empty",
      "level": 0
    },
    {
      "x": 3,
      "y": 5,
      "z": 1,
      "name": "Empty",
      "level": 0
    },
    {
      "x": 3,
      "y": 0,
      "z": 2,
      "name": "Empty",
      "level": 0
    },
    {
      "x": 3,
      "y": 1,
      "z": 2,
      "name": "Empty",
      "level": 0
    },
    {
      "x": 3,
      "y": 2,
      "z": 2,
      "name": "Empty",
      "level": 0
    },
    {
      "x": 3,
      "y": 3,
      "z": 2,
      "name": "Empty",
      "level": 0
    },
    {
      "x": 3,
      "y": 4,
      "z": 2,
      "name": "Empty",
      "level": 0
    },
    {
      "x": 3,
      "y": 5,
      "z": 2,
      "name": "Empty",
      "level": 0
    },
    {
      "x": 3,
      "y": 0,
      "z": 3,
      "name": "Empty",
      "level": 0
    },
    {
      "x": 3,
      "y": 1,
      "z": 3,
      "name": "Empty",
      "level": 0
    },
    {
      "x": 3,
      "y": 2,
      "z": 3,
      "name": "Empty",
      "level": 0
    },
    {
      "x": 3,
      "y": 3,
      "z": 3,
      "name": "Empty",
      "level": 0
    },
    {
      "x": 3,
      "y": 4,
      "z": 3,
      "name": "Empty",
      "level": 0
    },
    {
      "x": 3,
      "y": 5,
      "z": 3,
      "name": "Empty",
      "level": 0
    },
    {
      "x": 3,
      "y": 0,
      "z": 4,
      "name": "Empty",
      "level": 0
    },
    {
      "x": 3,
      "y": 1,
      "z": 4,
      "name": "Empty",
      "level": 0
    },
    {
      "x": 3,
      "y": 2,
      "z": 4,
      "name": "Empty",
      "level": 0
    },
    {
      "x": 3,
      "y": 3,
      "z": 4,
      "name": "Empty",
      "level": 0
    },
    {
      "x": 3,
      "y": 4,
      "z": 4,
      "name": "Empty",
      "level": 0
    },
    {
      "x": 3,
      "y": 5,
      "z": 4,
      "name": "Empty",
      "level": 0
    },
    {
      "x": 4,
      "y": 4,
      "z": -2,
      "name": "Empty",
      "level": 0
    },
    {
      "x": 4,
      "y": 4,
      "z": -1,
      "name": "Empty",
      "level": 0
    },
    {
      "x": 4,
      "y": 4,
      "z": 0,
      "name": "Empty",
      "level": 0
    },
    {
      "x": 4,
      "y": 4,
      "z": 1,
      "name": "Empty",
      "level": 0
    },
    {
      "x": 4,
      "y": 4,
      "z": 2,
      "name": "Empty",
      "level": 0
    },
    {
      "x": 4,
      "y": 4,
      "z": 3,
      "name": "Empty",
      "level": 0
    },
    {
      "x": 4,
      "y": 4,
      "z": 4,
      "name": "Empty",
      "level": 0
    }
  ]
}