{
  "version": 8,
  "blockIdVersion": 11,
  "anchorX": 0,
  "anchorY": 0,
  "anchorZ": 0,
  "blocks": [
    {
      "x": -32,
      "y": 13,
      "z": 11,
      "name": "Wood_Softwood_Stairs",
      "rotation": 9
    },
    {
      "x": -31,
      "y": 4,
      "z": 5,
      "name": "Wood_Softwood_Roof_Hollow",
      "rotation": 2
    },
    {
      "x": -31,
      "y": 4,
      "z": 6,
      "name": "Wood_Oak_Branch_Short",
      "support": 15,
      "rotation": 3
    },
    {
      "x": -31,
      "y": 5,
      "z": 6,
      "name": "Wood_Softwood_Roof_Steep",
      "rotation": 2
    },
    {
      "x": -31,
      "y": 6,
      "z": 6,
      "name": "Wood_Softwood_Roof_Steep",
      "filler": 1024,
      "rotation": 2
    },
    {
      "x": -31,
      "y": 6,
      "z": 7,
      "name": "Wood_Softwood_Stairs",
      "rotation": 10
    },
    {
      "x": -31,
      "y": 7,
      "z": 7,
      "name": "Wood_Softwood_Roof_Steep",
      "rotation": 2
    },
    {
      "x": -31,
      "y": 8,
      "z": 7,
      "name": "Wood_Softwood_Roof_Steep",
      "filler": 1024,
      "rotation": 2
    },
    {
      "x": -31,
      "y": 8,
      "z": 8,
      "name": "Wood_Softwood_Stairs",
      "rotation": 10
    },
    {
      "x": -31,
      "y": 9,
      "z": 8,
      "name": "Wood_Softwood_Roof_Steep",
      "rotation": 2
    },
    {
      "x": -31,
      "y": 10,
      "z": 8,
      "name": "Wood_Softwood_Roof_Steep",
      "filler": 1024,
      "rotation": 2
    },
    {
      "x": -31,
      "y": 10,
      "z": 9,
      "name": "Wood_Softwood_Stairs",
      "rotation": 10
    },
    {
      "x": -31,
      "y": 11,
      "z": 9,
      "name": "Wood_Softwood_Roof",
      "rotation": 2
    },
    {
      "x": -31,
      "y": 11,
      "z": 10,
      "name": "Wood_Softwood_Stairs",
      "rotation": 10
    },
    {
      "x": -31,
      "y": 12,
      "z": 10,
      "name": "Wood_Softwood_Roof",
      "rotation": 2
    },
    {
      "x": -31,
      "y": 4,
      "z": 11,
      "name": "Wood_Oak_Branch_Short",
      "support": 15,
      "rotation": 3
    },
    {
      "x": -31,
      "y": 8,
      "z": 11,
      "name": "Wood_Oak_Branch_Short",
      "support": 15,
      "rotation": 3
    },
    {
      "x": -31,
      "y": 12,
      "z": 11,
      "name": "Wood_Softwood_Stairs",
      "rotation": 9
    },
    {
      "x": -31,
      "y": 13,
      "z": 11,
      "name": "Wood_Softwood_Stairs",
      "rotation": 1
    },
    {
      "x": -31,
      "y": 11,
      "z": 12,
      "name": "Wood_Softwood_Stairs",
      "rotation": 8
    },
    {
      "x": -31,
      "y": 12,
      "z": 12,
      "name": "Wood_Softwood_Roof"
    },
    {
      "x": -31,
      "y": 10,
      "z": 13,
      "name": "Wood_Softwood_Stairs",
      "rotation": 8
    },
    {
      "x": -31,
      "y": 11,
      "z": 13,
      "name": "Wood_Softwood_Roof"
    },
    {
      "x": -31,
      "y": 8,
      "z": 14,
      "name": "Wood_Softwood_Stairs",
      "rotation": 8
    },
    {
      "x": -31,
      "y": 9,
      "z": 14,
      "name": "Wood_Softwood_Roof_Steep"
    },
    {
      "x": -31,
      "y": 10,
      "z": 14,
      "name": "Wood_Softwood_Roof_Steep",
      "filler": 1024
    },
    {
      "x": -31,
      "y": 6,
      "z": 15,
      "name": "Wood_Softwood_Stairs",
      "rotation": 8
    },
    {
      "x": -31,
      "y": 7,
      "z": 15,
      "name": "Wood_Softwood_Roof_Steep"
    },
    {
      "x": -31,
      "y": 8,
      "z": 15,
      "name": "Wood_Softwood_Roof_Steep",
      "filler": 1024
    },
    {
      "x": -31,
      "y": 4,
      "z": 16,
      "name": "Wood_Oak_Branch_Short",
      "support": 15,
      "rotation": 3
    },
    {
      "x": -31,
      "y": 5,
      "z": 16,
      "name": "Wood_Softwood_Roof_Steep"
    },
    {
      "x": -31,
      "y": 6,
      "z": 16,
      "name": "Wood_Softwood_Roof_Steep",
      "filler": 1024
    },
    {
      "x": -31,
      "y": 4,
      "z": 17,
      "name": "Wood_Softwood_Roof_Hollow"
    },
    {
      "x": -30,
      "y": 4,
      "z": 5,
      "name": "Wood_Softwood_Roof_Hollow",
      "rotation": 2
    },
    {
      "x": -30,
      "y": 0,
      "z": 6,
      "name": "Rock_Stone_Cobble"
    },
    {
      "x": -30,
      "y": 1,
      "z": 6,
      "name": "Wood_Oak_Trunk",
      "support": 15
    },
    {
      "x": -30,
      "y": 2,
      "z": 6,
      "name": "Wood_Oak_Trunk",
      "support": 15
    },
    {
      "x": -30,
      "y": 3,
      "z": 6,
      "name": "Wood_Oak_Trunk",
      "support": 15
    },
    {
      "x": -30,
      "y": 4,
      "z": 6,
      "name": "Wood_Oak_Trunk",
      "support": 15
    },
    {
      "x": -30,
      "y": 5,
      "z": 6,
      "name": "Wood_Softwood_Roof_Steep",
      "rotation": 2
    },
    {
      "x": -30,
      "y": 6,
      "z": 6,
      "name": "Wood_Softwood_Roof_Steep",
      "filler": 1024,
      "rotation": 2
    },
    {
      "x": -30,
      "y": 4,
      "z": 7,
      "name": "Wood_Oak_Trunk",
      "support": 15,
      "rotation": 4
    },
    {
      "x": -30,
      "y": 6,
      "z": 7,
      "name": "Wood_Softwood_Stairs",
      "rotation": 10
    },
    {
      "x": -30,
      "y": 7,
      "z": 7,
      "name": "Wood_Softwood_Roof_Steep",
      "rotation": 2
    },
    {
      "x": -30,
      "y": 8,
      "z": 7,
      "name": "Wood_Softwood_Roof_Steep",
      "filler": 1024,
      "rotation": 2
    },
    {
      "x": -30,
      "y": 4,
      "z": 8,
      "name": "Wood_Oak_Trunk",
      "support": 15,
      "rotation": 4
    },
    {
      "x": -30,
      "y": 8,
      "z": 8,
      "name": "Wood_Oak_Trunk",
      "support": 15,
      "rotation": 4
    },
    {
      "x": -30,
      "y": 9,
      "z": 8,
      "name": "Wood_Softwood_Roof_Steep",
      "rotation": 2
    },
    {
      "x": -30,
      "y": 10,
      "z": 8,
      "name": "Wood_Softwood_Roof_Steep",
      "filler": 1024,
      "rotation": 2
    },
    {
      "x": -30,
      "y": 4,
      "z": 9,
      "name": "Wood_Oak_Trunk",
      "support": 15,
      "rotation": 4
    },
    {
      "x": -30,
      "y": 8,
      "z": 9,
      "name": "Wood_Oak_Trunk",
      "support": 15,
      "rotation": 4
    },
    {
      "x": -30,
      "y": 10,
      "z": 9,
      "name": "Wood_Softwood_Stairs",
      "rotation": 10
    },
    {
      "x": -30,
      "y": 11,
      "z": 9,
      "name": "Wood_Softwood_Roof",
      "rotation": 2
    },
    {
      "x": -30,
      "y": 4,
      "z": 10,
      "name": "Wood_Oak_Trunk",
      "support": 15,
      "rotation": 4
    },
    {
      "x": -30,
      "y": 8,
      "z": 10,
      "name": "Wood_Oak_Trunk",
      "support": 15,
      "rotation": 4
    },
    {
      "x": -30,
      "y": 11,
      "z": 10,
      "name": "Wood_Softwood_Stairs",
      "rotation": 10
    },
    {
      "x": -30,
      "y": 12,
      "z": 10,
      "name": "Wood_Softwood_Roof",
      "rotation": 2
    },
    {
      "x": -30,
      "y": 4,
      "z": 11,
      "name": "Wood_Oak_Trunk",
      "support": 15,
      "rotation": 4
    },
    {
      "x": -30,
      "y": 8,
      "z": 11,
      "name": "Wood_Oak_Trunk",
      "support": 15,
      "rotation": 4
    },
    {
      "x": -30,
      "y": 12,
      "z": 11,
      "name": "Wood_Softwood_Planks"
    },
    {
      "x": -30,
      "y": 13,
      "z": 11,
      "name": "Wood_Softwood_Planks_Half"
    },
    {
      "x": -30,
      "y": 4,
      "z": 12,
      "name": "Wood_Oak_Trunk",
      "support": 15,
      "rotation": 4
    },
    {
      "x": -30,
      "y": 8,
      "z": 12,
      "name": "Wood_Oak_Trunk",
      "support": 15,
      "rotation": 4
    },
    {
      "x": -30,
      "y": 11,
      "z": 12,
      "name": "Wood_Softwood_Stairs",
      "rotation": 8
    },
    {
      "x": -30,
      "y": 12,
      "z": 12,
      "name": "Wood_Softwood_Roof"
    },
    {
      "x": -30,
      "y": 4,
      "z": 13,
      "name": "Wood_Oak_Trunk",
      "support": 15,
      "rotation": 4
    },
    {
      "x": -30,
      "y": 8,
      "z": 13,
      "name": "Wood_Oak_Trunk",
      "support": 15,
      "rotation": 4
    },
    {
      "x": -30,
      "y": 10,
      "z": 13,
      "name": "Wood_Softwood_Stairs",
      "rotation": 8
    },
    {
      "x": -30,
      "y": 11,
      "z": 13,
      "name": "Wood_Softwood_Roof"
    },
    {
      "x": -30,
      "y": 4,
      "z": 14,
      "name": "Wood_Oak_Trunk",
      "support": 15,
      "rotation": 4
    },
    {
      "x": -30,
      "y": 8,
      "z": 14,
      "name": "Wood_Oak_Trunk",
      "support": 15,
      "rotation": 4
    },
    {
      "x": -30,
      "y": 9,
      "z": 14,
      "name": "Wood_Softwood_Roof_Steep"
    },
    {
      "x": -30,
      "y": 10,
      "z": 14,
      "name": "Wood_Softwood_Roof_Steep",
      "filler": 1024
    },
    {
      "x": -30,
      "y": 4,
      "z": 15,
      "name": "Wood_Oak_Trunk",
      "support": 15,
      "rotation": 4
    },
    {
      "x": -30,
      "y": 6,
      "z": 15,
      "name": "Wood_Softwood_Stairs",
      "rotation": 8
    },
    {
      "x": -30,
      "y": 7,
      "z": 15,
      "name": "Wood_Softwood_Roof_Steep"
    },
    {
      "x": -30,
      "y": 8,
      "z": 15,
      "name": "Wood_Softwood_Roof_Steep",
      "filler": 1024
    },
    {
      "x": -30,
      "y": 0,
      "z": 16,
      "name": "Rock_Stone_Cobble"
    },
    {
      "x": -30,
      "y": 1,
      "z": 16,
      "name": "Wood_Oak_Trunk",
      "support": 15
    },
    {
      "x": -30,
      "y": 2,
      "z": 16,
      "name": "Wood_Oak_Trunk",
      "support": 15
    },
    {
      "x": -30,
      "y": 3,
      "z": 16,
      "name": "Wood_Oak_Trunk",
      "support": 15
    },
    {
      "x": -30,
      "y": 4,
      "z": 16,
      "name": "Wood_Oak_Trunk",
      "support": 15
    },
    {
      "x": -30,
      "y": 5,
      "z": 16,
      "name": "Wood_Softwood_Roof_Steep"
    },
    {
      "x": -30,
      "y": 6,
      "z": 16,
      "name": "Wood_Softwood_Roof_Steep",
      "filler": 1024
    },
    {
      "x": -30,
      "y": 4,
      "z": 17,
      "name": "Wood_Softwood_Roof_Hollow"
    },
    {
      "x": -29,
      "y": 4,
      "z": 5,
      "name": "Wood_Softwood_Roof_Hollow",
      "rotation": 2
    },
    {
      "x": -29,
      "y": 4,
      "z": 6,
      "name": "Wood_Oak_Trunk",
      "support": 15,
      "rotation": 5
    },
    {
      "x": -29,
      "y": 5,
      "z": 6,
      "name": "Wood_Softwood_Roof_Steep",
      "rotation": 2
    },
    {
      "x": -29,
      "y": 6,
      "z": 6,
      "name": "Wood_Softwood_Roof_Steep",
      "filler": 1024,
      "rotation": 2
    },
    {
      "x": -29,
      "y": 0,
      "z": 7,
      "name": "Rock_Stone_Cobble"
    },
    {
      "x": -29,
      "y": 1,
      "z": 7,
      "name": "Rock_Stone_Brick"
    },
    {
      "x": -29,
      "y": 2,
      "z": 7,
      "name": "Rock_Quartzite"
    },
    {
      "x": -29,
      "y": 3,
      "z": 7,
      "name": "Rock_Quartzite"
    },
    {
      "x": -29,
      "y": 4,
      "z": 7,
      "name": "Wood_Softwood_Planks"
    },
    {
      "x": -29,
      "y": 5,
      "z": 7,
      "name": "Rock_Quartzite"
    },
    {
      "x": -29,
      "y": 6,
      "z": 7,
      "name": "Rock_Quartzite"
    },
    {
      "x": -29,
      "y": 7,
      "z": 7,
      "name": "Wood_Softwood_Roof_Steep",
      "rotation": 2
    },
    {
      "x": -29,
      "y": 8,
      "z": 7,
      "name": "Wood_Softwood_Roof_Steep",
      "filler": 1024,
      "rotation": 2
    },
    {
      "x": -29,
      "y": 0,
      "z": 8,
      "name": "Rock_Stone_Cobble"
    },
    {
      "x": -29,
      "y": 1,
      "z": 8,
      "name": "Rock_Stone_Brick"
    },
    {
      "x": -29,
      "y": 2,
      "z": 8,
      "name": "Rock_Quartzite"
    },
    {
      "x": -29,
      "y": 3,
      "z": 8,
      "name": "Rock_Quartzite"
    },
    {
      "x": -29,
      "y": 4,
      "z": 8,
      "name": "Wood_Softwood_Planks"
    },
    {
      "x": -29,
      "y": 5,
      "z": 8,
      "name": "Rock_Quartzite"
    },
    {
      "x": -29,
      "y": 6,
      "z": 8,
      "name": "Rock_Quartzite"
    },
    {
      "x": -29,
      "y": 7,
      "z": 8,
      "name": "Rock_Quartzite"
    },
    {
      "x": -29,
      "y": 8,
      "z": 8,
      "name": "Wood_Softwood_Planks"
    },
    {
      "x": -29,
      "y": 9,
      "z": 8,
      "name": "Wood_Softwood_Roof_Steep",
      "rotation": 2
    },
    {
      "x": -29,
      "y": 10,
      "z": 8,
      "name": "Wood_Softwood_Roof_Steep",
      "filler": 1024,
      "rotation": 2
    },
    {
      "x": -29,
      "y": 0,
      "z": 9,
      "name": "Rock_Stone_Cobble"
    },
    {
      "x": -29,
      "y": 1,
      "z": 9,
      "name": "Wood_Oak_Trunk",
      "support": 15
    },
    {
      "x": -29,
      "y": 2,
      "z": 9,
      "name": "Wood_Oak_Trunk",
      "support": 15
    },
    {
      "x": -29,
      "y": 3,
      "z": 9,
      "name": "Wood_Oak_Trunk",
      "support": 15
    },
    {
      "x": -29,
      "y": 4,
      "z": 9,
      "name": "Wood_Softwood_Planks"
    },
    {
      "x": -29,
      "y": 5,
      "z": 9,
      "name": "Rock_Quartzite"
    },
    {
      "x": -29,
      "y": 6,
      "z": 9,
      "name": "Rock_Quartzite"
    },
    {
      "x": -29,
      "y": 7,
      "z": 9,
      "name": "Rock_Quartzite"
    },
    {
      "x": -29,
      "y": 8,
      "z": 9,
      "name": "Wood_Softwood_Planks"
    },
    {
      "x": -29,
      "y": 9,
      "z": 9,
      "name": "Rock_Quartzite"
    },
    {
      "x": -29,
      "y": 10,
      "z": 9,
      "name": "Rock_Quartzite"
    },
    {
      "x": -29,
      "y": 11,
      "z": 9,
      "name": "Wood_Softwood_Roof",
      "rotation": 2
    },
    {
      "x": -29,
      "y": 0,
      "z": 10,
      "name": "Rock_Stone_Cobble"
    },
    {
      "x": -29,
      "y": 1,
      "z": 10,
      "name": "Rock_Stone_Brick"
    },
    {
      "x": -29,
      "y": 2,
      "z": 10,
      "name": "Rock_Quartzite"
    },
    {
      "x": -29,
      "y": 3,
      "z": 10,
      "name": "Rock_Quartzite"
    },
    {
      "x": -29,
      "y": 4,
      "z": 10,
      "name": "Wood_Softwood_Planks"
    },
    {
      "x": -29,
      "y": 5,
      "z": 10,
      "name": "Rock_Quartzite"
    },
    {
      "x": -29,
      "y": 6,
      "z": 10,
      "name": "Rock_Quartzite"
    },
    {
      "x": -29,
      "y": 7,
      "z": 10,
      "name": "Rock_Quartzite"
    },
    {
      "x": -29,
      "y": 8,
      "z": 10,
      "name": "Wood_Softwood_Planks"
    },
    {
      "x": -29,
      "y": 9,
      "z": 10,
      "name": "Rock_Quartzite"
    },
    {
      "x": -29,
      "y": 10,
      "z": 10,
      "name": "Rock_Quartzite"
    },
    {
      "x": -29,
      "y": 11,
      "z": 10,
      "name": "Rock_Quartzite"
    },
    {
      "x": -29,
      "y": 12,
      "z": 10,
      "name": "Wood_Softwood_Roof",
      "rotation": 2
    },
    {
      "x": -29,
      "y": 0,
      "z": 11,
      "name": "Rock_Stone_Cobble"
    },
    {
      "x": -29,
      "y": 1,
      "z": 11,
      "name": "Rock_Stone_Brick"
    },
    {
      "x": -29,
      "y": 2,
      "z": 11,
      "name": "Rock_Quartzite"
    },
    {
      "x": -29,
      "y": 3,
      "z": 11,
      "name": "Rock_Quartzite"
    },
    {
      "x": -29,
      "y": 4,
      "z": 11,
      "name": "Wood_Softwood_Planks"
    },
    {
      "x": -29,
      "y": 5,
      "z": 11,
      "name": "Wood_Oak_Trunk",
      "support": 15
    },
    {
      "x": -29,
      "y": 6,
      "z": 11,
      "name": "Wood_Oak_Trunk",
      "support": 15
    },
    {
      "x": -29,
      "y": 7,
      "z": 11,
      "name": "Wood_Oak_Trunk",
      "support": 15
    },
    {
      "x": -29,
      "y": 8,
      "z": 11,
      "name": "Wood_Softwood_Planks"
    },
    {
      "x": -29,
      "y": 9,
      "z": 11,
      "name": "Wood_Oak_Trunk",
      "support": 15
    },
    {
      "x": -29,
      "y": 10,
      "z": 11,
      "name": "Wood_Oak_Trunk",
      "support": 15
    },
    {
      "x": -29,
      "y": 11,
      "z": 11,
      "name": "Wood_Oak_Trunk",
      "support": 15
    },
    {
      "x": -29,
      "y": 13,
      "z": 11,
      "name": "Wood_Softwood_Planks_Half"
    },
    {
      "x": -29,
      "y": 0,
      "z": 12,
      "name": "Rock_Stone_Cobble"
    },
    {
      "x": -29,
      "y": 1,
      "z": 12,
      "name": "Rock_Stone_Brick"
    },
    {
      "x": -29,
      "y": 2,
      "z": 12,
      "name": "Rock_Quartzite"
    },
    {
      "x": -29,
      "y": 3,
      "z": 12,
      "name": "Rock_Quartzite"
    },
    {
      "x": -29,
      "y": 4,
      "z": 12,
      "name": "Wood_Softwood_Planks"
    },
    {
      "x": -29,
      "y": 5,
      "z": 12,
      "name": "Rock_Quartzite"
    },
    {
      "x": -29,
      "y": 6,
      "z": 12,
      "name": "Rock_Quartzite"
    },
    {
      "x": -29,
      "y": 7,
      "z": 12,
      "name": "Rock_Quartzite"
    },
    {
      "x": -29,
      "y": 8,
      "z": 12,
      "name": "Rock_Quartzite"
    },
    {
      "x": -29,
      "y": 9,
      "z": 12,
      "name": "Rock_Quartzite"
    },
    {
      "x": -29,
      "y": 10,
      "z": 12,
      "name": "Rock_Quartzite"
    },
    {
      "x": -29,
      "y": 11,
      "z": 12,
      "name": "Rock_Quartzite"
    },
    {
      "x": -29,
      "y": 12,
      "z": 12,
      "name": "Wood_Softwood_Roof"
    },
    {
      "x": -29,
      "y": 0,
      "z": 13,
      "name": "Rock_Stone_Cobble"
    },
    {
      "x": -29,
      "y": 1,
      "z": 13,
      "name": "Wood_Oak_Trunk",
      "support": 15
    },
    {
      "x": -29,
      "y": 2,
      "z": 13,
      "name": "Wood_Oak_Trunk",
      "support": 15
    },
    {
      "x": -29,
      "y": 3,
      "z": 13,
      "name": "Wood_Oak_Trunk",
      "support": 15
    },
    {
      "x": -29,
      "y": 4,
      "z": 13,
      "name": "Wood_Softwood_Planks"
    },
    {
      "x": -29,
      "y": 5,
      "z": 13,
      "name": "Rock_Quartzite"
    },
    {
      "x": -29,
      "y": 6,
      "z": 13,
      "name": "Furniture_Tavern_Window",
      "rotation": 1
    },
    {
      "x": -29,
      "y": 7,
      "z": 13,
      "name": "Furniture_Tavern_Window",
      "rotation": 1
    },
    {
      "x": -29,
      "y": 8,
      "z": 13,
      "name": "Rock_Quartzite"
    },
    {
      "x": -29,
      "y": 9,
      "z": 13,
      "name": "Rock_Quartzite"
    },
    {
      "x": -29,
      "y": 10,
      "z": 13,
      "name": "Rock_Quartzite"
    },
    {
      "x": -29,
      "y": 11,
      "z": 13,
      "name": "Wood_Softwood_Roof"
    },
    {
      "x": -29,
      "y": 0,
      "z": 14,
      "name": "Rock_Stone_Cobble"
    },
    {
      "x": -29,
      "y": 1,
      "z": 14,
      "name": "Rock_Stone_Brick"
    },
    {
      "x": -29,
      "y": 2,
      "z": 14,
      "name": "Rock_Quartzite"
    },
    {
      "x": -29,
      "y": 3,
      "z": 14,
      "name": "Rock_Quartzite"
    },
    {
      "x": -29,
      "y": 4,
      "z": 14,
      "name": "Wood_Softwood_Planks"
    },
    {
      "x": -29,
      "y": 5,
      "z": 14,
      "name": "Rock_Quartzite"
    },
    {
      "x": -29,
      "y": 6,
      "z": 14,
      "name": "Rock_Quartzite"
    },
    {
      "x": -29,
      "y": 7,
      "z": 14,
      "name": "Rock_Quartzite"
    },
    {
      "x": -29,
      "y": 8,
      "z": 14,
      "name": "Rock_Quartzite"
    },
    {
      "x": -29,
      "y": 9,
      "z": 14,
      "name": "Wood_Softwood_Roof_Steep"
    },
    {
      "x": -29,
      "y": 10,
      "z": 14,
      "name": "Wood_Softwood_Roof_Steep",
      "filler": 1024
    },
    {
      "x": -29,
      "y": 0,
      "z": 15,
      "name": "Rock_Stone_Cobble"
    },
    {
      "x": -29,
      "y": 1,
      "z": 15,
      "name": "Rock_Stone_Brick"
    },
    {
      "x": -29,
      "y": 2,
      "z": 15,
      "name": "Rock_Quartzite"
    },
    {
      "x": -29,
      "y": 3,
      "z": 15,
      "name": "Rock_Quartzite"
    },
    {
      "x": -29,
      "y": 4,
      "z": 15,
      "name": "Wood_Softwood_Planks"
    },
    {
      "x": -29,
      "y": 5,
      "z": 15,
      "name": "Rock_Quartzite"
    },
    {
      "x": -29,
      "y": 6,
      "z": 15,
      "name": "Rock_Quartzite"
    },
    {
      "x": -29,
      "y": 7,
      "z": 15,
      "name": "Wood_Softwood_Roof_Steep"
    },
    {
      "x": -29,
      "y": 8,
      "z": 15,
      "name": "Wood_Softwood_Roof_Steep",
      "filler": 1024
    },
    {
      "x": -29,
      "y": 4,
      "z": 16,
      "name": "Wood_Oak_Trunk",
      "support": 15,
      "rotation": 5
    },
    {
      "x": -29,
      "y": 5,
      "z": 16,
      "name": "Wood_Softwood_Roof_Steep"
    },
    {
      "x": -29,
      "y": 6,
      "z": 16,
      "name": "Wood_Softwood_Roof_Steep",
      "filler": 1024
    },
    {
      "x": -29,
      "y": 4,
      "z": 17,
      "name": "Wood_Softwood_Roof_Hollow"
    },
    {
      "x": -28,
      "y": 4,
      "z": 5,
      "name": "Wood_Softwood_Roof_Hollow",
      "rotation": 2
    },
    {
      "x": -28,
      "y": 5,
      "z": 5,
      "name": "Wood_Softwood_Roof_Steep",
      "rotation": 3
    },
    {
      "x": -28,
      "y": 6,
      "z": 5,
      "name": "Wood_Softwood_Roof_Steep",
      "filler": 1024,
      "rotation": 3
    },
    {
      "x": -28,
      "y": 4,
      "z": 6,
      "name": "Wood_Oak_Trunk",
      "support": 15,
      "rotation": 5
    },
    {
      "x": -28,
      "y": 5,
      "z": 6,
      "name": "*Wood_Softwood_Roof_Steep_State_Definitions_Inverted_Corner_Right",
      "rotation": 3
    },
    {
      "x": -28,
      "y": 6,
      "z": 6,
      "name": "*Wood_Softwood_Roof_Steep_State_Definitions_Inverted_Corner_Right",
      "filler": 1024,
      "rotation": 3
    },
    {
      "x": -28,
      "y": 0,
      "z": 7,
      "name": "Rock_Stone_Cobble"
    },
    {
      "x": -28,
      "y": 1,
      "z": 7,
      "name": "Rock_Stone_Brick"
    },
    {
      "x": -28,
      "y": 2,
      "z": 7,
      "name": "Furniture_Tavern_Window"
    },
    {
      "x": -28,
      "y": 3,
      "z": 7,
      "name": "Furniture_Tavern_Window"
    },
    {
      "x": -28,
      "y": 4,
      "z": 7,
      "name": "Wood_Softwood_Planks"
    },
    {
      "x": -28,
      "y": 5,
      "z": 7,
      "name": "Rock_Quartzite"
    },
    {
      "x": -28,
      "y": 6,
      "z": 7,
      "name": "Rock_Quartzite"
    },
    {
      "x": -28,
      "y": 7,
      "z": 7,
      "name": "Wood_Softwood_Roof_Steep",
      "rotation": 2
    },
    {
      "x": -28,
      "y": 8,
      "z": 7,
      "name": "Wood_Softwood_Roof_Steep",
      "filler": 1024,
      "rotation": 2
    },
    {
      "x": -28,
      "y": 0,
      "z": 8,
      "name": "Wood_Softwood_Planks"
    },
    {
      "x": -28,
      "y": 4,
      "z": 8,
      "name": "Wood_Softwood_Planks"
    },
    {
      "x": -28,
      "y": 5,
      "z": 8,
      "name": "Furniture_Tavern_Bed",
      "filler": 992,
      "rotation": 1
    },
    {
      "x": -28,
      "y": 6,
      "z": 8,
      "name": "Furniture_Tavern_Bed",
      "filler": 2016,
      "rotation": 1
    },
    {
      "x": -28,
      "y": 8,
      "z": 8,
      "name": "Wood_Softwood_Planks"
    },
    {
      "x": -28,
      "y": 9,
      "z": 8,
      "name": "Wood_Softwood_Roof_Steep",
      "rotation": 2
    },
    {
      "x": -28,
      "y": 10,
      "z": 8,
      "name": "Wood_Softwood_Roof_Steep",
      "filler": 1024,
      "rotation": 2
    },
    {
      "x": -28,
      "y": 0,
      "z": 9,
      "name": "Wood_Softwood_Planks"
    },
    {
      "x": -28,
      "y": 1,
      "z": 9,
      "name": "Furniture_Tavern_Barrel"
    },
    {
      "x": -28,
      "y": 4,
      "z": 9,
      "name": "Wood_Softwood_Planks"
    },
    {
      "x": -28,
      "y": 5,
      "z": 9,
      "name": "Furniture_Tavern_Bed",
      "components": {
        "Components": {
          "PlacedByInteraction": {
            "WhoPlacedUuid": {
              "$binary": "gqJcCRGLSleXtmq6BvFR8g==",
              "$type": "04"
            }
          },
          "RespawnBlock": {}
        }
      },
      "rotation": 1
    },
    {
      "x": -28,
      "y": 6,
      "z": 9,
      "name": "Furniture_Tavern_Bed",
      "filler": 1024,
      "rotation": 1
    },
    {
      "x": -28,
      "y": 8,
      "z": 9,
      "name": "Wood_Softwood_Planks"
    },
    {
      "x": -28,
      "y": 11,
      "z": 9,
      "name": "Wood_Softwood_Roof_Hollow",
      "rotation": 2
    },
    {
      "x": -28,
      "y": 0,
      "z": 10,
      "name": "Wood_Softwood_Planks"
    },
    {
      "x": -28,
      "y": 1,
      "z": 10,
      "name": "Rock_Stone_Brick"
    },
    {
      "x": -28,
      "y": 2,
      "z": 10,
      "name": "Rock_Quartzite"
    },
    {
      "x": -28,
      "y": 3,
      "z": 10,
      "name": "Rock_Quartzite"
    },
    {
      "x": -28,
      "y": 4,
      "z": 10,
      "name": "Wood_Softwood_Planks"
    },
    {
      "x": -28,
      "y": 5,
      "z": 10,
      "name": "Furniture_Village_Wardrobe",
      "rotation": 1
    },
    {
      "x": -28,
      "y": 6,
      "z": 10,
      "name": "Furniture_Village_Wardrobe",
      "filler": 1024,
      "rotation": 1
    },
    {
      "x": -28,
      "y": 8,
      "z": 10,
      "name": "Wood_Softwood_Planks"
    },
    {
      "x": -28,
      "y": 12,
      "z": 10,
      "name": "Wood_Softwood_Roof_Hollow",
      "rotation": 2
    },
    {
      "x": -28,
      "y": 0,
      "z": 11,
      "name": "Wood_Softwood_Planks"
    },
    {
      "x": -28,
      "y": 1,
      "z": 11,
      "name": "Furniture_Village_Chair",
      "rotation": 1
    },
    {
      "x": -28,
      "y": 2,
      "z": 11,
      "name": "Furniture_Village_Chair",
      "filler": 1024,
      "rotation": 1
    },
    {
      "x": -28,
      "y": 4,
      "z": 11,
      "name": "Wood_Softwood_Planks"
    },
    {
      "x": -28,
      "y": 5,
      "z": 11,
      "name": "Furniture_Village_Wardrobe",
      "filler": 32,
      "rotation": 1
    },
    {
      "x": -28,
      "y": 6,
      "z": 11,
      "name": "Furniture_Village_Wardrobe",
      "filler": 1056,
      "rotation": 1
    },
    {
      "x": -28,
      "y": 8,
      "z": 11,
      "name": "Wood_Softwood_Planks"
    },
    {
      "x": -28,
      "y": 13,
      "z": 11,
      "name": "Wood_Softwood_Planks_Half"
    },
    {
      "x": -28,
      "y": 0,
      "z": 12,
      "name": "Wood_Softwood_Planks"
    },
    {
      "x": -28,
      "y": 1,
      "z": 12,
      "name": "Furniture_Tavern_Bed",
      "filler": 991,
      "rotation": 2
    },
    {
      "x": -28,
      "y": 2,
      "z": 12,
      "name": "Furniture_Tavern_Bed",
      "filler": 2015,
      "rotation": 2
    },
    {
      "x": -28,
      "y": 4,
      "z": 12,
      "name": "Wood_Softwood_Planks"
    },
    {
      "x": -28,
      "y": 5,
      "z": 12,
      "name": "Rock_Quartzite"
    },
    {
      "x": -28,
      "y": 6,
      "z": 12,
      "name": "Rock_Quartzite"
    },
    {
      "x": -28,
      "y": 7,
      "z": 12,
      "name": "Rock_Quartzite"
    },
    {
      "x": -28,
      "y": 8,
      "z": 12,
      "name": "Wood_Softwood_Planks"
    },
    {
      "x": -28,
      "y": 12,
      "z": 12,
      "name": "Wood_Softwood_Roof_Hollow"
    },
    {
      "x": -28,
      "y": 0,
      "z": 13,
      "name": "Wood_Softwood_Planks"
    },
    {
      "x": -28,
      "y": 1,
      "z": 13,
      "name": "Furniture_Tavern_Bed",
      "filler": 1023,
      "rotation": 2
    },
    {
      "x": -28,
      "y": 2,
      "z": 13,
      "name": "Furniture_Tavern_Bed",
      "filler": 2047,
      "rotation": 2
    },
    {
      "x": -28,
      "y": 4,
      "z": 13,
      "name": "Wood_Softwood_Planks"
    },
    {
      "x": -28,
      "y": 5,
      "z": 13,
      "name": "Furniture_Village_Counter",
      "rotation": 1
    },
    {
      "x": -28,
      "y": 8,
      "z": 13,
      "name": "Wood_Softwood_Planks"
    },
    {
      "x": -28,
      "y": 10,
      "z": 13,
      "name": "Wood_Softwood_Planks"
    },
    {
      "x": -28,
      "y": 11,
      "z": 13,
      "name": "Wood_Softwood_Roof"
    },
    {
      "x": -28,
      "y": 0,
      "z": 14,
      "name": "Wood_Softwood_Planks"
    },
    {
      "x": -28,
      "y": 1,
      "z": 14,
      "name": "Furniture_Tavern_Bed",
      "filler": 31,
      "rotation": 2
    },
    {
      "x": -28,
      "y": 2,
      "z": 14,
      "name": "Furniture_Tavern_Bed",
      "filler": 1055,
      "rotation": 2
    },
    {
      "x": -28,
      "y": 4,
      "z": 14,
      "name": "Wood_Softwood_Planks"
    },
    {
      "x": -28,
      "y": 5,
      "z": 14,
      "name": "Furniture_Village_Counter",
      "filler": 32,
      "rotation": 1
    },
    {
      "x": -28,
      "y": 8,
      "z": 14,
      "name": "Wood_Softwood_Planks"
    },
    {
      "x": -28,
      "y": 9,
      "z": 14,
      "name": "Wood_Softwood_Roof_Steep"
    },
    {
      "x": -28,
      "y": 10,
      "z": 14,
      "name": "Wood_Softwood_Roof_Steep",
      "filler": 1024
    },
    {
      "x": -28,
      "y": 0,
      "z": 15,
      "name": "Rock_Stone_Cobble"
    },
    {
      "x": -28,
      "y": 1,
      "z": 15,
      "name": "Rock_Stone_Brick"
    },
    {
      "x": -28,
      "y": 2,
      "z": 15,
      "name": "Furniture_Tavern_Window"
    },
    {
      "x": -28,
      "y": 3,
      "z": 15,
      "name": "Furniture_Tavern_Window"
    },
    {
      "x": -28,
      "y": 4,
      "z": 15,
      "name": "Wood_Softwood_Planks"
    },
    {
      "x": -28,
      "y": 5,
      "z": 15,
      "name": "Rock_Quartzite"
    },
    {
      "x": -28,
      "y": 6,
      "z": 15,
      "name": "Rock_Quartzite"
    },
    {
      "x": -28,
      "y": 7,
      "z": 15,
      "name": "Wood_Softwood_Roof_Steep"
    },
    {
      "x": -28,
      "y": 8,
      "z": 15,
      "name": "Wood_Softwood_Roof_Steep",
      "filler": 1024
    },
    {
      "x": -28,
      "y": 4,
      "z": 16,
      "name": "Wood_Oak_Trunk",
      "support": 15,
      "rotation": 5
    },
    {
      "x": -28,
      "y": 5,
      "z": 16,
      "name": "Wood_Softwood_Roof_Steep"
    },
    {
      "x": -28,
      "y": 6,
      "z": 16,
      "name": "Wood_Softwood_Roof_Steep",
      "filler": 1024
    },
    {
      "x": -28,
      "y": 4,
      "z": 17,
      "name": "Wood_Softwood_Roof_Hollow"
    },
    {
      "x": -27,
      "y": 4,
      "z": 5,
      "name": "Wood_Softwood_Roof_Hollow",
      "rotation": 2
    },
    {
      "x": -27,
      "y": 6,
      "z": 5,
      "name": "Wood_Softwood_Stairs",
      "rotation": 11
    },
    {
      "x": -27,
      "y": 7,
      "z": 5,
      "name": "Wood_Softwood_Roof_Steep",
      "rotation": 3
    },
    {
      "x": -27,
      "y": 8,
      "z": 5,
      "name": "Wood_Softwood_Roof_Steep",
      "filler": 1024,
      "rotation": 3
    },
    {
      "x": -27,
      "y": 4,
      "z": 6,
      "name": "Wood_Oak_Trunk",
      "support": 15,
      "rotation": 5
    },
    {
      "x": -27,
      "y": 6,
      "z": 6,
      "name": "Wood_Softwood_Stairs",
      "rotation": 11
    },
    {
      "x": -27,
      "y": 7,
      "z": 6,
      "name": "Wood_Softwood_Roof_Steep",
      "rotation": 3
    },
    {
      "x": -27,
      "y": 8,
      "z": 6,
      "name": "Wood_Softwood_Roof_Steep",
      "filler": 1024,
      "rotation": 3
    },
    {
      "x": -27,
      "y": 0,
      "z": 7,
      "name": "Rock_Stone_Cobble"
    },
    {
      "x": -27,
      "y": 1,
      "z": 7,
      "name": "Rock_Stone_Brick"
    },
    {
      "x": -27,
      "y": 2,
      "z": 7,
      "name": "Rock_Quartzite"
    },
    {
      "x": -27,
      "y": 3,
      "z": 7,
      "name": "Rock_Quartzite"
    },
    {
      "x": -27,
      "y": 4,
      "z": 7,
      "name": "Wood_Softwood_Planks"
    },
    {
      "x": -27,
      "y": 5,
      "z": 7,
      "name": "Rock_Quartzite"
    },
    {
      "x": -27,
      "y": 6,
      "z": 7,
      "name": "Rock_Quartzite"
    },
    {
      "x": -27,
      "y": 7,
      "z": 7,
      "name": "*Wood_Softwood_Roof_Steep_State_Definitions_Inverted_Corner_Right",
      "rotation": 3
    },
    {
      "x": -27,
      "y": 8,
      "z": 7,
      "name": "*Wood_Softwood_Roof_Steep_State_Definitions_Inverted_Corner_Right",
      "filler": 1024,
      "rotation": 3
    },
    {
      "x": -27,
      "y": 0,
      "z": 8,
      "name": "Wood_Softwood_Planks"
    },
    {
      "x": -27,
      "y": 4,
      "z": 8,
      "name": "Wood_Softwood_Planks"
    },
    {
      "x": -27,
      "y": 5,
      "z": 8,
      "name": "Furniture_Tavern_Bed",
      "filler": 993,
      "rotation": 1
    },
    {
      "x": -27,
      "y": 6,
      "z": 8,
      "name": "Furniture_Tavern_Bed",
      "filler": 2017,
      "rotation": 1
    },
    {
      "x": -27,
      "y": 8,
      "z": 8,
      "name": "Wood_Softwood_Planks"
    },
    {
      "x": -27,
      "y": 9,
      "z": 8,
      "name": "Wood_Softwood_Roof_Steep",
      "rotation": 2
    },
    {
      "x": -27,
      "y": 10,
      "z": 8,
      "name": "Wood_Softwood_Roof_Steep",
      "filler": 1024,
      "rotation": 2
    },
    {
      "x": -27,
      "y": 0,
      "z": 9,
      "name": "Wood_Softwood_Planks"
    },
    {
      "x": -27,
      "y": 1,
      "z": 9,
      "name": "Furniture_Tavern_Barrel"
    },
    {
      "x": -27,
      "y": 4,
      "z": 9,
      "name": "Wood_Softwood_Planks"
    },
    {
      "x": -27,
      "y": 5,
      "z": 9,
      "name": "Furniture_Tavern_Bed",
      "filler": 1,
      "rotation": 1
    },
    {
      "x": -27,
      "y": 6,
      "z": 9,
      "name": "Furniture_Tavern_Bed",
      "filler": 1025,
      "rotation": 1
    },
    {
      "x": -27,
      "y": 8,
      "z": 9,
      "name": "Wood_Softwood_Planks"
    },
    {
      "x": -27,
      "y": 11,
      "z": 9,
      "name": "Wood_Softwood_Roof_Hollow",
      "rotation": 2
    },
    {
      "x": -27,
      "y": 0,
      "z": 10,
      "name": "Wood_Softwood_Planks"
    },
    {
      "x": -27,
      "y": 1,
      "z": 10,
      "name": "Rock_Stone_Brick"
    },
    {
      "x": -27,
      "y": 2,
      "z": 10,
      "name": "Rock_Quartzite"
    },
    {
      "x": -27,
      "y": 3,
      "z": 10,
      "name": "Rock_Quartzite"
    },
    {
      "x": -27,
      "y": 4,
      "z": 10,
      "name": "Wood_Softwood_Planks"
    },
    {
      "x": -27,
      "y": 8,
      "z": 10,
      "name": "Wood_Softwood_Planks"
    },
    {
      "x": -27,
      "y": 12,
      "z": 10,
      "name": "Wood_Softwood_Roof_Hollow",
      "rotation": 2
    },
    {
      "x": -27,
      "y": 0,
      "z": 11,
      "name": "Wood_Softwood_Planks"
    },
    {
      "x": -27,
      "y": 4,
      "z": 11,
      "name": "Wood_Softwood_Planks"
    },
    {
      "x": -27,
      "y": 8,
      "z": 11,
      "name": "Wood_Softwood_Planks"
    },
    {
      "x": -27,
      "y": 13,
      "z": 11,
      "name": "Wood_Softwood_Planks_Half"
    },
    {
      "x": -27,
      "y": 0,
      "z": 12,
      "name": "Wood_Softwood_Planks"
    },
    {
      "x": -27,
      "y": 1,
      "z": 12,
      "name": "Furniture_Tavern_Bed",
      "filler": 960,
      "rotation": 2
    },
    {
      "x": -27,
      "y": 2,
      "z": 12,
      "name": "Furniture_Tavern_Bed",
      "filler": 1984,
      "rotation": 2
    },
    {
      "x": -27,
      "y": 4,
      "z": 12,
      "name": "Wood_Softwood_Planks"
    },
    {
      "x": -27,
      "y": 5,
      "z": 12,
      "name": "Rock_Quartzite"
    },
    {
      "x": -27,
      "y": 6,
      "z": 12,
      "name": "Rock_Quartzite"
    },
    {
      "x": -27,
      "y": 7,
      "z": 12,
      "name": "Rock_Quartzite"
    },
    {
      "x": -27,
      "y": 8,
      "z": 12,
      "name": "Wood_Softwood_Planks"
    },
    {
      "x": -27,
      "y": 12,
      "z": 12,
      "name": "Wood_Softwood_Roof_Hollow"
    },
    {
      "x": -27,
      "y": 0,
      "z": 13,
      "name": "Wood_Softwood_Planks"
    },
    {
      "x": -27,
      "y": 1,
      "z": 13,
      "name": "Furniture_Tavern_Bed",
      "filler": 992,
      "rotation": 2
    },
    {
      "x": -27,
      "y": 2,
      "z": 13,
      "name": "Furniture_Tavern_Bed",
      "filler": 2016,
      "rotation": 2
    },
    {
      "x": -27,
      "y": 4,
      "z": 13,
      "name": "Wood_Softwood_Planks"
    },
    {
      "x": -27,
      "y": 8,
      "z": 13,
      "name": "Wood_Softwood_Planks"
    },
    {
      "x": -27,
      "y": 10,
      "z": 13,
      "name": "Wood_Softwood_Planks"
    },
    {
      "x": -27,
      "y": 11,
      "z": 13,
      "name": "Wood_Softwood_Roof"
    },
    {
      "x": -27,
      "y": 0,
      "z": 14,
      "name": "Wood_Softwood_Planks"
    },
    {
      "x": -27,
      "y": 1,
      "z": 14,
      "name": "Furniture_Tavern_Bed",
      "components": {
        "Components": {
          "PlacedByInteraction": {
            "WhoPlacedUuid": {
              "$binary": "gqJcCRGLSleXtmq6BvFR8g==",
              "$type": "04"
            }
          },
          "RespawnBlock": {}
        }
      },
      "rotation": 2
    },
    {
      "x": -27,
      "y": 2,
      "z": 14,
      "name": "Furniture_Tavern_Bed",
      "filler": 1024,
      "rotation": 2
    },
    {
      "x": -27,
      "y": 4,
      "z": 14,
      "name": "Wood_Softwood_Planks"
    },
    {
      "x": -27,
      "y": 5,
      "z": 14,
      "name": "Furniture_Village_Counter",
      "rotation": 2
    },
    {
      "x": -27,
      "y": 8,
      "z": 14,
      "name": "Wood_Softwood_Planks"
    },
    {
      "x": -27,
      "y": 9,
      "z": 14,
      "name": "Wood_Softwood_Roof_Steep"
    },
    {
      "x": -27,
      "y": 10,
      "z": 14,
      "name": "Wood_Softwood_Roof_Steep",
      "filler": 1024
    },
    {
      "x": -27,
      "y": 0,
      "z": 15,
      "name": "Rock_Stone_Cobble"
    },
    {
      "x": -27,
      "y": 1,
      "z": 15,
      "name": "Rock_Stone_Brick"
    },
    {
      "x": -27,
      "y": 2,
      "z": 15,
      "name": "Rock_Quartzite"
    },
    {
      "x": -27,
      "y": 3,
      "z": 15,
      "name": "Rock_Quartzite"
    },
    {
      "x": -27,
      "y": 4,
      "z": 15,
      "name": "Wood_Softwood_Planks"
    },
    {
      "x": -27,
      "y": 5,
      "z": 15,
      "name": "Rock_Quartzite"
    },
    {
      "x": -27,
      "y": 6,
      "z": 15,
      "name": "Rock_Quartzite"
    },
    {
      "x": -27,
      "y": 7,
      "z": 15,
      "name": "Wood_Softwood_Roof_Steep"
    },
    {
      "x": -27,
      "y": 8,
      "z": 15,
      "name": "Wood_Softwood_Roof_Steep",
      "filler": 1024
    },
    {
      "x": -27,
      "y": 4,
      "z": 16,
      "name": "Wood_Oak_Trunk",
      "support": 15,
      "rotation": 5
    },
    {
      "x": -27,
      "y": 5,
      "z": 16,
      "name": "Wood_Softwood_Roof_Steep"
    },
    {
      "x": -27,
      "y": 6,
      "z": 16,
      "name": "Wood_Softwood_Roof_Steep",
      "filler": 1024
    },
    {
      "x": -27,
      "y": 4,
      "z": 17,
      "name": "Wood_Softwood_Roof_Hollow"
    },
    {
      "x": -26,
      "y": 4,
      "z": 5,
      "name": "Wood_Softwood_Roof_Hollow",
      "rotation": 2
    },
    {
      "x": -26,
      "y": 8,
      "z": 5,
      "name": "Wood_Softwood_Stairs",
      "rotation": 11
    },
    {
      "x": -26,
      "y": 9,
      "z": 5,
      "name": "Wood_Softwood_Roof",
      "rotation": 3
    },
    {
      "x": -26,
      "y": 4,
      "z": 6,
      "name": "Wood_Oak_Trunk",
      "support": 15,
      "rotation": 5
    },
    {
      "x": -26,
      "y": 8,
      "z": 6,
      "name": "Wood_Oak_Trunk",
      "support": 15,
      "rotation": 5
    },
    {
      "x": -26,
      "y": 9,
      "z": 6,
      "name": "Wood_Softwood_Roof",
      "rotation": 3
    },
    {
      "x": -26,
      "y": 0,
      "z": 7,
      "name": "Rock_Stone_Cobble"
    },
    {
      "x": -26,
      "y": 1,
      "z": 7,
      "name": "Wood_Oak_Trunk",
      "support": 15
    },
    {
      "x": -26,
      "y": 2,
      "z": 7,
      "name": "Wood_Oak_Trunk",
      "support": 15
    },
    {
      "x": -26,
      "y": 3,
      "z": 7,
      "name": "Wood_Oak_Trunk",
      "support": 15
    },
    {
      "x": -26,
      "y": 4,
      "z": 7,
      "name": "Wood_Softwood_Planks"
    },
    {
      "x": -26,
      "y": 5,
      "z": 7,
      "name": "Rock_Quartzite"
    },
    {
      "x": -26,
      "y": 6,
      "z": 7,
      "name": "Furniture_Tavern_Window"
    },
    {
      "x": -26,
      "y": 7,
      "z": 7,
      "name": "Furniture_Tavern_Window"
    },
    {
      "x": -26,
      "y": 8,
      "z": 7,
      "name": "Wood_Softwood_Planks"
    },
    {
      "x": -26,
      "y": 9,
      "z": 7,
      "name": "Wood_Softwood_Roof",
      "rotation": 3
    },
    {
      "x": -26,
      "y": 0,
      "z": 8,
      "name": "Wood_Softwood_Planks"
    },
    {
      "x": -26,
      "y": 4,
      "z": 8,
      "name": "Wood_Softwood_Planks"
    },
    {
      "x": -26,
      "y": 5,
      "z": 8,
      "name": "Furniture_Tavern_Bed",
      "filler": 994,
      "rotation": 1
    },
    {
      "x": -26,
      "y": 6,
      "z": 8,
      "name": "Furniture_Tavern_Bed",
      "filler": 2018,
      "rotation": 1
    },
    {
      "x": -26,
      "y": 8,
      "z": 8,
      "name": "Wood_Softwood_Planks"
    },
    {
      "x": -26,
      "y": 9,
      "z": 8,
      "name": "Wood_Softwood_Roof_Steep",
      "rotation": 2
    },
    {
      "x": -26,
      "y": 10,
      "z": 8,
      "name": "Wood_Softwood_Roof_Steep",
      "filler": 1024,
      "rotation": 2
    },
    {
      "x": -26,
      "y": 0,
      "z": 9,
      "name": "Wood_Softwood_Planks"
    },
    {
      "x": -26,
      "y": 4,
      "z": 9,
      "name": "Wood_Softwood_Planks"
    },
    {
      "x": -26,
      "y": 5,
      "z": 9,
      "name": "Furniture_Tavern_Bed",
      "filler": 2,
      "rotation": 1
    },
    {
      "x": -26,
      "y": 6,
      "z": 9,
      "name": "Furniture_Tavern_Bed",
      "filler": 1026,
      "rotation": 1
    },
    {
      "x": -26,
      "y": 8,
      "z": 9,
      "name": "Wood_Softwood_Planks"
    },
    {
      "x": -26,
      "y": 11,
      "z": 9,
      "name": "Wood_Softwood_Roof_Hollow",
      "rotation": 2
    },
    {
      "x": -26,
      "y": 0,
      "z": 10,
      "name": "Wood_Softwood_Planks"
    },
    {
      "x": -26,
      "y": 1,
      "z": 10,
      "name": "*Furniture_Village_Door_State_Definitions_CloseDoorIn"
    },
    {
      "x": -26,
      "y": 2,
      "z": 10,
      "name": "*Furniture_Village_Door_State_Definitions_CloseDoorIn",
      "filler": 1024
    },
    {
      "x": -26,
      "y": 3,
      "z": 10,
      "name": "Rock_Quartzite"
    },
    {
      "x": -26,
      "y": 4,
      "z": 10,
      "name": "Wood_Softwood_Planks"
    },
    {
      "x": -26,
      "y": 8,
      "z": 10,
      "name": "Wood_Softwood_Planks"
    },
    {
      "x": -26,
      "y": 12,
      "z": 10,
      "name": "Wood_Softwood_Roof_Hollow",
      "rotation": 2
    },
    {
      "x": -26,
      "y": 0,
      "z": 11,
      "name": "Wood_Softwood_Planks"
    },
    {
      "x": -26,
      "y": 4,
      "z": 11,
      "name": "Wood_Softwood_Planks"
    },
    {
      "x": -26,
      "y": 8,
      "z": 11,
      "name": "Wood_Softwood_Planks"
    },
    {
      "x": -26,
      "y": 13,
      "z": 11,
      "name": "Wood_Softwood_Planks_Half"
    },
    {
      "x": -26,
      "y": 0,
      "z": 12,
      "name": "Wood_Softwood_Planks"
    },
    {
      "x": -26,
      "y": 4,
      "z": 12,
      "name": "Wood_Softwood_Planks"
    },
    {
      "x": -26,
      "y": 5,
      "z": 12,
      "name": "*Furniture_Village_Door_State_Definitions_CloseDoorIn"
    },
    {
      "x": -26,
      "y": 6,
      "z": 12,
      "name": "*Furniture_Village_Door_State_Definitions_CloseDoorIn",
      "filler": 1024
    },
    {
      "x": -26,
      "y": 7,
      "z": 12,
      "name": "Rock_Quartzite"
    },
    {
      "x": -26,
      "y": 8,
      "z": 12,
      "name": "Wood_Softwood_Planks"
    },
    {
      "x": -26,
      "y": 12,
      "z": 12,
      "name": "Wood_Softwood_Roof_Hollow"
    },
    {
      "x": -26,
      "y": 0,
      "z": 13,
      "name": "Wood_Softwood_Planks"
    },
    {
      "x": -26,
      "y": 4,
      "z": 13,
      "name": "Wood_Softwood_Planks"
    },
    {
      "x": -26,
      "y": 8,
      "z": 13,
      "name": "Wood_Softwood_Planks"
    },
    {
      "x": -26,
      "y": 10,
      "z": 13,
      "name": "Wood_Softwood_Planks"
    },
    {
      "x": -26,
      "y": 11,
      "z": 13,
      "name": "Wood_Softwood_Roof"
    },
    {
      "x": -26,
      "y": 0,
      "z": 14,
      "name": "Wood_Softwood_Planks"
    },
    {
      "x": -26,
      "y": 1,
      "z": 14,
      "name": "Furniture_Tavern_Chest_Small",
      "components": {
        "Components": {
          "PlacedByInteraction": {
            "WhoPlacedUuid": {
              "$binary": "gqJcCRGLSleXtmq6BvFR8g==",
              "$type": "04"
            }
          },
          "ItemContainerBlock": {
            "ItemContainer": {
              "Capacity": 18,
              "Items": {}
            },
            "Capacity": 18
          }
        }
      },
      "rotation": 2
    },
    {
      "x": -26,
      "y": 4,
      "z": 14,
      "name": "Wood_Softwood_Planks"
    },
    {
      "x": -26,
      "y": 5,
      "z": 14,
      "name": "Furniture_Village_Counter",
      "filler": 1,
      "rotation": 2
    },
    {
      "x": -26,
      "y": 8,
      "z": 14,
      "name": "Wood_Softwood_Planks"
    },
    {
      "x": -26,
      "y": 9,
      "z": 14,
      "name": "Wood_Softwood_Roof_Steep"
    },
    {
      "x": -26,
      "y": 10,
      "z": 14,
      "name": "Wood_Softwood_Roof_Steep",
      "filler": 1024
    },
    {
      "x": -26,
      "y": 0,
      "z": 15,
      "name": "Rock_Stone_Cobble"
    },
    {
      "x": -26,
      "y": 1,
      "z": 15,
      "name": "Wood_Oak_Trunk",
      "support": 15
    },
    {
      "x": -26,
      "y": 2,
      "z": 15,
      "name": "Wood_Oak_Trunk",
      "support": 15
    },
    {
      "x": -26,
      "y": 3,
      "z": 15,
      "name": "Wood_Oak_Trunk",
      "support": 15
    },
    {
      "x": -26,
      "y": 4,
      "z": 15,
      "name": "Wood_Softwood_Planks"
    },
    {
      "x": -26,
      "y": 5,
      "z": 15,
      "name": "Rock_Quartzite"
    },
    {
      "x": -26,
      "y": 6,
      "z": 15,
      "name": "Rock_Quartzite"
    },
    {
      "x": -26,
      "y": 7,
      "z": 15,
      "name": "Wood_Softwood_Roof_Steep"
    },
    {
      "x": -26,
      "y": 8,
      "z": 15,
      "name": "Wood_Softwood_Roof_Steep",
      "filler": 1024
    },
    {
      "x": -26,
      "y": 4,
      "z": 16,
      "name": "Wood_Oak_Trunk",
      "support": 15,
      "rotation": 5
    },
    {
      "x": -26,
      "y": 5,
      "z": 16,
      "name": "Wood_Softwood_Roof_Steep"
    },
    {
      "x": -26,
      "y": 6,
      "z": 16,
      "name": "Wood_Softwood_Roof_Steep",
      "filler": 1024
    },
    {
      "x": -26,
      "y": 4,
      "z": 17,
      "name": "Wood_Softwood_Roof_Hollow"
    },
    {
      "x": -25,
      "y": 10,
      "z": 4,
      "name": "Wood_Softwood_Stairs",
      "rotation": 8
    },
    {
      "x": -25,
      "y": 4,
      "z": 5,
      "name": "Wood_Softwood_Roof_Hollow",
      "rotation": 2
    },
    {
      "x": -25,
      "y": 8,
      "z": 5,
      "name": "Wood_Oak_Branch_Short",
      "support": 15,
      "rotation": 2
    },
    {
      "x": -25,
      "y": 9,
      "z": 5,
      "name": "Wood_Softwood_Planks_Half",
      "rotation": 8
    },
    {
      "x": -25,
      "y": 10,
      "z": 5,
      "name": "Wood_Softwood_Stairs"
    },
    {
      "x": -25,
      "y": 4,
      "z": 6,
      "name": "Wood_Oak_Trunk",
      "support": 15,
      "rotation": 5
    },
    {
      "x": -25,
      "y": 8,
      "z": 6,
      "name": "Wood_Oak_Trunk",
      "support": 15,
      "rotation": 5
    },
    {
      "x": -25,
      "y": 9,
      "z": 6,
      "name": "Wood_Softwood_Planks_Half",
      "rotation": 8
    },
    {
      "x": -25,
      "y": 10,
      "z": 6,
      "name": "Wood_Softwood_Planks_Half"
    },
    {
      "x": -25,
      "y": 0,
      "z": 7,
      "name": "Rock_Stone_Cobble"
    },
    {
      "x": -25,
      "y": 1,
      "z": 7,
      "name": "Rock_Stone_Brick"
    },
    {
      "x": -25,
      "y": 2,
      "z": 7,
      "name": "Rock_Quartzite"
    },
    {
      "x": -25,
      "y": 3,
      "z": 7,
      "name": "Rock_Quartzite"
    },
    {
      "x": -25,
      "y": 4,
      "z": 7,
      "name": "Wood_Softwood_Planks"
    },
    {
      "x": -25,
      "y": 5,
      "z": 7,
      "name": "Wood_Oak_Trunk",
      "support": 15
    },
    {
      "x": -25,
      "y": 6,
      "z": 7,
      "name": "Wood_Oak_Trunk",
      "support": 15
    },
    {
      "x": -25,
      "y": 7,
      "z": 7,
      "name": "Wood_Oak_Trunk",
      "support": 15
    },
    {
      "x": -25,
      "y": 8,
      "z": 7,
      "name": "Wood_Oak_Trunk",
      "support": 15
    },
    {
      "x": -25,
      "y": 9,
      "z": 7,
      "name": "Wood_Oak_Trunk",
      "support": 15
    },
    {
      "x": -25,
      "y": 10,
      "z": 7,
      "name": "Wood_Softwood_Planks_Half"
    },
    {
      "x": -25,
      "y": 0,
      "z": 8,
      "name": "Wood_Softwood_Planks"
    },
    {
      "x": -25,
      "y": 4,
      "z": 8,
      "name": "Wood_Softwood_Planks"
    },
    {
      "x": -25,
      "y": 5,
      "z": 8,
      "name": "Rock_Quartzite"
    },
    {
      "x": -25,
      "y": 6,
      "z": 8,
      "name": "Rock_Quartzite"
    },
    {
      "x": -25,
      "y": 7,
      "z": 8,
      "name": "Rock_Quartzite"
    },
    {
      "x": -25,
      "y": 8,
      "z": 8,
      "name": "Wood_Softwood_Planks"
    },
    {
      "x": -25,
      "y": 9,
      "z": 8,
      "name": "Wood_Softwood_Roof_Steep",
      "rotation": 2
    },
    {
      "x": -25,
      "y": 10,
      "z": 8,
      "name": "Wood_Softwood_Roof_Steep",
      "filler": 1024,
      "rotation": 2
    },
    {
      "x": -25,
      "y": 0,
      "z": 9,
      "name": "Wood_Softwood_Planks"
    },
    {
      "x": -25,
      "y": 2,
      "z": 9,
      "name": "Wood_Torch_Wall",
      "rotation": 2
    },
    {
      "x": -25,
      "y": 4,
      "z": 9,
      "name": "Wood_Softwood_Planks"
    },
    {
      "x": -25,
      "y": 5,
      "z": 9,
      "name": "Rock_Quartzite"
    },
    {
      "x": -25,
      "y": 6,
      "z": 9,
      "name": "Rock_Quartzite"
    },
    {
      "x": -25,
      "y": 7,
      "z": 9,
      "name": "Rock_Quartzite"
    },
    {
      "x": -25,
      "y": 8,
      "z": 9,
      "name": "Wood_Softwood_Planks"
    },
    {
      "x": -25,
      "y": 11,
      "z": 9,
      "name": "Wood_Softwood_Roof_Hollow",
      "rotation": 2
    },
    {
      "x": -25,
      "y": 0,
      "z": 10,
      "name": "Wood_Softwood_Planks"
    },
    {
      "x": -25,
      "y": 1,
      "z": 10,
      "name": "Wood_Oak_Trunk",
      "support": 15
    },
    {
      "x": -25,
      "y": 2,
      "z": 10,
      "name": "Wood_Oak_Trunk",
      "support": 15
    },
    {
      "x": -25,
      "y": 3,
      "z": 10,
      "name": "Wood_Oak_Trunk",
      "support": 15
    },
    {
      "x": -25,
      "y": 4,
      "z": 10,
      "name": "Wood_Softwood_Planks"
    },
    {
      "x": -25,
      "y": 5,
      "z": 10,
      "name": "Rock_Quartzite"
    },
    {
      "x": -25,
      "y": 6,
      "z": 10,
      "name": "Rock_Quartzite"
    },
    {
      "x": -25,
      "y": 7,
      "z": 10,
      "name": "Rock_Quartzite"
    },
    {
      "x": -25,
      "y": 8,
      "z": 10,
      "name": "Wood_Softwood_Planks"
    },
    {
      "x": -25,
      "y": 12,
      "z": 10,
      "name": "Wood_Softwood_Roof_Hollow",
      "rotation": 2
    },
    {
      "x": -25,
      "y": 0,
      "z": 11,
      "name": "Wood_Softwood_Planks"
    },
    {
      "x": -25,
      "y": 1,
      "z": 11,
      "name": "Rock_Stone_Brick"
    },
    {
      "x": -25,
      "y": 2,
      "z": 11,
      "name": "Rock_Quartzite"
    },
    {
      "x": -25,
      "y": 3,
      "z": 11,
      "name": "Rock_Quartzite"
    },
    {
      "x": -25,
      "y": 4,
      "z": 11,
      "name": "Wood_Softwood_Planks"
    },
    {
      "x": -25,
      "y": 5,
      "z": 11,
      "name": "Rock_Quartzite"
    },
    {
      "x": -25,
      "y": 6,
      "z": 11,
      "name": "Rock_Quartzite"
    },
    {
      "x": -25,
      "y": 7,
      "z": 11,
      "name": "Rock_Quartzite"
    },
    {
      "x": -25,
      "y": 8,
      "z": 11,
      "name": "Wood_Softwood_Planks"
    },
    {
      "x": -25,
      "y": 13,
      "z": 11,
      "name": "Wood_Softwood_Planks_Half"
    },
    {
      "x": -25,
      "y": 0,
      "z": 12,
      "name": "Wood_Softwood_Planks"
    },
    {
      "x": -25,
      "y": 1,
      "z": 12,
      "name": "Rock_Stone_Brick"
    },
    {
      "x": -25,
      "y": 2,
      "z": 12,
      "name": "Rock_Quartzite"
    },
    {
      "x": -25,
      "y": 3,
      "z": 12,
      "name": "Rock_Quartzite"
    },
    {
      "x": -25,
      "y": 4,
      "z": 12,
      "name": "Wood_Softwood_Planks"
    },
    {
      "x": -25,
      "y": 5,
      "z": 12,
      "name": "Wood_Oak_Trunk",
      "support": 15
    },
    {
      "x": -25,
      "y": 6,
      "z": 12,
      "name": "Wood_Oak_Trunk",
      "support": 15
    },
    {
      "x": -25,
      "y": 7,
      "z": 12,
      "name": "Wood_Oak_Trunk",
      "support": 15
    },
    {
      "x": -25,
      "y": 8,
      "z": 12,
      "name": "Wood_Softwood_Planks"
    },
    {
      "x": -25,
      "y": 12,
      "z": 12,
      "name": "Wood_Softwood_Roof_Hollow"
    },
    {
      "x": -25,
      "y": 0,
      "z": 13,
      "name": "Wood_Softwood_Planks"
    },
    {
      "x": -25,
      "y": 1,
      "z": 13,
      "name": "Rock_Stone_Brick"
    },
    {
      "x": -25,
      "y": 2,
      "z": 13,
      "name": "Rock_Quartzite"
    },
    {
      "x": -25,
      "y": 3,
      "z": 13,
      "name": "Rock_Quartzite"
    },
    {
      "x": -25,
      "y": 4,
      "z": 13,
      "name": "Wood_Softwood_Planks"
    },
    {
      "x": -25,
      "y": 8,
      "z": 13,
      "name": "Wood_Softwood_Planks"
    },
    {
      "x": -25,
      "y": 10,
      "z": 13,
      "name": "Wood_Softwood_Planks"
    },
    {
      "x": -25,
      "y": 11,
      "z": 13,
      "name": "Wood_Softwood_Roof"
    },
    {
      "x": -25,
      "y": 0,
      "z": 14,
      "name": "Wood_Softwood_Planks"
    },
    {
      "x": -25,
      "y": 1,
      "z": 14,
      "name": "Rock_Stone_Brick"
    },
    {
      "x": -25,
      "y": 2,
      "z": 14,
      "name": "Rock_Quartzite"
    },
    {
      "x": -25,
      "y": 3,
      "z": 14,
      "name": "Rock_Quartzite"
    },
    {
      "x": -25,
      "y": 4,
      "z": 14,
      "name": "Wood_Softwood_Planks"
    },
    {
      "x": -25,
      "y": 8,
      "z": 14,
      "name": "Wood_Softwood_Planks"
    },
    {
      "x": -25,
      "y": 9,
      "z": 14,
      "name": "Wood_Softwood_Roof_Steep"
    },
    {
      "x": -25,
      "y": 10,
      "z": 14,
      "name": "Wood_Softwood_Roof_Steep",
      "filler": 1024
    },
    {
      "x": -25,
      "y": 0,
      "z": 15,
      "name": "Rock_Stone_Cobble"
    },
    {
      "x": -25,
      "y": 1,
      "z": 15,
      "name": "Rock_Stone_Brick"
    },
    {
      "x": -25,
      "y": 2,
      "z": 15,
      "name": "Rock_Quartzite"
    },
    {
      "x": -25,
      "y": 3,
      "z": 15,
      "name": "Rock_Quartzite"
    },
    {
      "x": -25,
      "y": 4,
      "z": 15,
      "name": "Wood_Softwood_Planks"
    },
    {
      "x": -25,
      "y": 5,
      "z": 15,
      "name": "Wood_Oak_Trunk",
      "support": 15
    },
    {
      "x": -25,
      "y": 6,
      "z": 15,
      "name": "Wood_Oak_Trunk",
      "support": 15
    },
    {
      "x": -25,
      "y": 7,
      "z": 15,
      "name": "Wood_Softwood_Roof_Steep"
    },
    {
      "x": -25,
      "y": 8,
      "z": 15,
      "name": "Wood_Softwood_Roof_Steep",
      "filler": 1024
    },
    {
      "x": -25,
      "y": 4,
      "z": 16,
      "name": "Wood_Oak_Trunk",
      "support": 15,
      "rotation": 5
    },
    {
      "x": -25,
      "y": 5,
      "z": 16,
      "name": "Wood_Softwood_Roof_Steep"
    },
    {
      "x": -25,
      "y": 6,
      "z": 16,
      "name": "Wood_Softwood_Roof_Steep",
      "filler": 1024
    },
    {
      "x": -25,
      "y": 4,
      "z": 17,
      "name": "Wood_Softwood_Roof_Hollow"
    },
    {
      "x": -24,
      "y": 4,
      "z": 5,
      "name": "Wood_Softwood_Roof_Hollow",
      "rotation": 2
    },
    {
      "x": -24,
      "y": 8,
      "z": 5,
      "name": "Wood_Softwood_Stairs",
      "rotation": 9
    },
    {
      "x": -24,
      "y": 9,
      "z": 5,
      "name": "Wood_Softwood_Roof",
      "rotation": 1
    },
    {
      "x": -24,
      "y": 4,
      "z": 6,
      "name": "Wood_Oak_Trunk",
      "support": 15,
      "rotation": 5
    },
    {
      "x": -24,
      "y": 8,
      "z": 6,
      "name": "Wood_Oak_Trunk",
      "support": 15,
      "rotation": 5
    },
    {
      "x": -24,
      "y": 9,
      "z": 6,
      "name": "Wood_Softwood_Roof",
      "rotation": 1
    },
    {
      "x": -24,
      "y": 0,
      "z": 7,
      "name": "Rock_Stone_Cobble"
    },
    {
      "x": -24,
      "y": 1,
      "z": 7,
      "name": "Rock_Stone_Brick"
    },
    {
      "x": -24,
      "y": 2,
      "z": 7,
      "name": "Rock_Quartzite"
    },
    {
      "x": -24,
      "y": 3,
      "z": 7,
      "name": "Rock_Quartzite"
    },
    {
      "x": -24,
      "y": 4,
      "z": 7,
      "name": "Wood_Softwood_Planks"
    },
    {
      "x": -24,
      "y": 5,
      "z": 7,
      "name": "Rock_Quartzite"
    },
    {
      "x": -24,
      "y": 6,
      "z": 7,
      "name": "Furniture_Tavern_Window"
    },
    {
      "x": -24,
      "y": 7,
      "z": 7,
      "name": "Furniture_Tavern_Window"
    },
    {
      "x": -24,
      "y": 8,
      "z": 7,
      "name": "Wood_Softwood_Planks"
    },
    {
      "x": -24,
      "y": 9,
      "z": 7,
      "name": "Wood_Softwood_Roof",
      "rotation": 1
    },
    {
      "x": -24,
      "y": 0,
      "z": 8,
      "name": "Wood_Softwood_Planks"
    },
    {
      "x": -24,
      "y": 4,
      "z": 8,
      "name": "Wood_Softwood_Planks"
    },
    {
      "x": -24,
      "y": 5,
      "z": 8,
      "name": "Furniture_Tavern_Bed",
      "filler": 30,
      "rotation": 3
    },
    {
      "x": -24,
      "y": 6,
      "z": 8,
      "name": "Furniture_Tavern_Bed",
      "filler": 1054,
      "rotation": 3
    },
    {
      "x": -24,
      "y": 8,
      "z": 8,
      "name": "Wood_Softwood_Planks"
    },
    {
      "x": -24,
      "y": 9,
      "z": 8,
      "name": "Wood_Softwood_Roof_Steep",
      "rotation": 2
    },
    {
      "x": -24,
      "y": 10,
      "z": 8,
      "name": "Wood_Softwood_Roof_Steep",
      "filler": 1024,
      "rotation": 2
    },
    {
      "x": -24,
      "y": 0,
      "z": 9,
      "name": "Wood_Softwood_Planks"
    },
    {
      "x": -24,
      "y": 4,
      "z": 9,
      "name": "Wood_Softwood_Planks"
    },
    {
      "x": -24,
      "y": 5,
      "z": 9,
      "name": "Furniture_Tavern_Bed",
      "filler": 62,
      "rotation": 3
    },
    {
      "x": -24,
      "y": 6,
      "z": 9,
      "name": "Furniture_Tavern_Bed",
      "filler": 1086,
      "rotation": 3
    },
    {
      "x": -24,
      "y": 8,
      "z": 9,
      "name": "Wood_Softwood_Planks"
    },
    {
      "x": -24,
      "y": 11,
      "z": 9,
      "name": "Wood_Softwood_Roof_Hollow",
      "rotation": 2
    },
    {
      "x": -24,
      "y": 0,
      "z": 10,
      "name": "Wood_Softwood_Planks"
    },
    {
      "x": -24,
      "y": 1,
      "z": 10,
      "name": "*Furniture_Village_Door_State_Definitions_CloseDoorOut",
      "rotation": 2
    },
    {
      "x": -24,
      "y": 2,
      "z": 10,
      "name": "*Furniture_Village_Door_State_Definitions_CloseDoorOut",
      "filler": 1024,
      "rotation": 2
    },
    {
      "x": -24,
      "y": 3,
      "z": 10,
      "name": "Rock_Quartzite"
    },
    {
      "x": -24,
      "y": 4,
      "z": 10,
      "name": "Wood_Softwood_Planks"
    },
    {
      "x": -24,
      "y": 8,
      "z": 10,
      "name": "Wood_Softwood_Planks"
    },
    {
      "x": -24,
      "y": 12,
      "z": 10,
      "name": "Wood_Softwood_Roof_Hollow",
      "rotation": 2
    },
    {
      "x": -24,
      "y": 0,
      "z": 11,
      "name": "Wood_Softwood_Planks"
    },
    {
      "x": -24,
      "y": 4,
      "z": 11,
      "name": "Wood_Softwood_Planks"
    },
    {
      "x": -24,
      "y": 8,
      "z": 11,
      "name": "Wood_Softwood_Planks"
    },
    {
      "x": -24,
      "y": 13,
      "z": 11,
      "name": "Wood_Softwood_Planks_Half"
    },
    {
      "x": -24,
      "y": 0,
      "z": 12,
      "name": "Wood_Softwood_Planks"
    },
    {
      "x": -24,
      "y": 4,
      "z": 12,
      "name": "Wood_Softwood_Planks"
    },
    {
      "x": -24,
      "y": 5,
      "z": 12,
      "name": "*Furniture_Village_Door_State_Definitions_CloseDoorOut",
      "rotation": 2
    },
    {
      "x": -24,
      "y": 6,
      "z": 12,
      "name": "*Furniture_Village_Door_State_Definitions_CloseDoorOut",
      "filler": 1024,
      "rotation": 2
    },
    {
      "x": -24,
      "y": 7,
      "z": 12,
      "name": "Rock_Quartzite"
    },
    {
      "x": -24,
      "y": 8,
      "z": 12,
      "name": "Wood_Softwood_Planks"
    },
    {
      "x": -24,
      "y": 12,
      "z": 12,
      "name": "Wood_Softwood_Roof_Hollow"
    },
    {
      "x": -24,
      "y": 0,
      "z": 13,
      "name": "Wood_Softwood_Planks"
    },
    {
      "x": -24,
      "y": 4,
      "z": 13,
      "name": "Wood_Softwood_Planks"
    },
    {
      "x": -24,
      "y": 8,
      "z": 13,
      "name": "Wood_Softwood_Planks"
    },
    {
      "x": -24,
      "y": 10,
      "z": 13,
      "name": "Wood_Softwood_Planks"
    },
    {
      "x": -24,
      "y": 11,
      "z": 13,
      "name": "Wood_Softwood_Roof"
    },
    {
      "x": -24,
      "y": 0,
      "z": 14,
      "name": "Wood_Softwood_Planks"
    },
    {
      "x": -24,
      "y": 1,
      "z": 14,
      "name": "Furniture_Tavern_Chest_Small",
      "components": {
        "Components": {
          "PlacedByInteraction": {
            "WhoPlacedUuid": {
              "$binary": "gqJcCRGLSleXtmq6BvFR8g==",
              "$type": "04"
            }
          },
          "ItemContainerBlock": {
            "ItemContainer": {
              "Capacity": 18,
              "Items": {}
            },
            "Capacity": 18
          }
        }
      },
      "rotation": 2
    },
    {
      "x": -24,
      "y": 4,
      "z": 14,
      "name": "Wood_Softwood_Planks"
    },
    {
      "x": -24,
      "y": 8,
      "z": 14,
      "name": "Wood_Softwood_Planks"
    },
    {
      "x": -24,
      "y": 9,
      "z": 14,
      "name": "Wood_Softwood_Roof_Steep"
    },
    {
      "x": -24,
      "y": 10,
      "z": 14,
      "name": "Wood_Softwood_Roof_Steep",
      "filler": 1024
    },
    {
      "x": -24,
      "y": 0,
      "z": 15,
      "name": "Rock_Stone_Cobble"
    },
    {
      "x": -24,
      "y": 1,
      "z": 15,
      "name": "Rock_Stone_Brick"
    },
    {
      "x": -24,
      "y": 2,
      "z": 15,
      "name": "Furniture_Tavern_Window"
    },
    {
      "x": -24,
      "y": 3,
      "z": 15,
      "name": "Furniture_Tavern_Window"
    },
    {
      "x": -24,
      "y": 4,
      "z": 15,
      "name": "Wood_Softwood_Planks"
    },
    {
      "x": -24,
      "y": 5,
      "z": 15,
      "name": "Rock_Quartzite"
    },
    {
      "x": -24,
      "y": 6,
      "z": 15,
      "name": "Rock_Quartzite"
    },
    {
      "x": -24,
      "y": 7,
      "z": 15,
      "name": "Wood_Softwood_Roof_Steep"
    },
    {
      "x": -24,
      "y": 8,
      "z": 15,
      "name": "Wood_Softwood_Roof_Steep",
      "filler": 1024
    },
    {
      "x": -24,
      "y": 4,
      "z": 16,
      "name": "Wood_Oak_Trunk",
      "support": 15,
      "rotation": 5
    },
    {
      "x": -24,
      "y": 5,
      "z": 16,
      "name": "Wood_Softwood_Roof_Steep"
    },
    {
      "x": -24,
      "y": 6,
      "z": 16,
      "name": "Wood_Softwood_Roof_Steep",
      "filler": 1024
    },
    {
      "x": -24,
      "y": 4,
      "z": 17,
      "name": "Wood_Softwood_Roof_Hollow"
    },
    {
      "x": -23,
      "y": 4,
      "z": 5,
      "name": "Wood_Softwood_Roof_Hollow",
      "rotation": 2
    },
    {
      "x": -23,
      "y": 6,
      "z": 5,
      "name": "Wood_Softwood_Stairs",
      "rotation": 9
    },
    {
      "x": -23,
      "y": 7,
      "z": 5,
      "name": "Wood_Softwood_Roof_Steep",
      "rotation": 1
    },
    {
      "x": -23,
      "y": 8,
      "z": 5,
      "name": "Wood_Softwood_Roof_Steep",
      "filler": 1024,
      "rotation": 1
    },
    {
      "x": -23,
      "y": 4,
      "z": 6,
      "name": "Wood_Oak_Trunk",
      "support": 15,
      "rotation": 5
    },
    {
      "x": -23,
      "y": 6,
      "z": 6,
      "name": "Wood_Softwood_Stairs",
      "rotation": 9
    },
    {
      "x": -23,
      "y": 7,
      "z": 6,
      "name": "Wood_Softwood_Roof_Steep",
      "rotation": 1
    },
    {
      "x": -23,
      "y": 8,
      "z": 6,
      "name": "Wood_Softwood_Roof_Steep",
      "filler": 1024,
      "rotation": 1
    },
    {
      "x": -23,
      "y": 0,
      "z": 7,
      "name": "Rock_Stone_Cobble"
    },
    {
      "x": -23,
      "y": 1,
      "z": 7,
      "name": "Rock_Stone_Brick"
    },
    {
      "x": -23,
      "y": 2,
      "z": 7,
      "name": "Rock_Quartzite"
    },
    {
      "x": -23,
      "y": 3,
      "z": 7,
      "name": "Rock_Quartzite"
    },
    {
      "x": -23,
      "y": 4,
      "z": 7,
      "name": "Wood_Softwood_Planks"
    },
    {
      "x": -23,
      "y": 5,
      "z": 7,
      "name": "Rock_Quartzite"
    },
    {
      "x": -23,
      "y": 6,
      "z": 7,
      "name": "Rock_Quartzite"
    },
    {
      "x": -23,
      "y": 7,
      "z": 7,
      "name": "*Wood_Softwood_Roof_Steep_State_Definitions_Inverted_Corner_Right",
      "rotation": 2
    },
    {
      "x": -23,
      "y": 8,
      "z": 7,
      "name": "*Wood_Softwood_Roof_Steep_State_Definitions_Inverted_Corner_Right",
      "filler": 1024,
      "rotation": 2
    },
    {
      "x": -23,
      "y": 0,
      "z": 8,
      "name": "Wood_Softwood_Planks"
    },
    {
      "x": -23,
      "y": 4,
      "z": 8,
      "name": "Wood_Softwood_Planks"
    },
    {
      "x": -23,
      "y": 5,
      "z": 8,
      "name": "Furniture_Tavern_Bed",
      "filler": 31,
      "rotation": 3
    },
    {
      "x": -23,
      "y": 6,
      "z": 8,
      "name": "Furniture_Tavern_Bed",
      "filler": 1055,
      "rotation": 3
    },
    {
      "x": -23,
      "y": 8,
      "z": 8,
      "name": "Wood_Softwood_Planks"
    },
    {
      "x": -23,
      "y": 9,
      "z": 8,
      "name": "Wood_Softwood_Roof_Steep",
      "rotation": 2
    },
    {
      "x": -23,
      "y": 10,
      "z": 8,
      "name": "Wood_Softwood_Roof_Steep",
      "filler": 1024,
      "rotation": 2
    },
    {
      "x": -23,
      "y": 0,
      "z": 9,
      "name": "Wood_Softwood_Planks"
    },
    {
      "x": -23,
      "y": 1,
      "z": 9,
      "name": "Furniture_Village_Counter",
      "rotation": 2
    },
    {
      "x": -23,
      "y": 4,
      "z": 9,
      "name": "Wood_Softwood_Planks"
    },
    {
      "x": -23,
      "y": 5,
      "z": 9,
      "name": "Furniture_Tavern_Bed",
      "filler": 63,
      "rotation": 3
    },
    {
      "x": -23,
      "y": 6,
      "z": 9,
      "name": "Furniture_Tavern_Bed",
      "filler": 1087,
      "rotation": 3
    },
    {
      "x": -23,
      "y": 8,
      "z": 9,
      "name": "Wood_Softwood_Planks"
    },
    {
      "x": -23,
      "y": 11,
      "z": 9,
      "name": "Wood_Softwood_Roof_Hollow",
      "rotation": 2
    },
    {
      "x": -23,
      "y": 0,
      "z": 10,
      "name": "Wood_Softwood_Planks"
    },
    {
      "x": -23,
      "y": 1,
      "z": 10,
      "name": "Rock_Stone_Brick"
    },
    {
      "x": -23,
      "y": 2,
      "z": 10,
      "name": "Rock_Quartzite"
    },
    {
      "x": -23,
      "y": 3,
      "z": 10,
      "name": "Rock_Quartzite"
    },
    {
      "x": -23,
      "y": 4,
      "z": 10,
      "name": "Wood_Softwood_Planks"
    },
    {
      "x": -23,
      "y": 8,
      "z": 10,
      "name": "Wood_Softwood_Planks"
    },
    {
      "x": -23,
      "y": 12,
      "z": 10,
      "name": "Wood_Softwood_Roof_Hollow",
      "rotation": 2
    },
    {
      "x": -23,
      "y": 0,
      "z": 11,
      "name": "Wood_Softwood_Planks"
    },
    {
      "x": -23,
      "y": 1,
      "z": 11,
      "name": "Furniture_Village_Bookcase"
    },
    {
      "x": -23,
      "y": 2,
      "z": 11,
      "name": "Furniture_Village_Shelf_Full"
    },
    {
      "x": -23,
      "y": 3,
      "z": 11,
      "name": "Furniture_Village_Shelf_Full"
    },
    {
      "x": -23,
      "y": 4,
      "z": 11,
      "name": "Wood_Softwood_Planks"
    },
    {
      "x": -23,
      "y": 8,
      "z": 11,
      "name": "Wood_Softwood_Planks"
    },
    {
      "x": -23,
      "y": 13,
      "z": 11,
      "name": "Wood_Softwood_Planks_Half"
    },
    {
      "x": -23,
      "y": 0,
      "z": 12,
      "name": "Wood_Softwood_Planks"
    },
    {
      "x": -23,
      "y": 1,
      "z": 12,
      "name": "Furniture_Tavern_Bed",
      "filler": 991,
      "rotation": 2
    },
    {
      "x": -23,
      "y": 2,
      "z": 12,
      "name": "Furniture_Tavern_Bed",
      "filler": 2015,
      "rotation": 2
    },
    {
      "x": -23,
      "y": 4,
      "z": 12,
      "name": "Wood_Softwood_Planks"
    },
    {
      "x": -23,
      "y": 5,
      "z": 12,
      "name": "Rock_Quartzite"
    },
    {
      "x": -23,
      "y": 6,
      "z": 12,
      "name": "Rock_Quartzite"
    },
    {
      "x": -23,
      "y": 7,
      "z": 12,
      "name": "Rock_Quartzite"
    },
    {
      "x": -23,
      "y": 8,
      "z": 12,
      "name": "Wood_Softwood_Planks"
    },
    {
      "x": -23,
      "y": 12,
      "z": 12,
      "name": "Wood_Softwood_Roof_Hollow"
    },
    {
      "x": -23,
      "y": 0,
      "z": 13,
      "name": "Wood_Softwood_Planks"
    },
    {
      "x": -23,
      "y": 1,
      "z": 13,
      "name": "Furniture_Tavern_Bed",
      "filler": 1023,
      "rotation": 2
    },
    {
      "x": -23,
      "y": 2,
      "z": 13,
      "name": "Furniture_Tavern_Bed",
      "filler": 2047,
      "rotation": 2
    },
    {
      "x": -23,
      "y": 4,
      "z": 13,
      "name": "Wood_Softwood_Planks"
    },
    {
      "x": -23,
      "y": 8,
      "z": 13,
      "name": "Wood_Softwood_Planks"
    },
    {
      "x": -23,
      "y": 10,
      "z": 13,
      "name": "Wood_Softwood_Planks"
    },
    {
      "x": -23,
      "y": 11,
      "z": 13,
      "name": "Wood_Softwood_Roof"
    },
    {
      "x": -23,
      "y": 0,
      "z": 14,
      "name": "Wood_Softwood_Planks"
    },
    {
      "x": -23,
      "y": 1,
      "z": 14,
      "name": "Furniture_Tavern_Bed",
      "filler": 31,
      "rotation": 2
    },
    {
      "x": -23,
      "y": 2,
      "z": 14,
      "name": "Furniture_Tavern_Bed",
      "filler": 1055,
      "rotation": 2
    },
    {
      "x": -23,
      "y": 4,
      "z": 14,
      "name": "Wood_Softwood_Planks"
    },
    {
      "x": -23,
      "y": 8,
      "z": 14,
      "name": "Wood_Softwood_Planks"
    },
    {
      "x": -23,
      "y": 9,
      "z": 14,
      "name": "Wood_Softwood_Roof_Steep"
    },
    {
      "x": -23,
      "y": 10,
      "z": 14,
      "name": "Wood_Softwood_Roof_Steep",
      "filler": 1024
    },
    {
      "x": -23,
      "y": 0,
      "z": 15,
      "name": "Rock_Stone_Cobble"
    },
    {
      "x": -23,
      "y": 1,
      "z": 15,
      "name": "Rock_Stone_Brick"
    },
    {
      "x": -23,
      "y": 2,
      "z": 15,
      "name": "Rock_Quartzite"
    },
    {
      "x": -23,
      "y": 3,
      "z": 15,
      "name": "Rock_Quartzite"
    },
    {
      "x": -23,
      "y": 4,
      "z": 15,
      "name": "Wood_Softwood_Planks"
    },
    {
      "x": -23,
      "y": 5,
      "z": 15,
      "name": "Rock_Quartzite"
    },
    {
      "x": -23,
      "y": 6,
      "z": 15,
      "name": "Rock_Quartzite"
    },
    {
      "x": -23,
      "y": 7,
      "z": 15,
      "name": "Wood_Softwood_Roof_Steep"
    },
    {
      "x": -23,
      "y": 8,
      "z": 15,
      "name": "Wood_Softwood_Roof_Steep",
      "filler": 1024
    },
    {
      "x": -23,
      "y": 4,
      "z": 16,
      "name": "Wood_Oak_Trunk",
      "support": 15,
      "rotation": 5
    },
    {
      "x": -23,
      "y": 5,
      "z": 16,
      "name": "Wood_Softwood_Roof_Steep"
    },
    {
      "x": -23,
      "y": 6,
      "z": 16,
      "name": "Wood_Softwood_Roof_Steep",
      "filler": 1024
    },
    {
      "x": -23,
      "y": 4,
      "z": 17,
      "name": "*Wood_Softwood_Roof_Hollow_State_Definitions_Inverted_Corner_Right"
    },
    {
      "x": -23,
      "y": 4,
      "z": 18,
      "name": "Wood_Softwood_Roof_Hollow",
      "rotation": 3
    },
    {
      "x": -23,
      "y": 4,
      "z": 19,
      "name": "Wood_Softwood_Roof_Hollow",
      "rotation": 3
    },
    {
      "x": -23,
      "y": 4,
      "z": 20,
      "name": "Wood_Softwood_Roof_Hollow",
      "rotation": 3
    },
    {
      "x": -23,
      "y": 4,
      "z": 21,
      "name": "Wood_Softwood_Roof_Hollow",
      "rotation": 3
    },
    {
      "x": -23,
      "y": 4,
      "z": 22,
      "name": "Wood_Softwood_Roof_Hollow",
      "rotation": 3
    },
    {
      "x": -23,
      "y": 4,
      "z": 23,
      "name": "Wood_Softwood_Roof_Hollow",
      "rotation": 3
    },
    {
      "x": -23,
      "y": 4,
      "z": 24,
      "name": "Wood_Softwood_Roof_Hollow",
      "rotation": 3
    },
    {
      "x": -22,
      "y": 4,
      "z": 5,
      "name": "Wood_Softwood_Roof_Hollow",
      "rotation": 2
    },
    {
      "x": -22,
      "y": 5,
      "z": 5,
      "name": "Wood_Softwood_Roof_Steep",
      "rotation": 1
    },
    {
      "x": -22,
      "y": 6,
      "z": 5,
      "name": "Wood_Softwood_Roof_Steep",
      "filler": 1024,
      "rotation": 1
    },
    {
      "x": -22,
      "y": 0,
      "z": 6,
      "name": "Rock_Stone_Cobble"
    },
    {
      "x": -22,
      "y": 1,
      "z": 6,
      "name": "Wood_Oak_Trunk",
      "support": 15
    },
    {
      "x": -22,
      "y": 2,
      "z": 6,
      "name": "Wood_Oak_Trunk",
      "support": 15
    },
    {
      "x": -22,
      "y": 3,
      "z": 6,
      "name": "Wood_Oak_Trunk",
      "support": 15
    },
    {
      "x": -22,
      "y": 4,
      "z": 6,
      "name": "Wood_Oak_Trunk",
      "support": 15,
      "rotation": 5
    },
    {
      "x": -22,
      "y": 5,
      "z": 6,
      "name": "*Wood_Softwood_Roof_Steep_State_Definitions_Inverted_Corner_Left",
      "rotation": 1
    },
    {
      "x": -22,
      "y": 6,
      "z": 6,
      "name": "*Wood_Softwood_Roof_Steep_State_Definitions_Inverted_Corner_Left",
      "filler": 1024,
      "rotation": 1
    },
    {
      "x": -22,
      "y": 0,
      "z": 7,
      "name": "Rock_Stone_Cobble"
    },
    {
      "x": -22,
      "y": 1,
      "z": 7,
      "name": "Wood_Oak_Trunk",
      "support": 15
    },
    {
      "x": -22,
      "y": 2,
      "z": 7,
      "name": "Wood_Oak_Trunk",
      "support": 15
    },
    {
      "x": -22,
      "y": 3,
      "z": 7,
      "name": "Wood_Oak_Trunk",
      "support": 15
    },
    {
      "x": -22,
      "y": 4,
      "z": 7,
      "name": "Wood_Softwood_Planks"
    },
    {
      "x": -22,
      "y": 5,
      "z": 7,
      "name": "Rock_Quartzite"
    },
    {
      "x": -22,
      "y": 6,
      "z": 7,
      "name": "Rock_Quartzite"
    },
    {
      "x": -22,
      "y": 7,
      "z": 7,
      "name": "Wood_Softwood_Roof_Steep",
      "rotation": 2
    },
    {
      "x": -22,
      "y": 8,
      "z": 7,
      "name": "Wood_Softwood_Roof_Steep",
      "filler": 1024,
      "rotation": 2
    },
    {
      "x": -22,
      "y": 0,
      "z": 8,
      "name": "Wood_Softwood_Planks"
    },
    {
      "x": -22,
      "y": 4,
      "z": 8,
      "name": "Wood_Softwood_Planks"
    },
    {
      "x": -22,
      "y": 5,
      "z": 8,
      "name": "Furniture_Tavern_Bed",
      "components": {
        "Components": {
          "PlacedByInteraction": {
            "WhoPlacedUuid": {
              "$binary": "gqJcCRGLSleXtmq6BvFR8g==",
              "$type": "04"
            }
          },
          "RespawnBlock": {}
        }
      },
      "rotation": 3
    },
    {
      "x": -22,
      "y": 6,
      "z": 8,
      "name": "Furniture_Tavern_Bed",
      "filler": 1024,
      "rotation": 3
    },
    {
      "x": -22,
      "y": 8,
      "z": 8,
      "name": "Wood_Softwood_Planks"
    },
    {
      "x": -22,
      "y": 9,
      "z": 8,
      "name": "Wood_Softwood_Roof_Steep",
      "rotation": 2
    },
    {
      "x": -22,
      "y": 10,
      "z": 8,
      "name": "Wood_Softwood_Roof_Steep",
      "filler": 1024,
      "rotation": 2
    },
    {
      "x": -22,
      "y": 0,
      "z": 9,
      "name": "Wood_Softwood_Planks"
    },
    {
      "x": -22,
      "y": 1,
      "z": 9,
      "name": "Furniture_Village_Counter",
      "filler": 1,
      "rotation": 2
    },
    {
      "x": -22,
      "y": 2,
      "z": 9,
      "name": "Furniture_Human_Ruins_Pot_Small"
    },
    {
      "x": -22,
      "y": 4,
      "z": 9,
      "name": "Wood_Softwood_Planks"
    },
    {
      "x": -22,
      "y": 5,
      "z": 9,
      "name": "Furniture_Tavern_Bed",
      "filler": 32,
      "rotation": 3
    },
    {
      "x": -22,
      "y": 6,
      "z": 9,
      "name": "Furniture_Tavern_Bed",
      "filler": 1056,
      "rotation": 3
    },
    {
      "x": -22,
      "y": 8,
      "z": 9,
      "name": "Wood_Softwood_Planks"
    },
    {
      "x": -22,
      "y": 11,
      "z": 9,
      "name": "Wood_Softwood_Roof_Hollow",
      "rotation": 2
    },
    {
      "x": -22,
      "y": 0,
      "z": 10,
      "name": "Wood_Softwood_Planks"
    },
    {
      "x": -22,
      "y": 1,
      "z": 10,
      "name": "Rock_Stone_Brick"
    },
    {
      "x": -22,
      "y": 2,
      "z": 10,
      "name": "Rock_Quartzite"
    },
    {
      "x": -22,
      "y": 3,
      "z": 10,
      "name": "Rock_Quartzite"
    },
    {
      "x": -22,
      "y": 4,
      "z": 10,
      "name": "Wood_Softwood_Planks"
    },
    {
      "x": -22,
      "y": 5,
      "z": 10,
      "name": "Furniture_Village_Wardrobe",
      "filler": 992,
      "rotation": 3
    },
    {
      "x": -22,
      "y": 6,
      "z": 10,
      "name": "Furniture_Village_Wardrobe",
      "filler": 2016,
      "rotation": 3
    },
    {
      "x": -22,
      "y": 8,
      "z": 10,
      "name": "Wood_Softwood_Planks"
    },
    {
      "x": -22,
      "y": 12,
      "z": 10,
      "name": "Wood_Softwood_Roof_Hollow",
      "rotation": 2
    },
    {
      "x": -22,
      "y": 0,
      "z": 11,
      "name": "Wood_Softwood_Planks"
    },
    {
      "x": -22,
      "y": 1,
      "z": 11,
      "name": "Furniture_Village_Bookcase"
    },
    {
      "x": -22,
      "y": 2,
      "z": 11,
      "name": "Furniture_Village_Bookcase"
    },
    {
      "x": -22,
      "y": 3,
      "z": 11,
      "name": "Furniture_Village_Bookcase"
    },
    {
      "x": -22,
      "y": 4,
      "z": 11,
      "name": "Wood_Softwood_Planks"
    },
    {
      "x": -22,
      "y": 5,
      "z": 11,
      "name": "Furniture_Village_Wardrobe",
      "rotation": 3
    },
    {
      "x": -22,
      "y": 6,
      "z": 11,
      "name": "Furniture_Village_Wardrobe",
      "filler": 1024,
      "rotation": 3
    },
    {
      "x": -22,
      "y": 7,
      "z": 11,
      "name": "Deco_Book_Pile_Small",
      "rotation": 3
    },
    {
      "x": -22,
      "y": 8,
      "z": 11,
      "name": "Wood_Softwood_Planks"
    },
    {
      "x": -22,
      "y": 13,
      "z": 11,
      "name": "Wood_Softwood_Planks_Half"
    },
    {
      "x": -22,
      "y": 0,
      "z": 12,
      "name": "Wood_Softwood_Planks"
    },
    {
      "x": -22,
      "y": 1,
      "z": 12,
      "name": "Furniture_Tavern_Bed",
      "filler": 960,
      "rotation": 2
    },
    {
      "x": -22,
      "y": 2,
      "z": 12,
      "name": "Furniture_Tavern_Bed",
      "filler": 1984,
      "rotation": 2
    },
    {
      "x": -22,
      "y": 4,
      "z": 12,
      "name": "Wood_Softwood_Planks"
    },
    {
      "x": -22,
      "y": 5,
      "z": 12,
      "name": "Rock_Quartzite"
    },
    {
      "x": -22,
      "y": 6,
      "z": 12,
      "name": "Rock_Quartzite"
    },
    {
      "x": -22,
      "y": 7,
      "z": 12,
      "name": "Rock_Quartzite"
    },
    {
      "x": -22,
      "y": 8,
      "z": 12,
      "name": "Wood_Softwood_Planks"
    },
    {
      "x": -22,
      "y": 12,
      "z": 12,
      "name": "Wood_Softwood_Roof_Hollow"
    },
    {
      "x": -22,
      "y": 0,
      "z": 13,
      "name": "Wood_Softwood_Planks"
    },
    {
      "x": -22,
      "y": 1,
      "z": 13,
      "name": "Furniture_Tavern_Bed",
      "filler": 992,
      "rotation": 2
    },
    {
      "x": -22,
      "y": 2,
      "z": 13,
      "name": "Furniture_Tavern_Bed",
      "filler": 2016,
      "rotation": 2
    },
    {
      "x": -22,
      "y": 4,
      "z": 13,
      "name": "Wood_Softwood_Planks"
    },
    {
      "x": -22,
      "y": 8,
      "z": 13,
      "name": "Wood_Softwood_Planks"
    },
    {
      "x": -22,
      "y": 10,
      "z": 13,
      "name": "Wood_Softwood_Planks"
    },
    {
      "x": -22,
      "y": 11,
      "z": 13,
      "name": "Wood_Softwood_Roof"
    },
    {
      "x": -22,
      "y": 0,
      "z": 14,
      "name": "Wood_Softwood_Planks"
    },
    {
      "x": -22,
      "y": 1,
      "z": 14,
      "name": "Furniture_Tavern_Bed",
      "components": {
        "Components": {
          "PlacedByInteraction": {
            "WhoPlacedUuid": {
              "$binary": "gqJcCRGLSleXtmq6BvFR8g==",
              "$type": "04"
            }
          },
          "RespawnBlock": {
            "OwnerUUID": {
              "$binary": "gqJcCRGLSleXtmq6BvFR8g==",
              "$type": "04"
            }
          }
        }
      },
      "rotation": 2
    },
    {
      "x": -22,
      "y": 2,
      "z": 14,
      "name": "Furniture_Tavern_Bed",
      "filler": 1024,
      "rotation": 2
    },
    {
      "x": -22,
      "y": 4,
      "z": 14,
      "name": "Wood_Softwood_Planks"
    },
    {
      "x": -22,
      "y": 8,
      "z": 14,
      "name": "Wood_Softwood_Planks"
    },
    {
      "x": -22,
      "y": 9,
      "z": 14,
      "name": "Wood_Softwood_Roof_Steep"
    },
    {
      "x": -22,
      "y": 10,
      "z": 14,
      "name": "Wood_Softwood_Roof_Steep",
      "filler": 1024
    },
    {
      "x": -22,
      "y": 0,
      "z": 15,
      "name": "Rock_Stone_Cobble"
    },
    {
      "x": -22,
      "y": 1,
      "z": 15,
      "name": "Rock_Stone_Brick"
    },
    {
      "x": -22,
      "y": 2,
      "z": 15,
      "name": "Rock_Quartzite"
    },
    {
      "x": -22,
      "y": 3,
      "z": 15,
      "name": "Rock_Quartzite"
    },
    {
      "x": -22,
      "y": 4,
      "z": 15,
      "name": "Wood_Softwood_Planks"
    },
    {
      "x": -22,
      "y": 5,
      "z": 15,
      "name": "Rock_Quartzite"
    },
    {
      "x": -22,
      "y": 6,
      "z": 15,
      "name": "Rock_Quartzite"
    },
    {
      "x": -22,
      "y": 7,
      "z": 15,
      "name": "Wood_Softwood_Roof_Steep"
    },
    {
      "x": -22,
      "y": 8,
      "z": 15,
      "name": "Wood_Softwood_Roof_Steep",
      "filler": 1024
    },
    {
      "x": -22,
      "y": 0,
      "z": 16,
      "name": "Rock_Stone_Cobble"
    },
    {
      "x": -22,
      "y": 1,
      "z": 16,
      "name": "Wood_Oak_Trunk",
      "support": 15
    },
    {
      "x": -22,
      "y": 2,
      "z": 16,
      "name": "Wood_Oak_Trunk",
      "support": 15
    },
    {
      "x": -22,
      "y": 3,
      "z": 16,
      "name": "Wood_Oak_Trunk",
      "support": 15
    },
    {
      "x": -22,
      "y": 4,
      "z": 16,
      "name": "Wood_Oak_Trunk",
      "support": 15
    },
    {
      "x": -22,
      "y": 5,
      "z": 16,
      "name": "*Wood_Softwood_Roof_Steep_State_Definitions_Inverted_Corner_Left",
      "rotation": 3
    },
    {
      "x": -22,
      "y": 6,
      "z": 16,
      "name": "*Wood_Softwood_Roof_Steep_State_Definitions_Inverted_Corner_Left",
      "filler": 1024,
      "rotation": 3
    },
    {
      "x": -22,
      "y": 4,
      "z": 17,
      "name": "Wood_Oak_Trunk",
      "support": 15,
      "rotation": 4
    },
    {
      "x": -22,
      "y": 5,
      "z": 17,
      "name": "Wood_Softwood_Roof_Steep",
      "rotation": 3
    },
    {
      "x": -22,
      "y": 6,
      "z": 17,
      "name": "Wood_Softwood_Roof_Steep",
      "filler": 1024,
      "rotation": 3
    },
    {
      "x": -22,
      "y": 4,
      "z": 18,
      "name": "Wood_Oak_Trunk",
      "support": 15,
      "rotation": 4
    },
    {
      "x": -22,
      "y": 5,
      "z": 18,
      "name": "Wood_Softwood_Roof_Steep",
      "rotation": 3
    },
    {
      "x": -22,
      "y": 6,
      "z": 18,
      "name": "Wood_Softwood_Roof_Steep",
      "filler": 1024,
      "rotation": 3
    },
    {
      "x": -22,
      "y": 0,
      "z": 19,
      "name": "Rock_Stone_Cobble"
    },
    {
      "x": -22,
      "y": 1,
      "z": 19,
      "name": "Wood_Oak_Trunk",
      "support": 15
    },
    {
      "x": -22,
      "y": 2,
      "z": 19,
      "name": "Wood_Oak_Trunk",
      "support": 15
    },
    {
      "x": -22,
      "y": 3,
      "z": 19,
      "name": "Wood_Oak_Trunk",
      "support": 15
    },
    {
      "x": -22,
      "y": 4,
      "z": 19,
      "name": "Wood_Oak_Trunk",
      "support": 15
    },
    {
      "x": -22,
      "y": 5,
      "z": 19,
      "name": "Wood_Softwood_Roof_Steep",
      "rotation": 3
    },
    {
      "x": -22,
      "y": 6,
      "z": 19,
      "name": "Wood_Softwood_Roof_Steep",
      "filler": 1024,
      "rotation": 3
    },
    {
      "x": -22,
      "y": 4,
      "z": 20,
      "name": "Wood_Oak_Trunk",
      "support": 15,
      "rotation": 4
    },
    {
      "x": -22,
      "y": 5,
      "z": 20,
      "name": "Wood_Softwood_Roof_Steep",
      "rotation": 3
    },
    {
      "x": -22,
      "y": 6,
      "z": 20,
      "name": "Wood_Softwood_Roof_Steep",
      "filler": 1024,
      "rotation": 3
    },
    {
      "x": -22,
      "y": 4,
      "z": 21,
      "name": "Wood_Oak_Trunk",
      "support": 15,
      "rotation": 4
    },
    {
      "x": -22,
      "y": 5,
      "z": 21,
      "name": "Wood_Softwood_Roof_Steep",
      "rotation": 3
    },
    {
      "x": -22,
      "y": 6,
      "z": 21,
      "name": "Wood_Softwood_Roof_Steep",
      "filler": 1024,
      "rotation": 3
    },
    {
      "x": -22,
      "y": 4,
      "z": 22,
      "name": "Wood_Oak_Trunk",
      "support": 15,
      "rotation": 4
    },
    {
      "x": -22,
      "y": 5,
      "z": 22,
      "name": "Wood_Softwood_Roof_Steep",
      "rotation": 3
    },
    {
      "x": -22,
      "y": 6,
      "z": 22,
      "name": "Wood_Softwood_Roof_Steep",
      "filler": 1024,
      "rotation": 3
    },
    {
      "x": -22,
      "y": 0,
      "z": 23,
      "name": "Rock_Stone_Cobble"
    },
    {
      "x": -22,
      "y": 1,
      "z": 23,
      "name": "Wood_Oak_Trunk",
      "support": 15
    },
    {
      "x": -22,
      "y": 2,
      "z": 23,
      "name": "Wood_Oak_Trunk",
      "support": 15
    },
    {
      "x": -22,
      "y": 3,
      "z": 23,
      "name": "Wood_Oak_Trunk",
      "support": 15
    },
    {
      "x": -22,
      "y": 4,
      "z": 23,
      "name": "Wood_Oak_Trunk",
      "support": 15
    },
    {
      "x": -22,
      "y": 5,
      "z": 23,
      "name": "Wood_Softwood_Roof_Steep",
      "rotation": 3
    },
    {
      "x": -22,
      "y": 6,
      "z": 23,
      "name": "Wood_Softwood_Roof_Steep",
      "filler": 1024,
      "rotation": 3
    },
    {
      "x": -22,
      "y": 4,
      "z": 24,
      "name": "Wood_Oak_Branch_Short",
      "support": 15
    },
    {
      "x": -22,
      "y": 5,
      "z": 24,
      "name": "Wood_Softwood_Roof_Steep",
      "rotation": 3
    },
    {
      "x": -22,
      "y": 6,
      "z": 24,
      "name": "Wood_Softwood_Roof_Steep",
      "filler": 1024,
      "rotation": 3
    },
    {
      "x": -21,
      "y": 4,
      "z": 5,
      "name": "Wood_Softwood_Roof_Hollow",
      "rotation": 2
    },
    {
      "x": -21,
      "y": 4,
      "z": 6,
      "name": "Wood_Oak_Trunk",
      "support": 15,
      "rotation": 5
    },
    {
      "x": -21,
      "y": 5,
      "z": 6,
      "name": "Wood_Softwood_Roof_Steep",
      "rotation": 2
    },
    {
      "x": -21,
      "y": 6,
      "z": 6,
      "name": "Wood_Softwood_Roof_Steep",
      "filler": 1024,
      "rotation": 2
    },
    {
      "x": -21,
      "y": 0,
      "z": 7,
      "name": "Rock_Stone_Cobble"
    },
    {
      "x": -21,
      "y": 1,
      "z": 7,
      "name": "Rock_Stone_Brick"
    },
    {
      "x": -21,
      "y": 2,
      "z": 7,
      "name": "Rock_Quartzite"
    },
    {
      "x": -21,
      "y": 3,
      "z": 7,
      "name": "Rock_Quartzite"
    },
    {
      "x": -21,
      "y": 4,
      "z": 7,
      "name": "Wood_Softwood_Planks"
    },
    {
      "x": -21,
      "y": 5,
      "z": 7,
      "name": "Rock_Quartzite"
    },
    {
      "x": -21,
      "y": 6,
      "z": 7,
      "name": "Rock_Quartzite"
    },
    {
      "x": -21,
      "y": 7,
      "z": 7,
      "name": "Wood_Softwood_Roof_Steep",
      "rotation": 2
    },
    {
      "x": -21,
      "y": 8,
      "z": 7,
      "name": "Wood_Softwood_Roof_Steep",
      "filler": 1024,
      "rotation": 2
    },
    {
      "x": -21,
      "y": 0,
      "z": 8,
      "name": "Wood_Softwood_Planks"
    },
    {
      "x": -21,
      "y": 4,
      "z": 8,
      "name": "Wood_Softwood_Planks"
    },
    {
      "x": -21,
      "y": 5,
      "z": 8,
      "name": "Rock_Quartzite"
    },
    {
      "x": -21,
      "y": 6,
      "z": 8,
      "name": "Rock_Quartzite"
    },
    {
      "x": -21,
      "y": 7,
      "z": 8,
      "name": "Rock_Quartzite"
    },
    {
      "x": -21,
      "y": 8,
      "z": 8,
      "name": "Wood_Oak_Trunk",
      "support": 15,
      "rotation": 4
    },
    {
      "x": -21,
      "y": 9,
      "z": 8,
      "name": "Wood_Softwood_Roof_Steep",
      "rotation": 2
    },
    {
      "x": -21,
      "y": 10,
      "z": 8,
      "name": "Wood_Softwood_Roof_Steep",
      "filler": 1024,
      "rotation": 2
    },
    {
      "x": -21,
      "y": 0,
      "z": 9,
      "name": "Wood_Softwood_Planks"
    },
    {
      "x": -21,
      "y": 1,
      "z": 9,
      "name": "Furniture_Human_Ruins_Pot_Small"
    },
    {
      "x": -21,
      "y": 4,
      "z": 9,
      "name": "Wood_Softwood_Planks"
    },
    {
      "x": -21,
      "y": 5,
      "z": 9,
      "name": "Rock_Quartzite"
    },
    {
      "x": -21,
      "y": 6,
      "z": 9,
      "name": "Rock_Quartzite"
    },
    {
      "x": -21,
      "y": 7,
      "z": 9,
      "name": "Rock_Quartzite"
    },
    {
      "x": -21,
      "y": 8,
      "z": 9,
      "name": "Wood_Oak_Trunk",
      "support": 15,
      "rotation": 4
    },
    {
      "x": -21,
      "y": 9,
      "z": 9,
      "name": "Rock_Quartzite"
    },
    {
      "x": -21,
      "y": 10,
      "z": 9,
      "name": "Rock_Quartzite"
    },
    {
      "x": -21,
      "y": 11,
      "z": 9,
      "name": "Wood_Softwood_Roof",
      "rotation": 2
    },
    {
      "x": -21,
      "y": 0,
      "z": 10,
      "name": "Wood_Softwood_Planks"
    },
    {
      "x": -21,
      "y": 1,
      "z": 10,
      "name": "Wood_Oak_Trunk",
      "support": 15
    },
    {
      "x": -21,
      "y": 2,
      "z": 10,
      "name": "Wood_Oak_Trunk",
      "support": 15
    },
    {
      "x": -21,
      "y": 3,
      "z": 10,
      "name": "Wood_Oak_Trunk",
      "support": 15
    },
    {
      "x": -21,
      "y": 4,
      "z": 10,
      "name": "Wood_Softwood_Planks"
    },
    {
      "x": -21,
      "y": 5,
      "z": 10,
      "name": "Rock_Quartzite"
    },
    {
      "x": -21,
      "y": 6,
      "z": 10,
      "name": "Rock_Quartzite"
    },
    {
      "x": -21,
      "y": 7,
      "z": 10,
      "name": "Rock_Quartzite"
    },
    {
      "x": -21,
      "y": 8,
      "z": 10,
      "name": "Wood_Oak_Trunk",
      "support": 15,
      "rotation": 4
    },
    {
      "x": -21,
      "y": 9,
      "z": 10,
      "name": "Rock_Quartzite"
    },
    {
      "x": -21,
      "y": 10,
      "z": 10,
      "name": "Rock_Quartzite"
    },
    {
      "x": -21,
      "y": 11,
      "z": 10,
      "name": "Rock_Quartzite"
    },
    {
      "x": -21,
      "y": 12,
      "z": 10,
      "name": "Wood_Softwood_Roof",
      "rotation": 2
    },
    {
      "x": -21,
      "y": 0,
      "z": 11,
      "name": "Wood_Softwood_Planks"
    },
    {
      "x": -21,
      "y": 1,
      "z": 11,
      "name": "Rock_Stone_Brick"
    },
    {
      "x": -21,
      "y": 2,
      "z": 11,
      "name": "Rock_Quartzite"
    },
    {
      "x": -21,
      "y": 3,
      "z": 11,
      "name": "Rock_Quartzite"
    },
    {
      "x": -21,
      "y": 4,
      "z": 11,
      "name": "Wood_Softwood_Planks"
    },
    {
      "x": -21,
      "y": 5,
      "z": 11,
      "name": "Rock_Quartzite"
    },
    {
      "x": -21,
      "y": 6,
      "z": 11,
      "name": "Rock_Quartzite"
    },
    {
      "x": -21,
      "y": 7,
      "z": 11,
      "name": "Rock_Quartzite"
    },
    {
      "x": -21,
      "y": 8,
      "z": 11,
      "name": "Wood_Oak_Trunk",
      "support": 15,
      "rotation": 4
    },
    {
      "x": -21,
      "y": 9,
      "z": 11,
      "name": "Wood_Oak_Trunk",
      "support": 15,
      "rotation": 5
    },
    {
      "x": -21,
      "y": 10,
      "z": 11,
      "name": "Rock_Quartzite"
    },
    {
      "x": -21,
      "y": 11,
      "z": 11,
      "name": "Rock_Quartzite"
    },
    {
      "x": -21,
      "y": 13,
      "z": 11,
      "name": "Wood_Softwood_Planks_Half"
    },
    {
      "x": -21,
      "y": 0,
      "z": 12,
      "name": "Wood_Softwood_Planks"
    },
    {
      "x": -21,
      "y": 1,
      "z": 12,
      "name": "Rock_Stone_Brick"
    },
    {
      "x": -21,
      "y": 2,
      "z": 12,
      "name": "Rock_Quartzite"
    },
    {
      "x": -21,
      "y": 3,
      "z": 12,
      "name": "Rock_Quartzite"
    },
    {
      "x": -21,
      "y": 4,
      "z": 12,
      "name": "Wood_Softwood_Planks"
    },
    {
      "x": -21,
      "y": 5,
      "z": 12,
      "name": "Wood_Oak_Trunk",
      "support": 15
    },
    {
      "x": -21,
      "y": 6,
      "z": 12,
      "name": "Wood_Oak_Trunk",
      "support": 15
    },
    {
      "x": -21,
      "y": 7,
      "z": 12,
      "name": "Wood_Oak_Trunk",
      "support": 15
    },
    {
      "x": -21,
      "y": 8,
      "z": 12,
      "name": "Wood_Oak_Trunk",
      "support": 15,
      "rotation": 4
    },
    {
      "x": -21,
      "y": 9,
      "z": 12,
      "name": "Rock_Quartzite"
    },
    {
      "x": -21,
      "y": 10,
      "z": 12,
      "name": "Rock_Quartzite"
    },
    {
      "x": -21,
      "y": 11,
      "z": 12,
      "name": "Rock_Quartzite"
    },
    {
      "x": -21,
      "y": 12,
      "z": 12,
      "name": "Wood_Softwood_Roof"
    },
    {
      "x": -21,
      "y": 0,
      "z": 13,
      "name": "Wood_Softwood_Planks"
    },
    {
      "x": -21,
      "y": 1,
      "z": 13,
      "name": "Rock_Stone_Brick"
    },
    {
      "x": -21,
      "y": 2,
      "z": 13,
      "name": "Rock_Quartzite"
    },
    {
      "x": -21,
      "y": 3,
      "z": 13,
      "name": "Rock_Quartzite"
    },
    {
      "x": -21,
      "y": 4,
      "z": 13,
      "name": "Wood_Softwood_Planks"
    },
    {
      "x": -21,
      "y": 8,
      "z": 13,
      "name": "Wood_Oak_Trunk",
      "support": 15,
      "rotation": 4
    },
    {
      "x": -21,
      "y": 9,
      "z": 13,
      "name": "Rock_Quartzite"
    },
    {
      "x": -21,
      "y": 10,
      "z": 13,
      "name": "Rock_Quartzite"
    },
    {
      "x": -21,
      "y": 11,
      "z": 13,
      "name": "Wood_Softwood_Roof"
    },
    {
      "x": -21,
      "y": 0,
      "z": 14,
      "name": "Wood_Softwood_Planks"
    },
    {
      "x": -21,
      "y": 1,
      "z": 14,
      "name": "Rock_Stone_Brick"
    },
    {
      "x": -21,
      "y": 2,
      "z": 14,
      "name": "Rock_Quartzite"
    },
    {
      "x": -21,
      "y": 3,
      "z": 14,
      "name": "Rock_Quartzite"
    },
    {
      "x": -21,
      "y": 4,
      "z": 14,
      "name": "Wood_Softwood_Planks"
    },
    {
      "x": -21,
      "y": 8,
      "z": 14,
      "name": "Wood_Oak_Trunk",
      "support": 15,
      "rotation": 4
    },
    {
      "x": -21,
      "y": 9,
      "z": 14,
      "name": "Wood_Softwood_Roof_Steep"
    },
    {
      "x": -21,
      "y": 10,
      "z": 14,
      "name": "Wood_Softwood_Roof_Steep",
      "filler": 1024
    },
    {
      "x": -21,
      "y": 0,
      "z": 15,
      "name": "Rock_Stone_Cobble"
    },
    {
      "x": -21,
      "y": 1,
      "z": 15,
      "name": "Wood_Oak_Trunk",
      "support": 15
    },
    {
      "x": -21,
      "y": 2,
      "z": 15,
      "name": "Wood_Oak_Trunk",
      "support": 15
    },
    {
      "x": -21,
      "y": 3,
      "z": 15,
      "name": "Wood_Oak_Trunk",
      "support": 15
    },
    {
      "x": -21,
      "y": 4,
      "z": 15,
      "name": "Wood_Softwood_Planks"
    },
    {
      "x": -21,
      "y": 5,
      "z": 15,
      "name": "Wood_Oak_Trunk",
      "support": 15
    },
    {
      "x": -21,
      "y": 6,
      "z": 15,
      "name": "Wood_Oak_Trunk",
      "support": 15
    },
    {
      "x": -21,
      "y": 7,
      "z": 15,
      "name": "*Wood_Softwood_Roof_Steep_State_Definitions_Inverted_Corner_Left",
      "rotation": 3
    },
    {
      "x": -21,
      "y": 8,
      "z": 15,
      "name": "*Wood_Softwood_Roof_Steep_State_Definitions_Inverted_Corner_Left",
      "filler": 1024,
      "rotation": 3
    },
    {
      "x": -21,
      "y": 0,
      "z": 16,
      "name": "Rock_Stone_Cobble"
    },
    {
      "x": -21,
      "y": 1,
      "z": 16,
      "name": "Rock_Stone_Brick"
    },
    {
      "x": -21,
      "y": 2,
      "z": 16,
      "name": "Rock_Quartzite"
    },
    {
      "x": -21,
      "y": 3,
      "z": 16,
      "name": "Rock_Quartzite"
    },
    {
      "x": -21,
      "y": 4,
      "z": 16,
      "name": "Wood_Softwood_Planks"
    },
    {
      "x": -21,
      "y": 5,
      "z": 16,
      "name": "Rock_Quartzite"
    },
    {
      "x": -21,
      "y": 6,
      "z": 16,
      "name": "Rock_Quartzite"
    },
    {
      "x": -21,
      "y": 7,
      "z": 16,
      "name": "Wood_Softwood_Roof_Steep",
      "rotation": 3
    },
    {
      "x": -21,
      "y": 8,
      "z": 16,
      "name": "Wood_Softwood_Roof_Steep",
      "filler": 1024,
      "rotation": 3
    },
    {
