{
  "version": 8,
  "blockIdVersion": 11,
  "anchorX": 0,
  "anchorY": 0,
  "anchorZ": 0,
  "blocks": [
    {
      "x": 1,
      "y": 1,
      "z": -14,
      "name": "Rock_Stone_Cobble"
    },
    {
      "x": 1,
      "y": 9,
      "z": -14,
      "name": "Wood_Softwood_Roof_Hollow",
      "rotation": 3
    },
    {
      "x": 1,
      "y": 1,
      "z": -13,
      "name": "Rock_Stone_Cobble"
    },
    {
      "x": 1,
      "y": 8,
      "z": -13,
      "name": "Wood_Beech_Branch_Corner",
      "support": 15,
      "rotation": 3
    },
    {
      "x": 1,
      "y": 9,
      "z": -13,
      "name": "Wood_Softwood_Roof",
      "rotation": 3
    },
    {
      "x": 1,
      "y": 1,
      "z": -12,
      "name": "Rock_Stone_Cobble_Mossy"
    },
    {
      "x": 1,
      "y": 5,
      "z": -12,
      "name": "Plant_Vine_Wall",
      "support": 15,
      "rotation": 3
    },
    {
      "x": 1,
      "y": 9,
      "z": -12,
      "name": "Wood_Softwood_Roof_Hollow",
      "rotation": 3
    },
    {
      "x": 1,
      "y": 1,
      "z": -11,
      "name": "Rock_Stone_Cobble"
    },
    {
      "x": 1,
      "y": 9,
      "z": -11,
      "name": "Wood_Softwood_Roof_Hollow",
      "rotation": 3
    },
    {
      "x": 1,
      "y": 1,
      "z": -10,
      "name": "Rock_Stone_Cobble"
    },
    {
      "x": 1,
      "y": 9,
      "z": -10,
      "name": "Wood_Softwood_Roof_Hollow",
      "rotation": 3
    },
    {
      "x": 1,
      "y": 1,
      "z": -9,
      "name": "Rock_Stone_Cobble"
    },
    {
      "x": 1,
      "y": 9,
      "z": -9,
      "name": "Wood_Softwood_Roof_Hollow",
      "rotation": 3
    },
    {
      "x": 1,
      "y": 1,
      "z": -8,
      "name": "Rock_Stone_Cobble"
    },
    {
      "x": 1,
      "y": 7,
      "z": -8,
      "name": "Plant_Vine_Wall",
      "support": 15,
      "rotation": 3
    },
    {
      "x": 1,
      "y": 9,
      "z": -8,
      "name": "Wood_Softwood_Roof_Hollow",
      "rotation": 3
    },
    {
      "x": 1,
      "y": 1,
      "z": -7,
      "name": "Rock_Stone_Cobble"
    },
    {
      "x": 1,
      "y": 8,
      "z": -7,
      "name": "Wood_Beech_Branch_Corner",
      "support": 15,
      "rotation": 3
    },
    {
      "x": 1,
      "y": 9,
      "z": -7,
      "name": "Wood_Softwood_Roof",
      "rotation": 3
    },
    {
      "x": 1,
      "y": 1,
      "z": -6,
      "name": "Rock_Stone_Cobble"
    },
    {
      "x": 1,
      "y": 4,
      "z": -6,
      "name": "Cloth_Roof_White_Flap",
      "rotation": 3
    },
    {
      "x": 1,
      "y": 9,
      "z": -6,
      "name": "Wood_Softwood_Roof_Hollow",
      "rotation": 3
    },
    {
      "x": 1,
      "y": 1,
      "z": -5,
      "name": "Rock_Stone_Cobble"
    },
    {
      "x": 1,
      "y": 4,
      "z": -5,
      "name": "Cloth_Roof_Green_Flap",
      "rotation": 3
    },
    {
      "x": 1,
      "y": 1,
      "z": -4,
      "name": "Rock_Stone_Cobble_Mossy"
    },
    {
      "x": 1,
      "y": 4,
      "z": -4,
      "name": "Cloth_Roof_White_Flap",
      "rotation": 3
    },
    {
      "x": 1,
      "y": 1,
      "z": -3,
      "name": "Rock_Stone_Cobble_Mossy"
    },
    {
      "x": 1,
      "y": 4,
      "z": -3,
      "name": "Cloth_Roof_Green_Flap",
      "rotation": 3
    },
    {
      "x": 1,
      "y": 1,
      "z": -2,
      "name": "Rock_Stone_Cobble"
    },
    {
      "x": 1,
      "y": 4,
      "z": -2,
      "name": "Cloth_Roof_White_Flap",
      "rotation": 3
    },
    {
      "x": 1,
      "y": 1,
      "z": -1,
      "name": "Rock_Stone_Cobble"
    },
    {
      "x": 2,
      "y": 1,
      "z": -14,
      "name": "Rock_Stone_Cobble"
    },
    {
      "x": 2,
      "y": 9,
      "z": -14,
      "name": "Wood_Beech_Branch_Corner",
      "support": 15,
      "rotation": 2
    },
    {
      "x": 2,
      "y": 10,
      "z": -14,
      "name": "Wood_Softwood_Roof",
      "rotation": 3
    },
    {
      "x": 2,
      "y": 1,
      "z": -13,
      "name": "Rock_Stone_Cobble"
    },
    {
      "x": 2,
      "y": 2,
      "z": -13,
      "name": "Wood_Beech_Trunk",
      "support": 15
    },
    {
      "x": 2,
      "y": 3,
      "z": -13,
      "name": "Wood_Beech_Trunk",
      "support": 15
    },
    {
      "x": 2,
      "y": 4,
      "z": -13,
      "name": "Wood_Beech_Trunk",
      "support": 15
    },
    {
      "x": 2,
      "y": 5,
      "z": -13,
      "name": "Wood_Beech_Trunk",
      "support": 15
    },
    {
      "x": 2,
      "y": 6,
      "z": -13,
      "name": "Wood_Beech_Trunk",
      "support": 15
    },
    {
      "x": 2,
      "y": 7,
      "z": -13,
      "name": "Wood_Beech_Trunk",
      "support": 15
    },
    {
      "x": 2,
      "y": 8,
      "z": -13,
      "name": "Wood_Beech_Trunk",
      "support": 15
    },
    {
      "x": 2,
      "y": 9,
      "z": -13,
      "name": "Wood_Beech_Trunk",
      "support": 15
    },
    {
      "x": 2,
      "y": 10,
      "z": -13,
      "name": "Wood_Softwood_Roof",
      "rotation": 3
    },
    {
      "x": 2,
      "y": 1,
      "z": -12,
      "name": "Rock_Stone_Cobble"
    },
    {
      "x": 2,
      "y": 2,
      "z": -12,
      "name": "Rock_Stone_Brick"
    },
    {
      "x": 2,
      "y": 3,
      "z": -12,
      "name": "*Wood_Village_Wall_Full_State_Definitions_Bottom"
    },
    {
      "x": 2,
      "y": 4,
      "z": -12,
      "name": "*Wood_Village_Wall_Full_State_Definitions_Top"
    },
    {
      "x": 2,
      "y": 5,
      "z": -12,
      "name": "Wood_Beech_Trunk",
      "support": 15,
      "rotation": 4
    },
    {
      "x": 2,
      "y": 6,
      "z": -12,
      "name": "*Wood_Village_Wall_Full_State_Definitions_Bottom"
    },
    {
      "x": 2,
      "y": 7,
      "z": -12,
      "name": "*Wood_Village_Wall_Full_State_Definitions_Middle"
    },
    {
      "x": 2,
      "y": 8,
      "z": -12,
      "name": "*Wood_Village_Wall_Full_State_Definitions_Top"
    },
    {
      "x": 2,
      "y": 9,
      "z": -12,
      "name": "Wood_Beech_Trunk",
      "support": 15,
      "rotation": 4
    },
    {
      "x": 2,
      "y": 10,
      "z": -12,
      "name": "Wood_Softwood_Roof",
      "rotation": 3
    },
    {
      "x": 2,
      "y": 1,
      "z": -11,
      "name": "Rock_Stone_Cobble_Mossy"
    },
    {
      "x": 2,
      "y": 2,
      "z": -11,
      "name": "Rock_Stone_Brick"
    },
    {
      "x": 2,
      "y": 3,
      "z": -11,
      "name": "*Wood_Village_Wall_Full_State_Definitions_Bottom"
    },
    {
      "x": 2,
      "y": 4,
      "z": -11,
      "name": "*Wood_Village_Wall_Full_State_Definitions_Top"
    },
    {
      "x": 2,
      "y": 5,
      "z": -11,
      "name": "Wood_Beech_Trunk",
      "support": 15,
      "rotation": 4
    },
    {
      "x": 2,
      "y": 6,
      "z": -11,
      "name": "Wood_Village_Wall_Full"
    },
    {
      "x": 2,
      "y": 7,
      "z": -11,
      "name": "Furniture_Village_Window",
      "rotation": 1
    },
    {
      "x": 2,
      "y": 8,
      "z": -11,
      "name": "Wood_Village_Wall_Full"
    },
    {
      "x": 2,
      "y": 9,
      "z": -11,
      "name": "Wood_Beech_Trunk",
      "support": 15,
      "rotation": 4
    },
    {
      "x": 2,
      "y": 10,
      "z": -11,
      "name": "Wood_Softwood_Roof",
      "rotation": 3
    },
    {
      "x": 2,
      "y": 1,
      "z": -10,
      "name": "Wood_Softwood_Planks"
    },
    {
      "x": 2,
      "y": 2,
      "z": -10,
      "name": "Furniture_Village_Door",
      "rotation": 3
    },
    {
      "x": 2,
      "y": 3,
      "z": -10,
      "name": "Furniture_Village_Door",
      "filler": 1024,
      "rotation": 3
    },
    {
      "x": 2,
      "y": 4,
      "z": -10,
      "name": "Wood_Village_Wall_Full"
    },
    {
      "x": 2,
      "y": 5,
      "z": -10,
      "name": "Wood_Beech_Trunk",
      "support": 15,
      "rotation": 4
    },
    {
      "x": 2,
      "y": 6,
      "z": -10,
      "name": "*Wood_Village_Wall_Full_State_Definitions_Bottom"
    },
    {
      "x": 2,
      "y": 7,
      "z": -10,
      "name": "*Wood_Village_Wall_Full_State_Definitions_Middle"
    },
    {
      "x": 2,
      "y": 8,
      "z": -10,
      "name": "*Wood_Village_Wall_Full_State_Definitions_Top"
    },
    {
      "x": 2,
      "y": 9,
      "z": -10,
      "name": "Wood_Beech_Trunk",
      "support": 15,
      "rotation": 4
    },
    {
      "x": 2,
      "y": 10,
      "z": -10,
      "name": "Wood_Softwood_Roof",
      "rotation": 3
    },
    {
      "x": 2,
      "y": 1,
      "z": -9,
      "name": "Rock_Stone_Cobble"
    },
    {
      "x": 2,
      "y": 2,
      "z": -9,
      "name": "Rock_Stone_Brick"
    },
    {
      "x": 2,
      "y": 3,
      "z": -9,
      "name": "*Wood_Village_Wall_Full_State_Definitions_Bottom"
    },
    {
      "x": 2,
      "y": 4,
      "z": -9,
      "name": "*Wood_Village_Wall_Full_State_Definitions_Top"
    },
    {
      "x": 2,
      "y": 5,
      "z": -9,
      "name": "Wood_Beech_Trunk",
      "support": 15,
      "rotation": 4
    },
    {
      "x": 2,
      "y": 6,
      "z": -9,
      "name": "Wood_Village_Wall_Full"
    },
    {
      "x": 2,
      "y": 7,
      "z": -9,
      "name": "Furniture_Village_Window",
      "rotation": 1
    },
    {
      "x": 2,
      "y": 8,
      "z": -9,
      "name": "Wood_Village_Wall_Full"
    },
    {
      "x": 2,
      "y": 9,
      "z": -9,
      "name": "Wood_Beech_Trunk",
      "support": 15,
      "rotation": 4
    },
    {
      "x": 2,
      "y": 10,
      "z": -9,
      "name": "Wood_Softwood_Roof",
      "rotation": 3
    },
    {
      "x": 2,
      "y": 1,
      "z": -8,
      "name": "Rock_Stone_Cobble"
    },
    {
      "x": 2,
      "y": 2,
      "z": -8,
      "name": "Rock_Stone_Brick_Mossy"
    },
    {
      "x": 2,
      "y": 3,
      "z": -8,
      "name": "*Wood_Village_Wall_Full_State_Definitions_Bottom"
    },
    {
      "x": 2,
      "y": 4,
      "z": -8,
      "name": "*Wood_Village_Wall_Full_State_Definitions_Top"
    },
    {
      "x": 2,
      "y": 5,
      "z": -8,
      "name": "Wood_Beech_Trunk",
      "support": 15,
      "rotation": 4
    },
    {
      "x": 2,
      "y": 6,
      "z": -8,
      "name": "*Wood_Village_Wall_Full_State_Definitions_Bottom"
    },
    {
      "x": 2,
      "y": 7,
      "z": -8,
      "name": "*Wood_Village_Wall_Full_State_Definitions_Middle"
    },
    {
      "x": 2,
      "y": 8,
      "z": -8,
      "name": "*Wood_Village_Wall_Full_State_Definitions_Top"
    },
    {
      "x": 2,
      "y": 9,
      "z": -8,
      "name": "Wood_Beech_Trunk",
      "support": 15,
      "rotation": 4
    },
    {
      "x": 2,
      "y": 10,
      "z": -8,
      "name": "Wood_Softwood_Roof",
      "rotation": 3
    },
    {
      "x": 2,
      "y": 1,
      "z": -7,
      "name": "Rock_Stone_Cobble_Mossy"
    },
    {
      "x": 2,
      "y": 2,
      "z": -7,
      "name": "Wood_Beech_Trunk",
      "support": 15
    },
    {
      "x": 2,
      "y": 3,
      "z": -7,
      "name": "Wood_Beech_Trunk",
      "support": 15
    },
    {
      "x": 2,
      "y": 4,
      "z": -7,
      "name": "Wood_Beech_Trunk",
      "support": 15
    },
    {
      "x": 2,
      "y": 5,
      "z": -7,
      "name": "Wood_Beech_Trunk",
      "support": 15
    },
    {
      "x": 2,
      "y": 6,
      "z": -7,
      "name": "Wood_Beech_Trunk",
      "support": 15
    },
    {
      "x": 2,
      "y": 7,
      "z": -7,
      "name": "Wood_Beech_Trunk",
      "support": 15
    },
    {
      "x": 2,
      "y": 8,
      "z": -7,
      "name": "Wood_Beech_Trunk",
      "support": 15
    },
    {
      "x": 2,
      "y": 9,
      "z": -7,
      "name": "Wood_Beech_Trunk",
      "support": 15
    },
    {
      "x": 2,
      "y": 10,
      "z": -7,
      "name": "Wood_Softwood_Roof",
      "rotation": 3
    },
    {
      "x": 2,
      "y": 1,
      "z": -6,
      "name": "Rock_Stone_Brick_Smooth"
    },
    {
      "x": 2,
      "y": 3,
      "z": -6,
      "name": "Wood_Torch_Wall",
      "support": 15
    },
    {
      "x": 2,
      "y": 5,
      "z": -6,
      "name": "Cloth_Roof_White",
      "rotation": 3
    },
    {
      "x": 2,
      "y": 7,
      "z": -6,
      "name": "Plant_Vine_Wall",
      "support": 15
    },
    {
      "x": 2,
      "y": 9,
      "z": -6,
      "name": "Wood_Beech_Branch_Corner",
      "support": 15
    },
    {
      "x": 2,
      "y": 10,
      "z": -6,
      "name": "Wood_Softwood_Roof",
      "rotation": 3
    },
    {
      "x": 2,
      "y": 1,
      "z": -5,
      "name": "Rock_Stone_Brick_Smooth"
    },
    {
      "x": 2,
      "y": 5,
      "z": -5,
      "name": "Cloth_Roof_Green",
      "rotation": 3
    },
    {
      "x": 2,
      "y": 1,
      "z": -4,
      "name": "Rock_Stone_Brick_Smooth"
    },
    {
      "x": 2,
      "y": 5,
      "z": -4,
      "name": "Cloth_Roof_White",
      "rotation": 3
    },
    {
      "x": 2,
      "y": 1,
      "z": -3,
      "name": "Rock_Stone_Brick_Smooth"
    },
    {
      "x": 2,
      "y": 2,
      "z": -3,
      "name": "Furniture_Village_Planter",
      "support": 15
    },
    {
      "x": 2,
      "y": 3,
      "z": -3,
      "name": "Plant_Flower_Orchid_Pink",
      "support": 15
    },
    {
      "x": 2,
      "y": 5,
      "z": -3,
      "name": "Cloth_Roof_Green",
      "rotation": 3
    },
    {
      "x": 2,
      "y": 1,
      "z": -2,
      "name": "Rock_Stone_Brick_Smooth"
    },
    {
      "x": 2,
      "y": 2,
      "z": -2,
      "name": "Wood_Beech_Trunk",
      "support": 15
    },
    {
      "x": 2,
      "y": 3,
      "z": -2,
      "name": "Wood_Softwood_Beam"
    },
    {
      "x": 2,
      "y": 4,
      "z": -2,
      "name": "Wood_Softwood_Beam"
    },
    {
      "x": 2,
      "y": 5,
      "z": -2,
      "name": "*Cloth_Roof_White_State_Definitions_Corner_Right"
    },
    {
      "x": 2,
      "y": 1,
      "z": -1,
      "name": "Rock_Stone_Cobble_Mossy"
    },
    {
      "x": 2,
      "y": 4,
      "z": -1,
      "name": "Cloth_Roof_White_Flap"
    },
    {
      "x": 3,
      "y": 1,
      "z": -14,
      "name": "Rock_Stone_Cobble"
    },
    {
      "x": 3,
      "y": 10,
      "z": -14,
      "name": "Wood_Softwood_Stairs",
      "rotation": 11
    },
    {
      "x": 3,
      "y": 11,
      "z": -14,
      "name": "Wood_Softwood_Roof",
      "rotation": 3
    },
    {
      "x": 3,
      "y": 1,
      "z": -13,
      "name": "Rock_Stone_Cobble"
    },
    {
      "x": 3,
      "y": 2,
      "z": -13,
      "name": "Rock_Stone_Brick"
    },
    {
      "x": 3,
      "y": 3,
      "z": -13,
      "name": "*Wood_Village_Wall_Full_State_Definitions_Bottom"
    },
    {
      "x": 3,
      "y": 4,
      "z": -13,
      "name": "*Wood_Village_Wall_Full_State_Definitions_Top"
    },
    {
      "x": 3,
      "y": 5,
      "z": -13,
      "name": "Wood_Beech_Trunk",
      "support": 15,
      "rotation": 5
    },
    {
      "x": 3,
      "y": 6,
      "z": -13,
      "name": "*Wood_Village_Wall_Full_State_Definitions_Bottom"
    },
    {
      "x": 3,
      "y": 7,
      "z": -13,
      "name": "*Wood_Village_Wall_Full_State_Definitions_Middle"
    },
    {
      "x": 3,
      "y": 8,
      "z": -13,
      "name": "*Wood_Village_Wall_Full_State_Definitions_Top"
    },
    {
      "x": 3,
      "y": 9,
      "z": -13,
      "name": "Wood_Beech_Trunk",
      "support": 15,
      "rotation": 5
    },
    {
      "x": 3,
      "y": 10,
      "z": -13,
      "name": "Wood_Village_Wall_Full"
    },
    {
      "x": 3,
      "y": 11,
      "z": -13,
      "name": "Wood_Softwood_Roof",
      "rotation": 3
    },
    {
      "x": 3,
      "y": 1,
      "z": -12,
      "name": "Wood_Softwood_Planks"
    },
    {
      "x": 3,
      "y": 5,
      "z": -12,
      "name": "Wood_Softwood_Planks"
    },
    {
      "x": 3,
      "y": 6,
      "z": -12,
      "name": "Plant_Leaves_Oak",
      "support": 15
    },
    {
      "x": 3,
      "y": 7,
      "z": -12,
      "name": "Plant_Leaves_Oak",
      "support": 15
    },
    {
      "x": 3,
      "y": 10,
      "z": -12,
      "name": "Wood_Softwood_Stairs",
      "rotation": 11
    },
    {
      "x": 3,
      "y": 11,
      "z": -12,
      "name": "Wood_Softwood_Roof",
      "rotation": 3
    },
    {
      "x": 3,
      "y": 1,
      "z": -11,
      "name": "Wood_Softwood_Planks"
    },
    {
      "x": 3,
      "y": 5,
      "z": -11,
      "name": "Wood_Softwood_Planks"
    },
    {
      "x": 3,
      "y": 6,
      "z": -11,
      "name": "Furniture_Tavern_Planter",
      "support": 15
    },
    {
      "x": 3,
      "y": 7,
      "z": -11,
      "name": "Plant_Flower_Water_Duckweed",
      "support": 15
    },
    {
      "x": 3,
      "y": 10,
      "z": -11,
      "name": "Wood_Softwood_Stairs",
      "rotation": 11
    },
    {
      "x": 3,
      "y": 11,
      "z": -11,
      "name": "Wood_Softwood_Roof",
      "rotation": 3
    },
    {
      "x": 3,
      "y": 1,
      "z": -10,
      "name": "Wood_Softwood_Planks"
    },
    {
      "x": 3,
      "y": 5,
      "z": -10,
      "name": "Wood_Softwood_Planks"
    },
    {
      "x": 3,
      "y": 10,
      "z": -10,
      "name": "Wood_Softwood_Stairs",
      "rotation": 11
    },
    {
      "x": 3,
      "y": 11,
      "z": -10,
      "name": "Wood_Softwood_Roof",
      "rotation": 3
    },
    {
      "x": 3,
      "y": 1,
      "z": -9,
      "name": "Wood_Softwood_Planks"
    },
    {
      "x": 3,
      "y": 2,
      "z": -9,
      "name": "Aetherhaven_Management_Block",
      "components": {
        "Components": {
          "AetherhavenManagementBlock": {
            "PlotId": "",
            "TownId": ""
          },
          "PlacedByInteraction": {
            "WhoPlacedUuid": {
              "$binary": "v7RyWIT/TYKnXA2XcxdQtw==",
              "$type": "04"
            }
          }
        }
      },
      "rotation": 1
    },
    {
      "x": 3,
      "y": 5,
      "z": -9,
      "name": "Wood_Softwood_Planks"
    },
    {
      "x": 3,
      "y": 6,
      "z": -9,
      "name": "Furniture_Tavern_Planter",
      "support": 15
    },
    {
      "x": 3,
      "y": 7,
      "z": -9,
      "name": "Plant_Flower_Orchid_Poisoned",
      "support": 15
    },
    {
      "x": 3,
      "y": 10,
      "z": -9,
      "name": "Wood_Softwood_Stairs",
      "rotation": 11
    },
    {
      "x": 3,
      "y": 11,
      "z": -9,
      "name": "Wood_Softwood_Roof",
      "rotation": 3
    },
    {
      "x": 3,
      "y": 1,
      "z": -8,
      "name": "Wood_Softwood_Planks"
    },
    {
      "x": 3,
      "y": 2,
      "z": -8,
      "name": "Furniture_Tavern_Planter",
      "support": 15
    },
    {
      "x": 3,
      "y": 3,
      "z": -8,
      "name": "Plant_Flower_Common_Cyan",
      "support": 15
    },
    {
      "x": 3,
      "y": 5,
      "z": -8,
      "name": "Wood_Softwood_Planks"
    },
    {
      "x": 3,
      "y": 6,
      "z": -8,
      "name": "Plant_Leaves_Oak",
      "support": 15
    },
    {
      "x": 3,
      "y": 7,
      "z": -8,
      "name": "Plant_Leaves_Oak",
      "support": 15
    },
    {
      "x": 3,
      "y": 10,
      "z": -8,
      "name": "Wood_Softwood_Stairs",
      "rotation": 11
    },
    {
      "x": 3,
      "y": 11,
      "z": -8,
      "name": "Wood_Softwood_Roof",
      "rotation": 3
    },
    {
      "x": 3,
      "y": 1,
      "z": -7,
      "name": "Wood_Softwood_Planks"
    },
    {
      "x": 3,
      "y": 2,
      "z": -7,
      "name": "Wood_Softwood_Stairs",
      "rotation": 11
    },
    {
      "x": 3,
      "y": 3,
      "z": -7,
      "name": "Aetherhaven_Shop_Spot",
      "components": {
        "Components": {
          "AetherhavenShopSpotBlock": {
            "SpotId": "68dee57a-96bf-4715-a889-ff43ca58f926",
            "TownId": "d87b9d18-a6de-42a7-9697-90f4c2aa0d9f",
            "PlotId": "00000000-0000-0000-0000-000000000000",
            "PlayerControlled": false,
            "LootTableId": "florist_common",
            "Configured": true
          },
          "PlacedByInteraction": {
            "WhoPlacedUuid": {
              "$binary": "v7RyWIT/TYKnXA2XcxdQtw==",
              "$type": "04"
            }
          }
        }
      }
    },
    {
      "x": 3,
      "y": 4,
      "z": -7,
      "name": "Wood_Softwood_Stairs",
      "rotation": 11
    },
    {
      "x": 3,
      "y": 5,
      "z": -7,
      "name": "Wood_Beech_Trunk",
      "support": 15,
      "rotation": 5
    },
    {
      "x": 3,
      "y": 6,
      "z": -7,
      "name": "*Wood_Village_Wall_Full_State_Definitions_Bottom"
    },
    {
      "x": 3,
      "y": 7,
      "z": -7,
      "name": "*Wood_Village_Wall_Full_State_Definitions_Middle"
    },
    {
      "x": 3,
      "y": 8,
      "z": -7,
      "name": "*Wood_Village_Wall_Full_State_Definitions_Top"
    },
    {
      "x": 3,
      "y": 9,
      "z": -7,
      "name": "Wood_Beech_Trunk",
      "support": 15,
      "rotation": 5
    },
    {
      "x": 3,
      "y": 10,
      "z": -7,
      "name": "Wood_Village_Wall_Full"
    },
    {
      "x": 3,
      "y": 11,
      "z": -7,
      "name": "Wood_Softwood_Roof",
      "rotation": 3
    },
    {
      "x": 3,
      "y": 1,
      "z": -6,
      "name": "Rock_Stone_Brick"
    },
    {
      "x": 3,
      "y": 6,
      "z": -6,
      "name": "Cloth_Roof_Green_Flat"
    },
    {
      "x": 3,
      "y": 10,
      "z": -6,
      "name": "Wood_Softwood_Stairs",
      "rotation": 11
    },
    {
      "x": 3,
      "y": 11,
      "z": -6,
      "name": "Wood_Softwood_Roof",
      "rotation": 3
    },
    {
      "x": 3,
      "y": 1,
      "z": -5,
      "name": "Rock_Stone_Brick"
    },
    {
      "x": 3,
      "y": 6,
      "z": -5,
      "name": "Cloth_Roof_White_Flat"
    },
    {
      "x": 3,
      "y": 1,
      "z": -4,
      "name": "Rock_Stone_Brick"
    },
    {
      "x": 3,
      "y": 6,
      "z": -4,
      "name": "Cloth_Roof_Green_Flat"
    },
    {
      "x": 3,
      "y": 1,
      "z": -3,
      "name": "Rock_Stone_Brick"
    },
    {
      "x": 3,
      "y": 6,
      "z": -3,
      "name": "Cloth_Roof_White_Flat"
    },
    {
      "x": 3,
      "y": 1,
      "z": -2,
      "name": "Rock_Stone_Brick_Smooth"
    },
    {
      "x": 3,
      "y": 2,
      "z": -2,
      "name": "Furniture_Village_Planter",
      "support": 15
    },
    {
      "x": 3,
      "y": 3,
      "z": -2,
      "name": "Plant_Flower_Common_Orange",
      "support": 15
    },
    {
      "x": 3,
      "y": 5,
      "z": -2,
      "name": "Cloth_Roof_Green"
    },
    {
      "x": 3,
      "y": 1,
      "z": -1,
      "name": "Rock_Stone_Cobble"
    },
    {
      "x": 3,
      "y": 4,
      "z": -1,
      "name": "Cloth_Roof_Green_Flap"
    },
    {
      "x": 4,
      "y": 1,
      "z": -14,
      "name": "Rock_Stone_Cobble_Mossy"
    },
    {
      "x": 4,
      "y": 4,
      "z": -14,
      "name": "Plant_Vine_Wall",
      "support": 15,
      "rotation": 2
    },
    {
      "x": 4,
      "y": 11,
      "z": -14,
      "name": "Wood_Softwood_Stairs",
      "rotation": 11
    },
    {
      "x": 4,
      "y": 12,
      "z": -14,
      "name": "Wood_Softwood_Roof",
      "rotation": 3
    },
    {
      "x": 4,
      "y": 1,
      "z": -13,
      "name": "Rock_Stone_Cobble"
    },
    {
      "x": 4,
      "y": 2,
      "z": -13,
      "name": "Rock_Stone_Brick_Mossy"
    },
    {
      "x": 4,
      "y": 3,
      "z": -13,
      "name": "*Wood_Village_Wall_Full_State_Definitions_Bottom"
    },
    {
      "x": 4,
      "y": 4,
      "z": -13,
      "name": "*Wood_Village_Wall_Full_State_Definitions_Top"
    },
    {
      "x": 4,
      "y": 5,
      "z": -13,
      "name": "Wood_Beech_Trunk",
      "support": 15,
      "rotation": 5
    },
    {
      "x": 4,
      "y": 6,
      "z": -13,
      "name": "*Wood_Village_Wall_Full_State_Definitions_Bottom"
    },
    {
      "x": 4,
      "y": 7,
      "z": -13,
      "name": "*Wood_Village_Wall_Full_State_Definitions_Middle"
    },
    {
      "x": 4,
      "y": 8,
      "z": -13,
      "name": "*Wood_Village_Wall_Full_State_Definitions_Top"
    },
    {
      "x": 4,
      "y": 9,
      "z": -13,
      "name": "Wood_Beech_Trunk",
      "support": 15,
      "rotation": 5
    },
    {
      "x": 4,
      "y": 10,
      "z": -13,
      "name": "*Wood_Village_Wall_Full_State_Definitions_Bottom"
    },
    {
      "x": 4,
      "y": 11,
      "z": -13,
      "name": "*Wood_Village_Wall_Full_State_Definitions_Top"
    },
    {
      "x": 4,
      "y": 12,
      "z": -13,
      "name": "Wood_Softwood_Roof",
      "rotation": 3
    },
    {
      "x": 4,
      "y": 1,
      "z": -12,
      "name": "Wood_Softwood_Planks"
    },
    {
      "x": 4,
      "y": 2,
      "z": -12,
      "name": "Wood_Softwood_Stairs",
      "rotation": 3
    },
    {
      "x": 4,
      "y": 11,
      "z": -12,
      "name": "Wood_Softwood_Stairs",
      "rotation": 11
    },
    {
      "x": 4,
      "y": 12,
      "z": -12,
      "name": "Wood_Softwood_Roof",
      "rotation": 3
    },
    {
      "x": 4,
      "y": 1,
      "z": -11,
      "name": "Wood_Softwood_Planks"
    },
    {
      "x": 4,
      "y": 2,
      "z": -11,
      "name": "Plant_Moss_Rug_Green",
      "support": 15
    },
    {
      "x": 4,
      "y": 5,
      "z": -11,
      "name": "Wood_Softwood_Planks"
    },
    {
      "x": 4,
      "y": 6,
      "z": -11,
      "name": "Plant_Moss_Rug_Green",
      "support": 15
    },
    {
      "x": 4,
      "y": 11,
      "z": -11,
      "name": "Wood_Softwood_Stairs",
      "rotation": 11
    },
    {
      "x": 4,
      "y": 12,
      "z": -11,
      "name": "Wood_Softwood_Roof",
      "rotation": 3
    },
    {
      "x": 4,
      "y": 1,
      "z": -10,
      "name": "Wood_Softwood_Planks"
    },
    {
      "x": 4,
      "y": 2,
      "z": -10,
      "name": "Plant_Moss_Rug_Green",
      "support": 15
    },
    {
      "x": 4,
      "y": 4,
      "z": -10,
      "name": "Furniture_Kweebec_Lantern_Ceiling",
      "support": 15
    },
    {
      "x": 4,
      "y": 5,
      "z": -10,
      "name": "Wood_Softwood_Planks"
    },
    {
      "x": 4,
      "y": 6,
      "z": -10,
      "name": "Plant_Moss_Rug_Green",
      "support": 15
    },
    {
      "x": 4,
      "y": 9,
      "z": -10,
      "name": "Furniture_Kweebec_Lantern_Ceiling",
      "support": 15
    },
    {
      "x": 4,
      "y": 10,
      "z": -10,
      "name": "Wood_Softwood_Beam"
    },
    {
      "x": 4,
      "y": 11,
      "z": -10,
      "name": "Wood_Softwood_Planks"
    },
    {
      "x": 4,
      "y": 12,
      "z": -10,
      "name": "Wood_Softwood_Roof",
      "rotation": 3
    },
    {
      "x": 4,
      "y": 1,
      "z": -9,
      "name": "Wood_Softwood_Planks"
    },
    {
      "x": 4,
      "y": 2,
      "z": -9,
      "name": "Plant_Moss_Rug_Green",
      "support": 15
    },
    {
      "x": 4,
      "y": 5,
      "z": -9,
      "name": "Wood_Softwood_Planks"
    },
    {
      "x": 4,
      "y": 6,
      "z": -9,
      "name": "Plant_Moss_Rug_Green",
      "support": 15
    },
    {
      "x": 4,
      "y": 11,
      "z": -9,
      "name": "Wood_Softwood_Stairs",
      "rotation": 11
    },
    {
      "x": 4,
      "y": 12,
      "z": -9,
      "name": "Wood_Softwood_Roof",
      "rotation": 3
    },
    {
      "x": 4,
      "y": 1,
      "z": -8,
      "name": "Wood_Softwood_Planks"
    },
    {
      "x": 4,
      "y": 5,
      "z": -8,
      "name": "Wood_Softwood_Planks"
    },
    {
      "x": 4,
      "y": 6,
      "z": -8,
      "name": "Furniture_Tavern_Planter",
      "support": 15
    },
    {
      "x": 4,
      "y": 7,
      "z": -8,
      "name": "Plant_Flower_Common_White2",
      "support": 15
    },
    {
      "x": 4,
      "y": 11,
      "z": -8,
      "name": "Wood_Softwood_Stairs",
      "rotation": 11
    },
    {
      "x": 4,
      "y": 12,
      "z": -8,
      "name": "Wood_Softwood_Roof",
      "rotation": 3
    },
    {
      "x": 4,
      "y": 1,
      "z": -7,
      "name": "Wood_Softwood_Planks"
    },
    {
      "x": 4,
      "y": 2,
      "z": -7,
      "name": "Wood_Softwood_Planks_Half",
      "rotation": 8
    },
    {
      "x": 4,
      "y": 3,
      "z": -7,
      "name": "Aetherhaven_Shop_Spot",
      "components": {
        "Components": {
          "AetherhavenShopSpotBlock": {
            "SpotId": "d43640e4-6697-447c-a823-46fbb84cb3ee",
            "TownId": "d87b9d18-a6de-42a7-9697-90f4c2aa0d9f",
            "PlotId": "00000000-0000-0000-0000-000000000000",
            "PlayerControlled": false,
            "LootTableId": "florist_common",
            "Configured": true
          },
          "PlacedByInteraction": {
            "WhoPlacedUuid": {
              "$binary": "v7RyWIT/TYKnXA2XcxdQtw==",
              "$type": "04"
            }
          }
        }
      }
    },
    {
      "x": 4,
      "y": 5,
      "z": -7,
      "name": "Wood_Beech_Trunk",
      "support": 15,
      "rotation": 5
    },
    {
      "x": 4,
      "y": 6,
      "z": -7,
      "name": "*Wood_Village_Wall_Full_State_Definitions_Bottom"
    },
    {
      "x": 4,
      "y": 7,
      "z": -7,
      "name": "*Wood_Village_Wall_Full_State_Definitions_Middle"
    },
    {
      "x": 4,
      "y": 8,
      "z": -7,
      "name": "*Wood_Village_Wall_Full_State_Definitions_Top"
    },
    {
      "x": 4,
      "y": 9,
      "z": -7,
      "name": "Wood_Beech_Trunk",
      "support": 15,
      "rotation": 5
    },
    {
      "x": 4,
      "y": 10,
      "z": -7,
      "name": "*Wood_Village_Wall_Full_State_Definitions_Bottom"
    },
    {
      "x": 4,
      "y": 11,
      "z": -7,
      "name": "*Wood_Village_Wall_Full_State_Definitions_Top"
    },
    {
      "x": 4,
      "y": 12,
      "z": -7,
      "name": "Wood_Softwood_Roof",
      "rotation": 3
    },
    {
      "x": 4,
      "y": 1,
      "z": -6,
      "name": "Rock_Stone_Brick"
    },
    {
      "x": 4,
      "y": 6,
      "z": -6,
      "name": "Cloth_Roof_White_Flat"
    },
    {
      "x": 4,
      "y": 11,
      "z": -6,
      "name": "Wood_Softwood_Stairs",
      "rotation": 11
    },
    {
      "x": 4,
      "y": 12,
      "z": -6,
      "name": "Wood_Softwood_Roof",
      "rotation": 3
    },
    {
      "x": 4,
      "y": 1,
      "z": -5,
      "name": "Rock_Stone_Brick"
    },
    {
      "x": 4,
      "y": 6,
      "z": -5,
      "name": "Cloth_Roof_Green_Flat"
    },
    {
      "x": 4,
      "y": 1,
      "z": -4,
      "name": "Rock_Stone_Brick"
    },
    {
      "x": 4,
      "y": 6,
      "z": -4,
      "name": "Cloth_Roof_White_Flat"
    },
    {
      "x": 4,
      "y": 1,
      "z": -3,
      "name": "Rock_Stone_Brick"
    },
    {
      "x": 4,
      "y": 6,
      "z": -3,
      "name": "Cloth_Roof_Green_Flat"
    },
    {
      "x": 4,
      "y": 1,
      "z": -2,
      "name": "Rock_Stone_Brick_Smooth"
    },
    {
      "x": 4,
      "y": 5,
      "z": -2,
      "name": "Cloth_Roof_White"
    },
    {
      "x": 4,
      "y": 1,
      "z": -1,
      "name": "Rock_Stone_Cobble_Mossy"
    },
    {
      "x": 4,
      "y": 4,
      "z": -1,
      "name": "Cloth_Roof_White_Flap"
    },
    {
      "x": 5,
      "y": 1,
      "z": -14,
      "name": "Rock_Stone_Cobble"
    },
    {
      "x": 5,
      "y": 12,
      "z": -14,
      "name": "Wood_Softwood_Stairs",
      "rotation": 11
    },
    {
      "x": 5,
      "y": 13,
      "z": -14,
      "name": "Wood_Softwood_Roof",
      "rotation": 3
    },
    {
      "x": 5,
      "y": 1,
      "z": -13,
      "name": "Rock_Stone_Cobble"
    },
    {
      "x": 5,
      "y": 2,
      "z": -13,
      "name": "Rock_Stone_Brick"
    },
    {
      "x": 5,
      "y": 3,
      "z": -13,
      "name": "*Wood_Village_Wall_Full_State_Definitions_Bottom"
    },
    {
      "x": 5,
      "y": 4,
      "z": -13,
      "name": "*Wood_Village_Wall_Full_State_Definitions_Top"
    },
    {
      "x": 5,
      "y": 5,
      "z": -13,
      "name": "Wood_Beech_Trunk",
      "support": 15,
      "rotation": 5
    },
    {
      "x": 5,
      "y": 6,
      "z": -13,
      "name": "Wood_Village_Wall_Full"
    },
    {
      "x": 5,
      "y": 7,
      "z": -13,
      "name": "Furniture_Village_Window"
    },
    {
      "x": 5,
      "y": 8,
      "z": -13,
      "name": "Wood_Village_Wall_Full"
    },
    {
      "x": 5,
      "y": 9,
      "z": -13,
      "name": "Wood_Beech_Trunk",
      "support": 15,
      "rotation": 5
    },
    {
      "x": 5,
      "y": 10,
      "z": -13,
      "name": "Furniture_Village_Window"
    },
    {
      "x": 5,
      "y": 11,
      "z": -13,
      "name": "*Wood_Village_Wall_Full_State_Definitions_Bottom"
    },
    {
      "x": 5,
      "y": 12,
      "z": -13,
      "name": "*Wood_Village_Wall_Full_State_Definitions_Top"
    },
    {
      "x": 5,
      "y": 13,
      "z": -13,
      "name": "Wood_Softwood_Roof",
      "rotation": 3
    },
    {
      "x": 5,
      "y": 1,
      "z": -12,
      "name": "Wood_Softwood_Planks"
    },
    {
      "x": 5,
      "y": 2,
      "z": -12,
      "name": "Wood_Softwood_Stairs",
      "rotation": 11
    },
    {
      "x": 5,
      "y": 3,
      "z": -12,
      "name": "Wood_Softwood_Stairs",
      "rotation": 3
    },
    {
      "x": 5,
      "y": 12,
      "z": -12,
      "name": "Wood_Softwood_Stairs",
      "rotation": 11
    },
    {
      "x": 5,
      "y": 13,
      "z": -12,
      "name": "Wood_Softwood_Roof",
      "rotation": 3
    },
    {
      "x": 5,
      "y": 1,
      "z": -11,
      "name": "Wood_Softwood_Planks"
    },
    {
      "x": 5,
      "y": 2,
      "z": -11,
      "name": "Plant_Moss_Rug_Green",
      "support": 15
    },
    {
      "x": 5,
      "y": 5,
      "z": -11,
      "name": "Wood_Softwood_Planks"
    },
    {
      "x": 5,
      "y": 6,
      "z": -11,
      "name": "Plant_Moss_Rug_Green",
      "support": 15
    },
    {
      "x": 5,
      "y": 12,
      "z": -11,
      "name": "Wood_Softwood_Stairs",
      "rotation": 11
    },
    {
      "x": 5,
      "y": 13,
      "z": -11,
      "name": "Wood_Softwood_Roof",
      "rotation": 3
    },
    {
      "x": 5,
      "y": 1,
      "z": -10,
      "name": "Wood_Softwood_Planks"
    },
    {
      "x": 5,
      "y": 2,
      "z": -10,
      "name": "Plant_Moss_Rug_Green",
      "support": 15
    },
    {
      "x": 5,
      "y": 5,
      "z": -10,
      "name": "Wood_Softwood_Planks"
    },
    {
      "x": 5,
      "y": 6,
      "z": -10,
      "name": "Plant_Moss_Rug_Green",
      "support": 15
    },
    {
      "x": 5,
      "y": 12,
      "z": -10,
      "name": "Wood_Softwood_Stairs",
      "rotation": 11
    },
    {
      "x": 5,
      "y": 13,
      "z": -10,
      "name": "Wood_Softwood_Roof",
      "rotation": 3
    },
    {
      "x": 5,
      "y": 1,
      "z": -9,
      "name": "Wood_Softwood_Planks"
    },
    {
      "x": 5,
      "y": 2,
      "z": -9,
      "name": "Plant_Moss_Rug_Green",
      "support": 15
    },
    {
      "x": 5,
      "y": 5,
      "z": -9,
      "name": "Wood_Softwood_Planks"
    },
    {
      "x": 5,
      "y": 6,
      "z": -9,
      "name": "Plant_Moss_Rug_Green",
      "support": 15
    },
    {
      "x": 5,
      "y": 12,
      "z": -9,
      "name": "Wood_Softwood_Stairs",
      "rotation": 11
    },
    {
      "x": 5,
      "y": 13,
      "z": -9,
      "name": "Wood_Softwood_Roof",
      "rotation": 3
    },
    {
      "x": 5,
      "y": 1,
      "z": -8,
      "name": "Wood_Softwood_Planks"
    },
    {
      "x": 5,
      "y": 5,
      "z": -8,
      "name": "Wood_Softwood_Planks"
    },
    {
      "x": 5,
      "y": 12,
      "z": -8,
      "name": "Wood_Softwood_Stairs",
      "rotation": 11
    },
    {
      "x": 5,
      "y": 13,
      "z": -8,
      "name": "Wood_Softwood_Roof",
      "rotation": 3
    },
    {
      "x": 5,
      "y": 1,
      "z": -7,
      "name": "Wood_Softwood_Planks"
    },
    {
      "x": 5,
      "y": 2,
      "z": -7,
      "name": "Furniture_Village_Counter",
      "support": 15,
      "rotation": 2
    },
    {
      "x": 5,
      "y": 3,
      "z": -7,
      "name": "Aetherhaven_Shop_Spot",
      "components": {
        "Components": {
          "AetherhavenShopSpotBlock": {
            "SpotId": "594f7bb4-ee28-4d96-8d05-beb177a0e98a",
            "TownId": "d87b9d18-a6de-42a7-9697-90f4c2aa0d9f",
            "PlotId": "00000000-0000-0000-0000-000000000000",
            "PlayerControlled": false,
            "LootTableId": "florist_water",
            "Configured": true
          },
          "PlacedByInteraction": {
            "WhoPlacedUuid": {
              "$binary": "v7RyWIT/TYKnXA2XcxdQtw==",
              "$type": "04"
            }
          }
        }
      }
    },
    {
      "x": 5,
      "y": 5,
      "z": -7,
      "name": "Wood_Beech_Trunk",
      "support": 15,
      "rotation": 5
    },
    {
      "x": 5,
      "y": 6,
      "z": -7,
      "name": "Wood_Village_Wall_Full"
    },
    {
      "x": 5,
      "y": 7,
      "z": -7,
      "name": "Furniture_Village_Window"
    },
    {
      "x": 5,
      "y": 8,
      "z": -7,
      "name": "Wood_Village_Wall_Full"
    },
    {
      "x": 5,
      "y": 9,
      "z": -7,
      "name": "Wood_Beech_Trunk",
      "support": 15,
      "rotation": 5
    },
    {
      "x": 5,
      "y": 10,
      "z": -7,
      "name": "Furniture_Village_Window"
    },
    {
      "x": 5,
      "y": 11,
      "z": -7,
      "name": "*Wood_Village_Wall_Full_State_Definitions_Bottom"
    },
    {
      "x": 5,
      "y": 12,
      "z": -7,
      "name": "*Wood_Village_Wall_Full_State_Definitions_Top"
    },
    {
      "x": 5,
      "y": 13,
      "z": -7,
      "name": "Wood_Softwood_Roof",
      "rotation": 3
    },
    {
      "x": 5,
      "y": 1,
      "z": -6,
      "name": "Rock_Stone_Brick"
    },
    {
      "x": 5,
      "y": 6,
      "z": -6,
      "name": "Cloth_Roof_Green_Flat"
    },
    {
      "x": 5,
      "y": 12,
      "z": -6,
      "name": "Wood_Softwood_Stairs",
      "rotation": 11
    },
    {
      "x": 5,
      "y": 13,
      "z": -6,
      "name": "Wood_Softwood_Roof",
      "rotation": 3
    },
    {
      "x": 5,
      "y": 1,
      "z": -5,
      "name": "Rock_Stone_Brick"
    },
    {
      "x": 5,
      "y": 6,
      "z": -5,
      "name": "Cloth_Roof_White_Flat"
    },
    {
      "x": 5,
      "y": 1,
      "z": -4,
      "name": "Rock_Stone_Brick"
    },
    {
      "x": 5,
      "y": 6,
      "z": -4,
      "name": "Cloth_Roof_Green_Flat"
    },
    {
      "x": 5,
      "y": 1,
      "z": -3,
      "name": "Rock_Stone_Brick"
    },
    {
      "x": 5,
      "y": 6,
      "z": -3,
      "name": "Cloth_Roof_White_Flat"
    },
    {
      "x": 5,
      "y": 1,
      "z": -2,
      "name": "Rock_Stone_Brick_Smooth"
    },
    {
      "x": 5,
      "y": 5,
      "z": -2,
      "name": "Cloth_Roof_Green"
    },
    {
      "x": 5,
      "y": 1,
      "z": -1,
      "name": "Rock_Stone_Cobble"
    },
    {
      "x": 5,
      "y": 4,
      "z": -1,
      "name": "Cloth_Roof_Green_Flap"
    },
    {
      "x": 6,
      "y": 1,
      "z": -14,
      "name": "Rock_Stone_Cobble"
    },
    {
      "x": 6,
      "y": 12,
      "z": -14,
      "name": "Wood_Softwood_Stairs",
      "rotation": 9
    },
    {
      "x": 6,
      "y": 13,
      "z": -14,
      "name": "Wood_Softwood_Roof",
      "rotation": 1
    },
    {
      "x": 6,
      "y": 1,
      "z": -13,
      "name": "Rock_Stone_Cobble"
    },
    {
      "x": 6,
      "y": 2,
      "z": -13,
      "name": "Rock_Stone_Brick_Mossy"
    },
    {
      "x": 6,
      "y": 3,
      "z": -13,
      "name": "*Wood_Village_Wall_Full_State_Definitions_Bottom"
    },
    {
      "x": 6,
      "y": 4,
      "z": -13,
      "name": "*Wood_Village_Wall_Full_State_Definitions_Top"
    },
    {
      "x": 6,
      "y": 5,
      "z": -13,
      "name": "Wood_Beech_Trunk",
      "support": 15,
      "rotation": 5
    },
    {
      "x": 6,
      "y": 6,
      "z": -13,
      "name": "Wood_Village_Wall_Full"
    },
    {
      "x": 6,
      "y": 7,
      "z": -13,
      "name": "Furniture_Village_Window"
    },
    {
      "x": 6,
      "y": 8,
      "z": -13,
      "name": "Wood_Village_Wall_Full"
    },
    {
      "x": 6,
      "y": 9,
      "z": -13,
      "name": "Wood_Beech_Trunk",
      "support": 15,
      "rotation": 5
    },
    {
      "x": 6,
      "y": 10,
      "z": -13,
      "name": "Furniture_Village_Window"
    },
    {
      "x": 6,
      "y": 11,
      "z": -13,
      "name": "*Wood_Village_Wall_Full_State_Definitions_Bottom"
    },
    {
      "x": 6,
      "y": 12,
      "z": -13,
      "name": "*Wood_Village_Wall_Full_State_Definitions_Top"
    },
    {
      "x": 6,
      "y": 13,
      "z": -13,
      "name": "Wood_Softwood_Roof",
      "rotation": 1
    },
    {
      "x": 6,
      "y": 1,
      "z": -12,
      "name": "Wood_Softwood_Planks"
    },
    {
      "x": 6,
      "y": 2,
      "z": -12,
      "name": "Furniture_Village_Crate"
    },
    {
      "x": 6,
      "y": 3,
      "z": -12,
      "name": "Wood_Softwood_Stairs",
      "rotation": 11
    },
    {
      "x": 6,
      "y": 4,
      "z": -12,
      "name": "Wood_Softwood_Stairs",
      "rotation": 3
    },
    {
      "x": 6,
      "y": 12,
      "z": -12,
      "name": "Wood_Softwood_Stairs",
      "rotation": 9
    },
    {
      "x": 6,
      "y": 13,
      "z": -12,
      "name": "Wood_Softwood_Roof",
      "rotation": 1
    },
    {
      "x": 6,
      "y": 1,
      "z": -11,
      "name": "Wood_Softwood_Planks"
    },
    {
      "x": 6,
      "y": 2,
      "z": -11,
      "name": "Plant_Moss_Rug_Green",
      "support": 15
    },
    {
      "x": 6,
      "y": 5,
      "z": -11,
      "name": "Wood_Softwood_Planks"
    },
    {
      "x": 6,
      "y": 6,
      "z": -11,
      "name": "Plant_Moss_Rug_Green",
      "support": 15
    },
    {
      "x": 6,
      "y": 12,
      "z": -11,
      "name": "Wood_Softwood_Stairs",
      "rotation": 9
    },
    {
      "x": 6,
      "y": 13,
      "z": -11,
      "name": "Wood_Softwood_Roof",
      "rotation": 1
    },
    {
      "x": 6,
      "y": 1,
      "z": -10,
      "name": "Wood_Softwood_Planks"
    },
    {
      "x": 6,
      "y": 2,
      "z": -10,
      "name": "Plant_Moss_Rug_Green",
      "support": 15
    },
    {
      "x": 6,
      "y": 5,
      "z": -10,
      "name": "Wood_Softwood_Planks"
    },
    {
      "x": 6,
      "y": 6,
      "z": -10,
      "name": "Plant_Moss_Rug_Green",
      "support": 15
    },
    {
      "x": 6,
      "y": 12,
      "z": -10,
      "name": "Wood_Softwood_Stairs",
      "rotation": 9
    },
    {
      "x": 6,
      "y": 13,
      "z": -10,
      "name": "Wood_Softwood_Roof",
      "rotation": 1
    },
    {
      "x": 6,
      "y": 1,
      "z": -9,
      "name": "Wood_Softwood_Planks"
    },
    {
      "x": 6,
      "y": 2,
      "z": -9,
      "name": "Plant_Moss_Rug_Green",
      "support": 15
    },
    {
      "x": 6,
      "y": 5,
      "z": -9,
      "name": "Wood_Softwood_Planks"
    },
    {
      "x": 6,
      "y": 6,
      "z": -9,
      "name": "Plant_Moss_Rug_Green",
      "support": 15
    },
    {
      "x": 6,
      "y": 12,
      "z": -9,
      "name": "Wood_Softwood_Stairs",
      "rotation": 9
    },
    {
      "x": 6,
      "y": 13,
      "z": -9,
      "name": "Wood_Softwood_Roof",
      "rotation": 1
    },
    {
      "x": 6,
      "y": 1,
      "z": -8,
      "name": "Wood_Softwood_Planks"
    },
    {
      "x": 6,
      "y": 5,
      "z": -8,
      "name": "Wood_Softwood_Planks"
    },
    {
      "x": 6,
      "y": 12,
      "z": -8,
      "name": "Wood_Softwood_Stairs",
      "rotation": 9
    },
    {
      "x": 6,
      "y": 13,
      "z": -8,
      "name": "Wood_Softwood_Roof",
      "rotation": 1
    },
    {
      "x": 6,
      "y": 1,
      "z": -7,
      "name": "Wood_Softwood_Planks"
    },
    {
      "x": 6,
      "y": 2,
      "z": -7,
      "name": "Furniture_Village_Counter",
      "support": 15,
      "filler": 1,
      "rotation": 2
    },
    {
      "x": 6,
      "y": 3,
      "z": -7,
      "name": "Aetherhaven_Shop_Spot",
      "components": {
        "Components": {
          "AetherhavenShopSpotBlock": {
            "SpotId": "ce377ef5-ccc6-45f1-bb5f-0eb21f08952b",
            "TownId": "d87b9d18-a6de-42a7-9697-90f4c2aa0d9f",
            "PlotId": "00000000-0000-0000-0000-000000000000",
            "PlayerControlled": false,
            "LootTableId": "florist_orchid",
            "Configured": true
          },
          "PlacedByInteraction": {
            "WhoPlacedUuid": {
              "$binary": "v7RyWIT/TYKnXA2XcxdQtw==",
              "$type": "04"
            }
          }
        }
      }
    },
    {
      "x": 6,
      "y": 5,
      "z": -7,
      "name": "Wood_Beech_Trunk",
      "support": 15,
      "rotation": 5
    },
    {
      "x": 6,
      "y": 6,
      "z": -7,
      "name": "Wood_Village_Wall_Full"
    },
    {
      "x": 6,
      "y": 7,
      "z": -7,
      "name": "Furniture_Village_Window"
    },
    {
      "x": 6,
      "y": 8,
      "z": -7,
      "name": "Wood_Village_Wall_Full"
    },
    {
      "x": 6,
      "y": 9,
      "z": -7,
      "name": "Wood_Beech_Trunk",
      "support": 15,
      "rotation": 5
    },
    {
      "x": 6,
      "y": 10,
      "z": -7,
      "name": "Furniture_Village_Window"
    },
    {
      "x": 6,
      "y": 11,
      "z": -7,
      "name": "*Wood_Village_Wall_Full_State_Definitions_Bottom"
    },
    {
      "x": 6,
      "y": 12,
      "z": -7,
      "name": "*Wood_Village_Wall_Full_State_Definitions_Top"
    },
    {
      "x": 6,
      "y": 13,
      "z": -7,
      "name": "Wood_Softwood_Roof",
      "rotation": 1
    },
    {
      "x": 6,
      "y": 1,
      "z": -6,
      "name": "Rock_Stone_Brick"
    },
    {
      "x": 6,
      "y": 6,
      "z": -6,
      "name": "Cloth_Roof_White_Flat"
    },
    {
      "x": 6,
      "y": 12,
      "z": -6,
      "name": "Wood_Softwood_Stairs",
      "rotation": 9
    },
    {
      "x": 6,
      "y": 13,
      "z": -6,
      "name": "Wood_Softwood_Roof",
      "rotation": 1
    },
    {
      "x": 6,
      "y": 1,
      "z": -5,
      "name": "Rock_Stone_Brick"
    },
    {
      "x": 6,
      "y": 6,
      "z": -5,
      "name": "Cloth_Roof_Green_Flat"
    },
    {
      "x": 6,
      "y": 1,
      "z": -4,
      "name": "Rock_Stone_Brick"
    },
    {
      "x": 6,
      "y": 6,
      "z": -4,
      "name": "Cloth_Roof_White_Flat"
    },
    {
      "x": 6,
      "y": 1,
      "z": -3,
      "name": "Rock_Stone_Brick"
    },
    {
      "x": 6,
      "y": 6,
      "z": -3,
      "name": "Cloth_Roof_Green_Flat"
    },
    {
      "x": 6,
      "y": 1,
      "z": -2,
      "name": "Rock_Stone_Brick_Smooth"
    },
    {
      "x": 6,
      "y": 5,
      "z": -2,
      "name": "Cloth_Roof_White"
    },
    {
      "x": 6,
      "y": 1,
      "z": -1,
      "name": "Rock_Stone_Cobble"
    },
    {
      "x": 6,
      "y": 4,
      "z": -1,
      "name": "Cloth_Roof_White_Flap"
    },
    {
      "x": 7,
      "y": 1,
      "z": -14,
      "name": "Rock_Stone_Cobble"
    },
    {
      "x": 7,
      "y": 7,
      "z": -14,
      "name": "Plant_Vine_Wall",
      "support": 15,
      "rotation": 2
    },
    {
      "x": 7,
      "y": 11,
      "z": -14,
      "name": "Wood_Softwood_Stairs",
      "rotation": 9
    },
    {
      "x": 7,
      "y": 12,
      "z": -14,
      "name": "Wood_Softwood_Roof",
      "rotation": 1
    },
    {
      "x": 7,
      "y": 1,
      "z": -13,
      "name": "Rock_Stone_Cobble_Mossy"
    },
    {
      "x": 7,
      "y": 2,
      "z": -13,
      "name": "Rock_Stone_Brick"
    },
    {
      "x": 7,
      "y": 3,
      "z": -13,
      "name": "*Wood_Village_Wall_Full_State_Definitions_Bottom"
    },
    {
      "x": 7,
      "y": 4,
      "z": -13,
      "name": "*Wood_Village_Wall_Full_State_Definitions_Top"
    },
    {
      "x": 7,
      "y": 5,
      "z": -13,
      "name": "Wood_Beech_Trunk",
      "support": 15,
      "rotation": 5
    },
    {
      "x": 7,
      "y": 6,
      "z": -13,
      "name": "*Wood_Village_Wall_Full_State_Definitions_Bottom"
    },
    {
      "x": 7,
      "y": 7,
      "z": -13,
      "name": "*Wood_Village_Wall_Full_State_Definitions_Middle"
    },
    {
      "x": 7,
      "y": 8,
      "z": -13,
      "name": "*Wood_Village_Wall_Full_State_Definitions_Top"
    },
    {
      "x": 7,
      "y": 9,
      "z": -13,
      "name": "Wood_Beech_Trunk",
      "support": 15,
      "rotation": 5
    },
    {
      "x": 7,
      "y": 10,
      "z": -13,
      "name": "*Wood_Village_Wall_Full_State_Definitions_Bottom"
    },
    {
      "x": 7,
      "y": 11,
      "z": -13,
      "name": "*Wood_Village_Wall_Full_State_Definitions_Top"
    },
    {
      "x": 7,
      "y": 12,
      "z": -13,
      "name": "Wood_Softwood_Roof",
      "rotation": 1
    },
    {
      "x": 7,
      "y": 1,
      "z": -12,
      "name": "Wood_Softwood_Planks"
    },
    {
      "x": 7,
      "y": 2,
      "z": -12,
      "name": "Furniture_Village_Crate"
    },
    {
      "x": 7,
      "y": 3,
      "z": -12,
      "name": "Furniture_Tavern_Barrel",
      "support": 15
    },
    {
      "x": 7,
      "y": 4,
      "z": -12,
      "name": "Wood_Softwood_Stairs",
      "rotation": 11
    },
    {
      "x": 7,
      "y": 5,
      "z": -12,
      "name": "Wood_Softwood_Stairs",
      "rotation": 3
    },
    {
      "x": 7,
      "y": 11,
      "z": -12,
      "name": "Wood_Softwood_Stairs",
      "rotation": 9
    },
    {
      "x": 7,
      "y": 12,
      "z": -12,
      "name": "Wood_Softwood_Roof",
      "rotation": 1
    },
    {
      "x": 7,
      "y": 1,
      "z": -11,
      "name": "Wood_Softwood_Planks"
    },
    {
      "x": 7,
      "y": 2,
      "z": -11,
      "name": "Plant_Moss_Rug_Green",
      "support": 15
    },
    {
      "x": 7,
      "y": 5,
      "z": -11,
      "name": "Wood_Softwood_Planks"
    },
    {
      "x": 7,
      "y": 6,
      "z": -11,
      "name": "Plant_Moss_Rug_Green",
      "support": 15
    },
    {
      "x": 7,
      "y": 11,
      "z": -11,
      "name": "Wood_Softwood_Stairs",
      "rotation": 9
    },
    {
      "x": 7,
      "y": 12,
      "z": -11,
      "name": "Wood_Softwood_Roof",
      "rotation": 1
    },
    {
      "x": 7,
      "y": 1,
      "z": -10,
      "name": "Wood_Softwood_Planks"
    },
    {
      "x": 7,
      "y": 2,
      "z": -10,
      "name": "Plant_Moss_Rug_Green",
      "support": 15
    },
    {
      "x": 7,
      "y": 4,
      "z": -10,
      "name": "Furniture_Kweebec_Lantern_Ceiling",
      "support": 15
    },
    {
      "x": 7,
      "y": 5,
      "z": -10,
      "name": "Wood_Softwood_Planks"
    },
    {
      "x": 7,
      "y": 6,
      "z": -10,
      "name": "Plant_Moss_Rug_Green",
      "support": 15
    },
    {
      "x": 7,
      "y": 9,
      "z": -10,
      "name": "Furniture_Kweebec_Lantern_Ceiling",
      "support": 15
    },
    {
      "x": 7,
      "y": 10,
      "z": -10,
      "name": "Wood_Softwood_Beam"
    },
    {
      "x": 7,
      "y": 11,
      "z": -10,
      "name": "Wood_Softwood_Planks"
    },
    {
      "x": 7,
      "y": 12,
      "z": -10,
      "name": "Wood_Softwood_Roof",
      "rotation": 1
    },
    {
      "x": 7,
      "y": 1,
      "z": -9,
      "name": "Wood_Softwood_Planks"
    },
    {
      "x": 7,
      "y": 2,
      "z": -9,
      "name": "Plant_Moss_Rug_Green",
      "support": 15
    },
    {
      "x": 7,
      "y": 5,
      "z": -9,
      "name": "Wood_Softwood_Planks"
    },
    {
      "x": 7,
      "y": 6,
      "z": -9,
      "name": "Plant_Moss_Rug_Green",
      "support": 15
    },
    {
      "x": 7,
      "y": 11,
      "z": -9,
      "name": "Wood_Softwood_Stairs",
      "rotation": 9
    },
    {
      "x": 7,
      "y": 12,
      "z": -9,
      "name": "Wood_Softwood_Roof",
      "rotation": 1
    },
    {
      "x": 7,
      "y": 1,
      "z": -8,
      "name": "Wood_Softwood_Planks"
    },
    {
      "x": 7,
      "y": 5,
      "z": -8,
      "name": "Wood_Softwood_Planks"
    },
    {
      "x": 7,
      "y": 6,
      "z": -8,
      "name": "Furniture_Tavern_Planter",
      "support": 15
    },
    {
      "x": 7,
      "y": 7,
      "z": -8,
      "name": "Plant_Flower_Common_Violet2",
      "support": 15
    },
    {
      "x": 7,
      "y": 11,
      "z": -8,
      "name": "Wood_Softwood_Stairs",
      "rotation": 9
    },
    {
      "x": 7,
      "y": 12,
      "z": -8,
      "name": "Wood_Softwood_Roof",
      "rotation": 1
    },
    {
      "x": 7,
      "y": 1,
      "z": -7,
      "name": "Wood_Softwood_Planks"
    },
    {
      "x": 7,
      "y": 2,
      "z": -7,
      "name": "Wood_Softwood_Planks_Half",
      "rotation": 8
    },
    {
      "x": 7,
      "y": 3,
      "z": -7,
      "name": "Aetherhaven_Shop_Spot",
      "components": {
        "Components": {
          "AetherhavenShopSpotBlock": {
            "SpotId": "4bbcd5a4-1736-4929-a3f0-7897fb4e873f",
            "TownId": "d87b9d18-a6de-42a7-9697-90f4c2aa0d9f",
            "PlotId": "00000000-0000-0000-0000-000000000000",
            "PlayerControlled": false,
            "LootTableId": "florist_misc",
            "Configured": true
          },
          "PlacedByInteraction": {
            "WhoPlacedUuid": {
              "$binary": "v7RyWIT/TYKnXA2XcxdQtw==",
              "$type": "04"
            }
          }
        }
      }
    },
    {
      "x": 7,
      "y": 5,
      "z": -7,
      "name": "Wood_Beech_Trunk",
      "support": 15,
      "rotation": 5
    },
    {
      "x": 7,
      "y": 6,
      "z": -7,
      "name": "*Wood_Village_Wall_Full_State_Definitions_Bottom"
    },
    {
      "x": 7,
      "y": 7,
      "z": -7,
      "name": "*Wood_Village_Wall_Full_State_Definitions_Middle"
    },
    {
      "x": 7,
      "y": 8,
      "z": -7,
      "name": "*Wood_Village_Wall_Full_State_Definitions_Top"
    },
    {
      "x": 7,
      "y": 9,
      "z": -7,
      "name": "Wood_Beech_Trunk",
      "support": 15,
      "rotation": 5
    },
    {
      "x": 7,
      "y": 10,
      "z": -7,
      "name": "*Wood_Village_Wall_Full_State_Definitions_Bottom"
    },
    {
      "x": 7,
      "y": 11,
      "z": -7,
      "name": "*Wood_Village_Wall_Full_State_Definitions_Top"
    },
    {
      "x": 7,
      "y": 12,
      "z": -7,
      "name": "Wood_Softwood_Roof",
      "rotation": 1
    },
    {
      "x": 7,
      "y": 1,
      "z": -6,
      "name": "Rock_Stone_Brick"
    },
    {
      "x": 7,
      "y": 6,
      "z": -6,
      "name": "Cloth_Roof_Green_Flat"
    },
    {
      "x": 7,
      "y": 11,
      "z": -6,
      "name": "Wood_Softwood_Stairs",
      "rotation": 9
    },
    {
      "x": 7,
      "y": 12,
      "z": -6,
      "name": "Wood_Softwood_Roof",
      "rotation": 1
    },
    {
      "x": 7,
      "y": 1,
      "z": -5,
      "name": "Rock_Stone_Brick"
    },
    {
      "x": 7,
      "y": 6,
      "z": -5,
      "name": "Cloth_Roof_White_Flat"
    },
    {
      "x": 7,
      "y": 1,
      "z": -4,
      "name": "Rock_Stone_Brick"
    },
    {
      "x": 7,
      "y": 6,
      "z": -4,
      "name": "Cloth_Roof_Green_Flat"
    },
    {
      "x": 7,
      "y": 1,
      "z": -3,
      "name": "Rock_Stone_Brick"
    },
    {
      "x": 7,
      "y": 6,
      "z": -3,
      "name": "Cloth_Roof_White_Flat"
    },
    {
      "x": 7,
      "y": 1,
      "z": -2,
      "name": "Rock_Stone_Brick_Smooth"
    },
    {
      "x": 7,
      "y": 5,
      "z": -2,
      "name": "Cloth_Roof_Green"
    },
    {
      "x": 7,
      "y": 1,
      "z": -1,
      "name": "Rock_Stone_Cobble"
    },
    {
      "x": 7,
      "y": 4,
      "z": -1,
      "name": "Cloth_Roof_Green_Flap"
    },
    {
      "x": 8,
      "y": 1,
      "z": -14,
      "name": "Rock_Stone_Cobble"
    },
    {
      "x": 8,
      "y": 4,
      "z": -14,
      "name": "Plant_Vine_Wall",
      "support": 15,
      "rotation": 2
    },
    {
      "x": 8,
      "y": 10,
      "z": -14,
      "name": "Wood_Softwood_Stairs",
      "rotation": 9
    },
    {
      "x": 8,
      "y": 11,
      "z": -14,
      "name": "Wood_Softwood_Roof",
      "rotation": 1
    },
    {
      "x": 8,
      "y": 1,
      "z": -13,
      "name": "Rock_Stone_Cobble"
    },
    {
      "x": 8,
      "y": 2,
      "z": -13,
      "name": "Rock_Stone_Brick"
    },
    {
      "x": 8,
      "y": 3,
      "z": -13,
      "name": "*Wood_Village_Wall_Full_State_Definitions_Bottom"
    },
    {
      "x": 8,
      "y": 4,
      "z": -13,
      "name": "*Wood_Village_Wall_Full_State_Definitions_Top"
    },
    {
      "x": 8,
      "y": 5,
      "z": -13,
      "name": "Wood_Beech_Trunk",
      "support": 15,
      "rotation": 5
    },
    {
      "x": 8,
      "y": 6,
      "z": -13,
      "name": "*Wood_Village_Wall_Full_State_Definitions_Bottom"
    },
    {
      "x": 8,
      "y": 7,
      "z": -13,
      "name": "*Wood_Village_Wall_Full_State_Definitions_Middle"
    },
    {
      "x": 8,
      "y": 8,
      "z": -13,
      "name": "*Wood_Village_Wall_Full_State_Definitions_Top"
    },
    {
      "x": 8,
      "y": 9,
      "z": -13,
      "name": "Wood_Beech_Trunk",
      "support": 15,
      "rotation": 5
    },
    {
      "x": 8,
      "y": 10,
      "z": -13,
      "name": "Wood_Village_Wall_Full"
    },
    {
      "x": 8,
      "y": 11,
      "z": -13,
      "name": "Wood_Softwood_Roof",
      "rotation": 1
    },
    {
      "x": 8,
      "y": 1,
      "z": -12,
      "name": "Wood_Softwood_Planks"
    },
    {
      "x": 8,
      "y": 2,
      "z": -12,
      "name": "Furniture_Tavern_Planter",
      "support": 15
    },
    {
      "x": 8,
      "y": 3,
      "z": -12,
      "name": "Plant_Flower_Common_Pink",
      "support": 15
    },
    {
      "x": 8,
      "y": 4,
      "z": -12,
      "name": "Plant_Flower_Common_Pink",
      "support": 15,
      "filler": 1024
    },
    {
      "x": 8,
      "y": 5,
      "z": -12,
      "name": "Wood_Softwood_Planks"
    },
    {
      "x": 8,
      "y": 10,
      "z": -12,
      "name": "Wood_Softwood_Stairs",
      "rotation": 9
    },
    {
      "x": 8,
      "y": 11,
      "z": -12,
      "name": "Wood_Softwood_Roof",
      "rotation": 1
    },
    {
      "x": 8,
      "y": 1,
      "z": -11,
      "name": "Wood_Softwood_Planks"
    },
    {
      "x": 8,
      "y": 5,
      "z": -11,
      "name": "Wood_Softwood_Planks"
    },
    {
      "x": 8,
      "y": 10,
      "z": -11,
      "name": "Wood_Softwood_Stairs",
      "rotation": 9
    },
    {
      "x": 8,
      "y": 11,
      "z": -11,
      "name": "Wood_Softwood_Roof",
      "rotation": 1
    },
    {
      "x": 8,
      "y": 1,
      "z": -10,
      "name": "Wood_Softwood_Planks"
    },
    {
      "x": 8,
      "y": 2,
      "z": -10,
      "name": "Furniture_Tavern_Planter",
      "support": 15
    },
    {
      "x": 8,
      "y": 3,
      "z": -10,
      "name": "Plant_Flower_Common_Purple",
      "support": 15
    },
    {
      "x": 8,
      "y": 5,
      "z": -10,
      "name": "Wood_Softwood_Planks"
    },
    {
      "x": 8,
      "y": 10,
      "z": -10,
      "name": "Wood_Softwood_Stairs",
      "rotation": 9
    },
    {
      "x": 8,
      "y": 11,
      "z": -10,
      "name": "Wood_Softwood_Roof",
      "rotation": 1
    },
    {
      "x": 8,
      "y": 1,
      "z": -9,
      "name": "Wood_Softwood_Planks"
    },
    {
      "x": 8,
      "y": 5,
      "z": -9,
      "name": "Wood_Softwood_Planks"
    },
    {
      "x": 8,
      "y": 6,
      "z": -9,
      "name": "Furniture_Tavern_Planter",
      "support": 15
    },
    {
      "x": 8,
      "y": 7,
      "z": -9,
      "name": "Plant_Flower_Common_Pink2",
      "support": 15
    },
    {
      "x": 8,
      "y": 10,
      "z": -9,
      "name": "Wood_Softwood_Stairs",
      "rotation": 9
    },
    {
      "x": 8,
      "y": 11,
      "z": -9,
      "name": "Wood_Softwood_Roof",
      "rotation": 1
    },
    {
      "x": 8,
      "y": 1,
      "z": -8,
      "name": "Wood_Softwood_Planks"
    },
    {
      "x": 8,
      "y": 2,
      "z": -8,
      "name": "Furniture_Tavern_Barrel",
      "support": 15
    },
    {
      "x": 8,
      "y": 5,
      "z": -8,
      "name": "Wood_Softwood_Planks"
    },
    {
      "x": 8,
      "y": 6,
      "z": -8,
      "name": "Plant_Leaves_Oak",
      "support": 15
    },
    {
      "x": 8,
      "y": 7,
      "z": -8,
      "name": "Plant_Leaves_Oak",
      "support": 15
    },
    {
      "x": 8,
      "y": 10,
      "z": -8,
      "name": "Wood_Softwood_Stairs",
      "rotation": 9
    },
    {
      "x": 8,
      "y": 11,
      "z": -8,
      "name": "Wood_Softwood_Roof",
      "rotation": 1
    },
    {
      "x": 8,
      "y": 1,
      "z": -7,
      "name": "Wood_Softwood_Planks"
    },
    {
      "x": 8,
      "y": 2,
      "z": -7,
      "name": "Wood_Softwood_Stairs",
      "rotation": 9
    },
    {
      "x": 8,
      "y": 3,
      "z": -7,
      "name": "Aetherhaven_Shop_Spot",
      "components": {
        "Components": {
          "AetherhavenShopSpotBlock": {
            "SpotId": "452f0e1c-a1a2-4b55-8e70-11be9235befa",
            "TownId": "d87b9d18-a6de-42a7-9697-90f4c2aa0d9f",
            "PlotId": "00000000-0000-0000-0000-000000000000",
            "PlayerControlled": false,
            "LootTableId": "florist_shrubs",
            "Configured": true
          },
          "PlacedByInteraction": {
            "WhoPlacedUuid": {
              "$binary": "v7RyWIT/TYKnXA2XcxdQtw==",
              "$type": "04"
            }
          }
        }
      }
    },
    {
      "x": 8,
      "y": 4,
      "z": -7,
      "name": "Wood_Softwood_Stairs",
      "rotation": 9
    },
    {
      "x": 8,
      "y": 5,
      "z": -7,
      "name": "Wood_Beech_Trunk",
      "support": 15,
      "rotation": 5
    },
    {
      "x": 8,
      "y": 6,
      "z": -7,
      "name": "*Wood_Village_Wall_Full_State_Definitions_Bottom"
    },
    {
      "x": 8,
      "y": 7,
      "z": -7,
      "name": "*Wood_Village_Wall_Full_State_Definitions_Middle"
    },
    {
      "x": 8,
      "y": 8,
      "z": -7,
      "name": "*Wood_Village_Wall_Full_State_Definitions_Top"
    },
    {
      "x": 8,
      "y": 9,
      "z": -7,
      "name": "Wood_Beech_Trunk",
      "support": 15,
      "rotation": 5
    },
    {
      "x": 8,
      "y": 10,
      "z": -7,
      "name": "Wood_Village_Wall_Full"
    },
    {
      "x": 8,
      "y": 11,
      "z": -7,
      "name": "Wood_Softwood_Roof",
      "rotation": 1
    },
    {
      "x": 8,
      "y": 1,
      "z": -6,
      "name": "Rock_Stone_Brick"
    },
    {
      "x": 8,
      "y": 6,
      "z": -6,
      "name": "Cloth_Roof_White_Flat"
    },
    {
      "x": 8,
      "y": 10,
      "z": -6,
      "name": "Wood_Softwood_Stairs",
      "rotation": 9
    },
    {
      "x": 8,
      "y": 11,
      "z": -6,
      "name": "Wood_Softwood_Roof",
      "rotation": 1
    },
    {
      "x": 8,
      "y": 1,
      "z": -5,
      "name": "Rock_Stone_Brick"
    },
    {
      "x": 8,
      "y": 6,
      "z": -5,
      "name": "Cloth_Roof_Green_Flat"
    },
    {
      "x": 8,
      "y": 1,
      "z": -4,
      "name": "Rock_Stone_Brick"
    },
    {
      "x": 8,
      "y": 6,
      "z": -4,
      "name": "Cloth_Roof_White_Flat"
    },
    {
      "x": 8,
      "y": 1,
      "z": -3,
      "name": "Rock_Stone_Brick"
    },
    {
      "x": 8,
      "y": 6,
      "z": -3,
      "name": "Cloth_Roof_Green_Flat"
    },
    {
      "x": 8,
      "y": 1,
      "z": -2,
      "name": "Rock_Stone_Brick_Smooth"
    },
    {
      "x": 8,
      "y": 2,
      "z": -2,
      "name": "Furniture_Village_Planter",
      "support": 15
    },
    {
      "x": 8,
      "y": 3,
      "z": -2,
      "name": "Plant_Flower_Tall_Yellow",
      "support": 15
    },
    {
      "x": 8,
      "y": 5,
      "z": -2,
      "name": "Cloth_Roof_White"
    },
    {
      "x": 8,
      "y": 1,
      "z": -1,
      "name": "Rock_Stone_Cobble_Mossy"
    },
    {
      "x": 8,
      "y": 4,
      "z": -1,
      "name": "Cloth_Roof_White_Flap"
    },
    {
      "x": 9,
      "y": 1,
      "z": -14,
      "name": "Rock_Stone_Cobble"
    },
    {
      "x": 9,
      "y": 9,
      "z": -14,
      "name": "Wood_Beech_Branch_Corner",
      "support": 15,
      "rotation": 2
    },
    {
      "x": 9,
      "y": 10,
      "z": -14,
      "name": "Wood_Softwood_Roof",
      "rotation": 1
    },
    {
      "x": 9,
      "y": 1,
      "z": -13,
      "name": "Rock_Stone_Cobble_Mossy"
    },
    {
      "x": 9,
      "y": 2,
      "z": -13,
      "name": "Wood_Beech_Trunk",
      "support": 15
    },
    {
      "x": 9,
      "y": 3,
      "z": -13,
      "name": "Wood_Beech_Trunk",
      "support": 15
    },
    {
      "x": 9,
      "y": 4,
      "z": -13,
      "name": "Wood_Beech_Trunk",
      "support": 15
    },
    {
      "x": 9,
      "y": 5,
      "z": -13,
      "name": "Wood_Beech_Trunk",
      "support": 15
    },
    {
      "x": 9,
      "y": 6,
      "z": -13,
      "name": "Wood_Beech_Trunk",
      "support": 15
    },
    {
      "x": 9,
      "y": 7,
      "z": -13,
      "name": "Wood_Beech_Trunk",
      "support": 15
    },
    {
      "x": 9,
      "y": 8,
      "z": -13,
      "name": "Wood_Beech_Trunk",
      "support": 15
    },
    {
      "x": 9,
      "y": 9,
      "z": -13,
      "name": "Wood_Beech_Trunk",
      "support": 15
    },
    {
      "x": 9,
      "y": 10,
      "z": -13,
      "name": "Wood_Softwood_Roof",
      "rotation": 1
    },
    {
      "x": 9,
      "y": 1,
      "z": -12,
      "name": "Rock_Stone_Cobble"
    },
    {
      "x": 9,
      "y": 2,
      "z": -12,
      "name": "Rock_Stone_Brick"
    },
    {
      "x": 9,
      "y": 3,
      "z": -12,
      "name": "*Wood_Village_Wall_Full_State_Definitions_Bottom"
    },
    {
      "x": 9,
      "y": 4,
      "z": -12,
      "name": "*Wood_Village_Wall_Full_State_Definitions_Top"
    },
    {
      "x": 9,
      "y": 5,
      "z": -12,
      "name": "Wood_Beech_Trunk",
      "support": 15,
      "rotation": 4
    },
    {
      "x": 9,
      "y": 6,
      "z": -12,
      "name": "*Wood_Village_Wall_Full_State_Definitions_Bottom"
    },
    {
      "x": 9,
      "y": 7,
      "z": -12,
      "name": "*Wood_Village_Wall_Full_State_Definitions_Middle"
    },
    {
      "x": 9,
      "y": 8,
      "z": -12,
      "name": "*Wood_Village_Wall_Full_State_Definitions_Top"
    },
    {
      "x": 9,
      "y": 9,
      "z": -12,
      "name": "Wood_Beech_Trunk",
      "support": 15,
      "rotation": 4
    },
    {
      "x": 9,
      "y": 10,
      "z": -12,
      "name": "Wood_Softwood_Roof",
      "rotation": 1
    },
    {
      "x": 9,
      "y": 1,
      "z": -11,
      "name": "Rock_Stone_Cobble"
    },
    {
      "x": 9,
      "y": 2,
      "z": -11,
      "name": "Rock_Stone_Brick"
    },
    {
      "x": 9,
      "y": 3,
      "z": -11,
      "name": "Furniture_Village_Window",
      "rotation": 1
    },
    {
      "x": 9,
      "y": 4,
      "z": -11,
      "name": "Wood_Village_Wall_Full"
    },
    {
      "x": 9,
      "y": 5,
      "z": -11,
      "name": "Wood_Beech_Trunk",
      "support": 15,
      "rotation": 4
    },
    {
      "x": 9,
      "y": 6,
      "z": -11,
      "name": "Wood_Village_Wall_Full"
    },
    {
      "x": 9,
      "y": 7,
      "z": -11,
      "name": "Furniture_Village_Window",
      "rotation": 1
    },
    {
      "x": 9,
      "y": 8,
      "z": -11,
      "name": "Wood_Village_Wall_Full"
    },
    {
      "x": 9,
      "y": 9,
      "z": -11,
      "name": "Wood_Beech_Trunk",
      "support": 15,
      "rotation": 4
    },
    {
      "x": 9,
      "y": 10,
      "z": -11,
      "name": "Wood_Softwood_Roof",
      "rotation": 1
    },
    {
      "x": 9,
      "y": 1,
      "z": -10,
      "name": "Rock_Stone_Cobble"
    },
    {
      "x": 9,
      "y": 2,
      "z": -10,
      "name": "Rock_Stone_Brick"
    },
    {
      "x": 9,
      "y": 3,
      "z": -10,
      "name": "*Wood_Village_Wall_Full_State_Definitions_Bottom"
    },
    {
      "x": 9,
      "y": 4,
      "z": -10,
      "name": "*Wood_Village_Wall_Full_State_Definitions_Top"
    },
    {
      "x": 9,
      "y": 5,
      "z": -10,
      "name": "Wood_Beech_Trunk",
      "support": 15,
      "rotation": 4
    },
    {
      "x": 9,
      "y": 6,
      "z": -10,
      "name": "*Wood_Village_Wall_Full_State_Definitions_Bottom"
    },
    {
      "x": 9,
      "y": 7,
      "z": -10,
      "name": "*Wood_Village_Wall_Full_State_Definitions_Middle"
    },
    {
      "x": 9,
      "y": 8,
      "z": -10,
      "name": "*Wood_Village_Wall_Full_State_Definitions_Top"
    },
    {
      "x": 9,
      "y": 9,
      "z": -10,
      "name": "Wood_Beech_Trunk",
      "support": 15,
      "rotation": 4
    },
    {
      "x": 9,
      "y": 10,
      "z": -10,
      "name": "Wood_Softwood_Roof",
      "rotation": 1
    },
    {
      "x": 9,
      "y": 1,
      "z": -9,
      "name": "Rock_Stone_Cobble"
    },
    {
      "x": 9,
      "y": 2,
      "z": -9,
      "name": "Rock_Stone_Brick_Mossy"
    },
    {
      "x": 9,
      "y": 3,
      "z": -9,
      "name": "Furniture_Village_Window",
      "rotation": 1
    },
    {
      "x": 9,
      "y": 4,
      "z": -9,
      "name": "Wood_Village_Wall_Full"
    },
    {
      "x": 9,
      "y": 5,
      "z": -9,
      "name": "Wood_Beech_Trunk",
      "support": 15,
      "rotation": 4
    },
    {
      "x": 9,
      "y": 6,
      "z": -9,
      "name": "Wood_Village_Wall_Full"
    },
    {
      "x": 9,
      "y": 7,
      "z": -9,
      "name": "Furniture_Village_Window",
      "rotation": 1
    },
    {
      "x": 9,
      "y": 8,
      "z": -9,
      "name": "Wood_Village_Wall_Full"
    },
    {
      "x": 9,
      "y": 9,
      "z": -9,
      "name": "Wood_Beech_Trunk",
      "support": 15,
      "rotation": 4
    },
    {
      "x": 9,
      "y": 10,
      "z": -9,
      "name": "Wood_Softwood_Roof",
      "rotation": 1
    },
    {
      "x": 9,
      "y": 1,
      "z": -8,
      "name": "Rock_Stone_Cobble_Mossy"
    },
    {
      "x": 9,
      "y": 2,
      "z": -8,
      "name": "Rock_Stone_Brick"
    },
    {
      "x": 9,
      "y": 3,
      "z": -8,
      "name": "*Wood_Village_Wall_Full_State_Definitions_Bottom"
    },
    {
      "x": 9,
      "y": 4,
      "z": -8,
      "name": "*Wood_Village_Wall_Full_State_Definitions_Top"
    },
    {
      "x": 9,
      "y": 5,
      "z": -8,
      "name": "Wood_Beech_Trunk",
      "support": 15,
      "rotation": 4
    },
    {
      "x": 9,
      "y": 6,
      "z": -8,
      "name": "*Wood_Village_Wall_Full_State_Definitions_Bottom"
    },
    {
      "x": 9,
      "y": 7,
      "z": -8,
      "name": "*Wood_Village_Wall_Full_State_Definitions_Middle"
    },
    {
      "x": 9,
      "y": 8,
      "z": -8,
      "name": "*Wood_Village_Wall_Full_State_Definitions_Top"
    },
    {
      "x": 9,
      "y": 9,
      "z": -8,
      "name": "Wood_Beech_Trunk",
      "support": 15,
      "rotation": 4
    },
    {
      "x": 9,
      "y": 10,
      "z": -8,
      "name": "Wood_Softwood_Roof",
      "rotation": 1
    },
    {
      "x": 9,
      "y": 1,
      "z": -7,
      "name": "Rock_Stone_Cobble"
    },
    {
      "x": 9,
      "y": 2,
      "z": -7,
      "name": "Wood_Beech_Trunk",
      "support": 15
    },
    {
      "x": 9,
      "y": 3,
      "z": -7,
      "name": "Wood_Beech_Trunk",
      "support": 15
    },
    {
      "x": 9,
      "y": 4,
      "z": -7,
      "name": "Wood_Beech_Trunk",
      "support": 15
    },
    {
      "x": 9,
      "y": 5,
      "z": -7,
      "name": "Wood_Beech_Trunk",
      "support": 15
    },
    {
      "x": 9,
      "y": 6,
      "z": -7,
      "name": "Wood_Beech_Trunk",
      "support": 15
    },
    {
      "x": 9,
      "y": 7,
      "z": -7,
      "name": "Wood_Beech_Trunk",
      "support": 15
    },
    {
      "x": 9,
      "y": 8,
      "z": -7,
      "name": "Wood_Beech_Trunk",
      "support": 15
    },
    {
      "x": 9,
      "y": 9,
      "z": -7,
      "name": "Wood_Beech_Trunk",
      "support": 15
    },
    {
      "x": 9,
      "y": 10,
      "z": -7,
      "name": "Wood_Softwood_Roof",
      "rotation": 1
    },
    {
      "x": 9,
      "y": 1,
      "z": -6,
      "name": "Rock_Stone_Brick_Smooth"
    },
    {
      "x": 9,
      "y": 3,
      "z": -6,
      "name": "Wood_Torch_Wall",
      "support": 15
    },
    {
      "x": 9,
      "y": 5,
      "z": -6,
      "name": "Cloth_Roof_Green",
      "rotation": 1
    },
    {
      "x": 9,
      "y": 7,
      "z": -6,
      "name": "Plant_Vine_Wall",
      "support": 15
    },
    {
      "x": 9,
      "y": 9,
      "z": -6,
      "name": "Wood_Beech_Branch_Corner",
      "support": 15
    },
    {
      "x": 9,
      "y": 10,
      "z": -6,
      "name": "Wood_Softwood_Roof",
      "rotation": 1
    },
    {
      "x": 9,
      "y": 1,
      "z": -5,
      "name": "Rock_Stone_Brick_Smooth"
    },
    {
      "x": 9,
      "y": 5,
      "z": -5,
      "name": "Cloth_Roof_White",
      "rotation": 1
    },
    {
      "x": 9,
      "y": 1,
      "z": -4,
      "name": "Rock_Stone_Brick_Smooth"
    },
    {
      "x": 9,
      "y": 5,
      "z": -4,
      "name": "Cloth_Roof_Green",
      "rotation": 1
    },
    {
      "x": 9,
      "y": 1,
      "z": -3,
      "name": "Rock_Stone_Brick_Smooth"
    },
    {
      "x": 9,
      "y": 2,
      "z": -3,
      "name": "Furniture_Village_Planter",
      "support": 15
    },
    {
      "x": 9,
      "y": 3,
      "z": -3,
      "name": "Plant_Flower_Common_Red",
      "support": 15
    },
    {
      "x": 9,
      "y": 5,
      "z": -3,
      "name": "Cloth_Roof_White",
      "rotation": 1
    },
    {
      "x": 9,
      "y": 1,
      "z": -2,
      "name": "Rock_Stone_Brick_Smooth"
    },
    {
      "x": 9,
      "y": 2,
      "z": -2,
      "name": "Wood_Beech_Trunk",
      "support": 15
    },
    {
      "x": 9,
      "y": 3,
      "z": -2,
      "name": "Wood_Softwood_Beam"
    },
    {
      "x": 9,
      "y": 4,
      "z": -2,
      "name": "Wood_Softwood_Beam"
    },
    {
      "x": 9,
      "y": 5,
      "z": -2,
      "name": "*Cloth_Roof_Green_State_Definitions_Corner_Left"
    },
    {
      "x": 9,
      "y": 1,
      "z": -1,
      "name": "Rock_Stone_Cobble"
    },
    {
      "x": 9,
      "y": 4,
      "z": -1,
      "name": "Cloth_Roof_Green_Flap"
    },
    {
      "x": 10,
      "y": 1,
      "z": -14,
      "name": "Rock_Stone_Cobble"
    },
    {
      "x": 10,
      "y": 9,
      "z": -14,
      "name": "Wood_Softwood_Roof_Hollow",
      "rotation": 1
    },
    {
      "x": 10,
      "y": 1,
      "z": -13,
      "name": "Rock_Stone_Cobble_Mossy"
    },
    {
      "x": 10,
      "y": 8,
      "z": -13,
      "name": "Wood_Beech_Branch_Corner",
      "support": 15,
      "rotation": 1
    },
    {
      "x": 10,
      "y": 9,
      "z": -13,
      "name": "Wood_Softwood_Roof",
      "rotation": 1
    },
    {
      "x": 10,
      "y": 1,
      "z": -12,
      "name": "Rock_Stone_Cobble"
    },
    {
      "x": 10,
      "y": 7,
      "z": -12,
      "name": "Plant_Vine_Wall",
      "support": 15,
      "rotation": 1
    },
    {
      "x": 10,
      "y": 9,
      "z": -12,
      "name": "Wood_Softwood_Roof_Hollow",
      "rotation": 1
    },
    {
      "x": 10,
      "y": 1,
      "z": -11,
      "name": "Rock_Stone_Cobble"
    },
    {
      "x": 10,
      "y": 9,
      "z": -11,
      "name": "Wood_Softwood_Roof_Hollow",
      "rotation": 1
    },
    {
      "x": 10,
      "y": 1,
      "z": -10,
      "name": "Rock_Stone_Cobble_Mossy"
    },
    {
      "x": 10,
      "y": 9,
      "z": -10,
      "name": "Wood_Softwood_Roof_Hollow",
      "rotation": 1
    },
    {
      "x": 10,
      "y": 1,
      "z": -9,
      "name": "Rock_Stone_Cobble"
    },
    {
      "x": 10,
      "y": 9,
      "z": -9,
      "name": "Wood_Softwood_Roof_Hollow",
      "rotation": 1
    },
    {
      "x": 10,
      "y": 1,
      "z": -8,
      "name": "Rock_Stone_Cobble"
    },
    {
      "x": 10,
      "y": 4,
      "z": -8,
      "name": "Plant_Vine_Wall",
      "support": 15,
      "rotation": 1
    },
    {
      "x": 10,
      "y": 9,
      "z": -8,
      "name": "Wood_Softwood_Roof_Hollow",
      "rotation": 1
    },
    {
      "x": 10,
      "y": 1,
      "z": -7,
      "name": "Rock_Stone_Cobble_Mossy"
    },
    {
      "x": 10,
      "y": 8,
      "z": -7,
      "name": "Wood_Beech_Branch_Corner",
      "support": 15,
      "rotation": 1
    },
    {
      "x": 10,
      "y": 9,
      "z": -7,
      "name": "Wood_Softwood_Roof",
      "rotation": 1
    },
    {
      "x": 10,
      "y": 1,
      "z": -6,
      "name": "Rock_Stone_Cobble_Mossy"
    },
    {
      "x": 10,
      "y": 4,
      "z": -6,
      "name": "Cloth_Roof_Green_Flap",
      "rotation": 1
    },
    {
      "x": 10,
      "y": 9,
      "z": -6,
      "name": "Wood_Softwood_Roof_Hollow",
      "rotation": 1
    },
    {
      "x": 10,
      "y": 1,
      "z": -5,
      "name": "Rock_Stone_Cobble"
    },
    {
      "x": 10,
      "y": 4,
      "z": -5,
      "name": "Cloth_Roof_White_Flap",
      "rotation": 1
    },
    {
      "x": 10,
      "y": 1,
      "z": -4,
      "name": "Rock_Stone_Cobble"
    },
    {
      "x": 10,
      "y": 4,
      "z": -4,
      "name": "Cloth_Roof_Green_Flap",
      "rotation": 1
    },
    {
      "x": 10,
      "y": 1,
      "z": -3,
      "name": "Rock_Stone_Cobble"
    },
    {
      "x": 10,
      "y": 4,
      "z": -3,
      "name": "Cloth_Roof_White_Flap",
      "rotation": 1
    },
    {
      "x": 10,
      "y": 1,
      "z": -2,
      "name": "Rock_Stone_Cobble"
    },
    {
      "x": 10,
      "y": 4,
      "z": -2,
      "name": "Cloth_Roof_Green_Flap",
      "rotation": 1
    },
    {
      "x": 10,
      "y": 1,
      "z": -1,
      "name": "Rock_Stone_Cobble_Mossy"
    }
  ]
}