{
  "version": 8,
  "blockIdVersion": 11,
  "anchorX": 0,
  "anchorY": 0,
  "anchorZ": 0,
  "blocks": [
    {
      "x": 1,
      "y": 1,
      "z": -15,
      "name": "Rock_Stone_Cobble"
    },
    {
      "x": 1,
      "y": 1,
      "z": -14,
      "name": "Rock_Stone_Cobble"
    },
    {
      "x": 1,
      "y": 1,
      "z": -13,
      "name": "Rock_Stone_Cobble"
    },
    {
      "x": 1,
      "y": 1,
      "z": -12,
      "name": "Rock_Stone_Cobble"
    },
    {
      "x": 1,
      "y": 5,
      "z": -12,
      "name": "Wood_Softwood_Roof_Hollow",
      "rotation": 2
    },
    {
      "x": 1,
      "y": 1,
      "z": -11,
      "name": "Rock_Stone_Cobble"
    },
    {
      "x": 1,
      "y": 5,
      "z": -11,
      "name": "Wood_Softwood_Planks_Half",
      "rotation": 8
    },
    {
      "x": 1,
      "y": 6,
      "z": -11,
      "name": "Wood_Softwood_Roof",
      "rotation": 2
    },
    {
      "x": 1,
      "y": 1,
      "z": -10,
      "name": "Rock_Stone_Cobble"
    },
    {
      "x": 1,
      "y": 6,
      "z": -10,
      "name": "Wood_Softwood_Planks_Half",
      "rotation": 8
    },
    {
      "x": 1,
      "y": 7,
      "z": -10,
      "name": "Wood_Softwood_Roof",
      "rotation": 2
    },
    {
      "x": 1,
      "y": 1,
      "z": -9,
      "name": "Rock_Stone_Cobble"
    },
    {
      "x": 1,
      "y": 6,
      "z": -9,
      "name": "Plant_Vine_Wall",
      "support": 15,
      "rotation": 3
    },
    {
      "x": 1,
      "y": 7,
      "z": -9,
      "name": "Wood_Softwood_Planks_Half",
      "rotation": 8
    },
    {
      "x": 1,
      "y": 8,
      "z": -9,
      "name": "Wood_Softwood_Roof",
      "rotation": 2
    },
    {
      "x": 1,
      "y": 1,
      "z": -8,
      "name": "Rock_Stone_Cobble"
    },
    {
      "x": 1,
      "y": 4,
      "z": -8,
      "name": "Plant_Vine_Wall",
      "support": 15,
      "rotation": 3
    },
    {
      "x": 1,
      "y": 8,
      "z": -8,
      "name": "Wood_Softwood_Planks_Half",
      "rotation": 8
    },
    {
      "x": 1,
      "y": 9,
      "z": -8,
      "name": "Wood_Softwood_Roof_Flat"
    },
    {
      "x": 1,
      "y": 1,
      "z": -7,
      "name": "Rock_Stone_Cobble"
    },
    {
      "x": 1,
      "y": 7,
      "z": -7,
      "name": "Wood_Softwood_Planks_Half",
      "rotation": 8
    },
    {
      "x": 1,
      "y": 8,
      "z": -7,
      "name": "Wood_Softwood_Roof"
    },
    {
      "x": 1,
      "y": 1,
      "z": -6,
      "name": "Rock_Stone_Cobble"
    },
    {
      "x": 1,
      "y": 6,
      "z": -6,
      "name": "Wood_Softwood_Planks_Half",
      "rotation": 8
    },
    {
      "x": 1,
      "y": 7,
      "z": -6,
      "name": "Wood_Softwood_Roof"
    },
    {
      "x": 1,
      "y": 1,
      "z": -5,
      "name": "Rock_Stone_Cobble"
    },
    {
      "x": 1,
      "y": 5,
      "z": -5,
      "name": "Wood_Softwood_Planks_Half",
      "rotation": 8
    },
    {
      "x": 1,
      "y": 6,
      "z": -5,
      "name": "Wood_Softwood_Roof"
    },
    {
      "x": 1,
      "y": 1,
      "z": -4,
      "name": "Rock_Stone_Cobble"
    },
    {
      "x": 1,
      "y": 5,
      "z": -4,
      "name": "Wood_Softwood_Roof_Hollow"
    },
    {
      "x": 1,
      "y": 1,
      "z": -3,
      "name": "Rock_Stone_Cobble"
    },
    {
      "x": 1,
      "y": 1,
      "z": -2,
      "name": "Rock_Stone_Cobble"
    },
    {
      "x": 1,
      "y": 1,
      "z": -1,
      "name": "Rock_Stone_Cobble"
    },
    {
      "x": 2,
      "y": 1,
      "z": -15,
      "name": "Rock_Stone_Cobble"
    },
    {
      "x": 2,
      "y": 1,
      "z": -14,
      "name": "Rock_Stone_Cobble"
    },
    {
      "x": 2,
      "y": 1,
      "z": -13,
      "name": "Rock_Stone_Cobble"
    },
    {
      "x": 2,
      "y": 1,
      "z": -12,
      "name": "Rock_Stone_Cobble"
    },
    {
      "x": 2,
      "y": 5,
      "z": -12,
      "name": "Wood_Softwood_Roof_Hollow",
      "rotation": 2
    },
    {
      "x": 2,
      "y": 1,
      "z": -11,
      "name": "Soil_Dirt"
    },
    {
      "x": 2,
      "y": 2,
      "z": -11,
      "name": "Wood_Beech_Trunk",
      "support": 15
    },
    {
      "x": 2,
      "y": 3,
      "z": -11,
      "name": "Wood_Beech_Trunk",
      "support": 15
    },
    {
      "x": 2,
      "y": 4,
      "z": -11,
      "name": "Wood_Beech_Trunk",
      "support": 15
    },
    {
      "x": 2,
      "y": 5,
      "z": -11,
      "name": "Wood_Beech_Trunk",
      "support": 15
    },
    {
      "x": 2,
      "y": 6,
      "z": -11,
      "name": "Wood_Softwood_Roof",
      "rotation": 2
    },
    {
      "x": 2,
      "y": 1,
      "z": -10,
      "name": "Soil_Dirt"
    },
    {
      "x": 2,
      "y": 2,
      "z": -10,
      "name": "Rock_Stone_Brick"
    },
    {
      "x": 2,
      "y": 3,
      "z": -10,
      "name": "*Wood_Village_Wall_Full_State_Definitions_Bottom"
    },
    {
      "x": 2,
      "y": 4,
      "z": -10,
      "name": "*Wood_Village_Wall_Full_State_Definitions_Top"
    },
    {
      "x": 2,
      "y": 5,
      "z": -10,
      "name": "Wood_Beech_Trunk",
      "support": 15,
      "rotation": 4
    },
    {
      "x": 2,
      "y": 6,
      "z": -10,
      "name": "Wood_Village_Wall_Full"
    },
    {
      "x": 2,
      "y": 7,
      "z": -10,
      "name": "Wood_Softwood_Roof",
      "rotation": 2
    },
    {
      "x": 2,
      "y": 1,
      "z": -9,
      "name": "Soil_Dirt"
    },
    {
      "x": 2,
      "y": 2,
      "z": -9,
      "name": "Rock_Stone_Brick"
    },
    {
      "x": 2,
      "y": 3,
      "z": -9,
      "name": "*Wood_Village_Wall_Full_State_Definitions_Bottom"
    },
    {
      "x": 2,
      "y": 4,
      "z": -9,
      "name": "*Wood_Village_Wall_Full_State_Definitions_Top"
    },
    {
      "x": 2,
      "y": 5,
      "z": -9,
      "name": "Wood_Beech_Trunk",
      "support": 15,
      "rotation": 4
    },
    {
      "x": 2,
      "y": 6,
      "z": -9,
      "name": "*Wood_Village_Wall_Full_State_Definitions_Bottom"
    },
    {
      "x": 2,
      "y": 7,
      "z": -9,
      "name": "*Wood_Village_Wall_Full_State_Definitions_Top"
    },
    {
      "x": 2,
      "y": 8,
      "z": -9,
      "name": "Wood_Softwood_Roof",
      "rotation": 2
    },
    {
      "x": 2,
      "y": 1,
      "z": -8,
      "name": "Soil_Dirt"
    },
    {
      "x": 2,
      "y": 2,
      "z": -8,
      "name": "Rock_Stone_Brick"
    },
    {
      "x": 2,
      "y": 3,
      "z": -8,
      "name": "*Wood_Village_Wall_Full_State_Definitions_Bottom"
    },
    {
      "x": 2,
      "y": 4,
      "z": -8,
      "name": "*Wood_Village_Wall_Full_State_Definitions_Top"
    },
    {
      "x": 2,
      "y": 5,
      "z": -8,
      "name": "Wood_Beech_Trunk",
      "support": 15,
      "rotation": 4
    },
    {
      "x": 2,
      "y": 6,
      "z": -8,
      "name": "*Wood_Village_Wall_Full_State_Definitions_Bottom"
    },
    {
      "x": 2,
      "y": 7,
      "z": -8,
      "name": "*Wood_Village_Wall_Full_State_Definitions_Middle"
    },
    {
      "x": 2,
      "y": 8,
      "z": -8,
      "name": "*Wood_Village_Wall_Full_State_Definitions_Top"
    },
    {
      "x": 2,
      "y": 9,
      "z": -8,
      "name": "Wood_Softwood_Roof_Flat"
    },
    {
      "x": 2,
      "y": 1,
      "z": -7,
      "name": "Soil_Dirt"
    },
    {
      "x": 2,
      "y": 2,
      "z": -7,
      "name": "Rock_Stone_Brick"
    },
    {
      "x": 2,
      "y": 3,
      "z": -7,
      "name": "Furniture_Village_Window",
      "rotation": 1
    },
    {
      "x": 2,
      "y": 4,
      "z": -7,
      "name": "Furniture_Village_Window",
      "rotation": 1
    },
    {
      "x": 2,
      "y": 5,
      "z": -7,
      "name": "Wood_Beech_Trunk",
      "support": 15,
      "rotation": 4
    },
    {
      "x": 2,
      "y": 6,
      "z": -7,
      "name": "*Wood_Village_Wall_Full_State_Definitions_Bottom"
    },
    {
      "x": 2,
      "y": 7,
      "z": -7,
      "name": "*Wood_Village_Wall_Full_State_Definitions_Top"
    },
    {
      "x": 2,
      "y": 8,
      "z": -7,
      "name": "Wood_Softwood_Roof"
    },
    {
      "x": 2,
      "y": 1,
      "z": -6,
      "name": "Soil_Dirt"
    },
    {
      "x": 2,
      "y": 2,
      "z": -6,
      "name": "Rock_Stone_Brick"
    },
    {
      "x": 2,
      "y": 3,
      "z": -6,
      "name": "*Wood_Village_Wall_Full_State_Definitions_Bottom"
    },
    {
      "x": 2,
      "y": 4,
      "z": -6,
      "name": "*Wood_Village_Wall_Full_State_Definitions_Top"
    },
    {
      "x": 2,
      "y": 5,
      "z": -6,
      "name": "Wood_Beech_Trunk",
      "support": 15,
      "rotation": 4
    },
    {
      "x": 2,
      "y": 6,
      "z": -6,
      "name": "Wood_Village_Wall_Full"
    },
    {
      "x": 2,
      "y": 7,
      "z": -6,
      "name": "Wood_Softwood_Roof"
    },
    {
      "x": 2,
      "y": 1,
      "z": -5,
      "name": "Soil_Dirt"
    },
    {
      "x": 2,
      "y": 2,
      "z": -5,
      "name": "Wood_Beech_Trunk",
      "support": 15
    },
    {
      "x": 2,
      "y": 3,
      "z": -5,
      "name": "Wood_Beech_Trunk",
      "support": 15
    },
    {
      "x": 2,
      "y": 4,
      "z": -5,
      "name": "Wood_Beech_Trunk",
      "support": 15
    },
    {
      "x": 2,
      "y": 5,
      "z": -5,
      "name": "Wood_Beech_Trunk",
      "support": 15
    },
    {
      "x": 2,
      "y": 6,
      "z": -5,
      "name": "Wood_Softwood_Roof"
    },
    {
      "x": 2,
      "y": 1,
      "z": -4,
      "name": "Rock_Stone_Cobble"
    },
    {
      "x": 2,
      "y": 2,
      "z": -4,
      "name": "Ingredient_Flour"
    },
    {
      "x": 2,
      "y": 5,
      "z": -4,
      "name": "Wood_Softwood_Roof_Hollow"
    },
    {
      "x": 2,
      "y": 1,
      "z": -3,
      "name": "Rock_Stone_Cobble"
    },
    {
      "x": 2,
      "y": 1,
      "z": -2,
      "name": "Rock_Stone_Cobble"
    },
    {
      "x": 2,
      "y": 1,
      "z": -1,
      "name": "Rock_Stone_Cobble"
    },
    {
      "x": 3,
      "y": 1,
      "z": -15,
      "name": "Rock_Stone_Cobble"
    },
    {
      "x": 3,
      "y": 1,
      "z": -14,
      "name": "Rock_Stone_Cobble"
    },
    {
      "x": 3,
      "y": 1,
      "z": -13,
      "name": "Rock_Stone_Cobble"
    },
    {
      "x": 3,
      "y": 1,
      "z": -12,
      "name": "Rock_Stone_Cobble"
    },
    {
      "x": 3,
      "y": 3,
      "z": -12,
      "name": "Plant_Vine_Wall",
      "support": 15,
      "rotation": 2
    },
    {
      "x": 3,
      "y": 5,
      "z": -12,
      "name": "Wood_Softwood_Roof_Hollow",
      "rotation": 2
    },
    {
      "x": 3,
      "y": 1,
      "z": -11,
      "name": "Soil_Dirt"
    },
    {
      "x": 3,
      "y": 2,
      "z": -11,
      "name": "Rock_Stone_Brick"
    },
    {
      "x": 3,
      "y": 3,
      "z": -11,
      "name": "*Wood_Village_Wall_Full_State_Definitions_Bottom"
    },
    {
      "x": 3,
      "y": 4,
      "z": -11,
      "name": "*Wood_Village_Wall_Full_State_Definitions_Top"
    },
    {
      "x": 3,
      "y": 5,
      "z": -11,
      "name": "Wood_Beech_Trunk",
      "support": 15,
      "rotation": 5
    },
    {
      "x": 3,
      "y": 6,
      "z": -11,
      "name": "Wood_Softwood_Roof",
      "rotation": 2
    },
    {
      "x": 3,
      "y": 1,
      "z": -10,
      "name": "Wood_Softwood_Planks"
    },
    {
      "x": 3,
      "y": 2,
      "z": -10,
      "name": "Ingredient_Hay"
    },
    {
      "x": 3,
      "y": 3,
      "z": -10,
      "name": "Ingredient_Hay"
    },
    {
      "x": 3,
      "y": 5,
      "z": -10,
      "name": "Furniture_Village_Platform",
      "rotation": 1
    },
    {
      "x": 3,
      "y": 6,
      "z": -10,
      "name": "Wood_Softwood_Stairs",
      "rotation": 10
    },
    {
      "x": 3,
      "y": 7,
      "z": -10,
      "name": "Wood_Softwood_Roof",
      "rotation": 2
    },
    {
      "x": 3,
      "y": 1,
      "z": -9,
      "name": "Wood_Softwood_Planks"
    },
    {
      "x": 3,
      "y": 2,
      "z": -9,
      "name": "Ingredient_Hay"
    },
    {
      "x": 3,
      "y": 3,
      "z": -9,
      "name": "Ingredient_Hay"
    },
    {
      "x": 3,
      "y": 5,
      "z": -9,
      "name": "Furniture_Village_Platform",
      "rotation": 1
    },
    {
      "x": 3,
      "y": 7,
      "z": -9,
      "name": "Wood_Softwood_Stairs",
      "rotation": 10
    },
    {
      "x": 3,
      "y": 8,
      "z": -9,
      "name": "Wood_Softwood_Roof",
      "rotation": 2
    },
    {
      "x": 3,
      "y": 1,
      "z": -8,
      "name": "Wood_Softwood_Planks"
    },
    {
      "x": 3,
      "y": 2,
      "z": -8,
      "name": "Ingredient_Hay"
    },
    {
      "x": 3,
      "y": 5,
      "z": -8,
      "name": "Furniture_Village_Platform",
      "rotation": 1
    },
    {
      "x": 3,
      "y": 6,
      "z": -8,
      "name": "Ingredient_Flour"
    },
    {
      "x": 3,
      "y": 8,
      "z": -8,
      "name": "Wood_Softwood_Planks"
    },
    {
      "x": 3,
      "y": 9,
      "z": -8,
      "name": "Wood_Softwood_Roof_Flat"
    },
    {
      "x": 3,
      "y": 1,
      "z": -7,
      "name": "Wood_Softwood_Planks"
    },
    {
      "x": 3,
      "y": 5,
      "z": -7,
      "name": "Furniture_Village_Platform",
      "rotation": 1
    },
    {
      "x": 3,
      "y": 6,
      "z": -7,
      "name": "Ingredient_Flour"
    },
    {
      "x": 3,
      "y": 7,
      "z": -7,
      "name": "Wood_Softwood_Stairs",
      "rotation": 8
    },
    {
      "x": 3,
      "y": 8,
      "z": -7,
      "name": "Wood_Softwood_Roof"
    },
    {
      "x": 3,
      "y": 1,
      "z": -6,
      "name": "Wood_Softwood_Planks"
    },
    {
      "x": 3,
      "y": 5,
      "z": -6,
      "name": "Furniture_Village_Platform",
      "rotation": 1
    },
    {
      "x": 3,
      "y": 6,
      "z": -6,
      "name": "Wood_Softwood_Stairs",
      "rotation": 8
    },
    {
      "x": 3,
      "y": 7,
      "z": -6,
      "name": "Wood_Softwood_Roof"
    },
    {
      "x": 3,
      "y": 1,
      "z": -5,
      "name": "Soil_Dirt"
    },
    {
      "x": 3,
      "y": 2,
      "z": -5,
      "name": "Rock_Stone_Brick"
    },
    {
      "x": 3,
      "y": 3,
      "z": -5,
      "name": "*Wood_Village_Wall_Full_State_Definitions_Bottom"
    },
    {
      "x": 3,
      "y": 4,
      "z": -5,
      "name": "*Wood_Village_Wall_Full_State_Definitions_Top"
    },
    {
      "x": 3,
      "y": 5,
      "z": -5,
      "name": "Wood_Beech_Trunk",
      "support": 15,
      "rotation": 5
    },
    {
      "x": 3,
      "y": 6,
      "z": -5,
      "name": "Wood_Softwood_Roof"
    },
    {
      "x": 3,
      "y": 1,
      "z": -4,
      "name": "Rock_Stone_Cobble"
    },
    {
      "x": 3,
      "y": 2,
      "z": -4,
      "name": "Ingredient_Flour"
    },
    {
      "x": 3,
      "y": 4,
      "z": -4,
      "name": "Plant_Vine_Wall",
      "support": 15
    },
    {
      "x": 3,
      "y": 5,
      "z": -4,
      "name": "Wood_Softwood_Roof_Hollow"
    },
    {
      "x": 3,
      "y": 1,
      "z": -3,
      "name": "Rock_Stone_Cobble"
    },
    {
      "x": 3,
      "y": 2,
      "z": -3,
      "name": "Ingredient_Flour"
    },
    {
      "x": 3,
      "y": 1,
      "z": -2,
      "name": "Rock_Stone_Cobble"
    },
    {
      "x": 3,
      "y": 1,
      "z": -1,
      "name": "Rock_Stone_Cobble"
    },
    {
      "x": 4,
      "y": 1,
      "z": -15,
      "name": "Rock_Stone_Cobble"
    },
    {
      "x": 4,
      "y": 1,
      "z": -14,
      "name": "Rock_Stone_Cobble"
    },
    {
      "x": 4,
      "y": 1,
      "z": -13,
      "name": "Rock_Stone_Cobble"
    },
    {
      "x": 4,
      "y": 1,
      "z": -12,
      "name": "Rock_Stone_Cobble"
    },
    {
      "x": 4,
      "y": 5,
      "z": -12,
      "name": "Wood_Softwood_Roof_Hollow",
      "rotation": 2
    },
    {
      "x": 4,
      "y": 1,
      "z": -11,
      "name": "Soil_Dirt"
    },
    {
      "x": 4,
      "y": 2,
      "z": -11,
      "name": "Rock_Stone_Brick"
    },
    {
      "x": 4,
      "y": 3,
      "z": -11,
      "name": "*Wood_Village_Wall_Full_State_Definitions_Bottom"
    },
    {
      "x": 4,
      "y": 4,
      "z": -11,
      "name": "*Wood_Village_Wall_Full_State_Definitions_Top"
    },
    {
      "x": 4,
      "y": 5,
      "z": -11,
      "name": "Wood_Beech_Trunk",
      "support": 15,
      "rotation": 5
    },
    {
      "x": 4,
      "y": 6,
      "z": -11,
      "name": "Wood_Softwood_Roof",
      "rotation": 2
    },
    {
      "x": 4,
      "y": 1,
      "z": -10,
      "name": "Wood_Softwood_Planks"
    },
    {
      "x": 4,
      "y": 2,
      "z": -10,
      "name": "Ingredient_Hay"
    },
    {
      "x": 4,
      "y": 5,
      "z": -10,
      "name": "Furniture_Village_Platform",
      "rotation": 1
    },
    {
      "x": 4,
      "y": 6,
      "z": -10,
      "name": "Wood_Softwood_Stairs",
      "rotation": 10
    },
    {
      "x": 4,
      "y": 7,
      "z": -10,
      "name": "Wood_Softwood_Roof",
      "rotation": 2
    },
    {
      "x": 4,
      "y": 1,
      "z": -9,
      "name": "Wood_Softwood_Planks"
    },
    {
      "x": 4,
      "y": 2,
      "z": -9,
      "name": "Ingredient_Hay"
    },
    {
      "x": 4,
      "y": 5,
      "z": -9,
      "name": "Furniture_Village_Platform",
      "rotation": 1
    },
    {
      "x": 4,
      "y": 7,
      "z": -9,
      "name": "Wood_Softwood_Stairs",
      "rotation": 10
    },
    {
      "x": 4,
      "y": 8,
      "z": -9,
      "name": "Wood_Softwood_Roof",
      "rotation": 2
    },
    {
      "x": 4,
      "y": 1,
      "z": -8,
      "name": "Wood_Softwood_Planks"
    },
    {
      "x": 4,
      "y": 5,
      "z": -8,
      "name": "Furniture_Village_Platform",
      "rotation": 1
    },
    {
      "x": 4,
      "y": 8,
      "z": -8,
      "name": "Wood_Softwood_Planks"
    },
    {
      "x": 4,
      "y": 9,
      "z": -8,
      "name": "Wood_Softwood_Roof_Flat"
    },
    {
      "x": 4,
      "y": 1,
      "z": -7,
      "name": "Wood_Softwood_Planks"
    },
    {
      "x": 4,
      "y": 5,
      "z": -7,
      "name": "Furniture_Village_Platform",
      "rotation": 1
    },
    {
      "x": 4,
      "y": 6,
      "z": -7,
      "name": "Ingredient_Flour"
    },
    {
      "x": 4,
      "y": 7,
      "z": -7,
      "name": "Wood_Softwood_Stairs",
      "rotation": 8
    },
    {
      "x": 4,
      "y": 8,
      "z": -7,
      "name": "Wood_Softwood_Roof"
    },
    {
      "x": 4,
      "y": 1,
      "z": -6,
      "name": "Wood_Softwood_Planks"
    },
    {
      "x": 4,
      "y": 5,
      "z": -6,
      "name": "Furniture_Village_Platform",
      "rotation": 1
    },
    {
      "x": 4,
      "y": 6,
      "z": -6,
      "name": "Wood_Softwood_Stairs",
      "rotation": 8
    },
    {
      "x": 4,
      "y": 7,
      "z": -6,
      "name": "Wood_Softwood_Roof"
    },
    {
      "x": 4,
      "y": 1,
      "z": -5,
      "name": "Soil_Dirt"
    },
    {
      "x": 4,
      "y": 2,
      "z": -5,
      "name": "Rock_Stone_Brick"
    },
    {
      "x": 4,
      "y": 3,
      "z": -5,
      "name": "*Wood_Village_Wall_Full_State_Definitions_Bottom"
    },
    {
      "x": 4,
      "y": 4,
      "z": -5,
      "name": "*Wood_Village_Wall_Full_State_Definitions_Top"
    },
    {
      "x": 4,
      "y": 5,
      "z": -5,
      "name": "Wood_Beech_Trunk",
      "support": 15,
      "rotation": 5
    },
    {
      "x": 4,
      "y": 6,
      "z": -5,
      "name": "Wood_Softwood_Roof"
    },
    {
      "x": 4,
      "y": 1,
      "z": -4,
      "name": "Rock_Stone_Cobble"
    },
    {
      "x": 4,
      "y": 2,
      "z": -4,
      "name": "Ingredient_Flour"
    },
    {
      "x": 4,
      "y": 5,
      "z": -4,
      "name": "Wood_Softwood_Roof_Hollow"
    },
    {
      "x": 4,
      "y": 1,
      "z": -3,
      "name": "Rock_Stone_Cobble"
    },
    {
      "x": 4,
      "y": 2,
      "z": -3,
      "name": "Ingredient_Flour"
    },
    {
      "x": 4,
      "y": 1,
      "z": -2,
      "name": "Rock_Stone_Cobble"
    },
    {
      "x": 4,
      "y": 1,
      "z": -1,
      "name": "Rock_Stone_Cobble"
    },
    {
      "x": 5,
      "y": 1,
      "z": -15,
      "name": "Rock_Stone_Cobble"
    },
    {
      "x": 5,
      "y": 1,
      "z": -14,
      "name": "Rock_Stone_Cobble"
    },
    {
      "x": 5,
      "y": 1,
      "z": -13,
      "name": "Rock_Stone_Cobble"
    },
    {
      "x": 5,
      "y": 1,
      "z": -12,
      "name": "Rock_Stone_Cobble"
    },
    {
      "x": 5,
      "y": 5,
      "z": -12,
      "name": "Wood_Softwood_Roof_Hollow",
      "rotation": 2
    },
    {
      "x": 5,
      "y": 1,
      "z": -11,
      "name": "Soil_Dirt"
    },
    {
      "x": 5,
      "y": 2,
      "z": -11,
      "name": "Wood_Beech_Trunk",
      "support": 15
    },
    {
      "x": 5,
      "y": 3,
      "z": -11,
      "name": "Wood_Beech_Trunk",
      "support": 15
    },
    {
      "x": 5,
      "y": 4,
      "z": -11,
      "name": "Wood_Beech_Trunk",
      "support": 15
    },
    {
      "x": 5,
      "y": 5,
      "z": -11,
      "name": "Wood_Beech_Trunk",
      "support": 15,
      "rotation": 5
    },
    {
      "x": 5,
      "y": 6,
      "z": -11,
      "name": "Wood_Softwood_Roof",
      "rotation": 2
    },
    {
      "x": 5,
      "y": 1,
      "z": -10,
      "name": "Wood_Softwood_Planks"
    },
    {
      "x": 5,
      "y": 2,
      "z": -10,
      "name": "Ingredient_Flour"
    },
    {
      "x": 5,
      "y": 5,
      "z": -10,
      "name": "Wood_Beech_Trunk",
      "support": 15,
      "rotation": 4
    },
    {
      "x": 5,
      "y": 6,
      "z": -10,
      "name": "Wood_Softwood_Stairs",
      "rotation": 10
    },
    {
      "x": 5,
      "y": 7,
      "z": -10,
      "name": "Wood_Softwood_Roof",
      "rotation": 2
    },
    {
      "x": 5,
      "y": 1,
      "z": -9,
      "name": "Wood_Softwood_Planks"
    },
    {
      "x": 5,
      "y": 2,
      "z": -9,
      "name": "Ingredient_Flour"
    },
    {
      "x": 5,
      "y": 5,
      "z": -9,
      "name": "Wood_Beech_Trunk",
      "support": 15,
      "rotation": 4
    },
    {
      "x": 5,
      "y": 7,
      "z": -9,
      "name": "Wood_Softwood_Stairs",
      "rotation": 10
    },
    {
      "x": 5,
      "y": 8,
      "z": -9,
      "name": "Wood_Softwood_Roof",
      "rotation": 2
    },
    {
      "x": 5,
      "y": 1,
      "z": -8,
      "name": "Wood_Softwood_Planks"
    },
    {
      "x": 5,
      "y": 4,
      "z": -8,
      "name": "Deco_Lantern_Ceiling"
    },
    {
      "x": 5,
      "y": 5,
      "z": -8,
      "name": "Wood_Beech_Trunk",
      "support": 15,
      "rotation": 4
    },
    {
      "x": 5,
      "y": 8,
      "z": -8,
      "name": "Wood_Softwood_Planks"
    },
    {
      "x": 5,
      "y": 9,
      "z": -8,
      "name": "Wood_Softwood_Roof_Flat"
    },
    {
      "x": 5,
      "y": 1,
      "z": -7,
      "name": "Wood_Softwood_Planks"
    },
    {
      "x": 5,
      "y": 2,
      "z": -7,
      "name": "Wood_Beech_Trunk",
      "support": 15
    },
    {
      "x": 5,
      "y": 3,
      "z": -7,
      "name": "Wood_Beech_Trunk",
      "support": 15
    },
    {
      "x": 5,
      "y": 4,
      "z": -7,
      "name": "Wood_Beech_Trunk",
      "support": 15
    },
    {
      "x": 5,
      "y": 5,
      "z": -7,
      "name": "Wood_Beech_Trunk",
      "support": 15,
      "rotation": 4
    },
    {
      "x": 5,
      "y": 7,
      "z": -7,
      "name": "Wood_Softwood_Stairs",
      "rotation": 8
    },
    {
      "x": 5,
      "y": 8,
      "z": -7,
      "name": "Wood_Softwood_Roof"
    },
    {
      "x": 5,
      "y": 1,
      "z": -6,
      "name": "Wood_Softwood_Planks"
    },
    {
      "x": 5,
      "y": 5,
      "z": -6,
      "name": "Wood_Beech_Trunk",
      "support": 15,
      "rotation": 4
    },
    {
      "x": 5,
      "y": 6,
      "z": -6,
      "name": "Wood_Softwood_Stairs",
      "rotation": 8
    },
    {
      "x": 5,
      "y": 7,
      "z": -6,
      "name": "Wood_Softwood_Roof"
    },
    {
      "x": 5,
      "y": 1,
      "z": -5,
      "name": "Soil_Dirt"
    },
    {
      "x": 5,
      "y": 2,
      "z": -5,
      "name": "Wood_Beech_Trunk",
      "support": 15
    },
    {
      "x": 5,
      "y": 3,
      "z": -5,
      "name": "Wood_Beech_Trunk",
      "support": 15
    },
    {
      "x": 5,
      "y": 4,
      "z": -5,
      "name": "Wood_Beech_Trunk",
      "support": 15
    },
    {
      "x": 5,
      "y": 5,
      "z": -5,
      "name": "Wood_Beech_Trunk",
      "support": 15,
      "rotation": 5
    },
    {
      "x": 5,
      "y": 6,
      "z": -5,
      "name": "Wood_Softwood_Roof"
    },
    {
      "x": 5,
      "y": 1,
      "z": -4,
      "name": "Rock_Stone_Cobble"
    },
    {
      "x": 5,
      "y": 2,
      "z": -4,
      "name": "Ingredient_Flour"
    },
    {
      "x": 5,
      "y": 5,
      "z": -4,
      "name": "Wood_Softwood_Roof_Hollow"
    },
    {
      "x": 5,
      "y": 1,
      "z": -3,
      "name": "Rock_Stone_Cobble"
    },
    {
      "x": 5,
      "y": 1,
      "z": -2,
      "name": "Rock_Stone_Cobble"
    },
    {
      "x": 5,
      "y": 1,
      "z": -1,
      "name": "Rock_Stone_Cobble"
    },
    {
      "x": 6,
      "y": 1,
      "z": -15,
      "name": "Rock_Stone_Cobble"
    },
    {
      "x": 6,
      "y": 1,
      "z": -14,
      "name": "Rock_Stone_Cobble"
    },
    {
      "x": 6,
      "y": 1,
      "z": -13,
      "name": "Rock_Stone_Cobble"
    },
    {
      "x": 6,
      "y": 1,
      "z": -12,
      "name": "Rock_Stone_Cobble"
    },
    {
      "x": 6,
      "y": 4,
      "z": -12,
      "name": "Plant_Vine_Wall",
      "support": 15,
      "rotation": 2
    },
    {
      "x": 6,
      "y": 5,
      "z": -12,
      "name": "Wood_Softwood_Roof_Hollow",
      "rotation": 2
    },
    {
      "x": 6,
      "y": 1,
      "z": -11,
      "name": "Soil_Dirt"
    },
    {
      "x": 6,
      "y": 2,
      "z": -11,
      "name": "Rock_Stone_Brick"
    },
    {
      "x": 6,
      "y": 3,
      "z": -11,
      "name": "*Wood_Village_Wall_Full_State_Definitions_Bottom"
    },
    {
      "x": 6,
      "y": 4,
      "z": -11,
      "name": "*Wood_Village_Wall_Full_State_Definitions_Top"
    },
    {
      "x": 6,
      "y": 5,
      "z": -11,
      "name": "Wood_Beech_Trunk",
      "support": 15,
      "rotation": 5
    },
    {
      "x": 6,
      "y": 6,
      "z": -11,
      "name": "Wood_Softwood_Roof",
      "rotation": 2
    },
    {
      "x": 6,
      "y": 1,
      "z": -10,
      "name": "Wood_Softwood_Planks"
    },
    {
      "x": 6,
      "y": 2,
      "z": -10,
      "name": "Ingredient_Flour"
    },
    {
      "x": 6,
      "y": 6,
      "z": -10,
      "name": "Wood_Softwood_Stairs",
      "rotation": 10
    },
    {
      "x": 6,
      "y": 7,
      "z": -10,
      "name": "Wood_Softwood_Roof",
      "rotation": 2
    },
    {
      "x": 6,
      "y": 1,
      "z": -9,
      "name": "Wood_Softwood_Planks"
    },
    {
      "x": 6,
      "y": 7,
      "z": -9,
      "name": "Wood_Softwood_Stairs",
      "rotation": 10
    },
    {
      "x": 6,
      "y": 8,
      "z": -9,
      "name": "Wood_Softwood_Roof",
      "rotation": 2
    },
    {
      "x": 6,
      "y": 1,
      "z": -8,
      "name": "Wood_Softwood_Planks"
    },
    {
      "x": 6,
      "y": 8,
      "z": -8,
      "name": "Wood_Softwood_Planks"
    },
    {
      "x": 6,
      "y": 9,
      "z": -8,
      "name": "Wood_Softwood_Roof_Flat"
    },
    {
      "x": 6,
      "y": 1,
      "z": -7,
      "name": "Wood_Softwood_Planks"
    },
    {
      "x": 6,
      "y": 2,
      "z": -7,
      "name": "Furniture_Village_Ladder",
      "rotation": 1
    },
    {
      "x": 6,
      "y": 3,
      "z": -7,
      "name": "Furniture_Village_Ladder",
      "rotation": 1
    },
    {
      "x": 6,
      "y": 4,
      "z": -7,
      "name": "Furniture_Village_Ladder",
      "rotation": 1
    },
    {
      "x": 6,
      "y": 5,
      "z": -7,
      "name": "Furniture_Village_Ladder",
      "rotation": 1
    },
    {
      "x": 6,
      "y": 7,
      "z": -7,
      "name": "Wood_Softwood_Stairs",
      "rotation": 8
    },
    {
      "x": 6,
      "y": 8,
      "z": -7,
      "name": "Wood_Softwood_Roof"
    },
    {
      "x": 6,
      "y": 1,
      "z": -6,
      "name": "Wood_Softwood_Planks"
    },
    {
      "x": 6,
      "y": 2,
      "z": -6,
      "name": "Aetherhaven_Production_Storage",
      "rotation": 2
    },
    {
      "x": 6,
      "y": 3,
      "z": -6,
      "name": "Aetherhaven_Production_Storage",
      "filler": 1024,
      "rotation": 2
    },
    {
      "x": 6,
      "y": 6,
      "z": -6,
      "name": "Wood_Softwood_Stairs",
      "rotation": 8
    },
    {
      "x": 6,
      "y": 7,
      "z": -6,
      "name": "Wood_Softwood_Roof"
    },
    {
      "x": 6,
      "y": 1,
      "z": -5,
      "name": "Soil_Dirt"
    },
    {
      "x": 6,
      "y": 2,
      "z": -5,
      "name": "Rock_Stone_Brick"
    },
    {
      "x": 6,
      "y": 3,
      "z": -5,
      "name": "*Wood_Village_Wall_Full_State_Definitions_Bottom"
    },
    {
      "x": 6,
      "y": 4,
      "z": -5,
      "name": "*Wood_Village_Wall_Full_State_Definitions_Top"
    },
    {
      "x": 6,
      "y": 5,
      "z": -5,
      "name": "Wood_Beech_Trunk",
      "support": 15,
      "rotation": 5
    },
    {
      "x": 6,
      "y": 6,
      "z": -5,
      "name": "Wood_Softwood_Roof"
    },
    {
      "x": 6,
      "y": 1,
      "z": -4,
      "name": "Rock_Stone_Cobble"
    },
    {
      "x": 6,
      "y": 5,
      "z": -4,
      "name": "Wood_Softwood_Roof_Hollow"
    },
    {
      "x": 6,
      "y": 1,
      "z": -3,
      "name": "Rock_Stone_Cobble"
    },
    {
      "x": 6,
      "y": 1,
      "z": -2,
      "name": "Rock_Stone_Cobble"
    },
    {
      "x": 6,
      "y": 1,
      "z": -1,
      "name": "Rock_Stone_Cobble"
    },
    {
      "x": 7,
      "y": 1,
      "z": -15,
      "name": "Rock_Stone_Cobble"
    },
    {
      "x": 7,
      "y": 1,
      "z": -14,
      "name": "Rock_Stone_Cobble"
    },
    {
      "x": 7,
      "y": 1,
      "z": -13,
      "name": "Rock_Stone_Cobble"
    },
    {
      "x": 7,
      "y": 1,
      "z": -12,
      "name": "Rock_Stone_Cobble"
    },
    {
      "x": 7,
      "y": 5,
      "z": -12,
      "name": "Wood_Softwood_Roof_Hollow",
      "rotation": 2
    },
    {
      "x": 7,
      "y": 1,
      "z": -11,
      "name": "Soil_Dirt"
    },
    {
      "x": 7,
      "y": 2,
      "z": -11,
      "name": "Rock_Stone_Brick"
    },
    {
      "x": 7,
      "y": 3,
      "z": -11,
      "name": "Furniture_Village_Window"
    },
    {
      "x": 7,
      "y": 4,
      "z": -11,
      "name": "Furniture_Village_Window"
    },
    {
      "x": 7,
      "y": 5,
      "z": -11,
      "name": "Wood_Beech_Trunk",
      "support": 15,
      "rotation": 5
    },
    {
      "x": 7,
      "y": 6,
      "z": -11,
      "name": "Wood_Softwood_Roof",
      "rotation": 2
    },
    {
      "x": 7,
      "y": 1,
      "z": -10,
      "name": "Wood_Softwood_Planks"
    },
    {
      "x": 7,
      "y": 6,
      "z": -10,
      "name": "Wood_Softwood_Stairs",
      "rotation": 10
    },
    {
      "x": 7,
      "y": 7,
      "z": -10,
      "name": "Wood_Softwood_Roof",
      "rotation": 2
    },
    {
      "x": 7,
      "y": 1,
      "z": -9,
      "name": "Wood_Softwood_Planks"
    },
    {
      "x": 7,
      "y": 7,
      "z": -9,
      "name": "Wood_Softwood_Stairs",
      "rotation": 10
    },
    {
      "x": 7,
      "y": 8,
      "z": -9,
      "name": "Wood_Softwood_Roof",
      "rotation": 2
    },
    {
      "x": 7,
      "y": 1,
      "z": -8,
      "name": "Wood_Softwood_Planks"
    },
    {
      "x": 7,
      "y": 8,
      "z": -8,
      "name": "Wood_Softwood_Planks"
    },
    {
      "x": 7,
      "y": 9,
      "z": -8,
      "name": "Wood_Softwood_Roof_Flat"
    },
    {
      "x": 7,
      "y": 1,
      "z": -7,
      "name": "Wood_Softwood_Planks"
    },
    {
      "x": 7,
      "y": 7,
      "z": -7,
      "name": "Wood_Softwood_Stairs",
      "rotation": 8
    },
    {
      "x": 7,
      "y": 8,
      "z": -7,
      "name": "Wood_Softwood_Roof"
    },
    {
      "x": 7,
      "y": 1,
      "z": -6,
      "name": "Wood_Softwood_Planks"
    },
    {
      "x": 7,
      "y": 2,
      "z": -6,
      "name": "Aetherhaven_Production_Storage",
      "filler": 1,
      "rotation": 2
    },
    {
      "x": 7,
      "y": 3,
      "z": -6,
      "name": "Aetherhaven_Production_Storage",
      "filler": 1025,
      "rotation": 2
    },
    {
      "x": 7,
      "y": 6,
      "z": -6,
      "name": "Wood_Softwood_Stairs",
      "rotation": 8
    },
    {
      "x": 7,
      "y": 7,
      "z": -6,
      "name": "Wood_Softwood_Roof"
    },
    {
      "x": 7,
      "y": 1,
      "z": -5,
      "name": "Soil_Dirt"
    },
    {
      "x": 7,
      "y": 2,
      "z": -5,
      "name": "Rock_Stone_Brick"
    },
    {
      "x": 7,
      "y": 3,
      "z": -5,
      "name": "*Wood_Village_Wall_Full_State_Definitions_Bottom"
    },
    {
      "x": 7,
      "y": 4,
      "z": -5,
      "name": "*Wood_Village_Wall_Full_State_Definitions_Top"
    },
    {
      "x": 7,
      "y": 5,
      "z": -5,
      "name": "Wood_Beech_Trunk",
      "support": 15,
      "rotation": 5
    },
    {
      "x": 7,
      "y": 6,
      "z": -5,
      "name": "Wood_Softwood_Roof"
    },
    {
      "x": 7,
      "y": 1,
      "z": -4,
      "name": "Rock_Stone_Cobble"
    },
    {
      "x": 7,
      "y": 3,
      "z": -4,
      "name": "Plant_Vine_Wall",
      "support": 15
    },
    {
      "x": 7,
      "y": 5,
      "z": -4,
      "name": "Wood_Softwood_Roof_Hollow"
    },
    {
      "x": 7,
      "y": 1,
      "z": -3,
      "name": "Rock_Stone_Cobble"
    },
    {
      "x": 7,
      "y": 1,
      "z": -2,
      "name": "Rock_Stone_Cobble"
    },
    {
      "x": 7,
      "y": 1,
      "z": -1,
      "name": "Rock_Stone_Cobble"
    },
    {
      "x": 8,
      "y": 1,
      "z": -15,
      "name": "Rock_Stone_Cobble"
    },
    {
      "x": 8,
      "y": 1,
      "z": -14,
      "name": "Rock_Stone_Cobble"
    },
    {
      "x": 8,
      "y": 1,
      "z": -13,
      "name": "Rock_Stone_Cobble"
    },
    {
      "x": 8,
      "y": 1,
      "z": -12,
      "name": "Rock_Stone_Cobble"
    },
    {
      "x": 8,
      "y": 5,
      "z": -12,
      "name": "Wood_Softwood_Roof_Hollow",
      "rotation": 2
    },
    {
      "x": 8,
      "y": 1,
      "z": -11,
      "name": "Soil_Dirt"
    },
    {
      "x": 8,
      "y": 2,
      "z": -11,
      "name": "Rock_Stone_Brick"
    },
    {
      "x": 8,
      "y": 3,
      "z": -11,
      "name": "*Wood_Village_Wall_Full_State_Definitions_Bottom"
    },
    {
      "x": 8,
      "y": 4,
      "z": -11,
      "name": "*Wood_Village_Wall_Full_State_Definitions_Top"
    },
    {
      "x": 8,
      "y": 5,
      "z": -11,
      "name": "Wood_Beech_Trunk",
      "support": 15,
      "rotation": 5
    },
    {
      "x": 8,
      "y": 6,
      "z": -11,
      "name": "Wood_Softwood_Roof",
      "rotation": 2
    },
    {
      "x": 8,
      "y": 1,
      "z": -10,
      "name": "Wood_Softwood_Planks"
    },
    {
      "x": 8,
      "y": 2,
      "z": -10,
      "name": "Ingredient_Flour"
    },
    {
      "x": 8,
      "y": 6,
      "z": -10,
      "name": "Wood_Softwood_Stairs",
      "rotation": 10
    },
    {
      "x": 8,
      "y": 7,
      "z": -10,
      "name": "Wood_Softwood_Roof",
      "rotation": 2
    },
    {
      "x": 8,
      "y": 1,
      "z": -9,
      "name": "Wood_Softwood_Planks"
    },
    {
      "x": 8,
      "y": 7,
      "z": -9,
      "name": "Wood_Softwood_Stairs",
      "rotation": 10
    },
    {
      "x": 8,
      "y": 8,
      "z": -9,
      "name": "Wood_Softwood_Roof",
      "rotation": 2
    },
    {
      "x": 8,
      "y": 1,
      "z": -8,
      "name": "Wood_Softwood_Planks"
    },
    {
      "x": 8,
      "y": 8,
      "z": -8,
      "name": "Wood_Softwood_Planks"
    },
    {
      "x": 8,
      "y": 9,
      "z": -8,
      "name": "Wood_Softwood_Roof_Flat"
    },
    {
      "x": 8,
      "y": 1,
      "z": -7,
      "name": "Wood_Softwood_Planks"
    },
    {
      "x": 8,
      "y": 7,
      "z": -7,
      "name": "Wood_Softwood_Stairs",
      "rotation": 8
    },
    {
      "x": 8,
      "y": 8,
      "z": -7,
      "name": "Wood_Softwood_Roof"
    },
    {
      "x": 8,
      "y": 1,
      "z": -6,
      "name": "Wood_Softwood_Planks"
    },
    {
      "x": 8,
      "y": 6,
      "z": -6,
      "name": "Wood_Softwood_Stairs",
      "rotation": 8
    },
    {
      "x": 8,
      "y": 7,
      "z": -6,
      "name": "Wood_Softwood_Roof"
    },
    {
      "x": 8,
      "y": 1,
      "z": -5,
      "name": "Rock_Stone_Cobble"
    },
    {
      "x": 8,
      "y": 2,
      "z": -5,
      "name": "*Furniture_Village_Door_State_Definitions_CloseDoorIn"
    },
    {
      "x": 8,
      "y": 3,
      "z": -5,
      "name": "*Furniture_Village_Door_State_Definitions_CloseDoorIn",
      "filler": 1024
    },
    {
      "x": 8,
      "y": 4,
      "z": -5,
      "name": "Wood_Village_Wall_Full"
    },
    {
      "x": 8,
      "y": 5,
      "z": -5,
      "name": "Wood_Beech_Trunk",
      "support": 15,
      "rotation": 5
    },
    {
      "x": 8,
      "y": 6,
      "z": -5,
      "name": "Wood_Softwood_Roof"
    },
    {
      "x": 8,
      "y": 1,
      "z": -4,
      "name": "Rock_Stone_Cobble"
    },
    {
      "x": 8,
      "y": 5,
      "z": -4,
      "name": "Wood_Softwood_Roof_Hollow"
    },
    {
      "x": 8,
      "y": 1,
      "z": -3,
      "name": "Rock_Stone_Cobble"
    },
    {
      "x": 8,
      "y": 1,
      "z": -2,
      "name": "Rock_Stone_Cobble"
    },
    {
      "x": 8,
      "y": 1,
      "z": -1,
      "name": "Rock_Stone_Cobble"
    },
    {
      "x": 9,
      "y": 1,
      "z": -15,
      "name": "Rock_Stone_Cobble"
    },
    {
      "x": 9,
      "y": 1,
      "z": -14,
      "name": "Rock_Stone_Cobble"
    },
    {
      "x": 9,
      "y": 16,
      "z": -14,
      "name": "Cloth_Block_Wool_White"
    },
    {
      "x": 9,
      "y": 17,
      "z": -14,
      "name": "Wood_Hardwood_Fence",
      "rotation": 2
    },
    {
      "x": 9,
      "y": 1,
      "z": -13,
      "name": "Rock_Stone_Cobble"
    },
    {
      "x": 9,
      "y": 1,
      "z": -12,
      "name": "Rock_Stone_Cobble"
    },
    {
      "x": 9,
      "y": 5,
      "z": -12,
      "name": "Wood_Softwood_Roof_Hollow",
      "rotation": 2
    },
    {
      "x": 9,
      "y": 1,
      "z": -11,
      "name": "Soil_Dirt"
    },
    {
      "x": 9,
      "y": 2,
      "z": -11,
      "name": "Rock_Stone_Brick"
    },
    {
      "x": 9,
      "y": 3,
      "z": -11,
      "name": "*Wood_Village_Wall_Full_State_Definitions_Bottom"
    },
    {
      "x": 9,
      "y": 4,
      "z": -11,
      "name": "*Wood_Village_Wall_Full_State_Definitions_Top"
    },
    {
      "x": 9,
      "y": 5,
      "z": -11,
      "name": "Wood_Beech_Trunk",
      "support": 15,
      "rotation": 5
    },
    {
      "x": 9,
      "y": 6,
      "z": -11,
      "name": "Wood_Softwood_Roof",
      "rotation": 2
    },
    {
      "x": 9,
      "y": 1,
      "z": -10,
      "name": "Soil_Dirt"
    },
    {
      "x": 9,
      "y": 2,
      "z": -10,
      "name": "Ingredient_Hay"
    },
    {
      "x": 9,
      "y": 6,
      "z": -10,
      "name": "Wood_Softwood_Stairs",
      "rotation": 10
    },
    {
      "x": 9,
      "y": 7,
      "z": -10,
      "name": "Wood_Softwood_Roof",
      "rotation": 2
    },
    {
      "x": 9,
      "y": 1,
      "z": -9,
      "name": "Wood_Softwood_Planks"
    },
    {
      "x": 9,
      "y": 7,
      "z": -9,
      "name": "Wood_Softwood_Stairs",
      "rotation": 10
    },
    {
      "x": 9,
      "y": 8,
      "z": -9,
      "name": "Wood_Softwood_Roof",
      "rotation": 2
    },
    {
      "x": 9,
      "y": 1,
      "z": -8,
      "name": "Wood_Softwood_Planks"
    },
    {
      "x": 9,
      "y": 2,
      "z": -8,
      "name": "Aetherhaven_Management_Block",
      "components": {
        "Components": {
          "AetherhavenManagementBlock": {
            "PlotId": "",
            "TownId": ""
          },
          "PlacedByInteraction": {
            "WhoPlacedUuid": {
              "$binary": "gqJcCRGLSleXtmq6BvFR8g==",
              "$type": "04"
            }
          }
        }
      },
      "rotation": 3
    },
    {
      "x": 9,
      "y": 8,
      "z": -8,
      "name": "Wood_Softwood_Planks"
    },
    {
      "x": 9,
      "y": 9,
      "z": -8,
      "name": "Wood_Softwood_Roof_Flat"
    },
    {
      "x": 9,
      "y": 1,
      "z": -7,
      "name": "Wood_Softwood_Planks"
    },
    {
      "x": 9,
      "y": 2,
      "z": -7,
      "name": "Ingredient_Hay"
    },
    {
      "x": 9,
      "y": 7,
      "z": -7,
      "name": "Wood_Softwood_Stairs",
      "rotation": 8
    },
    {
      "x": 9,
      "y": 8,
      "z": -7,
      "name": "Wood_Softwood_Roof"
    },
    {
      "x": 9,
      "y": 1,
      "z": -6,
      "name": "Wood_Softwood_Planks"
    },
    {
      "x": 9,
      "y": 2,
      "z": -6,
      "name": "Ingredient_Hay"
    },
    {
      "x": 9,
      "y": 3,
      "z": -6,
      "name": "Ingredient_Hay"
    },
    {
      "x": 9,
      "y": 6,
      "z": -6,
      "name": "Wood_Softwood_Stairs",
      "rotation": 8
    },
    {
      "x": 9,
      "y": 7,
      "z": -6,
      "name": "Wood_Softwood_Roof"
    },
    {
      "x": 9,
      "y": 1,
      "z": -5,
      "name": "Soil_Dirt"
    },
    {
      "x": 9,
      "y": 2,
      "z": -5,
      "name": "Rock_Stone_Brick"
    },
    {
      "x": 9,
      "y": 3,
      "z": -5,
      "name": "*Wood_Village_Wall_Full_State_Definitions_Bottom"
    },
    {
      "x": 9,
      "y": 4,
      "z": -5,
      "name": "*Wood_Village_Wall_Full_State_Definitions_Top"
    },
    {
      "x": 9,
      "y": 5,
      "z": -5,
      "name": "Wood_Beech_Trunk",
      "support": 15,
      "rotation": 5
    },
    {
      "x": 9,
      "y": 6,
      "z": -5,
      "name": "Wood_Softwood_Roof"
    },
    {
      "x": 9,
      "y": 1,
      "z": -4,
      "name": "Rock_Stone_Cobble"
    },
    {
      "x": 9,
      "y": 2,
      "z": -4,
      "name": "Ingredient_Hay"
    },
    {
      "x": 9,
      "y": 5,
      "z": -4,
      "name": "Wood_Softwood_Roof_Hollow"
    },
    {
      "x": 9,
      "y": 1,
      "z": -3,
      "name": "Rock_Stone_Cobble"
    },
    {
      "x": 9,
      "y": 1,
      "z": -2,
      "name": "Rock_Stone_Cobble"
    },
    {
      "x": 9,
      "y": 13,
      "z": -2,
      "name": "Wood_Hardwood_Fence"
    },
    {
      "x": 9,
      "y": 14,
      "z": -2,
      "name": "Cloth_Block_Wool_White"
    },
    {
      "x": 9,
      "y": 1,
      "z": -1,
      "name": "Rock_Stone_Cobble"
    },
    {
      "x": 10,
      "y": 1,
      "z": -15,
      "name": "Rock_Stone_Cobble"
    },
    {
      "x": 10,
      "y": 1,
      "z": -14,
      "name": "Rock_Stone_Cobble"
    },
    {
      "x": 10,
      "y": 15,
      "z": -14,
      "name": "Cloth_Block_Wool_White"
    },
    {
      "x": 10,
      "y": 16,
      "z": -14,
      "name": "Cloth_Block_Wool_White"
    },
    {
      "x": 10,
      "y": 17,
      "z": -14,
      "name": "Wood_Hardwood_Fence",
      "rotation": 2
    },
    {
      "x": 10,
      "y": 1,
      "z": -13,
      "name": "Rock_Stone_Cobble"
    },
    {
      "x": 10,
      "y": 7,
      "z": -13,
      "name": "*Wood_Softwood_Roof_Shallow_State_Definitions_Corner_Left",
      "rotation": 2
    },
    {
      "x": 10,
      "y": 1,
      "z": -12,
      "name": "Rock_Stone_Cobble"
    },
    {
      "x": 10,
      "y": 4,
      "z": -12,
      "name": "Plant_Vine_Wall",
      "support": 15,
      "rotation": 2
    },
    {
      "x": 10,
      "y": 5,
      "z": -12,
      "name": "Wood_Softwood_Roof_Hollow",
      "rotation": 2
    },
    {
      "x": 10,
      "y": 6,
      "z": -12,
      "name": "Wood_Beech_Branch_Corner",
      "support": 15,
      "rotation": 3
    },
    {
      "x": 10,
      "y": 7,
      "z": -12,
      "name": "*Wood_Softwood_Roof_Shallow_State_Definitions_Corner_Left",
      "filler": 32,
      "rotation": 2
    },
    {
      "x": 10,
      "y": 1,
      "z": -11,
      "name": "Soil_Dirt"
    },
    {
      "x": 10,
      "y": 2,
      "z": -11,
      "name": "Wood_Beech_Trunk",
      "support": 15
    },
    {
      "x": 10,
      "y": 3,
      "z": -11,
      "name": "Wood_Beech_Trunk",
      "support": 15
    },
    {
      "x": 10,
      "y": 4,
      "z": -11,
      "name": "Wood_Beech_Trunk",
      "support": 15
    },
    {
      "x": 10,
      "y": 5,
      "z": -11,
      "name": "Wood_Beech_Trunk",
      "support": 15
    },
    {
      "x": 10,
      "y": 6,
      "z": -11,
      "name": "Wood_Softwood_Roof",
      "rotation": 2
    },
    {
      "x": 10,
      "y": 7,
      "z": -11,
      "name": "Wood_Softwood_Roof_Shallow",
      "rotation": 3
    },
    {
      "x": 10,
      "y": 1,
      "z": -10,
      "name": "Soil_Dirt"
    },
    {
      "x": 10,
      "y": 2,
      "z": -10,
      "name": "Rock_Stone_Brick"
    },
    {
      "x": 10,
      "y": 3,
      "z": -10,
      "name": "*Wood_Village_Wall_Full_State_Definitions_Bottom"
    },
    {
      "x": 10,
      "y": 4,
      "z": -10,
      "name": "*Wood_Village_Wall_Full_State_Definitions_Top"
    },
    {
      "x": 10,
      "y": 5,
      "z": -10,
      "name": "Wood_Beech_Trunk",
      "support": 15,
      "rotation": 4
    },
    {
      "x": 10,
      "y": 6,
      "z": -10,
      "name": "Wood_Beech_Trunk",
      "support": 15,
      "rotation": 4
    },
    {
      "x": 10,
      "y": 7,
      "z": -10,
      "name": "Wood_Softwood_Roof",
      "rotation": 2
    },
    {
      "x": 10,
      "y": 1,
      "z": -9,
      "name": "Wood_Softwood_Planks"
    },
    {
      "x": 10,
      "y": 2,
      "z": -9,
      "name": "*Furniture_Village_Door_State_Definitions_CloseDoorOut",
      "rotation": 3
    },
    {
      "x": 10,
      "y": 3,
      "z": -9,
      "name": "*Furniture_Village_Door_State_Definitions_CloseDoorOut",
      "filler": 1024,
      "rotation": 3
    },
    {
      "x": 10,
      "y": 4,
      "z": -9,
      "name": "Wood_Village_Wall_Full"
    },
    {
      "x": 10,
      "y": 5,
      "z": -9,
      "name": "Wood_Beech_Trunk",
      "support": 15,
      "rotation": 4
    },
    {
      "x": 10,
      "y": 6,
      "z": -9,
      "name": "Wood_Beech_Trunk",
      "support": 15,
      "rotation": 4
    },
    {
      "x": 10,
      "y": 7,
      "z": -9,
      "name": "Wood_Village_Wall_Full"
    },
    {
      "x": 10,
      "y": 8,
      "z": -9,
      "name": "Wood_Softwood_Roof",
      "rotation": 2
    },
    {
      "x": 10,
      "y": 1,
      "z": -8,
      "name": "Soil_Dirt"
    },
    {
      "x": 10,
      "y": 2,
      "z": -8,
      "name": "Rock_Stone_Brick"
    },
    {
      "x": 10,
      "y": 3,
      "z": -8,
      "name": "*Wood_Village_Wall_Full_State_Definitions_Bottom"
    },
    {
      "x": 10,
      "y": 4,
      "z": -8,
      "name": "*Wood_Village_Wall_Full_State_Definitions_Top"
    },
    {
      "x": 10,
      "y": 5,
      "z": -8,
      "name": "Wood_Beech_Trunk",
      "support": 15,
      "rotation": 4
    },
    {
      "x": 10,
      "y": 6,
      "z": -8,
      "name": "Wood_Beech_Trunk",
      "support": 15,
      "rotation": 4
    },
    {
      "x": 10,
      "y": 7,
      "z": -8,
      "name": "Wood_Village_Wall_Full"
    },
    {
      "x": 10,
      "y": 8,
      "z": -8,
      "name": "Wood_Softwood_Planks"
    },
    {
      "x": 10,
      "y": 9,
      "z": -8,
      "name": "Wood_Softwood_Roof_Flat"
    },
    {
      "x": 10,
      "y": 1,
      "z": -7,
      "name": "Soil_Dirt"
    },
    {
      "x": 10,
      "y": 2,
      "z": -7,
      "name": "Rock_Stone_Brick"
    },
    {
      "x": 10,
      "y": 3,
      "z": -7,
      "name": "*Wood_Village_Wall_Full_State_Definitions_Bottom"
    },
    {
      "x": 10,
      "y": 4,
      "z": -7,
      "name": "*Wood_Village_Wall_Full_State_Definitions_Top"
    },
    {
      "x": 10,
      "y": 5,
      "z": -7,
      "name": "Wood_Beech_Trunk",
      "support": 15,
      "rotation": 4
    },
    {
      "x": 10,
      "y": 6,
      "z": -7,
      "name": "Wood_Beech_Trunk",
      "support": 15,
      "rotation": 4
    },
    {
      "x": 10,
      "y": 7,
      "z": -7,
      "name": "Wood_Village_Wall_Full"
    },
    {
      "x": 10,
      "y": 8,
      "z": -7,
      "name": "Wood_Softwood_Roof"
    },
    {
      "x": 10,
      "y": 1,
      "z": -6,
      "name": "Soil_Dirt"
    },
    {
      "x": 10,
      "y": 2,
      "z": -6,
      "name": "Rock_Stone_Brick"
    },
    {
      "x": 10,
      "y": 3,
      "z": -6,
      "name": "*Wood_Village_Wall_Full_State_Definitions_Bottom"
    },
    {
      "x": 10,
      "y": 4,
      "z": -6,
      "name": "*Wood_Village_Wall_Full_State_Definitions_Top"
    },
    {
      "x": 10,
      "y": 5,
      "z": -6,
      "name": "Wood_Beech_Trunk",
      "support": 15,
      "rotation": 4
    },
    {
      "x": 10,
      "y": 6,
      "z": -6,
      "name": "Wood_Beech_Trunk",
      "support": 15,
      "rotation": 4
    },
    {
      "x": 10,
      "y": 7,
      "z": -6,
      "name": "Wood_Softwood_Roof"
    },
    {
      "x": 10,
      "y": 1,
      "z": -5,
      "name": "Soil_Dirt"
    },
    {
      "x": 10,
      "y": 2,
      "z": -5,
      "name": "Wood_Beech_Trunk",
      "support": 15
    },
    {
      "x": 10,
      "y": 3,
      "z": -5,
      "name": "Wood_Beech_Trunk",
      "support": 15
    },
    {
      "x": 10,
      "y": 4,
      "z": -5,
      "name": "Wood_Beech_Trunk",
      "support": 15
    },
    {
      "x": 10,
      "y": 5,
      "z": -5,
      "name": "Wood_Beech_Trunk",
      "support": 15
    },
    {
      "x": 10,
      "y": 6,
      "z": -5,
      "name": "Wood_Softwood_Roof"
    },
    {
      "x": 10,
      "y": 7,
      "z": -5,
      "name": "Wood_Softwood_Roof_Shallow",
      "rotation": 3
    },
    {
      "x": 10,
      "y": 1,
      "z": -4,
      "name": "Rock_Stone_Cobble"
    },
    {
      "x": 10,
      "y": 2,
      "z": -4,
      "name": "Ingredient_Hay"
    },
    {
      "x": 10,
      "y": 3,
      "z": -4,
      "name": "Ingredient_Hay"
    },
    {
      "x": 10,
      "y": 5,
      "z": -4,
      "name": "Wood_Softwood_Roof_Hollow"
    },
    {
      "x": 10,
      "y": 6,
      "z": -4,
      "name": "Wood_Beech_Branch_Corner",
      "support": 15,
      "rotation": 3
    },
    {
      "x": 10,
      "y": 7,
      "z": -4,
      "name": "*Wood_Softwood_Roof_Shallow_State_Definitions_Corner_Right",
      "filler": 992
    },
    {
      "x": 10,
      "y": 1,
      "z": -3,
      "name": "Rock_Stone_Cobble"
    },
    {
      "x": 10,
      "y": 2,
      "z": -3,
      "name": "Ingredient_Hay"
    },
    {
      "x": 10,
      "y": 7,
      "z": -3,
      "name": "*Wood_Softwood_Roof_Shallow_State_Definitions_Corner_Right"
    },
    {
      "x": 10,
      "y": 1,
      "z": -2,
      "name": "Rock_Stone_Cobble"
    },
    {
      "x": 10,
      "y": 13,
      "z": -2,
      "name": "Wood_Hardwood_Fence"
    },
    {
      "x": 10,
      "y": 14,
      "z": -2,
      "name": "Cloth_Block_Wool_White"
    },
    {
      "x": 10,
      "y": 15,
      "z": -2,
      "name": "Cloth_Block_Wool_White"
    },
    {
      "x": 10,
      "y": 1,
      "z": -1,
      "name": "Rock_Stone_Cobble"
    },
    {
      "x": 11,
      "y": 1,
      "z": -15,
      "name": "Rock_Stone_Cobble"
    },
    {
      "x": 11,
      "y": 1,
      "z": -14,
      "name": "Rock_Stone_Cobble"
    },
    {
      "x": 11,
      "y": 15,
      "z": -14,
      "name": "Cloth_Block_Wool_White"
    },
    {
      "x": 11,
      "y": 16,
      "z": -14,
      "name": "Wood_Hardwood_Fence",
      "rotation": 2
    },
    {
      "x": 11,
      "y": 17,
      "z": -14,
      "name": "Wood_Hardwood_Fence",
      "rotation": 2
    },
    {
      "x": 11,
      "y": 1,
      "z": -13,
      "name": "Rock_Stone_Cobble"
    },
    {
      "x": 11,
      "y": 6,
      "z": -13,
      "name": "Wood_Beech_Branch_Corner",
      "support": 15,
      "rotation": 2
    },
    {
      "x": 11,
      "y": 7,
      "z": -13,
      "name": "*Wood_Softwood_Roof_Shallow_State_Definitions_Corner_Left",
      "filler": 1,
      "rotation": 2
    },
    {
      "x": 11,
      "y": 1,
      "z": -12,
      "name": "Soil_Dirt"
    },
    {
      "x": 11,
      "y": 2,
      "z": -12,
      "name": "Rock_Stone_Brick_Decorative"
    },
    {
      "x": 11,
      "y": 3,
      "z": -12,
      "name": "Rock_Stone_Brick"
    },
    {
      "x": 11,
      "y": 4,
      "z": -12,
      "name": "Rock_Stone_Brick"
    },
    {
      "x": 11,
      "y": 5,
      "z": -12,
      "name": "Rock_Stone_Brick"
    },
    {
      "x": 11,
      "y": 6,
      "z": -12,
      "name": "Wood_Beech_Trunk_Full",
      "support": 15,
      "rotation": 5
    },
    {
      "x": 11,
      "y": 7,
      "z": -12,
      "name": "*Wood_Softwood_Roof_Shallow_State_Definitions_Corner_Left",
      "filler": 33,
      "rotation": 2
    },
    {
      "x": 11,
      "y": 17,
      "z": -12,
      "name": "Wood_Softwood_Roof_Hollow",
      "rotation": 3
    },
    {
      "x": 11,
      "y": 1,
      "z": -11,
      "name": "Soil_Dirt"
    },
    {
      "x": 11,
      "y": 2,
      "z": -11,
      "name": "Rock_Stone_Brick_Decorative"
    },
    {
      "x": 11,
      "y": 3,
      "z": -11,
      "name": "Rock_Stone_Brick"
    },
    {
      "x": 11,
      "y": 4,
      "z": -11,
      "name": "Rock_Stone_Brick"
    },
    {
      "x": 11,
      "y": 5,
      "z": -11,
      "name": "Rock_Stone_Brick"
    },
    {
      "x": 11,
      "y": 6,
      "z": -11,
      "name": "Wood_Beech_Trunk",
      "support": 15,
      "rotation": 4
    },
    {
      "x": 11,
      "y": 7,
      "z": -11,
      "name": "Wood_Softwood_Roof_Shallow",
      "filler": 1,
      "rotation": 3
    },
    {
      "x": 11,
      "y": 17,
      "z": -11,
      "name": "Wood_Softwood_Roof_Hollow",
      "rotation": 3
    },
    {
      "x": 11,
      "y": 1,
      "z": -10,
      "name": "Rock_Stone"
    },
    {
      "x": 11,
      "y": 2,
      "z": -10,
      "name": "Ingredient_Flour"
    },
    {
      "x": 11,
      "y": 6,
      "z": -10,
      "name": "Wood_Softwood_Stairs",
      "rotation": 10
    },
    {
      "x": 11,
      "y": 7,
      "z": -10,
      "name": "Wood_Softwood_Roof",
      "rotation": 2
    },
    {
      "x": 11,
      "y": 11,
      "z": -10,
      "name": "Plant_Vine_Wall",
      "support": 15,
      "rotation": 3
    },
    {
      "x": 11,
      "y": 17,
      "z": -10,
      "name": "Wood_Softwood_Roof_Hollow",
      "rotation": 3
    },
    {
      "x": 11,
      "y": 1,
      "z": -9,
      "name": "Rock_Stone"
    },
    {
      "x": 11,
      "y": 7,
      "z": -9,
      "name": "Wood_Softwood_Planks"
    },
    {
      "x": 11,
      "y": 8,
      "z": -9,
      "name": "Wood_Softwood_Roof",
      "rotation": 2
    },
    {
      "x": 11,
      "y": 17,
      "z": -9,
      "name": "Wood_Softwood_Roof_Hollow",
      "rotation": 3
    },
    {
      "x": 11,
      "y": 1,
      "z": -8,
      "name": "Rock_Stone"
    },
    {
      "x": 11,
      "y": 7,
      "z": -8,
      "name": "Wood_Softwood_Planks"
    },
    {
      "x": 11,
      "y": 8,
      "z": -8,
      "name": "Wood_Softwood_Planks"
    },
    {
      "x": 11,
      "y": 9,
      "z": -8,
      "name": "Wood_Softwood_Roof_Flat"
    },
    {
      "x": 11,
      "y": 17,
      "z": -8,
      "name": "Wood_Softwood_Roof_Hollow",
      "rotation": 3
    },
    {
      "x": 11,
      "y": 1,
      "z": -7,
      "name": "Rock_Stone"
    },
    {
      "x": 11,
      "y": 7,
      "z": -7,
      "name": "Wood_Softwood_Planks"
    },
    {
      "x": 11,
      "y": 8,
      "z": -7,
      "name": "Wood_Softwood_Roof"
    },
    {
      "x": 11,
      "y": 15,
      "z": -7,
      "name": "Plant_Vine_Wall",
      "support": 15,
      "rotation": 3
    },
    {
      "x": 11,
      "y": 17,
      "z": -7,
      "name": "Wood_Softwood_Roof_Hollow",
      "rotation": 3
    },
    {
      "x": 11,
      "y": 1,
      "z": -6,
      "name": "Rock_Stone"
    },
    {
      "x": 11,
      "y": 2,
      "z": -6,
      "name": "Ingredient_Hay"
    },
    {
      "x": 11,
      "y": 3,
      "z": -6,
      "name": "Ingredient_Hay"
    },
    {
      "x": 11,
      "y": 6,
      "z": -6,
      "name": "Wood_Softwood_Stairs",
      "rotation": 8
    },
    {
      "x": 11,
      "y": 7,
      "z": -6,
      "name": "Wood_Softwood_Roof"
    },
    {
      "x": 11,
      "y": 14,
      "z": -6,
      "name": "Plant_Vine_Wall",
      "support": 15,
      "rotation": 3
    },
    {
      "x": 11,
      "y": 17,
      "z": -6,
      "name": "Wood_Softwood_Roof_Hollow",
      "rotation": 3
    },
    {
      "x": 11,
      "y": 1,
      "z": -5,
      "name": "Soil_Dirt"
    },
    {
      "x": 11,
      "y": 2,
      "z": -5,
      "name": "Rock_Stone_Brick_Decorative"
    },
    {
      "x": 11,
      "y": 3,
      "z": -5,
      "name": "Rock_Stone_Brick"
    },
    {
      "x": 11,
      "y": 4,
      "z": -5,
      "name": "Rock_Stone_Brick"
    },
    {
      "x": 11,
      "y": 5,
      "z": -5,
      "name": "Rock_Stone_Brick"
    },
    {
      "x": 11,
      "y": 6,
      "z": -5,
      "name": "Wood_Beech_Trunk",
      "support": 15,
      "rotation": 4
    },
    {
      "x": 11,
      "y": 7,
      "z": -5,
      "name": "Wood_Softwood_Roof_Shallow",
      "filler": 1,
      "rotation": 3
    },
    {
      "x": 11,
      "y": 17,
      "z": -5,
      "name": "Wood_Softwood_Roof_Hollow",
      "rotation": 3
    },
    {
      "x": 11,
      "y": 1,
      "z": -4,
      "name": "Soil_Dirt"
    },
    {
      "x": 11,
      "y": 2,
      "z": -4,
      "name": "Rock_Stone_Brick_Decorative"
    },
    {
      "x": 11,
      "y": 3,
      "z": -4,
      "name": "Rock_Stone_Brick"
    },
    {
      "x": 11,
      "y": 4,
      "z": -4,
      "name": "Rock_Stone_Brick"
    },
    {
      "x": 11,
      "y": 5,
      "z": -4,
      "name": "Rock_Stone_Brick"
    },
    {
      "x": 11,
      "y": 6,
      "z": -4,
      "name": "Wood_Beech_Trunk_Full",
      "support": 15,
      "rotation": 5
    },
    {
      "x": 11,
      "y": 7,
      "z": -4,
      "name": "*Wood_Softwood_Roof_Shallow_State_Definitions_Corner_Right",
      "filler": 993
    },
    {
      "x": 11,
      "y": 17,
      "z": -4,
      "name": "Wood_Softwood_Roof_Hollow",
      "rotation": 3
    },
    {
      "x": 11,
      "y": 1,
      "z": -3,
      "name": "Rock_Stone_Cobble"
    },
    {
      "x": 11,
      "y": 2,
      "z": -3,
      "name": "Ingredient_Hay"
    },
    {
      "x": 11,
      "y": 6,
      "z": -3,
      "name": "Wood_Beech_Branch_Corner",
      "support": 15
    },
    {
      "x": 11,
      "y": 7,
      "z": -3,
      "name": "*Wood_Softwood_Roof_Shallow_State_Definitions_Corner_Right",
      "filler": 1
    },
    {
      "x": 11,
      "y": 1,
      "z": -2,
      "name": "Rock_Stone_Cobble"
    },
    {
      "x": 11,
      "y": 2,
      "z": -2,
      "name": "Ingredient_Hay"
    },
    {
      "x": 11,
      "y": 13,
      "z": -2,
      "name": "Wood_Hardwood_Fence"
    },
    {
      "x": 11,
      "y": 14,
      "z": -2,
      "name": "Wood_Hardwood_Fence"
    },
    {
      "x": 11,
      "y": 15,
      "z": -2,
      "name": "Cloth_Block_Wool_White"
    },
    {
      "x": 11,
      "y": 1,
      "z": -1,
      "name": "Rock_Stone_Cobble"
    },
    {
      "x": 12,
      "y": 1,
      "z": -15,
      "name": "Rock_Stone_Cobble"
    },
    {
      "x": 12,
      "y": 1,
      "z": -14,
      "name": "Rock_Stone_Cobble"
    },
    {
      "x": 12,
      "y": 6,
      "z": -14,
      "name": "*Wood_Softwood_Roof_Hollow_State_Definitions_Corner_Right",
      "rotation": 3
    },
    {
      "x": 12,
      "y": 14,
      "z": -14,
      "name": "Cloth_Block_Wool_White"
    },
    {
      "x": 12,
      "y": 15,
      "z": -14,
      "name": "Cloth_Block_Wool_White"
    },
    {
      "x": 12,
      "y": 16,
      "z": -14,
      "name": "Wood_Hardwood_Fence",
      "rotation": 2
    },
    {
      "x": 12,
      "y": 1,
      "z": -13,
      "name": "Rock_Stone_Cobble"
    },
    {
      "x": 12,
      "y": 6,
      "z": -13,
      "name": "Wood_Softwood_Roof_Hollow",
      "rotation": 3
    },
    {
      "x": 12,
      "y": 7,
      "z": -13,
      "name": "Wood_Softwood_Roof_Shallow",
      "rotation": 2
    },
    {
      "x": 12,
      "y": 1,
      "z": -12,
      "name": "Soil_Dirt"
    },
    {
      "x": 12,
      "y": 2,
      "z": -12,
      "name": "Rock_Stone_Brick_Decorative"
    },
    {
      "x": 12,
      "y": 3,
      "z": -12,
      "name": "Rock_Stone_Brick"
    },
    {
      "x": 12,
      "y": 4,
      "z": -12,
      "name": "Rock_Stone_Brick"
    },
    {
      "x": 12,
      "y": 5,
      "z": -12,
      "name": "Rock_Stone_Brick"
    },
    {
      "x": 12,
      "y": 6,
      "z": -12,
      "name": "Wood_Beech_Trunk",
      "support": 15,
      "rotation": 5
    },
    {
      "x": 12,
      "y": 7,
      "z": -12,
      "name": "Wood_Softwood_Roof_Shallow",
      "filler": 32,
      "rotation": 2
    },
    {
      "x": 12,
      "y": 17,
      "z": -12,
      "name": "Wood_Softwood_Planks_Half",
      "rotation": 8
    },
    {
      "x": 12,
      "y": 18,
      "z": -12,
      "name": "Wood_Softwood_Roof",
      "rotation": 3
    },
    {
      "x": 12,
      "y": 1,
      "z": -11,
      "name": "Rock_Stone"
    },
    {
      "x": 12,
      "y": 6,
      "z": -11,
      "name": "Wood_Softwood_Planks_Half",
      "rotation": 8
    },
    {
      "x": 12,
      "y": 7,
      "z": -11,
      "name": "Wood_Beech_Trunk",
      "support": 15
    },
    {
      "x": 12,
      "y": 8,
      "z": -11,
      "name": "Wood_Softwood_Roof_Flat",
      "rotation": 3
    },
    {
      "x": 12,
      "y": 12,
      "z": -11,
      "name": "Plant_Vine_Wall",
      "support": 15,
      "rotation": 3
    },
    {
      "x": 12,
      "y": 17,
      "z": -11,
      "name": "Wood_Softwood_Planks_Half",
      "rotation": 8
    },
    {
      "x": 12,
      "y": 18,
      "z": -11,
      "name": "Wood_Softwood_Roof",
      "rotation": 3
    },
    {
      "x": 12,
      "y": 1,
      "z": -10,
      "name": "Rock_Stone"
    },
    {
      "x": 12,
      "y": 7,
      "z": -10,
      "name": "Rock_Stone_Brick"
    },
    {
      "x": 12,
      "y": 8,
      "z": -10,
      "name": "Wood_Beech_Trunk",
      "support": 15
    },
    {
      "x": 12,
      "y": 9,
      "z": -10,
      "name": "Wood_Beech_Trunk",
      "support": 15
    },
    {
      "x": 12,
      "y": 10,
      "z": -10,
      "name": "Wood_Beech_Trunk",
      "support": 15
    },
    {
      "x": 12,
      "y": 11,
      "z": -10,
      "name": "Wood_Beech_Trunk",
      "support": 15
    },
    {
      "x": 12,
      "y": 12,
      "z": -10,
      "name": "Wood_Beech_Trunk",
      "support": 15
    },
    {
      "x": 12,
      "y": 13,
      "z": -10,
      "name": "Wood_Beech_Trunk",
      "support": 15
    },
    {
      "x": 12,
      "y": 14,
      "z": -10,
      "name": "Wood_Beech_Trunk",
      "support": 15
    },
    {
      "x": 12,
      "y": 15,
      "z": -10,
      "name": "Wood_Beech_Trunk",
      "support": 15
    },
    {
      "x": 12,
      "y": 16,
      "z": -10,
      "name": "Wood_Beech_Trunk",
      "support": 15
    },
    {
      "x": 12,
      "y": 17,
      "z": -10,
      "name": "Wood_Beech_Trunk",
      "support": 15
    },
    {
      "x": 12,
      "y": 18,
      "z": -10,
      "name": "Wood_Softwood_Roof",
      "rotation": 3
    },
    {
      "x": 12,
      "y": 1,
      "z": -9,
      "name": "Rock_Stone"
    },
    {
      "x": 12,
      "y": 7,
      "z": -9,
      "name": "Rock_Stone_Brick"
    },
    {
      "x": 12,
      "y": 8,
      "z": -9,
      "name": "Wood_Beech_Trunk",
      "support": 15,
      "rotation": 4
    },
    {
      "x": 12,
      "y": 9,
      "z": -9,
      "name": "*Wood_Village_Wall_Full_State_Definitions_Bottom"
    },
    {
      "x": 12,
      "y": 10,
      "z": -9,
      "name": "*Wood_Village_Wall_Full_State_Definitions_Top"
    },
    {
      "x": 12,
      "y": 11,
      "z": -9,
      "name": "Wood_Beech_Trunk",
      "support": 15,
      "rotation": 4
    },
    {
      "x": 12,
      "y": 12,
      "z": -9,
      "name": "*Wood_Village_Wall_Full_State_Definitions_Bottom"
    },
    {
      "x": 12,
      "y": 13,
      "z": -9,
      "name": "*Wood_Village_Wall_Full_State_Definitions_Middle"
    },
    {
      "x": 12,
      "y": 14,
      "z": -9,
      "name": "*Wood_Village_Wall_Full_State_Definitions_Top"
    },
    {
      "x": 12,
      "y": 15,
      "z": -9,
      "name": "Wood_Beech_Trunk",
      "support": 15,
      "rotation": 4
    },
    {
      "x": 12,
      "y": 16,
      "z": -9,
      "name": "*Wood_Village_Wall_Full_State_Definitions_Bottom"
    },
    {
      "x": 12,
      "y": 17,
      "z": -9,
      "name": "*Wood_Village_Wall_Full_State_Definitions_Top"
    },
    {
      "x": 12,
      "y": 18,
      "z": -9,
      "name": "Wood_Softwood_Roof",
      "rotation": 3
    },
    {
      "x": 12,
      "y": 1,
      "z": -8,
      "name": "Rock_Stone"
    },
    {
      "x": 12,
      "y": 6,
      "z": -8,
      "name": "Deco_Lantern_Ceiling"
    },
    {
      "x": 12,
      "y": 7,
      "z": -8,
      "name": "Rock_Stone_Brick"
    },
    {
      "x": 12,
      "y": 8,
      "z": -8,
      "name": "Wood_Beech_Trunk",
      "support": 15,
      "rotation": 4
    },
    {
      "x": 12,
      "y": 9,
      "z": -8,
      "name": "*Wood_Village_Wall_Full_State_Definitions_Bottom"
    },
    {
      "x": 12,
      "y": 10,
      "z": -8,
      "name": "*Wood_Village_Wall_Full_State_Definitions_Top"
    },
    {
      "x": 12,
      "y": 11,
      "z": -8,
      "name": "Wood_Beech_Trunk",
      "support": 15,
      "rotation": 4
    },
    {
      "x": 12,
      "y": 12,
      "z": -8,
      "name": "Furniture_Village_Window",
      "rotation": 1
    },
    {
      "x": 12,
      "y": 13,
      "z": -8,
      "name": "Furniture_Village_Window",
      "rotation": 1
    },
    {
      "x": 12,
      "y": 14,
      "z": -8,
      "name": "Wood_Village_Wall_Full"
    },
    {
      "x": 12,
      "y": 15,
      "z": -8,
      "name": "Wood_Beech_Trunk",
      "support": 15,
      "rotation": 4
    },
    {
      "x": 12,
      "y": 16,
      "z": -8,
      "name": "*Wood_Village_Wall_Full_State_Definitions_Bottom"
    },
    {
      "x": 12,
      "y": 17,
      "z": -8,
      "name": "*Wood_Village_Wall_Full_State_Definitions_Top"
    },
    {
      "x": 12,
      "y": 18,
      "z": -8,
      "name": "Wood_Softwood_Roof",
      "rotation": 3
    },
    {
      "x": 12,
      "y": 1,
      "z": -7,
      "name": "Rock_Stone"
    },
    {
      "x": 12,
      "y": 7,
      "z": -7,
      "name": "Rock_Stone_Brick"
    },
    {
      "x": 12,
      "y": 8,
      "z": -7,
      "name": "Wood_Beech_Trunk",
      "support": 15,
      "rotation": 4
    },
    {
      "x": 12,
      "y": 9,
      "z": -7,
      "name": "*Wood_Village_Wall_Full_State_Definitions_Bottom"
    },
    {
      "x": 12,
      "y": 10,
      "z": -7,
      "name": "*Wood_Village_Wall_Full_State_Definitions_Top"
    },
    {
      "x": 12,
      "y": 11,
      "z": -7,
      "name": "Wood_Beech_Trunk",
      "support": 15,
      "rotation": 4
    },
    {
      "x": 12,
      "y": 12,
      "z": -7,
      "name": "*Wood_Village_Wall_Full_State_Definitions_Bottom"
    },
    {
      "x": 12,
      "y": 13,
      "z": -7,
      "name": "*Wood_Village_Wall_Full_State_Definitions_Middle"
    },
    {
      "x": 12,
      "y": 14,
      "z": -7,
      "name": "*Wood_Village_Wall_Full_State_Definitions_Top"
    },
    {
      "x": 12,
      "y": 15,
      "z": -7,
      "name": "Wood_Beech_Trunk",
      "support": 15,
      "rotation": 4
    },
    {
      "x": 12,
      "y": 16,
      "z": -7,
      "name": "*Wood_Village_Wall_Full_State_Definitions_Bottom"
    },
    {
      "x": 12,
      "y": 17,
      "z": -7,
      "name": "*Wood_Village_Wall_Full_State_Definitions_Top"
    },
    {
      "x": 12,
      "y": 18,
      "z": -7,
      "name": "Wood_Softwood_Roof",
      "rotation": 3
    },
    {
      "x": 12,
      "y": 1,
      "z": -6,
      "name": "Rock_Stone"
    },
    {
      "x": 12,
      "y": 7,
      "z": -6,
      "name": "Rock_Stone_Brick"
    },
    {
      "x": 12,
      "y": 8,
      "z": -6,
      "name": "Wood_Beech_Trunk",
      "support": 15
    },
    {
      "x": 12,
      "y": 9,
      "z": -6,
      "name": "Wood_Beech_Trunk",
      "support": 15
    },
    {
      "x": 12,
      "y": 10,
      "z": -6,
      "name": "Wood_Beech_Trunk",
      "support": 15
    },
    {
      "x": 12,
      "y": 11,
      "z": -6,
      "name": "Wood_Beech_Trunk",
      "support": 15
    },
    {
      "x": 12,
      "y": 12,
      "z": -6,
      "name": "Wood_Beech_Trunk",
      "support": 15
    },
    {
      "x": 12,
      "y": 13,
      "z": -6,
      "name": "Wood_Beech_Trunk",
      "support": 15
    },
    {
      "x": 12,
      "y": 14,
      "z": -6,
      "name": "Wood_Beech_Trunk",
      "support": 15
    },
    {
      "x": 12,
      "y": 15,
      "z": -6,
      "name": "Wood_Beech_Trunk",
      "support": 15
    },
    {
      "x": 12,
      "y": 16,
      "z": -6,
      "name": "Wood_Beech_Trunk",
      "support": 15
    },
    {
      "x": 12,
      "y": 17,
      "z": -6,
      "name": "Wood_Beech_Trunk",
      "support": 15
    },
    {
      "x": 12,
      "y": 18,
      "z": -6,
      "name": "Wood_Softwood_Roof",
      "rotation": 3
    },
    {
      "x": 12,
      "y": 1,
      "z": -5,
      "name": "Rock_Stone"
    },
    {
      "x": 12,
      "y": 2,
      "z": -5,
      "name": "Ingredient_Hay"
    },
    {
      "x": 12,
      "y": 6,
      "z": -5,
      "name": "Wood_Softwood_Planks_Half",
      "rotation": 8
    },
    {
      "x": 12,
      "y": 7,
      "z": -5,
      "name": "Wood_Beech_Trunk",
      "support": 15
    },
    {
      "x": 12,
      "y": 8,
      "z": -5,
      "name": "Wood_Softwood_Roof_Flat",
      "rotation": 3
    },
    {
      "x": 12,
      "y": 17,
      "z": -5,
      "name": "Wood_Softwood_Planks_Half",
      "rotation": 8
    },
    {
      "x": 12,
      "y": 18,
      "z": -5,
      "name": "Wood_Softwood_Roof",
      "rotation": 3
    },
    {
      "x": 12,
      "y": 1,
      "z": -4,
      "name": "Soil_Dirt"
    },
    {
      "x": 12,
      "y": 2,
      "z": -4,
      "name": "Rock_Stone_Brick_Decorative"
    },
    {
      "x": 12,
      "y": 3,
      "z": -4,
      "name": "Rock_Stone_Brick"
    },
    {
      "x": 12,
      "y": 4,
      "z": -4,
      "name": "Rock_Stone_Brick"
    },
    {
      "x": 12,
      "y": 5,
      "z": -4,
      "name": "Rock_Stone_Brick"
    },
    {
      "x": 12,
      "y": 6,
      "z": -4,
      "name": "Wood_Beech_Trunk",
      "support": 15,
      "rotation": 5
    },
    {
      "x": 12,
      "y": 7,
      "z": -4,
      "name": "Wood_Softwood_Roof_Shallow",
      "filler": 992
    },
    {
      "x": 12,
      "y": 17,
      "z": -4,
      "name": "Wood_Softwood_Planks_Half",
      "rotation": 8
    },
    {
      "x": 12,
      "y": 18,
      "z": -4,
      "name": "Wood_Softwood_Roof",
      "rotation": 3
    },
    {
      "x": 12,
      "y": 1,
      "z": -3,
      "name": "Rock_Stone_Cobble"
    },
    {
      "x": 12,
      "y": 2,
      "z": -3,
      "name": "Ingredient_Hay"
    },
    {
      "x": 12,
      "y": 3,
      "z": -3,
      "name": "Ingredient_Hay"
    },
    {
      "x": 12,
      "y": 6,
      "z": -3,
      "name": "Wood_Softwood_Roof_Hollow",
      "rotation": 3
    },
    {
      "x": 12,
      "y": 7,
      "z": -3,
      "name": "Wood_Softwood_Roof_Shallow"
    },
    {
      "x": 12,
      "y": 1,
      "z": -2,
      "name": "Rock_Stone_Cobble"
    },
    {
      "x": 12,
      "y": 2,
      "z": -2,
      "name": "Ingredient_Hay"
    },
    {
      "x": 12,
      "y": 6,
      "z": -2,
      "name": "*Wood_Softwood_Roof_Hollow_State_Definitions_Corner_Left",
      "rotation": 3
    },
    {
      "x": 12,
      "y": 14,
      "z": -2,
      "name": "Wood_Hardwood_Fence"
    },
    {
      "x": 12,
      "y": 15,
      "z": -2,
      "name": "Cloth_Block_Wool_White"
    },
    {
      "x": 12,
      "y": 16,
      "z": -2,
      "name": "Cloth_Block_Wool_White"
    },
    {
      "x": 12,
      "y": 1,
      "z": -1,
      "name": "Rock_Stone_Cobble"
    },
    {
      "x": 13,
      "y": 1,
      "z": -15,
      "name": "Rock_Stone_Cobble"
    },
    {
      "x": 13,
      "y": 1,
      "z": -14,
      "name": "Rock_Stone_Cobble"
    },
    {
      "x": 13,
      "y": 5,
      "z": -14,
      "name": "Wood_Beech_Branch_Corner",
      "support": 15,
      "rotation": 2
    },
    {
      "x": 13,
      "y": 6,
      "z": -14,
      "name": "Wood_Softwood_Roof",
      "rotation": 2
    },
    {
      "x": 13,
      "y": 9,
      "z": -14,
      "name": "Wood_Hardwood_Fence",
      "rotation": 2
    },
    {
      "x": 13,
      "y": 10,
      "z": -14,
      "name": "Wood_Hardwood_Fence",
      "rotation": 2
    },
    {
      "x": 13,
      "y": 11,
      "z": -14,
      "name": "Wood_Hardwood_Fence",
      "rotation": 2
    },
    {
      "x": 13,
      "y": 14,
      "z": -14,
      "name": "Cloth_Block_Wool_White"
    },
    {
      "x": 13,
      "y": 15,
      "z": -14,
      "name": "Wood_Hardwood_Fence",
      "rotation": 2
    },
    {
      "x": 13,
      "y": 16,
      "z": -14,
      "name": "Wood_Hardwood_Fence",
      "rotation": 2
    },
    {
      "x": 13,
      "y": 1,
      "z": -13,
      "name": "Soil_Dirt"
    },
    {
      "x": 13,
      "y": 2,
      "z": -13,
      "name": "Wood_Beech_Trunk",
      "support": 15
    },
    {
      "x": 13,
      "y": 3,
      "z": -13,
      "name": "Wood_Beech_Trunk",
      "support": 15
    },
    {
      "x": 13,
      "y": 4,
      "z": -13,
      "name": "Wood_Beech_Trunk",
      "support": 15
    },
    {
      "x": 13,
      "y": 5,
      "z": -13,
      "name": "Wood_Beech_Trunk",
      "support": 15
    },
    {
      "x": 13,
      "y": 6,
      "z": -13,
      "name": "Wood_Beech_Trunk",
      "support": 15
    },
    {
      "x": 13,
      "y": 7,
      "z": -13,
      "name": "Wood_Softwood_Roof_Shallow",
      "rotation": 2
    },
    {
      "x": 13,
      "y": 1,
      "z": -12,
      "name": "Rock_Stone"
    },
    {
      "x": 13,
      "y": 2,
      "z": -12,
      "name": "Ingredient_Hay"
    },
    {
      "x": 13,
      "y": 3,
      "z": -12,
      "name": "Ingredient_Hay"
    },
    {
      "x": 13,
      "y": 6,
      "z": -12,
      "name": "Wood_Softwood_Stairs",
      "rotation": 11
    },
    {
      "x": 13,
      "y": 7,
      "z": -12,
      "name": "Wood_Softwood_Roof_Shallow",
      "filler": 32,
      "rotation": 2
    },
    {
      "x": 13,
      "y": 18,
      "z": -12,
      "name": "Wood_Softwood_Planks_Half",
      "rotation": 8
    },
    {
      "x": 13,
      "y": 19,
      "z": -12,
      "name": "Wood_Softwood_Roof_Shallow",
      "rotation": 3
    },
    {
      "x": 13,
      "y": 1,
      "z": -11,
      "name": "Rock_Stone"
    },
    {
      "x": 13,
      "y": 7,
      "z": -11,
      "name": "Rock_Stone_Brick"
    },
    {
      "x": 13,
      "y": 8,
      "z": -11,
      "name": "Wood_Beech_Trunk",
      "support": 15
    },
    {
      "x": 13,
      "y": 9,
      "z": -11,
      "name": "Wood_Beech_Trunk",
      "support": 15
    },
    {
      "x": 13,
      "y": 10,
      "z": -11,
      "name": "Wood_Beech_Trunk",
      "support": 15
    },
    {
      "x": 13,
      "y": 11,
      "z": -11,
      "name": "Wood_Beech_Trunk",
      "support": 15
    },
    {
      "x": 13,
      "y": 12,
      "z": -11,
      "name": "Wood_Beech_Trunk",
      "support": 15
    },
    {
      "x": 13,
      "y": 13,
      "z": -11,
      "name": "Wood_Beech_Trunk",
      "support": 15
    },
    {
      "x": 13,
      "y": 14,
      "z": -11,
      "name": "Wood_Beech_Trunk",
      "support": 15
    },
    {
      "x": 13,
      "y": 15,
      "z": -11,
      "name": "Wood_Beech_Trunk",
      "support": 15
    },
    {
      "x": 13,
      "y": 16,
      "z": -11,
      "name": "Wood_Beech_Trunk",
      "support": 15
    },
    {
      "x": 13,
      "y": 17,
      "z": -11,
      "name": "Wood_Beech_Trunk",
      "support": 15
    },
    {
      "x": 13,
      "y": 18,
      "z": -11,
      "name": "Wood_Beech_Trunk",
      "support": 15
    },
    {
      "x": 13,
      "y": 19,
      "z": -11,
      "name": "Wood_Softwood_Roof_Shallow",
      "rotation": 3
    },
    {
      "x": 13,
      "y": 1,
      "z": -10,
      "name": "Rock_Stone"
    },
    {
      "x": 13,
      "y": 19,
      "z": -10,
      "name": "Wood_Softwood_Roof_Shallow",
      "rotation": 3
    },
    {
      "x": 13,
      "y": 1,
      "z": -9,
      "name": "Rock_Stone"
    },
    {
      "x": 13,
      "y": 2,
      "z": -9,
      "name": "Wood_Softwood_Stairs",
      "rotation": 8
    },
    {
      "x": 13,
      "y": 19,
      "z": -9,
      "name": "Wood_Softwood_Roof_Shallow",
      "rotation": 3
    },
    {
      "x": 13,
      "y": 1,
      "z": -8,
      "name": "Soil_Dirt"
    },
    {
      "x": 13,
      "y": 2,
      "z": -8,
      "name": "Wood_Beech_Trunk",
      "support": 15,
      "rotation": 5
    },
    {
      "x": 13,
      "y": 19,
      "z": -8,
      "name": "Wood_Softwood_Roof_Shallow",
      "rotation": 3
    },
    {
      "x": 13,
      "y": 1,
      "z": -7,
      "name": "Rock_Stone"
    },
    {
      "x": 13,
      "y": 2,
      "z": -7,
      "name": "Wood_Softwood_Stairs",
      "rotation": 10
    },
    {
      "x": 13,
      "y": 19,
      "z": -7,
      "name": "Wood_Softwood_Roof_Shallow",
      "rotation": 3
    },
    {
      "x": 13,
      "y": 1,
      "z": -6,
      "name": "Rock_Stone"
    },
    {
      "x": 13,
      "y": 19,
      "z": -6,
      "name": "Wood_Softwood_Roof_Shallow",
      "rotation": 3
    },
    {
      "x": 13,
      "y": 1,
      "z": -5,
      "name": "Rock_Stone"
    },
    {
      "x": 13,
      "y": 7,
      "z": -5,
      "name": "Rock_Stone_Brick"
    },
    {
      "x": 13,
      "y": 8,
      "z": -5,
      "name": "Wood_Beech_Trunk",
      "support": 15
    },
    {
      "x": 13,
      "y": 9,
      "z": -5,
      "name": "Wood_Beech_Trunk",
      "support": 15
    },
    {
      "x": 13,
      "y": 10,
      "z": -5,
      "name": "Wood_Beech_Trunk",
      "support": 15
    },
    {
      "x": 13,
      "y": 11,
      "z": -5,
      "name": "Wood_Beech_Trunk",
      "support": 15
    },
    {
      "x": 13,
      "y": 12,
      "z": -5,
      "name": "Wood_Beech_Trunk",
      "support": 15
    },
    {
      "x": 13,
      "y": 13,
      "z": -5,
      "name": "Wood_Beech_Trunk",
      "support": 15
    },
    {
      "x": 13,
      "y": 14,
      "z": -5,
      "name": "Wood_Beech_Trunk",
      "support": 15
    },
    {
      "x": 13,
      "y": 15,
      "z": -5,
      "name": "Wood_Beech_Trunk",
      "support": 15
    },
    {
      "x": 13,
      "y": 16,
      "z": -5,
      "name": "Wood_Beech_Trunk",
      "support": 15
    },
    {
      "x": 13,
      "y": 17,
      "z": -5,
      "name": "Wood_Beech_Trunk",
      "support": 15
    },
    {
      "x": 13,
      "y": 18,
      "z": -5,
      "name": "Wood_Beech_Trunk",
      "support": 15
    },
    {
      "x": 13,
      "y": 19,
      "z": -5,
      "name": "Wood_Softwood_Roof_Shallow",
      "rotation": 3
    },
    {
      "x": 13,
      "y": 1,
      "z": -4,
      "name": "Rock_Stone"
    },
    {
      "x": 13,
      "y": 2,
      "z": -4,
      "name": "Ingredient_Flour"
    },
    {
      "x": 13,
      "y": 6,
      "z": -4,
      "name": "Wood_Softwood_Stairs",
      "rotation": 11
    },
    {
      "x": 13,
      "y": 7,
      "z": -4,
      "name": "Wood_Softwood_Roof_Shallow",
      "filler": 992
    },
    {
      "x": 13,
      "y": 11,
      "z": -4,
      "name": "Plant_Vine_Wall",
      "support": 15
    },
    {
      "x": 13,
      "y": 12,
      "z": -4,
      "name": "Plant_Vine_Wall",
      "support": 15
    },
    {
      "x": 13,
      "y": 18,
      "z": -4,
      "name": "Wood_Softwood_Planks_Half",
      "rotation": 8
    },
    {
      "x": 13,
      "y": 19,
      "z": -4,
      "name": "Wood_Softwood_Roof_Shallow",
      "rotation": 3
    },
    {
      "x": 13,
      "y": 1,
      "z": -3,
      "name": "Soil_Dirt"
    },
    {
      "x": 13,
      "y": 2,
      "z": -3,
      "name": "Wood_Beech_Trunk",
      "support": 15
    },
    {
      "x": 13,
      "y": 3,
      "z": -3,
      "name": "Wood_Beech_Trunk",
      "support": 15
    },
    {
      "x": 13,
      "y": 4,
      "z": -3,
      "name": "Wood_Beech_Trunk",
      "support": 15
    },
    {
      "x": 13,
      "y": 5,
      "z": -3,
      "name": "Wood_Beech_Trunk",
      "support": 15
    },
    {
      "x": 13,
      "y": 6,
      "z": -3,
      "name": "Wood_Beech_Trunk",
      "support": 15
    },
    {
      "x": 13,
      "y": 7,
      "z": -3,
      "name": "Wood_Softwood_Roof_Shallow"
    },
    {
      "x": 13,
      "y": 1,
      "z": -2,
      "name": "Rock_Stone_Cobble"
    },
    {
      "x": 13,
      "y": 2,
      "z": -2,
      "name": "Ingredient_Hay"
    },
    {
      "x": 13,
      "y": 5,
      "z": -2,
      "name": "Wood_Beech_Branch_Corner",
      "support": 15
    },
    {
      "x": 13,
      "y": 6,
      "z": -2,
      "name": "Wood_Softwood_Roof"
    },
    {
      "x": 13,
      "y": 14,
      "z": -2,
      "name": "Wood_Hardwood_Fence"
    },
    {
      "x": 13,
      "y": 15,
      "z": -2,
      "name": "Wood_Hardwood_Fence"
    },
    {
      "x": 13,
      "y": 16,
      "z": -2,
      "name": "Cloth_Block_Wool_White"
    },
    {
      "x": 13,
      "y": 19,
      "z": -2,
      "name": "Wood_Hardwood_Fence"
    },
    {
      "x": 13,
      "y": 20,
      "z": -2,
      "name": "Wood_Hardwood_Fence"
    },
    {
      "x": 13,
      "y": 21,
      "z": -2,
      "name": "Wood_Hardwood_Fence"
    },
    {
      "x": 13,
      "y": 1,
      "z": -1,
      "name": "Rock_Stone_Cobble"
    },
    {
      "x": 14,
      "y": 1,
      "z": -15,
      "name": "Rock_Stone_Cobble"
    },
    {
      "x": 14,
      "y": 1,
      "z": -14,
      "name": "Rock_Stone_Cobble"
    },
    {
      "x": 14,
      "y": 6,
      "z": -14,
      "name": "Wood_Softwood_Roof_Hollow",
      "rotation": 2
    },
    {
      "x": 14,
      "y": 9,
      "z": -14,
      "name": "Cloth_Block_Wool_White"
    },
    {
      "x": 14,
      "y": 10,
      "z": -14,
      "name": "Cloth_Block_Wool_White"
    },
    {
      "x": 14,
      "y": 11,
      "z": -14,
      "name": "Wood_Hardwood_Fence",
      "rotation": 2
    },
    {
      "x": 14,
      "y": 12,
      "z": -14,
      "name": "Wood_Hardwood_Fence",
      "rotation": 2
    },
    {
      "x": 14,
      "y": 13,
      "z": -14,
      "name": "Wood_Hardwood_Fence",
      "rotation": 2
    },
    {
      "x": 14,
      "y": 14,
      "z": -14,
      "name": "Cloth_Block_Wool_White"
    },
    {
      "x": 14,
      "y": 15,
      "z": -14,
      "name": "Wood_Hardwood_Fence",
      "rotation": 2
    },
    {
      "x": 14,
      "y": 16,
      "z": -14,
      "name": "Cloth_Block_Wool_White"
    },
    {
      "x": 14,
      "y": 17,
      "z": -14,
      "name": "Cloth_Block_Wool_White"
    },
    {
      "x": 14,
      "y": 18,
      "z": -14,
      "name": "Cloth_Block_Wool_White"
    },
    {
      "x": 14,
      "y": 1,
      "z": -13,
      "name": "Soil_Dirt"
    },
    {
      "x": 14,
      "y": 2,
      "z": -13,
      "name": "Rock_Stone_Brick_Decorative"
    },
    {
      "x": 14,
      "y": 3,
      "z": -13,
      "name": "Rock_Stone_Brick"
    },
    {
      "x": 14,
      "y": 4,
      "z": -13,
      "name": "Rock_Stone_Brick"
    },
    {
      "x": 14,
      "y": 5,
      "z": -13,
      "name": "Rock_Stone_Brick"
    },
    {
      "x": 14,
      "y": 6,
      "z": -13,
      "name": "Wood_Beech_Trunk",
      "support": 15,
      "rotation": 5
    },
    {
      "x": 14,
      "y": 7,
      "z": -13,
      "name": "Wood_Softwood_Roof_Shallow",
      "rotation": 2
    },
    {
      "x": 14,
      "y": 1,
      "z": -12,
      "name": "Rock_Stone"
    },
    {
      "x": 14,
      "y": 2,
      "z": -12,
      "name": "Ingredient_Hay"
    },
    {
      "x": 14,
      "y": 7,
      "z": -12,
      "name": "Wood_Softwood_Roof_Shallow",
      "filler": 32,
      "rotation": 2
    },
    {
      "x": 14,
      "y": 19,
      "z": -12,
      "name": "Wood_Softwood_Roof_Shallow",
      "filler": 1,
      "rotation": 3
    },
    {
      "x": 14,
      "y": 1,
      "z": -11,
      "name": "Rock_Stone"
    },
    {
      "x": 14,
      "y": 7,
      "z": -11,
      "name": "Rock_Stone_Brick"
    },
    {
      "x": 14,
      "y": 8,
      "z": -11,
      "name": "Wood_Beech_Trunk",
      "support": 15,
      "rotation": 5
    },
    {
      "x": 14,
      "y": 9,
      "z": -11,
      "name": "*Wood_Village_Wall_Full_State_Definitions_Bottom"
    },
    {
      "x": 14,
      "y": 10,
      "z": -11,
      "name": "*Wood_Village_Wall_Full_State_Definitions_Top"
    },
    {
      "x": 14,
      "y": 11,
      "z": -11,
      "name": "Wood_Beech_Trunk",
      "support": 15,
      "rotation": 5
    },
    {
      "x": 14,
      "y": 12,
      "z": -11,
      "name": "*Wood_Village_Wall_Full_State_Definitions_Bottom"
    },
    {
      "x": 14,
      "y": 13,
      "z": -11,
      "name": "*Wood_Village_Wall_Full_State_Definitions_Middle"
    },
    {
      "x": 14,
      "y": 14,
      "z": -11,
      "name": "*Wood_Village_Wall_Full_State_Definitions_Top"
    },
    {
      "x": 14,
      "y": 15,
      "z": -11,
      "name": "Wood_Beech_Trunk",
      "support": 15,
      "rotation": 5
    },
    {
      "x": 14,
      "y": 16,
      "z": -11,
      "name": "*Wood_Village_Wall_Full_State_Definitions_Bottom"
    },
    {
      "x": 14,
      "y": 17,
      "z": -11,
      "name": "*Wood_Village_Wall_Full_State_Definitions_Top"
    },
    {
      "x": 14,
      "y": 18,
      "z": -11,
      "name": "Wood_Beech_Trunk",
      "support": 15,
      "rotation": 5
    },
    {
      "x": 14,
      "y": 19,
      "z": -11,
      "name": "Wood_Softwood_Roof_Shallow",
      "filler": 1,
      "rotation": 3
    },
    {
      "x": 14,
      "y": 1,
      "z": -10,
      "name": "Rock_Stone"
    },
    {
      "x": 14,
      "y": 2,
      "z": -10,
      "name": "Wood_Softwood_Stairs",
      "rotation": 9
    },
    {
      "x": 14,
      "y": 19,
      "z": -10,
      "name": "Wood_Softwood_Roof_Shallow",
      "filler": 1,
      "rotation": 3
    },
    {
      "x": 14,
      "y": 1,
      "z": -9,
      "name": "Soil_Dirt"
    },
    {
      "x": 14,
      "y": 2,
      "z": -9,
      "name": "Wood_Softwood_Planks"
    },
    {
      "x": 14,
      "y": 15,
      "z": -9,
      "name": "Rock_Stone_Brick_Smooth_Half",
      "rotation": 7
    },
    {
      "x": 14,
      "y": 19,
      "z": -9,
      "name": "Wood_Softwood_Roof_Shallow",
      "filler": 1,
      "rotation": 3
    },
    {
      "x": 14,
      "y": 1,
      "z": -8,
      "name": "Soil_Dirt"
    },
    {
      "x": 14,
      "y": 2,
      "z": -8,
      "name": "Ingredient_Hay"
    },
    {
      "x": 14,
      "y": 19,
      "z": -8,
      "name": "Wood_Softwood_Roof_Shallow",
      "filler": 1,
      "rotation": 3
    },
    {
      "x": 14,
      "y": 1,
      "z": -7,
      "name": "Soil_Dirt"
    },
    {
      "x": 14,
      "y": 2,
      "z": -7,
      "name": "Wood_Softwood_Planks"
    },
    {
      "x": 14,
      "y": 15,
      "z": -7,
      "name": "Rock_Stone_Brick_Smooth_Half",
      "rotation": 7
    },
    {
      "x": 14,
      "y": 19,
      "z": -7,
      "name": "Wood_Softwood_Roof_Shallow",
      "filler": 1,
      "rotation": 3
    },
    {
      "x": 14,
      "y": 1,
      "z": -6,
      "name": "Rock_Stone"
    },
    {
      "x": 14,
      "y": 2,
      "z": -6,
      "name": "Wood_Softwood_Stairs",
      "rotation": 9
    },
    {
      "x": 14,
      "y": 19,
      "z": -6,
      "name": "Wood_Softwood_Roof_Shallow",
      "filler": 1,
      "rotation": 3
    },
    {
      "x": 14,
      "y": 1,
      "z": -5,
      "name": "Rock_Stone"
    },
    {
      "x": 14,
      "y": 7,
      "z": -5,
      "name": "Rock_Stone_Brick"
    },
    {
      "x": 14,
      "y": 8,
      "z": -5,
      "name": "Wood_Beech_Trunk",
      "support": 15,
      "rotation": 5
    },
    {
      "x": 14,
      "y": 9,
      "z": -5,
      "name": "*Wood_Village_Wall_Full_State_Definitions_Bottom"
    },
    {
      "x": 14,
      "y": 10,
      "z": -5,
      "name": "*Wood_Village_Wall_Full_State_Definitions_Top"
    },
    {
      "x": 14,
      "y": 11,
      "z": -5,
      "name": "Wood_Beech_Trunk",
      "support": 15,
      "rotation": 5
    },
    {
      "x": 14,
      "y": 12,
      "z": -5,
      "name": "*Wood_Village_Wall_Full_State_Definitions_Bottom"
    },
    {
      "x": 14,
      "y": 13,
      "z": -5,
      "name": "*Wood_Village_Wall_Full_State_Definitions_Middle"
    },
    {
      "x": 14,
      "y": 14,
      "z": -5,
      "name": "*Wood_Village_Wall_Full_State_Definitions_Top"
    },
    {
      "x": 14,
      "y": 15,
      "z": -5,
      "name": "Wood_Beech_Trunk",
      "support": 15,
      "rotation": 5
    },
    {
      "x": 14,
      "y": 16,
      "z": -5,
      "name": "*Wood_Village_Wall_Full_State_Definitions_Bottom"
    },
    {
      "x": 14,
      "y": 17,
      "z": -5,
      "name": "*Wood_Village_Wall_Full_State_Definitions_Top"
    },
    {
      "x": 14,
      "y": 18,
      "z": -5,
      "name": "Wood_Beech_Trunk",
      "support": 15,
      "rotation": 5
    },
    {
      "x": 14,
      "y": 19,
      "z": -5,
      "name": "Wood_Softwood_Roof_Shallow",
      "filler": 1,
      "rotation": 3
    },
    {
      "x": 14,
      "y": 1,
      "z": -4,
      "name": "Rock_Stone"
    },
    {
      "x": 14,
      "y": 7,
      "z": -4,
      "name": "Wood_Softwood_Roof_Shallow",
      "filler": 992
    },
    {
      "x": 14,
      "y": 13,
      "z": -4,
      "name": "Plant_Vine_Wall",
      "support": 15
    },
    {
      "x": 14,
      "y": 19,
      "z": -4,
      "name": "Wood_Softwood_Roof_Shallow",
      "filler": 1,
      "rotation": 3
    },
    {
      "x": 14,
      "y": 1,
      "z": -3,
      "name": "Soil_Dirt"
    },
    {
      "x": 14,
      "y": 2,
      "z": -3,
      "name": "Rock_Stone_Brick_Decorative"
    },
    {
      "x": 14,
      "y": 3,
      "z": -3,
      "name": "Rock_Stone_Brick"
    },
    {
      "x": 14,
      "y": 4,
      "z": -3,
      "name": "Rock_Stone_Brick"
    },
    {
      "x": 14,
      "y": 5,
      "z": -3,
      "name": "Rock_Stone_Brick"
    },
    {
      "x": 14,
      "y": 6,
      "z": -3,
      "name": "Wood_Beech_Trunk",
      "support": 15,
      "rotation": 5
    },
    {
      "x": 14,
      "y": 7,
      "z": -3,
      "name": "Wood_Softwood_Roof_Shallow"
    },
    {
      "x": 14,
      "y": 1,
      "z": -2,
      "name": "Rock_Stone_Cobble"
    },
    {
      "x": 14,
      "y": 4,
      "z": -2,
      "name": "Plant_Vine_Wall",
      "support": 15
    },
    {
      "x": 14,
      "y": 6,
      "z": -2,
      "name": "Wood_Softwood_Roof_Hollow"
    },
    {
      "x": 14,
      "y": 12,
      "z": -2,
      "name": "Cloth_Block_Wool_White"
    },
    {
      "x": 14,
      "y": 13,
      "z": -2,
      "name": "Cloth_Block_Wool_White"
    },
    {
      "x": 14,
      "y": 14,
      "z": -2,
      "name": "Cloth_Block_Wool_White"
    },
    {
      "x": 14,
      "y": 15,
      "z": -2,
      "name": "Wood_Hardwood_Fence"
    },
    {
      "x": 14,
      "y": 16,
      "z": -2,
      "name": "Cloth_Block_Wool_White"
    },
    {
      "x": 14,
      "y": 17,
      "z": -2,
      "name": "Wood_Hardwood_Fence"
    },
    {
      "x": 14,
      "y": 18,
      "z": -2,
      "name": "Wood_Hardwood_Fence"
    },
    {
      "x": 14,
      "y": 19,
      "z": -2,
      "name": "Wood_Hardwood_Fence"
    },
    {
      "x": 14,
      "y": 20,
      "z": -2,
      "name": "Cloth_Block_Wool_White"
    },
    {
      "x": 14,
      "y": 21,
      "z": -2,
      "name": "Cloth_Block_Wool_White"
    },
    {
      "x": 14,
      "y": 1,
      "z": -1,
      "name": "Rock_Stone_Cobble"
    },
    {
      "x": 15,
      "y": 1,
      "z": -15,
      "name": "Rock_Stone_Cobble"
    },
    {
      "x": 15,
      "y": 15,
      "z": -15,
      "name": "Wood_Softwood_Planks_Half",
      "rotation": 6
    },
    {
      "x": 15,
      "y": 1,
      "z": -14,
      "name": "Rock_Stone_Cobble"
    },
    {
      "x": 15,
      "y": 4,
      "z": -14,
      "name": "Plant_Vine_Wall",
      "support": 15,
      "rotation": 2
    },
    {
      "x": 15,
      "y": 6,
      "z": -14,
      "name": "Wood_Softwood_Roof_Hollow",
      "rotation": 2
    },
    {
      "x": 15,
      "y": 10,
      "z": -14,
      "name": "Cloth_Block_Wool_White"
    },
    {
      "x": 15,
      "y": 11,
      "z": -14,
      "name": "Cloth_Block_Wool_White"
    },
    {
      "x": 15,
      "y": 12,
      "z": -14,
      "name": "Cloth_Block_Wool_White"
    },
    {
      "x": 15,
      "y": 13,
      "z": -14,
      "name": "Wood_Hardwood_Fence",
      "rotation": 2
    },
    {
      "x": 15,
      "y": 14,
      "z": -14,
      "name": "Wood_Hardwood_Fence",
      "rotation": 2
    },
    {
      "x": 15,
      "y": 15,
      "z": -14,
      "name": "Wood_Beech_Trunk",
      "support": 15,
      "rotation": 4
    },
    {
      "x": 15,
      "y": 16,
      "z": -14,
      "name": "Wood_Hardwood_Fence",
      "rotation": 2
    },
    {
      "x": 15,
      "y": 17,
      "z": -14,
      "name": "Wood_Hardwood_Fence",
      "rotation": 2
    },
    {
      "x": 15,
      "y": 18,
      "z": -14,
      "name": "Cloth_Block_Wool_White"
    },
    {
      "x": 15,
      "y": 19,
      "z": -14,
      "name": "Cloth_Block_Wool_White"
    },
    {
      "x": 15,
      "y": 20,
      "z": -14,
      "name": "Cloth_Block_Wool_White"
    },
    {
      "x": 15,
      "y": 1,
      "z": -13,
      "name": "Soil_Dirt"
    },
    {
      "x": 15,
      "y": 2,
      "z": -13,
      "name": "Rock_Stone_Brick_Decorative"
    },
    {
      "x": 15,
      "y": 3,
      "z": -13,
      "name": "Rock_Stone_Brick"
    },
    {
      "x": 15,
      "y": 4,
      "z": -13,
      "name": "Rock_Stone_Brick"
    },
    {
      "x": 15,
      "y": 5,
      "z": -13,
      "name": "Rock_Stone_Brick"
    },
    {
      "x": 15,
      "y": 6,
      "z": -13,
      "name": "Wood_Beech_Trunk",
      "support": 15,
      "rotation": 5
    },
    {
      "x": 15,
      "y": 7,
      "z": -13,
      "name": "Wood_Softwood_Roof_Shallow",
      "rotation": 2
    },
    {
      "x": 15,
      "y": 15,
      "z": -13,
      "name": "Wood_Beech_Trunk",
      "support": 15,
      "rotation": 4
    },
    {
      "x": 15,
      "y": 1,
      "z": -12,
      "name": "Rock_Stone"
    },
    {
      "x": 15,
      "y": 7,
      "z": -12,
      "name": "Wood_Softwood_Roof_Shallow",
      "filler": 32,
      "rotation": 2
    },
    {
      "x": 15,
      "y": 15,
      "z": -12,
      "name": "Wood_Beech_Trunk",
      "support": 15,
      "rotation": 4
    },
    {
      "x": 15,
      "y": 19,
      "z": -12,
      "name": "Wood_Softwood_Planks_Half",
      "rotation": 8
    },
    {
      "x": 15,
      "y": 20,
      "z": -12,
      "name": "Wood_Softwood_Roof_Flat",
      "rotation": 1
    },
    {
      "x": 15,
      "y": 1,
      "z": -11,
      "name": "Rock_Stone"
    },
    {
      "x": 15,
      "y": 6,
      "z": -11,
      "name": "Deco_Lantern_Ceiling"
    },
    {
      "x": 15,
      "y": 7,
      "z": -11,
      "name": "Rock_Stone_Brick"
    },
    {
      "x": 15,
      "y": 8,
      "z": -11,
      "name": "Wood_Beech_Trunk",
      "support": 15,
      "rotation": 5
    },
    {
      "x": 15,
      "y": 9,
      "z": -11,
      "name": "*Wood_Village_Wall_Full_State_Definitions_Bottom"
    },
    {
      "x": 15,
      "y": 10,
      "z": -11,
      "name": "*Wood_Village_Wall_Full_State_Definitions_Top"
    },
    {
      "x": 15,
      "y": 11,
      "z": -11,
      "name": "Wood_Beech_Trunk",
      "support": 15,
      "rotation": 5
    },
    {
      "x": 15,
      "y": 12,
      "z": -11,
      "name": "Furniture_Village_Window"
    },
    {
      "x": 15,
      "y": 13,
      "z": -11,
      "name": "Furniture_Village_Window"
    },
    {
      "x": 15,
      "y": 14,
      "z": -11,
      "name": "Wood_Village_Wall_Full"
    },
    {
      "x": 15,
      "y": 15,
      "z": -11,
      "name": "Wood_Beech_Trunk",
      "support": 15,
      "rotation": 4
    },
    {
      "x": 15,
      "y": 16,
      "z": -11,
      "name": "*Wood_Village_Wall_Full_State_Definitions_Bottom"
    },
    {
      "x": 15,
      "y": 17,
      "z": -11,
      "name": "*Wood_Village_Wall_Full_State_Definitions_Top"
    },
    {
      "x": 15,
      "y": 18,
      "z": -11,
      "name": "Wood_Beech_Trunk",
      "support": 15,
      "rotation": 5
    },
    {
      "x": 15,
      "y": 19,
      "z": -11,
      "name": "Wood_Village_Wall_Full"
    },
    {
      "x": 15,
      "y": 20,
      "z": -11,
      "name": "Wood_Softwood_Roof_Flat",
      "rotation": 1
    },
    {
      "x": 15,
      "y": 1,
      "z": -10,
      "name": "Soil_Dirt"
    },
    {
      "x": 15,
      "y": 2,
      "z": -10,
      "name": "Wood_Beech_Trunk",
      "support": 15,
      "rotation": 4
    },
    {
      "x": 15,
      "y": 15,
      "z": -10,
      "name": "Wood_Beech_Trunk",
      "support": 15,
      "rotation": 4
    },
    {
      "x": 15,
      "y": 19,
      "z": -10,
      "name": "Wood_Softwood_Planks_Half",
      "rotation": 8
    },
    {
      "x": 15,
      "y": 20,
      "z": -10,
      "name": "Wood_Softwood_Roof_Flat",
      "rotation": 1
    },
    {
      "x": 15,
      "y": 1,
      "z": -9,
      "name": "Soil_Dirt"
    },
    {
      "x": 15,
      "y": 2,
      "z": -9,
      "name": "Ingredient_Hay"
    },
    {
      "x": 15,
      "y": 15,
      "z": -9,
      "name": "Wood_Beech_Trunk",
      "support": 15,
      "rotation": 4
    },
    {
      "x": 15,
      "y": 19,
      "z": -9,
      "name": "Wood_Softwood_Planks_Half",
      "rotation": 8
    },
    {
      "x": 15,
      "y": 20,
      "z": -9,
      "name": "Wood_Softwood_Roof_Flat",
      "rotation": 1
    },
    {
      "x": 15,
      "y": 1,
      "z": -8,
      "name": "Soil_Dirt"
    },
    {
      "x": 15,
      "y": 2,
      "z": -8,
      "name": "Wood_Beech_Trunk",
      "support": 15
    },
    {
      "x": 15,
      "y": 3,
      "z": -8,
      "name": "Wood_Beech_Trunk",
      "support": 15
    },
    {
      "x": 15,
      "y": 4,
      "z": -8,
      "name": "Soil_Clay_Brick_Beam"
    },
    {
      "x": 15,
      "y": 5,
      "z": -8,
      "name": "Soil_Clay_Brick_Beam"
    },
    {
      "x": 15,
      "y": 6,
      "z": -8,
      "name": "Soil_Clay_Brick_Beam"
    },
    {
      "x": 15,
      "y": 7,
      "z": -8,
