{
  "version": 8,
  "blockIdVersion": 11,
  "anchorX": 0,
  "anchorY": 0,
  "anchorZ": 0,
  "blocks": [
    {
      "x": -24,
      "y": 11,
      "z": 11,
      "name": "Wood_Softwood_Stairs",
      "rotation": 9
    },
    {
      "x": -23,
      "y": 4,
      "z": 6,
      "name": "Wood_Softwood_Roof_Hollow",
      "rotation": 2
    },
    {
      "x": -23,
      "y": 4,
      "z": 7,
      "name": "Wood_Oak_Branch_Short",
      "support": 15,
      "rotation": 3
    },
    {
      "x": -23,
      "y": 5,
      "z": 7,
      "name": "Wood_Softwood_Roof_Steep",
      "rotation": 2
    },
    {
      "x": -23,
      "y": 6,
      "z": 7,
      "name": "Wood_Softwood_Roof_Steep",
      "filler": 1024,
      "rotation": 2
    },
    {
      "x": -23,
      "y": 6,
      "z": 8,
      "name": "Wood_Softwood_Stairs",
      "rotation": 10
    },
    {
      "x": -23,
      "y": 7,
      "z": 8,
      "name": "Wood_Softwood_Roof_Steep",
      "rotation": 2
    },
    {
      "x": -23,
      "y": 8,
      "z": 8,
      "name": "Wood_Softwood_Roof_Steep",
      "filler": 1024,
      "rotation": 2
    },
    {
      "x": -23,
      "y": 8,
      "z": 9,
      "name": "Wood_Softwood_Stairs",
      "rotation": 10
    },
    {
      "x": -23,
      "y": 9,
      "z": 9,
      "name": "Wood_Softwood_Roof",
      "rotation": 2
    },
    {
      "x": -23,
      "y": 9,
      "z": 10,
      "name": "Wood_Softwood_Stairs",
      "rotation": 10
    },
    {
      "x": -23,
      "y": 10,
      "z": 10,
      "name": "Wood_Softwood_Roof",
      "rotation": 2
    },
    {
      "x": -23,
      "y": 4,
      "z": 11,
      "name": "Wood_Oak_Branch_Short",
      "support": 15,
      "rotation": 3
    },
    {
      "x": -23,
      "y": 8,
      "z": 11,
      "name": "Wood_Oak_Branch_Short",
      "support": 15,
      "rotation": 3
    },
    {
      "x": -23,
      "y": 10,
      "z": 11,
      "name": "Wood_Softwood_Stairs",
      "rotation": 9
    },
    {
      "x": -23,
      "y": 11,
      "z": 11,
      "name": "Wood_Softwood_Stairs",
      "rotation": 1
    },
    {
      "x": -23,
      "y": 9,
      "z": 12,
      "name": "Wood_Softwood_Stairs",
      "rotation": 8
    },
    {
      "x": -23,
      "y": 10,
      "z": 12,
      "name": "Wood_Softwood_Roof"
    },
    {
      "x": -23,
      "y": 8,
      "z": 13,
      "name": "Wood_Softwood_Stairs",
      "rotation": 8
    },
    {
      "x": -23,
      "y": 9,
      "z": 13,
      "name": "Wood_Softwood_Roof"
    },
    {
      "x": -23,
      "y": 6,
      "z": 14,
      "name": "Wood_Softwood_Stairs",
      "rotation": 8
    },
    {
      "x": -23,
      "y": 7,
      "z": 14,
      "name": "Wood_Softwood_Roof_Steep"
    },
    {
      "x": -23,
      "y": 8,
      "z": 14,
      "name": "Wood_Softwood_Roof_Steep",
      "filler": 1024
    },
    {
      "x": -23,
      "y": 4,
      "z": 15,
      "name": "Wood_Oak_Branch_Short",
      "support": 15,
      "rotation": 3
    },
    {
      "x": -23,
      "y": 5,
      "z": 15,
      "name": "Wood_Softwood_Roof_Steep"
    },
    {
      "x": -23,
      "y": 6,
      "z": 15,
      "name": "Wood_Softwood_Roof_Steep",
      "filler": 1024
    },
    {
      "x": -23,
      "y": 4,
      "z": 16,
      "name": "Wood_Softwood_Roof_Hollow"
    },
    {
      "x": -22,
      "y": 4,
      "z": 6,
      "name": "Wood_Softwood_Roof_Hollow",
      "rotation": 2
    },
    {
      "x": -22,
      "y": 0,
      "z": 7,
      "name": "Rock_Stone_Cobble"
    },
    {
      "x": -22,
      "y": 1,
      "z": 7,
      "name": "Wood_Oak_Trunk",
      "support": 15
    },
    {
      "x": -22,
      "y": 2,
      "z": 7,
      "name": "Wood_Oak_Trunk",
      "support": 15
    },
    {
      "x": -22,
      "y": 3,
      "z": 7,
      "name": "Wood_Oak_Trunk",
      "support": 15
    },
    {
      "x": -22,
      "y": 4,
      "z": 7,
      "name": "Wood_Oak_Trunk",
      "support": 15
    },
    {
      "x": -22,
      "y": 5,
      "z": 7,
      "name": "Wood_Softwood_Roof_Steep",
      "rotation": 2
    },
    {
      "x": -22,
      "y": 6,
      "z": 7,
      "name": "Wood_Softwood_Roof_Steep",
      "filler": 1024,
      "rotation": 2
    },
    {
      "x": -22,
      "y": 4,
      "z": 8,
      "name": "Wood_Oak_Trunk",
      "support": 15,
      "rotation": 4
    },
    {
      "x": -22,
      "y": 6,
      "z": 8,
      "name": "Wood_Softwood_Stairs",
      "rotation": 10
    },
    {
      "x": -22,
      "y": 7,
      "z": 8,
      "name": "Wood_Softwood_Roof_Steep",
      "rotation": 2
    },
    {
      "x": -22,
      "y": 8,
      "z": 8,
      "name": "Wood_Softwood_Roof_Steep",
      "filler": 1024,
      "rotation": 2
    },
    {
      "x": -22,
      "y": 4,
      "z": 9,
      "name": "Wood_Oak_Trunk",
      "support": 15,
      "rotation": 4
    },
    {
      "x": -22,
      "y": 8,
      "z": 9,
      "name": "Wood_Oak_Trunk",
      "support": 15,
      "rotation": 4
    },
    {
      "x": -22,
      "y": 9,
      "z": 9,
      "name": "Wood_Softwood_Roof",
      "rotation": 2
    },
    {
      "x": -22,
      "y": 4,
      "z": 10,
      "name": "Wood_Oak_Trunk",
      "support": 15,
      "rotation": 4
    },
    {
      "x": -22,
      "y": 8,
      "z": 10,
      "name": "Wood_Oak_Trunk",
      "support": 15,
      "rotation": 4
    },
    {
      "x": -22,
      "y": 9,
      "z": 10,
      "name": "Wood_Softwood_Stairs",
      "rotation": 10
    },
    {
      "x": -22,
      "y": 10,
      "z": 10,
      "name": "Wood_Softwood_Roof",
      "rotation": 2
    },
    {
      "x": -22,
      "y": 4,
      "z": 11,
      "name": "Wood_Oak_Trunk",
      "support": 15,
      "rotation": 4
    },
    {
      "x": -22,
      "y": 8,
      "z": 11,
      "name": "Wood_Oak_Trunk",
      "support": 15,
      "rotation": 4
    },
    {
      "x": -22,
      "y": 10,
      "z": 11,
      "name": "Wood_Softwood_Planks"
    },
    {
      "x": -22,
      "y": 11,
      "z": 11,
      "name": "Wood_Softwood_Planks_Half"
    },
    {
      "x": -22,
      "y": 4,
      "z": 12,
      "name": "Wood_Oak_Trunk",
      "support": 15,
      "rotation": 4
    },
    {
      "x": -22,
      "y": 8,
      "z": 12,
      "name": "Wood_Oak_Trunk",
      "support": 15,
      "rotation": 4
    },
    {
      "x": -22,
      "y": 9,
      "z": 12,
      "name": "Wood_Softwood_Stairs",
      "rotation": 8
    },
    {
      "x": -22,
      "y": 10,
      "z": 12,
      "name": "Wood_Softwood_Roof"
    },
    {
      "x": -22,
      "y": 4,
      "z": 13,
      "name": "Wood_Oak_Trunk",
      "support": 15,
      "rotation": 4
    },
    {
      "x": -22,
      "y": 8,
      "z": 13,
      "name": "Wood_Oak_Trunk",
      "support": 15,
      "rotation": 4
    },
    {
      "x": -22,
      "y": 9,
      "z": 13,
      "name": "Wood_Softwood_Roof"
    },
    {
      "x": -22,
      "y": 4,
      "z": 14,
      "name": "Wood_Oak_Trunk",
      "support": 15,
      "rotation": 4
    },
    {
      "x": -22,
      "y": 6,
      "z": 14,
      "name": "Wood_Softwood_Stairs",
      "rotation": 8
    },
    {
      "x": -22,
      "y": 7,
      "z": 14,
      "name": "Wood_Softwood_Roof_Steep"
    },
    {
      "x": -22,
      "y": 8,
      "z": 14,
      "name": "Wood_Softwood_Roof_Steep",
      "filler": 1024
    },
    {
      "x": -22,
      "y": 0,
      "z": 15,
      "name": "Rock_Stone_Cobble"
    },
    {
      "x": -22,
      "y": 1,
      "z": 15,
      "name": "Wood_Oak_Trunk",
      "support": 15
    },
    {
      "x": -22,
      "y": 2,
      "z": 15,
      "name": "Wood_Oak_Trunk",
      "support": 15
    },
    {
      "x": -22,
      "y": 3,
      "z": 15,
      "name": "Wood_Oak_Trunk",
      "support": 15
    },
    {
      "x": -22,
      "y": 4,
      "z": 15,
      "name": "Wood_Oak_Trunk",
      "support": 15
    },
    {
      "x": -22,
      "y": 5,
      "z": 15,
      "name": "Wood_Softwood_Roof_Steep"
    },
    {
      "x": -22,
      "y": 6,
      "z": 15,
      "name": "Wood_Softwood_Roof_Steep",
      "filler": 1024
    },
    {
      "x": -22,
      "y": 4,
      "z": 16,
      "name": "Wood_Softwood_Roof_Hollow"
    },
    {
      "x": -21,
      "y": 4,
      "z": 6,
      "name": "Wood_Softwood_Roof_Hollow",
      "rotation": 2
    },
    {
      "x": -21,
      "y": 4,
      "z": 7,
      "name": "Wood_Oak_Trunk",
      "support": 15,
      "rotation": 5
    },
    {
      "x": -21,
      "y": 5,
      "z": 7,
      "name": "Wood_Softwood_Roof_Steep",
      "rotation": 2
    },
    {
      "x": -21,
      "y": 6,
      "z": 7,
      "name": "Wood_Softwood_Roof_Steep",
      "filler": 1024,
      "rotation": 2
    },
    {
      "x": -21,
      "y": 0,
      "z": 8,
      "name": "Rock_Stone_Cobble"
    },
    {
      "x": -21,
      "y": 1,
      "z": 8,
      "name": "Rock_Stone_Brick"
    },
    {
      "x": -21,
      "y": 2,
      "z": 8,
      "name": "Rock_Quartzite"
    },
    {
      "x": -21,
      "y": 3,
      "z": 8,
      "name": "Rock_Quartzite"
    },
    {
      "x": -21,
      "y": 4,
      "z": 8,
      "name": "Wood_Softwood_Planks"
    },
    {
      "x": -21,
      "y": 5,
      "z": 8,
      "name": "Rock_Quartzite"
    },
    {
      "x": -21,
      "y": 6,
      "z": 8,
      "name": "Rock_Quartzite"
    },
    {
      "x": -21,
      "y": 7,
      "z": 8,
      "name": "Wood_Softwood_Roof_Steep",
      "rotation": 2
    },
    {
      "x": -21,
      "y": 8,
      "z": 8,
      "name": "Wood_Softwood_Roof_Steep",
      "filler": 1024,
      "rotation": 2
    },
    {
      "x": -21,
      "y": 0,
      "z": 9,
      "name": "Rock_Stone_Cobble"
    },
    {
      "x": -21,
      "y": 1,
      "z": 9,
      "name": "Rock_Stone_Brick"
    },
    {
      "x": -21,
      "y": 2,
      "z": 9,
      "name": "Rock_Quartzite"
    },
    {
      "x": -21,
      "y": 3,
      "z": 9,
      "name": "Rock_Quartzite"
    },
    {
      "x": -21,
      "y": 4,
      "z": 9,
      "name": "Wood_Softwood_Planks"
    },
    {
      "x": -21,
      "y": 5,
      "z": 9,
      "name": "Rock_Quartzite"
    },
    {
      "x": -21,
      "y": 6,
      "z": 9,
      "name": "Rock_Quartzite"
    },
    {
      "x": -21,
      "y": 7,
      "z": 9,
      "name": "Rock_Quartzite"
    },
    {
      "x": -21,
      "y": 8,
      "z": 9,
      "name": "Wood_Softwood_Planks"
    },
    {
      "x": -21,
      "y": 9,
      "z": 9,
      "name": "Wood_Softwood_Roof",
      "rotation": 2
    },
    {
      "x": -21,
      "y": 0,
      "z": 10,
      "name": "Rock_Stone_Cobble"
    },
    {
      "x": -21,
      "y": 1,
      "z": 10,
      "name": "Rock_Stone_Brick"
    },
    {
      "x": -21,
      "y": 2,
      "z": 10,
      "name": "Furniture_Tavern_Window",
      "rotation": 1
    },
    {
      "x": -21,
      "y": 3,
      "z": 10,
      "name": "Furniture_Tavern_Window",
      "rotation": 1
    },
    {
      "x": -21,
      "y": 4,
      "z": 10,
      "name": "Wood_Softwood_Planks"
    },
    {
      "x": -21,
      "y": 5,
      "z": 10,
      "name": "Rock_Quartzite"
    },
    {
      "x": -21,
      "y": 6,
      "z": 10,
      "name": "Rock_Quartzite"
    },
    {
      "x": -21,
      "y": 7,
      "z": 10,
      "name": "Rock_Quartzite"
    },
    {
      "x": -21,
      "y": 8,
      "z": 10,
      "name": "Wood_Softwood_Planks"
    },
    {
      "x": -21,
      "y": 9,
      "z": 10,
      "name": "Rock_Quartzite"
    },
    {
      "x": -21,
      "y": 10,
      "z": 10,
      "name": "Wood_Softwood_Roof",
      "rotation": 2
    },
    {
      "x": -21,
      "y": 0,
      "z": 11,
      "name": "Rock_Stone_Cobble"
    },
    {
      "x": -21,
      "y": 1,
      "z": 11,
      "name": "Wood_Oak_Trunk",
      "support": 15
    },
    {
      "x": -21,
      "y": 2,
      "z": 11,
      "name": "Wood_Oak_Trunk",
      "support": 15
    },
    {
      "x": -21,
      "y": 3,
      "z": 11,
      "name": "Wood_Oak_Trunk",
      "support": 15
    },
    {
      "x": -21,
      "y": 4,
      "z": 11,
      "name": "Wood_Softwood_Planks"
    },
    {
      "x": -21,
      "y": 5,
      "z": 11,
      "name": "Wood_Oak_Trunk",
      "support": 15
    },
    {
      "x": -21,
      "y": 6,
      "z": 11,
      "name": "Wood_Oak_Trunk",
      "support": 15
    },
    {
      "x": -21,
      "y": 7,
      "z": 11,
      "name": "Wood_Oak_Trunk",
      "support": 15
    },
    {
      "x": -21,
      "y": 8,
      "z": 11,
      "name": "Wood_Softwood_Planks"
    },
    {
      "x": -21,
      "y": 9,
      "z": 11,
      "name": "Wood_Oak_Trunk",
      "support": 15
    },
    {
      "x": -21,
      "y": 10,
      "z": 11,
      "name": "Wood_Oak_Trunk",
      "support": 15
    },
    {
      "x": -21,
      "y": 11,
      "z": 11,
      "name": "Wood_Softwood_Planks_Half"
    },
    {
      "x": -21,
      "y": 0,
      "z": 12,
      "name": "Rock_Stone_Cobble"
    },
    {
      "x": -21,
      "y": 1,
      "z": 12,
      "name": "Rock_Stone_Brick"
    },
    {
      "x": -21,
      "y": 2,
      "z": 12,
      "name": "Rock_Quartzite"
    },
    {
      "x": -21,
      "y": 3,
      "z": 12,
      "name": "Rock_Quartzite"
    },
    {
      "x": -21,
      "y": 4,
      "z": 12,
      "name": "Wood_Softwood_Planks"
    },
    {
      "x": -21,
      "y": 5,
      "z": 12,
      "name": "Rock_Quartzite"
    },
    {
      "x": -21,
      "y": 6,
      "z": 12,
      "name": "Rock_Quartzite"
    },
    {
      "x": -21,
      "y": 7,
      "z": 12,
      "name": "Rock_Quartzite"
    },
    {
      "x": -21,
      "y": 8,
      "z": 12,
      "name": "Wood_Softwood_Planks"
    },
    {
      "x": -21,
      "y": 9,
      "z": 12,
      "name": "Rock_Quartzite"
    },
    {
      "x": -21,
      "y": 10,
      "z": 12,
      "name": "Wood_Softwood_Roof"
    },
    {
      "x": -21,
      "y": 0,
      "z": 13,
      "name": "Rock_Stone_Cobble"
    },
    {
      "x": -21,
      "y": 1,
      "z": 13,
      "name": "Rock_Stone_Brick"
    },
    {
      "x": -21,
      "y": 2,
      "z": 13,
      "name": "Rock_Quartzite"
    },
    {
      "x": -21,
      "y": 3,
      "z": 13,
      "name": "Rock_Quartzite"
    },
    {
      "x": -21,
      "y": 4,
      "z": 13,
      "name": "Wood_Softwood_Planks"
    },
    {
      "x": -21,
      "y": 5,
      "z": 13,
      "name": "Rock_Quartzite"
    },
    {
      "x": -21,
      "y": 6,
      "z": 13,
      "name": "Furniture_Tavern_Window",
      "rotation": 1
    },
    {
      "x": -21,
      "y": 7,
      "z": 13,
      "name": "Furniture_Tavern_Window",
      "rotation": 1
    },
    {
      "x": -21,
      "y": 8,
      "z": 13,
      "name": "Wood_Softwood_Planks"
    },
    {
      "x": -21,
      "y": 9,
      "z": 13,
      "name": "Wood_Softwood_Roof"
    },
    {
      "x": -21,
      "y": 0,
      "z": 14,
      "name": "Rock_Stone_Cobble"
    },
    {
      "x": -21,
      "y": 1,
      "z": 14,
      "name": "Rock_Stone_Brick"
    },
    {
      "x": -21,
      "y": 2,
      "z": 14,
      "name": "Rock_Quartzite"
    },
    {
      "x": -21,
      "y": 3,
      "z": 14,
      "name": "Rock_Quartzite"
    },
    {
      "x": -21,
      "y": 4,
      "z": 14,
      "name": "Wood_Softwood_Planks"
    },
    {
      "x": -21,
      "y": 5,
      "z": 14,
      "name": "Rock_Quartzite"
    },
    {
      "x": -21,
      "y": 6,
      "z": 14,
      "name": "Rock_Quartzite"
    },
    {
      "x": -21,
      "y": 7,
      "z": 14,
      "name": "Wood_Softwood_Roof_Steep"
    },
    {
      "x": -21,
      "y": 8,
      "z": 14,
      "name": "Wood_Softwood_Roof_Steep",
      "filler": 1024
    },
    {
      "x": -21,
      "y": 4,
      "z": 15,
      "name": "Wood_Oak_Trunk",
      "support": 15,
      "rotation": 5
    },
    {
      "x": -21,
      "y": 5,
      "z": 15,
      "name": "Wood_Softwood_Roof_Steep"
    },
    {
      "x": -21,
      "y": 6,
      "z": 15,
      "name": "Wood_Softwood_Roof_Steep",
      "filler": 1024
    },
    {
      "x": -21,
      "y": 4,
      "z": 16,
      "name": "Wood_Softwood_Roof_Hollow"
    },
    {
      "x": -20,
      "y": 4,
      "z": 6,
      "name": "Wood_Softwood_Roof_Hollow",
      "rotation": 2
    },
    {
      "x": -20,
      "y": 4,
      "z": 7,
      "name": "Wood_Oak_Trunk",
      "support": 15,
      "rotation": 5
    },
    {
      "x": -20,
      "y": 5,
      "z": 7,
      "name": "Wood_Softwood_Roof_Steep",
      "rotation": 2
    },
    {
      "x": -20,
      "y": 6,
      "z": 7,
      "name": "Wood_Softwood_Roof_Steep",
      "filler": 1024,
      "rotation": 2
    },
    {
      "x": -20,
      "y": 0,
      "z": 8,
      "name": "Rock_Stone_Cobble"
    },
    {
      "x": -20,
      "y": 1,
      "z": 8,
      "name": "Rock_Stone_Brick"
    },
    {
      "x": -20,
      "y": 2,
      "z": 8,
      "name": "Rock_Quartzite"
    },
    {
      "x": -20,
      "y": 3,
      "z": 8,
      "name": "Rock_Quartzite"
    },
    {
      "x": -20,
      "y": 4,
      "z": 8,
      "name": "Wood_Softwood_Planks"
    },
    {
      "x": -20,
      "y": 5,
      "z": 8,
      "name": "Rock_Quartzite"
    },
    {
      "x": -20,
      "y": 6,
      "z": 8,
      "name": "Rock_Quartzite"
    },
    {
      "x": -20,
      "y": 7,
      "z": 8,
      "name": "Wood_Softwood_Roof_Steep",
      "rotation": 2
    },
    {
      "x": -20,
      "y": 8,
      "z": 8,
      "name": "Wood_Softwood_Roof_Steep",
      "filler": 1024,
      "rotation": 2
    },
    {
      "x": -20,
      "y": 0,
      "z": 9,
      "name": "Wood_Softwood_Planks"
    },
    {
      "x": -20,
      "y": 1,
      "z": 9,
      "name": "Furniture_Village_Counter",
      "filler": 31
    },
    {
      "x": -20,
      "y": 2,
      "z": 9,
      "name": "Deco_Book_Pile_Small"
    },
    {
      "x": -20,
      "y": 4,
      "z": 9,
      "name": "Wood_Softwood_Planks"
    },
    {
      "x": -20,
      "y": 8,
      "z": 9,
      "name": "Wood_Softwood_Planks"
    },
    {
      "x": -20,
      "y": 9,
      "z": 9,
      "name": "Wood_Softwood_Roof",
      "rotation": 2
    },
    {
      "x": -20,
      "y": 0,
      "z": 10,
      "name": "Wood_Softwood_Planks"
    },
    {
      "x": -20,
      "y": 4,
      "z": 10,
      "name": "Wood_Softwood_Planks"
    },
    {
      "x": -20,
      "y": 8,
      "z": 10,
      "name": "Wood_Softwood_Planks"
    },
    {
      "x": -20,
      "y": 10,
      "z": 10,
      "name": "Wood_Softwood_Roof_Hollow",
      "rotation": 2
    },
    {
      "x": -20,
      "y": 0,
      "z": 11,
      "name": "Wood_Softwood_Planks"
    },
    {
      "x": -20,
      "y": 4,
      "z": 11,
      "name": "Wood_Softwood_Planks"
    },
    {
      "x": -20,
      "y": 5,
      "z": 11,
      "name": "Ingredient_Flour"
    },
    {
      "x": -20,
      "y": 6,
      "z": 11,
      "name": "Wood_Torch_Wall",
      "rotation": 1
    },
    {
      "x": -20,
      "y": 8,
      "z": 11,
      "name": "Wood_Softwood_Planks"
    },
    {
      "x": -20,
      "y": 11,
      "z": 11,
      "name": "Wood_Softwood_Planks_Half"
    },
    {
      "x": -20,
      "y": 0,
      "z": 12,
      "name": "Wood_Softwood_Planks"
    },
    {
      "x": -20,
      "y": 4,
      "z": 12,
      "name": "Wood_Softwood_Planks"
    },
    {
      "x": -20,
      "y": 5,
      "z": 12,
      "name": "Furniture_Tavern_Barrel"
    },
    {
      "x": -20,
      "y": 8,
      "z": 12,
      "name": "Wood_Softwood_Planks"
    },
    {
      "x": -20,
      "y": 10,
      "z": 12,
      "name": "Wood_Softwood_Roof_Hollow"
    },
    {
      "x": -20,
      "y": 0,
      "z": 13,
      "name": "Wood_Softwood_Planks"
    },
    {
      "x": -20,
      "y": 1,
      "z": 13,
      "name": "Deco_Book_Pile_Small",
      "rotation": 2
    },
    {
      "x": -20,
      "y": 4,
      "z": 13,
      "name": "Wood_Softwood_Planks"
    },
    {
      "x": -20,
      "y": 5,
      "z": 13,
      "name": "Furniture_Tavern_Barrel"
    },
    {
      "x": -20,
      "y": 8,
      "z": 13,
      "name": "Wood_Softwood_Planks"
    },
    {
      "x": -20,
      "y": 9,
      "z": 13,
      "name": "Wood_Softwood_Roof"
    },
    {
      "x": -20,
      "y": 0,
      "z": 14,
      "name": "Rock_Stone_Cobble"
    },
    {
      "x": -20,
      "y": 1,
      "z": 14,
      "name": "Rock_Stone_Brick"
    },
    {
      "x": -20,
      "y": 2,
      "z": 14,
      "name": "Rock_Quartzite"
    },
    {
      "x": -20,
      "y": 3,
      "z": 14,
      "name": "Rock_Quartzite"
    },
    {
      "x": -20,
      "y": 4,
      "z": 14,
      "name": "Wood_Softwood_Planks"
    },
    {
      "x": -20,
      "y": 5,
      "z": 14,
      "name": "Rock_Quartzite"
    },
    {
      "x": -20,
      "y": 6,
      "z": 14,
      "name": "Rock_Quartzite"
    },
    {
      "x": -20,
      "y": 7,
      "z": 14,
      "name": "Wood_Softwood_Roof_Steep"
    },
    {
      "x": -20,
      "y": 8,
      "z": 14,
      "name": "Wood_Softwood_Roof_Steep",
      "filler": 1024
    },
    {
      "x": -20,
      "y": 4,
      "z": 15,
      "name": "Wood_Oak_Trunk",
      "support": 15,
      "rotation": 5
    },
    {
      "x": -20,
      "y": 5,
      "z": 15,
      "name": "Wood_Softwood_Roof_Steep"
    },
    {
      "x": -20,
      "y": 6,
      "z": 15,
      "name": "Wood_Softwood_Roof_Steep",
      "filler": 1024
    },
    {
      "x": -20,
      "y": 4,
      "z": 16,
      "name": "Wood_Softwood_Roof_Hollow"
    },
    {
      "x": -19,
      "y": 4,
      "z": 6,
      "name": "Wood_Softwood_Roof_Hollow",
      "rotation": 2
    },
    {
      "x": -19,
      "y": 4,
      "z": 7,
      "name": "Wood_Oak_Trunk",
      "support": 15,
      "rotation": 5
    },
    {
      "x": -19,
      "y": 5,
      "z": 7,
      "name": "*Wood_Softwood_Roof_Steep_State_Definitions_Inverted_Corner_Right",
      "rotation": 3
    },
    {
      "x": -19,
      "y": 6,
      "z": 7,
      "name": "*Wood_Softwood_Roof_Steep_State_Definitions_Inverted_Corner_Right",
      "filler": 1024,
      "rotation": 3
    },
    {
      "x": -19,
      "y": 0,
      "z": 8,
      "name": "Rock_Stone_Cobble"
    },
    {
      "x": -19,
      "y": 1,
      "z": 8,
      "name": "Rock_Stone_Brick"
    },
    {
      "x": -19,
      "y": 2,
      "z": 8,
      "name": "Rock_Quartzite"
    },
    {
      "x": -19,
      "y": 3,
      "z": 8,
      "name": "Rock_Quartzite"
    },
    {
      "x": -19,
      "y": 4,
      "z": 8,
      "name": "Wood_Softwood_Planks"
    },
    {
      "x": -19,
      "y": 5,
      "z": 8,
      "name": "Rock_Quartzite"
    },
    {
      "x": -19,
      "y": 6,
      "z": 8,
      "name": "Rock_Quartzite"
    },
    {
      "x": -19,
      "y": 7,
      "z": 8,
      "name": "Wood_Softwood_Roof_Steep",
      "rotation": 2
    },
    {
      "x": -19,
      "y": 8,
      "z": 8,
      "name": "Wood_Softwood_Roof_Steep",
      "filler": 1024,
      "rotation": 2
    },
    {
      "x": -19,
      "y": 0,
      "z": 9,
      "name": "Wood_Softwood_Planks"
    },
    {
      "x": -19,
      "y": 1,
      "z": 9,
      "name": "Furniture_Village_Counter"
    },
    {
      "x": -19,
      "y": 2,
      "z": 9,
      "name": "Deco_Book_Pile_Small"
    },
    {
      "x": -19,
      "y": 4,
      "z": 9,
      "name": "Wood_Softwood_Planks"
    },
    {
      "x": -19,
      "y": 8,
      "z": 9,
      "name": "Wood_Softwood_Planks"
    },
    {
      "x": -19,
      "y": 9,
      "z": 9,
      "name": "Wood_Softwood_Roof",
      "rotation": 2
    },
    {
      "x": -19,
      "y": 0,
      "z": 10,
      "name": "Wood_Softwood_Planks"
    },
    {
      "x": -19,
      "y": 4,
      "z": 10,
      "name": "Wood_Softwood_Planks"
    },
    {
      "x": -19,
      "y": 8,
      "z": 10,
      "name": "Wood_Softwood_Planks"
    },
    {
      "x": -19,
      "y": 10,
      "z": 10,
      "name": "Wood_Softwood_Roof_Hollow",
      "rotation": 2
    },
    {
      "x": -19,
      "y": 0,
      "z": 11,
      "name": "Wood_Softwood_Planks"
    },
    {
      "x": -19,
      "y": 4,
      "z": 11,
      "name": "Wood_Softwood_Planks"
    },
    {
      "x": -19,
      "y": 8,
      "z": 11,
      "name": "Wood_Softwood_Planks"
    },
    {
      "x": -19,
      "y": 11,
      "z": 11,
      "name": "Wood_Softwood_Planks_Half"
    },
    {
      "x": -19,
      "y": 0,
      "z": 12,
      "name": "Wood_Softwood_Planks"
    },
    {
      "x": -19,
      "y": 4,
      "z": 12,
      "name": "Wood_Softwood_Planks"
    },
    {
      "x": -19,
      "y": 8,
      "z": 12,
      "name": "Wood_Softwood_Planks"
    },
    {
      "x": -19,
      "y": 10,
      "z": 12,
      "name": "Wood_Softwood_Roof_Hollow"
    },
    {
      "x": -19,
      "y": 0,
      "z": 13,
      "name": "Wood_Softwood_Planks"
    },
    {
      "x": -19,
      "y": 1,
      "z": 13,
      "name": "Furniture_Village_Bookcase",
      "rotation": 2
    },
    {
      "x": -19,
      "y": 2,
      "z": 13,
      "name": "Furniture_Village_Shelf_Full",
      "rotation": 2
    },
    {
      "x": -19,
      "y": 3,
      "z": 13,
      "name": "Furniture_Village_Bookcase",
      "rotation": 2
    },
    {
      "x": -19,
      "y": 4,
      "z": 13,
      "name": "Wood_Softwood_Planks"
    },
    {
      "x": -19,
      "y": 5,
      "z": 13,
      "name": "Furniture_Tavern_Barrel"
    },
    {
      "x": -19,
      "y": 8,
      "z": 13,
      "name": "Wood_Softwood_Planks"
    },
    {
      "x": -19,
      "y": 9,
      "z": 13,
      "name": "Wood_Softwood_Roof"
    },
    {
      "x": -19,
      "y": 0,
      "z": 14,
      "name": "Rock_Stone_Cobble"
    },
    {
      "x": -19,
      "y": 1,
      "z": 14,
      "name": "Rock_Stone_Brick"
    },
    {
      "x": -19,
      "y": 2,
      "z": 14,
      "name": "Rock_Quartzite"
    },
    {
      "x": -19,
      "y": 3,
      "z": 14,
      "name": "Rock_Quartzite"
    },
    {
      "x": -19,
      "y": 4,
      "z": 14,
      "name": "Wood_Softwood_Planks"
    },
    {
      "x": -19,
      "y": 5,
      "z": 14,
      "name": "Rock_Quartzite"
    },
    {
      "x": -19,
      "y": 6,
      "z": 14,
      "name": "Rock_Quartzite"
    },
    {
      "x": -19,
      "y": 7,
      "z": 14,
      "name": "Wood_Softwood_Roof_Steep"
    },
    {
      "x": -19,
      "y": 8,
      "z": 14,
      "name": "Wood_Softwood_Roof_Steep",
      "filler": 1024
    },
    {
      "x": -19,
      "y": 4,
      "z": 15,
      "name": "Wood_Oak_Trunk",
      "support": 15,
      "rotation": 5
    },
    {
      "x": -19,
      "y": 5,
      "z": 15,
      "name": "Wood_Softwood_Roof_Steep"
    },
    {
      "x": -19,
      "y": 6,
      "z": 15,
      "name": "Wood_Softwood_Roof_Steep",
      "filler": 1024
    },
    {
      "x": -19,
      "y": 4,
      "z": 16,
      "name": "Wood_Softwood_Roof_Hollow"
    },
    {
      "x": -18,
      "y": 4,
      "z": 6,
      "name": "Wood_Softwood_Roof_Hollow",
      "rotation": 2
    },
    {
      "x": -18,
      "y": 4,
      "z": 7,
      "name": "Wood_Oak_Trunk",
      "support": 15,
      "rotation": 5
    },
    {
      "x": -18,
      "y": 6,
      "z": 7,
      "name": "Wood_Softwood_Stairs",
      "rotation": 11
    },
    {
      "x": -18,
      "y": 7,
      "z": 7,
      "name": "Wood_Softwood_Roof_Steep",
      "rotation": 3
    },
    {
      "x": -18,
      "y": 8,
      "z": 7,
      "name": "Wood_Softwood_Roof_Steep",
      "filler": 1024,
      "rotation": 3
    },
    {
      "x": -18,
      "y": 0,
      "z": 8,
      "name": "Rock_Stone_Cobble"
    },
    {
      "x": -18,
      "y": 1,
      "z": 8,
      "name": "Wood_Oak_Trunk",
      "support": 15
    },
    {
      "x": -18,
      "y": 2,
      "z": 8,
      "name": "Wood_Oak_Trunk",
      "support": 15
    },
    {
      "x": -18,
      "y": 3,
      "z": 8,
      "name": "Wood_Oak_Trunk",
      "support": 15
    },
    {
      "x": -18,
      "y": 4,
      "z": 8,
      "name": "Wood_Softwood_Planks"
    },
    {
      "x": -18,
      "y": 5,
      "z": 8,
      "name": "Rock_Quartzite"
    },
    {
      "x": -18,
      "y": 6,
      "z": 8,
      "name": "Rock_Quartzite"
    },
    {
      "x": -18,
      "y": 7,
      "z": 8,
      "name": "*Wood_Softwood_Roof_Steep_State_Definitions_Inverted_Corner_Left",
      "rotation": 2
    },
    {
      "x": -18,
      "y": 8,
      "z": 8,
      "name": "*Wood_Softwood_Roof_Steep_State_Definitions_Inverted_Corner_Left",
      "filler": 1024,
      "rotation": 2
    },
    {
      "x": -18,
      "y": 0,
      "z": 9,
      "name": "Wood_Softwood_Planks"
    },
    {
      "x": -18,
      "y": 1,
      "z": 9,
      "name": "Furniture_Village_Counter",
      "filler": 31
    },
    {
      "x": -18,
      "y": 2,
      "z": 9,
      "name": "Wood_Torch_Wall"
    },
    {
      "x": -18,
      "y": 4,
      "z": 9,
      "name": "Wood_Softwood_Planks"
    },
    {
      "x": -18,
      "y": 5,
      "z": 9,
      "name": "Furniture_Tavern_Barrel"
    },
    {
      "x": -18,
      "y": 8,
      "z": 9,
      "name": "Wood_Softwood_Planks"
    },
    {
      "x": -18,
      "y": 9,
      "z": 9,
      "name": "Wood_Softwood_Roof",
      "rotation": 2
    },
    {
      "x": -18,
      "y": 0,
      "z": 10,
      "name": "Wood_Softwood_Planks"
    },
    {
      "x": -18,
      "y": 4,
      "z": 10,
      "name": "Wood_Softwood_Planks"
    },
    {
      "x": -18,
      "y": 8,
      "z": 10,
      "name": "Wood_Softwood_Planks"
    },
    {
      "x": -18,
      "y": 10,
      "z": 10,
      "name": "Wood_Softwood_Roof_Hollow",
      "rotation": 2
    },
    {
      "x": -18,
      "y": 0,
      "z": 11,
      "name": "Wood_Softwood_Planks"
    },
    {
      "x": -18,
      "y": 4,
      "z": 11,
      "name": "Wood_Softwood_Planks"
    },
    {
      "x": -18,
      "y": 8,
      "z": 11,
      "name": "Wood_Softwood_Planks"
    },
    {
      "x": -18,
      "y": 11,
      "z": 11,
      "name": "Wood_Softwood_Planks_Half"
    },
    {
      "x": -18,
      "y": 0,
      "z": 12,
      "name": "Wood_Softwood_Planks"
    },
    {
      "x": -18,
      "y": 4,
      "z": 12,
      "name": "Wood_Softwood_Planks"
    },
    {
      "x": -18,
      "y": 8,
      "z": 12,
      "name": "Wood_Softwood_Planks"
    },
    {
      "x": -18,
      "y": 10,
      "z": 12,
      "name": "Wood_Softwood_Roof_Hollow"
    },
    {
      "x": -18,
      "y": 0,
      "z": 13,
      "name": "Wood_Softwood_Planks"
    },
    {
      "x": -18,
      "y": 1,
      "z": 13,
      "name": "Aetherhaven_Treasury",
      "components": {
        "Components": {
          "AetherhavenTreasuryBlock": {
            "PlotId": "58ee0f5f-74f7-4028-a5c1-f108b38c4bce",
            "TownId": "05cce4be-9006-44d0-aebe-81596273763e"
          }
        }
      },
      "rotation": 2
    },
    {
      "x": -18,
      "y": 2,
      "z": 13,
      "name": "Aetherhaven_Management_Block",
      "components": {
        "Components": {
          "AetherhavenManagementBlock": {
            "PlotId": "58ee0f5f-74f7-4028-a5c1-f108b38c4bce",
            "TownId": "05cce4be-9006-44d0-aebe-81596273763e"
          }
        }
      },
      "rotation": 2
    },
    {
      "x": -18,
      "y": 3,
      "z": 13,
      "name": "Furniture_Village_Bookcase",
      "rotation": 2
    },
    {
      "x": -18,
      "y": 4,
      "z": 13,
      "name": "Wood_Softwood_Planks"
    },
    {
      "x": -18,
      "y": 5,
      "z": 13,
      "name": "Ingredient_Flour"
    },
    {
      "x": -18,
      "y": 8,
      "z": 13,
      "name": "Wood_Softwood_Planks"
    },
    {
      "x": -18,
      "y": 9,
      "z": 13,
      "name": "Wood_Softwood_Roof"
    },
    {
      "x": -18,
      "y": 0,
      "z": 14,
      "name": "Rock_Stone_Cobble"
    },
    {
      "x": -18,
      "y": 1,
      "z": 14,
      "name": "Wood_Oak_Trunk",
      "support": 15
    },
    {
      "x": -18,
      "y": 2,
      "z": 14,
      "name": "Wood_Oak_Trunk",
      "support": 15
    },
    {
      "x": -18,
      "y": 3,
      "z": 14,
      "name": "Wood_Oak_Trunk",
      "support": 15
    },
    {
      "x": -18,
      "y": 4,
      "z": 14,
      "name": "Wood_Softwood_Planks"
    },
    {
      "x": -18,
      "y": 5,
      "z": 14,
      "name": "Rock_Quartzite"
    },
    {
      "x": -18,
      "y": 6,
      "z": 14,
      "name": "Rock_Quartzite"
    },
    {
      "x": -18,
      "y": 7,
      "z": 14,
      "name": "Wood_Softwood_Roof_Steep"
    },
    {
      "x": -18,
      "y": 8,
      "z": 14,
      "name": "Wood_Softwood_Roof_Steep",
      "filler": 1024
    },
    {
      "x": -18,
      "y": 4,
      "z": 15,
      "name": "Wood_Oak_Trunk",
      "support": 15,
      "rotation": 5
    },
    {
      "x": -18,
      "y": 5,
      "z": 15,
      "name": "Wood_Softwood_Roof_Steep"
    },
    {
      "x": -18,
      "y": 6,
      "z": 15,
      "name": "Wood_Softwood_Roof_Steep",
      "filler": 1024
    },
    {
      "x": -18,
      "y": 4,
      "z": 16,
      "name": "Wood_Softwood_Roof_Hollow"
    },
    {
      "x": -17,
      "y": 4,
      "z": 6,
      "name": "Wood_Softwood_Roof_Hollow",
      "rotation": 2
    },
    {
      "x": -17,
      "y": 9,
      "z": 6,
      "name": "Wood_Softwood_Stairs",
      "rotation": 8
    },
    {
      "x": -17,
      "y": 4,
      "z": 7,
      "name": "Wood_Oak_Trunk",
      "support": 15,
      "rotation": 5
    },
    {
      "x": -17,
      "y": 8,
      "z": 7,
      "name": "Wood_Softwood_Stairs",
      "rotation": 8
    },
    {
      "x": -17,
      "y": 9,
      "z": 7,
      "name": "Wood_Softwood_Stairs"
    },
    {
      "x": -17,
      "y": 0,
      "z": 8,
      "name": "Rock_Stone_Cobble"
    },
    {
      "x": -17,
      "y": 1,
      "z": 8,
      "name": "Rock_Stone_Brick"
    },
    {
      "x": -17,
      "y": 2,
      "z": 8,
      "name": "Rock_Quartzite"
    },
    {
      "x": -17,
      "y": 3,
      "z": 8,
      "name": "Rock_Quartzite"
    },
    {
      "x": -17,
      "y": 4,
      "z": 8,
      "name": "Wood_Softwood_Planks"
    },
    {
      "x": -17,
      "y": 5,
      "z": 8,
      "name": "Rock_Quartzite"
    },
    {
      "x": -17,
      "y": 6,
      "z": 8,
      "name": "Furniture_Tavern_Window"
    },
    {
      "x": -17,
      "y": 7,
      "z": 8,
      "name": "Furniture_Tavern_Window"
    },
    {
      "x": -17,
      "y": 8,
      "z": 8,
      "name": "Wood_Softwood_Planks"
    },
    {
      "x": -17,
      "y": 9,
      "z": 8,
      "name": "Wood_Softwood_Planks_Half"
    },
    {
      "x": -17,
      "y": 0,
      "z": 9,
      "name": "Wood_Softwood_Planks"
    },
    {
      "x": -17,
      "y": 1,
      "z": 9,
      "name": "Furniture_Village_Counter"
    },
    {
      "x": -17,
      "y": 2,
      "z": 9,
      "name": "Deco_Mug"
    },
    {
      "x": -17,
      "y": 4,
      "z": 9,
      "name": "Wood_Softwood_Planks"
    },
    {
      "x": -17,
      "y": 5,
      "z": 9,
      "name": "Furniture_Village_Crate"
    },
    {
      "x": -17,
      "y": 8,
      "z": 9,
      "name": "Wood_Softwood_Planks"
    },
    {
      "x": -17,
      "y": 9,
      "z": 9,
      "name": "Wood_Softwood_Roof",
      "rotation": 2
    },
    {
      "x": -17,
      "y": 0,
      "z": 10,
      "name": "Wood_Softwood_Planks"
    },
    {
      "x": -17,
      "y": 4,
      "z": 10,
      "name": "Wood_Softwood_Planks"
    },
    {
      "x": -17,
      "y": 8,
      "z": 10,
      "name": "Wood_Softwood_Planks"
    },
    {
      "x": -17,
      "y": 10,
      "z": 10,
      "name": "Wood_Softwood_Roof_Hollow",
      "rotation": 2
    },
    {
      "x": -17,
      "y": 0,
      "z": 11,
      "name": "Wood_Softwood_Planks"
    },
    {
      "x": -17,
      "y": 4,
      "z": 11,
      "name": "Wood_Softwood_Planks"
    },
    {
      "x": -17,
      "y": 8,
      "z": 11,
      "name": "Wood_Softwood_Planks"
    },
    {
      "x": -17,
      "y": 11,
      "z": 11,
      "name": "Wood_Softwood_Planks_Half"
    },
    {
      "x": -17,
      "y": 0,
      "z": 12,
      "name": "Wood_Softwood_Planks"
    },
    {
      "x": -17,
      "y": 4,
      "z": 12,
      "name": "Wood_Softwood_Planks"
    },
    {
      "x": -17,
      "y": 8,
      "z": 12,
      "name": "Wood_Softwood_Planks"
    },
    {
      "x": -17,
      "y": 10,
      "z": 12,
      "name": "Wood_Softwood_Roof_Hollow"
    },
    {
      "x": -17,
      "y": 0,
      "z": 13,
      "name": "Wood_Softwood_Planks"
    },
    {
      "x": -17,
      "y": 1,
      "z": 13,
      "name": "Aetherhaven_Town_Planning_Desk",
      "components": {
        "Components": {
          "PlacedByInteraction": {
            "WhoPlacedUuid": {
              "$binary": "gqJcCRGLSleXtmq6BvFR8g==",
              "$type": "04"
            }
          },
          "BenchBlock": {
            "TierLevel": 1,
            "UpgradeItems": []
          }
        }
      },
      "rotation": 2
    },
    {
      "x": -17,
      "y": 4,
      "z": 13,
      "name": "Wood_Softwood_Planks"
    },
    {
      "x": -17,
      "y": 5,
      "z": 13,
      "name": "Ingredient_Flour"
    },
    {
      "x": -17,
      "y": 8,
      "z": 13,
      "name": "Wood_Softwood_Planks"
    },
    {
      "x": -17,
      "y": 9,
      "z": 13,
      "name": "Wood_Softwood_Roof"
    },
    {
      "x": -17,
      "y": 0,
      "z": 14,
      "name": "Rock_Stone_Cobble"
    },
    {
      "x": -17,
      "y": 1,
      "z": 14,
      "name": "Rock_Stone_Brick"
    },
    {
      "x": -17,
      "y": 2,
      "z": 14,
      "name": "Rock_Quartzite"
    },
    {
      "x": -17,
      "y": 3,
      "z": 14,
      "name": "Rock_Quartzite"
    },
    {
      "x": -17,
      "y": 4,
      "z": 14,
      "name": "Wood_Softwood_Planks"
    },
    {
      "x": -17,
      "y": 5,
      "z": 14,
      "name": "Rock_Quartzite"
    },
    {
      "x": -17,
      "y": 6,
      "z": 14,
      "name": "Rock_Quartzite"
    },
    {
      "x": -17,
      "y": 7,
      "z": 14,
      "name": "Wood_Softwood_Roof_Steep"
    },
    {
      "x": -17,
      "y": 8,
      "z": 14,
      "name": "Wood_Softwood_Roof_Steep",
      "filler": 1024
    },
    {
      "x": -17,
      "y": 4,
      "z": 15,
      "name": "Wood_Oak_Trunk",
      "support": 15,
      "rotation": 5
    },
    {
      "x": -17,
      "y": 5,
      "z": 15,
      "name": "Wood_Softwood_Roof_Steep"
    },
    {
      "x": -17,
      "y": 6,
      "z": 15,
      "name": "Wood_Softwood_Roof_Steep",
      "filler": 1024
    },
    {
      "x": -17,
      "y": 4,
      "z": 16,
      "name": "Wood_Softwood_Roof_Hollow"
    },
    {
      "x": -16,
      "y": 4,
      "z": 6,
      "name": "Wood_Softwood_Roof_Hollow",
      "rotation": 2
    },
    {
      "x": -16,
      "y": 4,
      "z": 7,
      "name": "Wood_Oak_Trunk",
      "support": 15,
      "rotation": 5
    },
    {
      "x": -16,
      "y": 6,
      "z": 7,
      "name": "Wood_Softwood_Stairs",
      "rotation": 9
    },
    {
      "x": -16,
      "y": 7,
      "z": 7,
      "name": "Wood_Softwood_Roof_Steep",
      "rotation": 1
    },
    {
      "x": -16,
      "y": 8,
      "z": 7,
      "name": "Wood_Softwood_Roof_Steep",
      "filler": 1024,
      "rotation": 1
    },
    {
      "x": -16,
      "y": 0,
      "z": 8,
      "name": "Rock_Stone_Cobble"
    },
    {
      "x": -16,
      "y": 1,
      "z": 8,
      "name": "Rock_Stone_Brick"
    },
    {
      "x": -16,
      "y": 2,
      "z": 8,
      "name": "Furniture_Tavern_Window"
    },
    {
      "x": -16,
      "y": 3,
      "z": 8,
      "name": "Furniture_Tavern_Window"
    },
    {
      "x": -16,
      "y": 4,
      "z": 8,
      "name": "Wood_Softwood_Planks"
    },
    {
      "x": -16,
      "y": 5,
      "z": 8,
      "name": "Rock_Quartzite"
    },
    {
      "x": -16,
      "y": 6,
      "z": 8,
      "name": "Rock_Quartzite"
    },
    {
      "x": -16,
      "y": 7,
      "z": 8,
      "name": "*Wood_Softwood_Roof_Steep_State_Definitions_Inverted_Corner_Right",
      "rotation": 2
    },
    {
      "x": -16,
      "y": 8,
      "z": 8,
      "name": "*Wood_Softwood_Roof_Steep_State_Definitions_Inverted_Corner_Right",
      "filler": 1024,
      "rotation": 2
    },
    {
      "x": -16,
      "y": 0,
      "z": 9,
      "name": "Wood_Softwood_Planks"
    },
    {
      "x": -16,
      "y": 1,
      "z": 9,
      "name": "*Furniture_Tavern_Chest_Large_State_Definitions_CloseWindow",
      "filler": 31
    },
    {
      "x": -16,
      "y": 4,
      "z": 9,
      "name": "Wood_Softwood_Planks"
    },
    {
      "x": -16,
      "y": 5,
      "z": 9,
      "name": "Furniture_Village_Crate"
    },
    {
      "x": -16,
      "y": 6,
      "z": 9,
      "name": "Furniture_Village_Crate"
    },
    {
      "x": -16,
      "y": 8,
      "z": 9,
      "name": "Wood_Softwood_Planks"
    },
    {
      "x": -16,
      "y": 9,
      "z": 9,
      "name": "Wood_Softwood_Roof",
      "rotation": 2
    },
    {
      "x": -16,
      "y": 0,
      "z": 10,
      "name": "Wood_Softwood_Planks"
    },
    {
      "x": -16,
      "y": 4,
      "z": 10,
      "name": "Wood_Softwood_Planks"
    },
    {
      "x": -16,
      "y": 5,
      "z": 10,
      "name": "Furniture_Tavern_Barrel"
    },
    {
      "x": -16,
      "y": 8,
      "z": 10,
      "name": "Wood_Softwood_Planks"
    },
    {
      "x": -16,
      "y": 10,
      "z": 10,
      "name": "Wood_Softwood_Roof_Hollow",
      "rotation": 2
    },
    {
      "x": -16,
      "y": 0,
      "z": 11,
      "name": "Wood_Softwood_Planks"
    },
    {
      "x": -16,
      "y": 4,
      "z": 11,
      "name": "Wood_Softwood_Planks"
    },
    {
      "x": -16,
      "y": 8,
      "z": 11,
      "name": "Wood_Softwood_Planks"
    },
    {
      "x": -16,
      "y": 11,
      "z": 11,
      "name": "Wood_Softwood_Planks_Half"
    },
    {
      "x": -16,
      "y": 0,
      "z": 12,
      "name": "Wood_Softwood_Planks"
    },
    {
      "x": -16,
      "y": 1,
      "z": 12,
      "name": "Furniture_Village_Chair"
    },
    {
      "x": -16,
      "y": 2,
      "z": 12,
      "name": "Furniture_Village_Chair",
      "filler": 1024
    },
    {
      "x": -16,
      "y": 4,
      "z": 12,
      "name": "Wood_Softwood_Planks"
    },
    {
      "x": -16,
      "y": 8,
      "z": 12,
      "name": "Wood_Softwood_Planks"
    },
    {
      "x": -16,
      "y": 10,
      "z": 12,
      "name": "Wood_Softwood_Roof_Hollow"
    },
    {
      "x": -16,
      "y": 0,
      "z": 13,
      "name": "Wood_Softwood_Planks"
    },
    {
      "x": -16,
      "y": 1,
      "z": 13,
      "name": "Aetherhaven_Town_Planning_Desk",
      "filler": 1,
      "rotation": 2
    },
    {
      "x": -16,
      "y": 4,
      "z": 13,
      "name": "Wood_Softwood_Planks"
    },
    {
      "x": -16,
      "y": 8,
      "z": 13,
      "name": "Wood_Softwood_Planks"
    },
    {
      "x": -16,
      "y": 9,
      "z": 13,
      "name": "Wood_Softwood_Roof"
    },
    {
      "x": -16,
      "y": 0,
      "z": 14,
      "name": "Rock_Stone_Cobble"
    },
    {
      "x": -16,
      "y": 1,
      "z": 14,
      "name": "Rock_Stone_Brick"
    },
    {
      "x": -16,
      "y": 2,
      "z": 14,
      "name": "Furniture_Tavern_Window"
    },
    {
      "x": -16,
      "y": 3,
      "z": 14,
      "name": "Furniture_Tavern_Window"
    },
    {
      "x": -16,
      "y": 4,
      "z": 14,
      "name": "Wood_Softwood_Planks"
    },
    {
      "x": -16,
      "y": 5,
      "z": 14,
      "name": "Rock_Quartzite"
    },
    {
      "x": -16,
      "y": 6,
      "z": 14,
      "name": "Rock_Quartzite"
    },
    {
      "x": -16,
      "y": 7,
      "z": 14,
      "name": "Wood_Softwood_Roof_Steep"
    },
    {
      "x": -16,
      "y": 8,
      "z": 14,
      "name": "Wood_Softwood_Roof_Steep",
      "filler": 1024
    },
    {
      "x": -16,
      "y": 4,
      "z": 15,
      "name": "Wood_Oak_Trunk",
      "support": 15,
      "rotation": 5
    },
    {
      "x": -16,
      "y": 5,
      "z": 15,
      "name": "Wood_Softwood_Roof_Steep"
    },
    {
      "x": -16,
      "y": 6,
      "z": 15,
      "name": "Wood_Softwood_Roof_Steep",
      "filler": 1024
    },
    {
      "x": -16,
      "y": 4,
      "z": 16,
      "name": "Wood_Softwood_Roof_Hollow"
    },
    {
      "x": -15,
      "y": 4,
      "z": 2,
      "name": "Wood_Softwood_Roof_Hollow",
      "rotation": 3
    },
    {
      "x": -15,
      "y": 4,
      "z": 3,
      "name": "Wood_Softwood_Roof_Hollow",
      "rotation": 3
    },
    {
      "x": -15,
      "y": 4,
      "z": 4,
      "name": "Wood_Softwood_Roof_Hollow",
      "rotation": 3
    },
    {
      "x": -15,
      "y": 4,
      "z": 5,
      "name": "Wood_Softwood_Roof_Hollow",
      "rotation": 3
    },
    {
      "x": -15,
      "y": 4,
      "z": 6,
      "name": "*Wood_Softwood_Roof_Hollow_State_Definitions_Inverted_Corner_Right",
      "rotation": 3
    },
    {
      "x": -15,
      "y": 4,
      "z": 7,
      "name": "Wood_Oak_Trunk",
      "support": 15,
      "rotation": 5
    },
    {
      "x": -15,
      "y": 5,
      "z": 7,
      "name": "*Wood_Softwood_Roof_Steep_State_Definitions_Inverted_Corner_Left",
      "rotation": 1
    },
    {
      "x": -15,
      "y": 6,
      "z": 7,
      "name": "*Wood_Softwood_Roof_Steep_State_Definitions_Inverted_Corner_Left",
      "filler": 1024,
      "rotation": 1
    },
    {
      "x": -15,
      "y": 0,
      "z": 8,
      "name": "Rock_Stone_Cobble"
    },
    {
      "x": -15,
      "y": 1,
      "z": 8,
      "name": "Rock_Stone_Brick"
    },
    {
      "x": -15,
      "y": 2,
      "z": 8,
      "name": "Rock_Quartzite"
    },
    {
      "x": -15,
      "y": 3,
      "z": 8,
      "name": "Rock_Quartzite"
    },
    {
      "x": -15,
      "y": 4,
      "z": 8,
      "name": "Wood_Softwood_Planks"
    },
    {
      "x": -15,
      "y": 5,
      "z": 8,
      "name": "Rock_Quartzite"
    },
    {
      "x": -15,
      "y": 6,
      "z": 8,
      "name": "Rock_Quartzite"
    },
    {
      "x": -15,
      "y": 7,
      "z": 8,
      "name": "Wood_Softwood_Roof_Steep",
      "rotation": 2
    },
    {
      "x": -15,
      "y": 8,
      "z": 8,
      "name": "Wood_Softwood_Roof_Steep",
      "filler": 1024,
      "rotation": 2
    },
    {
      "x": -15,
      "y": 0,
      "z": 9,
      "name": "Wood_Softwood_Planks"
    },
    {
      "x": -15,
      "y": 1,
      "z": 9,
      "name": "*Furniture_Tavern_Chest_Large_State_Definitions_CloseWindow",
      "components": {
        "Components": {
          "ItemContainerBlock": {
            "ItemContainer": {
              "Capacity": 36,
              "Items": {}
            },
            "Capacity": 36
          }
        }
      }
    },
    {
      "x": -15,
      "y": 4,
      "z": 9,
      "name": "Wood_Softwood_Planks"
    },
    {
      "x": -15,
      "y": 5,
      "z": 9,
      "name": "Furniture_Village_Crate"
    },
    {
      "x": -15,
      "y": 6,
      "z": 9,
      "name": "Furniture_Tavern_Barrel"
    },
    {
      "x": -15,
      "y": 8,
      "z": 9,
      "name": "Wood_Softwood_Planks"
    },
    {
      "x": -15,
      "y": 9,
      "z": 9,
      "name": "Wood_Softwood_Roof",
      "rotation": 2
    },
    {
      "x": -15,
      "y": 0,
      "z": 10,
      "name": "Wood_Softwood_Planks"
    },
    {
      "x": -15,
      "y": 4,
      "z": 10,
      "name": "Wood_Softwood_Planks"
    },
    {
      "x": -15,
      "y": 5,
      "z": 10,
      "name": "Furniture_Village_Crate"
    },
    {
      "x": -15,
      "y": 8,
      "z": 10,
      "name": "Wood_Softwood_Planks"
    },
    {
      "x": -15,
      "y": 10,
      "z": 10,
      "name": "Wood_Softwood_Roof_Hollow",
      "rotation": 2
    },
    {
      "x": -15,
      "y": 0,
      "z": 11,
      "name": "Wood_Softwood_Planks"
    },
    {
      "x": -15,
      "y": 4,
      "z": 11,
      "name": "Wood_Softwood_Planks"
    },
    {
      "x": -15,
      "y": 8,
      "z": 11,
      "name": "Wood_Softwood_Planks"
    },
    {
      "x": -15,
      "y": 11,
      "z": 11,
      "name": "Wood_Softwood_Planks_Half"
    },
    {
      "x": -15,
      "y": 0,
      "z": 12,
      "name": "Wood_Softwood_Planks"
    },
    {
      "x": -15,
      "y": 1,
      "z": 12,
      "name": "Furniture_Village_Counter",
      "filler": 992,
      "rotation": 3
    },
    {
      "x": -15,
      "y": 4,
      "z": 12,
      "name": "Wood_Softwood_Planks"
    },
    {
      "x": -15,
      "y": 8,
      "z": 12,
      "name": "Wood_Softwood_Planks"
    },
    {
      "x": -15,
      "y": 10,
      "z": 12,
      "name": "Wood_Softwood_Roof_Hollow"
    },
    {
      "x": -15,
      "y": 0,
      "z": 13,
      "name": "Wood_Softwood_Planks"
    },
    {
      "x": -15,
      "y": 1,
      "z": 13,
      "name": "Furniture_Village_Counter",
      "rotation": 3
    },
    {
      "x": -15,
      "y": 4,
      "z": 13,
      "name": "Wood_Softwood_Planks"
    },
    {
      "x": -15,
      "y": 5,
      "z": 13,
      "name": "Furniture_Village_Crate"
    },
    {
      "x": -15,
      "y": 8,
      "z": 13,
      "name": "Wood_Softwood_Planks"
    },
    {
      "x": -15,
      "y": 9,
      "z": 13,
      "name": "Wood_Softwood_Roof"
    },
    {
      "x": -15,
      "y": 0,
      "z": 14,
      "name": "Rock_Stone_Cobble"
    },
    {
      "x": -15,
      "y": 1,
      "z": 14,
      "name": "Rock_Stone_Brick"
    },
    {
      "x": -15,
      "y": 2,
      "z": 14,
      "name": "Rock_Quartzite"
    },
    {
      "x": -15,
      "y": 3,
      "z": 14,
      "name": "Rock_Quartzite"
    },
    {
      "x": -15,
      "y": 4,
      "z": 14,
      "name": "Wood_Softwood_Planks"
    },
    {
      "x": -15,
      "y": 5,
      "z": 14,
      "name": "Rock_Quartzite"
    },
    {
      "x": -15,
      "y": 6,
      "z": 14,
      "name": "Rock_Quartzite"
    },
    {
      "x": -15,
      "y": 7,
      "z": 14,
      "name": "Wood_Softwood_Roof_Steep"
    },
    {
      "x": -15,
      "y": 8,
      "z": 14,
      "name": "Wood_Softwood_Roof_Steep",
      "filler": 1024
    },
    {
      "x": -15,
      "y": 4,
      "z": 15,
      "name": "Wood_Oak_Trunk",
      "support": 15,
      "rotation": 5
    },
    {
      "x": -15,
      "y": 5,
      "z": 15,
      "name": "Wood_Softwood_Roof_Steep"
    },
    {
      "x": -15,
      "y": 6,
      "z": 15,
      "name": "Wood_Softwood_Roof_Steep",
      "filler": 1024
    },
    {
      "x": -15,
      "y": 4,
      "z": 16,
      "name": "Wood_Softwood_Roof_Hollow"
    },
    {
      "x": -14,
      "y": 4,
      "z": 2,
      "name": "Wood_Oak_Branch_Short",
      "support": 15,
      "rotation": 2
    },
    {
      "x": -14,
      "y": 5,
      "z": 2,
      "name": "Wood_Softwood_Roof_Shallow",
      "rotation": 3
    },
    {
      "x": -14,
      "y": 0,
      "z": 3,
      "name": "Rock_Stone_Cobble"
    },
    {
      "x": -14,
      "y": 1,
      "z": 3,
      "name": "Wood_Oak_Trunk",
      "support": 15
    },
    {
      "x": -14,
      "y": 2,
      "z": 3,
      "name": "Wood_Oak_Trunk",
      "support": 15
    },
    {
      "x": -14,
      "y": 3,
      "z": 3,
      "name": "Wood_Oak_Trunk",
      "support": 15
    },
    {
      "x": -14,
      "y": 4,
      "z": 3,
      "name": "Wood_Oak_Trunk",
      "support": 15
    },
    {
      "x": -14,
      "y": 5,
      "z": 3,
      "name": "Wood_Softwood_Roof_Shallow",
      "rotation": 3
    },
    {
      "x": -14,
      "y": 4,
      "z": 4,
      "name": "Wood_Oak_Trunk",
      "support": 15,
      "rotation": 4
    },
    {
      "x": -14,
      "y": 5,
      "z": 4,
      "name": "Wood_Softwood_Roof_Shallow",
      "rotation": 3
    },
    {
      "x": -14,
      "y": 4,
      "z": 5,
      "name": "Wood_Oak_Trunk",
      "support": 15,
      "rotation": 4
    },
    {
      "x": -14,
      "y": 5,
      "z": 5,
      "name": "Wood_Softwood_Roof_Shallow",
      "rotation": 3
    },
    {
      "x": -14,
      "y": 4,
      "z": 6,
      "name": "Wood_Oak_Trunk",
      "support": 15,
      "rotation": 4
    },
    {
      "x": -14,
      "y": 5,
      "z": 6,
      "name": "Wood_Softwood_Roof_Shallow",
      "rotation": 3
    },
    {
      "x": -14,
      "y": 0,
      "z": 7,
      "name": "Rock_Stone_Cobble"
    },
    {
      "x": -14,
      "y": 1,
      "z": 7,
      "name": "Wood_Oak_Trunk",
      "support": 15
    },
    {
      "x": -14,
      "y": 2,
      "z": 7,
      "name": "Wood_Oak_Trunk",
      "support": 15
    },
    {
      "x": -14,
      "y": 3,
      "z": 7,
      "name": "Wood_Oak_Trunk",
      "support": 15
    },
    {
      "x": -14,
      "y": 4,
      "z": 7,
      "name": "Wood_Oak_Trunk",
      "support": 15
    },
    {
      "x": -14,
      "y": 5,
      "z": 7,
      "name": "Wood_Softwood_Roof_Steep",
      "rotation": 2
    },
    {
      "x": -14,
      "y": 6,
      "z": 7,
      "name": "Wood_Softwood_Roof_Steep",
      "filler": 1024,
      "rotation": 2
    },
    {
      "x": -14,
      "y": 0,
      "z": 8,
      "name": "Rock_Stone_Cobble"
    },
    {
      "x": -14,
      "y": 1,
      "z": 8,
      "name": "Wood_Oak_Trunk",
      "support": 15
    },
    {
      "x": -14,
      "y": 2,
      "z": 8,
      "name": "Wood_Oak_Trunk",
      "support": 15
    },
    {
      "x": -14,
      "y": 3,
      "z": 8,
      "name": "Wood_Oak_Trunk",
      "support": 15
    },
    {
      "x": -14,
      "y": 4,
      "z": 8,
      "name": "Wood_Softwood_Planks"
    },
    {
      "x": -14,
      "y": 5,
      "z": 8,
      "name": "Rock_Quartzite"
    },
    {
      "x": -14,
      "y": 6,
      "z": 8,
      "name": "Rock_Quartzite"
    },
    {
      "x": -14,
      "y": 7,
      "z": 8,
      "name": "Wood_Softwood_Roof_Steep",
      "rotation": 2
    },
    {
      "x": -14,
      "y": 8,
      "z": 8,
      "name": "Wood_Softwood_Roof_Steep",
      "filler": 1024,
      "rotation": 2
    },
    {
      "x": -14,
      "y": 0,
      "z": 9,
      "name": "Wood_Softwood_Planks"
    },
    {
      "x": -14,
      "y": 1,
      "z": 9,
      "name": "Rock_Stone_Brick"
    },
    {
      "x": -14,
      "y": 2,
      "z": 9,
      "name": "Rock_Quartzite"
    },
    {
      "x": -14,
      "y": 3,
      "z": 9,
      "name": "Rock_Quartzite"
    },
    {
      "x": -14,
      "y": 4,
      "z": 9,
      "name": "Wood_Softwood_Planks"
    },
    {
      "x": -14,
      "y": 5,
      "z": 9,
      "name": "Furniture_Village_Crate"
    },
    {
      "x": -14,
      "y": 8,
      "z": 9,
      "name": "Wood_Softwood_Planks"
    },
    {
      "x": -14,
      "y": 9,
      "z": 9,
      "name": "Wood_Softwood_Roof",
      "rotation": 2
    },
    {
      "x": -14,
      "y": 0,
      "z": 10,
      "name": "Wood_Softwood_Planks"
    },
    {
      "x": -14,
      "y": 1,
      "z": 10,
      "name": "*Furniture_Village_Door_State_Definitions_CloseDoorIn",
      "rotation": 1
    },
    {
      "x": -14,
      "y": 2,
      "z": 10,
      "name": "*Furniture_Village_Door_State_Definitions_CloseDoorIn",
      "filler": 1024,
      "rotation": 1
    },
    {
      "x": -14,
      "y": 3,
      "z": 10,
      "name": "Rock_Quartzite"
    },
    {
      "x": -14,
      "y": 4,
      "z": 10,
      "name": "Wood_Softwood_Planks"
    },
    {
      "x": -14,
      "y": 8,
      "z": 10,
      "name": "Wood_Softwood_Planks"
    },
    {
      "x": -14,
      "y": 10,
      "z": 10,
      "name": "Wood_Softwood_Roof_Hollow",
      "rotation": 2
    },
    {
      "x": -14,
      "y": 0,
      "z": 11,
      "name": "Wood_Softwood_Planks"
    },
    {
      "x": -14,
      "y": 1,
      "z": 11,
      "name": "Wood_Oak_Trunk",
      "support": 15
    },
    {
      "x": -14,
      "y": 2,
      "z": 11,
      "name": "Wood_Oak_Trunk",
      "support": 15
    },
    {
      "x": -14,
      "y": 3,
      "z": 11,
      "name": "Wood_Oak_Trunk",
      "support": 15
    },
    {
      "x": -14,
      "y": 4,
      "z": 11,
      "name": "Wood_Softwood_Planks"
    },
    {
      "x": -14,
      "y": 8,
      "z": 11,
      "name": "Wood_Softwood_Planks"
    },
    {
      "x": -14,
      "y": 11,
      "z": 11,
      "name": "Wood_Softwood_Planks_Half"
    },
    {
      "x": -14,
      "y": 0,
      "z": 12,
      "name": "Wood_Softwood_Planks"
    },
    {
      "x": -14,
      "y": 1,
      "z": 12,
      "name": "Rock_Stone_Brick"
    },
    {
      "x": -14,
      "y": 2,
      "z": 12,
      "name": "Rock_Quartzite"
    },
    {
      "x": -14,
      "y": 3,
      "z": 12,
      "name": "Rock_Quartzite"
    },
    {
      "x": -14,
      "y": 4,
      "z": 12,
      "name": "Wood_Softwood_Planks"
    },
    {
      "x": -14,
      "y": 5,
      "z": 12,
      "name": "Furniture_Tavern_Barrel"
    },
    {
      "x": -14,
      "y": 8,
      "z": 12,
      "name": "Wood_Softwood_Planks"
    },
    {
      "x": -14,
      "y": 10,
      "z": 12,
      "name": "Wood_Softwood_Roof_Hollow"
    },
    {
      "x": -14,
      "y": 0,
      "z": 13,
      "name": "Wood_Softwood_Planks"
    },
    {
      "x": -14,
      "y": 1,
      "z": 13,
      "name": "Rock_Stone_Brick"
    },
    {
      "x": -14,
      "y": 2,
      "z": 13,
      "name": "Rock_Quartzite"
    },
    {
      "x": -14,
      "y": 3,
      "z": 13,
      "name": "Rock_Quartzite"
    },
    {
      "x": -14,
      "y": 4,
      "z": 13,
      "name": "Wood_Softwood_Planks"
    },
    {
      "x": -14,
      "y": 5,
      "z": 13,
      "name": "Furniture_Village_Crate"
    },
    {
      "x": -14,
      "y": 6,
      "z": 13,
      "name": "Furniture_Village_Crate"
    },
    {
      "x": -14,
      "y": 8,
      "z": 13,
      "name": "Wood_Softwood_Planks"
    },
    {
      "x": -14,
      "y": 9,
      "z": 13,
      "name": "Wood_Softwood_Roof"
    },
    {
      "x": -14,
      "y": 0,
      "z": 14,
      "name": "Rock_Stone_Cobble"
    },
    {
      "x": -14,
      "y": 1,
      "z": 14,
      "name": "Wood_Oak_Trunk",
      "support": 15
    },
    {
      "x": -14,
      "y": 2,
      "z": 14,
      "name": "Wood_Oak_Trunk",
      "support": 15
    },
    {
      "x": -14,
      "y": 3,
      "z": 14,
      "name": "Wood_Oak_Trunk",
      "support": 15
    },
    {
      "x": -14,
      "y": 4,
      "z": 14,
      "name": "Wood_Softwood_Planks"
    },
    {
      "x": -14,
      "y": 5,
      "z": 14,
      "name": "Rock_Quartzite"
    },
    {
      "x": -14,
      "y": 6,
      "z": 14,
      "name": "Rock_Quartzite"
    },
    {
      "x": -14,
      "y": 7,
      "z": 14,
      "name": "Wood_Softwood_Roof_Steep"
    },
    {
      "x": -14,
      "y": 8,
      "z": 14,
      "name": "Wood_Softwood_Roof_Steep",
      "filler": 1024
    },
    {
      "x": -14,
      "y": 0,
      "z": 15,
      "name": "Rock_Stone_Cobble"
    },
    {
      "x": -14,
      "y": 1,
      "z": 15,
      "name": "Wood_Oak_Trunk",
      "support": 15
    },
    {
      "x": -14,
      "y": 2,
      "z": 15,
      "name": "Wood_Oak_Trunk",
      "support": 15
    },
    {
      "x": -14,
      "y": 3,
      "z": 15,
      "name": "Wood_Oak_Trunk",
      "support": 15
    },
    {
      "x": -14,
      "y": 4,
      "z": 15,
      "name": "Wood_Oak_Trunk",
      "support": 15
    },
    {
      "x": -14,
      "y": 5,
      "z": 15,
      "name": "Wood_Softwood_Roof_Steep"
    },
    {
      "x": -14,
      "y": 6,
      "z": 15,
      "name": "Wood_Softwood_Roof_Steep",
      "filler": 1024
    },
    {
      "x": -14,
      "y": 4,
      "z": 16,
      "name": "Wood_Softwood_Roof_Hollow"
    },
    {
      "x": -13,
      "y": 5,
      "z": 2,
      "name": "Wood_Softwood_Roof_Shallow",
      "filler": 1,
      "rotation": 3
    },
    {
      "x": -13,
      "y": 4,
      "z": 3,
      "name": "Wood_Oak_Trunk",
      "support": 15,
      "rotation": 5
    },
    {
      "x": -13,
      "y": 5,
      "z": 3,
      "name": "Wood_Softwood_Roof_Shallow",
      "filler": 1,
      "rotation": 3
    },
    {
      "x": -13,
      "y": 0,
      "z": 4,
      "name": "Rock_Stone_Cobble"
    },
    {
      "x": -13,
      "y": 1,
      "z": 4,
      "name": "Rock_Stone_Brick"
    },
    {
      "x": -13,
      "y": 2,
      "z": 4,
      "name": "Rock_Quartzite"
    },
    {
      "x": -13,
      "y": 3,
      "z": 4,
      "name": "Rock_Quartzite"
    },
    {
      "x": -13,
      "y": 4,
      "z": 4,
      "name": "Wood_Softwood_Planks"
    },
    {
      "x": -13,
      "y": 5,
      "z": 4,
      "name": "Wood_Softwood_Roof_Shallow",
      "filler": 1,
      "rotation": 3
    },
    {
      "x": -13,
      "y": 0,
      "z": 5,
      "name": "Rock_Stone_Cobble"
    },
    {
      "x": -13,
      "y": 1,
      "z": 5,
      "name": "Rock_Stone_Brick"
    },
    {
      "x": -13,
      "y": 2,
      "z": 5,
      "name": "Rock_Quartzite"
    },
    {
      "x": -13,
      "y": 3,
      "z": 5,
      "name": "Rock_Quartzite"
    },
    {
      "x": -13,
      "y": 4,
      "z": 5,
      "name": "Wood_Softwood_Planks"
    },
    {
      "x": -13,
      "y": 5,
      "z": 5,
      "name": "Wood_Softwood_Roof_Shallow",
      "filler": 1,
      "rotation": 3
    },
    {
      "x": -13,
      "y": 0,
      "z": 6,
      "name": "Rock_Stone_Cobble"
    },
    {
      "x": -13,
      "y": 1,
      "z": 6,
      "name": "Rock_Stone_Brick"
    },
    {
      "x": -13,
      "y": 2,
      "z": 6,
      "name": "Rock_Quartzite"
    },
    {
      "x": -13,
      "y": 3,
      "z": 6,
      "name": "Rock_Quartzite"
    },
    {
      "x": -13,
      "y": 4,
      "z": 6,
      "name": "Wood_Softwood_Planks"
    },
    {
      "x": -13,
      "y": 5,
      "z": 6,
      "name": "Wood_Softwood_Roof_Shallow",
      "filler": 1,
      "rotation": 3
    },
    {
      "x": -13,
      "y": 0,
      "z": 7,
      "name": "Rock_Stone_Cobble"
    },
    {
      "x": -13,
      "y": 1,
      "z": 7,
      "name": "Wood_Oak_Trunk",
      "support": 15
    },
    {
      "x": -13,
      "y": 2,
      "z": 7,
      "name": "Wood_Oak_Trunk",
      "support": 15
    },
    {
      "x": -13,
      "y": 3,
      "z": 7,
      "name": "Wood_Oak_Trunk",
      "support": 15
    },
    {
      "x": -13,
      "y": 4,
      "z": 7,
      "name": "Wood_Softwood_Planks"
    },
    {
      "x": -13,
      "y": 5,
      "z": 7,
      "name": "Wood_Softwood_Roof_Steep",
      "rotation": 2
    },
    {
      "x": -13,
      "y": 6,
      "z": 7,
      "name": "Wood_Softwood_Roof_Steep",
      "filler": 1024,
      "rotation": 2
    },
    {
      "x": -13,
      "y": 0,
      "z": 8,
      "name": "Wood_Softwood_Planks"
    },
    {
      "x": -13,
      "y": 1,
      "z": 8,
      "name": "Furniture_Tavern_Wardrobe",
      "rotation": 1
    },
    {
      "x": -13,
      "y": 2,
      "z": 8,
      "name": "Furniture_Tavern_Wardrobe",
      "filler": 1024,
      "rotation": 1
    },
    {
      "x": -13,
      "y": 3,
      "z": 8,
      "name": "Deco_Book_Pile_Small",
      "rotation": 1
    },
    {
      "x": -13,
      "y": 4,
      "z": 8,
      "name": "Wood_Softwood_Planks"
    },
    {
      "x": -13,
      "y": 5,
      "z": 8,
      "name": "Rock_Quartzite"
    },
    {
      "x": -13,
      "y": 6,
      "z": 8,
      "name": "Rock_Quartzite"
    },
    {
      "x": -13,
      "y": 7,
      "z": 8,
      "name": "Wood_Softwood_Roof_Steep",
      "rotation": 2
    },
    {
      "x": -13,
      "y": 8,
      "z": 8,
      "name": "Wood_Softwood_Roof_Steep",
      "filler": 1024,
      "rotation": 2
    },
    {
      "x": -13,
      "y": 0,
      "z": 9,
      "name": "Wood_Softwood_Planks"
    },
    {
      "x": -13,
      "y": 1,
      "z": 9,
      "name": "Furniture_Tavern_Wardrobe",
      "filler": 32,
      "rotation": 1
    },
    {
      "x": -13,
      "y": 2,
      "z": 9,
      "name": "Furniture_Tavern_Wardrobe",
      "filler": 1056,
      "rotation": 1
    },
    {
      "x": -13,
      "y": 4,
      "z": 9,
      "name": "Wood_Softwood_Planks"
    },
    {
      "x": -13,
      "y": 5,
      "z": 9,
      "name": "Ingredient_Flour"
    },
    {
      "x": -13,
      "y": 8,
      "z": 9,
      "name": "Wood_Softwood_Planks"
    },
    {
      "x": -13,
      "y": 9,
      "z": 9,
      "name": "Wood_Softwood_Roof",
      "rotation": 2
    },
    {
      "x": -13,
      "y": 0,
      "z": 10,
      "name": "Wood_Softwood_Planks"
    },
    {
      "x": -13,
      "y": 4,
      "z": 10,
      "name": "Wood_Softwood_Planks"
    },
    {
      "x": -13,
      "y": 8,
      "z": 10,
      "name": "Wood_Softwood_Planks"
    },
    {
      "x": -13,
      "y": 10,
      "z": 10,
      "name": "Wood_Softwood_Roof_Hollow",
      "rotation": 2
    },
    {
      "x": -13,
      "y": 0,
      "z": 11,
      "name": "Wood_Softwood_Planks"
    },
    {
      "x": -13,
      "y": 1,
      "z": 11,
      "name": "Furniture_Village_Stool",
      "rotation": 1
    },
    {
      "x": -13,
      "y": 2,
      "z": 11,
      "name": "Wood_Torch_Wall",
      "rotation": 1
    },
    {
      "x": -13,
      "y": 4,
      "z": 11,
      "name": "Wood_Softwood_Planks"
    },
    {
      "x": -13,
      "y": 8,
      "z": 11,
      "name": "Wood_Softwood_Planks"
    },
    {
      "x": -13,
      "y": 11,
      "z": 11,
      "name": "Wood_Softwood_Planks_Half"
    },
    {
      "x": -13,
      "y": 0,
      "z": 12,
      "name": "Wood_Softwood_Planks"
    },
    {
      "x": -13,
      "y": 1,
      "z": 12,
      "name": "*Furniture_Tavern_Chest_Large_State_Definitions_CloseWindow",
      "components": {
        "Components": {
          "PlacedByInteraction": {
            "WhoPlacedUuid": {
              "$binary": "gqJcCRGLSleXtmq6BvFR8g==",
              "$type": "04"
            }
          },
          "ItemContainerBlock": {
            "ItemContainer": {
              "Capacity": 36,
              "Items": {}
            },
            "Capacity": 36
          }
        }
      },
      "rotation": 1
    },
    {
      "x": -13,
      "y": 2,
      "z": 12,
      "name": "Furniture_Village_Painting_1x1",
      "rotation": 1
    },
    {
      "x": -13,
      "y": 4,
      "z": 12,
      "name": "Wood_Softwood_Planks"
    },
    {
      "x": -13,
      "y": 5,
      "z": 12,
      "name": "Furniture_Tavern_Barrel"
    },
    {
      "x": -13,
      "y": 8,
      "z": 12,
      "name": "Wood_Softwood_Planks"
    },
    {
      "x": -13,
      "y": 10,
      "z": 12,
      "name": "Wood_Softwood_Roof_Hollow"
    },
    {
      "x": -13,
      "y": 0,
      "z": 13,
      "name": "Wood_Softwood_Planks"
    },
    {
      "x": -13,
      "y": 1,
      "z": 13,
      "name": "*Furniture_Tavern_Chest_Large_State_Definitions_CloseWindow",
      "filler": 32,
      "rotation": 1
    },
    {
      "x": -13,
      "y": 2,
      "z": 13,
      "name": "Furniture_Village_Painting_1x1",
      "rotation": 1
    },
    {
      "x": -13,
      "y": 4,
      "z": 13,
      "name": "Wood_Softwood_Planks"
    },
    {
      "x": -13,
      "y": 5,
      "z": 13,
      "name": "Furniture_Village_Crate"
    },
    {
      "x": -13,
      "y": 6,
      "z": 13,
      "name": "Wood_Torch_Wall",
      "rotation": 2
    },
    {
      "x": -13,
      "y": 8,
      "z": 13,
      "name": "Wood_Softwood_Planks"
    },
    {
      "x": -13,
      "y": 9,
      "z": 13,
      "name": "Wood_Softwood_Roof"
    },
    {
      "x": -13,
      "y": 0,
      "z": 14,
      "name": "Rock_Stone_Cobble"
    },
    {
      "x": -13,
      "y": 1,
      "z": 14,
      "name": "Rock_Stone_Brick"
    },
    {
      "x": -13,
      "y": 2,
      "z": 14,
      "name": "Rock_Quartzite"
    },
    {
      "x": -13,
      "y": 3,
      "z": 14,
      "name": "Rock_Quartzite"
    },
    {
      "x": -13,
      "y": 4,
      "z": 14,
      "name": "Wood_Softwood_Planks"
    },
    {
      "x": -13,
      "y": 5,
      "z": 14,
      "name": "Wood_Oak_Trunk",
      "support": 15
    },
    {
      "x": -13,
      "y": 6,
      "z": 14,
      "name": "Wood_Oak_Trunk",
      "support": 15
    },
    {
      "x": -13,
      "y": 7,
      "z": 14,
      "name": "Wood_Softwood_Roof_Steep"
    },
    {
      "x": -13,
      "y": 8,
      "z": 14,
      "name": "Wood_Softwood_Roof_Steep",
      "filler": 1024
    },
    {
      "x": -13,
      "y": 4,
      "z": 15,
      "name": "Wood_Oak_Trunk",
      "support": 15,
      "rotation": 5
    },
    {
      "x": -13,
      "y": 5,
      "z": 15,
      "name": "Wood_Softwood_Roof_Steep"
    },
    {
      "x": -13,
      "y": 6,
      "z": 15,
      "name": "Wood_Softwood_Roof_Steep",
      "filler": 1024
    },
    {
      "x": -13,
      "y": 4,
      "z": 16,
      "name": "Wood_Softwood_Roof_Hollow"
    },
    {
      "x": -12,
      "y": 5,
      "z": 2,
      "name": "Wood_Softwood_Stairs",
      "rotation": 11
    },
    {
      "x": -12,
      "y": 6,
      "z": 2,
      "name": "Wood_Softwood_Roof_Shallow",
      "rotation": 3
    },
    {
      "x": -12,
      "y": 4,
      "z": 3,
      "name": "Wood_Oak_Trunk",
      "support": 15,
      "rotation": 5
    },
    {
      "x": -12,
      "y": 5,
      "z": 3,
      "name": "Wood_Softwood_Stairs",
      "rotation": 11
    },
    {
      "x": -12,
      "y": 6,
      "z": 3,
      "name": "Wood_Softwood_Roof_Shallow",
      "rotation": 3
    },
    {
      "x": -12,
      "y": 0,
      "z": 4,
      "name": "Rock_Stone_Cobble"
    },
    {
      "x": -12,
      "y": 1,
      "z": 4,
      "name": "Rock_Stone_Brick"
    },
    {
      "x": -12,
      "y": 2,
      "z": 4,
      "name": "Furniture_Tavern_Window"
    },
    {
      "x": -12,
      "y": 3,
      "z": 4,
      "name": "Furniture_Tavern_Window"
    },
    {
      "x": -12,
      "y": 4,
      "z": 4,
      "name": "Wood_Softwood_Planks"
    },
    {
      "x": -12,
      "y": 5,
      "z": 4,
      "name": "Rock_Quartzite"
    },
    {
      "x": -12,
      "y": 6,
      "z": 4,
      "name": "Wood_Softwood_Roof_Shallow",
      "rotation": 3
    },
    {
      "x": -12,
      "y": 0,
      "z": 5,
      "name": "Wood_Softwood_Planks"
    },
    {
      "x": -12,
      "y": 1,
      "z": 5,
      "name": "Furniture_Village_Pot"
    },
    {
      "x": -12,
      "y": 4,
      "z": 5,
      "name": "Wood_Softwood_Planks"
    },
    {
      "x": -12,
      "y": 6,
      "z": 5,
      "name": "Wood_Softwood_Roof_Shallow",
      "rotation": 3
    },
    {
      "x": -12,
      "y": 0,
      "z": 6,
      "name": "Wood_Softwood_Planks"
    },
    {
      "x": -12,
      "y": 1,
      "z": 6,
      "name": "Furniture_Tavern_Barrel"
    },
    {
      "x": -12,
      "y": 4,
      "z": 6,
      "name": "Wood_Softwood_Planks"
    },
    {
      "x": -12,
      "y": 6,
      "z": 6,
      "name": "Wood_Softwood_Roof_Shallow",
      "rotation": 3
    },
    {
      "x": -12,
      "y": 0,
      "z": 7,
      "name": "Wood_Softwood_Planks"
    },
    {
      "x": -12,
      "y": 4,
      "z": 7,
      "name": "Wood_Softwood_Planks"
    },
    {
      "x": -12,
      "y": 5,
      "z": 7,
      "name": "Wood_Softwood_Roof_Steep",
      "rotation": 2
    },
    {
      "x": -12,
      "y": 6,
      "z": 7,
      "name": "Wood_Softwood_Roof_Steep",
      "filler": 1024,
      "rotation": 2
    },
    {
      "x": -12,
      "y": 0,
      "z": 8,
      "name": "Wood_Softwood_Planks"
    },
    {
      "x": -12,
      "y": 4,
      "z": 8,
      "name": "Wood_Softwood_Planks"
    },
    {
      "x": -12,
      "y": 5,
      "z": 8,
      "name": "Rock_Quartzite"
    },
    {
      "x": -12,
      "y": 6,
      "z": 8,
      "name": "Rock_Quartzite"
    },
    {
      "x": -12,
      "y": 7,
      "z": 8,
      "name": "Wood_Softwood_Roof_Steep",
      "rotation": 2
    },
    {
      "x": -12,
      "y": 8,
      "z": 8,
      "name": "Wood_Softwood_Roof_Steep",
      "filler": 1024,
      "rotation": 2
    },
    {
      "x": -12,
      "y": 0,
      "z": 9,
      "name": "Wood_Softwood_Planks"
    },
    {
      "x": -12,
      "y": 4,
      "z": 9,
      "name": "Wood_Softwood_Planks"
    },
    {
      "x": -12,
      "y": 5,
      "z": 9,
      "name": "Ingredient_Flour"
    },
    {
      "x": -12,
      "y": 8,
      "z": 9,
      "name": "Wood_Softwood_Planks"
    },
    {
      "x": -12,
      "y": 9,
      "z": 9,
      "name": "Wood_Softwood_Roof",
      "rotation": 2
    },
    {
      "x": -12,
      "y": 0,
      "z": 10,
      "name": "Wood_Softwood_Planks"
    },
    {
      "x": -12,
      "y": 4,
      "z": 10,
      "name": "Wood_Softwood_Planks"
    },
    {
      "x": -12,
      "y": 8,
      "z": 10,
      "name": "Wood_Softwood_Planks"
    },
    {
      "x": -12,
      "y": 10,
      "z": 10,
      "name": "Wood_Softwood_Roof_Hollow",
      "rotation": 2
    },
    {
      "x": -12,
      "y": 0,
      "z": 11,
      "name": "Wood_Softwood_Planks"
    },
    {
      "x": -12,
      "y": 4,
      "z": 11,
      "name": "Wood_Softwood_Planks"
    },
    {
      "x": -12,
      "y": 8,
      "z": 11,
      "name": "Wood_Softwood_Planks"
    },
    {
      "x": -12,
      "y": 11,
      "z": 11,
      "name": "Wood_Softwood_Planks_Half"
    },
    {
      "x": -12,
      "y": 0,
      "z": 12,
      "name": "Wood_Softwood_Planks"
    },
    {
      "x": -12,
      "y": 4,
      "z": 12,
      "name": "Wood_Softwood_Planks"
    },
    {
      "x": -12,
      "y": 8,
      "z": 12,
      "name": "Wood_Softwood_Planks"
    },
    {
      "x": -12,
      "y": 10,
      "z": 12,
      "name": "Wood_Softwood_Roof_Hollow"
    },
    {
      "x": -12,
      "y": 0,
      "z": 13,
      "name": "Wood_Softwood_Planks"
    },
    {
      "x": -12,
      "y": 4,
      "z": 13,
      "name": "Wood_Softwood_Planks"
    },
    {
      "x": -12,
      "y": 8,
      "z": 13,
      "name": "Wood_Softwood_Planks"
    },
    {
      "x": -12,
      "y": 9,
      "z": 13,
      "name": "Wood_Softwood_Roof"
    },
    {
      "x": -12,
      "y": 0,
      "z": 14,
      "name": "Rock_Stone_Cobble"
    },
    {
      "x": -12,
      "y": 1,
      "z": 14,
      "name": "Bench_Furnace",
      "components": {
        "Components": {
          "BenchBlock": {
            "TierLevel": 1,
            "UpgradeItems": []
          },
          "ProcessingBenchBlock": {
            "InputContainer": {
              "Id": "Simple",
              "Capacity": 2,
              "Items": {}
            },
            "FuelContainer": {
              "Id": "Simple",
              "Capacity": 1,
              "Items": {}
            },
            "OutputContainer": {
              "Id": "Simple",
              "Capacity": 4,
              "Items": {}
            },
            "Progress": 0.0,
            "FuelTime": 0.0,
            "Active": false,
            "NextExtra": 2,
            "LastTickGameTime": "0001-02-01T20:37:03.745188031Z"
          },
          "PlacedByInteraction": {
            "WhoPlacedUuid": {
              "$binary": "gqJcCRGLSleXtmq6BvFR8g==",
              "$type": "04"
            }
          }
        }
      },
      "rotation": 2
    },
    {
      "x": -12,
      "y": 2,
      "z": 14,
      "name": "Bench_Furnace",
      "filler": 1024,
      "rotation": 2
    },
    {
      "x": -12,
      "y": 3,
      "z": 14,
      "name": "Rock_Stone_Cobble_Stairs",
      "rotation": 9
    },
    {
      "x": -12,
      "y": 4,
      "z": 14,
      "name": "Rock_Stone_Cobble"
    },
    {
      "x": -12,
      "y": 5,
      "z": 14,
      "name": "Bench_Furnace",
      "components": {
        "Components": {
          "BenchBlock": {
            "TierLevel": 1,
            "UpgradeItems": []
          },
          "ProcessingBenchBlock": {
            "InputContainer": {
              "Id": "Simple",
              "Capacity": 2,
              "Items": {}
            },
            "FuelContainer": {
              "Id": "Simple",
              "Capacity": 1,
              "Items": {}
            },
            "OutputContainer": {
              "Id": "Simple",
              "Capacity": 4,
              "Items": {}
            },
            "Progress": 0.0,
            "FuelTime": 0.0,
            "Active": false,
            "NextExtra": 2,
            "LastTickGameTime": "0001-02-01T20:37:03.745188031Z"
          },
          "PlacedByInteraction": {
            "WhoPlacedUuid": {
              "$binary": "gqJcCRGLSleXtmq6BvFR8g==",
              "$type": "04"
            }
          }
        }
      },
      "rotation": 2
    },
    {
      "x": -12,
      "y": 6,
      "z": 14,
      "name": "Bench_Furnace",
      "filler": 1024,
      "rotation": 2
    },
    {
      "x": -12,
      "y": 7,
      "z": 14,
      "name": "Rock_Stone_Cobble_Stairs",
      "rotation": 9
    },
    {
      "x": -12,
      "y": 8,
      "z": 14,
      "name": "Rock_Stone_Cobble"
    },
    {
      "x": -12,
      "y": 9,
      "z": 14,
      "name": "Rock_Stone_Cobble"
    },
    {
      "x": -12,
      "y": 10,
      "z": 14,
      "name": "Rock_Stone_Cobble"
    },
    {
      "x": -12,
      "y": 11,
      "z": 14,
      "name": "Rock_Stone_Cobble"
    },
    {
      "x": -12,
      "y": 12,
      "z": 14,
      "name": "Rock_Stone_Cobble"
    },
    {
      "x": -12,
      "y": 13,
      "z": 14,
      "name": "Rock_Stone_Cobble"
    },
    {
      "x": -12,
      "y": 14,
      "z": 14,
      "name": "Furniture_Village_Planter"
    },
    {
      "x": -12,
      "y": 15,
      "z": 14,
      "name": "Aetherhaven_Smokestack",
      "support": 15
    },
    {
      "x": -12,
      "y": 0,
      "z": 15,
      "name": "Rock_Stone_Cobble"
    },
    {
      "x": -12,
      "y": 1,
      "z": 15,
      "name": "Rock_Stone_Cobble"
    },
    {
      "x": -12,
      "y": 2,
      "z": 15,
      "name": "Rock_Stone_Cobble"
    },
    {
      "x": -12,
      "y": 3,
      "z": 15,
      "name": "Rock_Stone_Cobble"
    },
    {
      "x": -12,
      "y": 4,
      "z": 15,
      "name": "Rock_Stone_Cobble"
    },
    {
      "x": -12,
      "y": 5,
      "z": 15,
      "name": "Rock_Stone_Cobble"
    },
    {
      "x": -12,
      "y": 6,
      "z": 15,
      "name": "Rock_Stone_Cobble"
    },
    {
      "x": -12,
      "y": 7,
      "z": 15,
      "name": "Rock_Stone_Cobble"
    },
    {
      "x": -12,
      "y": 8,
      "z": 15,
      "name": "Rock_Stone_Cobble_Stairs"
    },
    {
      "x": -12,
      "y": 4,
      "z": 16,
      "name": "Wood_Softwood_Roof_Hollow"
    },
    {
      "x": -11,
      "y": 6,
      "z": 2,
      "name": "Wood_Softwood_Roof_Shallow",
      "filler": 1,
      "rotation": 3
    },
    {
      "x": -11,
      "y": 4,
      "z": 3,
      "name": "Wood_Oak_Trunk",
      "support": 15,
      "rotation": 5
    },
    {
      "x": -11,
      "y": 6,
      "z": 3,
      "name": "Wood_Softwood_Roof_Shallow",
      "filler": 1,
      "rotation": 3
    },
    {
      "x": -11,
      "y": 0,
      "z": 4,
      "name": "Rock_Stone_Cobble"
    },
    {
      "x": -11,
      "y": 1,
      "z": 4,
      "name": "Wood_Oak_Trunk",
      "support": 15
    },
    {
      "x": -11,
      "y": 2,
      "z": 4,
      "name": "Wood_Oak_Trunk",
      "support": 15
    },
    {
      "x": -11,
      "y": 3,
      "z": 4,
      "name": "Wood_Oak_Trunk",
      "support": 15
    },
    {
      "x": -11,
      "y": 4,
      "z": 4,
      "name": "Wood_Softwood_Planks"
    },
    {
      "x": -11,
      "y": 5,
      "z": 4,
      "name": "Rock_Quartzite"
    },
    {
      "x": -11,
      "y": 6,
      "z": 4,
      "name": "Wood_Softwood_Roof_Shallow",
      "filler": 1,
      "rotation": 3
    },
    {
      "x": -11,
      "y": 0,
      "z": 5,
      "name": "Wood_Softwood_Planks"
    },
    {
      "x": -11,
      "y": 4,
      "z": 5,
      "name": "Wood_Softwood_Planks"
    },
    {
      "x": -11,
      "y": 6,
      "z": 5,
      "name": "Wood_Softwood_Roof_Shallow",
      "filler": 1,
      "rotation": 3
    },
    {
      "x": -11,
      "y": 0,
      "z": 6,
      "name": "Wood_Softwood_Planks"
    },
    {
      "x": -11,
      "y": 4,
      "z": 6,
      "name": "Wood_Softwood_Planks"
    },
    {
      "x": -11,
      "y": 6,
      "z": 6,
      "name": "Wood_Softwood_Roof_Shallow",
      "filler": 1,
      "rotation": 3
    },
    {
      "x": -11,
      "y": 0,
      "z": 7,
      "name": "Wood_Softwood_Planks"
    },
    {
      "x": -11,
      "y": 1,
      "z": 7,
      "name": "Cloth_Roof_Leather_Flat"
    },
    {
      "x": -11,
      "y": 4,
      "z": 7,
      "name": "Wood_Softwood_Planks"
    },
    {
      "x": -11,
      "y": 5,
      "z": 7,
      "name": "Wood_Softwood_Roof_Steep",
      "rotation": 2
    },
    {
      "x": -11,
      "y": 6,
      "z": 7,
      "name": "Wood_Softwood_Roof_Steep",
      "filler": 1024,
      "rotation": 2
    },
    {
      "x": -11,
      "y": 0,
      "z": 8,
      "name": "Wood_Softwood_Planks"
    },
    {
      "x": -11,
      "y": 1,
      "z": 8,
      "name": "Cloth_Roof_Leather_Flat"
    },
    {
      "x": -11,
      "y": 4,
      "z": 8,
      "name": "Wood_Softwood_Planks"
    },
    {
      "x": -11,
      "y": 5,
      "z": 8,
      "name": "Rock_Quartzite"
    },
    {
      "x": -11,
      "y": 6,
      "z": 8,
      "name": "Rock_Quartzite"
    },
    {
      "x": -11,
      "y": 7,
      "z": 8,
      "name": "Wood_Softwood_Roof_Steep",
      "rotation": 2
    },
    {
      "x": -11,
      "y": 8,
      "z": 8,
      "name": "Wood_Softwood_Roof_Steep",
      "filler": 1024,
      "rotation": 2
    },
    {
      "x": -11,
      "y": 0,
      "z": 9,
      "name": "Wood_Softwood_Planks"
    },
    {
      "x": -11,
      "y": 1,
      "z": 9,
      "name": "Cloth_Roof_Leather_Flat"
    },
    {
      "x": -11,
      "y": 4,
      "z": 9,
      "name": "Wood_Softwood_Planks"
    },
    {
      "x": -11,
      "y": 5,
      "z": 9,
      "name": "Furniture_Tavern_Barrel"
    },
    {
      "x": -11,
      "y": 8,
      "z": 9,
      "name": "Wood_Softwood_Planks"
    },
    {
      "x": -11,
      "y": 9,
      "z": 9,
      "name": "Wood_Softwood_Roof",
      "rotation": 2
    },
    {
      "x": -11,
      "y": 0,
      "z": 10,
      "name": "Wood_Softwood_Planks"
    },
    {
      "x": -11,
      "y": 1,
      "z": 10,
      "name": "Cloth_Roof_Leather_Flat"
    },
    {
      "x": -11,
      "y": 4,
      "z": 10,
      "name": "Wood_Softwood_Planks"
    },
    {
      "x": -11,
      "y": 8,
      "z": 10,
      "name": "Wood_Softwood_Planks"
    },
    {
      "x": -11,
      "y": 10,
      "z": 10,
      "name": "Wood_Softwood_Roof_Hollow",
      "rotation": 2
    },
    {
      "x": -11,
      "y": 0,
      "z": 11,
      "name": "Wood_Softwood_Planks"
    },
    {
      "x": -11,
      "y": 1,
      "z": 11,
      "name": "Cloth_Roof_Leather_Flat"
    },
    {
      "x": -11,
      "y": 4,
      "z": 11,
      "name": "Wood_Softwood_Planks"
    },
    {
      "x": -11,
      "y": 8,
      "z": 11,
      "name": "Wood_Softwood_Planks"
    },
    {
      "x": -11,
      "y": 11,
      "z": 11,
      "name": "Wood_Softwood_Planks_Half"
    },
    {
      "x": -11,
      "y": 0,
      "z": 12,
      "name": "Wood_Softwood_Planks"
    },
    {
      "x": -11,
      "y": 4,
      "z": 12,
      "name": "Wood_Softwood_Planks"
    },
    {
      "x": -11,
      "y": 8,
      "z": 12,
      "name": "Wood_Softwood_Planks"
    },
    {
      "x": -11,
      "y": 10,
      "z": 12,
      "name": "Wood_Softwood_Roof_Hollow"
    },
    {
      "x": -11,
      "y": 0,
      "z": 13,
      "name": "Wood_Softwood_Planks"
    },
    {
      "x": -11,
      "y": 4,
      "z": 13,
      "name": "Wood_Softwood_Planks"
    },
    {
      "x": -11,
      "y": 8,
      "z": 13,
      "name": "Wood_Softwood_Planks"
    },
    {
      "x": -11,
      "y": 9,
      "z": 13,
      "name": "Wood_Softwood_Roof"
    },
    {
      "x": -11,
      "y": 0,
      "z": 14,
      "name": "Rock_Stone_Cobble"
    },
    {
      "x": -11,
      "y": 1,
      "z": 14,
      "name": "Bench_Furnace",
      "filler": 1,
      "rotation": 2
    },
    {
      "x": -11,
      "y": 2,
      "z": 14,
      "name": "Bench_Furnace",
      "filler": 1025,
      "rotation": 2
    },
    {
      "x": -11,
      "y": 3,
      "z": 14,
      "name": "Rock_Stone_Cobble_Stairs",
      "rotation": 11
    },
    {
      "x": -11,
      "y": 4,
      "z": 14,
      "name": "Rock_Stone_Cobble"
    },
    {
      "x": -11,
      "y": 5,
      "z": 14,
      "name": "Bench_Furnace",
      "filler": 1,
      "rotation": 2
    },
    {
      "x": -11,
      "y": 6,
      "z": 14,
      "name": "Bench_Furnace",
      "filler": 1025,
      "rotation": 2
    },
    {
      "x": -11,
      "y": 7,
      "z": 14,
      "name": "Rock_Stone_Cobble_Stairs",
      "rotation": 11
    },
    {
      "x": -11,
      "y": 8,
      "z": 14,
      "name": "Rock_Stone_Cobble"
    },
    {
      "x": -11,
      "y": 9,
      "z": 14,
      "name": "Rock_Stone_Cobble"
    },
    {
      "x": -11,
      "y": 10,
      "z": 14,
      "name": "Rock_Stone_Cobble"
    },
    {
      "x": -11,
      "y": 11,
      "z": 14,
      "name": "Rock_Stone_Cobble_Stairs",
      "rotation": 1
    },
    {
      "x": -11,
      "y": 0,
      "z": 15,
      "name": "Rock_Stone_Cobble"
    },
    {
      "x": -11,
      "y": 1,
      "z": 15,
      "name": "Rock_Stone_Cobble"
    },
    {
      "x": -11,
      "y": 2,
      "z": 15,
      "name": "Rock_Stone_Cobble"
    },
    {
      "x": -11,
      "y": 3,
      "z": 15,
      "name": "Rock_Stone_Cobble"
    },
    {
      "x": -11,
      "y": 4,
      "z": 15,
      "name": "Rock_Stone_Cobble"
    },
    {
      "x": -11,
      "y": 5,
      "z": 15,
      "name": "Rock_Stone_Cobble"
    },
    {
      "x": -11,
      "y": 6,
      "z": 15,
      "name": "Rock_Stone_Cobble"
    },
    {
      "x": -11,
      "y": 7,
      "z": 15,
      "name": "Rock_Stone_Cobble"
    },
    {
      "x": -11,
      "y": 8,
      "z": 15,
      "name": "Rock_Stone_Cobble"
    },
    {
      "x": -11,
      "y": 9,
      "z": 15,
      "name": "Rock_Stone_Cobble"
    },
    {
      "x": -11,
      "y": 10,
      "z": 15,
      "name": "Rock_Stone_Cobble_Stairs"
    },
    {
      "x": -11,
      "y": 4,
      "z": 16,
      "name": "Wood_Softwood_Roof_Hollow"
    },
    {
      "x": -10,
      "y": 7,
      "z": 1,
      "name": "Wood_Softwood_Stairs",
      "rotation": 8
    },
    {
      "x": -10,
      "y": 6,
      "z": 2,
      "name": "Wood_Softwood_Planks_Half",
      "rotation": 8
    },
    {
      "x": -10,
      "y": 7,
      "z": 2,
      "name": "Wood_Softwood_Stairs"
    },
    {
      "x": -10,
      "y": 4,
      "z": 3,
      "name": "Wood_Oak_Trunk",
      "support": 15,
      "rotation": 5
    },
    {
      "x": -10,
      "y": 6,
      "z": 3,
      "name": "Wood_Softwood_Stairs",
      "rotation": 8
    },
    {
      "x": -10,
      "y": 7,
      "z": 3,
      "name": "Wood_Softwood_Planks_Half"
    },
    {
      "x": -10,
      "y": 1,
      "z": 4,
      "name": "*Furniture_Village_Door_State_Definitions_CloseDoorIn"
    },
    {
      "x": -10,
      "y": 2,
      "z": 4,
      "name": "*Furniture_Village_Door_State_Definitions_CloseDoorIn",
      "filler": 1024
    },
    {
      "x": -10,
      "y": 3,
      "z": 4,
      "name": "Rock_Quartzite"
    },
    {
      "x": -10,
      "y": 4,
      "z": 4,
      "name": "Wood_Softwood_Planks"
    },
    {
      "x": -10,
      "y": 5,
      "z": 4,
      "name": "Wood_Oak_Trunk",
      "support": 15
    },
    {
      "x": -10,
      "y": 6,
      "z": 4,
      "name": "Wood_Oak_Trunk",
      "support": 15
    },
    {
      "x": -10,
      "y": 7,
      "z": 4,
      "name": "Wood_Softwood_Planks_Half"
    },
    {
      "x": -10,
      "y": 0,
      "z": 5,
      "name": "Wood_Softwood_Planks"
    },
    {
      "x": -10,
      "y": 4,
      "z": 5,
      "name": "Wood_Softwood_Planks"
    },
    {
      "x": -10,
      "y": 6,
      "z": 5,
      "name": "Soil_Dirt"
    },
    {
      "x": -10,
      "y": 7,
      "z": 5,
      "name": "Wood_Softwood_Planks_Half"
    },
    {
      "x": -10,
      "y": 0,
      "z": 6,
      "name": "Wood_Softwood_Planks"
    },
    {
      "x": -10,
      "y": 4,
      "z": 6,
      "name": "Wood_Softwood_Planks"
    },
    {
      "x": -10,
      "y": 6,
      "z": 6,
      "name": "Soil_Dirt"
    },
    {
      "x": -10,
      "y": 7,
      "z": 6,
      "name": "Wood_Softwood_Planks_Half"
    },
    {
      "x": -10,
      "y": 0,
      "z": 7,
      "name": "Wood_Softwood_Planks"
    },
    {
      "x": -10,
      "y": 1,
      "z": 7,
      "name": "Cloth_Roof_Leather_Flat"
    },
    {
      "x": -10,
      "y": 4,
      "z": 7,
      "name": "Wood_Softwood_Planks"
    },
    {
      "x": -10,
      "y": 5,
      "z": 7,
      "name": "Wood_Softwood_Roof_Steep",
      "rotation": 2
    },
    {
      "x": -10,
      "y": 6,
      "z": 7,
      "name": "Wood_Softwood_Roof_Steep",
      "filler": 1024,
      "rotation": 2
    },
    {
      "x": -10,
      "y": 7,
      "z": 7,
      "name": "Wood_Softwood_Planks_Half"
    },
    {
      "x": -10,
      "y": 0,
      "z": 8,
      "name": "Wood_Softwood_Planks"
    },
    {
      "x": -10,
      "y": 1,
      "z": 8,
      "name": "Cloth_Roof_Leather_Flat"
    },
    {
      "x": -10,
      "y": 4,
      "z": 8,
      "name": "Wood_Softwood_Planks"
    },
    {
      "x": -10,
      "y": 5,
      "z": 8,
      "name": "Rock_Quartzite"
    },
    {
      "x": -10,
      "y": 6,
      "z": 8,
      "name": "Rock_Quartzite"
    },
    {
      "x": -10,
      "y": 7,
      "z": 8,
      "name": "Wood_Softwood_Roof_Steep",
      "rotation": 2
    },
    {
      "x": -10,
      "y": 8,
      "z": 8,
      "name": "Wood_Softwood_Roof_Steep",
      "filler": 1024,
      "rotation": 2
    },
    {
      "x": -10,
      "y": 0,
      "z": 9,
      "name": "Wood_Softwood_Planks"
    },
    {
      "x": -10,
      "y": 1,
      "z": 9,
      "name": "Cloth_Roof_Leather_Flat"
    },
    {
      "x": -10,
      "y": 4,
      "z": 9,
      "name": "Wood_Softwood_Planks"
    },
    {
      "x": -10,
      "y": 5,
      "z": 9,
      "name": "Furniture_Village_Crate"
    },
    {
      "x": -10,
      "y": 8,
      "z": 9,
      "name": "Wood_Softwood_Planks"
    },
    {
      "x": -10,
      "y": 9,
      "z": 9,
      "name": "Wood_Softwood_Roof",
      "rotation": 2
    },
    {
      "x": -10,
      "y": 0,
      "z": 10,
      "name": "Wood_Softwood_Planks"
    },
    {
      "x": -10,
      "y": 1,
      "z": 10,
      "name": "Cloth_Roof_Leather_Flat"
    },
    {
      "x": -10,
      "y": 4,
      "z": 10,
      "name": "Wood_Softwood_Planks"
    },
    {
      "x": -10,
      "y": 8,
      "z": 10,
      "name": "Wood_Softwood_Planks"
    },
    {
      "x": -10,
      "y": 10,
      "z": 10,
      "name": "Wood_Softwood_Roof_Hollow",
      "rotation": 2
    },
    {
      "x": -10,
      "y": 0,
      "z": 11,
      "name": "Wood_Softwood_Planks"
    },
    {
      "x": -10,
      "y": 1,
      "z": 11,
      "name": "Cloth_Roof_Leather_Flat"
    },
    {
      "x": -10,
      "y": 4,
      "z": 11,
      "name": "Wood_Softwood_Planks"
    },
    {
      "x": -10,
      "y": 8,
      "z": 11,
      "name": "Wood_Softwood_Planks"
    },
    {
      "x": -10,
      "y": 11,
      "z": 11,
      "name": "Wood_Softwood_Planks_Half"
    },
    {
      "x": -10,
      "y": 0,
      "z": 12,
      "name": "Wood_Softwood_Planks"
    },
    {
      "x": -10,
      "y": 4,
      "z": 12,
      "name": "Wood_Softwood_Planks"
    },
    {
      "x": -10,
      "y": 8,
      "z": 12,
      "name": "Wood_Softwood_Planks"
    },
    {
      "x": -10,
      "y": 10,
      "z": 12,
      "name": "Wood_Softwood_Roof_Hollow"
    },
    {
      "x": -10,
      "y": 0,
      "z": 13,
      "name": "Wood_Softwood_Planks"
    },
    {
      "x": -10,
      "y": 4,
      "z": 13,
      "name": "Wood_Softwood_Planks"
    },
    {
      "x": -10,
      "y": 5,
      "z": 13,
      "name": "Furniture_Village_Crate"
    },
    {
      "x": -10,
      "y": 6,
      "z": 13,
      "name": "Wood_Torch_Wall",
      "rotation": 2
    },
    {
      "x": -10,
      "y": 8,
      "z": 13,
      "name": "Wood_Softwood_Planks"
    },
    {
      "x": -10,
      "y": 9,
      "z": 13,
      "name": "Wood_Softwood_Roof"
    },
    {
      "x": -10,
      "y": 0,
      "z": 14,
      "name": "Rock_Stone_Cobble"
    },
    {
      "x": -10,
      "y": 1,
      "z": 14,
      "name": "Wood_Oak_Trunk",
      "support": 15
    },
    {
      "x": -10,
      "y": 2,
      "z": 14,
      "name": "Wood_Oak_Trunk",
      "support": 15
    },
    {
      "x": -10,
      "y": 3,
      "z": 14,
      "name": "Wood_Oak_Trunk",
      "support": 15
    },
    {
      "x": -10,
      "y": 4,
      "z": 14,
      "name": "Wood_Softwood_Planks"
    },
    {
      "x": -10,
      "y": 5,
      "z": 14,
      "name": "Wood_Oak_Trunk",
      "support": 15
    },
    {
      "x": -10,
      "y": 6,
      "z": 14,
      "name": "Wood_Oak_Trunk",
      "support": 15
    },
    {
      "x": -10,
      "y": 7,
      "z": 14,
      "name": "Wood_Softwood_Roof_Steep"
    },
    {
      "x": -10,
      "y": 8,
      "z": 14,
      "name": "Wood_Softwood_Roof_Steep",
      "filler": 1024
    },
    {
      "x": -10,
      "y": 4,
      "z": 15,
      "name": "Wood_Oak_Trunk",
      "support": 15,
      "rotation": 5
    },
    {
      "x": -10,
      "y": 5,
      "z": 15,
      "name": "Wood_Softwood_Roof_Steep"
    },
    {
      "x": -10,
      "y": 6,
      "z": 15,
      "name": "Wood_Softwood_Roof_Steep",
      "filler": 1024
    },
    {
      "x": -10,
      "y": 4,
      "z": 16,
      "name": "Wood_Softwood_Roof_Hollow"
    },
    {
      "x": -9,
      "y": 6,
      "z": 2,
      "name": "Wood_Softwood_Roof_Shallow",
      "filler": 31,
      "rotation": 1
    },
    {
      "x": -9,
      "y": 2,
      "z": 3,
      "name": "Wood_Torch_Wall",
      "rotation": 2
    },
    {
      "x": -9,
      "y": 4,
      "z": 3,
      "name": "Wood_Oak_Trunk",
      "support": 15,
      "rotation": 5
    },
    {
      "x": -9,
      "y": 6,
      "z": 3,
      "name": "Wood_Softwood_Roof_Shallow",
      "filler": 31,
      "rotation": 1
    },
    {
      "x": -9,
      "y": 0,
      "z": 4,
      "name": "Rock_Stone_Cobble"
    },
    {
      "x": -9,
      "y": 1,
      "z": 4,
      "name": "Wood_Oak_Trunk",
      "support": 15
    },
    {
      "x": -9,
      "y": 2,
      "z": 4,
      "name": "Wood_Oak_Trunk",
      "support": 15
    },
    {
      "x": -9,
      "y": 3,
      "z": 4,
      "name": "Wood_Oak_Trunk",
      "support": 15
    },
    {
      "x": -9,
      "y": 4,
      "z": 4,
      "name": "Wood_Softwood_Planks"
    },
    {
      "x": -9,
      "y": 5,
      "z": 4,
      "name": "Rock_Quartzite"
    },
    {
      "x": -9,
      "y": 6,
      "z": 4,
      "name": "Wood_Softwood_Roof_Shallow",
      "filler": 31,
      "rotation": 1
    },
    {
      "x": -9,
      "y": 0,
      "z": 5,
      "name": "Wood_Softwood_Planks"
    },
    {
      "x": -9,
      "y": 4,
      "z": 5,
      "name": "Wood_Softwood_Planks"
    },
    {
      "x": -9,
      "y": 6,
      "z": 5,
      "name": "Wood_Softwood_Roof_Shallow",
      "filler": 31,
      "rotation": 1
    },
    {
      "x": -9,
      "y": 0,
      "z": 6,
      "name": "Wood_Softwood_Planks"
    },
    {
      "x": -9,
      "y": 4,
      "z": 6,
      "name": "Wood_Softwood_Planks"
    },
    {
      "x": -9,
      "y": 6,
      "z": 6,
      "name": "Wood_Softwood_Roof_Shallow",
      "filler": 31,
      "rotation": 1
    },
    {
      "x": -9,
      "y": 0,
      "z": 7,
      "name": "Wood_Softwood_Planks"
    },
    {
      "x": -9,
      "y": 4,
      "z": 7,
      "name": "Wood_Softwood_Planks"
    },
    {
      "x": -9,
      "y": 5,
      "z": 7,
      "name": "Wood_Softwood_Roof_Steep",
      "rotation": 2
    },
    {
      "x": -9,
      "y": 6,
      "z": 7,
      "name": "Wood_Softwood_Roof_Steep",
      "filler": 1024,
      "rotation": 2
    },
    {
      "x": -9,
      "y": 0,
      "z": 8,
      "name": "Wood_Softwood_Planks"
    },
    {
      "x": -9,
      "y": 4,
      "z": 8,
      "name": "Wood_Softwood_Planks"
    },
    {
      "x": -9,
      "y": 5,
      "z": 8,
      "name": "Rock_Quartzite"
    },
    {
      "x": -9,
      "y": 6,
      "z": 8,
      "name": "Rock_Quartzite"
    },
    {
      "x": -9,
      "y": 7,
      "z": 8,
      "name": "Wood_Softwood_Roof_Steep",
      "rotation": 2
    },
    {
      "x": -9,
      "y": 8,
      "z": 8,
      "name": "Wood_Softwood_Roof_Steep",
      "filler": 1024,
      "rotation": 2
    },
    {
      "x": -9,
      "y": 0,
      "z": 9,
      "name": "Wood_Softwood_Planks"
    },
    {
      "x": -9,
      "y": 4,
      "z": 9,
      "name": "Wood_Softwood_Planks"
    },
    {
      "x": -9,
      "y": 5,
      "z": 9,
      "name": "Furniture_Village_Crate"
    },
    {
      "x": -9,
      "y": 6,
      "z": 9,
      "name": "Furniture_Village_Crate"
    },
    {
      "x": -9,
      "y": 8,
      "z": 9,
      "name": "Wood_Softwood_Planks"
    },
    {
      "x": -9,
      "y": 9,
      "z": 9,
      "name": "Wood_Softwood_Roof",
      "rotation": 2
    },
    {
      "x": -9,
      "y": 0,
      "z": 10,
      "name": "Wood_Softwood_Planks"
    },
    {
      "x": -9,
      "y": 4,
      "z": 10,
      "name": "Wood_Softwood_Planks"
    },
    {
      "x": -9,
      "y": 5,
      "z": 10,
      "name": "Furniture_Village_Crate"
    },
    {
      "x": -9,
      "y": 8,
      "z": 10,
      "name": "Wood_Softwood_Planks"
    },
    {
      "x": -9,
      "y": 10,
      "z": 10,
      "name": "Wood_Softwood_Roof_Hollow",
      "rotation": 2
    },
    {
      "x": -9,
      "y": 0,
      "z": 11,
      "name": "Wood_Softwood_Planks"
    },
    {
      "x": -9,
      "y": 4,
      "z": 11,
      "name": "Wood_Softwood_Planks"
    },
    {
      "x": -9,
      "y": 8,
      "z": 11,
      "name": "Wood_Softwood_Planks"
    },
    {
      "x": -9,
      "y": 11,
      "z": 11,
      "name": "Wood_Softwood_Planks_Half"
    },
    {
      "x": -9,
      "y": 0,
      "z": 12,
      "name": "Wood_Softwood_Planks"
    },
    {
      "x": -9,
      "y": 4,
      "z": 12,
      "name": "Wood_Softwood_Planks"
    },
    {
      "x": -9,
      "y": 8,
      "z": 12,
      "name": "Wood_Softwood_Planks"
    },
    {
      "x": -9,
      "y": 10,
      "z": 12,
      "name": "Wood_Softwood_Roof_Hollow"
    },
    {
      "x": -9,
      "y": 0,
      "z": 13,
      "name": "Wood_Softwood_Planks"
    },
    {
      "x": -9,
      "y": 4,
      "z": 13,
      "name": "Wood_Softwood_Planks"
    },
    {
      "x": -9,
      "y": 8,
      "z": 13,
      "name": "Wood_Softwood_Planks"
    },
    {
      "x": -9,
      "y": 9,
      "z": 13,
      "name": "Wood_Softwood_Roof"
    },
    {
      "x": -9,
      "y": 0,
      "z": 14,
      "name": "Rock_Stone_Cobble"
    },
    {
      "x": -9,
      "y": 1,
      "z": 14,
      "name": "Rock_Stone_Brick"
    },
    {
      "x": -9,
      "y": 2,
      "z": 14,
      "name": "Rock_Quartzite"
    },
    {
      "x": -9,
      "y": 3,
      "z": 14,
      "name": "Rock_Quartzite"
    },
    {
      "x": -9,
      "y": 4,
      "z": 14,
      "name": "Wood_Softwood_Planks"
    },
    {
      "x": -9,
      "y": 5,
      "z": 14,
      "name": "Rock_Quartzite"
    },
    {
      "x": -9,
      "y": 6,
      "z": 14,
      "name": "Rock_Quartzite"
    },
    {
      "x": -9,
      "y": 7,
      "z": 14,
      "name": "Wood_Softwood_Roof_Steep"
    },
    {
      "x": -9,
      "y": 8,
      "z": 14,
