{
  "version": 8,
  "blockIdVersion": 11,
  "anchorX": 0,
  "anchorY": 0,
  "anchorZ": 0,
  "blocks": [
    {
      "x": 1,
      "y": 0,
      "z": 1,
      "name": "Soil_Grass"
    },
    {
      "x": 1,
      "y": 0,
      "z": 2,
      "name": "Soil_Grass"
    },
    {
      "x": 1,
      "y": 0,
      "z": 3,
      "name": "Soil_Grass"
    },
    {
      "x": 1,
      "y": 0,
      "z": 4,
      "name": "Soil_Grass"
    },
    {
      "x": 1,
      "y": 0,
      "z": 5,
      "name": "Soil_Grass"
    },
    {
      "x": 1,
      "y": 0,
      "z": 6,
      "name": "Soil_Grass"
    },
    {
      "x": 1,
      "y": 0,
      "z": 7,
      "name": "Soil_Grass"
    },
    {
      "x": 1,
      "y": 0,
      "z": 8,
      "name": "Soil_Grass"
    },
    {
      "x": 1,
      "y": 0,
      "z": 9,
      "name": "Soil_Grass"
    },
    {
      "x": 1,
      "y": 0,
      "z": 10,
      "name": "Soil_Grass"
    },
    {
      "x": 1,
      "y": 0,
      "z": 11,
      "name": "Soil_Grass"
    },
    {
      "x": 1,
      "y": 0,
      "z": 12,
      "name": "Soil_Grass"
    },
    {
      "x": 1,
      "y": 0,
      "z": 13,
      "name": "Soil_Grass"
    },
    {
      "x": 1,
      "y": 0,
      "z": 14,
      "name": "Soil_Grass"
    },
    {
      "x": 1,
      "y": 0,
      "z": 15,
      "name": "Soil_Grass"
    },
    {
      "x": 1,
      "y": 0,
      "z": 16,
      "name": "Soil_Grass"
    },
    {
      "x": 1,
      "y": 0,
      "z": 17,
      "name": "Soil_Grass"
    },
    {
      "x": 1,
      "y": 0,
      "z": 18,
      "name": "Soil_Grass"
    },
    {
      "x": 1,
      "y": 0,
      "z": 19,
      "name": "Soil_Grass"
    },
    {
      "x": 1,
      "y": 0,
      "z": 20,
      "name": "Soil_Grass"
    },
    {
      "x": 1,
      "y": 0,
      "z": 21,
      "name": "Soil_Grass"
    },
    {
      "x": 1,
      "y": 0,
      "z": 22,
      "name": "Soil_Grass"
    },
    {
      "x": 1,
      "y": 0,
      "z": 23,
      "name": "Soil_Grass"
    },
    {
      "x": 1,
      "y": 0,
      "z": 24,
      "name": "Soil_Grass"
    },
    {
      "x": 1,
      "y": 0,
      "z": 25,
      "name": "Soil_Grass"
    },
    {
      "x": 1,
      "y": 0,
      "z": 26,
      "name": "Soil_Grass"
    },
    {
      "x": 1,
      "y": 0,
      "z": 27,
      "name": "Soil_Grass"
    },
    {
      "x": 1,
      "y": 0,
      "z": 28,
      "name": "Soil_Grass"
    },
    {
      "x": 1,
      "y": 0,
      "z": 29,
      "name": "Soil_Grass"
    },
    {
      "x": 1,
      "y": 0,
      "z": 30,
      "name": "Soil_Grass"
    },
    {
      "x": 2,
      "y": 0,
      "z": 1,
      "name": "Soil_Grass"
    },
    {
      "x": 2,
      "y": 0,
      "z": 2,
      "name": "Soil_Grass"
    },
    {
      "x": 2,
      "y": 0,
      "z": 3,
      "name": "Soil_Grass"
    },
    {
      "x": 2,
      "y": 0,
      "z": 4,
      "name": "Soil_Grass"
    },
    {
      "x": 2,
      "y": 0,
      "z": 5,
      "name": "Soil_Grass"
    },
    {
      "x": 2,
      "y": 0,
      "z": 6,
      "name": "Soil_Grass"
    },
    {
      "x": 2,
      "y": 0,
      "z": 7,
      "name": "Soil_Grass"
    },
    {
      "x": 2,
      "y": 0,
      "z": 8,
      "name": "Soil_Grass"
    },
    {
      "x": 2,
      "y": 0,
      "z": 9,
      "name": "Soil_Grass"
    },
    {
      "x": 2,
      "y": 0,
      "z": 10,
      "name": "Soil_Grass"
    },
    {
      "x": 2,
      "y": 0,
      "z": 11,
      "name": "Soil_Grass"
    },
    {
      "x": 2,
      "y": 0,
      "z": 12,
      "name": "Soil_Grass"
    },
    {
      "x": 2,
      "y": 0,
      "z": 13,
      "name": "Soil_Grass"
    },
    {
      "x": 2,
      "y": 0,
      "z": 14,
      "name": "Soil_Grass"
    },
    {
      "x": 2,
      "y": 3,
      "z": 14,
      "name": "Deco_Rope",
      "support": 15
    },
    {
      "x": 2,
      "y": 4,
      "z": 14,
      "name": "Deco_Rope",
      "support": 15
    },
    {
      "x": 2,
      "y": 5,
      "z": 14,
      "name": "Deco_Rope",
      "support": 15
    },
    {
      "x": 2,
      "y": 6,
      "z": 14,
      "name": "Deco_Rope",
      "support": 15
    },
    {
      "x": 2,
      "y": 7,
      "z": 14,
      "name": "Deco_Rope",
      "support": 15
    },
    {
      "x": 2,
      "y": 8,
      "z": 14,
      "name": "Deco_Rope",
      "support": 15
    },
    {
      "x": 2,
      "y": 9,
      "z": 14,
      "name": "Deco_Rope",
      "support": 15
    },
    {
      "x": 2,
      "y": 10,
      "z": 14,
      "name": "Deco_Rope",
      "support": 15
    },
    {
      "x": 2,
      "y": 11,
      "z": 14,
      "name": "Deco_Rope",
      "support": 15
    },
    {
      "x": 2,
      "y": 12,
      "z": 14,
      "name": "Deco_Rope",
      "support": 15
    },
    {
      "x": 2,
      "y": 13,
      "z": 14,
      "name": "Deco_Rope",
      "support": 15
    },
    {
      "x": 2,
      "y": 14,
      "z": 14,
      "name": "Deco_Rope",
      "support": 15
    },
    {
      "x": 2,
      "y": 15,
      "z": 14,
      "name": "Deco_Rope",
      "support": 15
    },
    {
      "x": 2,
      "y": 16,
      "z": 14,
      "name": "Deco_Rope",
      "support": 15
    },
    {
      "x": 2,
      "y": 17,
      "z": 14,
      "name": "Deco_Rope",
      "support": 15
    },
    {
      "x": 2,
      "y": 18,
      "z": 14,
      "name": "Deco_Rope",
      "support": 15
    },
    {
      "x": 2,
      "y": 19,
      "z": 14,
      "name": "Deco_Rope",
      "support": 15
    },
    {
      "x": 2,
      "y": 20,
      "z": 14,
      "name": "Deco_Rope",
      "support": 15
    },
    {
      "x": 2,
      "y": 21,
      "z": 14,
      "name": "Deco_Rope",
      "support": 15
    },
    {
      "x": 2,
      "y": 22,
      "z": 14,
      "name": "Deco_Rope",
      "support": 15
    },
    {
      "x": 2,
      "y": 23,
      "z": 14,
      "name": "Deco_Rope",
      "support": 15
    },
    {
      "x": 2,
      "y": 24,
      "z": 14,
      "name": "Deco_Rope",
      "support": 15
    },
    {
      "x": 2,
      "y": 25,
      "z": 14,
      "name": "Deco_Rope",
      "support": 15
    },
    {
      "x": 2,
      "y": 26,
      "z": 14,
      "name": "Deco_Rope",
      "support": 15
    },
    {
      "x": 2,
      "y": 27,
      "z": 14,
      "name": "Deco_Rope",
      "support": 15
    },
    {
      "x": 2,
      "y": 28,
      "z": 14,
      "name": "Deco_Rope",
      "support": 15
    },
    {
      "x": 2,
      "y": 29,
      "z": 14,
      "name": "Deco_Rope",
      "support": 15
    },
    {
      "x": 2,
      "y": 30,
      "z": 14,
      "name": "Deco_Rope",
      "support": 15
    },
    {
      "x": 2,
      "y": 31,
      "z": 14,
      "name": "Deco_Rope",
      "support": 15
    },
    {
      "x": 2,
      "y": 32,
      "z": 14,
      "name": "Deco_Rope",
      "support": 15
    },
    {
      "x": 2,
      "y": 33,
      "z": 14,
      "name": "Deco_Rope",
      "support": 15
    },
    {
      "x": 2,
      "y": 34,
      "z": 14,
      "name": "Deco_Rope",
      "support": 15
    },
    {
      "x": 2,
      "y": 35,
      "z": 14,
      "name": "Deco_Rope",
      "support": 15
    },
    {
      "x": 2,
      "y": 36,
      "z": 14,
      "name": "Deco_Rope",
      "support": 15
    },
    {
      "x": 2,
      "y": 37,
      "z": 14,
      "name": "Deco_Rope",
      "support": 15
    },
    {
      "x": 2,
      "y": 38,
      "z": 14,
      "name": "Deco_Rope",
      "support": 15
    },
    {
      "x": 2,
      "y": 39,
      "z": 14,
      "name": "Deco_Rope",
      "support": 15
    },
    {
      "x": 2,
      "y": 40,
      "z": 14,
      "name": "Deco_Rope",
      "support": 15
    },
    {
      "x": 2,
      "y": 41,
      "z": 14,
      "name": "Deco_Rope",
      "support": 15
    },
    {
      "x": 2,
      "y": 42,
      "z": 14,
      "name": "Deco_Rope",
      "support": 15
    },
    {
      "x": 2,
      "y": 43,
      "z": 14,
      "name": "Deco_Rope",
      "support": 15
    },
    {
      "x": 2,
      "y": 44,
      "z": 14,
      "name": "Deco_Rope",
      "support": 15
    },
    {
      "x": 2,
      "y": 45,
      "z": 14,
      "name": "Deco_Rope",
      "support": 15
    },
    {
      "x": 2,
      "y": 46,
      "z": 14,
      "name": "Deco_Rope",
      "support": 15
    },
    {
      "x": 2,
      "y": 47,
      "z": 14,
      "name": "Deco_Rope",
      "support": 15
    },
    {
      "x": 2,
      "y": 48,
      "z": 14,
      "name": "Deco_Rope",
      "support": 15
    },
    {
      "x": 2,
      "y": 49,
      "z": 14,
      "name": "Deco_Rope",
      "support": 15
    },
    {
      "x": 2,
      "y": 50,
      "z": 14,
      "name": "Deco_Rope",
      "support": 15
    },
    {
      "x": 2,
      "y": 51,
      "z": 14,
      "name": "Deco_Rope",
      "support": 15
    },
    {
      "x": 2,
      "y": 52,
      "z": 14,
      "name": "Deco_Rope",
      "support": 15
    },
    {
      "x": 2,
      "y": 53,
      "z": 14,
      "name": "Deco_Rope",
      "support": 15
    },
    {
      "x": 2,
      "y": 54,
      "z": 14,
      "name": "Deco_Rope",
      "support": 15
    },
    {
      "x": 2,
      "y": 55,
      "z": 14,
      "name": "Deco_Rope",
      "support": 15
    },
    {
      "x": 2,
      "y": 56,
      "z": 14,
      "name": "Deco_Rope",
      "support": 15
    },
    {
      "x": 2,
      "y": 57,
      "z": 14,
      "name": "Deco_Rope",
      "support": 15
    },
    {
      "x": 2,
      "y": 58,
      "z": 14,
      "name": "Deco_Rope",
      "support": 15
    },
    {
      "x": 2,
      "y": 59,
      "z": 14,
      "name": "Deco_Rope",
      "support": 15
    },
    {
      "x": 2,
      "y": 60,
      "z": 14,
      "name": "Deco_Rope",
      "support": 15
    },
    {
      "x": 2,
      "y": 61,
      "z": 14,
      "name": "Deco_Rope",
      "support": 15
    },
    {
      "x": 2,
      "y": 62,
      "z": 14,
      "name": "Wood_Hardwood_Planks"
    },
    {
      "x": 2,
      "y": 0,
      "z": 15,
      "name": "Soil_Grass"
    },
    {
      "x": 2,
      "y": 0,
      "z": 16,
      "name": "Soil_Grass"
    },
    {
      "x": 2,
      "y": 0,
      "z": 17,
      "name": "Soil_Grass"
    },
    {
      "x": 2,
      "y": 0,
      "z": 18,
      "name": "Soil_Grass"
    },
    {
      "x": 2,
      "y": 0,
      "z": 19,
      "name": "Soil_Grass"
    },
    {
      "x": 2,
      "y": 0,
      "z": 20,
      "name": "Soil_Grass"
    },
    {
      "x": 2,
      "y": 0,
      "z": 21,
      "name": "Soil_Grass"
    },
    {
      "x": 2,
      "y": 0,
      "z": 22,
      "name": "Soil_Grass"
    },
    {
      "x": 2,
      "y": 0,
      "z": 23,
      "name": "Soil_Grass"
    },
    {
      "x": 2,
      "y": 0,
      "z": 24,
      "name": "Soil_Grass"
    },
    {
      "x": 2,
      "y": 0,
      "z": 25,
      "name": "Soil_Grass"
    },
    {
      "x": 2,
      "y": 0,
      "z": 26,
      "name": "Soil_Grass"
    },
    {
      "x": 2,
      "y": 0,
      "z": 27,
      "name": "Soil_Grass"
    },
    {
      "x": 2,
      "y": 0,
      "z": 28,
      "name": "Soil_Grass"
    },
    {
      "x": 2,
      "y": 0,
      "z": 29,
      "name": "Soil_Grass"
    },
    {
      "x": 2,
      "y": 0,
      "z": 30,
      "name": "Soil_Grass"
    },
    {
      "x": 3,
      "y": 0,
      "z": 1,
      "name": "Soil_Grass"
    },
    {
      "x": 3,
      "y": 0,
      "z": 2,
      "name": "Soil_Grass"
    },
    {
      "x": 3,
      "y": 0,
      "z": 3,
      "name": "Soil_Grass"
    },
    {
      "x": 3,
      "y": 0,
      "z": 4,
      "name": "Soil_Grass"
    },
    {
      "x": 3,
      "y": 0,
      "z": 5,
      "name": "Soil_Grass"
    },
    {
      "x": 3,
      "y": 0,
      "z": 6,
      "name": "Soil_Grass"
    },
    {
      "x": 3,
      "y": 0,
      "z": 7,
      "name": "Soil_Grass"
    },
    {
      "x": 3,
      "y": 0,
      "z": 8,
      "name": "Soil_Grass"
    },
    {
      "x": 3,
      "y": 0,
      "z": 9,
      "name": "Soil_Grass"
    },
    {
      "x": 3,
      "y": 0,
      "z": 10,
      "name": "Soil_Grass"
    },
    {
      "x": 3,
      "y": 64,
      "z": 10,
      "name": "Wood_Hardwood_Planks_Half",
      "rotation": 8
    },
    {
      "x": 3,
      "y": 65,
      "z": 10,
      "name": "Cloth_Block_Wool_Purple"
    },
    {
      "x": 3,
      "y": 0,
      "z": 11,
      "name": "Soil_Grass"
    },
    {
      "x": 3,
      "y": 64,
      "z": 11,
      "name": "Wood_Hardwood_Planks"
    },
    {
      "x": 3,
      "y": 65,
      "z": 11,
      "name": "Cloth_Block_Wool_Purple"
    },
    {
      "x": 3,
      "y": 0,
      "z": 12,
      "name": "Soil_Grass"
    },
    {
      "x": 3,
      "y": 59,
      "z": 12,
      "name": "Wood_Hardwood_Planks_Half"
    },
    {
      "x": 3,
      "y": 60,
      "z": 12,
      "name": "Wood_Hardwood_Planks_Half"
    },
    {
      "x": 3,
      "y": 63,
      "z": 12,
      "name": "Wood_Hardwood_Planks_Half",
      "rotation": 8
    },
    {
      "x": 3,
      "y": 64,
      "z": 12,
      "name": "Wood_Hardwood_Planks"
    },
    {
      "x": 3,
      "y": 65,
      "z": 12,
      "name": "Cloth_Block_Wool_Purple"
    },
    {
      "x": 3,
      "y": 0,
      "z": 13,
      "name": "Soil_Grass"
    },
    {
      "x": 3,
      "y": 27,
      "z": 13,
      "name": "Plant_Leaves_Bottle",
      "support": 15
    },
    {
      "x": 3,
      "y": 28,
      "z": 13,
      "name": "Plant_Leaves_Bottle",
      "support": 15
    },
    {
      "x": 3,
      "y": 29,
      "z": 13,
      "name": "Plant_Leaves_Bottle",
      "support": 15
    },
    {
      "x": 3,
      "y": 59,
      "z": 13,
      "name": "Wood_Hardwood_Planks_Half",
      "rotation": 8
    },
    {
      "x": 3,
      "y": 64,
      "z": 13,
      "name": "Wood_Hardwood_Planks"
    },
    {
      "x": 3,
      "y": 65,
      "z": 13,
      "name": "Cloth_Block_Wool_Purple"
    },
    {
      "x": 3,
      "y": 66,
      "z": 13,
      "name": "Soil_Clay_Purple"
    },
    {
      "x": 3,
      "y": 0,
      "z": 14,
      "name": "Soil_Grass"
    },
    {
      "x": 3,
      "y": 58,
      "z": 14,
      "name": "Wood_Hardwood_Planks_Half",
      "rotation": 8
    },
    {
      "x": 3,
      "y": 59,
      "z": 14,
      "name": "Wood_Hardwood_Planks"
    },
    {
      "x": 3,
      "y": 62,
      "z": 14,
      "name": "Wood_Hardwood_Planks"
    },
    {
      "x": 3,
      "y": 64,
      "z": 14,
      "name": "Wood_Hardwood_Planks"
    },
    {
      "x": 3,
      "y": 65,
      "z": 14,
      "name": "Cloth_Block_Wool_Purple"
    },
    {
      "x": 3,
      "y": 66,
      "z": 14,
      "name": "Soil_Clay_Purple"
    },
    {
      "x": 3,
      "y": 0,
      "z": 15,
      "name": "Soil_Grass"
    },
    {
      "x": 3,
      "y": 58,
      "z": 15,
      "name": "Wood_Hardwood_Planks_Half",
      "rotation": 8
    },
    {
      "x": 3,
      "y": 59,
      "z": 15,
      "name": "Wood_Hardwood_Planks"
    },
    {
      "x": 3,
      "y": 62,
      "z": 15,
      "name": "Wood_Hardwood_Planks_Half",
      "rotation": 8
    },
    {
      "x": 3,
      "y": 64,
      "z": 15,
      "name": "Wood_Hardwood_Planks"
    },
    {
      "x": 3,
      "y": 65,
      "z": 15,
      "name": "Cloth_Block_Wool_Purple"
    },
    {
      "x": 3,
      "y": 66,
      "z": 15,
      "name": "Soil_Clay_Purple"
    },
    {
      "x": 3,
      "y": 0,
      "z": 16,
      "name": "Soil_Grass"
    },
    {
      "x": 3,
      "y": 58,
      "z": 16,
      "name": "Wood_Hardwood_Planks_Half",
      "rotation": 8
    },
    {
      "x": 3,
      "y": 59,
      "z": 16,
      "name": "Wood_Hardwood_Planks"
    },
    {
      "x": 3,
      "y": 62,
      "z": 16,
      "name": "Wood_Hardwood_Planks"
    },
    {
      "x": 3,
      "y": 64,
      "z": 16,
      "name": "Wood_Hardwood_Planks"
    },
    {
      "x": 3,
      "y": 65,
      "z": 16,
      "name": "Cloth_Block_Wool_Purple"
    },
    {
      "x": 3,
      "y": 66,
      "z": 16,
      "name": "Soil_Clay_Purple"
    },
    {
      "x": 3,
      "y": 0,
      "z": 17,
      "name": "Soil_Grass"
    },
    {
      "x": 3,
      "y": 59,
      "z": 17,
      "name": "Wood_Hardwood_Planks_Half",
      "rotation": 8
    },
    {
      "x": 3,
      "y": 64,
      "z": 17,
      "name": "Wood_Hardwood_Planks"
    },
    {
      "x": 3,
      "y": 65,
      "z": 17,
      "name": "Cloth_Block_Wool_Purple"
    },
    {
      "x": 3,
      "y": 66,
      "z": 17,
      "name": "Cloth_Block_Wool_Purple"
    },
    {
      "x": 3,
      "y": 0,
      "z": 18,
      "name": "Soil_Grass"
    },
    {
      "x": 3,
      "y": 59,
      "z": 18,
      "name": "Wood_Hardwood_Planks_Half"
    },
    {
      "x": 3,
      "y": 60,
      "z": 18,
      "name": "Wood_Hardwood_Planks_Half"
    },
    {
      "x": 3,
      "y": 63,
      "z": 18,
      "name": "Wood_Hardwood_Planks_Half",
      "rotation": 8
    },
    {
      "x": 3,
      "y": 64,
      "z": 18,
      "name": "Wood_Hardwood_Planks"
    },
    {
      "x": 3,
      "y": 65,
      "z": 18,
      "name": "Cloth_Block_Wool_Purple"
    },
    {
      "x": 3,
      "y": 0,
      "z": 19,
      "name": "Soil_Grass"
    },
    {
      "x": 3,
      "y": 64,
      "z": 19,
      "name": "Wood_Hardwood_Planks"
    },
    {
      "x": 3,
      "y": 65,
      "z": 19,
      "name": "Cloth_Block_Wool_Purple"
    },
    {
      "x": 3,
      "y": 0,
      "z": 20,
      "name": "Soil_Grass"
    },
    {
      "x": 3,
      "y": 64,
      "z": 20,
      "name": "Wood_Hardwood_Planks_Half",
      "rotation": 8
    },
    {
      "x": 3,
      "y": 65,
      "z": 20,
      "name": "Soil_Clay_Purple"
    },
    {
      "x": 3,
      "y": 0,
      "z": 21,
      "name": "Soil_Grass"
    },
    {
      "x": 3,
      "y": 0,
      "z": 22,
      "name": "Soil_Grass"
    },
    {
      "x": 3,
      "y": 0,
      "z": 23,
      "name": "Soil_Grass"
    },
    {
      "x": 3,
      "y": 0,
      "z": 24,
      "name": "Soil_Grass"
    },
    {
      "x": 3,
      "y": 0,
      "z": 25,
      "name": "Soil_Grass"
    },
    {
      "x": 3,
      "y": 0,
      "z": 26,
      "name": "Soil_Grass"
    },
    {
      "x": 3,
      "y": 0,
      "z": 27,
      "name": "Soil_Grass"
    },
    {
      "x": 3,
      "y": 0,
      "z": 28,
      "name": "Soil_Grass"
    },
    {
      "x": 3,
      "y": 0,
      "z": 29,
      "name": "Soil_Grass"
    },
    {
      "x": 3,
      "y": 0,
      "z": 30,
      "name": "Soil_Grass"
    },
    {
      "x": 4,
      "y": 0,
      "z": 1,
      "name": "Soil_Grass"
    },
    {
      "x": 4,
      "y": 0,
      "z": 2,
      "name": "Soil_Grass"
    },
    {
      "x": 4,
      "y": 0,
      "z": 3,
      "name": "Soil_Grass"
    },
    {
      "x": 4,
      "y": 0,
      "z": 4,
      "name": "Soil_Grass"
    },
    {
      "x": 4,
      "y": 0,
      "z": 5,
      "name": "Soil_Grass"
    },
    {
      "x": 4,
      "y": 0,
      "z": 6,
      "name": "Soil_Grass"
    },
    {
      "x": 4,
      "y": 0,
      "z": 7,
      "name": "Soil_Grass"
    },
    {
      "x": 4,
      "y": 0,
      "z": 8,
      "name": "Soil_Grass"
    },
    {
      "x": 4,
      "y": 0,
      "z": 9,
      "name": "Soil_Grass"
    },
    {
      "x": 4,
      "y": 64,
      "z": 9,
      "name": "Wood_Hardwood_Planks_Half",
      "rotation": 8
    },
    {
      "x": 4,
      "y": 65,
      "z": 9,
      "name": "Soil_Clay_Purple"
    },
    {
      "x": 4,
      "y": 0,
      "z": 10,
      "name": "Soil_Grass"
    },
    {
      "x": 4,
      "y": 59,
      "z": 10,
      "name": "Wood_Hardwood_Planks_Half"
    },
    {
      "x": 4,
      "y": 60,
      "z": 10,
      "name": "Wood_Hardwood_Planks_Half"
    },
    {
      "x": 4,
      "y": 63,
      "z": 10,
      "name": "Wood_Hardwood_Planks_Half",
      "rotation": 8
    },
    {
      "x": 4,
      "y": 64,
      "z": 10,
      "name": "Wood_Hardwood_Planks"
    },
    {
      "x": 4,
      "y": 65,
      "z": 10,
      "name": "Cloth_Block_Wool_Purple"
    },
    {
      "x": 4,
      "y": 0,
      "z": 11,
      "name": "Soil_Grass"
    },
    {
      "x": 4,
      "y": 2,
      "z": 11,
      "name": "Plant_Leaves_Bottle",
      "support": 15
    },
    {
      "x": 4,
      "y": 3,
      "z": 11,
      "name": "Plant_Leaves_Bottle",
      "support": 15
    },
    {
      "x": 4,
      "y": 59,
      "z": 11,
      "name": "Wood_Hardwood_Planks_Half"
    },
    {
      "x": 4,
      "y": 60,
      "z": 11,
      "name": "Wood_Hardwood_Planks_Half"
    },
    {
      "x": 4,
      "y": 63,
      "z": 11,
      "name": "Wood_Hardwood_Planks_Half",
      "rotation": 8
    },
    {
      "x": 4,
      "y": 64,
      "z": 11,
      "name": "Wood_Hardwood_Planks"
    },
    {
      "x": 4,
      "y": 66,
      "z": 11,
      "name": "Cloth_Block_Wool_Purple"
    },
    {
      "x": 4,
      "y": 67,
      "z": 11,
      "name": "Cloth_Block_Wool_Purple"
    },
    {
      "x": 4,
      "y": 0,
      "z": 12,
      "name": "Soil_Grass"
    },
    {
      "x": 4,
      "y": 1,
      "z": 12,
      "name": "Plant_Leaves_Bottle",
      "support": 15
    },
    {
      "x": 4,
      "y": 2,
      "z": 12,
      "name": "Plant_Leaves_Bottle",
      "support": 15
    },
    {
      "x": 4,
      "y": 25,
      "z": 12,
      "name": "Plant_Leaves_Bottle",
      "support": 15
    },
    {
      "x": 4,
      "y": 26,
      "z": 12,
      "name": "Plant_Leaves_Bottle",
      "support": 15
    },
    {
      "x": 4,
      "y": 57,
      "z": 12,
      "name": "Wood_Hardwood_Planks"
    },
    {
      "x": 4,
      "y": 58,
      "z": 12,
      "name": "Wood_Hardwood_Planks"
    },
    {
      "x": 4,
      "y": 59,
      "z": 12,
      "name": "Rock_Chalk_Brick_Smooth"
    },
    {
      "x": 4,
      "y": 60,
      "z": 12,
      "name": "Rock_Chalk_Brick_Smooth"
    },
    {
      "x": 4,
      "y": 61,
      "z": 12,
      "name": "Rock_Chalk_Brick_Smooth"
    },
    {
      "x": 4,
      "y": 62,
      "z": 12,
      "name": "Rock_Chalk_Brick_Smooth"
    },
    {
      "x": 4,
      "y": 63,
      "z": 12,
      "name": "Rock_Chalk_Brick_Smooth"
    },
    {
      "x": 4,
      "y": 66,
      "z": 12,
      "name": "Soil_Clay_Purple"
    },
    {
      "x": 4,
      "y": 67,
      "z": 12,
      "name": "Soil_Clay_Purple"
    },
    {
      "x": 4,
      "y": 68,
      "z": 12,
      "name": "Cloth_Block_Wool_Purple"
    },
    {
      "x": 4,
      "y": 0,
      "z": 13,
      "name": "Soil_Grass"
    },
    {
      "x": 4,
      "y": 2,
      "z": 13,
      "name": "Plant_Leaves_Bottle",
      "support": 15
    },
    {
      "x": 4,
      "y": 3,
      "z": 13,
      "name": "Plant_Leaves_Bottle",
      "support": 15
    },
    {
      "x": 4,
      "y": 4,
      "z": 13,
      "name": "Plant_Leaves_Bottle",
      "support": 15
    },
    {
      "x": 4,
      "y": 5,
      "z": 13,
      "name": "Plant_Leaves_Bottle",
      "support": 15
    },
    {
      "x": 4,
      "y": 26,
      "z": 13,
      "name": "Plant_Leaves_Bottle",
      "support": 15
    },
    {
      "x": 4,
      "y": 27,
      "z": 13,
      "name": "Plant_Leaves_Bottle",
      "support": 15
    },
    {
      "x": 4,
      "y": 28,
      "z": 13,
      "name": "Plant_Leaves_Bottle",
      "support": 15
    },
    {
      "x": 4,
      "y": 29,
      "z": 13,
      "name": "Plant_Leaves_Bottle",
      "support": 15
    },
    {
      "x": 4,
      "y": 50,
      "z": 13,
      "name": "Wood_Hardwood_Stairs",
      "rotation": 9
    },
    {
      "x": 4,
      "y": 51,
      "z": 13,
      "name": "Wood_Hardwood_Planks"
    },
    {
      "x": 4,
      "y": 52,
      "z": 13,
      "name": "Wood_Hardwood_Planks_Half"
    },
    {
      "x": 4,
      "y": 57,
      "z": 13,
      "name": "Wood_Hardwood_Planks"
    },
    {
      "x": 4,
      "y": 58,
      "z": 13,
      "name": "Wood_Hardwood_Planks"
    },
    {
      "x": 4,
      "y": 59,
      "z": 13,
      "name": "Rock_Chalk_Brick_Smooth"
    },
    {
      "x": 4,
      "y": 60,
      "z": 13,
      "name": "Rock_Chalk_Brick_Smooth"
    },
    {
      "x": 4,
      "y": 61,
      "z": 13,
      "name": "Rock_Chalk_Brick_Smooth"
    },
    {
      "x": 4,
      "y": 62,
      "z": 13,
      "name": "Rock_Chalk_Brick_Smooth"
    },
    {
      "x": 4,
      "y": 63,
      "z": 13,
      "name": "Rock_Chalk_Brick_Smooth"
    },
    {
      "x": 4,
      "y": 67,
      "z": 13,
      "name": "Soil_Clay_Purple"
    },
    {
      "x": 4,
      "y": 68,
      "z": 13,
      "name": "Soil_Clay_Purple"
    },
    {
      "x": 4,
      "y": 69,
      "z": 13,
      "name": "Cloth_Block_Wool_Purple"
    },
    {
      "x": 4,
      "y": 0,
      "z": 14,
      "name": "Soil_Grass"
    },
    {
      "x": 4,
      "y": 2,
      "z": 14,
      "name": "Plant_Leaves_Bottle",
      "support": 15
    },
    {
      "x": 4,
      "y": 3,
      "z": 14,
      "name": "Plant_Leaves_Bottle",
      "support": 15
    },
    {
      "x": 4,
      "y": 5,
      "z": 14,
      "name": "Plant_Leaves_Bottle",
      "support": 15
    },
    {
      "x": 4,
      "y": 11,
      "z": 14,
      "name": "Rock_Stone_Brick_Smooth"
    },
    {
      "x": 4,
      "y": 12,
      "z": 14,
      "name": "Rock_Stone_Brick_Smooth"
    },
    {
      "x": 4,
      "y": 22,
      "z": 14,
      "name": "Rock_Stone_Brick_Smooth"
    },
    {
      "x": 4,
      "y": 23,
      "z": 14,
      "name": "Rock_Stone_Brick_Smooth"
    },
    {
      "x": 4,
      "y": 24,
      "z": 14,
      "name": "Rock_Stone_Brick_Smooth"
    },
    {
      "x": 4,
      "y": 25,
      "z": 14,
      "name": "Rock_Stone_Brick_Smooth"
    },
    {
      "x": 4,
      "y": 28,
      "z": 14,
      "name": "Plant_Leaves_Bottle",
      "support": 15
    },
    {
      "x": 4,
      "y": 51,
      "z": 14,
      "name": "Wood_Hardwood_Planks"
    },
    {
      "x": 4,
      "y": 52,
      "z": 14,
      "name": "Wood_Hardwood_Planks"
    },
    {
      "x": 4,
      "y": 57,
      "z": 14,
      "name": "Wood_Hardwood_Planks"
    },
    {
      "x": 4,
      "y": 58,
      "z": 14,
      "name": "Wood_Hardwood_Planks"
    },
    {
      "x": 4,
      "y": 59,
      "z": 14,
      "name": "Wood_Hardwood_Planks"
    },
    {
      "x": 4,
      "y": 62,
      "z": 14,
      "name": "Wood_Hardwood_Planks"
    },
    {
      "x": 4,
      "y": 63,
      "z": 14,
      "name": "Rock_Chalk_Brick_Smooth"
    },
    {
      "x": 4,
      "y": 67,
      "z": 14,
      "name": "Cloth_Block_Wool_Purple"
    },
    {
      "x": 4,
      "y": 68,
      "z": 14,
      "name": "Soil_Clay_Purple"
    },
    {
      "x": 4,
      "y": 69,
      "z": 14,
      "name": "Soil_Clay_Purple"
    },
    {
      "x": 4,
      "y": 70,
      "z": 14,
      "name": "Cloth_Block_Wool_Purple"
    },
    {
      "x": 4,
      "y": 0,
      "z": 15,
      "name": "Soil_Grass"
    },
    {
      "x": 4,
      "y": 2,
      "z": 15,
      "name": "Plant_Leaves_Bottle",
      "support": 15
    },
    {
      "x": 4,
      "y": 3,
      "z": 15,
      "name": "Plant_Leaves_Bottle",
      "support": 15
    },
    {
      "x": 4,
      "y": 10,
      "z": 15,
      "name": "Rock_Stone_Brick_Smooth"
    },
    {
      "x": 4,
      "y": 11,
      "z": 15,
      "name": "Rock_Stone_Brick_Smooth"
    },
    {
      "x": 4,
      "y": 12,
      "z": 15,
      "name": "Rock_Stone_Brick_Smooth"
    },
    {
      "x": 4,
      "y": 13,
      "z": 15,
      "name": "Rock_Stone_Brick_Smooth"
    },
    {
      "x": 4,
      "y": 14,
      "z": 15,
      "name": "Rock_Stone_Brick_Smooth"
    },
    {
      "x": 4,
      "y": 21,
      "z": 15,
      "name": "Rock_Stone_Brick_Smooth"
    },
    {
      "x": 4,
      "y": 22,
      "z": 15,
      "name": "Rock_Stone_Brick_Smooth"
    },
    {
      "x": 4,
      "y": 23,
      "z": 15,
      "name": "Rock_Stone_Brick_Smooth"
    },
    {
      "x": 4,
      "y": 24,
      "z": 15,
      "name": "Rock_Stone_Brick_Smooth"
    },
    {
      "x": 4,
      "y": 25,
      "z": 15,
      "name": "Rock_Stone_Brick_Smooth"
    },
    {
      "x": 4,
      "y": 26,
      "z": 15,
      "name": "Rock_Stone_Brick_Smooth"
    },
    {
      "x": 4,
      "y": 50,
      "z": 15,
      "name": "Wood_Hardwood_Stairs",
      "rotation": 9
    },
    {
      "x": 4,
      "y": 51,
      "z": 15,
      "name": "Wood_Hardwood_Planks"
    },
    {
      "x": 4,
      "y": 52,
      "z": 15,
      "name": "Wood_Hardwood_Planks"
    },
    {
      "x": 4,
      "y": 57,
      "z": 15,
      "name": "Wood_Hardwood_Planks"
    },
    {
      "x": 4,
      "y": 58,
      "z": 15,
      "name": "Wood_Hardwood_Planks"
    },
    {
      "x": 4,
      "y": 59,
      "z": 15,
      "name": "Wood_Hardwood_Planks"
    },
    {
      "x": 4,
      "y": 62,
      "z": 15,
      "name": "*Furniture_Crude_Trapdoor_State_Definitions_CloseDoorOut",
      "rotation": 3
    },
    {
      "x": 4,
      "y": 63,
      "z": 15,
      "name": "Rock_Chalk_Brick_Smooth"
    },
    {
      "x": 4,
      "y": 67,
      "z": 15,
      "name": "Soil_Clay_Purple"
    },
    {
      "x": 4,
      "y": 68,
      "z": 15,
      "name": "Cloth_Block_Wool_Purple"
    },
    {
      "x": 4,
      "y": 69,
      "z": 15,
      "name": "Soil_Clay_Purple"
    },
    {
      "x": 4,
      "y": 70,
      "z": 15,
      "name": "Cloth_Block_Wool_Purple"
    },
    {
      "x": 4,
      "y": 0,
      "z": 16,
      "name": "Soil_Grass"
    },
    {
      "x": 4,
      "y": 2,
      "z": 16,
      "name": "Plant_Leaves_Bottle",
      "support": 15
    },
    {
      "x": 4,
      "y": 3,
      "z": 16,
      "name": "Plant_Leaves_Bottle",
      "support": 15
    },
    {
      "x": 4,
      "y": 4,
      "z": 16,
      "name": "Plant_Leaves_Bottle",
      "support": 15
    },
    {
      "x": 4,
      "y": 9,
      "z": 16,
      "name": "Rock_Stone_Brick_Smooth"
    },
    {
      "x": 4,
      "y": 10,
      "z": 16,
      "name": "Rock_Stone_Brick_Smooth"
    },
    {
      "x": 4,
      "y": 11,
      "z": 16,
      "name": "Rock_Stone_Brick_Smooth"
    },
    {
      "x": 4,
      "y": 12,
      "z": 16,
      "name": "Rock_Stone_Brick_Smooth"
    },
    {
      "x": 4,
      "y": 13,
      "z": 16,
      "name": "Rock_Stone_Brick_Smooth"
    },
    {
      "x": 4,
      "y": 14,
      "z": 16,
      "name": "Rock_Stone_Brick_Smooth"
    },
    {
      "x": 4,
      "y": 23,
      "z": 16,
      "name": "Rock_Stone_Brick_Smooth"
    },
    {
      "x": 4,
      "y": 24,
      "z": 16,
      "name": "Rock_Stone_Brick_Smooth"
    },
    {
      "x": 4,
      "y": 25,
      "z": 16,
      "name": "Rock_Stone_Brick_Smooth"
    },
    {
      "x": 4,
      "y": 26,
      "z": 16,
      "name": "Rock_Stone_Brick_Smooth"
    },
    {
      "x": 4,
      "y": 51,
      "z": 16,
      "name": "Wood_Hardwood_Planks"
    },
    {
      "x": 4,
      "y": 52,
      "z": 16,
      "name": "Wood_Hardwood_Planks"
    },
    {
      "x": 4,
      "y": 57,
      "z": 16,
      "name": "Wood_Hardwood_Planks"
    },
    {
      "x": 4,
      "y": 58,
      "z": 16,
      "name": "Wood_Hardwood_Planks"
    },
    {
      "x": 4,
      "y": 59,
      "z": 16,
      "name": "Wood_Hardwood_Planks"
    },
    {
      "x": 4,
      "y": 62,
      "z": 16,
      "name": "Wood_Hardwood_Planks"
    },
    {
      "x": 4,
      "y": 63,
      "z": 16,
      "name": "Rock_Chalk_Brick_Smooth"
    },
    {
      "x": 4,
      "y": 67,
      "z": 16,
      "name": "Soil_Clay_Purple"
    },
    {
      "x": 4,
      "y": 68,
      "z": 16,
      "name": "Cloth_Block_Wool_Purple"
    },
    {
      "x": 4,
      "y": 69,
      "z": 16,
      "name": "Soil_Clay_Purple"
    },
    {
      "x": 4,
      "y": 70,
      "z": 16,
      "name": "Soil_Clay_Purple"
    },
    {
      "x": 4,
      "y": 0,
      "z": 17,
      "name": "Soil_Grass"
    },
    {
      "x": 4,
      "y": 2,
      "z": 17,
      "name": "Plant_Leaves_Bottle",
      "support": 15
    },
    {
      "x": 4,
      "y": 12,
      "z": 17,
      "name": "Rock_Stone_Brick_Smooth"
    },
    {
      "x": 4,
      "y": 13,
      "z": 17,
      "name": "Rock_Stone_Brick_Smooth"
    },
    {
      "x": 4,
      "y": 14,
      "z": 17,
      "name": "Rock_Stone_Brick_Smooth"
    },
    {
      "x": 4,
      "y": 15,
      "z": 17,
      "name": "Rock_Stone_Brick_Smooth"
    },
    {
      "x": 4,
      "y": 16,
      "z": 17,
      "name": "Rock_Stone_Brick_Smooth"
    },
    {
      "x": 4,
      "y": 25,
      "z": 17,
      "name": "Rock_Stone_Brick_Smooth"
    },
    {
      "x": 4,
      "y": 50,
      "z": 17,
      "name": "Wood_Hardwood_Stairs",
      "rotation": 9
    },
    {
      "x": 4,
      "y": 51,
      "z": 17,
      "name": "Wood_Hardwood_Planks"
    },
    {
      "x": 4,
      "y": 52,
      "z": 17,
      "name": "Wood_Hardwood_Planks_Half"
    },
    {
      "x": 4,
      "y": 57,
      "z": 17,
      "name": "Wood_Hardwood_Planks"
    },
    {
      "x": 4,
      "y": 58,
      "z": 17,
      "name": "Wood_Hardwood_Planks"
    },
    {
      "x": 4,
      "y": 59,
      "z": 17,
      "name": "Rock_Chalk_Brick_Smooth"
    },
    {
      "x": 4,
      "y": 60,
      "z": 17,
      "name": "Rock_Chalk_Brick_Smooth"
    },
    {
      "x": 4,
      "y": 61,
      "z": 17,
      "name": "Rock_Chalk_Brick_Smooth"
    },
    {
      "x": 4,
      "y": 62,
      "z": 17,
      "name": "Rock_Chalk_Brick_Smooth"
    },
    {
      "x": 4,
      "y": 63,
      "z": 17,
      "name": "Rock_Chalk_Brick_Smooth"
    },
    {
      "x": 4,
      "y": 67,
      "z": 17,
      "name": "Cloth_Block_Wool_Purple"
    },
    {
      "x": 4,
      "y": 68,
      "z": 17,
      "name": "Cloth_Block_Wool_Purple"
    },
    {
      "x": 4,
      "y": 69,
      "z": 17,
      "name": "Soil_Clay_Purple"
    },
    {
      "x": 4,
      "y": 0,
      "z": 18,
      "name": "Soil_Grass"
    },
    {
      "x": 4,
      "y": 13,
      "z": 18,
      "name": "Rock_Stone_Brick_Smooth"
    },
    {
      "x": 4,
      "y": 14,
      "z": 18,
      "name": "Rock_Stone_Brick_Smooth"
    },
    {
      "x": 4,
      "y": 57,
      "z": 18,
      "name": "Wood_Hardwood_Planks"
    },
    {
      "x": 4,
      "y": 58,
      "z": 18,
      "name": "Wood_Hardwood_Planks"
    },
    {
      "x": 4,
      "y": 59,
      "z": 18,
      "name": "Rock_Chalk_Brick_Smooth"
    },
    {
      "x": 4,
      "y": 60,
      "z": 18,
      "name": "Rock_Chalk_Brick_Smooth"
    },
    {
      "x": 4,
      "y": 61,
      "z": 18,
      "name": "Rock_Chalk_Brick_Smooth"
    },
    {
      "x": 4,
      "y": 62,
      "z": 18,
      "name": "Rock_Chalk_Brick_Smooth"
    },
    {
      "x": 4,
      "y": 63,
      "z": 18,
      "name": "Rock_Chalk_Brick_Smooth"
    },
    {
      "x": 4,
      "y": 66,
      "z": 18,
      "name": "Soil_Clay_Purple"
    },
    {
      "x": 4,
      "y": 67,
      "z": 18,
      "name": "Soil_Clay_Purple"
    },
    {
      "x": 4,
      "y": 68,
      "z": 18,
      "name": "Soil_Clay_Purple"
    },
    {
      "x": 4,
      "y": 0,
      "z": 19,
      "name": "Soil_Grass"
    },
    {
      "x": 4,
      "y": 59,
      "z": 19,
      "name": "Wood_Hardwood_Planks_Half"
    },
    {
      "x": 4,
      "y": 60,
      "z": 19,
      "name": "Wood_Hardwood_Planks_Half"
    },
    {
      "x": 4,
      "y": 63,
      "z": 19,
      "name": "Wood_Hardwood_Planks_Half",
      "rotation": 8
    },
    {
      "x": 4,
      "y": 64,
      "z": 19,
      "name": "Wood_Hardwood_Planks"
    },
    {
      "x": 4,
      "y": 66,
      "z": 19,
      "name": "Soil_Clay_Purple"
    },
    {
      "x": 4,
      "y": 67,
      "z": 19,
      "name": "Soil_Clay_Purple"
    },
    {
      "x": 4,
      "y": 0,
      "z": 20,
      "name": "Soil_Grass"
    },
    {
      "x": 4,
      "y": 59,
      "z": 20,
      "name": "Wood_Hardwood_Planks_Half"
    },
    {
      "x": 4,
      "y": 60,
      "z": 20,
      "name": "Wood_Hardwood_Planks_Half"
    },
    {
      "x": 4,
      "y": 63,
      "z": 20,
      "name": "Wood_Hardwood_Planks_Half",
      "rotation": 8
    },
    {
      "x": 4,
      "y": 64,
      "z": 20,
      "name": "Wood_Hardwood_Planks"
    },
    {
      "x": 4,
      "y": 65,
      "z": 20,
      "name": "Soil_Clay_Purple"
    },
    {
      "x": 4,
      "y": 0,
      "z": 21,
      "name": "Soil_Grass"
    },
    {
      "x": 4,
      "y": 64,
      "z": 21,
      "name": "Wood_Hardwood_Planks_Half",
      "rotation": 8
    },
    {
      "x": 4,
      "y": 65,
      "z": 21,
      "name": "Soil_Clay_Purple"
    },
    {
      "x": 4,
      "y": 0,
      "z": 22,
      "name": "Soil_Grass"
    },
    {
      "x": 4,
      "y": 0,
      "z": 23,
      "name": "Soil_Grass"
    },
    {
      "x": 4,
      "y": 0,
      "z": 24,
      "name": "Soil_Grass"
    },
    {
      "x": 4,
      "y": 0,
      "z": 25,
      "name": "Soil_Grass"
    },
    {
      "x": 4,
      "y": 0,
      "z": 26,
      "name": "Soil_Grass"
    },
    {
      "x": 4,
      "y": 0,
      "z": 27,
      "name": "Soil_Grass"
    },
    {
      "x": 4,
      "y": 0,
      "z": 28,
      "name": "Soil_Grass"
    },
    {
      "x": 4,
      "y": 0,
      "z": 29,
      "name": "Soil_Grass"
    },
    {
      "x": 4,
      "y": 0,
      "z": 30,
      "name": "Soil_Grass"
    },
    {
      "x": 5,
      "y": 0,
      "z": 1,
      "name": "Soil_Grass"
    },
    {
      "x": 5,
      "y": 0,
      "z": 2,
      "name": "Soil_Grass"
    },
    {
      "x": 5,
      "y": 0,
      "z": 3,
      "name": "Soil_Grass"
    },
    {
      "x": 5,
      "y": 0,
      "z": 4,
      "name": "Soil_Grass"
    },
    {
      "x": 5,
      "y": 0,
      "z": 5,
      "name": "Soil_Grass"
    },
    {
      "x": 5,
      "y": 0,
      "z": 6,
      "name": "Soil_Grass"
    },
    {
      "x": 5,
      "y": 0,
      "z": 7,
      "name": "Soil_Grass"
    },
    {
      "x": 5,
      "y": 0,
      "z": 8,
      "name": "Soil_Grass"
    },
    {
      "x": 5,
      "y": 20,
      "z": 8,
      "name": "Plant_Leaves_Bottle",
      "support": 15
    },
    {
      "x": 5,
      "y": 64,
      "z": 8,
      "name": "Wood_Hardwood_Planks_Half",
      "rotation": 8
    },
    {
      "x": 5,
      "y": 65,
      "z": 8,
      "name": "Soil_Clay_Purple"
    },
    {
      "x": 5,
      "y": 0,
      "z": 9,
      "name": "Soil_Grass"
    },
    {
      "x": 5,
      "y": 20,
      "z": 9,
      "name": "Plant_Leaves_Bottle",
      "support": 15
    },
    {
      "x": 5,
      "y": 21,
      "z": 9,
      "name": "Plant_Leaves_Bottle",
      "support": 15
    },
    {
      "x": 5,
      "y": 59,
      "z": 9,
      "name": "Wood_Hardwood_Planks_Half"
    },
    {
      "x": 5,
      "y": 60,
      "z": 9,
      "name": "Wood_Hardwood_Planks_Half"
    },
    {
      "x": 5,
      "y": 63,
      "z": 9,
      "name": "Wood_Hardwood_Planks_Half",
      "rotation": 8
    },
    {
      "x": 5,
      "y": 64,
      "z": 9,
      "name": "Wood_Hardwood_Planks"
    },
    {
      "x": 5,
      "y": 66,
      "z": 9,
      "name": "Soil_Clay_Purple"
    },
    {
      "x": 5,
      "y": 0,
      "z": 10,
      "name": "Soil_Grass"
    },
    {
      "x": 5,
      "y": 22,
      "z": 10,
      "name": "Plant_Leaves_Bottle",
      "support": 15
    },
    {
      "x": 5,
      "y": 23,
      "z": 10,
      "name": "Plant_Leaves_Bottle",
      "support": 15
    },
    {
      "x": 5,
      "y": 51,
      "z": 10,
      "name": "Wood_Hardwood_Planks"
    },
    {
      "x": 5,
      "y": 52,
      "z": 10,
      "name": "Wood_Hardwood_Planks_Half"
    },
    {
      "x": 5,
      "y": 57,
      "z": 10,
      "name": "Wood_Hardwood_Planks"
    },
    {
      "x": 5,
      "y": 58,
      "z": 10,
      "name": "Wood_Hardwood_Planks"
    },
    {
      "x": 5,
      "y": 59,
      "z": 10,
      "name": "Rock_Chalk_Brick_Smooth"
    },
    {
      "x": 5,
      "y": 60,
      "z": 10,
      "name": "Rock_Chalk_Brick_Smooth"
    },
    {
      "x": 5,
      "y": 61,
      "z": 10,
      "name": "Rock_Chalk_Brick_Smooth"
    },
    {
      "x": 5,
      "y": 62,
      "z": 10,
      "name": "Rock_Chalk_Brick_Smooth"
    },
    {
      "x": 5,
      "y": 63,
      "z": 10,
      "name": "Rock_Chalk_Brick_Smooth"
    },
    {
      "x": 5,
      "y": 66,
      "z": 10,
      "name": "Cloth_Block_Wool_Purple"
    },
    {
      "x": 5,
      "y": 67,
      "z": 10,
      "name": "Cloth_Block_Wool_Purple"
    },
    {
      "x": 5,
      "y": 68,
      "z": 10,
      "name": "Soil_Clay_Purple"
    },
    {
      "x": 5,
      "y": 0,
      "z": 11,
      "name": "Soil_Grass"
    },
    {
      "x": 5,
      "y": 2,
      "z": 11,
      "name": "Plant_Leaves_Bottle",
      "support": 15
    },
    {
      "x": 5,
      "y": 3,
      "z": 11,
      "name": "Plant_Leaves_Bottle",
      "support": 15
    },
    {
      "x": 5,
      "y": 4,
      "z": 11,
      "name": "Plant_Leaves_Bottle",
      "support": 15
    },
    {
      "x": 5,
      "y": 6,
      "z": 11,
      "name": "Plant_Leaves_Bottle",
      "support": 15
    },
    {
      "x": 5,
      "y": 7,
      "z": 11,
      "name": "Plant_Leaves_Bottle",
      "support": 15
    },
    {
      "x": 5,
      "y": 23,
      "z": 11,
      "name": "Plant_Leaves_Bottle",
      "support": 15
    },
    {
      "x": 5,
      "y": 24,
      "z": 11,
      "name": "Plant_Leaves_Bottle",
      "support": 15
    },
    {
      "x": 5,
      "y": 25,
      "z": 11,
      "name": "Plant_Leaves_Bottle",
      "support": 15
    },
    {
      "x": 5,
      "y": 50,
      "z": 11,
      "name": "Wood_Hardwood_Stairs",
      "rotation": 9
    },
    {
      "x": 5,
      "y": 51,
      "z": 11,
      "name": "Wood_Hardwood_Planks"
    },
    {
      "x": 5,
      "y": 52,
      "z": 11,
      "name": "Wood_Hardwood_Planks"
    },
    {
      "x": 5,
      "y": 57,
      "z": 11,
      "name": "Wood_Hardwood_Planks"
    },
    {
      "x": 5,
      "y": 58,
      "z": 11,
      "name": "Wood_Hardwood_Planks"
    },
    {
      "x": 5,
      "y": 59,
      "z": 11,
      "name": "Rock_Chalk_Brick_Smooth"
    },
    {
      "x": 5,
      "y": 60,
      "z": 11,
      "name": "Rock_Chalk_Brick_Smooth"
    },
    {
      "x": 5,
      "y": 61,
      "z": 11,
      "name": "Rock_Chalk_Brick_Smooth"
    },
    {
      "x": 5,
      "y": 62,
      "z": 11,
      "name": "Rock_Chalk_Brick_Smooth"
    },
    {
      "x": 5,
      "y": 63,
      "z": 11,
      "name": "Rock_Chalk_Brick_Smooth"
    },
    {
      "x": 5,
      "y": 68,
      "z": 11,
      "name": "Soil_Clay_Purple"
    },
    {
      "x": 5,
      "y": 69,
      "z": 11,
      "name": "Soil_Clay_Purple"
    },
    {
      "x": 5,
      "y": 70,
      "z": 11,
      "name": "Soil_Clay_Purple"
    },
    {
      "x": 5,
      "y": 0,
      "z": 12,
      "name": "Soil_Grass"
    },
    {
      "x": 5,
      "y": 1,
      "z": 12,
      "name": "Plant_Leaves_Bottle",
      "support": 15
    },
    {
      "x": 5,
      "y": 2,
      "z": 12,
      "name": "Plant_Leaves_Bottle",
      "support": 15
    },
    {
      "x": 5,
      "y": 3,
      "z": 12,
      "name": "Plant_Leaves_Bottle",
      "support": 15
    },
    {
      "x": 5,
      "y": 4,
      "z": 12,
      "name": "Plant_Leaves_Bottle",
      "support": 15
    },
    {
      "x": 5,
      "y": 5,
      "z": 12,
      "name": "Plant_Leaves_Bottle",
      "support": 15
    },
    {
      "x": 5,
      "y": 6,
      "z": 12,
      "name": "Plant_Leaves_Bottle",
      "support": 15
    },
    {
      "x": 5,
      "y": 7,
      "z": 12,
      "name": "Plant_Leaves_Bottle",
      "support": 15
    },
    {
      "x": 5,
      "y": 8,
      "z": 12,
      "name": "Plant_Leaves_Bottle",
      "support": 15
    },
    {
      "x": 5,
      "y": 9,
      "z": 12,
      "name": "Plant_Leaves_Bottle",
      "support": 15
    },
    {
      "x": 5,
      "y": 10,
      "z": 12,
      "name": "Plant_Leaves_Bottle",
      "support": 15
    },
    {
      "x": 5,
      "y": 11,
      "z": 12,
      "name": "Plant_Leaves_Bottle",
      "support": 15
    },
    {
      "x": 5,
      "y": 12,
      "z": 12,
      "name": "Plant_Leaves_Bottle",
      "support": 15
    },
    {
      "x": 5,
      "y": 25,
      "z": 12,
      "name": "Plant_Leaves_Bottle",
      "support": 15
    },
    {
      "x": 5,
      "y": 26,
      "z": 12,
      "name": "Plant_Leaves_Bottle",
      "support": 15
    },
    {
      "x": 5,
      "y": 27,
      "z": 12,
      "name": "Plant_Leaves_Bottle",
      "support": 15
    },
    {
      "x": 5,
      "y": 51,
      "z": 12,
      "name": "Wood_Hardwood_Planks"
    },
    {
      "x": 5,
      "y": 52,
      "z": 12,
      "name": "Wood_Hardwood_Planks"
    },
    {
      "x": 5,
      "y": 53,
      "z": 12,
      "name": "Wood_Ash_Trunk",
      "support": 15,
      "rotation": 2
    },
    {
      "x": 5,
      "y": 54,
      "z": 12,
      "name": "Wood_Ash_Trunk",
      "support": 15,
      "rotation": 2
    },
    {
      "x": 5,
      "y": 55,
      "z": 12,
      "name": "Wood_Ash_Trunk",
      "support": 15,
      "rotation": 2
    },
    {
      "x": 5,
      "y": 56,
      "z": 12,
      "name": "Wood_Ash_Trunk",
      "support": 15,
      "rotation": 2
    },
    {
      "x": 5,
      "y": 57,
      "z": 12,
      "name": "Wood_Hardwood_Planks"
    },
    {
      "x": 5,
      "y": 58,
      "z": 12,
      "name": "Wood_Hardwood_Planks"
    },
    {
      "x": 5,
      "y": 60,
      "z": 12,
      "name": "Rock_Chalk_Brick_Smooth"
    },
    {
      "x": 5,
      "y": 61,
      "z": 12,
      "name": "Rock_Chalk_Brick_Smooth"
    },
    {
      "x": 5,
      "y": 62,
      "z": 12,
      "name": "Rock_Chalk_Brick_Smooth"
    },
    {
      "x": 5,
      "y": 63,
      "z": 12,
      "name": "Rock_Chalk_Brick_Smooth"
    },
    {
      "x": 5,
      "y": 69,
      "z": 12,
      "name": "Soil_Clay_Purple"
    },
    {
      "x": 5,
      "y": 70,
      "z": 12,
      "name": "Soil_Clay_Purple"
    },
    {
      "x": 5,
      "y": 71,
      "z": 12,
      "name": "Soil_Clay_Purple"
    },
    {
      "x": 5,
      "y": 0,
      "z": 13,
      "name": "Soil_Grass"
    },
    {
      "x": 5,
      "y": 1,
      "z": 13,
      "name": "Rock_Stone_Cobble"
    },
    {
      "x": 5,
      "y": 2,
      "z": 13,
      "name": "Rock_Stone_Cobble"
    },
    {
      "x": 5,
      "y": 3,
      "z": 13,
      "name": "Rock_Stone_Cobble"
    },
    {
      "x": 5,
      "y": 4,
      "z": 13,
      "name": "Rock_Stone_Cobble"
    },
    {
      "x": 5,
      "y": 5,
      "z": 13,
      "name": "Rock_Stone_Cobble"
    },
    {
      "x": 5,
      "y": 6,
      "z": 13,
      "name": "Rock_Stone_Cobble"
    },
    {
      "x": 5,
      "y": 7,
      "z": 13,
      "name": "Rock_Stone_Brick"
    },
    {
      "x": 5,
      "y": 8,
      "z": 13,
      "name": "Rock_Stone_Brick"
    },
    {
      "x": 5,
      "y": 9,
      "z": 13,
      "name": "Rock_Stone_Brick"
    },
    {
      "x": 5,
      "y": 10,
      "z": 13,
      "name": "Rock_Stone_Cobble"
    },
    {
      "x": 5,
      "y": 11,
      "z": 13,
      "name": "Rock_Stone_Cobble"
    },
    {
      "x": 5,
      "y": 12,
      "z": 13,
      "name": "Rock_Stone_Cobble"
    },
    {
      "x": 5,
      "y": 13,
      "z": 13,
      "name": "Rock_Stone_Cobble"
    },
    {
      "x": 5,
      "y": 14,
      "z": 13,
      "name": "Rock_Stone_Cobble"
    },
    {
      "x": 5,
      "y": 15,
      "z": 13,
      "name": "Rock_Stone_Cobble"
    },
    {
      "x": 5,
      "y": 16,
      "z": 13,
      "name": "Rock_Stone_Cobble"
    },
    {
      "x": 5,
      "y": 17,
      "z": 13,
      "name": "Rock_Stone_Cobble"
    },
    {
      "x": 5,
      "y": 18,
      "z": 13,
      "name": "Rock_Stone_Brick"
    },
    {
      "x": 5,
      "y": 19,
      "z": 13,
      "name": "Rock_Stone_Brick"
    },
    {
      "x": 5,
      "y": 20,
      "z": 13,
      "name": "Rock_Stone_Brick"
    },
    {
      "x": 5,
      "y": 21,
      "z": 13,
      "name": "Rock_Stone_Brick"
    },
    {
      "x": 5,
      "y": 22,
      "z": 13,
      "name": "Rock_Stone_Brick"
    },
    {
      "x": 5,
      "y": 23,
      "z": 13,
      "name": "Rock_Stone_Brick"
    },
    {
      "x": 5,
      "y": 24,
      "z": 13,
      "name": "Rock_Stone_Brick"
    },
    {
      "x": 5,
      "y": 25,
      "z": 13,
      "name": "Rock_Stone_Brick"
    },
    {
      "x": 5,
      "y": 26,
      "z": 13,
      "name": "Rock_Stone_Brick"
    },
    {
      "x": 5,
      "y": 27,
      "z": 13,
      "name": "Rock_Stone_Brick"
    },
    {
      "x": 5,
      "y": 28,
      "z": 13,
      "name": "Rock_Stone_Brick"
    },
    {
      "x": 5,
      "y": 29,
      "z": 13,
      "name": "Rock_Stone_Brick"
    },
    {
      "x": 5,
      "y": 30,
      "z": 13,
      "name": "Plant_Leaves_Bottle",
      "support": 15
    },
    {
      "x": 5,
      "y": 49,
      "z": 13,
      "name": "Wood_Hardwood_Stairs",
      "rotation": 9
    },
    {
      "x": 5,
      "y": 50,
      "z": 13,
      "name": "Wood_Hardwood_Stairs",
      "rotation": 1
    },
    {
      "x": 5,
      "y": 51,
      "z": 13,
      "name": "Wood_Hardwood_Planks_Half",
      "rotation": 8
    },
    {
      "x": 5,
      "y": 52,
      "z": 13,
      "name": "Wood_Hardwood_Planks"
    },
    {
      "x": 5,
      "y": 53,
      "z": 13,
      "name": "Wood_Hardwood_Stairs",
      "rotation": 2
    },
    {
      "x": 5,
      "y": 55,
      "z": 13,
      "name": "Wood_Hardwood_Stairs",
      "rotation": 8
    },
    {
      "x": 5,
      "y": 56,
      "z": 13,
      "name": "Wood_Hardwood_Stairs"
    },
    {
      "x": 5,
      "y": 57,
      "z": 13,
      "name": "Wood_Hardwood_Planks"
    },
    {
      "x": 5,
      "y": 60,
      "z": 13,
      "name": "Rock_Stone_Brick"
    },
    {
      "x": 5,
      "y": 62,
      "z": 13,
      "name": "Wood_Hardwood_Stairs",
      "rotation": 1
    },
    {
      "x": 5,
      "y": 70,
      "z": 13,
      "name": "Soil_Clay_Purple"
    },
    {
      "x": 5,
      "y": 71,
      "z": 13,
      "name": "Soil_Clay_Purple"
    },
    {
      "x": 5,
      "y": 72,
      "z": 13,
      "name": "Cloth_Block_Wool_Purple"
    },
    {
      "x": 5,
      "y": 0,
      "z": 14,
      "name": "Soil_Grass"
    },
    {
      "x": 5,
      "y": 1,
      "z": 14,
      "name": "Rock_Stone_Cobble"
    },
    {
      "x": 5,
      "y": 2,
      "z": 14,
      "name": "Rock_Stone_Cobble"
    },
    {
      "x": 5,
      "y": 3,
      "z": 14,
      "name": "Rock_Stone_Cobble"
    },
    {
      "x": 5,
      "y": 4,
      "z": 14,
      "name": "Rock_Stone_Cobble"
    },
    {
      "x": 5,
      "y": 5,
      "z": 14,
      "name": "Rock_Stone_Cobble"
    },
    {
      "x": 5,
      "y": 6,
      "z": 14,
      "name": "Rock_Stone_Cobble"
    },
    {
      "x": 5,
      "y": 7,
      "z": 14,
      "name": "Rock_Stone_Cobble"
    },
    {
      "x": 5,
      "y": 8,
      "z": 14,
      "name": "Rock_Stone_Cobble"
    },
    {
      "x": 5,
      "y": 9,
      "z": 14,
      "name": "Rock_Stone_Cobble"
    },
    {
      "x": 5,
      "y": 10,
      "z": 14,
      "name": "Rock_Stone_Cobble"
    },
    {
      "x": 5,
      "y": 11,
      "z": 14,
      "name": "Rock_Stone_Brick"
    },
    {
      "x": 5,
      "y": 12,
      "z": 14,
      "name": "Rock_Stone_Brick"
    },
    {
      "x": 5,
      "y": 13,
      "z": 14,
      "name": "Rock_Stone_Brick"
    },
    {
      "x": 5,
      "y": 14,
      "z": 14,
      "name": "Rock_Stone_Brick"
    },
    {
      "x": 5,
      "y": 15,
      "z": 14,
      "name": "Rock_Stone_Brick"
    },
    {
      "x": 5,
      "y": 16,
      "z": 14,
      "name": "Rock_Stone_Brick"
    },
    {
      "x": 5,
      "y": 17,
      "z": 14,
      "name": "Rock_Stone_Brick"
    },
    {
      "x": 5,
      "y": 18,
      "z": 14,
      "name": "Rock_Stone_Brick"
    },
    {
      "x": 5,
      "y": 19,
      "z": 14,
      "name": "Rock_Stone_Brick"
    },
    {
      "x": 5,
      "y": 20,
      "z": 14,
      "name": "Rock_Stone_Brick"
    },
    {
      "x": 5,
      "y": 21,
      "z": 14,
      "name": "Rock_Stone_Brick"
    },
    {
      "x": 5,
      "y": 22,
      "z": 14,
      "name": "Rock_Stone_Brick"
    },
    {
      "x": 5,
      "y": 23,
      "z": 14,
      "name": "Rock_Stone_Brick"
    },
    {
      "x": 5,
      "y": 24,
      "z": 14,
      "name": "Rock_Stone_Brick"
    },
    {
      "x": 5,
      "y": 25,
      "z": 14,
      "name": "Rock_Stone_Brick"
    },
    {
      "x": 5,
      "y": 26,
      "z": 14,
      "name": "Rock_Stone_Brick"
    },
    {
      "x": 5,
      "y": 27,
      "z": 14,
      "name": "Rock_Stone_Brick"
    },
    {
      "x": 5,
      "y": 28,
      "z": 14,
      "name": "Rock_Stone_Brick"
    },
    {
      "x": 5,
      "y": 29,
      "z": 14,
      "name": "Rock_Stone_Brick"
    },
    {
      "x": 5,
      "y": 30,
      "z": 14,
      "name": "Plant_Leaves_Bottle",
      "support": 15
    },
    {
      "x": 5,
      "y": 51,
      "z": 14,
      "name": "Wood_Hardwood_Planks_Half",
      "rotation": 8
    },
    {
      "x": 5,
      "y": 52,
      "z": 14,
      "name": "Wood_Hardwood_Planks"
    },
    {
      "x": 5,
      "y": 53,
      "z": 14,
      "name": "Wood_Hardwood_Stairs",
      "rotation": 10
    },
    {
      "x": 5,
      "y": 54,
      "z": 14,
      "name": "Wood_Hardwood_Stairs",
      "rotation": 2
    },
    {
      "x": 5,
      "y": 55,
      "z": 14,
      "name": "Wood_Hardwood_Stairs"
    },
    {
      "x": 5,
      "y": 57,
      "z": 14,
      "name": "Wood_Hardwood_Planks"
    },
    {
      "x": 5,
      "y": 60,
      "z": 14,
      "name": "Wood_Hardwood_Planks"
    },
    {
      "x": 5,
      "y": 61,
      "z": 14,
      "name": "Wood_Hardwood_Planks"
    },
    {
      "x": 5,
      "y": 62,
      "z": 14,
      "name": "Wood_Hardwood_Planks"
    },
    {
      "x": 5,
      "y": 71,
      "z": 14,
      "name": "Soil_Clay_Purple"
    },
    {
      "x": 5,
      "y": 72,
      "z": 14,
      "name": "Cloth_Block_Wool_Purple"
    },
    {
      "x": 5,
      "y": 73,
      "z": 14,
      "name": "Cloth_Block_Wool_Purple"
    },
    {
      "x": 5,
      "y": 0,
      "z": 15,
      "name": "Soil_Grass"
    },
    {
      "x": 5,
      "y": 1,
      "z": 15,
      "name": "Rock_Stone_Cobble"
    },
    {
      "x": 5,
      "y": 2,
      "z": 15,
      "name": "Rock_Stone_Cobble"
    },
    {
      "x": 5,
      "y": 3,
      "z": 15,
      "name": "Rock_Stone_Cobble"
    },
    {
      "x": 5,
      "y": 4,
      "z": 15,
      "name": "Rock_Stone_Cobble"
    },
    {
      "x": 5,
      "y": 5,
      "z": 15,
      "name": "Rock_Stone_Brick"
    },
    {
      "x": 5,
      "y": 6,
      "z": 15,
      "name": "Rock_Stone_Brick"
    },
    {
      "x": 5,
      "y": 7,
      "z": 15,
      "name": "Rock_Stone_Brick"
    },
    {
      "x": 5,
      "y": 8,
      "z": 15,
      "name": "Rock_Stone_Brick"
    },
    {
      "x": 5,
      "y": 9,
      "z": 15,
      "name": "Rock_Stone_Brick"
    },
    {
      "x": 5,
      "y": 10,
      "z": 15,
      "name": "Rock_Stone_Brick"
    },
    {
      "x": 5,
      "y": 11,
      "z": 15,
      "name": "Rock_Stone_Brick"
    },
    {
      "x": 5,
      "y": 12,
      "z": 15,
      "name": "Rock_Stone_Brick"
    },
    {
      "x": 5,
      "y": 13,
      "z": 15,
      "name": "Rock_Stone_Brick"
    },
    {
      "x": 5,
      "y": 14,
      "z": 15,
      "name": "Rock_Stone_Brick"
    },
    {
      "x": 5,
      "y": 15,
      "z": 15,
      "name": "Rock_Stone_Brick"
    },
    {
      "x": 5,
      "y": 16,
      "z": 15,
      "name": "Rock_Stone_Brick"
    },
    {
      "x": 5,
      "y": 17,
      "z": 15,
      "name": "Rock_Stone_Brick"
    },
    {
      "x": 5,
      "y": 18,
      "z": 15,
      "name": "Rock_Stone_Brick"
    },
    {
      "x": 5,
      "y": 19,
      "z": 15,
      "name": "Rock_Stone_Brick"
    },
    {
      "x": 5,
      "y": 20,
      "z": 15,
      "name": "Rock_Stone_Brick"
    },
    {
      "x": 5,
      "y": 21,
      "z": 15,
      "name": "Rock_Stone_Brick"
    },
    {
      "x": 5,
      "y": 22,
      "z": 15,
      "name": "Rock_Stone_Brick"
    },
    {
      "x": 5,
      "y": 23,
      "z": 15,
      "name": "Rock_Stone_Brick"
    },
    {
      "x": 5,
      "y": 24,
      "z": 15,
      "name": "Rock_Stone_Cobble"
    },
    {
      "x": 5,
      "y": 25,
      "z": 15,
      "name": "Rock_Stone_Cobble"
    },
    {
      "x": 5,
      "y": 26,
      "z": 15,
      "name": "Rock_Stone_Cobble"
    },
    {
      "x": 5,
      "y": 27,
      "z": 15,
      "name": "Rock_Stone_Cobble"
    },
    {
      "x": 5,
      "y": 28,
      "z": 15,
      "name": "Rock_Stone_Cobble"
    },
    {
      "x": 5,
      "y": 29,
      "z": 15,
      "name": "Rock_Stone_Cobble"
    },
    {
      "x": 5,
      "y": 31,
      "z": 15,
      "name": "Plant_Leaves_Bottle",
      "support": 15
    },
    {
      "x": 5,
      "y": 49,
      "z": 15,
      "name": "Wood_Hardwood_Stairs",
      "rotation": 9
    },
    {
      "x": 5,
      "y": 50,
      "z": 15,
      "name": "Wood_Hardwood_Stairs",
      "rotation": 1
    },
    {
      "x": 5,
      "y": 51,
      "z": 15,
      "name": "Wood_Hardwood_Planks_Half",
      "rotation": 8
    },
    {
      "x": 5,
      "y": 52,
      "z": 15,
      "name": "Wood_Hardwood_Planks"
    },
    {
      "x": 5,
      "y": 54,
      "z": 15,
      "name": "Wood_Hardwood_Planks_Half"
    },
    {
      "x": 5,
      "y": 55,
      "z": 15,
      "name": "Wood_Hardwood_Planks_Half"
    },
    {
      "x": 5,
      "y": 57,
      "z": 15,
      "name": "Wood_Hardwood_Planks"
    },
    {
      "x": 5,
      "y": 59,
      "z": 15,
      "name": "Wood_Hardwood_Planks"
    },
    {
      "x": 5,
      "y": 60,
      "z": 15,
      "name": "*Furniture_Village_Door_State_Definitions_CloseDoorOut",
      "rotation": 3
    },
    {
      "x": 5,
      "y": 61,
      "z": 15,
      "name": "*Furniture_Village_Door_State_Definitions_CloseDoorOut",
      "filler": 1024,
      "rotation": 3
    },
    {
      "x": 5,
      "y": 62,
      "z": 15,
      "name": "Wood_Hardwood_Planks"
    },
    {
      "x": 5,
      "y": 64,
      "z": 15,
      "name": "Rock_Stone_Brick"
    },
    {
      "x": 5,
      "y": 71,
      "z": 15,
      "name": "Soil_Clay_Purple"
    },
    {
      "x": 5,
      "y": 72,
      "z": 15,
      "name": "Cloth_Block_Wool_Purple"
    },
    {
      "x": 5,
      "y": 73,
      "z": 15,
      "name": "Cloth_Block_Wool_Purple"
    },
    {
      "x": 5,
      "y": 0,
      "z": 16,
      "name": "Soil_Grass"
    },
    {
      "x": 5,
      "y": 1,
      "z": 16,
      "name": "Rock_Stone_Cobble"
    },
    {
      "x": 5,
      "y": 2,
      "z": 16,
      "name": "Rock_Stone_Cobble"
    },
    {
      "x": 5,
      "y": 3,
      "z": 16,
      "name": "Rock_Stone_Cobble"
    },
    {
      "x": 5,
      "y": 4,
      "z": 16,
      "name": "Rock_Stone_Cobble"
    },
    {
      "x": 5,
      "y": 5,
      "z": 16,
      "name": "Rock_Stone_Brick"
    },
    {
      "x": 5,
      "y": 6,
      "z": 16,
      "name": "Rock_Stone_Brick"
    },
    {
      "x": 5,
      "y": 7,
      "z": 16,
      "name": "Rock_Stone_Brick"
    },
    {
      "x": 5,
      "y": 8,
      "z": 16,
      "name": "Rock_Stone_Brick"
    },
    {
      "x": 5,
      "y": 9,
      "z": 16,
      "name": "Rock_Stone_Brick"
    },
    {
      "x": 5,
      "y": 10,
      "z": 16,
      "name": "Rock_Stone_Brick"
    },
    {
      "x": 5,
      "y": 11,
      "z": 16,
      "name": "Rock_Stone_Brick"
    },
    {
      "x": 5,
      "y": 12,
      "z": 16,
      "name": "Rock_Stone_Brick"
    },
    {
      "x": 5,
      "y": 13,
      "z": 16,
      "name": "Rock_Stone_Brick"
    },
    {
      "x": 5,
      "y": 14,
      "z": 16,
      "name": "Rock_Stone_Brick"
    },
    {
      "x": 5,
      "y": 15,
      "z": 16,
      "name": "Rock_Stone_Brick"
    },
    {
      "x": 5,
      "y": 16,
      "z": 16,
      "name": "Rock_Stone_Brick"
    },
    {
      "x": 5,
      "y": 17,
      "z": 16,
      "name": "Rock_Stone_Brick"
    },
    {
      "x": 5,
      "y": 18,
      "z": 16,
      "name": "Rock_Stone_Brick"
    },
    {
      "x": 5,
      "y": 19,
      "z": 16,
      "name": "Rock_Stone_Cobble"
    },
    {
      "x": 5,
      "y": 20,
      "z": 16,
      "name": "Rock_Stone_Cobble"
    },
    {
      "x": 5,
      "y": 21,
      "z": 16,
      "name": "Rock_Stone_Brick"
    },
    {
      "x": 5,
      "y": 22,
      "z": 16,
      "name": "Rock_Stone_Brick"
    },
    {
      "x": 5,
      "y": 23,
      "z": 16,
      "name": "Rock_Stone_Brick"
    },
    {
      "x": 5,
      "y": 24,
      "z": 16,
      "name": "Rock_Stone_Brick"
    },
    {
      "x": 5,
      "y": 25,
      "z": 16,
      "name": "Rock_Stone_Brick"
    },
    {
      "x": 5,
      "y": 26,
      "z": 16,
      "name": "Rock_Stone_Brick"
    },
    {
      "x": 5,
      "y": 27,
      "z": 16,
      "name": "Rock_Stone_Brick"
    },
    {
      "x": 5,
      "y": 28,
      "z": 16,
      "name": "Rock_Stone_Cobble"
    },
    {
      "x": 5,
      "y": 29,
      "z": 16,
      "name": "Rock_Stone_Cobble"
    },
    {
      "x": 5,
      "y": 51,
      "z": 16,
      "name": "Wood_Hardwood_Planks_Half",
      "rotation": 8
    },
    {
      "x": 5,
      "y": 52,
      "z": 16,
      "name": "Wood_Hardwood_Planks"
    },
    {
      "x": 5,
      "y": 53,
      "z": 16,
      "name": "Wood_Hardwood_Stairs",
      "rotation": 8
    },
    {
      "x": 5,
      "y": 54,
      "z": 16,
      "name": "Wood_Hardwood_Stairs"
    },
    {
      "x": 5,
      "y": 55,
      "z": 16,
      "name": "Wood_Hardwood_Stairs",
      "rotation": 2
    },
    {
      "x": 5,
      "y": 57,
      "z": 16,
      "name": "Wood_Hardwood_Planks"
    },
    {
      "x": 5,
      "y": 60,
      "z": 16,
      "name": "Wood_Hardwood_Planks"
    },
    {
      "x": 5,
      "y": 61,
      "z": 16,
      "name": "Wood_Hardwood_Planks"
    },
    {
      "x": 5,
      "y": 62,
      "z": 16,
      "name": "Wood_Hardwood_Planks"
    },
    {
      "x": 5,
      "y": 63,
      "z": 16,
      "name": "Rock_Stone_Brick"
    },
    {
      "x": 5,
      "y": 71,
      "z": 16,
      "name": "Soil_Clay_Purple"
    },
    {
      "x": 5,
      "y": 72,
      "z": 16,
      "name": "Soil_Clay_Purple"
    },
    {
      "x": 5,
      "y": 73,
      "z": 16,
      "name": "Cloth_Block_Wool_Purple"
    },
    {
      "x": 5,
      "y": 0,
      "z": 17,
      "name": "Soil_Grass"
    },
    {
      "x": 5,
      "y": 1,
      "z": 17,
      "name": "Rock_Stone_Cobble"
    },
    {
      "x": 5,
      "y": 2,
      "z": 17,
      "name": "Rock_Stone_Cobble"
    },
    {
      "x": 5,
      "y": 3,
      "z": 17,
      "name": "Rock_Stone_Cobble"
    },
    {
      "x": 5,
      "y": 4,
      "z": 17,
      "name": "Rock_Stone_Cobble"
    },
    {
      "x": 5,
      "y": 5,
      "z": 17,
      "name": "Rock_Stone_Brick"
    },
    {
      "x": 5,
      "y": 6,
      "z": 17,
      "name": "Rock_Stone_Brick"
    },
    {
      "x": 5,
      "y": 7,
      "z": 17,
      "name": "Rock_Stone_Brick"
    },
    {
      "x": 5,
      "y": 8,
      "z": 17,
      "name": "Rock_Stone_Brick"
    },
    {
      "x": 5,
      "y": 9,
      "z": 17,
      "name": "Rock_Stone_Brick"
    },
    {
      "x": 5,
      "y": 10,
      "z": 17,
      "name": "Rock_Stone_Brick"
    },
    {
      "x": 5,
      "y": 11,
      "z": 17,
      "name": "Rock_Stone_Brick"
    },
    {
      "x": 5,
      "y": 12,
      "z": 17,
      "name": "Rock_Stone_Cobble"
    },
    {
      "x": 5,
      "y": 13,
      "z": 17,
      "name": "Rock_Stone_Cobble"
    },
    {
      "x": 5,
      "y": 14,
      "z": 17,
      "name": "Rock_Stone_Cobble"
    },
    {
      "x": 5,
      "y": 15,
      "z": 17,
      "name": "Rock_Stone_Cobble"
    },
    {
      "x": 5,
      "y": 16,
      "z": 17,
      "name": "Rock_Stone_Cobble"
    },
    {
      "x": 5,
      "y": 17,
      "z": 17,
      "name": "Rock_Stone_Cobble"
    },
    {
      "x": 5,
      "y": 18,
      "z": 17,
      "name": "Rock_Stone_Cobble"
    },
    {
      "x": 5,
      "y": 19,
      "z": 17,
      "name": "Rock_Stone_Cobble"
    },
    {
      "x": 5,
      "y": 20,
      "z": 17,
      "name": "Rock_Stone_Cobble"
    },
    {
      "x": 5,
      "y": 21,
      "z": 17,
      "name": "Rock_Stone_Cobble"
    },
    {
      "x": 5,
      "y": 22,
      "z": 17,
      "name": "Rock_Stone_Brick"
    },
    {
      "x": 5,
      "y": 23,
      "z": 17,
      "name": "Rock_Stone_Brick"
    },
    {
      "x": 5,
      "y": 24,
      "z": 17,
      "name": "Rock_Stone_Brick"
    },
    {
      "x": 5,
      "y": 25,
      "z": 17,
      "name": "Rock_Stone_Brick"
    },
    {
      "x": 5,
      "y": 26,
      "z": 17,
      "name": "Rock_Stone_Brick"
    },
    {
      "x": 5,
      "y": 27,
      "z": 17,
      "name": "Rock_Stone_Brick"
    },
    {
      "x": 5,
      "y": 28,
      "z": 17,
      "name": "Rock_Stone_Brick"
    },
    {
      "x": 5,
      "y": 29,
      "z": 17,
      "name": "Rock_Stone_Cobble"
    },
    {
      "x": 5,
      "y": 49,
      "z": 17,
      "name": "Wood_Hardwood_Stairs",
      "rotation": 9
    },
    {
      "x": 5,
      "y": 50,
      "z": 17,
      "name": "Wood_Hardwood_Stairs",
      "rotation": 1
    },
    {
      "x": 5,
      "y": 51,
      "z": 17,
      "name": "Wood_Hardwood_Planks_Half",
      "rotation": 8
    },
    {
      "x": 5,
      "y": 52,
      "z": 17,
      "name": "Wood_Hardwood_Planks"
    },
    {
      "x": 5,
      "y": 53,
      "z": 17,
      "name": "Wood_Hardwood_Stairs"
    },
    {
      "x": 5,
      "y": 55,
      "z": 17,
      "name": "Wood_Hardwood_Stairs",
      "rotation": 10
    },
    {
      "x": 5,
      "y": 56,
      "z": 17,
      "name": "Wood_Hardwood_Stairs",
      "rotation": 2
    },
    {
      "x": 5,
      "y": 57,
      "z": 17,
      "name": "Wood_Hardwood_Planks"
    },
    {
      "x": 5,
      "y": 61,
      "z": 17,
      "name": "Rock_Stone_Brick"
    },
    {
      "x": 5,
      "y": 62,
      "z": 17,
      "name": "Rock_Stone_Brick"
    },
    {
      "x": 5,
      "y": 70,
      "z": 17,
      "name": "Soil_Clay_Purple"
    },
    {
      "x": 5,
      "y": 71,
      "z": 17,
      "name": "Soil_Clay_Purple"
    },
    {
      "x": 5,
      "y": 72,
      "z": 17,
      "name": "Cloth_Block_Wool_Purple"
    },
    {
      "x": 5,
      "y": 0,
      "z": 18,
      "name": "Soil_Grass"
    },
    {
      "x": 5,
      "y": 2,
      "z": 18,
      "name": "Plant_Leaves_Bottle",
      "support": 15
    },
    {
      "x": 5,
      "y": 3,
      "z": 18,
      "name": "Plant_Leaves_Bottle",
      "support": 15
    },
    {
      "x": 5,
      "y": 4,
      "z": 18,
      "name": "Plant_Leaves_Bottle",
      "support": 15
    },
    {
      "x": 5,
      "y": 5,
      "z": 18,
      "name": "Plant_Leaves_Bottle",
      "support": 15
    },
    {
      "x": 5,
      "y": 6,
      "z": 18,
      "name": "Plant_Leaves_Bottle",
      "support": 15
    },
    {
      "x": 5,
      "y": 11,
      "z": 18,
      "name": "Rock_Stone_Brick_Smooth"
    },
    {
      "x": 5,
      "y": 12,
      "z": 18,
      "name": "Rock_Stone_Brick_Smooth"
    },
    {
      "x": 5,
      "y": 13,
      "z": 18,
      "name": "Rock_Stone_Brick_Smooth"
    },
    {
      "x": 5,
      "y": 14,
      "z": 18,
      "name": "Rock_Stone_Brick_Smooth"
    },
    {
      "x": 5,
      "y": 15,
      "z": 18,
      "name": "Rock_Stone_Brick_Smooth"
    },
    {
      "x": 5,
      "y": 16,
      "z": 18,
      "name": "Rock_Stone_Brick_Smooth"
    },
    {
      "x": 5,
      "y": 17,
      "z": 18,
      "name": "Rock_Stone_Brick_Smooth"
    },
    {
      "x": 5,
      "y": 51,
      "z": 18,
      "name": "Wood_Hardwood_Planks"
    },
    {
      "x": 5,
      "y": 52,
      "z": 18,
      "name": "Wood_Hardwood_Planks"
    },
    {
      "x": 5,
      "y": 53,
      "z": 18,
      "name": "Wood_Ash_Trunk",
      "support": 15,
      "rotation": 2
    },
    {
      "x": 5,
      "y": 54,
      "z": 18,
      "name": "Wood_Ash_Trunk",
      "support": 15,
      "rotation": 2
    },
    {
      "x": 5,
      "y": 55,
      "z": 18,
      "name": "Wood_Ash_Trunk",
      "support": 15,
      "rotation": 2
    },
    {
      "x": 5,
      "y": 56,
      "z": 18,
      "name": "Wood_Ash_Trunk",
      "support": 15,
      "rotation": 2
    },
    {
      "x": 5,
      "y": 57,
      "z": 18,
      "name": "Wood_Hardwood_Planks"
    },
    {
      "x": 5,
      "y": 58,
      "z": 18,
      "name": "Wood_Hardwood_Planks"
    },
    {
      "x": 5,
      "y": 60,
      "z": 18,
      "name": "Rock_Chalk_Brick_Smooth"
    },
    {
      "x": 5,
      "y": 61,
      "z": 18,
      "name": "Rock_Chalk_Brick_Smooth"
    },
    {
      "x": 5,
      "y": 62,
      "z": 18,
      "name": "Rock_Chalk_Brick_Smooth"
    },
    {
      "x": 5,
      "y": 63,
      "z": 18,
      "name": "Rock_Chalk_Brick_Smooth"
    },
    {
      "x": 5,
      "y": 69,
      "z": 18,
      "name": "Soil_Clay_Purple"
    },
    {
      "x": 5,
      "y": 70,
      "z": 18,
      "name": "Soil_Clay_Purple"
    },
    {
      "x": 5,
      "y": 71,
      "z": 18,
      "name": "Soil_Clay_Purple"
    },
    {
      "x": 5,
      "y": 0,
      "z": 19,
      "name": "Soil_Grass"
    },
    {
      "x": 5,
      "y": 4,
      "z": 19,
      "name": "Plant_Leaves_Bottle",
      "support": 15
    },
    {
      "x": 5,
      "y": 5,
      "z": 19,
      "name": "Plant_Leaves_Bottle",
      "support": 15
    },
    {
      "x": 5,
      "y": 6,
      "z": 19,
      "name": "Plant_Leaves_Bottle",
      "support": 15
    },
    {
      "x": 5,
      "y": 7,
      "z": 19,
      "name": "Plant_Leaves_Bottle",
      "support": 15
    },
    {
      "x": 5,
      "y": 9,
      "z": 19,
      "name": "Plant_Leaves_Bottle",
      "support": 15
    },
    {
      "x": 5,
      "y": 13,
      "z": 19,
      "name": "Rock_Stone_Brick_Smooth"
    },
    {
      "x": 5,
      "y": 14,
      "z": 19,
      "name": "Rock_Stone_Brick_Smooth"
    },
    {
      "x": 5,
      "y": 15,
      "z": 19,
      "name": "Rock_Stone_Brick_Smooth"
    },
    {
      "x": 5,
      "y": 50,
      "z": 19,
      "name": "Wood_Hardwood_Stairs",
      "rotation": 9
    },
    {
      "x": 5,
      "y": 51,
      "z": 19,
      "name": "Wood_Hardwood_Planks"
    },
    {
      "x": 5,
      "y": 52,
      "z": 19,
      "name": "Wood_Hardwood_Planks"
    },
    {
      "x": 5,
      "y": 57,
      "z": 19,
      "name": "Wood_Hardwood_Planks"
    },
    {
      "x": 5,
      "y": 58,
      "z": 19,
      "name": "Wood_Hardwood_Planks"
    },
    {
      "x": 5,
      "y": 59,
      "z": 19,
      "name": "Rock_Chalk_Brick_Smooth"
    },
    {
      "x": 5,
      "y": 60,
      "z": 19,
      "name": "Rock_Chalk_Brick_Smooth"
    },
    {
      "x": 5,
      "y": 61,
      "z": 19,
      "name": "Rock_Chalk_Brick_Smooth"
    },
    {
      "x": 5,
      "y": 62,
      "z": 19,
      "name": "Rock_Chalk_Brick_Smooth"
    },
    {
      "x": 5,
      "y": 63,
      "z": 19,
      "name": "Rock_Chalk_Brick_Smooth"
    },
    {
      "x": 5,
      "y": 68,
      "z": 19,
      "name": "Soil_Clay_Purple"
    },
    {
      "x": 5,
      "y": 69,
      "z": 19,
      "name": "Soil_Clay_Purple"
    },
    {
      "x": 5,
      "y": 70,
      "z": 19,
      "name": "Cloth_Block_Wool_Purple"
    },
    {
      "x": 5,
      "y": 0,
      "z": 20,
      "name": "Soil_Grass"
    },
    {
      "x": 5,
      "y": 18,
      "z": 20,
      "name": "Plant_Leaves_Bottle",
      "support": 15
    },
    {
      "x": 5,
      "y": 51,
      "z": 20,
      "name": "Wood_Hardwood_Planks"
    },
    {
      "x": 5,
      "y": 52,
      "z": 20,
      "name": "Wood_Hardwood_Planks_Half"
    },
    {
      "x": 5,
      "y": 57,
      "z": 20,
      "name": "Wood_Hardwood_Planks"
    },
    {
      "x": 5,
      "y": 58,
      "z": 20,
      "name": "Wood_Hardwood_Planks"
    },
    {
      "x": 5,
      "y": 59,
      "z": 20,
      "name": "Rock_Chalk_Brick_Smooth"
    },
    {
      "x": 5,
      "y": 60,
      "z": 20,
      "name": "Rock_Chalk_Brick_Smooth"
    },
    {
      "x": 5,
      "y": 61,
      "z": 20,
      "name": "Rock_Chalk_Brick_Smooth"
    },
    {
      "x": 5,
      "y": 62,
      "z": 20,
      "name": "Rock_Chalk_Brick_Smooth"
    },
    {
      "x": 5,
      "y": 63,
      "z": 20,
      "name": "Rock_Chalk_Brick_Smooth"
    },
    {
      "x": 5,
      "y": 66,
      "z": 20,
      "name": "Soil_Clay_Purple"
    },
    {
      "x": 5,
      "y": 67,
      "z": 20,
      "name": "Soil_Clay_Purple"
    },
    {
      "x": 5,
      "y": 68,
      "z": 20,
      "name": "Soil_Clay_Purple"
    },
    {
      "x": 5,
      "y": 0,
      "z": 21,
      "name": "Soil_Grass"
    },
    {
      "x": 5,
      "y": 59,
      "z": 21,
      "name": "Wood_Hardwood_Planks_Half"
    },
    {
      "x": 5,
      "y": 60,
      "z": 21,
      "name": "Wood_Hardwood_Planks_Half"
    },
    {
      "x": 5,
      "y": 63,
      "z": 21,
      "name": "Wood_Hardwood_Planks_Half",
      "rotation": 8
    },
    {
      "x": 5,
      "y": 64,
      "z": 21,
      "name": "Wood_Hardwood_Planks"
    },
    {
      "x": 5,
      "y": 66,
      "z": 21,
      "name": "Soil_Clay_Purple"
    },
    {
      "x": 5,
      "y": 0,
      "z": 22,
      "name": "Soil_Grass"
    },
    {
      "x": 5,
      "y": 64,
      "z": 22,
      "name": "Wood_Hardwood_Planks_Half",
      "rotation": 8
    },
    {
      "x": 5,
      "y": 65,
      "z": 22,
      "name": "Soil_Clay_Purple"
    },
    {
      "x": 5,
      "y": 0,
      "z": 23,
      "name": "Soil_Grass"
    },
    {
      "x": 5,
      "y": 0,
      "z": 24,
      "name": "Soil_Grass"
    },
    {
      "x": 5,
      "y": 0,
      "z": 25,
      "name": "Soil_Grass"
    },
    {
      "x": 5,
      "y": 0,
      "z": 26,
      "name": "Soil_Grass"
    },
    {
      "x": 5,
      "y": 0,
      "z": 27,
      "name": "Soil_Grass"
    },
    {
      "x": 5,
      "y": 0,
      "z": 28,
      "name": "Soil_Grass"
    },
    {
      "x": 5,
      "y": 0,
      "z": 29,
      "name": "Soil_Grass"
    },
    {
      "x": 5,
      "y": 0,
      "z": 30,
      "name": "Soil_Grass"
    },
    {
      "x": 6,
      "y": 0,
      "z": 1,
      "name": "Soil_Grass"
    },
    {
      "x": 6,
      "y": 0,
      "z": 2,
      "name": "Soil_Grass"
    },
    {
      "x": 6,
      "y": 0,
      "z": 3,
      "name": "Soil_Grass"
    },
    {
      "x": 6,
      "y": 0,
      "z": 4,
      "name": "Soil_Grass"
    },
    {
      "x": 6,
      "y": 0,
      "z": 5,
      "name": "Soil_Grass"
    },
    {
      "x": 6,
      "y": 0,
      "z": 6,
      "name": "Soil_Grass"
    },
    {
      "x": 6,
      "y": 0,
      "z": 7,
      "name": "Soil_Grass"
    },
    {
      "x": 6,
      "y": 64,
      "z": 7,
      "name": "Wood_Hardwood_Planks_Half",
      "rotation": 8
    },
    {
      "x": 6,
      "y": 65,
      "z": 7,
      "name": "Soil_Clay_Purple"
    },
    {
      "x": 6,
      "y": 0,
      "z": 8,
      "name": "Soil_Grass"
    },
    {
      "x": 6,
      "y": 19,
      "z": 8,
      "name": "Plant_Leaves_Bottle",
      "support": 15
    },
    {
      "x": 6,
      "y": 20,
      "z": 8,
      "name": "Plant_Leaves_Bottle",
      "support": 15
    },
    {
      "x": 6,
      "y": 59,
      "z": 8,
      "name": "Wood_Hardwood_Planks_Half"
    },
    {
      "x": 6,
      "y": 60,
      "z": 8,
      "name": "Wood_Hardwood_Planks_Half"
    },
    {
      "x": 6,
      "y": 63,
      "z": 8,
      "name": "Wood_Hardwood_Planks_Half",
      "rotation": 8
    },
    {
      "x": 6,
      "y": 64,
      "z": 8,
      "name": "Wood_Hardwood_Planks"
    },
    {
      "x": 6,
      "y": 65,
      "z": 8,
      "name": "Wood_Hardwood_Planks"
    },
    {
      "x": 6,
      "y": 66,
      "z": 8,
      "name": "Cloth_Block_Wool_Purple"
    },
    {
      "x": 6,
      "y": 67,
      "z": 8,
      "name": "Cloth_Block_Wool_Purple"
    },
    {
      "x": 6,
      "y": 0,
      "z": 9,
      "name": "Soil_Grass"
    },
    {
      "x": 6,
      "y": 20,
      "z": 9,
      "name": "Plant_Leaves_Bottle",
      "support": 15
    },
    {
      "x": 6,
      "y": 21,
      "z": 9,
      "name": "Plant_Leaves_Bottle",
      "support": 15
    },
    {
      "x": 6,
      "y": 51,
      "z": 9,
      "name": "Wood_Hardwood_Planks"
    },
    {
      "x": 6,
      "y": 52,
      "z": 9,
      "name": "Wood_Hardwood_Planks_Half"
    },
    {
      "x": 6,
      "y": 57,
      "z": 9,
      "name": "Wood_Hardwood_Planks"
    },
    {
      "x": 6,
      "y": 58,
      "z": 9,
      "name": "Wood_Hardwood_Planks"
    },
    {
      "x": 6,
      "y": 59,
      "z": 9,
      "name": "Rock_Chalk_Brick_Smooth"
    },
    {
      "x": 6,
      "y": 60,
      "z": 9,
      "name": "Rock_Chalk_Brick_Smooth"
    },
    {
      "x": 6,
      "y": 61,
      "z": 9,
      "name": "Rock_Chalk_Brick_Smooth"
    },
    {
      "x": 6,
      "y": 62,
      "z": 9,
      "name": "Rock_Chalk_Brick_Smooth"
    },
    {
      "x": 6,
      "y": 63,
      "z": 9,
      "name": "Rock_Chalk_Brick_Smooth"
    },
    {
      "x": 6,
      "y": 67,
      "z": 9,
      "name": "Cloth_Block_Wool_Purple"
    },
    {
      "x": 6,
      "y": 68,
      "z": 9,
      "name": "Cloth_Block_Wool_Purple"
    },
    {
      "x": 6,
      "y": 69,
      "z": 9,
      "name": "Cloth_Block_Wool_Purple"
    },
    {
      "x": 6,
      "y": 0,
      "z": 10,
      "name": "Soil_Grass"
    },
    {
      "x": 6,
      "y": 2,
      "z": 10,
      "name": "Plant_Leaves_Bottle",
      "support": 15
    },
    {
      "x": 6,
      "y": 3,
      "z": 10,
      "name": "Plant_Leaves_Bottle",
      "support": 15
    },
    {
      "x": 6,
      "y": 4,
      "z": 10,
      "name": "Plant_Leaves_Bottle",
      "support": 15
    },
    {
      "x": 6,
      "y": 5,
      "z": 10,
      "name": "Plant_Leaves_Bottle",
      "support": 15
    },
    {
      "x": 6,
      "y": 6,
      "z": 10,
      "name": "Plant_Leaves_Bottle",
      "support": 15
    },
    {
      "x": 6,
      "y": 20,
      "z": 10,
      "name": "Plant_Leaves_Bottle",
      "support": 15
    },
    {
      "x": 6,
      "y": 21,
      "z": 10,
      "name": "Plant_Leaves_Bottle",
      "support": 15
    },
    {
      "x": 6,
      "y": 22,
      "z": 10,
      "name": "Plant_Leaves_Bottle",
      "support": 15
    },
    {
      "x": 6,
      "y": 51,
      "z": 10,
      "name": "Wood_Hardwood_Planks_Half",
      "rotation": 8
    },
    {
      "x": 6,
      "y": 52,
      "z": 10,
      "name": "Wood_Hardwood_Planks"
    },
    {
      "x": 6,
      "y": 57,
      "z": 10,
      "name": "Wood_Hardwood_Planks"
    },
    {
      "x": 6,
      "y": 58,
      "z": 10,
      "name": "Wood_Hardwood_Planks"
    },
    {
      "x": 6,
      "y": 59,
      "z": 10,
      "name": "Rock_Chalk_Brick_Smooth"
    },
    {
      "x": 6,
      "y": 60,
      "z": 10,
      "name": "Rock_Chalk_Brick_Smooth"
    },
    {
      "x": 6,
      "y": 61,
      "z": 10,
      "name": "Rock_Chalk_Brick_Smooth"
    },
    {
      "x": 6,
      "y": 62,
      "z": 10,
      "name": "Rock_Chalk_Brick_Smooth"
    },
    {
      "x": 6,
      "y": 63,
      "z": 10,
      "name": "Rock_Chalk_Brick_Smooth"
    },
    {
      "x": 6,
      "y": 69,
      "z": 10,
      "name": "Soil_Clay_Purple"
    },
    {
      "x": 6,
      "y": 70,
      "z": 10,
      "name": "Soil_Clay_Purple"
    },
    {
      "x": 6,
      "y": 71,
      "z": 10,
      "name": "Soil_Clay_Purple"
    },
    {
      "x": 6,
      "y": 0,
      "z": 11,
      "name": "Soil_Dirt"
    },
    {
      "x": 6,
      "y": 1,
      "z": 11,
      "name": "Rock_Stone_Cobble"
    },
    {
      "x": 6,
      "y": 2,
      "z": 11,
      "name": "Rock_Stone_Cobble"
    },
    {
      "x": 6,
      "y": 3,
      "z": 11,
      "name": "Rock_Stone_Cobble"
    },
    {
      "x": 6,
      "y": 4,
      "z": 11,
      "name": "Rock_Stone_Cobble"
    },
    {
      "x": 6,
      "y": 5,
      "z": 11,
      "name": "Rock_Stone_Cobble"
    },
    {
      "x": 6,
      "y": 6,
      "z": 11,
      "name": "Rock_Stone_Cobble"
    },
    {
      "x": 6,
      "y": 7,
      "z": 11,
      "name": "Rock_Stone_Cobble"
    },
    {
      "x": 6,
      "y": 8,
      "z": 11,
      "name": "Rock_Stone_Cobble"
    },
    {
      "x": 6,
      "y": 9,
      "z": 11,
      "name": "Rock_Stone_Cobble"
    },
    {
      "x": 6,
      "y": 10,
      "z": 11,
      "name": "Rock_Stone_Cobble"
    },
    {
      "x": 6,
      "y": 11,
      "z": 11,
      "name": "Rock_Stone_Cobble"
    },
    {
      "x": 6,
      "y": 12,
      "z": 11,
      "name": "Rock_Stone_Cobble"
    },
    {
      "x": 6,
      "y": 13,
      "z": 11,
      "name": "Rock_Stone_Cobble"
    },
    {
      "x": 6,
      "y": 14,
      "z": 11,
      "name": "Rock_Stone_Cobble"
    },
    {
      "x": 6,
      "y": 15,
      "z": 11,
      "name": "Rock_Stone_Cobble"
    },
    {
      "x": 6,
      "y": 16,
      "z": 11,
      "name": "Rock_Stone_Cobble"
    },
    {
      "x": 6,
      "y": 17,
      "z": 11,
      "name": "Rock_Stone_Cobble"
    },
    {
      "x": 6,
      "y": 18,
      "z": 11,
      "name": "Rock_Stone_Cobble"
    },
    {
      "x": 6,
      "y": 19,
      "z": 11,
      "name": "Rock_Stone_Cobble"
    },
    {
      "x": 6,
      "y": 20,
      "z": 11,
      "name": "Rock_Stone_Cobble"
    },
    {
      "x": 6,
      "y": 21,
      "z": 11,
      "name": "Rock_Stone_Brick"
    },
    {
      "x": 6,
      "y": 22,
      "z": 11,
      "name": "Rock_Stone_Brick"
    },
    {
      "x": 6,
      "y": 23,
      "z": 11,
      "name": "Rock_Stone_Brick"
    },
    {
      "x": 6,
      "y": 24,
      "z": 11,
      "name": "Rock_Stone_Brick"
    },
    {
      "x": 6,
      "y": 25,
      "z": 11,
      "name": "Rock_Stone_Brick"
    },
    {
      "x": 6,
      "y": 26,
      "z": 11,
      "name": "Rock_Stone_Cobble"
    },
    {
      "x": 6,
      "y": 27,
      "z": 11,
      "name": "Rock_Stone_Cobble"
    },
    {
      "x": 6,
      "y": 28,
      "z": 11,
      "name": "Rock_Stone_Cobble"
    },
    {
      "x": 6,
      "y": 29,
      "z": 11,
      "name": "Rock_Stone_Brick"
    },
    {
      "x": 6,
      "y": 49,
      "z": 11,
      "name": "Wood_Hardwood_Stairs",
      "rotation": 9
    },
    {
      "x": 6,
      "y": 50,
      "z": 11,
      "name": "Wood_Hardwood_Stairs",
      "rotation": 1
    },
    {
      "x": 6,
      "y": 51,
      "z": 11,
      "name": "Wood_Hardwood_Planks_Half",
      "rotation": 8
    },
    {
      "x": 6,
      "y": 52,
      "z": 11,
      "name": "Wood_Hardwood_Planks"
    },
    {
      "x": 6,
      "y": 53,
      "z": 11,
      "name": "Wood_Hardwood_Beam"
    },
    {
      "x": 6,
      "y": 54,
      "z": 11,
      "name": "Wood_Hardwood_Beam"
    },
    {
      "x": 6,
      "y": 55,
      "z": 11,
      "name": "Wood_Hardwood_Beam"
    },
    {
      "x": 6,
      "y": 56,
      "z": 11,
      "name": "Wood_Hardwood_Beam"
    },
    {
      "x": 6,
      "y": 57,
      "z": 11,
      "name": "Wood_Hardwood_Planks"
    },
    {
      "x": 6,
      "y": 60,
      "z": 11,
      "name": "Cloth_Block_Wool_Black"
    },
    {
      "x": 6,
      "y": 61,
      "z": 11,
      "name": "Cloth_Block_Wool_Black"
    },
    {
      "x": 6,
      "y": 62,
      "z": 11,
      "name": "Cloth_Block_Wool_Black"
    },
    {
      "x": 6,
      "y": 63,
      "z": 11,
      "name": "Rock_Stone_Brick"
    },
    {
      "x": 6,
      "y": 71,
      "z": 11,
      "name": "Cloth_Block_Wool_Purple"
    },
    {
      "x": 6,
      "y": 72,
      "z": 11,
      "name": "Soil_Clay_Purple"
    },
    {
      "x": 6,
      "y": 73,
      "z": 11,
      "name": "Soil_Clay_Purple"
    },
    {
      "x": 6,
      "y": 0,
      "z": 12,
      "name": "Soil_Grass"
    },
    {
      "x": 6,
      "y": 1,
      "z": 12,
      "name": "Rock_Stone_Cobble"
    },
    {
      "x": 6,
      "y": 2,
      "z": 12,
      "name": "Rock_Stone_Cobble"
    },
    {
      "x": 6,
      "y": 3,
      "z": 12,
      "name": "Rock_Stone_Cobble"
    },
    {
      "x": 6,
      "y": 4,
      "z": 12,
      "name": "Rock_Stone_Cobble"
    },
    {
      "x": 6,
      "y": 5,
      "z": 12,
      "name": "Rock_Stone_Cobble"
    },
    {
      "x": 6,
      "y": 6,
      "z": 12,
      "name": "Rock_Stone_Cobble"
    },
    {
      "x": 6,
      "y": 7,
      "z": 12,
      "name": "Rock_Stone_Brick"
    },
    {
      "x": 6,
      "y": 8,
      "z": 12,
      "name": "Rock_Stone_Brick"
    },
    {
      "x": 6,
      "y": 9,
      "z": 12,
      "name": "Rock_Stone_Brick"
    },
    {
      "x": 6,
      "y": 10,
      "z": 12,
      "name": "Rock_Stone_Brick"
    },
    {
      "x": 6,
      "y": 11,
      "z": 12,
      "name": "Rock_Stone_Brick"
    },
    {
      "x": 6,
      "y": 12,
      "z": 12,
      "name": "Rock_Stone_Brick"
    },
    {
      "x": 6,
      "y": 13,
      "z": 12,
      "name": "Rock_Stone_Brick"
    },
    {
      "x": 6,
      "y": 14,
      "z": 12,
      "name": "Rock_Stone_Brick"
    },
    {
      "x": 6,
      "y": 15,
      "z": 12,
      "name": "Rock_Stone_Brick"
    },
    {
      "x": 6,
      "y": 16,
      "z": 12,
      "name": "Rock_Stone_Cobble"
    },
    {
      "x": 6,
      "y": 17,
      "z": 12,
      "name": "Rock_Stone_Brick"
    },
    {
      "x": 6,
      "y": 18,
      "z": 12,
      "name": "Rock_Stone_Cobble"
    },
    {
      "x": 6,
      "y": 19,
      "z": 12,
      "name": "Rock_Stone_Cobble"
    },
    {
      "x": 6,
      "y": 20,
      "z": 12,
      "name": "Rock_Stone_Cobble"
    },
    {
      "x": 6,
      "y": 21,
      "z": 12,
      "name": "Rock_Stone_Cobble"
    },
    {
      "x": 6,
      "y": 22,
      "z": 12,
      "name": "Rock_Stone_Brick"
    },
    {
      "x": 6,
      "y": 23,
      "z": 12,
      "name": "Rock_Stone_Brick"
    },
    {
      "x": 6,
      "y": 24,
      "z": 12,
      "name": "Rock_Stone_Brick"
    },
    {
      "x": 6,
      "y": 25,
      "z": 12,
      "name": "Rock_Stone_Brick"
    },
    {
      "x": 6,
      "y": 26,
      "z": 12,
      "name": "Rock_Stone_Brick"
    },
    {
      "x": 6,
      "y": 27,
      "z": 12,
      "name": "Rock_Stone_Cobble"
    },
    {
      "x": 6,
      "y": 28,
      "z": 12,
      "name": "Rock_Stone_Cobble"
    },
    {
      "x": 6,
      "y": 29,
      "z": 12,
      "name": "Rock_Stone_Brick"
    },
    {
      "x": 6,
      "y": 51,
      "z": 12,
      "name": "Wood_Hardwood_Planks_Half",
      "rotation": 8
    },
    {
      "x": 6,
      "y": 52,
      "z": 12,
      "name": "Wood_Hardwood_Planks"
    },
    {
      "x": 6,
      "y": 53,
      "z": 12,
      "name": "Wood_Ash_Trunk",
      "support": 15,
      "rotation": 2
    },
    {
      "x": 6,
      "y": 54,
      "z": 12,
      "name": "Wood_Ash_Trunk",
      "support": 15,
      "rotation": 2
    },
    {
      "x": 6,
      "y": 55,
      "z": 12,
      "name": "Wood_Ash_Trunk",
      "support": 15,
      "rotation": 2
    },
    {
      "x": 6,
      "y": 56,
      "z": 12,
      "name": "Wood_Ash_Trunk",
      "support": 15,
      "rotation": 2
    },
    {
      "x": 6,
      "y": 57,
      "z": 12,
      "name": "Wood_Hardwood_Planks"
    },
    {
      "x": 6,
      "y": 58,
      "z": 12,
      "name": "Rock_Stone_Brick"
    },
    {
      "x": 6,
      "y": 59,
      "z": 12,
      "name": "Rock_Stone_Brick"
    },
    {
      "x": 6,
      "y": 60,
      "z": 12,
      "name": "Rock_Stone_Brick"
    },
    {
      "x": 6,
      "y": 61,
      "z": 12,
      "name": "Rock_Stone_Brick"
    },
    {
      "x": 6,
      "y": 62,
      "z": 12,
      "name": "Rock_Stone_Brick"
    },
    {
      "x": 6,
      "y": 63,
      "z": 12,
      "name": "Rock_Stone_Brick"
    },
    {
      "x": 6,
      "y": 64,
      "z": 12,
      "name": "Rock_Stone_Brick"
    },
    {
      "x": 6,
      "y": 65,
      "z": 12,
      "name": "Rock_Stone_Brick"
    },
    {
      "x": 6,
      "y": 66,
      "z": 12,
      "name": "Rock_Stone_Brick"
    },
    {
      "x": 6,
      "y": 72,
      "z": 12,
      "name": "Cloth_Block_Wool_Purple"
    },
    {
      "x": 6,
      "y": 73,
      "z": 12,
      "name": "Soil_Clay_Purple"
    },
    {
      "x": 6,
      "y": 74,
      "z": 12,
      "name": "Soil_Clay_Purple"
    },
    {
      "x": 6,
      "y": 75,
      "z": 12,
      "name": "Soil_Clay_Purple"
    },
    {
      "x": 6,
      "y": 0,
      "z": 13,
      "name": "Soil_Grass"
    },
    {
      "x": 6,
      "y": 29,
      "z": 13,
      "name": "Rock_Stone_Cobble"
    },
    {
      "x": 6,
      "y": 37,
      "z": 13,
      "name": "Rock_Stone_Brick_Smooth"
    },
    {
      "x": 6,
      "y": 47,
      "z": 13,
      "name": "*Furniture_Crude_Trapdoor_State_Definitions_OpenDoorOut",
      "rotation": 3
    },
    {
      "x": 6,
      "y": 48,
      "z": 13,
      "name": "Wood_Hardwood_Stairs",
      "rotation": 9
    },
    {
      "x": 6,
      "y": 49,
      "z": 13,
      "name": "Wood_Hardwood_Stairs",
      "rotation": 1
    },
    {
      "x": 6,
      "y": 51,
      "z": 13,
      "name": "Rock_Chalk_Brick_Smooth"
    },
    {
      "x": 6,
      "y": 52,
      "z": 13,
      "name": "Rock_Chalk_Brick_Smooth"
    },
    {
      "x": 6,
      "y": 53,
      "z": 13,
      "name": "Rock_Chalk_Brick_Smooth"
    },
    {
      "x": 6,
      "y": 54,
      "z": 13,
      "name": "Rock_Chalk_Brick_Smooth"
    },
    {
      "x": 6,
      "y": 55,
      "z": 13,
      "name": "Rock_Chalk_Brick_Smooth"
    },
    {
      "x": 6,
      "y": 56,
      "z": 13,
      "name": "Rock_Chalk_Brick_Smooth"
    },
    {
      "x": 6,
      "y": 57,
      "z": 13,
      "name": "Wood_Hardwood_Planks"
    },
    {
      "x": 6,
      "y": 58,
      "z": 13,
      "name": "Rock_Stone_Brick"
    },
    {
      "x": 6,
      "y": 59,
      "z": 13,
      "name": "Rock_Stone_Brick"
    },
    {
      "x": 6,
      "y": 60,
      "z": 13,
      "name": "Wood_Hardwood_Stairs"
    },
    {
      "x": 6,
      "y": 61,
      "z": 13,
      "name": "Wood_Hardwood_Stairs",
      "rotation": 11
    },
    {
      "x": 6,
      "y": 62,
      "z": 13,
      "name": "Wood_Hardwood_Stairs",
      "rotation": 8
    },
    {
      "x": 6,
      "y": 63,
      "z": 13,
      "name": "Wood_Hardwood_Stairs",
      "rotation": 1
    },
    {
      "x": 6,
      "y": 64,
      "z": 13,
      "name": "Wood_Hardwood_Stairs",
      "rotation": 11
    },
    {
      "x": 6,
      "y": 65,
      "z": 13,
      "name": "Rock_Stone_Brick"
    },
    {
      "x": 6,
      "y": 66,
      "z": 13,
      "name": "Rock_Stone_Brick"
    },
    {
      "x": 6,
      "y": 73,
      "z": 13,
      "name": "Cloth_Block_Wool_Purple"
    },
    {
      "x": 6,
      "y": 74,
      "z": 13,
      "name": "Soil_Clay_Purple"
    },
    {
      "x": 6,
      "y": 75,
      "z": 13,
      "name": "Soil_Clay_Purple"
    },
    {
      "x": 6,
      "y": 76,
      "z": 13,
      "name": "Soil_Clay_Purple"
    },
    {
      "x": 6,
      "y": 0,
      "z": 14,
      "name": "Soil_Grass"
    },
    {
      "x": 6,
      "y": 29,
      "z": 14,
      "name": "Rock_Stone_Cobble"
    },
    {
      "x": 6,
      "y": 30,
      "z": 14,
      "name": "Plant_Leaves_Bottle",
      "support": 15
    },
    {
      "x": 6,
      "y": 37,
      "z": 14,
      "name": "Rock_Stone_Brick_Smooth"
    },
    {
      "x": 6,
      "y": 38,
      "z": 14,
      "name": "Rock_Stone_Brick_Smooth"
    },
    {
      "x": 6,
      "y": 39,
      "z": 14,
      "name": "Rock_Stone_Brick_Smooth"
    },
    {
      "x": 6,
      "y": 42,
      "z": 14,
      "name": "Rock_Stone_Brick_Smooth"
    },
    {
      "x": 6,
      "y": 51,
      "z": 14,
      "name": "Rock_Chalk_Brick_Smooth"
    },
    {
      "x": 6,
      "y": 52,
      "z": 14,
      "name": "Rock_Chalk_Brick_Smooth"
    },
    {
      "x": 6,
      "y": 53,
      "z": 14,
      "name": "Rock_Chalk_Brick_Smooth"
    },
    {
      "x": 6,
      "y": 54,
      "z": 14,
      "name": "Rock_Chalk_Brick_Smooth"
    },
    {
      "x": 6,
      "y": 55,
      "z": 14,
      "name": "Rock_Chalk_Brick_Smooth"
    },
    {
      "x": 6,
      "y": 56,
      "z": 14,
      "name": "Rock_Chalk_Brick_Smooth"
    },
    {
      "x": 6,
      "y": 57,
      "z": 14,
      "name": "Wood_Hardwood_Planks"
    },
    {
      "x": 6,
      "y": 58,
      "z": 14,
      "name": "Rock_Stone_Brick"
    },
    {
      "x": 6,
      "y": 59,
      "z": 14,
      "name": "Rock_Stone_Brick"
    },
    {
      "x": 6,
      "y": 60,
      "z": 14,
      "name": "Rock_Stone_Brick"
    },
    {
      "x": 6,
      "y": 61,
      "z": 14,
      "name": "Rock_Stone_Brick"
    },
    {
      "x": 6,
      "y": 62,
      "z": 14,
      "name": "Rock_Stone_Brick"
    },
    {
      "x": 6,
      "y": 63,
      "z": 14,
      "name": "Rock_Stone_Brick"
    },
    {
      "x": 6,
      "y": 64,
      "z": 14,
      "name": "Rock_Stone_Brick"
    },
    {
      "x": 6,
      "y": 65,
      "z": 14,
      "name": "Rock_Stone_Brick"
    },
    {
      "x": 6,
      "y": 66,
      "z": 14,
      "name": "Rock_Stone_Brick"
    },
    {
      "x": 6,
      "y": 74,
      "z": 14,
      "name": "Cloth_Block_Wool_Purple"
    },
    {
      "x": 6,
      "y": 75,
      "z": 14,
      "name": "Cloth_Block_Wool_Purple"
    },
    {
      "x": 6,
      "y": 76,
      "z": 14,
      "name": "Soil_Clay_Purple"
    },
    {
      "x": 6,
      "y": 77,
      "z": 14,
      "name": "Soil_Clay_Purple"
    },
    {
      "x": 6,
      "y": 0,
      "z": 15,
      "name": "Soil_Grass"
    },
    {
      "x": 6,
      "y": 29,
      "z": 15,
      "name": "Rock_Stone_Cobble"
    },
    {
      "x": 6,
      "y": 30,
      "z": 15,
      "name": "Plant_Leaves_Bottle",
      "support": 15
    },
    {
      "x": 6,
      "y": 31,
      "z": 15,
      "name": "Plant_Leaves_Bottle",
      "support": 15
    },
    {
      "x": 6,
      "y": 32,
      "z": 15,
      "name": "Rock_Stone_Brick"
    },
    {
      "x": 6,
      "y": 37,
      "z": 15,
      "name": "Rock_Stone_Brick_Smooth"
    },
    {
      "x": 6,
      "y": 38,
      "z": 15,
      "name": "Rock_Stone_Brick_Smooth"
    },
    {
      "x": 6,
      "y": 39,
      "z": 15,
      "name": "Rock_Stone_Brick_Smooth"
    },
    {
      "x": 6,
      "y": 40,
      "z": 15,
      "name": "Rock_Stone_Brick_Smooth"
    },
    {
      "x": 6,
      "y": 41,
      "z": 15,
      "name": "Rock_Stone_Brick_Smooth"
    },
    {
      "x": 6,
      "y": 42,
      "z": 15,
      "name": "Rock_Stone_Brick_Smooth"
    },
    {
      "x": 6,
      "y": 43,
      "z": 15,
      "name": "Rock_Stone_Brick_Smooth"
    },
    {
      "x": 6,
      "y": 44,
      "z": 15,
      "name": "Rock_Stone_Brick_Smooth"
    },
    {
      "x": 6,
      "y": 47,
      "z": 15,
      "name": "*Furniture_Crude_Trapdoor_State_Definitions_OpenDoorOut",
      "rotation": 3
    },
    {
      "x": 6,
      "y": 48,
      "z": 15,
      "name": "Wood_Hardwood_Stairs",
      "rotation": 9
    },
    {
      "x": 6,
      "y": 49,
      "z": 15,
      "name": "Wood_Hardwood_Stairs",
      "rotation": 1
    },
    {
      "x": 6,
      "y": 51,
      "z": 15,
      "name": "Rock_Chalk_Brick_Smooth"
    },
    {
      "x": 6,
      "y": 52,
      "z": 15,
      "name": "Rock_Chalk_Brick_Smooth"
    },
    {
      "x": 6,
      "y": 53,
      "z": 15,
      "name": "Rock_Chalk_Brick_Smooth"
    },
    {
      "x": 6,
      "y": 54,
      "z": 15,
      "name": "Rock_Chalk_Brick_Smooth"
    },
    {
      "x": 6,
      "y": 55,
      "z": 15,
      "name": "Rock_Chalk_Brick_Smooth"
    },
    {
      "x": 6,
      "y": 56,
      "z": 15,
      "name": "Rock_Chalk_Brick_Smooth"
    },
    {
      "x": 6,
      "y": 57,
      "z": 15,
      "name": "Wood_Hardwood_Planks"
    },
    {
      "x": 6,
      "y": 58,
      "z": 15,
      "name": "Rock_Stone_Brick"
    },
    {
      "x": 6,
      "y": 59,
      "z": 15,
      "name": "Rock_Stone_Brick"
    },
    {
      "x": 6,
      "y": 62,
      "z": 15,
      "name": "Rock_Stone_Brick"
    },
    {
      "x": 6,
      "y": 63,
      "z": 15,
      "name": "Rock_Stone_Brick"
    },
    {
      "x": 6,
      "y": 64,
      "z": 15,
      "name": "Wood_Hardwood_Stairs"
    },
    {
      "x": 6,
      "y": 65,
      "z": 15,
      "name": "Rock_Stone_Brick"
    },
    {
      "x": 6,
      "y": 66,
      "z": 15,
      "name": "Rock_Stone_Brick"
    },
    {
      "x": 6,
      "y": 74,
      "z": 15,
      "name": "Cloth_Block_Wool_Purple"
    },
    {
      "x": 6,
      "y": 75,
      "z": 15,
      "name": "Cloth_Block_Wool_Purple"
    },
    {
      "x": 6,
      "y": 76,
      "z": 15,
      "name": "Soil_Clay_Purple"
    },
    {
      "x": 6,
      "y": 77,
      "z": 15,
      "name": "Soil_Clay_Purple"
    },
    {
      "x": 6,
      "y": 0,
      "z": 16,
      "name": "Soil_Grass"
    },
    {
      "x": 6,
      "y": 29,
      "z": 16,
      "name": "Rock_Stone_Cobble"
    },
    {
      "x": 6,
      "y": 32,
      "z": 16,
      "name": "Plant_Leaves_Bottle",
      "support": 15
    },
    {
      "x": 6,
      "y": 39,
      "z": 16,
      "name": "Rock_Stone_Brick_Smooth"
    },
    {
      "x": 6,
      "y": 40,
      "z": 16,
      "name": "Rock_Stone_Brick_Smooth"
    },
    {
      "x": 6,
      "y": 41,
      "z": 16,
      "name": "Rock_Stone_Brick_Smooth"
    },
    {
      "x": 6,
      "y": 42,
      "z": 16,
      "name": "Rock_Stone_Brick_Smooth"
    },
    {
      "x": 6,
      "y": 43,
      "z": 16,
      "name": "Rock_Stone_Brick_Smooth"
    },
    {
      "x": 6,
      "y": 51,
      "z": 16,
      "name": "Rock_Chalk_Brick_Smooth"
    },
    {
      "x": 6,
      "y": 52,
      "z": 16,
      "name": "Rock_Chalk_Brick_Smooth"
    },
    {
      "x": 6,
      "y": 53,
      "z": 16,
      "name": "Rock_Chalk_Brick_Smooth"
    },
    {
      "x": 6,
      "y": 54,
      "z": 16,
      "name": "Rock_Chalk_Brick_Smooth"
    },
    {
      "x": 6,
      "y": 55,
      "z": 16,
      "name": "Rock_Chalk_Brick_Smooth"
    },
    {
      "x": 6,
      "y": 56,
      "z": 16,
      "name": "Rock_Chalk_Brick_Smooth"
    },
    {
      "x": 6,
      "y": 57,
      "z": 16,
      "name": "Wood_Hardwood_Planks"
    },
    {
      "x": 6,
      "y": 58,
      "z": 16,
      "name": "Rock_Stone_Brick"
    },
    {
      "x": 6,
      "y": 59,
      "z": 16,
      "name": "Rock_Stone_Brick"
    },
    {
      "x": 6,
      "y": 60,
      "z": 16,
      "name": "Rock_Stone_Brick"
    },
    {
      "x": 6,
      "y": 61,
      "z": 16,
      "name": "Rock_Stone_Brick"
    },
    {
      "x": 6,
      "y": 62,
      "z": 16,
      "name": "Rock_Stone_Brick"
    },
    {
      "x": 6,
      "y": 63,
      "z": 16,
      "name": "Wood_Hardwood_Stairs",
      "rotation": 2
    },
    {
      "x": 6,
      "y": 64,
      "z": 16,
      "name": "Wood_Hardwood_Stairs",
      "rotation": 11
    },
    {
      "x": 6,
      "y": 65,
      "z": 16,
      "name": "Rock_Stone_Brick"
    },
    {
      "x": 6,
      "y": 66,
      "z": 16,
      "name": "Rock_Stone_Brick"
    },
    {
      "x": 6,
      "y": 74,
      "z": 16,
