{
  "version": 8,
  "blockIdVersion": 11,
  "anchorX": 0,
  "anchorY": 0,
  "anchorZ": 0,
  "blocks": [
    {
      "x": 1,
      "y": 6,
      "z": -10,
      "name": "Wood_Beech_Trunk",
      "support": 15,
      "rotation": 5
    },
    {
      "x": 1,
      "y": 25,
      "z": -10,
      "name": "Wood_Darkwood_Stairs",
      "rotation": 9
    },
    {
      "x": 1,
      "y": 26,
      "z": -10,
      "name": "Wood_Darkwood_Stairs",
      "rotation": 3
    },
    {
      "x": 1,
      "y": 6,
      "z": -9,
      "name": "Wood_Hardwood_Stairs",
      "rotation": 10
    },
    {
      "x": 1,
      "y": 26,
      "z": -9,
      "name": "Wood_Darkwood_Stairs",
      "rotation": 3
    },
    {
      "x": 1,
      "y": 6,
      "z": -8,
      "name": "Wood_Hardwood_Planks_Half",
      "rotation": 8
    },
    {
      "x": 1,
      "y": 26,
      "z": -8,
      "name": "Wood_Darkwood_Stairs",
      "rotation": 3
    },
    {
      "x": 1,
      "y": 26,
      "z": -7,
      "name": "Wood_Darkwood_Stairs",
      "rotation": 3
    },
    {
      "x": 1,
      "y": 26,
      "z": -6,
      "name": "Wood_Darkwood_Stairs",
      "rotation": 3
    },
    {
      "x": 1,
      "y": 26,
      "z": -5,
      "name": "Wood_Darkwood_Stairs",
      "rotation": 3
    },
    {
      "x": 1,
      "y": 6,
      "z": -4,
      "name": "Wood_Hardwood_Planks_Half",
      "rotation": 8
    },
    {
      "x": 1,
      "y": 26,
      "z": -4,
      "name": "Wood_Darkwood_Stairs",
      "rotation": 3
    },
    {
      "x": 1,
      "y": 6,
      "z": -3,
      "name": "Wood_Hardwood_Stairs",
      "rotation": 8
    },
    {
      "x": 1,
      "y": 26,
      "z": -3,
      "name": "Wood_Darkwood_Stairs",
      "rotation": 3
    },
    {
      "x": 1,
      "y": 6,
      "z": -2,
      "name": "Wood_Beech_Trunk",
      "support": 15,
      "rotation": 5
    },
    {
      "x": 1,
      "y": 25,
      "z": -2,
      "name": "Wood_Darkwood_Stairs",
      "rotation": 9
    },
    {
      "x": 1,
      "y": 26,
      "z": -2,
      "name": "Wood_Darkwood_Stairs",
      "rotation": 3
    },
    {
      "x": 2,
      "y": 6,
      "z": -11,
      "name": "Wood_Beech_Trunk",
      "support": 15,
      "rotation": 4
    },
    {
      "x": 2,
      "y": 0,
      "z": -10,
      "name": "Rock_Stone_Brick_Pillar_Base"
    },
    {
      "x": 2,
      "y": 1,
      "z": -10,
      "name": "Rock_Stone_Brick_Pillar_Middle"
    },
    {
      "x": 2,
      "y": 2,
      "z": -10,
      "name": "Rock_Stone_Brick_Pillar_Middle"
    },
    {
      "x": 2,
      "y": 3,
      "z": -10,
      "name": "Rock_Stone_Brick_Pillar_Middle"
    },
    {
      "x": 2,
      "y": 4,
      "z": -10,
      "name": "Rock_Stone_Brick_Pillar_Middle"
    },
    {
      "x": 2,
      "y": 5,
      "z": -10,
      "name": "Rock_Stone_Brick_Pillar_Base",
      "rotation": 8
    },
    {
      "x": 2,
      "y": 6,
      "z": -10,
      "name": "Wood_Beech_Trunk",
      "support": 15,
      "rotation": 5
    },
    {
      "x": 2,
      "y": 7,
      "z": -10,
      "name": "Wood_Hardwood_Planks_Half"
    },
    {
      "x": 2,
      "y": 25,
      "z": -10,
      "name": "Furniture_Crude_Trapdoor",
      "rotation": 2
    },
    {
      "x": 2,
      "y": 26,
      "z": -10,
      "name": "Wood_Darkwood_Planks"
    },
    {
      "x": 2,
      "y": 27,
      "z": -10,
      "name": "Wood_Darkwood_Stairs",
      "rotation": 3
    },
    {
      "x": 2,
      "y": 6,
      "z": -9,
      "name": "Wood_Beech_Trunk",
      "support": 15,
      "rotation": 4
    },
    {
      "x": 2,
      "y": 18,
      "z": -9,
      "name": "Wood_Hardwood_Stairs",
      "rotation": 9
    },
    {
      "x": 2,
      "y": 19,
      "z": -9,
      "name": "Wood_Beech_Trunk",
      "support": 15,
      "rotation": 5
    },
    {
      "x": 2,
      "y": 25,
      "z": -9,
      "name": "Wood_Hardwood_Stairs",
      "rotation": 9
    },
    {
      "x": 2,
      "y": 26,
      "z": -9,
      "name": "Rock_Basalt_Cobble_Roof_Steep",
      "rotation": 3
    },
    {
      "x": 2,
      "y": 27,
      "z": -9,
      "name": "Rock_Basalt_Cobble_Roof_Steep",
      "filler": 1024,
      "rotation": 3
    },
    {
      "x": 2,
      "y": 6,
      "z": -8,
      "name": "Wood_Beech_Trunk",
      "support": 15,
      "rotation": 4
    },
    {
      "x": 2,
      "y": 19,
      "z": -8,
      "name": "Wood_Hardwood_Stairs",
      "rotation": 10
    },
    {
      "x": 2,
      "y": 25,
      "z": -8,
      "name": "*Furniture_Crude_Trapdoor_State_Definitions_CloseDoorOut",
      "rotation": 3
    },
    {
      "x": 2,
      "y": 26,
      "z": -8,
      "name": "Rock_Basalt_Cobble_Roof_Steep",
      "rotation": 3
    },
    {
      "x": 2,
      "y": 27,
      "z": -8,
      "name": "Rock_Basalt_Cobble_Roof_Steep",
      "filler": 1024,
      "rotation": 3
    },
    {
      "x": 2,
      "y": 6,
      "z": -7,
      "name": "Wood_Beech_Trunk",
      "support": 15,
      "rotation": 4
    },
    {
      "x": 2,
      "y": 25,
      "z": -7,
      "name": "Wood_Hardwood_Stairs",
      "rotation": 9
    },
    {
      "x": 2,
      "y": 26,
      "z": -7,
      "name": "Rock_Basalt_Cobble_Roof_Steep",
      "rotation": 3
    },
    {
      "x": 2,
      "y": 27,
      "z": -7,
      "name": "Rock_Basalt_Cobble_Roof_Steep",
      "filler": 1024,
      "rotation": 3
    },
    {
      "x": 2,
      "y": 6,
      "z": -6,
      "name": "Wood_Beech_Trunk",
      "support": 15,
      "rotation": 4
    },
    {
      "x": 2,
      "y": 19,
      "z": -6,
      "name": "Wood_Hardwood_Stairs",
      "rotation": 9
    },
    {
      "x": 2,
      "y": 25,
      "z": -6,
      "name": "*Furniture_Crude_Trapdoor_State_Definitions_CloseDoorOut",
      "rotation": 3
    },
    {
      "x": 2,
      "y": 26,
      "z": -6,
      "name": "Rock_Basalt_Cobble_Roof_Steep",
      "rotation": 3
    },
    {
      "x": 2,
      "y": 27,
      "z": -6,
      "name": "Rock_Basalt_Cobble_Roof_Steep",
      "filler": 1024,
      "rotation": 3
    },
    {
      "x": 2,
      "y": 6,
      "z": -5,
      "name": "Wood_Beech_Trunk",
      "support": 15,
      "rotation": 4
    },
    {
      "x": 2,
      "y": 25,
      "z": -5,
      "name": "Wood_Hardwood_Stairs",
      "rotation": 9
    },
    {
      "x": 2,
      "y": 26,
      "z": -5,
      "name": "Rock_Basalt_Cobble_Roof_Steep",
      "rotation": 3
    },
    {
      "x": 2,
      "y": 27,
      "z": -5,
      "name": "Rock_Basalt_Cobble_Roof_Steep",
      "filler": 1024,
      "rotation": 3
    },
    {
      "x": 2,
      "y": 6,
      "z": -4,
      "name": "Wood_Beech_Trunk",
      "support": 15,
      "rotation": 4
    },
    {
      "x": 2,
      "y": 19,
      "z": -4,
      "name": "Wood_Hardwood_Stairs",
      "rotation": 8
    },
    {
      "x": 2,
      "y": 25,
      "z": -4,
      "name": "*Furniture_Crude_Trapdoor_State_Definitions_CloseDoorOut",
      "rotation": 3
    },
    {
      "x": 2,
      "y": 26,
      "z": -4,
      "name": "Rock_Basalt_Cobble_Roof_Steep",
      "rotation": 3
    },
    {
      "x": 2,
      "y": 27,
      "z": -4,
      "name": "Rock_Basalt_Cobble_Roof_Steep",
      "filler": 1024,
      "rotation": 3
    },
    {
      "x": 2,
      "y": 6,
      "z": -3,
      "name": "Wood_Beech_Trunk",
      "support": 15,
      "rotation": 4
    },
    {
      "x": 2,
      "y": 18,
      "z": -3,
      "name": "Wood_Hardwood_Stairs",
      "rotation": 9
    },
    {
      "x": 2,
      "y": 19,
      "z": -3,
      "name": "Wood_Beech_Trunk",
      "support": 15,
      "rotation": 5
    },
    {
      "x": 2,
      "y": 25,
      "z": -3,
      "name": "Wood_Hardwood_Stairs",
      "rotation": 9
    },
    {
      "x": 2,
      "y": 26,
      "z": -3,
      "name": "Rock_Basalt_Cobble_Roof_Steep",
      "rotation": 3
    },
    {
      "x": 2,
      "y": 27,
      "z": -3,
      "name": "Rock_Basalt_Cobble_Roof_Steep",
      "filler": 1024,
      "rotation": 3
    },
    {
      "x": 2,
      "y": 0,
      "z": -2,
      "name": "Rock_Stone_Brick_Pillar_Base"
    },
    {
      "x": 2,
      "y": 1,
      "z": -2,
      "name": "Rock_Stone_Brick_Pillar_Middle"
    },
    {
      "x": 2,
      "y": 2,
      "z": -2,
      "name": "Rock_Stone_Brick_Pillar_Middle"
    },
    {
      "x": 2,
      "y": 3,
      "z": -2,
      "name": "Rock_Stone_Brick_Pillar_Middle"
    },
    {
      "x": 2,
      "y": 4,
      "z": -2,
      "name": "Rock_Stone_Brick_Pillar_Middle"
    },
    {
      "x": 2,
      "y": 5,
      "z": -2,
      "name": "Rock_Stone_Brick_Pillar_Base",
      "rotation": 8
    },
    {
      "x": 2,
      "y": 6,
      "z": -2,
      "name": "Wood_Beech_Trunk",
      "support": 15,
      "rotation": 5
    },
    {
      "x": 2,
      "y": 7,
      "z": -2,
      "name": "Wood_Hardwood_Planks_Half"
    },
    {
      "x": 2,
      "y": 25,
      "z": -2,
      "name": "Furniture_Crude_Trapdoor"
    },
    {
      "x": 2,
      "y": 26,
      "z": -2,
      "name": "Wood_Darkwood_Planks"
    },
    {
      "x": 2,
      "y": 27,
      "z": -2,
      "name": "Wood_Darkwood_Stairs",
      "rotation": 3
    },
    {
      "x": 2,
      "y": 6,
      "z": -1,
      "name": "Wood_Beech_Trunk",
      "support": 15,
      "rotation": 4
    },
    {
      "x": 3,
      "y": 6,
      "z": -11,
      "name": "Wood_Hardwood_Stairs",
      "rotation": 11
    },
    {
      "x": 3,
      "y": 6,
      "z": -10,
      "name": "Wood_Beech_Trunk",
      "support": 15,
      "rotation": 5
    },
    {
      "x": 3,
      "y": 18,
      "z": -10,
      "name": "Wood_Hardwood_Stairs",
      "rotation": 8
    },
    {
      "x": 3,
      "y": 19,
      "z": -10,
      "name": "Wood_Beech_Trunk",
      "support": 15,
      "rotation": 4
    },
    {
      "x": 3,
      "y": 25,
      "z": -10,
      "name": "Wood_Hardwood_Stairs",
      "rotation": 8
    },
    {
      "x": 3,
      "y": 27,
      "z": -10,
      "name": "Wood_Darkwood_Planks"
    },
    {
      "x": 3,
      "y": 28,
      "z": -10,
      "name": "Wood_Darkwood_Planks"
    },
    {
      "x": 3,
      "y": 29,
      "z": -10,
      "name": "Wood_Darkwood_Planks"
    },
    {
      "x": 3,
      "y": 30,
      "z": -10,
      "name": "Wood_Darkwood_Stairs",
      "rotation": 3
    },
    {
      "x": 3,
      "y": 0,
      "z": -9,
      "name": "Rock_Stone_Cobble"
    },
    {
      "x": 3,
      "y": 1,
      "z": -9,
      "name": "Rock_Stone_Brick"
    },
    {
      "x": 3,
      "y": 2,
      "z": -9,
      "name": "Rock_Calcite"
    },
    {
      "x": 3,
      "y": 3,
      "z": -9,
      "name": "Rock_Stone_Brick"
    },
    {
      "x": 3,
      "y": 4,
      "z": -9,
      "name": "Rock_Stone"
    },
    {
      "x": 3,
      "y": 5,
      "z": -9,
      "name": "Rock_Stone"
    },
    {
      "x": 3,
      "y": 6,
      "z": -9,
      "name": "Rock_Stone_Cobble_Beam"
    },
    {
      "x": 3,
      "y": 7,
      "z": -9,
      "name": "Rock_Stone"
    },
    {
      "x": 3,
      "y": 8,
      "z": -9,
      "name": "Rock_Stone_Brick"
    },
    {
      "x": 3,
      "y": 9,
      "z": -9,
      "name": "Rock_Calcite"
    },
    {
      "x": 3,
      "y": 10,
      "z": -9,
      "name": "Rock_Stone_Brick"
    },
    {
      "x": 3,
      "y": 11,
      "z": -9,
      "name": "Rock_Stone"
    },
    {
      "x": 3,
      "y": 12,
      "z": -9,
      "name": "Rock_Calcite"
    },
    {
      "x": 3,
      "y": 13,
      "z": -9,
      "name": "Rock_Stone"
    },
    {
      "x": 3,
      "y": 14,
      "z": -9,
      "name": "Rock_Stone_Cobble"
    },
    {
      "x": 3,
      "y": 15,
      "z": -9,
      "name": "Rock_Calcite"
    },
    {
      "x": 3,
      "y": 16,
      "z": -9,
      "name": "Rock_Stone"
    },
    {
      "x": 3,
      "y": 17,
      "z": -9,
      "name": "Rock_Stone_Cobble_Beam"
    },
    {
      "x": 3,
      "y": 18,
      "z": -9,
      "name": "Rock_Stone"
    },
    {
      "x": 3,
      "y": 19,
      "z": -9,
      "name": "Wood_Beech_Trunk",
      "rotation": 2
    },
    {
      "x": 3,
      "y": 20,
      "z": -9,
      "name": "Wood_Beech_Trunk",
      "rotation": 2
    },
    {
      "x": 3,
      "y": 21,
      "z": -9,
      "name": "Wood_Beech_Trunk",
      "rotation": 2
    },
    {
      "x": 3,
      "y": 22,
      "z": -9,
      "name": "Wood_Beech_Trunk",
      "rotation": 2
    },
    {
      "x": 3,
      "y": 23,
      "z": -9,
      "name": "Wood_Beech_Trunk",
      "rotation": 2
    },
    {
      "x": 3,
      "y": 24,
      "z": -9,
      "name": "Wood_Beech_Trunk",
      "rotation": 2
    },
    {
      "x": 3,
      "y": 25,
      "z": -9,
      "name": "Wood_Beech_Trunk",
      "rotation": 2
    },
    {
      "x": 3,
      "y": 26,
      "z": -9,
      "name": "Wood_Hardwood_Planks"
    },
    {
      "x": 3,
      "y": 28,
      "z": -9,
      "name": "Rock_Basalt_Cobble_Roof_Steep",
      "rotation": 3
    },
    {
      "x": 3,
      "y": 29,
      "z": -9,
      "name": "Rock_Basalt_Cobble_Roof_Steep",
      "filler": 1024,
      "rotation": 3
    },
    {
      "x": 3,
      "y": 0,
      "z": -8,
      "name": "Rock_Stone"
    },
    {
      "x": 3,
      "y": 1,
      "z": -8,
      "name": "Rock_Stone"
    },
    {
      "x": 3,
      "y": 2,
      "z": -8,
      "name": "Rock_Stone"
    },
    {
      "x": 3,
      "y": 3,
      "z": -8,
      "name": "Rock_Stone_Brick"
    },
    {
      "x": 3,
      "y": 4,
      "z": -8,
      "name": "Rock_Calcite"
    },
    {
      "x": 3,
      "y": 5,
      "z": -8,
      "name": "Rock_Stone"
    },
    {
      "x": 3,
      "y": 6,
      "z": -8,
      "name": "Rock_Stone_Cobble"
    },
    {
      "x": 3,
      "y": 7,
      "z": -8,
      "name": "Rock_Stone_Brick"
    },
    {
      "x": 3,
      "y": 8,
      "z": -8,
      "name": "Rock_Stone"
    },
    {
      "x": 3,
      "y": 9,
      "z": -8,
      "name": "Rock_Stone_Brick"
    },
    {
      "x": 3,
      "y": 10,
      "z": -8,
      "name": "Rock_Stone"
    },
    {
      "x": 3,
      "y": 11,
      "z": -8,
      "name": "Rock_Calcite"
    },
    {
      "x": 3,
      "y": 12,
      "z": -8,
      "name": "Rock_Calcite"
    },
    {
      "x": 3,
      "y": 13,
      "z": -8,
      "name": "Rock_Stone_Cobble"
    },
    {
      "x": 3,
      "y": 14,
      "z": -8,
      "name": "Rock_Calcite"
    },
    {
      "x": 3,
      "y": 15,
      "z": -8,
      "name": "Rock_Stone"
    },
    {
      "x": 3,
      "y": 16,
      "z": -8,
      "name": "Rock_Stone"
    },
    {
      "x": 3,
      "y": 17,
      "z": -8,
      "name": "Rock_Stone"
    },
    {
      "x": 3,
      "y": 18,
      "z": -8,
      "name": "Rock_Stone"
    },
    {
      "x": 3,
      "y": 19,
      "z": -8,
      "name": "Wood_Beech_Trunk",
      "rotation": 4
    },
    {
      "x": 3,
      "y": 20,
      "z": -8,
      "name": "Wood_Hardwood_Stairs"
    },
    {
      "x": 3,
      "y": 21,
      "z": -8,
      "name": "Wood_Burnt_Branch_Short",
      "support": 15,
      "rotation": 3
    },
    {
      "x": 3,
      "y": 22,
      "z": -8,
      "name": "Wood_Burnt_Branch_Short",
      "support": 15,
      "rotation": 3
    },
    {
      "x": 3,
      "y": 23,
      "z": -8,
      "name": "Wood_Burnt_Branch_Short",
      "support": 15,
      "rotation": 3
    },
    {
      "x": 3,
      "y": 24,
      "z": -8,
      "name": "Wood_Hardwood_Stairs",
      "rotation": 10
    },
    {
      "x": 3,
      "y": 25,
      "z": -8,
      "name": "Wood_Beech_Trunk",
      "rotation": 4
    },
    {
      "x": 3,
      "y": 26,
      "z": -8,
      "name": "Wood_Hardwood_Planks"
    },
    {
      "x": 3,
      "y": 27,
      "z": -8,
      "name": "Rock_Slate_Cobble_Stairs",
      "rotation": 3
    },
    {
      "x": 3,
      "y": 28,
      "z": -8,
      "name": "Rock_Basalt_Cobble_Roof_Steep",
      "rotation": 3
    },
    {
      "x": 3,
      "y": 29,
      "z": -8,
      "name": "Rock_Basalt_Cobble_Roof_Steep",
      "filler": 1024,
      "rotation": 3
    },
    {
      "x": 3,
      "y": 4,
      "z": -7,
      "name": "Rock_Calcite_Cobble_Stairs",
      "rotation": 10
    },
    {
      "x": 3,
      "y": 5,
      "z": -7,
      "name": "Rock_Stone_Brick"
    },
    {
      "x": 3,
      "y": 6,
      "z": -7,
      "name": "Rock_Stone_Brick"
    },
    {
      "x": 3,
      "y": 10,
      "z": -7,
      "name": "Rock_Calcite_Cobble_Stairs",
      "rotation": 10
    },
    {
      "x": 3,
      "y": 11,
      "z": -7,
      "name": "Rock_Stone_Brick"
    },
    {
      "x": 3,
      "y": 12,
      "z": -7,
      "name": "Rock_Stone_Cobble"
    },
    {
      "x": 3,
      "y": 13,
      "z": -7,
      "name": "Rock_Stone"
    },
    {
      "x": 3,
      "y": 14,
      "z": -7,
      "name": "Rock_Stone"
    },
    {
      "x": 3,
      "y": 15,
      "z": -7,
      "name": "Furniture_Tavern_Window",
      "rotation": 1
    },
    {
      "x": 3,
      "y": 16,
      "z": -7,
      "name": "Furniture_Tavern_Window",
      "rotation": 1
    },
    {
      "x": 3,
      "y": 17,
      "z": -7,
      "name": "Rock_Stone_Brick"
    },
    {
      "x": 3,
      "y": 18,
      "z": -7,
      "name": "Rock_Calcite"
    },
    {
      "x": 3,
      "y": 19,
      "z": -7,
      "name": "Wood_Beech_Trunk",
      "rotation": 4
    },
    {
      "x": 3,
      "y": 20,
      "z": -7,
      "name": "Wood_Burnt_Branch_Short",
      "support": 15,
      "rotation": 3
    },
    {
      "x": 3,
      "y": 24,
      "z": -7,
      "name": "Wood_Burnt_Branch_Short",
      "support": 15,
      "rotation": 3
    },
    {
      "x": 3,
      "y": 25,
      "z": -7,
      "name": "Wood_Beech_Trunk",
      "rotation": 4
    },
    {
      "x": 3,
      "y": 26,
      "z": -7,
      "name": "Wood_Hardwood_Planks"
    },
    {
      "x": 3,
      "y": 27,
      "z": -7,
      "name": "Rock_Slate_Cobble_Stairs",
      "rotation": 3
    },
    {
      "x": 3,
      "y": 28,
      "z": -7,
      "name": "Rock_Basalt_Cobble_Roof_Steep",
      "rotation": 3
    },
    {
      "x": 3,
      "y": 29,
      "z": -7,
      "name": "Rock_Basalt_Cobble_Roof_Steep",
      "filler": 1024,
      "rotation": 3
    },
    {
      "x": 3,
      "y": 5,
      "z": -6,
      "name": "Rock_Stone"
    },
    {
      "x": 3,
      "y": 6,
      "z": -6,
      "name": "Rock_Stone"
    },
    {
      "x": 3,
      "y": 10,
      "z": -6,
      "name": "Rock_Stone_Brick"
    },
    {
      "x": 3,
      "y": 11,
      "z": -6,
      "name": "Rock_Stone"
    },
    {
      "x": 3,
      "y": 12,
      "z": -6,
      "name": "Rock_Stone_Cobble"
    },
    {
      "x": 3,
      "y": 13,
      "z": -6,
      "name": "Rock_Calcite"
    },
    {
      "x": 3,
      "y": 14,
      "z": -6,
      "name": "Furniture_Tavern_Window",
      "rotation": 1
    },
    {
      "x": 3,
      "y": 15,
      "z": -6,
      "name": "Furniture_Tavern_Window",
      "rotation": 1
    },
    {
      "x": 3,
      "y": 16,
      "z": -6,
      "name": "Furniture_Tavern_Window",
      "rotation": 1
    },
    {
      "x": 3,
      "y": 17,
      "z": -6,
      "name": "Furniture_Tavern_Window",
      "rotation": 1
    },
    {
      "x": 3,
      "y": 18,
      "z": -6,
      "name": "Rock_Stone_Cobble"
    },
    {
      "x": 3,
      "y": 19,
      "z": -6,
      "name": "Wood_Beech_Trunk",
      "rotation": 4
    },
    {
      "x": 3,
      "y": 20,
      "z": -6,
      "name": "Wood_Burnt_Branch_Short",
      "support": 15,
      "rotation": 3
    },
    {
      "x": 3,
      "y": 22,
      "z": -6,
      "name": "Wood_Apple_Branch_Corner",
      "support": 15,
      "rotation": 2
    },
    {
      "x": 3,
      "y": 23,
      "z": -6,
      "name": "Wood_Apple_Branch_Long",
      "support": 15
    },
    {
      "x": 3,
      "y": 24,
      "z": -6,
      "name": "Wood_Burnt_Branch_Short",
      "support": 15,
      "rotation": 3
    },
    {
      "x": 3,
      "y": 25,
      "z": -6,
      "name": "Wood_Beech_Trunk",
      "rotation": 4
    },
    {
      "x": 3,
      "y": 26,
      "z": -6,
      "name": "Wood_Hardwood_Planks"
    },
    {
      "x": 3,
      "y": 27,
      "z": -6,
      "name": "Rock_Slate_Cobble_Stairs",
      "rotation": 3
    },
    {
      "x": 3,
      "y": 28,
      "z": -6,
      "name": "Rock_Basalt_Cobble_Roof_Steep",
      "rotation": 3
    },
    {
      "x": 3,
      "y": 29,
      "z": -6,
      "name": "Rock_Basalt_Cobble_Roof_Steep",
      "filler": 1024,
      "rotation": 3
    },
    {
      "x": 3,
      "y": 4,
      "z": -5,
      "name": "Rock_Calcite_Cobble_Stairs",
      "rotation": 8
    },
    {
      "x": 3,
      "y": 5,
      "z": -5,
      "name": "Rock_Stone"
    },
    {
      "x": 3,
      "y": 6,
      "z": -5,
      "name": "Rock_Stone_Cobble"
    },
    {
      "x": 3,
      "y": 10,
      "z": -5,
      "name": "Rock_Calcite_Cobble_Stairs",
      "rotation": 8
    },
    {
      "x": 3,
      "y": 11,
      "z": -5,
      "name": "Rock_Stone_Cobble"
    },
    {
      "x": 3,
      "y": 12,
      "z": -5,
      "name": "Rock_Stone"
    },
    {
      "x": 3,
      "y": 13,
      "z": -5,
      "name": "Rock_Stone"
    },
    {
      "x": 3,
      "y": 14,
      "z": -5,
      "name": "Rock_Calcite"
    },
    {
      "x": 3,
      "y": 15,
      "z": -5,
      "name": "Furniture_Tavern_Window",
      "rotation": 1
    },
    {
      "x": 3,
      "y": 16,
      "z": -5,
      "name": "Furniture_Tavern_Window",
      "rotation": 1
    },
    {
      "x": 3,
      "y": 17,
      "z": -5,
      "name": "Rock_Stone_Brick"
    },
    {
      "x": 3,
      "y": 18,
      "z": -5,
      "name": "Rock_Stone"
    },
    {
      "x": 3,
      "y": 19,
      "z": -5,
      "name": "Wood_Beech_Trunk",
      "rotation": 4
    },
    {
      "x": 3,
      "y": 20,
      "z": -5,
      "name": "Wood_Burnt_Branch_Short",
      "support": 15,
      "rotation": 3
    },
    {
      "x": 3,
      "y": 22,
      "z": -5,
      "name": "Wood_Apple_Branch_Long",
      "support": 15,
      "rotation": 4
    },
    {
      "x": 3,
      "y": 24,
      "z": -5,
      "name": "Wood_Burnt_Branch_Short",
      "support": 15,
      "rotation": 3
    },
    {
      "x": 3,
      "y": 25,
      "z": -5,
      "name": "Wood_Beech_Trunk",
      "rotation": 4
    },
    {
      "x": 3,
      "y": 26,
      "z": -5,
      "name": "Wood_Hardwood_Planks"
    },
    {
      "x": 3,
      "y": 27,
      "z": -5,
      "name": "Rock_Slate_Cobble_Stairs",
      "rotation": 3
    },
    {
      "x": 3,
      "y": 28,
      "z": -5,
      "name": "Rock_Basalt_Cobble_Roof_Steep",
      "rotation": 3
    },
    {
      "x": 3,
      "y": 29,
      "z": -5,
      "name": "Rock_Basalt_Cobble_Roof_Steep",
      "filler": 1024,
      "rotation": 3
    },
    {
      "x": 3,
      "y": 0,
      "z": -4,
      "name": "Rock_Calcite"
    },
    {
      "x": 3,
      "y": 1,
      "z": -4,
      "name": "Rock_Stone"
    },
    {
      "x": 3,
      "y": 2,
      "z": -4,
      "name": "Rock_Stone_Brick"
    },
    {
      "x": 3,
      "y": 3,
      "z": -4,
      "name": "Rock_Stone"
    },
    {
      "x": 3,
      "y": 4,
      "z": -4,
      "name": "Rock_Calcite"
    },
    {
      "x": 3,
      "y": 6,
      "z": -4,
      "name": "Rock_Calcite"
    },
    {
      "x": 3,
      "y": 7,
      "z": -4,
      "name": "Rock_Stone"
    },
    {
      "x": 3,
      "y": 8,
      "z": -4,
      "name": "Rock_Stone"
    },
    {
      "x": 3,
      "y": 9,
      "z": -4,
      "name": "Rock_Stone_Brick"
    },
    {
      "x": 3,
      "y": 10,
      "z": -4,
      "name": "Rock_Stone"
    },
    {
      "x": 3,
      "y": 11,
      "z": -4,
      "name": "Rock_Calcite"
    },
    {
      "x": 3,
      "y": 12,
      "z": -4,
      "name": "Rock_Stone"
    },
    {
      "x": 3,
      "y": 13,
      "z": -4,
      "name": "Rock_Stone"
    },
    {
      "x": 3,
      "y": 14,
      "z": -4,
      "name": "Rock_Stone_Brick"
    },
    {
      "x": 3,
      "y": 15,
      "z": -4,
      "name": "Rock_Stone"
    },
    {
      "x": 3,
      "y": 16,
      "z": -4,
      "name": "Rock_Stone"
    },
    {
      "x": 3,
      "y": 17,
      "z": -4,
      "name": "Rock_Stone"
    },
    {
      "x": 3,
      "y": 18,
      "z": -4,
      "name": "Rock_Stone"
    },
    {
      "x": 3,
      "y": 19,
      "z": -4,
      "name": "Wood_Beech_Trunk",
      "rotation": 4
    },
    {
      "x": 3,
      "y": 20,
      "z": -4,
      "name": "Wood_Hardwood_Stairs",
      "rotation": 2
    },
    {
      "x": 3,
      "y": 21,
      "z": -4,
      "name": "Wood_Burnt_Branch_Short",
      "support": 15,
      "rotation": 3
    },
    {
      "x": 3,
      "y": 22,
      "z": -4,
      "name": "Wood_Burnt_Branch_Short",
      "support": 15,
      "rotation": 3
    },
    {
      "x": 3,
      "y": 23,
      "z": -4,
      "name": "Wood_Burnt_Branch_Short",
      "support": 15,
      "rotation": 3
    },
    {
      "x": 3,
      "y": 24,
      "z": -4,
      "name": "Wood_Hardwood_Stairs",
      "rotation": 8
    },
    {
      "x": 3,
      "y": 25,
      "z": -4,
      "name": "Wood_Beech_Trunk",
      "rotation": 4
    },
    {
      "x": 3,
      "y": 26,
      "z": -4,
      "name": "Wood_Hardwood_Planks"
    },
    {
      "x": 3,
      "y": 27,
      "z": -4,
      "name": "Rock_Slate_Cobble_Stairs",
      "rotation": 3
    },
    {
      "x": 3,
      "y": 28,
      "z": -4,
      "name": "Rock_Basalt_Cobble_Roof_Steep",
      "rotation": 3
    },
    {
      "x": 3,
      "y": 29,
      "z": -4,
      "name": "Rock_Basalt_Cobble_Roof_Steep",
      "filler": 1024,
      "rotation": 3
    },
    {
      "x": 3,
      "y": 0,
      "z": -3,
      "name": "Rock_Stone"
    },
    {
      "x": 3,
      "y": 1,
      "z": -3,
      "name": "Rock_Stone_Brick"
    },
    {
      "x": 3,
      "y": 2,
      "z": -3,
      "name": "Rock_Stone_Brick"
    },
    {
      "x": 3,
      "y": 3,
      "z": -3,
      "name": "Rock_Stone_Cobble_Beam"
    },
    {
      "x": 3,
      "y": 4,
      "z": -3,
      "name": "Rock_Calcite"
    },
    {
      "x": 3,
      "y": 5,
      "z": -3,
      "name": "Rock_Stone"
    },
    {
      "x": 3,
      "y": 6,
      "z": -3,
      "name": "Rock_Stone_Brick"
    },
    {
      "x": 3,
      "y": 7,
      "z": -3,
      "name": "Rock_Stone_Brick_Pillar_Base"
    },
    {
      "x": 3,
      "y": 8,
      "z": -3,
      "name": "Rock_Stone_Brick_Pillar_Middle"
    },
    {
      "x": 3,
      "y": 9,
      "z": -3,
      "name": "Rock_Stone_Brick_Pillar_Middle"
    },
    {
      "x": 3,
      "y": 10,
      "z": -3,
      "name": "Rock_Stone_Brick_Pillar_Middle"
    },
    {
      "x": 3,
      "y": 11,
      "z": -3,
      "name": "Rock_Stone_Brick_Pillar_Base",
      "rotation": 8
    },
    {
      "x": 3,
      "y": 12,
      "z": -3,
      "name": "Rock_Stone_Brick"
    },
    {
      "x": 3,
      "y": 13,
      "z": -3,
      "name": "Rock_Stone_Brick_Pillar_Base"
    },
    {
      "x": 3,
      "y": 14,
      "z": -3,
      "name": "Rock_Stone_Brick_Pillar_Middle"
    },
    {
      "x": 3,
      "y": 15,
      "z": -3,
      "name": "Rock_Stone_Brick_Pillar_Middle"
    },
    {
      "x": 3,
      "y": 16,
      "z": -3,
      "name": "Rock_Stone_Brick_Pillar_Middle"
    },
    {
      "x": 3,
      "y": 17,
      "z": -3,
      "name": "Rock_Stone_Brick_Pillar_Base",
      "rotation": 8
    },
    {
      "x": 3,
      "y": 18,
      "z": -3,
      "name": "Rock_Stone"
    },
    {
      "x": 3,
      "y": 19,
      "z": -3,
      "name": "Wood_Beech_Trunk",
      "rotation": 2
    },
    {
      "x": 3,
      "y": 20,
      "z": -3,
      "name": "Wood_Beech_Trunk",
      "rotation": 2
    },
    {
      "x": 3,
      "y": 21,
      "z": -3,
      "name": "Wood_Beech_Trunk",
      "rotation": 2
    },
    {
      "x": 3,
      "y": 22,
      "z": -3,
      "name": "Wood_Beech_Trunk",
      "rotation": 2
    },
    {
      "x": 3,
      "y": 23,
      "z": -3,
      "name": "Wood_Beech_Trunk",
      "rotation": 2
    },
    {
      "x": 3,
      "y": 24,
      "z": -3,
      "name": "Wood_Beech_Trunk",
      "rotation": 2
    },
    {
      "x": 3,
      "y": 25,
      "z": -3,
      "name": "Wood_Beech_Trunk",
      "rotation": 2
    },
    {
      "x": 3,
      "y": 26,
      "z": -3,
      "name": "Wood_Hardwood_Planks"
    },
    {
      "x": 3,
      "y": 27,
      "z": -3,
      "name": "*Rock_Slate_Cobble_Stairs_State_Definitions_Corner_Right"
    },
    {
      "x": 3,
      "y": 28,
      "z": -3,
      "name": "Rock_Basalt_Cobble_Roof_Steep",
      "rotation": 3
    },
    {
      "x": 3,
      "y": 29,
      "z": -3,
      "name": "Rock_Basalt_Cobble_Roof_Steep",
      "filler": 1024,
      "rotation": 3
    },
    {
      "x": 3,
      "y": 6,
      "z": -2,
      "name": "Wood_Beech_Trunk",
      "support": 15,
      "rotation": 5
    },
    {
      "x": 3,
      "y": 18,
      "z": -2,
      "name": "Wood_Hardwood_Stairs",
      "rotation": 10
    },
    {
      "x": 3,
      "y": 19,
      "z": -2,
      "name": "Wood_Beech_Trunk",
      "support": 15,
      "rotation": 4
    },
    {
      "x": 3,
      "y": 25,
      "z": -2,
      "name": "Wood_Hardwood_Stairs",
      "rotation": 10
    },
    {
      "x": 3,
      "y": 27,
      "z": -2,
      "name": "Wood_Darkwood_Planks"
    },
    {
      "x": 3,
      "y": 28,
      "z": -2,
      "name": "Wood_Darkwood_Planks"
    },
    {
      "x": 3,
      "y": 29,
      "z": -2,
      "name": "Wood_Darkwood_Planks"
    },
    {
      "x": 3,
      "y": 30,
      "z": -2,
      "name": "Wood_Darkwood_Stairs",
      "rotation": 3
    },
    {
      "x": 3,
      "y": 6,
      "z": -1,
      "name": "Wood_Hardwood_Stairs",
      "rotation": 11
    },
    {
      "x": 4,
      "y": 6,
      "z": -11,
      "name": "Wood_Hardwood_Planks_Half",
      "rotation": 8
    },
    {
      "x": 4,
      "y": 6,
      "z": -10,
      "name": "Wood_Beech_Trunk",
      "support": 15,
      "rotation": 5
    },
    {
      "x": 4,
      "y": 19,
      "z": -10,
      "name": "Wood_Hardwood_Stairs",
      "rotation": 11
    },
    {
      "x": 4,
      "y": 25,
      "z": -10,
      "name": "Furniture_Crude_Trapdoor",
      "rotation": 2
    },
    {
      "x": 4,
      "y": 29,
      "z": -10,
      "name": "Wood_Darkwood_Stairs",
      "rotation": 11
    },
    {
      "x": 4,
      "y": 30,
      "z": -10,
      "name": "Wood_Darkwood_Planks"
    },
    {
      "x": 4,
      "y": 31,
      "z": -10,
      "name": "Wood_Darkwood_Stairs",
      "rotation": 3
    },
    {
      "x": 4,
      "y": 0,
      "z": -9,
      "name": "Rock_Stone"
    },
    {
      "x": 4,
      "y": 1,
      "z": -9,
      "name": "Rock_Stone"
    },
    {
      "x": 4,
      "y": 2,
      "z": -9,
      "name": "Rock_Stone"
    },
    {
      "x": 4,
      "y": 3,
      "z": -9,
      "name": "Rock_Stone"
    },
    {
      "x": 4,
      "y": 4,
      "z": -9,
      "name": "Rock_Stone_Cobble"
    },
    {
      "x": 4,
      "y": 5,
      "z": -9,
      "name": "Rock_Stone"
    },
    {
      "x": 4,
      "y": 6,
      "z": -9,
      "name": "Rock_Calcite"
    },
    {
      "x": 4,
      "y": 7,
      "z": -9,
      "name": "Rock_Stone_Brick"
    },
    {
      "x": 4,
      "y": 8,
      "z": -9,
      "name": "Rock_Calcite"
    },
    {
      "x": 4,
      "y": 9,
      "z": -9,
      "name": "Rock_Calcite"
    },
    {
      "x": 4,
      "y": 10,
      "z": -9,
      "name": "Rock_Stone"
    },
    {
      "x": 4,
      "y": 11,
      "z": -9,
      "name": "Rock_Stone"
    },
    {
      "x": 4,
      "y": 12,
      "z": -9,
      "name": "Rock_Stone"
    },
    {
      "x": 4,
      "y": 13,
      "z": -9,
      "name": "Rock_Stone"
    },
    {
      "x": 4,
      "y": 14,
      "z": -9,
      "name": "Rock_Stone_Cobble"
    },
    {
      "x": 4,
      "y": 15,
      "z": -9,
      "name": "Rock_Calcite"
    },
    {
      "x": 4,
      "y": 16,
      "z": -9,
      "name": "Rock_Stone"
    },
    {
      "x": 4,
      "y": 17,
      "z": -9,
      "name": "Rock_Stone"
    },
    {
      "x": 4,
      "y": 18,
      "z": -9,
      "name": "Rock_Stone"
    },
    {
      "x": 4,
      "y": 19,
      "z": -9,
      "name": "Wood_Beech_Trunk",
      "rotation": 5
    },
    {
      "x": 4,
      "y": 20,
      "z": -9,
      "name": "Wood_Hardwood_Stairs",
      "rotation": 1
    },
    {
      "x": 4,
      "y": 21,
      "z": -9,
      "name": "Wood_Burnt_Branch_Short",
      "support": 15,
      "rotation": 2
    },
    {
      "x": 4,
      "y": 22,
      "z": -9,
      "name": "Wood_Burnt_Branch_Short",
      "support": 15,
      "rotation": 2
    },
    {
      "x": 4,
      "y": 23,
      "z": -9,
      "name": "Wood_Burnt_Branch_Short",
      "support": 15,
      "rotation": 2
    },
    {
      "x": 4,
      "y": 24,
      "z": -9,
      "name": "Wood_Hardwood_Stairs",
      "rotation": 11
    },
    {
      "x": 4,
      "y": 25,
      "z": -9,
      "name": "Wood_Beech_Trunk",
      "rotation": 5
    },
    {
      "x": 4,
      "y": 26,
      "z": -9,
      "name": "Wood_Hardwood_Planks"
    },
    {
      "x": 4,
      "y": 27,
      "z": -9,
      "name": "Wood_Hardwood_Planks"
    },
    {
      "x": 4,
      "y": 28,
      "z": -9,
      "name": "Wood_Hardwood_Planks"
    },
    {
      "x": 4,
      "y": 29,
      "z": -9,
      "name": "Wood_Hardwood_Planks"
    },
    {
      "x": 4,
      "y": 30,
      "z": -9,
      "name": "Rock_Basalt_Cobble_Roof_Steep",
      "rotation": 3
    },
    {
      "x": 4,
      "y": 31,
      "z": -9,
      "name": "Rock_Basalt_Cobble_Roof_Steep",
      "filler": 1024,
      "rotation": 3
    },
    {
      "x": 4,
      "y": 20,
      "z": -8,
      "name": "Rock_Sandstone_Brick_Smooth"
    },
    {
      "x": 4,
      "y": 21,
      "z": -8,
      "name": "Rock_Sandstone_Brick_Smooth"
    },
    {
      "x": 4,
      "y": 22,
      "z": -8,
      "name": "Rock_Sandstone_Brick_Smooth"
    },
    {
      "x": 4,
      "y": 23,
      "z": -8,
      "name": "Rock_Sandstone_Brick_Smooth"
    },
    {
      "x": 4,
      "y": 24,
      "z": -8,
      "name": "Rock_Sandstone_Brick_Smooth"
    },
    {
      "x": 4,
      "y": 25,
      "z": -8,
      "name": "*Wood_Hardwood_Stairs_State_Definitions_Inverted_Corner_Left"
    },
    {
      "x": 4,
      "y": 27,
      "z": -8,
      "name": "*Wood_Hardwood_Stairs_State_Definitions_Inverted_Corner_Left",
      "rotation": 11
    },
    {
      "x": 4,
      "y": 30,
      "z": -8,
      "name": "Rock_Basalt_Cobble_Roof_Steep",
      "rotation": 3
    },
    {
      "x": 4,
      "y": 31,
      "z": -8,
      "name": "Rock_Basalt_Cobble_Roof_Steep",
      "filler": 1024,
      "rotation": 3
    },
    {
      "x": 4,
      "y": 20,
      "z": -7,
      "name": "Rock_Sandstone_Brick_Smooth"
    },
    {
      "x": 4,
      "y": 21,
      "z": -7,
      "name": "Rock_Sandstone_Brick_Smooth"
    },
    {
      "x": 4,
      "y": 22,
      "z": -7,
      "name": "Rock_Sandstone_Brick_Smooth"
    },
    {
      "x": 4,
      "y": 23,
      "z": -7,
      "name": "Rock_Sandstone_Brick_Smooth"
    },
    {
      "x": 4,
      "y": 24,
      "z": -7,
      "name": "Rock_Sandstone_Brick_Smooth"
    },
    {
      "x": 4,
      "y": 25,
      "z": -7,
      "name": "Wood_Hardwood_Stairs",
      "rotation": 1
    },
    {
      "x": 4,
      "y": 27,
      "z": -7,
      "name": "Wood_Hardwood_Stairs",
      "rotation": 11
    },
    {
      "x": 4,
      "y": 30,
      "z": -7,
      "name": "Rock_Basalt_Cobble_Roof_Steep",
      "rotation": 3
    },
    {
      "x": 4,
      "y": 31,
      "z": -7,
      "name": "Rock_Basalt_Cobble_Roof_Steep",
      "filler": 1024,
      "rotation": 3
    },
    {
      "x": 4,
      "y": 20,
      "z": -6,
      "name": "Rock_Sandstone_Brick_Smooth"
    },
    {
      "x": 4,
      "y": 21,
      "z": -6,
      "name": "Rock_Sandstone_Brick_Smooth"
    },
    {
      "x": 4,
      "y": 22,
      "z": -6,
      "name": "Rock_Sandstone_Brick_Stairs"
    },
    {
      "x": 4,
      "y": 23,
      "z": -6,
      "name": "Rock_Sandstone_Brick_Smooth"
    },
    {
      "x": 4,
      "y": 24,
      "z": -6,
      "name": "Rock_Sandstone_Brick_Smooth"
    },
    {
      "x": 4,
      "y": 25,
      "z": -6,
      "name": "Wood_Hardwood_Stairs",
      "rotation": 1
    },
    {
      "x": 4,
      "y": 27,
      "z": -6,
      "name": "Wood_Hardwood_Stairs",
      "rotation": 11
    },
    {
      "x": 4,
      "y": 30,
      "z": -6,
      "name": "Rock_Basalt_Cobble_Roof_Steep",
      "rotation": 3
    },
    {
      "x": 4,
      "y": 31,
      "z": -6,
      "name": "Rock_Basalt_Cobble_Roof_Steep",
      "filler": 1024,
      "rotation": 3
    },
    {
      "x": 4,
      "y": 20,
      "z": -5,
      "name": "Rock_Sandstone_Brick_Smooth"
    },
    {
      "x": 4,
      "y": 21,
      "z": -5,
      "name": "Rock_Sandstone_Brick_Smooth"
    },
    {
      "x": 4,
      "y": 22,
      "z": -5,
      "name": "Rock_Sandstone_Brick_Smooth"
    },
    {
      "x": 4,
      "y": 23,
      "z": -5,
      "name": "Rock_Sandstone_Brick_Smooth"
    },
    {
      "x": 4,
      "y": 24,
      "z": -5,
      "name": "Rock_Sandstone_Brick_Smooth"
    },
    {
      "x": 4,
      "y": 25,
      "z": -5,
      "name": "Wood_Hardwood_Stairs",
      "rotation": 1
    },
    {
      "x": 4,
      "y": 27,
      "z": -5,
      "name": "Wood_Hardwood_Stairs",
      "rotation": 11
    },
    {
      "x": 4,
      "y": 30,
      "z": -5,
      "name": "Rock_Basalt_Cobble_Roof_Steep",
      "rotation": 3
    },
    {
      "x": 4,
      "y": 31,
      "z": -5,
      "name": "Rock_Basalt_Cobble_Roof_Steep",
      "filler": 1024,
      "rotation": 3
    },
    {
      "x": 4,
      "y": 5,
      "z": -4,
      "name": "Rock_Stone_Brick"
    },
    {
      "x": 4,
      "y": 20,
      "z": -4,
      "name": "Rock_Sandstone_Brick_Smooth"
    },
    {
      "x": 4,
      "y": 21,
      "z": -4,
      "name": "Rock_Sandstone_Brick_Smooth"
    },
    {
      "x": 4,
      "y": 22,
      "z": -4,
      "name": "Rock_Sandstone_Brick_Smooth"
    },
    {
      "x": 4,
      "y": 23,
      "z": -4,
      "name": "Rock_Sandstone_Brick_Smooth"
    },
    {
      "x": 4,
      "y": 24,
      "z": -4,
      "name": "Rock_Sandstone_Brick_Smooth"
    },
    {
      "x": 4,
      "y": 25,
      "z": -4,
      "name": "*Wood_Hardwood_Stairs_State_Definitions_Inverted_Corner_Right",
      "rotation": 2
    },
    {
      "x": 4,
      "y": 27,
      "z": -4,
      "name": "*Wood_Hardwood_Stairs_State_Definitions_Inverted_Corner_Left",
      "rotation": 8
    },
    {
      "x": 4,
      "y": 30,
      "z": -4,
      "name": "Rock_Basalt_Cobble_Roof_Steep",
      "rotation": 3
    },
    {
      "x": 4,
      "y": 31,
      "z": -4,
      "name": "Rock_Basalt_Cobble_Roof_Steep",
      "filler": 1024,
      "rotation": 3
    },
    {
      "x": 4,
      "y": 0,
      "z": -3,
      "name": "Rock_Stone_Brick"
    },
    {
      "x": 4,
      "y": 1,
      "z": -3,
      "name": "Rock_Stone"
    },
    {
      "x": 4,
      "y": 2,
      "z": -3,
      "name": "Rock_Calcite"
    },
    {
      "x": 4,
      "y": 3,
      "z": -3,
      "name": "Rock_Calcite"
    },
    {
      "x": 4,
      "y": 4,
      "z": -3,
      "name": "Rock_Stone_Brick"
    },
    {
      "x": 4,
      "y": 5,
      "z": -3,
      "name": "Rock_Stone_Brick"
    },
    {
      "x": 4,
      "y": 6,
      "z": -3,
      "name": "Rock_Calcite"
    },
    {
      "x": 4,
      "y": 7,
      "z": -3,
      "name": "Rock_Stone_Cobble"
    },
    {
      "x": 4,
      "y": 8,
      "z": -3,
      "name": "Rock_Stone"
    },
    {
      "x": 4,
      "y": 9,
      "z": -3,
      "name": "Rock_Stone_Brick"
    },
    {
      "x": 4,
      "y": 10,
      "z": -3,
      "name": "Rock_Stone_Brick"
    },
    {
      "x": 4,
      "y": 11,
      "z": -3,
      "name": "Rock_Stone"
    },
    {
      "x": 4,
      "y": 12,
      "z": -3,
      "name": "Rock_Stone_Brick"
    },
    {
      "x": 4,
      "y": 13,
      "z": -3,
      "name": "Rock_Stone_Cobble"
    },
    {
      "x": 4,
      "y": 14,
      "z": -3,
      "name": "Rock_Stone_Brick"
    },
    {
      "x": 4,
      "y": 15,
      "z": -3,
      "name": "Rock_Calcite"
    },
    {
      "x": 4,
      "y": 16,
      "z": -3,
      "name": "Rock_Stone"
    },
    {
      "x": 4,
      "y": 17,
      "z": -3,
      "name": "Rock_Stone"
    },
    {
      "x": 4,
      "y": 18,
      "z": -3,
      "name": "Rock_Stone_Cobble"
    },
    {
      "x": 4,
      "y": 19,
      "z": -3,
      "name": "Wood_Beech_Trunk",
      "rotation": 5
    },
    {
      "x": 4,
      "y": 20,
      "z": -3,
      "name": "Wood_Hardwood_Stairs",
      "rotation": 1
    },
    {
      "x": 4,
      "y": 21,
      "z": -3,
      "name": "Wood_Burnt_Branch_Short",
      "support": 15
    },
    {
      "x": 4,
      "y": 22,
      "z": -3,
      "name": "Wood_Burnt_Branch_Short",
      "support": 15
    },
    {
      "x": 4,
      "y": 23,
      "z": -3,
      "name": "Wood_Burnt_Branch_Short",
      "support": 15
    },
    {
      "x": 4,
      "y": 24,
      "z": -3,
      "name": "Wood_Hardwood_Stairs",
      "rotation": 11
    },
    {
      "x": 4,
      "y": 25,
      "z": -3,
      "name": "Wood_Beech_Trunk",
      "rotation": 5
    },
    {
      "x": 4,
      "y": 26,
      "z": -3,
      "name": "Wood_Hardwood_Planks"
    },
    {
      "x": 4,
      "y": 27,
      "z": -3,
      "name": "Wood_Hardwood_Planks"
    },
    {
      "x": 4,
      "y": 28,
      "z": -3,
      "name": "Wood_Hardwood_Planks"
    },
    {
      "x": 4,
      "y": 29,
      "z": -3,
      "name": "Wood_Hardwood_Planks"
    },
    {
      "x": 4,
      "y": 30,
      "z": -3,
      "name": "Rock_Basalt_Cobble_Roof_Steep",
      "rotation": 3
    },
    {
      "x": 4,
      "y": 31,
      "z": -3,
      "name": "Rock_Basalt_Cobble_Roof_Steep",
      "filler": 1024,
      "rotation": 3
    },
    {
      "x": 4,
      "y": 6,
      "z": -2,
      "name": "Wood_Beech_Trunk",
      "support": 15,
      "rotation": 5
    },
    {
      "x": 4,
      "y": 19,
      "z": -2,
      "name": "Wood_Hardwood_Stairs",
      "rotation": 11
    },
    {
      "x": 4,
      "y": 25,
      "z": -2,
      "name": "Furniture_Crude_Trapdoor"
    },
    {
      "x": 4,
      "y": 29,
      "z": -2,
      "name": "Wood_Darkwood_Stairs",
      "rotation": 11
    },
    {
      "x": 4,
      "y": 30,
      "z": -2,
      "name": "Wood_Darkwood_Planks"
    },
    {
      "x": 4,
      "y": 31,
      "z": -2,
      "name": "Wood_Darkwood_Stairs",
      "rotation": 3
    },
    {
      "x": 4,
      "y": 6,
      "z": -1,
      "name": "Wood_Hardwood_Planks_Half",
      "rotation": 8
    },
    {
      "x": 5,
      "y": 6,
      "z": -10,
      "name": "Wood_Beech_Trunk",
      "support": 15,
      "rotation": 5
    },
    {
      "x": 5,
      "y": 25,
      "z": -10,
      "name": "Wood_Hardwood_Stairs",
      "rotation": 8
    },
    {
      "x": 5,
      "y": 30,
      "z": -10,
      "name": "Wood_Darkwood_Stairs",
      "rotation": 11
    },
    {
      "x": 5,
      "y": 31,
      "z": -10,
      "name": "Wood_Darkwood_Planks"
    },
    {
      "x": 5,
      "y": 32,
      "z": -10,
      "name": "Wood_Darkwood_Planks"
    },
    {
      "x": 5,
      "y": 33,
      "z": -10,
      "name": "Wood_Darkwood_Stairs",
      "rotation": 3
    },
    {
      "x": 5,
      "y": 4,
      "z": -9,
      "name": "Rock_Calcite_Cobble_Stairs",
      "rotation": 11
    },
    {
      "x": 5,
      "y": 5,
      "z": -9,
      "name": "Rock_Stone"
    },
    {
      "x": 5,
      "y": 6,
      "z": -9,
      "name": "Rock_Calcite"
    },
    {
      "x": 5,
      "y": 10,
      "z": -9,
      "name": "Rock_Calcite_Cobble_Stairs",
      "rotation": 11
    },
    {
      "x": 5,
      "y": 11,
      "z": -9,
      "name": "Rock_Stone"
    },
    {
      "x": 5,
      "y": 12,
      "z": -9,
      "name": "Rock_Stone_Brick"
    },
    {
      "x": 5,
      "y": 13,
      "z": -9,
      "name": "Rock_Calcite"
    },
    {
      "x": 5,
      "y": 14,
      "z": -9,
      "name": "Rock_Stone_Brick"
    },
    {
      "x": 5,
      "y": 15,
      "z": -9,
      "name": "Furniture_Tavern_Window"
    },
    {
      "x": 5,
      "y": 16,
      "z": -9,
      "name": "Furniture_Tavern_Window"
    },
    {
      "x": 5,
      "y": 17,
      "z": -9,
      "name": "Rock_Stone"
    },
    {
      "x": 5,
      "y": 18,
      "z": -9,
      "name": "Rock_Calcite"
    },
    {
      "x": 5,
      "y": 19,
      "z": -9,
      "name": "Wood_Beech_Trunk",
      "rotation": 5
    },
    {
      "x": 5,
      "y": 20,
      "z": -9,
      "name": "Wood_Burnt_Branch_Short",
      "support": 15,
      "rotation": 2
    },
    {
      "x": 5,
      "y": 22,
      "z": -9,
      "name": "Wood_Apple_Branch_Long",
      "support": 15,
      "rotation": 5
    },
    {
      "x": 5,
      "y": 24,
      "z": -9,
      "name": "Wood_Burnt_Branch_Short",
      "support": 15,
      "rotation": 2
    },
    {
      "x": 5,
      "y": 25,
      "z": -9,
      "name": "Wood_Beech_Trunk",
      "rotation": 5
    },
    {
      "x": 5,
      "y": 26,
      "z": -9,
      "name": "Wood_Hardwood_Planks"
    },
    {
      "x": 5,
      "y": 27,
      "z": -9,
      "name": "Wood_Hardwood_Planks"
    },
    {
      "x": 5,
      "y": 28,
      "z": -9,
      "name": "Furniture_Tavern_Window"
    },
    {
      "x": 5,
      "y": 29,
      "z": -9,
      "name": "Wood_Hardwood_Planks"
    },
    {
      "x": 5,
      "y": 30,
      "z": -9,
      "name": "Wood_Hardwood_Planks"
    },
    {
      "x": 5,
      "y": 32,
      "z": -9,
      "name": "Rock_Basalt_Cobble_Roof_Steep",
      "rotation": 3
    },
    {
      "x": 5,
      "y": 33,
      "z": -9,
      "name": "Rock_Basalt_Cobble_Roof_Steep",
      "filler": 1024,
      "rotation": 3
    },
    {
      "x": 5,
      "y": 20,
      "z": -8,
      "name": "Rock_Sandstone_Brick_Smooth"
    },
    {
      "x": 5,
      "y": 21,
      "z": -8,
      "name": "Rock_Sandstone_Brick_Smooth"
    },
    {
      "x": 5,
      "y": 22,
      "z": -8,
      "name": "Rock_Sandstone_Brick_Smooth"
    },
    {
      "x": 5,
      "y": 23,
      "z": -8,
      "name": "Rock_Sandstone_Brick_Smooth"
    },
    {
      "x": 5,
      "y": 24,
      "z": -8,
      "name": "Rock_Sandstone_Brick_Smooth"
    },
    {
      "x": 5,
      "y": 25,
      "z": -8,
      "name": "Wood_Hardwood_Stairs"
    },
    {
      "x": 5,
      "y": 27,
      "z": -8,
      "name": "Wood_Hardwood_Stairs",
      "rotation": 10
    },
    {
      "x": 5,
      "y": 32,
      "z": -8,
      "name": "Rock_Basalt_Cobble_Roof_Steep",
      "rotation": 3
    },
    {
      "x": 5,
      "y": 33,
      "z": -8,
      "name": "Rock_Basalt_Cobble_Roof_Steep",
      "filler": 1024,
      "rotation": 3
    },
    {
      "x": 5,
      "y": 3,
      "z": -7,
      "name": "Wood_Hardwood_Planks_Half",
      "rotation": 8
    },
    {
      "x": 5,
      "y": 7,
      "z": -7,
      "name": "Wood_Hardwood_Planks_Half",
      "rotation": 8
    },
    {
      "x": 5,
      "y": 11,
      "z": -7,
      "name": "Wood_Hardwood_Planks_Half",
      "rotation": 8
    },
    {
      "x": 5,
      "y": 15,
      "z": -7,
      "name": "Wood_Hardwood_Planks_Half",
      "rotation": 8
    },
    {
      "x": 5,
      "y": 19,
      "z": -7,
      "name": "Wood_Hardwood_Planks_Half",
      "rotation": 8
    },
    {
      "x": 5,
      "y": 23,
      "z": -7,
      "name": "Wood_Hardwood_Planks_Half",
      "rotation": 8
    },
    {
      "x": 5,
      "y": 27,
      "z": -7,
      "name": "Wood_Hardwood_Planks_Half",
      "rotation": 8
    },
    {
      "x": 5,
      "y": 32,
      "z": -7,
      "name": "Rock_Basalt_Cobble_Roof_Steep",
      "rotation": 3
    },
    {
      "x": 5,
      "y": 33,
      "z": -7,
      "name": "Rock_Basalt_Cobble_Roof_Steep",
      "filler": 1024,
      "rotation": 3
    },
    {
      "x": 5,
      "y": 0,
      "z": -6,
      "name": "Wood_Hardwood_Planks_Half"
    },
    {
      "x": 5,
      "y": 2,
      "z": -6,
      "name": "Wood_Torch_Wall",
      "rotation": 3
    },
    {
      "x": 5,
      "y": 4,
      "z": -6,
      "name": "Wood_Hardwood_Planks_Half"
    },
    {
      "x": 5,
      "y": 6,
      "z": -6,
      "name": "Wood_Torch_Wall",
      "rotation": 3
    },
    {
      "x": 5,
      "y": 8,
      "z": -6,
      "name": "Wood_Hardwood_Planks_Half"
    },
    {
      "x": 5,
      "y": 10,
      "z": -6,
      "name": "Wood_Torch_Wall",
      "rotation": 3
    },
    {
      "x": 5,
      "y": 12,
      "z": -6,
      "name": "Wood_Hardwood_Planks_Half"
    },
    {
      "x": 5,
      "y": 14,
      "z": -6,
      "name": "Wood_Torch_Wall",
      "rotation": 3
    },
    {
      "x": 5,
      "y": 16,
      "z": -6,
      "name": "Wood_Hardwood_Planks_Half"
    },
    {
      "x": 5,
      "y": 20,
      "z": -6,
      "name": "Wood_Hardwood_Planks_Half"
    },
    {
      "x": 5,
      "y": 24,
      "z": -6,
      "name": "Wood_Hardwood_Planks_Half"
    },
    {
      "x": 5,
      "y": 27,
      "z": -6,
      "name": "Wood_Hardwood_Planks_Half",
      "rotation": 8
    },
    {
      "x": 5,
      "y": 32,
      "z": -6,
      "name": "Rock_Basalt_Cobble_Roof_Steep",
      "rotation": 3
    },
    {
      "x": 5,
      "y": 33,
      "z": -6,
      "name": "Rock_Basalt_Cobble_Roof_Steep",
      "filler": 1024,
      "rotation": 3
    },
    {
      "x": 5,
      "y": 0,
      "z": -5,
      "name": "Wood_Hardwood_Planks_Half",
      "rotation": 8
    },
    {
      "x": 5,
      "y": 4,
      "z": -5,
      "name": "Wood_Hardwood_Planks_Half",
      "rotation": 8
    },
    {
      "x": 5,
      "y": 8,
      "z": -5,
      "name": "Wood_Hardwood_Planks_Half",
      "rotation": 8
    },
    {
      "x": 5,
      "y": 12,
      "z": -5,
      "name": "Wood_Hardwood_Planks_Half",
      "rotation": 8
    },
    {
      "x": 5,
      "y": 16,
      "z": -5,
      "name": "Wood_Hardwood_Planks_Half",
      "rotation": 8
    },
    {
      "x": 5,
      "y": 20,
      "z": -5,
      "name": "Wood_Hardwood_Planks_Half",
      "rotation": 8
    },
    {
      "x": 5,
      "y": 24,
      "z": -5,
      "name": "Wood_Hardwood_Planks_Half",
      "rotation": 8
    },
    {
      "x": 5,
      "y": 27,
      "z": -5,
      "name": "Wood_Hardwood_Planks_Half",
      "rotation": 8
    },
    {
      "x": 5,
      "y": 32,
      "z": -5,
      "name": "Rock_Basalt_Cobble_Roof_Steep",
      "rotation": 3
    },
    {
      "x": 5,
      "y": 33,
      "z": -5,
      "name": "Rock_Basalt_Cobble_Roof_Steep",
      "filler": 1024,
      "rotation": 3
    },
    {
      "x": 5,
      "y": 20,
      "z": -4,
      "name": "Rock_Sandstone_Brick_Smooth"
    },
    {
      "x": 5,
      "y": 21,
      "z": -4,
      "name": "Rock_Sandstone_Brick_Smooth"
    },
    {
      "x": 5,
      "y": 22,
      "z": -4,
      "name": "Rock_Sandstone_Brick_Smooth"
    },
    {
      "x": 5,
      "y": 23,
      "z": -4,
      "name": "Rock_Sandstone_Brick_Smooth"
    },
    {
      "x": 5,
      "y": 24,
      "z": -4,
      "name": "Rock_Sandstone_Brick_Smooth"
    },
    {
      "x": 5,
      "y": 25,
      "z": -4,
      "name": "Wood_Hardwood_Stairs",
      "rotation": 2
    },
    {
      "x": 5,
      "y": 27,
      "z": -4,
      "name": "Wood_Hardwood_Stairs",
      "rotation": 8
    },
    {
      "x": 5,
      "y": 32,
      "z": -4,
      "name": "Rock_Basalt_Cobble_Roof_Steep",
      "rotation": 3
    },
    {
      "x": 5,
      "y": 33,
      "z": -4,
      "name": "Rock_Basalt_Cobble_Roof_Steep",
      "filler": 1024,
      "rotation": 3
    },
    {
      "x": 5,
      "y": 4,
      "z": -3,
      "name": "Rock_Calcite_Cobble_Stairs",
      "rotation": 11
    },
    {
      "x": 5,
      "y": 5,
      "z": -3,
      "name": "Rock_Calcite"
    },
    {
      "x": 5,
      "y": 6,
      "z": -3,
      "name": "Rock_Stone"
    },
    {
      "x": 5,
      "y": 10,
      "z": -3,
      "name": "Rock_Calcite_Cobble_Stairs",
      "rotation": 11
    },
    {
      "x": 5,
      "y": 11,
      "z": -3,
      "name": "Rock_Stone"
    },
    {
      "x": 5,
      "y": 12,
      "z": -3,
      "name": "Rock_Stone_Cobble"
    },
    {
      "x": 5,
      "y": 13,
      "z": -3,
      "name": "Rock_Stone"
    },
    {
      "x": 5,
      "y": 14,
      "z": -3,
      "name": "Rock_Stone_Brick"
    },
    {
      "x": 5,
      "y": 15,
      "z": -3,
      "name": "Furniture_Tavern_Window"
    },
    {
      "x": 5,
      "y": 16,
      "z": -3,
      "name": "Furniture_Tavern_Window"
    },
    {
      "x": 5,
      "y": 17,
      "z": -3,
      "name": "Rock_Stone"
    },
    {
      "x": 5,
      "y": 18,
      "z": -3,
      "name": "Rock_Stone"
    },
    {
      "x": 5,
      "y": 19,
      "z": -3,
      "name": "Wood_Beech_Trunk",
      "rotation": 5
    },
    {
      "x": 5,
      "y": 20,
      "z": -3,
      "name": "Wood_Burnt_Branch_Short",
      "support": 15
    },
    {
      "x": 5,
      "y": 24,
      "z": -3,
      "name": "Wood_Burnt_Branch_Short",
      "support": 15
    },
    {
      "x": 5,
      "y": 25,
      "z": -3,
      "name": "Wood_Beech_Trunk",
      "rotation": 5
    },
    {
      "x": 5,
      "y": 26,
      "z": -3,
      "name": "Wood_Hardwood_Planks"
    },
    {
      "x": 5,
      "y": 27,
      "z": -3,
      "name": "Wood_Hardwood_Planks"
    },
    {
      "x": 5,
      "y": 28,
      "z": -3,
      "name": "Furniture_Tavern_Window"
    },
    {
      "x": 5,
      "y": 29,
      "z": -3,
      "name": "Wood_Hardwood_Planks"
    },
    {
      "x": 5,
      "y": 30,
      "z": -3,
      "name": "Wood_Hardwood_Planks"
    },
    {
      "x": 5,
      "y": 32,
      "z": -3,
      "name": "Rock_Basalt_Cobble_Roof_Steep",
      "rotation": 3
    },
    {
      "x": 5,
      "y": 33,
      "z": -3,
      "name": "Rock_Basalt_Cobble_Roof_Steep",
      "filler": 1024,
      "rotation": 3
    },
    {
      "x": 5,
      "y": 6,
      "z": -2,
      "name": "Wood_Beech_Trunk",
      "support": 15,
      "rotation": 5
    },
    {
      "x": 5,
      "y": 25,
      "z": -2,
      "name": "Wood_Hardwood_Stairs",
      "rotation": 10
    },
    {
      "x": 5,
      "y": 30,
      "z": -2,
      "name": "Wood_Darkwood_Stairs",
      "rotation": 11
    },
    {
      "x": 5,
      "y": 31,
      "z": -2,
      "name": "Wood_Darkwood_Planks"
    },
    {
      "x": 5,
      "y": 32,
      "z": -2,
      "name": "Wood_Darkwood_Planks"
    },
    {
      "x": 5,
      "y": 33,
      "z": -2,
      "name": "Wood_Darkwood_Stairs",
      "rotation": 3
    },
    {
      "x": 6,
      "y": 34,
      "z": -11,
      "name": "Wood_Darkwood_Stairs",
      "rotation": 8
    },
    {
      "x": 6,
      "y": 6,
      "z": -10,
      "name": "Wood_Beech_Trunk",
      "support": 15,
      "rotation": 5
    },
    {
      "x": 6,
      "y": 19,
      "z": -10,
      "name": "Wood_Hardwood_Stairs",
      "rotation": 8
    },
    {
      "x": 6,
      "y": 25,
      "z": -10,
      "name": "Furniture_Crude_Trapdoor",
      "rotation": 2
    },
    {
      "x": 6,
      "y": 33,
      "z": -10,
      "name": "Wood_Darkwood_Planks"
    },
    {
      "x": 6,
      "y": 34,
      "z": -10,
      "name": "Wood_Darkwood_Planks"
    },
    {
      "x": 6,
      "y": 5,
      "z": -9,
      "name": "Rock_Calcite"
    },
    {
      "x": 6,
      "y": 6,
      "z": -9,
      "name": "Rock_Calcite"
    },
    {
      "x": 6,
      "y": 10,
      "z": -9,
      "name": "Rock_Calcite"
    },
    {
      "x": 6,
      "y": 11,
      "z": -9,
      "name": "Rock_Stone"
    },
    {
      "x": 6,
      "y": 12,
      "z": -9,
      "name": "Rock_Calcite"
    },
    {
      "x": 6,
      "y": 13,
      "z": -9,
      "name": "Rock_Calcite"
    },
    {
      "x": 6,
      "y": 14,
      "z": -9,
      "name": "Furniture_Tavern_Window"
    },
    {
      "x": 6,
      "y": 15,
      "z": -9,
      "name": "Furniture_Tavern_Window"
    },
    {
      "x": 6,
      "y": 16,
      "z": -9,
      "name": "Furniture_Tavern_Window"
    },
    {
      "x": 6,
      "y": 17,
      "z": -9,
      "name": "Furniture_Tavern_Window"
    },
    {
      "x": 6,
      "y": 18,
      "z": -9,
      "name": "Rock_Stone"
    },
    {
      "x": 6,
      "y": 19,
      "z": -9,
      "name": "Wood_Beech_Trunk",
      "rotation": 5
    },
    {
      "x": 6,
      "y": 20,
      "z": -9,
      "name": "Wood_Burnt_Branch_Short",
      "support": 15,
      "rotation": 2
    },
    {
      "x": 6,
      "y": 22,
      "z": -9,
      "name": "Wood_Apple_Branch_Corner",
      "support": 15,
      "rotation": 1
    },
    {
      "x": 6,
      "y": 23,
      "z": -9,
      "name": "Wood_Apple_Branch_Long",
      "support": 15
    },
    {
      "x": 6,
      "y": 24,
      "z": -9,
      "name": "Wood_Burnt_Branch_Short",
      "support": 15,
      "rotation": 2
    },
    {
      "x": 6,
      "y": 25,
      "z": -9,
      "name": "Wood_Beech_Trunk",
      "rotation": 5
    },
    {
      "x": 6,
      "y": 26,
      "z": -9,
      "name": "Wood_Hardwood_Planks"
    },
    {
      "x": 6,
      "y": 27,
      "z": -9,
      "name": "Furniture_Tavern_Window"
    },
    {
      "x": 6,
      "y": 28,
      "z": -9,
      "name": "Furniture_Tavern_Window"
    },
    {
      "x": 6,
      "y": 29,
      "z": -9,
      "name": "Furniture_Tavern_Window"
    },
    {
      "x": 6,
      "y": 30,
      "z": -9,
      "name": "Wood_Hardwood_Planks"
    },
    {
      "x": 6,
      "y": 31,
      "z": -9,
      "name": "Wood_Hardwood_Planks"
    },
    {
      "x": 6,
      "y": 32,
      "z": -9,
      "name": "Wood_Hardwood_Planks"
    },
    {
      "x": 6,
      "y": 33,
      "z": -9,
      "name": "Wood_Hardwood_Planks"
    },
    {
      "x": 6,
      "y": 34,
      "z": -9,
      "name": "Wood_Darkwood_Stairs"
    },
    {
      "x": 6,
      "y": 20,
      "z": -8,
      "name": "Rock_Sandstone_Brick_Smooth"
    },
    {
      "x": 6,
      "y": 21,
      "z": -8,
      "name": "Rock_Sandstone_Brick_Smooth"
    },
    {
      "x": 6,
      "y": 22,
      "z": -8,
      "name": "Rock_Sandstone_Brick_Stairs",
      "rotation": 3
    },
    {
      "x": 6,
      "y": 23,
      "z": -8,
      "name": "Rock_Sandstone_Brick_Smooth"
    },
    {
      "x": 6,
      "y": 24,
      "z": -8,
      "name": "Rock_Sandstone_Brick_Smooth"
    },
    {
      "x": 6,
      "y": 25,
      "z": -8,
      "name": "Wood_Hardwood_Stairs"
    },
    {
      "x": 6,
      "y": 27,
      "z": -8,
      "name": "Wood_Hardwood_Stairs",
      "rotation": 10
    },
    {
      "x": 6,
      "y": 33,
      "z": -8,
      "name": "Wood_Darkwood_Planks"
    },
    {
      "x": 6,
      "y": 3,
      "z": -7,
      "name": "Wood_Hardwood_Planks_Half"
    },
    {
      "x": 6,
      "y": 7,
      "z": -7,
      "name": "Wood_Hardwood_Planks_Half"
    },
    {
      "x": 6,
      "y": 11,
      "z": -7,
      "name": "Wood_Hardwood_Planks_Half"
    },
    {
      "x": 6,
      "y": 15,
      "z": -7,
      "name": "Wood_Hardwood_Planks_Half"
    },
    {
      "x": 6,
      "y": 19,
      "z": -7,
      "name": "Wood_Hardwood_Planks_Half"
    },
    {
      "x": 6,
      "y": 23,
      "z": -7,
      "name": "Wood_Hardwood_Planks_Half"
    },
    {
      "x": 6,
      "y": 27,
      "z": -7,
      "name": "Wood_Hardwood_Planks_Half",
      "rotation": 8
    },
    {
      "x": 6,
      "y": 33,
      "z": -7,
      "name": "Wood_Darkwood_Planks"
    },
    {
      "x": 6,
      "y": 0,
      "z": -6,
      "name": "Wood_Beech_Trunk",
      "rotation": 2
    },
    {
      "x": 6,
      "y": 1,
      "z": -6,
      "name": "Wood_Beech_Trunk",
      "rotation": 2
    },
    {
      "x": 6,
      "y": 2,
      "z": -6,
      "name": "Wood_Beech_Trunk",
      "rotation": 2
    },
    {
      "x": 6,
      "y": 3,
      "z": -6,
      "name": "Wood_Beech_Trunk",
      "rotation": 2
    },
    {
      "x": 6,
      "y": 4,
      "z": -6,
      "name": "Wood_Beech_Trunk",
      "rotation": 2
    },
    {
      "x": 6,
      "y": 5,
      "z": -6,
      "name": "Wood_Beech_Trunk",
      "rotation": 2
    },
    {
      "x": 6,
      "y": 6,
      "z": -6,
      "name": "Wood_Beech_Trunk",
      "rotation": 2
    },
    {
      "x": 6,
      "y": 7,
      "z": -6,
      "name": "Wood_Beech_Trunk",
      "rotation": 2
    },
    {
      "x": 6,
      "y": 8,
      "z": -6,
      "name": "Wood_Beech_Trunk",
      "rotation": 2
    },
    {
      "x": 6,
      "y": 9,
      "z": -6,
      "name": "Wood_Beech_Trunk",
      "rotation": 2
    },
    {
      "x": 6,
      "y": 10,
      "z": -6,
      "name": "Wood_Beech_Trunk",
      "rotation": 2
    },
    {
      "x": 6,
      "y": 11,
      "z": -6,
      "name": "Wood_Beech_Trunk",
      "rotation": 2
    },
    {
      "x": 6,
      "y": 12,
      "z": -6,
      "name": "Wood_Beech_Trunk",
      "rotation": 2
    },
    {
      "x": 6,
      "y": 13,
      "z": -6,
      "name": "Wood_Beech_Trunk",
      "rotation": 2
    },
    {
      "x": 6,
      "y": 14,
      "z": -6,
      "name": "Wood_Beech_Trunk",
      "rotation": 2
    },
    {
      "x": 6,
      "y": 15,
      "z": -6,
      "name": "Wood_Beech_Trunk",
      "rotation": 2
    },
    {
      "x": 6,
      "y": 16,
      "z": -6,
      "name": "Wood_Beech_Trunk",
      "rotation": 2
    },
    {
      "x": 6,
      "y": 17,
      "z": -6,
      "name": "Wood_Beech_Trunk",
      "rotation": 2
    },
    {
      "x": 6,
      "y": 18,
      "z": -6,
      "name": "Wood_Beech_Trunk",
      "rotation": 2
    },
    {
      "x": 6,
      "y": 19,
      "z": -6,
      "name": "Wood_Beech_Trunk",
      "rotation": 2
    },
    {
      "x": 6,
      "y": 20,
      "z": -6,
      "name": "Wood_Beech_Trunk",
      "rotation": 2
    },
    {
      "x": 6,
      "y": 21,
      "z": -6,
      "name": "Wood_Beech_Trunk",
      "rotation": 2
    },
    {
      "x": 6,
      "y": 22,
      "z": -6,
      "name": "Wood_Beech_Trunk",
      "rotation": 2
    },
    {
      "x": 6,
      "y": 23,
      "z": -6,
      "name": "Wood_Beech_Trunk",
      "rotation": 2
    },
    {
      "x": 6,
      "y": 24,
      "z": -6,
      "name": "Wood_Beech_Trunk",
      "rotation": 2
    },
    {
      "x": 6,
      "y": 27,
      "z": -6,
      "name": "Wood_Hardwood_Planks_Half",
      "rotation": 8
    },
    {
      "x": 6,
      "y": 33,
      "z": -6,
      "name": "Wood_Darkwood_Planks"
    },
    {
      "x": 6,
      "y": 1,
      "z": -5,
      "name": "Wood_Hardwood_Planks_Half"
    },
    {
      "x": 6,
      "y": 5,
      "z": -5,
      "name": "Wood_Hardwood_Planks_Half"
    },
    {
      "x": 6,
      "y": 9,
      "z": -5,
      "name": "Wood_Hardwood_Planks_Half"
    },
    {
      "x": 6,
      "y": 13,
      "z": -5,
      "name": "Wood_Hardwood_Planks_Half"
    },
    {
      "x": 6,
      "y": 17,
      "z": -5,
      "name": "Wood_Hardwood_Planks_Half"
    },
    {
      "x": 6,
      "y": 21,
      "z": -5,
      "name": "Wood_Hardwood_Planks_Half"
    },
    {
      "x": 6,
      "y": 24,
      "z": -5,
      "name": "Wood_Hardwood_Planks_Half",
      "rotation": 8
    },
    {
      "x": 6,
      "y": 27,
      "z": -5,
      "name": "Wood_Hardwood_Planks_Half",
      "rotation": 8
    },
    {
      "x": 6,
      "y": 33,
      "z": -5,
      "name": "Wood_Darkwood_Planks"
    },
    {
      "x": 6,
      "y": 20,
      "z": -4,
      "name": "Rock_Sandstone_Brick_Smooth"
    },
    {
      "x": 6,
      "y": 21,
      "z": -4,
      "name": "Rock_Sandstone_Brick_Smooth"
    },
    {
      "x": 6,
      "y": 22,
      "z": -4,
      "name": "Rock_Sandstone_Brick_Stairs",
      "rotation": 1
    },
    {
      "x": 6,
      "y": 23,
      "z": -4,
      "name": "Rock_Sandstone_Brick_Smooth"
    },
    {
      "x": 6,
      "y": 24,
      "z": -4,
      "name": "Rock_Sandstone_Brick_Smooth"
    },
    {
      "x": 6,
      "y": 25,
      "z": -4,
      "name": "Wood_Beech_Trunk",
      "rotation": 2
    },
    {
      "x": 6,
      "y": 26,
      "z": -4,
      "name": "Wood_Beech_Trunk",
      "rotation": 2
    },
    {
      "x": 6,
      "y": 27,
      "z": -4,
      "name": "Wood_Beech_Trunk",
      "rotation": 2
    },
    {
      "x": 6,
      "y": 33,
      "z": -4,
      "name": "Wood_Darkwood_Planks"
    },
    {
      "x": 6,
      "y": 5,
      "z": -3,
      "name": "Rock_Stone"
    },
    {
      "x": 6,
      "y": 6,
      "z": -3,
      "name": "Rock_Stone"
    },
    {
      "x": 6,
      "y": 10,
      "z": -3,
      "name": "Rock_Stone"
    },
    {
      "x": 6,
      "y": 11,
      "z": -3,
      "name": "Rock_Stone"
    },
    {
      "x": 6,
      "y": 12,
      "z": -3,
      "name": "Rock_Stone"
    },
    {
      "x": 6,
      "y": 13,
      "z": -3,
      "name": "Rock_Calcite"
    },
    {
      "x": 6,
      "y": 14,
      "z": -3,
      "name": "Furniture_Tavern_Window"
    },
    {
      "x": 6,
      "y": 15,
      "z": -3,
      "name": "Furniture_Tavern_Window"
    },
    {
      "x": 6,
      "y": 16,
      "z": -3,
      "name": "Furniture_Tavern_Window"
    },
    {
      "x": 6,
      "y": 17,
      "z": -3,
      "name": "Furniture_Tavern_Window"
    },
    {
      "x": 6,
      "y": 18,
      "z": -3,
      "name": "Rock_Stone_Cobble"
    },
    {
      "x": 6,
      "y": 19,
      "z": -3,
      "name": "Wood_Beech_Trunk",
      "rotation": 5
    },
    {
      "x": 6,
      "y": 20,
      "z": -3,
      "name": "Wood_Burnt_Branch_Short",
      "support": 15
    },
    {
      "x": 6,
      "y": 22,
      "z": -3,
      "name": "Wood_Apple_Branch_Corner",
      "support": 15,
      "rotation": 3
    },
    {
      "x": 6,
      "y": 23,
      "z": -3,
      "name": "Wood_Apple_Branch_Long",
      "support": 15
    },
    {
      "x": 6,
      "y": 24,
      "z": -3,
      "name": "Wood_Burnt_Branch_Short",
      "support": 15
    },
    {
      "x": 6,
      "y": 25,
      "z": -3,
      "name": "Wood_Beech_Trunk",
      "rotation": 5
    },
    {
      "x": 6,
      "y": 26,
      "z": -3,
      "name": "Wood_Hardwood_Planks"
    },
    {
      "x": 6,
      "y": 27,
      "z": -3,
      "name": "Furniture_Tavern_Window"
    },
    {
      "x": 6,
      "y": 28,
      "z": -3,
      "name": "Furniture_Tavern_Window"
    },
    {
      "x": 6,
      "y": 29,
      "z": -3,
      "name": "Furniture_Tavern_Window"
    },
    {
      "x": 6,
      "y": 30,
      "z": -3,
      "name": "Wood_Hardwood_Planks"
    },
    {
      "x": 6,
      "y": 31,
      "z": -3,
      "name": "Wood_Hardwood_Planks"
    },
    {
      "x": 6,
      "y": 32,
      "z": -3,
      "name": "Wood_Hardwood_Planks"
    },
    {
      "x": 6,
      "y": 34,
      "z": -3,
      "name": "Wood_Darkwood_Stairs",
      "rotation": 2
    },
    {
      "x": 6,
      "y": 6,
      "z": -2,
      "name": "Wood_Beech_Trunk",
      "support": 15,
      "rotation": 5
    },
    {
      "x": 6,
      "y": 19,
      "z": -2,
      "name": "Wood_Hardwood_Stairs",
      "rotation": 10
    },
    {
      "x": 6,
      "y": 25,
      "z": -2,
      "name": "Furniture_Crude_Trapdoor"
    },
    {
      "x": 6,
      "y": 33,
      "z": -2,
      "name": "Wood_Darkwood_Planks"
    },
    {
      "x": 6,
      "y": 34,
      "z": -2,
      "name": "Wood_Darkwood_Planks"
    },
    {
      "x": 6,
      "y": 34,
      "z": -1,
      "name": "Wood_Darkwood_Stairs",
      "rotation": 10
    },
    {
      "x": 7,
      "y": 6,
      "z": -10,
      "name": "Wood_Beech_Trunk",
      "support": 15,
      "rotation": 5
    },
    {
      "x": 7,
      "y": 25,
      "z": -10,
      "name": "Wood_Hardwood_Stairs",
      "rotation": 8
    },
    {
      "x": 7,
      "y": 30,
      "z": -10,
      "name": "Wood_Darkwood_Stairs",
      "rotation": 9
    },
    {
      "x": 7,
      "y": 31,
      "z": -10,
      "name": "Wood_Darkwood_Planks"
    },
    {
      "x": 7,
      "y": 32,
      "z": -10,
      "name": "Wood_Darkwood_Planks"
    },
    {
      "x": 7,
      "y": 33,
      "z": -10,
      "name": "Wood_Darkwood_Stairs",
      "rotation": 1
    },
    {
      "x": 7,
      "y": 4,
      "z": -9,
      "name": "Rock_Calcite_Cobble_Stairs",
      "rotation": 9
    },
    {
      "x": 7,
      "y": 5,
      "z": -9,
      "name": "Rock_Stone"
    },
    {
      "x": 7,
      "y": 6,
      "z": -9,
      "name": "Rock_Stone"
    },
    {
      "x": 7,
      "y": 10,
      "z": -9,
      "name": "Rock_Calcite_Cobble_Stairs",
      "rotation": 9
    },
    {
      "x": 7,
      "y": 11,
      "z": -9,
      "name": "Rock_Calcite"
    },
    {
      "x": 7,
      "y": 12,
      "z": -9,
      "name": "Rock_Stone_Cobble"
    },
    {
      "x": 7,
      "y": 13,
      "z": -9,
      "name": "Rock_Stone"
    },
    {
      "x": 7,
      "y": 14,
      "z": -9,
      "name": "Rock_Stone"
    },
    {
      "x": 7,
      "y": 15,
      "z": -9,
      "name": "Furniture_Tavern_Window"
    },
    {
      "x": 7,
      "y": 16,
      "z": -9,
      "name": "Furniture_Tavern_Window"
    },
    {
      "x": 7,
      "y": 17,
      "z": -9,
      "name": "Rock_Stone_Brick"
    },
    {
      "x": 7,
      "y": 18,
      "z": -9,
      "name": "Rock_Calcite"
    },
    {
      "x": 7,
      "y": 19,
      "z": -9,
      "name": "Wood_Beech_Trunk",
      "rotation": 5
    },
    {
      "x": 7,
      "y": 20,
      "z": -9,
      "name": "Wood_Burnt_Branch_Short",
      "support": 15,
      "rotation": 2
    },
    {
      "x": 7,
      "y": 24,
      "z": -9,
      "name": "Wood_Burnt_Branch_Short",
      "support": 15,
      "rotation": 2
    },
    {
      "x": 7,
      "y": 25,
      "z": -9,
      "name": "Wood_Beech_Trunk",
      "rotation": 5
    },
    {
      "x": 7,
      "y": 26,
      "z": -9,
      "name": "Wood_Hardwood_Planks"
    },
    {
      "x": 7,
      "y": 27,
      "z": -9,
      "name": "Wood_Hardwood_Planks"
    },
    {
      "x": 7,
      "y": 28,
      "z": -9,
      "name": "Furniture_Tavern_Window"
    },
    {
      "x": 7,
      "y": 29,
      "z": -9,
      "name": "Wood_Hardwood_Planks"
    },
    {
      "x": 7,
      "y": 30,
      "z": -9,
      "name": "Wood_Hardwood_Planks"
    },
    {
      "x": 7,
      "y": 32,
      "z": -9,
      "name": "Rock_Basalt_Cobble_Roof_Steep",
      "rotation": 1
    },
    {
      "x": 7,
      "y": 33,
      "z": -9,
      "name": "Rock_Basalt_Cobble_Roof_Steep",
      "filler": 1024,
      "rotation": 1
    },
    {
      "x": 7,
      "y": 20,
      "z": -8,
      "name": "Rock_Sandstone_Brick_Smooth"
    },
    {
      "x": 7,
      "y": 21,
      "z": -8,
      "name": "Rock_Sandstone_Brick_Smooth"
    },
    {
      "x": 7,
      "y": 22,
      "z": -8,
      "name": "Rock_Sandstone_Brick_Smooth"
    },
    {
      "x": 7,
      "y": 23,
      "z": -8,
      "name": "Rock_Sandstone_Brick_Smooth"
    },
    {
      "x": 7,
      "y": 24,
      "z": -8,
      "name": "Rock_Sandstone_Brick_Smooth"
    },
    {
      "x": 7,
      "y": 25,
      "z": -8,
      "name": "Wood_Hardwood_Stairs"
    },
    {
      "x": 7,
      "y": 27,
      "z": -8,
      "name": "Wood_Hardwood_Stairs",
      "rotation": 10
    },
    {
      "x": 7,
      "y": 32,
      "z": -8,
      "name": "Rock_Basalt_Cobble_Roof_Steep",
      "rotation": 1
    },
    {
      "x": 7,
      "y": 33,
      "z": -8,
      "name": "Rock_Basalt_Cobble_Roof_Steep",
      "filler": 1024,
      "rotation": 1
    },
    {
      "x": 7,
      "y": 2,
      "z": -7,
      "name": "Wood_Hardwood_Planks_Half",
      "rotation": 8
    },
    {
      "x": 7,
      "y": 6,
      "z": -7,
      "name": "Wood_Hardwood_Planks_Half",
      "rotation": 8
    },
    {
      "x": 7,
      "y": 10,
      "z": -7,
      "name": "Wood_Hardwood_Planks_Half",
      "rotation": 8
    },
    {
      "x": 7,
      "y": 14,
      "z": -7,
      "name": "Wood_Hardwood_Planks_Half",
      "rotation": 8
    },
    {
      "x": 7,
      "y": 18,
      "z": -7,
      "name": "Wood_Hardwood_Planks_Half",
      "rotation": 8
    },
    {
      "x": 7,
      "y": 22,
      "z": -7,
      "name": "Wood_Hardwood_Planks_Half",
      "rotation": 8
    },
    {
      "x": 7,
      "y": 27,
      "z": -7,
      "name": "Wood_Hardwood_Planks_Half",
      "rotation": 8
    },
    {
      "x": 7,
      "y": 32,
      "z": -7,
      "name": "Rock_Basalt_Cobble_Roof_Steep",
      "rotation": 1
    },
    {
      "x": 7,
      "y": 33,
      "z": -7,
      "name": "Rock_Basalt_Cobble_Roof_Steep",
      "filler": 1024,
      "rotation": 1
    },
    {
      "x": 7,
      "y": 2,
      "z": -6,
      "name": "Wood_Hardwood_Planks_Half"
    },
    {
      "x": 7,
      "y": 6,
      "z": -6,
      "name": "Wood_Hardwood_Planks_Half"
    },
    {
      "x": 7,
      "y": 10,
      "z": -6,
      "name": "Wood_Hardwood_Planks_Half"
    },
    {
      "x": 7,
      "y": 14,
      "z": -6,
      "name": "Wood_Hardwood_Planks_Half"
    },
    {
      "x": 7,
      "y": 18,
      "z": -6,
      "name": "Wood_Hardwood_Planks_Half"
    },
    {
      "x": 7,
      "y": 22,
      "z": -6,
      "name": "Wood_Hardwood_Planks_Half"
    },
    {
      "x": 7,
      "y": 27,
      "z": -6,
      "name": "Wood_Hardwood_Planks_Half",
      "rotation": 8
    },
    {
      "x": 7,
      "y": 32,
      "z": -6,
      "name": "Rock_Basalt_Cobble_Roof_Steep",
      "rotation": 1
    },
    {
      "x": 7,
      "y": 33,
      "z": -6,
      "name": "Rock_Basalt_Cobble_Roof_Steep",
      "filler": 1024,
      "rotation": 1
    },
    {
      "x": 7,
      "y": 1,
      "z": -5,
      "name": "Wood_Hardwood_Planks_Half",
      "rotation": 8
    },
    {
      "x": 7,
      "y": 5,
      "z": -5,
      "name": "Wood_Hardwood_Planks_Half",
      "rotation": 8
    },
    {
      "x": 7,
      "y": 9,
      "z": -5,
      "name": "Wood_Hardwood_Planks_Half",
      "rotation": 8
    },
    {
      "x": 7,
      "y": 13,
      "z": -5,
      "name": "Wood_Hardwood_Planks_Half",
      "rotation": 8
    },
    {
      "x": 7,
      "y": 21,
      "z": -5,
      "name": "Wood_Hardwood_Planks_Half",
      "rotation": 8
    },
    {
      "x": 7,
      "y": 22,
      "z": -5,
      "name": "Wood_Torch_Wall",
      "rotation": 3
    },
    {
      "x": 7,
      "y": 24,
      "z": -5,
      "name": "Wood_Hardwood_Planks_Half",
      "rotation": 8
    },
    {
      "x": 7,
      "y": 27,
      "z": -5,
      "name": "Wood_Hardwood_Planks_Half",
      "rotation": 8
    },
    {
      "x": 7,
      "y": 32,
      "z": -5,
      "name": "Rock_Basalt_Cobble_Roof_Steep",
      "rotation": 1
    },
    {
      "x": 7,
      "y": 33,
      "z": -5,
      "name": "Rock_Basalt_Cobble_Roof_Steep",
      "filler": 1024,
      "rotation": 1
    },
    {
      "x": 7,
      "y": 20,
      "z": -4,
      "name": "Rock_Sandstone_Brick_Smooth"
    },
    {
      "x": 7,
      "y": 21,
      "z": -4,
      "name": "Rock_Sandstone_Brick_Smooth"
    },
    {
      "x": 7,
      "y": 22,
      "z": -4,
      "name": "Rock_Sandstone_Brick_Smooth"
    },
    {
      "x": 7,
      "y": 23,
      "z": -4,
      "name": "Rock_Sandstone_Brick_Smooth"
    },
    {
      "x": 7,
      "y": 24,
      "z": -4,
      "name": "Rock_Sandstone_Brick_Smooth"
    },
    {
      "x": 7,
      "y": 25,
      "z": -4,
      "name": "Wood_Hardwood_Stairs",
      "rotation": 2
    },
    {
      "x": 7,
      "y": 27,
      "z": -4,
      "name": "Wood_Hardwood_Stairs",
      "rotation": 8
    },
    {
      "x": 7,
      "y": 32,
      "z": -4,
      "name": "Rock_Basalt_Cobble_Roof_Steep",
      "rotation": 1
    },
    {
      "x": 7,
      "y": 33,
      "z": -4,
      "name": "Rock_Basalt_Cobble_Roof_Steep",
      "filler": 1024,
      "rotation": 1
    },
    {
      "x": 7,
      "y": 4,
      "z": -3,
      "name": "Rock_Calcite_Cobble_Stairs",
      "rotation": 9
    },
    {
      "x": 7,
      "y": 5,
      "z": -3,
      "name": "Rock_Stone"
    },
    {
      "x": 7,
      "y": 6,
      "z": -3,
      "name": "Rock_Stone"
    },
    {
      "x": 7,
      "y": 10,
      "z": -3,
      "name": "Rock_Calcite_Cobble_Stairs",
      "rotation": 9
    },
    {
      "x": 7,
      "y": 11,
      "z": -3,
      "name": "Rock_Calcite"
    },
    {
      "x": 7,
      "y": 12,
      "z": -3,
      "name": "Rock_Stone_Brick"
    },
    {
      "x": 7,
      "y": 13,
      "z": -3,
      "name": "Rock_Stone"
    },
    {
      "x": 7,
      "y": 14,
      "z": -3,
      "name": "Rock_Stone"
    },
    {
      "x": 7,
      "y": 15,
      "z": -3,
      "name": "Furniture_Tavern_Window"
    },
    {
      "x": 7,
      "y": 16,
      "z": -3,
      "name": "Furniture_Tavern_Window"
    },
    {
      "x": 7,
      "y": 17,
      "z": -3,
      "name": "Rock_Stone_Brick"
    },
    {
      "x": 7,
      "y": 18,
      "z": -3,
      "name": "Rock_Stone"
    },
    {
      "x": 7,
      "y": 19,
      "z": -3,
      "name": "Wood_Beech_Trunk",
      "rotation": 5
    },
    {
      "x": 7,
      "y": 20,
      "z": -3,
      "name": "Wood_Burnt_Branch_Short",
      "support": 15
    },
    {
      "x": 7,
      "y": 22,
      "z": -3,
      "name": "Wood_Apple_Branch_Long",
      "support": 15,
      "rotation": 5
    },
    {
      "x": 7,
      "y": 24,
      "z": -3,
      "name": "Wood_Burnt_Branch_Short",
      "support": 15
    },
    {
      "x": 7,
      "y": 25,
      "z": -3,
      "name": "Wood_Beech_Trunk",
      "rotation": 5
    },
    {
      "x": 7,
      "y": 26,
      "z": -3,
      "name": "Wood_Hardwood_Planks"
    },
    {
      "x": 7,
      "y": 27,
      "z": -3,
      "name": "Wood_Hardwood_Planks"
    },
    {
      "x": 7,
      "y": 28,
      "z": -3,
      "name": "Furniture_Tavern_Window"
    },
    {
      "x": 7,
      "y": 29,
      "z": -3,
      "name": "Wood_Hardwood_Planks"
    },
    {
      "x": 7,
      "y": 30,
      "z": -3,
      "name": "Wood_Hardwood_Planks"
    },
    {
      "x": 7,
      "y": 31,
      "z": -3,
      "name": "Wood_Hardwood_Planks"
    },
    {
      "x": 7,
      "y": 32,
      "z": -3,
      "name": "Rock_Basalt_Cobble_Roof_Steep",
      "rotation": 1
    },
    {
      "x": 7,
      "y": 33,
      "z": -3,
      "name": "Rock_Basalt_Cobble_Roof_Steep",
      "filler": 1024,
      "rotation": 1
    },
    {
      "x": 7,
      "y": 6,
      "z": -2,
      "name": "Wood_Beech_Trunk",
      "support": 15,
      "rotation": 5
    },
    {
      "x": 7,
      "y": 25,
      "z": -2,
      "name": "Wood_Hardwood_Stairs",
      "rotation": 10
    },
    {
      "x": 7,
      "y": 30,
      "z": -2,
      "name": "Wood_Darkwood_Stairs",
      "rotation": 9
    },
    {
      "x": 7,
      "y": 31,
      "z": -2,
      "name": "Wood_Darkwood_Planks"
    },
    {
      "x": 7,
      "y": 32,
      "z": -2,
      "name": "Wood_Darkwood_Planks"
    },
    {
      "x": 7,
      "y": 33,
      "z": -2,
      "name": "Wood_Darkwood_Stairs",
      "rotation": 1
    },
    {
      "x": 8,
      "y": 6,
      "z": -11,
      "name": "Wood_Hardwood_Planks_Half",
      "rotation": 8
    },
    {
      "x": 8,
      "y": 6,
      "z": -10,
      "name": "Wood_Beech_Trunk",
      "support": 15,
      "rotation": 5
    },
    {
      "x": 8,
      "y": 19,
      "z": -10,
      "name": "Wood_Hardwood_Stairs",
      "rotation": 9
    },
    {
      "x": 8,
      "y": 25,
      "z": -10,
      "name": "Furniture_Crude_Trapdoor",
      "rotation": 2
    },
    {
      "x": 8,
      "y": 29,
      "z": -10,
      "name": "Wood_Darkwood_Stairs",
      "rotation": 9
    },
    {
      "x": 8,
      "y": 30,
      "z": -10,
      "name": "Wood_Darkwood_Planks"
    },
    {
      "x": 8,
      "y": 31,
      "z": -10,
      "name": "Wood_Darkwood_Stairs",
      "rotation": 1
    },
    {
      "x": 8,
      "y": 0,
      "z": -9,
      "name": "Rock_Stone"
    },
    {
      "x": 8,
      "y": 1,
      "z": -9,
      "name": "Rock_Stone_Brick"
    },
    {
      "x": 8,
      "y": 2,
      "z": -9,
      "name": "Rock_Calcite"
    },
    {
      "x": 8,
      "y": 3,
      "z": -9,
      "name": "Rock_Stone_Cobble"
    },
    {
      "x": 8,
      "y": 4,
      "z": -9,
      "name": "Rock_Stone_Cobble"
    },
    {
      "x": 8,
      "y": 5,
      "z": -9,
      "name": "Rock_Stone_Brick"
    },
    {
      "x": 8,
      "y": 6,
      "z": -9,
      "name": "Rock_Stone"
    },
    {
      "x": 8,
      "y": 7,
      "z": -9,
      "name": "Rock_Stone"
    },
    {
      "x": 8,
      "y": 8,
      "z": -9,
      "name": "Rock_Stone"
    },
    {
      "x": 8,
      "y": 9,
      "z": -9,
      "name": "Rock_Calcite"
    },
    {
      "x": 8,
      "y": 10,
      "z": -9,
      "name": "Rock_Stone_Brick"
    },
    {
      "x": 8,
      "y": 11,
      "z": -9,
      "name": "Rock_Stone"
    },
    {
      "x": 8,
      "y": 12,
      "z": -9,
      "name": "Rock_Stone_Cobble"
    },
    {
      "x": 8,
      "y": 13,
      "z": -9,
      "name": "Rock_Calcite"
    },
    {
      "x": 8,
      "y": 14,
      "z": -9,
      "name": "Rock_Stone_Cobble"
    },
    {
      "x": 8,
      "y": 15,
      "z": -9,
      "name": "Rock_Stone"
    },
    {
      "x": 8,
      "y": 16,
      "z": -9,
      "name": "Rock_Calcite"
    },
    {
      "x": 8,
      "y": 17,
      "z": -9,
      "name": "Rock_Calcite"
    },
    {
      "x": 8,
      "y": 18,
      "z": -9,
      "name": "Rock_Stone_Cobble"
    },
    {
      "x": 8,
      "y": 19,
      "z": -9,
      "name": "Wood_Beech_Trunk",
      "rotation": 5
    },
    {
      "x": 8,
      "y": 20,
      "z": -9,
      "name": "Wood_Hardwood_Stairs",
      "rotation": 3
    },
    {
      "x": 8,
      "y": 21,
      "z": -9,
      "name": "Wood_Burnt_Branch_Short",
      "support": 15,
      "rotation": 2
    },
    {
      "x": 8,
      "y": 22,
      "z": -9,
      "name": "Wood_Burnt_Branch_Short",
      "support": 15,
      "rotation": 2
    },
    {
      "x": 8,
      "y": 23,
      "z": -9,
      "name": "Wood_Burnt_Branch_Short",
      "support": 15,
      "rotation": 2
    },
    {
      "x": 8,
      "y": 24,
      "z": -9,
      "name": "Wood_Hardwood_Stairs",
      "rotation": 9
    },
    {
      "x": 8,
      "y": 25,
      "z": -9,
      "name": "Wood_Beech_Trunk",
      "rotation": 5
    },
    {
      "x": 8,
      "y": 26,
      "z": -9,
      "name": "Wood_Hardwood_Planks"
    },
    {
      "x": 8,
      "y": 27,
      "z": -9,
      "name": "Wood_Hardwood_Planks"
    },
    {
      "x": 8,
      "y": 28,
      "z": -9,
      "name": "Wood_Hardwood_Planks"
    },
    {
      "x": 8,
      "y": 29,
      "z": -9,
      "name": "Wood_Hardwood_Planks"
    },
    {
      "x": 8,
      "y": 30,
      "z": -9,
      "name": "Rock_Basalt_Cobble_Roof_Steep",
      "rotation": 1
    },
    {
      "x": 8,
      "y": 31,
      "z": -9,
      "name": "Rock_Basalt_Cobble_Roof_Steep",
      "filler": 1024,
      "rotation": 1
    },
    {
      "x": 8,
      "y": 20,
      "z": -8,
      "name": "Rock_Sandstone_Brick_Smooth"
    },
    {
      "x": 8,
      "y": 21,
      "z": -8,
      "name": "Rock_Sandstone_Brick_Smooth"
    },
    {
      "x": 8,
      "y": 22,
      "z": -8,
      "name": "Rock_Sandstone_Brick_Smooth"
    },
    {
      "x": 8,
      "y": 23,
      "z": -8,
      "name": "Rock_Sandstone_Brick_Smooth"
    },
    {
      "x": 8,
      "y": 24,
      "z": -8,
      "name": "Rock_Sandstone_Brick_Smooth"
    },
    {
      "x": 8,
      "y": 25,
      "z": -8,
      "name": "*Wood_Hardwood_Stairs_State_Definitions_Inverted_Corner_Right"
    },
    {
      "x": 8,
      "y": 27,
      "z": -8,
      "name": "*Wood_Hardwood_Stairs_State_Definitions_Inverted_Corner_Left",
      "rotation": 10
    },
    {
      "x": 8,
      "y": 30,
      "z": -8,
      "name": "Rock_Basalt_Cobble_Roof_Steep",
      "rotation": 1
    },
    {
      "x": 8,
      "y": 31,
      "z": -8,
      "name": "Rock_Basalt_Cobble_Roof_Steep",
      "filler": 1024,
      "rotation": 1
    },
    {
      "x": 8,
      "y": 20,
      "z": -7,
      "name": "Rock_Sandstone_Brick_Smooth"
    },
    {
      "x": 8,
      "y": 21,
      "z": -7,
      "name": "Rock_Sandstone_Brick_Smooth"
    },
    {
      "x": 8,
      "y": 22,
      "z": -7,
      "name": "Rock_Sandstone_Brick_Smooth"
    },
    {
      "x": 8,
      "y": 23,
      "z": -7,
      "name": "Rock_Sandstone_Brick_Smooth"
    },
    {
      "x": 8,
      "y": 24,
      "z": -7,
      "name": "Rock_Sandstone_Brick_Smooth"
    },
    {
      "x": 8,
      "y": 25,
      "z": -7,
      "name": "Wood_Hardwood_Stairs",
      "rotation": 3
    },
    {
      "x": 8,
      "y": 27,
      "z": -7,
      "name": "Wood_Hardwood_Stairs",
      "rotation": 9
    },
    {
      "x": 8,
      "y": 30,
      "z": -7,
      "name": "Rock_Basalt_Cobble_Roof_Steep",
      "rotation": 1
    },
    {
      "x": 8,
      "y": 31,
      "z": -7,
      "name": "Rock_Basalt_Cobble_Roof_Steep",
      "filler": 1024,
      "rotation": 1
    },
    {
      "x": 8,
      "y": 20,
      "z": -6,
      "name": "Rock_Sandstone_Brick_Smooth"
    },
    {
      "x": 8,
      "y": 21,
      "z": -6,
      "name": "Rock_Sandstone_Brick_Smooth"
    },
    {
      "x": 8,
      "y": 22,
      "z": -6,
      "name": "Rock_Sandstone_Brick_Stairs",
      "rotation": 2
    },
    {
      "x": 8,
      "y": 23,
      "z": -6,
      "name": "Rock_Sandstone_Brick_Smooth"
    },
    {
      "x": 8,
      "y": 24,
      "z": -6,
      "name": "Rock_Sandstone_Brick_Smooth"
    },
    {
      "x": 8,
      "y": 25,
      "z": -6,
      "name": "Wood_Hardwood_Stairs",
      "rotation": 3
    },
    {
      "x": 8,
      "y": 27,
      "z": -6,
      "name": "Wood_Hardwood_Stairs",
      "rotation": 9
    },
    {
      "x": 8,
      "y": 30,
      "z": -6,
      "name": "Rock_Basalt_Cobble_Roof_Steep",
      "rotation": 1
    },
    {
      "x": 8,
      "y": 31,
      "z": -6,
      "name": "Rock_Basalt_Cobble_Roof_Steep",
      "filler": 1024,
      "rotation": 1
    },
    {
      "x": 8,
      "y": 20,
      "z": -5,
      "name": "Rock_Sandstone_Brick_Smooth"
    },
    {
      "x": 8,
      "y": 21,
      "z": -5,
      "name": "Rock_Sandstone_Brick_Smooth"
    },
    {
      "x": 8,
      "y": 22,
      "z": -5,
      "name": "Rock_Sandstone_Brick_Smooth"
    },
    {
      "x": 8,
      "y": 23,
      "z": -5,
      "name": "Rock_Sandstone_Brick_Smooth"
    },
    {
      "x": 8,
      "y": 24,
      "z": -5,
      "name": "Rock_Sandstone_Brick_Smooth"
    },
    {
      "x": 8,
      "y": 25,
      "z": -5,
      "name": "Wood_Hardwood_Stairs",
      "rotation": 3
    },
    {
      "x": 8,
      "y": 27,
      "z": -5,
      "name": "Wood_Hardwood_Stairs",
      "rotation": 9
    },
    {
      "x": 8,
      "y": 30,
      "z": -5,
      "name": "Rock_Basalt_Cobble_Roof_Steep",
      "rotation": 1
    },
    {
      "x": 8,
      "y": 31,
      "z": -5,
      "name": "Rock_Basalt_Cobble_Roof_Steep",
      "filler": 1024,
      "rotation": 1
    },
    {
      "x": 8,
      "y": 20,
      "z": -4,
      "name": "Rock_Sandstone_Brick_Smooth"
    },
    {
      "x": 8,
      "y": 21,
      "z": -4,
      "name": "Rock_Sandstone_Brick_Smooth"
    },
    {
      "x": 8,
      "y": 22,
      "z": -4,
      "name": "Rock_Sandstone_Brick_Smooth"
    },
    {
      "x": 8,
      "y": 23,
      "z": -4,
      "name": "Rock_Sandstone_Brick_Smooth"
    },
    {
      "x": 8,
      "y": 24,
      "z": -4,
      "name": "Rock_Sandstone_Brick_Smooth"
    },
    {
      "x": 8,
      "y": 25,
      "z": -4,
      "name": "*Wood_Hardwood_Stairs_State_Definitions_Inverted_Corner_Right",
      "rotation": 3
    },
    {
      "x": 8,
      "y": 27,
      "z": -4,
      "name": "*Wood_Hardwood_Stairs_State_Definitions_Inverted_Corner_Left",
      "rotation": 9
    },
    {
      "x": 8,
      "y": 30,
      "z": -4,
      "name": "Rock_Basalt_Cobble_Roof_Steep",
      "rotation": 1
    },
    {
      "x": 8,
      "y": 31,
      "z": -4,
      "name": "Rock_Basalt_Cobble_Roof_Steep",
      "filler": 1024,
      "rotation": 1
    },
    {
      "x": 8,
      "y": 0,
      "z": -3,
      "name": "Rock_Calcite"
    },
    {
      "x": 8,
      "y": 1,
      "z": -3,
      "name": "Rock_Calcite"
    },
    {
      "x": 8,
      "y": 2,
      "z": -3,
      "name": "Rock_Calcite"
    },
    {
      "x": 8,
      "y": 3,
      "z": -3,
      "name": "Rock_Calcite"
    },
    {
      "x": 8,
      "y": 4,
      "z": -3,
      "name": "Rock_Calcite"
    },
    {
      "x": 8,
      "y": 5,
      "z": -3,
      "name": "Rock_Stone"
    },
    {
      "x": 8,
      "y": 6,
      "z": -3,
      "name": "Rock_Stone_Cobble"
    },
    {
      "x": 8,
      "y": 7,
      "z": -3,
      "name": "Rock_Stone_Brick"
    },
    {
      "x": 8,
      "y": 8,
      "z": -3,
      "name": "Rock_Stone_Brick"
    },
    {
      "x": 8,
      "y": 9,
      "z": -3,
      "name": "Rock_Stone"
    },
    {
      "x": 8,
      "y": 10,
      "z": -3,
      "name": "Rock_Stone"
    },
    {
      "x": 8,
      "y": 11,
      "z": -3,
      "name": "Rock_Calcite"
    },
    {
      "x": 8,
      "y": 12,
      "z": -3,
      "name": "Rock_Stone_Brick"
    },
    {
      "x": 8,
      "y": 13,
      "z": -3,
      "name": "Rock_Stone_Brick"
    },
    {
      "x": 8,
      "y": 14,
      "z": -3,
      "name": "Rock_Stone_Brick"
    },
    {
      "x": 8,
      "y": 15,
      "z": -3,
      "name": "Rock_Stone"
    },
    {
      "x": 8,
      "y": 16,
      "z": -3,
      "name": "Rock_Stone"
    },
    {
      "x": 8,
      "y": 17,
      "z": -3,
      "name": "Rock_Stone"
    },
    {
      "x": 8,
      "y": 18,
      "z": -3,
      "name": "Rock_Calcite"
    },
    {
      "x": 8,
      "y": 19,
      "z": -3,
      "name": "Wood_Beech_Trunk",
      "rotation": 5
    },
    {
      "x": 8,
      "y": 20,
      "z": -3,
      "name": "Wood_Hardwood_Stairs",
      "rotation": 3
    },
    {
      "x": 8,
      "y": 21,
      "z": -3,
      "name": "Wood_Burnt_Branch_Short",
      "support": 15
    },
    {
      "x": 8,
      "y": 22,
      "z": -3,
      "name": "Wood_Burnt_Branch_Short",
      "support": 15
    },
    {
      "x": 8,
      "y": 23,
      "z": -3,
      "name": "Wood_Burnt_Branch_Short",
      "support": 15
    },
    {
      "x": 8,
      "y": 24,
      "z": -3,
      "name": "Wood_Hardwood_Stairs",
      "rotation": 9
    },
    {
      "x": 8,
      "y": 25,
      "z": -3,
      "name": "Wood_Beech_Trunk",
      "rotation": 5
    },
    {
      "x": 8,
      "y": 26,
      "z": -3,
      "name": "Wood_Hardwood_Planks"
    },
    {
      "x": 8,
      "y": 27,
      "z": -3,
      "name": "Wood_Hardwood_Planks"
    },
    {
      "x": 8,
      "y": 28,
      "z": -3,
      "name": "Wood_Hardwood_Planks"
    },
    {
      "x": 8,
      "y": 29,
      "z": -3,
      "name": "Wood_Hardwood_Planks"
    },
    {
      "x": 8,
      "y": 30,
      "z": -3,
      "name": "Rock_Basalt_Cobble_Roof_Steep",
      "rotation": 1
    },
    {
      "x": 8,
      "y": 31,
      "z": -3,
      "name": "Rock_Basalt_Cobble_Roof_Steep",
      "filler": 1024,
      "rotation": 1
    },
    {
      "x": 8,
      "y": 6,
      "z": -2,
      "name": "Wood_Beech_Trunk",
      "support": 15,
      "rotation": 5
    },
    {
      "x": 8,
      "y": 19,
      "z": -2,
      "name": "Wood_Hardwood_Stairs",
      "rotation": 9
    },
    {
      "x": 8,
      "y": 25,
      "z": -2,
      "name": "Furniture_Crude_Trapdoor"
    },
    {
      "x": 8,
      "y": 29,
      "z": -2,
      "name": "Wood_Darkwood_Stairs",
      "rotation": 9
    },
    {
      "x": 8,
      "y": 30,
      "z": -2,
      "name": "Wood_Darkwood_Planks"
    },
    {
      "x": 8,
      "y": 31,
      "z": -2,
      "name": "Wood_Darkwood_Stairs",
      "rotation": 1
    },
    {
      "x": 8,
      "y": 6,
      "z": -1,
      "name": "Wood_Hardwood_Planks_Half",
      "rotation": 8
    },
    {
      "x": 9,
      "y": 6,
      "z": -11,
      "name": "Wood_Hardwood_Stairs",
      "rotation": 9
    },
    {
      "x": 9,
      "y": 6,
      "z": -10,
      "name": "Wood_Beech_Trunk",
      "support": 15,
      "rotation": 5
    },
    {
      "x": 9,
      "y": 18,
      "z": -10,
      "name": "Wood_Hardwood_Stairs",
      "rotation": 8
    },
    {
      "x": 9,
      "y": 19,
      "z": -10,
      "name": "Wood_Beech_Trunk",
      "support": 15,
      "rotation": 4
    },
    {
      "x": 9,
      "y": 25,
      "z": -10,
      "name": "Wood_Hardwood_Stairs",
      "rotation": 8
    },
    {
      "x": 9,
      "y": 27,
      "z": -10,
      "name": "Wood_Darkwood_Planks"
    },
    {
      "x": 9,
      "y": 28,
      "z": -10,
      "name": "Wood_Darkwood_Planks"
    },
    {
      "x": 9,
      "y": 29,
      "z": -10,
      "name": "Wood_Darkwood_Planks"
    },
    {
      "x": 9,
      "y": 30,
      "z": -10,
      "name": "Wood_Darkwood_Stairs",
      "rotation": 1
    },
    {
      "x": 9,
      "y": 0,
      "z": -9,
      "name": "Rock_Calcite"
    },
    {
      "x": 9,
      "y": 1,
      "z": -9,
      "name": "Rock_Stone_Cobble_Beam"
    },
    {
      "x": 9,
      "y": 2,
      "z": -9,
      "name": "Rock_Stone"
    },
    {
      "x": 9,
      "y": 3,
      "z": -9,
      "name": "Rock_Stone_Brick"
    },
    {
      "x": 9,
      "y": 4,
      "z": -9,
      "name": "Rock_Stone_Cobble"
    },
    {
      "x": 9,
      "y": 5,
      "z": -9,
      "name": "Rock_Stone"
    },
    {
      "x": 9,
      "y": 6,
      "z": -9,
      "name": "Rock_Stone_Brick"
    },
    {
      "x": 9,
      "y": 7,
      "z": -9,
      "name": "Rock_Stone_Brick"
    },
    {
      "x": 9,
      "y": 8,
      "z": -9,
      "name": "Rock_Stone_Cobble_Beam"
    },
    {
      "x": 9,
      "y": 9,
      "z": -9,
      "name": "Rock_Stone"
    },
    {
      "x": 9,
      "y": 10,
      "z": -9,
      "name": "Rock_Stone_Brick"
    },
    {
      "x": 9,
      "y": 11,
      "z": -9,
      "name": "Rock_Stone"
    },
    {
      "x": 9,
      "y": 12,
      "z": -9,
      "name": "Rock_Calcite"
    },
    {
      "x": 9,
      "y": 13,
      "z": -9,
      "name": "Rock_Stone"
    },
    {
      "x": 9,
      "y": 14,
      "z": -9,
      "name": "Rock_Stone"
    },
    {
      "x": 9,
      "y": 15,
      "z": -9,
      "name": "Rock_Stone_Brick"
    },
    {
      "x": 9,
      "y": 16,
      "z": -9,
      "name": "Rock_Calcite"
    },
    {
      "x": 9,
      "y": 17,
      "z": -9,
      "name": "Rock_Stone"
    },
    {
      "x": 9,
      "y": 18,
      "z": -9,
      "name": "Rock_Stone"
    },
    {
      "x": 9,
      "y": 19,
      "z": -9,
      "name": "Wood_Beech_Trunk",
      "rotation": 2
    },
    {
      "x": 9,
      "y": 20,
      "z": -9,
      "name": "Wood_Beech_Trunk",
      "rotation": 2
    },
    {
      "x": 9,
      "y": 21,
      "z": -9,
      "name": "Wood_Beech_Trunk",
      "rotation": 2
    },
    {
      "x": 9,
      "y": 22,
      "z": -9,
      "name": "Wood_Beech_Trunk",
      "rotation": 2
    },
    {
      "x": 9,
      "y": 23,
      "z": -9,
      "name": "Wood_Beech_Trunk",
      "rotation": 2
    },
    {
      "x": 9,
      "y": 24,
      "z": -9,
      "name": "Wood_Beech_Trunk",
      "rotation": 2
    },
    {
      "x": 9,
      "y": 25,
      "z": -9,
      "name": "Wood_Beech_Trunk",
      "rotation": 2
    },
    {
      "x": 9,
      "y": 26,
      "z": -9,
      "name": "Wood_Hardwood_Planks"
    },
    {
      "x": 9,
      "y": 28,
      "z": -9,
      "name": "Rock_Basalt_Cobble_Roof_Steep",
      "rotation": 1
    },
    {
      "x": 9,
      "y": 29,
      "z": -9,
      "name": "Rock_Basalt_Cobble_Roof_Steep",
      "filler": 1024,
      "rotation": 1
    },
    {
      "x": 9,
      "y": 0,
      "z": -8,
      "name": "Rock_Calcite"
    },
    {
      "x": 9,
      "y": 1,
      "z": -8,
      "name": "Rock_Calcite"
    },
    {
      "x": 9,
      "y": 2,
      "z": -8,
      "name": "Rock_Stone_Brick"
    },
    {
      "x": 9,
      "y": 3,
      "z": -8,
      "name": "Rock_Stone"
    },
    {
      "x": 9,
      "y": 4,
      "z": -8,
      "name": "Rock_Stone_Cobble"
    },
    {
      "x": 9,
      "y": 5,
      "z": -8,
      "name": "Rock_Stone"
    },
    {
      "x": 9,
      "y": 6,
      "z": -8,
      "name": "Rock_Stone"
    },
    {
      "x": 9,
      "y": 7,
      "z": -8,
      "name": "Rock_Stone"
    },
    {
      "x": 9,
      "y": 8,
      "z": -8,
      "name": "Rock_Calcite"
    },
    {
      "x": 9,
      "y": 9,
      "z": -8,
      "name": "Rock_Stone_Brick"
    },
    {
      "x": 9,
      "y": 10,
      "z": -8,
      "name": "Rock_Stone"
    },
    {
      "x": 9,
      "y": 11,
      "z": -8,
      "name": "Rock_Stone_Brick"
    },
    {
      "x": 9,
      "y": 12,
      "z": -8,
      "name": "Rock_Calcite"
    },
    {
      "x": 9,
      "y": 13,
      "z": -8,
      "name": "Rock_Calcite"
    },
    {
      "x": 9,
      "y": 14,
      "z": -8,
      "name": "Rock_Stone"
    },
    {
      "x": 9,
      "y": 15,
      "z": -8,
      "name": "Rock_Stone"
    },
    {
      "x": 9,
      "y": 16,
      "z": -8,
      "name": "Rock_Stone"
    },
    {
      "x": 9,
      "y": 17,
      "z": -8,
      "name": "Rock_Stone"
    },
    {
      "x": 9,
      "y": 18,
      "z": -8,
      "name": "Rock_Stone_Brick"
    },
    {
      "x": 9,
      "y": 19,
      "z": -8,
      "name": "Wood_Beech_Trunk",
      "rotation": 4
    },
    {
      "x": 9,
      "y": 20,
      "z": -8,
      "name": "Wood_Hardwood_Stairs"
    },
    {
      "x": 9,
      "y": 21,
      "z": -8,
      "name": "Wood_Burnt_Branch_Short",
      "support": 15,
      "rotation": 1
    },
    {
      "x": 9,
      "y": 22,
      "z": -8,
      "name": "Wood_Burnt_Branch_Short",
      "support": 15,
      "rotation": 1
    },
    {
      "x": 9,
      "y": 23,
      "z": -8,
      "name": "Wood_Burnt_Branch_Short",
      "support": 15,
      "rotation": 1
    },
    {
      "x": 9,
      "y": 24,
      "z": -8,
      "name": "Wood_Hardwood_Stairs",
      "rotation": 10
    },
    {
      "x": 9,
      "y": 25,
      "z": -8,
      "name": "Wood_Beech_Trunk",
      "rotation": 4
    },
    {
      "x": 9,
      "y": 26,
      "z": -8,
      "name": "Wood_Hardwood_Planks"
    },
    {
      "x": 9,
      "y": 27,
      "z": -8,
      "name": "Rock_Slate_Cobble_Stairs",
      "rotation": 1
    },
    {
      "x": 9,
      "y": 28,
      "z": -8,
      "name": "Rock_Basalt_Cobble_Roof_Steep",
      "rotation": 1
    },
    {
      "x": 9,
      "y": 29,
      "z": -8,
      "name": "Rock_Basalt_Cobble_Roof_Steep",
      "filler": 1024,
      "rotation": 1
    },
    {
      "x": 9,
      "y": 4,
      "z": -7,
      "name": "Rock_Calcite_Cobble_Stairs",
      "rotation": 10
    },
    {
      "x": 9,
      "y": 5,
      "z": -7,
      "name": "Rock_Stone"
    },
    {
      "x": 9,
      "y": 6,
      "z": -7,
      "name": "Rock_Calcite"
    },
    {
      "x": 9,
      "y": 10,
      "z": -7,
      "name": "Rock_Calcite_Cobble_Stairs",
      "rotation": 10
    },
    {
      "x": 9,
      "y": 11,
      "z": -7,
      "name": "Rock_Stone_Brick"
    },
    {
      "x": 9,
      "y": 12,
      "z": -7,
      "name": "Rock_Stone"
    },
    {
      "x": 9,
      "y": 13,
      "z": -7,
      "name": "Rock_Stone_Brick"
    },
    {
      "x": 9,
      "y": 14,
      "z": -7,
      "name": "Rock_Stone"
    },
    {
