{
  "version": 8,
  "blockIdVersion": 11,
  "anchorX": 0,
  "anchorY": 0,
  "anchorZ": 0,
  "blocks": [
    {
      "x": 1,
      "y": 0,
      "z": -9,
      "name": "Rock_Stone_Cobble"
    },
    {
      "x": 1,
      "y": 4,
      "z": -9,
      "name": "Wood_Softwood_Roof_Hollow",
      "rotation": 3
    },
    {
      "x": 1,
      "y": 0,
      "z": -8,
      "name": "Rock_Stone_Cobble"
    },
    {
      "x": 1,
      "y": 4,
      "z": -8,
      "name": "Wood_Softwood_Roof_Hollow",
      "rotation": 3
    },
    {
      "x": 1,
      "y": 0,
      "z": -7,
      "name": "Rock_Stone_Cobble_Mossy"
    },
    {
      "x": 1,
      "y": 4,
      "z": -7,
      "name": "Wood_Softwood_Roof_Hollow",
      "rotation": 3
    },
    {
      "x": 1,
      "y": 0,
      "z": -6,
      "name": "Rock_Stone_Cobble"
    },
    {
      "x": 1,
      "y": 4,
      "z": -6,
      "name": "Wood_Softwood_Roof_Hollow",
      "rotation": 3
    },
    {
      "x": 1,
      "y": 0,
      "z": -5,
      "name": "Rock_Stone_Cobble"
    },
    {
      "x": 1,
      "y": 2,
      "z": -5,
      "name": "Plant_Vine_Wall",
      "support": 15,
      "rotation": 3
    },
    {
      "x": 1,
      "y": 4,
      "z": -5,
      "name": "Wood_Softwood_Roof_Hollow",
      "rotation": 3
    },
    {
      "x": 1,
      "y": 0,
      "z": -4,
      "name": "Rock_Stone_Cobble"
    },
    {
      "x": 1,
      "y": 4,
      "z": -4,
      "name": "Wood_Softwood_Roof_Hollow",
      "rotation": 3
    },
    {
      "x": 1,
      "y": 0,
      "z": -3,
      "name": "Rock_Stone_Cobble"
    },
    {
      "x": 1,
      "y": 4,
      "z": -3,
      "name": "Wood_Softwood_Roof_Hollow",
      "rotation": 3
    },
    {
      "x": 1,
      "y": 0,
      "z": -2,
      "name": "Rock_Stone_Cobble"
    },
    {
      "x": 1,
      "y": 4,
      "z": -2,
      "name": "Wood_Softwood_Roof_Hollow",
      "rotation": 3
    },
    {
      "x": 1,
      "y": 0,
      "z": -1,
      "name": "Rock_Stone_Cobble"
    },
    {
      "x": 1,
      "y": 4,
      "z": -1,
      "name": "Wood_Softwood_Roof_Hollow",
      "rotation": 3
    },
    {
      "x": 2,
      "y": 0,
      "z": -9,
      "name": "Rock_Stone_Cobble"
    },
    {
      "x": 2,
      "y": 4,
      "z": -9,
      "name": "Wood_Beech_Branch_Corner",
      "support": 15,
      "rotation": 2
    },
    {
      "x": 2,
      "y": 5,
      "z": -9,
      "name": "Wood_Softwood_Roof",
      "rotation": 3
    },
    {
      "x": 2,
      "y": 0,
      "z": -8,
      "name": "Rock_Stone_Cobble"
    },
    {
      "x": 2,
      "y": 1,
      "z": -8,
      "name": "Wood_Beech_Trunk",
      "support": 15
    },
    {
      "x": 2,
      "y": 2,
      "z": -8,
      "name": "Wood_Beech_Trunk",
      "support": 15
    },
    {
      "x": 2,
      "y": 3,
      "z": -8,
      "name": "Wood_Beech_Trunk",
      "support": 15
    },
    {
      "x": 2,
      "y": 4,
      "z": -8,
      "name": "Wood_Beech_Trunk",
      "support": 15,
      "rotation": 4
    },
    {
      "x": 2,
      "y": 5,
      "z": -8,
      "name": "Wood_Softwood_Roof",
      "rotation": 3
    },
    {
      "x": 2,
      "y": 0,
      "z": -7,
      "name": "Rock_Stone_Cobble_Mossy"
    },
    {
      "x": 2,
      "y": 1,
      "z": -7,
      "name": "Rock_Stone_Brick_Mossy"
    },
    {
      "x": 2,
      "y": 2,
      "z": -7,
      "name": "*Wood_Village_Wall_Full_State_Definitions_Bottom"
    },
    {
      "x": 2,
      "y": 3,
      "z": -7,
      "name": "*Wood_Village_Wall_Full_State_Definitions_Top"
    },
    {
      "x": 2,
      "y": 4,
      "z": -7,
      "name": "Wood_Beech_Trunk",
      "support": 15,
      "rotation": 4
    },
    {
      "x": 2,
      "y": 5,
      "z": -7,
      "name": "Wood_Softwood_Roof",
      "rotation": 3
    },
    {
      "x": 2,
      "y": 0,
      "z": -6,
      "name": "Rock_Stone_Cobble"
    },
    {
      "x": 2,
      "y": 1,
      "z": -6,
      "name": "Rock_Stone_Brick"
    },
    {
      "x": 2,
      "y": 2,
      "z": -6,
      "name": "Furniture_Village_Window",
      "rotation": 1
    },
    {
      "x": 2,
      "y": 3,
      "z": -6,
      "name": "Furniture_Village_Window",
      "rotation": 1
    },
    {
      "x": 2,
      "y": 4,
      "z": -6,
      "name": "Wood_Beech_Trunk",
      "support": 15,
      "rotation": 4
    },
    {
      "x": 2,
      "y": 5,
      "z": -6,
      "name": "Wood_Softwood_Roof",
      "rotation": 3
    },
    {
      "x": 2,
      "y": 0,
      "z": -5,
      "name": "Rock_Stone_Cobble"
    },
    {
      "x": 2,
      "y": 1,
      "z": -5,
      "name": "Rock_Stone_Brick"
    },
    {
      "x": 2,
      "y": 2,
      "z": -5,
      "name": "*Wood_Village_Wall_Full_State_Definitions_Bottom"
    },
    {
      "x": 2,
      "y": 3,
      "z": -5,
      "name": "*Wood_Village_Wall_Full_State_Definitions_Top"
    },
    {
      "x": 2,
      "y": 4,
      "z": -5,
      "name": "Wood_Beech_Trunk",
      "support": 15,
      "rotation": 4
    },
    {
      "x": 2,
      "y": 5,
      "z": -5,
      "name": "Wood_Softwood_Roof",
      "rotation": 3
    },
    {
      "x": 2,
      "y": 0,
      "z": -4,
      "name": "Rock_Stone_Cobble"
    },
    {
      "x": 2,
      "y": 1,
      "z": -4,
      "name": "Rock_Stone_Brick"
    },
    {
      "x": 2,
      "y": 2,
      "z": -4,
      "name": "Furniture_Village_Window",
      "rotation": 1
    },
    {
      "x": 2,
      "y": 3,
      "z": -4,
      "name": "Furniture_Village_Window",
      "rotation": 1
    },
    {
      "x": 2,
      "y": 4,
      "z": -4,
      "name": "Wood_Beech_Trunk",
      "support": 15,
      "rotation": 4
    },
    {
      "x": 2,
      "y": 5,
      "z": -4,
      "name": "Wood_Softwood_Roof",
      "rotation": 3
    },
    {
      "x": 2,
      "y": 0,
      "z": -3,
      "name": "Rock_Stone_Cobble_Mossy"
    },
    {
      "x": 2,
      "y": 1,
      "z": -3,
      "name": "Rock_Stone_Brick"
    },
    {
      "x": 2,
      "y": 2,
      "z": -3,
      "name": "*Wood_Village_Wall_Full_State_Definitions_Bottom"
    },
    {
      "x": 2,
      "y": 3,
      "z": -3,
      "name": "*Wood_Village_Wall_Full_State_Definitions_Top"
    },
    {
      "x": 2,
      "y": 4,
      "z": -3,
      "name": "Wood_Beech_Trunk",
      "support": 15,
      "rotation": 4
    },
    {
      "x": 2,
      "y": 5,
      "z": -3,
      "name": "Wood_Softwood_Roof",
      "rotation": 3
    },
    {
      "x": 2,
      "y": 0,
      "z": -2,
      "name": "Rock_Stone_Cobble"
    },
    {
      "x": 2,
      "y": 1,
      "z": -2,
      "name": "Wood_Beech_Trunk",
      "support": 15
    },
    {
      "x": 2,
      "y": 2,
      "z": -2,
      "name": "Wood_Beech_Trunk",
      "support": 15
    },
    {
      "x": 2,
      "y": 3,
      "z": -2,
      "name": "Wood_Beech_Trunk",
      "support": 15
    },
    {
      "x": 2,
      "y": 4,
      "z": -2,
      "name": "Wood_Beech_Trunk",
      "support": 15
    },
    {
      "x": 2,
      "y": 5,
      "z": -2,
      "name": "Wood_Softwood_Roof",
      "rotation": 3
    },
    {
      "x": 2,
      "y": 0,
      "z": -1,
      "name": "Rock_Stone_Cobble"
    },
    {
      "x": 2,
      "y": 4,
      "z": -1,
      "name": "Wood_Beech_Branch_Corner",
      "support": 15
    },
    {
      "x": 2,
      "y": 5,
      "z": -1,
      "name": "Wood_Softwood_Roof",
      "rotation": 3
    },
    {
      "x": 3,
      "y": 0,
      "z": -9,
      "name": "Rock_Stone_Cobble"
    },
    {
      "x": 3,
      "y": 4,
      "z": -9,
      "name": "Plant_Vine_Wall",
      "support": 15,
      "rotation": 2
    },
    {
      "x": 3,
      "y": 5,
      "z": -9,
      "name": "Wood_Softwood_Stairs",
      "rotation": 11
    },
    {
      "x": 3,
      "y": 6,
      "z": -9,
      "name": "Wood_Softwood_Roof",
      "rotation": 3
    },
    {
      "x": 3,
      "y": 0,
      "z": -8,
      "name": "Rock_Stone_Cobble"
    },
    {
      "x": 3,
      "y": 1,
      "z": -8,
      "name": "Rock_Stone_Brick"
    },
    {
      "x": 3,
      "y": 2,
      "z": -8,
      "name": "*Wood_Village_Wall_Full_State_Definitions_Bottom"
    },
    {
      "x": 3,
      "y": 3,
      "z": -8,
      "name": "*Wood_Village_Wall_Full_State_Definitions_Top"
    },
    {
      "x": 3,
      "y": 4,
      "z": -8,
      "name": "Wood_Beech_Trunk",
      "support": 15,
      "rotation": 5
    },
    {
      "x": 3,
      "y": 5,
      "z": -8,
      "name": "Wood_Village_Wall_Full"
    },
    {
      "x": 3,
      "y": 6,
      "z": -8,
      "name": "Wood_Softwood_Roof",
      "rotation": 3
    },
    {
      "x": 3,
      "y": 0,
      "z": -7,
      "name": "Wood_Softwood_Planks"
    },
    {
      "x": 3,
      "y": 1,
      "z": -7,
      "name": "Furniture_Village_Crate"
    },
    {
      "x": 3,
      "y": 5,
      "z": -7,
      "name": "Wood_Softwood_Stairs",
      "rotation": 11
    },
    {
      "x": 3,
      "y": 6,
      "z": -7,
      "name": "Wood_Softwood_Roof",
      "rotation": 3
    },
    {
      "x": 3,
      "y": 0,
      "z": -6,
      "name": "Wood_Softwood_Planks"
    },
    {
      "x": 3,
      "y": 5,
      "z": -6,
      "name": "Wood_Softwood_Stairs",
      "rotation": 11
    },
    {
      "x": 3,
      "y": 6,
      "z": -6,
      "name": "Wood_Softwood_Roof",
      "rotation": 3
    },
    {
      "x": 3,
      "y": 0,
      "z": -5,
      "name": "Wood_Softwood_Planks"
    },
    {
      "x": 3,
      "y": 1,
      "z": -5,
      "name": "Wood_Deadwood_Planks"
    },
    {
      "x": 3,
      "y": 2,
      "z": -5,
      "name": "Furniture_Human_Ruins_Candle",
      "support": 15
    },
    {
      "x": 3,
      "y": 3,
      "z": -5,
      "name": "Furniture_Human_Ruins_Candle",
      "support": 15,
      "filler": 1024
    },
    {
      "x": 3,
      "y": 5,
      "z": -5,
      "name": "Wood_Softwood_Stairs",
      "rotation": 11
    },
    {
      "x": 3,
      "y": 6,
      "z": -5,
      "name": "Wood_Softwood_Roof",
      "rotation": 3
    },
    {
      "x": 3,
      "y": 0,
      "z": -4,
      "name": "Wood_Softwood_Planks"
    },
    {
      "x": 3,
      "y": 1,
      "z": -4,
      "name": "Furniture_Village_Crate"
    },
    {
      "x": 3,
      "y": 5,
      "z": -4,
      "name": "Wood_Softwood_Stairs",
      "rotation": 11
    },
    {
      "x": 3,
      "y": 6,
      "z": -4,
      "name": "Wood_Softwood_Roof",
      "rotation": 3
    },
    {
      "x": 3,
      "y": 0,
      "z": -3,
      "name": "Wood_Softwood_Planks"
    },
    {
      "x": 3,
      "y": 1,
      "z": -3,
      "name": "Furniture_Tavern_Barrel",
      "support": 15
    },
    {
      "x": 3,
      "y": 5,
      "z": -3,
      "name": "Wood_Softwood_Stairs",
      "rotation": 11
    },
    {
      "x": 3,
      "y": 6,
      "z": -3,
      "name": "Wood_Softwood_Roof",
      "rotation": 3
    },
    {
      "x": 3,
      "y": 0,
      "z": -2,
      "name": "Rock_Stone_Cobble"
    },
    {
      "x": 3,
      "y": 1,
      "z": -2,
      "name": "Rock_Stone_Brick"
    },
    {
      "x": 3,
      "y": 2,
      "z": -2,
      "name": "*Wood_Village_Wall_Full_State_Definitions_Bottom"
    },
    {
      "x": 3,
      "y": 3,
      "z": -2,
      "name": "*Wood_Village_Wall_Full_State_Definitions_Top"
    },
    {
      "x": 3,
      "y": 4,
      "z": -2,
      "name": "Wood_Beech_Trunk",
      "support": 15,
      "rotation": 5
    },
    {
      "x": 3,
      "y": 5,
      "z": -2,
      "name": "Wood_Village_Wall_Full"
    },
    {
      "x": 3,
      "y": 6,
      "z": -2,
      "name": "Wood_Softwood_Roof",
      "rotation": 3
    },
    {
      "x": 3,
      "y": 0,
      "z": -1,
      "name": "Rock_Stone_Cobble"
    },
    {
      "x": 3,
      "y": 3,
      "z": -1,
      "name": "Plant_Vine_Wall",
      "support": 15
    },
    {
      "x": 3,
      "y": 5,
      "z": -1,
      "name": "Wood_Softwood_Stairs",
      "rotation": 11
    },
    {
      "x": 3,
      "y": 6,
      "z": -1,
      "name": "Wood_Softwood_Roof",
      "rotation": 3
    },
    {
      "x": 4,
      "y": 0,
      "z": -9,
      "name": "Rock_Stone_Cobble"
    },
    {
      "x": 4,
      "y": 4,
      "z": -9,
      "name": "Wood_Beech_Branch_Short",
      "support": 15,
      "rotation": 2
    },
    {
      "x": 4,
      "y": 6,
      "z": -9,
      "name": "Wood_Softwood_Stairs",
      "rotation": 11
    },
    {
      "x": 4,
      "y": 7,
      "z": -9,
      "name": "Wood_Softwood_Roof_Flat"
    },
    {
      "x": 4,
      "y": 0,
      "z": -8,
      "name": "Rock_Stone_Cobble"
    },
    {
      "x": 4,
      "y": 1,
      "z": -8,
      "name": "Rock_Stone_Brick"
    },
    {
      "x": 4,
      "y": 2,
      "z": -8,
      "name": "Furniture_Village_Window"
    },
    {
      "x": 4,
      "y": 3,
      "z": -8,
      "name": "Furniture_Village_Window"
    },
    {
      "x": 4,
      "y": 4,
      "z": -8,
      "name": "Wood_Beech_Trunk",
      "support": 15,
      "rotation": 5
    },
    {
      "x": 4,
      "y": 5,
      "z": -8,
      "name": "*Wood_Village_Wall_Full_State_Definitions_Bottom"
    },
    {
      "x": 4,
      "y": 6,
      "z": -8,
      "name": "*Wood_Village_Wall_Full_State_Definitions_Top"
    },
    {
      "x": 4,
      "y": 7,
      "z": -8,
      "name": "Wood_Softwood_Roof_Flat"
    },
    {
      "x": 4,
      "y": 0,
      "z": -7,
      "name": "Wood_Softwood_Planks"
    },
    {
      "x": 4,
      "y": 6,
      "z": -7,
      "name": "Wood_Softwood_Stairs",
      "rotation": 11
    },
    {
      "x": 4,
      "y": 7,
      "z": -7,
      "name": "Wood_Softwood_Roof_Flat"
    },
    {
      "x": 4,
      "y": 0,
      "z": -6,
      "name": "Wood_Softwood_Planks"
    },
    {
      "x": 4,
      "y": 6,
      "z": -6,
      "name": "Wood_Softwood_Stairs",
      "rotation": 11
    },
    {
      "x": 4,
      "y": 7,
      "z": -6,
      "name": "Wood_Softwood_Roof_Flat"
    },
    {
      "x": 4,
      "y": 8,
      "z": -6,
      "name": "Cloth_Block_Wool_Black"
    },
    {
      "x": 4,
      "y": 9,
      "z": -6,
      "name": "Cloth_Block_Wool_Black"
    },
    {
      "x": 4,
      "y": 10,
      "z": -6,
      "name": "Cloth_Block_Wool_Black"
    },
    {
      "x": 4,
      "y": 0,
      "z": -5,
      "name": "Wood_Softwood_Planks"
    },
    {
      "x": 4,
      "y": 1,
      "z": -5,
      "name": "Wood_Deadwood_Planks"
    },
    {
      "x": 4,
      "y": 2,
      "z": -5,
      "name": "Aetherhaven_Shop_Spot",
      "components": {
        "Components": {
          "AetherhavenShopSpotBlock": {
            "SpotId": "3ce1e2d4-8cc0-4ae0-911e-7bc29474adfd",
            "TownId": "d87b9d18-a6de-42a7-9697-90f4c2aa0d9f",
            "PlotId": "e9019450-8a66-4d6f-97e2-0ae8922cd2db",
            "PlayerControlled": false,
            "LootTableId": "pyro_powder",
            "Configured": true
          },
          "PlacedByInteraction": {
            "WhoPlacedUuid": {
              "$binary": "v7RyWIT/TYKnXA2XcxdQtw==",
              "$type": "04"
            }
          }
        }
      }
    },
    {
      "x": 4,
      "y": 6,
      "z": -5,
      "name": "Wood_Softwood_Stairs",
      "rotation": 11
    },
    {
      "x": 4,
      "y": 7,
      "z": -5,
      "name": "Wood_Softwood_Roof_Flat"
    },
    {
      "x": 4,
      "y": 8,
      "z": -5,
      "name": "Cloth_Block_Wool_Black"
    },
    {
      "x": 4,
      "y": 9,
      "z": -5,
      "name": "Cloth_Block_Wool_Black"
    },
    {
      "x": 4,
      "y": 10,
      "z": -5,
      "name": "Cloth_Block_Wool_Black"
    },
    {
      "x": 4,
      "y": 14,
      "z": -5,
      "name": "Cloth_Block_Wool_Orange"
    },
    {
      "x": 4,
      "y": 0,
      "z": -4,
      "name": "Wood_Softwood_Planks"
    },
    {
      "x": 4,
      "y": 6,
      "z": -4,
      "name": "Wood_Softwood_Stairs",
      "rotation": 11
    },
    {
      "x": 4,
      "y": 7,
      "z": -4,
      "name": "Wood_Softwood_Roof_Flat"
    },
    {
      "x": 4,
      "y": 8,
      "z": -4,
      "name": "Cloth_Block_Wool_Black"
    },
    {
      "x": 4,
      "y": 9,
      "z": -4,
      "name": "Cloth_Block_Wool_Black"
    },
    {
      "x": 4,
      "y": 10,
      "z": -4,
      "name": "Cloth_Block_Wool_Black"
    },
    {
      "x": 4,
      "y": 0,
      "z": -3,
      "name": "Wood_Softwood_Planks"
    },
    {
      "x": 4,
      "y": 6,
      "z": -3,
      "name": "Wood_Softwood_Stairs",
      "rotation": 11
    },
    {
      "x": 4,
      "y": 7,
      "z": -3,
      "name": "Wood_Softwood_Roof_Flat"
    },
    {
      "x": 4,
      "y": 0,
      "z": -2,
      "name": "Rock_Stone_Cobble"
    },
    {
      "x": 4,
      "y": 1,
      "z": -2,
      "name": "Rock_Stone_Brick_Mossy"
    },
    {
      "x": 4,
      "y": 2,
      "z": -2,
      "name": "Furniture_Village_Window"
    },
    {
      "x": 4,
      "y": 3,
      "z": -2,
      "name": "Furniture_Village_Window"
    },
    {
      "x": 4,
      "y": 4,
      "z": -2,
      "name": "Wood_Beech_Trunk",
      "support": 15,
      "rotation": 5
    },
    {
      "x": 4,
      "y": 5,
      "z": -2,
      "name": "*Wood_Village_Wall_Full_State_Definitions_Bottom"
    },
    {
      "x": 4,
      "y": 6,
      "z": -2,
      "name": "*Wood_Village_Wall_Full_State_Definitions_Top"
    },
    {
      "x": 4,
      "y": 7,
      "z": -2,
      "name": "Wood_Softwood_Roof_Flat"
    },
    {
      "x": 4,
      "y": 0,
      "z": -1,
      "name": "Rock_Stone_Cobble"
    },
    {
      "x": 4,
      "y": 4,
      "z": -1,
      "name": "Wood_Beech_Branch_Short",
      "support": 15
    },
    {
      "x": 4,
      "y": 6,
      "z": -1,
      "name": "Wood_Softwood_Stairs",
      "rotation": 11
    },
    {
      "x": 4,
      "y": 7,
      "z": -1,
      "name": "Wood_Softwood_Roof_Flat"
    },
    {
      "x": 5,
      "y": 0,
      "z": -9,
      "name": "Rock_Stone_Cobble"
    },
    {
      "x": 5,
      "y": 6,
      "z": -9,
      "name": "Wood_Softwood_Planks_Half",
      "rotation": 8
    },
    {
      "x": 5,
      "y": 7,
      "z": -9,
      "name": "Wood_Softwood_Roof_Flat"
    },
    {
      "x": 5,
      "y": 0,
      "z": -8,
      "name": "Rock_Stone_Cobble"
    },
    {
      "x": 5,
      "y": 1,
      "z": -8,
      "name": "Rock_Stone_Brick"
    },
    {
      "x": 5,
      "y": 2,
      "z": -8,
      "name": "Furniture_Village_Window"
    },
    {
      "x": 5,
      "y": 3,
      "z": -8,
      "name": "Furniture_Village_Window"
    },
    {
      "x": 5,
      "y": 4,
      "z": -8,
      "name": "Wood_Beech_Trunk",
      "support": 15,
      "rotation": 5
    },
    {
      "x": 5,
      "y": 5,
      "z": -8,
      "name": "Furniture_Village_Window"
    },
    {
      "x": 5,
      "y": 6,
      "z": -8,
      "name": "Wood_Village_Wall_Full"
    },
    {
      "x": 5,
      "y": 7,
      "z": -8,
      "name": "Wood_Softwood_Roof_Flat"
    },
    {
      "x": 5,
      "y": 0,
      "z": -7,
      "name": "Wood_Softwood_Planks"
    },
    {
      "x": 5,
      "y": 6,
      "z": -7,
      "name": "Wood_Softwood_Planks_Half",
      "rotation": 8
    },
    {
      "x": 5,
      "y": 7,
      "z": -7,
      "name": "Wood_Softwood_Roof_Flat",
      "rotation": 2
    },
    {
      "x": 5,
      "y": 8,
      "z": -7,
      "name": "Cloth_Block_Wool_Black"
    },
    {
      "x": 5,
      "y": 9,
      "z": -7,
      "name": "Cloth_Block_Wool_Black"
    },
    {
      "x": 5,
      "y": 10,
      "z": -7,
      "name": "Cloth_Block_Wool_Black"
    },
    {
      "x": 5,
      "y": 0,
      "z": -6,
      "name": "Wood_Softwood_Planks"
    },
    {
      "x": 5,
      "y": 6,
      "z": -6,
      "name": "Wood_Softwood_Planks_Half",
      "rotation": 8
    },
    {
      "x": 5,
      "y": 7,
      "z": -6,
      "name": "Cloth_Block_Wool_Black"
    },
    {
      "x": 5,
      "y": 8,
      "z": -6,
      "name": "Cloth_Block_Wool_Black"
    },
    {
      "x": 5,
      "y": 10,
      "z": -6,
      "name": "Cloth_Block_Wool_Black"
    },
    {
      "x": 5,
      "y": 11,
      "z": -6,
      "name": "Cloth_Block_Wool_Black"
    },
    {
      "x": 5,
      "y": 0,
      "z": -5,
      "name": "Wood_Softwood_Planks"
    },
    {
      "x": 5,
      "y": 1,
      "z": -5,
      "name": "Wood_Deadwood_Planks"
    },
    {
      "x": 5,
      "y": 2,
      "z": -5,
      "name": "Aetherhaven_Shop_Spot",
      "components": {
        "Components": {
          "AetherhavenShopSpotBlock": {
            "SpotId": "d084f524-910f-4218-ae20-de82d3e82606",
            "TownId": "d87b9d18-a6de-42a7-9697-90f4c2aa0d9f",
            "PlotId": "e9019450-8a66-4d6f-97e2-0ae8922cd2db",
            "PlayerControlled": false,
            "LootTableId": "pyro_bomb",
            "Configured": true
          },
          "PlacedByInteraction": {
            "WhoPlacedUuid": {
              "$binary": "v7RyWIT/TYKnXA2XcxdQtw==",
              "$type": "04"
            }
          }
        }
      }
    },
    {
      "x": 5,
      "y": 6,
      "z": -5,
      "name": "Wood_Softwood_Planks_Half",
      "rotation": 8
    },
    {
      "x": 5,
      "y": 7,
      "z": -5,
      "name": "Cloth_Block_Wool_Black"
    },
    {
      "x": 5,
      "y": 11,
      "z": -5,
      "name": "Cloth_Block_Wool_Black"
    },
    {
      "x": 5,
      "y": 15,
      "z": -5,
      "name": "Cloth_Block_Wool_White"
    },
    {
      "x": 5,
      "y": 0,
      "z": -4,
      "name": "Wood_Softwood_Planks"
    },
    {
      "x": 5,
      "y": 6,
      "z": -4,
      "name": "Wood_Softwood_Planks_Half",
      "rotation": 8
    },
    {
      "x": 5,
      "y": 7,
      "z": -4,
      "name": "Cloth_Block_Wool_Black"
    },
    {
      "x": 5,
      "y": 10,
      "z": -4,
      "name": "Cloth_Block_Wool_Black"
    },
    {
      "x": 5,
      "y": 11,
      "z": -4,
      "name": "Cloth_Block_Wool_Black"
    },
    {
      "x": 5,
      "y": 0,
      "z": -3,
      "name": "Wood_Softwood_Planks"
    },
    {
      "x": 5,
      "y": 6,
      "z": -3,
      "name": "Wood_Softwood_Planks_Half",
      "rotation": 8
    },
    {
      "x": 5,
      "y": 7,
      "z": -3,
      "name": "Wood_Softwood_Roof_Flat"
    },
    {
      "x": 5,
      "y": 8,
      "z": -3,
      "name": "Cloth_Block_Wool_Black"
    },
    {
      "x": 5,
      "y": 9,
      "z": -3,
      "name": "Cloth_Block_Wool_Black"
    },
    {
      "x": 5,
      "y": 10,
      "z": -3,
      "name": "Cloth_Block_Wool_Black"
    },
    {
      "x": 5,
      "y": 0,
      "z": -2,
      "name": "Rock_Stone_Cobble_Mossy"
    },
    {
      "x": 5,
      "y": 1,
      "z": -2,
      "name": "Rock_Stone_Brick"
    },
    {
      "x": 5,
      "y": 2,
      "z": -2,
      "name": "Furniture_Village_Window"
    },
    {
      "x": 5,
      "y": 3,
      "z": -2,
      "name": "Furniture_Village_Window"
    },
    {
      "x": 5,
      "y": 4,
      "z": -2,
      "name": "Wood_Beech_Trunk",
      "support": 15,
      "rotation": 5
    },
    {
      "x": 5,
      "y": 5,
      "z": -2,
      "name": "Furniture_Village_Window"
    },
    {
      "x": 5,
      "y": 6,
      "z": -2,
      "name": "Wood_Village_Wall_Full"
    },
    {
      "x": 5,
      "y": 7,
      "z": -2,
      "name": "Wood_Softwood_Roof_Flat"
    },
    {
      "x": 5,
      "y": 0,
      "z": -1,
      "name": "Rock_Stone_Cobble_Mossy"
    },
    {
      "x": 5,
      "y": 6,
      "z": -1,
      "name": "Wood_Softwood_Planks_Half",
      "rotation": 8
    },
    {
      "x": 5,
      "y": 7,
      "z": -1,
      "name": "Wood_Softwood_Roof_Flat"
    },
    {
      "x": 6,
      "y": 0,
      "z": -9,
      "name": "Rock_Stone_Cobble_Mossy"
    },
    {
      "x": 6,
      "y": 4,
      "z": -9,
      "name": "Wood_Beech_Branch_Short",
      "support": 15,
      "rotation": 2
    },
    {
      "x": 6,
      "y": 6,
      "z": -9,
      "name": "Wood_Softwood_Planks_Half",
      "rotation": 8
    },
    {
      "x": 6,
      "y": 7,
      "z": -9,
      "name": "Wood_Softwood_Roof_Flat"
    },
    {
      "x": 6,
      "y": 0,
      "z": -8,
      "name": "Rock_Stone_Cobble"
    },
    {
      "x": 6,
      "y": 1,
      "z": -8,
      "name": "Rock_Stone_Brick"
    },
    {
      "x": 6,
      "y": 2,
      "z": -8,
      "name": "*Wood_Village_Wall_Full_State_Definitions_Bottom"
    },
    {
      "x": 6,
      "y": 3,
      "z": -8,
      "name": "*Wood_Village_Wall_Full_State_Definitions_Top"
    },
    {
      "x": 6,
      "y": 4,
      "z": -8,
      "name": "Wood_Beech_Trunk",
      "support": 15,
      "rotation": 5
    },
    {
      "x": 6,
      "y": 5,
      "z": -8,
      "name": "Furniture_Village_Window"
    },
    {
      "x": 6,
      "y": 6,
      "z": -8,
      "name": "Wood_Village_Wall_Full"
    },
    {
      "x": 6,
      "y": 7,
      "z": -8,
      "name": "Wood_Softwood_Roof_Flat"
    },
    {
      "x": 6,
      "y": 8,
      "z": -8,
      "name": "Cloth_Block_Wool_Black"
    },
    {
      "x": 6,
      "y": 9,
      "z": -8,
      "name": "Cloth_Block_Wool_Black"
    },
    {
      "x": 6,
      "y": 10,
      "z": -8,
      "name": "Cloth_Block_Wool_Black"
    },
    {
      "x": 6,
      "y": 0,
      "z": -7,
      "name": "Wood_Softwood_Planks"
    },
    {
      "x": 6,
      "y": 1,
      "z": -7,
      "name": "Wood_Deadwood_Planks"
    },
    {
      "x": 6,
      "y": 2,
      "z": -7,
      "name": "Wood_Deadwood_Stairs",
      "rotation": 3
    },
    {
      "x": 6,
      "y": 6,
      "z": -7,
      "name": "Wood_Softwood_Planks_Half",
      "rotation": 8
    },
    {
      "x": 6,
      "y": 7,
      "z": -7,
      "name": "Cloth_Block_Wool_Black"
    },
    {
      "x": 6,
      "y": 8,
      "z": -7,
      "name": "Cloth_Block_Wool_Black"
    },
    {
      "x": 6,
      "y": 10,
      "z": -7,
      "name": "Cloth_Block_Wool_Black"
    },
    {
      "x": 6,
      "y": 11,
      "z": -7,
      "name": "Cloth_Block_Wool_Black"
    },
    {
      "x": 6,
      "y": 0,
      "z": -6,
      "name": "Wood_Softwood_Planks"
    },
    {
      "x": 6,
      "y": 11,
      "z": -6,
      "name": "Cloth_Block_Wool_Black"
    },
    {
      "x": 6,
      "y": 12,
      "z": -6,
      "name": "Cloth_Block_Wool_Black"
    },
    {
      "x": 6,
      "y": 0,
      "z": -5,
      "name": "Wood_Softwood_Planks"
    },
    {
      "x": 6,
      "y": 1,
      "z": -5,
      "name": "Wood_Deadwood_Planks"
    },
    {
      "x": 6,
      "y": 2,
      "z": -5,
      "name": "Aetherhaven_Shop_Spot",
      "components": {
        "Components": {
          "AetherhavenShopSpotBlock": {
            "SpotId": "03f6a04a-cd68-4b2c-8387-1b71dc28c347",
            "TownId": "d87b9d18-a6de-42a7-9697-90f4c2aa0d9f",
            "PlotId": "e9019450-8a66-4d6f-97e2-0ae8922cd2db",
            "PlayerControlled": false,
            "LootTableId": "pyro_bomb",
            "Configured": true
          },
          "PlacedByInteraction": {
            "WhoPlacedUuid": {
              "$binary": "v7RyWIT/TYKnXA2XcxdQtw==",
              "$type": "04"
            }
          }
        }
      }
    },
    {
      "x": 6,
      "y": 12,
      "z": -5,
      "name": "Cloth_Block_Wool_Black"
    },
    {
      "x": 6,
      "y": 15,
      "z": -5,
      "name": "Cloth_Block_Wool_White"
    },
    {
      "x": 6,
      "y": 0,
      "z": -4,
      "name": "Wood_Softwood_Planks"
    },
    {
      "x": 6,
      "y": 11,
      "z": -4,
      "name": "Cloth_Block_Wool_Black"
    },
    {
      "x": 6,
      "y": 12,
      "z": -4,
      "name": "Cloth_Block_Wool_Black"
    },
    {
      "x": 6,
      "y": 0,
      "z": -3,
      "name": "Wood_Softwood_Planks"
    },
    {
      "x": 6,
      "y": 6,
      "z": -3,
      "name": "Wood_Softwood_Planks_Half",
      "rotation": 8
    },
    {
      "x": 6,
      "y": 7,
      "z": -3,
      "name": "Cloth_Block_Wool_Black"
    },
    {
      "x": 6,
      "y": 8,
      "z": -3,
      "name": "Cloth_Block_Wool_Black"
    },
    {
      "x": 6,
      "y": 10,
      "z": -3,
      "name": "Cloth_Block_Wool_Black"
    },
    {
      "x": 6,
      "y": 11,
      "z": -3,
      "name": "Cloth_Block_Wool_Black"
    },
    {
      "x": 6,
      "y": 0,
      "z": -2,
      "name": "Rock_Stone_Cobble"
    },
    {
      "x": 6,
      "y": 1,
      "z": -2,
      "name": "Rock_Stone_Brick"
    },
    {
      "x": 6,
      "y": 2,
      "z": -2,
      "name": "*Wood_Village_Wall_Full_State_Definitions_Bottom"
    },
    {
      "x": 6,
      "y": 3,
      "z": -2,
      "name": "*Wood_Village_Wall_Full_State_Definitions_Top"
    },
    {
      "x": 6,
      "y": 4,
      "z": -2,
      "name": "Wood_Beech_Trunk",
      "support": 15,
      "rotation": 5
    },
    {
      "x": 6,
      "y": 5,
      "z": -2,
      "name": "Furniture_Village_Window"
    },
    {
      "x": 6,
      "y": 6,
      "z": -2,
      "name": "Wood_Village_Wall_Full"
    },
    {
      "x": 6,
      "y": 7,
      "z": -2,
      "name": "Wood_Softwood_Roof_Flat"
    },
    {
      "x": 6,
      "y": 8,
      "z": -2,
      "name": "Cloth_Block_Wool_Black"
    },
    {
      "x": 6,
      "y": 9,
      "z": -2,
      "name": "Cloth_Block_Wool_Yellow_Light"
    },
    {
      "x": 6,
      "y": 10,
      "z": -2,
      "name": "Cloth_Block_Wool_Black"
    },
    {
      "x": 6,
      "y": 0,
      "z": -1,
      "name": "Rock_Stone_Cobble"
    },
    {
      "x": 6,
      "y": 4,
      "z": -1,
      "name": "Wood_Beech_Branch_Short",
      "support": 15
    },
    {
      "x": 6,
      "y": 6,
      "z": -1,
      "name": "Wood_Softwood_Planks_Half",
      "rotation": 8
    },
    {
      "x": 6,
      "y": 7,
      "z": -1,
      "name": "Wood_Softwood_Roof_Flat"
    },
    {
      "x": 7,
      "y": 0,
      "z": -9,
      "name": "Rock_Stone_Cobble"
    },
    {
      "x": 7,
      "y": 6,
      "z": -9,
      "name": "Wood_Softwood_Planks_Half",
      "rotation": 8
    },
    {
      "x": 7,
      "y": 7,
      "z": -9,
      "name": "Wood_Softwood_Roof_Flat"
    },
    {
      "x": 7,
      "y": 8,
      "z": -9,
      "name": "Cloth_Block_Wool_Black"
    },
    {
      "x": 7,
      "y": 9,
      "z": -9,
      "name": "Cloth_Block_Wool_Black"
    },
    {
      "x": 7,
      "y": 10,
      "z": -9,
      "name": "Cloth_Block_Wool_Black"
    },
    {
      "x": 7,
      "y": 0,
      "z": -8,
      "name": "Rock_Stone_Cobble"
    },
    {
      "x": 7,
      "y": 1,
      "z": -8,
      "name": "Rock_Stone_Brick_Mossy"
    },
    {
      "x": 7,
      "y": 2,
      "z": -8,
      "name": "*Wood_Village_Wall_Full_State_Definitions_Bottom"
    },
    {
      "x": 7,
      "y": 3,
      "z": -8,
      "name": "*Wood_Village_Wall_Full_State_Definitions_Top"
    },
    {
      "x": 7,
      "y": 4,
      "z": -8,
      "name": "Wood_Beech_Trunk",
      "support": 15,
      "rotation": 5
    },
    {
      "x": 7,
      "y": 5,
      "z": -8,
      "name": "*Wood_Village_Wall_Full_State_Definitions_Bottom"
    },
    {
      "x": 7,
      "y": 6,
      "z": -8,
      "name": "*Wood_Village_Wall_Full_State_Definitions_Top"
    },
    {
      "x": 7,
      "y": 7,
      "z": -8,
      "name": "Cloth_Block_Wool_Black"
    },
    {
      "x": 7,
      "y": 8,
      "z": -8,
      "name": "Cloth_Block_Wool_Black"
    },
    {
      "x": 7,
      "y": 10,
      "z": -8,
      "name": "Cloth_Block_Wool_Black"
    },
    {
      "x": 7,
      "y": 11,
      "z": -8,
      "name": "Cloth_Block_Wool_Black"
    },
    {
      "x": 7,
      "y": 0,
      "z": -7,
      "name": "Wood_Softwood_Planks"
    },
    {
      "x": 7,
      "y": 1,
      "z": -7,
      "name": "Wood_Deadwood_Planks"
    },
    {
      "x": 7,
      "y": 2,
      "z": -7,
      "name": "Wood_Deadwood_Stairs",
      "rotation": 11
    },
    {
      "x": 7,
      "y": 3,
      "z": -7,
      "name": "Wood_Deadwood_Planks_Half"
    },
    {
      "x": 7,
      "y": 11,
      "z": -7,
      "name": "Cloth_Block_Wool_Black"
    },
    {
      "x": 7,
      "y": 12,
      "z": -7,
      "name": "Cloth_Block_Wool_Black"
    },
    {
      "x": 7,
      "y": 0,
      "z": -6,
      "name": "Wood_Softwood_Planks"
    },
    {
      "x": 7,
      "y": 4,
      "z": -6,
      "name": "Furniture_Tavern_Chandelier",
      "support": 15,
      "filler": 32767
    },
    {
      "x": 7,
      "y": 5,
      "z": -6,
      "name": "Furniture_Tavern_Chandelier",
      "support": 15,
      "filler": 1023
    },
    {
      "x": 7,
      "y": 12,
      "z": -6,
      "name": "Cloth_Block_Wool_Black"
    },
    {
      "x": 7,
      "y": 0,
      "z": -5,
      "name": "Wood_Softwood_Planks"
    },
    {
      "x": 7,
      "y": 1,
      "z": -5,
      "name": "Furniture_Human_Ruins_Desk",
      "support": 15,
      "filler": 31
    },
    {
      "x": 7,
      "y": 2,
      "z": -5,
      "name": "Aetherhaven_Shop_Spot",
      "components": {
        "Components": {
          "AetherhavenShopSpotBlock": {
            "SpotId": "71f4473f-18d3-425c-855c-e8a94a7f2915",
            "TownId": "d87b9d18-a6de-42a7-9697-90f4c2aa0d9f",
            "PlotId": "e9019450-8a66-4d6f-97e2-0ae8922cd2db",
            "PlayerControlled": false,
            "LootTableId": "pyro_bomb",
            "Configured": true
          },
          "PlacedByInteraction": {
            "WhoPlacedUuid": {
              "$binary": "v7RyWIT/TYKnXA2XcxdQtw==",
              "$type": "04"
            }
          }
        }
      }
    },
    {
      "x": 7,
      "y": 4,
      "z": -5,
      "name": "Furniture_Tavern_Chandelier",
      "support": 15,
      "filler": 31775
    },
    {
      "x": 7,
      "y": 5,
      "z": -5,
      "name": "Furniture_Tavern_Chandelier",
      "support": 15,
      "filler": 31
    },
    {
      "x": 7,
      "y": 12,
      "z": -5,
      "name": "Cloth_Block_Wool_Black"
    },
    {
      "x": 7,
      "y": 14,
      "z": -5,
      "name": "Cloth_Block_Wool_White"
    },
    {
      "x": 7,
      "y": 0,
      "z": -4,
      "name": "Wood_Softwood_Planks"
    },
    {
      "x": 7,
      "y": 4,
      "z": -4,
      "name": "Furniture_Tavern_Chandelier",
      "support": 15,
      "filler": 31807
    },
    {
      "x": 7,
      "y": 5,
      "z": -4,
      "name": "Furniture_Tavern_Chandelier",
      "support": 15,
      "filler": 63
    },
    {
      "x": 7,
      "y": 12,
      "z": -4,
      "name": "Cloth_Block_Wool_Black"
    },
    {
      "x": 7,
      "y": 0,
      "z": -3,
      "name": "Wood_Softwood_Planks"
    },
    {
      "x": 7,
      "y": 11,
      "z": -3,
      "name": "Cloth_Block_Wool_Black"
    },
    {
      "x": 7,
      "y": 12,
      "z": -3,
      "name": "Cloth_Block_Wool_Black"
    },
    {
      "x": 7,
      "y": 0,
      "z": -2,
      "name": "Rock_Stone_Cobble"
    },
    {
      "x": 7,
      "y": 1,
      "z": -2,
      "name": "Rock_Stone_Brick"
    },
    {
      "x": 7,
      "y": 2,
      "z": -2,
      "name": "*Wood_Village_Wall_Full_State_Definitions_Bottom"
    },
    {
      "x": 7,
      "y": 3,
      "z": -2,
      "name": "*Wood_Village_Wall_Full_State_Definitions_Top"
    },
    {
      "x": 7,
      "y": 4,
      "z": -2,
      "name": "Wood_Beech_Trunk",
      "support": 15,
      "rotation": 5
    },
    {
      "x": 7,
      "y": 5,
      "z": -2,
      "name": "*Wood_Village_Wall_Full_State_Definitions_Bottom"
    },
    {
      "x": 7,
      "y": 6,
      "z": -2,
      "name": "*Wood_Village_Wall_Full_State_Definitions_Top"
    },
    {
      "x": 7,
      "y": 7,
      "z": -2,
      "name": "Cloth_Block_Wool_Black"
    },
    {
      "x": 7,
      "y": 8,
      "z": -2,
      "name": "Cloth_Block_Wool_Black"
    },
    {
      "x": 7,
      "y": 10,
      "z": -2,
      "name": "Cloth_Block_Wool_Black"
    },
    {
      "x": 7,
      "y": 11,
      "z": -2,
      "name": "Cloth_Block_Wool_Black"
    },
    {
      "x": 7,
      "y": 0,
      "z": -1,
      "name": "Rock_Stone_Cobble_Mossy"
    },
    {
      "x": 7,
      "y": 6,
      "z": -1,
      "name": "Wood_Softwood_Planks_Half",
      "rotation": 8
    },
    {
      "x": 7,
      "y": 7,
      "z": -1,
      "name": "Cloth_Block_Wool_Yellow_Light"
    },
    {
      "x": 7,
      "y": 8,
      "z": -1,
      "name": "Cloth_Block_Wool_Yellow_Light"
    },
    {
      "x": 7,
      "y": 9,
      "z": -1,
      "name": "Cloth_Block_Wool_Black"
    },
    {
      "x": 7,
      "y": 10,
      "z": -1,
      "name": "Cloth_Block_Wool_Yellow_Light"
    },
    {
      "x": 8,
      "y": 0,
      "z": -9,
      "name": "Rock_Stone_Cobble_Mossy"
    },
    {
      "x": 8,
      "y": 4,
      "z": -9,
      "name": "Wood_Beech_Branch_Short",
      "support": 15,
      "rotation": 2
    },
    {
      "x": 8,
      "y": 6,
      "z": -9,
      "name": "Wood_Softwood_Planks_Half",
      "rotation": 8
    },
    {
      "x": 8,
      "y": 7,
      "z": -9,
      "name": "Wood_Softwood_Roof_Flat"
    },
    {
      "x": 8,
      "y": 8,
      "z": -9,
      "name": "Cloth_Block_Wool_Black"
    },
    {
      "x": 8,
      "y": 9,
      "z": -9,
      "name": "Cloth_Block_Wool_Black"
    },
    {
      "x": 8,
      "y": 10,
      "z": -9,
      "name": "Cloth_Block_Wool_Black"
    },
    {
      "x": 8,
      "y": 0,
      "z": -8,
      "name": "Rock_Stone_Cobble"
    },
    {
      "x": 8,
      "y": 1,
      "z": -8,
      "name": "Wood_Beech_Trunk",
      "support": 15
    },
    {
      "x": 8,
      "y": 2,
      "z": -8,
      "name": "Wood_Beech_Trunk",
      "support": 15
    },
    {
      "x": 8,
      "y": 3,
      "z": -8,
      "name": "Wood_Beech_Trunk",
      "support": 15
    },
    {
      "x": 8,
      "y": 4,
      "z": -8,
      "name": "Wood_Beech_Trunk",
      "support": 15
    },
    {
      "x": 8,
      "y": 5,
      "z": -8,
      "name": "Wood_Beech_Trunk",
      "support": 15
    },
    {
      "x": 8,
      "y": 6,
      "z": -8,
      "name": "Wood_Beech_Trunk",
      "support": 15
    },
    {
      "x": 8,
      "y": 7,
      "z": -8,
      "name": "Cloth_Block_Wool_Black"
    },
    {
      "x": 8,
      "y": 11,
      "z": -8,
      "name": "Cloth_Block_Wool_Black"
    },
    {
      "x": 8,
      "y": 0,
      "z": -7,
      "name": "Wood_Softwood_Planks"
    },
    {
      "x": 8,
      "y": 1,
      "z": -7,
      "name": "Wood_Deadwood_Planks"
    },
    {
      "x": 8,
      "y": 2,
      "z": -7,
      "name": "Aetherhaven_Management_Block",
      "components": {
        "Components": {
          "AetherhavenManagementBlock": {
            "PlotId": "e9019450-8a66-4d6f-97e2-0ae8922cd2db",
            "TownId": "d87b9d18-a6de-42a7-9697-90f4c2aa0d9f"
          }
        }
      }
    },
    {
      "x": 8,
      "y": 3,
      "z": -7,
      "name": "Wood_Deadwood_Planks_Half"
    },
    {
      "x": 8,
      "y": 12,
      "z": -7,
      "name": "Cloth_Block_Wool_Black"
    },
    {
      "x": 8,
      "y": 0,
      "z": -6,
      "name": "Wood_Softwood_Planks"
    },
    {
      "x": 8,
      "y": 4,
      "z": -6,
      "name": "Furniture_Tavern_Chandelier",
      "support": 15,
      "filler": 32736
    },
    {
      "x": 8,
      "y": 5,
      "z": -6,
      "name": "Furniture_Tavern_Chandelier",
      "support": 15,
      "filler": 992
    },
    {
      "x": 8,
      "y": 12,
      "z": -6,
      "name": "Cloth_Block_Wool_Black"
    },
    {
      "x": 8,
      "y": 0,
      "z": -5,
      "name": "Wood_Softwood_Planks"
    },
    {
      "x": 8,
      "y": 1,
      "z": -5,
      "name": "Furniture_Human_Ruins_Desk",
      "support": 15
    },
    {
      "x": 8,
      "y": 2,
      "z": -5,
      "name": "Aetherhaven_Shop_Spot",
      "components": {
        "Components": {
          "AetherhavenShopSpotBlock": {
            "SpotId": "340f48ec-9331-4b5a-92ad-6e29b334ecd2",
            "TownId": "d87b9d18-a6de-42a7-9697-90f4c2aa0d9f",
            "PlotId": "e9019450-8a66-4d6f-97e2-0ae8922cd2db",
            "PlayerControlled": false,
            "LootTableId": "pyro_bomb",
            "Configured": true
          },
          "PlacedByInteraction": {
            "WhoPlacedUuid": {
              "$binary": "v7RyWIT/TYKnXA2XcxdQtw==",
              "$type": "04"
            }
          }
        }
      }
    },
    {
      "x": 8,
      "y": 4,
      "z": -5,
      "name": "Furniture_Tavern_Chandelier",
      "support": 15,
      "filler": 31744
    },
    {
      "x": 8,
      "y": 5,
      "z": -5,
      "name": "Furniture_Tavern_Chandelier",
      "support": 15
    },
    {
      "x": 8,
      "y": 6,
      "z": -5,
      "name": "Deco_Iron_Chain_Small"
    },
    {
      "x": 8,
      "y": 7,
      "z": -5,
      "name": "Deco_Iron_Chain_Small"
    },
    {
      "x": 8,
      "y": 8,
      "z": -5,
      "name": "Deco_Iron_Chain_Small"
    },
    {
      "x": 8,
      "y": 9,
      "z": -5,
      "name": "Deco_Iron_Chain_Small"
    },
    {
      "x": 8,
      "y": 10,
      "z": -5,
      "name": "Deco_Iron_Chain_Small"
    },
    {
      "x": 8,
      "y": 11,
      "z": -5,
      "name": "Deco_Iron_Chain_Small"
    },
    {
      "x": 8,
      "y": 12,
      "z": -5,
      "name": "Cloth_Block_Wool_White"
    },
    {
      "x": 8,
      "y": 13,
      "z": -5,
      "name": "Cloth_Block_Wool_White"
    },
    {
      "x": 8,
      "y": 0,
      "z": -4,
      "name": "Wood_Softwood_Planks"
    },
    {
      "x": 8,
      "y": 4,
      "z": -4,
      "name": "Furniture_Tavern_Chandelier",
      "support": 15,
      "filler": 31776
    },
    {
      "x": 8,
      "y": 5,
      "z": -4,
      "name": "Furniture_Tavern_Chandelier",
      "support": 15,
      "filler": 32
    },
    {
      "x": 8,
      "y": 12,
      "z": -4,
      "name": "Cloth_Block_Wool_Black"
    },
    {
      "x": 8,
      "y": 0,
      "z": -3,
      "name": "Wood_Softwood_Planks"
    },
    {
      "x": 8,
      "y": 12,
      "z": -3,
      "name": "Cloth_Block_Wool_Black"
    },
    {
      "x": 8,
      "y": 0,
      "z": -2,
      "name": "Wood_Softwood_Planks"
    },
    {
      "x": 8,
      "y": 1,
      "z": -2,
      "name": "*Furniture_Village_Door_State_Definitions_CloseDoorOut"
    },
    {
      "x": 8,
      "y": 2,
      "z": -2,
      "name": "*Furniture_Village_Door_State_Definitions_CloseDoorOut",
      "filler": 1024
    },
    {
      "x": 8,
      "y": 3,
      "z": -2,
      "name": "Wood_Village_Wall_Full"
    },
    {
      "x": 8,
      "y": 4,
      "z": -2,
      "name": "Wood_Beech_Trunk",
      "support": 15,
      "rotation": 5
    },
    {
      "x": 8,
      "y": 5,
      "z": -2,
      "name": "Wood_Beech_Trunk",
      "support": 15
    },
    {
      "x": 8,
      "y": 6,
      "z": -2,
      "name": "Wood_Beech_Trunk",
      "support": 15
    },
    {
      "x": 8,
      "y": 7,
      "z": -2,
      "name": "Cloth_Block_Wool_Black"
    },
    {
      "x": 8,
      "y": 11,
      "z": -2,
      "name": "Cloth_Block_Wool_Black"
    },
    {
      "x": 8,
      "y": 0,
      "z": -1,
      "name": "Rock_Stone_Cobble"
    },
    {
      "x": 8,
      "y": 4,
      "z": -1,
      "name": "Wood_Beech_Branch_Short",
      "support": 15
    },
    {
      "x": 8,
      "y": 6,
      "z": -1,
      "name": "Wood_Softwood_Planks_Half",
      "rotation": 8
    },
    {
      "x": 8,
      "y": 7,
      "z": -1,
      "name": "Cloth_Block_Wool_Yellow_Light"
    },
    {
      "x": 8,
      "y": 8,
      "z": -1,
      "name": "Cloth_Block_Wool_Black"
    },
    {
      "x": 8,
      "y": 9,
      "z": -1,
      "name": "Cloth_Block_Wool_Yellow_Light"
    },
    {
      "x": 8,
      "y": 10,
      "z": -1,
      "name": "Cloth_Block_Wool_Yellow_Light"
    },
    {
      "x": 9,
      "y": 0,
      "z": -9,
      "name": "Rock_Stone_Cobble"
    },
    {
      "x": 9,
      "y": 5,
      "z": -9,
      "name": "Plant_Vine_Wall",
      "support": 15,
      "rotation": 2
    },
    {
      "x": 9,
      "y": 6,
      "z": -9,
      "name": "Wood_Softwood_Planks_Half",
      "rotation": 8
    },
    {
      "x": 9,
      "y": 7,
      "z": -9,
      "name": "Wood_Softwood_Roof_Flat"
    },
    {
      "x": 9,
      "y": 8,
      "z": -9,
      "name": "Cloth_Block_Wool_Black"
    },
    {
      "x": 9,
      "y": 9,
      "z": -9,
      "name": "Cloth_Block_Wool_Black"
    },
    {
      "x": 9,
      "y": 10,
      "z": -9,
      "name": "Cloth_Block_Wool_Black"
    },
    {
      "x": 9,
      "y": 0,
      "z": -8,
      "name": "Rock_Stone_Cobble_Mossy"
    },
    {
      "x": 9,
      "y": 1,
      "z": -8,
      "name": "Rock_Stone_Brick"
    },
    {
      "x": 9,
      "y": 2,
      "z": -8,
      "name": "*Wood_Village_Wall_Full_State_Definitions_Bottom"
    },
    {
      "x": 9,
      "y": 3,
      "z": -8,
      "name": "*Wood_Village_Wall_Full_State_Definitions_Top"
    },
    {
      "x": 9,
      "y": 4,
      "z": -8,
      "name": "Wood_Beech_Trunk",
      "support": 15,
      "rotation": 5
    },
    {
      "x": 9,
      "y": 5,
      "z": -8,
      "name": "*Wood_Village_Wall_Full_State_Definitions_Bottom"
    },
    {
      "x": 9,
      "y": 6,
      "z": -8,
      "name": "*Wood_Village_Wall_Full_State_Definitions_Top"
    },
    {
      "x": 9,
      "y": 7,
      "z": -8,
      "name": "Cloth_Block_Wool_Black"
    },
    {
      "x": 9,
      "y": 10,
      "z": -8,
      "name": "Cloth_Block_Wool_Black"
    },
    {
      "x": 9,
      "y": 11,
      "z": -8,
      "name": "Cloth_Block_Wool_Black"
    },
    {
      "x": 9,
      "y": 0,
      "z": -7,
      "name": "Wood_Softwood_Planks"
    },
    {
      "x": 9,
      "y": 1,
      "z": -7,
      "name": "Wood_Deadwood_Planks"
    },
    {
      "x": 9,
      "y": 2,
      "z": -7,
      "name": "Wood_Deadwood_Stairs",
      "rotation": 9
    },
    {
      "x": 9,
      "y": 3,
      "z": -7,
      "name": "Wood_Deadwood_Planks_Half"
    },
    {
      "x": 9,
      "y": 11,
      "z": -7,
      "name": "Cloth_Block_Wool_Black"
    },
    {
      "x": 9,
      "y": 12,
      "z": -7,
      "name": "Cloth_Block_Wool_Black"
    },
    {
      "x": 9,
      "y": 0,
      "z": -6,
      "name": "Wood_Softwood_Planks"
    },
    {
      "x": 9,
      "y": 4,
      "z": -6,
      "name": "Furniture_Tavern_Chandelier",
      "support": 15,
      "filler": 32737
    },
    {
      "x": 9,
      "y": 5,
      "z": -6,
      "name": "Furniture_Tavern_Chandelier",
      "support": 15,
      "filler": 993
    },
    {
      "x": 9,
      "y": 12,
      "z": -6,
      "name": "Cloth_Block_Wool_Black"
    },
    {
      "x": 9,
      "y": 0,
      "z": -5,
      "name": "Wood_Softwood_Planks"
    },
    {
      "x": 9,
      "y": 1,
      "z": -5,
      "name": "Wood_Deadwood_Planks"
    },
    {
      "x": 9,
      "y": 2,
      "z": -5,
      "name": "Aetherhaven_Shop_Spot",
      "components": {
        "Components": {
          "AetherhavenShopSpotBlock": {
            "SpotId": "97a80dc6-e2d2-4be2-9a0a-926e1a60a44d",
            "TownId": "d87b9d18-a6de-42a7-9697-90f4c2aa0d9f",
            "PlotId": "e9019450-8a66-4d6f-97e2-0ae8922cd2db",
            "PlayerControlled": false,
            "LootTableId": "pyro_berry",
            "Configured": true
          },
          "PlacedByInteraction": {
            "WhoPlacedUuid": {
              "$binary": "v7RyWIT/TYKnXA2XcxdQtw==",
              "$type": "04"
            }
          }
        }
      }
    },
    {
      "x": 9,
      "y": 4,
      "z": -5,
      "name": "Furniture_Tavern_Chandelier",
      "support": 15,
      "filler": 31745
    },
    {
      "x": 9,
      "y": 5,
      "z": -5,
      "name": "Furniture_Tavern_Chandelier",
      "support": 15,
      "filler": 1
    },
    {
      "x": 9,
      "y": 12,
      "z": -5,
      "name": "Cloth_Block_Wool_Black"
    },
    {
      "x": 9,
      "y": 0,
      "z": -4,
      "name": "Wood_Softwood_Planks"
    },
    {
      "x": 9,
      "y": 4,
      "z": -4,
      "name": "Furniture_Tavern_Chandelier",
      "support": 15,
      "filler": 31777
    },
    {
      "x": 9,
      "y": 5,
      "z": -4,
      "name": "Furniture_Tavern_Chandelier",
      "support": 15,
      "filler": 33
    },
    {
      "x": 9,
      "y": 12,
      "z": -4,
      "name": "Cloth_Block_Wool_Black"
    },
    {
      "x": 9,
      "y": 0,
      "z": -3,
      "name": "Wood_Softwood_Planks"
    },
    {
      "x": 9,
      "y": 11,
      "z": -3,
      "name": "Cloth_Block_Wool_Black"
    },
    {
      "x": 9,
      "y": 12,
      "z": -3,
      "name": "Cloth_Block_Wool_Black"
    },
    {
      "x": 9,
      "y": 0,
      "z": -2,
      "name": "Rock_Stone_Cobble"
    },
    {
      "x": 9,
      "y": 1,
      "z": -2,
      "name": "Rock_Stone_Brick"
    },
    {
      "x": 9,
      "y": 2,
      "z": -2,
      "name": "*Wood_Village_Wall_Full_State_Definitions_Bottom"
    },
    {
      "x": 9,
      "y": 3,
      "z": -2,
      "name": "*Wood_Village_Wall_Full_State_Definitions_Top"
    },
    {
      "x": 9,
      "y": 4,
      "z": -2,
      "name": "Wood_Beech_Trunk",
      "support": 15,
      "rotation": 5
    },
    {
      "x": 9,
      "y": 5,
      "z": -2,
      "name": "*Wood_Village_Wall_Full_State_Definitions_Bottom"
    },
    {
      "x": 9,
      "y": 6,
      "z": -2,
      "name": "*Wood_Village_Wall_Full_State_Definitions_Top"
    },
    {
      "x": 9,
      "y": 7,
      "z": -2,
      "name": "Cloth_Block_Wool_Black"
    },
    {
      "x": 9,
      "y": 8,
      "z": -2,
      "name": "Cloth_Block_Wool_Black"
    },
    {
      "x": 9,
      "y": 10,
      "z": -2,
      "name": "Cloth_Block_Wool_Black"
    },
    {
      "x": 9,
      "y": 11,
      "z": -2,
      "name": "Cloth_Block_Wool_Black"
    },
    {
      "x": 9,
      "y": 0,
      "z": -1,
      "name": "Rock_Stone_Cobble"
    },
    {
      "x": 9,
      "y": 4,
      "z": -1,
      "name": "Plant_Vine_Wall",
      "support": 15
    },
    {
      "x": 9,
      "y": 6,
      "z": -1,
      "name": "Wood_Softwood_Planks_Half",
      "rotation": 8
    },
    {
      "x": 9,
      "y": 7,
      "z": -1,
      "name": "Cloth_Block_Wool_Yellow_Light"
    },
    {
      "x": 9,
      "y": 8,
      "z": -1,
      "name": "Cloth_Block_Wool_Yellow_Light"
    },
    {
      "x": 9,
      "y": 9,
      "z": -1,
      "name": "Cloth_Block_Wool_Black"
    },
    {
      "x": 9,
      "y": 10,
      "z": -1,
      "name": "Cloth_Block_Wool_Yellow_Light"
    },
    {
      "x": 10,
      "y": 0,
      "z": -9,
      "name": "Rock_Stone_Cobble"
    },
    {
      "x": 10,
      "y": 4,
      "z": -9,
      "name": "Wood_Beech_Branch_Short",
      "support": 15,
      "rotation": 2
    },
    {
      "x": 10,
      "y": 6,
      "z": -9,
      "name": "Wood_Softwood_Planks_Half",
      "rotation": 8
    },
    {
      "x": 10,
      "y": 7,
      "z": -9,
      "name": "Wood_Softwood_Roof_Flat"
    },
    {
      "x": 10,
      "y": 0,
      "z": -8,
      "name": "Rock_Stone_Cobble_Mossy"
    },
    {
      "x": 10,
      "y": 1,
      "z": -8,
      "name": "Rock_Stone_Brick"
    },
    {
      "x": 10,
      "y": 2,
      "z": -8,
      "name": "*Wood_Village_Wall_Full_State_Definitions_Bottom"
    },
    {
      "x": 10,
      "y": 3,
      "z": -8,
      "name": "*Wood_Village_Wall_Full_State_Definitions_Top"
    },
    {
      "x": 10,
      "y": 4,
      "z": -8,
      "name": "Wood_Beech_Trunk",
      "support": 15,
      "rotation": 5
    },
    {
      "x": 10,
      "y": 5,
      "z": -8,
      "name": "Furniture_Village_Window"
    },
    {
      "x": 10,
      "y": 6,
      "z": -8,
      "name": "Wood_Village_Wall_Full"
    },
    {
      "x": 10,
      "y": 7,
      "z": -8,
      "name": "Wood_Softwood_Roof_Flat"
    },
    {
      "x": 10,
      "y": 8,
      "z": -8,
      "name": "Cloth_Block_Wool_Black"
    },
    {
      "x": 10,
      "y": 9,
      "z": -8,
      "name": "Cloth_Block_Wool_Black"
    },
    {
      "x": 10,
      "y": 10,
      "z": -8,
      "name": "Cloth_Block_Wool_Black"
    },
    {
      "x": 10,
      "y": 0,
      "z": -7,
      "name": "Wood_Softwood_Planks"
    },
    {
      "x": 10,
      "y": 1,
      "z": -7,
      "name": "Wood_Deadwood_Planks"
    },
    {
      "x": 10,
      "y": 2,
      "z": -7,
      "name": "Wood_Deadwood_Stairs",
      "rotation": 1
    },
    {
      "x": 10,
      "y": 6,
      "z": -7,
      "name": "Wood_Softwood_Planks_Half",
      "rotation": 8
    },
    {
      "x": 10,
      "y": 7,
      "z": -7,
      "name": "Cloth_Block_Wool_Black"
    },
    {
      "x": 10,
      "y": 8,
      "z": -7,
      "name": "Cloth_Block_Wool_Black"
    },
    {
      "x": 10,
      "y": 10,
      "z": -7,
      "name": "Cloth_Block_Wool_Black"
    },
    {
      "x": 10,
      "y": 11,
      "z": -7,
      "name": "Cloth_Block_Wool_Black"
    },
    {
      "x": 10,
      "y": 0,
      "z": -6,
      "name": "Wood_Softwood_Planks"
    },
    {
      "x": 10,
      "y": 11,
      "z": -6,
      "name": "Cloth_Block_Wool_Black"
    },
    {
      "x": 10,
      "y": 12,
      "z": -6,
      "name": "Cloth_Block_Wool_Black"
    },
    {
      "x": 10,
      "y": 0,
      "z": -5,
      "name": "Wood_Softwood_Planks"
    },
    {
      "x": 10,
      "y": 1,
      "z": -5,
      "name": "Wood_Deadwood_Planks"
    },
    {
      "x": 10,
      "y": 2,
      "z": -5,
      "name": "Aetherhaven_Shop_Spot",
      "components": {
        "Components": {
          "AetherhavenShopSpotBlock": {
            "SpotId": "3ad0c7e2-6d83-4e78-ac54-d88833ad0a05",
            "TownId": "d87b9d18-a6de-42a7-9697-90f4c2aa0d9f",
            "PlotId": "e9019450-8a66-4d6f-97e2-0ae8922cd2db",
            "PlayerControlled": false,
            "LootTableId": "pyro_poison",
            "Configured": true
          },
          "PlacedByInteraction": {
            "WhoPlacedUuid": {
              "$binary": "v7RyWIT/TYKnXA2XcxdQtw==",
              "$type": "04"
            }
          }
        }
      }
    },
    {
      "x": 10,
      "y": 12,
      "z": -5,
      "name": "Cloth_Block_Wool_Black"
    },
    {
      "x": 10,
      "y": 0,
      "z": -4,
      "name": "Wood_Softwood_Planks"
    },
    {
      "x": 10,
      "y": 11,
      "z": -4,
      "name": "Cloth_Block_Wool_Black"
    },
    {
      "x": 10,
      "y": 12,
      "z": -4,
      "name": "Cloth_Block_Wool_Black"
    },
    {
      "x": 10,
      "y": 0,
      "z": -3,
      "name": "Wood_Softwood_Planks"
    },
    {
      "x": 10,
      "y": 6,
      "z": -3,
      "name": "Wood_Softwood_Planks_Half",
      "rotation": 8
    },
    {
      "x": 10,
      "y": 7,
      "z": -3,
      "name": "Cloth_Block_Wool_Black"
    },
    {
      "x": 10,
      "y": 8,
      "z": -3,
      "name": "Cloth_Block_Wool_Black"
    },
    {
      "x": 10,
      "y": 10,
      "z": -3,
      "name": "Cloth_Block_Wool_Black"
    },
    {
      "x": 10,
      "y": 11,
      "z": -3,
      "name": "Cloth_Block_Wool_Black"
    },
    {
      "x": 10,
      "y": 0,
      "z": -2,
      "name": "Rock_Stone_Cobble"
    },
    {
      "x": 10,
      "y": 1,
      "z": -2,
      "name": "Rock_Stone_Brick"
    },
    {
      "x": 10,
      "y": 2,
      "z": -2,
      "name": "*Wood_Village_Wall_Full_State_Definitions_Bottom"
    },
    {
      "x": 10,
      "y": 3,
      "z": -2,
      "name": "*Wood_Village_Wall_Full_State_Definitions_Top"
    },
    {
      "x": 10,
      "y": 4,
      "z": -2,
      "name": "Wood_Beech_Trunk",
      "support": 15,
      "rotation": 5
    },
    {
      "x": 10,
      "y": 5,
      "z": -2,
      "name": "Furniture_Village_Window"
    },
    {
      "x": 10,
      "y": 6,
      "z": -2,
      "name": "Wood_Village_Wall_Full"
    },
    {
      "x": 10,
      "y": 7,
      "z": -2,
      "name": "Wood_Softwood_Roof_Flat"
    },
    {
      "x": 10,
      "y": 8,
      "z": -2,
      "name": "Cloth_Block_Wool_Black"
    },
    {
      "x": 10,
      "y": 9,
      "z": -2,
      "name": "Cloth_Block_Wool_Yellow_Light"
    },
    {
      "x": 10,
      "y": 10,
      "z": -2,
      "name": "Cloth_Block_Wool_Black"
    },
    {
      "x": 10,
      "y": 0,
      "z": -1,
      "name": "Rock_Stone_Cobble"
    },
    {
      "x": 10,
      "y": 4,
      "z": -1,
      "name": "Wood_Beech_Branch_Short",
      "support": 15
    },
    {
      "x": 10,
      "y": 6,
      "z": -1,
      "name": "Wood_Softwood_Planks_Half",
      "rotation": 8
    },
    {
      "x": 10,
      "y": 7,
      "z": -1,
      "name": "Wood_Softwood_Roof_Flat"
    },
    {
      "x": 11,
      "y": 0,
      "z": -9,
      "name": "Rock_Stone_Cobble"
    },
    {
      "x": 11,
      "y": 6,
      "z": -9,
      "name": "Wood_Softwood_Planks_Half",
      "rotation": 8
    },
    {
      "x": 11,
      "y": 7,
      "z": -9,
      "name": "Wood_Softwood_Roof_Flat"
    },
    {
      "x": 11,
      "y": 0,
      "z": -8,
      "name": "Rock_Stone_Cobble"
    },
    {
      "x": 11,
      "y": 1,
      "z": -8,
      "name": "Rock_Stone_Brick"
    },
    {
      "x": 11,
      "y": 2,
      "z": -8,
      "name": "Furniture_Village_Window"
    },
    {
      "x": 11,
      "y": 3,
      "z": -8,
      "name": "Furniture_Village_Window"
    },
    {
      "x": 11,
      "y": 4,
      "z": -8,
      "name": "Wood_Beech_Trunk",
      "support": 15,
      "rotation": 5
    },
    {
      "x": 11,
      "y": 5,
      "z": -8,
      "name": "Furniture_Village_Window"
    },
    {
      "x": 11,
      "y": 6,
      "z": -8,
      "name": "Wood_Village_Wall_Full"
    },
    {
      "x": 11,
      "y": 7,
      "z": -8,
      "name": "Wood_Softwood_Roof_Flat"
    },
    {
      "x": 11,
      "y": 0,
      "z": -7,
      "name": "Wood_Softwood_Planks"
    },
    {
      "x": 11,
      "y": 6,
      "z": -7,
      "name": "Wood_Softwood_Planks_Half",
      "rotation": 8
    },
    {
      "x": 11,
      "y": 7,
      "z": -7,
      "name": "Wood_Softwood_Roof_Flat"
    },
    {
      "x": 11,
      "y": 8,
      "z": -7,
      "name": "Cloth_Block_Wool_Black"
    },
    {
      "x": 11,
      "y": 9,
      "z": -7,
      "name": "Cloth_Block_Wool_Black"
    },
    {
      "x": 11,
      "y": 10,
      "z": -7,
      "name": "Cloth_Block_Wool_Black"
    },
    {
      "x": 11,
      "y": 0,
      "z": -6,
      "name": "Wood_Softwood_Planks"
    },
    {
      "x": 11,
      "y": 6,
      "z": -6,
      "name": "Wood_Softwood_Planks_Half",
      "rotation": 8
    },
    {
      "x": 11,
      "y": 7,
      "z": -6,
      "name": "Cloth_Block_Wool_Black"
    },
    {
      "x": 11,
      "y": 8,
      "z": -6,
      "name": "Cloth_Block_Wool_Black"
    },
    {
      "x": 11,
      "y": 10,
      "z": -6,
      "name": "Cloth_Block_Wool_Black"
    },
    {
      "x": 11,
      "y": 11,
      "z": -6,
      "name": "Cloth_Block_Wool_Black"
    },
    {
      "x": 11,
      "y": 0,
      "z": -5,
      "name": "Wood_Softwood_Planks"
    },
    {
      "x": 11,
      "y": 1,
      "z": -5,
      "name": "Wood_Deadwood_Planks"
    },
    {
      "x": 11,
      "y": 2,
      "z": -5,
      "name": "Aetherhaven_Shop_Spot",
      "components": {
        "Components": {
          "AetherhavenShopSpotBlock": {
            "SpotId": "fc8233da-6c66-41bc-b504-3f36d3bf7bec",
            "TownId": "d87b9d18-a6de-42a7-9697-90f4c2aa0d9f",
            "PlotId": "e9019450-8a66-4d6f-97e2-0ae8922cd2db",
            "PlayerControlled": false,
            "LootTableId": "pyro_stun",
            "Configured": true
          },
          "PlacedByInteraction": {
            "WhoPlacedUuid": {
              "$binary": "v7RyWIT/TYKnXA2XcxdQtw==",
              "$type": "04"
            }
          }
        }
      }
    },
    {
      "x": 11,
      "y": 6,
      "z": -5,
      "name": "Wood_Softwood_Planks_Half",
      "rotation": 8
    },
    {
      "x": 11,
      "y": 7,
      "z": -5,
      "name": "Cloth_Block_Wool_Black"
    },
    {
      "x": 11,
      "y": 11,
      "z": -5,
      "name": "Cloth_Block_Wool_Black"
    },
    {
      "x": 11,
      "y": 0,
      "z": -4,
      "name": "Wood_Softwood_Planks"
    },
    {
      "x": 11,
      "y": 6,
      "z": -4,
      "name": "Wood_Softwood_Planks_Half",
      "rotation": 8
    },
    {
      "x": 11,
      "y": 7,
      "z": -4,
      "name": "Cloth_Block_Wool_Black"
    },
    {
      "x": 11,
      "y": 8,
      "z": -4,
      "name": "Cloth_Block_Wool_Black"
    },
    {
      "x": 11,
      "y": 10,
      "z": -4,
      "name": "Cloth_Block_Wool_Black"
    },
    {
      "x": 11,
      "y": 11,
      "z": -4,
      "name": "Cloth_Block_Wool_Black"
    },
    {
      "x": 11,
      "y": 0,
      "z": -3,
      "name": "Wood_Softwood_Planks"
    },
    {
      "x": 11,
      "y": 6,
      "z": -3,
      "name": "Wood_Softwood_Planks_Half",
      "rotation": 8
    },
    {
      "x": 11,
      "y": 7,
      "z": -3,
      "name": "Wood_Softwood_Roof_Flat"
    },
    {
      "x": 11,
      "y": 8,
      "z": -3,
      "name": "Cloth_Block_Wool_Black"
    },
    {
      "x": 11,
      "y": 9,
      "z": -3,
      "name": "Cloth_Block_Wool_Black"
    },
    {
      "x": 11,
      "y": 10,
      "z": -3,
      "name": "Cloth_Block_Wool_Black"
    },
    {
      "x": 11,
      "y": 0,
      "z": -2,
      "name": "Rock_Stone_Cobble_Mossy"
    },
    {
      "x": 11,
      "y": 1,
      "z": -2,
      "name": "Rock_Stone_Brick_Mossy"
    },
    {
      "x": 11,
      "y": 2,
      "z": -2,
      "name": "Furniture_Village_Window"
    },
    {
      "x": 11,
      "y": 3,
      "z": -2,
      "name": "Furniture_Village_Window"
    },
    {
      "x": 11,
      "y": 4,
      "z": -2,
      "name": "Wood_Beech_Trunk",
      "support": 15,
      "rotation": 5
    },
    {
      "x": 11,
      "y": 5,
      "z": -2,
      "name": "Furniture_Village_Window"
    },
    {
      "x": 11,
      "y": 6,
      "z": -2,
      "name": "Wood_Village_Wall_Full"
    },
    {
      "x": 11,
      "y": 7,
      "z": -2,
      "name": "Wood_Softwood_Roof_Flat"
    },
    {
      "x": 11,
      "y": 0,
      "z": -1,
      "name": "Rock_Stone_Cobble_Mossy"
    },
    {
      "x": 11,
      "y": 6,
      "z": -1,
      "name": "Wood_Softwood_Planks_Half",
      "rotation": 8
    },
    {
      "x": 11,
      "y": 7,
      "z": -1,
      "name": "Wood_Softwood_Roof_Flat"
    },
    {
      "x": 12,
      "y": 0,
      "z": -9,
      "name": "Rock_Stone_Cobble"
    },
    {
      "x": 12,
      "y": 4,
      "z": -9,
      "name": "Wood_Beech_Branch_Short",
      "support": 15,
      "rotation": 2
    },
    {
      "x": 12,
      "y": 6,
      "z": -9,
      "name": "Wood_Softwood_Stairs",
      "rotation": 9
    },
    {
      "x": 12,
      "y": 7,
      "z": -9,
      "name": "Wood_Softwood_Roof_Flat"
    },
    {
      "x": 12,
      "y": 0,
      "z": -8,
      "name": "Rock_Stone_Cobble"
    },
    {
      "x": 12,
      "y": 1,
      "z": -8,
      "name": "Rock_Stone_Brick_Mossy"
    },
    {
      "x": 12,
      "y": 2,
      "z": -8,
      "name": "Furniture_Village_Window"
    },
    {
      "x": 12,
      "y": 3,
      "z": -8,
      "name": "Furniture_Village_Window"
    },
    {
      "x": 12,
      "y": 4,
      "z": -8,
      "name": "Wood_Beech_Trunk",
      "support": 15,
      "rotation": 5
    },
    {
      "x": 12,
      "y": 5,
      "z": -8,
      "name": "*Wood_Village_Wall_Full_State_Definitions_Bottom"
    },
    {
      "x": 12,
      "y": 6,
      "z": -8,
      "name": "*Wood_Village_Wall_Full_State_Definitions_Top"
    },
    {
      "x": 12,
      "y": 7,
      "z": -8,
      "name": "Wood_Softwood_Roof_Flat"
    },
    {
      "x": 12,
      "y": 0,
      "z": -7,
      "name": "Wood_Softwood_Planks"
    },
    {
      "x": 12,
      "y": 6,
      "z": -7,
      "name": "Wood_Softwood_Stairs",
      "rotation": 9
    },
    {
      "x": 12,
      "y": 7,
      "z": -7,
      "name": "Wood_Softwood_Roof_Flat"
    },
    {
      "x": 12,
      "y": 0,
      "z": -6,
      "name": "Wood_Softwood_Planks"
    },
    {
      "x": 12,
      "y": 6,
      "z": -6,
      "name": "Wood_Softwood_Stairs",
      "rotation": 9
    },
    {
      "x": 12,
      "y": 7,
      "z": -6,
      "name": "Wood_Softwood_Roof_Flat"
    },
    {
      "x": 12,
      "y": 8,
      "z": -6,
      "name": "Cloth_Block_Wool_Black"
    },
    {
      "x": 12,
      "y": 9,
      "z": -6,
      "name": "Cloth_Block_Wool_Black"
    },
    {
      "x": 12,
      "y": 10,
      "z": -6,
      "name": "Cloth_Block_Wool_Black"
    },
    {
      "x": 12,
      "y": 0,
      "z": -5,
      "name": "Wood_Softwood_Planks"
    },
    {
      "x": 12,
      "y": 1,
      "z": -5,
      "name": "Wood_Deadwood_Fence_Gate"
    },
    {
      "x": 12,
      "y": 6,
      "z": -5,
      "name": "Wood_Softwood_Stairs",
      "rotation": 9
    },
    {
      "x": 12,
      "y": 7,
      "z": -5,
      "name": "Wood_Softwood_Roof_Flat"
    },
    {
      "x": 12,
      "y": 8,
      "z": -5,
      "name": "Cloth_Block_Wool_Black"
    },
    {
      "x": 12,
      "y": 9,
      "z": -5,
      "name": "Cloth_Block_Wool_Black"
    },
    {
      "x": 12,
      "y": 10,
      "z": -5,
      "name": "Cloth_Block_Wool_Black"
    },
    {
      "x": 12,
      "y": 0,
      "z": -4,
      "name": "Wood_Softwood_Planks"
    },
    {
      "x": 12,
      "y": 6,
      "z": -4,
      "name": "Wood_Softwood_Stairs",
      "rotation": 9
    },
    {
      "x": 12,
      "y": 7,
      "z": -4,
      "name": "Wood_Softwood_Roof_Flat"
    },
    {
      "x": 12,
      "y": 8,
      "z": -4,
      "name": "Cloth_Block_Wool_Black"
    },
    {
      "x": 12,
      "y": 9,
      "z": -4,
      "name": "Cloth_Block_Wool_Black"
    },
    {
      "x": 12,
      "y": 10,
      "z": -4,
      "name": "Cloth_Block_Wool_Black"
    },
    {
      "x": 12,
      "y": 0,
      "z": -3,
      "name": "Wood_Softwood_Planks"
    },
    {
      "x": 12,
      "y": 6,
      "z": -3,
      "name": "Wood_Softwood_Stairs",
      "rotation": 9
    },
    {
      "x": 12,
      "y": 7,
      "z": -3,
      "name": "Wood_Softwood_Roof_Flat"
    },
    {
      "x": 12,
      "y": 0,
      "z": -2,
      "name": "Rock_Stone_Cobble_Mossy"
    },
    {
      "x": 12,
      "y": 1,
      "z": -2,
      "name": "Rock_Stone_Brick"
    },
    {
      "x": 12,
      "y": 2,
      "z": -2,
      "name": "Furniture_Village_Window"
    },
    {
      "x": 12,
      "y": 3,
      "z": -2,
      "name": "Furniture_Village_Window"
    },
    {
      "x": 12,
      "y": 4,
      "z": -2,
      "name": "Wood_Beech_Trunk",
      "support": 15,
      "rotation": 5
    },
    {
      "x": 12,
      "y": 5,
      "z": -2,
      "name": "*Wood_Village_Wall_Full_State_Definitions_Bottom"
    },
    {
      "x": 12,
      "y": 6,
      "z": -2,
      "name": "*Wood_Village_Wall_Full_State_Definitions_Top"
    },
    {
      "x": 12,
      "y": 7,
      "z": -2,
      "name": "Wood_Softwood_Roof_Flat"
    },
    {
      "x": 12,
      "y": 0,
      "z": -1,
      "name": "Rock_Stone_Cobble"
    },
    {
      "x": 12,
      "y": 4,
      "z": -1,
      "name": "Wood_Beech_Branch_Short",
      "support": 15
    },
    {
      "x": 12,
      "y": 6,
      "z": -1,
      "name": "Wood_Softwood_Stairs",
      "rotation": 9
    },
    {
      "x": 12,
      "y": 7,
      "z": -1,
      "name": "Wood_Softwood_Roof_Flat"
    },
    {
      "x": 13,
      "y": 0,
      "z": -9,
      "name": "Rock_Stone_Cobble"
    },
    {
      "x": 13,
      "y": 3,
      "z": -9,
      "name": "Plant_Vine_Wall",
      "support": 15,
      "rotation": 2
    },
    {
      "x": 13,
      "y": 5,
      "z": -9,
      "name": "Wood_Softwood_Stairs",
      "rotation": 9
    },
    {
      "x": 13,
      "y": 6,
      "z": -9,
      "name": "Wood_Softwood_Roof",
      "rotation": 1
    },
    {
      "x": 13,
      "y": 0,
      "z": -8,
      "name": "Rock_Stone_Cobble"
    },
    {
      "x": 13,
      "y": 1,
      "z": -8,
      "name": "Rock_Stone_Brick"
    },
    {
      "x": 13,
      "y": 2,
      "z": -8,
      "name": "*Wood_Village_Wall_Full_State_Definitions_Bottom"
    },
    {
      "x": 13,
      "y": 3,
      "z": -8,
      "name": "*Wood_Village_Wall_Full_State_Definitions_Top"
    },
    {
      "x": 13,
      "y": 4,
      "z": -8,
      "name": "Wood_Beech_Trunk",
      "support": 15,
      "rotation": 5
    },
    {
      "x": 13,
      "y": 5,
      "z": -8,
      "name": "Wood_Village_Wall_Full"
    },
    {
      "x": 13,
      "y": 6,
      "z": -8,
      "name": "Wood_Softwood_Roof",
      "rotation": 1
    },
    {
      "x": 13,
      "y": 0,
      "z": -7,
      "name": "Wood_Softwood_Planks"
    },
    {
      "x": 13,
      "y": 1,
      "z": -7,
      "name": "Furniture_Tavern_Barrel",
      "support": 15
    },
    {
      "x": 13,
      "y": 5,
      "z": -7,
      "name": "Wood_Softwood_Stairs",
      "rotation": 9
    },
    {
      "x": 13,
      "y": 6,
      "z": -7,
      "name": "Wood_Softwood_Roof",
      "rotation": 1
    },
    {
      "x": 13,
      "y": 0,
      "z": -6,
      "name": "Wood_Softwood_Planks"
    },
    {
      "x": 13,
      "y": 5,
      "z": -6,
      "name": "Wood_Softwood_Stairs",
      "rotation": 9
    },
    {
      "x": 13,
      "y": 6,
      "z": -6,
      "name": "Wood_Softwood_Roof",
      "rotation": 1
    },
    {
      "x": 13,
      "y": 0,
      "z": -5,
      "name": "Wood_Softwood_Planks"
    },
    {
      "x": 13,
      "y": 1,
      "z": -5,
      "name": "Wood_Deadwood_Planks"
    },
    {
      "x": 13,
      "y": 2,
      "z": -5,
      "name": "Furniture_Human_Ruins_Candle",
      "support": 15
    },
    {
      "x": 13,
      "y": 3,
      "z": -5,
      "name": "Furniture_Human_Ruins_Candle",
      "support": 15,
      "filler": 1024
    },
    {
      "x": 13,
      "y": 5,
      "z": -5,
      "name": "Wood_Softwood_Stairs",
      "rotation": 9
    },
    {
      "x": 13,
      "y": 6,
      "z": -5,
      "name": "Wood_Softwood_Roof",
      "rotation": 1
    },
    {
      "x": 13,
      "y": 0,
      "z": -4,
      "name": "Wood_Softwood_Planks"
    },
    {
      "x": 13,
      "y": 1,
      "z": -4,
      "name": "Furniture_Tavern_Barrel",
      "support": 15
    },
    {
      "x": 13,
      "y": 5,
      "z": -4,
      "name": "Wood_Softwood_Stairs",
      "rotation": 9
    },
    {
      "x": 13,
      "y": 6,
      "z": -4,
      "name": "Wood_Softwood_Roof",
      "rotation": 1
    },
    {
      "x": 13,
      "y": 0,
      "z": -3,
      "name": "Wood_Softwood_Planks"
    },
    {
      "x": 13,
      "y": 1,
      "z": -3,
      "name": "Furniture_Village_Crate"
    },
    {
      "x": 13,
      "y": 2,
      "z": -3,
      "name": "Furniture_Village_Crate"
    },
    {
      "x": 13,
      "y": 5,
      "z": -3,
      "name": "Wood_Softwood_Stairs",
      "rotation": 9
    },
    {
      "x": 13,
      "y": 6,
      "z": -3,
      "name": "Wood_Softwood_Roof",
      "rotation": 1
    },
    {
      "x": 13,
      "y": 0,
      "z": -2,
      "name": "Rock_Stone_Cobble_Mossy"
    },
    {
      "x": 13,
      "y": 1,
      "z": -2,
      "name": "Rock_Stone_Brick"
    },
    {
      "x": 13,
      "y": 2,
      "z": -2,
      "name": "*Wood_Village_Wall_Full_State_Definitions_Bottom"
    },
    {
      "x": 13,
      "y": 3,
      "z": -2,
      "name": "*Wood_Village_Wall_Full_State_Definitions_Top"
    },
    {
      "x": 13,
      "y": 4,
      "z": -2,
      "name": "Wood_Beech_Trunk",
      "support": 15,
      "rotation": 5
    },
    {
      "x": 13,
      "y": 5,
      "z": -2,
      "name": "Wood_Village_Wall_Full"
    },
    {
      "x": 13,
      "y": 6,
      "z": -2,
      "name": "Wood_Softwood_Roof",
      "rotation": 1
    },
    {
      "x": 13,
      "y": 0,
      "z": -1,
      "name": "Rock_Stone_Cobble"
    },
    {
      "x": 13,
      "y": 5,
      "z": -1,
      "name": "Wood_Softwood_Stairs",
      "rotation": 9
    },
    {
      "x": 13,
      "y": 6,
      "z": -1,
      "name": "Wood_Softwood_Roof",
      "rotation": 1
    },
    {
      "x": 14,
      "y": 0,
      "z": -9,
      "name": "Rock_Stone_Cobble_Mossy"
    },
    {
      "x": 14,
      "y": 4,
      "z": -9,
      "name": "Wood_Beech_Branch_Corner",
      "support": 15,
      "rotation": 2
    },
    {
      "x": 14,
      "y": 5,
      "z": -9,
      "name": "Wood_Softwood_Roof",
      "rotation": 1
    },
    {
      "x": 14,
      "y": 0,
      "z": -8,
      "name": "Rock_Stone_Cobble"
    },
    {
      "x": 14,
      "y": 1,
      "z": -8,
      "name": "Wood_Beech_Trunk",
      "support": 15
    },
    {
      "x": 14,
      "y": 2,
      "z": -8,
      "name": "Wood_Beech_Trunk",
      "support": 15
    },
    {
      "x": 14,
      "y": 3,
      "z": -8,
      "name": "Wood_Beech_Trunk",
      "support": 15
    },
    {
      "x": 14,
      "y": 4,
      "z": -8,
      "name": "Wood_Beech_Trunk",
      "support": 15
    },
    {
      "x": 14,
      "y": 5,
      "z": -8,
      "name": "Wood_Softwood_Roof",
      "rotation": 1
    },
    {
      "x": 14,
      "y": 0,
      "z": -7,
      "name": "Rock_Stone_Cobble"
    },
    {
      "x": 14,
      "y": 1,
      "z": -7,
      "name": "Rock_Stone_Brick"
    },
    {
      "x": 14,
      "y": 2,
      "z": -7,
      "name": "*Wood_Village_Wall_Full_State_Definitions_Bottom"
    },
    {
      "x": 14,
      "y": 3,
      "z": -7,
      "name": "*Wood_Village_Wall_Full_State_Definitions_Top"
    },
    {
      "x": 14,
      "y": 4,
      "z": -7,
      "name": "Wood_Beech_Trunk",
      "support": 15,
      "rotation": 4
    },
    {
      "x": 14,
      "y": 5,
      "z": -7,
      "name": "Wood_Softwood_Roof",
      "rotation": 1
    },
    {
      "x": 14,
      "y": 0,
      "z": -6,
      "name": "Rock_Stone_Cobble"
    },
    {
      "x": 14,
      "y": 1,
      "z": -6,
      "name": "Rock_Stone_Brick_Mossy"
    },
    {
      "x": 14,
      "y": 2,
      "z": -6,
      "name": "Furniture_Village_Window",
      "rotation": 1
    },
    {
      "x": 14,
      "y": 3,
      "z": -6,
      "name": "Furniture_Village_Window",
      "rotation": 1
    },
    {
      "x": 14,
      "y": 4,
      "z": -6,
      "name": "Wood_Beech_Trunk",
      "support": 15,
      "rotation": 4
    },
    {
      "x": 14,
      "y": 5,
      "z": -6,
      "name": "Wood_Softwood_Roof",
      "rotation": 1
    },
    {
      "x": 14,
      "y": 0,
      "z": -5,
      "name": "Rock_Stone_Cobble"
    },
    {
      "x": 14,
      "y": 1,
      "z": -5,
      "name": "Rock_Stone_Brick"
    },
    {
      "x": 14,
      "y": 2,
      "z": -5,
      "name": "*Wood_Village_Wall_Full_State_Definitions_Bottom"
    },
    {
      "x": 14,
      "y": 3,
      "z": -5,
      "name": "*Wood_Village_Wall_Full_State_Definitions_Top"
    },
    {
      "x": 14,
      "y": 4,
      "z": -5,
      "name": "Wood_Beech_Trunk",
      "support": 15,
      "rotation": 4
    },
    {
      "x": 14,
      "y": 5,
      "z": -5,
      "name": "Wood_Softwood_Roof",
      "rotation": 1
    },
    {
      "x": 14,
      "y": 0,
      "z": -4,
      "name": "Rock_Stone_Cobble"
    },
    {
      "x": 14,
      "y": 1,
      "z": -4,
      "name": "Rock_Stone_Brick"
    },
    {
      "x": 14,
      "y": 2,
      "z": -4,
      "name": "Furniture_Village_Window",
      "rotation": 1
    },
    {
      "x": 14,
      "y": 3,
      "z": -4,
      "name": "Furniture_Village_Window",
      "rotation": 1
    },
    {
      "x": 14,
      "y": 4,
      "z": -4,
      "name": "Wood_Beech_Trunk",
      "support": 15,
      "rotation": 4
    },
    {
      "x": 14,
      "y": 5,
      "z": -4,
      "name": "Wood_Softwood_Roof",
      "rotation": 1
    },
    {
      "x": 14,
      "y": 0,
      "z": -3,
      "name": "Rock_Stone_Cobble"
    },
    {
      "x": 14,
      "y": 1,
      "z": -3,
      "name": "Rock_Stone_Brick"
    },
    {
      "x": 14,
      "y": 2,
      "z": -3,
      "name": "*Wood_Village_Wall_Full_State_Definitions_Bottom"
    },
    {
      "x": 14,
      "y": 3,
      "z": -3,
      "name": "*Wood_Village_Wall_Full_State_Definitions_Top"
    },
    {
      "x": 14,
      "y": 4,
      "z": -3,
      "name": "Wood_Beech_Trunk",
      "support": 15,
      "rotation": 4
    },
    {
      "x": 14,
      "y": 5,
      "z": -3,
      "name": "Wood_Softwood_Roof",
      "rotation": 1
    },
    {
      "x": 14,
      "y": 0,
      "z": -2,
      "name": "Rock_Stone_Cobble"
    },
    {
      "x": 14,
      "y": 1,
      "z": -2,
      "name": "Wood_Beech_Trunk",
      "support": 15
    },
    {
      "x": 14,
      "y": 2,
      "z": -2,
      "name": "Wood_Beech_Trunk",
      "support": 15
    },
    {
      "x": 14,
      "y": 3,
      "z": -2,
      "name": "Wood_Beech_Trunk",
      "support": 15
    },
    {
      "x": 14,
      "y": 4,
      "z": -2,
      "name": "Wood_Beech_Trunk",
      "support": 15
    },
    {
      "x": 14,
      "y": 5,
      "z": -2,
      "name": "Wood_Softwood_Roof",
      "rotation": 1
    },
    {
      "x": 14,
      "y": 0,
      "z": -1,
      "name": "Rock_Stone_Cobble"
    },
    {
      "x": 14,
      "y": 2,
      "z": -1,
      "name": "Plant_Vine_Wall",
      "support": 15
    },
    {
      "x": 14,
      "y": 4,
      "z": -1,
      "name": "Wood_Beech_Branch_Corner",
      "support": 15
    },
    {
      "x": 14,
      "y": 5,
      "z": -1,
      "name": "Wood_Softwood_Roof",
      "rotation": 1
    },
    {
      "x": 15,
      "y": 0,
      "z": -9,
      "name": "Rock_Stone_Cobble_Mossy"
    },
    {
      "x": 15,
      "y": 4,
      "z": -9,
      "name": "Wood_Softwood_Roof_Hollow",
      "rotation": 1
    },
    {
      "x": 15,
      "y": 0,
      "z": -8,
      "name": "Rock_Stone_Cobble_Mossy"
    },
    {
      "x": 15,
      "y": 3,
      "z": -8,
      "name": "Wood_Beech_Branch_Corner",
      "support": 15,
      "rotation": 1
    },
    {
      "x": 15,
      "y": 4,
      "z": -8,
      "name": "Wood_Softwood_Roof",
      "rotation": 1
    },
    {
      "x": 15,
      "y": 0,
      "z": -7,
      "name": "Rock_Stone_Cobble"
    },
    {
      "x": 15,
      "y": 4,
      "z": -7,
      "name": "Wood_Softwood_Roof_Hollow",
      "rotation": 1
    },
    {
      "x": 15,
      "y": 0,
      "z": -6,
      "name": "Rock_Stone_Cobble"
    },
    {
      "x": 15,
      "y": 4,
      "z": -6,
      "name": "Wood_Softwood_Roof_Hollow",
      "rotation": 1
    },
    {
      "x": 15,
      "y": 0,
      "z": -5,
      "name": "Rock_Stone_Cobble"
    },
    {
      "x": 15,
      "y": 3,
      "z": -5,
      "name": "Plant_Vine_Wall",
      "support": 15,
      "rotation": 1
    },
    {
      "x": 15,
      "y": 4,
      "z": -5,
      "name": "Wood_Softwood_Roof_Hollow",
      "rotation": 1
    },
    {
      "x": 15,
      "y": 0,
      "z": -4,
      "name": "Rock_Stone_Cobble"
    },
    {
      "x": 15,
      "y": 4,
      "z": -4,
      "name": "Wood_Softwood_Roof_Hollow",
      "rotation": 1
    },
    {
      "x": 15,
      "y": 0,
      "z": -3,
      "name": "Rock_Stone_Cobble"
    },
    {
      "x": 15,
      "y": 4,
      "z": -3,
      "name": "Wood_Softwood_Roof_Hollow",
      "rotation": 1
    },
    {
      "x": 15,
      "y": 0,
      "z": -2,
      "name": "Rock_Stone_Cobble"
    },
    {
      "x": 15,
      "y": 3,
      "z": -2,
      "name": "Wood_Beech_Branch_Corner",
      "support": 15,
      "rotation": 1
    },
    {
      "x": 15,
      "y": 4,
      "z": -2,
      "name": "Wood_Softwood_Roof",
      "rotation": 1
    },
    {
      "x": 15,
      "y": 0,
      "z": -1,
      "name": "Rock_Stone_Cobble"
    },
    {
      "x": 15,
      "y": 4,
      "z": -1,
      "name": "Wood_Softwood_Roof_Hollow",
      "rotation": 1
    }
  ],
  "entities": [
    {
      "Components": {
        "Invulnerable": {},
        "PreventItemMerging": {},
        "Prop": {},
        "Transform": {
          "Position": {
            "X": 7.3764848709106445,
            "Y": 3.5046539306640625,
            "Z": -6.441661834716797
          },
          "Rotation": {
            "Pitch": 0.0,
            "Yaw": -2.796621561050415,
            "Roll": 0.0
          }
        },
        "UUID": {
          "UUID": {
            "$binary": "hNTj4j1pNVKVKxjLzqCVSw==",
            "$type": "04"
          }
        },
        "PreventPickup": {},
        "EntityScale": {
          "Scale": 1.0
        },
        "Item": {
          "Item": {
            "Id": "Weapon_Bomb",
            "Quantity": 1,
            "Durability": 0.0,
            "MaxDurability": 0.0,
            "Quality": 11,
            "OverrideDroppedItemAnimation": true
          },
          "StackDelay": 1.5,
          "PickupDelay": 0.5,
          "PickupThrottle": 0.0,
          "RemovedByPlayerPickup": false
        },
        "PrefabCopyable": {},
        "HeadRotation": {
          "Rotation": {
            "Pitch": 0.0,
            "Yaw": -2.796621561050415,
            "Roll": 0.0
          }
        }
      }
    },
    {
      "Components": {
        "Invulnerable": {},
        "PreventItemMerging": {},
        "Prop": {},
        "Transform": {
          "Position": {
            "X": 7.985733985900879,
            "Y": 3.5046768188476562,
            "Z": -6.4416656494140625
          },
          "Rotation": {
            "Pitch": 0.14999358355998993,
            "Yaw": 2.19307279586792,
            "Roll": 0.10678723454475403
          }
        },
        "UUID": {
          "UUID": {
            "$binary": "jegkzsaCOqC4iZkmVGQGOw==",
            "$type": "04"
          }
        },
        "PreventPickup": {},
        "EntityScale": {
          "Scale": 1.0
        },
        "Item": {
          "Item": {
            "Id": "Weapon_Bomb",
            "Quantity": 1,
            "Durability": 0.0,
            "MaxDurability": 0.0,
            "Quality": 11,
            "OverrideDroppedItemAnimation": true
          },
          "StackDelay": 1.5,
          "PickupDelay": 0.5,
          "PickupThrottle": 0.0,
          "RemovedByPlayerPickup": false
        },
        "PrefabCopyable": {},
        "HeadRotation": {
          "Rotation": {
            "Pitch": 0.14999371767044067,
            "Yaw": 2.1930720806121826,
            "Roll": 0.10678716003894806
          }
        }
      }
    },
    {
      "Components": {
        "Invulnerable": {},
        "PreventItemMerging": {},
        "Prop": {},
        "Transform": {
          "Position": {
            "X": 8.574987411499023,
            "Y": 3.4955291748046875,
            "Z": -6.357368469238281
          },
          "Rotation": {
            "Pitch": 0.0,
            "Yaw": 1.640582799911499,
            "Roll": 0.0
          }
        },
        "UUID": {
          "UUID": {
            "$binary": "9AGHd4gzPLuAb8EjUdmFHQ==",
            "$type": "04"
          }
        },
        "PreventPickup": {},
        "EntityScale": {
          "Scale": 1.0
        },
        "Item": {
          "Item": {
            "Id": "Ingredient_Powder_Boom",
            "Quantity": 1,
            "Durability": 0.0,
            "MaxDurability": 0.0,
            "Quality": 11,
            "OverrideDroppedItemAnimation": true
          },
          "StackDelay": 1.5,
          "PickupDelay": 0.5,
          "PickupThrottle": 0.0,
          "RemovedByPlayerPickup": false
        },
        "PrefabCopyable": {},
        "HeadRotation": {
          "Rotation": {
            "Pitch": 0.0,
            "Yaw": 1.640582799911499,
            "Roll": 0.0
          }
        }
      }
    },
    {
      "Components": {
        "Invulnerable": {},
        "PreventItemMerging": {},
        "Prop": {},
        "Transform": {
          "Position": {
            "X": 8.931035995483398,
            "Y": 3.4932327270507812,
            "Z": -6.491161346435547
          },
          "Rotation": {
            "Pitch": 0.0,
            "Yaw": 1.9978567361831665,
            "Roll": 0.0
          }
        },
        "UUID": {
          "UUID": {
            "$binary": "mmLa9QfhOc+RpcWGSBl09w==",
            "$type": "04"
          }
        },
        "PreventPickup": {},
        "EntityScale": {
          "Scale": 1.0
        },
        "Item": {
          "Item": {
            "Id": "Ingredient_Powder_Boom",
            "Quantity": 1,
            "Durability": 0.0,
            "MaxDurability": 0.0,
            "Quality": 11,
            "OverrideDroppedItemAnimation": true
          },
          "StackDelay": 1.5,
          "PickupDelay": 0.5,
          "PickupThrottle": 0.0,
          "RemovedByPlayerPickup": false
        },
        "PrefabCopyable": {},
        "HeadRotation": {
          "Rotation": {
            "Pitch": 0.0,
            "Yaw": 1.9978563785552979,
            "Roll": 0.0
          }
        }
      }
    },
    {
      "Components": {
        "Invulnerable": {},
        "PreventItemMerging": {},
        "Prop": {},
        "Transform": {
          "Position": {
            "X": 9.61922836303711,
            "Y": 3.5046768188476562,
            "Z": -6.4416656494140625
          },
          "Rotation": {
            "Pitch": -0.030199801549315453,
            "Yaw": 2.8188886642456055,
            "Roll": 0.1674160659313202
          }
        },
        "UUID": {
          "UUID": {
            "$binary": "d//eGg+8NjeF64jBZdsVMQ==",
            "$type": "04"
          }
        },
        "PreventPickup": {},
        "EntityScale": {
          "Scale": 1.0
        },
        "Item": {
          "Item": {
            "Id": "Weapon_Bomb",
            "Quantity": 1,
            "Durability": 0.0,
            "MaxDurability": 0.0,
            "Quality": 11,
            "OverrideDroppedItemAnimation": true
          },
          "StackDelay": 1.5,
          "PickupDelay": 0.5,
          "PickupThrottle": 0.0,
          "RemovedByPlayerPickup": false
        },
        "PrefabCopyable": {},
        "HeadRotation": {
          "Rotation": {
            "Pitch": -0.03019886091351509,
            "Yaw": 2.8188881874084473,
            "Roll": 0.16741614043712616
          }
        }
      }
    }
  ]
}