{
  "version": 8,
  "blockIdVersion": 11,
  "anchorX": 0,
  "anchorY": 0,
  "anchorZ": 0,
  "blocks": [
    {
      "x": 1,
      "y": 4,
      "z": -16,
      "name": "Soil_Dirt"
    },
    {
      "x": 1,
      "y": 7,
      "z": -16,
      "name": "Furniture_Crude_Platform"
    },
    {
      "x": 1,
      "y": 8,
      "z": -16,
      "name": "Rock_Stone"
    },
    {
      "x": 1,
      "y": 9,
      "z": -16,
      "name": "Rubble_Stone"
    },
    {
      "x": 1,
      "y": 4,
      "z": -15,
      "name": "Soil_Dirt"
    },
    {
      "x": 1,
      "y": 7,
      "z": -15,
      "name": "Furniture_Crude_Platform"
    },
    {
      "x": 1,
      "y": 8,
      "z": -15,
      "name": "Deco_Rope_Diagonal",
      "rotation": 3
    },
    {
      "x": 1,
      "y": 4,
      "z": -14,
      "name": "Soil_Dirt"
    },
    {
      "x": 1,
      "y": 7,
      "z": -14,
      "name": "Furniture_Crude_Platform"
    },
    {
      "x": 1,
      "y": 8,
      "z": -14,
      "name": "Rubble_Stone_Medium"
    },
    {
      "x": 1,
      "y": 4,
      "z": -13,
      "name": "Soil_Dirt"
    },
    {
      "x": 2,
      "y": 4,
      "z": -17,
      "name": "Soil_Dirt"
    },
    {
      "x": 2,
      "y": 4,
      "z": -16,
      "name": "Soil_Dirt"
    },
    {
      "x": 2,
      "y": 5,
      "z": -16,
      "name": "Plant_Bush",
      "support": 15
    },
    {
      "x": 2,
      "y": 7,
      "z": -16,
      "name": "Furniture_Crude_Platform"
    },
    {
      "x": 2,
      "y": 8,
      "z": -16,
      "name": "Deco_Rope_Diagonal",
      "rotation": 2
    },
    {
      "x": 2,
      "y": 4,
      "z": -15,
      "name": "Soil_Dirt"
    },
    {
      "x": 2,
      "y": 5,
      "z": -15,
      "name": "Rubble_Stone"
    },
    {
      "x": 2,
      "y": 7,
      "z": -15,
      "name": "Furniture_Crude_Platform"
    },
    {
      "x": 2,
      "y": 8,
      "z": -15,
      "name": "Rock_Basalt_Cobble"
    },
    {
      "x": 2,
      "y": 9,
      "z": -15,
      "name": "Soil_Gravel"
    },
    {
      "x": 2,
      "y": 10,
      "z": -15,
      "name": "Deco_Iron_Chain_Small"
    },
    {
      "x": 2,
      "y": 11,
      "z": -15,
      "name": "Wood_Beech_Trunk_Full",
      "support": 15,
      "rotation": 5
    },
    {
      "x": 2,
      "y": 4,
      "z": -14,
      "name": "Soil_Dirt"
    },
    {
      "x": 2,
      "y": 5,
      "z": -14,
      "name": "Plant_Moss_Rug_Green",
      "support": 15
    },
    {
      "x": 2,
      "y": 7,
      "z": -14,
      "name": "Furniture_Crude_Platform"
    },
    {
      "x": 2,
      "y": 8,
      "z": -14,
      "name": "Deco_Rope_Diagonal"
    },
    {
      "x": 2,
      "y": 4,
      "z": -13,
      "name": "Soil_Dirt"
    },
    {
      "x": 2,
      "y": 5,
      "z": -13,
      "name": "Plant_Moss_Rug_Green",
      "support": 15
    },
    {
      "x": 2,
      "y": 4,
      "z": -12,
      "name": "Soil_Dirt"
    },
    {
      "x": 3,
      "y": 4,
      "z": -17,
      "name": "Soil_Dirt"
    },
    {
      "x": 3,
      "y": 4,
      "z": -16,
      "name": "Soil_Dirt"
    },
    {
      "x": 3,
      "y": 7,
      "z": -16,
      "name": "Furniture_Crude_Platform"
    },
    {
      "x": 3,
      "y": 8,
      "z": -16,
      "name": "Rubble_Stone_Medium"
    },
    {
      "x": 3,
      "y": 4,
      "z": -15,
      "name": "Soil_Dirt"
    },
    {
      "x": 3,
      "y": 7,
      "z": -15,
      "name": "Furniture_Crude_Platform"
    },
    {
      "x": 3,
      "y": 8,
      "z": -15,
      "name": "Deco_Rope_Diagonal",
      "rotation": 1
    },
    {
      "x": 3,
      "y": 11,
      "z": -15,
      "name": "Wood_Beech_Trunk_Full",
      "support": 15,
      "rotation": 5
    },
    {
      "x": 3,
      "y": 4,
      "z": -14,
      "name": "Soil_Dirt"
    },
    {
      "x": 3,
      "y": 5,
      "z": -14,
      "name": "Plant_Moss_Rug_Green",
      "support": 15
    },
    {
      "x": 3,
      "y": 7,
      "z": -14,
      "name": "Furniture_Crude_Platform"
    },
    {
      "x": 3,
      "y": 8,
      "z": -14,
      "name": "Soil_Gravel"
    },
    {
      "x": 3,
      "y": 9,
      "z": -14,
      "name": "Rubble_Stone_Medium"
    },
    {
      "x": 3,
      "y": 4,
      "z": -13,
      "name": "Soil_Dirt"
    },
    {
      "x": 3,
      "y": 4,
      "z": -12,
      "name": "Soil_Dirt"
    },
    {
      "x": 4,
      "y": 4,
      "z": -25,
      "name": "Soil_Dirt"
    },
    {
      "x": 4,
      "y": 5,
      "z": -25,
      "name": "Rubble_Stone"
    },
    {
      "x": 4,
      "y": 4,
      "z": -24,
      "name": "Wood_Softwood_Planks"
    },
    {
      "x": 4,
      "y": 4,
      "z": -23,
      "name": "Wood_Softwood_Planks"
    },
    {
      "x": 4,
      "y": 4,
      "z": -22,
      "name": "Wood_Softwood_Planks"
    },
    {
      "x": 4,
      "y": 4,
      "z": -19,
      "name": "Soil_Dirt"
    },
    {
      "x": 4,
      "y": 4,
      "z": -18,
      "name": "Soil_Dirt"
    },
    {
      "x": 4,
      "y": 4,
      "z": -17,
      "name": "Soil_Dirt"
    },
    {
      "x": 4,
      "y": 5,
      "z": -17,
      "name": "Plant_Moss_Rug_Lime",
      "support": 15
    },
    {
      "x": 4,
      "y": 4,
      "z": -16,
      "name": "Soil_Dirt"
    },
    {
      "x": 4,
      "y": 4,
      "z": -15,
      "name": "Soil_Dirt"
    },
    {
      "x": 4,
      "y": 5,
      "z": -15,
      "name": "Plant_Bush",
      "support": 15
    },
    {
      "x": 4,
      "y": 11,
      "z": -15,
      "name": "Wood_Softwood_Planks_Half",
      "rotation": 8
    },
    {
      "x": 4,
      "y": 12,
      "z": -15,
      "name": "Wood_Softwood_Planks_Half"
    },
    {
      "x": 4,
      "y": 4,
      "z": -14,
      "name": "Soil_Dirt"
    },
    {
      "x": 4,
      "y": 4,
      "z": -13,
      "name": "Soil_Dirt"
    },
    {
      "x": 4,
      "y": 5,
      "z": -13,
      "name": "Plant_Bush",
      "support": 15
    },
    {
      "x": 4,
      "y": 4,
      "z": -12,
      "name": "Soil_Dirt"
    },
    {
      "x": 4,
      "y": 4,
      "z": -11,
      "name": "Soil_Dirt"
    },
    {
      "x": 5,
      "y": 4,
      "z": -27,
      "name": "Soil_Dirt"
    },
    {
      "x": 5,
      "y": 5,
      "z": -27,
      "name": "Cloth_Roof_Orange",
      "rotation": 2
    },
    {
      "x": 5,
      "y": 4,
      "z": -26,
      "name": "Wood_Softwood_Planks"
    },
    {
      "x": 5,
      "y": 6,
      "z": -26,
      "name": "Cloth_Roof_Orange",
      "rotation": 2
    },
    {
      "x": 5,
      "y": 4,
      "z": -25,
      "name": "Wood_Softwood_Planks"
    },
    {
      "x": 5,
      "y": 7,
      "z": -25,
      "name": "Cloth_Roof_Orange",
      "rotation": 2
    },
    {
      "x": 5,
      "y": 4,
      "z": -24,
      "name": "Wood_Softwood_Planks"
    },
    {
      "x": 5,
      "y": 5,
      "z": -24,
      "name": "Wood_Beech_Branch_Long"
    },
    {
      "x": 5,
      "y": 6,
      "z": -24,
      "name": "Wood_Softwood_Beam"
    },
    {
      "x": 5,
      "y": 7,
      "z": -24,
      "name": "Wood_Softwood_Beam"
    },
    {
      "x": 5,
      "y": 8,
      "z": -24,
      "name": "Cloth_Roof_Orange_Flat"
    },
    {
      "x": 5,
      "y": 4,
      "z": -23,
      "name": "Wood_Softwood_Planks"
    },
    {
      "x": 5,
      "y": 7,
      "z": -23,
      "name": "Cloth_Roof_Orange"
    },
    {
      "x": 5,
      "y": 4,
      "z": -22,
      "name": "Wood_Softwood_Planks"
    },
    {
      "x": 5,
      "y": 6,
      "z": -22,
      "name": "Cloth_Roof_Orange"
    },
    {
      "x": 5,
      "y": 4,
      "z": -21,
      "name": "Wood_Softwood_Planks"
    },
    {
      "x": 5,
      "y": 5,
      "z": -21,
      "name": "Cloth_Roof_Orange"
    },
    {
      "x": 5,
      "y": 4,
      "z": -20,
      "name": "Soil_Dirt"
    },
    {
      "x": 5,
      "y": 4,
      "z": -19,
      "name": "Soil_Dirt"
    },
    {
      "x": 5,
      "y": 5,
      "z": -19,
      "name": "Plant_Bush",
      "support": 15
    },
    {
      "x": 5,
      "y": 4,
      "z": -18,
      "name": "Soil_Dirt"
    },
    {
      "x": 5,
      "y": 4,
      "z": -17,
      "name": "Soil_Dirt"
    },
    {
      "x": 5,
      "y": 5,
      "z": -17,
      "name": "Wood_Beech_Trunk",
      "support": 15
    },
    {
      "x": 5,
      "y": 6,
      "z": -17,
      "name": "Wood_Beech_Trunk",
      "support": 15
    },
    {
      "x": 5,
      "y": 7,
      "z": -17,
      "name": "Wood_Beech_Trunk",
      "support": 15
    },
    {
      "x": 5,
      "y": 8,
      "z": -17,
      "name": "Wood_Beech_Trunk",
      "support": 15
    },
    {
      "x": 5,
      "y": 4,
      "z": -16,
      "name": "Soil_Dirt"
    },
    {
      "x": 5,
      "y": 7,
      "z": -16,
      "name": "Wood_Beech_Branch_Long",
      "support": 15,
      "rotation": 4
    },
    {
      "x": 5,
      "y": 8,
      "z": -16,
      "name": "Wood_Softwood_Planks_Half"
    },
    {
      "x": 5,
      "y": 4,
      "z": -15,
      "name": "Soil_Dirt"
    },
    {
      "x": 5,
      "y": 7,
      "z": -15,
      "name": "Wood_Beech_Branch_Long",
      "support": 15,
      "rotation": 4
    },
    {
      "x": 5,
      "y": 8,
      "z": -15,
      "name": "Wood_Softwood_Planks_Half"
    },
    {
      "x": 5,
      "y": 11,
      "z": -15,
      "name": "Wood_Softwood_Planks_Half",
      "rotation": 8
    },
    {
      "x": 5,
      "y": 12,
      "z": -15,
      "name": "Wood_Softwood_Planks_Half"
    },
    {
      "x": 5,
      "y": 4,
      "z": -14,
      "name": "Soil_Dirt"
    },
    {
      "x": 5,
      "y": 7,
      "z": -14,
      "name": "Wood_Beech_Branch_Long",
      "support": 15,
      "rotation": 4
    },
    {
      "x": 5,
      "y": 8,
      "z": -14,
      "name": "Wood_Softwood_Planks_Half"
    },
    {
      "x": 5,
      "y": 4,
      "z": -13,
      "name": "Soil_Dirt"
    },
    {
      "x": 5,
      "y": 5,
      "z": -13,
      "name": "Wood_Beech_Trunk",
      "support": 15
    },
    {
      "x": 5,
      "y": 6,
      "z": -13,
      "name": "Wood_Beech_Trunk",
      "support": 15
    },
    {
      "x": 5,
      "y": 7,
      "z": -13,
      "name": "Wood_Beech_Trunk",
      "support": 15
    },
    {
      "x": 5,
      "y": 8,
      "z": -13,
      "name": "Wood_Beech_Trunk",
      "support": 15
    },
    {
      "x": 5,
      "y": 4,
      "z": -12,
      "name": "Soil_Dirt"
    },
    {
      "x": 5,
      "y": 5,
      "z": -12,
      "name": "Rubble_Stone_Mossy_Medium",
      "support": 15
    },
    {
      "x": 5,
      "y": 4,
      "z": -11,
      "name": "Soil_Dirt"
    },
    {
      "x": 6,
      "y": 4,
      "z": -27,
      "name": "Wood_Softwood_Planks"
    },
    {
      "x": 6,
      "y": 5,
      "z": -27,
      "name": "Cloth_Roof_Orange",
      "rotation": 2
    },
    {
      "x": 6,
      "y": 4,
      "z": -26,
      "name": "Wood_Softwood_Planks"
    },
    {
      "x": 6,
      "y": 5,
      "z": -26,
      "name": "Furniture_Tavern_Barrel"
    },
    {
      "x": 6,
      "y": 6,
      "z": -26,
      "name": "Cloth_Roof_Orange",
      "rotation": 2
    },
    {
      "x": 6,
      "y": 4,
      "z": -25,
      "name": "Wood_Softwood_Planks"
    },
    {
      "x": 6,
      "y": 7,
      "z": -25,
      "name": "Cloth_Roof_Orange",
      "rotation": 2
    },
    {
      "x": 6,
      "y": 4,
      "z": -24,
      "name": "Wood_Softwood_Planks"
    },
    {
      "x": 6,
      "y": 8,
      "z": -24,
      "name": "Cloth_Roof_Orange_Flat"
    },
    {
      "x": 6,
      "y": 4,
      "z": -23,
      "name": "Wood_Softwood_Planks"
    },
    {
      "x": 6,
      "y": 5,
      "z": -23,
      "name": "Furniture_Village_Crate"
    },
    {
      "x": 6,
      "y": 6,
      "z": -23,
      "name": "Furniture_Crude_Stool",
      "rotation": 1
    },
    {
      "x": 6,
      "y": 7,
      "z": -23,
      "name": "Cloth_Roof_Orange"
    },
    {
      "x": 6,
      "y": 4,
      "z": -22,
      "name": "Wood_Softwood_Planks"
    },
    {
      "x": 6,
      "y": 5,
      "z": -22,
      "name": "Furniture_Village_Crate"
    },
    {
      "x": 6,
      "y": 6,
      "z": -22,
      "name": "Cloth_Roof_Orange"
    },
    {
      "x": 6,
      "y": 4,
      "z": -21,
      "name": "Wood_Softwood_Planks"
    },
    {
      "x": 6,
      "y": 5,
      "z": -21,
      "name": "Cloth_Roof_Orange"
    },
    {
      "x": 6,
      "y": 4,
      "z": -20,
      "name": "Soil_Dirt"
    },
    {
      "x": 6,
      "y": 5,
      "z": -20,
      "name": "Plant_Moss_Rug_Green",
      "support": 15
    },
    {
      "x": 6,
      "y": 4,
      "z": -19,
      "name": "Soil_Dirt"
    },
    {
      "x": 6,
      "y": 4,
      "z": -18,
      "name": "Soil_Dirt"
    },
    {
      "x": 6,
      "y": 4,
      "z": -17,
      "name": "Soil_Dirt"
    },
    {
      "x": 6,
      "y": 5,
      "z": -17,
      "name": "Aetherhaven_Production_Storage",
      "rotation": 2
    },
    {
      "x": 6,
      "y": 6,
      "z": -17,
      "name": "Aetherhaven_Production_Storage",
      "filler": 1024,
      "rotation": 2
    },
    {
      "x": 6,
      "y": 7,
      "z": -17,
      "name": "Wood_Beech_Branch_Long",
      "support": 15,
      "rotation": 5
    },
    {
      "x": 6,
      "y": 8,
      "z": -17,
      "name": "Wood_Softwood_Planks_Half"
    },
    {
      "x": 6,
      "y": 4,
      "z": -16,
      "name": "Soil_Dirt"
    },
    {
      "x": 6,
      "y": 5,
      "z": -16,
      "name": "Rubble_Stone_Medium"
    },
    {
      "x": 6,
      "y": 8,
      "z": -16,
      "name": "Wood_Softwood_Planks_Half"
    },
    {
      "x": 6,
      "y": 4,
      "z": -15,
      "name": "Soil_Dirt"
    },
    {
      "x": 6,
      "y": 5,
      "z": -15,
      "name": "Rock_Stone"
    },
    {
      "x": 6,
      "y": 6,
      "z": -15,
      "name": "Rock_Stone_Cobble_Half"
    },
    {
      "x": 6,
      "y": 8,
      "z": -15,
      "name": "Wood_Softwood_Planks_Half"
    },
    {
      "x": 6,
      "y": 11,
      "z": -15,
      "name": "Deco_Rope_Diagonal",
      "rotation": 1
    },
    {
      "x": 6,
      "y": 12,
      "z": -15,
      "name": "Wood_Beech_Trunk_Full",
      "support": 15,
      "rotation": 5
    },
    {
      "x": 6,
      "y": 4,
      "z": -14,
      "name": "Soil_Dirt"
    },
    {
      "x": 6,
      "y": 5,
      "z": -14,
      "name": "Rock_Stone_Cobble_Half",
      "rotation": 4
    },
    {
      "x": 6,
      "y": 8,
      "z": -14,
      "name": "Wood_Softwood_Planks_Half"
    },
    {
      "x": 6,
      "y": 4,
      "z": -13,
      "name": "Soil_Dirt"
    },
    {
      "x": 6,
      "y": 7,
      "z": -13,
      "name": "Wood_Beech_Branch_Long",
      "support": 15,
      "rotation": 5
    },
    {
      "x": 6,
      "y": 8,
      "z": -13,
      "name": "Wood_Softwood_Planks_Half"
    },
    {
      "x": 6,
      "y": 4,
      "z": -12,
      "name": "Soil_Dirt"
    },
    {
      "x": 6,
      "y": 5,
      "z": -12,
      "name": "Plant_Moss_Rug_Green",
      "support": 15
    },
    {
      "x": 6,
      "y": 4,
      "z": -11,
      "name": "Soil_Dirt"
    },
    {
      "x": 6,
      "y": 5,
      "z": -11,
      "name": "Plant_Moss_Rug_Green",
      "support": 15
    },
    {
      "x": 7,
      "y": 4,
      "z": -27,
      "name": "Wood_Softwood_Planks"
    },
    {
      "x": 7,
      "y": 5,
      "z": -27,
      "name": "Cloth_Roof_Orange",
      "rotation": 2
    },
    {
      "x": 7,
      "y": 4,
      "z": -26,
      "name": "Wood_Softwood_Planks"
    },
    {
      "x": 7,
      "y": 5,
      "z": -26,
      "name": "Rubble_Stone"
    },
    {
      "x": 7,
      "y": 6,
      "z": -26,
      "name": "Cloth_Roof_Orange",
      "rotation": 2
    },
    {
      "x": 7,
      "y": 4,
      "z": -25,
      "name": "Wood_Softwood_Planks"
    },
    {
      "x": 7,
      "y": 7,
      "z": -25,
      "name": "Cloth_Roof_Orange",
      "rotation": 2
    },
    {
      "x": 7,
      "y": 4,
      "z": -24,
      "name": "Wood_Softwood_Planks"
    },
    {
      "x": 7,
      "y": 8,
      "z": -24,
      "name": "Cloth_Roof_Orange_Flat"
    },
    {
      "x": 7,
      "y": 4,
      "z": -23,
      "name": "Wood_Softwood_Planks"
    },
    {
      "x": 7,
      "y": 7,
      "z": -23,
      "name": "Cloth_Roof_Orange"
    },
    {
      "x": 7,
      "y": 4,
      "z": -22,
      "name": "Wood_Softwood_Planks"
    },
    {
      "x": 7,
      "y": 5,
      "z": -22,
      "name": "Furniture_Village_Crate"
    },
    {
      "x": 7,
      "y": 6,
      "z": -22,
      "name": "Cloth_Roof_Orange"
    },
    {
      "x": 7,
      "y": 4,
      "z": -21,
      "name": "Wood_Softwood_Planks"
    },
    {
      "x": 7,
      "y": 5,
      "z": -21,
      "name": "Cloth_Roof_Orange"
    },
    {
      "x": 7,
      "y": 4,
      "z": -20,
      "name": "Soil_Dirt"
    },
    {
      "x": 7,
      "y": 4,
      "z": -19,
      "name": "Soil_Dirt"
    },
    {
      "x": 7,
      "y": 5,
      "z": -19,
      "name": "Plant_Moss_Rug_Green",
      "support": 15
    },
    {
      "x": 7,
      "y": 4,
      "z": -18,
      "name": "Soil_Dirt"
    },
    {
      "x": 7,
      "y": 4,
      "z": -17,
      "name": "Soil_Dirt"
    },
    {
      "x": 7,
      "y": 5,
      "z": -17,
      "name": "Aetherhaven_Production_Storage",
      "filler": 1,
      "rotation": 2
    },
    {
      "x": 7,
      "y": 6,
      "z": -17,
      "name": "Aetherhaven_Production_Storage",
      "filler": 1025,
      "rotation": 2
    },
    {
      "x": 7,
      "y": 7,
      "z": -17,
      "name": "Wood_Beech_Branch_Long",
      "support": 15,
      "rotation": 5
    },
    {
      "x": 7,
      "y": 8,
      "z": -17,
      "name": "Wood_Softwood_Planks_Half"
    },
    {
      "x": 7,
      "y": 4,
      "z": -16,
      "name": "Soil_Dirt"
    },
    {
      "x": 7,
      "y": 5,
      "z": -16,
      "name": "Rock_Stone_Cobble_Half"
    },
    {
      "x": 7,
      "y": 8,
      "z": -16,
      "name": "Wood_Softwood_Planks_Half"
    },
    {
      "x": 7,
      "y": 12,
      "z": -16,
      "name": "Wood_Beech_Branch_Long",
      "support": 15,
      "rotation": 4
    },
    {
      "x": 7,
      "y": 4,
      "z": -15,
      "name": "Soil_Dirt"
    },
    {
      "x": 7,
      "y": 5,
      "z": -15,
      "name": "Wood_Beech_Trunk",
      "support": 15
    },
    {
      "x": 7,
      "y": 6,
      "z": -15,
      "name": "Wood_Beech_Trunk",
      "support": 15
    },
    {
      "x": 7,
      "y": 7,
      "z": -15,
      "name": "Wood_Beech_Trunk",
      "support": 15
    },
    {
      "x": 7,
      "y": 8,
      "z": -15,
      "name": "Wood_Beech_Trunk",
      "support": 15
    },
    {
      "x": 7,
      "y": 9,
      "z": -15,
      "name": "Wood_Beech_Trunk",
      "support": 15
    },
    {
      "x": 7,
      "y": 10,
      "z": -15,
      "name": "Wood_Beech_Trunk",
      "support": 15
    },
    {
      "x": 7,
      "y": 11,
      "z": -15,
      "name": "Wood_Beech_Trunk",
      "support": 15
    },
    {
      "x": 7,
      "y": 12,
      "z": -15,
      "name": "Wood_Beech_Trunk_Full",
      "support": 15,
      "rotation": 5
    },
    {
      "x": 7,
      "y": 13,
      "z": -15,
      "name": "Wood_Beech_Trunk_Full",
      "support": 15
    },
    {
      "x": 7,
      "y": 4,
      "z": -14,
      "name": "Soil_Dirt"
    },
    {
      "x": 7,
      "y": 5,
      "z": -14,
      "name": "Rock_Stone"
    },
    {
      "x": 7,
      "y": 6,
      "z": -14,
      "name": "Rock_Basalt_Cobble"
    },
    {
      "x": 7,
      "y": 7,
      "z": -14,
      "name": "Rubble_Stone_Medium"
    },
    {
      "x": 7,
      "y": 8,
      "z": -14,
      "name": "Wood_Softwood_Planks_Half"
    },
    {
      "x": 7,
      "y": 12,
      "z": -14,
      "name": "Wood_Beech_Branch_Long",
      "support": 15,
      "rotation": 4
    },
    {
      "x": 7,
      "y": 4,
      "z": -13,
      "name": "Soil_Gravel"
    },
    {
      "x": 7,
      "y": 5,
      "z": -13,
      "name": "Rubble_Stone"
    },
    {
      "x": 7,
      "y": 7,
      "z": -13,
      "name": "Wood_Beech_Branch_Long",
      "support": 15,
      "rotation": 5
    },
    {
      "x": 7,
      "y": 8,
      "z": -13,
      "name": "Wood_Softwood_Planks_Half"
    },
    {
      "x": 7,
      "y": 4,
      "z": -12,
      "name": "Soil_Dirt"
    },
    {
      "x": 7,
      "y": 4,
      "z": -11,
      "name": "Soil_Dirt"
    },
    {
      "x": 7,
      "y": 5,
      "z": -11,
      "name": "Plant_Moss_Rug_Green",
      "support": 15
    },
    {
      "x": 7,
      "y": 4,
      "z": -10,
      "name": "Soil_Dirt"
    },
    {
      "x": 8,
      "y": 4,
      "z": -28,
      "name": "Soil_Dirt"
    },
    {
      "x": 8,
      "y": 4,
      "z": -27,
      "name": "Wood_Softwood_Planks"
    },
    {
      "x": 8,
      "y": 5,
      "z": -27,
      "name": "Cloth_Roof_Orange",
      "rotation": 2
    },
    {
      "x": 8,
      "y": 4,
      "z": -26,
      "name": "Wood_Softwood_Planks"
    },
    {
      "x": 8,
      "y": 6,
      "z": -26,
      "name": "Cloth_Roof_Orange",
      "rotation": 2
    },
    {
      "x": 8,
      "y": 4,
      "z": -25,
      "name": "Wood_Softwood_Planks"
    },
    {
      "x": 8,
      "y": 7,
      "z": -25,
      "name": "Cloth_Roof_Orange",
      "rotation": 2
    },
    {
      "x": 8,
      "y": 4,
      "z": -24,
      "name": "Wood_Softwood_Planks"
    },
    {
      "x": 8,
      "y": 8,
      "z": -24,
      "name": "Cloth_Roof_Orange_Flat"
    },
    {
      "x": 8,
      "y": 4,
      "z": -23,
      "name": "Wood_Softwood_Planks"
    },
    {
      "x": 8,
      "y": 7,
      "z": -23,
      "name": "Cloth_Roof_Orange"
    },
    {
      "x": 8,
      "y": 4,
      "z": -22,
      "name": "Wood_Softwood_Planks"
    },
    {
      "x": 8,
      "y": 5,
      "z": -22,
      "name": "Aetherhaven_Management_Block",
      "components": {
        "Components": {
          "AetherhavenManagementBlock": {
            "PlotId": "",
            "TownId": ""
          },
          "PlacedByInteraction": {
            "WhoPlacedUuid": {
              "$binary": "v7RyWIT/TYKnXA2XcxdQtw==",
              "$type": "04"
            }
          }
        }
      },
      "rotation": 1
    },
    {
      "x": 8,
      "y": 6,
      "z": -22,
      "name": "Cloth_Roof_Orange"
    },
    {
      "x": 8,
      "y": 4,
      "z": -21,
      "name": "Wood_Softwood_Planks"
    },
    {
      "x": 8,
      "y": 5,
      "z": -21,
      "name": "Cloth_Roof_Orange"
    },
    {
      "x": 8,
      "y": 4,
      "z": -20,
      "name": "Soil_Dirt"
    },
    {
      "x": 8,
      "y": 4,
      "z": -19,
      "name": "Soil_Dirt"
    },
    {
      "x": 8,
      "y": 5,
      "z": -19,
      "name": "Plant_Bush",
      "support": 15
    },
    {
      "x": 8,
      "y": 4,
      "z": -18,
      "name": "Soil_Dirt"
    },
    {
      "x": 8,
      "y": 5,
      "z": -18,
      "name": "Plant_Moss_Rug_Green",
      "support": 15
    },
    {
      "x": 8,
      "y": 4,
      "z": -17,
      "name": "Soil_Dirt"
    },
    {
      "x": 8,
      "y": 7,
      "z": -17,
      "name": "Wood_Beech_Branch_Long",
      "support": 15,
      "rotation": 5
    },
    {
      "x": 8,
      "y": 8,
      "z": -17,
      "name": "Wood_Softwood_Planks_Half"
    },
    {
      "x": 8,
      "y": 4,
      "z": -16,
      "name": "Soil_Dirt"
    },
    {
      "x": 8,
      "y": 5,
      "z": -16,
      "name": "Rock_Stone_Cobble_Half",
      "rotation": 6
    },
    {
      "x": 8,
      "y": 8,
      "z": -16,
      "name": "Wood_Softwood_Planks_Half"
    },
    {
      "x": 8,
      "y": 4,
      "z": -15,
      "name": "Soil_Dirt"
    },
    {
      "x": 8,
      "y": 5,
      "z": -15,
      "name": "Soil_Gravel"
    },
    {
      "x": 8,
      "y": 6,
      "z": -15,
      "name": "Rock_Basalt"
    },
    {
      "x": 8,
      "y": 7,
      "z": -15,
      "name": "Rubble_Stone"
    },
    {
      "x": 8,
      "y": 8,
      "z": -15,
      "name": "Wood_Softwood_Planks_Half"
    },
    {
      "x": 8,
      "y": 10,
      "z": -15,
      "name": "Deco_Rope_Diagonal",
      "rotation": 3
    },
    {
      "x": 8,
      "y": 12,
      "z": -15,
      "name": "Wood_Softwood_Planks_Half",
      "rotation": 8
    },
    {
      "x": 8,
      "y": 13,
      "z": -15,
      "name": "Wood_Softwood_Planks_Half"
    },
    {
      "x": 8,
      "y": 4,
      "z": -14,
      "name": "Soil_Dirt"
    },
    {
      "x": 8,
      "y": 5,
      "z": -14,
      "name": "Rock_Stone"
    },
    {
      "x": 8,
      "y": 6,
      "z": -14,
      "name": "Rock_Stone_Cobble_Half",
      "rotation": 4
    },
    {
      "x": 8,
      "y": 8,
      "z": -14,
      "name": "Wood_Softwood_Planks_Half"
    },
    {
      "x": 8,
      "y": 4,
      "z": -13,
      "name": "Soil_Dirt"
    },
    {
      "x": 8,
      "y": 5,
      "z": -13,
      "name": "Furniture_Tavern_Barrel"
    },
    {
      "x": 8,
      "y": 7,
      "z": -13,
      "name": "Wood_Beech_Branch_Long",
      "support": 15,
      "rotation": 5
    },
    {
      "x": 8,
      "y": 8,
      "z": -13,
      "name": "Wood_Softwood_Planks_Half"
    },
    {
      "x": 8,
      "y": 4,
      "z": -12,
      "name": "Soil_Dirt"
    },
    {
      "x": 8,
      "y": 4,
      "z": -11,
      "name": "Soil_Dirt"
    },
    {
      "x": 8,
      "y": 5,
      "z": -11,
      "name": "Plant_Bush",
      "support": 15
    },
    {
      "x": 8,
      "y": 4,
      "z": -10,
      "name": "Soil_Dirt"
    },
    {
      "x": 9,
      "y": 4,
      "z": -28,
      "name": "Soil_Dirt"
    },
    {
      "x": 9,
      "y": 4,
      "z": -27,
      "name": "Wood_Softwood_Planks"
    },
    {
      "x": 9,
      "y": 5,
      "z": -27,
      "name": "Cloth_Roof_Orange",
      "rotation": 2
    },
    {
      "x": 9,
      "y": 4,
      "z": -26,
      "name": "Wood_Softwood_Planks"
    },
    {
      "x": 9,
      "y": 5,
      "z": -26,
      "name": "Furniture_Crude_Stool",
      "rotation": 1
    },
    {
      "x": 9,
      "y": 6,
      "z": -26,
      "name": "Cloth_Roof_Orange",
      "rotation": 2
    },
    {
      "x": 9,
      "y": 4,
      "z": -25,
      "name": "Wood_Softwood_Planks"
    },
    {
      "x": 9,
      "y": 7,
      "z": -25,
      "name": "Cloth_Roof_Orange",
      "rotation": 2
    },
    {
      "x": 9,
      "y": 4,
      "z": -24,
      "name": "Wood_Softwood_Planks"
    },
    {
      "x": 9,
      "y": 8,
      "z": -24,
      "name": "Cloth_Roof_Orange_Flat"
    },
    {
      "x": 9,
      "y": 4,
      "z": -23,
      "name": "Wood_Softwood_Planks"
    },
    {
      "x": 9,
      "y": 7,
      "z": -23,
      "name": "Cloth_Roof_Orange"
    },
    {
      "x": 9,
      "y": 4,
      "z": -22,
      "name": "Wood_Softwood_Planks"
    },
    {
      "x": 9,
      "y": 6,
      "z": -22,
      "name": "Cloth_Roof_Orange"
    },
    {
      "x": 9,
      "y": 4,
      "z": -21,
      "name": "Wood_Softwood_Planks"
    },
    {
      "x": 9,
      "y": 5,
      "z": -21,
      "name": "Cloth_Roof_Orange"
    },
    {
      "x": 9,
      "y": 4,
      "z": -20,
      "name": "Soil_Dirt"
    },
    {
      "x": 9,
      "y": 4,
      "z": -19,
      "name": "Soil_Dirt"
    },
    {
      "x": 9,
      "y": 4,
      "z": -18,
      "name": "Soil_Dirt"
    },
    {
      "x": 9,
      "y": 4,
      "z": -17,
      "name": "Soil_Dirt"
    },
    {
      "x": 9,
      "y": 5,
      "z": -17,
      "name": "Wood_Beech_Trunk",
      "support": 15
    },
    {
      "x": 9,
      "y": 6,
      "z": -17,
      "name": "Wood_Beech_Trunk",
      "support": 15
    },
    {
      "x": 9,
      "y": 7,
      "z": -17,
      "name": "Wood_Beech_Trunk",
      "support": 15
    },
    {
      "x": 9,
      "y": 8,
      "z": -17,
      "name": "Wood_Beech_Trunk",
      "support": 15
    },
    {
      "x": 9,
      "y": 4,
      "z": -16,
      "name": "Soil_Dirt"
    },
    {
      "x": 9,
      "y": 5,
      "z": -16,
      "name": "Rubble_Stone"
    },
    {
      "x": 9,
      "y": 6,
      "z": -16,
      "name": "Wood_Beech_Branch_Long",
      "support": 15,
      "rotation": 4
    },
    {
      "x": 9,
      "y": 7,
      "z": -16,
      "name": "Wood_Beech_Branch_Long",
      "support": 15,
      "rotation": 4
    },
    {
      "x": 9,
      "y": 8,
      "z": -16,
      "name": "Wood_Softwood_Planks_Half"
    },
    {
      "x": 9,
      "y": 4,
      "z": -15,
      "name": "Soil_Dirt"
    },
    {
      "x": 9,
      "y": 5,
      "z": -15,
      "name": "Rock_Stone_Cobble_Half",
      "rotation": 5
    },
    {
      "x": 9,
      "y": 6,
      "z": -15,
      "name": "Wood_Beech_Branch_Long",
      "support": 15,
      "rotation": 4
    },
    {
      "x": 9,
      "y": 7,
      "z": -15,
      "name": "Wood_Beech_Branch_Long",
      "support": 15,
      "rotation": 4
    },
    {
      "x": 9,
      "y": 8,
      "z": -15,
      "name": "Wood_Softwood_Planks_Half"
    },
    {
      "x": 9,
      "y": 11,
      "z": -15,
      "name": "Deco_Rope_Diagonal",
      "rotation": 3
    },
    {
      "x": 9,
      "y": 12,
      "z": -15,
      "name": "Wood_Softwood_Planks_Half",
      "rotation": 8
    },
    {
      "x": 9,
      "y": 13,
      "z": -15,
      "name": "Wood_Softwood_Planks_Half"
    },
    {
      "x": 9,
      "y": 4,
      "z": -14,
      "name": "Soil_Dirt"
    },
    {
      "x": 9,
      "y": 6,
      "z": -14,
      "name": "Wood_Beech_Branch_Long",
      "support": 15,
      "rotation": 4
    },
    {
      "x": 9,
      "y": 7,
      "z": -14,
      "name": "Wood_Beech_Branch_Long",
      "support": 15,
      "rotation": 4
    },
    {
      "x": 9,
      "y": 8,
      "z": -14,
      "name": "Wood_Softwood_Planks_Half"
    },
    {
      "x": 9,
      "y": 4,
      "z": -13,
      "name": "Soil_Dirt"
    },
    {
      "x": 9,
      "y": 5,
      "z": -13,
      "name": "Wood_Beech_Trunk",
      "support": 15
    },
    {
      "x": 9,
      "y": 6,
      "z": -13,
      "name": "Wood_Beech_Trunk",
      "support": 15
    },
    {
      "x": 9,
      "y": 7,
      "z": -13,
      "name": "Wood_Beech_Trunk",
      "support": 15
    },
    {
      "x": 9,
      "y": 8,
      "z": -13,
      "name": "Wood_Beech_Trunk",
      "support": 15
    },
    {
      "x": 9,
      "y": 4,
      "z": -12,
      "name": "Soil_Dirt"
    },
    {
      "x": 9,
      "y": 5,
      "z": -12,
      "name": "Rubble_Stone_Mossy_Medium",
      "support": 15
    },
    {
      "x": 9,
      "y": 4,
      "z": -11,
      "name": "Soil_Dirt"
    },
    {
      "x": 9,
      "y": 4,
      "z": -10,
      "name": "Soil_Dirt"
    },
    {
      "x": 10,
      "y": 4,
      "z": -28,
      "name": "Soil_Dirt"
    },
    {
      "x": 10,
      "y": 4,
      "z": -27,
      "name": "Wood_Softwood_Planks"
    },
    {
      "x": 10,
      "y": 5,
      "z": -27,
      "name": "Cloth_Roof_Orange",
      "rotation": 2
    },
    {
      "x": 10,
      "y": 4,
      "z": -26,
      "name": "Wood_Softwood_Planks"
    },
    {
      "x": 10,
      "y": 6,
      "z": -26,
      "name": "Cloth_Roof_Orange",
      "rotation": 2
    },
    {
      "x": 10,
      "y": 4,
      "z": -25,
      "name": "Wood_Softwood_Planks"
    },
    {
      "x": 10,
      "y": 7,
      "z": -25,
      "name": "Cloth_Roof_Orange",
      "rotation": 2
    },
    {
      "x": 10,
      "y": 4,
      "z": -24,
      "name": "Wood_Softwood_Planks"
    },
    {
      "x": 10,
      "y": 5,
      "z": -24,
      "name": "Wood_Beech_Branch_Long"
    },
    {
      "x": 10,
      "y": 6,
      "z": -24,
      "name": "Wood_Softwood_Beam"
    },
    {
      "x": 10,
      "y": 7,
      "z": -24,
      "name": "Wood_Softwood_Beam"
    },
    {
      "x": 10,
      "y": 8,
      "z": -24,
      "name": "Cloth_Roof_Orange_Flat"
    },
    {
      "x": 10,
      "y": 4,
      "z": -23,
      "name": "Wood_Softwood_Planks"
    },
    {
      "x": 10,
      "y": 7,
      "z": -23,
      "name": "Cloth_Roof_Orange"
    },
    {
      "x": 10,
      "y": 4,
      "z": -22,
      "name": "Wood_Softwood_Planks"
    },
    {
      "x": 10,
      "y": 6,
      "z": -22,
      "name": "Cloth_Roof_Orange"
    },
    {
      "x": 10,
      "y": 4,
      "z": -21,
      "name": "Soil_Dirt"
    },
    {
      "x": 10,
      "y": 5,
      "z": -21,
      "name": "Cloth_Roof_Orange"
    },
    {
      "x": 10,
      "y": 4,
      "z": -20,
      "name": "Soil_Dirt"
    },
    {
      "x": 10,
      "y": 4,
      "z": -19,
      "name": "Wood_Softwood_Planks"
    },
    {
      "x": 10,
      "y": 4,
      "z": -18,
      "name": "Wood_Softwood_Planks"
    },
    {
      "x": 10,
      "y": 4,
      "z": -17,
      "name": "Wood_Softwood_Planks"
    },
    {
      "x": 10,
      "y": 4,
      "z": -16,
      "name": "Wood_Softwood_Planks"
    },
    {
      "x": 10,
      "y": 6,
      "z": -16,
      "name": "Aetherhaven_Quest_Board",
      "filler": 992,
      "rotation": 2
    },
    {
      "x": 10,
      "y": 7,
      "z": -16,
      "name": "Aetherhaven_Quest_Board",
      "filler": 2016,
      "rotation": 2
    },
    {
      "x": 10,
      "y": 4,
      "z": -15,
      "name": "Wood_Softwood_Planks"
    },
    {
      "x": 10,
      "y": 6,
      "z": -15,
      "name": "Aetherhaven_Quest_Board",
      "rotation": 2
    },
    {
      "x": 10,
      "y": 7,
      "z": -15,
      "name": "Aetherhaven_Quest_Board",
      "filler": 1024,
      "rotation": 2
    },
    {
      "x": 10,
      "y": 12,
      "z": -15,
      "name": "Deco_Rope_Diagonal",
      "rotation": 3
    },
    {
      "x": 10,
      "y": 13,
      "z": -15,
      "name": "Wood_Beech_Trunk_Full",
      "support": 15,
      "rotation": 5
    },
    {
      "x": 10,
      "y": 4,
      "z": -14,
      "name": "Wood_Softwood_Planks"
    },
    {
      "x": 10,
      "y": 6,
      "z": -14,
      "name": "Aetherhaven_Quest_Board",
      "filler": 32,
      "rotation": 2
    },
    {
      "x": 10,
      "y": 7,
      "z": -14,
      "name": "Aetherhaven_Quest_Board",
      "filler": 1056,
      "rotation": 2
    },
    {
      "x": 10,
      "y": 4,
      "z": -13,
      "name": "Wood_Softwood_Planks"
    },
    {
      "x": 10,
      "y": 6,
      "z": -13,
      "name": "Lobby_Wall_Poster01",
      "rotation": 1
    },
    {
      "x": 10,
      "y": 4,
      "z": -12,
      "name": "Wood_Softwood_Planks"
    },
    {
      "x": 10,
      "y": 4,
      "z": -11,
      "name": "Wood_Softwood_Planks"
    },
    {
      "x": 10,
      "y": 3,
      "z": -10,
      "name": "Rock_Stone"
    },
    {
      "x": 10,
      "y": 4,
      "z": -10,
      "name": "Soil_Dirt"
    },
    {
      "x": 10,
      "y": 4,
      "z": -9,
      "name": "Soil_Dirt"
    },
    {
      "x": 11,
      "y": 4,
      "z": -29,
      "name": "Soil_Dirt"
    },
    {
      "x": 11,
      "y": 5,
      "z": -29,
      "name": "Furniture_Village_Crate"
    },
    {
      "x": 11,
      "y": 6,
      "z": -29,
      "name": "Furniture_Village_Crate"
    },
    {
      "x": 11,
      "y": 4,
      "z": -28,
      "name": "Soil_Dirt"
    },
    {
      "x": 11,
      "y": 5,
      "z": -28,
      "name": "Furniture_Village_Crate"
    },
    {
      "x": 11,
      "y": 4,
      "z": -27,
      "name": "Soil_Dirt"
    },
    {
      "x": 11,
      "y": 4,
      "z": -26,
      "name": "Wood_Softwood_Planks"
    },
    {
      "x": 11,
      "y": 5,
      "z": -26,
      "name": "Furniture_Village_Bench",
      "rotation": 1
    },
    {
      "x": 11,
      "y": 6,
      "z": -26,
      "name": "Furniture_Village_Bench",
      "filler": 1024,
      "rotation": 1
    },
    {
      "x": 11,
      "y": 4,
      "z": -25,
      "name": "Wood_Softwood_Planks"
    },
    {
      "x": 11,
      "y": 5,
      "z": -25,
      "name": "Furniture_Village_Bench",
      "filler": 32,
      "rotation": 1
    },
    {
      "x": 11,
      "y": 6,
      "z": -25,
      "name": "Furniture_Village_Bench",
      "filler": 1056,
      "rotation": 1
    },
    {
      "x": 11,
      "y": 4,
      "z": -24,
      "name": "Wood_Softwood_Planks"
    },
    {
      "x": 11,
      "y": 4,
      "z": -23,
      "name": "Wood_Softwood_Planks"
    },
    {
      "x": 11,
      "y": 4,
      "z": -22,
      "name": "Soil_Dirt"
    },
    {
      "x": 11,
      "y": 4,
      "z": -21,
      "name": "Soil_Dirt"
    },
    {
      "x": 11,
      "y": 4,
      "z": -20,
      "name": "Wood_Softwood_Planks"
    },
    {
      "x": 11,
      "y": 5,
      "z": -20,
      "name": "Furniture_Tavern_Barrel"
    },
    {
      "x": 11,
      "y": 4,
      "z": -19,
      "name": "Wood_Softwood_Planks"
    },
    {
      "x": 11,
      "y": 5,
      "z": -19,
      "name": "Furniture_Village_Crate"
    },
    {
      "x": 11,
      "y": 4,
      "z": -18,
      "name": "Wood_Softwood_Planks"
    },
    {
      "x": 11,
      "y": 5,
      "z": -18,
      "name": "Furniture_Village_Crate"
    },
    {
      "x": 11,
      "y": 6,
      "z": -18,
      "name": "Furniture_Tavern_Barrel"
    },
    {
      "x": 11,
      "y": 3,
      "z": -17,
      "name": "Rock_Stone"
    },
    {
      "x": 11,
      "y": 4,
      "z": -17,
      "name": "Wood_Softwood_Planks"
    },
    {
      "x": 11,
      "y": 3,
      "z": -16,
      "name": "Rock_Stone"
    },
    {
      "x": 11,
      "y": 4,
      "z": -16,
      "name": "Wood_Softwood_Planks"
    },
    {
      "x": 11,
      "y": 3,
      "z": -15,
      "name": "Rock_Stone"
    },
    {
      "x": 11,
      "y": 4,
      "z": -15,
      "name": "Wood_Softwood_Planks"
    },
    {
      "x": 11,
      "y": 13,
      "z": -15,
      "name": "Wood_Beech_Trunk_Full",
      "support": 15,
      "rotation": 5
    },
    {
      "x": 11,
      "y": 4,
      "z": -14,
      "name": "Wood_Softwood_Planks"
    },
    {
      "x": 11,
      "y": 4,
      "z": -13,
      "name": "Wood_Softwood_Planks"
    },
    {
      "x": 11,
      "y": 4,
      "z": -12,
      "name": "Wood_Softwood_Planks"
    },
    {
      "x": 11,
      "y": 5,
      "z": -12,
      "name": "Furniture_Village_Crate"
    },
    {
      "x": 11,
      "y": 6,
      "z": -12,
      "name": "Furniture_Tavern_Barrel"
    },
    {
      "x": 11,
      "y": 3,
      "z": -11,
      "name": "Rock_Stone"
    },
    {
      "x": 11,
      "y": 4,
      "z": -11,
      "name": "Wood_Softwood_Planks"
    },
    {
      "x": 11,
      "y": 4,
      "z": -10,
      "name": "Wood_Softwood_Planks"
    },
    {
      "x": 11,
      "y": 4,
      "z": -9,
      "name": "Soil_Dirt"
    },
    {
      "x": 11,
      "y": 4,
      "z": -8,
      "name": "Soil_Dirt"
    },
    {
      "x": 11,
      "y": 5,
      "z": -8,
      "name": "Plant_Bush",
      "support": 15
    },
    {
      "x": 11,
      "y": 4,
      "z": -7,
      "name": "Soil_Dirt"
    },
    {
      "x": 12,
      "y": 4,
      "z": -29,
      "name": "Soil_Dirt"
    },
    {
      "x": 12,
      "y": 5,
      "z": -29,
      "name": "Furniture_Village_Crate"
    },
    {
      "x": 12,
      "y": 6,
      "z": -29,
      "name": "Furniture_Village_Crate"
    },
    {
      "x": 12,
      "y": 4,
      "z": -28,
      "name": "Soil_Dirt"
    },
    {
      "x": 12,
      "y": 5,
      "z": -28,
      "name": "Furniture_Village_Crate"
    },
    {
      "x": 12,
      "y": 6,
      "z": -28,
      "name": "Furniture_Lumberjack_Lantern"
    },
    {
      "x": 12,
      "y": 4,
      "z": -27,
      "name": "Soil_Dirt"
    },
    {
      "x": 12,
      "y": 5,
      "z": -27,
      "name": "Rubble_Stone_Mossy_Medium",
      "support": 15
    },
    {
      "x": 12,
      "y": 4,
      "z": -26,
      "name": "Soil_Dirt"
    },
    {
      "x": 12,
      "y": 4,
      "z": -25,
      "name": "Soil_Dirt"
    },
    {
      "x": 12,
      "y": 4,
      "z": -24,
      "name": "Soil_Dirt"
    },
    {
      "x": 12,
      "y": 4,
      "z": -23,
      "name": "Soil_Dirt"
    },
    {
      "x": 12,
      "y": 5,
      "z": -23,
      "name": "Furniture_Crude_Stool",
      "rotation": 1
    },
    {
      "x": 12,
      "y": 4,
      "z": -22,
      "name": "Wood_Softwood_Planks"
    },
    {
      "x": 12,
      "y": 4,
      "z": -21,
      "name": "Wood_Softwood_Planks"
    },
    {
      "x": 12,
      "y": 4,
      "z": -20,
      "name": "Wood_Softwood_Planks"
    },
    {
      "x": 12,
      "y": 5,
      "z": -20,
      "name": "Furniture_Village_Crate"
    },
    {
      "x": 12,
      "y": 4,
      "z": -19,
      "name": "Wood_Softwood_Planks"
    },
    {
      "x": 12,
      "y": 5,
      "z": -19,
      "name": "Furniture_Village_Crate"
    },
    {
      "x": 12,
      "y": 6,
      "z": -19,
      "name": "Furniture_Lumberjack_Lantern"
    },
    {
      "x": 12,
      "y": 7,
      "z": -19,
      "name": "Plant_Moss_Wall_Green",
      "support": 15,
      "rotation": 2
    },
    {
      "x": 12,
      "y": 3,
      "z": -18,
      "name": "Rock_Stone"
    },
    {
      "x": 12,
      "y": 4,
      "z": -18,
      "name": "Wood_Softwood_Planks"
    },
    {
      "x": 12,
      "y": 5,
      "z": -18,
      "name": "Wood_Beech_Trunk",
      "support": 15
    },
    {
      "x": 12,
      "y": 6,
      "z": -18,
      "name": "Wood_Beech_Trunk",
      "support": 15
    },
    {
      "x": 12,
      "y": 7,
      "z": -18,
      "name": "Wood_Beech_Trunk",
      "support": 15
    },
    {
      "x": 12,
      "y": 8,
      "z": -18,
      "name": "Wood_Beech_Branch_Long",
      "support": 15
    },
    {
      "x": 12,
      "y": 2,
      "z": -17,
      "name": "Rock_Stone"
    },
    {
      "x": 12,
      "y": 3,
      "z": -17,
      "name": "Rock_Stone"
    },
    {
      "x": 12,
      "y": 4,
      "z": -17,
      "name": "Wood_Softwood_Planks"
    },
    {
      "x": 12,
      "y": 5,
      "z": -17,
      "name": "Wood_Softwood_Fence",
      "rotation": 3
    },
    {
      "x": 12,
      "y": 3,
      "z": -16,
      "name": "Rock_Stone"
    },
    {
      "x": 12,
      "y": 4,
      "z": -16,
      "name": "Rock_Stone"
    },
    {
      "x": 12,
      "y": 1,
      "z": -15,
      "name": "Rock_Basalt"
    },
    {
      "x": 12,
      "y": 2,
      "z": -15,
      "name": "Rock_Stone"
    },
    {
      "x": 12,
      "y": 3,
      "z": -15,
      "name": "Rock_Stone"
    },
    {
      "x": 12,
      "y": 13,
      "z": -15,
      "name": "Wood_Softwood_Planks_Half",
      "rotation": 8
    },
    {
      "x": 12,
      "y": 14,
      "z": -15,
      "name": "Wood_Softwood_Planks_Half"
    },
    {
      "x": 12,
      "y": 2,
      "z": -14,
      "name": "Rock_Stone"
    },
    {
      "x": 12,
      "y": 3,
      "z": -14,
      "name": "Rock_Basalt"
    },
    {
      "x": 12,
      "y": 2,
      "z": -13,
      "name": "Rock_Stone"
    },
    {
      "x": 12,
      "y": 3,
      "z": -13,
      "name": "Rock_Basalt"
    },
    {
      "x": 12,
      "y": 4,
      "z": -13,
      "name": "Wood_Softwood_Planks"
    },
    {
      "x": 12,
      "y": 5,
      "z": -13,
      "name": "Wood_Softwood_Fence",
      "rotation": 3
    },
    {
      "x": 12,
      "y": 4,
      "z": -12,
      "name": "Wood_Softwood_Planks"
    },
    {
      "x": 12,
      "y": 5,
      "z": -12,
      "name": "Wood_Beech_Trunk",
      "support": 15
    },
    {
      "x": 12,
      "y": 6,
      "z": -12,
      "name": "Wood_Beech_Trunk",
      "support": 15
    },
    {
      "x": 12,
      "y": 7,
      "z": -12,
      "name": "Wood_Beech_Trunk",
      "support": 15
    },
    {
      "x": 12,
      "y": 8,
      "z": -12,
      "name": "Wood_Beech_Branch_Long",
      "support": 15
    },
    {
      "x": 12,
      "y": 4,
      "z": -11,
      "name": "Wood_Softwood_Planks"
    },
    {
      "x": 12,
      "y": 5,
      "z": -11,
      "name": "Furniture_Tavern_Barrel"
    },
    {
      "x": 12,
      "y": 4,
      "z": -10,
      "name": "Wood_Softwood_Planks"
    },
    {
      "x": 12,
      "y": 4,
      "z": -9,
      "name": "Wood_Softwood_Planks"
    },
    {
      "x": 12,
      "y": 4,
      "z": -8,
      "name": "Wood_Softwood_Planks"
    },
    {
      "x": 12,
      "y": 4,
      "z": -7,
      "name": "Soil_Dirt"
    },
    {
      "x": 12,
      "y": 4,
      "z": -6,
      "name": "Soil_Dirt"
    },
    {
      "x": 12,
      "y": 4,
      "z": -5,
      "name": "Soil_Dirt"
    },
    {
      "x": 12,
      "y": 4,
      "z": -4,
      "name": "Soil_Dirt"
    },
    {
      "x": 12,
      "y": 5,
      "z": -4,
      "name": "Wood_Beech_Branch_Long",
      "support": 15
    },
    {
      "x": 12,
      "y": 6,
      "z": -4,
      "name": "*Furniture_Crude_Torch_State_Definitions_Off",
      "rotation": 2
    },
    {
      "x": 13,
      "y": 4,
      "z": -29,
      "name": "Soil_Dirt"
    },
    {
      "x": 13,
      "y": 5,
      "z": -29,
      "name": "Furniture_Tavern_Barrel"
    },
    {
      "x": 13,
      "y": 4,
      "z": -28,
      "name": "Soil_Dirt"
    },
    {
      "x": 13,
      "y": 5,
      "z": -28,
      "name": "Rubble_Stone"
    },
    {
      "x": 13,
      "y": 4,
      "z": -27,
      "name": "Plant_Moss_Block_Green_Dark",
      "support": 15
    },
    {
      "x": 13,
      "y": 4,
      "z": -26,
      "name": "Soil_Gravel"
    },
    {
      "x": 13,
      "y": 4,
      "z": -25,
      "name": "Soil_Dirt"
    },
    {
      "x": 13,
      "y": 4,
      "z": -24,
      "name": "Soil_Dirt"
    },
    {
      "x": 13,
      "y": 4,
      "z": -23,
      "name": "Soil_Dirt"
    },
    {
      "x": 13,
      "y": 4,
      "z": -22,
      "name": "Soil_Dirt"
    },
    {
      "x": 13,
      "y": 4,
      "z": -21,
      "name": "Soil_Dirt"
    },
    {
      "x": 13,
      "y": 4,
      "z": -20,
      "name": "Wood_Softwood_Planks"
    },
    {
      "x": 13,
      "y": 4,
      "z": -19,
      "name": "Wood_Softwood_Planks"
    },
    {
      "x": 13,
      "y": 3,
      "z": -18,
      "name": "Rock_Stone"
    },
    {
      "x": 13,
      "y": 4,
      "z": -18,
      "name": "Wood_Softwood_Planks"
    },
    {
      "x": 13,
      "y": 5,
      "z": -18,
      "name": "Wood_Softwood_Fence",
      "rotation": 2
    },
    {
      "x": 13,
      "y": 2,
      "z": -17,
      "name": "Rock_Stone"
    },
    {
      "x": 13,
      "y": 3,
      "z": -17,
      "name": "Rock_Basalt_Cobble"
    },
    {
      "x": 13,
      "y": 2,
      "z": -16,
      "name": "Rock_Stone"
    },
    {
      "x": 13,
      "y": 3,
      "z": -16,
      "name": "Rock_Stone"
    },
    {
      "x": 13,
      "y": 1,
      "z": -15,
      "name": "Rock_Stone"
    },
    {
      "x": 13,
      "y": 2,
      "z": -15,
      "name": "Rock_Stone"
    },
    {
      "x": 13,
      "y": 13,
      "z": -15,
      "name": "Wood_Softwood_Planks_Half",
      "rotation": 8
    },
    {
      "x": 13,
      "y": 14,
      "z": -15,
      "name": "Wood_Softwood_Planks_Half"
    },
    {
      "x": 13,
      "y": 1,
      "z": -14,
      "name": "Rock_Basalt"
    },
    {
      "x": 13,
      "y": 2,
      "z": -14,
      "name": "Rock_Basalt"
    },
    {
      "x": 13,
      "y": 1,
      "z": -13,
      "name": "Rock_Basalt"
    },
    {
      "x": 13,
      "y": 2,
      "z": -13,
      "name": "Soil_Gravel",
      "support": 15
    },
    {
      "x": 13,
      "y": 2,
      "z": -12,
      "name": "Rock_Stone"
    },
    {
      "x": 13,
      "y": 3,
      "z": -12,
      "name": "Rock_Basalt"
    },
    {
      "x": 13,
      "y": 4,
      "z": -12,
      "name": "Wood_Softwood_Planks"
    },
    {
      "x": 13,
      "y": 5,
      "z": -12,
      "name": "Wood_Softwood_Fence"
    },
    {
      "x": 13,
      "y": 4,
      "z": -11,
      "name": "Wood_Softwood_Planks"
    },
    {
      "x": 13,
      "y": 5,
      "z": -11,
      "name": "Furniture_Village_Crate"
    },
    {
      "x": 13,
      "y": 6,
      "z": -11,
      "name": "Furniture_Lumberjack_Lantern"
    },
    {
      "x": 13,
      "y": 4,
      "z": -10,
      "name": "Wood_Softwood_Planks"
    },
    {
      "x": 13,
      "y": 4,
      "z": -9,
      "name": "Wood_Softwood_Planks"
    },
    {
      "x": 13,
      "y": 4,
      "z": -8,
      "name": "Wood_Softwood_Planks"
    },
    {
      "x": 13,
      "y": 5,
      "z": -8,
      "name": "Cloth_Roof_Green",
      "rotation": 3
    },
    {
      "x": 13,
      "y": 4,
      "z": -7,
      "name": "Wood_Softwood_Planks"
    },
    {
      "x": 13,
      "y": 5,
      "z": -7,
      "name": "Cloth_Roof_Green",
      "rotation": 3
    },
    {
      "x": 13,
      "y": 4,
      "z": -6,
      "name": "Soil_Dirt"
    },
    {
      "x": 13,
      "y": 5,
      "z": -6,
      "name": "Cloth_Roof_Green",
      "rotation": 3
    },
    {
      "x": 13,
      "y": 4,
      "z": -5,
      "name": "Soil_Dirt"
    },
    {
      "x": 13,
      "y": 5,
      "z": -5,
      "name": "Cloth_Roof_Green",
      "rotation": 3
    },
    {
      "x": 13,
      "y": 4,
      "z": -4,
      "name": "Soil_Gravel"
    },
    {
      "x": 13,
      "y": 5,
      "z": -4,
      "name": "Cloth_Roof_Green",
      "rotation": 3
    },
    {
      "x": 13,
      "y": 4,
      "z": -3,
      "name": "Soil_Dirt"
    },
    {
      "x": 13,
      "y": 4,
      "z": -2,
      "name": "Soil_Dirt"
    },
    {
      "x": 13,
      "y": 4,
      "z": -1,
      "name": "Soil_Dirt"
    },
    {
      "x": 14,
      "y": 4,
      "z": -30,
      "name": "Soil_Dirt"
    },
    {
      "x": 14,
      "y": 4,
      "z": -29,
      "name": "Soil_Dirt"
    },
    {
      "x": 14,
      "y": 4,
      "z": -28,
      "name": "Soil_Dirt"
    },
    {
      "x": 14,
      "y": 4,
      "z": -27,
      "name": "Rock_Stone"
    },
    {
      "x": 14,
      "y": 4,
      "z": -26,
      "name": "Plant_Moss_Block_Green_Dark",
      "support": 15
    },
    {
      "x": 14,
      "y": 4,
      "z": -25,
      "name": "Soil_Dirt"
    },
    {
      "x": 14,
      "y": 4,
      "z": -24,
      "name": "Soil_Dirt"
    },
    {
      "x": 14,
      "y": 4,
      "z": -23,
      "name": "Rock_Basalt_Cobble"
    },
    {
      "x": 14,
      "y": 5,
      "z": -23,
      "name": "Furniture_Crude_Brazier"
    },
    {
      "x": 14,
      "y": 4,
      "z": -22,
      "name": "Soil_Dirt"
    },
    {
      "x": 14,
      "y": 4,
      "z": -21,
      "name": "Rock_Basalt"
    },
    {
      "x": 14,
      "y": 4,
      "z": -20,
      "name": "Wood_Softwood_Planks"
    },
    {
      "x": 14,
      "y": 4,
      "z": -19,
      "name": "Wood_Softwood_Planks"
    },
    {
      "x": 14,
      "y": 3,
      "z": -18,
      "name": "Rock_Stone"
    },
    {
      "x": 14,
      "y": 1,
      "z": -17,
      "name": "Rock_Stone"
    },
    {
      "x": 14,
      "y": 2,
      "z": -17,
      "name": "Rock_Stone"
    },
    {
      "x": 14,
      "y": 1,
      "z": -16,
      "name": "Rock_Stone"
    },
    {
      "x": 14,
      "y": 2,
      "z": -16,
      "name": "Rock_Basalt_Cobble"
    },
    {
      "x": 14,
      "y": 9,
      "z": -16,
      "name": "Furniture_Crude_Platform"
    },
    {
      "x": 14,
      "y": 10,
      "z": -16,
      "name": "Furniture_Tavern_Barrel"
    },
    {
      "x": 14,
      "y": 1,
      "z": -15,
      "name": "Rock_Stone"
    },
    {
      "x": 14,
      "y": 2,
      "z": -15,
      "name": "Rock_Stone"
    },
    {
      "x": 14,
      "y": 9,
      "z": -15,
      "name": "Furniture_Crude_Platform"
    },
    {
      "x": 14,
      "y": 14,
      "z": -15,
      "name": "Wood_Beech_Trunk_Full",
      "support": 15,
      "rotation": 5
    },
    {
      "x": 14,
      "y": 1,
      "z": -14,
      "name": "Rock_Basalt"
    },
    {
      "x": 14,
      "y": 2,
      "z": -14,
      "name": "Soil_Gravel",
      "support": 15
    },
    {
      "x": 14,
      "y": 9,
      "z": -14,
      "name": "Furniture_Crude_Platform"
    },
    {
      "x": 14,
      "y": 1,
      "z": -13,
      "name": "Rock_Basalt"
    },
    {
      "x": 14,
      "y": 2,
      "z": -13,
      "name": "Soil_Gravel",
      "support": 15
    },
    {
      "x": 14,
      "y": 2,
      "z": -12,
      "name": "Rock_Basalt"
    },
    {
      "x": 14,
      "y": 3,
      "z": -12,
      "name": "Rock_Stone"
    },
    {
      "x": 14,
      "y": 4,
      "z": -11,
      "name": "Wood_Softwood_Planks"
    },
    {
      "x": 14,
      "y": 4,
      "z": -10,
      "name": "Wood_Softwood_Planks"
    },
    {
      "x": 14,
      "y": 4,
      "z": -9,
      "name": "Wood_Softwood_Planks"
    },
    {
      "x": 14,
      "y": 4,
      "z": -8,
      "name": "Wood_Softwood_Planks"
    },
    {
      "x": 14,
      "y": 6,
      "z": -8,
      "name": "Cloth_Roof_Green",
      "rotation": 3
    },
    {
      "x": 14,
      "y": 4,
      "z": -7,
      "name": "Wood_Softwood_Planks"
    },
    {
      "x": 14,
      "y": 5,
      "z": -7,
      "name": "Furniture_Village_Crate"
    },
    {
      "x": 14,
      "y": 6,
      "z": -7,
      "name": "Cloth_Roof_Green",
      "rotation": 3
    },
    {
      "x": 14,
      "y": 4,
      "z": -6,
      "name": "Rock_Basalt"
    },
    {
      "x": 14,
      "y": 5,
      "z": -6,
      "name": "Furniture_Village_Crate"
    },
    {
      "x": 14,
      "y": 6,
      "z": -6,
      "name": "Cloth_Roof_Green",
      "rotation": 3
    },
    {
      "x": 14,
      "y": 4,
      "z": -5,
      "name": "Rock_Basalt"
    },
    {
      "x": 14,
      "y": 6,
      "z": -5,
      "name": "Cloth_Roof_Green",
      "rotation": 3
    },
    {
      "x": 14,
      "y": 4,
      "z": -4,
      "name": "Soil_Dirt"
    },
    {
      "x": 14,
      "y": 6,
      "z": -4,
      "name": "Cloth_Roof_Green",
      "rotation": 3
    },
    {
      "x": 14,
      "y": 4,
      "z": -3,
      "name": "Rock_Basalt"
    },
    {
      "x": 14,
      "y": 4,
      "z": -2,
      "name": "Soil_Dirt"
    },
    {
      "x": 14,
      "y": 4,
      "z": -1,
      "name": "Soil_Dirt"
    },
    {
      "x": 15,
      "y": 4,
      "z": -30,
      "name": "Soil_Dirt"
    },
    {
      "x": 15,
      "y": 4,
      "z": -29,
      "name": "Soil_Dirt"
    },
    {
      "x": 15,
      "y": 4,
      "z": -28,
      "name": "Rock_Basalt"
    },
    {
      "x": 15,
      "y": 4,
      "z": -27,
      "name": "Rock_Basalt"
    },
    {
      "x": 15,
      "y": 4,
      "z": -26,
      "name": "Rock_Basalt_Cobble"
    },
    {
      "x": 15,
      "y": 4,
      "z": -25,
      "name": "Soil_Dirt"
    },
    {
      "x": 15,
      "y": 4,
      "z": -24,
      "name": "Soil_Dirt"
    },
    {
      "x": 15,
      "y": 5,
      "z": -24,
      "name": "Furniture_Crude_Stool"
    },
    {
      "x": 15,
      "y": 4,
      "z": -23,
      "name": "Soil_Dirt"
    },
    {
      "x": 15,
      "y": 4,
      "z": -22,
      "name": "Rock_Basalt_Cobble"
    },
    {
      "x": 15,
      "y": 4,
      "z": -21,
      "name": "Rock_Basalt_Cobble"
    },
    {
      "x": 15,
      "y": 5,
      "z": -21,
      "name": "Furniture_Crude_Stool"
    },
    {
      "x": 15,
      "y": 4,
      "z": -20,
      "name": "Wood_Softwood_Planks"
    },
    {
      "x": 15,
      "y": 4,
      "z": -19,
      "name": "Wood_Softwood_Planks"
    },
    {
      "x": 15,
      "y": 2,
      "z": -18,
      "name": "Rock_Basalt"
    },
    {
      "x": 15,
      "y": 3,
      "z": -18,
      "name": "Rock_Stone"
    },
    {
      "x": 15,
      "y": 1,
      "z": -17,
      "name": "Rock_Stone"
    },
    {
      "x": 15,
      "y": 2,
      "z": -17,
      "name": "Rock_Stone"
    },
    {
      "x": 15,
      "y": 3,
      "z": -17,
      "name": "Rock_Stone"
    },
    {
      "x": 15,
      "y": 1,
      "z": -16,
      "name": "Rock_Stone"
    },
    {
      "x": 15,
      "y": 9,
      "z": -16,
      "name": "Furniture_Crude_Platform"
    },
    {
      "x": 15,
      "y": 0,
      "z": -15,
      "name": "Rock_Stone"
    },
    {
      "x": 15,
      "y": 1,
      "z": -15,
      "name": "Rock_Stone"
    },
    {
      "x": 15,
      "y": 2,
      "z": -15,
      "name": "Rock_Stone"
    },
    {
      "x": 15,
      "y": 9,
      "z": -15,
      "name": "Furniture_Crude_Platform"
    },
    {
      "x": 15,
      "y": 10,
      "z": -15,
      "name": "Deco_Iron_Chain_Small"
    },
    {
      "x": 15,
      "y": 11,
      "z": -15,
      "name": "Deco_Iron_Chain_Small"
    },
    {
      "x": 15,
      "y": 12,
      "z": -15,
      "name": "Deco_Iron_Chain_Small"
    },
    {
      "x": 15,
      "y": 13,
      "z": -15,
      "name": "Deco_Iron_Chain_Small"
    },
    {
      "x": 15,
      "y": 14,
      "z": -15,
      "name": "Wood_Beech_Trunk_Full",
      "support": 15,
      "rotation": 5
    },
    {
      "x": 15,
      "y": 0,
      "z": -14,
      "name": "Rock_Stone"
    },
    {
      "x": 15,
      "y": 9,
      "z": -14,
      "name": "Furniture_Crude_Platform"
    },
    {
      "x": 15,
      "y": 10,
      "z": -14,
      "name": "Furniture_Village_Crate"
    },
    {
      "x": 15,
      "y": 0,
      "z": -13,
      "name": "Rock_Stone"
    },
    {
      "x": 15,
      "y": 1,
      "z": -13,
      "name": "Rock_Basalt"
    },
    {
      "x": 15,
      "y": 2,
      "z": -13,
      "name": "Rock_Basalt"
    },
    {
      "x": 15,
      "y": 2,
      "z": -12,
      "name": "Rock_Stone"
    },
    {
      "x": 15,
      "y": 3,
      "z": -12,
      "name": "Rock_Basalt"
    },
    {
      "x": 15,
      "y": 4,
      "z": -11,
      "name": "Wood_Softwood_Planks"
    },
    {
      "x": 15,
      "y": 4,
      "z": -10,
      "name": "Wood_Softwood_Planks"
    },
    {
      "x": 15,
      "y": 4,
      "z": -9,
      "name": "Wood_Softwood_Planks"
    },
    {
      "x": 15,
      "y": 4,
      "z": -8,
      "name": "Wood_Softwood_Planks"
    },
    {
      "x": 15,
      "y": 5,
      "z": -8,
      "name": "Wood_Softwood_Beam"
    },
    {
      "x": 15,
      "y": 6,
      "z": -8,
      "name": "Wood_Softwood_Beam"
    },
    {
      "x": 15,
      "y": 7,
      "z": -8,
      "name": "Cloth_Roof_Green_Flat"
    },
    {
      "x": 15,
      "y": 4,
      "z": -7,
      "name": "Rock_Basalt"
    },
    {
      "x": 15,
      "y": 7,
      "z": -7,
      "name": "Cloth_Roof_Green_Flat"
    },
    {
      "x": 15,
      "y": 4,
      "z": -6,
      "name": "Soil_Dirt"
    },
    {
      "x": 15,
      "y": 5,
      "z": -6,
      "name": "Furniture_Village_Crate"
    },
    {
      "x": 15,
      "y": 7,
      "z": -6,
      "name": "Cloth_Roof_Green_Flat"
    },
    {
      "x": 15,
      "y": 4,
      "z": -5,
      "name": "Rock_Basalt_Cobble"
    },
    {
      "x": 15,
      "y": 5,
      "z": -5,
      "name": "Furniture_Village_Crate"
    },
    {
      "x": 15,
      "y": 7,
      "z": -5,
      "name": "Cloth_Roof_Green_Flat"
    },
    {
      "x": 15,
      "y": 4,
      "z": -4,
      "name": "Rock_Basalt"
    },
    {
      "x": 15,
      "y": 5,
      "z": -4,
      "name": "Wood_Softwood_Beam"
    },
    {
      "x": 15,
      "y": 6,
      "z": -4,
      "name": "Wood_Softwood_Beam"
    },
    {
      "x": 15,
      "y": 7,
      "z": -4,
      "name": "Cloth_Roof_Green_Flat"
    },
    {
      "x": 15,
      "y": 4,
      "z": -3,
      "name": "Soil_Dirt"
    },
    {
      "x": 15,
      "y": 4,
      "z": -2,
      "name": "Soil_Dirt"
    },
    {
      "x": 15,
      "y": 4,
      "z": -1,
      "name": "Soil_Dirt"
    },
    {
      "x": 16,
      "y": 4,
      "z": -30,
      "name": "Soil_Dirt"
    },
    {
      "x": 16,
      "y": 4,
      "z": -29,
      "name": "Soil_Dirt"
    },
    {
      "x": 16,
      "y": 4,
      "z": -28,
      "name": "Soil_Dirt"
    },
    {
      "x": 16,
      "y": 4,
      "z": -27,
      "name": "Wood_Softwood_Planks"
    },
    {
      "x": 16,
      "y": 4,
      "z": -26,
      "name": "Wood_Softwood_Planks"
    },
    {
      "x": 16,
      "y": 4,
      "z": -25,
      "name": "Soil_Dirt"
    },
    {
      "x": 16,
      "y": 4,
      "z": -24,
      "name": "Soil_Dirt"
    },
    {
      "x": 16,
      "y": 4,
      "z": -23,
      "name": "Soil_Dirt"
    },
    {
      "x": 16,
      "y": 4,
      "z": -22,
      "name": "Soil_Dirt"
    },
    {
      "x": 16,
      "y": 5,
      "z": -22,
      "name": "Rubble_Stone"
    },
    {
      "x": 16,
      "y": 4,
      "z": -21,
      "name": "Wood_Softwood_Planks"
    },
    {
      "x": 16,
      "y": 4,
      "z": -20,
      "name": "Wood_Softwood_Planks"
    },
    {
      "x": 16,
      "y": 4,
      "z": -19,
      "name": "Wood_Softwood_Planks"
    },
    {
      "x": 16,
      "y": 3,
      "z": -18,
      "name": "Rock_Stone"
    },
    {
      "x": 16,
      "y": 1,
      "z": -17,
      "name": "Rock_Stone"
    },
    {
      "x": 16,
      "y": 2,
      "z": -17,
      "name": "Rock_Stone"
    },
    {
      "x": 16,
      "y": 3,
      "z": -17,
      "name": "Rock_Basalt"
    },
    {
      "x": 16,
      "y": 1,
      "z": -16,
      "name": "Rock_Stone"
    },
    {
      "x": 16,
      "y": 9,
      "z": -16,
      "name": "Furniture_Crude_Platform"
    },
    {
      "x": 16,
      "y": 1,
      "z": -15,
      "name": "Rock_Stone"
    },
    {
      "x": 16,
      "y": 9,
      "z": -15,
      "name": "Furniture_Crude_Platform"
    },
    {
      "x": 16,
      "y": 10,
      "z": -15,
      "name": "Furniture_Tavern_Barrel"
    },
    {
      "x": 16,
      "y": 1,
      "z": -14,
      "name": "Rock_Stone"
    },
    {
      "x": 16,
      "y": 9,
      "z": -14,
      "name": "Furniture_Crude_Platform"
    },
    {
      "x": 16,
      "y": 1,
      "z": -13,
      "name": "Rock_Stone"
    },
    {
      "x": 16,
      "y": 2,
      "z": -12,
      "name": "Rock_Stone"
    },
    {
      "x": 16,
      "y": 3,
      "z": -12,
      "name": "Rock_Basalt"
    },
    {
      "x": 16,
      "y": 4,
      "z": -11,
      "name": "Wood_Softwood_Planks"
    },
    {
      "x": 16,
      "y": 4,
      "z": -10,
      "name": "Wood_Softwood_Planks"
    },
    {
      "x": 16,
      "y": 4,
      "z": -9,
      "name": "Wood_Softwood_Planks"
    },
    {
      "x": 16,
      "y": 4,
      "z": -8,
      "name": "Wood_Softwood_Planks"
    },
    {
      "x": 16,
      "y": 6,
      "z": -8,
      "name": "Cloth_Roof_Green",
      "rotation": 1
    },
    {
      "x": 16,
      "y": 4,
      "z": -7,
      "name": "Wood_Softwood_Planks"
    },
    {
      "x": 16,
      "y": 6,
      "z": -7,
      "name": "Cloth_Roof_Green",
      "rotation": 1
    },
    {
      "x": 16,
      "y": 4,
      "z": -6,
      "name": "Soil_Dirt"
    },
    {
      "x": 16,
      "y": 6,
      "z": -6,
      "name": "Cloth_Roof_Green",
      "rotation": 1
    },
    {
      "x": 16,
      "y": 4,
      "z": -5,
      "name": "Ore_Iron_Basalt"
    },
    {
      "x": 16,
      "y": 6,
      "z": -5,
      "name": "Cloth_Roof_Green",
      "rotation": 1
    },
    {
      "x": 16,
      "y": 4,
      "z": -4,
      "name": "Rock_Basalt"
    },
    {
      "x": 16,
      "y": 6,
      "z": -4,
      "name": "Cloth_Roof_Green",
      "rotation": 1
    },
    {
      "x": 16,
      "y": 4,
      "z": -3,
      "name": "Soil_Dirt"
    },
    {
      "x": 16,
      "y": 4,
      "z": -2,
      "name": "Soil_Dirt"
    },
    {
      "x": 17,
      "y": 4,
      "z": -29,
      "name": "Soil_Dirt"
    },
    {
      "x": 17,
      "y": 4,
      "z": -28,
      "name": "Wood_Softwood_Planks"
    },
    {
      "x": 17,
      "y": 5,
      "z": -28,
      "name": "Furniture_Crude_Stool"
    },
    {
      "x": 17,
      "y": 4,
      "z": -27,
      "name": "Wood_Softwood_Planks"
    },
    {
      "x": 17,
      "y": 4,
      "z": -26,
      "name": "Wood_Softwood_Planks"
    },
    {
      "x": 17,
      "y": 4,
      "z": -25,
      "name": "Wood_Softwood_Planks"
    },
    {
      "x": 17,
      "y": 5,
      "z": -25,
      "name": "Wood_Beech_Branch_Long"
    },
    {
      "x": 17,
      "y": 6,
      "z": -25,
      "name": "*Furniture_Crude_Torch_State_Definitions_Off",
      "rotation": 2
    },
    {
      "x": 17,
      "y": 4,
      "z": -24,
      "name": "Soil_Dirt"
    },
    {
      "x": 17,
      "y": 4,
      "z": -23,
      "name": "Soil_Dirt"
    },
    {
      "x": 17,
      "y": 4,
      "z": -22,
      "name": "Soil_Dirt"
    },
    {
      "x": 17,
      "y": 4,
      "z": -21,
      "name": "Soil_Dirt"
    },
    {
      "x": 17,
      "y": 4,
      "z": -20,
      "name": "Wood_Softwood_Planks"
    },
    {
      "x": 17,
      "y": 4,
      "z": -19,
      "name": "Wood_Softwood_Planks"
    },
    {
      "x": 17,
      "y": 2,
      "z": -18,
      "name": "Rock_Stone"
    },
    {
      "x": 17,
      "y": 4,
      "z": -18,
      "name": "Wood_Softwood_Planks"
    },
    {
      "x": 17,
      "y": 5,
      "z": -18,
      "name": "Wood_Softwood_Fence",
      "rotation": 2
    },
    {
      "x": 17,
      "y": 2,
      "z": -17,
      "name": "Rock_Stone"
    },
    {
      "x": 17,
      "y": 3,
      "z": -17,
      "name": "Rock_Basalt"
    },
    {
      "x": 17,
      "y": 2,
      "z": -16,
      "name": "Rock_Stone"
    },
    {
      "x": 17,
      "y": 3,
      "z": -16,
      "name": "Rock_Basalt_Cobble"
    },
    {
      "x": 17,
      "y": 1,
      "z": -15,
      "name": "Rock_Stone"
    },
    {
      "x": 17,
      "y": 2,
      "z": -15,
      "name": "Rock_Stone"
    },
    {
      "x": 17,
      "y": 3,
      "z": -15,
      "name": "Rock_Stone"
    },
    {
      "x": 17,
      "y": 1,
      "z": -14,
      "name": "Rock_Stone"
    },
    {
      "x": 17,
      "y": 2,
      "z": -14,
      "name": "Ore_Iron_Basalt"
    },
    {
      "x": 17,
      "y": 2,
      "z": -13,
      "name": "Rock_Basalt"
    },
    {
      "x": 17,
      "y": 3,
      "z": -13,
      "name": "Rock_Stone"
    },
    {
      "x": 17,
      "y": 2,
      "z": -12,
      "name": "Rock_Stone"
    },
    {
      "x": 17,
      "y": 3,
      "z": -12,
      "name": "Rock_Stone"
    },
    {
      "x": 17,
      "y": 4,
      "z": -12,
      "name": "Wood_Softwood_Planks"
    },
    {
      "x": 17,
      "y": 5,
      "z": -12,
      "name": "Wood_Softwood_Fence"
    },
    {
      "x": 17,
      "y": 4,
      "z": -11,
      "name": "Wood_Softwood_Planks"
    },
    {
      "x": 17,
      "y": 4,
      "z": -10,
      "name": "Wood_Softwood_Planks"
    },
    {
      "x": 17,
      "y": 4,
      "z": -9,
      "name": "Wood_Softwood_Planks"
    },
    {
      "x": 17,
      "y": 4,
      "z": -8,
      "name": "Wood_Softwood_Planks"
    },
    {
      "x": 17,
      "y": 5,
      "z": -8,
      "name": "Cloth_Roof_Green",
      "rotation": 1
    },
    {
      "x": 17,
      "y": 4,
      "z": -7,
      "name": "Soil_Dirt"
    },
    {
      "x": 17,
      "y": 5,
      "z": -7,
      "name": "Cloth_Roof_Green",
      "rotation": 1
    },
    {
      "x": 17,
      "y": 4,
      "z": -6,
      "name": "Rock_Basalt"
    },
    {
      "x": 17,
      "y": 5,
      "z": -6,
      "name": "Cloth_Roof_Green",
      "rotation": 1
    },
    {
      "x": 17,
      "y": 4,
      "z": -5,
      "name": "Soil_Dirt"
    },
    {
      "x": 17,
      "y": 5,
      "z": -5,
      "name": "Cloth_Roof_Green",
      "rotation": 1
    },
    {
      "x": 17,
      "y": 4,
      "z": -4,
      "name": "Soil_Dirt"
    },
    {
      "x": 17,
      "y": 5,
      "z": -4,
      "name": "Cloth_Roof_Green",
      "rotation": 1
    },
    {
      "x": 17,
      "y": 4,
      "z": -3,
      "name": "Rock_Stone"
    },
    {
      "x": 18,
      "y": 4,
      "z": -29,
      "name": "Soil_Dirt"
    },
    {
      "x": 18,
      "y": 4,
      "z": -28,
      "name": "Wood_Softwood_Planks"
    },
    {
      "x": 18,
      "y": 4,
      "z": -27,
      "name": "Wood_Softwood_Planks"
    },
    {
      "x": 18,
      "y": 4,
      "z": -26,
      "name": "Wood_Softwood_Planks"
    },
    {
      "x": 18,
      "y": 4,
      "z": -25,
      "name": "Wood_Softwood_Planks"
    },
    {
      "x": 18,
      "y": 4,
      "z": -24,
      "name": "Soil_Dirt"
    },
    {
      "x": 18,
      "y": 4,
      "z": -23,
      "name": "Soil_Dirt"
    },
    {
      "x": 18,
      "y": 4,
      "z": -22,
      "name": "Wood_Softwood_Planks"
    },
    {
      "x": 18,
      "y": 4,
      "z": -21,
      "name": "Wood_Softwood_Planks"
    },
    {
      "x": 18,
      "y": 4,
      "z": -20,
      "name": "Wood_Softwood_Planks"
    },
    {
      "x": 18,
      "y": 4,
      "z": -19,
      "name": "Wood_Softwood_Planks"
    },
    {
      "x": 18,
      "y": 4,
      "z": -18,
      "name": "Wood_Softwood_Planks"
    },
    {
      "x": 18,
      "y": 5,
      "z": -18,
      "name": "Wood_Beech_Trunk",
      "support": 15
    },
    {
      "x": 18,
      "y": 6,
      "z": -18,
      "name": "Wood_Beech_Trunk",
      "support": 15
    },
    {
      "x": 18,
      "y": 7,
      "z": -18,
      "name": "Wood_Beech_Trunk",
      "support": 15
    },
    {
      "x": 18,
      "y": 8,
      "z": -18,
      "name": "Wood_Beech_Branch_Long",
      "support": 15
    },
    {
      "x": 18,
      "y": 4,
      "z": -17,
      "name": "Wood_Softwood_Planks"
    },
    {
      "x": 18,
      "y": 5,
      "z": -17,
      "name": "Wood_Softwood_Fence",
      "rotation": 1
    },
    {
      "x": 18,
      "y": 2,
      "z": -16,
      "name": "Rock_Basalt"
    },
    {
      "x": 18,
      "y": 3,
      "z": -16,
      "name": "Rock_Basalt"
    },
    {
      "x": 18,
      "y": 2,
      "z": -15,
      "name": "Rock_Basalt"
    },
    {
      "x": 18,
      "y": 3,
      "z": -15,
      "name": "Rock_Stone"
    },
    {
      "x": 18,
      "y": 2,
      "z": -14,
      "name": "Rock_Basalt"
    },
    {
      "x": 18,
      "y": 3,
      "z": -14,
      "name": "Rock_Stone"
    },
    {
      "x": 18,
      "y": 2,
      "z": -13,
      "name": "Rock_Basalt"
    },
    {
      "x": 18,
      "y": 3,
      "z": -13,
      "name": "Rock_Stone"
    },
    {
      "x": 18,
      "y": 4,
      "z": -13,
      "name": "Plant_Moss_Block_Green_Dark",
      "support": 15
    },
    {
      "x": 18,
      "y": 5,
      "z": -13,
      "name": "Wood_Softwood_Fence",
      "rotation": 1
    },
    {
      "x": 18,
      "y": 4,
      "z": -12,
      "name": "Wood_Softwood_Planks"
    },
    {
      "x": 18,
      "y": 5,
      "z": -12,
      "name": "Wood_Beech_Trunk",
      "support": 15
    },
    {
      "x": 18,
      "y": 6,
      "z": -12,
      "name": "Wood_Beech_Trunk",
      "support": 15
    },
    {
      "x": 18,
      "y": 7,
      "z": -12,
      "name": "Wood_Beech_Trunk",
      "support": 15
    },
    {
      "x": 18,
      "y": 8,
      "z": -12,
      "name": "Wood_Beech_Branch_Long",
      "support": 15
    },
    {
      "x": 18,
      "y": 4,
      "z": -11,
      "name": "Wood_Softwood_Planks"
    },
    {
      "x": 18,
      "y": 5,
      "z": -11,
      "name": "Furniture_Tavern_Barrel"
    },
    {
      "x": 18,
      "y": 4,
      "z": -10,
      "name": "Wood_Softwood_Planks"
    },
    {
      "x": 18,
      "y": 4,
      "z": -9,
      "name": "Wood_Softwood_Planks"
    },
    {
      "x": 18,
      "y": 4,
      "z": -8,
      "name": "Wood_Softwood_Planks"
    },
    {
      "x": 18,
      "y": 4,
      "z": -7,
      "name": "Soil_Dirt"
    },
    {
      "x": 18,
      "y": 4,
      "z": -6,
      "name": "Soil_Dirt"
    },
    {
      "x": 18,
      "y": 4,
      "z": -5,
      "name": "Soil_Dirt"
    },
    {
      "x": 18,
      "y": 4,
      "z": -4,
      "name": "Soil_Dirt"
    },
    {
      "x": 19,
      "y": 4,
      "z": -28,
      "name": "Wood_Softwood_Planks"
    },
    {
      "x": 19,
      "y": 4,
      "z": -27,
      "name": "Wood_Softwood_Planks"
    },
    {
      "x": 19,
      "y": 4,
      "z": -26,
      "name": "Wood_Softwood_Planks"
    },
    {
      "x": 19,
      "y": 5,
      "z": -26,
      "name": "Furniture_Crude_Stool",
      "rotation": 3
    },
    {
      "x": 19,
      "y": 4,
      "z": -25,
      "name": "Wood_Softwood_Planks"
    },
    {
      "x": 19,
      "y": 5,
      "z": -25,
      "name": "Furniture_Village_Crate"
    },
    {
      "x": 19,
      "y": 6,
      "z": -25,
      "name": "Furniture_Crude_Stool",
      "rotation": 3
    },
    {
      "x": 19,
      "y": 4,
      "z": -24,
      "name": "Soil_Dirt"
    },
    {
      "x": 19,
      "y": 4,
      "z": -23,
      "name": "Soil_Dirt"
    },
    {
      "x": 19,
      "y": 5,
      "z": -23,
      "name": "Halloween_Wagon"
    },
    {
      "x": 19,
      "y": 4,
      "z": -22,
      "name": "Soil_Dirt"
    },
    {
      "x": 19,
      "y": 5,
      "z": -22,
      "name": "Halloween_Wagon",
      "filler": 32
    },
    {
      "x": 19,
      "y": 4,
      "z": -21,
      "name": "Soil_Dirt"
    },
    {
      "x": 19,
      "y": 4,
      "z": -20,
      "name": "Soil_Dirt"
    },
    {
      "x": 19,
      "y": 4,
      "z": -19,
      "name": "Wood_Softwood_Planks"
    },
    {
      "x": 19,
      "y": 4,
      "z": -18,
      "name": "Wood_Softwood_Planks"
    },
    {
      "x": 19,
      "y": 4,
      "z": -17,
      "name": "Wood_Softwood_Planks"
    },
    {
      "x": 19,
      "y": 4,
      "z": -16,
      "name": "Wood_Softwood_Planks"
    },
    {
      "x": 19,
      "y": 4,
      "z": -15,
      "name": "Wood_Softwood_Planks"
    },
    {
      "x": 19,
      "y": 4,
      "z": -14,
      "name": "Plant_Moss_Block_Green_Dark",
      "support": 15
    },
    {
      "x": 19,
      "y": 4,
      "z": -13,
      "name": "Rock_Stone_Mossy"
    },
    {
      "x": 19,
      "y": 4,
      "z": -12,
      "name": "Wood_Softwood_Planks"
    },
    {
      "x": 19,
      "y": 5,
      "z": -12,
      "name": "Furniture_Village_Crate"
    },
    {
      "x": 19,
      "y": 6,
      "z": -12,
      "name": "Furniture_Tavern_Barrel"
    },
    {
      "x": 19,
      "y": 4,
      "z": -11,
      "name": "Wood_Softwood_Planks"
    },
    {
      "x": 19,
      "y": 5,
      "z": -11,
      "name": "Furniture_Village_Crate"
    },
    {
      "x": 19,
      "y": 4,
      "z": -10,
      "name": "Wood_Softwood_Planks"
    },
    {
      "x": 19,
      "y": 4,
      "z": -9,
      "name": "Wood_Softwood_Planks"
    },
    {
      "x": 19,
      "y": 4,
      "z": -8,
      "name": "Soil_Dirt"
    },
    {
      "x": 19,
      "y": 4,
      "z": -7,
      "name": "Soil_Dirt"
    },
    {
      "x": 20,
      "y": 4,
      "z": -28,
      "name": "Wood_Softwood_Planks"
    },
    {
      "x": 20,
      "y": 4,
      "z": -27,
      "name": "Wood_Softwood_Planks"
    },
    {
      "x": 20,
      "y": 4,
      "z": -26,
      "name": "Wood_Softwood_Planks"
    },
    {
      "x": 20,
      "y": 5,
      "z": -26,
      "name": "Furniture_Village_Crate"
    },
    {
      "x": 20,
      "y": 6,
      "z": -26,
      "name": "Furniture_Tavern_Barrel"
    },
    {
      "x": 20,
      "y": 4,
      "z": -25,
      "name": "Wood_Softwood_Planks"
    },
    {
      "x": 20,
      "y": 5,
      "z": -25,
      "name": "Furniture_Village_Crate"
    },
    {
      "x": 20,
      "y": 6,
      "z": -25,
      "name": "Furniture_Village_Crate"
    },
    {
      "x": 20,
      "y": 7,
      "z": -25,
      "name": "Deco_Potion",
      "rotation": 1
    },
    {
      "x": 20,
      "y": 4,
      "z": -24,
      "name": "Soil_Dirt"
    },
    {
      "x": 20,
      "y": 4,
      "z": -23,
      "name": "Soil_Dirt"
    },
    {
      "x": 20,
      "y": 5,
      "z": -23,
      "name": "Halloween_Wagon",
      "filler": 1
    },
    {
      "x": 20,
      "y": 4,
      "z": -22,
      "name": "Soil_Dirt"
    },
    {
      "x": 20,
      "y": 5,
      "z": -22,
      "name": "Halloween_Wagon",
      "filler": 33
    },
    {
      "x": 20,
      "y": 4,
      "z": -21,
      "name": "Soil_Dirt"
    },
    {
      "x": 20,
      "y": 5,
      "z": -21,
      "name": "Furniture_Village_Crate"
    },
    {
      "x": 20,
      "y": 4,
      "z": -20,
      "name": "Soil_Dirt"
    },
    {
      "x": 20,
      "y": 5,
      "z": -20,
      "name": "Furniture_Village_Crate"
    },
    {
      "x": 20,
      "y": 4,
      "z": -19,
      "name": "Wood_Softwood_Planks"
    },
    {
      "x": 20,
      "y": 4,
      "z": -18,
      "name": "Wood_Softwood_Planks"
    },
    {
      "x": 20,
      "y": 4,
      "z": -17,
      "name": "Wood_Softwood_Planks"
    },
    {
      "x": 20,
      "y": 4,
      "z": -16,
      "name": "Wood_Softwood_Planks"
    },
    {
      "x": 20,
      "y": 4,
      "z": -15,
      "name": "Wood_Softwood_Planks"
    },
    {
      "x": 20,
      "y": 4,
      "z": -14,
      "name": "Plant_Moss_Block_Green_Dark",
      "support": 15
    },
    {
      "x": 20,
      "y": 4,
      "z": -13,
      "name": "Rock_Stone_Mossy"
    },
    {
      "x": 20,
      "y": 4,
      "z": -12,
      "name": "Rock_Stone_Mossy"
    },
    {
      "x": 20,
      "y": 4,
      "z": -11,
      "name": "Wood_Softwood_Planks"
    },
    {
      "x": 20,
      "y": 4,
      "z": -10,
      "name": "Wood_Softwood_Planks"
    },
    {
      "x": 20,
      "y": 4,
      "z": -9,
      "name": "Wood_Softwood_Planks"
    },
    {
      "x": 20,
      "y": 4,
      "z": -8,
      "name": "Soil_Dirt"
    },
    {
      "x": 21,
      "y": 4,
      "z": -23,
      "name": "Soil_Dirt"
    },
    {
      "x": 21,
      "y": 4,
      "z": -22,
      "name": "Soil_Dirt"
    },
    {
      "x": 21,
      "y": 4,
      "z": -21,
      "name": "Soil_Dirt"
    },
    {
      "x": 21,
      "y": 5,
      "z": -21,
      "name": "Furniture_Village_Crate"
    },
    {
      "x": 21,
      "y": 6,
      "z": -21,
      "name": "Furniture_Village_Crate"
    },
    {
      "x": 21,
      "y": 4,
      "z": -20,
      "name": "Soil_Dirt"
    },
    {
      "x": 21,
      "y": 5,
      "z": -20,
      "name": "Furniture_Village_Crate"
    },
    {
      "x": 21,
      "y": 6,
      "z": -20,
      "name": "Furniture_Village_Crate"
    },
    {
      "x": 21,
      "y": 4,
      "z": -19,
      "name": "Soil_Dirt"
    },
    {
      "x": 21,
      "y": 5,
      "z": -19,
      "name": "Furniture_Village_Crate"
    },
    {
      "x": 21,
      "y": 4,
      "z": -18,
      "name": "Soil_Dirt"
    },
    {
      "x": 21,
      "y": 4,
      "z": -17,
      "name": "Wood_Softwood_Planks"
    },
    {
      "x": 21,
      "y": 4,
      "z": -16,
      "name": "Wood_Softwood_Planks"
    },
    {
      "x": 21,
      "y": 4,
      "z": -15,
      "name": "Rock_Stone"
    },
    {
      "x": 21,
      "y": 4,
      "z": -14,
      "name": "Wood_Softwood_Planks"
    },
    {
      "x": 21,
      "y": 4,
      "z": -13,
      "name": "Rock_Stone_Mossy"
    },
    {
      "x": 21,
      "y": 4,
      "z": -12,
      "name": "Soil_Dirt"
    },
    {
      "x": 21,
      "y": 5,
      "z": -12,
      "name": "Rubble_Stone"
    },
    {
      "x": 21,
      "y": 4,
      "z": -11,
      "name": "Plant_Moss_Block_Green_Dark",
      "support": 15
    },
    {
      "x": 21,
      "y": 4,
      "z": -10,
      "name": "Plant_Moss_Block_Green_Dark",
      "support": 15
    },
    {
      "x": 21,
      "y": 4,
      "z": -9,
      "name": "Soil_Dirt"
    },
    {
      "x": 22,
      "y": 4,
      "z": -19,
      "name": "Soil_Dirt"
    },
    {
      "x": 22,
      "y": 5,
      "z": -19,
      "name": "Furniture_Tavern_Barrel"
    },
    {
      "x": 22,
      "y": 4,
      "z": -18,
      "name": "Soil_Dirt"
    },
    {
      "x": 22,
      "y": 4,
      "z": -17,
      "name": "Soil_Dirt"
    },
    {
      "x": 22,
      "y": 4,
      "z": -16,
      "name": "Rock_Basalt"
    },
    {
      "x": 22,
      "y": 4,
      "z": -15,
      "name": "Wood_Softwood_Planks"
    },
    {
      "x": 22,
      "y": 4,
      "z": -14,
      "name": "Rock_Basalt"
    },
    {
      "x": 22,
      "y": 4,
      "z": -13,
      "name": "Soil_Dirt"
    },
    {
      "x": 22,
      "y": 4,
      "z": -12,
      "name": "Soil_Dirt"
    },
    {
      "x": 22,
      "y": 4,
      "z": -11,
      "name": "Plant_Moss_Block_Green_Dark",
      "support": 15
    },
    {
      "x": 22,
      "y": 4,
      "z": -10,
      "name": "Soil_Dirt"
    },
    {
      "x": 23,
      "y": 4,
      "z": -19,
      "name": "Soil_Dirt"
    },
    {
      "x": 23,
      "y": 4,
      "z": -18,
      "name": "Soil_Dirt"
    },
    {
      "x": 23,
      "y": 5,
      "z": -18,
      "name": "Cloth_Roof_Blue",
      "rotation": 2
    },
    {
      "x": 23,
      "y": 4,
      "z": -17,
      "name": "Wood_Softwood_Planks"
    },
    {
      "x": 23,
      "y": 5,
      "z": -17,
      "name": "Furniture_Crude_Stool",
      "rotation": 3
    },
    {
      "x": 23,
      "y": 6,
      "z": -17,
      "name": "Cloth_Roof_Blue",
      "rotation": 2
    },
    {
      "x": 23,
      "y": 4,
      "z": -16,
      "name": "Wood_Softwood_Planks"
    },
    {
      "x": 23,
      "y": 7,
      "z": -16,
      "name": "Cloth_Roof_Blue",
      "rotation": 2
    },
    {
      "x": 23,
      "y": 4,
      "z": -15,
      "name": "Wood_Softwood_Planks"
    },
    {
      "x": 23,
      "y": 5,
      "z": -15,
      "name": "Wood_Beech_Branch_Long"
    },
    {
      "x": 23,
      "y": 6,
      "z": -15,
      "name": "Wood_Softwood_Beam"
    },
    {
      "x": 23,
      "y": 7,
      "z": -15,
      "name": "Wood_Softwood_Beam"
    },
    {
      "x": 23,
      "y": 8,
      "z": -15,
      "name": "Cloth_Roof_Blue_Flat"
    },
    {
      "x": 23,
      "y": 7,
      "z": -14,
      "name": "Cloth_Roof_Blue"
    },
    {
      "x": 23,
      "y": 4,
      "z": -13,
      "name": "Wood_Softwood_Planks"
    },
    {
      "x": 23,
      "y": 6,
      "z": -13,
      "name": "Cloth_Roof_Blue"
    },
    {
      "x": 23,
      "y": 4,
      "z": -12,
      "name": "Soil_Dirt"
    },
    {
      "x": 23,
      "y": 5,
      "z": -12,
      "name": "Cloth_Roof_Blue"
    },
    {
      "x": 23,
      "y": 4,
      "z": -11,
      "name": "Soil_Dirt"
    },
    {
      "x": 23,
      "y": 4,
      "z": -10,
      "name": "Soil_Dirt"
    },
    {
      "x": 24,
      "y": 4,
      "z": -19,
      "name": "Wood_Softwood_Planks"
    },
    {
      "x": 24,
      "y": 4,
      "z": -18,
      "name": "Wood_Softwood_Planks"
    },
    {
      "x": 24,
      "y": 5,
      "z": -18,
      "name": "Cloth_Roof_Blue",
      "rotation": 2
    },
    {
      "x": 24,
      "y": 4,
      "z": -17,
      "name": "Wood_Softwood_Planks"
    },
    {
      "x": 24,
      "y": 6,
      "z": -17,
      "name": "Cloth_Roof_Blue",
      "rotation": 2
    },
    {
      "x": 24,
      "y": 4,
      "z": -16,
      "name": "Wood_Softwood_Planks"
    },
    {
      "x": 24,
      "y": 7,
      "z": -16,
      "name": "Cloth_Roof_Blue",
      "rotation": 2
    },
    {
      "x": 24,
      "y": 4,
      "z": -15,
      "name": "Wood_Softwood_Planks"
    },
    {
      "x": 24,
      "y": 8,
      "z": -15,
      "name": "Cloth_Roof_Blue_Flat"
    },
    {
      "x": 24,
      "y": 4,
      "z": -14,
      "name": "Wood_Softwood_Planks"
    },
    {
      "x": 24,
      "y": 7,
      "z": -14,
      "name": "Cloth_Roof_Blue"
    },
    {
      "x": 24,
      "y": 4,
      "z": -13,
      "name": "Wood_Softwood_Planks"
    },
    {
      "x": 24,
      "y": 5,
      "z": -13,
      "name": "Furniture_Crude_Bed",
      "filler": 31,
      "rotation": 3
    },
    {
      "x": 24,
      "y": 6,
      "z": -13,
      "name": "Cloth_Roof_Blue"
    },
    {
      "x": 24,
      "y": 4,
      "z": -12,
      "name": "Wood_Softwood_Planks"
    },
    {
      "x": 24,
      "y": 5,
      "z": -12,
      "name": "Cloth_Roof_Blue"
    },
    {
      "x": 24,
      "y": 4,
      "z": -11,
      "name": "Soil_Dirt"
    },
    {
      "x": 25,
      "y": 4,
      "z": -18,
      "name": "Wood_Softwood_Planks"
    },
    {
      "x": 25,
      "y": 5,
      "z": -18,
      "name": "Cloth_Roof_Blue",
      "rotation": 2
    },
    {
      "x": 25,
      "y": 4,
      "z": -17,
      "name": "Wood_Softwood_Planks"
    },
    {
      "x": 25,
      "y": 6,
      "z": -17,
      "name": "Cloth_Roof_Blue",
      "rotation": 2
    },
    {
      "x": 25,
      "y": 4,
      "z": -16,
      "name": "Wood_Softwood_Planks"
    },
    {
      "x": 25,
      "y": 5,
      "z": -16,
      "name": "Furniture_Village_Crate"
    },
    {
      "x": 25,
      "y": 6,
      "z": -16,
      "name": "Furniture_Lumberjack_Lantern"
    },
    {
      "x": 25,
      "y": 7,
      "z": -16,
      "name": "Cloth_Roof_Blue",
      "rotation": 2
    },
    {
      "x": 25,
      "y": 4,
      "z": -15,
      "name": "Wood_Softwood_Planks"
    },
    {
      "x": 25,
      "y": 8,
      "z": -15,
      "name": "Cloth_Roof_Blue_Flat"
    },
    {
      "x": 25,
      "y": 4,
      "z": -14,
      "name": "Wood_Softwood_Planks"
    },
    {
      "x": 25,
      "y": 7,
      "z": -14,
      "name": "Cloth_Roof_Blue"
    },
    {
      "x": 25,
      "y": 4,
      "z": -13,
      "name": "Wood_Softwood_Planks"
    },
    {
      "x": 25,
      "y": 5,
      "z": -13,
      "name": "Furniture_Crude_Bed",
      "components": {
        "Components": {
          "PlacedByInteraction": {
            "WhoPlacedUuid": {
              "$binary": "8sLHK5K0OeyImipqK/jB6Q==",
              "$type": "04"
            }
          },
          "RespawnBlock": {}
        }
      },
      "rotation": 3
    },
    {
      "x": 25,
      "y": 6,
      "z": -13,
      "name": "Cloth_Roof_Blue"
    },
    {
      "x": 25,
      "y": 4,
      "z": -12,
      "name": "Wood_Softwood_Planks"
    },
    {
      "x": 25,
      "y": 5,
      "z": -12,
      "name": "Cloth_Roof_Blue"
    },
    {
      "x": 25,
      "y": 4,
      "z": -11,
      "name": "Soil_Dirt"
    },
    {
      "x": 26,
      "y": 4,
      "z": -18,
      "name": "Wood_Softwood_Planks"
    },
    {
      "x": 26,
      "y": 5,
      "z": -18,
      "name": "Cloth_Roof_Blue",
      "rotation": 2
    },
    {
      "x": 26,
      "y": 4,
      "z": -17,
      "name": "Wood_Softwood_Planks"
    },
    {
      "x": 26,
      "y": 5,
      "z": -17,
      "name": "Furniture_Village_Crate"
    },
    {
      "x": 26,
      "y": 6,
      "z": -17,
      "name": "Cloth_Roof_Blue",
      "rotation": 2
    },
    {
      "x": 26,
      "y": 4,
      "z": -16,
      "name": "Wood_Softwood_Planks"
    },
    {
      "x": 26,
      "y": 7,
      "z": -16,
      "name": "Cloth_Roof_Blue",
      "rotation": 2
    },
    {
      "x": 26,
      "y": 4,
      "z": -15,
      "name": "Wood_Softwood_Planks"
    },
    {
      "x": 26,
      "y": 8,
      "z": -15,
      "name": "Cloth_Roof_Blue_Flat"
    },
    {
      "x": 26,
      "y": 4,
      "z": -14,
      "name": "Wood_Softwood_Planks"
    },
    {
      "x": 26,
      "y": 7,
      "z": -14,
      "name": "Cloth_Roof_Blue"
    },
    {
      "x": 26,
      "y": 4,
      "z": -13,
      "name": "Wood_Softwood_Planks"
    },
    {
      "x": 26,
      "y": 6,
      "z": -13,
      "name": "Cloth_Roof_Blue"
    },
    {
      "x": 26,
      "y": 4,
      "z": -12,
      "name": "Wood_Softwood_Planks"
    },
    {
      "x": 26,
      "y": 5,
      "z": -12,
      "name": "Cloth_Roof_Blue"
    },
    {
      "x": 26,
      "y": 4,
      "z": -11,
      "name": "Soil_Dirt"
    },
    {
      "x": 27,
      "y": 4,
      "z": -18,
      "name": "Wood_Softwood_Planks"
    },
    {
      "x": 27,
      "y": 5,
      "z": -18,
      "name": "Cloth_Roof_Blue",
      "rotation": 2
    },
    {
      "x": 27,
      "y": 4,
      "z": -17,
      "name": "Wood_Softwood_Planks"
    },
    {
      "x": 27,
      "y": 5,
      "z": -17,
      "name": "Furniture_Village_Crate"
    },
    {
      "x": 27,
      "y": 6,
      "z": -17,
      "name": "Cloth_Roof_Blue",
      "rotation": 2
    },
    {
      "x": 27,
      "y": 4,
      "z": -16,
      "name": "Wood_Softwood_Planks"
    },
    {
      "x": 27,
      "y": 5,
      "z": -16,
      "name": "Furniture_Village_Crate"
    },
    {
      "x": 27,
      "y": 6,
      "z": -16,
      "name": "Deco_Scroll",
      "rotation": 1
    },
    {
      "x": 27,
      "y": 7,
      "z": -16,
      "name": "Cloth_Roof_Blue",
      "rotation": 2
    },
    {
      "x": 27,
      "y": 4,
      "z": -15,
      "name": "Wood_Softwood_Planks"
    },
    {
      "x": 27,
      "y": 8,
      "z": -15,
      "name": "Cloth_Roof_Blue_Flat"
    },
    {
      "x": 27,
      "y": 4,
      "z": -14,
      "name": "Wood_Softwood_Planks"
    },
    {
      "x": 27,
      "y": 7,
      "z": -14,
      "name": "Cloth_Roof_Blue"
    },
    {
      "x": 27,
      "y": 4,
      "z": -13,
      "name": "Wood_Softwood_Planks"
    },
    {
      "x": 27,
      "y": 5,
      "z": -13,
      "name": "Furniture_Tavern_Barrel"
    },
    {
      "x": 27,
      "y": 6,
      "z": -13,
      "name": "Cloth_Roof_Blue"
    },
    {
      "x": 27,
      "y": 4,
      "z": -12,
      "name": "Soil_Dirt"
    },
    {
      "x": 27,
      "y": 5,
      "z": -12,
      "name": "Cloth_Roof_Blue"
    },
    {
      "x": 28,
      "y": 4,
      "z": -18,
      "name": "Soil_Dirt"
    },
    {
      "x": 28,
      "y": 5,
      "z": -18,
      "name": "Cloth_Roof_Blue",
      "rotation": 2
    },
    {
      "x": 28,
      "y": 4,
      "z": -17,
      "name": "Wood_Softwood_Planks"
    },
    {
      "x": 28,
      "y": 5,
      "z": -17,
      "name": "Rubble_Stone"
    },
    {
      "x": 28,
      "y": 6,
      "z": -17,
      "name": "Cloth_Roof_Blue",
      "rotation": 2
    },
    {
      "x": 28,
      "y": 4,
      "z": -16,
      "name": "Wood_Softwood_Planks"
    },
    {
      "x": 28,
      "y": 7,
      "z": -16,
      "name": "Cloth_Roof_Blue",
      "rotation": 2
    },
    {
      "x": 28,
      "y": 4,
      "z": -15,
      "name": "Wood_Softwood_Planks"
    },
    {
      "x": 28,
      "y": 5,
      "z": -15,
      "name": "Wood_Beech_Branch_Long"
    },
    {
      "x": 28,
      "y": 6,
      "z": -15,
      "name": "Wood_Softwood_Beam"
    },
    {
      "x": 28,
      "y": 7,
      "z": -15,
      "name": "Wood_Softwood_Beam"
    },
    {
      "x": 28,
      "y": 8,
      "z": -15,
      "name": "Cloth_Roof_Blue_Flat"
    },
    {
      "x": 28,
      "y": 4,
      "z": -14,
      "name": "Wood_Softwood_Planks"
    },
    {
      "x": 28,
      "y": 7,
      "z": -14,
      "name": "Cloth_Roof_Blue"
    },
    {
      "x": 28,
      "y": 4,
      "z": -13,
      "name": "Wood_Softwood_Planks"
    },
    {
      "x": 28,
      "y": 5,
      "z": -13,
      "name": "Rubble_Stone_Medium"
    },
    {
      "x": 28,
      "y": 6,
      "z": -13,
      "name": "Cloth_Roof_Blue"
    },
    {
      "x": 28,
      "y": 4,
      "z": -12,
      "name": "Soil_Dirt"
    },
    {
      "x": 28,
      "y": 5,
      "z": -12,
      "name": "Cloth_Roof_Blue"
    },
    {
      "x": 29,
      "y": 4,
      "z": -16,
      "name": "Soil_Dirt"
    },
    {
      "x": 29,
      "y": 4,
      "z": -15,
      "name": "Wood_Softwood_Planks"
    },
    {
      "x": 29,
      "y": 4,
      "z": -14,
      "name": "Wood_Softwood_Planks"
    },
    {
      "x": 29,
      "y": 4,
      "z": -13,
      "name": "Soil_Dirt"
    }
  ],
  "fluids": [
    {
      "x": 1,
      "y": 4,
      "z": -16,
      "name": "Empty",
      "level": 0
    },
    {
      "x": 1,
      "y": 7,
      "z": -16,
      "name": "Empty",
      "level": 0
    },
    {
      "x": 1,
      "y": 8,
      "z": -16,
      "name": "Empty",
      "level": 0
    },
    {
      "x": 1,
      "y": 9,
      "z": -16,
      "name": "Empty",
      "level": 0
    },
    {
      "x": 1,
      "y": 4,
      "z": -15,
      "name": "Empty",
      "level": 0
    },
    {
      "x": 1,
      "y": 7,
      "z": -15,
      "name": "Empty",
      "level": 0
    },
    {
      "x": 1,
      "y": 8,
      "z": -15,
      "name": "Empty",
      "level": 0
    },
    {
      "x": 1,
      "y": 4,
      "z": -14,
      "name": "Empty",
      "level": 0
    },
    {
      "x": 1,
      "y": 7,
      "z": -14,
      "name": "Empty",
      "level": 0
    },
    {
      "x": 1,
      "y": 8,
      "z": -14,
      "name": "Empty",
      "level": 0
    },
    {
      "x": 1,
      "y": 4,
      "z": -13,
      "name": "Empty",
      "level": 0
    },
    {
      "x": 2,
      "y": 4,
      "z": -17,
      "name": "Empty",
      "level": 0
    },
    {
      "x": 2,
      "y": 4,
      "z": -16,
      "name": "Empty",
      "level": 0
    },
    {
      "x": 2,
      "y": 5,
      "z": -16,
      "name": "Empty",
      "level": 0
    },
    {
      "x": 2,
      "y": 7,
      "z": -16,
      "name": "Empty",
      "level": 0
    },
    {
      "x": 2,
      "y": 8,
      "z": -16,
      "name": "Empty",
      "level": 0
    },
    {
      "x": 2,
      "y": 4,
      "z": -15,
      "name": "Empty",
      "level": 0
    },
    {
      "x": 2,
      "y": 5,
      "z": -15,
      "name": "Empty",
      "level": 0
    },
    {
      "x": 2,
      "y": 7,
      "z": -15,
      "name": "Empty",
      "level": 0
    },
    {
      "x": 2,
      "y": 8,
      "z": -15,
      "name": "Empty",
      "level": 0
    },
    {
      "x": 2,
      "y": 9,
      "z": -15,
      "name": "Empty",
      "level": 0
    },
    {
      "x": 2,
      "y": 10,
      "z": -15,
      "name": "Empty",
      "level": 0
    },
    {
      "x": 2,
      "y": 11,
      "z": -15,
      "name": "Empty",
      "level": 0
    },
    {
      "x": 2,
      "y": 4,
      "z": -14,
      "name": "Empty",
      "level": 0
    },
    {
      "x": 2,
      "y": 5,
      "z": -14,
      "name": "Empty",
      "level": 0
    },
    {
      "x": 2,
      "y": 7,
      "z": -14,
      "name": "Empty",
      "level": 0
    },
    {
      "x": 2,
      "y": 8,
      "z": -14,
      "name": "Empty",
      "level": 0
    },
    {
      "x": 2,
      "y": 4,
      "z": -13,
      "name": "Empty",
      "level": 0
    },
    {
      "x": 2,
      "y": 5,
      "z": -13,
      "name": "Empty",
      "level": 0
    },
    {
      "x": 2,
      "y": 4,
      "z": -12,
      "name": "Empty",
      "level": 0
    },
    {
      "x": 3,
      "y": 4,
      "z": -17,
      "name": "Empty",
      "level": 0
    },
    {
      "x": 3,
      "y": 4,
      "z": -16,
      "name": "Empty",
      "level": 0
    },
    {
      "x": 3,
      "y": 7,
      "z": -16,
      "name": "Empty",
      "level": 0
    },
    {
      "x": 3,
      "y": 8,
      "z": -16,
      "name": "Empty",
      "level": 0
    },
    {
      "x": 3,
      "y": 4,
      "z": -15,
      "name": "Empty",
      "level": 0
    },
    {
      "x": 3,
      "y": 7,
      "z": -15,
      "name": "Empty",
      "level": 0
    },
    {
      "x": 3,
      "y": 8,
      "z": -15,
      "name": "Empty",
      "level": 0
    },
    {
      "x": 3,
      "y": 11,
      "z": -15,
      "name": "Empty",
      "level": 0
    },
    {
      "x": 3,
      "y": 4,
      "z": -14,
      "name": "Empty",
      "level": 0
    },
    {
      "x": 3,
      "y": 5,
      "z": -14,
      "name": "Empty",
      "level": 0
    },
    {
      "x": 3,
      "y": 7,
      "z": -14,
      "name": "Empty",
      "level": 0
    },
    {
      "x": 3,
      "y": 8,
      "z": -14,
      "name": "Empty",
      "level": 0
    },
    {
      "x": 3,
      "y": 9,
      "z": -14,
      "name": "Empty",
      "level": 0
    },
    {
      "x": 3,
      "y": 4,
      "z": -13,
      "name": "Empty",
      "level": 0
    },
    {
      "x": 3,
      "y": 4,
      "z": -12,
      "name": "Empty",
      "level": 0
    },
    {
      "x": 4,
      "y": 4,
      "z": -25,
      "name": "Empty",
      "level": 0
    },
    {
      "x": 4,
      "y": 5,
      "z": -25,
      "name": "Empty",
      "level": 0
    },
    {
      "x": 4,
      "y": 4,
      "z": -24,
      "name": "Empty",
      "level": 0
    },
    {
      "x": 4,
      "y": 4,
      "z": -23,
      "name": "Empty",
      "level": 0
    },
    {
      "x": 4,
      "y": 4,
      "z": -22,
      "name": "Empty",
      "level": 0
    },
    {
      "x": 4,
      "y": 4,
      "z": -19,
      "name": "Empty",
      "level": 0
    },
    {
      "x": 4,
      "y": 4,
      "z": -18,
      "name": "Empty",
      "level": 0
    },
    {
      "x": 4,
      "y": 4,
      "z": -17,
      "name": "Empty",
      "level": 0
    },
    {
      "x": 4,
      "y": 5,
      "z": -17,
      "name": "Empty",
      "level": 0
    },
    {
      "x": 4,
      "y": 4,
      "z": -16,
      "name": "Empty",
      "level": 0
    },
    {
      "x": 4,
      "y": 4,
      "z": -15,
      "name": "Empty",
      "level": 0
    },
    {
      "x": 4,
      "y": 5,
      "z": -15,
      "name": "Empty",
      "level": 0
    },
    {
      "x": 4,
      "y": 11,
      "z": -15,
      "name": "Empty",
      "level": 0
    },
    {
      "x": 4,
      "y": 12,
      "z": -15,
      "name": "Empty",
      "level": 0
    },
    {
      "x": 4,
      "y": 4,
      "z": -14,
      "name": "Empty",
      "level": 0
    },
    {
      "x": 4,
      "y": 4,
      "z": -13,
      "name": "Empty",
      "level": 0
    },
    {
      "x": 4,
      "y": 5,
      "z": -13,
      "name": "Empty",
      "level": 0
    },
    {
      "x": 4,
      "y": 4,
      "z": -12,
      "name": "Empty",
      "level": 0
    },
    {
      "x": 4,
      "y": 4,
      "z": -11,
      "name": "Empty",
      "level": 0
    },
    {
      "x": 5,
      "y": 4,
      "z": -27,
      "name": "Empty",
      "level": 0
    },
    {
      "x": 5,
      "y": 5,
      "z": -27,
      "name": "Empty",
      "level": 0
    },
    {
      "x": 5,
      "y": 4,
      "z": -26,
      "name": "Empty",
      "level": 0
    },
    {
      "x": 5,
      "y": 6,
      "z": -26,
      "name": "Empty",
      "level": 0
    },
    {
      "x": 5,
      "y": 4,
      "z": -25,
      "name": "Empty",
      "level": 0
    },
    {
      "x": 5,
      "y": 7,
      "z": -25,
      "name": "Empty",
      "level": 0
    },
    {
      "x": 5,
      "y": 4,
      "z": -24,
      "name": "Empty",
      "level": 0
    },
    {
      "x": 5,
      "y": 5,
      "z": -24,
      "name": "Empty",
      "level": 0
    },
    {
      "x": 5,
      "y": 6,
      "z": -24,
      "name": "Empty",
      "level": 0
    },
    {
      "x": 5,
      "y": 7,
      "z": -24,
      "name": "Empty",
      "level": 0
    },
    {
      "x": 5,
      "y": 8,
      "z": -24,
      "name": "Empty",
      "level": 0
    },
    {
      "x": 5,
      "y": 4,
      "z": -23,
      "name": "Empty",
      "level": 0
    },
    {
      "x": 5,
      "y": 7,
      "z": -23,
      "name": "Empty",
      "level": 0
    },
    {
      "x": 5,
      "y": 4,
      "z": -22,
      "name": "Empty",
      "level": 0
    },
    {
      "x": 5,
      "y": 6,
      "z": -22,
      "name": "Empty",
      "level": 0
    },
    {
      "x": 5,
      "y": 4,
      "z": -21,
      "name": "Empty",
      "level": 0
    },
    {
      "x": 5,
      "y": 5,
      "z": -21,
      "name": "Empty",
      "level": 0
    },
    {
      "x": 5,
      "y": 4,
      "z": -20,
      "name": "Empty",
      "level": 0
    },
    {
      "x": 5,
      "y": 4,
      "z": -19,
      "name": "Empty",
      "level": 0
    },
    {
      "x": 5,
      "y": 5,
      "z": -19,
      "name": "Empty",
      "level": 0
    },
    {
      "x": 5,
      "y": 4,
      "z": -18,
      "name": "Empty",
      "level": 0
    },
    {
      "x": 5,
      "y": 4,
      "z": -17,
      "name": "Empty",
      "level": 0
    },
    {
      "x": 5,
      "y": 5,
      "z": -17,
      "name": "Empty",
      "level": 0
    },
    {
      "x": 5,
      "y": 6,
      "z": -17,
      "name": "Empty",
