{
  "version": 8,
  "blockIdVersion": 11,
  "anchorX": 0,
  "anchorY": 0,
  "anchorZ": 0,
  "blocks": [
    {
      "x": 1,
      "y": 1,
      "z": -11,
      "name": "Rock_Stone_Cobble"
    },
    {
      "x": 1,
      "y": 5,
      "z": -11,
      "name": "Wood_Softwood_Roof_Hollow",
      "rotation": 2
    },
    {
      "x": 1,
      "y": 1,
      "z": -10,
      "name": "Rock_Stone_Cobble"
    },
    {
      "x": 1,
      "y": 5,
      "z": -10,
      "name": "Wood_Beech_Branch_Corner",
      "support": 15,
      "rotation": 3
    },
    {
      "x": 1,
      "y": 6,
      "z": -10,
      "name": "Wood_Softwood_Roof",
      "rotation": 2
    },
    {
      "x": 1,
      "y": 1,
      "z": -9,
      "name": "Rock_Stone_Cobble"
    },
    {
      "x": 1,
      "y": 5,
      "z": -9,
      "name": "Plant_Vine_Wall",
      "support": 15,
      "rotation": 3
    },
    {
      "x": 1,
      "y": 6,
      "z": -9,
      "name": "Wood_Softwood_Stairs",
      "rotation": 10
    },
    {
      "x": 1,
      "y": 7,
      "z": -9,
      "name": "Wood_Softwood_Roof",
      "rotation": 2
    },
    {
      "x": 1,
      "y": 1,
      "z": -8,
      "name": "Rock_Stone_Cobble_Mossy"
    },
    {
      "x": 1,
      "y": 7,
      "z": -8,
      "name": "Wood_Softwood_Stairs",
      "rotation": 10
    },
    {
      "x": 1,
      "y": 8,
      "z": -8,
      "name": "Wood_Softwood_Roof",
      "rotation": 2
    },
    {
      "x": 1,
      "y": 1,
      "z": -7,
      "name": "Rock_Stone_Cobble_Mossy"
    },
    {
      "x": 1,
      "y": 8,
      "z": -7,
      "name": "Wood_Softwood_Planks"
    },
    {
      "x": 1,
      "y": 9,
      "z": -7,
      "name": "Wood_Softwood_Roof_Flat"
    },
    {
      "x": 1,
      "y": 1,
      "z": -6,
      "name": "Rock_Stone_Cobble"
    },
    {
      "x": 1,
      "y": 7,
      "z": -6,
      "name": "Wood_Softwood_Stairs",
      "rotation": 8
    },
    {
      "x": 1,
      "y": 8,
      "z": -6,
      "name": "Wood_Softwood_Roof"
    },
    {
      "x": 1,
      "y": 1,
      "z": -5,
      "name": "Rock_Stone_Cobble"
    },
    {
      "x": 1,
      "y": 3,
      "z": -5,
      "name": "Plant_Vine_Wall",
      "support": 15,
      "rotation": 3
    },
    {
      "x": 1,
      "y": 6,
      "z": -5,
      "name": "Wood_Softwood_Stairs",
      "rotation": 8
    },
    {
      "x": 1,
      "y": 7,
      "z": -5,
      "name": "Wood_Softwood_Roof"
    },
    {
      "x": 1,
      "y": 1,
      "z": -4,
      "name": "Rock_Stone_Cobble"
    },
    {
      "x": 1,
      "y": 5,
      "z": -4,
      "name": "Wood_Beech_Branch_Corner",
      "support": 15,
      "rotation": 3
    },
    {
      "x": 1,
      "y": 6,
      "z": -4,
      "name": "Wood_Softwood_Roof"
    },
    {
      "x": 1,
      "y": 1,
      "z": -3,
      "name": "Rock_Stone_Cobble"
    },
    {
      "x": 1,
      "y": 5,
      "z": -3,
      "name": "Wood_Softwood_Roof_Hollow"
    },
    {
      "x": 1,
      "y": 1,
      "z": -2,
      "name": "Rock_Stone_Cobble_Mossy"
    },
    {
      "x": 1,
      "y": 1,
      "z": -1,
      "name": "Rock_Stone_Cobble_Mossy"
    },
    {
      "x": 2,
      "y": 1,
      "z": -11,
      "name": "Rock_Stone_Cobble_Mossy"
    },
    {
      "x": 2,
      "y": 4,
      "z": -11,
      "name": "Wood_Beech_Branch_Corner",
      "support": 15,
      "rotation": 2
    },
    {
      "x": 2,
      "y": 5,
      "z": -11,
      "name": "Wood_Softwood_Roof",
      "rotation": 2
    },
    {
      "x": 2,
      "y": 1,
      "z": -10,
      "name": "Rock_Stone_Cobble"
    },
    {
      "x": 2,
      "y": 2,
      "z": -10,
      "name": "Wood_Beech_Trunk",
      "support": 15
    },
    {
      "x": 2,
      "y": 3,
      "z": -10,
      "name": "Wood_Beech_Trunk",
      "support": 15
    },
    {
      "x": 2,
      "y": 4,
      "z": -10,
      "name": "Wood_Beech_Trunk",
      "support": 15
    },
    {
      "x": 2,
      "y": 5,
      "z": -10,
      "name": "Wood_Beech_Trunk",
      "support": 15
    },
    {
      "x": 2,
      "y": 6,
      "z": -10,
      "name": "Wood_Softwood_Roof",
      "rotation": 2
    },
    {
      "x": 2,
      "y": 1,
      "z": -9,
      "name": "Rock_Stone_Cobble"
    },
    {
      "x": 2,
      "y": 2,
      "z": -9,
      "name": "Rock_Stone_Brick"
    },
    {
      "x": 2,
      "y": 3,
      "z": -9,
      "name": "*Wood_Village_Wall_Full_State_Definitions_Bottom"
    },
    {
      "x": 2,
      "y": 4,
      "z": -9,
      "name": "*Wood_Village_Wall_Full_State_Definitions_Top"
    },
    {
      "x": 2,
      "y": 5,
      "z": -9,
      "name": "Wood_Beech_Trunk",
      "support": 15,
      "rotation": 4
    },
    {
      "x": 2,
      "y": 6,
      "z": -9,
      "name": "Wood_Village_Wall_Full"
    },
    {
      "x": 2,
      "y": 7,
      "z": -9,
      "name": "Wood_Softwood_Roof",
      "rotation": 2
    },
    {
      "x": 2,
      "y": 1,
      "z": -8,
      "name": "Rock_Stone_Cobble"
    },
    {
      "x": 2,
      "y": 2,
      "z": -8,
      "name": "Rock_Stone_Brick"
    },
    {
      "x": 2,
      "y": 3,
      "z": -8,
      "name": "*Wood_Village_Wall_Full_State_Definitions_Bottom"
    },
    {
      "x": 2,
      "y": 4,
      "z": -8,
      "name": "*Wood_Village_Wall_Full_State_Definitions_Top"
    },
    {
      "x": 2,
      "y": 5,
      "z": -8,
      "name": "Wood_Beech_Trunk",
      "support": 15,
      "rotation": 4
    },
    {
      "x": 2,
      "y": 6,
      "z": -8,
      "name": "*Wood_Village_Wall_Full_State_Definitions_Bottom"
    },
    {
      "x": 2,
      "y": 7,
      "z": -8,
      "name": "*Wood_Village_Wall_Full_State_Definitions_Top"
    },
    {
      "x": 2,
      "y": 8,
      "z": -8,
      "name": "Wood_Softwood_Roof",
      "rotation": 2
    },
    {
      "x": 2,
      "y": 1,
      "z": -7,
      "name": "Rock_Stone_Cobble"
    },
    {
      "x": 2,
      "y": 2,
      "z": -7,
      "name": "Rock_Stone_Brick"
    },
    {
      "x": 2,
      "y": 3,
      "z": -7,
      "name": "Furniture_Village_Window",
      "rotation": 1
    },
    {
      "x": 2,
      "y": 4,
      "z": -7,
      "name": "Furniture_Village_Window",
      "rotation": 1
    },
    {
      "x": 2,
      "y": 5,
      "z": -7,
      "name": "Wood_Beech_Trunk",
      "support": 15,
      "rotation": 4
    },
    {
      "x": 2,
      "y": 6,
      "z": -7,
      "name": "Furniture_Village_Window",
      "rotation": 1
    },
    {
      "x": 2,
      "y": 7,
      "z": -7,
      "name": "Wood_Village_Wall_Full"
    },
    {
      "x": 2,
      "y": 8,
      "z": -7,
      "name": "Wood_Beech_Trunk",
      "support": 15,
      "rotation": 5
    },
    {
      "x": 2,
      "y": 9,
      "z": -7,
      "name": "Wood_Softwood_Roof_Flat"
    },
    {
      "x": 2,
      "y": 1,
      "z": -6,
      "name": "Rock_Stone_Cobble"
    },
    {
      "x": 2,
      "y": 2,
      "z": -6,
      "name": "Rock_Stone_Brick_Mossy"
    },
    {
      "x": 2,
      "y": 3,
      "z": -6,
      "name": "*Wood_Village_Wall_Full_State_Definitions_Bottom"
    },
    {
      "x": 2,
      "y": 4,
      "z": -6,
      "name": "*Wood_Village_Wall_Full_State_Definitions_Top"
    },
    {
      "x": 2,
      "y": 5,
      "z": -6,
      "name": "Wood_Beech_Trunk",
      "support": 15,
      "rotation": 4
    },
    {
      "x": 2,
      "y": 6,
      "z": -6,
      "name": "*Wood_Village_Wall_Full_State_Definitions_Bottom"
    },
    {
      "x": 2,
      "y": 7,
      "z": -6,
      "name": "*Wood_Village_Wall_Full_State_Definitions_Top"
    },
    {
      "x": 2,
      "y": 8,
      "z": -6,
      "name": "Wood_Softwood_Roof"
    },
    {
      "x": 2,
      "y": 1,
      "z": -5,
      "name": "Rock_Stone_Cobble"
    },
    {
      "x": 2,
      "y": 2,
      "z": -5,
      "name": "Rock_Stone_Brick"
    },
    {
      "x": 2,
      "y": 3,
      "z": -5,
      "name": "*Wood_Village_Wall_Full_State_Definitions_Bottom"
    },
    {
      "x": 2,
      "y": 4,
      "z": -5,
      "name": "*Wood_Village_Wall_Full_State_Definitions_Top"
    },
    {
      "x": 2,
      "y": 5,
      "z": -5,
      "name": "Wood_Beech_Trunk",
      "support": 15,
      "rotation": 4
    },
    {
      "x": 2,
      "y": 6,
      "z": -5,
      "name": "Wood_Village_Wall_Full"
    },
    {
      "x": 2,
      "y": 7,
      "z": -5,
      "name": "Wood_Softwood_Roof"
    },
    {
      "x": 2,
      "y": 1,
      "z": -4,
      "name": "Rock_Stone_Cobble"
    },
    {
      "x": 2,
      "y": 2,
      "z": -4,
      "name": "Wood_Beech_Trunk",
      "support": 15
    },
    {
      "x": 2,
      "y": 3,
      "z": -4,
      "name": "Wood_Beech_Trunk",
      "support": 15
    },
    {
      "x": 2,
      "y": 4,
      "z": -4,
      "name": "Wood_Beech_Trunk",
      "support": 15
    },
    {
      "x": 2,
      "y": 5,
      "z": -4,
      "name": "Wood_Beech_Trunk",
      "support": 15
    },
    {
      "x": 2,
      "y": 6,
      "z": -4,
      "name": "Wood_Softwood_Roof"
    },
    {
      "x": 2,
      "y": 1,
      "z": -3,
      "name": "Rock_Stone_Cobble"
    },
    {
      "x": 2,
      "y": 5,
      "z": -3,
      "name": "Wood_Softwood_Roof_Hollow"
    },
    {
      "x": 2,
      "y": 1,
      "z": -2,
      "name": "Rock_Stone_Cobble"
    },
    {
      "x": 2,
      "y": 1,
      "z": -1,
      "name": "Rock_Stone_Cobble"
    },
    {
      "x": 3,
      "y": 1,
      "z": -11,
      "name": "Rock_Stone_Cobble"
    },
    {
      "x": 3,
      "y": 3,
      "z": -11,
      "name": "Plant_Vine_Wall",
      "support": 15,
      "rotation": 2
    },
    {
      "x": 3,
      "y": 5,
      "z": -11,
      "name": "Wood_Softwood_Roof_Hollow",
      "rotation": 2
    },
    {
      "x": 3,
      "y": 1,
      "z": -10,
      "name": "Rock_Stone_Cobble"
    },
    {
      "x": 3,
      "y": 2,
      "z": -10,
      "name": "Rock_Stone_Brick"
    },
    {
      "x": 3,
      "y": 3,
      "z": -10,
      "name": "*Wood_Village_Wall_Full_State_Definitions_Bottom"
    },
    {
      "x": 3,
      "y": 4,
      "z": -10,
      "name": "*Wood_Village_Wall_Full_State_Definitions_Top"
    },
    {
      "x": 3,
      "y": 5,
      "z": -10,
      "name": "Wood_Beech_Trunk",
      "support": 15,
      "rotation": 5
    },
    {
      "x": 3,
      "y": 6,
      "z": -10,
      "name": "Wood_Softwood_Roof",
      "rotation": 2
    },
    {
      "x": 3,
      "y": 1,
      "z": -9,
      "name": "Wood_Softwood_Planks"
    },
    {
      "x": 3,
      "y": 2,
      "z": -9,
      "name": "Furniture_Tavern_Barrel",
      "support": 15
    },
    {
      "x": 3,
      "y": 3,
      "z": -9,
      "name": "Furniture_Tavern_Shelf",
      "support": 15,
      "rotation": 1
    },
    {
      "x": 3,
      "y": 6,
      "z": -9,
      "name": "Wood_Softwood_Stairs",
      "rotation": 10
    },
    {
      "x": 3,
      "y": 7,
      "z": -9,
      "name": "Wood_Softwood_Roof",
      "rotation": 2
    },
    {
      "x": 3,
      "y": 1,
      "z": -8,
      "name": "Wood_Softwood_Planks"
    },
    {
      "x": 3,
      "y": 2,
      "z": -8,
      "name": "Bench_Cooking",
      "components": {
        "Components": {
          "BenchBlock": {
            "TierLevel": 1,
            "UpgradeItems": []
          },
          "PlacedByInteraction": {
            "WhoPlacedUuid": {
              "$binary": "v7RyWIT/TYKnXA2XcxdQtw==",
              "$type": "04"
            }
          }
        }
      },
      "support": 15,
      "rotation": 1
    },
    {
      "x": 3,
      "y": 7,
      "z": -8,
      "name": "Wood_Softwood_Stairs",
      "rotation": 10
    },
    {
      "x": 3,
      "y": 8,
      "z": -8,
      "name": "Wood_Softwood_Roof",
      "rotation": 2
    },
    {
      "x": 3,
      "y": 1,
      "z": -7,
      "name": "Wood_Softwood_Planks"
    },
    {
      "x": 3,
      "y": 8,
      "z": -7,
      "name": "Wood_Beech_Trunk",
      "support": 15,
      "rotation": 5
    },
    {
      "x": 3,
      "y": 9,
      "z": -7,
      "name": "Wood_Softwood_Roof_Flat"
    },
    {
      "x": 3,
      "y": 1,
      "z": -6,
      "name": "Wood_Softwood_Planks"
    },
    {
      "x": 3,
      "y": 2,
      "z": -6,
      "name": "Furniture_Tavern_Barrel",
      "support": 15
    },
    {
      "x": 3,
      "y": 3,
      "z": -6,
      "name": "Furniture_Tavern_Shelf",
      "support": 15,
      "rotation": 1
    },
    {
      "x": 3,
      "y": 7,
      "z": -6,
      "name": "Wood_Softwood_Stairs",
      "rotation": 8
    },
    {
      "x": 3,
      "y": 8,
      "z": -6,
      "name": "Wood_Softwood_Roof"
    },
    {
      "x": 3,
      "y": 1,
      "z": -5,
      "name": "Wood_Softwood_Planks"
    },
    {
      "x": 3,
      "y": 2,
      "z": -5,
      "name": "Furniture_Tavern_Barrel",
      "support": 15
    },
    {
      "x": 3,
      "y": 3,
      "z": -5,
      "name": "Furniture_Tavern_Shelf",
      "support": 15,
      "rotation": 1
    },
    {
      "x": 3,
      "y": 6,
      "z": -5,
      "name": "Wood_Softwood_Stairs",
      "rotation": 8
    },
    {
      "x": 3,
      "y": 7,
      "z": -5,
      "name": "Wood_Softwood_Roof"
    },
    {
      "x": 3,
      "y": 1,
      "z": -4,
      "name": "Rock_Stone_Cobble_Mossy"
    },
    {
      "x": 3,
      "y": 2,
      "z": -4,
      "name": "Rock_Stone_Brick"
    },
    {
      "x": 3,
      "y": 3,
      "z": -4,
      "name": "*Wood_Village_Wall_Full_State_Definitions_Bottom"
    },
    {
      "x": 3,
      "y": 4,
      "z": -4,
      "name": "*Wood_Village_Wall_Full_State_Definitions_Top"
    },
    {
      "x": 3,
      "y": 5,
      "z": -4,
      "name": "Wood_Beech_Trunk",
      "support": 15,
      "rotation": 5
    },
    {
      "x": 3,
      "y": 6,
      "z": -4,
      "name": "Wood_Softwood_Roof"
    },
    {
      "x": 3,
      "y": 1,
      "z": -3,
      "name": "Rock_Stone_Cobble"
    },
    {
      "x": 3,
      "y": 4,
      "z": -3,
      "name": "Plant_Vine_Wall",
      "support": 15
    },
    {
      "x": 3,
      "y": 5,
      "z": -3,
      "name": "Wood_Softwood_Roof_Hollow"
    },
    {
      "x": 3,
      "y": 1,
      "z": -2,
      "name": "Rock_Stone_Cobble"
    },
    {
      "x": 3,
      "y": 1,
      "z": -1,
      "name": "Rock_Stone_Cobble"
    },
    {
      "x": 4,
      "y": 1,
      "z": -11,
      "name": "Rock_Stone_Cobble"
    },
    {
      "x": 4,
      "y": 5,
      "z": -11,
      "name": "Wood_Softwood_Roof_Hollow",
      "rotation": 2
    },
    {
      "x": 4,
      "y": 1,
      "z": -10,
      "name": "Rock_Stone_Cobble"
    },
    {
      "x": 4,
      "y": 2,
      "z": -10,
      "name": "Rock_Stone_Brick"
    },
    {
      "x": 4,
      "y": 3,
      "z": -10,
      "name": "*Wood_Village_Wall_Full_State_Definitions_Bottom"
    },
    {
      "x": 4,
      "y": 4,
      "z": -10,
      "name": "*Wood_Village_Wall_Full_State_Definitions_Top"
    },
    {
      "x": 4,
      "y": 5,
      "z": -10,
      "name": "Wood_Beech_Trunk",
      "support": 15,
      "rotation": 5
    },
    {
      "x": 4,
      "y": 6,
      "z": -10,
      "name": "Wood_Softwood_Roof",
      "rotation": 2
    },
    {
      "x": 4,
      "y": 1,
      "z": -9,
      "name": "Wood_Softwood_Planks"
    },
    {
      "x": 4,
      "y": 6,
      "z": -9,
      "name": "Wood_Softwood_Stairs",
      "rotation": 10
    },
    {
      "x": 4,
      "y": 7,
      "z": -9,
      "name": "Wood_Softwood_Roof",
      "rotation": 2
    },
    {
      "x": 4,
      "y": 1,
      "z": -8,
      "name": "Wood_Softwood_Planks"
    },
    {
      "x": 4,
      "y": 5,
      "z": -8,
      "name": "Furniture_Tavern_Chandelier",
      "support": 15,
      "filler": 32767
    },
    {
      "x": 4,
      "y": 6,
      "z": -8,
      "name": "Furniture_Tavern_Chandelier",
      "support": 15,
      "filler": 1023
    },
    {
      "x": 4,
      "y": 7,
      "z": -8,
      "name": "Wood_Softwood_Stairs",
      "rotation": 10
    },
    {
      "x": 4,
      "y": 8,
      "z": -8,
      "name": "Wood_Softwood_Roof",
      "rotation": 2
    },
    {
      "x": 4,
      "y": 1,
      "z": -7,
      "name": "Wood_Softwood_Planks"
    },
    {
      "x": 4,
      "y": 5,
      "z": -7,
      "name": "Furniture_Tavern_Chandelier",
      "support": 15,
      "filler": 31775
    },
    {
      "x": 4,
      "y": 6,
      "z": -7,
      "name": "Furniture_Tavern_Chandelier",
      "support": 15,
      "filler": 31
    },
    {
      "x": 4,
      "y": 8,
      "z": -7,
      "name": "Wood_Beech_Trunk",
      "support": 15,
      "rotation": 5
    },
    {
      "x": 4,
      "y": 9,
      "z": -7,
      "name": "Wood_Softwood_Roof_Flat"
    },
    {
      "x": 4,
      "y": 1,
      "z": -6,
      "name": "Wood_Softwood_Planks"
    },
    {
      "x": 4,
      "y": 5,
      "z": -6,
      "name": "Furniture_Tavern_Chandelier",
      "support": 15,
      "filler": 31807
    },
    {
      "x": 4,
      "y": 6,
      "z": -6,
      "name": "Furniture_Tavern_Chandelier",
      "support": 15,
      "filler": 63
    },
    {
      "x": 4,
      "y": 7,
      "z": -6,
      "name": "Wood_Softwood_Stairs",
      "rotation": 8
    },
    {
      "x": 4,
      "y": 8,
      "z": -6,
      "name": "Wood_Softwood_Roof"
    },
    {
      "x": 4,
      "y": 1,
      "z": -5,
      "name": "Wood_Softwood_Planks"
    },
    {
      "x": 4,
      "y": 6,
      "z": -5,
      "name": "Wood_Softwood_Stairs",
      "rotation": 8
    },
    {
      "x": 4,
      "y": 7,
      "z": -5,
      "name": "Wood_Softwood_Roof"
    },
    {
      "x": 4,
      "y": 1,
      "z": -4,
      "name": "Rock_Stone_Cobble"
    },
    {
      "x": 4,
      "y": 2,
      "z": -4,
      "name": "Rock_Stone_Brick_Mossy"
    },
    {
      "x": 4,
      "y": 3,
      "z": -4,
      "name": "Furniture_Village_Window"
    },
    {
      "x": 4,
      "y": 4,
      "z": -4,
      "name": "Furniture_Village_Window"
    },
    {
      "x": 4,
      "y": 5,
      "z": -4,
      "name": "Wood_Beech_Trunk",
      "support": 15,
      "rotation": 5
    },
    {
      "x": 4,
      "y": 6,
      "z": -4,
      "name": "Wood_Softwood_Roof"
    },
    {
      "x": 4,
      "y": 1,
      "z": -3,
      "name": "Rock_Stone_Cobble"
    },
    {
      "x": 4,
      "y": 2,
      "z": -3,
      "name": "Furniture_Tavern_Planter",
      "support": 15
    },
    {
      "x": 4,
      "y": 3,
      "z": -3,
      "name": "Plant_Flower_Common_Red2",
      "support": 15
    },
    {
      "x": 4,
      "y": 5,
      "z": -3,
      "name": "Wood_Softwood_Roof_Hollow"
    },
    {
      "x": 4,
      "y": 1,
      "z": -2,
      "name": "Rock_Stone_Cobble"
    },
    {
      "x": 4,
      "y": 1,
      "z": -1,
      "name": "Rock_Stone_Cobble_Mossy"
    },
    {
      "x": 5,
      "y": 1,
      "z": -11,
      "name": "Rock_Stone_Cobble"
    },
    {
      "x": 5,
      "y": 5,
      "z": -11,
      "name": "Wood_Softwood_Roof_Hollow",
      "rotation": 2
    },
    {
      "x": 5,
      "y": 1,
      "z": -10,
      "name": "Rock_Stone_Cobble"
    },
    {
      "x": 5,
      "y": 2,
      "z": -10,
      "name": "Rock_Stone_Brick_Mossy"
    },
    {
      "x": 5,
      "y": 3,
      "z": -10,
      "name": "Furniture_Village_Window"
    },
    {
      "x": 5,
      "y": 4,
      "z": -10,
      "name": "Furniture_Village_Window"
    },
    {
      "x": 5,
      "y": 5,
      "z": -10,
      "name": "Wood_Beech_Trunk",
      "support": 15,
      "rotation": 5
    },
    {
      "x": 5,
      "y": 6,
      "z": -10,
      "name": "Wood_Softwood_Roof",
      "rotation": 2
    },
    {
      "x": 5,
      "y": 1,
      "z": -9,
      "name": "Wood_Softwood_Planks"
    },
    {
      "x": 5,
      "y": 2,
      "z": -9,
      "name": "Wood_Softwood_Fence_Gate",
      "rotation": 1
    },
    {
      "x": 5,
      "y": 6,
      "z": -9,
      "name": "Wood_Softwood_Stairs",
      "rotation": 10
    },
    {
      "x": 5,
      "y": 7,
      "z": -9,
      "name": "Wood_Softwood_Roof",
      "rotation": 2
    },
    {
      "x": 5,
      "y": 1,
      "z": -8,
      "name": "Wood_Softwood_Planks"
    },
    {
      "x": 5,
      "y": 2,
      "z": -8,
      "name": "Wood_Softwood_Planks"
    },
    {
      "x": 5,
      "y": 3,
      "z": -8,
      "name": "Aetherhaven_Shop_Spot",
      "components": {
        "Components": {
          "AetherhavenShopSpotBlock": {
            "SpotId": "dad7c65d-3924-45b6-aa3d-ac8926217bab",
            "TownId": "d87b9d18-a6de-42a7-9697-90f4c2aa0d9f",
            "PlotId": "00000000-0000-0000-0000-000000000000",
            "PlayerControlled": false,
            "LootTableId": "chef_pie",
            "Configured": true
          },
          "PlacedByInteraction": {
            "WhoPlacedUuid": {
              "$binary": "v7RyWIT/TYKnXA2XcxdQtw==",
              "$type": "04"
            }
          }
        }
      },
      "rotation": 1
    },
    {
      "x": 5,
      "y": 5,
      "z": -8,
      "name": "Furniture_Tavern_Chandelier",
      "support": 15,
      "filler": 32736
    },
    {
      "x": 5,
      "y": 6,
      "z": -8,
      "name": "Furniture_Tavern_Chandelier",
      "support": 15,
      "filler": 992
    },
    {
      "x": 5,
      "y": 7,
      "z": -8,
      "name": "Wood_Softwood_Stairs",
      "rotation": 10
    },
    {
      "x": 5,
      "y": 8,
      "z": -8,
      "name": "Wood_Softwood_Roof",
      "rotation": 2
    },
    {
      "x": 5,
      "y": 1,
      "z": -7,
      "name": "Wood_Softwood_Planks"
    },
    {
      "x": 5,
      "y": 2,
      "z": -7,
      "name": "Furniture_Village_Counter",
      "support": 15,
      "filler": 992,
      "rotation": 3
    },
    {
      "x": 5,
      "y": 3,
      "z": -7,
      "name": "Aetherhaven_Shop_Spot",
      "components": {
        "Components": {
          "AetherhavenShopSpotBlock": {
            "SpotId": "3cdd1a48-9735-47c7-9f38-5b473c5618cd",
            "TownId": "d87b9d18-a6de-42a7-9697-90f4c2aa0d9f",
            "PlotId": "00000000-0000-0000-0000-000000000000",
            "PlayerControlled": false,
            "LootTableId": "chef_salad",
            "Configured": true
          },
          "PlacedByInteraction": {
            "WhoPlacedUuid": {
              "$binary": "v7RyWIT/TYKnXA2XcxdQtw==",
              "$type": "04"
            }
          }
        }
      },
      "rotation": 1
    },
    {
      "x": 5,
      "y": 5,
      "z": -7,
      "name": "Furniture_Tavern_Chandelier",
      "support": 15,
      "filler": 31744
    },
    {
      "x": 5,
      "y": 6,
      "z": -7,
      "name": "Furniture_Tavern_Chandelier",
      "support": 15
    },
    {
      "x": 5,
      "y": 7,
      "z": -7,
      "name": "Deco_Rope",
      "support": 15
    },
    {
      "x": 5,
      "y": 8,
      "z": -7,
      "name": "Wood_Beech_Trunk",
      "support": 15,
      "rotation": 5
    },
    {
      "x": 5,
      "y": 9,
      "z": -7,
      "name": "Wood_Softwood_Roof_Flat"
    },
    {
      "x": 5,
      "y": 1,
      "z": -6,
      "name": "Wood_Softwood_Planks"
    },
    {
      "x": 5,
      "y": 2,
      "z": -6,
      "name": "Furniture_Village_Counter",
      "support": 15,
      "rotation": 3
    },
    {
      "x": 5,
      "y": 3,
      "z": -6,
      "name": "Aetherhaven_Shop_Spot",
      "components": {
        "Components": {
          "AetherhavenShopSpotBlock": {
            "SpotId": "b02581f4-1c81-4ba7-8abe-f66e923f1035",
            "TownId": "d87b9d18-a6de-42a7-9697-90f4c2aa0d9f",
            "PlotId": "00000000-0000-0000-0000-000000000000",
            "PlayerControlled": false,
            "LootTableId": "chef_kebab",
            "Configured": true
          },
          "PlacedByInteraction": {
            "WhoPlacedUuid": {
              "$binary": "v7RyWIT/TYKnXA2XcxdQtw==",
              "$type": "04"
            }
          }
        }
      },
      "rotation": 1
    },
    {
      "x": 5,
      "y": 5,
      "z": -6,
      "name": "Furniture_Tavern_Chandelier",
      "support": 15,
      "filler": 31776
    },
    {
      "x": 5,
      "y": 6,
      "z": -6,
      "name": "Furniture_Tavern_Chandelier",
      "support": 15,
      "filler": 32
    },
    {
      "x": 5,
      "y": 7,
      "z": -6,
      "name": "Wood_Softwood_Stairs",
      "rotation": 8
    },
    {
      "x": 5,
      "y": 8,
      "z": -6,
      "name": "Wood_Softwood_Roof"
    },
    {
      "x": 5,
      "y": 1,
      "z": -5,
      "name": "Wood_Softwood_Planks"
    },
    {
      "x": 5,
      "y": 2,
      "z": -5,
      "name": "Wood_Softwood_Planks"
    },
    {
      "x": 5,
      "y": 3,
      "z": -5,
      "name": "Furniture_Crude_Candle",
      "support": 15
    },
    {
      "x": 5,
      "y": 6,
      "z": -5,
      "name": "Wood_Softwood_Stairs",
      "rotation": 8
    },
    {
      "x": 5,
      "y": 7,
      "z": -5,
      "name": "Wood_Softwood_Roof"
    },
    {
      "x": 5,
      "y": 1,
      "z": -4,
      "name": "Rock_Stone_Cobble"
    },
    {
      "x": 5,
      "y": 2,
      "z": -4,
      "name": "Rock_Stone_Brick"
    },
    {
      "x": 5,
      "y": 3,
      "z": -4,
      "name": "Furniture_Village_Window"
    },
    {
      "x": 5,
      "y": 4,
      "z": -4,
      "name": "Furniture_Village_Window"
    },
    {
      "x": 5,
      "y": 5,
      "z": -4,
      "name": "Wood_Beech_Trunk",
      "support": 15,
      "rotation": 5
    },
    {
      "x": 5,
      "y": 6,
      "z": -4,
      "name": "Wood_Softwood_Roof"
    },
    {
      "x": 5,
      "y": 1,
      "z": -3,
      "name": "Rock_Stone_Cobble"
    },
    {
      "x": 5,
      "y": 5,
      "z": -3,
      "name": "Wood_Softwood_Roof_Hollow"
    },
    {
      "x": 5,
      "y": 1,
      "z": -2,
      "name": "Rock_Stone_Cobble"
    },
    {
      "x": 5,
      "y": 1,
      "z": -1,
      "name": "Rock_Stone_Cobble"
    },
    {
      "x": 6,
      "y": 1,
      "z": -11,
      "name": "Rock_Stone_Cobble"
    },
    {
      "x": 6,
      "y": 5,
      "z": -11,
      "name": "Wood_Softwood_Roof_Hollow",
      "rotation": 2
    },
    {
      "x": 6,
      "y": 1,
      "z": -10,
      "name": "Rock_Stone_Cobble"
    },
    {
      "x": 6,
      "y": 2,
      "z": -10,
      "name": "Rock_Stone_Brick"
    },
    {
      "x": 6,
      "y": 3,
      "z": -10,
      "name": "Furniture_Village_Window"
    },
    {
      "x": 6,
      "y": 4,
      "z": -10,
      "name": "Furniture_Village_Window"
    },
    {
      "x": 6,
      "y": 5,
      "z": -10,
      "name": "Wood_Beech_Trunk",
      "support": 15,
      "rotation": 5
    },
    {
      "x": 6,
      "y": 6,
      "z": -10,
      "name": "Wood_Softwood_Roof",
      "rotation": 2
    },
    {
      "x": 6,
      "y": 1,
      "z": -9,
      "name": "Wood_Softwood_Planks"
    },
    {
      "x": 6,
      "y": 6,
      "z": -9,
      "name": "Wood_Softwood_Stairs",
      "rotation": 10
    },
    {
      "x": 6,
      "y": 7,
      "z": -9,
      "name": "Wood_Softwood_Roof",
      "rotation": 2
    },
    {
      "x": 6,
      "y": 1,
      "z": -8,
      "name": "Wood_Softwood_Planks"
    },
    {
      "x": 6,
      "y": 5,
      "z": -8,
      "name": "Furniture_Tavern_Chandelier",
      "support": 15,
      "filler": 32737
    },
    {
      "x": 6,
      "y": 6,
      "z": -8,
      "name": "Furniture_Tavern_Chandelier",
      "support": 15,
      "filler": 993
    },
    {
      "x": 6,
      "y": 7,
      "z": -8,
      "name": "Wood_Softwood_Stairs",
      "rotation": 10
    },
    {
      "x": 6,
      "y": 8,
      "z": -8,
      "name": "Wood_Softwood_Roof",
      "rotation": 2
    },
    {
      "x": 6,
      "y": 1,
      "z": -7,
      "name": "Wood_Softwood_Planks"
    },
    {
      "x": 6,
      "y": 5,
      "z": -7,
      "name": "Furniture_Tavern_Chandelier",
      "support": 15,
      "filler": 31745
    },
    {
      "x": 6,
      "y": 6,
      "z": -7,
      "name": "Furniture_Tavern_Chandelier",
      "support": 15,
      "filler": 1
    },
    {
      "x": 6,
      "y": 8,
      "z": -7,
      "name": "Wood_Beech_Trunk",
      "support": 15,
      "rotation": 5
    },
    {
      "x": 6,
      "y": 9,
      "z": -7,
      "name": "Wood_Softwood_Roof_Flat"
    },
    {
      "x": 6,
      "y": 1,
      "z": -6,
      "name": "Wood_Softwood_Planks"
    },
    {
      "x": 6,
      "y": 5,
      "z": -6,
      "name": "Furniture_Tavern_Chandelier",
      "support": 15,
      "filler": 31777
    },
    {
      "x": 6,
      "y": 6,
      "z": -6,
      "name": "Furniture_Tavern_Chandelier",
      "support": 15,
      "filler": 33
    },
    {
      "x": 6,
      "y": 7,
      "z": -6,
      "name": "Wood_Softwood_Stairs",
      "rotation": 8
    },
    {
      "x": 6,
      "y": 8,
      "z": -6,
      "name": "Wood_Softwood_Roof"
    },
    {
      "x": 6,
      "y": 1,
      "z": -5,
      "name": "Wood_Softwood_Planks"
    },
    {
      "x": 6,
      "y": 6,
      "z": -5,
      "name": "Wood_Softwood_Stairs",
      "rotation": 8
    },
    {
      "x": 6,
      "y": 7,
      "z": -5,
      "name": "Wood_Softwood_Roof"
    },
    {
      "x": 6,
      "y": 1,
      "z": -4,
      "name": "Rock_Stone_Cobble"
    },
    {
      "x": 6,
      "y": 2,
      "z": -4,
      "name": "Rock_Stone_Brick"
    },
    {
      "x": 6,
      "y": 3,
      "z": -4,
      "name": "*Wood_Village_Wall_Full_State_Definitions_Bottom"
    },
    {
      "x": 6,
      "y": 4,
      "z": -4,
      "name": "*Wood_Village_Wall_Full_State_Definitions_Top"
    },
    {
      "x": 6,
      "y": 5,
      "z": -4,
      "name": "Wood_Beech_Trunk",
      "support": 15,
      "rotation": 5
    },
    {
      "x": 6,
      "y": 6,
      "z": -4,
      "name": "Wood_Softwood_Roof"
    },
    {
      "x": 6,
      "y": 1,
      "z": -3,
      "name": "Rock_Stone_Cobble"
    },
    {
      "x": 6,
      "y": 5,
      "z": -3,
      "name": "Wood_Softwood_Roof_Hollow"
    },
    {
      "x": 6,
      "y": 1,
      "z": -2,
      "name": "Rock_Stone_Cobble_Mossy"
    },
    {
      "x": 6,
      "y": 1,
      "z": -1,
      "name": "Rock_Stone_Cobble"
    },
    {
      "x": 7,
      "y": 1,
      "z": -11,
      "name": "Rock_Stone_Cobble"
    },
    {
      "x": 7,
      "y": 5,
      "z": -11,
      "name": "Wood_Softwood_Roof_Hollow",
      "rotation": 2
    },
    {
      "x": 7,
      "y": 1,
      "z": -10,
      "name": "Rock_Stone_Cobble"
    },
    {
      "x": 7,
      "y": 2,
      "z": -10,
      "name": "Rock_Stone_Brick"
    },
    {
      "x": 7,
      "y": 3,
      "z": -10,
      "name": "*Wood_Village_Wall_Full_State_Definitions_Bottom"
    },
    {
      "x": 7,
      "y": 4,
      "z": -10,
      "name": "*Wood_Village_Wall_Full_State_Definitions_Top"
    },
    {
      "x": 7,
      "y": 5,
      "z": -10,
      "name": "Wood_Beech_Trunk",
      "support": 15,
      "rotation": 5
    },
    {
      "x": 7,
      "y": 6,
      "z": -10,
      "name": "Wood_Softwood_Roof",
      "rotation": 2
    },
    {
      "x": 7,
      "y": 1,
      "z": -9,
      "name": "Wood_Softwood_Planks"
    },
    {
      "x": 7,
      "y": 6,
      "z": -9,
      "name": "Wood_Softwood_Stairs",
      "rotation": 10
    },
    {
      "x": 7,
      "y": 7,
      "z": -9,
      "name": "Wood_Softwood_Roof",
      "rotation": 2
    },
    {
      "x": 7,
      "y": 1,
      "z": -8,
      "name": "Wood_Softwood_Planks"
    },
    {
      "x": 7,
      "y": 7,
      "z": -8,
      "name": "Wood_Softwood_Stairs",
      "rotation": 10
    },
    {
      "x": 7,
      "y": 8,
      "z": -8,
      "name": "Wood_Softwood_Roof",
      "rotation": 2
    },
    {
      "x": 7,
      "y": 1,
      "z": -7,
      "name": "Wood_Softwood_Planks"
    },
    {
      "x": 7,
      "y": 8,
      "z": -7,
      "name": "Wood_Beech_Trunk",
      "support": 15,
      "rotation": 5
    },
    {
      "x": 7,
      "y": 9,
      "z": -7,
      "name": "Wood_Softwood_Roof_Flat"
    },
    {
      "x": 7,
      "y": 1,
      "z": -6,
      "name": "Wood_Softwood_Planks"
    },
    {
      "x": 7,
      "y": 7,
      "z": -6,
      "name": "Wood_Softwood_Stairs",
      "rotation": 8
    },
    {
      "x": 7,
      "y": 8,
      "z": -6,
      "name": "Wood_Softwood_Roof"
    },
    {
      "x": 7,
      "y": 1,
      "z": -5,
      "name": "Wood_Softwood_Planks"
    },
    {
      "x": 7,
      "y": 6,
      "z": -5,
      "name": "Wood_Softwood_Stairs",
      "rotation": 8
    },
    {
      "x": 7,
      "y": 7,
      "z": -5,
      "name": "Wood_Softwood_Roof"
    },
    {
      "x": 7,
      "y": 1,
      "z": -4,
      "name": "Rock_Stone_Cobble"
    },
    {
      "x": 7,
      "y": 2,
      "z": -4,
      "name": "Rock_Stone_Brick"
    },
    {
      "x": 7,
      "y": 3,
      "z": -4,
      "name": "Furniture_Village_Window"
    },
    {
      "x": 7,
      "y": 4,
      "z": -4,
      "name": "Furniture_Village_Window"
    },
    {
      "x": 7,
      "y": 5,
      "z": -4,
      "name": "Wood_Beech_Trunk",
      "support": 15,
      "rotation": 5
    },
    {
      "x": 7,
      "y": 6,
      "z": -4,
      "name": "Wood_Softwood_Roof"
    },
    {
      "x": 7,
      "y": 1,
      "z": -3,
      "name": "Rock_Stone_Cobble"
    },
    {
      "x": 7,
      "y": 5,
      "z": -3,
      "name": "Wood_Softwood_Roof_Hollow"
    },
    {
      "x": 7,
      "y": 1,
      "z": -2,
      "name": "Rock_Stone_Cobble_Mossy"
    },
    {
      "x": 7,
      "y": 1,
      "z": -1,
      "name": "Rock_Stone_Cobble_Mossy"
    },
    {
      "x": 8,
      "y": 1,
      "z": -11,
      "name": "Rock_Stone_Cobble"
    },
    {
      "x": 8,
      "y": 4,
      "z": -11,
      "name": "Plant_Vine_Wall",
      "support": 15,
      "rotation": 2
    },
    {
      "x": 8,
      "y": 5,
      "z": -11,
      "name": "Wood_Softwood_Roof_Hollow",
      "rotation": 2
    },
    {
      "x": 8,
      "y": 1,
      "z": -10,
      "name": "Rock_Stone_Cobble"
    },
    {
      "x": 8,
      "y": 2,
      "z": -10,
      "name": "Rock_Stone_Brick"
    },
    {
      "x": 8,
      "y": 3,
      "z": -10,
      "name": "*Wood_Village_Wall_Full_State_Definitions_Bottom"
    },
    {
      "x": 8,
      "y": 4,
      "z": -10,
      "name": "*Wood_Village_Wall_Full_State_Definitions_Top"
    },
    {
      "x": 8,
      "y": 5,
      "z": -10,
      "name": "Wood_Beech_Trunk",
      "support": 15,
      "rotation": 5
    },
    {
      "x": 8,
      "y": 6,
      "z": -10,
      "name": "Wood_Softwood_Roof",
      "rotation": 2
    },
    {
      "x": 8,
      "y": 1,
      "z": -9,
      "name": "Wood_Softwood_Planks"
    },
    {
      "x": 8,
      "y": 2,
      "z": -9,
      "name": "Furniture_Tavern_Chair",
      "components": {
        "Components": {}
      },
      "support": 15
    },
    {
      "x": 8,
      "y": 6,
      "z": -9,
      "name": "Wood_Softwood_Stairs",
      "rotation": 10
    },
    {
      "x": 8,
      "y": 7,
      "z": -9,
      "name": "Wood_Softwood_Roof",
      "rotation": 2
    },
    {
      "x": 8,
      "y": 1,
      "z": -8,
      "name": "Wood_Softwood_Planks"
    },
    {
      "x": 8,
      "y": 2,
      "z": -8,
      "name": "Furniture_Tavern_Table",
      "support": 15
    },
    {
      "x": 8,
      "y": 7,
      "z": -8,
      "name": "Wood_Softwood_Stairs",
      "rotation": 10
    },
    {
      "x": 8,
      "y": 8,
      "z": -8,
      "name": "Wood_Softwood_Roof",
      "rotation": 2
    },
    {
      "x": 8,
      "y": 1,
      "z": -7,
      "name": "Wood_Softwood_Planks"
    },
    {
      "x": 8,
      "y": 2,
      "z": -7,
      "name": "Furniture_Tavern_Table",
      "support": 15,
      "filler": 32
    },
    {
      "x": 8,
      "y": 8,
      "z": -7,
      "name": "Wood_Beech_Trunk",
      "support": 15,
      "rotation": 5
    },
    {
      "x": 8,
      "y": 9,
      "z": -7,
      "name": "Wood_Softwood_Roof_Flat"
    },
    {
      "x": 8,
      "y": 1,
      "z": -6,
      "name": "Wood_Softwood_Planks"
    },
    {
      "x": 8,
      "y": 7,
      "z": -6,
      "name": "Wood_Softwood_Stairs",
      "rotation": 8
    },
    {
      "x": 8,
      "y": 8,
      "z": -6,
      "name": "Wood_Softwood_Roof"
    },
    {
      "x": 8,
      "y": 1,
      "z": -5,
      "name": "Wood_Softwood_Planks"
    },
    {
      "x": 8,
      "y": 6,
      "z": -5,
      "name": "Wood_Softwood_Stairs",
      "rotation": 8
    },
    {
      "x": 8,
      "y": 7,
      "z": -5,
      "name": "Wood_Softwood_Roof"
    },
    {
      "x": 8,
      "y": 1,
      "z": -4,
      "name": "Rock_Stone_Cobble"
    },
    {
      "x": 8,
      "y": 2,
      "z": -4,
      "name": "Rock_Stone_Brick_Mossy"
    },
    {
      "x": 8,
      "y": 3,
      "z": -4,
      "name": "Furniture_Village_Window"
    },
    {
      "x": 8,
      "y": 4,
      "z": -4,
      "name": "Furniture_Village_Window"
    },
    {
      "x": 8,
      "y": 5,
      "z": -4,
      "name": "Wood_Beech_Trunk",
      "support": 15,
      "rotation": 5
    },
    {
      "x": 8,
      "y": 6,
      "z": -4,
      "name": "Wood_Softwood_Roof"
    },
    {
      "x": 8,
      "y": 1,
      "z": -3,
      "name": "Rock_Stone_Cobble"
    },
    {
      "x": 8,
      "y": 2,
      "z": -3,
      "name": "Furniture_Tavern_Planter",
      "support": 15
    },
    {
      "x": 8,
      "y": 3,
      "z": -3,
      "name": "Plant_Flower_Common_Pink2",
      "support": 15
    },
    {
      "x": 8,
      "y": 5,
      "z": -3,
      "name": "Wood_Softwood_Roof_Hollow"
    },
    {
      "x": 8,
      "y": 1,
      "z": -2,
      "name": "Rock_Stone_Cobble_Mossy"
    },
    {
      "x": 8,
      "y": 1,
      "z": -1,
      "name": "Rock_Stone_Cobble"
    },
    {
      "x": 9,
      "y": 1,
      "z": -11,
      "name": "Rock_Stone_Cobble"
    },
    {
      "x": 9,
      "y": 5,
      "z": -11,
      "name": "Wood_Softwood_Roof_Hollow",
      "rotation": 2
    },
    {
      "x": 9,
      "y": 1,
      "z": -10,
      "name": "Rock_Stone_Cobble"
    },
    {
      "x": 9,
      "y": 2,
      "z": -10,
      "name": "Rock_Stone_Brick"
    },
    {
      "x": 9,
      "y": 3,
      "z": -10,
      "name": "*Wood_Village_Wall_Full_State_Definitions_Bottom"
    },
    {
      "x": 9,
      "y": 4,
      "z": -10,
      "name": "*Wood_Village_Wall_Full_State_Definitions_Top"
    },
    {
      "x": 9,
      "y": 5,
      "z": -10,
      "name": "Wood_Beech_Trunk",
      "support": 15,
      "rotation": 5
    },
    {
      "x": 9,
      "y": 6,
      "z": -10,
      "name": "Wood_Softwood_Roof",
      "rotation": 2
    },
    {
      "x": 9,
      "y": 1,
      "z": -9,
      "name": "Wood_Softwood_Planks"
    },
    {
      "x": 9,
      "y": 6,
      "z": -9,
      "name": "Wood_Softwood_Stairs",
      "rotation": 10
    },
    {
      "x": 9,
      "y": 7,
      "z": -9,
      "name": "Wood_Softwood_Roof",
      "rotation": 2
    },
    {
      "x": 9,
      "y": 1,
      "z": -8,
      "name": "Wood_Softwood_Planks"
    },
    {
      "x": 9,
      "y": 2,
      "z": -8,
      "name": "Furniture_Tavern_Table",
      "support": 15,
      "filler": 1
    },
    {
      "x": 9,
      "y": 5,
      "z": -8,
      "name": "Furniture_Tavern_Chandelier",
      "support": 15,
      "filler": 32767
    },
    {
      "x": 9,
      "y": 6,
      "z": -8,
      "name": "Furniture_Tavern_Chandelier",
      "support": 15,
      "filler": 1023
    },
    {
      "x": 9,
      "y": 7,
      "z": -8,
      "name": "Wood_Softwood_Stairs",
      "rotation": 10
    },
    {
      "x": 9,
      "y": 8,
      "z": -8,
      "name": "Wood_Softwood_Roof",
      "rotation": 2
    },
    {
      "x": 9,
      "y": 1,
      "z": -7,
      "name": "Wood_Softwood_Planks"
    },
    {
      "x": 9,
      "y": 2,
      "z": -7,
      "name": "Furniture_Tavern_Table",
      "support": 15,
      "filler": 33
    },
    {
      "x": 9,
      "y": 5,
      "z": -7,
      "name": "Furniture_Tavern_Chandelier",
      "support": 15,
      "filler": 31775
    },
    {
      "x": 9,
      "y": 6,
      "z": -7,
      "name": "Furniture_Tavern_Chandelier",
      "support": 15,
      "filler": 31
    },
    {
      "x": 9,
      "y": 8,
      "z": -7,
      "name": "Wood_Beech_Trunk",
      "support": 15,
      "rotation": 5
    },
    {
      "x": 9,
      "y": 9,
      "z": -7,
      "name": "Wood_Softwood_Roof_Flat"
    },
    {
      "x": 9,
      "y": 1,
      "z": -6,
      "name": "Wood_Softwood_Planks"
    },
    {
      "x": 9,
      "y": 2,
      "z": -6,
      "name": "Furniture_Tavern_Chair",
      "components": {
        "Components": {}
      },
      "support": 15,
      "rotation": 2
    },
    {
      "x": 9,
      "y": 5,
      "z": -6,
      "name": "Furniture_Tavern_Chandelier",
      "support": 15,
      "filler": 31807
    },
    {
      "x": 9,
      "y": 6,
      "z": -6,
      "name": "Furniture_Tavern_Chandelier",
      "support": 15,
      "filler": 63
    },
    {
      "x": 9,
      "y": 7,
      "z": -6,
      "name": "Wood_Softwood_Stairs",
      "rotation": 8
    },
    {
      "x": 9,
      "y": 8,
      "z": -6,
      "name": "Wood_Softwood_Roof"
    },
    {
      "x": 9,
      "y": 1,
      "z": -5,
      "name": "Wood_Softwood_Planks"
    },
    {
      "x": 9,
      "y": 6,
      "z": -5,
      "name": "Wood_Softwood_Stairs",
      "rotation": 8
    },
    {
      "x": 9,
      "y": 7,
      "z": -5,
      "name": "Wood_Softwood_Roof"
    },
    {
      "x": 9,
      "y": 1,
      "z": -4,
      "name": "Rock_Stone_Cobble_Mossy"
    },
    {
      "x": 9,
      "y": 2,
      "z": -4,
      "name": "Rock_Stone_Brick"
    },
    {
      "x": 9,
      "y": 3,
      "z": -4,
      "name": "*Wood_Village_Wall_Full_State_Definitions_Bottom"
    },
    {
      "x": 9,
      "y": 4,
      "z": -4,
      "name": "*Wood_Village_Wall_Full_State_Definitions_Top"
    },
    {
      "x": 9,
      "y": 5,
      "z": -4,
      "name": "Wood_Beech_Trunk",
      "support": 15,
      "rotation": 5
    },
    {
      "x": 9,
      "y": 6,
      "z": -4,
      "name": "Wood_Softwood_Roof"
    },
    {
      "x": 9,
      "y": 1,
      "z": -3,
      "name": "Rock_Stone_Cobble"
    },
    {
      "x": 9,
      "y": 5,
      "z": -3,
      "name": "*Wood_Softwood_Roof_Hollow_State_Definitions_Inverted_Corner_Right"
    },
    {
      "x": 9,
      "y": 1,
      "z": -2,
      "name": "Rock_Stone_Cobble"
    },
    {
      "x": 9,
      "y": 5,
      "z": -2,
      "name": "Wood_Softwood_Roof_Hollow",
      "rotation": 3
    },
    {
      "x": 9,
      "y": 1,
      "z": -1,
      "name": "Rock_Stone_Cobble"
    },
    {
      "x": 9,
      "y": 5,
      "z": -1,
      "name": "Wood_Softwood_Roof_Hollow",
      "rotation": 3
    },
    {
      "x": 10,
      "y": 1,
      "z": -11,
      "name": "Rock_Stone_Cobble"
    },
    {
      "x": 10,
      "y": 5,
      "z": -11,
      "name": "Wood_Softwood_Roof_Hollow",
      "rotation": 2
    },
    {
      "x": 10,
      "y": 1,
      "z": -10,
      "name": "Rock_Stone_Cobble"
    },
    {
      "x": 10,
      "y": 2,
      "z": -10,
      "name": "Rock_Stone_Brick"
    },
    {
      "x": 10,
      "y": 3,
      "z": -10,
      "name": "Furniture_Village_Window"
    },
    {
      "x": 10,
      "y": 4,
      "z": -10,
      "name": "Furniture_Village_Window"
    },
    {
      "x": 10,
      "y": 5,
      "z": -10,
      "name": "Wood_Beech_Trunk",
      "support": 15,
      "rotation": 5
    },
    {
      "x": 10,
      "y": 6,
      "z": -10,
      "name": "Wood_Softwood_Roof",
      "rotation": 2
    },
    {
      "x": 10,
      "y": 1,
      "z": -9,
      "name": "Wood_Softwood_Planks"
    },
    {
      "x": 10,
      "y": 6,
      "z": -9,
      "name": "Wood_Softwood_Stairs",
      "rotation": 10
    },
    {
      "x": 10,
      "y": 7,
      "z": -9,
      "name": "Wood_Softwood_Roof",
      "rotation": 2
    },
    {
      "x": 10,
      "y": 1,
      "z": -8,
      "name": "Wood_Softwood_Planks"
    },
    {
      "x": 10,
      "y": 2,
      "z": -8,
      "name": "Furniture_Tavern_Chair",
      "components": {
        "Components": {}
      },
      "support": 15,
      "rotation": 3
    },
    {
      "x": 10,
      "y": 5,
      "z": -8,
      "name": "Furniture_Tavern_Chandelier",
      "support": 15,
      "filler": 32736
    },
    {
      "x": 10,
      "y": 6,
      "z": -8,
      "name": "Furniture_Tavern_Chandelier",
      "support": 15,
      "filler": 992
    },
    {
      "x": 10,
      "y": 7,
      "z": -8,
      "name": "Wood_Softwood_Stairs",
      "rotation": 10
    },
    {
      "x": 10,
      "y": 8,
      "z": -8,
      "name": "Wood_Softwood_Roof",
      "rotation": 2
    },
    {
      "x": 10,
      "y": 1,
      "z": -7,
      "name": "Wood_Softwood_Planks"
    },
    {
      "x": 10,
      "y": 5,
      "z": -7,
      "name": "Furniture_Tavern_Chandelier",
      "support": 15,
      "filler": 31744
    },
    {
      "x": 10,
      "y": 6,
      "z": -7,
      "name": "Furniture_Tavern_Chandelier",
      "support": 15
    },
    {
      "x": 10,
      "y": 7,
      "z": -7,
      "name": "Deco_Rope",
      "support": 15
    },
    {
      "x": 10,
      "y": 8,
      "z": -7,
      "name": "Wood_Beech_Trunk",
      "support": 15,
      "rotation": 5
    },
    {
      "x": 10,
      "y": 9,
      "z": -7,
      "name": "Wood_Softwood_Roof_Flat"
    },
    {
      "x": 10,
      "y": 1,
      "z": -6,
      "name": "Wood_Softwood_Planks"
    },
    {
      "x": 10,
      "y": 5,
      "z": -6,
      "name": "Furniture_Tavern_Chandelier",
      "support": 15,
      "filler": 31776
    },
    {
      "x": 10,
      "y": 6,
      "z": -6,
      "name": "Furniture_Tavern_Chandelier",
      "support": 15,
      "filler": 32
    },
    {
      "x": 10,
      "y": 7,
      "z": -6,
      "name": "Wood_Softwood_Stairs",
      "rotation": 8
    },
    {
      "x": 10,
      "y": 8,
      "z": -6,
      "name": "Wood_Softwood_Roof"
    },
    {
      "x": 10,
      "y": 1,
      "z": -5,
      "name": "Wood_Softwood_Planks"
    },
    {
      "x": 10,
      "y": 6,
      "z": -5,
      "name": "Wood_Softwood_Stairs",
      "rotation": 8
    },
    {
      "x": 10,
      "y": 7,
      "z": -5,
      "name": "Wood_Softwood_Roof"
    },
    {
      "x": 10,
      "y": 1,
      "z": -4,
      "name": "Rock_Stone_Cobble_Mossy"
    },
    {
      "x": 10,
      "y": 2,
      "z": -4,
      "name": "Wood_Beech_Trunk",
      "support": 15
    },
    {
      "x": 10,
      "y": 3,
      "z": -4,
      "name": "Wood_Beech_Trunk",
      "support": 15
    },
    {
      "x": 10,
      "y": 4,
      "z": -4,
      "name": "Wood_Beech_Trunk",
      "support": 15
    },
    {
      "x": 10,
      "y": 5,
      "z": -4,
      "name": "Wood_Beech_Trunk",
      "support": 15
    },
    {
      "x": 10,
      "y": 6,
      "z": -4,
      "name": "*Wood_Softwood_Roof_State_Definitions_Inverted_Corner_Left",
      "rotation": 3
    },
    {
      "x": 10,
      "y": 1,
      "z": -3,
      "name": "Rock_Stone_Cobble"
    },
    {
      "x": 10,
      "y": 2,
      "z": -3,
      "name": "Rock_Stone_Brick"
    },
    {
      "x": 10,
      "y": 3,
      "z": -3,
      "name": "*Wood_Village_Wall_Full_State_Definitions_Bottom"
    },
    {
      "x": 10,
      "y": 4,
      "z": -3,
      "name": "*Wood_Village_Wall_Full_State_Definitions_Top"
    },
    {
      "x": 10,
      "y": 5,
      "z": -3,
      "name": "Wood_Beech_Trunk",
      "support": 15,
      "rotation": 4
    },
    {
      "x": 10,
      "y": 6,
      "z": -3,
      "name": "Wood_Softwood_Roof",
      "rotation": 3
    },
    {
      "x": 10,
      "y": 1,
      "z": -2,
      "name": "Rock_Stone_Cobble"
    },
    {
      "x": 10,
      "y": 2,
      "z": -2,
      "name": "Wood_Beech_Trunk",
      "support": 15
    },
    {
      "x": 10,
      "y": 3,
      "z": -2,
      "name": "Wood_Beech_Trunk",
      "support": 15
    },
    {
      "x": 10,
      "y": 4,
      "z": -2,
      "name": "Wood_Beech_Trunk",
      "support": 15
    },
    {
      "x": 10,
      "y": 5,
      "z": -2,
      "name": "Wood_Beech_Trunk",
      "support": 15
    },
    {
      "x": 10,
      "y": 6,
      "z": -2,
      "name": "Wood_Softwood_Roof",
      "rotation": 3
    },
    {
      "x": 10,
      "y": 1,
      "z": -1,
      "name": "Rock_Stone_Cobble_Mossy"
    },
    {
      "x": 10,
      "y": 5,
      "z": -1,
      "name": "Wood_Beech_Branch_Corner",
      "support": 15
    },
    {
      "x": 10,
      "y": 6,
      "z": -1,
      "name": "Wood_Softwood_Roof",
      "rotation": 3
    },
    {
      "x": 11,
      "y": 1,
      "z": -11,
      "name": "Rock_Stone_Cobble"
    },
    {
      "x": 11,
      "y": 5,
      "z": -11,
      "name": "Wood_Softwood_Roof_Hollow",
      "rotation": 2
    },
    {
      "x": 11,
      "y": 1,
      "z": -10,
      "name": "Rock_Stone_Cobble"
    },
    {
      "x": 11,
      "y": 2,
      "z": -10,
      "name": "Rock_Stone_Brick_Mossy"
    },
    {
      "x": 11,
      "y": 3,
      "z": -10,
      "name": "Furniture_Village_Window"
    },
    {
      "x": 11,
      "y": 4,
      "z": -10,
      "name": "Furniture_Village_Window"
    },
    {
      "x": 11,
      "y": 5,
      "z": -10,
      "name": "Wood_Beech_Trunk",
      "support": 15,
      "rotation": 5
    },
    {
      "x": 11,
      "y": 6,
      "z": -10,
      "name": "Wood_Softwood_Roof",
      "rotation": 2
    },
    {
      "x": 11,
      "y": 1,
      "z": -9,
      "name": "Wood_Softwood_Planks"
    },
    {
      "x": 11,
      "y": 6,
      "z": -9,
      "name": "Wood_Softwood_Stairs",
      "rotation": 10
    },
    {
      "x": 11,
      "y": 7,
      "z": -9,
      "name": "Wood_Softwood_Roof",
      "rotation": 2
    },
    {
      "x": 11,
      "y": 1,
      "z": -8,
      "name": "Wood_Softwood_Planks"
    },
    {
      "x": 11,
      "y": 5,
      "z": -8,
      "name": "Furniture_Tavern_Chandelier",
      "support": 15,
      "filler": 32737
    },
    {
      "x": 11,
      "y": 6,
      "z": -8,
      "name": "Furniture_Tavern_Chandelier",
      "support": 15,
      "filler": 993
    },
    {
      "x": 11,
      "y": 7,
      "z": -8,
      "name": "Wood_Softwood_Stairs",
      "rotation": 10
    },
    {
      "x": 11,
      "y": 8,
      "z": -8,
      "name": "Wood_Softwood_Roof",
      "rotation": 2
    },
    {
      "x": 11,
      "y": 1,
      "z": -7,
      "name": "Wood_Softwood_Planks"
    },
    {
      "x": 11,
      "y": 5,
      "z": -7,
      "name": "Furniture_Tavern_Chandelier",
      "support": 15,
      "filler": 31745
    },
    {
      "x": 11,
      "y": 6,
      "z": -7,
      "name": "Furniture_Tavern_Chandelier",
      "support": 15,
      "filler": 1
    },
    {
      "x": 11,
      "y": 8,
      "z": -7,
      "name": "Wood_Beech_Trunk",
      "support": 15,
      "rotation": 5
    },
    {
      "x": 11,
      "y": 9,
      "z": -7,
      "name": "Wood_Softwood_Roof_Flat"
    },
    {
      "x": 11,
      "y": 1,
      "z": -6,
      "name": "Wood_Softwood_Planks"
    },
    {
      "x": 11,
      "y": 5,
      "z": -6,
      "name": "Furniture_Tavern_Chandelier",
      "support": 15,
      "filler": 31777
    },
    {
      "x": 11,
      "y": 6,
      "z": -6,
      "name": "Furniture_Tavern_Chandelier",
      "support": 15,
      "filler": 33
    },
    {
      "x": 11,
      "y": 7,
      "z": -6,
      "name": "Wood_Softwood_Stairs",
      "rotation": 8
    },
    {
      "x": 11,
      "y": 8,
      "z": -6,
      "name": "Wood_Softwood_Roof"
    },
    {
      "x": 11,
      "y": 1,
      "z": -5,
      "name": "Wood_Softwood_Planks"
    },
    {
      "x": 11,
      "y": 6,
      "z": -5,
      "name": "*Wood_Softwood_Stairs_State_Definitions_Corner_Left",
      "rotation": 8
    },
    {
      "x": 11,
      "y": 7,
      "z": -5,
      "name": "*Wood_Softwood_Roof_State_Definitions_Inverted_Corner_Left",
      "rotation": 3
    },
    {
      "x": 11,
      "y": 1,
      "z": -4,
      "name": "Wood_Softwood_Planks"
    },
    {
      "x": 11,
      "y": 6,
      "z": -4,
      "name": "Wood_Softwood_Stairs",
      "rotation": 11
    },
    {
      "x": 11,
      "y": 7,
      "z": -4,
      "name": "Wood_Softwood_Roof",
      "rotation": 3
    },
    {
      "x": 11,
      "y": 1,
      "z": -3,
      "name": "Wood_Softwood_Planks"
    },
    {
      "x": 11,
      "y": 2,
      "z": -3,
      "name": "Furniture_Tavern_Candle",
      "support": 15
    },
    {
      "x": 11,
      "y": 6,
      "z": -3,
      "name": "Wood_Softwood_Stairs",
      "rotation": 11
    },
    {
      "x": 11,
      "y": 7,
      "z": -3,
      "name": "Wood_Softwood_Roof",
      "rotation": 3
    },
    {
      "x": 11,
      "y": 1,
      "z": -2,
      "name": "Rock_Stone_Cobble"
    },
    {
      "x": 11,
      "y": 2,
      "z": -2,
      "name": "Rock_Stone_Brick"
    },
    {
      "x": 11,
      "y": 3,
      "z": -2,
      "name": "*Wood_Village_Wall_Full_State_Definitions_Bottom"
    },
    {
      "x": 11,
      "y": 4,
      "z": -2,
      "name": "*Wood_Village_Wall_Full_State_Definitions_Top"
    },
    {
      "x": 11,
      "y": 5,
      "z": -2,
      "name": "Wood_Beech_Trunk",
      "support": 15,
      "rotation": 5
    },
    {
      "x": 11,
      "y": 6,
      "z": -2,
      "name": "Wood_Village_Wall_Full"
    },
    {
      "x": 11,
      "y": 7,
      "z": -2,
      "name": "Wood_Softwood_Roof",
      "rotation": 3
    },
    {
      "x": 11,
      "y": 1,
      "z": -1,
      "name": "Rock_Stone_Cobble"
    },
    {
      "x": 11,
      "y": 5,
      "z": -1,
      "name": "Plant_Vine_Wall",
      "support": 15
    },
    {
      "x": 11,
      "y": 6,
      "z": -1,
      "name": "Wood_Softwood_Stairs",
      "rotation": 11
    },
    {
      "x": 11,
      "y": 7,
      "z": -1,
      "name": "Wood_Softwood_Roof",
      "rotation": 3
    },
    {
      "x": 12,
      "y": 1,
      "z": -11,
      "name": "Rock_Stone_Cobble"
    },
    {
      "x": 12,
      "y": 5,
      "z": -11,
      "name": "Wood_Softwood_Roof_Hollow",
      "rotation": 2
    },
    {
      "x": 12,
      "y": 1,
      "z": -10,
      "name": "Rock_Stone_Cobble"
    },
    {
      "x": 12,
      "y": 2,
      "z": -10,
      "name": "Rock_Stone_Brick"
    },
    {
      "x": 12,
      "y": 3,
      "z": -10,
      "name": "*Wood_Village_Wall_Full_State_Definitions_Bottom"
    },
    {
      "x": 12,
      "y": 4,
      "z": -10,
      "name": "*Wood_Village_Wall_Full_State_Definitions_Top"
    },
    {
      "x": 12,
      "y": 5,
      "z": -10,
      "name": "Wood_Beech_Trunk",
      "support": 15,
      "rotation": 5
    },
    {
      "x": 12,
      "y": 6,
      "z": -10,
      "name": "Wood_Softwood_Roof",
      "rotation": 2
    },
    {
      "x": 12,
      "y": 1,
      "z": -9,
      "name": "Wood_Softwood_Planks"
    },
    {
      "x": 12,
      "y": 6,
      "z": -9,
      "name": "Wood_Softwood_Stairs",
      "rotation": 10
    },
    {
      "x": 12,
      "y": 7,
      "z": -9,
      "name": "Wood_Softwood_Roof",
      "rotation": 2
    },
    {
      "x": 12,
      "y": 1,
      "z": -8,
      "name": "Wood_Softwood_Planks"
    },
    {
      "x": 12,
      "y": 7,
      "z": -8,
      "name": "Wood_Beech_Trunk",
      "support": 15,
      "rotation": 4
    },
    {
      "x": 12,
      "y": 8,
      "z": -8,
      "name": "*Wood_Softwood_Roof_State_Definitions_Corner_Right",
      "rotation": 2
    },
    {
      "x": 12,
      "y": 1,
      "z": -7,
      "name": "Wood_Softwood_Planks"
    },
    {
      "x": 12,
      "y": 2,
      "z": -7,
      "name": "Furniture_Tavern_Table",
      "support": 15,
      "filler": 31,
      "rotation": 3
    },
    {
      "x": 12,
      "y": 7,
      "z": -7,
      "name": "Wood_Beech_Trunk",
      "support": 15,
      "rotation": 4
    },
    {
      "x": 12,
      "y": 8,
      "z": -7,
      "name": "Wood_Softwood_Roof",
      "rotation": 1
    },
    {
      "x": 12,
      "y": 1,
      "z": -6,
      "name": "Wood_Softwood_Planks"
    },
    {
      "x": 12,
      "y": 2,
      "z": -6,
      "name": "Furniture_Tavern_Table",
      "support": 15,
      "filler": 63,
      "rotation": 3
    },
    {
      "x": 12,
      "y": 7,
      "z": -6,
      "name": "Wood_Beech_Trunk",
      "support": 15,
      "rotation": 4
    },
    {
      "x": 12,
      "y": 8,
      "z": -6,
      "name": "*Wood_Softwood_Roof_State_Definitions_Corner_Right",
      "rotation": 1
    },
    {
      "x": 12,
      "y": 1,
      "z": -5,
      "name": "Wood_Softwood_Planks"
    },
    {
      "x": 12,
      "y": 2,
      "z": -5,
      "name": "Furniture_Tavern_Chair",
      "components": {
        "Components": {}
      },
      "support": 15,
      "rotation": 2
    },
    {
      "x": 12,
      "y": 7,
      "z": -5,
      "name": "Wood_Beech_Trunk",
      "support": 15,
      "rotation": 4
    },
    {
      "x": 12,
      "y": 8,
      "z": -5,
      "name": "Wood_Softwood_Roof_Flat",
      "rotation": 3
    },
    {
      "x": 12,
      "y": 1,
      "z": -4,
      "name": "Wood_Softwood_Planks"
    },
    {
      "x": 12,
      "y": 5,
      "z": -4,
      "name": "Deco_Lantern_Ceiling",
      "support": 15
    },
    {
      "x": 12,
      "y": 6,
      "z": -4,
      "name": "Deco_Rope",
      "support": 15
    },
    {
      "x": 12,
      "y": 7,
      "z": -4,
      "name": "Wood_Beech_Trunk",
      "support": 15,
      "rotation": 4
    },
    {
      "x": 12,
      "y": 8,
      "z": -4,
      "name": "Wood_Softwood_Roof_Flat",
      "rotation": 3
    },
    {
      "x": 12,
      "y": 1,
      "z": -3,
      "name": "Wood_Softwood_Planks"
    },
    {
      "x": 12,
      "y": 7,
      "z": -3,
      "name": "Wood_Beech_Trunk",
      "support": 15,
      "rotation": 4
    },
    {
      "x": 12,
      "y": 8,
      "z": -3,
      "name": "Wood_Softwood_Roof_Flat",
      "rotation": 3
    },
    {
      "x": 12,
      "y": 1,
      "z": -2,
      "name": "Wood_Softwood_Planks"
    },
    {
      "x": 12,
      "y": 2,
      "z": -2,
      "name": "*Furniture_Village_Door_State_Definitions_CloseDoorOut"
    },
    {
      "x": 12,
      "y": 3,
      "z": -2,
      "name": "*Furniture_Village_Door_State_Definitions_CloseDoorOut",
      "filler": 1024
    },
    {
      "x": 12,
      "y": 4,
      "z": -2,
      "name": "Wood_Village_Wall_Full"
    },
    {
      "x": 12,
      "y": 5,
      "z": -2,
      "name": "Wood_Beech_Trunk",
      "support": 15,
      "rotation": 5
    },
    {
      "x": 12,
      "y": 6,
      "z": -2,
      "name": "Wood_Village_Wall_Full"
    },
    {
      "x": 12,
      "y": 7,
      "z": -2,
      "name": "Wood_Beech_Trunk",
      "support": 15,
      "rotation": 4
    },
    {
      "x": 12,
      "y": 8,
      "z": -2,
      "name": "Wood_Softwood_Roof_Flat",
      "rotation": 3
    },
    {
      "x": 12,
      "y": 1,
      "z": -1,
      "name": "Rock_Stone_Cobble"
    },
    {
      "x": 12,
      "y": 5,
      "z": -1,
      "name": "Furniture_Village_Sign",
      "rotation": 1
    },
    {
      "x": 12,
      "y": 7,
      "z": -1,
      "name": "Wood_Softwood_Planks"
    },
    {
      "x": 12,
      "y": 8,
      "z": -1,
      "name": "Wood_Softwood_Roof_Flat",
      "rotation": 3
    },
    {
      "x": 13,
      "y": 1,
      "z": -11,
      "name": "Rock_Stone_Cobble"
    },
    {
      "x": 13,
      "y": 3,
      "z": -11,
      "name": "Plant_Vine_Wall",
      "support": 15,
      "rotation": 2
    },
    {
      "x": 13,
      "y": 5,
      "z": -11,
      "name": "Wood_Softwood_Roof_Hollow",
      "rotation": 2
    },
    {
      "x": 13,
      "y": 1,
      "z": -10,
      "name": "Rock_Stone_Cobble"
    },
    {
      "x": 13,
      "y": 2,
      "z": -10,
      "name": "Rock_Stone_Brick"
    },
    {
      "x": 13,
      "y": 3,
      "z": -10,
      "name": "*Wood_Village_Wall_Full_State_Definitions_Bottom"
    },
    {
      "x": 13,
      "y": 4,
      "z": -10,
      "name": "*Wood_Village_Wall_Full_State_Definitions_Top"
    },
    {
      "x": 13,
      "y": 5,
      "z": -10,
      "name": "Wood_Beech_Trunk",
      "support": 15,
      "rotation": 5
    },
    {
      "x": 13,
      "y": 6,
      "z": -10,
      "name": "Wood_Softwood_Roof",
      "rotation": 2
    },
    {
      "x": 13,
      "y": 1,
      "z": -9,
      "name": "Wood_Softwood_Planks"
    },
    {
      "x": 13,
      "y": 2,
      "z": -9,
      "name": "Furniture_Tavern_Candle",
      "support": 15
    },
    {
      "x": 13,
      "y": 6,
      "z": -9,
      "name": "*Wood_Softwood_Stairs_State_Definitions_Inverted_Corner_Left",
      "rotation": 10
    },
    {
      "x": 13,
      "y": 7,
      "z": -9,
      "name": "*Wood_Softwood_Roof_State_Definitions_Corner_Right",
      "rotation": 2
    },
    {
      "x": 13,
      "y": 1,
      "z": -8,
      "name": "Wood_Softwood_Planks"
    },
    {
      "x": 13,
      "y": 2,
      "z": -8,
      "name": "Furniture_Tavern_Chair",
      "components": {
        "Components": {}
      },
      "support": 15
    },
    {
      "x": 13,
      "y": 6,
      "z": -8,
      "name": "Wood_Softwood_Stairs",
      "rotation": 9
    },
    {
      "x": 13,
      "y": 7,
      "z": -8,
      "name": "Wood_Softwood_Roof",
      "rotation": 1
    },
    {
      "x": 13,
      "y": 1,
      "z": -7,
      "name": "Wood_Softwood_Planks"
    },
    {
      "x": 13,
      "y": 2,
      "z": -7,
      "name": "Furniture_Tavern_Table",
      "support": 15,
      "rotation": 3
    },
    {
      "x": 13,
      "y": 6,
      "z": -7,
      "name": "Wood_Softwood_Stairs",
      "rotation": 9
    },
    {
      "x": 13,
      "y": 7,
      "z": -7,
      "name": "Wood_Softwood_Roof",
      "rotation": 1
    },
    {
      "x": 13,
      "y": 1,
      "z": -6,
      "name": "Wood_Softwood_Planks"
    },
    {
      "x": 13,
      "y": 2,
      "z": -6,
      "name": "Furniture_Tavern_Table",
      "support": 15,
      "filler": 32,
      "rotation": 3
    },
    {
      "x": 13,
      "y": 6,
      "z": -6,
      "name": "Wood_Softwood_Stairs",
      "rotation": 9
    },
    {
      "x": 13,
      "y": 7,
      "z": -6,
      "name": "Wood_Softwood_Roof",
      "rotation": 1
    },
    {
      "x": 13,
      "y": 1,
      "z": -5,
      "name": "Wood_Softwood_Planks"
    },
    {
      "x": 13,
      "y": 6,
      "z": -5,
      "name": "Wood_Softwood_Stairs",
      "rotation": 9
    },
    {
      "x": 13,
      "y": 7,
      "z": -5,
      "name": "Wood_Softwood_Roof",
      "rotation": 1
    },
    {
      "x": 13,
      "y": 1,
      "z": -4,
      "name": "Wood_Softwood_Planks"
    },
    {
      "x": 13,
      "y": 6,
      "z": -4,
      "name": "Wood_Softwood_Stairs",
      "rotation": 9
    },
    {
      "x": 13,
      "y": 7,
      "z": -4,
      "name": "Wood_Softwood_Roof",
      "rotation": 1
    },
    {
      "x": 13,
      "y": 1,
      "z": -3,
      "name": "Wood_Softwood_Planks"
    },
    {
      "x": 13,
      "y": 3,
      "z": -3,
      "name": "Aetherhaven_Management_Block",
      "components": {
        "Components": {
          "AetherhavenManagementBlock": {
            "PlotId": "",
            "TownId": ""
          },
          "PlacedByInteraction": {
            "WhoPlacedUuid": {
              "$binary": "v7RyWIT/TYKnXA2XcxdQtw==",
              "$type": "04"
            }
          }
        }
      },
      "rotation": 2
    },
    {
      "x": 13,
      "y": 6,
      "z": -3,
      "name": "Wood_Softwood_Stairs",
      "rotation": 9
    },
    {
      "x": 13,
      "y": 7,
      "z": -3,
      "name": "Wood_Softwood_Roof",
      "rotation": 1
    },
    {
      "x": 13,
      "y": 1,
      "z": -2,
      "name": "Rock_Stone_Cobble_Mossy"
    },
    {
      "x": 13,
      "y": 2,
      "z": -2,
      "name": "Rock_Stone_Brick"
    },
    {
      "x": 13,
      "y": 3,
      "z": -2,
      "name": "*Wood_Village_Wall_Full_State_Definitions_Bottom"
    },
    {
      "x": 13,
      "y": 4,
      "z": -2,
      "name": "*Wood_Village_Wall_Full_State_Definitions_Top"
    },
    {
      "x": 13,
      "y": 5,
      "z": -2,
      "name": "Wood_Beech_Trunk",
      "support": 15,
      "rotation": 5
    },
    {
      "x": 13,
      "y": 6,
      "z": -2,
      "name": "Wood_Village_Wall_Full"
    },
    {
      "x": 13,
      "y": 7,
      "z": -2,
      "name": "Wood_Softwood_Roof",
      "rotation": 1
    },
    {
      "x": 13,
      "y": 1,
      "z": -1,
      "name": "Rock_Stone_Cobble"
    },
    {
      "x": 13,
      "y": 6,
      "z": -1,
      "name": "Wood_Softwood_Stairs",
      "rotation": 9
    },
    {
      "x": 13,
      "y": 7,
      "z": -1,
      "name": "Wood_Softwood_Roof",
      "rotation": 1
    },
    {
      "x": 14,
      "y": 1,
      "z": -11,
      "name": "Rock_Stone_Cobble"
    },
    {
      "x": 14,
      "y": 4,
      "z": -11,
      "name": "Wood_Beech_Branch_Corner",
      "support": 15,
      "rotation": 2
    },
    {
      "x": 14,
      "y": 5,
      "z": -11,
      "name": "Wood_Softwood_Roof",
      "rotation": 2
    },
    {
      "x": 14,
      "y": 1,
      "z": -10,
      "name": "Rock_Stone_Cobble_Mossy"
    },
    {
      "x": 14,
      "y": 2,
      "z": -10,
      "name": "Wood_Beech_Trunk",
      "support": 15
    },
    {
      "x": 14,
      "y": 3,
      "z": -10,
      "name": "Wood_Beech_Trunk",
      "support": 15
    },
    {
      "x": 14,
      "y": 4,
      "z": -10,
      "name": "Wood_Beech_Trunk",
      "support": 15
    },
    {
      "x": 14,
      "y": 5,
      "z": -10,
      "name": "Wood_Beech_Trunk",
      "support": 15
    },
    {
      "x": 14,
      "y": 6,
      "z": -10,
      "name": "*Wood_Softwood_Roof_State_Definitions_Corner_Left",
      "rotation": 1
    },
    {
      "x": 14,
      "y": 1,
      "z": -9,
      "name": "Rock_Stone_Cobble"
    },
    {
      "x": 14,
      "y": 2,
      "z": -9,
      "name": "Rock_Stone_Brick"
    },
    {
      "x": 14,
      "y": 3,
      "z": -9,
      "name": "*Wood_Village_Wall_Full_State_Definitions_Bottom"
    },
    {
      "x": 14,
      "y": 4,
      "z": -9,
      "name": "*Wood_Village_Wall_Full_State_Definitions_Top"
    },
    {
      "x": 14,
      "y": 5,
      "z": -9,
      "name": "Wood_Beech_Trunk",
      "support": 15,
      "rotation": 4
    },
    {
      "x": 14,
      "y": 6,
      "z": -9,
      "name": "Wood_Softwood_Roof",
      "rotation": 1
    },
    {
      "x": 14,
      "y": 1,
      "z": -8,
      "name": "Rock_Stone_Cobble"
    },
    {
      "x": 14,
      "y": 2,
      "z": -8,
      "name": "Rock_Stone_Brick"
    },
    {
      "x": 14,
      "y": 3,
      "z": -8,
      "name": "Furniture_Village_Window",
      "rotation": 1
    },
    {
      "x": 14,
      "y": 4,
      "z": -8,
      "name": "Furniture_Village_Window",
      "rotation": 1
    },
    {
      "x": 14,
      "y": 5,
      "z": -8,
      "name": "Wood_Beech_Trunk",
      "support": 15,
      "rotation": 4
    },
    {
      "x": 14,
      "y": 6,
      "z": -8,
      "name": "Wood_Softwood_Roof",
      "rotation": 1
    },
    {
      "x": 14,
      "y": 1,
      "z": -7,
      "name": "Rock_Stone_Cobble_Mossy"
    },
    {
      "x": 14,
      "y": 2,
      "z": -7,
      "name": "Rock_Stone_Brick"
    },
    {
      "x": 14,
      "y": 3,
      "z": -7,
      "name": "Furniture_Village_Window",
      "rotation": 1
    },
    {
      "x": 14,
      "y": 4,
      "z": -7,
      "name": "Furniture_Village_Window",
      "rotation": 1
    },
    {
      "x": 14,
      "y": 5,
      "z": -7,
      "name": "Wood_Beech_Trunk",
      "support": 15,
      "rotation": 4
    },
    {
      "x": 14,
      "y": 6,
      "z": -7,
      "name": "Wood_Softwood_Roof",
      "rotation": 1
    },
    {
      "x": 14,
      "y": 1,
      "z": -6,
      "name": "Rock_Stone_Cobble"
    },
    {
      "x": 14,
      "y": 2,
      "z": -6,
      "name": "Rock_Stone_Brick"
    },
    {
      "x": 14,
      "y": 3,
      "z": -6,
      "name": "*Wood_Village_Wall_Full_State_Definitions_Bottom"
    },
    {
      "x": 14,
      "y": 4,
      "z": -6,
      "name": "*Wood_Village_Wall_Full_State_Definitions_Top"
    },
    {
      "x": 14,
      "y": 5,
      "z": -6,
      "name": "Wood_Beech_Trunk",
      "support": 15,
      "rotation": 4
    },
    {
      "x": 14,
      "y": 6,
      "z": -6,
      "name": "Wood_Softwood_Roof",
      "rotation": 1
    },
    {
      "x": 14,
      "y": 1,
      "z": -5,
      "name": "Rock_Stone_Cobble_Mossy"
    },
    {
      "x": 14,
      "y": 2,
      "z": -5,
      "name": "Rock_Stone_Brick"
    },
    {
      "x": 14,
      "y": 3,
      "z": -5,
      "name": "Furniture_Village_Window",
      "rotation": 1
    },
    {
      "x": 14,
      "y": 4,
      "z": -5,
      "name": "Furniture_Village_Window",
      "rotation": 1
    },
    {
      "x": 14,
      "y": 5,
      "z": -5,
      "name": "Wood_Beech_Trunk",
      "support": 15,
      "rotation": 4
    },
    {
      "x": 14,
      "y": 6,
      "z": -5,
      "name": "Wood_Softwood_Roof",
      "rotation": 1
    },
    {
      "x": 14,
      "y": 1,
      "z": -4,
      "name": "Rock_Stone_Cobble"
    },
    {
      "x": 14,
      "y": 2,
      "z": -4,
      "name": "Rock_Stone_Brick_Mossy"
    },
    {
      "x": 14,
      "y": 3,
      "z": -4,
      "name": "Furniture_Village_Window",
      "rotation": 1
    },
    {
      "x": 14,
      "y": 4,
      "z": -4,
      "name": "Furniture_Village_Window",
      "rotation": 1
    },
    {
      "x": 14,
      "y": 5,
      "z": -4,
      "name": "Wood_Beech_Trunk",
      "support": 15,
      "rotation": 4
    },
    {
      "x": 14,
      "y": 6,
      "z": -4,
      "name": "Wood_Softwood_Roof",
      "rotation": 1
    },
    {
      "x": 14,
      "y": 1,
      "z": -3,
      "name": "Rock_Stone_Cobble"
    },
    {
      "x": 14,
      "y": 2,
      "z": -3,
      "name": "Rock_Stone_Brick"
    },
    {
      "x": 14,
      "y": 3,
      "z": -3,
      "name": "*Wood_Village_Wall_Full_State_Definitions_Bottom"
    },
    {
      "x": 14,
      "y": 4,
      "z": -3,
      "name": "*Wood_Village_Wall_Full_State_Definitions_Top"
    },
    {
      "x": 14,
      "y": 5,
      "z": -3,
      "name": "Wood_Beech_Trunk",
      "support": 15,
      "rotation": 4
    },
    {
      "x": 14,
      "y": 6,
      "z": -3,
      "name": "Wood_Softwood_Roof",
      "rotation": 1
    },
    {
      "x": 14,
      "y": 1,
      "z": -2,
      "name": "Rock_Stone_Cobble"
    },
    {
      "x": 14,
      "y": 2,
      "z": -2,
      "name": "Wood_Beech_Trunk",
      "support": 15
    },
    {
      "x": 14,
      "y": 3,
      "z": -2,
      "name": "Wood_Beech_Trunk",
      "support": 15
    },
    {
      "x": 14,
      "y": 4,
      "z": -2,
      "name": "Wood_Beech_Trunk",
      "support": 15
    },
    {
      "x": 14,
      "y": 5,
      "z": -2,
      "name": "Wood_Beech_Trunk",
      "support": 15
    },
    {
      "x": 14,
      "y": 6,
      "z": -2,
      "name": "Wood_Softwood_Roof",
      "rotation": 1
    },
    {
      "x": 14,
      "y": 1,
      "z": -1,
      "name": "Rock_Stone_Cobble"
    },
    {
      "x": 14,
      "y": 5,
      "z": -1,
      "name": "Wood_Beech_Branch_Corner",
      "support": 15
    },
    {
      "x": 14,
      "y": 6,
      "z": -1,
      "name": "Wood_Softwood_Roof",
      "rotation": 1
    },
    {
      "x": 15,
      "y": 1,
      "z": -11,
      "name": "Rock_Stone_Cobble"
    },
    {
      "x": 15,
      "y": 5,
      "z": -11,
      "name": "*Wood_Softwood_Roof_Hollow_State_Definitions_Corner_Left",
      "rotation": 1
    },
    {
      "x": 15,
      "y": 1,
      "z": -10,
      "name": "Rock_Stone_Cobble"
    },
    {
      "x": 15,
      "y": 4,
      "z": -10,
      "name": "Wood_Beech_Branch_Corner",
      "support": 15,
      "rotation": 1
    },
    {
      "x": 15,
      "y": 5,
      "z": -10,
      "name": "Wood_Softwood_Roof",
      "rotation": 1
    },
    {
      "x": 15,
      "y": 1,
      "z": -9,
      "name": "Rock_Stone_Cobble_Mossy"
    },
    {
      "x": 15,
      "y": 5,
      "z": -9,
      "name": "Wood_Softwood_Roof_Hollow",
      "rotation": 1
    },
    {
      "x": 15,
      "y": 1,
      "z": -8,
      "name": "Rock_Stone_Cobble"
    },
    {
      "x": 15,
      "y": 5,
      "z": -8,
      "name": "Wood_Softwood_Roof_Hollow",
      "rotation": 1
    },
    {
      "x": 15,
      "y": 1,
      "z": -7,
      "name": "Rock_Stone_Cobble"
    },
    {
      "x": 15,
      "y": 5,
      "z": -7,
      "name": "Wood_Softwood_Roof_Hollow",
      "rotation": 1
    },
    {
      "x": 15,
      "y": 1,
      "z": -6,
      "name": "Rock_Stone_Cobble"
    },
    {
      "x": 15,
      "y": 4,
      "z": -6,
      "name": "Plant_Vine_Wall",
      "support": 15,
      "rotation": 1
    },
    {
      "x": 15,
      "y": 5,
      "z": -6,
      "name": "Wood_Softwood_Roof_Hollow",
      "rotation": 1
    },
    {
      "x": 15,
      "y": 1,
      "z": -5,
      "name": "Rock_Stone_Cobble"
    },
    {
      "x": 15,
      "y": 5,
      "z": -5,
      "name": "Wood_Softwood_Roof_Hollow",
      "rotation": 1
    },
    {
      "x": 15,
      "y": 1,
      "z": -4,
      "name": "Rock_Stone_Cobble"
    },
    {
      "x": 15,
      "y": 5,
      "z": -4,
      "name": "Wood_Softwood_Roof_Hollow",
      "rotation": 1
    },
    {
      "x": 15,
      "y": 1,
      "z": -3,
      "name": "Rock_Stone_Cobble"
    },
    {
      "x": 15,
      "y": 5,
      "z": -3,
      "name": "Wood_Softwood_Roof_Hollow",
      "rotation": 1
    },
    {
      "x": 15,
      "y": 1,
      "z": -2,
      "name": "Rock_Stone_Cobble"
    },
    {
      "x": 15,
      "y": 4,
      "z": -2,
      "name": "Wood_Beech_Branch_Corner",
      "support": 15,
      "rotation": 1
    },
    {
      "x": 15,
      "y": 5,
      "z": -2,
      "name": "Wood_Softwood_Roof",
      "rotation": 1
    },
    {
      "x": 15,
      "y": 1,
      "z": -1,
      "name": "Rock_Stone_Cobble"
    },
    {
      "x": 15,
      "y": 5,
      "z": -1,
      "name": "Wood_Softwood_Roof_Hollow",
      "rotation": 1
    }
  ],
  "entities": [
    {
      "Components": {
        "AetherhavenBlockEntityScaleMigrated": {},
        "Transform": {
          "Position": {
            "X": 3.1654967824604796,
            "Y": 4.294966770766848,
            "Z": -5.483929902635111
          },
          "Rotation": {
            "Pitch": -1.4132819175720215,
            "Yaw": -0.0,
            "Roll": -6.2831854820251465
          }
        },
        "Prop": {},
        "BlockEntity": {
          "Version": 1,
          "BlockTypeKey": "Deco_Plate"
        },
        "UUID": {
          "UUID": {
            "$binary": "+rQqhDBwP2SRgE19HEOpLQ==",
            "$type": "04"
          }
        },
        "EntityScale": {
          "Scale": 0.5
        },
        "Item": {
          "Item": {
            "Id": "Deco_Plate",
            "Quantity": 1,
            "Durability": 0.0,
            "MaxDurability": 0.0,
            "Quality": 0,
            "OverrideDroppedItemAnimation": true
          },
          "StackDelay": 1.5,
          "PickupDelay": 0.5,
          "PickupThrottle": 0.0,
          "RemovedByPlayerPickup": false
        },
        "PrefabCopyable": {},
        "Invulnerable": {},
        "PreventItemMerging": {},
        "PreventPickup": {}
      }
    },
    {
      "Components": {
        "AetherhavenBlockEntityScaleMigrated": {},
        "Transform": {
          "Position": {
            "X": 3.1654967824604796,
            "Y": 4.294966770766848,
            "Z": -5.414807588181986
          },
          "Rotation": {
            "Pitch": -1.4132819175720215,
            "Yaw": -0.0,
            "Roll": -6.2831854820251465
          }
        },
        "Prop": {},
        "BlockEntity": {
          "Version": 1,
          "BlockTypeKey": "Deco_Plate"
        },
        "UUID": {
          "UUID": {
            "$binary": "lE1m8DdyOg6kF8R3K9JWpw==",
            "$type": "04"
          }
        },
        "EntityScale": {
          "Scale": 0.5
        },
        "Item": {
          "Item": {
            "Id": "Deco_Plate",
            "Quantity": 1,
            "Durability": 0.0,
            "MaxDurability": 0.0,
            "Quality": 0,
            "OverrideDroppedItemAnimation": true
          },
          "StackDelay": 1.5,
          "PickupDelay": 0.5,
          "PickupThrottle": 0.0,
          "RemovedByPlayerPickup": false
        },
        "PrefabCopyable": {},
        "Invulnerable": {},
        "PreventItemMerging": {},
        "PreventPickup": {}
      }
    },
    {
      "Components": {
        "AetherhavenBlockEntityScaleMigrated": {},
        "Transform": {
          "Position": {
            "X": 3.1654967824604796,
            "Y": 4.294966770766848,
            "Z": -5.360982209764018
          },
          "Rotation": {
            "Pitch": -1.4132819175720215,
            "Yaw": -0.0,
            "Roll": -6.2831854820251465
          }
        },
        "Prop": {},
        "BlockEntity": {
          "Version": 1,
          "BlockTypeKey": "Deco_Plate"
        },
        "UUID": {
          "UUID": {
            "$binary": "1WfCzvxiP+aN5Z4WUihg3A==",
            "$type": "04"
          }
        },
        "EntityScale": {
          "Scale": 0.5
        },
        "Item": {
          "Item": {
            "Id": "Deco_Plate",
            "Quantity": 1,
            "Durability": 0.0,
            "MaxDurability": 0.0,
            "Quality": 0,
            "OverrideDroppedItemAnimation": true
          },
          "StackDelay": 1.5,
          "PickupDelay": 0.5,
          "PickupThrottle": 0.0,
          "RemovedByPlayerPickup": false
        },
        "PrefabCopyable": {},
        "Invulnerable": {},
        "PreventItemMerging": {},
        "PreventPickup": {}
      }
    },
    {
      "Components": {
        "AetherhavenBlockEntityScaleMigrated": {},
        "Transform": {
          "Position": {
            "X": 3.2912750244140625,
            "Y": 4.250831604003906,
            "Z": -5.651039123535156
          },
          "Rotation": {
            "Pitch": 0.0,
            "Yaw": 2.1876869201660156,
            "Roll": 0.0
          }
        },
        "Prop": {},
        "BlockEntity": {
          "Version": 1,
          "BlockTypeKey": "Deco_Mug"
        },
        "UUID": {
          "UUID": {
            "$binary": "SLSlgRraMpC/ZKVUfnDbNw==",
            "$type": "04"
          }
        },
        "EntityScale": {
          "Scale": 0.5
        },
        "Item": {
          "Item": {
            "Id": "Deco_Mug",
            "Quantity": 1,
            "Durability": 0.0,
            "MaxDurability": 0.0,
            "Quality": 0,
            "OverrideDroppedItemAnimation": true
          },
          "StackDelay": 1.5,
          "PickupDelay": 0.5,
          "PickupThrottle": 0.0,
          "RemovedByPlayerPickup": false
        },
        "PrefabCopyable": {},
        "Invulnerable": {},
        "PreventItemMerging": {},
        "PreventPickup": {}
      }
    },
    {
      "Components": {
        "AetherhavenBlockEntityScaleMigrated": {},
        "Transform": {
          "Position": {
            "X": 3.2912826538085938,
            "Y": 4.250831604003906,
            "Z": -8.410789489746094
          },
          "Rotation": {
            "Pitch": 0.0,
            "Yaw": 2.8638830184936523,
            "Roll": 0.0
          }
        },
        "Prop": {},
        "BlockEntity": {
          "Version": 1,
          "BlockTypeKey": "Deco_Mug"
        },
        "UUID": {
          "UUID": {
            "$binary": "lsqxo+X3NtSxmYfdXLaxRA==",
            "$type": "04"
          }
        },
        "EntityScale": {
          "Scale": 0.5
        },
        "Item": {
          "Item": {
            "Id": "Deco_Mug",
            "Quantity": 1,
            "Durability": 0.0,
            "MaxDurability": 0.0,
            "Quality": 0,
            "OverrideDroppedItemAnimation": true
          },
          "StackDelay": 1.5,
          "PickupDelay": 0.5,
          "PickupThrottle": 0.0,
          "RemovedByPlayerPickup": false
        },
        "PrefabCopyable": {},
        "Invulnerable": {},
        "PreventItemMerging": {},
        "PreventPickup": {}
      }
    },
    {
      "Components": {
        "AetherhavenBlockEntityScaleMigrated": {},
        "Transform": {
          "Position": {
            "X": 3.2912826538085938,
            "Y": 4.250831604003906,
            "Z": -4.720314025878906
          },
          "Rotation": {
            "Pitch": 0.0,
            "Yaw": 1.3552712202072144,
            "Roll": 0.0
          }
        },
        "Prop": {},
        "BlockEntity": {
          "Version": 1,
          "BlockTypeKey": "Deco_Mug"
        },
        "UUID": {
          "UUID": {
            "$binary": "56ywiFFBNquwdozDpiukSg==",
            "$type": "04"
          }
        },
        "EntityScale": {
          "Scale": 0.5
        },
        "Item": {
          "Item": {
            "Id": "Deco_Mug",
            "Quantity": 1,
            "Durability": 0.0,
            "MaxDurability": 0.0,
            "Quality": 0,
            "OverrideDroppedItemAnimation": true
          },
          "StackDelay": 1.5,
          "PickupDelay": 0.5,
          "PickupThrottle": 0.0,
          "RemovedByPlayerPickup": false
        },
        "PrefabCopyable": {},
        "Invulnerable": {},
        "PreventItemMerging": {},
        "PreventPickup": {}
      }
    },
    {
      "Components": {
        "AetherhavenBlockEntityScaleMigrated": {},
        "Transform": {
          "Position": {
            "X": 3.2912826538085938,
            "Y": 4.250831604003906,
            "Z": -4.3015594482421875
          },
          "Rotation": {
            "Pitch": 0.0,
            "Yaw": 2.0195071697235107,
            "Roll": 0.0
          }
        },
        "Prop": {},
        "BlockEntity": {
          "Version": 1,
          "BlockTypeKey": "Deco_Mug"
        },
        "UUID": {
          "UUID": {
            "$binary": "7vjhzr4PNAiJw2nuqxvW9A==",
            "$type": "04"
          }
        },
        "EntityScale": {
          "Scale": 0.5
        },
        "Item": {
          "Item": {
            "Id": "Deco_Mug",
            "Quantity": 1,
            "Durability": 0.0,
            "MaxDurability": 0.0,
            "Quality": 0,
            "OverrideDroppedItemAnimation": true
          },
          "StackDelay": 1.5,
          "PickupDelay": 0.5,
          "PickupThrottle": 0.0,
          "RemovedByPlayerPickup": false
        },
        "PrefabCopyable": {},
        "Invulnerable": {},
        "PreventItemMerging": {},
        "PreventPickup": {}
      }
    },
    {
      "Components": {
        "AetherhavenBlockEntityScaleMigrated": {},
        "Transform": {
          "Position": {
            "X": 8.416816711425781,
            "Y": 3.2615585327148438,
            "Z": -7.568267822265625
          },
          "Rotation": {
            "Pitch": 0.0,
            "Yaw": 2.8638830184936523,
            "Roll": 0.0
          }
        },
        "Prop": {},
        "BlockEntity": {
          "Version": 1,
          "BlockTypeKey": "Deco_Mug"
        },
        "UUID": {
          "UUID": {
            "$binary": "wPma9sg8P/CclgjPWPV96A==",
            "$type": "04"
          }
        },
        "EntityScale": {
          "Scale": 0.5
        },
        "Item": {
          "Item": {
            "Id": "Deco_Mug",
            "Quantity": 1,
            "Durability": 0.0,
            "MaxDurability": 0.0,
            "Quality": 0,
            "OverrideDroppedItemAnimation": true
          },
          "StackDelay": 1.5,
          "PickupDelay": 0.5,
          "PickupThrottle": 0.0,
          "RemovedByPlayerPickup": false
        },
        "PrefabCopyable": {},
        "Invulnerable": {},
        "PreventItemMerging": {},
        "PreventPickup": {}
      }
    },
    {
      "Components": {
        "AetherhavenBlockEntityScaleMigrated": {},
        "Transform": {
          "Position": {
            "X": 8.950027465820312,
            "Y": 3.2615585327148438,
            "Z": -6.390472412109375
          },
          "Rotation": {
            "Pitch": 0.0,
            "Yaw": -0.28189992904663086,
            "Roll": 0.0
          }
        },
        "Prop": {},
        "BlockEntity": {
          "Version": 1,
          "BlockTypeKey": "Deco_Mug"
        },
        "UUID": {
          "UUID": {
            "$binary": "VyA9FR+vN5CCRwqC4tSZTA==",
            "$type": "04"
          }
        },
        "EntityScale": {
          "Scale": 0.5
        },
        "Item": {
          "Item": {
            "Id": "Deco_Mug",
            "Quantity": 1,
            "Durability": 0.0,
            "MaxDurability": 0.0,
            "Quality": 0,
            "OverrideDroppedItemAnimation": true
          },
          "StackDelay": 1.5,
          "PickupDelay": 0.5,
          "PickupThrottle": 0.0,
          "RemovedByPlayerPickup": false
        },
        "PrefabCopyable": {},
        "Invulnerable": {},
        "PreventItemMerging": {},
        "PreventPickup": {}
      }
    },
    {
      "Components": {
        "AetherhavenBlockEntityScaleMigrated": {},
        "Transform": {
          "Position": {
            "X": 9.52549774864275,
            "Y": 3.25,
            "Z": -7.10605026641224
          },
          "Rotation": {
            "Pitch": 0.0,
            "Yaw": 1.168129801750183,
            "Roll": 0.0
          }
        },
        "Prop": {},
        "BlockEntity": {
          "Version": 1,
          "BlockTypeKey": "Food_Salad_Caesar"
        },
        "UUID": {
          "UUID": {
            "$binary": "o6RONnStMm+GhysMjtwXwA==",
            "$type": "04"
          }
        },
        "EntityScale": {
          "Scale": 0.5
        },
        "Item": {
          "Item": {
            "Id": "Food_Salad_Caesar",
            "Quantity": 1,
            "Durability": 0.0,
            "MaxDurability": 0.0,
            "Quality": 5,
            "OverrideDroppedItemAnimation": true
          },
          "StackDelay": 1.5,
          "PickupDelay": 0.5,
          "PickupThrottle": 0.0,
          "RemovedByPlayerPickup": false
        },
        "PrefabCopyable": {},
        "Invulnerable": {},
        "PreventItemMerging": {},
        "PreventPickup": {}
      }
    },
    {
      "Components": {
        "AetherhavenBlockEntityScaleMigrated": {},
        "Transform": {
          "Position": {
            "X": 12.20751669844509,
            "Y": 5.524025039290336,
            "Z": -0.44644362351917266
          },
          "Rotation": {
            "Pitch": -1.551866054534912,
            "Yaw": 0.2541961669921875,
            "Roll": 1.3165796995162964
          }
        },
        "Prop": {},
        "BlockEntity": {
          "Version": 1,
          "BlockTypeKey": "Food_Salad_Mushroom"
        },
        "UUID": {
          "UUID": {
            "$binary": "c+kDdAenO+ak3yh1Hc7ldQ==",
            "$type": "04"
          }
        },
        "EntityScale": {
          "Scale": 0.5
        },
        "Item": {
          "Item": {
            "Id": "Food_Salad_Mushroom",
            "Quantity": 1,
            "Durability": 0.0,
            "MaxDurability": 0.0,
            "Quality": 1,
            "OverrideDroppedItemAnimation": true
          },
          "StackDelay": 1.5,
          "PickupDelay": 0.5,
          "PickupThrottle": 0.0,
          "RemovedByPlayerPickup": false
        },
        "PrefabCopyable": {},
        "Invulnerable": {},
        "PreventItemMerging": {},
        "PreventPickup": {}
      }
    },
    {
      "Components": {
        "AetherhavenBlockEntityScaleMigrated": {},
        "Transform": {
          "Position": {
            "X": 12.378959655761719,
            "Y": 3.2461090087890625,
            "Z": -5.64794921875
          },
          "Rotation": {
            "Pitch": 0.0,
            "Yaw": -1.0147323608398438,
            "Roll": 0.0
          }
        },
        "Prop": {},
        "BlockEntity": {
          "Version": 1,
          "BlockTypeKey": "Deco_Mug"
        },
        "UUID": {
          "UUID": {
            "$binary": "ddLCCFJyPru7ArI+4ewoZg==",
            "$type": "04"
          }
        },
        "EntityScale": {
          "Scale": 0.5
        },
        "Item": {
          "Item": {
            "Id": "Deco_Mug",
            "Quantity": 1,
            "Durability": 0.0,
            "MaxDurability": 0.0,
            "Quality": 0,
            "OverrideDroppedItemAnimation": true
          },
          "StackDelay": 1.5,
          "PickupDelay": 0.5,
          "PickupThrottle": 0.0,
          "RemovedByPlayerPickup": false
        },
        "PrefabCopyable": {},
        "Invulnerable": {},
        "PreventItemMerging": {},
        "PreventPickup": {}
      }
    },
    {
      "Components": {
        "AetherhavenBlockEntityScaleMigrated": {},
        "Transform": {
          "Position": {
            "X": 12.73483642891108,
            "Y": 5.524019403459505,
            "Z": -0.441442468869667
          },
          "Rotation": {
            "Pitch": -1.5518975257873535,
            "Yaw": -2.879190444946289,
            "Roll": 1.3165830373764038
          }
        },
        "Prop": {},
        "BlockEntity": {
          "Version": 1,
          "BlockTypeKey": "Food_Salad_Mushroom"
        },
        "UUID": {
          "UUID": {
            "$binary": "Jgj3AIEyOAavOiaUpncyLw==",
            "$type": "04"
          }
        },
        "EntityScale": {
          "Scale": 0.5
        },
        "Item": {
          "Item": {
            "Id": "Food_Salad_Mushroom",
            "Quantity": 1,
            "Durability": 0.0,
            "MaxDurability": 0.0,
            "Quality": 1,
            "OverrideDroppedItemAnimation": true
          },
          "StackDelay": 1.5,
          "PickupDelay": 0.5,
          "PickupThrottle": 0.0,
          "RemovedByPlayerPickup": false
        },
        "PrefabCopyable": {},
        "Invulnerable": {},
        "PreventItemMerging": {},
        "PreventPickup": {}
      }
    },
    {
      "Components": {
        "AetherhavenBlockEntityScaleMigrated": {},
        "Transform": {
          "Position": {
            "X": 13.107246398925781,
            "Y": 3.2615585327148438,
            "Z": -6.7338409423828125
          },
          "Rotation": {
            "Pitch": 0.0,
            "Yaw": 2.197920799255371,
            "Roll": -0.0
          }
        },
        "Prop": {},
        "BlockEntity": {
          "Version": 1,
          "BlockTypeKey": "Deco_Mug"
        },
        "UUID": {
          "UUID": {
            "$binary": "1hU7LgoeMXmWRHJgKOSQZg==",
            "$type": "04"
          }
        },
        "EntityScale": {
          "Scale": 0.5
        },
        "Item": {
          "Item": {
            "Id": "Deco_Mug",
            "Quantity": 1,
            "Durability": 0.0,
            "MaxDurability": 0.0,
            "Quality": 0,
            "OverrideDroppedItemAnimation": true
          },
          "StackDelay": 1.5,
          "PickupDelay": 0.5,
          "PickupThrottle": 0.0,
          "RemovedByPlayerPickup": false
        },
        "PrefabCopyable": {},
        "Invulnerable": {},
        "PreventItemMerging": {},
        "PreventPickup": {}
      }
    },
    {
      "Components": {
        "AetherhavenBlockEntityScaleMigrated": {},
        "Transform": {
          "Position": {
            "X": 13.393421530145133,
            "Y": 3.25,
            "Z": -5.569129257570637
          },
          "Rotation": {
            "Pitch": 0.0,
            "Yaw": 0.7953713536262512,
            "Roll": 0.0
          }
        },
        "Prop": {},
        "BlockEntity": {
          "Version": 1,
          "BlockTypeKey": "Food_Pie_Apple"
        },
        "UUID": {
          "UUID": {
            "$binary": "G5za8KnAO1ebHEAWAs/tsw==",
            "$type": "04"
          }
        },
        "EntityScale": {
          "Scale": 0.5
        },
        "Item": {
          "Item": {
            "Id": "Food_Pie_Apple",
            "Quantity": 1,
            "Durability": 0.0,
            "MaxDurability": 0.0,
            "Quality": 5,
            "OverrideDroppedItemAnimation": true
          },
          "StackDelay": 1.5,
          "PickupDelay": 0.5,
          "PickupThrottle": 0.0,
          "RemovedByPlayerPickup": false
        },
        "PrefabCopyable": {},
        "Invulnerable": {},
        "PreventItemMerging": {},
        "PreventPickup": {}
      }
    }
  ]
}