{
  "version": 8,
  "blockIdVersion": 11,
  "anchorX": 0,
  "anchorY": 0,
  "anchorZ": 0,
  "blocks": [
    {
      "x": 1,
      "y": 0,
      "z": 1,
      "name": "Soil_Grass"
    },
    {
      "x": 1,
      "y": 0,
      "z": 2,
      "name": "Soil_Grass"
    },
    {
      "x": 1,
      "y": 0,
      "z": 3,
      "name": "Soil_Grass"
    },
    {
      "x": 1,
      "y": 0,
      "z": 4,
      "name": "Soil_Grass"
    },
    {
      "x": 1,
      "y": 0,
      "z": 5,
      "name": "Soil_Grass"
    },
    {
      "x": 1,
      "y": 0,
      "z": 6,
      "name": "Soil_Grass"
    },
    {
      "x": 1,
      "y": 0,
      "z": 7,
      "name": "Soil_Grass"
    },
    {
      "x": 1,
      "y": 0,
      "z": 8,
      "name": "Soil_Grass_Deep"
    },
    {
      "x": 1,
      "y": 0,
      "z": 9,
      "name": "Soil_Pathway"
    },
    {
      "x": 1,
      "y": 0,
      "z": 10,
      "name": "Soil_Grass"
    },
    {
      "x": 1,
      "y": 0,
      "z": 11,
      "name": "Soil_Grass"
    },
    {
      "x": 1,
      "y": 0,
      "z": 12,
      "name": "Soil_Grass"
    },
    {
      "x": 1,
      "y": 0,
      "z": 13,
      "name": "Soil_Grass"
    },
    {
      "x": 1,
      "y": 0,
      "z": 14,
      "name": "Soil_Grass"
    },
    {
      "x": 1,
      "y": 0,
      "z": 15,
      "name": "Soil_Grass"
    },
    {
      "x": 1,
      "y": 0,
      "z": 16,
      "name": "Soil_Grass"
    },
    {
      "x": 1,
      "y": 0,
      "z": 17,
      "name": "Soil_Grass"
    },
    {
      "x": 1,
      "y": 0,
      "z": 18,
      "name": "Soil_Grass"
    },
    {
      "x": 2,
      "y": 0,
      "z": 1,
      "name": "Soil_Grass"
    },
    {
      "x": 2,
      "y": 5,
      "z": 1,
      "name": "Rock_Stone"
    },
    {
      "x": 2,
      "y": 6,
      "z": 1,
      "name": "Rock_Stone_Brick_Half"
    },
    {
      "x": 2,
      "y": 0,
      "z": 2,
      "name": "Soil_Grass"
    },
    {
      "x": 2,
      "y": 2,
      "z": 2,
      "name": "Plant_Leaves_Beech",
      "support": 15
    },
    {
      "x": 2,
      "y": 4,
      "z": 2,
      "name": "Rock_Stone_Brick_Stairs",
      "rotation": 9
    },
    {
      "x": 2,
      "y": 5,
      "z": 2,
      "name": "Rock_Stone_Brick"
    },
    {
      "x": 2,
      "y": 6,
      "z": 2,
      "name": "Rock_Stone_Brick_Beam"
    },
    {
      "x": 2,
      "y": 0,
      "z": 3,
      "name": "Soil_Grass"
    },
    {
      "x": 2,
      "y": 1,
      "z": 3,
      "name": "Plant_Leaves_Beech",
      "support": 15
    },
    {
      "x": 2,
      "y": 5,
      "z": 3,
      "name": "Rock_Stone_Brick"
    },
    {
      "x": 2,
      "y": 6,
      "z": 3,
      "name": "Rock_Stone_Brick_Half"
    },
    {
      "x": 2,
      "y": 0,
      "z": 4,
      "name": "Soil_Grass"
    },
    {
      "x": 2,
      "y": 1,
      "z": 4,
      "name": "Plant_Leaves_Beech",
      "support": 15
    },
    {
      "x": 2,
      "y": 2,
      "z": 4,
      "name": "Plant_Leaves_Beech",
      "support": 15
    },
    {
      "x": 2,
      "y": 4,
      "z": 4,
      "name": "Rock_Stone_Brick_Stairs",
      "rotation": 9
    },
    {
      "x": 2,
      "y": 5,
      "z": 4,
      "name": "Rock_Calcite_Cobble"
    },
    {
      "x": 2,
      "y": 6,
      "z": 4,
      "name": "Rock_Stone_Brick_Beam"
    },
    {
      "x": 2,
      "y": 0,
      "z": 5,
      "name": "Soil_Grass"
    },
    {
      "x": 2,
      "y": 2,
      "z": 5,
      "name": "Plant_Leaves_Beech",
      "support": 15
    },
    {
      "x": 2,
      "y": 3,
      "z": 5,
      "name": "Plant_Leaves_Beech",
      "support": 15
    },
    {
      "x": 2,
      "y": 5,
      "z": 5,
      "name": "Rock_Stone_Brick"
    },
    {
      "x": 2,
      "y": 6,
      "z": 5,
      "name": "Rock_Stone_Brick_Half"
    },
    {
      "x": 2,
      "y": 0,
      "z": 6,
      "name": "Soil_Grass"
    },
    {
      "x": 2,
      "y": 3,
      "z": 6,
      "name": "Plant_Leaves_Beech",
      "support": 15
    },
    {
      "x": 2,
      "y": 4,
      "z": 6,
      "name": "Rock_Stone_Brick_Stairs",
      "rotation": 9
    },
    {
      "x": 2,
      "y": 5,
      "z": 6,
      "name": "Rock_Stone_Brick"
    },
    {
      "x": 2,
      "y": 6,
      "z": 6,
      "name": "Rock_Stone_Brick_Beam"
    },
    {
      "x": 2,
      "y": 0,
      "z": 7,
      "name": "Soil_Grass"
    },
    {
      "x": 2,
      "y": 1,
      "z": 7,
      "name": "Furniture_Village_Statue",
      "rotation": 3
    },
    {
      "x": 2,
      "y": 2,
      "z": 7,
      "name": "Furniture_Village_Statue",
      "filler": 1024,
      "rotation": 3
    },
    {
      "x": 2,
      "y": 3,
      "z": 7,
      "name": "Furniture_Village_Statue",
      "filler": 2048,
      "rotation": 3
    },
    {
      "x": 2,
      "y": 5,
      "z": 7,
      "name": "Rock_Stone"
    },
    {
      "x": 2,
      "y": 6,
      "z": 7,
      "name": "Rock_Stone_Brick_Half"
    },
    {
      "x": 2,
      "y": 0,
      "z": 8,
      "name": "Soil_Pathway"
    },
    {
      "x": 2,
      "y": 4,
      "z": 8,
      "name": "Rock_Stone_Brick_Stairs",
      "rotation": 9
    },
    {
      "x": 2,
      "y": 5,
      "z": 8,
      "name": "Rock_Stone"
    },
    {
      "x": 2,
      "y": 6,
      "z": 8,
      "name": "Rock_Stone_Brick_Beam"
    },
    {
      "x": 2,
      "y": 0,
      "z": 9,
      "name": "Soil_Pathway"
    },
    {
      "x": 2,
      "y": 4,
      "z": 9,
      "name": "Rock_Stone_Brick_Half",
      "rotation": 8
    },
    {
      "x": 2,
      "y": 5,
      "z": 9,
      "name": "Rock_Stone_Brick"
    },
    {
      "x": 2,
      "y": 6,
      "z": 9,
      "name": "Rock_Stone_Brick_Half"
    },
    {
      "x": 2,
      "y": 0,
      "z": 10,
      "name": "Soil_Mud_Dry"
    },
    {
      "x": 2,
      "y": 4,
      "z": 10,
      "name": "Rock_Stone_Brick_Stairs",
      "rotation": 9
    },
    {
      "x": 2,
      "y": 5,
      "z": 10,
      "name": "Rock_Stone_Brick"
    },
    {
      "x": 2,
      "y": 6,
      "z": 10,
      "name": "Rock_Stone_Brick_Beam"
    },
    {
      "x": 2,
      "y": 0,
      "z": 11,
      "name": "Soil_Grass"
    },
    {
      "x": 2,
      "y": 1,
      "z": 11,
      "name": "Furniture_Village_Statue",
      "rotation": 3
    },
    {
      "x": 2,
      "y": 2,
      "z": 11,
      "name": "Furniture_Village_Statue",
      "filler": 1024,
      "rotation": 3
    },
    {
      "x": 2,
      "y": 3,
      "z": 11,
      "name": "Furniture_Village_Statue",
      "filler": 2048,
      "rotation": 3
    },
    {
      "x": 2,
      "y": 5,
      "z": 11,
      "name": "Rock_Stone"
    },
    {
      "x": 2,
      "y": 6,
      "z": 11,
      "name": "Rock_Stone_Brick_Half"
    },
    {
      "x": 2,
      "y": 0,
      "z": 12,
      "name": "Soil_Grass"
    },
    {
      "x": 2,
      "y": 4,
      "z": 12,
      "name": "Rock_Stone_Brick_Stairs",
      "rotation": 9
    },
    {
      "x": 2,
      "y": 5,
      "z": 12,
      "name": "Rock_Stone_Brick"
    },
    {
      "x": 2,
      "y": 6,
      "z": 12,
      "name": "Rock_Stone_Brick_Beam"
    },
    {
      "x": 2,
      "y": 0,
      "z": 13,
      "name": "Soil_Grass"
    },
    {
      "x": 2,
      "y": 4,
      "z": 13,
      "name": "Plant_Leaves_Beech",
      "support": 15
    },
    {
      "x": 2,
      "y": 5,
      "z": 13,
      "name": "Rock_Stone"
    },
    {
      "x": 2,
      "y": 6,
      "z": 13,
      "name": "Rock_Stone_Brick_Half"
    },
    {
      "x": 2,
      "y": 0,
      "z": 14,
      "name": "Soil_Grass"
    },
    {
      "x": 2,
      "y": 2,
      "z": 14,
      "name": "Plant_Leaves_Beech",
      "support": 15
    },
    {
      "x": 2,
      "y": 3,
      "z": 14,
      "name": "Plant_Leaves_Beech",
      "support": 15
    },
    {
      "x": 2,
      "y": 4,
      "z": 14,
      "name": "Rock_Stone_Brick_Stairs",
      "rotation": 9
    },
    {
      "x": 2,
      "y": 5,
      "z": 14,
      "name": "Rock_Stone"
    },
    {
      "x": 2,
      "y": 6,
      "z": 14,
      "name": "Rock_Stone_Brick_Beam"
    },
    {
      "x": 2,
      "y": 0,
      "z": 15,
      "name": "Soil_Grass"
    },
    {
      "x": 2,
      "y": 1,
      "z": 15,
      "name": "Plant_Leaves_Beech",
      "support": 15
    },
    {
      "x": 2,
      "y": 5,
      "z": 15,
      "name": "Rock_Stone"
    },
    {
      "x": 2,
      "y": 6,
      "z": 15,
      "name": "Rock_Stone_Brick_Half"
    },
    {
      "x": 2,
      "y": 0,
      "z": 16,
      "name": "Soil_Grass"
    },
    {
      "x": 2,
      "y": 4,
      "z": 16,
      "name": "Rock_Stone_Brick_Stairs",
      "rotation": 9
    },
    {
      "x": 2,
      "y": 5,
      "z": 16,
      "name": "Rock_Stone_Brick"
    },
    {
      "x": 2,
      "y": 6,
      "z": 16,
      "name": "Rock_Stone_Brick_Beam"
    },
    {
      "x": 2,
      "y": 0,
      "z": 17,
      "name": "Soil_Grass"
    },
    {
      "x": 2,
      "y": 5,
      "z": 17,
      "name": "Rock_Stone"
    },
    {
      "x": 2,
      "y": 6,
      "z": 17,
      "name": "Rock_Stone_Brick_Half"
    },
    {
      "x": 2,
      "y": 0,
      "z": 18,
      "name": "Soil_Grass"
    },
    {
      "x": 3,
      "y": 0,
      "z": 1,
      "name": "Soil_Grass"
    },
    {
      "x": 3,
      "y": 1,
      "z": 1,
      "name": "Plant_Leaves_Beech",
      "support": 15
    },
    {
      "x": 3,
      "y": 3,
      "z": 1,
      "name": "Plant_Leaves_Beech",
      "support": 15
    },
    {
      "x": 3,
      "y": 4,
      "z": 1,
      "name": "Rock_Stone_Brick_Stairs",
      "rotation": 8
    },
    {
      "x": 3,
      "y": 5,
      "z": 1,
      "name": "Rock_Stone"
    },
    {
      "x": 3,
      "y": 6,
      "z": 1,
      "name": "Rock_Stone_Brick_Beam"
    },
    {
      "x": 3,
      "y": 0,
      "z": 2,
      "name": "Soil_Grass"
    },
    {
      "x": 3,
      "y": 1,
      "z": 2,
      "name": "Rock_Stone_Brick"
    },
    {
      "x": 3,
      "y": 2,
      "z": 2,
      "name": "Rock_Stone_Brick"
    },
    {
      "x": 3,
      "y": 3,
      "z": 2,
      "name": "Rock_Stone_Brick"
    },
    {
      "x": 3,
      "y": 4,
      "z": 2,
      "name": "Rock_Stone"
    },
    {
      "x": 3,
      "y": 0,
      "z": 3,
      "name": "Soil_Grass"
    },
    {
      "x": 3,
      "y": 1,
      "z": 3,
      "name": "Rock_Stone_Brick"
    },
    {
      "x": 3,
      "y": 2,
      "z": 3,
      "name": "Rock_Stone_Brick"
    },
    {
      "x": 3,
      "y": 3,
      "z": 3,
      "name": "Rock_Stone_Brick"
    },
    {
      "x": 3,
      "y": 4,
      "z": 3,
      "name": "Rock_Stone_Brick"
    },
    {
      "x": 3,
      "y": 0,
      "z": 4,
      "name": "Soil_Dirt"
    },
    {
      "x": 3,
      "y": 1,
      "z": 4,
      "name": "Rock_Stone_Brick"
    },
    {
      "x": 3,
      "y": 2,
      "z": 4,
      "name": "Rock_Stone_Brick"
    },
    {
      "x": 3,
      "y": 3,
      "z": 4,
      "name": "Rock_Stone"
    },
    {
      "x": 3,
      "y": 4,
      "z": 4,
      "name": "Rock_Stone"
    },
    {
      "x": 3,
      "y": 0,
      "z": 5,
      "name": "Soil_Grass"
    },
    {
      "x": 3,
      "y": 1,
      "z": 5,
      "name": "Rock_Stone_Brick"
    },
    {
      "x": 3,
      "y": 2,
      "z": 5,
      "name": "Rock_Calcite_Cobble"
    },
    {
      "x": 3,
      "y": 3,
      "z": 5,
      "name": "Rock_Stone_Brick"
    },
    {
      "x": 3,
      "y": 4,
      "z": 5,
      "name": "Rock_Stone_Brick"
    },
    {
      "x": 3,
      "y": 0,
      "z": 6,
      "name": "Soil_Grass"
    },
    {
      "x": 3,
      "y": 1,
      "z": 6,
      "name": "Rock_Stone_Brick"
    },
    {
      "x": 3,
      "y": 2,
      "z": 6,
      "name": "Rock_Stone_Brick"
    },
    {
      "x": 3,
      "y": 3,
      "z": 6,
      "name": "Rock_Stone_Brick"
    },
    {
      "x": 3,
      "y": 4,
      "z": 6,
      "name": "Rock_Stone"
    },
    {
      "x": 3,
      "y": 0,
      "z": 7,
      "name": "Soil_Dirt"
    },
    {
      "x": 3,
      "y": 1,
      "z": 7,
      "name": "Rock_Stone_Brick"
    },
    {
      "x": 3,
      "y": 2,
      "z": 7,
      "name": "Rock_Stone_Brick"
    },
    {
      "x": 3,
      "y": 3,
      "z": 7,
      "name": "Rock_Calcite_Cobble"
    },
    {
      "x": 3,
      "y": 4,
      "z": 7,
      "name": "Rock_Stone"
    },
    {
      "x": 3,
      "y": 0,
      "z": 8,
      "name": "Soil_Mud_Dry"
    },
    {
      "x": 3,
      "y": 3,
      "z": 8,
      "name": "Deco_Iron_Bars",
      "rotation": 1
    },
    {
      "x": 3,
      "y": 4,
      "z": 8,
      "name": "Deco_Iron_Bars",
      "rotation": 1
    },
    {
      "x": 3,
      "y": 5,
      "z": 8,
      "name": "Rock_Stone_Brick_Half"
    },
    {
      "x": 3,
      "y": 0,
      "z": 9,
      "name": "Soil_Pathway"
    },
    {
      "x": 3,
      "y": 3,
      "z": 9,
      "name": "Deco_Iron_Bars",
      "rotation": 1
    },
    {
      "x": 3,
      "y": 4,
      "z": 9,
      "name": "Deco_Iron_Bars",
      "rotation": 1
    },
    {
      "x": 3,
      "y": 5,
      "z": 9,
      "name": "Rock_Stone_Brick_Half"
    },
    {
      "x": 3,
      "y": 0,
      "z": 10,
      "name": "Soil_Pathway"
    },
    {
      "x": 3,
      "y": 3,
      "z": 10,
      "name": "Deco_Iron_Bars",
      "rotation": 1
    },
    {
      "x": 3,
      "y": 4,
      "z": 10,
      "name": "Deco_Iron_Bars",
      "rotation": 1
    },
    {
      "x": 3,
      "y": 5,
      "z": 10,
      "name": "Rock_Stone_Brick_Half"
    },
    {
      "x": 3,
      "y": 0,
      "z": 11,
      "name": "Soil_Dirt"
    },
    {
      "x": 3,
      "y": 1,
      "z": 11,
      "name": "Rock_Stone_Brick"
    },
    {
      "x": 3,
      "y": 2,
      "z": 11,
      "name": "Rock_Stone_Brick"
    },
    {
      "x": 3,
      "y": 3,
      "z": 11,
      "name": "Rock_Stone_Brick"
    },
    {
      "x": 3,
      "y": 4,
      "z": 11,
      "name": "Rock_Stone_Brick"
    },
    {
      "x": 3,
      "y": 0,
      "z": 12,
      "name": "Soil_Grass"
    },
    {
      "x": 3,
      "y": 1,
      "z": 12,
      "name": "Rock_Stone_Brick"
    },
    {
      "x": 3,
      "y": 2,
      "z": 12,
      "name": "Rock_Stone_Brick"
    },
    {
      "x": 3,
      "y": 3,
      "z": 12,
      "name": "Rock_Stone_Brick"
    },
    {
      "x": 3,
      "y": 4,
      "z": 12,
      "name": "Rock_Stone_Brick"
    },
    {
      "x": 3,
      "y": 0,
      "z": 13,
      "name": "Soil_Dirt"
    },
    {
      "x": 3,
      "y": 1,
      "z": 13,
      "name": "Rock_Stone"
    },
    {
      "x": 3,
      "y": 2,
      "z": 13,
      "name": "Rock_Stone_Brick"
    },
    {
      "x": 3,
      "y": 3,
      "z": 13,
      "name": "Rock_Stone_Brick"
    },
    {
      "x": 3,
      "y": 4,
      "z": 13,
      "name": "Rock_Stone_Brick"
    },
    {
      "x": 3,
      "y": 0,
      "z": 14,
      "name": "Soil_Dirt"
    },
    {
      "x": 3,
      "y": 1,
      "z": 14,
      "name": "Rock_Calcite_Cobble"
    },
    {
      "x": 3,
      "y": 2,
      "z": 14,
      "name": "Rock_Stone_Brick"
    },
    {
      "x": 3,
      "y": 3,
      "z": 14,
      "name": "Rock_Stone_Brick"
    },
    {
      "x": 3,
      "y": 4,
      "z": 14,
      "name": "Rock_Stone"
    },
    {
      "x": 3,
      "y": 0,
      "z": 15,
      "name": "Soil_Dirt"
    },
    {
      "x": 3,
      "y": 1,
      "z": 15,
      "name": "Rock_Stone_Brick"
    },
    {
      "x": 3,
      "y": 2,
      "z": 15,
      "name": "Rock_Stone_Brick"
    },
    {
      "x": 3,
      "y": 3,
      "z": 15,
      "name": "Rock_Stone"
    },
    {
      "x": 3,
      "y": 4,
      "z": 15,
      "name": "Rock_Stone_Brick"
    },
    {
      "x": 3,
      "y": 0,
      "z": 16,
      "name": "Soil_Dirt"
    },
    {
      "x": 3,
      "y": 1,
      "z": 16,
      "name": "Rock_Stone_Brick"
    },
    {
      "x": 3,
      "y": 2,
      "z": 16,
      "name": "Rock_Stone"
    },
    {
      "x": 3,
      "y": 3,
      "z": 16,
      "name": "Rock_Stone_Brick"
    },
    {
      "x": 3,
      "y": 4,
      "z": 16,
      "name": "Rock_Stone_Brick"
    },
    {
      "x": 3,
      "y": 0,
      "z": 17,
      "name": "Soil_Grass"
    },
    {
      "x": 3,
      "y": 4,
      "z": 17,
      "name": "Rock_Stone_Brick_Stairs",
      "rotation": 10
    },
    {
      "x": 3,
      "y": 5,
      "z": 17,
      "name": "Rock_Stone"
    },
    {
      "x": 3,
      "y": 6,
      "z": 17,
      "name": "Rock_Stone_Brick_Beam"
    },
    {
      "x": 3,
      "y": 0,
      "z": 18,
      "name": "Soil_Grass"
    },
    {
      "x": 4,
      "y": 0,
      "z": 1,
      "name": "Soil_Grass"
    },
    {
      "x": 4,
      "y": 1,
      "z": 1,
      "name": "Plant_Leaves_Beech",
      "support": 15
    },
    {
      "x": 4,
      "y": 2,
      "z": 1,
      "name": "Plant_Leaves_Beech",
      "support": 15
    },
    {
      "x": 4,
      "y": 5,
      "z": 1,
      "name": "Rock_Calcite_Cobble"
    },
    {
      "x": 4,
      "y": 6,
      "z": 1,
      "name": "Rock_Stone_Brick_Half"
    },
    {
      "x": 4,
      "y": 0,
      "z": 2,
      "name": "Soil_Dirt"
    },
    {
      "x": 4,
      "y": 1,
      "z": 2,
      "name": "Rock_Calcite_Cobble"
    },
    {
      "x": 4,
      "y": 2,
      "z": 2,
      "name": "Rock_Stone"
    },
    {
      "x": 4,
      "y": 3,
      "z": 2,
      "name": "Rock_Stone_Brick"
    },
    {
      "x": 4,
      "y": 4,
      "z": 2,
      "name": "Rock_Stone_Brick"
    },
    {
      "x": 4,
      "y": 0,
      "z": 3,
      "name": "Soil_Dirt"
    },
    {
      "x": 4,
      "y": 1,
      "z": 3,
      "name": "Rock_Stone"
    },
    {
      "x": 4,
      "y": 2,
      "z": 3,
      "name": "Rock_Stone"
    },
    {
      "x": 4,
      "y": 3,
      "z": 3,
      "name": "Rock_Stone_Brick"
    },
    {
      "x": 4,
      "y": 4,
      "z": 3,
      "name": "Rock_Stone_Brick"
    },
    {
      "x": 4,
      "y": 5,
      "z": 3,
      "name": "Rock_Stone_Brick"
    },
    {
      "x": 4,
      "y": 0,
      "z": 4,
      "name": "Soil_Dirt"
    },
    {
      "x": 4,
      "y": 1,
      "z": 4,
      "name": "Rock_Stone_Brick"
    },
    {
      "x": 4,
      "y": 2,
      "z": 4,
      "name": "Rock_Stone_Brick"
    },
    {
      "x": 4,
      "y": 3,
      "z": 4,
      "name": "Rock_Stone_Brick"
    },
    {
      "x": 4,
      "y": 4,
      "z": 4,
      "name": "Rock_Stone"
    },
    {
      "x": 4,
      "y": 5,
      "z": 4,
      "name": "Rock_Stone"
    },
    {
      "x": 4,
      "y": 6,
      "z": 4,
      "name": "Rock_Stone_Brick_Beam"
    },
    {
      "x": 4,
      "y": 0,
      "z": 5,
      "name": "Soil_Dirt"
    },
    {
      "x": 4,
      "y": 1,
      "z": 5,
      "name": "Rock_Stone_Brick"
    },
    {
      "x": 4,
      "y": 2,
      "z": 5,
      "name": "Rock_Stone"
    },
    {
      "x": 4,
      "y": 3,
      "z": 5,
      "name": "Rock_Stone_Brick"
    },
    {
      "x": 4,
      "y": 4,
      "z": 5,
      "name": "Rock_Stone_Brick"
    },
    {
      "x": 4,
      "y": 5,
      "z": 5,
      "name": "Rock_Stone"
    },
    {
      "x": 4,
      "y": 0,
      "z": 6,
      "name": "Soil_Grass"
    },
    {
      "x": 4,
      "y": 1,
      "z": 6,
      "name": "Rock_Stone_Brick"
    },
    {
      "x": 4,
      "y": 2,
      "z": 6,
      "name": "Rock_Stone_Brick"
    },
    {
      "x": 4,
      "y": 3,
      "z": 6,
      "name": "Rock_Stone"
    },
    {
      "x": 4,
      "y": 4,
      "z": 6,
      "name": "Rock_Stone_Brick"
    },
    {
      "x": 4,
      "y": 5,
      "z": 6,
      "name": "Rock_Stone_Brick"
    },
    {
      "x": 4,
      "y": 6,
      "z": 6,
      "name": "Rock_Stone_Brick_Beam"
    },
    {
      "x": 4,
      "y": 0,
      "z": 7,
      "name": "Soil_Dirt"
    },
    {
      "x": 4,
      "y": 1,
      "z": 7,
      "name": "Rock_Stone"
    },
    {
      "x": 4,
      "y": 2,
      "z": 7,
      "name": "Rock_Stone_Brick"
    },
    {
      "x": 4,
      "y": 3,
      "z": 7,
      "name": "Rock_Stone_Brick"
    },
    {
      "x": 4,
      "y": 4,
      "z": 7,
      "name": "Rock_Stone_Brick"
    },
    {
      "x": 4,
      "y": 5,
      "z": 7,
      "name": "Rock_Stone_Brick"
    },
    {
      "x": 4,
      "y": 0,
      "z": 8,
      "name": "Soil_Pathway"
    },
    {
      "x": 4,
      "y": 3,
      "z": 8,
      "name": "Rock_Stone_Brick_Stairs",
      "rotation": 10
    },
    {
      "x": 4,
      "y": 4,
      "z": 8,
      "name": "Rock_Stone_Brick"
    },
    {
      "x": 4,
      "y": 5,
      "z": 8,
      "name": "Rock_Stone_Brick"
    },
    {
      "x": 4,
      "y": 6,
      "z": 8,
      "name": "Rock_Stone_Brick_Beam"
    },
    {
      "x": 4,
      "y": 0,
      "z": 9,
      "name": "Soil_Grass_Deep"
    },
    {
      "x": 4,
      "y": 4,
      "z": 9,
      "name": "Rock_Stone_Brick"
    },
    {
      "x": 4,
      "y": 5,
      "z": 9,
      "name": "Rock_Stone_Brick"
    },
    {
      "x": 4,
      "y": 0,
      "z": 10,
      "name": "Soil_Pathway"
    },
    {
      "x": 4,
      "y": 3,
      "z": 10,
      "name": "Rock_Stone_Brick_Stairs",
      "rotation": 8
    },
    {
      "x": 4,
      "y": 4,
      "z": 10,
      "name": "Rock_Stone_Brick"
    },
    {
      "x": 4,
      "y": 5,
      "z": 10,
      "name": "Rock_Stone_Brick"
    },
    {
      "x": 4,
      "y": 6,
      "z": 10,
      "name": "Rock_Stone_Brick_Beam"
    },
    {
      "x": 4,
      "y": 0,
      "z": 11,
      "name": "Soil_Grass"
    },
    {
      "x": 4,
      "y": 1,
      "z": 11,
      "name": "Rock_Stone"
    },
    {
      "x": 4,
      "y": 2,
      "z": 11,
      "name": "Rock_Stone_Brick"
    },
    {
      "x": 4,
      "y": 3,
      "z": 11,
      "name": "Rock_Stone_Brick"
    },
    {
      "x": 4,
      "y": 4,
      "z": 11,
      "name": "Rock_Stone_Brick"
    },
    {
      "x": 4,
      "y": 5,
      "z": 11,
      "name": "Rock_Stone_Brick"
    },
    {
      "x": 4,
      "y": 0,
      "z": 12,
      "name": "Soil_Dirt"
    },
    {
      "x": 4,
      "y": 1,
      "z": 12,
      "name": "Rock_Stone_Brick"
    },
    {
      "x": 4,
      "y": 2,
      "z": 12,
      "name": "Rock_Stone_Brick"
    },
    {
      "x": 4,
      "y": 3,
      "z": 12,
      "name": "Rock_Stone"
    },
    {
      "x": 4,
      "y": 4,
      "z": 12,
      "name": "Rock_Stone_Brick"
    },
    {
      "x": 4,
      "y": 5,
      "z": 12,
      "name": "Rock_Calcite_Cobble"
    },
    {
      "x": 4,
      "y": 6,
      "z": 12,
      "name": "Rock_Stone_Brick_Beam"
    },
    {
      "x": 4,
      "y": 0,
      "z": 13,
      "name": "Soil_Grass"
    },
    {
      "x": 4,
      "y": 1,
      "z": 13,
      "name": "Rock_Stone_Brick"
    },
    {
      "x": 4,
      "y": 2,
      "z": 13,
      "name": "Rock_Stone_Brick"
    },
    {
      "x": 4,
      "y": 3,
      "z": 13,
      "name": "Rock_Stone_Brick"
    },
    {
      "x": 4,
      "y": 4,
      "z": 13,
      "name": "Rock_Stone_Brick"
    },
    {
      "x": 4,
      "y": 5,
      "z": 13,
      "name": "Rock_Stone"
    },
    {
      "x": 4,
      "y": 0,
      "z": 14,
      "name": "Soil_Grass"
    },
    {
      "x": 4,
      "y": 1,
      "z": 14,
      "name": "Rock_Stone_Brick"
    },
    {
      "x": 4,
      "y": 2,
      "z": 14,
      "name": "Rock_Stone_Brick"
    },
    {
      "x": 4,
      "y": 3,
      "z": 14,
      "name": "Rock_Stone"
    },
    {
      "x": 4,
      "y": 4,
      "z": 14,
      "name": "Rock_Stone"
    },
    {
      "x": 4,
      "y": 5,
      "z": 14,
      "name": "Rock_Stone_Brick"
    },
    {
      "x": 4,
      "y": 6,
      "z": 14,
      "name": "Rock_Stone_Brick_Beam"
    },
    {
      "x": 4,
      "y": 0,
      "z": 15,
      "name": "Soil_Dirt"
    },
    {
      "x": 4,
      "y": 1,
      "z": 15,
      "name": "Rock_Stone_Brick"
    },
    {
      "x": 4,
      "y": 2,
      "z": 15,
      "name": "Rock_Stone"
    },
    {
      "x": 4,
      "y": 3,
      "z": 15,
      "name": "Rock_Stone_Brick"
    },
    {
      "x": 4,
      "y": 4,
      "z": 15,
      "name": "Rock_Stone"
    },
    {
      "x": 4,
      "y": 5,
      "z": 15,
      "name": "Rock_Stone"
    },
    {
      "x": 4,
      "y": 0,
      "z": 16,
      "name": "Soil_Dirt"
    },
    {
      "x": 4,
      "y": 1,
      "z": 16,
      "name": "Rock_Stone_Brick"
    },
    {
      "x": 4,
      "y": 2,
      "z": 16,
      "name": "Rock_Stone_Brick"
    },
    {
      "x": 4,
      "y": 3,
      "z": 16,
      "name": "Rock_Stone"
    },
    {
      "x": 4,
      "y": 4,
      "z": 16,
      "name": "Rock_Stone"
    },
    {
      "x": 4,
      "y": 0,
      "z": 17,
      "name": "Soil_Grass"
    },
    {
      "x": 4,
      "y": 5,
      "z": 17,
      "name": "Rock_Stone_Brick"
    },
    {
      "x": 4,
      "y": 6,
      "z": 17,
      "name": "Rock_Stone_Brick_Half"
    },
    {
      "x": 4,
      "y": 0,
      "z": 18,
      "name": "Soil_Grass"
    },
    {
      "x": 5,
      "y": 0,
      "z": 1,
      "name": "Soil_Grass"
    },
    {
      "x": 5,
      "y": 4,
      "z": 1,
      "name": "Rock_Stone_Brick_Stairs",
      "rotation": 8
    },
    {
      "x": 5,
      "y": 5,
      "z": 1,
      "name": "Rock_Stone_Brick"
    },
    {
      "x": 5,
      "y": 6,
      "z": 1,
      "name": "Rock_Stone_Brick_Beam"
    },
    {
      "x": 5,
      "y": 0,
      "z": 2,
      "name": "Soil_Grass"
    },
    {
      "x": 5,
      "y": 1,
      "z": 2,
      "name": "Rock_Stone_Brick"
    },
    {
      "x": 5,
      "y": 2,
      "z": 2,
      "name": "Rock_Stone_Brick"
    },
    {
      "x": 5,
      "y": 3,
      "z": 2,
      "name": "Rock_Stone_Brick"
    },
    {
      "x": 5,
      "y": 4,
      "z": 2,
      "name": "Rock_Stone_Brick"
    },
    {
      "x": 5,
      "y": 0,
      "z": 3,
      "name": "Soil_Dirt"
    },
    {
      "x": 5,
      "y": 1,
      "z": 3,
      "name": "Furniture_Village_Crate"
    },
    {
      "x": 5,
      "y": 2,
      "z": 3,
      "name": "Furniture_Village_Crate"
    },
    {
      "x": 5,
      "y": 3,
      "z": 3,
      "name": "Furniture_Tavern_Barrel"
    },
    {
      "x": 5,
      "y": 4,
      "z": 3,
      "name": "Rock_Stone_Brick_Stairs",
      "rotation": 10
    },
    {
      "x": 5,
      "y": 5,
      "z": 3,
      "name": "Rock_Stone"
    },
    {
      "x": 5,
      "y": 6,
      "z": 3,
      "name": "Rock_Stone_Brick_Beam"
    },
    {
      "x": 5,
      "y": 0,
      "z": 4,
      "name": "Soil_Dirt"
    },
    {
      "x": 5,
      "y": 1,
      "z": 4,
      "name": "Furniture_Village_Crate"
    },
    {
      "x": 5,
      "y": 2,
      "z": 4,
      "name": "Furniture_Village_Crate"
    },
    {
      "x": 5,
      "y": 0,
      "z": 5,
      "name": "Soil_Grass_Deep"
    },
    {
      "x": 5,
      "y": 1,
      "z": 5,
      "name": "Furniture_Village_Crate"
    },
    {
      "x": 5,
      "y": 0,
      "z": 6,
      "name": "Soil_Grass_Deep"
    },
    {
      "x": 5,
      "y": 0,
      "z": 7,
      "name": "Soil_Pathway"
    },
    {
      "x": 5,
      "y": 1,
      "z": 7,
      "name": "Furniture_Village_Brazier"
    },
    {
      "x": 5,
      "y": 0,
      "z": 8,
      "name": "Soil_Pathway"
    },
    {
      "x": 5,
      "y": 0,
      "z": 9,
      "name": "Soil_Pathway"
    },
    {
      "x": 5,
      "y": 0,
      "z": 10,
      "name": "Soil_Pathway"
    },
    {
      "x": 5,
      "y": 0,
      "z": 11,
      "name": "Soil_Grass_Deep"
    },
    {
      "x": 5,
      "y": 1,
      "z": 11,
      "name": "Furniture_Village_Brazier"
    },
    {
      "x": 5,
      "y": 0,
      "z": 12,
      "name": "Soil_Grass"
    },
    {
      "x": 5,
      "y": 1,
      "z": 12,
      "name": "Bench_Weapon",
      "components": {
        "Components": {
          "PlacedByInteraction": {
            "WhoPlacedUuid": {
              "$binary": "CGDBch1dRNaCa5bbX/Qg3A==",
              "$type": "04"
            }
          },
          "BenchBlock": {
            "TierLevel": 1,
            "UpgradeItems": []
          }
        }
      },
      "rotation": 1
    },
    {
      "x": 5,
      "y": 2,
      "z": 12,
      "name": "Bench_Weapon",
      "filler": 1024,
      "rotation": 1
    },
    {
      "x": 5,
      "y": 0,
      "z": 13,
      "name": "Soil_Grass"
    },
    {
      "x": 5,
      "y": 1,
      "z": 13,
      "name": "Bench_Weapon",
      "filler": 32,
      "rotation": 1
    },
    {
      "x": 5,
      "y": 2,
      "z": 13,
      "name": "Bench_Weapon",
      "filler": 1056,
      "rotation": 1
    },
    {
      "x": 5,
      "y": 0,
      "z": 14,
      "name": "Soil_Grass"
    },
    {
      "x": 5,
      "y": 0,
      "z": 15,
      "name": "Soil_Grass"
    },
    {
      "x": 5,
      "y": 1,
      "z": 15,
      "name": "Furniture_Village_Crate"
    },
    {
      "x": 5,
      "y": 2,
      "z": 15,
      "name": "Furniture_Tavern_Barrel"
    },
    {
      "x": 5,
      "y": 4,
      "z": 15,
      "name": "Rock_Stone_Brick_Stairs",
      "rotation": 8
    },
    {
      "x": 5,
      "y": 5,
      "z": 15,
      "name": "Rock_Stone_Brick"
    },
    {
      "x": 5,
      "y": 6,
      "z": 15,
      "name": "Rock_Stone_Brick_Beam"
    },
    {
      "x": 5,
      "y": 0,
      "z": 16,
      "name": "Soil_Grass"
    },
    {
      "x": 5,
      "y": 1,
      "z": 16,
      "name": "Rock_Stone"
    },
    {
      "x": 5,
      "y": 2,
      "z": 16,
      "name": "Rock_Stone"
    },
    {
      "x": 5,
      "y": 3,
      "z": 16,
      "name": "Rock_Stone_Brick"
    },
    {
      "x": 5,
      "y": 4,
      "z": 16,
      "name": "Rock_Stone_Brick"
    },
    {
      "x": 5,
      "y": 0,
      "z": 17,
      "name": "Soil_Grass"
    },
    {
      "x": 5,
      "y": 4,
      "z": 17,
      "name": "Rock_Stone_Brick_Stairs",
      "rotation": 10
    },
    {
      "x": 5,
      "y": 5,
      "z": 17,
      "name": "Rock_Stone"
    },
    {
      "x": 5,
      "y": 6,
      "z": 17,
      "name": "Rock_Stone_Brick_Beam"
    },
    {
      "x": 5,
      "y": 0,
      "z": 18,
      "name": "Soil_Grass"
    },
    {
      "x": 6,
      "y": 0,
      "z": 1,
      "name": "Soil_Grass"
    },
    {
      "x": 6,
      "y": 1,
      "z": 1,
      "name": "Plant_Leaves_Beech",
      "support": 15
    },
    {
      "x": 6,
      "y": 5,
      "z": 1,
      "name": "Rock_Stone_Brick"
    },
    {
      "x": 6,
      "y": 6,
      "z": 1,
      "name": "Rock_Stone_Brick_Half"
    },
    {
      "x": 6,
      "y": 0,
      "z": 2,
      "name": "Soil_Grass"
    },
    {
      "x": 6,
      "y": 1,
      "z": 2,
      "name": "Rock_Stone_Brick"
    },
    {
      "x": 6,
      "y": 2,
      "z": 2,
      "name": "Rock_Stone_Brick"
    },
    {
      "x": 6,
      "y": 3,
      "z": 2,
      "name": "Rock_Stone_Brick"
    },
    {
      "x": 6,
      "y": 4,
      "z": 2,
      "name": "Rock_Stone_Brick"
    },
    {
      "x": 6,
      "y": 0,
      "z": 3,
      "name": "Soil_Grass"
    },
    {
      "x": 6,
      "y": 1,
      "z": 3,
      "name": "Bench_Trough",
      "filler": 31
    },
    {
      "x": 6,
      "y": 5,
      "z": 3,
      "name": "Rock_Stone_Brick"
    },
    {
      "x": 6,
      "y": 0,
      "z": 4,
      "name": "Soil_Pathway"
    },
    {
      "x": 6,
      "y": 0,
      "z": 5,
      "name": "Soil_Pathway"
    },
    {
      "x": 6,
      "y": 0,
      "z": 6,
      "name": "Soil_Pathway"
    },
    {
      "x": 6,
      "y": 0,
      "z": 7,
      "name": "Soil_Grass_Deep"
    },
    {
      "x": 6,
      "y": 1,
      "z": 7,
      "name": "Rubble_Basalt_Medium",
      "support": 15
    },
    {
      "x": 6,
      "y": 0,
      "z": 8,
      "name": "Soil_Pathway"
    },
    {
      "x": 6,
      "y": 0,
      "z": 9,
      "name": "Soil_Mud_Dry"
    },
    {
      "x": 6,
      "y": 0,
      "z": 10,
      "name": "Soil_Grass_Deep"
    },
    {
      "x": 6,
      "y": 0,
      "z": 11,
      "name": "Soil_Pathway"
    },
    {
      "x": 6,
      "y": 0,
      "z": 12,
      "name": "Soil_Grass_Deep"
    },
    {
      "x": 6,
      "y": 0,
      "z": 13,
      "name": "Soil_Pathway"
    },
    {
      "x": 6,
      "y": 0,
      "z": 14,
      "name": "Soil_Grass"
    },
    {
      "x": 6,
      "y": 0,
      "z": 15,
      "name": "Soil_Grass"
    },
    {
      "x": 6,
      "y": 5,
      "z": 15,
      "name": "Rock_Stone_Brick"
    },
    {
      "x": 6,
      "y": 0,
      "z": 16,
      "name": "Soil_Dirt"
    },
    {
      "x": 6,
      "y": 1,
      "z": 16,
      "name": "Rock_Stone"
    },
    {
      "x": 6,
      "y": 2,
      "z": 16,
      "name": "Rock_Stone"
    },
    {
      "x": 6,
      "y": 3,
      "z": 16,
      "name": "Rock_Stone"
    },
    {
      "x": 6,
      "y": 4,
      "z": 16,
      "name": "Rock_Stone_Brick"
    },
    {
      "x": 6,
      "y": 0,
      "z": 17,
      "name": "Soil_Grass"
    },
    {
      "x": 6,
      "y": 1,
      "z": 17,
      "name": "Plant_Leaves_Beech",
      "support": 15
    },
    {
      "x": 6,
      "y": 5,
      "z": 17,
      "name": "Rock_Stone_Brick"
    },
    {
      "x": 6,
      "y": 6,
      "z": 17,
      "name": "Rock_Stone_Brick_Half"
    },
    {
      "x": 6,
      "y": 0,
      "z": 18,
      "name": "Soil_Grass"
    },
    {
      "x": 7,
      "y": 0,
      "z": 1,
      "name": "Soil_Grass"
    },
    {
      "x": 7,
      "y": 2,
      "z": 1,
      "name": "Plant_Leaves_Beech",
      "support": 15
    },
    {
      "x": 7,
      "y": 3,
      "z": 1,
      "name": "Plant_Leaves_Beech",
      "support": 15
    },
    {
      "x": 7,
      "y": 4,
      "z": 1,
      "name": "Rock_Stone_Brick_Stairs",
      "rotation": 8
    },
    {
      "x": 7,
      "y": 5,
      "z": 1,
      "name": "Rock_Stone_Brick"
    },
    {
      "x": 7,
      "y": 6,
      "z": 1,
      "name": "Rock_Stone_Brick_Beam"
    },
    {
      "x": 7,
      "y": 0,
      "z": 2,
      "name": "Soil_Grass"
    },
    {
      "x": 7,
      "y": 1,
      "z": 2,
      "name": "Rock_Calcite_Cobble"
    },
    {
      "x": 7,
      "y": 2,
      "z": 2,
      "name": "Rock_Stone_Brick"
    },
    {
      "x": 7,
      "y": 3,
      "z": 2,
      "name": "Rock_Stone_Brick"
    },
    {
      "x": 7,
      "y": 4,
      "z": 2,
      "name": "Rock_Stone_Brick"
    },
    {
      "x": 7,
      "y": 0,
      "z": 3,
      "name": "Soil_Grass"
    },
    {
      "x": 7,
      "y": 1,
      "z": 3,
      "name": "Bench_Trough",
      "components": {
        "Components": {
          "PlacedByInteraction": {
            "WhoPlacedUuid": {
              "$binary": "CGDBch1dRNaCa5bbX/Qg3A==",
              "$type": "04"
            }
          },
          "BenchBlock": {
            "TierLevel": 1,
            "UpgradeItems": []
          }
        }
      }
    },
    {
      "x": 7,
      "y": 4,
      "z": 3,
      "name": "Rock_Stone_Brick_Stairs",
      "rotation": 10
    },
    {
      "x": 7,
      "y": 5,
      "z": 3,
      "name": "Rock_Stone"
    },
    {
      "x": 7,
      "y": 6,
      "z": 3,
      "name": "Rock_Stone_Brick_Beam"
    },
    {
      "x": 7,
      "y": 0,
      "z": 4,
      "name": "Soil_Pathway"
    },
    {
      "x": 7,
      "y": 0,
      "z": 5,
      "name": "Soil_Pathway"
    },
    {
      "x": 7,
      "y": 0,
      "z": 6,
      "name": "Soil_Grass_Deep"
    },
    {
      "x": 7,
      "y": 0,
      "z": 7,
      "name": "Soil_Grass_Deep"
    },
    {
      "x": 7,
      "y": 0,
      "z": 8,
      "name": "Soil_Mud_Dry"
    },
    {
      "x": 7,
      "y": 0,
      "z": 9,
      "name": "Soil_Pathway"
    },
    {
      "x": 7,
      "y": 0,
      "z": 10,
      "name": "Soil_Pathway"
    },
    {
      "x": 7,
      "y": 0,
      "z": 11,
      "name": "Soil_Pathway"
    },
    {
      "x": 7,
      "y": 0,
      "z": 12,
      "name": "Soil_Grass_Deep"
    },
    {
      "x": 7,
      "y": 0,
      "z": 13,
      "name": "Soil_Pathway"
    },
    {
      "x": 7,
      "y": 0,
      "z": 14,
      "name": "Soil_Pathway"
    },
    {
      "x": 7,
      "y": 0,
      "z": 15,
      "name": "Soil_Grass"
    },
    {
      "x": 7,
      "y": 4,
      "z": 15,
      "name": "Rock_Stone_Brick_Stairs",
      "rotation": 8
    },
    {
      "x": 7,
      "y": 5,
      "z": 15,
      "name": "Rock_Stone_Brick"
    },
    {
      "x": 7,
      "y": 6,
      "z": 15,
      "name": "Rock_Stone_Brick_Beam"
    },
    {
      "x": 7,
      "y": 0,
      "z": 16,
      "name": "Soil_Grass"
    },
    {
      "x": 7,
      "y": 1,
      "z": 16,
      "name": "Rock_Stone_Brick"
    },
    {
      "x": 7,
      "y": 2,
      "z": 16,
      "name": "Rock_Stone"
    },
    {
      "x": 7,
      "y": 3,
      "z": 16,
      "name": "Rock_Calcite_Cobble"
    },
    {
      "x": 7,
      "y": 4,
      "z": 16,
      "name": "Rock_Calcite_Cobble"
    },
    {
      "x": 7,
      "y": 0,
      "z": 17,
      "name": "Soil_Grass"
    },
    {
      "x": 7,
      "y": 2,
      "z": 17,
      "name": "Plant_Leaves_Beech",
      "support": 15
    },
    {
      "x": 7,
      "y": 4,
      "z": 17,
      "name": "Rock_Stone_Brick_Stairs",
      "rotation": 10
    },
    {
      "x": 7,
      "y": 5,
      "z": 17,
      "name": "Rock_Stone"
    },
    {
      "x": 7,
      "y": 6,
      "z": 17,
      "name": "Rock_Stone_Brick_Beam"
    },
    {
      "x": 7,
      "y": 0,
      "z": 18,
      "name": "Soil_Grass"
    },
    {
      "x": 8,
      "y": 0,
      "z": 1,
      "name": "Soil_Grass"
    },
    {
      "x": 8,
      "y": 4,
      "z": 1,
      "name": "Plant_Leaves_Beech",
      "support": 15
    },
    {
      "x": 8,
      "y": 5,
      "z": 1,
      "name": "Rock_Stone_Brick"
    },
    {
      "x": 8,
      "y": 6,
      "z": 1,
      "name": "Rock_Stone_Brick_Half"
    },
    {
      "x": 8,
      "y": 0,
      "z": 2,
      "name": "Soil_Dirt"
    },
    {
      "x": 8,
      "y": 1,
      "z": 2,
      "name": "Rock_Stone_Brick"
    },
    {
      "x": 8,
      "y": 2,
      "z": 2,
      "name": "Rock_Stone"
    },
    {
      "x": 8,
      "y": 3,
      "z": 2,
      "name": "Rock_Stone"
    },
    {
      "x": 8,
      "y": 4,
      "z": 2,
      "name": "Rock_Stone_Brick"
    },
    {
      "x": 8,
      "y": 0,
      "z": 3,
      "name": "Soil_Grass"
    },
    {
      "x": 8,
      "y": 1,
      "z": 3,
      "name": "Tool_Feedbag"
    },
    {
      "x": 8,
      "y": 5,
      "z": 3,
      "name": "Rock_Stone_Brick"
    },
    {
      "x": 8,
      "y": 0,
      "z": 4,
      "name": "Soil_Grass_Deep"
    },
    {
      "x": 8,
      "y": 0,
      "z": 5,
      "name": "Soil_Pathway"
    },
    {
      "x": 8,
      "y": 0,
      "z": 6,
      "name": "Soil_Grass_Deep"
    },
    {
      "x": 8,
      "y": 0,
      "z": 7,
      "name": "Soil_Grass_Deep"
    },
    {
      "x": 8,
      "y": 0,
      "z": 8,
      "name": "Soil_Pathway"
    },
    {
      "x": 8,
      "y": 0,
      "z": 9,
      "name": "Soil_Mud_Dry"
    },
    {
      "x": 8,
      "y": 0,
      "z": 10,
      "name": "Soil_Pathway"
    },
    {
      "x": 8,
      "y": 0,
      "z": 11,
      "name": "Soil_Grass_Deep"
    },
    {
      "x": 8,
      "y": 1,
      "z": 11,
      "name": "Rubble_Basalt",
      "support": 15
    },
    {
      "x": 8,
      "y": 0,
      "z": 12,
      "name": "Soil_Pathway"
    },
    {
      "x": 8,
      "y": 0,
      "z": 13,
      "name": "Soil_Pathway"
    },
    {
      "x": 8,
      "y": 0,
      "z": 14,
      "name": "Soil_Pathway"
    },
    {
      "x": 8,
      "y": 0,
      "z": 15,
      "name": "Soil_Grass"
    },
    {
      "x": 8,
      "y": 5,
      "z": 15,
      "name": "Rock_Stone_Brick"
    },
    {
      "x": 8,
      "y": 0,
      "z": 16,
      "name": "Soil_Grass"
    },
    {
      "x": 8,
      "y": 1,
      "z": 16,
      "name": "Rock_Stone"
    },
    {
      "x": 8,
      "y": 2,
      "z": 16,
      "name": "Rock_Stone_Brick"
    },
    {
      "x": 8,
      "y": 3,
      "z": 16,
      "name": "Rock_Stone_Brick"
    },
    {
      "x": 8,
      "y": 4,
      "z": 16,
      "name": "Rock_Stone_Brick"
    },
    {
      "x": 8,
      "y": 0,
      "z": 17,
      "name": "Soil_Grass"
    },
    {
      "x": 8,
      "y": 3,
      "z": 17,
      "name": "Plant_Leaves_Beech",
      "support": 15
    },
    {
      "x": 8,
      "y": 4,
      "z": 17,
      "name": "Plant_Leaves_Beech",
      "support": 15
    },
    {
      "x": 8,
      "y": 5,
      "z": 17,
      "name": "Rock_Stone_Brick"
    },
    {
      "x": 8,
      "y": 6,
      "z": 17,
      "name": "Rock_Stone_Brick_Half"
    },
    {
      "x": 8,
      "y": 0,
      "z": 18,
      "name": "Soil_Grass"
    },
    {
      "x": 9,
      "y": 0,
      "z": 1,
      "name": "Soil_Grass"
    },
    {
      "x": 9,
      "y": 4,
      "z": 1,
      "name": "Rock_Stone_Brick_Stairs",
      "rotation": 8
    },
    {
      "x": 9,
      "y": 5,
      "z": 1,
      "name": "Rock_Stone_Brick"
    },
    {
      "x": 9,
      "y": 6,
      "z": 1,
      "name": "Rock_Stone_Brick_Beam"
    },
    {
      "x": 9,
      "y": 0,
      "z": 2,
      "name": "Soil_Grass"
    },
    {
      "x": 9,
      "y": 1,
      "z": 2,
      "name": "Rock_Stone_Brick"
    },
    {
      "x": 9,
      "y": 2,
      "z": 2,
      "name": "Rock_Stone_Brick"
    },
    {
      "x": 9,
      "y": 3,
      "z": 2,
      "name": "Rock_Stone_Brick"
    },
    {
      "x": 9,
      "y": 4,
      "z": 2,
      "name": "Rock_Stone_Brick"
    },
    {
      "x": 9,
      "y": 0,
      "z": 3,
      "name": "Soil_Grass"
    },
    {
      "x": 9,
      "y": 1,
      "z": 3,
      "name": "Bench_Trough",
      "filler": 31
    },
    {
      "x": 9,
      "y": 4,
      "z": 3,
      "name": "Rock_Stone_Brick_Stairs",
      "rotation": 10
    },
    {
      "x": 9,
      "y": 5,
      "z": 3,
      "name": "Rock_Stone_Brick"
    },
    {
      "x": 9,
      "y": 6,
      "z": 3,
      "name": "Rock_Stone_Brick_Beam"
    },
    {
      "x": 9,
      "y": 0,
      "z": 4,
      "name": "Soil_Grass"
    },
    {
      "x": 9,
      "y": 0,
      "z": 5,
      "name": "Soil_Grass"
    },
    {
      "x": 9,
      "y": 0,
      "z": 6,
      "name": "Soil_Pathway"
    },
    {
      "x": 9,
      "y": 0,
      "z": 7,
      "name": "Soil_Grass_Deep"
    },
    {
      "x": 9,
      "y": 0,
      "z": 8,
      "name": "Soil_Pathway"
    },
    {
      "x": 9,
      "y": 0,
      "z": 9,
      "name": "Soil_Pathway"
    },
    {
      "x": 9,
      "y": 0,
      "z": 10,
      "name": "Soil_Pathway"
    },
    {
      "x": 9,
      "y": 0,
      "z": 11,
      "name": "Soil_Pathway"
    },
    {
      "x": 9,
      "y": 0,
      "z": 12,
      "name": "Soil_Pathway"
    },
    {
      "x": 9,
      "y": 0,
      "z": 13,
      "name": "Soil_Grass_Deep"
    },
    {
      "x": 9,
      "y": 0,
      "z": 14,
      "name": "Soil_Pathway"
    },
    {
      "x": 9,
      "y": 0,
      "z": 15,
      "name": "Soil_Grass"
    },
    {
      "x": 9,
      "y": 4,
      "z": 15,
      "name": "Rock_Stone_Brick_Stairs",
      "rotation": 8
    },
    {
      "x": 9,
      "y": 5,
      "z": 15,
      "name": "Rock_Stone_Brick"
    },
    {
      "x": 9,
      "y": 6,
      "z": 15,
      "name": "Rock_Stone_Brick_Beam"
    },
    {
      "x": 9,
      "y": 0,
      "z": 16,
      "name": "Soil_Grass"
    },
    {
      "x": 9,
      "y": 1,
      "z": 16,
      "name": "Rock_Stone_Brick"
    },
    {
      "x": 9,
      "y": 2,
      "z": 16,
      "name": "Rock_Stone"
    },
    {
      "x": 9,
      "y": 3,
      "z": 16,
      "name": "Rock_Calcite_Cobble"
    },
    {
      "x": 9,
      "y": 4,
      "z": 16,
      "name": "Rock_Stone_Brick"
    },
    {
      "x": 9,
      "y": 0,
      "z": 17,
      "name": "Soil_Grass"
    },
    {
      "x": 9,
      "y": 4,
      "z": 17,
      "name": "Rock_Stone_Brick_Stairs",
      "rotation": 10
    },
    {
      "x": 9,
      "y": 5,
      "z": 17,
      "name": "Rock_Stone_Brick"
    },
    {
      "x": 9,
      "y": 6,
      "z": 17,
      "name": "Rock_Stone_Brick_Beam"
    },
    {
      "x": 9,
      "y": 0,
      "z": 18,
      "name": "Soil_Grass"
    },
    {
      "x": 10,
      "y": 0,
      "z": 1,
      "name": "Soil_Grass"
    },
    {
      "x": 10,
      "y": 5,
      "z": 1,
      "name": "Rock_Stone_Brick"
    },
    {
      "x": 10,
      "y": 6,
      "z": 1,
      "name": "Rock_Stone_Brick_Half"
    },
    {
      "x": 10,
      "y": 0,
      "z": 2,
      "name": "Soil_Grass"
    },
    {
      "x": 10,
      "y": 1,
      "z": 2,
      "name": "Rock_Calcite_Cobble"
    },
    {
      "x": 10,
      "y": 2,
      "z": 2,
      "name": "Rock_Stone_Brick"
    },
    {
      "x": 10,
      "y": 3,
      "z": 2,
      "name": "Rock_Stone_Brick"
    },
    {
      "x": 10,
      "y": 4,
      "z": 2,
      "name": "Rock_Calcite_Cobble"
    },
    {
      "x": 10,
      "y": 0,
      "z": 3,
      "name": "Soil_Grass"
    },
    {
      "x": 10,
      "y": 1,
      "z": 3,
      "name": "Bench_Trough",
      "components": {
        "Components": {
          "PlacedByInteraction": {
            "WhoPlacedUuid": {
              "$binary": "CGDBch1dRNaCa5bbX/Qg3A==",
              "$type": "04"
            }
          },
          "BenchBlock": {
            "TierLevel": 1,
            "UpgradeItems": []
          }
        }
      }
    },
    {
      "x": 10,
      "y": 5,
      "z": 3,
      "name": "Rock_Stone_Brick"
    },
    {
      "x": 10,
      "y": 0,
      "z": 4,
      "name": "Soil_Grass"
    },
    {
      "x": 10,
      "y": 0,
      "z": 5,
      "name": "Soil_Pathway"
    },
    {
      "x": 10,
      "y": 0,
      "z": 6,
      "name": "Soil_Pathway"
    },
    {
      "x": 10,
      "y": 6,
      "z": 6,
      "name": "Rock_Basalt_Cobble_Half",
      "rotation": 7
    },
    {
      "x": 10,
      "y": 0,
      "z": 7,
      "name": "Soil_Pathway"
    },
    {
      "x": 10,
      "y": 0,
      "z": 8,
      "name": "Soil_Pathway"
    },
    {
      "x": 10,
      "y": 0,
      "z": 9,
      "name": "Soil_Pathway"
    },
    {
      "x": 10,
      "y": 1,
      "z": 9,
      "name": "Halloween_Wagon"
    },
    {
      "x": 10,
      "y": 2,
      "z": 9,
      "name": "Ingredient_Hay"
    },
    {
      "x": 10,
      "y": 3,
      "z": 9,
      "name": "Deco_Map",
      "rotation": 1
    },
    {
      "x": 10,
      "y": 0,
      "z": 10,
      "name": "Soil_Pathway"
    },
    {
      "x": 10,
      "y": 1,
      "z": 10,
      "name": "Halloween_Wagon",
      "filler": 32
    },
    {
      "x": 10,
      "y": 0,
      "z": 11,
      "name": "Soil_Grass"
    },
    {
      "x": 10,
      "y": 0,
      "z": 12,
      "name": "Soil_Grass"
    },
    {
      "x": 10,
      "y": 0,
      "z": 13,
      "name": "Soil_Pathway"
    },
    {
      "x": 10,
      "y": 1,
      "z": 13,
      "name": "Rubble_Basalt",
      "support": 15
    },
    {
      "x": 10,
      "y": 0,
      "z": 14,
      "name": "Soil_Grass"
    },
    {
      "x": 10,
      "y": 0,
      "z": 15,
      "name": "Soil_Grass"
    },
    {
      "x": 10,
      "y": 5,
      "z": 15,
      "name": "Rock_Stone_Brick"
    },
    {
      "x": 10,
      "y": 0,
      "z": 16,
      "name": "Soil_Dirt"
    },
    {
      "x": 10,
      "y": 1,
      "z": 16,
      "name": "Rock_Calcite_Cobble"
    },
    {
      "x": 10,
      "y": 2,
      "z": 16,
      "name": "Rock_Stone"
    },
    {
      "x": 10,
      "y": 3,
      "z": 16,
      "name": "Rock_Stone_Brick"
    },
    {
      "x": 10,
      "y": 4,
      "z": 16,
      "name": "Rock_Stone_Brick"
    },
    {
      "x": 10,
      "y": 0,
      "z": 17,
      "name": "Soil_Grass"
    },
    {
      "x": 10,
      "y": 5,
      "z": 17,
      "name": "Rock_Stone_Brick"
    },
    {
      "x": 10,
      "y": 6,
      "z": 17,
      "name": "Rock_Stone_Brick_Half"
    },
    {
      "x": 10,
      "y": 0,
      "z": 18,
      "name": "Soil_Grass"
    },
    {
      "x": 11,
      "y": 0,
      "z": 1,
      "name": "Soil_Grass"
    },
    {
      "x": 11,
      "y": 4,
      "z": 1,
      "name": "Rock_Stone_Brick_Stairs",
      "rotation": 8
    },
    {
      "x": 11,
      "y": 5,
      "z": 1,
      "name": "Rock_Stone_Brick"
    },
    {
      "x": 11,
      "y": 6,
      "z": 1,
      "name": "Rock_Stone_Brick_Beam"
    },
    {
      "x": 11,
      "y": 0,
      "z": 2,
      "name": "Soil_Dirt"
    },
    {
      "x": 11,
      "y": 1,
      "z": 2,
      "name": "Rock_Stone_Brick"
    },
    {
      "x": 11,
      "y": 2,
      "z": 2,
      "name": "Rock_Stone_Brick"
    },
    {
      "x": 11,
      "y": 3,
      "z": 2,
      "name": "Rock_Stone_Brick"
    },
    {
      "x": 11,
      "y": 4,
      "z": 2,
      "name": "Rock_Stone_Brick"
    },
    {
      "x": 11,
      "y": 0,
      "z": 3,
      "name": "Soil_Grass"
    },
    {
      "x": 11,
      "y": 4,
      "z": 3,
      "name": "Rock_Stone_Brick_Stairs",
      "rotation": 10
    },
    {
      "x": 11,
      "y": 5,
      "z": 3,
      "name": "Rock_Stone_Brick"
    },
    {
      "x": 11,
      "y": 6,
      "z": 3,
      "name": "Rock_Stone_Brick_Beam"
    },
    {
      "x": 11,
      "y": 0,
      "z": 4,
      "name": "Soil_Grass"
    },
    {
      "x": 11,
      "y": 1,
      "z": 4,
      "name": "Rubble_Basalt",
      "support": 15
    },
    {
      "x": 11,
      "y": 3,
      "z": 4,
      "name": "Rock_Basalt_Cobble_Stairs",
      "rotation": 9
    },
    {
      "x": 11,
      "y": 4,
      "z": 4,
      "name": "Rock_Basalt_Cobble"
    },
    {
      "x": 11,
      "y": 5,
      "z": 4,
      "name": "Rock_Basalt_Cobble_Roof",
      "rotation": 2
    },
    {
      "x": 11,
      "y": 0,
      "z": 5,
      "name": "Soil_Grass_Deep"
    },
    {
      "x": 11,
      "y": 4,
      "z": 5,
      "name": "Rock_Basalt_Cobble_Half",
      "rotation": 4
    },
    {
      "x": 11,
      "y": 5,
      "z": 5,
      "name": "Rock_Basalt_Cobble"
    },
    {
      "x": 11,
      "y": 6,
      "z": 5,
      "name": "Rock_Basalt_Cobble_Roof",
      "rotation": 2
    },
    {
      "x": 11,
      "y": 0,
      "z": 6,
      "name": "Soil_Pathway"
    },
    {
      "x": 11,
      "y": 4,
      "z": 6,
      "name": "Deco_Lantern_Ceiling"
    },
    {
      "x": 11,
      "y": 5,
      "z": 6,
      "name": "Rock_Basalt_Cobble_Beam"
    },
    {
      "x": 11,
      "y": 6,
      "z": 6,
      "name": "Rock_Basalt_Cobble"
    },
    {
      "x": 11,
      "y": 7,
      "z": 6,
      "name": "Rock_Basalt_Cobble_Roof_Flat",
      "rotation": 3
    },
    {
      "x": 11,
      "y": 0,
      "z": 7,
      "name": "Soil_Grass_Deep"
    },
    {
      "x": 11,
      "y": 4,
      "z": 7,
      "name": "Rock_Basalt_Cobble_Half",
      "rotation": 6
    },
    {
      "x": 11,
      "y": 5,
      "z": 7,
      "name": "Rock_Basalt_Cobble"
    },
    {
      "x": 11,
      "y": 6,
      "z": 7,
      "name": "Rock_Basalt_Cobble_Roof"
    },
    {
      "x": 11,
      "y": 0,
      "z": 8,
      "name": "Soil_Mud_Dry"
    },
    {
      "x": 11,
      "y": 3,
      "z": 8,
      "name": "Rock_Basalt_Cobble_Stairs",
      "rotation": 9
    },
    {
      "x": 11,
      "y": 4,
      "z": 8,
      "name": "Rock_Basalt_Cobble"
    },
    {
      "x": 11,
      "y": 5,
      "z": 8,
      "name": "Rock_Basalt_Cobble_Roof"
    },
    {
      "x": 11,
      "y": 0,
      "z": 9,
      "name": "Soil_Grass"
    },
    {
      "x": 11,
      "y": 1,
      "z": 9,
      "name": "Halloween_Wagon",
      "filler": 1
    },
    {
      "x": 11,
      "y": 2,
      "z": 9,
      "name": "Ingredient_Hay"
    },
    {
      "x": 11,
      "y": 4,
      "z": 9,
      "name": "Rock_Basalt_Cobble_Roof_Hollow"
    },
    {
      "x": 11,
      "y": 0,
      "z": 10,
      "name": "Soil_Pathway"
    },
    {
      "x": 11,
      "y": 1,
      "z": 10,
      "name": "Halloween_Wagon",
      "filler": 33
    },
    {
      "x": 11,
      "y": 2,
      "z": 10,
      "name": "Ingredient_Hay"
    },
    {
      "x": 11,
      "y": 0,
      "z": 11,
      "name": "Soil_Grass"
    },
    {
      "x": 11,
      "y": 1,
      "z": 11,
      "name": "Rubble_Stone_Mossy",
      "support": 15
    },
    {
      "x": 11,
      "y": 0,
      "z": 12,
      "name": "Soil_Grass"
    },
    {
      "x": 11,
      "y": 1,
      "z": 12,
      "name": "Furniture_Village_Pot"
    },
    {
      "x": 11,
      "y": 2,
      "z": 12,
      "name": "Plant_Leaves_Beech",
      "support": 15
    },
    {
      "x": 11,
      "y": 3,
      "z": 12,
      "name": "Plant_Leaves_Beech",
      "support": 15
    },
    {
      "x": 11,
      "y": 0,
      "z": 13,
      "name": "Soil_Dirt"
    },
    {
      "x": 11,
      "y": 1,
      "z": 13,
      "name": "Rock_Stone_Brick"
    },
    {
      "x": 11,
      "y": 2,
      "z": 13,
      "name": "Rock_Stone_Brick"
    },
    {
      "x": 11,
      "y": 3,
      "z": 13,
      "name": "Rock_Stone_Brick"
    },
    {
      "x": 11,
      "y": 4,
      "z": 13,
      "name": "Rock_Stone_Brick_Stairs",
      "rotation": 3
    },
    {
      "x": 11,
      "y": 13,
      "z": 13,
      "name": "Wood_Hardwood_Stairs",
      "rotation": 9
    },
    {
      "x": 11,
      "y": 14,
      "z": 13,
      "name": "Wood_Darkwood_Beam"
    },
    {
      "x": 11,
      "y": 15,
      "z": 13,
      "name": "Wood_Darkwood_Beam"
    },
    {
      "x": 11,
      "y": 16,
      "z": 13,
      "name": "Wood_Darkwood_Beam"
    },
    {
      "x": 11,
      "y": 17,
      "z": 13,
      "name": "Wood_Hardwood_Stairs",
      "rotation": 9
    },
    {
      "x": 11,
      "y": 0,
      "z": 14,
      "name": "Soil_Dirt"
    },
    {
      "x": 11,
      "y": 1,
      "z": 14,
      "name": "Rock_Stone_Brick"
    },
    {
      "x": 11,
      "y": 2,
      "z": 14,
      "name": "Rock_Stone_Brick"
    },
    {
      "x": 11,
      "y": 3,
      "z": 14,
      "name": "Rock_Stone_Brick"
    },
    {
      "x": 11,
      "y": 4,
      "z": 14,
      "name": "Rock_Stone"
    },
    {
      "x": 11,
      "y": 5,
      "z": 14,
      "name": "Rock_Stone_Brick"
    },
    {
      "x": 11,
      "y": 6,
      "z": 14,
      "name": "Rock_Stone"
    },
    {
      "x": 11,
      "y": 7,
      "z": 14,
      "name": "Rock_Stone_Brick"
    },
    {
      "x": 11,
      "y": 8,
      "z": 14,
      "name": "Rock_Stone_Brick_Stairs",
      "rotation": 3
    },
    {
      "x": 11,
      "y": 12,
      "z": 14,
      "name": "*Furniture_Crude_Trapdoor_State_Definitions_OpenDoorOut",
      "rotation": 3
    },
    {
      "x": 11,
      "y": 13,
      "z": 14,
      "name": "Wood_Hardwood_Planks_Half",
      "rotation": 8
    },
    {
      "x": 11,
      "y": 14,
      "z": 14,
      "name": "*Furniture_Crude_Trapdoor_State_Definitions_OpenDoorOut",
      "rotation": 3
    },
    {
      "x": 11,
      "y": 17,
      "z": 14,
      "name": "*Furniture_Crude_Trapdoor_State_Definitions_CloseDoorOut",
      "rotation": 3
    },
    {
      "x": 11,
      "y": 18,
      "z": 14,
      "name": "Wood_Hardwood_Planks_Half"
    },
    {
      "x": 11,
      "y": 0,
      "z": 15,
      "name": "Soil_Grass"
    },
    {
      "x": 11,
      "y": 1,
      "z": 15,
      "name": "Rock_Stone"
    },
    {
      "x": 11,
      "y": 2,
      "z": 15,
      "name": "Rock_Stone"
    },
    {
      "x": 11,
      "y": 3,
      "z": 15,
      "name": "Rock_Stone"
    },
    {
      "x": 11,
      "y": 4,
      "z": 15,
      "name": "Rock_Stone"
    },
    {
      "x": 11,
      "y": 5,
      "z": 15,
      "name": "Rock_Stone_Brick"
    },
    {
      "x": 11,
      "y": 6,
      "z": 15,
      "name": "*Rock_Stone_Brick_Wall_State_Definitions_Corner",
      "rotation": 2
    },
    {
      "x": 11,
      "y": 13,
      "z": 15,
      "name": "Wood_Hardwood_Stairs",
      "rotation": 9
    },
    {
      "x": 11,
      "y": 14,
      "z": 15,
      "name": "Wood_Darkwood_Beam"
    },
    {
      "x": 11,
      "y": 15,
      "z": 15,
      "name": "Wood_Darkwood_Beam"
    },
    {
      "x": 11,
      "y": 16,
      "z": 15,
      "name": "Wood_Darkwood_Beam"
    },
    {
      "x": 11,
      "y": 17,
      "z": 15,
      "name": "Wood_Hardwood_Stairs",
      "rotation": 9
    },
    {
      "x": 11,
      "y": 0,
      "z": 16,
      "name": "Soil_Grass"
    },
    {
      "x": 11,
      "y": 1,
      "z": 16,
      "name": "Rock_Stone_Brick"
    },
    {
      "x": 11,
      "y": 2,
      "z": 16,
      "name": "Rock_Stone_Brick"
    },
    {
      "x": 11,
      "y": 3,
      "z": 16,
      "name": "Rock_Stone_Brick"
    },
    {
      "x": 11,
      "y": 4,
      "z": 16,
      "name": "Rock_Stone_Brick"
    },
    {
      "x": 11,
      "y": 28,
      "z": 16,
      "name": "Cloth_Block_Wool_Cyan"
    },
    {
      "x": 11,
      "y": 29,
      "z": 16,
      "name": "Cloth_Block_Wool_White"
    },
    {
      "x": 11,
      "y": 0,
      "z": 17,
      "name": "Soil_Grass"
    },
    {
      "x": 11,
      "y": 4,
      "z": 17,
      "name": "Rock_Stone_Brick_Stairs",
      "rotation": 10
    },
    {
      "x": 11,
      "y": 5,
      "z": 17,
      "name": "Rock_Stone_Brick"
    },
    {
      "x": 11,
      "y": 6,
      "z": 17,
      "name": "Rock_Stone_Brick_Beam"
    },
    {
      "x": 11,
      "y": 0,
      "z": 18,
      "name": "Soil_Grass"
    },
    {
      "x": 12,
      "y": 0,
      "z": 1,
      "name": "Soil_Grass"
    },
    {
      "x": 12,
      "y": 3,
      "z": 1,
      "name": "Plant_Leaves_Beech",
      "support": 15
    },
    {
      "x": 12,
      "y": 5,
      "z": 1,
      "name": "Rock_Stone_Brick"
    },
    {
      "x": 12,
      "y": 6,
      "z": 1,
      "name": "Rock_Stone_Brick_Half"
    },
    {
      "x": 12,
      "y": 0,
      "z": 2,
      "name": "Soil_Dirt"
    },
    {
      "x": 12,
      "y": 1,
      "z": 2,
      "name": "Rock_Stone_Brick"
    },
    {
      "x": 12,
      "y": 2,
      "z": 2,
      "name": "Rock_Stone_Brick"
    },
    {
      "x": 12,
      "y": 3,
      "z": 2,
      "name": "Rock_Stone_Brick"
    },
    {
      "x": 12,
      "y": 4,
      "z": 2,
      "name": "Rock_Stone_Brick"
    },
    {
      "x": 12,
      "y": 0,
      "z": 3,
      "name": "Soil_Grass"
    },
    {
      "x": 12,
      "y": 4,
      "z": 3,
      "name": "Wood_Darkwood_Stairs",
      "rotation": 3
    },
    {
      "x": 12,
      "y": 5,
      "z": 3,
      "name": "Rock_Stone_Brick"
    },
    {
      "x": 12,
      "y": 0,
      "z": 4,
      "name": "Soil_Dirt"
    },
    {
      "x": 12,
      "y": 1,
      "z": 4,
      "name": "Wood_Ash_Trunk",
      "rotation": 2
    },
    {
      "x": 12,
      "y": 2,
      "z": 4,
      "name": "Wood_Ash_Trunk",
      "rotation": 2
    },
    {
      "x": 12,
      "y": 3,
      "z": 4,
      "name": "Wood_Ash_Trunk",
      "rotation": 2
    },
    {
      "x": 12,
      "y": 4,
      "z": 4,
      "name": "Wood_Ash_Trunk",
      "rotation": 2
    },
    {
      "x": 12,
      "y": 5,
      "z": 4,
      "name": "Rock_Basalt_Cobble_Roof",
      "rotation": 2
    },
    {
      "x": 12,
      "y": 0,
      "z": 5,
      "name": "Soil_Pathway"
    },
    {
      "x": 12,
      "y": 1,
      "z": 5,
      "name": "Furniture_Village_Brazier"
    },
    {
      "x": 12,
      "y": 5,
      "z": 5,
      "name": "Rock_Basalt_Cobble"
    },
    {
      "x": 12,
      "y": 6,
      "z": 5,
      "name": "Rock_Basalt_Cobble_Roof",
      "rotation": 2
    },
    {
      "x": 12,
      "y": 0,
      "z": 6,
      "name": "Soil_Pathway"
    },
    {
      "x": 12,
      "y": 5,
      "z": 6,
      "name": "Rock_Basalt_Cobble_Stairs",
      "rotation": 9
    },
    {
      "x": 12,
      "y": 6,
      "z": 6,
      "name": "Rock_Basalt_Cobble"
    },
    {
      "x": 12,
      "y": 7,
      "z": 6,
      "name": "Rock_Basalt_Cobble_Roof_Flat",
      "rotation": 3
    },
    {
      "x": 12,
      "y": 0,
      "z": 7,
      "name": "Soil_Pathway"
    },
    {
      "x": 12,
      "y": 1,
      "z": 7,
      "name": "Furniture_Village_Pot"
    },
    {
      "x": 12,
      "y": 2,
      "z": 7,
      "name": "Plant_Leaves_Beech",
      "support": 15
    },
    {
      "x": 12,
      "y": 3,
      "z": 7,
      "name": "Plant_Leaves_Beech",
      "support": 15
    },
    {
      "x": 12,
      "y": 5,
      "z": 7,
      "name": "Rock_Basalt_Cobble"
    },
    {
      "x": 12,
      "y": 6,
      "z": 7,
      "name": "Rock_Basalt_Cobble_Roof"
    },
    {
      "x": 12,
      "y": 0,
      "z": 8,
      "name": "Soil_Dirt"
    },
    {
      "x": 12,
      "y": 1,
      "z": 8,
      "name": "Wood_Ash_Trunk",
      "rotation": 2
    },
    {
      "x": 12,
      "y": 2,
      "z": 8,
      "name": "Wood_Ash_Trunk",
      "rotation": 2
    },
    {
      "x": 12,
      "y": 3,
      "z": 8,
      "name": "Wood_Ash_Trunk",
      "rotation": 2
    },
    {
      "x": 12,
      "y": 4,
      "z": 8,
      "name": "Wood_Ash_Trunk",
      "rotation": 2
    },
    {
      "x": 12,
      "y": 5,
      "z": 8,
      "name": "Rock_Basalt_Cobble_Roof"
    },
    {
      "x": 12,
      "y": 0,
      "z": 9,
      "name": "Soil_Grass"
    },
    {
      "x": 12,
      "y": 4,
      "z": 9,
      "name": "*Rock_Basalt_Cobble_Roof_Hollow_State_Definitions_Inverted_Corner_Left",
      "rotation": 3
    },
    {
      "x": 12,
      "y": 0,
      "z": 10,
      "name": "Soil_Grass"
    },
    {
      "x": 12,
      "y": 4,
      "z": 10,
      "name": "Rock_Basalt_Cobble_Roof_Hollow",
      "rotation": 3
    },
    {
      "x": 12,
      "y": 0,
      "z": 11,
      "name": "Soil_Grass"
    },
    {
      "x": 12,
      "y": 0,
      "z": 12,
      "name": "Soil_Grass"
    },
    {
      "x": 12,
      "y": 1,
      "z": 12,
      "name": "Rock_Stone_Brick"
    },
    {
      "x": 12,
      "y": 2,
      "z": 12,
      "name": "Rock_Stone_Brick"
    },
    {
      "x": 12,
      "y": 3,
      "z": 12,
      "name": "Rock_Stone_Brick"
    },
    {
      "x": 12,
      "y": 4,
      "z": 12,
      "name": "Rock_Stone_Brick_Stairs",
      "rotation": 2
    },
    {
      "x": 12,
      "y": 7,
      "z": 12,
      "name": "Plant_Leaves_Beech",
      "support": 15
    },
    {
      "x": 12,
      "y": 8,
      "z": 12,
      "name": "Plant_Leaves_Beech",
      "support": 15
    },
    {
      "x": 12,
      "y": 13,
      "z": 12,
      "name": "Wood_Hardwood_Stairs",
      "rotation": 9
    },
    {
      "x": 12,
      "y": 15,
      "z": 12,
      "name": "*Furniture_Crude_Trapdoor_State_Definitions_OpenDoorOut",
      "rotation": 3
    },
    {
      "x": 12,
      "y": 17,
      "z": 12,
      "name": "Wood_Hardwood_Stairs",
      "rotation": 9
    },
    {
      "x": 12,
      "y": 0,
      "z": 13,
      "name": "Soil_Grass"
    },
    {
      "x": 12,
      "y": 1,
      "z": 13,
      "name": "Rock_Stone_Brick"
    },
    {
      "x": 12,
      "y": 2,
      "z": 13,
      "name": "Rock_Stone_Brick"
    },
    {
      "x": 12,
      "y": 3,
      "z": 13,
      "name": "Rock_Stone_Brick"
    },
    {
      "x": 12,
      "y": 4,
      "z": 13,
      "name": "Rock_Stone_Brick"
    },
    {
      "x": 12,
      "y": 5,
      "z": 13,
      "name": "Rock_Stone_Brick"
    },
    {
      "x": 12,
      "y": 6,
      "z": 13,
      "name": "Rock_Stone"
    },
    {
      "x": 12,
      "y": 7,
      "z": 13,
      "name": "Rock_Stone_Brick"
    },
    {
      "x": 12,
      "y": 8,
      "z": 13,
      "name": "Rock_Stone_Brick"
    },
    {
      "x": 12,
      "y": 9,
      "z": 13,
      "name": "Rock_Stone"
    },
    {
      "x": 12,
      "y": 10,
      "z": 13,
      "name": "Rock_Stone_Brick"
    },
    {
      "x": 12,
      "y": 11,
      "z": 13,
      "name": "Rock_Stone_Brick"
    },
    {
      "x": 12,
      "y": 12,
      "z": 13,
      "name": "Rock_Stone_Brick"
    },
    {
      "x": 12,
      "y": 13,
      "z": 13,
      "name": "Rock_Stone_Brick"
    },
    {
      "x": 12,
      "y": 14,
      "z": 13,
      "name": "Soil_Clay_Smooth_White"
    },
    {
      "x": 12,
      "y": 15,
      "z": 13,
      "name": "Rock_Calcite_Cobble"
    },
    {
      "x": 12,
      "y": 16,
      "z": 13,
      "name": "Soil_Clay_Smooth_White"
    },
    {
      "x": 12,
      "y": 17,
      "z": 13,
      "name": "Soil_Clay_Smooth_White"
    },
    {
      "x": 12,
      "y": 18,
      "z": 13,
      "name": "Rock_Aqua_Cobble_Stairs",
      "rotation": 3
    },
    {
      "x": 12,
      "y": 0,
      "z": 14,
      "name": "Soil_Grass"
    },
    {
      "x": 12,
      "y": 1,
      "z": 14,
      "name": "Rock_Stone_Brick"
    },
    {
      "x": 12,
      "y": 2,
      "z": 14,
      "name": "Rock_Stone_Brick"
    },
    {
      "x": 12,
      "y": 3,
      "z": 14,
      "name": "Rock_Stone_Brick"
    },
    {
      "x": 12,
      "y": 4,
      "z": 14,
      "name": "Rock_Stone"
    },
    {
      "x": 12,
      "y": 5,
      "z": 14,
      "name": "Rock_Stone_Brick"
    },
    {
      "x": 12,
      "y": 6,
      "z": 14,
      "name": "Rock_Stone"
    },
    {
      "x": 12,
      "y": 7,
      "z": 14,
      "name": "Rock_Stone"
    },
    {
      "x": 12,
      "y": 8,
      "z": 14,
      "name": "Rock_Stone_Brick"
    },
    {
      "x": 12,
      "y": 9,
      "z": 14,
      "name": "Rock_Stone"
    },
    {
      "x": 12,
      "y": 10,
      "z": 14,
      "name": "Rock_Stone_Brick_Stairs",
      "rotation": 3
    },
    {
      "x": 12,
      "y": 11,
      "z": 14,
      "name": "Rock_Stone_Brick_Stairs",
      "rotation": 9
    },
    {
      "x": 12,
      "y": 12,
      "z": 14,
      "name": "Rock_Stone"
    },
    {
      "x": 12,
      "y": 13,
      "z": 14,
      "name": "Rock_Stone_Brick"
    },
    {
      "x": 12,
      "y": 14,
      "z": 14,
      "name": "Soil_Clay_Smooth_White"
    },
    {
      "x": 12,
      "y": 17,
      "z": 14,
      "name": "Soil_Clay_Smooth_White"
    },
    {
      "x": 12,
      "y": 18,
      "z": 14,
      "name": "Wood_Blackwood_Planks"
    },
    {
      "x": 12,
      "y": 19,
      "z": 14,
      "name": "Rock_Aqua_Brick_Half"
    },
    {
      "x": 12,
      "y": 0,
      "z": 15,
      "name": "Soil_Dirt"
    },
    {
      "x": 12,
      "y": 1,
      "z": 15,
      "name": "Rock_Stone_Brick"
    },
    {
      "x": 12,
      "y": 2,
      "z": 15,
      "name": "Rock_Stone_Brick"
    },
    {
      "x": 12,
      "y": 3,
      "z": 15,
      "name": "Rock_Stone_Brick"
    },
    {
      "x": 12,
      "y": 4,
      "z": 15,
      "name": "Rock_Stone_Brick"
    },
    {
      "x": 12,
      "y": 5,
      "z": 15,
      "name": "Rock_Stone_Brick"
    },
    {
      "x": 12,
      "y": 6,
      "z": 15,
      "name": "Rock_Stone"
    },
    {
      "x": 12,
      "y": 7,
      "z": 15,
      "name": "Rock_Stone_Brick"
    },
    {
      "x": 12,
      "y": 8,
      "z": 15,
      "name": "Rock_Stone_Brick"
    },
    {
      "x": 12,
      "y": 9,
      "z": 15,
      "name": "Rock_Stone"
    },
    {
      "x": 12,
      "y": 10,
      "z": 15,
      "name": "Rock_Stone_Brick"
    },
    {
      "x": 12,
      "y": 11,
      "z": 15,
      "name": "Rock_Stone_Brick"
    },
    {
      "x": 12,
      "y": 12,
      "z": 15,
      "name": "Rock_Stone_Brick"
    },
    {
      "x": 12,
      "y": 13,
      "z": 15,
      "name": "Rock_Stone_Brick"
    },
    {
      "x": 12,
      "y": 14,
      "z": 15,
      "name": "Soil_Clay_Smooth_White"
    },
    {
      "x": 12,
      "y": 15,
      "z": 15,
      "name": "Soil_Clay_Smooth_White"
    },
    {
      "x": 12,
      "y": 16,
      "z": 15,
      "name": "Soil_Clay_Smooth_White"
    },
    {
      "x": 12,
      "y": 17,
      "z": 15,
      "name": "Soil_Clay_Smooth_White"
    },
    {
      "x": 12,
      "y": 18,
      "z": 15,
      "name": "Rock_Aqua_Cobble_Stairs",
      "rotation": 3
    },
    {
      "x": 12,
      "y": 30,
      "z": 15,
      "name": "Cloth_Block_Wool_Cyan"
    },
    {
      "x": 12,
      "y": 0,
      "z": 16,
      "name": "Soil_Dirt"
    },
    {
      "x": 12,
      "y": 1,
      "z": 16,
      "name": "Rock_Stone"
    },
    {
      "x": 12,
      "y": 2,
      "z": 16,
      "name": "Rock_Stone_Brick"
    },
    {
      "x": 12,
      "y": 3,
      "z": 16,
      "name": "Rock_Stone_Brick"
    },
    {
      "x": 12,
      "y": 4,
      "z": 16,
      "name": "Rock_Stone_Brick"
    },
    {
      "x": 12,
      "y": 13,
      "z": 16,
      "name": "Wood_Hardwood_Stairs",
      "rotation": 9
    },
    {
      "x": 12,
      "y": 15,
      "z": 16,
      "name": "*Furniture_Crude_Trapdoor_State_Definitions_OpenDoorOut",
      "rotation": 3
    },
    {
      "x": 12,
      "y": 17,
      "z": 16,
      "name": "Wood_Hardwood_Stairs",
      "rotation": 9
    },
    {
      "x": 12,
      "y": 29,
      "z": 16,
      "name": "Cloth_Block_Wool_Cyan"
    },
    {
      "x": 12,
      "y": 0,
      "z": 17,
      "name": "Soil_Grass"
    },
    {
      "x": 12,
      "y": 1,
      "z": 17,
      "name": "Plant_Leaves_Beech",
      "support": 15
    },
    {
      "x": 12,
      "y": 5,
      "z": 17,
      "name": "Rock_Stone_Brick"
    },
    {
      "x": 12,
      "y": 6,
      "z": 17,
      "name": "Rock_Stone_Brick_Half"
    },
    {
      "x": 12,
      "y": 0,
      "z": 18,
      "name": "Soil_Grass"
    },
    {
      "x": 13,
      "y": 0,
      "z": 1,
      "name": "Soil_Grass"
    },
    {
      "x": 13,
      "y": 1,
      "z": 1,
      "name": "Plant_Leaves_Beech",
      "support": 15
    },
    {
      "x": 13,
      "y": 2,
      "z": 1,
      "name": "Plant_Leaves_Beech",
      "support": 15
    },
    {
      "x": 13,
      "y": 4,
      "z": 1,
      "name": "Rock_Stone_Brick_Stairs",
      "rotation": 8
    },
    {
      "x": 13,
      "y": 5,
      "z": 1,
      "name": "Rock_Stone_Brick"
    },
    {
      "x": 13,
      "y": 6,
      "z": 1,
      "name": "Rock_Stone_Brick_Beam"
    },
    {
      "x": 13,
      "y": 0,
      "z": 2,
      "name": "Soil_Dirt"
    },
    {
      "x": 13,
      "y": 1,
      "z": 2,
      "name": "Rock_Stone_Brick"
    },
    {
      "x": 13,
      "y": 2,
      "z": 2,
      "name": "Rock_Stone_Brick"
    },
    {
      "x": 13,
      "y": 3,
      "z": 2,
      "name": "Rock_Stone_Brick"
    },
    {
      "x": 13,
      "y": 4,
      "z": 2,
      "name": "Rock_Calcite_Cobble"
    },
    {
      "x": 13,
      "y": 0,
      "z": 3,
      "name": "Rock_Stone_Brick"
    },
    {
      "x": 13,
      "y": 1,
      "z": 3,
      "name": "*Wood_Village_Wall_Grey_Full_State_Definitions_Bottom"
    },
    {
      "x": 13,
      "y": 2,
      "z": 3,
      "name": "*Wood_Village_Wall_Grey_Full_State_Definitions_Middle"
    },
    {
      "x": 13,
      "y": 3,
      "z": 3,
      "name": "*Wood_Village_Wall_Grey_Full_State_Definitions_Top"
    },
    {
      "x": 13,
      "y": 4,
      "z": 3,
      "name": "Wood_Banyan_Trunk_Full",
      "rotation": 2
    },
    {
      "x": 13,
      "y": 5,
      "z": 3,
      "name": "Rock_Stone"
    },
    {
      "x": 13,
      "y": 0,
      "z": 4,
      "name": "Rock_Stone_Brick"
    },
    {
      "x": 13,
      "y": 1,
      "z": 4,
      "name": "Wood_Banyan_Trunk_Full",
      "rotation": 2
    },
    {
      "x": 13,
      "y": 2,
      "z": 4,
      "name": "Wood_Banyan_Trunk_Full",
      "rotation": 2
    },
    {
      "x": 13,
      "y": 3,
      "z": 4,
      "name": "Wood_Banyan_Trunk_Full",
      "rotation": 2
    },
    {
      "x": 13,
      "y": 4,
      "z": 4,
      "name": "Wood_Banyan_Trunk_Full",
      "rotation": 2
    },
    {
      "x": 13,
      "y": 5,
      "z": 4,
      "name": "*Rock_Basalt_Cobble_Roof_State_Definitions_Inverted_Corner_Right",
      "rotation": 3
    },
    {
      "x": 13,
      "y": 0,
      "z": 5,
      "name": "Rock_Stone_Brick"
    },
    {
      "x": 13,
      "y": 1,
      "z": 5,
      "name": "*Wood_Village_Wall_Grey_Full_State_Definitions_Bottom"
    },
    {
      "x": 13,
      "y": 2,
      "z": 5,
      "name": "*Wood_Village_Wall_Grey_Full_State_Definitions_Middle"
    },
    {
      "x": 13,
      "y": 3,
      "z": 5,
      "name": "*Wood_Village_Wall_Grey_Full_State_Definitions_Middle"
    },
    {
      "x": 13,
      "y": 4,
      "z": 5,
      "name": "*Wood_Village_Wall_Grey_Full_State_Definitions_Middle"
    },
    {
      "x": 13,
      "y": 5,
      "z": 5,
      "name": "*Wood_Village_Wall_Grey_Full_State_Definitions_Top"
    },
    {
      "x": 13,
      "y": 6,
      "z": 5,
      "name": "Rock_Basalt_Cobble_Roof",
      "rotation": 2
    },
    {
      "x": 13,
      "y": 0,
      "z": 6,
      "name": "Rock_Stone_Brick"
    },
    {
      "x": 13,
      "y": 1,
      "z": 6,
      "name": "*Furniture_Village_Door_State_Definitions_OpenDoorOut",
      "rotation": 3
    },
    {
      "x": 13,
      "y": 2,
      "z": 6,
      "name": "*Furniture_Village_Door_State_Definitions_OpenDoorOut",
      "filler": 1024,
      "rotation": 3
    },
    {
      "x": 13,
      "y": 3,
      "z": 6,
      "name": "Wood_Village_Wall_Grey_Full"
    },
    {
      "x": 13,
      "y": 4,
      "z": 6,
      "name": "Furniture_Tavern_Window",
      "rotation": 1
    },
    {
      "x": 13,
      "y": 5,
      "z": 6,
      "name": "Wood_Village_Wall_Grey_Full"
    },
    {
      "x": 13,
      "y": 7,
      "z": 6,
      "name": "Rock_Basalt_Cobble_Roof_Flat",
      "rotation": 3
    },
    {
      "x": 13,
      "y": 0,
      "z": 7,
      "name": "Rock_Stone_Brick"
    },
    {
      "x": 13,
      "y": 1,
      "z": 7,
      "name": "*Wood_Village_Wall_Grey_Full_State_Definitions_Bottom"
    },
    {
      "x": 13,
      "y": 2,
      "z": 7,
      "name": "*Wood_Village_Wall_Grey_Full_State_Definitions_Middle"
    },
    {
      "x": 13,
      "y": 3,
      "z": 7,
      "name": "*Wood_Village_Wall_Grey_Full_State_Definitions_Middle"
    },
    {
      "x": 13,
      "y": 4,
      "z": 7,
      "name": "*Wood_Village_Wall_Grey_Full_State_Definitions_Middle"
    },
    {
      "x": 13,
      "y": 5,
      "z": 7,
      "name": "*Wood_Village_Wall_Grey_Full_State_Definitions_Top"
    },
    {
      "x": 13,
      "y": 6,
      "z": 7,
      "name": "Rock_Basalt_Cobble_Roof"
    },
    {
      "x": 13,
      "y": 0,
      "z": 8,
      "name": "Rock_Stone_Brick"
    },
    {
      "x": 13,
      "y": 1,
      "z": 8,
      "name": "*Wood_Village_Wall_Grey_Full_State_Definitions_Bottom"
    },
    {
      "x": 13,
      "y": 2,
      "z": 8,
      "name": "*Wood_Village_Wall_Grey_Full_State_Definitions_Middle"
    },
    {
      "x": 13,
      "y": 3,
      "z": 8,
      "name": "*Wood_Village_Wall_Grey_Full_State_Definitions_Middle"
    },
    {
      "x": 13,
      "y": 4,
      "z": 8,
      "name": "*Wood_Village_Wall_Grey_Full_State_Definitions_Top"
    },
    {
      "x": 13,
      "y": 5,
      "z": 8,
      "name": "*Rock_Basalt_Cobble_Roof_State_Definitions_Inverted_Corner_Right"
    },
    {
      "x": 13,
      "y": 0,
      "z": 9,
      "name": "Rock_Stone_Brick"
    },
    {
      "x": 13,
      "y": 1,
      "z": 9,
      "name": "Wood_Village_Wall_Grey_Full"
    },
    {
      "x": 13,
      "y": 2,
      "z": 9,
      "name": "Furniture_Tavern_Window",
      "rotation": 1
    },
    {
      "x": 13,
      "y": 3,
      "z": 9,
      "name": "*Wood_Village_Wall_Grey_Full_State_Definitions_Bottom"
    },
    {
      "x": 13,
      "y": 4,
      "z": 9,
      "name": "*Wood_Village_Wall_Grey_Full_State_Definitions_Top"
    },
    {
      "x": 13,
      "y": 5,
      "z": 9,
      "name": "Rock_Basalt_Cobble_Roof",
      "rotation": 3
    },
    {
      "x": 13,
      "y": 0,
      "z": 10,
      "name": "Rock_Stone_Brick"
    },
    {
      "x": 13,
      "y": 1,
      "z": 10,
      "name": "*Wood_Village_Wall_Grey_Full_State_Definitions_Bottom"
    },
    {
      "x": 13,
      "y": 2,
      "z": 10,
      "name": "*Wood_Village_Wall_Grey_Full_State_Definitions_Middle"
    },
    {
      "x": 13,
      "y": 3,
      "z": 10,
      "name": "*Wood_Village_Wall_Grey_Full_State_Definitions_Middle"
    },
    {
      "x": 13,
      "y": 4,
      "z": 10,
      "name": "*Wood_Village_Wall_Grey_Full_State_Definitions_Top"
    },
    {
      "x": 13,
      "y": 5,
      "z": 10,
      "name": "Rock_Basalt_Cobble_Roof",
      "rotation": 3
    },
    {
      "x": 13,
      "y": 0,
      "z": 11,
      "name": "Rock_Stone_Brick"
    },
    {
      "x": 13,
      "y": 1,
      "z": 11,
      "name": "Rock_Stone_Brick"
    },
    {
      "x": 13,
      "y": 2,
      "z": 11,
      "name": "Rock_Stone_Brick"
    },
    {
      "x": 13,
      "y": 3,
      "z": 11,
      "name": "Rock_Stone_Brick"
    },
    {
      "x": 13,
      "y": 4,
      "z": 11,
      "name": "Rock_Stone_Brick_Stairs",
      "rotation": 3
    },
    {
      "x": 13,
      "y": 5,
      "z": 11,
      "name": "Plant_Leaves_Beech",
      "support": 15
    },
    {
      "x": 13,
      "y": 6,
      "z": 11,
      "name": "Plant_Leaves_Beech",
      "support": 15
    },
    {
      "x": 13,
      "y": 13,
      "z": 11,
      "name": "Wood_Hardwood_Stairs",
      "rotation": 8
    },
    {
      "x": 13,
      "y": 15,
      "z": 11,
      "name": "*Furniture_Crude_Trapdoor_State_Definitions_OpenDoorOut",
      "rotation": 2
    },
    {
      "x": 13,
      "y": 17,
      "z": 11,
      "name": "Wood_Hardwood_Stairs",
      "rotation": 8
    },
    {
      "x": 13,
      "y": 0,
      "z": 12,
      "name": "Rock_Stone_Brick"
    },
    {
      "x": 13,
      "y": 1,
      "z": 12,
      "name": "Rock_Stone"
    },
    {
      "x": 13,
      "y": 2,
      "z": 12,
      "name": "Rock_Stone_Brick"
    },
    {
      "x": 13,
      "y": 3,
      "z": 12,
      "name": "Rock_Stone_Brick"
    },
    {
      "x": 13,
      "y": 4,
      "z": 12,
      "name": "Rock_Stone_Brick"
    },
    {
      "x": 13,
      "y": 5,
      "z": 12,
      "name": "Rock_Calcite_Cobble"
    },
    {
      "x": 13,
      "y": 6,
      "z": 12,
      "name": "Rock_Stone_Brick"
    },
    {
      "x": 13,
      "y": 7,
      "z": 12,
      "name": "Rock_Stone_Brick"
    },
    {
      "x": 13,
      "y": 8,
      "z": 12,
      "name": "Rock_Stone"
    },
    {
      "x": 13,
      "y": 9,
      "z": 12,
      "name": "Rock_Stone_Brick"
    },
    {
      "x": 13,
      "y": 10,
      "z": 12,
      "name": "Rock_Stone_Brick"
    },
    {
      "x": 13,
      "y": 11,
      "z": 12,
      "name": "Rock_Stone_Brick"
    },
    {
      "x": 13,
      "y": 12,
      "z": 12,
      "name": "Rock_Stone"
    },
    {
      "x": 13,
      "y": 13,
      "z": 12,
      "name": "Rock_Stone_Brick"
    },
    {
      "x": 13,
      "y": 14,
      "z": 12,
      "name": "Rock_Calcite_Cobble"
    },
    {
      "x": 13,
      "y": 15,
      "z": 12,
      "name": "Soil_Clay_Smooth_White"
    },
    {
      "x": 13,
      "y": 16,
      "z": 12,
      "name": "Soil_Clay_Smooth_White"
    },
    {
      "x": 13,
      "y": 17,
      "z": 12,
      "name": "Soil_Clay_Smooth_White"
    },
    {
      "x": 13,
      "y": 18,
      "z": 12,
      "name": "Rock_Aqua_Brick"
    },
    {
      "x": 13,
      "y": 19,
      "z": 12,
      "name": "Rock_Aqua_Cobble_Half"
    },
    {
      "x": 13,
      "y": 0,
      "z": 13,
      "name": "Rock_Stone_Brick"
    },
    {
      "x": 13,
      "y": 4,
      "z": 13,
      "name": "Rock_Stone_Brick"
    },
    {
      "x": 13,
      "y": 5,
      "z": 13,
      "name": "Furniture_Village_Crate"
    },
    {
      "x": 13,
      "y": 6,
      "z": 13,
      "name": "Furniture_Village_Crate"
    },
    {
      "x": 13,
      "y": 7,
      "z": 13,
      "name": "Furniture_Tavern_Candle"
    },
    {
      "x": 13,
      "y": 13,
      "z": 13,
      "name": "Wood_Drywood_Planks"
    },
    {
      "x": 13,
      "y": 18,
      "z": 13,
      "name": "Rock_Aqua_Brick"
    },
    {
      "x": 13,
      "y": 19,
      "z": 13,
      "name": "Rock_Aqua_Brick"
    },
    {
      "x": 13,
      "y": 20,
      "z": 13,
      "name": "Rock_Aqua_Cobble_Stairs",
      "rotation": 2
    },
    {
      "x": 13,
      "y": 0,
      "z": 14,
      "name": "Rock_Stone_Brick"
    },
    {
      "x": 13,
      "y": 4,
      "z": 14,
      "name": "Rock_Stone_Brick"
    },
    {
      "x": 13,
      "y": 5,
      "z": 14,
      "name": "Furniture_Village_Crate"
    },
    {
      "x": 13,
      "y": 13,
      "z": 14,
      "name": "Wood_Drywood_Planks"
    },
    {
      "x": 13,
      "y": 19,
      "z": 14,
      "name": "Rock_Aqua_Brick"
    },
    {
      "x": 13,
      "y": 20,
      "z": 14,
      "name": "Rock_Aqua_Brick"
    },
    {
      "x": 13,
      "y": 21,
      "z": 14,
      "name": "Rock_Aqua_Brick"
    },
    {
      "x": 13,
      "y": 22,
      "z": 14,
      "name": "Rock_Slate_Cobble_Wall"
    },
    {
      "x": 13,
      "y": 0,
      "z": 15,
      "name": "Rock_Stone_Brick"
    },
    {
      "x": 13,
      "y": 1,
      "z": 15,
      "name": "Furniture_Village_Crate"
    },
    {
      "x": 13,
      "y": 2,
      "z": 15,
      "name": "Furniture_Village_Crate"
    },
    {
      "x": 13,
      "y": 4,
      "z": 15,
      "name": "Rock_Stone_Brick"
    },
    {
      "x": 13,
      "y": 13,
      "z": 15,
      "name": "Wood_Drywood_Planks"
    },
    {
      "x": 13,
      "y": 18,
      "z": 15,
      "name": "Rock_Shale_Cobble"
    },
    {
      "x": 13,
      "y": 19,
      "z": 15,
      "name": "Rock_Aqua_Brick"
    },
    {
      "x": 13,
      "y": 20,
      "z": 15,
      "name": "Rock_Aqua_Cobble_Stairs"
    },
    {
      "x": 13,
      "y": 29,
      "z": 15,
      "name": "Cloth_Block_Wool_White"
    },
    {
      "x": 13,
      "y": 30,
      "z": 15,
      "name": "Cloth_Block_Wool_Cyan"
    },
    {
      "x": 13,
      "y": 0,
      "z": 16,
      "name": "Rock_Stone_Brick"
    },
    {
      "x": 13,
      "y": 1,
      "z": 16,
      "name": "Rock_Stone_Brick"
    },
    {
      "x": 13,
      "y": 2,
      "z": 16,
      "name": "Rock_Stone_Brick"
    },
    {
      "x": 13,
      "y": 3,
      "z": 16,
      "name": "Rock_Stone_Brick"
    },
    {
      "x": 13,
      "y": 4,
      "z": 16,
      "name": "Rock_Stone_Brick"
    },
    {
      "x": 13,
      "y": 7,
      "z": 16,
      "name": "Rock_Stone_Brick"
    },
    {
      "x": 13,
      "y": 8,
      "z": 16,
      "name": "Rock_Stone"
    },
    {
      "x": 13,
      "y": 9,
      "z": 16,
      "name": "Rock_Stone_Brick"
    },
    {
      "x": 13,
      "y": 10,
      "z": 16,
      "name": "Rock_Stone"
    },
    {
      "x": 13,
      "y": 11,
      "z": 16,
      "name": "Rock_Stone"
    },
    {
      "x": 13,
      "y": 12,
      "z": 16,
      "name": "Rock_Stone_Brick"
    },
    {
      "x": 13,
      "y": 13,
      "z": 16,
      "name": "Rock_Stone_Brick"
    },
    {
      "x": 13,
      "y": 14,
      "z": 16,
      "name": "Rock_Calcite_Cobble"
    },
    {
      "x": 13,
      "y": 15,
      "z": 16,
      "name": "Soil_Clay_Smooth_White"
    },
    {
      "x": 13,
      "y": 16,
      "z": 16,
      "name": "Soil_Clay_Smooth_White"
    },
    {
      "x": 13,
      "y": 17,
      "z": 16,
      "name": "Soil_Clay_Smooth_White"
    },
    {
      "x": 13,
      "y": 18,
      "z": 16,
      "name": "Rock_Aqua_Brick"
    },
    {
      "x": 13,
      "y": 19,
      "z": 16,
      "name": "Rock_Aqua_Cobble_Half"
    },
    {
      "x": 13,
      "y": 0,
      "z": 17,
      "name": "Soil_Grass"
    },
    {
      "x": 13,
      "y": 1,
      "z": 17,
      "name": "Plant_Leaves_Beech",
      "support": 15
    },
    {
      "x": 13,
      "y": 2,
      "z": 17,
      "name": "Plant_Leaves_Beech",
      "support": 15
    },
    {
      "x": 13,
      "y": 4,
      "z": 17,
      "name": "Rock_Stone_Brick_Stairs",
      "rotation": 10
    },
    {
      "x": 13,
      "y": 5,
      "z": 17,
      "name": "Rock_Stone_Brick"
    },
    {
      "x": 13,
      "y": 6,
      "z": 17,
      "name": "Rock_Stone_Brick_Wall",
      "rotation": 2
    },
    {
      "x": 13,
      "y": 13,
      "z": 17,
      "name": "Wood_Hardwood_Stairs",
      "rotation": 10
    },
    {
      "x": 13,
      "y": 15,
      "z": 17,
      "name": "*Furniture_Crude_Trapdoor_State_Definitions_OpenDoorOut"
    },
    {
      "x": 13,
      "y": 17,
      "z": 17,
      "name": "Wood_Hardwood_Stairs",
      "rotation": 10
    },
    {
      "x": 13,
      "y": 0,
      "z": 18,
      "name": "Soil_Grass"
    },
    {
      "x": 14,
      "y": 0,
      "z": 1,
      "name": "Soil_Grass"
    },
    {
      "x": 14,
      "y": 1,
      "z": 1,
      "name": "Plant_Leaves_Beech",
      "support": 15
    },
    {
      "x": 14,
      "y": 5,
      "z": 1,
      "name": "Rock_Stone_Brick"
    },
    {
      "x": 14,
      "y": 6,
      "z": 1,
      "name": "Rock_Stone_Brick_Half"
    },
    {
      "x": 14,
      "y": 0,
      "z": 2,
      "name": "Soil_Dirt"
    },
    {
      "x": 14,
      "y": 1,
      "z": 2,
      "name": "Rock_Stone_Brick"
    },
    {
      "x": 14,
      "y": 2,
      "z": 2,
      "name": "Rock_Stone_Brick"
    },
    {
      "x": 14,
      "y": 3,
      "z": 2,
      "name": "Rock_Stone_Brick"
    },
    {
      "x": 14,
      "y": 4,
      "z": 2,
      "name": "Rock_Stone_Brick"
    },
    {
      "x": 14,
      "y": 0,
      "z": 3,
      "name": "Rock_Stone_Brick"
    },
    {
      "x": 14,
      "y": 1,
      "z": 3,
      "name": "Rock_Stone_Brick"
    },
    {
      "x": 14,
      "y": 2,
      "z": 3,
      "name": "Rock_Stone_Brick"
    },
    {
      "x": 14,
      "y": 3,
      "z": 3,
      "name": "Rock_Stone_Brick"
    },
    {
      "x": 14,
      "y": 4,
      "z": 3,
      "name": "Rock_Stone"
    },
    {
      "x": 14,
      "y": 5,
      "z": 3,
      "name": "Rock_Basalt_Cobble"
    },
    {
      "x": 14,
      "y": 6,
      "z": 3,
      "name": "Rock_Basalt_Cobble_Roof",
      "rotation": 3
    },
    {
      "x": 14,
      "y": 0,
      "z": 4,
      "name": "Rock_Stone_Brick"
    },
    {
      "x": 14,
      "y": 1,
      "z": 4,
      "name": "Furniture_Village_Bookcase"
    },
    {
      "x": 14,
      "y": 2,
      "z": 4,
      "name": "Furniture_Village_Bookcase"
    },
    {
      "x": 14,
      "y": 3,
      "z": 4,
      "name": "Furniture_Village_Bookcase"
    },
    {
      "x": 14,
      "y": 5,
      "z": 4,
      "name": "Wood_Drywood_Planks"
    },
    {
      "x": 14,
      "y": 6,
      "z": 4,
      "name": "Rock_Basalt_Cobble_Roof",
      "rotation": 3
    },
    {
      "x": 14,
      "y": 0,
      "z": 5,
      "name": "Rock_Stone_Brick"
    },
    {
      "x": 14,
      "y": 5,
      "z": 5,
      "name": "Wood_Drywood_Planks"
    },
    {
      "x": 14,
      "y": 6,
      "z": 5,
      "name": "*Rock_Basalt_Cobble_Roof_State_Definitions_Inverted_Corner_Left",
      "rotation": 2
    },
    {
      "x": 14,
      "y": 0,
      "z": 6,
      "name": "Rock_Stone_Brick"
    },
    {
      "x": 14,
      "y": 1,
      "z": 6,
      "name": "*Furniture_Village_Door_State_Definitions_OpenDoorOut",
      "filler": 1,
      "rotation": 3
    },
    {
      "x": 14,
      "y": 2,
      "z": 6,
      "name": "*Furniture_Village_Door_State_Definitions_OpenDoorOut",
      "filler": 1025,
      "rotation": 3
    },
    {
      "x": 14,
      "y": 5,
      "z": 6,
      "name": "Wood_Drywood_Planks"
    },
    {
      "x": 14,
      "y": 6,
      "z": 6,
      "name": "Rock_Basalt_Cobble"
    },
    {
      "x": 14,
      "y": 7,
      "z": 6,
      "name": "Rock_Basalt_Cobble_Roof_Flat",
      "rotation": 3
    },
    {
      "x": 14,
      "y": 0,
      "z": 7,
      "name": "Rock_Stone_Brick"
    },
    {
      "x": 14,
      "y": 1,
      "z": 7,
      "name": "Cloth_Roof_White_Flat"
    },
    {
      "x": 14,
      "y": 2,
      "z": 7,
      "name": "Aetherhaven_Quest_Board",
      "filler": 992,
      "rotation": 2
    },
    {
      "x": 14,
      "y": 3,
      "z": 7,
      "name": "Aetherhaven_Quest_Board",
      "filler": 2016,
      "rotation": 2
    },
    {
      "x": 14,
      "y": 5,
      "z": 7,
      "name": "Wood_Drywood_Planks"
    },
    {
      "x": 14,
      "y": 6,
      "z": 7,
      "name": "*Rock_Basalt_Cobble_Roof_State_Definitions_Inverted_Corner_Right"
    },
    {
      "x": 14,
      "y": 0,
      "z": 8,
      "name": "Rock_Stone_Brick"
    },
    {
      "x": 14,
      "y": 2,
      "z": 8,
      "name": "Aetherhaven_Quest_Board",
      "rotation": 2
    },
    {
      "x": 14,
      "y": 3,
      "z": 8,
      "name": "Aetherhaven_Quest_Board",
      "filler": 1024,
      "rotation": 2
    },
    {
      "x": 14,
      "y": 5,
      "z": 8,
      "name": "Wood_Drywood_Planks"
    },
    {
      "x": 14,
      "y": 6,
      "z": 8,
      "name": "Rock_Basalt_Cobble_Roof",
      "rotation": 3
    },
    {
      "x": 14,
      "y": 0,
      "z": 9,
      "name": "Rock_Stone_Brick"
    },
    {
      "x": 14,
      "y": 2,
      "z": 9,
      "name": "Aetherhaven_Quest_Board",
      "filler": 32,
      "rotation": 2
    },
    {
      "x": 14,
      "y": 3,
      "z": 9,
      "name": "Aetherhaven_Quest_Board",
      "filler": 1056,
      "rotation": 2
    },
    {
      "x": 14,
      "y": 5,
      "z": 9,
      "name": "Wood_Drywood_Planks"
    },
    {
      "x": 14,
      "y": 6,
      "z": 9,
      "name": "Rock_Basalt_Cobble_Roof",
      "rotation": 3
    },
    {
      "x": 14,
      "y": 0,
      "z": 10,
      "name": "Rock_Stone_Brick"
    },
    {
      "x": 14,
      "y": 1,
      "z": 10,
      "name": "Cloth_Roof_White_Flat"
    },
    {
      "x": 14,
      "y": 5,
      "z": 10,
      "name": "Wood_Drywood_Planks"
    },
    {
      "x": 14,
      "y": 6,
      "z": 10,
      "name": "Rock_Basalt_Cobble_Roof",
      "rotation": 3
    },
    {
      "x": 14,
      "y": 13,
      "z": 10,
      "name": "Wood_Hardwood_Stairs",
      "rotation": 8
    },
    {
      "x": 14,
      "y": 14,
      "z": 10,
      "name": "Wood_Darkwood_Beam"
    },
    {
      "x": 14,
      "y": 15,
      "z": 10,
      "name": "Wood_Darkwood_Beam"
    },
    {
      "x": 14,
      "y": 16,
      "z": 10,
      "name": "Wood_Darkwood_Beam"
    },
    {
      "x": 14,
      "y": 17,
      "z": 10,
      "name": "Wood_Hardwood_Stairs",
      "rotation": 8
    },
    {
      "x": 14,
      "y": 0,
      "z": 11,
      "name": "Rock_Stone_Brick"
    },
    {
      "x": 14,
      "y": 1,
      "z": 11,
      "name": "Rock_Stone_Brick"
    },
    {
      "x": 14,
      "y": 2,
      "z": 11,
      "name": "Rock_Stone_Brick"
    },
    {
      "x": 14,
      "y": 3,
      "z": 11,
      "name": "Rock_Stone"
    },
    {
      "x": 14,
      "y": 4,
      "z": 11,
      "name": "Rock_Stone_Brick"
    },
    {
      "x": 14,
      "y": 5,
      "z": 11,
      "name": "Rock_Stone"
    },
    {
      "x": 14,
      "y": 6,
      "z": 11,
      "name": "Rock_Stone_Brick"
    },
    {
      "x": 14,
      "y": 7,
      "z": 11,
      "name": "Rock_Calcite_Cobble"
    },
    {
      "x": 14,
      "y": 8,
      "z": 11,
      "name": "Rock_Stone_Brick"
    },
    {
      "x": 14,
      "y": 9,
      "z": 11,
      "name": "Rock_Stone_Brick"
    },
    {
      "x": 14,
      "y": 10,
      "z": 11,
      "name": "Rock_Stone_Brick"
    },
    {
      "x": 14,
      "y": 11,
      "z": 11,
      "name": "Rock_Stone_Brick"
    },
    {
      "x": 14,
      "y": 12,
      "z": 11,
      "name": "Rock_Stone"
    },
    {
      "x": 14,
      "y": 13,
      "z": 11,
      "name": "Rock_Stone"
    },
    {
      "x": 14,
      "y": 14,
      "z": 11,
      "name": "Soil_Clay_Smooth_White"
    },
    {
      "x": 14,
      "y": 15,
      "z": 11,
      "name": "Soil_Clay_Smooth_White"
    },
    {
      "x": 14,
      "y": 16,
      "z": 11,
      "name": "Rock_Calcite_Cobble"
    },
    {
      "x": 14,
      "y": 17,
      "z": 11,
      "name": "Soil_Clay_Smooth_White"
    },
    {
      "x": 14,
      "y": 18,
      "z": 11,
      "name": "Rock_Aqua_Cobble_Stairs",
      "rotation": 2
    },
    {
      "x": 14,
      "y": 0,
      "z": 12,
      "name": "Rock_Stone_Brick"
    },
    {
      "x": 14,
      "y": 4,
      "z": 12,
      "name": "Rock_Stone_Brick"
    },
    {
      "x": 14,
      "y": 5,
      "z": 12,
      "name": "Furniture_Ancient_Bed",
      "filler": 30,
      "rotation": 3
    },
    {
      "x": 14,
      "y": 6,
      "z": 12,
      "name": "Furniture_Ancient_Bed",
      "filler": 1054,
      "rotation": 3
    },
    {
      "x": 14,
      "y": 13,
      "z": 12,
      "name": "Wood_Drywood_Planks"
    },
    {
      "x": 14,
      "y": 18,
      "z": 12,
      "name": "Rock_Aqua_Brick"
    },
    {
      "x": 14,
      "y": 19,
      "z": 12,
      "name": "Rock_Aqua_Brick"
    },
    {
      "x": 14,
      "y": 20,
      "z": 12,
      "name": "Rock_Aqua_Cobble_Stairs",
      "rotation": 3
    },
    {
      "x": 14,
      "y": 0,
      "z": 13,
      "name": "Rock_Stone_Brick"
    },
    {
      "x": 14,
      "y": 4,
      "z": 13,
      "name": "Rock_Stone_Brick"
    },
    {
      "x": 14,
      "y": 5,
      "z": 13,
      "name": "Furniture_Ancient_Bed",
      "filler": 62,
      "rotation": 3
    },
    {
      "x": 14,
      "y": 6,
      "z": 13,
      "name": "Furniture_Ancient_Bed",
      "filler": 1086,
      "rotation": 3
    },
    {
      "x": 14,
      "y": 13,
      "z": 13,
      "name": "Wood_Drywood_Planks"
    },
    {
      "x": 14,
      "y": 19,
      "z": 13,
      "name": "Rock_Aqua_Brick"
    },
    {
      "x": 14,
      "y": 20,
      "z": 13,
      "name": "Wood_Blackwood_Planks"
    },
    {
      "x": 14,
      "y": 21,
      "z": 13,
      "name": "Rock_Aqua_Brick_Half"
    },
    {
      "x": 14,
      "y": 0,
      "z": 14,
      "name": "Rock_Stone_Brick"
    },
    {
      "x": 14,
      "y": 1,
      "z": 14,
      "name": "Cloth_Roof_White_Flat"
    },
    {
      "x": 14,
      "y": 4,
      "z": 14,
      "name": "Rock_Stone_Brick"
    },
    {
      "x": 14,
      "y": 13,
      "z": 14,
      "name": "Wood_Drywood_Planks"
    },
    {
      "x": 14,
      "y": 21,
      "z": 14,
      "name": "Rock_Aqua_Brick"
    },
    {
      "x": 14,
      "y": 22,
      "z": 14,
      "name": "Rock_Aqua_Brick"
    },
    {
      "x": 14,
      "y": 23,
      "z": 14,
      "name": "Rock_Aqua_Brick"
    },
    {
      "x": 14,
      "y": 24,
      "z": 14,
      "name": "Rock_Slate_Cobble_Wall"
    },
    {
      "x": 14,
      "y": 30,
      "z": 14,
      "name": "Cloth_Block_Wool_White"
    },
    {
      "x": 14,
      "y": 31,
      "z": 14,
      "name": "Cloth_Block_Wool_Cyan"
    },
    {
      "x": 14,
      "y": 0,
      "z": 15,
      "name": "Rock_Stone_Brick"
    },
    {
      "x": 14,
      "y": 1,
      "z": 15,
      "name": "Furniture_Village_Crate"
    },
    {
      "x": 14,
      "y": 2,
      "z": 15,
      "name": "Furniture_Tavern_Barrel"
    },
    {
      "x": 14,
      "y": 4,
      "z": 15,
      "name": "Rock_Stone_Brick"
    },
    {
      "x": 14,
      "y": 13,
      "z": 15,
      "name": "Wood_Drywood_Planks"
    },
    {
      "x": 14,
      "y": 20,
      "z": 15,
      "name": "Wood_Blackwood_Planks"
    },
    {
      "x": 14,
      "y": 21,
      "z": 15,
      "name": "Rock_Aqua_Brick_Half"
    },
    {
      "x": 14,
      "y": 0,
      "z": 16,
      "name": "Rock_Stone_Brick"
    },
    {
      "x": 14,
      "y": 1,
      "z": 16,
      "name": "Furniture_Village_Crate"
    },
    {
      "x": 14,
      "y": 2,
      "z": 16,
      "name": "Furniture_Village_Crate"
    },
    {
      "x": 14,
      "y": 4,
      "z": 16,
      "name": "Rock_Stone_Brick"
    },
    {
      "x": 14,
      "y": 13,
      "z": 16,
      "name": "Wood_Drywood_Planks"
    },
    {
      "x": 14,
      "y": 18,
      "z": 16,
      "name": "Rock_Shale_Cobble"
    },
    {
      "x": 14,
      "y": 19,
      "z": 16,
      "name": "Rock_Aqua_Brick"
    },
    {
      "x": 14,
      "y": 20,
      "z": 16,
      "name": "Rock_Aqua_Cobble_Stairs",
      "rotation": 3
    },
    {
      "x": 14,
      "y": 0,
      "z": 17,
      "name": "Soil_Dirt"
    },
    {
      "x": 14,
      "y": 1,
      "z": 17,
      "name": "Rock_Stone"
    },
    {
      "x": 14,
      "y": 2,
      "z": 17,
      "name": "Rock_Stone"
    },
    {
      "x": 14,
      "y": 3,
      "z": 17,
      "name": "Rock_Calcite_Cobble"
    },
    {
      "x": 14,
      "y": 4,
      "z": 17,
      "name": "Rock_Stone_Brick"
    },
    {
      "x": 14,
      "y": 5,
      "z": 17,
      "name": "Rock_Stone_Brick"
    },
    {
      "x": 14,
      "y": 6,
      "z": 17,
      "name": "Rock_Stone_Brick"
    },
    {
      "x": 14,
      "y": 7,
      "z": 17,
      "name": "Rock_Calcite_Cobble"
    },
    {
      "x": 14,
      "y": 8,
      "z": 17,
      "name": "Rock_Stone_Brick"
    },
    {
      "x": 14,
      "y": 9,
      "z": 17,
      "name": "Rock_Stone_Brick"
    },
    {
      "x": 14,
      "y": 10,
      "z": 17,
      "name": "Rock_Stone_Brick"
    },
    {
      "x": 14,
      "y": 11,
      "z": 17,
      "name": "Rock_Stone_Brick"
    },
    {
      "x": 14,
      "y": 12,
      "z": 17,
      "name": "Rock_Stone_Brick"
    },
    {
      "x": 14,
      "y": 13,
      "z": 17,
      "name": "Rock_Stone_Brick"
    },
    {
      "x": 14,
      "y": 14,
      "z": 17,
      "name": "Soil_Clay_Smooth_White"
    },
    {
      "x": 14,
      "y": 15,
      "z": 17,
      "name": "Soil_Clay_Smooth_White"
    },
    {
      "x": 14,
      "y": 16,
      "z": 17,
      "name": "Soil_Clay_Smooth_White"
    },
    {
      "x": 14,
      "y": 17,
      "z": 17,
      "name": "Rock_Calcite_Cobble"
    },
    {
      "x": 14,
      "y": 18,
      "z": 17,
      "name": "Rock_Aqua_Cobble_Stairs"
    },
    {
      "x": 14,
      "y": 0,
      "z": 18,
      "name": "Soil_Grass"
    },
    {
      "x": 14,
      "y": 13,
      "z": 18,
      "name": "Wood_Hardwood_Stairs",
      "rotation": 10
    },
    {
      "x": 14,
      "y": 14,
      "z": 18,
      "name": "Wood_Darkwood_Beam"
    },
    {
      "x": 14,
      "y": 15,
      "z": 18,
      "name": "Wood_Darkwood_Beam"
    },
    {
      "x": 14,
      "y": 16,
      "z": 18,
      "name": "Wood_Darkwood_Beam"
    },
    {
      "x": 14,
      "y": 17,
      "z": 18,
      "name": "Wood_Hardwood_Stairs",
      "rotation": 10
    },
    {
      "x": 15,
      "y": 0,
      "z": 1,
      "name": "Soil_Grass"
    },
    {
      "x": 15,
      "y": 4,
      "z": 1,
      "name": "Rock_Stone_Brick_Stairs",
      "rotation": 8
    },
    {
      "x": 15,
      "y": 5,
      "z": 1,
      "name": "Rock_Stone_Brick"
    },
    {
      "x": 15,
      "y": 6,
      "z": 1,
      "name": "Rock_Stone_Brick_Beam"
    },
    {
      "x": 15,
      "y": 0,
      "z": 2,
      "name": "Soil_Dirt"
    },
    {
      "x": 15,
      "y": 1,
      "z": 2,
      "name": "Rock_Stone"
    },
    {
      "x": 15,
      "y": 2,
      "z": 2,
      "name": "Rock_Stone_Brick"
    },
    {
      "x": 15,
      "y": 3,
      "z": 2,
      "name": "Rock_Stone_Brick"
    },
    {
      "x": 15,
      "y": 4,
      "z": 2,
      "name": "Rock_Stone"
    },
    {
      "x": 15,
      "y": 0,
      "z": 3,
      "name": "Rock_Stone_Brick"
    },
    {
      "x": 15,
      "y": 1,
      "z": 3,
      "name": "Rock_Stone"
    },
    {
      "x": 15,
      "y": 2,
      "z": 3,
      "name": "Rock_Stone_Brick"
    },
    {
      "x": 15,
      "y": 3,
      "z": 3,
      "name": "Rock_Stone_Brick"
    },
    {
      "x": 15,
      "y": 4,
      "z": 3,
      "name": "Rock_Stone"
    },
    {
