{
  "version": 8,
  "blockIdVersion": 11,
  "anchorX": 0,
  "anchorY": 0,
  "anchorZ": 0,
  "blocks": [
    {
      "x": 1,
      "y": 1,
      "z": -14,
      "name": "Rock_Stone_Cobble"
    },
    {
      "x": 1,
      "y": 5,
      "z": -14,
      "name": "Wood_Softwood_Roof_Hollow",
      "rotation": 3
    },
    {
      "x": 1,
      "y": 1,
      "z": -13,
      "name": "Rock_Stone_Cobble"
    },
    {
      "x": 1,
      "y": 5,
      "z": -13,
      "name": "Wood_Softwood_Roof_Hollow",
      "rotation": 3
    },
    {
      "x": 1,
      "y": 1,
      "z": -12,
      "name": "Rock_Stone_Cobble_Mossy"
    },
    {
      "x": 1,
      "y": 3,
      "z": -12,
      "name": "Plant_Vine_Wall",
      "support": 15,
      "rotation": 3
    },
    {
      "x": 1,
      "y": 4,
      "z": -12,
      "name": "Plant_Vine_Wall",
      "support": 15,
      "rotation": 3
    },
    {
      "x": 1,
      "y": 5,
      "z": -12,
      "name": "Wood_Softwood_Roof_Hollow",
      "rotation": 3
    },
    {
      "x": 1,
      "y": 1,
      "z": -11,
      "name": "Rock_Stone_Cobble"
    },
    {
      "x": 1,
      "y": 5,
      "z": -11,
      "name": "Wood_Softwood_Roof_Hollow",
      "rotation": 3
    },
    {
      "x": 1,
      "y": 1,
      "z": -10,
      "name": "Rock_Stone_Cobble"
    },
    {
      "x": 1,
      "y": 5,
      "z": -10,
      "name": "Wood_Softwood_Roof_Hollow",
      "rotation": 3
    },
    {
      "x": 1,
      "y": 1,
      "z": -9,
      "name": "Rock_Stone_Cobble"
    },
    {
      "x": 1,
      "y": 5,
      "z": -9,
      "name": "Wood_Softwood_Roof_Hollow",
      "rotation": 3
    },
    {
      "x": 1,
      "y": 1,
      "z": -8,
      "name": "Rock_Stone_Cobble"
    },
    {
      "x": 1,
      "y": 3,
      "z": -8,
      "name": "Plant_Vine_Wall",
      "support": 15,
      "rotation": 3
    },
    {
      "x": 1,
      "y": 5,
      "z": -8,
      "name": "Wood_Softwood_Roof_Hollow",
      "rotation": 3
    },
    {
      "x": 1,
      "y": 1,
      "z": -7,
      "name": "Rock_Stone_Cobble"
    },
    {
      "x": 1,
      "y": 5,
      "z": -7,
      "name": "Wood_Softwood_Roof_Hollow",
      "rotation": 3
    },
    {
      "x": 1,
      "y": 1,
      "z": -6,
      "name": "Rock_Stone_Cobble"
    },
    {
      "x": 1,
      "y": 4,
      "z": -6,
      "name": "Cloth_Roof_Orange_Flap",
      "rotation": 3
    },
    {
      "x": 1,
      "y": 5,
      "z": -6,
      "name": "Wood_Softwood_Roof_Hollow",
      "rotation": 3
    },
    {
      "x": 1,
      "y": 1,
      "z": -5,
      "name": "Rock_Stone_Cobble"
    },
    {
      "x": 1,
      "y": 4,
      "z": -5,
      "name": "Cloth_Roof_White_Flap",
      "rotation": 3
    },
    {
      "x": 1,
      "y": 1,
      "z": -4,
      "name": "Rock_Stone_Cobble_Mossy"
    },
    {
      "x": 1,
      "y": 4,
      "z": -4,
      "name": "Cloth_Roof_Orange_Flap",
      "rotation": 3
    },
    {
      "x": 1,
      "y": 1,
      "z": -3,
      "name": "Rock_Stone_Cobble_Mossy"
    },
    {
      "x": 1,
      "y": 4,
      "z": -3,
      "name": "Cloth_Roof_White_Flap",
      "rotation": 3
    },
    {
      "x": 1,
      "y": 1,
      "z": -2,
      "name": "Rock_Stone_Cobble"
    },
    {
      "x": 1,
      "y": 1,
      "z": -1,
      "name": "Rock_Stone_Cobble"
    },
    {
      "x": 2,
      "y": 1,
      "z": -14,
      "name": "Rock_Stone_Cobble"
    },
    {
      "x": 2,
      "y": 4,
      "z": -14,
      "name": "Plant_Vine_Wall",
      "support": 15,
      "rotation": 2
    },
    {
      "x": 2,
      "y": 5,
      "z": -14,
      "name": "Wood_Beech_Branch_Corner",
      "support": 15,
      "rotation": 2
    },
    {
      "x": 2,
      "y": 6,
      "z": -14,
      "name": "Wood_Softwood_Roof",
      "rotation": 3
    },
    {
      "x": 2,
      "y": 1,
      "z": -13,
      "name": "Rock_Stone_Cobble"
    },
    {
      "x": 2,
      "y": 2,
      "z": -13,
      "name": "Wood_Beech_Trunk",
      "support": 15
    },
    {
      "x": 2,
      "y": 3,
      "z": -13,
      "name": "Wood_Beech_Trunk",
      "support": 15
    },
    {
      "x": 2,
      "y": 4,
      "z": -13,
      "name": "Wood_Beech_Trunk",
      "support": 15
    },
    {
      "x": 2,
      "y": 5,
      "z": -13,
      "name": "Wood_Beech_Trunk",
      "support": 15
    },
    {
      "x": 2,
      "y": 6,
      "z": -13,
      "name": "Wood_Softwood_Roof",
      "rotation": 3
    },
    {
      "x": 2,
      "y": 1,
      "z": -12,
      "name": "Rock_Stone_Cobble"
    },
    {
      "x": 2,
      "y": 2,
      "z": -12,
      "name": "Rock_Stone_Brick"
    },
    {
      "x": 2,
      "y": 3,
      "z": -12,
      "name": "*Wood_Village_Wall_Full_State_Definitions_Bottom"
    },
    {
      "x": 2,
      "y": 4,
      "z": -12,
      "name": "*Wood_Village_Wall_Full_State_Definitions_Top"
    },
    {
      "x": 2,
      "y": 5,
      "z": -12,
      "name": "Wood_Beech_Trunk",
      "support": 15,
      "rotation": 4
    },
    {
      "x": 2,
      "y": 6,
      "z": -12,
      "name": "Wood_Softwood_Roof",
      "rotation": 3
    },
    {
      "x": 2,
      "y": 1,
      "z": -11,
      "name": "Rock_Stone_Cobble_Mossy"
    },
    {
      "x": 2,
      "y": 2,
      "z": -11,
      "name": "Rock_Stone_Brick"
    },
    {
      "x": 2,
      "y": 3,
      "z": -11,
      "name": "Furniture_Village_Window",
      "rotation": 1
    },
    {
      "x": 2,
      "y": 4,
      "z": -11,
      "name": "Wood_Village_Wall_Full"
    },
    {
      "x": 2,
      "y": 5,
      "z": -11,
      "name": "Wood_Beech_Trunk",
      "support": 15,
      "rotation": 4
    },
    {
      "x": 2,
      "y": 6,
      "z": -11,
      "name": "Wood_Softwood_Roof",
      "rotation": 3
    },
    {
      "x": 2,
      "y": 1,
      "z": -10,
      "name": "Rock_Stone_Cobble"
    },
    {
      "x": 2,
      "y": 2,
      "z": -10,
      "name": "Rock_Stone_Brick"
    },
    {
      "x": 2,
      "y": 3,
      "z": -10,
      "name": "*Wood_Village_Wall_Full_State_Definitions_Bottom"
    },
    {
      "x": 2,
      "y": 4,
      "z": -10,
      "name": "*Wood_Village_Wall_Full_State_Definitions_Top"
    },
    {
      "x": 2,
      "y": 5,
      "z": -10,
      "name": "Wood_Beech_Trunk",
      "support": 15,
      "rotation": 4
    },
    {
      "x": 2,
      "y": 6,
      "z": -10,
      "name": "Wood_Softwood_Roof",
      "rotation": 3
    },
    {
      "x": 2,
      "y": 1,
      "z": -9,
      "name": "Rock_Stone_Cobble"
    },
    {
      "x": 2,
      "y": 2,
      "z": -9,
      "name": "Rock_Stone_Brick_Mossy"
    },
    {
      "x": 2,
      "y": 3,
      "z": -9,
      "name": "Furniture_Village_Window",
      "rotation": 1
    },
    {
      "x": 2,
      "y": 4,
      "z": -9,
      "name": "Wood_Village_Wall_Full"
    },
    {
      "x": 2,
      "y": 5,
      "z": -9,
      "name": "Wood_Beech_Trunk",
      "support": 15,
      "rotation": 4
    },
    {
      "x": 2,
      "y": 6,
      "z": -9,
      "name": "Wood_Softwood_Roof",
      "rotation": 3
    },
    {
      "x": 2,
      "y": 1,
      "z": -8,
      "name": "Rock_Stone_Cobble"
    },
    {
      "x": 2,
      "y": 2,
      "z": -8,
      "name": "Rock_Stone_Brick"
    },
    {
      "x": 2,
      "y": 3,
      "z": -8,
      "name": "*Wood_Village_Wall_Full_State_Definitions_Bottom"
    },
    {
      "x": 2,
      "y": 4,
      "z": -8,
      "name": "*Wood_Village_Wall_Full_State_Definitions_Top"
    },
    {
      "x": 2,
      "y": 5,
      "z": -8,
      "name": "Wood_Beech_Trunk",
      "support": 15,
      "rotation": 4
    },
    {
      "x": 2,
      "y": 6,
      "z": -8,
      "name": "Wood_Softwood_Roof",
      "rotation": 3
    },
    {
      "x": 2,
      "y": 1,
      "z": -7,
      "name": "Rock_Stone_Cobble_Mossy"
    },
    {
      "x": 2,
      "y": 2,
      "z": -7,
      "name": "Wood_Beech_Trunk",
      "support": 15
    },
    {
      "x": 2,
      "y": 3,
      "z": -7,
      "name": "Wood_Beech_Trunk",
      "support": 15
    },
    {
      "x": 2,
      "y": 4,
      "z": -7,
      "name": "Wood_Beech_Trunk",
      "support": 15
    },
    {
      "x": 2,
      "y": 5,
      "z": -7,
      "name": "Wood_Beech_Trunk",
      "support": 15
    },
    {
      "x": 2,
      "y": 6,
      "z": -7,
      "name": "Wood_Softwood_Roof",
      "rotation": 3
    },
    {
      "x": 2,
      "y": 1,
      "z": -6,
      "name": "Rock_Stone_Brick_Smooth"
    },
    {
      "x": 2,
      "y": 3,
      "z": -6,
      "name": "Wood_Torch_Wall",
      "support": 15
    },
    {
      "x": 2,
      "y": 5,
      "z": -6,
      "name": "Cloth_Roof_Orange",
      "rotation": 3
    },
    {
      "x": 2,
      "y": 6,
      "z": -6,
      "name": "Wood_Softwood_Roof_Hollow",
      "rotation": 3
    },
    {
      "x": 2,
      "y": 1,
      "z": -5,
      "name": "Rock_Stone_Brick_Smooth"
    },
    {
      "x": 2,
      "y": 5,
      "z": -5,
      "name": "Cloth_Roof_White",
      "rotation": 3
    },
    {
      "x": 2,
      "y": 1,
      "z": -4,
      "name": "Rock_Stone_Brick_Smooth"
    },
    {
      "x": 2,
      "y": 5,
      "z": -4,
      "name": "Cloth_Roof_Orange",
      "rotation": 3
    },
    {
      "x": 2,
      "y": 1,
      "z": -3,
      "name": "Rock_Stone_Cobble"
    },
    {
      "x": 2,
      "y": 2,
      "z": -3,
      "name": "Wood_Beech_Trunk",
      "support": 15
    },
    {
      "x": 2,
      "y": 3,
      "z": -3,
      "name": "Wood_Softwood_Beam"
    },
    {
      "x": 2,
      "y": 4,
      "z": -3,
      "name": "Wood_Softwood_Beam"
    },
    {
      "x": 2,
      "y": 5,
      "z": -3,
      "name": "*Cloth_Roof_White_State_Definitions_Corner_Right"
    },
    {
      "x": 2,
      "y": 1,
      "z": -2,
      "name": "Rock_Stone_Cobble"
    },
    {
      "x": 2,
      "y": 2,
      "z": -2,
      "name": "Furniture_Tavern_Planter",
      "support": 15
    },
    {
      "x": 2,
      "y": 3,
      "z": -2,
      "name": "Plant_Flower_Orchid_Red",
      "support": 15
    },
    {
      "x": 2,
      "y": 4,
      "z": -2,
      "name": "Cloth_Roof_White_Flap"
    },
    {
      "x": 2,
      "y": 1,
      "z": -1,
      "name": "Rock_Stone_Cobble_Mossy"
    },
    {
      "x": 3,
      "y": 1,
      "z": -14,
      "name": "Rock_Stone_Cobble"
    },
    {
      "x": 3,
      "y": 6,
      "z": -14,
      "name": "Wood_Softwood_Stairs",
      "rotation": 11
    },
    {
      "x": 3,
      "y": 7,
      "z": -14,
      "name": "Wood_Softwood_Roof_Steep",
      "rotation": 3
    },
    {
      "x": 3,
      "y": 8,
      "z": -14,
      "name": "Wood_Softwood_Roof_Steep",
      "filler": 1024,
      "rotation": 3
    },
    {
      "x": 3,
      "y": 1,
      "z": -13,
      "name": "Rock_Stone_Cobble"
    },
    {
      "x": 3,
      "y": 2,
      "z": -13,
      "name": "Rock_Stone_Brick"
    },
    {
      "x": 3,
      "y": 3,
      "z": -13,
      "name": "*Wood_Village_Wall_Full_State_Definitions_Bottom"
    },
    {
      "x": 3,
      "y": 4,
      "z": -13,
      "name": "*Wood_Village_Wall_Full_State_Definitions_Top"
    },
    {
      "x": 3,
      "y": 5,
      "z": -13,
      "name": "Wood_Beech_Trunk",
      "support": 15,
      "rotation": 5
    },
    {
      "x": 3,
      "y": 6,
      "z": -13,
      "name": "Wood_Village_Wall_Full"
    },
    {
      "x": 3,
      "y": 7,
      "z": -13,
      "name": "Wood_Softwood_Roof_Steep",
      "rotation": 3
    },
    {
      "x": 3,
      "y": 8,
      "z": -13,
      "name": "Wood_Softwood_Roof_Steep",
      "filler": 1024,
      "rotation": 3
    },
    {
      "x": 3,
      "y": 1,
      "z": -12,
      "name": "Wood_Softwood_Planks"
    },
    {
      "x": 3,
      "y": 2,
      "z": -12,
      "name": "Furniture_Village_Crate"
    },
    {
      "x": 3,
      "y": 3,
      "z": -12,
      "name": "Furniture_Village_Crate"
    },
    {
      "x": 3,
      "y": 5,
      "z": -12,
      "name": "Furniture_Village_Platform",
      "support": 15,
      "rotation": 1
    },
    {
      "x": 3,
      "y": 6,
      "z": -12,
      "name": "Wood_Softwood_Stairs",
      "rotation": 11
    },
    {
      "x": 3,
      "y": 7,
      "z": -12,
      "name": "Wood_Softwood_Roof_Steep",
      "rotation": 3
    },
    {
      "x": 3,
      "y": 8,
      "z": -12,
      "name": "Wood_Softwood_Roof_Steep",
      "filler": 1024,
      "rotation": 3
    },
    {
      "x": 3,
      "y": 1,
      "z": -11,
      "name": "Wood_Softwood_Planks"
    },
    {
      "x": 3,
      "y": 2,
      "z": -11,
      "name": "Furniture_Tavern_Barrel",
      "support": 15
    },
    {
      "x": 3,
      "y": 6,
      "z": -11,
      "name": "Wood_Softwood_Stairs",
      "rotation": 11
    },
    {
      "x": 3,
      "y": 7,
      "z": -11,
      "name": "Wood_Softwood_Roof_Steep",
      "rotation": 3
    },
    {
      "x": 3,
      "y": 8,
      "z": -11,
      "name": "Wood_Softwood_Roof_Steep",
      "filler": 1024,
      "rotation": 3
    },
    {
      "x": 3,
      "y": 1,
      "z": -10,
      "name": "Wood_Softwood_Planks"
    },
    {
      "x": 3,
      "y": 2,
      "z": -10,
      "name": "Furniture_Tavern_Chest_Large",
      "components": {
        "Components": {
          "ItemContainerBlock": {
            "ItemContainer": {
              "Capacity": 36,
              "Items": {}
            },
            "Capacity": 36
          }
        }
      },
      "support": 15,
      "rotation": 1
    },
    {
      "x": 3,
      "y": 6,
      "z": -10,
      "name": "Wood_Softwood_Stairs",
      "rotation": 11
    },
    {
      "x": 3,
      "y": 7,
      "z": -10,
      "name": "Wood_Softwood_Roof_Steep",
      "rotation": 3
    },
    {
      "x": 3,
      "y": 8,
      "z": -10,
      "name": "Wood_Softwood_Roof_Steep",
      "filler": 1024,
      "rotation": 3
    },
    {
      "x": 3,
      "y": 1,
      "z": -9,
      "name": "Wood_Softwood_Planks"
    },
    {
      "x": 3,
      "y": 2,
      "z": -9,
      "name": "Furniture_Tavern_Chest_Large",
      "support": 15,
      "filler": 32,
      "rotation": 1
    },
    {
      "x": 3,
      "y": 6,
      "z": -9,
      "name": "Wood_Softwood_Stairs",
      "rotation": 11
    },
    {
      "x": 3,
      "y": 7,
      "z": -9,
      "name": "Wood_Softwood_Roof_Steep",
      "rotation": 3
    },
    {
      "x": 3,
      "y": 8,
      "z": -9,
      "name": "Wood_Softwood_Roof_Steep",
      "filler": 1024,
      "rotation": 3
    },
    {
      "x": 3,
      "y": 1,
      "z": -8,
      "name": "Wood_Softwood_Planks"
    },
    {
      "x": 3,
      "y": 6,
      "z": -8,
      "name": "Wood_Softwood_Stairs",
      "rotation": 11
    },
    {
      "x": 3,
      "y": 7,
      "z": -8,
      "name": "Wood_Softwood_Roof_Steep",
      "rotation": 3
    },
    {
      "x": 3,
      "y": 8,
      "z": -8,
      "name": "Wood_Softwood_Roof_Steep",
      "filler": 1024,
      "rotation": 3
    },
    {
      "x": 3,
      "y": 1,
      "z": -7,
      "name": "Wood_Softwood_Planks"
    },
    {
      "x": 3,
      "y": 2,
      "z": -7,
      "name": "Wood_Softwood_Stairs",
      "rotation": 11
    },
    {
      "x": 3,
      "y": 3,
      "z": -7,
      "name": "Aetherhaven_Shop_Spot",
      "components": {
        "Components": {
          "AetherhavenShopSpotBlock": {
            "SpotId": "e96d1f81-a34f-42c9-acf2-ac24013d18ed",
            "TownId": "d87b9d18-a6de-42a7-9697-90f4c2aa0d9f",
            "PlotId": "00000000-0000-0000-0000-000000000000",
            "PlayerControlled": true,
            "LootTableId": "",
            "Configured": true
          },
          "PlacedByInteraction": {
            "WhoPlacedUuid": {
              "$binary": "v7RyWIT/TYKnXA2XcxdQtw==",
              "$type": "04"
            }
          }
        }
      }
    },
    {
      "x": 3,
      "y": 4,
      "z": -7,
      "name": "Wood_Softwood_Stairs",
      "rotation": 11
    },
    {
      "x": 3,
      "y": 5,
      "z": -7,
      "name": "Wood_Beech_Trunk",
      "support": 15,
      "rotation": 5
    },
    {
      "x": 3,
      "y": 6,
      "z": -7,
      "name": "Wood_Village_Wall_Full"
    },
    {
      "x": 3,
      "y": 7,
      "z": -7,
      "name": "Wood_Softwood_Roof_Steep",
      "rotation": 3
    },
    {
      "x": 3,
      "y": 8,
      "z": -7,
      "name": "Wood_Softwood_Roof_Steep",
      "filler": 1024,
      "rotation": 3
    },
    {
      "x": 3,
      "y": 1,
      "z": -6,
      "name": "Rock_Stone_Brick"
    },
    {
      "x": 3,
      "y": 6,
      "z": -6,
      "name": "Cloth_Roof_White_Flat"
    },
    {
      "x": 3,
      "y": 7,
      "z": -6,
      "name": "Wood_Softwood_Roof_Steep",
      "rotation": 3
    },
    {
      "x": 3,
      "y": 8,
      "z": -6,
      "name": "Wood_Softwood_Roof_Steep",
      "filler": 1024,
      "rotation": 3
    },
    {
      "x": 3,
      "y": 1,
      "z": -5,
      "name": "Rock_Stone_Brick_Mossy"
    },
    {
      "x": 3,
      "y": 6,
      "z": -5,
      "name": "Cloth_Roof_Orange_Flat"
    },
    {
      "x": 3,
      "y": 1,
      "z": -4,
      "name": "Rock_Stone_Brick"
    },
    {
      "x": 3,
      "y": 6,
      "z": -4,
      "name": "Cloth_Roof_White_Flat"
    },
    {
      "x": 3,
      "y": 1,
      "z": -3,
      "name": "Rock_Stone_Brick_Smooth"
    },
    {
      "x": 3,
      "y": 5,
      "z": -3,
      "name": "Cloth_Roof_Orange"
    },
    {
      "x": 3,
      "y": 1,
      "z": -2,
      "name": "Rock_Stone_Cobble_Mossy"
    },
    {
      "x": 3,
      "y": 4,
      "z": -2,
      "name": "Cloth_Roof_Orange_Flap"
    },
    {
      "x": 3,
      "y": 1,
      "z": -1,
      "name": "Rock_Stone_Cobble"
    },
    {
      "x": 4,
      "y": 1,
      "z": -14,
      "name": "Rock_Stone_Cobble_Mossy"
    },
    {
      "x": 4,
      "y": 7,
      "z": -14,
      "name": "Plant_Vine_Wall",
      "support": 15,
      "rotation": 2
    },
    {
      "x": 4,
      "y": 8,
      "z": -14,
      "name": "Wood_Softwood_Stairs",
      "rotation": 11
    },
    {
      "x": 4,
      "y": 9,
      "z": -14,
      "name": "Wood_Softwood_Roof",
      "rotation": 3
    },
    {
      "x": 4,
      "y": 1,
      "z": -13,
      "name": "Rock_Stone_Cobble"
    },
    {
      "x": 4,
      "y": 2,
      "z": -13,
      "name": "Rock_Stone_Brick_Mossy"
    },
    {
      "x": 4,
      "y": 3,
      "z": -13,
      "name": "Furniture_Village_Window"
    },
    {
      "x": 4,
      "y": 4,
      "z": -13,
      "name": "Furniture_Village_Window"
    },
    {
      "x": 4,
      "y": 5,
      "z": -13,
      "name": "Wood_Beech_Trunk",
      "support": 15,
      "rotation": 5
    },
    {
      "x": 4,
      "y": 6,
      "z": -13,
      "name": "*Wood_Village_Wall_Full_State_Definitions_Bottom"
    },
    {
      "x": 4,
      "y": 7,
      "z": -13,
      "name": "*Wood_Village_Wall_Full_State_Definitions_Middle"
    },
    {
      "x": 4,
      "y": 8,
      "z": -13,
      "name": "*Wood_Village_Wall_Full_State_Definitions_Top"
    },
    {
      "x": 4,
      "y": 9,
      "z": -13,
      "name": "Wood_Softwood_Roof",
      "rotation": 3
    },
    {
      "x": 4,
      "y": 1,
      "z": -12,
      "name": "Wood_Softwood_Planks"
    },
    {
      "x": 4,
      "y": 5,
      "z": -12,
      "name": "Furniture_Village_Platform",
      "support": 15,
      "rotation": 1
    },
    {
      "x": 4,
      "y": 6,
      "z": -12,
      "name": "Furniture_Village_Crate"
    },
    {
      "x": 4,
      "y": 8,
      "z": -12,
      "name": "Wood_Softwood_Stairs",
      "rotation": 11
    },
    {
      "x": 4,
      "y": 9,
      "z": -12,
      "name": "Wood_Softwood_Roof",
      "rotation": 3
    },
    {
      "x": 4,
      "y": 1,
      "z": -11,
      "name": "Wood_Softwood_Planks"
    },
    {
      "x": 4,
      "y": 8,
      "z": -11,
      "name": "Wood_Softwood_Stairs",
      "rotation": 11
    },
    {
      "x": 4,
      "y": 9,
      "z": -11,
      "name": "Wood_Softwood_Roof",
      "rotation": 3
    },
    {
      "x": 4,
      "y": 1,
      "z": -10,
      "name": "Wood_Softwood_Planks"
    },
    {
      "x": 4,
      "y": 5,
      "z": -10,
      "name": "Deco_Lantern_Ceiling",
      "support": 15
    },
    {
      "x": 4,
      "y": 6,
      "z": -10,
      "name": "Deco_Rope",
      "support": 15
    },
    {
      "x": 4,
      "y": 7,
      "z": -10,
      "name": "Deco_Rope",
      "support": 15
    },
    {
      "x": 4,
      "y": 8,
      "z": -10,
      "name": "Wood_Softwood_Planks"
    },
    {
      "x": 4,
      "y": 9,
      "z": -10,
      "name": "Wood_Softwood_Roof",
      "rotation": 3
    },
    {
      "x": 4,
      "y": 1,
      "z": -9,
      "name": "Wood_Softwood_Planks"
    },
    {
      "x": 4,
      "y": 8,
      "z": -9,
      "name": "Wood_Softwood_Stairs",
      "rotation": 11
    },
    {
      "x": 4,
      "y": 9,
      "z": -9,
      "name": "Wood_Softwood_Roof",
      "rotation": 3
    },
    {
      "x": 4,
      "y": 1,
      "z": -8,
      "name": "Wood_Softwood_Planks"
    },
    {
      "x": 4,
      "y": 8,
      "z": -8,
      "name": "Wood_Softwood_Stairs",
      "rotation": 11
    },
    {
      "x": 4,
      "y": 9,
      "z": -8,
      "name": "Wood_Softwood_Roof",
      "rotation": 3
    },
    {
      "x": 4,
      "y": 1,
      "z": -7,
      "name": "Wood_Softwood_Planks"
    },
    {
      "x": 4,
      "y": 2,
      "z": -7,
      "name": "Wood_Softwood_Planks_Half",
      "rotation": 8
    },
    {
      "x": 4,
      "y": 3,
      "z": -7,
      "name": "Aetherhaven_Shop_Spot",
      "components": {
        "Components": {
          "AetherhavenShopSpotBlock": {
            "SpotId": "10332bd6-5a2d-4f83-8fb2-242824b7bee2",
            "TownId": "d87b9d18-a6de-42a7-9697-90f4c2aa0d9f",
            "PlotId": "00000000-0000-0000-0000-000000000000",
            "PlayerControlled": true,
            "LootTableId": "",
            "Configured": true
          },
          "PlacedByInteraction": {
            "WhoPlacedUuid": {
              "$binary": "v7RyWIT/TYKnXA2XcxdQtw==",
              "$type": "04"
            }
          }
        }
      }
    },
    {
      "x": 4,
      "y": 5,
      "z": -7,
      "name": "Wood_Beech_Trunk",
      "support": 15,
      "rotation": 5
    },
    {
      "x": 4,
      "y": 6,
      "z": -7,
      "name": "*Wood_Village_Wall_Full_State_Definitions_Bottom"
    },
    {
      "x": 4,
      "y": 7,
      "z": -7,
      "name": "*Wood_Village_Wall_Full_State_Definitions_Middle"
    },
    {
      "x": 4,
      "y": 8,
      "z": -7,
      "name": "*Wood_Village_Wall_Full_State_Definitions_Top"
    },
    {
      "x": 4,
      "y": 9,
      "z": -7,
      "name": "Wood_Softwood_Roof",
      "rotation": 3
    },
    {
      "x": 4,
      "y": 1,
      "z": -6,
      "name": "Rock_Stone_Brick"
    },
    {
      "x": 4,
      "y": 6,
      "z": -6,
      "name": "Cloth_Roof_Orange_Flat"
    },
    {
      "x": 4,
      "y": 8,
      "z": -6,
      "name": "Wood_Softwood_Stairs",
      "rotation": 11
    },
    {
      "x": 4,
      "y": 9,
      "z": -6,
      "name": "Wood_Softwood_Roof",
      "rotation": 3
    },
    {
      "x": 4,
      "y": 1,
      "z": -5,
      "name": "Rock_Stone_Brick"
    },
    {
      "x": 4,
      "y": 6,
      "z": -5,
      "name": "Cloth_Roof_White_Flat"
    },
    {
      "x": 4,
      "y": 1,
      "z": -4,
      "name": "Rock_Stone_Brick"
    },
    {
      "x": 4,
      "y": 6,
      "z": -4,
      "name": "Cloth_Roof_Orange_Flat"
    },
    {
      "x": 4,
      "y": 1,
      "z": -3,
      "name": "Rock_Stone_Brick_Smooth"
    },
    {
      "x": 4,
      "y": 5,
      "z": -3,
      "name": "Cloth_Roof_White"
    },
    {
      "x": 4,
      "y": 1,
      "z": -2,
      "name": "Rock_Stone_Cobble"
    },
    {
      "x": 4,
      "y": 4,
      "z": -2,
      "name": "Cloth_Roof_White_Flap"
    },
    {
      "x": 4,
      "y": 1,
      "z": -1,
      "name": "Rock_Stone_Cobble_Mossy"
    },
    {
      "x": 5,
      "y": 1,
      "z": -14,
      "name": "Rock_Stone_Cobble"
    },
    {
      "x": 5,
      "y": 5,
      "z": -14,
      "name": "Wood_Beech_Branch_Short",
      "support": 15,
      "rotation": 2
    },
    {
      "x": 5,
      "y": 9,
      "z": -14,
      "name": "Wood_Softwood_Stairs",
      "rotation": 11
    },
    {
      "x": 5,
      "y": 10,
      "z": -14,
      "name": "Wood_Softwood_Roof_Flat"
    },
    {
      "x": 5,
      "y": 1,
      "z": -13,
      "name": "Rock_Stone_Cobble"
    },
    {
      "x": 5,
      "y": 2,
      "z": -13,
      "name": "Rock_Stone_Brick"
    },
    {
      "x": 5,
      "y": 3,
      "z": -13,
      "name": "Furniture_Village_Window"
    },
    {
      "x": 5,
      "y": 4,
      "z": -13,
      "name": "Furniture_Village_Window"
    },
    {
      "x": 5,
      "y": 5,
      "z": -13,
      "name": "Wood_Beech_Trunk",
      "support": 15,
      "rotation": 5
    },
    {
      "x": 5,
      "y": 6,
      "z": -13,
      "name": "*Wood_Village_Wall_Full_State_Definitions_Bottom"
    },
    {
      "x": 5,
      "y": 7,
      "z": -13,
      "name": "*Wood_Village_Wall_Full_State_Definitions_Middle"
    },
    {
      "x": 5,
      "y": 8,
      "z": -13,
      "name": "*Wood_Village_Wall_Full_State_Definitions_Middle"
    },
    {
      "x": 5,
      "y": 9,
      "z": -13,
      "name": "*Wood_Village_Wall_Full_State_Definitions_Top"
    },
    {
      "x": 5,
      "y": 10,
      "z": -13,
      "name": "Wood_Softwood_Roof_Flat"
    },
    {
      "x": 5,
      "y": 1,
      "z": -12,
      "name": "Wood_Softwood_Planks"
    },
    {
      "x": 5,
      "y": 2,
      "z": -12,
      "name": "Aetherhaven_Shop_Safe",
      "components": {
        "Components": {
          "AetherhavenShopSafeBlock": {
            "PlotId": "",
            "TownId": ""
          },
          "PlacedByInteraction": {
            "WhoPlacedUuid": {
              "$binary": "v7RyWIT/TYKnXA2XcxdQtw==",
              "$type": "04"
            }
          }
        }
      },
      "support": 15
    },
    {
      "x": 5,
      "y": 5,
      "z": -12,
      "name": "Furniture_Village_Platform",
      "support": 15,
      "rotation": 1
    },
    {
      "x": 5,
      "y": 6,
      "z": -12,
      "name": "Furniture_Tavern_Barrel",
      "support": 15
    },
    {
      "x": 5,
      "y": 9,
      "z": -12,
      "name": "Wood_Softwood_Stairs",
      "rotation": 11
    },
    {
      "x": 5,
      "y": 10,
      "z": -12,
      "name": "Wood_Softwood_Roof_Flat"
    },
    {
      "x": 5,
      "y": 1,
      "z": -11,
      "name": "Wood_Softwood_Planks"
    },
    {
      "x": 5,
      "y": 9,
      "z": -11,
      "name": "Wood_Softwood_Stairs",
      "rotation": 11
    },
    {
      "x": 5,
      "y": 10,
      "z": -11,
      "name": "Wood_Softwood_Roof_Flat"
    },
    {
      "x": 5,
      "y": 1,
      "z": -10,
      "name": "Wood_Softwood_Planks"
    },
    {
      "x": 5,
      "y": 2,
      "z": -10,
      "name": "Cloth_Roof_Orange_Flat"
    },
    {
      "x": 5,
      "y": 9,
      "z": -10,
      "name": "Wood_Softwood_Stairs",
      "rotation": 11
    },
    {
      "x": 5,
      "y": 10,
      "z": -10,
      "name": "Wood_Softwood_Roof_Flat"
    },
    {
      "x": 5,
      "y": 1,
      "z": -9,
      "name": "Wood_Softwood_Planks"
    },
    {
      "x": 5,
      "y": 2,
      "z": -9,
      "name": "Cloth_Roof_Orange_Flat"
    },
    {
      "x": 5,
      "y": 9,
      "z": -9,
      "name": "Wood_Softwood_Stairs",
      "rotation": 11
    },
    {
      "x": 5,
      "y": 10,
      "z": -9,
      "name": "Wood_Softwood_Roof_Flat"
    },
    {
      "x": 5,
      "y": 1,
      "z": -8,
      "name": "Wood_Softwood_Planks"
    },
    {
      "x": 5,
      "y": 9,
      "z": -8,
      "name": "Wood_Softwood_Stairs",
      "rotation": 11
    },
    {
      "x": 5,
      "y": 10,
      "z": -8,
      "name": "Wood_Softwood_Roof_Flat"
    },
    {
      "x": 5,
      "y": 1,
      "z": -7,
      "name": "Wood_Softwood_Planks"
    },
    {
      "x": 5,
      "y": 2,
      "z": -7,
      "name": "Wood_Softwood_Planks_Half",
      "rotation": 8
    },
    {
      "x": 5,
      "y": 3,
      "z": -7,
      "name": "Aetherhaven_Shop_Spot",
      "components": {
        "Components": {
          "AetherhavenShopSpotBlock": {
            "SpotId": "2816e0ab-e552-40ca-b601-5fcebe72daf6",
            "TownId": "d87b9d18-a6de-42a7-9697-90f4c2aa0d9f",
            "PlotId": "00000000-0000-0000-0000-000000000000",
            "PlayerControlled": true,
            "LootTableId": "",
            "Configured": true
          },
          "PlacedByInteraction": {
            "WhoPlacedUuid": {
              "$binary": "v7RyWIT/TYKnXA2XcxdQtw==",
              "$type": "04"
            }
          }
        }
      }
    },
    {
      "x": 5,
      "y": 5,
      "z": -7,
      "name": "Wood_Beech_Trunk",
      "support": 15,
      "rotation": 5
    },
    {
      "x": 5,
      "y": 6,
      "z": -7,
      "name": "*Wood_Village_Wall_Full_State_Definitions_Bottom"
    },
    {
      "x": 5,
      "y": 7,
      "z": -7,
      "name": "*Wood_Village_Wall_Full_State_Definitions_Middle"
    },
    {
      "x": 5,
      "y": 8,
      "z": -7,
      "name": "*Wood_Village_Wall_Full_State_Definitions_Middle"
    },
    {
      "x": 5,
      "y": 9,
      "z": -7,
      "name": "*Wood_Village_Wall_Full_State_Definitions_Top"
    },
    {
      "x": 5,
      "y": 10,
      "z": -7,
      "name": "Wood_Softwood_Roof_Flat"
    },
    {
      "x": 5,
      "y": 1,
      "z": -6,
      "name": "Rock_Stone_Brick"
    },
    {
      "x": 5,
      "y": 5,
      "z": -6,
      "name": "Wood_Beech_Branch_Short",
      "support": 15
    },
    {
      "x": 5,
      "y": 6,
      "z": -6,
      "name": "Cloth_Roof_White_Flat"
    },
    {
      "x": 5,
      "y": 9,
      "z": -6,
      "name": "Wood_Softwood_Stairs",
      "rotation": 11
    },
    {
      "x": 5,
      "y": 10,
      "z": -6,
      "name": "Wood_Softwood_Roof_Flat"
    },
    {
      "x": 5,
      "y": 1,
      "z": -5,
      "name": "Rock_Stone_Brick"
    },
    {
      "x": 5,
      "y": 6,
      "z": -5,
      "name": "Cloth_Roof_Orange_Flat"
    },
    {
      "x": 5,
      "y": 1,
      "z": -4,
      "name": "Rock_Stone_Brick"
    },
    {
      "x": 5,
      "y": 6,
      "z": -4,
      "name": "Cloth_Roof_White_Flat"
    },
    {
      "x": 5,
      "y": 1,
      "z": -3,
      "name": "Rock_Stone_Brick_Smooth"
    },
    {
      "x": 5,
      "y": 5,
      "z": -3,
      "name": "Cloth_Roof_Orange"
    },
    {
      "x": 5,
      "y": 1,
      "z": -2,
      "name": "Rock_Stone_Cobble"
    },
    {
      "x": 5,
      "y": 4,
      "z": -2,
      "name": "Cloth_Roof_Orange_Flap"
    },
    {
      "x": 5,
      "y": 1,
      "z": -1,
      "name": "Rock_Stone_Cobble"
    },
    {
      "x": 6,
      "y": 1,
      "z": -14,
      "name": "Rock_Stone_Cobble"
    },
    {
      "x": 6,
      "y": 9,
      "z": -14,
      "name": "Wood_Softwood_Planks_Half",
      "rotation": 8
    },
    {
      "x": 6,
      "y": 10,
      "z": -14,
      "name": "Wood_Softwood_Roof_Flat"
    },
    {
      "x": 6,
      "y": 1,
      "z": -13,
      "name": "Rock_Stone_Cobble"
    },
    {
      "x": 6,
      "y": 2,
      "z": -13,
      "name": "Rock_Stone_Brick"
    },
    {
      "x": 6,
      "y": 3,
      "z": -13,
      "name": "*Wood_Village_Wall_Full_State_Definitions_Bottom"
    },
    {
      "x": 6,
      "y": 4,
      "z": -13,
      "name": "*Wood_Village_Wall_Full_State_Definitions_Top"
    },
    {
      "x": 6,
      "y": 5,
      "z": -13,
      "name": "Wood_Beech_Trunk",
      "support": 15,
      "rotation": 5
    },
    {
      "x": 6,
      "y": 6,
      "z": -13,
      "name": "Furniture_Village_Window"
    },
    {
      "x": 6,
      "y": 7,
      "z": -13,
      "name": "Furniture_Village_Window"
    },
    {
      "x": 6,
      "y": 8,
      "z": -13,
      "name": "*Wood_Village_Wall_Full_State_Definitions_Bottom"
    },
    {
      "x": 6,
      "y": 9,
      "z": -13,
      "name": "*Wood_Village_Wall_Full_State_Definitions_Top"
    },
    {
      "x": 6,
      "y": 10,
      "z": -13,
      "name": "Wood_Softwood_Roof_Flat"
    },
    {
      "x": 6,
      "y": 1,
      "z": -12,
      "name": "Wood_Softwood_Planks"
    },
    {
      "x": 6,
      "y": 2,
      "z": -12,
      "name": "Furniture_Village_Counter",
      "support": 15,
      "filler": 31
    },
    {
      "x": 6,
      "y": 3,
      "z": -12,
      "name": "Aetherhaven_Management_Block",
      "components": {
        "Components": {
          "AetherhavenManagementBlock": {
            "PlotId": "",
            "TownId": ""
          },
          "PlacedByInteraction": {
            "WhoPlacedUuid": {
              "$binary": "v7RyWIT/TYKnXA2XcxdQtw==",
              "$type": "04"
            }
          }
        }
      }
    },
    {
      "x": 6,
      "y": 5,
      "z": -12,
      "name": "Furniture_Village_Platform",
      "support": 15,
      "rotation": 1
    },
    {
      "x": 6,
      "y": 9,
      "z": -12,
      "name": "Wood_Softwood_Planks_Half",
      "rotation": 8
    },
    {
      "x": 6,
      "y": 10,
      "z": -12,
      "name": "Wood_Softwood_Roof_Flat"
    },
    {
      "x": 6,
      "y": 1,
      "z": -11,
      "name": "Wood_Softwood_Planks"
    },
    {
      "x": 6,
      "y": 9,
      "z": -11,
      "name": "Wood_Softwood_Planks_Half",
      "rotation": 8
    },
    {
      "x": 6,
      "y": 10,
      "z": -11,
      "name": "Wood_Softwood_Roof_Flat"
    },
    {
      "x": 6,
      "y": 1,
      "z": -10,
      "name": "Wood_Softwood_Planks"
    },
    {
      "x": 6,
      "y": 2,
      "z": -10,
      "name": "Cloth_Roof_Orange_Flat"
    },
    {
      "x": 6,
      "y": 9,
      "z": -10,
      "name": "Wood_Softwood_Planks_Half",
      "rotation": 8
    },
    {
      "x": 6,
      "y": 10,
      "z": -10,
      "name": "Wood_Softwood_Roof_Flat"
    },
    {
      "x": 6,
      "y": 1,
      "z": -9,
      "name": "Wood_Softwood_Planks"
    },
    {
      "x": 6,
      "y": 2,
      "z": -9,
      "name": "Cloth_Roof_Orange_Flat"
    },
    {
      "x": 6,
      "y": 9,
      "z": -9,
      "name": "Wood_Softwood_Planks_Half",
      "rotation": 8
    },
    {
      "x": 6,
      "y": 10,
      "z": -9,
      "name": "Wood_Softwood_Roof_Flat"
    },
    {
      "x": 6,
      "y": 1,
      "z": -8,
      "name": "Wood_Softwood_Planks"
    },
    {
      "x": 6,
      "y": 9,
      "z": -8,
      "name": "Wood_Softwood_Planks_Half",
      "rotation": 8
    },
    {
      "x": 6,
      "y": 10,
      "z": -8,
      "name": "Wood_Softwood_Roof_Flat"
    },
    {
      "x": 6,
      "y": 1,
      "z": -7,
      "name": "Wood_Softwood_Planks"
    },
    {
      "x": 6,
      "y": 2,
      "z": -7,
      "name": "Furniture_Village_Counter",
      "support": 15,
      "rotation": 2
    },
    {
      "x": 6,
      "y": 3,
      "z": -7,
      "name": "Aetherhaven_Shop_Spot",
      "components": {
        "Components": {
          "AetherhavenShopSpotBlock": {
            "SpotId": "a251397d-e43b-49b2-8fdb-96822036e50e",
            "TownId": "d87b9d18-a6de-42a7-9697-90f4c2aa0d9f",
            "PlotId": "00000000-0000-0000-0000-000000000000",
            "PlayerControlled": true,
            "LootTableId": "",
            "Configured": true
          },
          "PlacedByInteraction": {
            "WhoPlacedUuid": {
              "$binary": "v7RyWIT/TYKnXA2XcxdQtw==",
              "$type": "04"
            }
          }
        }
      }
    },
    {
      "x": 6,
      "y": 5,
      "z": -7,
      "name": "Wood_Beech_Trunk",
      "support": 15,
      "rotation": 5
    },
    {
      "x": 6,
      "y": 6,
      "z": -7,
      "name": "Furniture_Village_Window"
    },
    {
      "x": 6,
      "y": 7,
      "z": -7,
      "name": "Furniture_Village_Window"
    },
    {
      "x": 6,
      "y": 8,
      "z": -7,
      "name": "*Wood_Village_Wall_Full_State_Definitions_Bottom"
    },
    {
      "x": 6,
      "y": 9,
      "z": -7,
      "name": "*Wood_Village_Wall_Full_State_Definitions_Top"
    },
    {
      "x": 6,
      "y": 10,
      "z": -7,
      "name": "Wood_Softwood_Roof_Flat"
    },
    {
      "x": 6,
      "y": 1,
      "z": -6,
      "name": "Rock_Stone_Brick"
    },
    {
      "x": 6,
      "y": 6,
      "z": -6,
      "name": "Cloth_Roof_Orange_Flat"
    },
    {
      "x": 6,
      "y": 9,
      "z": -6,
      "name": "Wood_Softwood_Planks_Half",
      "rotation": 8
    },
    {
      "x": 6,
      "y": 10,
      "z": -6,
      "name": "Wood_Softwood_Roof_Flat"
    },
    {
      "x": 6,
      "y": 1,
      "z": -5,
      "name": "Rock_Stone_Brick"
    },
    {
      "x": 6,
      "y": 6,
      "z": -5,
      "name": "Cloth_Roof_White_Flat"
    },
    {
      "x": 6,
      "y": 1,
      "z": -4,
      "name": "Rock_Stone_Brick_Mossy"
    },
    {
      "x": 6,
      "y": 6,
      "z": -4,
      "name": "Cloth_Roof_Orange_Flat"
    },
    {
      "x": 6,
      "y": 1,
      "z": -3,
      "name": "Rock_Stone_Brick_Smooth"
    },
    {
      "x": 6,
      "y": 5,
      "z": -3,
      "name": "Cloth_Roof_White"
    },
    {
      "x": 6,
      "y": 1,
      "z": -2,
      "name": "Rock_Stone_Cobble"
    },
    {
      "x": 6,
      "y": 4,
      "z": -2,
      "name": "Cloth_Roof_White_Flap"
    },
    {
      "x": 6,
      "y": 1,
      "z": -1,
      "name": "Rock_Stone_Cobble"
    },
    {
      "x": 7,
      "y": 1,
      "z": -14,
      "name": "Rock_Stone_Cobble"
    },
    {
      "x": 7,
      "y": 4,
      "z": -14,
      "name": "Plant_Vine_Wall",
      "support": 15,
      "rotation": 2
    },
    {
      "x": 7,
      "y": 9,
      "z": -14,
      "name": "Wood_Softwood_Planks_Half",
      "rotation": 8
    },
    {
      "x": 7,
      "y": 10,
      "z": -14,
      "name": "Wood_Softwood_Roof_Flat"
    },
    {
      "x": 7,
      "y": 1,
      "z": -13,
      "name": "Rock_Stone_Cobble_Mossy"
    },
    {
      "x": 7,
      "y": 2,
      "z": -13,
      "name": "Rock_Stone_Brick"
    },
    {
      "x": 7,
      "y": 3,
      "z": -13,
      "name": "*Wood_Village_Wall_Full_State_Definitions_Bottom"
    },
    {
      "x": 7,
      "y": 4,
      "z": -13,
      "name": "*Wood_Village_Wall_Full_State_Definitions_Top"
    },
    {
      "x": 7,
      "y": 5,
      "z": -13,
      "name": "Wood_Beech_Trunk",
      "support": 15,
      "rotation": 5
    },
    {
      "x": 7,
      "y": 6,
      "z": -13,
      "name": "Furniture_Village_Window"
    },
    {
      "x": 7,
      "y": 7,
      "z": -13,
      "name": "Furniture_Village_Window"
    },
    {
      "x": 7,
      "y": 8,
      "z": -13,
      "name": "*Wood_Village_Wall_Full_State_Definitions_Bottom"
    },
    {
      "x": 7,
      "y": 9,
      "z": -13,
      "name": "*Wood_Village_Wall_Full_State_Definitions_Top"
    },
    {
      "x": 7,
      "y": 10,
      "z": -13,
      "name": "Wood_Softwood_Roof_Flat"
    },
    {
      "x": 7,
      "y": 1,
      "z": -12,
      "name": "Wood_Softwood_Planks"
    },
    {
      "x": 7,
      "y": 2,
      "z": -12,
      "name": "Furniture_Village_Counter",
      "support": 15
    },
    {
      "x": 7,
      "y": 3,
      "z": -12,
      "name": "Furniture_Crude_Candle",
      "support": 15
    },
    {
      "x": 7,
      "y": 5,
      "z": -12,
      "name": "Furniture_Village_Platform",
      "support": 15,
      "rotation": 1
    },
    {
      "x": 7,
      "y": 9,
      "z": -12,
      "name": "Wood_Softwood_Planks_Half",
      "rotation": 8
    },
    {
      "x": 7,
      "y": 10,
      "z": -12,
      "name": "Wood_Softwood_Roof_Flat"
    },
    {
      "x": 7,
      "y": 1,
      "z": -11,
      "name": "Wood_Softwood_Planks"
    },
    {
      "x": 7,
      "y": 9,
      "z": -11,
      "name": "Wood_Softwood_Planks_Half",
      "rotation": 8
    },
    {
      "x": 7,
      "y": 10,
      "z": -11,
      "name": "Wood_Softwood_Roof_Flat"
    },
    {
      "x": 7,
      "y": 1,
      "z": -10,
      "name": "Wood_Softwood_Planks"
    },
    {
      "x": 7,
      "y": 2,
      "z": -10,
      "name": "Cloth_Roof_Orange_Flat"
    },
    {
      "x": 7,
      "y": 9,
      "z": -10,
      "name": "Wood_Softwood_Planks_Half",
      "rotation": 8
    },
    {
      "x": 7,
      "y": 10,
      "z": -10,
      "name": "Wood_Softwood_Roof_Flat"
    },
    {
      "x": 7,
      "y": 1,
      "z": -9,
      "name": "Wood_Softwood_Planks"
    },
    {
      "x": 7,
      "y": 2,
      "z": -9,
      "name": "Cloth_Roof_Orange_Flat"
    },
    {
      "x": 7,
      "y": 9,
      "z": -9,
      "name": "Wood_Softwood_Planks_Half",
      "rotation": 8
    },
    {
      "x": 7,
      "y": 10,
      "z": -9,
      "name": "Wood_Softwood_Roof_Flat"
    },
    {
      "x": 7,
      "y": 1,
      "z": -8,
      "name": "Wood_Softwood_Planks"
    },
    {
      "x": 7,
      "y": 9,
      "z": -8,
      "name": "Wood_Softwood_Planks_Half",
      "rotation": 8
    },
    {
      "x": 7,
      "y": 10,
      "z": -8,
      "name": "Wood_Softwood_Roof_Flat"
    },
    {
      "x": 7,
      "y": 1,
      "z": -7,
      "name": "Wood_Softwood_Planks"
    },
    {
      "x": 7,
      "y": 2,
      "z": -7,
      "name": "Furniture_Village_Counter",
      "support": 15,
      "filler": 1,
      "rotation": 2
    },
    {
      "x": 7,
      "y": 3,
      "z": -7,
      "name": "Aetherhaven_Shop_Spot",
      "components": {
        "Components": {
          "AetherhavenShopSpotBlock": {
            "SpotId": "988af15e-1e2e-4bf7-868c-110eaee81fd8",
            "TownId": "d87b9d18-a6de-42a7-9697-90f4c2aa0d9f",
            "PlotId": "00000000-0000-0000-0000-000000000000",
            "PlayerControlled": true,
            "LootTableId": "",
            "Configured": true
          },
          "PlacedByInteraction": {
            "WhoPlacedUuid": {
              "$binary": "v7RyWIT/TYKnXA2XcxdQtw==",
              "$type": "04"
            }
          }
        }
      }
    },
    {
      "x": 7,
      "y": 5,
      "z": -7,
      "name": "Wood_Beech_Trunk",
      "support": 15,
      "rotation": 5
    },
    {
      "x": 7,
      "y": 6,
      "z": -7,
      "name": "Furniture_Village_Window"
    },
    {
      "x": 7,
      "y": 7,
      "z": -7,
      "name": "Furniture_Village_Window"
    },
    {
      "x": 7,
      "y": 8,
      "z": -7,
      "name": "*Wood_Village_Wall_Full_State_Definitions_Bottom"
    },
    {
      "x": 7,
      "y": 9,
      "z": -7,
      "name": "*Wood_Village_Wall_Full_State_Definitions_Top"
    },
    {
      "x": 7,
      "y": 10,
      "z": -7,
      "name": "Wood_Softwood_Roof_Flat"
    },
    {
      "x": 7,
      "y": 1,
      "z": -6,
      "name": "Rock_Stone_Brick"
    },
    {
      "x": 7,
      "y": 6,
      "z": -6,
      "name": "Cloth_Roof_White_Flat"
    },
    {
      "x": 7,
      "y": 9,
      "z": -6,
      "name": "Wood_Softwood_Planks_Half",
      "rotation": 8
    },
    {
      "x": 7,
      "y": 10,
      "z": -6,
      "name": "Wood_Softwood_Roof_Flat"
    },
    {
      "x": 7,
      "y": 1,
      "z": -5,
      "name": "Rock_Stone_Brick"
    },
    {
      "x": 7,
      "y": 6,
      "z": -5,
      "name": "Cloth_Roof_Orange_Flat"
    },
    {
      "x": 7,
      "y": 1,
      "z": -4,
      "name": "Rock_Stone_Brick"
    },
    {
      "x": 7,
      "y": 6,
      "z": -4,
      "name": "Cloth_Roof_White_Flat"
    },
    {
      "x": 7,
      "y": 1,
      "z": -3,
      "name": "Rock_Stone_Brick_Smooth"
    },
    {
      "x": 7,
      "y": 5,
      "z": -3,
      "name": "Cloth_Roof_Orange"
    },
    {
      "x": 7,
      "y": 1,
      "z": -2,
      "name": "Rock_Stone_Cobble"
    },
    {
      "x": 7,
      "y": 4,
      "z": -2,
      "name": "Cloth_Roof_Orange_Flap"
    },
    {
      "x": 7,
      "y": 1,
      "z": -1,
      "name": "Rock_Stone_Cobble"
    },
    {
      "x": 8,
      "y": 1,
      "z": -14,
      "name": "Rock_Stone_Cobble"
    },
    {
      "x": 8,
      "y": 5,
      "z": -14,
      "name": "Wood_Beech_Branch_Short",
      "support": 15,
      "rotation": 2
    },
    {
      "x": 8,
      "y": 9,
      "z": -14,
      "name": "Wood_Softwood_Stairs",
      "rotation": 9
    },
    {
      "x": 8,
      "y": 10,
      "z": -14,
      "name": "Wood_Softwood_Roof_Flat"
    },
    {
      "x": 8,
      "y": 1,
      "z": -13,
      "name": "Rock_Stone_Cobble"
    },
    {
      "x": 8,
      "y": 2,
      "z": -13,
      "name": "Rock_Stone_Brick_Mossy"
    },
    {
      "x": 8,
      "y": 3,
      "z": -13,
      "name": "Furniture_Village_Window"
    },
    {
      "x": 8,
      "y": 4,
      "z": -13,
      "name": "Furniture_Village_Window"
    },
    {
      "x": 8,
      "y": 5,
      "z": -13,
      "name": "Wood_Beech_Trunk",
      "support": 15,
      "rotation": 5
    },
    {
      "x": 8,
      "y": 6,
      "z": -13,
      "name": "*Wood_Village_Wall_Full_State_Definitions_Bottom"
    },
    {
      "x": 8,
      "y": 7,
      "z": -13,
      "name": "*Wood_Village_Wall_Full_State_Definitions_Middle"
    },
    {
      "x": 8,
      "y": 8,
      "z": -13,
      "name": "*Wood_Village_Wall_Full_State_Definitions_Middle"
    },
    {
      "x": 8,
      "y": 9,
      "z": -13,
      "name": "*Wood_Village_Wall_Full_State_Definitions_Top"
    },
    {
      "x": 8,
      "y": 10,
      "z": -13,
      "name": "Wood_Softwood_Roof_Flat"
    },
    {
      "x": 8,
      "y": 1,
      "z": -12,
      "name": "Wood_Softwood_Planks"
    },
    {
      "x": 8,
      "y": 2,
      "z": -12,
      "name": "Furniture_Tavern_Chest_Large",
      "support": 15,
      "filler": 31
    },
    {
      "x": 8,
      "y": 5,
      "z": -12,
      "name": "Furniture_Village_Platform",
      "support": 15,
      "rotation": 1
    },
    {
      "x": 8,
      "y": 6,
      "z": -12,
      "name": "Furniture_Village_Crate"
    },
    {
      "x": 8,
      "y": 9,
      "z": -12,
      "name": "Wood_Softwood_Stairs",
      "rotation": 9
    },
    {
      "x": 8,
      "y": 10,
      "z": -12,
      "name": "Wood_Softwood_Roof_Flat"
    },
    {
      "x": 8,
      "y": 1,
      "z": -11,
      "name": "Wood_Softwood_Planks"
    },
    {
      "x": 8,
      "y": 9,
      "z": -11,
      "name": "Wood_Softwood_Stairs",
      "rotation": 9
    },
    {
      "x": 8,
      "y": 10,
      "z": -11,
      "name": "Wood_Softwood_Roof_Flat"
    },
    {
      "x": 8,
      "y": 1,
      "z": -10,
      "name": "Wood_Softwood_Planks"
    },
    {
      "x": 8,
      "y": 2,
      "z": -10,
      "name": "Cloth_Roof_Orange_Flat"
    },
    {
      "x": 8,
      "y": 9,
      "z": -10,
      "name": "Wood_Softwood_Stairs",
      "rotation": 9
    },
    {
      "x": 8,
      "y": 10,
      "z": -10,
      "name": "Wood_Softwood_Roof_Flat"
    },
    {
      "x": 8,
      "y": 1,
      "z": -9,
      "name": "Wood_Softwood_Planks"
    },
    {
      "x": 8,
      "y": 2,
      "z": -9,
      "name": "Cloth_Roof_Orange_Flat"
    },
    {
      "x": 8,
      "y": 9,
      "z": -9,
      "name": "Wood_Softwood_Stairs",
      "rotation": 9
    },
    {
      "x": 8,
      "y": 10,
      "z": -9,
      "name": "Wood_Softwood_Roof_Flat"
    },
    {
      "x": 8,
      "y": 1,
      "z": -8,
      "name": "Wood_Softwood_Planks"
    },
    {
      "x": 8,
      "y": 9,
      "z": -8,
      "name": "Wood_Softwood_Stairs",
      "rotation": 9
    },
    {
      "x": 8,
      "y": 10,
      "z": -8,
      "name": "Wood_Softwood_Roof_Flat"
    },
    {
      "x": 8,
      "y": 1,
      "z": -7,
      "name": "Wood_Softwood_Planks"
    },
    {
      "x": 8,
      "y": 2,
      "z": -7,
      "name": "Wood_Softwood_Planks_Half",
      "rotation": 8
    },
    {
      "x": 8,
      "y": 3,
      "z": -7,
      "name": "Aetherhaven_Shop_Spot",
      "components": {
        "Components": {
          "AetherhavenShopSpotBlock": {
            "SpotId": "64911c12-57c4-417f-8c8f-df698706b602",
            "TownId": "d87b9d18-a6de-42a7-9697-90f4c2aa0d9f",
            "PlotId": "00000000-0000-0000-0000-000000000000",
            "PlayerControlled": true,
            "LootTableId": "",
            "Configured": true
          },
          "PlacedByInteraction": {
            "WhoPlacedUuid": {
              "$binary": "v7RyWIT/TYKnXA2XcxdQtw==",
              "$type": "04"
            }
          }
        }
      }
    },
    {
      "x": 8,
      "y": 5,
      "z": -7,
      "name": "Wood_Beech_Trunk",
      "support": 15,
      "rotation": 5
    },
    {
      "x": 8,
      "y": 6,
      "z": -7,
      "name": "*Wood_Village_Wall_Full_State_Definitions_Bottom"
    },
    {
      "x": 8,
      "y": 7,
      "z": -7,
      "name": "*Wood_Village_Wall_Full_State_Definitions_Middle"
    },
    {
      "x": 8,
      "y": 8,
      "z": -7,
      "name": "*Wood_Village_Wall_Full_State_Definitions_Middle"
    },
    {
      "x": 8,
      "y": 9,
      "z": -7,
      "name": "*Wood_Village_Wall_Full_State_Definitions_Top"
    },
    {
      "x": 8,
      "y": 10,
      "z": -7,
      "name": "Wood_Softwood_Roof_Flat"
    },
    {
      "x": 8,
      "y": 1,
      "z": -6,
      "name": "Rock_Stone_Brick"
    },
    {
      "x": 8,
      "y": 5,
      "z": -6,
      "name": "Wood_Beech_Branch_Short",
      "support": 15
    },
    {
      "x": 8,
      "y": 6,
      "z": -6,
      "name": "Cloth_Roof_Orange_Flat"
    },
    {
      "x": 8,
      "y": 8,
      "z": -6,
      "name": "Plant_Vine_Wall",
      "support": 15
    },
    {
      "x": 8,
      "y": 9,
      "z": -6,
      "name": "Wood_Softwood_Stairs",
      "rotation": 9
    },
    {
      "x": 8,
      "y": 10,
      "z": -6,
      "name": "Wood_Softwood_Roof_Flat"
    },
    {
      "x": 8,
      "y": 1,
      "z": -5,
      "name": "Rock_Stone_Brick"
    },
    {
      "x": 8,
      "y": 6,
      "z": -5,
      "name": "Cloth_Roof_White_Flat"
    },
    {
      "x": 8,
      "y": 1,
      "z": -4,
      "name": "Rock_Stone_Brick"
    },
    {
      "x": 8,
      "y": 6,
      "z": -4,
      "name": "Cloth_Roof_Orange_Flat"
    },
    {
      "x": 8,
      "y": 1,
      "z": -3,
      "name": "Rock_Stone_Brick_Smooth"
    },
    {
      "x": 8,
      "y": 5,
      "z": -3,
      "name": "Cloth_Roof_White"
    },
    {
      "x": 8,
      "y": 1,
      "z": -2,
      "name": "Rock_Stone_Cobble"
    },
    {
      "x": 8,
      "y": 4,
      "z": -2,
      "name": "Cloth_Roof_White_Flap"
    },
    {
      "x": 8,
      "y": 1,
      "z": -1,
      "name": "Rock_Stone_Cobble_Mossy"
    },
    {
      "x": 9,
      "y": 1,
      "z": -14,
      "name": "Rock_Stone_Cobble"
    },
    {
      "x": 9,
      "y": 8,
      "z": -14,
      "name": "Wood_Softwood_Stairs",
      "rotation": 9
    },
    {
      "x": 9,
      "y": 9,
      "z": -14,
      "name": "Wood_Softwood_Roof",
      "rotation": 1
    },
    {
      "x": 9,
      "y": 1,
      "z": -13,
      "name": "Rock_Stone_Cobble_Mossy"
    },
    {
      "x": 9,
      "y": 2,
      "z": -13,
      "name": "Rock_Stone_Brick"
    },
    {
      "x": 9,
      "y": 3,
      "z": -13,
      "name": "Furniture_Village_Window"
    },
    {
      "x": 9,
      "y": 4,
      "z": -13,
      "name": "Furniture_Village_Window"
    },
    {
      "x": 9,
      "y": 5,
      "z": -13,
      "name": "Wood_Beech_Trunk",
      "support": 15,
      "rotation": 5
    },
    {
      "x": 9,
      "y": 6,
      "z": -13,
      "name": "*Wood_Village_Wall_Full_State_Definitions_Bottom"
    },
    {
      "x": 9,
      "y": 7,
      "z": -13,
      "name": "*Wood_Village_Wall_Full_State_Definitions_Middle"
    },
    {
      "x": 9,
      "y": 8,
      "z": -13,
      "name": "*Wood_Village_Wall_Full_State_Definitions_Top"
    },
    {
      "x": 9,
      "y": 9,
      "z": -13,
      "name": "Wood_Softwood_Roof",
      "rotation": 1
    },
    {
      "x": 9,
      "y": 1,
      "z": -12,
      "name": "Wood_Softwood_Planks"
    },
    {
      "x": 9,
      "y": 2,
      "z": -12,
      "name": "Furniture_Tavern_Chest_Large",
      "components": {
        "Components": {
          "ItemContainerBlock": {
            "ItemContainer": {
              "Capacity": 36,
              "Items": {}
            },
            "Capacity": 36
          }
        }
      },
      "support": 15
    },
    {
      "x": 9,
      "y": 5,
      "z": -12,
      "name": "Furniture_Village_Platform",
      "support": 15,
      "rotation": 1
    },
    {
      "x": 9,
      "y": 6,
      "z": -12,
      "name": "Furniture_Village_Crate"
    },
    {
      "x": 9,
      "y": 7,
      "z": -12,
      "name": "Furniture_Tavern_Barrel",
      "support": 15
    },
    {
      "x": 9,
      "y": 8,
      "z": -12,
      "name": "Wood_Softwood_Stairs",
      "rotation": 9
    },
    {
      "x": 9,
      "y": 9,
      "z": -12,
      "name": "Wood_Softwood_Roof",
      "rotation": 1
    },
    {
      "x": 9,
      "y": 1,
      "z": -11,
      "name": "Wood_Softwood_Planks"
    },
    {
      "x": 9,
      "y": 8,
      "z": -11,
      "name": "Wood_Softwood_Stairs",
      "rotation": 9
    },
    {
      "x": 9,
      "y": 9,
      "z": -11,
      "name": "Wood_Softwood_Roof",
      "rotation": 1
    },
    {
      "x": 9,
      "y": 1,
      "z": -10,
      "name": "Wood_Softwood_Planks"
    },
    {
      "x": 9,
      "y": 5,
      "z": -10,
      "name": "Deco_Lantern_Ceiling",
      "support": 15
    },
    {
      "x": 9,
      "y": 6,
      "z": -10,
      "name": "Deco_Rope",
      "support": 15
    },
    {
      "x": 9,
      "y": 7,
      "z": -10,
      "name": "Deco_Rope",
      "support": 15
    },
    {
      "x": 9,
      "y": 8,
      "z": -10,
      "name": "Wood_Softwood_Planks"
    },
    {
      "x": 9,
      "y": 9,
      "z": -10,
      "name": "Wood_Softwood_Roof",
      "rotation": 1
    },
    {
      "x": 9,
      "y": 1,
      "z": -9,
      "name": "Wood_Softwood_Planks"
    },
    {
      "x": 9,
      "y": 8,
      "z": -9,
      "name": "Wood_Softwood_Stairs",
      "rotation": 9
    },
    {
      "x": 9,
      "y": 9,
      "z": -9,
      "name": "Wood_Softwood_Roof",
      "rotation": 1
    },
    {
      "x": 9,
      "y": 1,
      "z": -8,
      "name": "Wood_Softwood_Planks"
    },
    {
      "x": 9,
      "y": 8,
      "z": -8,
      "name": "Wood_Softwood_Stairs",
      "rotation": 9
    },
    {
      "x": 9,
      "y": 9,
      "z": -8,
      "name": "Wood_Softwood_Roof",
      "rotation": 1
    },
    {
      "x": 9,
      "y": 1,
      "z": -7,
      "name": "Wood_Softwood_Planks"
    },
    {
      "x": 9,
      "y": 2,
      "z": -7,
      "name": "Wood_Softwood_Planks_Half",
      "rotation": 8
    },
    {
      "x": 9,
      "y": 3,
      "z": -7,
      "name": "Aetherhaven_Shop_Spot",
      "components": {
        "Components": {
          "AetherhavenShopSpotBlock": {
            "SpotId": "c6e794bb-2192-4506-a6b4-e140c7dd7600",
            "TownId": "d87b9d18-a6de-42a7-9697-90f4c2aa0d9f",
            "PlotId": "00000000-0000-0000-0000-000000000000",
            "PlayerControlled": true,
            "LootTableId": "",
            "Configured": true
          },
          "PlacedByInteraction": {
            "WhoPlacedUuid": {
              "$binary": "v7RyWIT/TYKnXA2XcxdQtw==",
              "$type": "04"
            }
          }
        }
      }
    },
    {
      "x": 9,
      "y": 5,
      "z": -7,
      "name": "Wood_Beech_Trunk",
      "support": 15,
      "rotation": 5
    },
    {
      "x": 9,
      "y": 6,
      "z": -7,
      "name": "*Wood_Village_Wall_Full_State_Definitions_Bottom"
    },
    {
      "x": 9,
      "y": 7,
      "z": -7,
      "name": "*Wood_Village_Wall_Full_State_Definitions_Middle"
    },
    {
      "x": 9,
      "y": 8,
      "z": -7,
      "name": "*Wood_Village_Wall_Full_State_Definitions_Top"
    },
    {
      "x": 9,
      "y": 9,
      "z": -7,
      "name": "Wood_Softwood_Roof",
      "rotation": 1
    },
    {
      "x": 9,
      "y": 1,
      "z": -6,
      "name": "Rock_Stone_Brick_Mossy"
    },
    {
      "x": 9,
      "y": 6,
      "z": -6,
      "name": "Cloth_Roof_White_Flat"
    },
    {
      "x": 9,
      "y": 8,
      "z": -6,
      "name": "Wood_Softwood_Stairs",
      "rotation": 9
    },
    {
      "x": 9,
      "y": 9,
      "z": -6,
      "name": "Wood_Softwood_Roof",
      "rotation": 1
    },
    {
      "x": 9,
      "y": 1,
      "z": -5,
      "name": "Rock_Stone_Brick"
    },
    {
      "x": 9,
      "y": 6,
      "z": -5,
      "name": "Cloth_Roof_Orange_Flat"
    },
    {
      "x": 9,
      "y": 1,
      "z": -4,
      "name": "Rock_Stone_Brick"
    },
    {
      "x": 9,
      "y": 6,
      "z": -4,
      "name": "Cloth_Roof_White_Flat"
    },
    {
      "x": 9,
      "y": 1,
      "z": -3,
      "name": "Rock_Stone_Brick_Smooth"
    },
    {
      "x": 9,
      "y": 5,
      "z": -3,
      "name": "Cloth_Roof_Orange"
    },
    {
      "x": 9,
      "y": 1,
      "z": -2,
      "name": "Rock_Stone_Cobble"
    },
    {
      "x": 9,
      "y": 4,
      "z": -2,
      "name": "Cloth_Roof_Orange_Flap"
    },
    {
      "x": 9,
      "y": 1,
      "z": -1,
      "name": "Rock_Stone_Cobble"
    },
    {
      "x": 10,
      "y": 1,
      "z": -14,
      "name": "Rock_Stone_Cobble"
    },
    {
      "x": 10,
      "y": 6,
      "z": -14,
      "name": "Wood_Softwood_Stairs",
      "rotation": 9
    },
    {
      "x": 10,
      "y": 7,
      "z": -14,
      "name": "Wood_Softwood_Roof_Steep",
      "rotation": 1
    },
    {
      "x": 10,
      "y": 8,
      "z": -14,
      "name": "Wood_Softwood_Roof_Steep",
      "filler": 1024,
      "rotation": 1
    },
    {
      "x": 10,
      "y": 1,
      "z": -13,
      "name": "Rock_Stone_Cobble"
    },
    {
      "x": 10,
      "y": 2,
      "z": -13,
      "name": "Rock_Stone_Brick"
    },
    {
      "x": 10,
      "y": 3,
      "z": -13,
      "name": "*Wood_Village_Wall_Full_State_Definitions_Bottom"
    },
    {
      "x": 10,
      "y": 4,
      "z": -13,
      "name": "*Wood_Village_Wall_Full_State_Definitions_Top"
    },
    {
      "x": 10,
      "y": 5,
      "z": -13,
      "name": "Wood_Beech_Trunk",
      "support": 15,
      "rotation": 5
    },
    {
      "x": 10,
      "y": 6,
      "z": -13,
      "name": "Wood_Village_Wall_Full"
    },
    {
      "x": 10,
      "y": 7,
      "z": -13,
      "name": "Wood_Softwood_Roof_Steep",
      "rotation": 1
    },
    {
      "x": 10,
      "y": 8,
      "z": -13,
      "name": "Wood_Softwood_Roof_Steep",
      "filler": 1024,
      "rotation": 1
    },
    {
      "x": 10,
      "y": 1,
      "z": -12,
      "name": "Wood_Softwood_Planks"
    },
    {
      "x": 10,
      "y": 2,
      "z": -12,
      "name": "Furniture_Village_Crate"
    },
    {
      "x": 10,
      "y": 5,
      "z": -12,
      "name": "Furniture_Village_Platform",
      "support": 15,
      "rotation": 1
    },
    {
      "x": 10,
      "y": 6,
      "z": -12,
      "name": "Wood_Softwood_Stairs",
      "rotation": 9
    },
    {
      "x": 10,
      "y": 7,
      "z": -12,
      "name": "Wood_Softwood_Roof_Steep",
      "rotation": 1
    },
    {
      "x": 10,
      "y": 8,
      "z": -12,
      "name": "Wood_Softwood_Roof_Steep",
      "filler": 1024,
      "rotation": 1
    },
    {
      "x": 10,
      "y": 1,
      "z": -11,
      "name": "Wood_Softwood_Planks"
    },
    {
      "x": 10,
      "y": 6,
      "z": -11,
      "name": "Wood_Softwood_Stairs",
      "rotation": 9
    },
    {
      "x": 10,
      "y": 7,
      "z": -11,
      "name": "Wood_Softwood_Roof_Steep",
      "rotation": 1
    },
    {
      "x": 10,
      "y": 8,
      "z": -11,
      "name": "Wood_Softwood_Roof_Steep",
      "filler": 1024,
      "rotation": 1
    },
    {
      "x": 10,
      "y": 1,
      "z": -10,
      "name": "Wood_Softwood_Planks"
    },
    {
      "x": 10,
      "y": 6,
      "z": -10,
      "name": "Wood_Softwood_Stairs",
      "rotation": 9
    },
    {
      "x": 10,
      "y": 7,
      "z": -10,
      "name": "Wood_Softwood_Roof_Steep",
      "rotation": 1
    },
    {
      "x": 10,
      "y": 8,
      "z": -10,
      "name": "Wood_Softwood_Roof_Steep",
      "filler": 1024,
      "rotation": 1
    },
    {
      "x": 10,
      "y": 1,
      "z": -9,
      "name": "Wood_Softwood_Planks"
    },
    {
      "x": 10,
      "y": 2,
      "z": -9,
      "name": "Furniture_Village_Crate"
    },
    {
      "x": 10,
      "y": 3,
      "z": -9,
      "name": "Furniture_Ancient_Sack",
      "support": 15,
      "rotation": 3
    },
    {
      "x": 10,
      "y": 6,
      "z": -9,
      "name": "Wood_Softwood_Stairs",
      "rotation": 9
    },
    {
      "x": 10,
      "y": 7,
      "z": -9,
      "name": "Wood_Softwood_Roof_Steep",
      "rotation": 1
    },
    {
      "x": 10,
      "y": 8,
      "z": -9,
      "name": "Wood_Softwood_Roof_Steep",
      "filler": 1024,
      "rotation": 1
    },
    {
      "x": 10,
      "y": 1,
      "z": -8,
      "name": "Wood_Softwood_Planks"
    },
    {
      "x": 10,
      "y": 2,
      "z": -8,
      "name": "Furniture_Tavern_Barrel",
      "support": 15
    },
    {
      "x": 10,
      "y": 6,
      "z": -8,
      "name": "Wood_Softwood_Stairs",
      "rotation": 9
    },
    {
      "x": 10,
      "y": 7,
      "z": -8,
      "name": "Wood_Softwood_Roof_Steep",
      "rotation": 1
    },
    {
      "x": 10,
      "y": 8,
      "z": -8,
      "name": "Wood_Softwood_Roof_Steep",
      "filler": 1024,
      "rotation": 1
    },
    {
      "x": 10,
      "y": 1,
      "z": -7,
      "name": "Wood_Softwood_Planks"
    },
    {
      "x": 10,
      "y": 2,
      "z": -7,
      "name": "Wood_Softwood_Stairs",
      "rotation": 9
    },
    {
      "x": 10,
      "y": 3,
      "z": -7,
      "name": "Aetherhaven_Shop_Spot",
      "components": {
        "Components": {
          "AetherhavenShopSpotBlock": {
            "SpotId": "af0c73f8-aea1-4992-8a05-127ca5d13d8b",
            "TownId": "d87b9d18-a6de-42a7-9697-90f4c2aa0d9f",
            "PlotId": "00000000-0000-0000-0000-000000000000",
            "PlayerControlled": true,
            "LootTableId": "",
            "Configured": true
          },
          "PlacedByInteraction": {
            "WhoPlacedUuid": {
              "$binary": "v7RyWIT/TYKnXA2XcxdQtw==",
              "$type": "04"
            }
          }
        }
      }
    },
    {
      "x": 10,
      "y": 4,
      "z": -7,
      "name": "Wood_Softwood_Stairs",
      "rotation": 9
    },
    {
      "x": 10,
      "y": 5,
      "z": -7,
      "name": "Wood_Beech_Trunk",
      "support": 15,
      "rotation": 5
    },
    {
      "x": 10,
      "y": 6,
      "z": -7,
      "name": "Wood_Village_Wall_Full"
    },
    {
      "x": 10,
      "y": 7,
      "z": -7,
      "name": "Wood_Softwood_Roof_Steep",
      "rotation": 1
    },
    {
      "x": 10,
      "y": 8,
      "z": -7,
      "name": "Wood_Softwood_Roof_Steep",
      "filler": 1024,
      "rotation": 1
    },
    {
      "x": 10,
      "y": 1,
      "z": -6,
      "name": "Rock_Stone_Brick"
    },
    {
      "x": 10,
      "y": 6,
      "z": -6,
      "name": "Cloth_Roof_Orange_Flat"
    },
    {
      "x": 10,
      "y": 7,
      "z": -6,
      "name": "Wood_Softwood_Roof_Steep",
      "rotation": 1
    },
    {
      "x": 10,
      "y": 8,
      "z": -6,
      "name": "Wood_Softwood_Roof_Steep",
      "filler": 1024,
      "rotation": 1
    },
    {
      "x": 10,
      "y": 1,
      "z": -5,
      "name": "Rock_Stone_Brick"
    },
    {
      "x": 10,
      "y": 6,
      "z": -5,
      "name": "Cloth_Roof_White_Flat"
    },
    {
      "x": 10,
      "y": 1,
      "z": -4,
      "name": "Rock_Stone_Brick"
    },
    {
      "x": 10,
      "y": 6,
      "z": -4,
      "name": "Cloth_Roof_Orange_Flat"
    },
    {
      "x": 10,
      "y": 1,
      "z": -3,
      "name": "Rock_Stone_Brick_Smooth"
    },
    {
      "x": 10,
      "y": 5,
      "z": -3,
      "name": "Cloth_Roof_White"
    },
    {
      "x": 10,
      "y": 1,
      "z": -2,
      "name": "Rock_Stone_Cobble"
    },
    {
      "x": 10,
      "y": 4,
      "z": -2,
      "name": "Cloth_Roof_White_Flap"
    },
    {
      "x": 10,
      "y": 1,
      "z": -1,
      "name": "Rock_Stone_Cobble"
    },
    {
      "x": 11,
      "y": 1,
      "z": -14,
      "name": "Rock_Stone_Cobble"
    },
    {
      "x": 11,
      "y": 5,
      "z": -14,
      "name": "Wood_Beech_Branch_Corner",
      "support": 15,
      "rotation": 2
    },
    {
      "x": 11,
      "y": 6,
      "z": -14,
      "name": "Wood_Softwood_Roof",
      "rotation": 1
    },
    {
      "x": 11,
      "y": 1,
      "z": -13,
      "name": "Rock_Stone_Cobble"
    },
    {
      "x": 11,
      "y": 2,
      "z": -13,
      "name": "Wood_Beech_Trunk",
      "support": 15
    },
    {
      "x": 11,
      "y": 3,
      "z": -13,
      "name": "Wood_Beech_Trunk",
      "support": 15
    },
    {
      "x": 11,
      "y": 4,
      "z": -13,
      "name": "Wood_Beech_Trunk",
      "support": 15
    },
    {
      "x": 11,
      "y": 5,
      "z": -13,
      "name": "Wood_Beech_Trunk",
      "support": 15
    },
    {
      "x": 11,
      "y": 6,
      "z": -13,
      "name": "Wood_Softwood_Roof",
      "rotation": 1
    },
    {
      "x": 11,
      "y": 1,
      "z": -12,
      "name": "Rock_Stone_Cobble"
    },
    {
      "x": 11,
      "y": 2,
      "z": -12,
      "name": "Rock_Stone_Brick"
    },
    {
      "x": 11,
      "y": 3,
      "z": -12,
      "name": "*Wood_Village_Wall_Full_State_Definitions_Bottom"
    },
    {
      "x": 11,
      "y": 4,
      "z": -12,
      "name": "*Wood_Village_Wall_Full_State_Definitions_Top"
    },
    {
      "x": 11,
      "y": 5,
      "z": -12,
      "name": "Wood_Beech_Trunk",
      "support": 15,
      "rotation": 4
    },
    {
      "x": 11,
      "y": 6,
      "z": -12,
      "name": "Wood_Softwood_Roof",
      "rotation": 1
    },
    {
      "x": 11,
      "y": 1,
      "z": -11,
      "name": "Rock_Stone_Cobble"
    },
    {
      "x": 11,
      "y": 2,
      "z": -11,
      "name": "Rock_Stone_Brick"
    },
    {
      "x": 11,
      "y": 3,
      "z": -11,
      "name": "*Wood_Village_Wall_Full_State_Definitions_Bottom"
    },
    {
      "x": 11,
      "y": 4,
      "z": -11,
      "name": "*Wood_Village_Wall_Full_State_Definitions_Top"
    },
    {
      "x": 11,
      "y": 5,
      "z": -11,
      "name": "Wood_Beech_Trunk",
      "support": 15,
      "rotation": 4
    },
    {
      "x": 11,
      "y": 6,
      "z": -11,
      "name": "Wood_Softwood_Roof",
      "rotation": 1
    },
    {
      "x": 11,
      "y": 1,
      "z": -10,
      "name": "Wood_Softwood_Planks"
    },
    {
      "x": 11,
      "y": 2,
      "z": -10,
      "name": "Furniture_Village_Door",
      "rotation": 1
    },
    {
      "x": 11,
      "y": 3,
      "z": -10,
      "name": "Furniture_Village_Door",
      "filler": 1024,
      "rotation": 1
    },
    {
      "x": 11,
      "y": 4,
      "z": -10,
      "name": "Wood_Village_Wall_Full"
    },
    {
      "x": 11,
      "y": 5,
      "z": -10,
      "name": "Wood_Beech_Trunk",
      "support": 15,
      "rotation": 4
    },
    {
      "x": 11,
      "y": 6,
      "z": -10,
      "name": "Wood_Softwood_Roof",
      "rotation": 1
    },
    {
      "x": 11,
      "y": 1,
      "z": -9,
      "name": "Rock_Stone_Cobble"
    },
    {
      "x": 11,
      "y": 2,
      "z": -9,
      "name": "Rock_Stone_Brick"
    },
    {
      "x": 11,
      "y": 3,
      "z": -9,
      "name": "*Wood_Village_Wall_Full_State_Definitions_Bottom"
    },
    {
      "x": 11,
      "y": 4,
      "z": -9,
      "name": "*Wood_Village_Wall_Full_State_Definitions_Top"
    },
    {
      "x": 11,
      "y": 5,
      "z": -9,
      "name": "Wood_Beech_Trunk",
      "support": 15,
      "rotation": 4
    },
    {
      "x": 11,
      "y": 6,
      "z": -9,
      "name": "Wood_Softwood_Roof",
      "rotation": 1
    },
    {
      "x": 11,
      "y": 1,
      "z": -8,
      "name": "Rock_Stone_Cobble"
    },
    {
      "x": 11,
      "y": 2,
      "z": -8,
      "name": "Rock_Stone_Brick"
    },
    {
      "x": 11,
      "y": 3,
      "z": -8,
      "name": "*Wood_Village_Wall_Full_State_Definitions_Bottom"
    },
    {
      "x": 11,
      "y": 4,
      "z": -8,
      "name": "*Wood_Village_Wall_Full_State_Definitions_Top"
    },
    {
      "x": 11,
      "y": 5,
      "z": -8,
      "name": "Wood_Beech_Trunk",
      "support": 15,
      "rotation": 4
    },
    {
      "x": 11,
      "y": 6,
      "z": -8,
      "name": "Wood_Softwood_Roof",
      "rotation": 1
    },
    {
      "x": 11,
      "y": 1,
      "z": -7,
      "name": "Rock_Stone_Cobble_Mossy"
    },
    {
      "x": 11,
      "y": 2,
      "z": -7,
      "name": "Wood_Beech_Trunk",
      "support": 15
    },
    {
      "x": 11,
      "y": 3,
      "z": -7,
      "name": "Wood_Beech_Trunk",
      "support": 15
    },
    {
      "x": 11,
      "y": 4,
      "z": -7,
      "name": "Wood_Beech_Trunk",
      "support": 15
    },
    {
      "x": 11,
      "y": 5,
      "z": -7,
      "name": "Wood_Beech_Trunk",
      "support": 15
    },
    {
      "x": 11,
      "y": 6,
      "z": -7,
      "name": "Wood_Softwood_Roof",
      "rotation": 1
    },
    {
      "x": 11,
      "y": 1,
      "z": -6,
      "name": "Rock_Stone_Brick_Smooth"
    },
    {
      "x": 11,
      "y": 3,
      "z": -6,
      "name": "Wood_Torch_Wall",
      "support": 15
    },
    {
      "x": 11,
      "y": 5,
      "z": -6,
      "name": "Cloth_Roof_White",
      "rotation": 1
    },
    {
      "x": 11,
      "y": 6,
      "z": -6,
      "name": "Wood_Softwood_Roof_Hollow",
      "rotation": 1
    },
    {
      "x": 11,
      "y": 1,
      "z": -5,
      "name": "Rock_Stone_Brick_Smooth"
    },
    {
      "x": 11,
      "y": 5,
      "z": -5,
      "name": "Cloth_Roof_Orange",
      "rotation": 1
    },
    {
      "x": 11,
      "y": 1,
      "z": -4,
      "name": "Rock_Stone_Brick_Smooth"
    },
    {
      "x": 11,
      "y": 5,
      "z": -4,
      "name": "Cloth_Roof_White",
      "rotation": 1
    },
    {
      "x": 11,
      "y": 1,
      "z": -3,
      "name": "Rock_Stone_Cobble"
    },
    {
      "x": 11,
      "y": 2,
      "z": -3,
      "name": "Wood_Beech_Trunk",
      "support": 15
    },
    {
      "x": 11,
      "y": 3,
      "z": -3,
      "name": "Wood_Softwood_Beam"
    },
    {
      "x": 11,
      "y": 4,
      "z": -3,
      "name": "Wood_Softwood_Beam"
    },
    {
      "x": 11,
      "y": 5,
      "z": -3,
      "name": "*Cloth_Roof_Orange_State_Definitions_Corner_Left"
    },
    {
      "x": 11,
      "y": 1,
      "z": -2,
      "name": "Rock_Stone_Cobble"
    },
    {
      "x": 11,
      "y": 2,
      "z": -2,
      "name": "Furniture_Tavern_Planter",
      "support": 15
    },
    {
      "x": 11,
      "y": 3,
      "z": -2,
      "name": "Plant_Flower_Flax_Blue",
      "support": 15
    },
    {
      "x": 11,
      "y": 4,
      "z": -2,
      "name": "Cloth_Roof_Orange_Flap"
    },
    {
      "x": 11,
      "y": 1,
      "z": -1,
      "name": "Rock_Stone_Cobble_Mossy"
    },
    {
      "x": 12,
      "y": 1,
      "z": -14,
      "name": "Rock_Stone_Cobble"
    },
    {
      "x": 12,
      "y": 5,
      "z": -14,
      "name": "Wood_Softwood_Roof_Hollow",
      "rotation": 1
    },
    {
      "x": 12,
      "y": 1,
      "z": -13,
      "name": "Rock_Stone_Cobble"
    },
    {
      "x": 12,
      "y": 4,
      "z": -13,
      "name": "Wood_Beech_Branch_Corner",
      "support": 15,
      "rotation": 1
    },
    {
      "x": 12,
      "y": 5,
      "z": -13,
      "name": "Wood_Softwood_Roof",
      "rotation": 1
    },
    {
      "x": 12,
      "y": 1,
      "z": -12,
      "name": "Rock_Stone_Cobble"
    },
    {
      "x": 12,
      "y": 5,
      "z": -12,
      "name": "Wood_Softwood_Roof_Hollow",
      "rotation": 1
    },
    {
      "x": 12,
      "y": 1,
      "z": -11,
      "name": "Rock_Stone_Cobble"
    },
    {
      "x": 12,
      "y": 4,
      "z": -11,
      "name": "Plant_Vine_Wall",
      "support": 15,
      "rotation": 1
    },
    {
      "x": 12,
      "y": 5,
      "z": -11,
      "name": "Wood_Softwood_Roof_Hollow",
      "rotation": 1
    },
    {
      "x": 12,
      "y": 1,
      "z": -10,
      "name": "Rock_Stone_Cobble_Mossy"
    },
    {
      "x": 12,
      "y": 5,
      "z": -10,
      "name": "Wood_Softwood_Roof_Hollow",
      "rotation": 1
    },
    {
      "x": 12,
      "y": 1,
      "z": -9,
      "name": "Rock_Stone_Cobble_Mossy"
    },
    {
      "x": 12,
      "y": 5,
      "z": -9,
      "name": "Wood_Softwood_Roof_Hollow",
      "rotation": 1
    },
    {
      "x": 12,
      "y": 1,
      "z": -8,
      "name": "Rock_Stone_Cobble"
    },
    {
      "x": 12,
      "y": 2,
      "z": -8,
      "name": "Plant_Vine_Wall",
      "support": 15,
      "rotation": 1
    },
    {
      "x": 12,
      "y": 5,
      "z": -8,
      "name": "Wood_Softwood_Roof_Hollow",
      "rotation": 1
    },
    {
      "x": 12,
      "y": 1,
      "z": -7,
      "name": "Rock_Stone_Cobble"
    },
    {
      "x": 12,
      "y": 2,
      "z": -7,
      "name": "Plant_Vine_Wall",
      "support": 15,
      "rotation": 1
    },
    {
      "x": 12,
      "y": 3,
      "z": -7,
      "name": "Plant_Vine_Wall",
      "support": 15,
      "rotation": 1
    },
    {
      "x": 12,
      "y": 4,
      "z": -7,
      "name": "Wood_Beech_Branch_Corner",
      "support": 15,
      "rotation": 1
    },
    {
      "x": 12,
      "y": 5,
      "z": -7,
      "name": "Wood_Softwood_Roof",
      "rotation": 1
    },
    {
      "x": 12,
      "y": 1,
      "z": -6,
      "name": "Rock_Stone_Cobble"
    },
    {
      "x": 12,
      "y": 4,
      "z": -6,
      "name": "Cloth_Roof_White_Flap",
      "rotation": 1
    },
    {
      "x": 12,
      "y": 5,
      "z": -6,
      "name": "Wood_Softwood_Roof_Hollow",
      "rotation": 1
    },
    {
      "x": 12,
      "y": 1,
      "z": -5,
      "name": "Rock_Stone_Cobble"
    },
    {
      "x": 12,
      "y": 4,
      "z": -5,
      "name": "Cloth_Roof_Orange_Flap",
      "rotation": 1
    },
    {
      "x": 12,
      "y": 1,
      "z": -4,
      "name": "Rock_Stone_Cobble_Mossy"
    },
    {
      "x": 12,
      "y": 4,
      "z": -4,
      "name": "Cloth_Roof_White_Flap",
      "rotation": 1
    },
    {
      "x": 12,
      "y": 1,
      "z": -3,
      "name": "Rock_Stone_Cobble"
    },
    {
      "x": 12,
      "y": 4,
      "z": -3,
      "name": "Cloth_Roof_Orange_Flap",
      "rotation": 1
    },
    {
      "x": 12,
      "y": 1,
      "z": -2,
      "name": "Rock_Stone_Cobble"
    },
    {
      "x": 12,
      "y": 1,
      "z": -1,
      "name": "Rock_Stone_Cobble"
    }
  ]
}