{
  "version": 8,
  "blockIdVersion": 11,
  "anchorX": 0,
  "anchorY": 0,
  "anchorZ": 0,
  "blocks": [
    {
      "x": 1,
      "y": 0,
      "z": -11,
      "name": "Rock_Stone_Cobble"
    },
    {
      "x": 1,
      "y": 0,
      "z": -10,
      "name": "Rock_Stone_Cobble"
    },
    {
      "x": 1,
      "y": 0,
      "z": -9,
      "name": "Rock_Stone_Cobble"
    },
    {
      "x": 1,
      "y": 0,
      "z": -8,
      "name": "Rock_Stone_Cobble"
    },
    {
      "x": 1,
      "y": 0,
      "z": -7,
      "name": "Rock_Stone_Cobble"
    },
    {
      "x": 1,
      "y": 0,
      "z": -6,
      "name": "Rock_Stone_Cobble"
    },
    {
      "x": 1,
      "y": 0,
      "z": -5,
      "name": "Rock_Stone_Cobble_Mossy"
    },
    {
      "x": 1,
      "y": 0,
      "z": -4,
      "name": "Rock_Stone_Cobble"
    },
    {
      "x": 1,
      "y": 0,
      "z": -3,
      "name": "Rock_Stone_Cobble"
    },
    {
      "x": 1,
      "y": 0,
      "z": -2,
      "name": "Rock_Stone_Cobble"
    },
    {
      "x": 1,
      "y": 0,
      "z": -1,
      "name": "Rock_Stone_Cobble"
    },
    {
      "x": 2,
      "y": 0,
      "z": -11,
      "name": "Rock_Stone_Cobble_Mossy"
    },
    {
      "x": 2,
      "y": 0,
      "z": -10,
      "name": "Rock_Stone_Cobble"
    },
    {
      "x": 2,
      "y": 0,
      "z": -9,
      "name": "Rock_Stone_Cobble"
    },
    {
      "x": 2,
      "y": 0,
      "z": -8,
      "name": "Wood_Softwood_Planks"
    },
    {
      "x": 2,
      "y": 1,
      "z": -8,
      "name": "Rock_Crystal_Red_Small",
      "support": 15,
      "rotation": 7
    },
    {
      "x": 2,
      "y": 0,
      "z": -7,
      "name": "Wood_Softwood_Planks"
    },
    {
      "x": 2,
      "y": 3,
      "z": -7,
      "name": "Cloth_Roof_White_Flap",
      "rotation": 3
    },
    {
      "x": 2,
      "y": 0,
      "z": -6,
      "name": "Wood_Softwood_Planks"
    },
    {
      "x": 2,
      "y": 3,
      "z": -6,
      "name": "Cloth_Roof_Blue_Flap",
      "rotation": 3
    },
    {
      "x": 2,
      "y": 0,
      "z": -5,
      "name": "Wood_Softwood_Planks"
    },
    {
      "x": 2,
      "y": 3,
      "z": -5,
      "name": "Cloth_Roof_White_Flap",
      "rotation": 3
    },
    {
      "x": 2,
      "y": 0,
      "z": -4,
      "name": "Wood_Softwood_Planks"
    },
    {
      "x": 2,
      "y": 3,
      "z": -4,
      "name": "Cloth_Roof_Blue_Flap",
      "rotation": 3
    },
    {
      "x": 2,
      "y": 0,
      "z": -3,
      "name": "Wood_Softwood_Planks"
    },
    {
      "x": 2,
      "y": 3,
      "z": -3,
      "name": "Cloth_Roof_White_Flap",
      "rotation": 3
    },
    {
      "x": 2,
      "y": 0,
      "z": -2,
      "name": "Rock_Stone_Cobble"
    },
    {
      "x": 2,
      "y": 0,
      "z": -1,
      "name": "Rock_Stone_Cobble"
    },
    {
      "x": 3,
      "y": 0,
      "z": -11,
      "name": "Rock_Stone_Cobble"
    },
    {
      "x": 3,
      "y": 8,
      "z": -11,
      "name": "Wood_Lightwood_Roof_Hollow",
      "rotation": 3
    },
    {
      "x": 3,
      "y": 0,
      "z": -10,
      "name": "Rock_Stone_Cobble"
    },
    {
      "x": 3,
      "y": 2,
      "z": -10,
      "name": "Plant_Vine_Wall",
      "support": 15,
      "rotation": 3
    },
    {
      "x": 3,
      "y": 7,
      "z": -10,
      "name": "Wood_Birch_Branch_Corner",
      "support": 15,
      "rotation": 3
    },
    {
      "x": 3,
      "y": 8,
      "z": -10,
      "name": "Wood_Lightwood_Roof",
      "rotation": 3
    },
    {
      "x": 3,
      "y": 0,
      "z": -9,
      "name": "Rock_Stone_Cobble"
    },
    {
      "x": 3,
      "y": 1,
      "z": -9,
      "name": "Rock_Crystal_Red_Block"
    },
    {
      "x": 3,
      "y": 2,
      "z": -9,
      "name": "Rock_Crystal_Red_Small",
      "support": 15
    },
    {
      "x": 3,
      "y": 5,
      "z": -9,
      "name": "Plant_Vine_Wall",
      "support": 15,
      "rotation": 3
    },
    {
      "x": 3,
      "y": 6,
      "z": -9,
      "name": "Plant_Vine_Wall",
      "support": 15,
      "rotation": 3
    },
    {
      "x": 3,
      "y": 8,
      "z": -9,
      "name": "Wood_Lightwood_Roof_Hollow",
      "rotation": 3
    },
    {
      "x": 3,
      "y": 0,
      "z": -8,
      "name": "Wood_Softwood_Planks"
    },
    {
      "x": 3,
      "y": 1,
      "z": -8,
      "name": "Rock_Crystal_Red_Block"
    },
    {
      "x": 3,
      "y": 2,
      "z": -8,
      "name": "Rock_Crystal_Red_Block"
    },
    {
      "x": 3,
      "y": 3,
      "z": -8,
      "name": "Cloth_Roof_White_Flap",
      "rotation": 2
    },
    {
      "x": 3,
      "y": 8,
      "z": -8,
      "name": "Wood_Lightwood_Roof_Hollow",
      "rotation": 3
    },
    {
      "x": 3,
      "y": 0,
      "z": -7,
      "name": "Rock_Stone_Cobble"
    },
    {
      "x": 3,
      "y": 1,
      "z": -7,
      "name": "Wood_Softwood_Planks"
    },
    {
      "x": 3,
      "y": 2,
      "z": -7,
      "name": "Wood_Softwood_Beam"
    },
    {
      "x": 3,
      "y": 3,
      "z": -7,
      "name": "Wood_Softwood_Beam"
    },
    {
      "x": 3,
      "y": 4,
      "z": -7,
      "name": "*Cloth_Roof_White_State_Definitions_Corner_Left",
      "rotation": 2
    },
    {
      "x": 3,
      "y": 8,
      "z": -7,
      "name": "Wood_Lightwood_Roof_Hollow",
      "rotation": 3
    },
    {
      "x": 3,
      "y": 0,
      "z": -6,
      "name": "Wood_Lightwood_Planks"
    },
    {
      "x": 3,
      "y": 1,
      "z": -6,
      "name": "Furniture_Village_Counter",
      "support": 15,
      "rotation": 1
    },
    {
      "x": 3,
      "y": 2,
      "z": -6,
      "name": "Aetherhaven_Shop_Spot",
      "components": {
        "Components": {
          "AetherhavenShopSpotBlock": {
            "SpotId": "dc19401d-b32e-440d-b654-9dbc2c100518",
            "TownId": "d87b9d18-a6de-42a7-9697-90f4c2aa0d9f",
            "PlotId": "360971ce-4228-453c-a050-2538b1b6cf61",
            "PlayerControlled": false,
            "LootTableId": "crystal_keeper_blocks",
            "Configured": true
          },
          "PlacedByInteraction": {
            "WhoPlacedUuid": {
              "$binary": "v7RyWIT/TYKnXA2XcxdQtw==",
              "$type": "04"
            }
          }
        }
      },
      "rotation": 3
    },
    {
      "x": 3,
      "y": 4,
      "z": -6,
      "name": "Cloth_Roof_Blue",
      "rotation": 3
    },
    {
      "x": 3,
      "y": 8,
      "z": -6,
      "name": "Wood_Lightwood_Roof_Hollow",
      "rotation": 3
    },
    {
      "x": 3,
      "y": 0,
      "z": -5,
      "name": "Wood_Lightwood_Planks"
    },
    {
      "x": 3,
      "y": 1,
      "z": -5,
      "name": "Furniture_Village_Counter",
      "support": 15,
      "filler": 32,
      "rotation": 1
    },
    {
      "x": 3,
      "y": 2,
      "z": -5,
      "name": "Aetherhaven_Shop_Spot",
      "components": {
        "Components": {
          "AetherhavenShopSpotBlock": {
            "SpotId": "c2d32822-bf5d-447b-8873-5a150bdd0ec7",
            "TownId": "d87b9d18-a6de-42a7-9697-90f4c2aa0d9f",
            "PlotId": "360971ce-4228-453c-a050-2538b1b6cf61",
            "PlayerControlled": false,
            "LootTableId": "crystal_keeper_crystals",
            "Configured": true
          },
          "PlacedByInteraction": {
            "WhoPlacedUuid": {
              "$binary": "v7RyWIT/TYKnXA2XcxdQtw==",
              "$type": "04"
            }
          }
        }
      },
      "rotation": 3
    },
    {
      "x": 3,
      "y": 4,
      "z": -5,
      "name": "Cloth_Roof_White",
      "rotation": 3
    },
    {
      "x": 3,
      "y": 6,
      "z": -5,
      "name": "Plant_Vine_Wall",
      "support": 15,
      "rotation": 3
    },
    {
      "x": 3,
      "y": 8,
      "z": -5,
      "name": "Wood_Lightwood_Roof_Hollow",
      "rotation": 3
    },
    {
      "x": 3,
      "y": 0,
      "z": -4,
      "name": "Wood_Lightwood_Planks"
    },
    {
      "x": 3,
      "y": 1,
      "z": -4,
      "name": "Wood_Softwood_Planks_Half",
      "rotation": 8
    },
    {
      "x": 3,
      "y": 2,
      "z": -4,
      "name": "Aetherhaven_Shop_Spot",
      "components": {
        "Components": {
          "AetherhavenShopSpotBlock": {
            "SpotId": "6d57af81-0a95-4d66-aadb-657e76f82034",
            "TownId": "d87b9d18-a6de-42a7-9697-90f4c2aa0d9f",
            "PlotId": "360971ce-4228-453c-a050-2538b1b6cf61",
            "PlayerControlled": false,
            "LootTableId": "crystal_keeper_crystals",
            "Configured": true
          },
          "PlacedByInteraction": {
            "WhoPlacedUuid": {
              "$binary": "v7RyWIT/TYKnXA2XcxdQtw==",
              "$type": "04"
            }
          }
        }
      },
      "rotation": 3
    },
    {
      "x": 3,
      "y": 4,
      "z": -4,
      "name": "Cloth_Roof_Blue",
      "rotation": 3
    },
    {
      "x": 3,
      "y": 7,
      "z": -4,
      "name": "Wood_Birch_Branch_Corner",
      "support": 15,
      "rotation": 3
    },
    {
      "x": 3,
      "y": 8,
      "z": -4,
      "name": "Wood_Lightwood_Roof",
      "rotation": 3
    },
    {
      "x": 3,
      "y": 0,
      "z": -3,
      "name": "Rock_Stone_Cobble"
    },
    {
      "x": 3,
      "y": 1,
      "z": -3,
      "name": "Wood_Softwood_Planks"
    },
    {
      "x": 3,
      "y": 2,
      "z": -3,
      "name": "Wood_Softwood_Beam"
    },
    {
      "x": 3,
      "y": 3,
      "z": -3,
      "name": "Wood_Softwood_Beam"
    },
    {
      "x": 3,
      "y": 4,
      "z": -3,
      "name": "*Cloth_Roof_White_State_Definitions_Corner_Left",
      "rotation": 3
    },
    {
      "x": 3,
      "y": 8,
      "z": -3,
      "name": "Wood_Lightwood_Roof_Hollow",
      "rotation": 3
    },
    {
      "x": 3,
      "y": 0,
      "z": -2,
      "name": "Wood_Softwood_Planks"
    },
    {
      "x": 3,
      "y": 3,
      "z": -2,
      "name": "Cloth_Roof_White_Flap"
    },
    {
      "x": 3,
      "y": 0,
      "z": -1,
      "name": "Rock_Stone_Cobble"
    },
    {
      "x": 4,
      "y": 0,
      "z": -11,
      "name": "Rock_Stone_Cobble"
    },
    {
      "x": 4,
      "y": 8,
      "z": -11,
      "name": "Wood_Birch_Branch_Corner",
      "support": 15,
      "rotation": 2
    },
    {
      "x": 4,
      "y": 9,
      "z": -11,
      "name": "Wood_Lightwood_Roof",
      "rotation": 3
    },
    {
      "x": 4,
      "y": 0,
      "z": -10,
      "name": "Rock_Stone_Cobble"
    },
    {
      "x": 4,
      "y": 1,
      "z": -10,
      "name": "Wood_Birch_Trunk",
      "support": 15
    },
    {
      "x": 4,
      "y": 2,
      "z": -10,
      "name": "Wood_Birch_Trunk",
      "support": 15
    },
    {
      "x": 4,
      "y": 3,
      "z": -10,
      "name": "Wood_Birch_Trunk",
      "support": 15
    },
    {
      "x": 4,
      "y": 4,
      "z": -10,
      "name": "Wood_Birch_Trunk",
      "support": 15
    },
    {
      "x": 4,
      "y": 5,
      "z": -10,
      "name": "Wood_Birch_Trunk",
      "support": 15
    },
    {
      "x": 4,
      "y": 6,
      "z": -10,
      "name": "Wood_Birch_Trunk",
      "support": 15
    },
    {
      "x": 4,
      "y": 7,
      "z": -10,
      "name": "Wood_Birch_Trunk",
      "support": 15
    },
    {
      "x": 4,
      "y": 8,
      "z": -10,
      "name": "Wood_Birch_Trunk",
      "support": 15
    },
    {
      "x": 4,
      "y": 9,
      "z": -10,
      "name": "Wood_Lightwood_Roof",
      "rotation": 3
    },
    {
      "x": 4,
      "y": 0,
      "z": -9,
      "name": "Rock_Stone_Cobble"
    },
    {
      "x": 4,
      "y": 1,
      "z": -9,
      "name": "Rock_Stone_Brick"
    },
    {
      "x": 4,
      "y": 2,
      "z": -9,
      "name": "*Wood_Village_Wall_White_Full_State_Definitions_Bottom"
    },
    {
      "x": 4,
      "y": 3,
      "z": -9,
      "name": "*Wood_Village_Wall_White_Full_State_Definitions_Top"
    },
    {
      "x": 4,
      "y": 4,
      "z": -9,
      "name": "Wood_Birch_Trunk",
      "support": 15,
      "rotation": 4
    },
    {
      "x": 4,
      "y": 5,
      "z": -9,
      "name": "*Wood_Village_Wall_White_Full_State_Definitions_Bottom"
    },
    {
      "x": 4,
      "y": 6,
      "z": -9,
      "name": "*Wood_Village_Wall_White_Full_State_Definitions_Middle"
    },
    {
      "x": 4,
      "y": 7,
      "z": -9,
      "name": "*Wood_Village_Wall_White_Full_State_Definitions_Top"
    },
    {
      "x": 4,
      "y": 8,
      "z": -9,
      "name": "Wood_Birch_Trunk",
      "support": 15,
      "rotation": 4
    },
    {
      "x": 4,
      "y": 9,
      "z": -9,
      "name": "Wood_Lightwood_Roof",
      "rotation": 3
    },
    {
      "x": 4,
      "y": 0,
      "z": -8,
      "name": "Rock_Stone_Cobble_Mossy"
    },
    {
      "x": 4,
      "y": 1,
      "z": -8,
      "name": "Rock_Stone_Brick"
    },
    {
      "x": 4,
      "y": 2,
      "z": -8,
      "name": "*Wood_Village_Wall_White_Full_State_Definitions_Bottom"
    },
    {
      "x": 4,
      "y": 3,
      "z": -8,
      "name": "*Wood_Village_Wall_White_Full_State_Definitions_Top"
    },
    {
      "x": 4,
      "y": 4,
      "z": -8,
      "name": "Wood_Birch_Trunk",
      "support": 15,
      "rotation": 4
    },
    {
      "x": 4,
      "y": 5,
      "z": -8,
      "name": "Wood_Village_Wall_White_Full"
    },
    {
      "x": 4,
      "y": 6,
      "z": -8,
      "name": "Furniture_Human_Ruins_Window",
      "rotation": 1
    },
    {
      "x": 4,
      "y": 7,
      "z": -8,
      "name": "Wood_Village_Wall_White_Full"
    },
    {
      "x": 4,
      "y": 8,
      "z": -8,
      "name": "Wood_Birch_Trunk",
      "support": 15,
      "rotation": 4
    },
    {
      "x": 4,
      "y": 9,
      "z": -8,
      "name": "Wood_Lightwood_Roof",
      "rotation": 3
    },
    {
      "x": 4,
      "y": 0,
      "z": -7,
      "name": "Rock_Stone_Cobble"
    },
    {
      "x": 4,
      "y": 1,
      "z": -7,
      "name": "Wood_Birch_Trunk",
      "support": 15
    },
    {
      "x": 4,
      "y": 2,
      "z": -7,
      "name": "Wood_Birch_Trunk",
      "support": 15
    },
    {
      "x": 4,
      "y": 3,
      "z": -7,
      "name": "Wood_Birch_Trunk",
      "support": 15
    },
    {
      "x": 4,
      "y": 4,
      "z": -7,
      "name": "Wood_Birch_Trunk",
      "support": 15,
      "rotation": 4
    },
    {
      "x": 4,
      "y": 5,
      "z": -7,
      "name": "*Wood_Village_Wall_White_Full_State_Definitions_Bottom"
    },
    {
      "x": 4,
      "y": 6,
      "z": -7,
      "name": "*Wood_Village_Wall_White_Full_State_Definitions_Middle"
    },
    {
      "x": 4,
      "y": 7,
      "z": -7,
      "name": "*Wood_Village_Wall_White_Full_State_Definitions_Top"
    },
    {
      "x": 4,
      "y": 8,
      "z": -7,
      "name": "Wood_Birch_Trunk",
      "support": 15,
      "rotation": 4
    },
    {
      "x": 4,
      "y": 9,
      "z": -7,
      "name": "Wood_Lightwood_Roof",
      "rotation": 3
    },
    {
      "x": 4,
      "y": 0,
      "z": -6,
      "name": "Wood_Lightwood_Planks"
    },
    {
      "x": 4,
      "y": 4,
      "z": -6,
      "name": "Wood_Birch_Trunk",
      "support": 15,
      "rotation": 4
    },
    {
      "x": 4,
      "y": 5,
      "z": -6,
      "name": "Wood_Village_Wall_White_Full"
    },
    {
      "x": 4,
      "y": 6,
      "z": -6,
      "name": "Furniture_Human_Ruins_Window",
      "rotation": 1
    },
    {
      "x": 4,
      "y": 7,
      "z": -6,
      "name": "Wood_Village_Wall_White_Full"
    },
    {
      "x": 4,
      "y": 8,
      "z": -6,
      "name": "Wood_Birch_Trunk",
      "support": 15,
      "rotation": 4
    },
    {
      "x": 4,
      "y": 9,
      "z": -6,
      "name": "Wood_Lightwood_Roof",
      "rotation": 3
    },
    {
      "x": 4,
      "y": 0,
      "z": -5,
      "name": "Wood_Lightwood_Planks"
    },
    {
      "x": 4,
      "y": 4,
      "z": -5,
      "name": "Wood_Birch_Trunk",
      "support": 15,
      "rotation": 4
    },
    {
      "x": 4,
      "y": 5,
      "z": -5,
      "name": "*Wood_Village_Wall_White_Full_State_Definitions_Bottom"
    },
    {
      "x": 4,
      "y": 6,
      "z": -5,
      "name": "*Wood_Village_Wall_White_Full_State_Definitions_Middle"
    },
    {
      "x": 4,
      "y": 7,
      "z": -5,
      "name": "*Wood_Village_Wall_White_Full_State_Definitions_Top"
    },
    {
      "x": 4,
      "y": 8,
      "z": -5,
      "name": "Wood_Birch_Trunk",
      "support": 15,
      "rotation": 4
    },
    {
      "x": 4,
      "y": 9,
      "z": -5,
      "name": "Wood_Lightwood_Roof",
      "rotation": 3
    },
    {
      "x": 4,
      "y": 0,
      "z": -4,
      "name": "Wood_Lightwood_Planks"
    },
    {
      "x": 4,
      "y": 4,
      "z": -4,
      "name": "Wood_Birch_Trunk",
      "support": 15
    },
    {
      "x": 4,
      "y": 5,
      "z": -4,
      "name": "Wood_Birch_Trunk",
      "support": 15
    },
    {
      "x": 4,
      "y": 6,
      "z": -4,
      "name": "Wood_Birch_Trunk",
      "support": 15
    },
    {
      "x": 4,
      "y": 7,
      "z": -4,
      "name": "Wood_Birch_Trunk",
      "support": 15
    },
    {
      "x": 4,
      "y": 8,
      "z": -4,
      "name": "Wood_Birch_Trunk",
      "support": 15
    },
    {
      "x": 4,
      "y": 9,
      "z": -4,
      "name": "Wood_Lightwood_Roof",
      "rotation": 3
    },
    {
      "x": 4,
      "y": 0,
      "z": -3,
      "name": "Wood_Lightwood_Planks"
    },
    {
      "x": 4,
      "y": 1,
      "z": -3,
      "name": "Wood_Softwood_Planks_Half",
      "rotation": 8
    },
    {
      "x": 4,
      "y": 2,
      "z": -3,
      "name": "Aetherhaven_Shop_Spot",
      "components": {
        "Components": {
          "AetherhavenShopSpotBlock": {
            "SpotId": "ff42973b-0a38-4700-9487-b6271054b103",
            "TownId": "d87b9d18-a6de-42a7-9697-90f4c2aa0d9f",
            "PlotId": "360971ce-4228-453c-a050-2538b1b6cf61",
            "PlayerControlled": false,
            "LootTableId": "crystal_keeper_shards",
            "Configured": true
          },
          "PlacedByInteraction": {
            "WhoPlacedUuid": {
              "$binary": "v7RyWIT/TYKnXA2XcxdQtw==",
              "$type": "04"
            }
          }
        }
      }
    },
    {
      "x": 4,
      "y": 4,
      "z": -3,
      "name": "Cloth_Roof_Blue"
    },
    {
      "x": 4,
      "y": 6,
      "z": -3,
      "name": "Plant_Vine_Wall",
      "support": 15
    },
    {
      "x": 4,
      "y": 7,
      "z": -3,
      "name": "Plant_Vine_Wall",
      "support": 15
    },
    {
      "x": 4,
      "y": 8,
      "z": -3,
      "name": "Wood_Birch_Branch_Corner",
      "support": 15
    },
    {
      "x": 4,
      "y": 9,
      "z": -3,
      "name": "Wood_Lightwood_Roof",
      "rotation": 3
    },
    {
      "x": 4,
      "y": 0,
      "z": -2,
      "name": "Wood_Softwood_Planks"
    },
    {
      "x": 4,
      "y": 3,
      "z": -2,
      "name": "Cloth_Roof_Blue_Flap"
    },
    {
      "x": 4,
      "y": 0,
      "z": -1,
      "name": "Rock_Stone_Cobble"
    },
    {
      "x": 5,
      "y": 0,
      "z": -11,
      "name": "Rock_Stone_Cobble"
    },
    {
      "x": 5,
      "y": 9,
      "z": -11,
      "name": "Wood_Lightwood_Stairs",
      "rotation": 11
    },
    {
      "x": 5,
      "y": 10,
      "z": -11,
      "name": "Wood_Lightwood_Roof",
      "rotation": 3
    },
    {
      "x": 5,
      "y": 0,
      "z": -10,
      "name": "Rock_Stone_Cobble"
    },
    {
      "x": 5,
      "y": 1,
      "z": -10,
      "name": "Rock_Stone_Brick"
    },
    {
      "x": 5,
      "y": 2,
      "z": -10,
      "name": "*Wood_Village_Wall_White_Full_State_Definitions_Bottom"
    },
    {
      "x": 5,
      "y": 3,
      "z": -10,
      "name": "*Wood_Village_Wall_White_Full_State_Definitions_Top"
    },
    {
      "x": 5,
      "y": 4,
      "z": -10,
      "name": "Wood_Birch_Trunk",
      "support": 15,
      "rotation": 5
    },
    {
      "x": 5,
      "y": 5,
      "z": -10,
      "name": "*Wood_Village_Wall_White_Full_State_Definitions_Bottom"
    },
    {
      "x": 5,
      "y": 6,
      "z": -10,
      "name": "*Wood_Village_Wall_White_Full_State_Definitions_Middle"
    },
    {
      "x": 5,
      "y": 7,
      "z": -10,
      "name": "*Wood_Village_Wall_White_Full_State_Definitions_Top"
    },
    {
      "x": 5,
      "y": 8,
      "z": -10,
      "name": "Wood_Birch_Trunk",
      "support": 15,
      "rotation": 5
    },
    {
      "x": 5,
      "y": 9,
      "z": -10,
      "name": "Wood_Village_Wall_White_Full"
    },
    {
      "x": 5,
      "y": 10,
      "z": -10,
      "name": "Wood_Lightwood_Roof",
      "rotation": 3
    },
    {
      "x": 5,
      "y": 0,
      "z": -9,
      "name": "Wood_Lightwood_Planks"
    },
    {
      "x": 5,
      "y": 1,
      "z": -9,
      "name": "Furniture_Tavern_Candle",
      "support": 15
    },
    {
      "x": 5,
      "y": 4,
      "z": -9,
      "name": "Wood_Lightwood_Planks"
    },
    {
      "x": 5,
      "y": 9,
      "z": -9,
      "name": "Wood_Lightwood_Stairs",
      "rotation": 11
    },
    {
      "x": 5,
      "y": 10,
      "z": -9,
      "name": "Wood_Lightwood_Roof",
      "rotation": 3
    },
    {
      "x": 5,
      "y": 0,
      "z": -8,
      "name": "Wood_Lightwood_Planks"
    },
    {
      "x": 5,
      "y": 1,
      "z": -8,
      "name": "Rock_Crystal_White_Small",
      "support": 15
    },
    {
      "x": 5,
      "y": 4,
      "z": -8,
      "name": "Wood_Lightwood_Planks"
    },
    {
      "x": 5,
      "y": 9,
      "z": -8,
      "name": "Wood_Lightwood_Stairs",
      "rotation": 11
    },
    {
      "x": 5,
      "y": 10,
      "z": -8,
      "name": "Wood_Lightwood_Roof",
      "rotation": 3
    },
    {
      "x": 5,
      "y": 0,
      "z": -7,
      "name": "Wood_Lightwood_Planks"
    },
    {
      "x": 5,
      "y": 1,
      "z": -7,
      "name": "Aetherhaven_Management_Block",
      "components": {
        "Components": {
          "AetherhavenManagementBlock": {
            "PlotId": "360971ce-4228-453c-a050-2538b1b6cf61",
            "TownId": "d87b9d18-a6de-42a7-9697-90f4c2aa0d9f"
          }
        }
      },
      "rotation": 1
    },
    {
      "x": 5,
      "y": 4,
      "z": -7,
      "name": "Wood_Lightwood_Planks"
    },
    {
      "x": 5,
      "y": 9,
      "z": -7,
      "name": "Wood_Lightwood_Stairs",
      "rotation": 11
    },
    {
      "x": 5,
      "y": 10,
      "z": -7,
      "name": "Wood_Lightwood_Roof",
      "rotation": 3
    },
    {
      "x": 5,
      "y": 0,
      "z": -6,
      "name": "Wood_Lightwood_Planks"
    },
    {
      "x": 5,
      "y": 4,
      "z": -6,
      "name": "Wood_Lightwood_Planks"
    },
    {
      "x": 5,
      "y": 9,
      "z": -6,
      "name": "Wood_Lightwood_Stairs",
      "rotation": 11
    },
    {
      "x": 5,
      "y": 10,
      "z": -6,
      "name": "Wood_Lightwood_Roof",
      "rotation": 3
    },
    {
      "x": 5,
      "y": 0,
      "z": -5,
      "name": "Wood_Lightwood_Planks"
    },
    {
      "x": 5,
      "y": 4,
      "z": -5,
      "name": "Wood_Lightwood_Planks"
    },
    {
      "x": 5,
      "y": 9,
      "z": -5,
      "name": "Wood_Lightwood_Stairs",
      "rotation": 11
    },
    {
      "x": 5,
      "y": 10,
      "z": -5,
      "name": "Wood_Lightwood_Roof",
      "rotation": 3
    },
    {
      "x": 5,
      "y": 0,
      "z": -4,
      "name": "Wood_Lightwood_Planks"
    },
    {
      "x": 5,
      "y": 4,
      "z": -4,
      "name": "Wood_Birch_Trunk",
      "support": 15,
      "rotation": 5
    },
    {
      "x": 5,
      "y": 5,
      "z": -4,
      "name": "*Wood_Village_Wall_White_Full_State_Definitions_Bottom"
    },
    {
      "x": 5,
      "y": 6,
      "z": -4,
      "name": "*Wood_Village_Wall_White_Full_State_Definitions_Middle"
    },
    {
      "x": 5,
      "y": 7,
      "z": -4,
      "name": "*Wood_Village_Wall_White_Full_State_Definitions_Top"
    },
    {
      "x": 5,
      "y": 8,
      "z": -4,
      "name": "Wood_Birch_Trunk",
      "support": 15,
      "rotation": 5
    },
    {
      "x": 5,
      "y": 9,
      "z": -4,
      "name": "Wood_Village_Wall_White_Full"
    },
    {
      "x": 5,
      "y": 10,
      "z": -4,
      "name": "Wood_Lightwood_Roof",
      "rotation": 3
    },
    {
      "x": 5,
      "y": 0,
      "z": -3,
      "name": "Wood_Lightwood_Planks"
    },
    {
      "x": 5,
      "y": 1,
      "z": -3,
      "name": "Furniture_Village_Counter",
      "support": 15,
      "rotation": 2
    },
    {
      "x": 5,
      "y": 2,
      "z": -3,
      "name": "Aetherhaven_Shop_Spot",
      "components": {
        "Components": {
          "AetherhavenShopSpotBlock": {
            "SpotId": "19cc5f35-442e-497e-a7cd-3824a0d0591e",
            "TownId": "d87b9d18-a6de-42a7-9697-90f4c2aa0d9f",
            "PlotId": "360971ce-4228-453c-a050-2538b1b6cf61",
            "PlayerControlled": false,
            "LootTableId": "crystal_keeper_shards",
            "Configured": true
          },
          "PlacedByInteraction": {
            "WhoPlacedUuid": {
              "$binary": "v7RyWIT/TYKnXA2XcxdQtw==",
              "$type": "04"
            }
          }
        }
      }
    },
    {
      "x": 5,
      "y": 4,
      "z": -3,
      "name": "Cloth_Roof_White"
    },
    {
      "x": 5,
      "y": 9,
      "z": -3,
      "name": "Wood_Lightwood_Stairs",
      "rotation": 11
    },
    {
      "x": 5,
      "y": 10,
      "z": -3,
      "name": "Wood_Lightwood_Roof",
      "rotation": 3
    },
    {
      "x": 5,
      "y": 0,
      "z": -2,
      "name": "Wood_Softwood_Planks"
    },
    {
      "x": 5,
      "y": 3,
      "z": -2,
      "name": "Cloth_Roof_White_Flap"
    },
    {
      "x": 5,
      "y": 0,
      "z": -1,
      "name": "Rock_Stone_Cobble"
    },
    {
      "x": 6,
      "y": 0,
      "z": -11,
      "name": "Rock_Stone_Cobble_Mossy"
    },
    {
      "x": 6,
      "y": 1,
      "z": -11,
      "name": "Rock_Crystal_Yellow_Medium",
      "support": 15,
      "rotation": 7
    },
    {
      "x": 6,
      "y": 3,
      "z": -11,
      "name": "Plant_Vine_Wall",
      "support": 15,
      "rotation": 2
    },
    {
      "x": 6,
      "y": 10,
      "z": -11,
      "name": "Wood_Lightwood_Planks"
    },
    {
      "x": 6,
      "y": 11,
      "z": -11,
      "name": "Wood_Lightwood_Roof_Flat",
      "rotation": 1
    },
    {
      "x": 6,
      "y": 0,
      "z": -10,
      "name": "Rock_Stone_Cobble_Mossy"
    },
    {
      "x": 6,
      "y": 1,
      "z": -10,
      "name": "Rock_Stone_Brick"
    },
    {
      "x": 6,
      "y": 2,
      "z": -10,
      "name": "*Wood_Village_Wall_White_Full_State_Definitions_Bottom"
    },
    {
      "x": 6,
      "y": 3,
      "z": -10,
      "name": "*Wood_Village_Wall_White_Full_State_Definitions_Top"
    },
    {
      "x": 6,
      "y": 4,
      "z": -10,
      "name": "Wood_Birch_Trunk",
      "support": 15,
      "rotation": 5
    },
    {
      "x": 6,
      "y": 5,
      "z": -10,
      "name": "Wood_Village_Wall_White_Full"
    },
    {
      "x": 6,
      "y": 6,
      "z": -10,
      "name": "Furniture_Human_Ruins_Window"
    },
    {
      "x": 6,
      "y": 7,
      "z": -10,
      "name": "Wood_Village_Wall_White_Full"
    },
    {
      "x": 6,
      "y": 8,
      "z": -10,
      "name": "Wood_Birch_Trunk",
      "support": 15,
      "rotation": 5
    },
    {
      "x": 6,
      "y": 9,
      "z": -10,
      "name": "*Wood_Village_Wall_White_Full_State_Definitions_Bottom"
    },
    {
      "x": 6,
      "y": 10,
      "z": -10,
      "name": "*Wood_Village_Wall_White_Full_State_Definitions_Top"
    },
    {
      "x": 6,
      "y": 11,
      "z": -10,
      "name": "Wood_Lightwood_Roof_Flat",
      "rotation": 3
    },
    {
      "x": 6,
      "y": 0,
      "z": -9,
      "name": "Wood_Lightwood_Planks"
    },
    {
      "x": 6,
      "y": 1,
      "z": -9,
      "name": "Furniture_Village_Crate"
    },
    {
      "x": 6,
      "y": 2,
      "z": -9,
      "name": "Rock_Crystal_Blue_Small",
      "support": 15
    },
    {
      "x": 6,
      "y": 3,
      "z": -9,
      "name": "Wood_Lightwood_Stairs",
      "rotation": 9
    },
    {
      "x": 6,
      "y": 4,
      "z": -9,
      "name": "Wood_Lightwood_Stairs",
      "rotation": 1
    },
    {
      "x": 6,
      "y": 10,
      "z": -9,
      "name": "Wood_Lightwood_Planks"
    },
    {
      "x": 6,
      "y": 11,
      "z": -9,
      "name": "Wood_Lightwood_Roof_Flat",
      "rotation": 3
    },
    {
      "x": 6,
      "y": 0,
      "z": -8,
      "name": "Wood_Lightwood_Planks"
    },
    {
      "x": 6,
      "y": 4,
      "z": -8,
      "name": "Wood_Lightwood_Planks"
    },
    {
      "x": 6,
      "y": 10,
      "z": -8,
      "name": "Wood_Lightwood_Planks"
    },
    {
      "x": 6,
      "y": 11,
      "z": -8,
      "name": "Wood_Lightwood_Roof_Flat",
      "rotation": 3
    },
    {
      "x": 6,
      "y": 0,
      "z": -7,
      "name": "Wood_Lightwood_Planks"
    },
    {
      "x": 6,
      "y": 4,
      "z": -7,
      "name": "Wood_Lightwood_Planks"
    },
    {
      "x": 6,
      "y": 7,
      "z": -7,
      "name": "Furniture_Temple_Light_Lantern_Ceiling",
      "support": 15
    },
    {
      "x": 6,
      "y": 8,
      "z": -7,
      "name": "Deco_Rope",
      "support": 15
    },
    {
      "x": 6,
      "y": 9,
      "z": -7,
      "name": "Deco_Rope",
      "support": 15
    },
    {
      "x": 6,
      "y": 10,
      "z": -7,
      "name": "Wood_Lightwood_Planks"
    },
    {
      "x": 6,
      "y": 11,
      "z": -7,
      "name": "Wood_Lightwood_Roof_Flat",
      "rotation": 3
    },
    {
      "x": 6,
      "y": 0,
      "z": -6,
      "name": "Wood_Lightwood_Planks"
    },
    {
      "x": 6,
      "y": 4,
      "z": -6,
      "name": "Wood_Lightwood_Planks"
    },
    {
      "x": 6,
      "y": 10,
      "z": -6,
      "name": "Wood_Lightwood_Planks"
    },
    {
      "x": 6,
      "y": 11,
      "z": -6,
      "name": "Wood_Lightwood_Roof_Flat",
      "rotation": 3
    },
    {
      "x": 6,
      "y": 0,
      "z": -5,
      "name": "Wood_Lightwood_Planks"
    },
    {
      "x": 6,
      "y": 4,
      "z": -5,
      "name": "Wood_Lightwood_Planks"
    },
    {
      "x": 6,
      "y": 10,
      "z": -5,
      "name": "Wood_Lightwood_Planks"
    },
    {
      "x": 6,
      "y": 11,
      "z": -5,
      "name": "Wood_Lightwood_Roof_Flat",
      "rotation": 3
    },
    {
      "x": 6,
      "y": 0,
      "z": -4,
      "name": "Wood_Lightwood_Planks"
    },
    {
      "x": 6,
      "y": 4,
      "z": -4,
      "name": "Wood_Birch_Trunk",
      "support": 15,
      "rotation": 5
    },
    {
      "x": 6,
      "y": 5,
      "z": -4,
      "name": "Wood_Village_Wall_White_Full"
    },
    {
      "x": 6,
      "y": 6,
      "z": -4,
      "name": "Furniture_Human_Ruins_Window"
    },
    {
      "x": 6,
      "y": 7,
      "z": -4,
      "name": "Wood_Village_Wall_White_Full"
    },
    {
      "x": 6,
      "y": 8,
      "z": -4,
      "name": "Wood_Birch_Trunk",
      "support": 15,
      "rotation": 5
    },
    {
      "x": 6,
      "y": 9,
      "z": -4,
      "name": "*Wood_Village_Wall_White_Full_State_Definitions_Bottom"
    },
    {
      "x": 6,
      "y": 10,
      "z": -4,
      "name": "*Wood_Village_Wall_White_Full_State_Definitions_Top"
    },
    {
      "x": 6,
      "y": 11,
      "z": -4,
      "name": "Wood_Lightwood_Roof_Flat",
      "rotation": 3
    },
    {
      "x": 6,
      "y": 0,
      "z": -3,
      "name": "Wood_Lightwood_Planks"
    },
    {
      "x": 6,
      "y": 1,
      "z": -3,
      "name": "Furniture_Village_Counter",
      "support": 15,
      "filler": 1,
      "rotation": 2
    },
    {
      "x": 6,
      "y": 2,
      "z": -3,
      "name": "Aetherhaven_Shop_Spot",
      "components": {
        "Components": {
          "AetherhavenShopSpotBlock": {
            "SpotId": "08016a73-c96f-4fd0-9b8c-3d1e88777934",
            "TownId": "d87b9d18-a6de-42a7-9697-90f4c2aa0d9f",
            "PlotId": "360971ce-4228-453c-a050-2538b1b6cf61",
            "PlayerControlled": false,
            "LootTableId": "crystal_keeper_shards",
            "Configured": true
          },
          "PlacedByInteraction": {
            "WhoPlacedUuid": {
              "$binary": "v7RyWIT/TYKnXA2XcxdQtw==",
              "$type": "04"
            }
          }
        }
      }
    },
    {
      "x": 6,
      "y": 4,
      "z": -3,
      "name": "Cloth_Roof_Blue"
    },
    {
      "x": 6,
      "y": 10,
      "z": -3,
      "name": "Wood_Lightwood_Planks"
    },
    {
      "x": 6,
      "y": 11,
      "z": -3,
      "name": "Wood_Lightwood_Roof_Flat",
      "rotation": 2
    },
    {
      "x": 6,
      "y": 0,
      "z": -2,
      "name": "Wood_Softwood_Planks"
    },
    {
      "x": 6,
      "y": 3,
      "z": -2,
      "name": "Cloth_Roof_Blue_Flap"
    },
    {
      "x": 6,
      "y": 0,
      "z": -1,
      "name": "Rock_Stone_Cobble"
    },
    {
      "x": 7,
      "y": 0,
      "z": -11,
      "name": "Rock_Stone_Cobble_Mossy"
    },
    {
      "x": 7,
      "y": 1,
      "z": -11,
      "name": "Rock_Crystal_Yellow_Block"
    },
    {
      "x": 7,
      "y": 9,
      "z": -11,
      "name": "Wood_Lightwood_Stairs",
      "rotation": 9
    },
    {
      "x": 7,
      "y": 10,
      "z": -11,
      "name": "Wood_Lightwood_Roof",
      "rotation": 1
    },
    {
      "x": 7,
      "y": 0,
      "z": -10,
      "name": "Rock_Stone_Cobble"
    },
    {
      "x": 7,
      "y": 1,
      "z": -10,
      "name": "Rock_Stone_Brick"
    },
    {
      "x": 7,
      "y": 2,
      "z": -10,
      "name": "*Wood_Village_Wall_White_Full_State_Definitions_Bottom"
    },
    {
      "x": 7,
      "y": 3,
      "z": -10,
      "name": "*Wood_Village_Wall_White_Full_State_Definitions_Top"
    },
    {
      "x": 7,
      "y": 4,
      "z": -10,
      "name": "Wood_Birch_Trunk",
      "support": 15,
      "rotation": 5
    },
    {
      "x": 7,
      "y": 5,
      "z": -10,
      "name": "*Wood_Village_Wall_White_Full_State_Definitions_Bottom"
    },
    {
      "x": 7,
      "y": 6,
      "z": -10,
      "name": "*Wood_Village_Wall_White_Full_State_Definitions_Middle"
    },
    {
      "x": 7,
      "y": 7,
      "z": -10,
      "name": "*Wood_Village_Wall_White_Full_State_Definitions_Top"
    },
    {
      "x": 7,
      "y": 8,
      "z": -10,
      "name": "Wood_Birch_Trunk",
      "support": 15,
      "rotation": 5
    },
    {
      "x": 7,
      "y": 9,
      "z": -10,
      "name": "Wood_Village_Wall_White_Full"
    },
    {
      "x": 7,
      "y": 10,
      "z": -10,
      "name": "Wood_Lightwood_Roof",
      "rotation": 1
    },
    {
      "x": 7,
      "y": 0,
      "z": -9,
      "name": "Wood_Lightwood_Planks"
    },
    {
      "x": 7,
      "y": 1,
      "z": -9,
      "name": "Furniture_Tavern_Barrel",
      "support": 15
    },
    {
      "x": 7,
      "y": 2,
      "z": -9,
      "name": "Wood_Lightwood_Stairs",
      "rotation": 9
    },
    {
      "x": 7,
      "y": 3,
      "z": -9,
      "name": "Wood_Lightwood_Stairs",
      "rotation": 1
    },
    {
      "x": 7,
      "y": 9,
      "z": -9,
      "name": "Wood_Lightwood_Stairs",
      "rotation": 9
    },
    {
      "x": 7,
      "y": 10,
      "z": -9,
      "name": "Wood_Lightwood_Roof",
      "rotation": 1
    },
    {
      "x": 7,
      "y": 0,
      "z": -8,
      "name": "Wood_Lightwood_Planks"
    },
    {
      "x": 7,
      "y": 4,
      "z": -8,
      "name": "Wood_Lightwood_Planks"
    },
    {
      "x": 7,
      "y": 9,
      "z": -8,
      "name": "Wood_Lightwood_Stairs",
      "rotation": 9
    },
    {
      "x": 7,
      "y": 10,
      "z": -8,
      "name": "Wood_Lightwood_Roof",
      "rotation": 1
    },
    {
      "x": 7,
      "y": 0,
      "z": -7,
      "name": "Wood_Lightwood_Planks"
    },
    {
      "x": 7,
      "y": 4,
      "z": -7,
      "name": "Wood_Lightwood_Planks"
    },
    {
      "x": 7,
      "y": 9,
      "z": -7,
      "name": "Wood_Lightwood_Stairs",
      "rotation": 9
    },
    {
      "x": 7,
      "y": 10,
      "z": -7,
      "name": "Wood_Lightwood_Roof",
      "rotation": 1
    },
    {
      "x": 7,
      "y": 0,
      "z": -6,
      "name": "Wood_Lightwood_Planks"
    },
    {
      "x": 7,
      "y": 4,
      "z": -6,
      "name": "Wood_Lightwood_Planks"
    },
    {
      "x": 7,
      "y": 9,
      "z": -6,
      "name": "Wood_Lightwood_Stairs",
      "rotation": 9
    },
    {
      "x": 7,
      "y": 10,
      "z": -6,
      "name": "Wood_Lightwood_Roof",
      "rotation": 1
    },
    {
      "x": 7,
      "y": 0,
      "z": -5,
      "name": "Wood_Lightwood_Planks"
    },
    {
      "x": 7,
      "y": 4,
      "z": -5,
      "name": "Wood_Lightwood_Planks"
    },
    {
      "x": 7,
      "y": 9,
      "z": -5,
      "name": "Wood_Lightwood_Stairs",
      "rotation": 9
    },
    {
      "x": 7,
      "y": 10,
      "z": -5,
      "name": "Wood_Lightwood_Roof",
      "rotation": 1
    },
    {
      "x": 7,
      "y": 0,
      "z": -4,
      "name": "Rock_Stone_Cobble"
    },
    {
      "x": 7,
      "y": 1,
      "z": -4,
      "name": "Wood_Birch_Trunk",
      "support": 15
    },
    {
      "x": 7,
      "y": 2,
      "z": -4,
      "name": "Wood_Birch_Trunk",
      "support": 15
    },
    {
      "x": 7,
      "y": 3,
      "z": -4,
      "name": "Wood_Birch_Trunk",
      "support": 15
    },
    {
      "x": 7,
      "y": 4,
      "z": -4,
      "name": "Wood_Birch_Trunk",
      "support": 15
    },
    {
      "x": 7,
      "y": 5,
      "z": -4,
      "name": "*Wood_Village_Wall_White_Full_State_Definitions_Bottom"
    },
    {
      "x": 7,
      "y": 6,
      "z": -4,
      "name": "*Wood_Village_Wall_White_Full_State_Definitions_Middle"
    },
    {
      "x": 7,
      "y": 7,
      "z": -4,
      "name": "*Wood_Village_Wall_White_Full_State_Definitions_Top"
    },
    {
      "x": 7,
      "y": 8,
      "z": -4,
      "name": "Wood_Birch_Trunk",
      "support": 15,
      "rotation": 5
    },
    {
      "x": 7,
      "y": 9,
      "z": -4,
      "name": "Wood_Village_Wall_White_Full"
    },
    {
      "x": 7,
      "y": 10,
      "z": -4,
      "name": "Wood_Lightwood_Roof",
      "rotation": 1
    },
    {
      "x": 7,
      "y": 0,
      "z": -3,
      "name": "Rock_Stone_Cobble"
    },
    {
      "x": 7,
      "y": 1,
      "z": -3,
      "name": "Wood_Softwood_Planks"
    },
    {
      "x": 7,
      "y": 2,
      "z": -3,
      "name": "Wood_Softwood_Beam"
    },
    {
      "x": 7,
      "y": 3,
      "z": -3,
      "name": "Wood_Softwood_Beam"
    },
    {
      "x": 7,
      "y": 4,
      "z": -3,
      "name": "*Cloth_Roof_White_State_Definitions_Corner_Right",
      "rotation": 1
    },
    {
      "x": 7,
      "y": 8,
      "z": -3,
      "name": "Plant_Vine_Wall",
      "support": 15
    },
    {
      "x": 7,
      "y": 9,
      "z": -3,
      "name": "Wood_Lightwood_Stairs",
      "rotation": 9
    },
    {
      "x": 7,
      "y": 10,
      "z": -3,
      "name": "Wood_Lightwood_Roof",
      "rotation": 1
    },
    {
      "x": 7,
      "y": 0,
      "z": -2,
      "name": "Wood_Softwood_Planks"
    },
    {
      "x": 7,
      "y": 3,
      "z": -2,
      "name": "Cloth_Roof_White_Flap"
    },
    {
      "x": 7,
      "y": 0,
      "z": -1,
      "name": "Rock_Stone_Cobble"
    },
    {
      "x": 8,
      "y": 0,
      "z": -11,
      "name": "Rock_Stone_Cobble"
    },
    {
      "x": 8,
      "y": 1,
      "z": -11,
      "name": "Rock_Crystal_Yellow_Block"
    },
    {
      "x": 8,
      "y": 2,
      "z": -11,
      "name": "Rock_Crystal_Yellow_Large",
      "support": 15
    },
    {
      "x": 8,
      "y": 5,
      "z": -11,
      "name": "Plant_Vine_Wall",
      "support": 15,
      "rotation": 2
    },
    {
      "x": 8,
      "y": 6,
      "z": -11,
      "name": "Plant_Vine_Wall",
      "support": 15,
      "rotation": 2
    },
    {
      "x": 8,
      "y": 8,
      "z": -11,
      "name": "Wood_Lightwood_Stairs",
      "rotation": 9
    },
    {
      "x": 8,
      "y": 9,
      "z": -11,
      "name": "Wood_Lightwood_Roof",
      "rotation": 1
    },
    {
      "x": 8,
      "y": 0,
      "z": -10,
      "name": "Rock_Stone_Cobble"
    },
    {
      "x": 8,
      "y": 1,
      "z": -10,
      "name": "Wood_Birch_Trunk",
      "support": 15
    },
    {
      "x": 8,
      "y": 2,
      "z": -10,
      "name": "Wood_Birch_Trunk",
      "support": 15
    },
    {
      "x": 8,
      "y": 3,
      "z": -10,
      "name": "Wood_Birch_Trunk",
      "support": 15
    },
    {
      "x": 8,
      "y": 4,
      "z": -10,
      "name": "Wood_Birch_Trunk",
      "support": 15
    },
    {
      "x": 8,
      "y": 5,
      "z": -10,
      "name": "Wood_Birch_Trunk",
      "support": 15
    },
    {
      "x": 8,
      "y": 6,
      "z": -10,
      "name": "Wood_Birch_Trunk",
      "support": 15
    },
    {
      "x": 8,
      "y": 7,
      "z": -10,
      "name": "Wood_Birch_Trunk",
      "support": 15
    },
    {
      "x": 8,
      "y": 8,
      "z": -10,
      "name": "Wood_Birch_Trunk",
      "support": 15
    },
    {
      "x": 8,
      "y": 9,
      "z": -10,
      "name": "Wood_Lightwood_Roof",
      "rotation": 1
    },
    {
      "x": 8,
      "y": 0,
      "z": -9,
      "name": "Wood_Lightwood_Planks"
    },
    {
      "x": 8,
      "y": 1,
      "z": -9,
      "name": "Wood_Lightwood_Stairs",
      "rotation": 9
    },
    {
      "x": 8,
      "y": 2,
      "z": -9,
      "name": "Wood_Lightwood_Stairs",
      "rotation": 1
    },
    {
      "x": 8,
      "y": 7,
      "z": -9,
      "name": "Wood_Lightwood_Stairs",
      "rotation": 9
    },
    {
      "x": 8,
      "y": 8,
      "z": -9,
      "name": "Wood_Birch_Trunk",
      "support": 15,
      "rotation": 4
    },
    {
      "x": 8,
      "y": 9,
      "z": -9,
      "name": "Wood_Lightwood_Roof",
      "rotation": 1
    },
    {
      "x": 8,
      "y": 0,
      "z": -8,
      "name": "Wood_Lightwood_Planks"
    },
    {
      "x": 8,
      "y": 4,
      "z": -8,
      "name": "Wood_Lightwood_Planks"
    },
    {
      "x": 8,
      "y": 7,
      "z": -8,
      "name": "Wood_Lightwood_Stairs",
      "rotation": 9
    },
    {
      "x": 8,
      "y": 8,
      "z": -8,
      "name": "Wood_Birch_Trunk",
      "support": 15,
      "rotation": 4
    },
    {
      "x": 8,
      "y": 9,
      "z": -8,
      "name": "Wood_Lightwood_Roof",
      "rotation": 1
    },
    {
      "x": 8,
      "y": 0,
      "z": -7,
      "name": "Wood_Lightwood_Planks"
    },
    {
      "x": 8,
      "y": 4,
      "z": -7,
      "name": "Wood_Lightwood_Planks"
    },
    {
      "x": 8,
      "y": 5,
      "z": -7,
      "name": "Rock_Crystal_Green_Block"
    },
    {
      "x": 8,
      "y": 7,
      "z": -7,
      "name": "Wood_Lightwood_Stairs",
      "rotation": 9
    },
    {
      "x": 8,
      "y": 8,
      "z": -7,
      "name": "Wood_Birch_Trunk",
      "support": 15,
      "rotation": 4
    },
    {
      "x": 8,
      "y": 9,
      "z": -7,
      "name": "Wood_Lightwood_Roof",
      "rotation": 1
    },
    {
      "x": 8,
      "y": 0,
      "z": -6,
      "name": "Wood_Lightwood_Planks"
    },
    {
      "x": 8,
      "y": 4,
      "z": -6,
      "name": "Wood_Lightwood_Planks"
    },
    {
      "x": 8,
      "y": 5,
      "z": -6,
      "name": "Rock_Crystal_Green_Block"
    },
    {
      "x": 8,
      "y": 7,
      "z": -6,
      "name": "Wood_Lightwood_Stairs",
      "rotation": 9
    },
    {
      "x": 8,
      "y": 8,
      "z": -6,
      "name": "Wood_Birch_Trunk",
      "support": 15,
      "rotation": 4
    },
    {
      "x": 8,
      "y": 9,
      "z": -6,
      "name": "Wood_Lightwood_Roof",
      "rotation": 1
    },
    {
      "x": 8,
      "y": 0,
      "z": -5,
      "name": "Wood_Lightwood_Planks"
    },
    {
      "x": 8,
      "y": 1,
      "z": -5,
      "name": "Furniture_Tavern_Candle",
      "support": 15
    },
    {
      "x": 8,
      "y": 4,
      "z": -5,
      "name": "Wood_Lightwood_Planks"
    },
    {
      "x": 8,
      "y": 7,
      "z": -5,
      "name": "Wood_Lightwood_Stairs",
      "rotation": 9
    },
    {
      "x": 8,
      "y": 8,
      "z": -5,
      "name": "Wood_Birch_Trunk",
      "support": 15,
      "rotation": 4
    },
    {
      "x": 8,
      "y": 9,
      "z": -5,
      "name": "Wood_Lightwood_Roof",
      "rotation": 1
    },
    {
      "x": 8,
      "y": 0,
      "z": -4,
      "name": "Rock_Stone_Cobble"
    },
    {
      "x": 8,
      "y": 1,
      "z": -4,
      "name": "Rock_Stone_Brick"
    },
    {
      "x": 8,
      "y": 2,
      "z": -4,
      "name": "*Wood_Village_Wall_White_Full_State_Definitions_Bottom"
    },
    {
      "x": 8,
      "y": 3,
      "z": -4,
      "name": "*Wood_Village_Wall_White_Full_State_Definitions_Top"
    },
    {
      "x": 8,
      "y": 4,
      "z": -4,
      "name": "Wood_Birch_Trunk",
      "support": 15,
      "rotation": 5
    },
    {
      "x": 8,
      "y": 5,
      "z": -4,
      "name": "Wood_Birch_Trunk",
      "support": 15
    },
    {
      "x": 8,
      "y": 6,
      "z": -4,
      "name": "Wood_Birch_Trunk",
      "support": 15
    },
    {
      "x": 8,
      "y": 7,
      "z": -4,
      "name": "Wood_Birch_Trunk",
      "support": 15
    },
    {
      "x": 8,
      "y": 8,
      "z": -4,
      "name": "Wood_Birch_Trunk",
      "support": 15
    },
    {
      "x": 8,
      "y": 9,
      "z": -4,
      "name": "Wood_Lightwood_Roof",
      "rotation": 1
    },
    {
      "x": 8,
      "y": 0,
      "z": -3,
      "name": "Wood_Softwood_Planks"
    },
    {
      "x": 8,
      "y": 3,
      "z": -3,
      "name": "Cloth_Roof_White_Flap",
      "rotation": 1
    },
    {
      "x": 8,
      "y": 7,
      "z": -3,
      "name": "Wood_Lightwood_Stairs",
      "rotation": 9
    },
    {
      "x": 8,
      "y": 8,
      "z": -3,
      "name": "Wood_Lightwood_Planks"
    },
    {
      "x": 8,
      "y": 9,
      "z": -3,
      "name": "Wood_Lightwood_Roof",
      "rotation": 1
    },
    {
      "x": 8,
      "y": 0,
      "z": -2,
      "name": "Rock_Stone_Cobble"
    },
    {
      "x": 8,
      "y": 0,
      "z": -1,
      "name": "Rock_Stone_Cobble"
    },
    {
      "x": 9,
      "y": 0,
      "z": -11,
      "name": "Rock_Stone_Cobble"
    },
    {
      "x": 9,
      "y": 7,
      "z": -11,
      "name": "Wood_Lightwood_Roof_Steep",
      "rotation": 1
    },
    {
      "x": 9,
      "y": 8,
      "z": -11,
      "name": "Wood_Lightwood_Roof_Steep",
      "filler": 1024,
      "rotation": 1
    },
    {
      "x": 9,
      "y": 0,
      "z": -10,
      "name": "Rock_Stone_Cobble"
    },
    {
      "x": 9,
      "y": 1,
      "z": -10,
      "name": "Rock_Stone_Brick"
    },
    {
      "x": 9,
      "y": 2,
      "z": -10,
      "name": "*Wood_Village_Wall_White_Full_State_Definitions_Bottom"
    },
    {
      "x": 9,
      "y": 3,
      "z": -10,
      "name": "*Wood_Village_Wall_White_Full_State_Definitions_Top"
    },
    {
      "x": 9,
      "y": 4,
      "z": -10,
      "name": "Wood_Birch_Trunk",
      "support": 15,
      "rotation": 5
    },
    {
      "x": 9,
      "y": 5,
      "z": -10,
      "name": "*Wood_Village_Wall_White_Full_State_Definitions_Bottom"
    },
    {
      "x": 9,
      "y": 6,
      "z": -10,
      "name": "*Wood_Village_Wall_White_Full_State_Definitions_Top"
    },
    {
      "x": 9,
      "y": 7,
      "z": -10,
      "name": "Wood_Lightwood_Roof_Steep",
      "rotation": 1
    },
    {
      "x": 9,
      "y": 8,
      "z": -10,
      "name": "Wood_Lightwood_Roof_Steep",
      "filler": 1024,
      "rotation": 1
    },
    {
      "x": 9,
      "y": 0,
      "z": -9,
      "name": "Wood_Lightwood_Planks"
    },
    {
      "x": 9,
      "y": 1,
      "z": -9,
      "name": "Wood_Lightwood_Stairs",
      "rotation": 1
    },
    {
      "x": 9,
      "y": 7,
      "z": -9,
      "name": "Wood_Lightwood_Roof_Steep",
      "rotation": 1
    },
    {
      "x": 9,
      "y": 8,
      "z": -9,
      "name": "Wood_Lightwood_Roof_Steep",
      "filler": 1024,
      "rotation": 1
    },
    {
      "x": 9,
      "y": 0,
      "z": -8,
      "name": "Wood_Lightwood_Planks"
    },
    {
      "x": 9,
      "y": 4,
      "z": -8,
      "name": "Wood_Lightwood_Planks"
    },
    {
      "x": 9,
      "y": 5,
      "z": -8,
      "name": "Rock_Crystal_Green_Block",
      "rotation": 4
    },
    {
      "x": 9,
      "y": 6,
      "z": -8,
      "name": "Rock_Crystal_Green_Block"
    },
    {
      "x": 9,
      "y": 7,
      "z": -8,
      "name": "Rock_Crystal_Green_Block",
      "rotation": 4
    },
    {
      "x": 9,
      "y": 8,
      "z": -8,
      "name": "Rock_Crystal_Green_Block"
    },
    {
      "x": 9,
      "y": 9,
      "z": -8,
      "name": "Rock_Crystal_Green_Small",
      "support": 15,
      "rotation": 6
    },
    {
      "x": 9,
      "y": 0,
      "z": -7,
      "name": "Wood_Lightwood_Planks"
    },
    {
      "x": 9,
      "y": 4,
      "z": -7,
      "name": "Wood_Lightwood_Planks"
    },
    {
      "x": 9,
      "y": 5,
      "z": -7,
      "name": "Rock_Crystal_Green_Block",
      "rotation": 4
    },
    {
      "x": 9,
      "y": 6,
      "z": -7,
      "name": "Rock_Crystal_Green_Block"
    },
    {
      "x": 9,
      "y": 7,
      "z": -7,
      "name": "Rock_Crystal_Green_Block",
      "rotation": 4
    },
    {
      "x": 9,
      "y": 8,
      "z": -7,
      "name": "Rock_Crystal_Green_Block"
    },
    {
      "x": 9,
      "y": 9,
      "z": -7,
      "name": "Rock_Crystal_Green_Block"
    },
    {
      "x": 9,
      "y": 10,
      "z": -7,
      "name": "Rock_Crystal_Green_Block"
    },
    {
      "x": 9,
      "y": 11,
      "z": -7,
      "name": "Rock_Crystal_Green_Small",
      "support": 15
    },
    {
      "x": 9,
      "y": 0,
      "z": -6,
      "name": "Wood_Lightwood_Planks"
    },
    {
      "x": 9,
      "y": 4,
      "z": -6,
      "name": "Wood_Lightwood_Planks"
    },
    {
      "x": 9,
      "y": 5,
      "z": -6,
      "name": "Rock_Crystal_Green_Block"
    },
    {
      "x": 9,
      "y": 6,
      "z": -6,
      "name": "Rock_Crystal_Green_Block"
    },
    {
      "x": 9,
      "y": 7,
      "z": -6,
      "name": "Rock_Crystal_Green_Block"
    },
    {
      "x": 9,
      "y": 8,
      "z": -6,
      "name": "Rock_Crystal_Green_Block",
      "rotation": 4
    },
    {
      "x": 9,
      "y": 9,
      "z": -6,
      "name": "Rock_Crystal_Green_Block"
    },
    {
      "x": 9,
      "y": 10,
      "z": -6,
      "name": "Rock_Crystal_Green_Small",
      "support": 15
    },
    {
      "x": 9,
      "y": 0,
      "z": -5,
      "name": "Rock_Stone_Cobble"
    },
    {
      "x": 9,
      "y": 1,
      "z": -5,
      "name": "Rock_Stone_Brick"
    },
    {
      "x": 9,
      "y": 2,
      "z": -5,
      "name": "*Wood_Village_Wall_White_Full_State_Definitions_Bottom"
    },
    {
      "x": 9,
      "y": 3,
      "z": -5,
      "name": "*Wood_Village_Wall_White_Full_State_Definitions_Top"
    },
    {
      "x": 9,
      "y": 4,
      "z": -5,
      "name": "Wood_Lightwood_Planks"
    },
    {
      "x": 9,
      "y": 5,
      "z": -5,
      "name": "Rock_Crystal_Green_Block"
    },
    {
      "x": 9,
      "y": 6,
      "z": -5,
      "name": "Rock_Crystal_Green_Block"
    },
    {
      "x": 9,
      "y": 7,
      "z": -5,
      "name": "Rock_Crystal_Green_Block",
      "rotation": 5
    },
    {
      "x": 9,
      "y": 8,
      "z": -5,
      "name": "Rock_Crystal_Green_Block"
    },
    {
      "x": 9,
      "y": 9,
      "z": -5,
      "name": "Rock_Crystal_Green_Medium",
      "support": 15
    },
    {
      "x": 9,
      "y": 0,
      "z": -4,
      "name": "Rock_Stone_Cobble"
    },
    {
      "x": 9,
      "y": 1,
      "z": -4,
      "name": "Wood_Softwood_Beam"
    },
    {
      "x": 9,
      "y": 2,
      "z": -4,
      "name": "Wood_Softwood_Beam"
    },
    {
      "x": 9,
      "y": 3,
      "z": -4,
      "name": "Wood_Lightwood_Roof"
    },
    {
      "x": 9,
      "y": 4,
      "z": -4,
      "name": "Wood_Birch_Trunk",
      "support": 15,
      "rotation": 5
    },
    {
      "x": 9,
      "y": 5,
      "z": -4,
      "name": "*Wood_Village_Wall_White_Full_State_Definitions_Bottom"
    },
    {
      "x": 9,
      "y": 6,
      "z": -4,
      "name": "*Wood_Village_Wall_White_Full_State_Definitions_Top"
    },
    {
      "x": 9,
      "y": 7,
      "z": -4,
      "name": "Wood_Lightwood_Roof_Steep",
      "rotation": 1
    },
    {
      "x": 9,
      "y": 8,
      "z": -4,
      "name": "Wood_Lightwood_Roof_Steep",
      "filler": 1024,
      "rotation": 1
    },
    {
      "x": 9,
      "y": 0,
      "z": -3,
      "name": "Rock_Stone_Cobble"
    },
    {
      "x": 9,
      "y": 6,
      "z": -3,
      "name": "Plant_Vine_Wall",
      "support": 15
    },
    {
      "x": 9,
      "y": 7,
      "z": -3,
      "name": "Wood_Lightwood_Roof_Steep",
      "rotation": 1
    },
    {
      "x": 9,
      "y": 8,
      "z": -3,
      "name": "Wood_Lightwood_Roof_Steep",
      "filler": 1024,
      "rotation": 1
    },
    {
      "x": 9,
      "y": 0,
      "z": -2,
      "name": "Rock_Stone_Cobble_Mossy"
    },
    {
      "x": 9,
      "y": 0,
      "z": -1,
      "name": "Rock_Stone_Cobble"
    },
    {
      "x": 10,
      "y": 0,
      "z": -11,
      "name": "Rock_Stone_Cobble"
    },
    {
      "x": 10,
      "y": 6,
      "z": -11,
      "name": "Wood_Lightwood_Stairs",
      "rotation": 9
    },
    {
      "x": 10,
      "y": 7,
      "z": -11,
      "name": "Wood_Lightwood_Roof_Flat",
      "rotation": 3
    },
    {
      "x": 10,
      "y": 0,
      "z": -10,
      "name": "Rock_Stone_Cobble"
    },
    {
      "x": 10,
      "y": 1,
      "z": -10,
      "name": "Rock_Stone_Brick"
    },
    {
      "x": 10,
      "y": 2,
      "z": -10,
      "name": "Furniture_Human_Ruins_Window"
    },
    {
      "x": 10,
      "y": 3,
      "z": -10,
      "name": "Furniture_Human_Ruins_Window"
    },
    {
      "x": 10,
      "y": 4,
      "z": -10,
      "name": "Wood_Birch_Trunk",
      "support": 15,
      "rotation": 5
    },
    {
      "x": 10,
      "y": 5,
      "z": -10,
      "name": "*Wood_Village_Wall_White_Full_State_Definitions_Bottom"
    },
    {
      "x": 10,
      "y": 6,
      "z": -10,
      "name": "*Wood_Village_Wall_White_Full_State_Definitions_Top"
    },
    {
      "x": 10,
      "y": 7,
      "z": -10,
      "name": "Wood_Lightwood_Roof_Flat",
      "rotation": 3
    },
    {
      "x": 10,
      "y": 0,
      "z": -9,
      "name": "Wood_Lightwood_Planks"
    },
    {
      "x": 10,
      "y": 7,
      "z": -9,
      "name": "Wood_Lightwood_Roof_Flat",
      "rotation": 3
    },
    {
      "x": 10,
      "y": 0,
      "z": -8,
      "name": "Wood_Lightwood_Planks"
    },
    {
      "x": 10,
      "y": 4,
      "z": -8,
      "name": "Wood_Lightwood_Planks"
    },
    {
      "x": 10,
      "y": 5,
      "z": -8,
      "name": "Rock_Crystal_Green_Block"
    },
    {
      "x": 10,
      "y": 6,
      "z": -8,
      "name": "Rock_Crystal_Green_Block"
    },
    {
      "x": 10,
      "y": 7,
      "z": -8,
      "name": "Rock_Crystal_Green_Block"
    },
    {
      "x": 10,
      "y": 8,
      "z": -8,
      "name": "Rock_Crystal_Green_Medium",
      "support": 15,
      "rotation": 5
    },
    {
      "x": 10,
      "y": 0,
      "z": -7,
      "name": "Wood_Lightwood_Planks"
    },
    {
      "x": 10,
      "y": 4,
      "z": -7,
      "name": "Wood_Lightwood_Planks"
    },
    {
      "x": 10,
      "y": 5,
      "z": -7,
      "name": "Rock_Crystal_Green_Block"
    },
    {
      "x": 10,
      "y": 6,
      "z": -7,
      "name": "Rock_Crystal_Green_Block"
    },
    {
      "x": 10,
      "y": 7,
      "z": -7,
      "name": "Rock_Crystal_Green_Block"
    },
    {
      "x": 10,
      "y": 8,
      "z": -7,
      "name": "Rock_Crystal_Green_Block"
    },
    {
      "x": 10,
      "y": 9,
      "z": -7,
      "name": "Rock_Crystal_Green_Small",
      "support": 15,
      "rotation": 5
    },
    {
      "x": 10,
      "y": 0,
      "z": -6,
      "name": "Wood_Lightwood_Planks"
    },
    {
      "x": 10,
      "y": 4,
      "z": -6,
      "name": "Wood_Lightwood_Planks"
    },
    {
      "x": 10,
      "y": 5,
      "z": -6,
      "name": "Rock_Crystal_Green_Block"
    },
    {
      "x": 10,
      "y": 6,
      "z": -6,
      "name": "Rock_Crystal_Green_Block"
    },
    {
      "x": 10,
      "y": 7,
      "z": -6,
      "name": "Rock_Crystal_Green_Block"
    },
    {
      "x": 10,
      "y": 8,
      "z": -6,
      "name": "Rock_Crystal_Green_Small",
      "support": 15
    },
    {
      "x": 10,
      "y": 0,
      "z": -5,
      "name": "Wood_Lightwood_Planks"
    },
    {
      "x": 10,
      "y": 1,
      "z": -5,
      "name": "Furniture_Village_Door"
    },
    {
      "x": 10,
      "y": 2,
      "z": -5,
      "name": "Furniture_Village_Door",
      "filler": 1024
    },
    {
      "x": 10,
      "y": 3,
      "z": -5,
      "name": "Wood_Village_Wall_White_Full"
    },
    {
      "x": 10,
      "y": 4,
      "z": -5,
      "name": "Wood_Lightwood_Planks"
    },
    {
      "x": 10,
      "y": 5,
      "z": -5,
      "name": "Rock_Crystal_Green_Block"
    },
    {
      "x": 10,
      "y": 6,
      "z": -5,
      "name": "Rock_Crystal_Green_Block"
    },
    {
      "x": 10,
      "y": 7,
      "z": -5,
      "name": "Wood_Lightwood_Roof_Flat",
      "rotation": 3
    },
    {
      "x": 10,
      "y": 0,
      "z": -4,
      "name": "Rock_Stone_Cobble"
    },
    {
      "x": 10,
      "y": 3,
      "z": -4,
      "name": "Wood_Lightwood_Roof_Hollow"
    },
    {
      "x": 10,
      "y": 4,
      "z": -4,
      "name": "Wood_Birch_Trunk",
      "support": 15,
      "rotation": 5
    },
    {
      "x": 10,
      "y": 5,
      "z": -4,
      "name": "*Wood_Village_Wall_White_Full_State_Definitions_Bottom"
    },
    {
      "x": 10,
      "y": 6,
      "z": -4,
      "name": "*Wood_Village_Wall_White_Full_State_Definitions_Top"
    },
    {
      "x": 10,
      "y": 7,
      "z": -4,
      "name": "Wood_Lightwood_Roof_Flat",
      "rotation": 3
    },
    {
      "x": 10,
      "y": 0,
      "z": -3,
      "name": "Rock_Stone_Cobble"
    },
    {
      "x": 10,
      "y": 4,
      "z": -3,
      "name": "Furniture_Village_Sign",
      "rotation": 1
    },
    {
      "x": 10,
      "y": 6,
      "z": -3,
      "name": "Wood_Lightwood_Stairs",
      "rotation": 9
    },
    {
      "x": 10,
      "y": 7,
      "z": -3,
      "name": "Wood_Lightwood_Roof_Flat",
      "rotation": 3
    },
    {
      "x": 10,
      "y": 0,
      "z": -2,
      "name": "Rock_Stone_Cobble"
    },
    {
      "x": 10,
      "y": 0,
      "z": -1,
      "name": "Rock_Stone_Cobble"
    },
    {
      "x": 11,
      "y": 0,
      "z": -11,
      "name": "Rock_Stone_Cobble_Mossy"
    },
    {
      "x": 11,
      "y": 6,
      "z": -11,
      "name": "Wood_Lightwood_Roof_Shallow",
      "filler": 31,
      "rotation": 1
    },
    {
      "x": 11,
      "y": 0,
      "z": -10,
      "name": "Rock_Stone_Cobble"
    },
    {
      "x": 11,
      "y": 1,
      "z": -10,
      "name": "Rock_Stone_Brick"
    },
    {
      "x": 11,
      "y": 2,
      "z": -10,
      "name": "Furniture_Human_Ruins_Window"
    },
    {
      "x": 11,
      "y": 3,
      "z": -10,
      "name": "Furniture_Human_Ruins_Window"
    },
    {
      "x": 11,
      "y": 4,
      "z": -10,
      "name": "Wood_Birch_Trunk",
      "support": 15,
      "rotation": 5
    },
    {
      "x": 11,
      "y": 5,
      "z": -10,
      "name": "Wood_Village_Wall_White_Full"
    },
    {
      "x": 11,
      "y": 6,
      "z": -10,
      "name": "Wood_Lightwood_Roof_Shallow",
      "filler": 31,
      "rotation": 1
    },
    {
      "x": 11,
      "y": 0,
      "z": -9,
      "name": "Wood_Lightwood_Planks"
    },
    {
      "x": 11,
      "y": 4,
      "z": -9,
      "name": "Wood_Lightwood_Planks"
    },
    {
      "x": 11,
      "y": 6,
      "z": -9,
      "name": "Wood_Lightwood_Roof_Shallow",
      "filler": 31,
      "rotation": 1
    },
    {
      "x": 11,
      "y": 0,
      "z": -8,
      "name": "Wood_Lightwood_Planks"
    },
    {
      "x": 11,
      "y": 4,
      "z": -8,
      "name": "Wood_Lightwood_Planks"
    },
    {
      "x": 11,
      "y": 6,
      "z": -8,
      "name": "Wood_Lightwood_Roof_Shallow",
      "filler": 31,
      "rotation": 1
    },
    {
      "x": 11,
      "y": 0,
      "z": -7,
      "name": "Wood_Lightwood_Planks"
    },
    {
      "x": 11,
      "y": 4,
      "z": -7,
      "name": "Wood_Lightwood_Planks"
    },
    {
      "x": 11,
      "y": 6,
      "z": -7,
      "name": "Wood_Lightwood_Roof_Shallow",
      "filler": 31,
      "rotation": 1
    },
    {
      "x": 11,
      "y": 8,
      "z": -7,
      "name": "Rock_Crystal_Green_Small",
      "support": 15,
      "rotation": 5
    },
    {
      "x": 11,
      "y": 0,
      "z": -6,
      "name": "Wood_Lightwood_Planks"
    },
    {
      "x": 11,
      "y": 4,
      "z": -6,
      "name": "Wood_Lightwood_Planks"
    },
    {
      "x": 11,
      "y": 6,
      "z": -6,
      "name": "Wood_Lightwood_Roof_Shallow",
      "filler": 31,
      "rotation": 1
    },
    {
      "x": 11,
      "y": 0,
      "z": -5,
      "name": "Rock_Stone_Cobble"
    },
    {
      "x": 11,
      "y": 1,
      "z": -5,
      "name": "Rock_Stone_Brick"
    },
    {
      "x": 11,
      "y": 2,
      "z": -5,
      "name": "*Wood_Village_Wall_White_Full_State_Definitions_Bottom"
    },
    {
      "x": 11,
      "y": 3,
      "z": -5,
      "name": "*Wood_Village_Wall_White_Full_State_Definitions_Top"
    },
    {
      "x": 11,
      "y": 4,
      "z": -5,
      "name": "Wood_Lightwood_Planks"
    },
    {
      "x": 11,
      "y": 6,
      "z": -5,
      "name": "Wood_Lightwood_Roof_Shallow",
      "filler": 31,
      "rotation": 1
    },
    {
      "x": 11,
      "y": 0,
      "z": -4,
      "name": "Rock_Stone_Cobble"
    },
    {
      "x": 11,
      "y": 1,
      "z": -4,
      "name": "Wood_Softwood_Beam"
    },
    {
      "x": 11,
      "y": 2,
      "z": -4,
      "name": "Wood_Softwood_Beam"
    },
    {
      "x": 11,
      "y": 3,
      "z": -4,
      "name": "Wood_Lightwood_Roof"
    },
    {
      "x": 11,
      "y": 4,
      "z": -4,
      "name": "Wood_Birch_Trunk",
      "support": 15,
      "rotation": 5
    },
    {
      "x": 11,
      "y": 5,
      "z": -4,
      "name": "Wood_Village_Wall_White_Full"
    },
    {
      "x": 11,
      "y": 6,
      "z": -4,
      "name": "Wood_Lightwood_Roof_Shallow",
      "filler": 31,
      "rotation": 1
    },
    {
      "x": 11,
      "y": 0,
      "z": -3,
      "name": "Rock_Stone_Cobble"
    },
    {
      "x": 11,
      "y": 6,
      "z": -3,
      "name": "Wood_Lightwood_Roof_Shallow",
      "filler": 31,
      "rotation": 1
    },
    {
      "x": 11,
      "y": 0,
      "z": -2,
      "name": "Rock_Stone_Cobble"
    },
    {
      "x": 11,
      "y": 0,
      "z": -1,
      "name": "Rock_Stone_Cobble"
    },
    {
      "x": 12,
      "y": 0,
      "z": -11,
      "name": "Rock_Stone_Cobble"
    },
    {
      "x": 12,
      "y": 4,
      "z": -11,
      "name": "Plant_Vine_Wall",
      "support": 15,
      "rotation": 2
    },
    {
      "x": 12,
      "y": 5,
      "z": -11,
      "name": "Wood_Lightwood_Stairs",
      "rotation": 9
    },
    {
      "x": 12,
      "y": 6,
      "z": -11,
      "name": "Wood_Lightwood_Roof_Shallow",
      "rotation": 1
    },
    {
      "x": 12,
      "y": 0,
      "z": -10,
      "name": "Rock_Stone_Cobble"
    },
    {
      "x": 12,
      "y": 1,
      "z": -10,
      "name": "Rock_Stone_Brick"
    },
    {
      "x": 12,
      "y": 2,
      "z": -10,
      "name": "*Wood_Village_Wall_White_Full_State_Definitions_Bottom"
    },
    {
      "x": 12,
      "y": 3,
      "z": -10,
      "name": "*Wood_Village_Wall_White_Full_State_Definitions_Top"
    },
    {
      "x": 12,
      "y": 4,
      "z": -10,
      "name": "Wood_Birch_Trunk",
      "support": 15,
      "rotation": 5
    },
    {
      "x": 12,
      "y": 5,
      "z": -10,
      "name": "Wood_Village_Wall_Full"
    },
    {
      "x": 12,
      "y": 6,
      "z": -10,
      "name": "Wood_Lightwood_Roof_Shallow",
      "rotation": 1
    },
    {
      "x": 12,
      "y": 0,
      "z": -9,
      "name": "Wood_Lightwood_Planks"
    },
    {
      "x": 12,
      "y": 1,
      "z": -9,
      "name": "Furniture_Village_Crate"
    },
    {
      "x": 12,
      "y": 2,
      "z": -9,
      "name": "Furniture_Village_Crate"
    },
    {
      "x": 12,
      "y": 3,
      "z": -9,
      "name": "Rock_Crystal_Yellow_Small",
      "support": 15
    },
    {
      "x": 12,
      "y": 4,
      "z": -9,
      "name": "Wood_Lightwood_Planks"
    },
    {
      "x": 12,
      "y": 5,
      "z": -9,
      "name": "Wood_Village_Wall_White_Full"
    },
    {
      "x": 12,
      "y": 6,
      "z": -9,
      "name": "Wood_Lightwood_Roof_Shallow",
      "rotation": 1
    },
    {
      "x": 12,
      "y": 0,
      "z": -8,
      "name": "Wood_Lightwood_Planks"
    },
    {
      "x": 12,
      "y": 1,
      "z": -8,
      "name": "Furniture_Village_Crate"
    },
    {
      "x": 12,
      "y": 4,
      "z": -8,
      "name": "Wood_Lightwood_Planks"
    },
    {
      "x": 12,
      "y": 5,
      "z": -8,
      "name": "Wood_Village_Wall_White_Full"
    },
    {
      "x": 12,
      "y": 6,
      "z": -8,
      "name": "Wood_Lightwood_Roof_Shallow",
      "rotation": 1
    },
    {
      "x": 12,
      "y": 0,
      "z": -7,
      "name": "Wood_Lightwood_Planks"
    },
    {
      "x": 12,
      "y": 1,
      "z": -7,
      "name": "Rock_Crystal_Pink_Small",
      "support": 15
    },
    {
      "x": 12,
      "y": 4,
      "z": -7,
      "name": "Wood_Lightwood_Planks"
    },
    {
      "x": 12,
      "y": 5,
      "z": -7,
      "name": "Wood_Village_Wall_White_Full"
    },
    {
      "x": 12,
      "y": 6,
      "z": -7,
      "name": "Wood_Lightwood_Roof_Shallow",
      "rotation": 1
    },
    {
      "x": 12,
      "y": 0,
      "z": -6,
      "name": "Wood_Lightwood_Planks"
    },
    {
      "x": 12,
      "y": 4,
      "z": -6,
      "name": "Wood_Lightwood_Planks"
    },
    {
      "x": 12,
      "y": 5,
      "z": -6,
      "name": "Wood_Village_Wall_White_Full"
    },
    {
      "x": 12,
      "y": 6,
      "z": -6,
      "name": "Wood_Lightwood_Roof_Shallow",
      "rotation": 1
    },
    {
      "x": 12,
      "y": 0,
      "z": -5,
      "name": "Wood_Lightwood_Planks"
    },
    {
      "x": 12,
      "y": 1,
      "z": -5,
      "name": "Furniture_Temple_Dark_Candle",
      "support": 15
    },
    {
      "x": 12,
      "y": 2,
      "z": -5,
      "name": "Furniture_Temple_Dark_Candle",
      "support": 15,
      "filler": 1024
    },
    {
      "x": 12,
      "y": 4,
      "z": -5,
      "name": "Wood_Lightwood_Planks"
    },
    {
      "x": 12,
      "y": 5,
      "z": -5,
      "name": "Wood_Village_Wall_White_Full"
    },
    {
      "x": 12,
      "y": 6,
      "z": -5,
      "name": "Wood_Lightwood_Roof_Shallow",
      "rotation": 1
    },
    {
      "x": 12,
      "y": 0,
      "z": -4,
      "name": "Rock_Stone_Cobble_Mossy"
    },
    {
      "x": 12,
      "y": 1,
      "z": -4,
      "name": "Rock_Stone_Brick"
    },
    {
      "x": 12,
      "y": 2,
      "z": -4,
      "name": "*Wood_Village_Wall_White_Full_State_Definitions_Bottom"
    },
    {
      "x": 12,
      "y": 3,
      "z": -4,
      "name": "*Wood_Village_Wall_White_Full_State_Definitions_Top"
    },
    {
      "x": 12,
      "y": 4,
      "z": -4,
      "name": "Wood_Birch_Trunk",
      "support": 15,
      "rotation": 5
    },
    {
      "x": 12,
      "y": 5,
      "z": -4,
      "name": "Wood_Village_Wall_White_Full"
    },
    {
      "x": 12,
      "y": 6,
      "z": -4,
      "name": "Wood_Lightwood_Roof_Shallow",
      "rotation": 1
    },
    {
      "x": 12,
      "y": 0,
      "z": -3,
      "name": "Rock_Stone_Cobble"
    },
    {
      "x": 12,
      "y": 3,
      "z": -3,
      "name": "Plant_Vine_Wall",
      "support": 15
    },
    {
      "x": 12,
      "y": 5,
      "z": -3,
      "name": "Wood_Lightwood_Stairs",
      "rotation": 9
    },
    {
      "x": 12,
      "y": 6,
      "z": -3,
      "name": "Wood_Lightwood_Roof_Shallow",
      "rotation": 1
    },
    {
      "x": 12,
      "y": 0,
      "z": -2,
      "name": "Rock_Stone_Cobble_Mossy"
    },
    {
      "x": 12,
      "y": 0,
      "z": -1,
      "name": "Rock_Stone_Cobble"
    },
    {
      "x": 13,
      "y": 0,
      "z": -11,
      "name": "Rock_Stone_Cobble_Mossy"
    },
    {
      "x": 13,
      "y": 4,
      "z": -11,
      "name": "Wood_Birch_Branch_Corner",
      "support": 15,
      "rotation": 2
    },
    {
      "x": 13,
      "y": 5,
      "z": -11,
      "name": "Wood_Lightwood_Roof",
      "rotation": 1
    },
    {
      "x": 13,
      "y": 0,
      "z": -10,
      "name": "Rock_Stone_Cobble_Mossy"
    },
    {
      "x": 13,
      "y": 1,
      "z": -10,
      "name": "Wood_Birch_Trunk",
      "support": 15
    },
    {
      "x": 13,
      "y": 2,
      "z": -10,
      "name": "Wood_Birch_Trunk",
      "support": 15
    },
    {
      "x": 13,
      "y": 3,
      "z": -10,
      "name": "Wood_Birch_Trunk",
      "support": 15
    },
    {
      "x": 13,
      "y": 4,
      "z": -10,
      "name": "Wood_Birch_Trunk",
      "support": 15
    },
    {
      "x": 13,
      "y": 5,
      "z": -10,
      "name": "Wood_Lightwood_Roof",
      "rotation": 1
    },
    {
      "x": 13,
      "y": 0,
      "z": -9,
      "name": "Rock_Stone_Cobble"
    },
    {
      "x": 13,
      "y": 1,
      "z": -9,
      "name": "Rock_Stone_Brick"
    },
    {
      "x": 13,
      "y": 2,
      "z": -9,
      "name": "*Wood_Village_Wall_White_Full_State_Definitions_Bottom"
    },
    {
      "x": 13,
      "y": 3,
      "z": -9,
      "name": "*Wood_Village_Wall_White_Full_State_Definitions_Top"
    },
    {
      "x": 13,
      "y": 4,
      "z": -9,
      "name": "Wood_Birch_Trunk",
      "support": 15,
      "rotation": 4
    },
    {
      "x": 13,
      "y": 5,
      "z": -9,
      "name": "Wood_Lightwood_Roof",
      "rotation": 1
    },
    {
      "x": 13,
      "y": 0,
      "z": -8,
      "name": "Rock_Stone_Cobble"
    },
    {
      "x": 13,
      "y": 1,
      "z": -8,
      "name": "Rock_Stone_Brick"
    },
    {
      "x": 13,
      "y": 2,
      "z": -8,
      "name": "Furniture_Human_Ruins_Window",
      "rotation": 1
    },
    {
      "x": 13,
      "y": 3,
      "z": -8,
      "name": "Furniture_Human_Ruins_Window",
      "rotation": 1
    },
    {
      "x": 13,
      "y": 4,
      "z": -8,
      "name": "Wood_Birch_Trunk",
      "support": 15,
      "rotation": 4
    },
    {
      "x": 13,
      "y": 5,
      "z": -8,
      "name": "Wood_Lightwood_Roof",
      "rotation": 1
    },
    {
      "x": 13,
      "y": 0,
      "z": -7,
      "name": "Rock_Stone_Cobble"
    },
    {
      "x": 13,
      "y": 1,
      "z": -7,
      "name": "Rock_Stone_Brick"
    },
    {
      "x": 13,
      "y": 2,
      "z": -7,
      "name": "*Wood_Village_Wall_White_Full_State_Definitions_Bottom"
    },
    {
      "x": 13,
      "y": 3,
      "z": -7,
      "name": "*Wood_Village_Wall_White_Full_State_Definitions_Top"
    },
    {
      "x": 13,
      "y": 4,
      "z": -7,
      "name": "Wood_Birch_Trunk",
      "support": 15,
      "rotation": 4
    },
    {
      "x": 13,
      "y": 5,
      "z": -7,
      "name": "Wood_Lightwood_Roof",
      "rotation": 1
    },
    {
      "x": 13,
      "y": 0,
      "z": -6,
      "name": "Rock_Stone_Cobble_Mossy"
    },
    {
      "x": 13,
      "y": 1,
      "z": -6,
      "name": "Rock_Stone_Brick"
    },
    {
      "x": 13,
      "y": 2,
      "z": -6,
      "name": "Furniture_Human_Ruins_Window",
      "rotation": 1
    },
    {
      "x": 13,
      "y": 3,
      "z": -6,
      "name": "Furniture_Human_Ruins_Window",
      "rotation": 1
    },
    {
      "x": 13,
      "y": 4,
      "z": -6,
      "name": "Wood_Birch_Trunk",
      "support": 15,
      "rotation": 4
    },
    {
      "x": 13,
      "y": 5,
      "z": -6,
      "name": "Wood_Lightwood_Roof",
      "rotation": 1
    },
    {
      "x": 13,
      "y": 0,
      "z": -5,
      "name": "Rock_Stone_Cobble_Mossy"
    },
    {
      "x": 13,
      "y": 1,
      "z": -5,
      "name": "Rock_Stone_Brick"
    },
    {
      "x": 13,
      "y": 2,
      "z": -5,
      "name": "*Wood_Village_Wall_White_Full_State_Definitions_Bottom"
    },
    {
      "x": 13,
      "y": 3,
      "z": -5,
      "name": "*Wood_Village_Wall_White_Full_State_Definitions_Top"
    },
    {
      "x": 13,
      "y": 4,
      "z": -5,
      "name": "Wood_Birch_Trunk",
      "support": 15,
      "rotation": 4
    },
    {
      "x": 13,
      "y": 5,
      "z": -5,
      "name": "Wood_Lightwood_Roof",
      "rotation": 1
    },
    {
      "x": 13,
      "y": 0,
      "z": -4,
      "name": "Rock_Stone_Cobble_Mossy"
    },
    {
      "x": 13,
      "y": 1,
      "z": -4,
      "name": "Wood_Birch_Trunk",
      "support": 15
    },
    {
      "x": 13,
      "y": 2,
      "z": -4,
      "name": "Wood_Birch_Trunk",
      "support": 15
    },
    {
      "x": 13,
      "y": 3,
      "z": -4,
      "name": "Wood_Birch_Trunk",
      "support": 15
    },
    {
      "x": 13,
      "y": 4,
      "z": -4,
      "name": "Wood_Birch_Trunk",
      "support": 15
    },
    {
      "x": 13,
      "y": 5,
      "z": -4,
      "name": "Wood_Lightwood_Roof",
      "rotation": 1
    },
    {
      "x": 13,
      "y": 0,
      "z": -3,
      "name": "Rock_Stone_Cobble"
    },
    {
      "x": 13,
      "y": 1,
      "z": -3,
      "name": "Rock_Crystal_Purple_Block"
    },
    {
      "x": 13,
      "y": 4,
      "z": -3,
      "name": "Wood_Birch_Branch_Corner",
      "support": 15
    },
    {
      "x": 13,
      "y": 5,
      "z": -3,
      "name": "Wood_Lightwood_Roof",
      "rotation": 1
    },
    {
      "x": 13,
      "y": 0,
      "z": -2,
      "name": "Rock_Stone_Cobble"
    },
    {
      "x": 13,
      "y": 0,
      "z": -1,
      "name": "Rock_Stone_Cobble"
    },
    {
      "x": 14,
      "y": 0,
      "z": -11,
      "name": "Rock_Stone_Cobble"
    },
    {
      "x": 14,
      "y": 4,
      "z": -11,
      "name": "Wood_Lightwood_Roof_Hollow",
      "rotation": 1
    },
    {
      "x": 14,
      "y": 0,
      "z": -10,
      "name": "Rock_Stone_Cobble"
    },
    {
      "x": 14,
      "y": 3,
      "z": -10,
      "name": "Wood_Birch_Branch_Corner",
      "support": 15,
      "rotation": 1
    },
    {
      "x": 14,
      "y": 4,
      "z": -10,
      "name": "Wood_Lightwood_Roof",
      "rotation": 1
    },
    {
      "x": 14,
      "y": 0,
      "z": -9,
      "name": "Rock_Stone_Cobble"
    },
    {
      "x": 14,
      "y": 1,
      "z": -9,
      "name": "Plant_Vine_Wall",
      "support": 15,
      "rotation": 1
    },
    {
      "x": 14,
      "y": 2,
      "z": -9,
      "name": "Plant_Vine_Wall",
      "support": 15,
      "rotation": 1
    },
    {
      "x": 14,
      "y": 4,
      "z": -9,
      "name": "Wood_Lightwood_Roof_Hollow",
      "rotation": 1
    },
    {
      "x": 14,
      "y": 0,
      "z": -8,
      "name": "Rock_Stone_Cobble"
    },
    {
      "x": 14,
      "y": 1,
      "z": -8,
      "name": "Plant_Vine_Wall",
      "support": 15,
      "rotation": 1
    },
    {
      "x": 14,
      "y": 4,
      "z": -8,
      "name": "Wood_Lightwood_Roof_Hollow",
      "rotation": 1
    },
    {
      "x": 14,
      "y": 0,
      "z": -7,
      "name": "Rock_Stone_Cobble_Mossy"
    },
    {
      "x": 14,
      "y": 4,
      "z": -7,
      "name": "Wood_Lightwood_Roof_Hollow",
      "rotation": 1
    },
    {
      "x": 14,
      "y": 0,
      "z": -6,
      "name": "Rock_Stone_Cobble"
    },
    {
      "x": 14,
      "y": 4,
      "z": -6,
      "name": "Wood_Lightwood_Roof_Hollow",
      "rotation": 1
    },
    {
      "x": 14,
      "y": 0,
      "z": -5,
      "name": "Rock_Stone_Cobble"
    },
    {
      "x": 14,
      "y": 2,
      "z": -5,
      "name": "Plant_Vine_Wall",
      "support": 15,
      "rotation": 1
    },
    {
      "x": 14,
      "y": 3,
      "z": -5,
      "name": "Plant_Vine_Wall",
      "support": 15,
      "rotation": 1
    },
    {
      "x": 14,
      "y": 4,
      "z": -5,
      "name": "Wood_Lightwood_Roof_Hollow",
      "rotation": 1
    },
    {
      "x": 14,
      "y": 0,
      "z": -4,
      "name": "Rock_Stone_Cobble"
    },
    {
      "x": 14,
      "y": 1,
      "z": -4,
      "name": "Rock_Crystal_Purple_Block"
    },
    {
      "x": 14,
      "y": 2,
      "z": -4,
      "name": "Rock_Crystal_Purple_Small",
      "support": 15
    },
    {
      "x": 14,
      "y": 3,
      "z": -4,
      "name": "Wood_Birch_Branch_Corner",
      "support": 15,
      "rotation": 1
    },
    {
      "x": 14,
      "y": 4,
      "z": -4,
      "name": "Wood_Lightwood_Roof",
      "rotation": 1
    },
    {
      "x": 14,
      "y": 0,
      "z": -3,
      "name": "Rock_Stone_Cobble"
    },
    {
      "x": 14,
      "y": 1,
      "z": -3,
      "name": "Rock_Crystal_Purple_Small",
      "support": 15
    },
    {
      "x": 14,
      "y": 4,
      "z": -3,
      "name": "Wood_Lightwood_Roof_Hollow",
      "rotation": 1
    },
    {
      "x": 14,
      "y": 0,
      "z": -2,
      "name": "Rock_Stone_Cobble_Mossy"
    },
    {
      "x": 14,
      "y": 0,
      "z": -1,
      "name": "Rock_Stone_Cobble"
    }
  ],
  "entities": [
    {
      "Components": {
        "Invulnerable": {},
        "PreventItemMerging": {},
        "Prop": {},
        "BlockEntity": {
          "BlockTypeKey": "Rock_Gem_Sapphire"
        },
        "Transform": {
          "Position": {
            "X": 10.493843078613281,
            "Y": 4.265892028808594,
            "Z": -2.4353981018066406
          },
          "Rotation": {
            "Pitch": 0.0,
            "Yaw": 0.7146497368812561,
            "Roll": 0.0
          }
        },
        "UUID": {
          "UUID": {
            "$binary": "RHoZEDqOOyePYl60ph27RA==",
            "$type": "04"
          }
        },
        "PreventPickup": {},
        "EntityScale": {
          "Scale": 1.0
        },
        "Item": {
          "Item": {
            "Id": "Rock_Gem_Sapphire",
            "Quantity": 1,
            "Durability": 0.0,
            "MaxDurability": 0.0,
            "OverrideDroppedItemAnimation": true
          },
          "StackDelay": 1.5,
          "PickupDelay": 0.5,
          "PickupThrottle": 0.0,
          "RemovedByPlayerPickup": false
        },
        "PrefabCopyable": {}
      }
    }
  ]
}