{
  "version": 8,
  "blockIdVersion": 11,
  "anchorX": 0,
  "anchorY": 0,
  "anchorZ": 0,
  "blocks": [
    {
      "x": 1,
      "y": 0,
      "z": -11,
      "name": "Soil_Grass"
    },
    {
      "x": 1,
      "y": 0,
      "z": -10,
      "name": "Soil_Grass"
    },
    {
      "x": 1,
      "y": 0,
      "z": -9,
      "name": "Soil_Grass"
    },
    {
      "x": 1,
      "y": 0,
      "z": -8,
      "name": "Soil_Grass"
    },
    {
      "x": 1,
      "y": 20,
      "z": -8,
      "name": "Rock_Stone_Brick_Half",
      "rotation": 7
    },
    {
      "x": 1,
      "y": 0,
      "z": -7,
      "name": "Soil_Grass"
    },
    {
      "x": 1,
      "y": 29,
      "z": -7,
      "name": "Cloth_Block_Wool_Cyan"
    },
    {
      "x": 1,
      "y": 0,
      "z": -6,
      "name": "Soil_Grass"
    },
    {
      "x": 1,
      "y": 15,
      "z": -6,
      "name": "Rock_Stone_Brick_Half",
      "rotation": 7
    },
    {
      "x": 1,
      "y": 20,
      "z": -6,
      "name": "Rock_Stone_Brick_Half",
      "rotation": 7
    },
    {
      "x": 1,
      "y": 0,
      "z": -5,
      "name": "Soil_Grass"
    },
    {
      "x": 1,
      "y": 0,
      "z": -4,
      "name": "Soil_Grass"
    },
    {
      "x": 1,
      "y": 1,
      "z": -4,
      "name": "Plant_Leaves_Ash",
      "support": 15
    },
    {
      "x": 1,
      "y": 20,
      "z": -4,
      "name": "Rock_Stone_Brick_Half",
      "rotation": 7
    },
    {
      "x": 1,
      "y": 0,
      "z": -3,
      "name": "Soil_Grass"
    },
    {
      "x": 1,
      "y": 0,
      "z": -2,
      "name": "Soil_Grass"
    },
    {
      "x": 1,
      "y": 0,
      "z": -1,
      "name": "Soil_Grass"
    },
    {
      "x": 2,
      "y": 0,
      "z": -11,
      "name": "Soil_Grass"
    },
    {
      "x": 2,
      "y": 0,
      "z": -10,
      "name": "Soil_Grass"
    },
    {
      "x": 2,
      "y": 0,
      "z": -9,
      "name": "Soil_Grass"
    },
    {
      "x": 2,
      "y": 14,
      "z": -9,
      "name": "Rock_Stone_Brick_Half",
      "rotation": 7
    },
    {
      "x": 2,
      "y": 15,
      "z": -9,
      "name": "Rock_Stone_Brick_Half",
      "rotation": 7
    },
    {
      "x": 2,
      "y": 16,
      "z": -9,
      "name": "Rock_Stone_Brick_Half",
      "rotation": 7
    },
    {
      "x": 2,
      "y": 0,
      "z": -8,
      "name": "Soil_Grass"
    },
    {
      "x": 2,
      "y": 1,
      "z": -8,
      "name": "Rock_Stone_Cobble_Mossy"
    },
    {
      "x": 2,
      "y": 2,
      "z": -8,
      "name": "Plant_Leaves_Ash",
      "support": 15
    },
    {
      "x": 2,
      "y": 13,
      "z": -8,
      "name": "Rock_Stone_Brick_Stairs",
      "rotation": 9
    },
    {
      "x": 2,
      "y": 14,
      "z": -8,
      "name": "Rock_Stone_Brick_Stairs",
      "rotation": 10
    },
    {
      "x": 2,
      "y": 15,
      "z": -8,
      "name": "Rock_Stone_Brick"
    },
    {
      "x": 2,
      "y": 16,
      "z": -8,
      "name": "Rock_Stone"
    },
    {
      "x": 2,
      "y": 19,
      "z": -8,
      "name": "Wood_Hardwood_Planks_Half",
      "rotation": 8
    },
    {
      "x": 2,
      "y": 20,
      "z": -8,
      "name": "Rock_Stone"
    },
    {
      "x": 2,
      "y": 21,
      "z": -8,
      "name": "Rock_Stone_Brick_Half"
    },
    {
      "x": 2,
      "y": 0,
      "z": -7,
      "name": "Soil_Grass"
    },
    {
      "x": 2,
      "y": 1,
      "z": -7,
      "name": "Rock_Stone_Cobble"
    },
    {
      "x": 2,
      "y": 2,
      "z": -7,
      "name": "Rock_Stone"
    },
    {
      "x": 2,
      "y": 3,
      "z": -7,
      "name": "Rock_Stone_Cobble_Half"
    },
    {
      "x": 2,
      "y": 6,
      "z": -7,
      "name": "Rock_Stone_Brick_Half",
      "rotation": 7
    },
    {
      "x": 2,
      "y": 7,
      "z": -7,
      "name": "Rock_Stone_Brick_Half",
      "rotation": 7
    },
    {
      "x": 2,
      "y": 8,
      "z": -7,
      "name": "Rock_Stone_Brick_Half",
      "rotation": 7
    },
    {
      "x": 2,
      "y": 9,
      "z": -7,
      "name": "Rock_Stone_Brick_Half",
      "rotation": 7
    },
    {
      "x": 2,
      "y": 13,
      "z": -7,
      "name": "Rock_Stone_Brick_Stairs",
      "rotation": 9
    },
    {
      "x": 2,
      "y": 15,
      "z": -7,
      "name": "Rock_Stone_Cobble"
    },
    {
      "x": 2,
      "y": 16,
      "z": -7,
      "name": "Rock_Stone_Cobble_Wall",
      "rotation": 1
    },
    {
      "x": 2,
      "y": 20,
      "z": -7,
      "name": "Rock_Stone"
    },
    {
      "x": 2,
      "y": 21,
      "z": -7,
      "name": "Rock_Stone_Cobble_Half"
    },
    {
      "x": 2,
      "y": 29,
      "z": -7,
      "name": "Cloth_Block_Wool_White"
    },
    {
      "x": 2,
      "y": 30,
      "z": -7,
      "name": "Cloth_Block_Wool_Cyan"
    },
    {
      "x": 2,
      "y": 0,
      "z": -6,
      "name": "Soil_Grass"
    },
    {
      "x": 2,
      "y": 3,
      "z": -6,
      "name": "Rock_Stone_Brick_Stairs",
      "rotation": 3
    },
    {
      "x": 2,
      "y": 4,
      "z": -6,
      "name": "Plant_Leaves_Ash",
      "support": 15
    },
    {
      "x": 2,
      "y": 5,
      "z": -6,
      "name": "Rock_Stone_Brick_Half",
      "rotation": 7
    },
    {
      "x": 2,
      "y": 9,
      "z": -6,
      "name": "Rock_Stone_Brick_Half",
      "rotation": 7
    },
    {
      "x": 2,
      "y": 11,
      "z": -6,
      "name": "Rock_Stone_Brick_Half",
      "rotation": 7
    },
    {
      "x": 2,
      "y": 13,
      "z": -6,
      "name": "Rock_Stone_Brick_Stairs",
      "rotation": 9
    },
    {
      "x": 2,
      "y": 14,
      "z": -6,
      "name": "*Rock_Stone_Brick_Half_State_Definitions_Block",
      "rotation": 7
    },
    {
      "x": 2,
      "y": 15,
      "z": -6,
      "name": "Rock_Stone_Brick"
    },
    {
      "x": 2,
      "y": 16,
      "z": -6,
      "name": "Rock_Stone_Brick_Stairs",
      "rotation": 1
    },
    {
      "x": 2,
      "y": 19,
      "z": -6,
      "name": "Wood_Hardwood_Planks_Half",
      "rotation": 8
    },
    {
      "x": 2,
      "y": 20,
      "z": -6,
      "name": "Rock_Stone_Brick"
    },
    {
      "x": 2,
      "y": 21,
      "z": -6,
      "name": "Rock_Stone_Brick"
    },
    {
      "x": 2,
      "y": 0,
      "z": -5,
      "name": "Soil_Grass"
    },
    {
      "x": 2,
      "y": 1,
      "z": -5,
      "name": "Rock_Stone_Cobble_Mossy"
    },
    {
      "x": 2,
      "y": 2,
      "z": -5,
      "name": "Rock_Stone_Cobble"
    },
    {
      "x": 2,
      "y": 3,
      "z": -5,
      "name": "Rock_Stone_Cobble_Mossy"
    },
    {
      "x": 2,
      "y": 10,
      "z": -5,
      "name": "Rock_Stone_Brick_Half",
      "rotation": 7
    },
    {
      "x": 2,
      "y": 11,
      "z": -5,
      "name": "Rock_Stone_Brick_Half",
      "rotation": 7
    },
    {
      "x": 2,
      "y": 13,
      "z": -5,
      "name": "Rock_Stone_Brick_Stairs",
      "rotation": 9
    },
    {
      "x": 2,
      "y": 15,
      "z": -5,
      "name": "Rock_Stone"
    },
    {
      "x": 2,
      "y": 16,
      "z": -5,
      "name": "Rock_Stone_Cobble_Wall",
      "rotation": 1
    },
    {
      "x": 2,
      "y": 20,
      "z": -5,
      "name": "Rock_Stone_Brick"
    },
    {
      "x": 2,
      "y": 21,
      "z": -5,
      "name": "Rock_Stone_Cobble_Half"
    },
    {
      "x": 2,
      "y": 0,
      "z": -4,
      "name": "Soil_Grass"
    },
    {
      "x": 2,
      "y": 1,
      "z": -4,
      "name": "Rock_Stone_Cobble"
    },
    {
      "x": 2,
      "y": 2,
      "z": -4,
      "name": "Plant_Leaves_Ash",
      "support": 15
    },
    {
      "x": 2,
      "y": 13,
      "z": -4,
      "name": "Rock_Stone_Brick_Stairs",
      "rotation": 9
    },
    {
      "x": 2,
      "y": 14,
      "z": -4,
      "name": "Rock_Stone_Brick_Stairs",
      "rotation": 8
    },
    {
      "x": 2,
      "y": 15,
      "z": -4,
      "name": "Rock_Stone_Brick"
    },
    {
      "x": 2,
      "y": 16,
      "z": -4,
      "name": "Rock_Stone_Brick"
    },
    {
      "x": 2,
      "y": 19,
      "z": -4,
      "name": "Wood_Hardwood_Planks_Half",
      "rotation": 8
    },
    {
      "x": 2,
      "y": 20,
      "z": -4,
      "name": "Rock_Stone_Brick"
    },
    {
      "x": 2,
      "y": 21,
      "z": -4,
      "name": "Rock_Stone_Brick_Half"
    },
    {
      "x": 2,
      "y": 0,
      "z": -3,
      "name": "Soil_Grass"
    },
    {
      "x": 2,
      "y": 1,
      "z": -3,
      "name": "Rock_Stone_Brick_Stairs",
      "rotation": 3
    },
    {
      "x": 2,
      "y": 2,
      "z": -3,
      "name": "Plant_Leaves_Ash",
      "support": 15
    },
    {
      "x": 2,
      "y": 14,
      "z": -3,
      "name": "Rock_Stone_Brick_Half",
      "rotation": 7
    },
    {
      "x": 2,
      "y": 15,
      "z": -3,
      "name": "Rock_Stone_Brick_Half",
      "rotation": 7
    },
    {
      "x": 2,
      "y": 16,
      "z": -3,
      "name": "Rock_Stone_Brick_Half",
      "rotation": 7
    },
    {
      "x": 2,
      "y": 0,
      "z": -2,
      "name": "Soil_Grass"
    },
    {
      "x": 2,
      "y": 0,
      "z": -1,
      "name": "Soil_Grass"
    },
    {
      "x": 3,
      "y": 0,
      "z": -11,
      "name": "Soil_Grass"
    },
    {
      "x": 3,
      "y": 0,
      "z": -10,
      "name": "Soil_Grass"
    },
    {
      "x": 3,
      "y": 14,
      "z": -10,
      "name": "Rock_Stone_Brick_Half",
      "rotation": 6
    },
    {
      "x": 3,
      "y": 15,
      "z": -10,
      "name": "Rock_Stone_Brick_Half",
      "rotation": 6
    },
    {
      "x": 3,
      "y": 16,
      "z": -10,
      "name": "Rock_Stone_Brick_Half",
      "rotation": 6
    },
    {
      "x": 3,
      "y": 0,
      "z": -9,
      "name": "Soil_Grass"
    },
    {
      "x": 3,
      "y": 1,
      "z": -9,
      "name": "Rock_Stone_Brick_Stairs",
      "rotation": 3
    },
    {
      "x": 3,
      "y": 2,
      "z": -9,
      "name": "Plant_Leaves_Ash",
      "support": 15
    },
    {
      "x": 3,
      "y": 13,
      "z": -9,
      "name": "Rock_Stone_Brick_Stairs",
      "rotation": 8
    },
    {
      "x": 3,
      "y": 14,
      "z": -9,
      "name": "Rock_Stone_Cobble"
    },
    {
      "x": 3,
      "y": 15,
      "z": -9,
      "name": "Rock_Stone_Cobble"
    },
    {
      "x": 3,
      "y": 16,
      "z": -9,
      "name": "Rock_Stone_Cobble"
    },
    {
      "x": 3,
      "y": 19,
      "z": -9,
      "name": "*Rock_Stone_Brick_Stairs_State_Definitions_Corner_Right",
      "rotation": 8
    },
    {
      "x": 3,
      "y": 20,
      "z": -9,
      "name": "Rock_Stone_Cobble_Mossy"
    },
    {
      "x": 3,
      "y": 0,
      "z": -8,
      "name": "Soil_Grass"
    },
    {
      "x": 3,
      "y": 1,
      "z": -8,
      "name": "Rock_Stone"
    },
    {
      "x": 3,
      "y": 2,
      "z": -8,
      "name": "Rock_Stone_Brick_Stairs",
      "rotation": 2
    },
    {
      "x": 3,
      "y": 3,
      "z": -8,
      "name": "Plant_Leaves_Ash",
      "support": 15
    },
    {
      "x": 3,
      "y": 4,
      "z": -8,
      "name": "Plant_Leaves_Ash",
      "support": 15
    },
    {
      "x": 3,
      "y": 5,
      "z": -8,
      "name": "Plant_Leaves_Ash",
      "support": 15
    },
    {
      "x": 3,
      "y": 6,
      "z": -8,
      "name": "Plant_Leaves_Ash",
      "support": 15
    },
    {
      "x": 3,
      "y": 7,
      "z": -8,
      "name": "Plant_Leaves_Ash",
      "support": 15
    },
    {
      "x": 3,
      "y": 9,
      "z": -8,
      "name": "Plant_Leaves_Ash",
      "support": 15
    },
    {
      "x": 3,
      "y": 10,
      "z": -8,
      "name": "Plant_Leaves_Ash",
      "support": 15
    },
    {
      "x": 3,
      "y": 12,
      "z": -8,
      "name": "Rock_Stone_Cobble_Stairs",
      "rotation": 9
    },
    {
      "x": 3,
      "y": 13,
      "z": -8,
      "name": "Rock_Stone"
    },
    {
      "x": 3,
      "y": 14,
      "z": -8,
      "name": "Rock_Stone"
    },
    {
      "x": 3,
      "y": 15,
      "z": -8,
      "name": "Rock_Stone_Brick"
    },
    {
      "x": 3,
      "y": 17,
      "z": -8,
      "name": "*Furniture_Crude_Trapdoor_State_Definitions_OpenDoorOut",
      "rotation": 3
    },
    {
      "x": 3,
      "y": 19,
      "z": -8,
      "name": "Wood_Hardwood_Stairs",
      "rotation": 9
    },
    {
      "x": 3,
      "y": 20,
      "z": -8,
      "name": "Rock_Stone"
    },
    {
      "x": 3,
      "y": 21,
      "z": -8,
      "name": "Rock_Stone_Cobble_Half"
    },
    {
      "x": 3,
      "y": 0,
      "z": -7,
      "name": "Soil_Grass"
    },
    {
      "x": 3,
      "y": 1,
      "z": -7,
      "name": "Rock_Stone"
    },
    {
      "x": 3,
      "y": 2,
      "z": -7,
      "name": "Rock_Stone"
    },
    {
      "x": 3,
      "y": 3,
      "z": -7,
      "name": "Rock_Stone_Brick"
    },
    {
      "x": 3,
      "y": 4,
      "z": -7,
      "name": "Rock_Stone"
    },
    {
      "x": 3,
      "y": 5,
      "z": -7,
      "name": "Rock_Stone_Cobble"
    },
    {
      "x": 3,
      "y": 6,
      "z": -7,
      "name": "Rock_Stone"
    },
    {
      "x": 3,
      "y": 7,
      "z": -7,
      "name": "Rock_Stone"
    },
    {
      "x": 3,
      "y": 8,
      "z": -7,
      "name": "Rock_Stone_Cobble"
    },
    {
      "x": 3,
      "y": 9,
      "z": -7,
      "name": "Rock_Stone"
    },
    {
      "x": 3,
      "y": 10,
      "z": -7,
      "name": "Rock_Calcite_Cobble"
    },
    {
      "x": 3,
      "y": 11,
      "z": -7,
      "name": "Rock_Stone"
    },
    {
      "x": 3,
      "y": 12,
      "z": -7,
      "name": "Rock_Stone_Brick"
    },
    {
      "x": 3,
      "y": 13,
      "z": -7,
      "name": "Rock_Stone_Cobble"
    },
    {
      "x": 3,
      "y": 14,
      "z": -7,
      "name": "Rock_Stone_Brick"
    },
    {
      "x": 3,
      "y": 15,
      "z": -7,
      "name": "Wood_Hardwood_Planks"
    },
    {
      "x": 3,
      "y": 20,
      "z": -7,
      "name": "Rock_Stone_Brick"
    },
    {
      "x": 3,
      "y": 21,
      "z": -7,
      "name": "Rock_Stone"
    },
    {
      "x": 3,
      "y": 30,
      "z": -7,
      "name": "Cloth_Block_Wool_White"
    },
    {
      "x": 3,
      "y": 31,
      "z": -7,
      "name": "Cloth_Block_Wool_Cyan"
    },
    {
      "x": 3,
      "y": 0,
      "z": -6,
      "name": "Soil_Grass"
    },
    {
      "x": 3,
      "y": 1,
      "z": -6,
      "name": "*Furniture_Village_Door_State_Definitions_OpenDoorOut",
      "rotation": 3
    },
    {
      "x": 3,
      "y": 2,
      "z": -6,
      "name": "*Furniture_Village_Door_State_Definitions_OpenDoorOut",
      "filler": 1024,
      "rotation": 3
    },
    {
      "x": 3,
      "y": 4,
      "z": -6,
      "name": "Rock_Stone_Brick"
    },
    {
      "x": 3,
      "y": 5,
      "z": -6,
      "name": "Rock_Stone_Brick"
    },
    {
      "x": 3,
      "y": 6,
      "z": -6,
      "name": "Deco_Iron_Bars",
      "rotation": 1
    },
    {
      "x": 3,
      "y": 7,
      "z": -6,
      "name": "Deco_Iron_Bars",
      "rotation": 1
    },
    {
      "x": 3,
      "y": 8,
      "z": -6,
      "name": "Deco_Iron_Bars",
      "rotation": 1
    },
    {
      "x": 3,
      "y": 9,
      "z": -6,
      "name": "Rock_Stone_Brick"
    },
    {
      "x": 3,
      "y": 10,
      "z": -6,
      "name": "Rock_Stone_Cobble"
    },
    {
      "x": 3,
      "y": 11,
      "z": -6,
      "name": "Rock_Stone_Brick"
    },
    {
      "x": 3,
      "y": 12,
      "z": -6,
      "name": "Rock_Stone_Cobble"
    },
    {
      "x": 3,
      "y": 13,
      "z": -6,
      "name": "Rock_Calcite_Cobble"
    },
    {
      "x": 3,
      "y": 14,
      "z": -6,
      "name": "Rock_Stone"
    },
    {
      "x": 3,
      "y": 15,
      "z": -6,
      "name": "Wood_Hardwood_Planks"
    },
    {
      "x": 3,
      "y": 19,
      "z": -6,
      "name": "Wood_Hardwood_Planks_Half",
      "rotation": 8
    },
    {
      "x": 3,
      "y": 20,
      "z": -6,
      "name": "Rock_Stone_Brick"
    },
    {
      "x": 3,
      "y": 21,
      "z": -6,
      "name": "Rock_Stone"
    },
    {
      "x": 3,
      "y": 22,
      "z": -6,
      "name": "Rock_Stone_Cobble_Stairs",
      "rotation": 3
    },
    {
      "x": 3,
      "y": 0,
      "z": -5,
      "name": "Soil_Dirt"
    },
    {
      "x": 3,
      "y": 1,
      "z": -5,
      "name": "Rock_Stone_Cobble"
    },
    {
      "x": 3,
      "y": 2,
      "z": -5,
      "name": "Rock_Stone"
    },
    {
      "x": 3,
      "y": 3,
      "z": -5,
      "name": "Rock_Stone_Cobble"
    },
    {
      "x": 3,
      "y": 4,
      "z": -5,
      "name": "Rock_Stone_Brick"
    },
    {
      "x": 3,
      "y": 5,
      "z": -5,
      "name": "Rock_Stone_Brick"
    },
    {
      "x": 3,
      "y": 6,
      "z": -5,
      "name": "Rock_Stone"
    },
    {
      "x": 3,
      "y": 7,
      "z": -5,
      "name": "Rock_Stone_Brick"
    },
    {
      "x": 3,
      "y": 8,
      "z": -5,
      "name": "Rock_Stone"
    },
    {
      "x": 3,
      "y": 9,
      "z": -5,
      "name": "Rock_Stone_Cobble"
    },
    {
      "x": 3,
      "y": 10,
      "z": -5,
      "name": "Rock_Stone_Brick"
    },
    {
      "x": 3,
      "y": 11,
      "z": -5,
      "name": "Rock_Stone"
    },
    {
      "x": 3,
      "y": 12,
      "z": -5,
      "name": "Rock_Stone_Cobble"
    },
    {
      "x": 3,
      "y": 13,
      "z": -5,
      "name": "Rock_Stone_Brick"
    },
    {
      "x": 3,
      "y": 14,
      "z": -5,
      "name": "Rock_Stone_Cobble"
    },
    {
      "x": 3,
      "y": 15,
      "z": -5,
      "name": "Wood_Hardwood_Planks"
    },
    {
      "x": 3,
      "y": 20,
      "z": -5,
      "name": "Rock_Stone"
    },
    {
      "x": 3,
      "y": 21,
      "z": -5,
      "name": "Rock_Stone_Brick"
    },
    {
      "x": 3,
      "y": 0,
      "z": -4,
      "name": "Soil_Dirt"
    },
    {
      "x": 3,
      "y": 1,
      "z": -4,
      "name": "Rock_Stone_Cobble_Mossy"
    },
    {
      "x": 3,
      "y": 2,
      "z": -4,
      "name": "Rock_Stone_Cobble"
    },
    {
      "x": 3,
      "y": 3,
      "z": -4,
      "name": "Rock_Stone_Brick_Stairs"
    },
    {
      "x": 3,
      "y": 6,
      "z": -4,
      "name": "Rock_Stone_Brick_Half",
      "rotation": 7
    },
    {
      "x": 3,
      "y": 7,
      "z": -4,
      "name": "Rock_Stone_Brick_Half",
      "rotation": 7
    },
    {
      "x": 3,
      "y": 8,
      "z": -4,
      "name": "Rock_Stone_Brick_Half",
      "rotation": 7
    },
    {
      "x": 3,
      "y": 9,
      "z": -4,
      "name": "Rock_Stone_Brick_Half",
      "rotation": 7
    },
    {
      "x": 3,
      "y": 12,
      "z": -4,
      "name": "Rock_Stone_Cobble_Stairs",
      "rotation": 9
    },
    {
      "x": 3,
      "y": 13,
      "z": -4,
      "name": "Rock_Stone"
    },
    {
      "x": 3,
      "y": 15,
      "z": -4,
      "name": "Rock_Stone_Brick"
    },
    {
      "x": 3,
      "y": 17,
      "z": -4,
      "name": "*Furniture_Crude_Trapdoor_State_Definitions_OpenDoorOut",
      "rotation": 3
    },
    {
      "x": 3,
      "y": 19,
      "z": -4,
      "name": "Wood_Hardwood_Stairs",
      "rotation": 9
    },
    {
      "x": 3,
      "y": 20,
      "z": -4,
      "name": "Rock_Stone_Brick"
    },
    {
      "x": 3,
      "y": 21,
      "z": -4,
      "name": "Rock_Stone_Cobble_Half"
    },
    {
      "x": 3,
      "y": 0,
      "z": -3,
      "name": "Soil_Grass"
    },
    {
      "x": 3,
      "y": 1,
      "z": -3,
      "name": "Rock_Stone"
    },
    {
      "x": 3,
      "y": 2,
      "z": -3,
      "name": "Rock_Stone_Cobble_Half"
    },
    {
      "x": 3,
      "y": 13,
      "z": -3,
      "name": "Rock_Stone_Brick_Stairs",
      "rotation": 10
    },
    {
      "x": 3,
      "y": 14,
      "z": -3,
      "name": "*Rock_Stone_Brick_Half_State_Definitions_Block",
      "rotation": 4
    },
    {
      "x": 3,
      "y": 15,
      "z": -3,
      "name": "Rock_Stone_Cobble"
    },
    {
      "x": 3,
      "y": 16,
      "z": -3,
      "name": "Rock_Stone_Cobble"
    },
    {
      "x": 3,
      "y": 19,
      "z": -3,
      "name": "*Rock_Stone_Brick_Stairs_State_Definitions_Corner_Right",
      "rotation": 9
    },
    {
      "x": 3,
      "y": 20,
      "z": -3,
      "name": "Rock_Stone_Brick"
    },
    {
      "x": 3,
      "y": 0,
      "z": -2,
      "name": "Soil_Grass"
    },
    {
      "x": 3,
      "y": 1,
      "z": -2,
      "name": "Rock_Stone_Cobble_Mossy_Half",
      "rotation": 4
    },
    {
      "x": 3,
      "y": 14,
      "z": -2,
      "name": "Rock_Stone_Brick_Half",
      "rotation": 4
    },
    {
      "x": 3,
      "y": 15,
      "z": -2,
      "name": "Rock_Stone_Brick_Half",
      "rotation": 4
    },
    {
      "x": 3,
      "y": 16,
      "z": -2,
      "name": "Rock_Stone_Brick_Half",
      "rotation": 4
    },
    {
      "x": 3,
      "y": 0,
      "z": -1,
      "name": "Soil_Grass"
    },
    {
      "x": 4,
      "y": 0,
      "z": -11,
      "name": "Soil_Grass"
    },
    {
      "x": 4,
      "y": 20,
      "z": -11,
      "name": "Rock_Stone_Brick_Half",
      "rotation": 6
    },
    {
      "x": 4,
      "y": 0,
      "z": -10,
      "name": "Soil_Grass"
    },
    {
      "x": 4,
      "y": 1,
      "z": -10,
      "name": "Plant_Leaves_Ash",
      "support": 15
    },
    {
      "x": 4,
      "y": 13,
      "z": -10,
      "name": "Rock_Stone_Brick_Stairs",
      "rotation": 8
    },
    {
      "x": 4,
      "y": 14,
      "z": -10,
      "name": "Rock_Stone_Brick_Stairs",
      "rotation": 11
    },
    {
      "x": 4,
      "y": 15,
      "z": -10,
      "name": "Rock_Stone"
    },
    {
      "x": 4,
      "y": 16,
      "z": -10,
      "name": "Rock_Stone_Cobble_Mossy"
    },
    {
      "x": 4,
      "y": 19,
      "z": -10,
      "name": "Wood_Hardwood_Planks_Half",
      "rotation": 8
    },
    {
      "x": 4,
      "y": 20,
      "z": -10,
      "name": "Rock_Stone_Cobble"
    },
    {
      "x": 4,
      "y": 21,
      "z": -10,
      "name": "Rock_Stone_Brick_Half"
    },
    {
      "x": 4,
      "y": 0,
      "z": -9,
      "name": "Soil_Dirt"
    },
    {
      "x": 4,
      "y": 1,
      "z": -9,
      "name": "Rock_Stone_Cobble_Mossy"
    },
    {
      "x": 4,
      "y": 2,
      "z": -9,
      "name": "Rock_Stone_Cobble_Mossy"
    },
    {
      "x": 4,
      "y": 3,
      "z": -9,
      "name": "Plant_Leaves_Ash",
      "support": 15
    },
    {
      "x": 4,
      "y": 4,
      "z": -9,
      "name": "Plant_Leaves_Ash",
      "support": 15
    },
    {
      "x": 4,
      "y": 5,
      "z": -9,
      "name": "Rock_Stone_Brick_Half",
      "rotation": 6
    },
    {
      "x": 4,
      "y": 6,
      "z": -9,
      "name": "Rock_Stone_Brick_Half",
      "rotation": 6
    },
    {
      "x": 4,
      "y": 7,
      "z": -9,
      "name": "Rock_Stone_Brick_Half",
      "rotation": 6
    },
    {
      "x": 4,
      "y": 8,
      "z": -9,
      "name": "Rock_Stone_Brick_Half",
      "rotation": 6
    },
    {
      "x": 4,
      "y": 10,
      "z": -9,
      "name": "Plant_Leaves_Ash",
      "support": 15
    },
    {
      "x": 4,
      "y": 11,
      "z": -9,
      "name": "Plant_Leaves_Ash",
      "support": 15
    },
    {
      "x": 4,
      "y": 12,
      "z": -9,
      "name": "Rock_Stone_Cobble_Stairs",
      "rotation": 8
    },
    {
      "x": 4,
      "y": 13,
      "z": -9,
      "name": "Rock_Stone_Brick"
    },
    {
      "x": 4,
      "y": 14,
      "z": -9,
      "name": "Rock_Stone"
    },
    {
      "x": 4,
      "y": 15,
      "z": -9,
      "name": "Rock_Stone_Cobble"
    },
    {
      "x": 4,
      "y": 17,
      "z": -9,
      "name": "*Furniture_Crude_Trapdoor_State_Definitions_OpenDoorOut",
      "rotation": 2
    },
    {
      "x": 4,
      "y": 19,
      "z": -9,
      "name": "Wood_Hardwood_Stairs",
      "rotation": 8
    },
    {
      "x": 4,
      "y": 20,
      "z": -9,
      "name": "Rock_Stone"
    },
    {
      "x": 4,
      "y": 21,
      "z": -9,
      "name": "Rock_Stone_Cobble_Half"
    },
    {
      "x": 4,
      "y": 0,
      "z": -8,
      "name": "Soil_Grass"
    },
    {
      "x": 4,
      "y": 1,
      "z": -8,
      "name": "Rock_Stone"
    },
    {
      "x": 4,
      "y": 2,
      "z": -8,
      "name": "Rock_Stone"
    },
    {
      "x": 4,
      "y": 3,
      "z": -8,
      "name": "Rock_Stone_Brick"
    },
    {
      "x": 4,
      "y": 4,
      "z": -8,
      "name": "Rock_Stone_Brick"
    },
    {
      "x": 4,
      "y": 5,
      "z": -8,
      "name": "Rock_Stone"
    },
    {
      "x": 4,
      "y": 6,
      "z": -8,
      "name": "Rock_Stone"
    },
    {
      "x": 4,
      "y": 7,
      "z": -8,
      "name": "Rock_Calcite_Cobble"
    },
    {
      "x": 4,
      "y": 8,
      "z": -8,
      "name": "Rock_Stone_Cobble"
    },
    {
      "x": 4,
      "y": 9,
      "z": -8,
      "name": "Rock_Stone_Cobble"
    },
    {
      "x": 4,
      "y": 10,
      "z": -8,
      "name": "Rock_Stone_Brick"
    },
    {
      "x": 4,
      "y": 11,
      "z": -8,
      "name": "Rock_Stone"
    },
    {
      "x": 4,
      "y": 12,
      "z": -8,
      "name": "Rock_Stone"
    },
    {
      "x": 4,
      "y": 13,
      "z": -8,
      "name": "Rock_Stone_Cobble_Mossy"
    },
    {
      "x": 4,
      "y": 14,
      "z": -8,
      "name": "Rock_Stone"
    },
    {
      "x": 4,
      "y": 15,
      "z": -8,
      "name": "Wood_Beech_Trunk",
      "rotation": 2
    },
    {
      "x": 4,
      "y": 16,
      "z": -8,
      "name": "Wood_Beech_Trunk",
      "rotation": 2
    },
    {
      "x": 4,
      "y": 17,
      "z": -8,
      "name": "Wood_Beech_Trunk",
      "rotation": 2
    },
    {
      "x": 4,
      "y": 18,
      "z": -8,
      "name": "Wood_Beech_Trunk",
      "rotation": 2
    },
    {
      "x": 4,
      "y": 19,
      "z": -8,
      "name": "Wood_Beech_Trunk",
      "rotation": 2
    },
    {
      "x": 4,
      "y": 20,
      "z": -8,
      "name": "Rock_Stone_Brick"
    },
    {
      "x": 4,
      "y": 21,
      "z": -8,
      "name": "Rock_Stone"
    },
    {
      "x": 4,
      "y": 0,
      "z": -7,
      "name": "Soil_Grass"
    },
    {
      "x": 4,
      "y": 4,
      "z": -7,
      "name": "Wood_Hardwood_Planks"
    },
    {
      "x": 4,
      "y": 7,
      "z": -7,
      "name": "Wood_Torch_Wall"
    },
    {
      "x": 4,
      "y": 14,
      "z": -7,
      "name": "Wood_Hardwood_Planks"
    },
    {
      "x": 4,
      "y": 15,
      "z": -7,
      "name": "Wood_Hardwood_Planks_Half"
    },
    {
      "x": 4,
      "y": 17,
      "z": -7,
      "name": "*Furniture_Crude_Trapdoor_State_Definitions_OpenDoorOut"
    },
    {
      "x": 4,
      "y": 19,
      "z": -7,
      "name": "Wood_Hardwood_Stairs",
      "rotation": 10
    },
    {
      "x": 4,
      "y": 20,
      "z": -7,
      "name": "Rock_Stone"
    },
    {
      "x": 4,
      "y": 22,
      "z": -7,
      "name": "Rock_Stone_Brick"
    },
    {
      "x": 4,
      "y": 23,
      "z": -7,
      "name": "Rock_Stone_Cobble_Stairs",
      "rotation": 3
    },
    {
      "x": 4,
      "y": 31,
      "z": -7,
      "name": "Cloth_Block_Wool_Cyan"
    },
    {
      "x": 4,
      "y": 0,
      "z": -6,
      "name": "Soil_Grass"
    },
    {
      "x": 4,
      "y": 1,
      "z": -6,
      "name": "*Furniture_Village_Door_State_Definitions_OpenDoorOut",
      "filler": 1,
      "rotation": 3
    },
    {
      "x": 4,
      "y": 2,
      "z": -6,
      "name": "*Furniture_Village_Door_State_Definitions_OpenDoorOut",
      "filler": 1025,
      "rotation": 3
    },
    {
      "x": 4,
      "y": 4,
      "z": -6,
      "name": "Wood_Hardwood_Planks"
    },
    {
      "x": 4,
      "y": 14,
      "z": -6,
      "name": "Wood_Hardwood_Planks"
    },
    {
      "x": 4,
      "y": 15,
      "z": -6,
      "name": "Wood_Hardwood_Planks_Half"
    },
    {
      "x": 4,
      "y": 19,
      "z": -6,
      "name": "Wood_Hardwood_Planks_Half",
      "rotation": 8
    },
    {
      "x": 4,
      "y": 20,
      "z": -6,
      "name": "Rock_Stone_Brick"
    },
    {
      "x": 4,
      "y": 22,
      "z": -6,
      "name": "Rock_Stone_Brick"
    },
    {
      "x": 4,
      "y": 23,
      "z": -6,
      "name": "Rock_Stone"
    },
    {
      "x": 4,
      "y": 24,
      "z": -6,
      "name": "Rock_Stone_Brick"
    },
    {
      "x": 4,
      "y": 25,
      "z": -6,
      "name": "Rock_Stone_Cobble_Stairs",
      "rotation": 3
    },
    {
      "x": 4,
      "y": 30,
      "z": -6,
      "name": "Cloth_Block_Wool_White"
    },
    {
      "x": 4,
      "y": 32,
      "z": -6,
      "name": "Cloth_Block_Wool_White"
    },
    {
      "x": 4,
      "y": 0,
      "z": -5,
      "name": "Soil_Grass"
    },
    {
      "x": 4,
      "y": 4,
      "z": -5,
      "name": "Wood_Hardwood_Planks"
    },
    {
      "x": 4,
      "y": 7,
      "z": -5,
      "name": "Wood_Torch_Wall",
      "rotation": 2
    },
    {
      "x": 4,
      "y": 14,
      "z": -5,
      "name": "Wood_Hardwood_Planks"
    },
    {
      "x": 4,
      "y": 15,
      "z": -5,
      "name": "Wood_Hardwood_Planks_Half"
    },
    {
      "x": 4,
      "y": 17,
      "z": -5,
      "name": "*Furniture_Crude_Trapdoor_State_Definitions_OpenDoorOut",
      "rotation": 2
    },
    {
      "x": 4,
      "y": 19,
      "z": -5,
      "name": "Wood_Hardwood_Stairs",
      "rotation": 8
    },
    {
      "x": 4,
      "y": 20,
      "z": -5,
      "name": "Rock_Stone_Cobble"
    },
    {
      "x": 4,
      "y": 22,
      "z": -5,
      "name": "Rock_Stone"
    },
    {
      "x": 4,
      "y": 23,
      "z": -5,
      "name": "Rock_Stone_Cobble_Stairs",
      "rotation": 3
    },
    {
      "x": 4,
      "y": 0,
      "z": -4,
      "name": "Soil_Grass"
    },
    {
      "x": 4,
      "y": 1,
      "z": -4,
      "name": "Rock_Stone_Cobble"
    },
    {
      "x": 4,
      "y": 2,
      "z": -4,
      "name": "Rock_Stone"
    },
    {
      "x": 4,
      "y": 3,
      "z": -4,
      "name": "Rock_Stone_Cobble"
    },
    {
      "x": 4,
      "y": 4,
      "z": -4,
      "name": "Rock_Stone_Brick"
    },
    {
      "x": 4,
      "y": 5,
      "z": -4,
      "name": "Rock_Stone"
    },
    {
      "x": 4,
      "y": 6,
      "z": -4,
      "name": "Rock_Calcite_Cobble"
    },
    {
      "x": 4,
      "y": 7,
      "z": -4,
      "name": "Rock_Stone_Brick"
    },
    {
      "x": 4,
      "y": 8,
      "z": -4,
      "name": "Rock_Stone"
    },
    {
      "x": 4,
      "y": 9,
      "z": -4,
      "name": "Rock_Stone_Brick"
    },
    {
      "x": 4,
      "y": 10,
      "z": -4,
      "name": "Rock_Calcite_Cobble"
    },
    {
      "x": 4,
      "y": 11,
      "z": -4,
      "name": "Rock_Stone_Cobble"
    },
    {
      "x": 4,
      "y": 12,
      "z": -4,
      "name": "Rock_Stone"
    },
    {
      "x": 4,
      "y": 13,
      "z": -4,
      "name": "Rock_Stone_Brick"
    },
    {
      "x": 4,
      "y": 14,
      "z": -4,
      "name": "Rock_Stone_Cobble"
    },
    {
      "x": 4,
      "y": 15,
      "z": -4,
      "name": "Wood_Beech_Trunk",
      "rotation": 2
    },
    {
      "x": 4,
      "y": 16,
      "z": -4,
      "name": "Wood_Beech_Trunk",
      "rotation": 2
    },
    {
      "x": 4,
      "y": 17,
      "z": -4,
      "name": "Wood_Beech_Trunk",
      "rotation": 2
    },
    {
      "x": 4,
      "y": 18,
      "z": -4,
      "name": "Wood_Beech_Trunk",
      "rotation": 2
    },
    {
      "x": 4,
      "y": 19,
      "z": -4,
      "name": "Wood_Beech_Trunk",
      "rotation": 2
    },
    {
      "x": 4,
      "y": 20,
      "z": -4,
      "name": "Rock_Stone"
    },
    {
      "x": 4,
      "y": 21,
      "z": -4,
      "name": "Rock_Stone"
    },
    {
      "x": 4,
      "y": 0,
      "z": -3,
      "name": "Soil_Grass"
    },
    {
      "x": 4,
      "y": 1,
      "z": -3,
      "name": "Rock_Stone_Cobble"
    },
    {
      "x": 4,
      "y": 2,
      "z": -3,
      "name": "Rock_Stone"
    },
    {
      "x": 4,
      "y": 3,
      "z": -3,
      "name": "Plant_Leaves_Ash",
      "support": 15
    },
    {
      "x": 4,
      "y": 5,
      "z": -3,
      "name": "Rock_Stone_Brick_Half",
      "rotation": 4
    },
    {
      "x": 4,
      "y": 6,
      "z": -3,
      "name": "Rock_Stone_Brick_Half",
      "rotation": 4
    },
    {
      "x": 4,
      "y": 7,
      "z": -3,
      "name": "Rock_Stone_Brick_Half",
      "rotation": 4
    },
    {
      "x": 4,
      "y": 8,
      "z": -3,
      "name": "Plant_Leaves_Ash",
      "support": 15
    },
    {
      "x": 4,
      "y": 9,
      "z": -3,
      "name": "Plant_Leaves_Ash",
      "support": 15
    },
    {
      "x": 4,
      "y": 11,
      "z": -3,
      "name": "Plant_Leaves_Ash",
      "support": 15
    },
    {
      "x": 4,
      "y": 12,
      "z": -3,
      "name": "Rock_Stone_Cobble_Stairs",
      "rotation": 10
    },
    {
      "x": 4,
      "y": 13,
      "z": -3,
      "name": "Rock_Stone"
    },
    {
      "x": 4,
      "y": 14,
      "z": -3,
      "name": "Rock_Stone_Brick"
    },
    {
      "x": 4,
      "y": 15,
      "z": -3,
      "name": "Rock_Stone"
    },
    {
      "x": 4,
      "y": 17,
      "z": -3,
      "name": "*Furniture_Crude_Trapdoor_State_Definitions_OpenDoorOut"
    },
    {
      "x": 4,
      "y": 19,
      "z": -3,
      "name": "Wood_Hardwood_Stairs",
      "rotation": 10
    },
    {
      "x": 4,
      "y": 20,
      "z": -3,
      "name": "Rock_Stone"
    },
    {
      "x": 4,
      "y": 21,
      "z": -3,
      "name": "Rock_Stone_Cobble_Half"
    },
    {
      "x": 4,
      "y": 0,
      "z": -2,
      "name": "Soil_Grass"
    },
    {
      "x": 4,
      "y": 1,
      "z": -2,
      "name": "Rock_Stone_Cobble_Mossy"
    },
    {
      "x": 4,
      "y": 13,
      "z": -2,
      "name": "Rock_Stone_Brick_Stairs",
      "rotation": 10
    },
    {
      "x": 4,
      "y": 14,
      "z": -2,
      "name": "Rock_Stone_Brick_Stairs",
      "rotation": 11
    },
    {
      "x": 4,
      "y": 15,
      "z": -2,
      "name": "Rock_Stone_Cobble"
    },
    {
      "x": 4,
      "y": 16,
      "z": -2,
      "name": "Rock_Stone_Brick"
    },
    {
      "x": 4,
      "y": 19,
      "z": -2,
      "name": "Wood_Hardwood_Planks_Half",
      "rotation": 8
    },
    {
      "x": 4,
      "y": 20,
      "z": -2,
      "name": "Rock_Stone_Brick"
    },
    {
      "x": 4,
      "y": 21,
      "z": -2,
      "name": "Rock_Stone_Brick_Half"
    },
    {
      "x": 4,
      "y": 0,
      "z": -1,
      "name": "Soil_Grass"
    },
    {
      "x": 4,
      "y": 20,
      "z": -1,
      "name": "Rock_Stone_Brick_Half",
      "rotation": 4
    },
    {
      "x": 5,
      "y": 0,
      "z": -11,
      "name": "Soil_Grass"
    },
    {
      "x": 5,
      "y": 0,
      "z": -10,
      "name": "Soil_Grass"
    },
    {
      "x": 5,
      "y": 1,
      "z": -10,
      "name": "Rock_Stone_Cobble_Mossy"
    },
    {
      "x": 5,
      "y": 2,
      "z": -10,
      "name": "Rock_Stone_Brick_Stairs",
      "rotation": 2
    },
    {
      "x": 5,
      "y": 13,
      "z": -10,
      "name": "Rock_Stone_Brick_Stairs",
      "rotation": 8
    },
    {
      "x": 5,
      "y": 15,
      "z": -10,
      "name": "Rock_Stone_Brick"
    },
    {
      "x": 5,
      "y": 16,
      "z": -10,
      "name": "Rock_Stone_Cobble_Wall"
    },
    {
      "x": 5,
      "y": 20,
      "z": -10,
      "name": "Rock_Stone"
    },
    {
      "x": 5,
      "y": 21,
      "z": -10,
      "name": "Rock_Stone_Cobble_Half"
    },
    {
      "x": 5,
      "y": 0,
      "z": -9,
      "name": "Soil_Grass"
    },
    {
      "x": 5,
      "y": 1,
      "z": -9,
      "name": "Rock_Stone_Brick"
    },
    {
      "x": 5,
      "y": 2,
      "z": -9,
      "name": "Rock_Stone_Cobble"
    },
    {
      "x": 5,
      "y": 3,
      "z": -9,
      "name": "Rock_Stone_Brick"
    },
    {
      "x": 5,
      "y": 4,
      "z": -9,
      "name": "Rock_Stone"
    },
    {
      "x": 5,
      "y": 5,
      "z": -9,
      "name": "Rock_Stone"
    },
    {
      "x": 5,
      "y": 6,
      "z": -9,
      "name": "Rock_Stone_Brick"
    },
    {
      "x": 5,
      "y": 7,
      "z": -9,
      "name": "Rock_Stone_Brick"
    },
    {
      "x": 5,
      "y": 8,
      "z": -9,
      "name": "Rock_Stone"
    },
    {
      "x": 5,
      "y": 9,
      "z": -9,
      "name": "Rock_Stone_Brick"
    },
    {
      "x": 5,
      "y": 10,
      "z": -9,
      "name": "Rock_Stone"
    },
    {
      "x": 5,
      "y": 11,
      "z": -9,
      "name": "Rock_Stone_Cobble"
    },
    {
      "x": 5,
      "y": 12,
      "z": -9,
      "name": "Rock_Stone"
    },
    {
      "x": 5,
      "y": 13,
      "z": -9,
      "name": "Rock_Stone"
    },
    {
      "x": 5,
      "y": 14,
      "z": -9,
      "name": "Rock_Stone_Cobble"
    },
    {
      "x": 5,
      "y": 15,
      "z": -9,
      "name": "Wood_Hardwood_Planks"
    },
    {
      "x": 5,
      "y": 20,
      "z": -9,
      "name": "Rock_Stone_Cobble_Mossy"
    },
    {
      "x": 5,
      "y": 21,
      "z": -9,
      "name": "Rock_Stone_Brick"
    },
    {
      "x": 5,
      "y": 0,
      "z": -8,
      "name": "Soil_Grass"
    },
    {
      "x": 5,
      "y": 4,
      "z": -8,
      "name": "Wood_Hardwood_Planks"
    },
    {
      "x": 5,
      "y": 14,
      "z": -8,
      "name": "Wood_Hardwood_Planks"
    },
    {
      "x": 5,
      "y": 15,
      "z": -8,
      "name": "Wood_Hardwood_Planks_Half"
    },
    {
      "x": 5,
      "y": 17,
      "z": -8,
      "name": "*Furniture_Crude_Trapdoor_State_Definitions_OpenDoorOut",
      "rotation": 1
    },
    {
      "x": 5,
      "y": 19,
      "z": -8,
      "name": "Wood_Hardwood_Stairs",
      "rotation": 11
    },
    {
      "x": 5,
      "y": 20,
      "z": -8,
      "name": "Rock_Stone"
    },
    {
      "x": 5,
      "y": 22,
      "z": -8,
      "name": "Rock_Stone_Brick"
    },
    {
      "x": 5,
      "y": 23,
      "z": -8,
      "name": "Rock_Stone_Cobble_Stairs",
      "rotation": 2
    },
    {
      "x": 5,
      "y": 0,
      "z": -7,
      "name": "Soil_Grass"
    },
    {
      "x": 5,
      "y": 4,
      "z": -7,
      "name": "Wood_Hardwood_Planks"
    },
    {
      "x": 5,
      "y": 14,
      "z": -7,
      "name": "Wood_Hardwood_Planks"
    },
    {
      "x": 5,
      "y": 20,
      "z": -7,
      "name": "Rock_Stone_Cobble_Mossy"
    },
    {
      "x": 5,
      "y": 22,
      "z": -7,
      "name": "Rock_Stone_Brick"
    },
    {
      "x": 5,
      "y": 23,
      "z": -7,
      "name": "Rock_Stone"
    },
    {
      "x": 5,
      "y": 24,
      "z": -7,
      "name": "Rock_Stone_Cobble"
    },
    {
      "x": 5,
      "y": 25,
      "z": -7,
      "name": "*Rock_Stone_Cobble_Wall_State_Definitions_Corner",
      "rotation": 1
    },
    {
      "x": 5,
      "y": 26,
      "z": -7,
      "name": "*Rock_Stone_Cobble_Wall_State_Definitions_Corner",
      "rotation": 1
    },
    {
      "x": 5,
      "y": 0,
      "z": -6,
      "name": "Soil_Grass"
    },
    {
      "x": 5,
      "y": 4,
      "z": -6,
      "name": "Wood_Hardwood_Planks"
    },
    {
      "x": 5,
      "y": 14,
      "z": -6,
      "name": "Wood_Hardwood_Planks"
    },
    {
      "x": 5,
      "y": 20,
      "z": -6,
      "name": "Rock_Stone_Brick"
    },
    {
      "x": 5,
      "y": 25,
      "z": -6,
      "name": "Rock_Stone_Brick"
    },
    {
      "x": 5,
      "y": 26,
      "z": -6,
      "name": "Rock_Stone"
    },
    {
      "x": 5,
      "y": 27,
      "z": -6,
      "name": "Rock_Stone_Cobble_Stairs",
      "rotation": 3
    },
    {
      "x": 5,
      "y": 31,
      "z": -6,
      "name": "Cloth_Block_Wool_White"
    },
    {
      "x": 5,
      "y": 32,
      "z": -6,
      "name": "Cloth_Block_Wool_Cyan"
    },
    {
      "x": 5,
      "y": 0,
      "z": -5,
      "name": "Soil_Grass"
    },
    {
      "x": 5,
      "y": 4,
      "z": -5,
      "name": "Wood_Hardwood_Planks"
    },
    {
      "x": 5,
      "y": 14,
      "z": -5,
      "name": "Wood_Hardwood_Planks"
    },
    {
      "x": 5,
      "y": 20,
      "z": -5,
      "name": "Rock_Stone_Brick"
    },
    {
      "x": 5,
      "y": 22,
      "z": -5,
      "name": "Rock_Stone_Cobble_Mossy"
    },
    {
      "x": 5,
      "y": 23,
      "z": -5,
      "name": "Rock_Stone"
    },
    {
      "x": 5,
      "y": 24,
      "z": -5,
      "name": "Rock_Stone"
    },
    {
      "x": 5,
      "y": 25,
      "z": -5,
      "name": "*Rock_Stone_Cobble_Wall_State_Definitions_Corner",
      "rotation": 2
    },
    {
      "x": 5,
      "y": 26,
      "z": -5,
      "name": "*Rock_Stone_Cobble_Wall_State_Definitions_Corner",
      "rotation": 2
    },
    {
      "x": 5,
      "y": 0,
      "z": -4,
      "name": "Soil_Grass"
    },
    {
      "x": 5,
      "y": 4,
      "z": -4,
      "name": "Wood_Hardwood_Planks"
    },
    {
      "x": 5,
      "y": 14,
      "z": -4,
      "name": "Wood_Hardwood_Planks"
    },
    {
      "x": 5,
      "y": 15,
      "z": -4,
      "name": "Wood_Hardwood_Planks_Half"
    },
    {
      "x": 5,
      "y": 17,
      "z": -4,
      "name": "*Furniture_Crude_Trapdoor_State_Definitions_OpenDoorOut",
      "rotation": 1
    },
    {
      "x": 5,
      "y": 19,
      "z": -4,
      "name": "Wood_Hardwood_Stairs",
      "rotation": 11
    },
    {
      "x": 5,
      "y": 20,
      "z": -4,
      "name": "Rock_Stone_Cobble"
    },
    {
      "x": 5,
      "y": 22,
      "z": -4,
      "name": "Rock_Stone_Cobble_Mossy"
    },
    {
      "x": 5,
      "y": 23,
      "z": -4,
      "name": "Rock_Stone_Cobble_Stairs"
    },
    {
      "x": 5,
      "y": 0,
      "z": -3,
      "name": "Soil_Dirt"
    },
    {
      "x": 5,
      "y": 1,
      "z": -3,
      "name": "Rock_Stone"
    },
    {
      "x": 5,
      "y": 2,
      "z": -3,
      "name": "Rock_Stone_Brick"
    },
    {
      "x": 5,
      "y": 3,
      "z": -3,
      "name": "Rock_Stone_Cobble"
    },
    {
      "x": 5,
      "y": 4,
      "z": -3,
      "name": "Rock_Stone_Brick"
    },
    {
      "x": 5,
      "y": 5,
      "z": -3,
      "name": "Rock_Stone"
    },
    {
      "x": 5,
      "y": 6,
      "z": -3,
      "name": "Rock_Stone_Cobble_Mossy"
    },
    {
      "x": 5,
      "y": 7,
      "z": -3,
      "name": "Rock_Stone_Brick"
    },
    {
      "x": 5,
      "y": 8,
      "z": -3,
      "name": "Rock_Stone_Brick"
    },
    {
      "x": 5,
      "y": 9,
      "z": -3,
      "name": "Rock_Stone"
    },
    {
      "x": 5,
      "y": 10,
      "z": -3,
      "name": "Rock_Stone"
    },
    {
      "x": 5,
      "y": 11,
      "z": -3,
      "name": "Rock_Stone"
    },
    {
      "x": 5,
      "y": 12,
      "z": -3,
      "name": "Rock_Stone_Cobble_Mossy"
    },
    {
      "x": 5,
      "y": 13,
      "z": -3,
      "name": "Rock_Stone_Brick"
    },
    {
      "x": 5,
      "y": 14,
      "z": -3,
      "name": "Rock_Stone_Cobble"
    },
    {
      "x": 5,
      "y": 15,
      "z": -3,
      "name": "Wood_Hardwood_Planks"
    },
    {
      "x": 5,
      "y": 20,
      "z": -3,
      "name": "Rock_Stone"
    },
    {
      "x": 5,
      "y": 21,
      "z": -3,
      "name": "Rock_Stone"
    },
    {
      "x": 5,
      "y": 0,
      "z": -2,
      "name": "Soil_Dirt"
    },
    {
      "x": 5,
      "y": 1,
      "z": -2,
      "name": "Rock_Stone"
    },
    {
      "x": 5,
      "y": 2,
      "z": -2,
      "name": "Rock_Stone"
    },
    {
      "x": 5,
      "y": 6,
      "z": -2,
      "name": "Rock_Stone_Brick_Half",
      "rotation": 4
    },
    {
      "x": 5,
      "y": 7,
      "z": -2,
      "name": "Rock_Stone_Brick_Half",
      "rotation": 4
    },
    {
      "x": 5,
      "y": 8,
      "z": -2,
      "name": "Rock_Stone_Brick_Half",
      "rotation": 4
    },
    {
      "x": 5,
      "y": 9,
      "z": -2,
      "name": "Rock_Stone_Brick_Half",
      "rotation": 4
    },
    {
      "x": 5,
      "y": 13,
      "z": -2,
      "name": "Rock_Stone_Brick_Stairs",
      "rotation": 10
    },
    {
      "x": 5,
      "y": 15,
      "z": -2,
      "name": "Rock_Stone_Cobble"
    },
    {
      "x": 5,
      "y": 16,
      "z": -2,
      "name": "Rock_Stone_Cobble_Wall"
    },
    {
      "x": 5,
      "y": 20,
      "z": -2,
      "name": "Rock_Stone_Brick"
    },
    {
      "x": 5,
      "y": 21,
      "z": -2,
      "name": "Rock_Stone_Cobble_Half"
    },
    {
      "x": 5,
      "y": 0,
      "z": -1,
      "name": "Soil_Grass"
    },
    {
      "x": 6,
      "y": 0,
      "z": -11,
      "name": "Soil_Grass"
    },
    {
      "x": 6,
      "y": 15,
      "z": -11,
      "name": "Rock_Stone_Brick_Half",
      "rotation": 6
    },
    {
      "x": 6,
      "y": 20,
      "z": -11,
      "name": "Rock_Stone_Brick_Half",
      "rotation": 6
    },
    {
      "x": 6,
      "y": 0,
      "z": -10,
      "name": "Soil_Dirt"
    },
    {
      "x": 6,
      "y": 1,
      "z": -10,
      "name": "Rock_Stone_Cobble"
    },
    {
      "x": 6,
      "y": 2,
      "z": -10,
      "name": "Rock_Stone_Cobble"
    },
    {
      "x": 6,
      "y": 3,
      "z": -10,
      "name": "Rock_Stone_Cobble_Mossy_Half"
    },
    {
      "x": 6,
      "y": 9,
      "z": -10,
      "name": "Rock_Stone_Brick_Half",
      "rotation": 6
    },
    {
      "x": 6,
      "y": 10,
      "z": -10,
      "name": "Rock_Stone_Brick_Half",
      "rotation": 6
    },
    {
      "x": 6,
      "y": 11,
      "z": -10,
      "name": "Rock_Stone_Brick_Half",
      "rotation": 6
    },
    {
      "x": 6,
      "y": 13,
      "z": -10,
      "name": "Rock_Stone_Brick_Stairs",
      "rotation": 8
    },
    {
      "x": 6,
      "y": 14,
      "z": -10,
      "name": "*Rock_Stone_Brick_Half_State_Definitions_Block",
      "rotation": 6
    },
    {
      "x": 6,
      "y": 15,
      "z": -10,
      "name": "Rock_Stone_Cobble"
    },
    {
      "x": 6,
      "y": 16,
      "z": -10,
      "name": "Rock_Stone_Brick_Stairs"
    },
    {
      "x": 6,
      "y": 19,
      "z": -10,
      "name": "Wood_Hardwood_Planks_Half",
      "rotation": 8
    },
    {
      "x": 6,
      "y": 20,
      "z": -10,
      "name": "Rock_Stone_Cobble"
    },
    {
      "x": 6,
      "y": 21,
      "z": -10,
      "name": "Rock_Stone"
    },
    {
      "x": 6,
      "y": 0,
      "z": -9,
      "name": "Soil_Dirt"
    },
    {
      "x": 6,
      "y": 1,
      "z": -9,
      "name": "Rock_Stone_Cobble"
    },
    {
      "x": 6,
      "y": 2,
      "z": -9,
      "name": "Rock_Stone"
    },
    {
      "x": 6,
      "y": 3,
      "z": -9,
      "name": "Rock_Stone_Cobble"
    },
    {
      "x": 6,
      "y": 4,
      "z": -9,
      "name": "Rock_Stone_Brick"
    },
    {
      "x": 6,
      "y": 5,
      "z": -9,
      "name": "Rock_Stone_Cobble"
    },
    {
      "x": 6,
      "y": 6,
      "z": -9,
      "name": "Deco_Iron_Bars"
    },
    {
      "x": 6,
      "y": 7,
      "z": -9,
      "name": "Deco_Iron_Bars"
    },
    {
      "x": 6,
      "y": 8,
      "z": -9,
      "name": "Deco_Iron_Bars"
    },
    {
      "x": 6,
      "y": 9,
      "z": -9,
      "name": "Rock_Stone_Cobble"
    },
    {
      "x": 6,
      "y": 10,
      "z": -9,
      "name": "Rock_Stone"
    },
    {
      "x": 6,
      "y": 11,
      "z": -9,
      "name": "Rock_Stone_Brick"
    },
    {
      "x": 6,
      "y": 12,
      "z": -9,
      "name": "Rock_Calcite_Cobble"
    },
    {
      "x": 6,
      "y": 13,
      "z": -9,
      "name": "Rock_Stone"
    },
    {
      "x": 6,
      "y": 14,
      "z": -9,
      "name": "Rock_Stone_Brick"
    },
    {
      "x": 6,
      "y": 15,
      "z": -9,
      "name": "Wood_Hardwood_Planks"
    },
    {
      "x": 6,
      "y": 19,
      "z": -9,
      "name": "Wood_Hardwood_Planks_Half",
      "rotation": 8
    },
    {
      "x": 6,
      "y": 20,
      "z": -9,
      "name": "Rock_Stone_Cobble_Mossy"
    },
    {
      "x": 6,
      "y": 21,
      "z": -9,
      "name": "Rock_Stone"
    },
    {
      "x": 6,
      "y": 22,
      "z": -9,
      "name": "Rock_Stone_Cobble_Stairs",
      "rotation": 2
    },
    {
      "x": 6,
      "y": 0,
      "z": -8,
      "name": "Soil_Grass"
    },
    {
      "x": 6,
      "y": 4,
      "z": -8,
      "name": "Wood_Hardwood_Planks"
    },
    {
      "x": 6,
      "y": 14,
      "z": -8,
      "name": "Wood_Hardwood_Planks"
    },
    {
      "x": 6,
      "y": 15,
      "z": -8,
      "name": "Wood_Hardwood_Planks_Half"
    },
    {
      "x": 6,
      "y": 19,
      "z": -8,
      "name": "Wood_Hardwood_Planks_Half",
      "rotation": 8
    },
    {
      "x": 6,
      "y": 20,
      "z": -8,
      "name": "Rock_Stone"
    },
    {
      "x": 6,
      "y": 22,
      "z": -8,
      "name": "Rock_Stone_Cobble_Mossy"
    },
    {
      "x": 6,
      "y": 23,
      "z": -8,
      "name": "Rock_Stone"
    },
    {
      "x": 6,
      "y": 24,
      "z": -8,
      "name": "Rock_Stone_Brick"
    },
    {
      "x": 6,
      "y": 25,
      "z": -8,
      "name": "Rock_Stone_Cobble_Stairs",
      "rotation": 2
    },
    {
      "x": 6,
      "y": 0,
      "z": -7,
      "name": "Soil_Grass"
    },
    {
      "x": 6,
      "y": 4,
      "z": -7,
      "name": "Wood_Hardwood_Planks"
    },
    {
      "x": 6,
      "y": 14,
      "z": -7,
      "name": "Wood_Hardwood_Planks"
    },
    {
      "x": 6,
      "y": 20,
      "z": -7,
      "name": "Rock_Stone_Brick"
    },
    {
      "x": 6,
      "y": 25,
      "z": -7,
      "name": "Rock_Stone_Cobble"
    },
    {
      "x": 6,
      "y": 26,
      "z": -7,
      "name": "Rock_Stone"
    },
    {
      "x": 6,
      "y": 27,
      "z": -7,
      "name": "Rock_Stone_Cobble_Stairs",
      "rotation": 2
    },
    {
      "x": 6,
      "y": 0,
      "z": -6,
      "name": "Soil_Grass"
    },
    {
      "x": 6,
      "y": 1,
      "z": -6,
      "name": "Furniture_Village_Ladder",
      "rotation": 3
    },
    {
      "x": 6,
      "y": 2,
      "z": -6,
      "name": "Furniture_Village_Ladder",
      "rotation": 3
    },
    {
      "x": 6,
      "y": 3,
      "z": -6,
      "name": "Furniture_Village_Ladder",
      "rotation": 3
    },
    {
      "x": 6,
      "y": 4,
      "z": -6,
      "name": "Furniture_Village_Ladder",
      "rotation": 3
    },
    {
      "x": 6,
      "y": 5,
      "z": -6,
      "name": "Furniture_Village_Ladder",
      "rotation": 3
    },
    {
      "x": 6,
      "y": 6,
      "z": -6,
      "name": "Furniture_Village_Ladder",
      "rotation": 3
    },
    {
      "x": 6,
      "y": 7,
      "z": -6,
      "name": "Furniture_Village_Ladder",
      "rotation": 3
    },
    {
      "x": 6,
      "y": 8,
      "z": -6,
      "name": "Furniture_Village_Ladder",
      "rotation": 3
    },
    {
      "x": 6,
      "y": 9,
      "z": -6,
      "name": "Furniture_Village_Ladder",
      "rotation": 3
    },
    {
      "x": 6,
      "y": 10,
      "z": -6,
      "name": "Furniture_Village_Ladder",
      "rotation": 3
    },
    {
      "x": 6,
      "y": 11,
      "z": -6,
      "name": "Furniture_Village_Ladder",
      "rotation": 3
    },
    {
      "x": 6,
      "y": 12,
      "z": -6,
      "name": "Furniture_Village_Ladder",
      "rotation": 3
    },
    {
      "x": 6,
      "y": 13,
      "z": -6,
      "name": "Furniture_Village_Ladder",
      "rotation": 3
    },
    {
      "x": 6,
      "y": 14,
      "z": -6,
      "name": "Furniture_Village_Ladder",
      "rotation": 3
    },
    {
      "x": 6,
      "y": 19,
      "z": -6,
      "name": "Deco_Lantern_Ceiling"
    },
    {
      "x": 6,
      "y": 20,
      "z": -6,
      "name": "Rock_Stone"
    },
    {
      "x": 6,
      "y": 21,
      "z": -6,
      "name": "Rock_Stone"
    },
    {
      "x": 6,
      "y": 22,
      "z": -6,
      "name": "Rock_Stone_Brick"
    },
    {
      "x": 6,
      "y": 23,
      "z": -6,
      "name": "Rock_Stone"
    },
    {
      "x": 6,
      "y": 24,
      "z": -6,
      "name": "Rock_Stone_Brick"
    },
    {
      "x": 6,
      "y": 25,
      "z": -6,
      "name": "Rock_Stone_Brick"
    },
    {
      "x": 6,
      "y": 26,
      "z": -6,
      "name": "Rock_Stone_Brick"
    },
    {
      "x": 6,
      "y": 27,
      "z": -6,
      "name": "Rock_Stone_Brick"
    },
    {
      "x": 6,
      "y": 28,
      "z": -6,
      "name": "Rock_Stone"
    },
    {
      "x": 6,
      "y": 29,
      "z": -6,
      "name": "Wood_Blackwood_Beam"
    },
    {
      "x": 6,
      "y": 30,
      "z": -6,
      "name": "Wood_Blackwood_Beam"
    },
    {
      "x": 6,
      "y": 31,
      "z": -6,
      "name": "Wood_Blackwood_Fence",
      "rotation": 2
    },
    {
      "x": 6,
      "y": 32,
      "z": -6,
      "name": "Wood_Blackwood_Fence",
      "rotation": 2
    },
    {
      "x": 6,
      "y": 0,
      "z": -5,
      "name": "Soil_Grass"
    },
    {
      "x": 6,
      "y": 4,
      "z": -5,
      "name": "Wood_Hardwood_Planks"
    },
    {
      "x": 6,
      "y": 14,
      "z": -5,
      "name": "Wood_Hardwood_Planks"
    },
    {
      "x": 6,
      "y": 20,
      "z": -5,
      "name": "Rock_Stone"
    },
    {
      "x": 6,
      "y": 25,
      "z": -5,
      "name": "Rock_Stone"
    },
    {
      "x": 6,
      "y": 26,
      "z": -5,
      "name": "Rock_Stone_Cobble"
    },
    {
      "x": 6,
      "y": 27,
      "z": -5,
      "name": "Rock_Stone_Cobble_Stairs"
    },
    {
      "x": 6,
      "y": 0,
      "z": -4,
      "name": "Soil_Grass"
    },
    {
      "x": 6,
      "y": 4,
      "z": -4,
      "name": "Wood_Hardwood_Planks"
    },
    {
      "x": 6,
      "y": 14,
      "z": -4,
      "name": "Wood_Hardwood_Planks"
    },
    {
      "x": 6,
      "y": 15,
      "z": -4,
      "name": "Wood_Hardwood_Planks_Half"
    },
    {
      "x": 6,
      "y": 19,
      "z": -4,
      "name": "Wood_Hardwood_Planks_Half",
      "rotation": 8
    },
    {
      "x": 6,
      "y": 20,
      "z": -4,
      "name": "Rock_Stone_Cobble"
    },
    {
      "x": 6,
      "y": 22,
      "z": -4,
      "name": "Rock_Stone_Brick"
    },
    {
      "x": 6,
      "y": 23,
      "z": -4,
      "name": "Rock_Stone"
    },
    {
      "x": 6,
      "y": 24,
      "z": -4,
      "name": "Rock_Stone"
    },
    {
      "x": 6,
      "y": 25,
      "z": -4,
      "name": "Rock_Stone_Cobble_Stairs"
    },
    {
      "x": 6,
      "y": 0,
      "z": -3,
      "name": "Soil_Dirt"
    },
    {
      "x": 6,
      "y": 1,
      "z": -3,
      "name": "Rock_Stone"
    },
    {
      "x": 6,
      "y": 2,
      "z": -3,
      "name": "Rock_Stone"
    },
    {
      "x": 6,
      "y": 3,
      "z": -3,
      "name": "Rock_Stone_Brick"
    },
    {
      "x": 6,
      "y": 4,
      "z": -3,
      "name": "Rock_Stone"
    },
    {
      "x": 6,
      "y": 5,
      "z": -3,
      "name": "Rock_Stone"
    },
    {
      "x": 6,
      "y": 6,
      "z": -3,
      "name": "Deco_Iron_Bars"
    },
    {
      "x": 6,
      "y": 7,
      "z": -3,
      "name": "Deco_Iron_Bars"
    },
    {
      "x": 6,
      "y": 8,
      "z": -3,
      "name": "Deco_Iron_Bars"
    },
    {
      "x": 6,
      "y": 9,
      "z": -3,
      "name": "Rock_Stone"
    },
    {
      "x": 6,
      "y": 10,
      "z": -3,
      "name": "Rock_Stone"
    },
    {
      "x": 6,
      "y": 11,
      "z": -3,
      "name": "Rock_Stone_Brick"
    },
    {
      "x": 6,
      "y": 12,
      "z": -3,
      "name": "Rock_Stone_Brick"
    },
    {
      "x": 6,
      "y": 13,
      "z": -3,
      "name": "Rock_Calcite_Cobble"
    },
    {
      "x": 6,
      "y": 14,
      "z": -3,
      "name": "Rock_Stone_Cobble"
    },
    {
      "x": 6,
      "y": 15,
      "z": -3,
      "name": "Wood_Hardwood_Planks"
    },
    {
      "x": 6,
      "y": 19,
      "z": -3,
      "name": "Wood_Hardwood_Planks_Half",
      "rotation": 8
    },
    {
      "x": 6,
      "y": 20,
      "z": -3,
      "name": "Rock_Stone_Cobble"
    },
    {
      "x": 6,
      "y": 21,
      "z": -3,
      "name": "Rock_Stone_Brick"
    },
    {
      "x": 6,
      "y": 22,
      "z": -3,
      "name": "Rock_Stone_Cobble_Stairs"
    },
    {
      "x": 6,
      "y": 0,
      "z": -2,
      "name": "Soil_Dirt"
    },
    {
      "x": 6,
      "y": 1,
      "z": -2,
      "name": "Rock_Stone_Cobble"
    },
    {
      "x": 6,
      "y": 2,
      "z": -2,
      "name": "Rock_Stone_Brick_Stairs"
    },
    {
      "x": 6,
      "y": 3,
      "z": -2,
      "name": "Rock_Stone_Brick_Half",
      "rotation": 4
    },
    {
      "x": 6,
      "y": 9,
      "z": -2,
      "name": "Plant_Leaves_Ash",
      "support": 15
    },
    {
      "x": 6,
      "y": 11,
      "z": -2,
      "name": "Plant_Leaves_Ash",
      "support": 15
    },
    {
      "x": 6,
      "y": 13,
      "z": -2,
      "name": "Rock_Stone_Brick_Stairs",
      "rotation": 10
    },
    {
      "x": 6,
      "y": 14,
      "z": -2,
      "name": "*Rock_Stone_Brick_Half_State_Definitions_Block",
      "rotation": 4
    },
    {
      "x": 6,
      "y": 15,
      "z": -2,
      "name": "Rock_Stone"
    },
    {
      "x": 6,
      "y": 16,
      "z": -2,
      "name": "Rock_Stone_Brick_Stairs",
      "rotation": 2
    },
    {
      "x": 6,
      "y": 19,
      "z": -2,
      "name": "Wood_Hardwood_Planks_Half",
      "rotation": 8
    },
    {
      "x": 6,
      "y": 20,
      "z": -2,
      "name": "Rock_Stone_Cobble"
    },
    {
      "x": 6,
      "y": 21,
      "z": -2,
      "name": "Rock_Stone_Cobble"
    },
    {
      "x": 6,
      "y": 0,
      "z": -1,
      "name": "Soil_Grass"
    },
    {
      "x": 6,
      "y": 1,
      "z": -1,
      "name": "Rock_Stone_Brick_Stairs"
    },
    {
      "x": 6,
      "y": 15,
      "z": -1,
      "name": "Rock_Stone_Brick_Half",
      "rotation": 4
    },
    {
      "x": 6,
      "y": 20,
      "z": -1,
      "name": "Rock_Stone_Brick_Half",
      "rotation": 4
    },
    {
      "x": 7,
      "y": 0,
      "z": -11,
      "name": "Soil_Grass"
    },
    {
      "x": 7,
      "y": 0,
      "z": -10,
      "name": "Soil_Grass"
    },
    {
      "x": 7,
      "y": 1,
      "z": -10,
      "name": "Rock_Stone_Cobble"
    },
    {
      "x": 7,
      "y": 2,
      "z": -10,
      "name": "Rock_Stone_Brick_Stairs",
      "rotation": 1
    },
    {
      "x": 7,
      "y": 6,
      "z": -10,
      "name": "Rock_Stone_Brick_Half",
      "rotation": 6
    },
    {
      "x": 7,
      "y": 7,
      "z": -10,
      "name": "Rock_Stone_Brick_Half",
      "rotation": 6
    },
    {
      "x": 7,
      "y": 8,
      "z": -10,
      "name": "Rock_Stone_Brick_Half",
      "rotation": 6
    },
    {
      "x": 7,
      "y": 12,
      "z": -10,
      "name": "Rock_Stone_Brick_Half",
      "rotation": 6
    },
    {
      "x": 7,
      "y": 13,
      "z": -10,
      "name": "Rock_Stone_Brick_Stairs",
      "rotation": 8
    },
    {
      "x": 7,
      "y": 15,
      "z": -10,
      "name": "Rock_Stone_Cobble"
    },
    {
      "x": 7,
      "y": 16,
      "z": -10,
      "name": "Rock_Stone_Cobble_Wall"
    },
    {
      "x": 7,
      "y": 20,
      "z": -10,
      "name": "Rock_Stone_Cobble"
    },
    {
      "x": 7,
      "y": 21,
      "z": -10,
      "name": "Rock_Stone_Cobble_Half"
    },
    {
      "x": 7,
      "y": 0,
      "z": -9,
      "name": "Soil_Grass"
    },
    {
      "x": 7,
      "y": 1,
      "z": -9,
      "name": "Rock_Stone_Brick"
    },
    {
      "x": 7,
      "y": 2,
      "z": -9,
      "name": "Rock_Stone_Cobble"
    },
    {
      "x": 7,
      "y": 3,
      "z": -9,
      "name": "Rock_Stone_Brick"
    },
    {
      "x": 7,
      "y": 4,
      "z": -9,
      "name": "Rock_Stone"
    },
    {
      "x": 7,
      "y": 5,
      "z": -9,
      "name": "Rock_Calcite_Cobble"
    },
    {
      "x": 7,
      "y": 6,
      "z": -9,
      "name": "Rock_Stone_Brick"
    },
    {
      "x": 7,
      "y": 7,
      "z": -9,
      "name": "Rock_Stone"
    },
    {
      "x": 7,
      "y": 8,
      "z": -9,
      "name": "Rock_Stone_Brick"
    },
    {
      "x": 7,
      "y": 9,
      "z": -9,
      "name": "Rock_Stone_Cobble_Mossy"
    },
    {
      "x": 7,
      "y": 10,
      "z": -9,
      "name": "Rock_Stone_Cobble_Mossy"
    },
    {
      "x": 7,
      "y": 11,
      "z": -9,
      "name": "Rock_Stone"
    },
    {
      "x": 7,
      "y": 12,
      "z": -9,
      "name": "Rock_Stone_Cobble"
    },
    {
      "x": 7,
      "y": 13,
      "z": -9,
      "name": "Rock_Stone"
    },
    {
      "x": 7,
      "y": 14,
      "z": -9,
      "name": "Rock_Stone_Brick"
    },
    {
      "x": 7,
      "y": 15,
      "z": -9,
      "name": "Wood_Hardwood_Planks"
    },
    {
      "x": 7,
      "y": 20,
      "z": -9,
      "name": "Rock_Stone"
    },
    {
      "x": 7,
      "y": 21,
      "z": -9,
      "name": "Rock_Stone_Brick"
    },
    {
      "x": 7,
      "y": 0,
      "z": -8,
      "name": "Soil_Grass"
    },
    {
      "x": 7,
      "y": 4,
      "z": -8,
      "name": "Wood_Hardwood_Planks"
    },
    {
      "x": 7,
      "y": 14,
      "z": -8,
      "name": "Wood_Hardwood_Planks"
    },
    {
      "x": 7,
      "y": 15,
      "z": -8,
      "name": "Wood_Hardwood_Planks_Half"
    },
    {
      "x": 7,
      "y": 17,
      "z": -8,
      "name": "*Furniture_Crude_Trapdoor_State_Definitions_OpenDoorOut",
      "rotation": 3
    },
    {
      "x": 7,
      "y": 19,
      "z": -8,
      "name": "Wood_Hardwood_Stairs",
      "rotation": 9
    },
    {
      "x": 7,
      "y": 20,
      "z": -8,
      "name": "Rock_Stone_Cobble_Mossy"
    },
    {
      "x": 7,
      "y": 22,
      "z": -8,
      "name": "Rock_Stone_Brick"
    },
    {
      "x": 7,
      "y": 23,
      "z": -8,
      "name": "Rock_Stone_Cobble_Stairs",
      "rotation": 2
    },
    {
      "x": 7,
      "y": 0,
      "z": -7,
      "name": "Soil_Grass"
    },
    {
      "x": 7,
      "y": 4,
      "z": -7,
      "name": "Wood_Hardwood_Planks"
    },
    {
      "x": 7,
      "y": 14,
      "z": -7,
      "name": "Wood_Hardwood_Planks"
    },
    {
      "x": 7,
      "y": 20,
      "z": -7,
      "name": "Rock_Stone"
    },
    {
      "x": 7,
      "y": 22,
      "z": -7,
      "name": "Rock_Stone"
    },
    {
      "x": 7,
      "y": 23,
      "z": -7,
      "name": "Rock_Stone_Brick"
    },
    {
      "x": 7,
      "y": 24,
      "z": -7,
      "name": "Rock_Stone_Brick"
    },
    {
      "x": 7,
      "y": 25,
      "z": -7,
      "name": "*Rock_Stone_Cobble_Wall_State_Definitions_Corner"
    },
    {
      "x": 7,
      "y": 26,
      "z": -7,
      "name": "*Rock_Stone_Cobble_Wall_State_Definitions_Corner"
    },
    {
      "x": 7,
      "y": 0,
      "z": -6,
      "name": "Soil_Grass"
    },
    {
      "x": 7,
      "y": 1,
      "z": -6,
      "name": "Wood_Beech_Trunk",
      "rotation": 2
    },
    {
      "x": 7,
      "y": 2,
      "z": -6,
      "name": "Wood_Beech_Trunk",
      "rotation": 2
    },
    {
      "x": 7,
      "y": 3,
      "z": -6,
      "name": "Wood_Beech_Trunk",
      "rotation": 2
    },
    {
      "x": 7,
      "y": 4,
      "z": -6,
      "name": "Wood_Beech_Trunk",
      "rotation": 2
    },
    {
      "x": 7,
      "y": 5,
      "z": -6,
      "name": "Wood_Beech_Trunk",
      "rotation": 2
    },
    {
      "x": 7,
      "y": 6,
      "z": -6,
      "name": "Wood_Beech_Trunk",
      "rotation": 2
    },
    {
      "x": 7,
      "y": 7,
      "z": -6,
      "name": "Wood_Beech_Trunk",
      "rotation": 2
    },
    {
      "x": 7,
      "y": 8,
      "z": -6,
      "name": "Wood_Beech_Trunk",
      "rotation": 2
    },
    {
      "x": 7,
      "y": 9,
      "z": -6,
      "name": "Wood_Beech_Trunk",
      "rotation": 2
    },
    {
      "x": 7,
      "y": 10,
      "z": -6,
      "name": "Wood_Beech_Trunk",
      "rotation": 2
    },
    {
      "x": 7,
      "y": 11,
      "z": -6,
      "name": "Wood_Beech_Trunk",
      "rotation": 2
    },
    {
      "x": 7,
      "y": 12,
      "z": -6,
      "name": "Wood_Beech_Trunk",
      "rotation": 2
    },
    {
      "x": 7,
      "y": 13,
      "z": -6,
      "name": "Wood_Beech_Trunk",
      "rotation": 2
    },
    {
      "x": 7,
      "y": 14,
      "z": -6,
      "name": "Wood_Hardwood_Planks"
    },
    {
      "x": 7,
      "y": 20,
      "z": -6,
      "name": "Rock_Stone_Brick"
    },
    {
      "x": 7,
      "y": 25,
      "z": -6,
      "name": "Rock_Stone_Brick"
    },
    {
      "x": 7,
      "y": 26,
      "z": -6,
      "name": "Rock_Stone_Cobble_Mossy"
    },
    {
      "x": 7,
      "y": 27,
      "z": -6,
      "name": "Rock_Stone_Cobble_Stairs",
      "rotation": 1
    },
    {
      "x": 7,
      "y": 0,
      "z": -5,
      "name": "Soil_Grass"
    },
    {
      "x": 7,
      "y": 4,
      "z": -5,
      "name": "Wood_Hardwood_Planks"
    },
    {
      "x": 7,
      "y": 14,
      "z": -5,
      "name": "Wood_Hardwood_Planks"
    },
    {
      "x": 7,
      "y": 20,
      "z": -5,
      "name": "Rock_Stone_Brick"
    },
    {
      "x": 7,
      "y": 22,
      "z": -5,
      "name": "Rock_Stone_Brick"
    },
    {
      "x": 7,
      "y": 23,
      "z": -5,
      "name": "Rock_Stone"
    },
    {
      "x": 7,
      "y": 24,
      "z": -5,
      "name": "Rock_Stone"
    },
    {
      "x": 7,
      "y": 25,
      "z": -5,
      "name": "*Rock_Stone_Cobble_Wall_State_Definitions_Corner",
      "rotation": 3
    },
    {
      "x": 7,
      "y": 26,
      "z": -5,
      "name": "*Rock_Stone_Cobble_Wall_State_Definitions_Corner",
      "rotation": 3
    },
    {
      "x": 7,
      "y": 0,
      "z": -4,
      "name": "Soil_Grass"
    },
    {
      "x": 7,
      "y": 4,
      "z": -4,
      "name": "Wood_Hardwood_Planks"
    },
    {
      "x": 7,
      "y": 14,
      "z": -4,
      "name": "Wood_Hardwood_Planks"
    },
    {
      "x": 7,
      "y": 15,
      "z": -4,
      "name": "Wood_Hardwood_Planks_Half"
    },
    {
      "x": 7,
      "y": 17,
      "z": -4,
      "name": "*Furniture_Crude_Trapdoor_State_Definitions_OpenDoorOut",
      "rotation": 3
    },
    {
      "x": 7,
      "y": 19,
      "z": -4,
      "name": "Wood_Hardwood_Stairs",
      "rotation": 9
    },
    {
      "x": 7,
      "y": 20,
      "z": -4,
      "name": "Rock_Stone_Brick"
    },
    {
      "x": 7,
      "y": 22,
      "z": -4,
      "name": "Rock_Stone_Brick"
    },
    {
      "x": 7,
      "y": 23,
      "z": -4,
      "name": "Rock_Stone_Cobble_Stairs"
    },
    {
      "x": 7,
      "y": 0,
      "z": -3,
      "name": "Soil_Grass"
    },
    {
      "x": 7,
      "y": 1,
      "z": -3,
      "name": "Rock_Stone_Brick"
    },
    {
      "x": 7,
      "y": 2,
      "z": -3,
      "name": "Rock_Stone_Cobble"
    },
    {
      "x": 7,
      "y": 3,
      "z": -3,
      "name": "Rock_Stone_Brick"
    },
    {
      "x": 7,
      "y": 4,
      "z": -3,
      "name": "Rock_Stone_Cobble"
    },
    {
      "x": 7,
      "y": 5,
      "z": -3,
      "name": "Rock_Stone_Brick"
    },
    {
      "x": 7,
      "y": 6,
      "z": -3,
      "name": "Rock_Stone"
    },
    {
      "x": 7,
      "y": 7,
      "z": -3,
      "name": "Rock_Calcite_Cobble"
    },
    {
      "x": 7,
      "y": 8,
      "z": -3,
      "name": "Rock_Stone_Cobble"
    },
    {
      "x": 7,
      "y": 9,
      "z": -3,
      "name": "Rock_Stone"
    },
    {
      "x": 7,
      "y": 10,
      "z": -3,
      "name": "Rock_Stone_Brick"
    },
    {
      "x": 7,
      "y": 11,
      "z": -3,
      "name": "Rock_Calcite_Cobble"
    },
    {
      "x": 7,
      "y": 12,
      "z": -3,
      "name": "Rock_Stone"
    },
    {
      "x": 7,
      "y": 13,
      "z": -3,
      "name": "Rock_Stone"
    },
    {
      "x": 7,
      "y": 14,
      "z": -3,
      "name": "Rock_Stone_Brick"
    },
    {
      "x": 7,
      "y": 15,
      "z": -3,
      "name": "Wood_Hardwood_Planks"
    },
    {
      "x": 7,
      "y": 20,
      "z": -3,
      "name": "Rock_Stone"
    },
    {
      "x": 7,
      "y": 21,
      "z": -3,
      "name": "Rock_Stone"
    },
    {
      "x": 7,
      "y": 0,
      "z": -2,
      "name": "Soil_Grass"
    },
    {
      "x": 7,
      "y": 1,
      "z": -2,
      "name": "Rock_Stone_Cobble"
    },
    {
      "x": 7,
      "y": 2,
      "z": -2,
      "name": "Rock_Stone_Cobble_Mossy_Half"
    },
    {
      "x": 7,
      "y": 4,
      "z": -2,
      "name": "Rock_Stone_Brick_Half",
      "rotation": 4
    },
    {
      "x": 7,
      "y": 5,
      "z": -2,
      "name": "Rock_Stone_Brick_Half",
      "rotation": 4
    },
    {
      "x": 7,
      "y": 6,
      "z": -2,
      "name": "Rock_Stone_Brick_Half",
      "rotation": 4
    },
    {
      "x": 7,
      "y": 7,
      "z": -2,
      "name": "Rock_Stone_Brick_Half",
      "rotation": 4
    },
    {
      "x": 7,
      "y": 9,
      "z": -2,
      "name": "Rock_Stone_Brick_Half",
      "rotation": 4
    },
    {
      "x": 7,
      "y": 13,
      "z": -2,
      "name": "Rock_Stone_Brick_Stairs",
      "rotation": 10
    },
    {
      "x": 7,
      "y": 15,
      "z": -2,
      "name": "Rock_Stone_Cobble"
    },
    {
      "x": 7,
      "y": 16,
      "z": -2,
      "name": "Rock_Stone_Cobble_Wall"
    },
    {
      "x": 7,
      "y": 20,
      "z": -2,
      "name": "Rock_Stone_Brick"
    },
    {
      "x": 7,
      "y": 21,
      "z": -2,
      "name": "Rock_Stone_Cobble_Half"
    },
    {
      "x": 7,
      "y": 0,
      "z": -1,
      "name": "Soil_Grass"
    },
    {
      "x": 8,
      "y": 0,
      "z": -11,
      "name": "Soil_Grass"
    },
    {
      "x": 8,
      "y": 20,
      "z": -11,
      "name": "Rock_Stone_Brick_Half",
      "rotation": 6
    },
    {
      "x": 8,
      "y": 0,
      "z": -10,
      "name": "Soil_Grass"
    },
    {
      "x": 8,
      "y": 1,
      "z": -10,
      "name": "Plant_Leaves_Ash",
      "support": 15
    },
    {
      "x": 8,
      "y": 13,
      "z": -10,
      "name": "Rock_Stone_Brick_Stairs",
      "rotation": 8
    },
    {
      "x": 8,
      "y": 14,
      "z": -10,
      "name": "Rock_Stone_Brick_Stairs",
      "rotation": 9
    },
    {
      "x": 8,
      "y": 15,
      "z": -10,
      "name": "Rock_Stone_Brick"
    },
    {
      "x": 8,
      "y": 16,
      "z": -10,
      "name": "Rock_Stone"
    },
    {
      "x": 8,
      "y": 19,
      "z": -10,
      "name": "Wood_Hardwood_Planks_Half",
      "rotation": 8
    },
    {
      "x": 8,
      "y": 20,
      "z": -10,
      "name": "Rock_Stone"
    },
    {
      "x": 8,
      "y": 21,
      "z": -10,
      "name": "Rock_Stone_Brick_Half"
    },
    {
      "x": 8,
      "y": 0,
      "z": -9,
      "name": "Soil_Dirt"
    },
    {
      "x": 8,
      "y": 1,
      "z": -9,
      "name": "Rock_Stone"
    },
    {
      "x": 8,
      "y": 2,
      "z": -9,
      "name": "Rock_Stone"
    },
    {
      "x": 8,
      "y": 3,
      "z": -9,
      "name": "Rock_Stone_Brick_Stairs",
      "rotation": 2
    },
    {
      "x": 8,
      "y": 10,
      "z": -9,
      "name": "Rock_Stone_Brick_Half",
      "rotation": 6
    },
    {
      "x": 8,
      "y": 11,
      "z": -9,
      "name": "Rock_Stone_Brick_Half",
      "rotation": 6
    },
    {
      "x": 8,
      "y": 12,
      "z": -9,
      "name": "Rock_Stone_Cobble_Stairs",
      "rotation": 8
    },
    {
      "x": 8,
      "y": 13,
      "z": -9,
      "name": "Rock_Stone_Brick"
    },
    {
      "x": 8,
      "y": 14,
      "z": -9,
      "name": "Rock_Stone"
    },
    {
      "x": 8,
      "y": 15,
      "z": -9,
      "name": "Rock_Stone_Brick"
    },
    {
      "x": 8,
      "y": 17,
      "z": -9,
      "name": "*Furniture_Crude_Trapdoor_State_Definitions_OpenDoorOut",
      "rotation": 2
    },
    {
      "x": 8,
      "y": 19,
      "z": -9,
      "name": "Wood_Hardwood_Stairs",
      "rotation": 8
    },
    {
      "x": 8,
      "y": 20,
      "z": -9,
      "name": "Rock_Stone_Cobble"
    },
    {
      "x": 8,
      "y": 21,
      "z": -9,
      "name": "Rock_Stone_Cobble_Half"
    },
    {
      "x": 8,
      "y": 0,
      "z": -8,
      "name": "Soil_Grass"
    },
    {
      "x": 8,
      "y": 1,
      "z": -8,
      "name": "Rock_Stone_Cobble_Mossy"
    },
    {
      "x": 8,
      "y": 2,
      "z": -8,
      "name": "Rock_Stone_Brick"
    },
    {
      "x": 8,
      "y": 3,
      "z": -8,
      "name": "Rock_Stone_Brick"
    },
    {
      "x": 8,
      "y": 4,
      "z": -8,
      "name": "Rock_Stone_Cobble"
    },
    {
      "x": 8,
      "y": 5,
      "z": -8,
      "name": "Rock_Stone_Brick"
    },
    {
      "x": 8,
      "y": 6,
      "z": -8,
      "name": "Rock_Stone"
    },
    {
      "x": 8,
      "y": 7,
      "z": -8,
      "name": "Rock_Stone_Cobble"
    },
    {
      "x": 8,
      "y": 8,
      "z": -8,
      "name": "Rock_Calcite_Cobble"
    },
    {
      "x": 8,
      "y": 9,
      "z": -8,
      "name": "Rock_Stone_Cobble"
    },
    {
      "x": 8,
      "y": 10,
      "z": -8,
      "name": "Rock_Stone_Cobble"
    },
    {
      "x": 8,
      "y": 11,
      "z": -8,
      "name": "Rock_Stone"
    },
    {
      "x": 8,
      "y": 12,
      "z": -8,
      "name": "Rock_Stone"
    },
    {
      "x": 8,
      "y": 13,
      "z": -8,
      "name": "Rock_Stone"
    },
    {
      "x": 8,
      "y": 14,
      "z": -8,
      "name": "Rock_Stone_Brick"
    },
    {
      "x": 8,
      "y": 15,
      "z": -8,
      "name": "Wood_Beech_Trunk",
      "rotation": 2
    },
    {
      "x": 8,
      "y": 16,
      "z": -8,
      "name": "Wood_Beech_Trunk",
      "rotation": 2
    },
    {
      "x": 8,
      "y": 17,
      "z": -8,
      "name": "Wood_Beech_Trunk",
      "rotation": 2
    },
    {
      "x": 8,
      "y": 18,
      "z": -8,
      "name": "Wood_Beech_Trunk",
      "rotation": 2
    },
    {
      "x": 8,
      "y": 19,
      "z": -8,
      "name": "Wood_Beech_Trunk",
      "rotation": 2
    },
    {
      "x": 8,
      "y": 20,
      "z": -8,
      "name": "Rock_Stone_Brick"
    },
    {
      "x": 8,
      "y": 21,
      "z": -8,
      "name": "Rock_Stone_Brick"
    },
    {
      "x": 8,
      "y": 0,
      "z": -7,
      "name": "Soil_Grass"
    },
    {
      "x": 8,
      "y": 4,
      "z": -7,
      "name": "Wood_Hardwood_Planks"
    },
    {
      "x": 8,
      "y": 7,
      "z": -7,
      "name": "Wood_Torch_Wall"
    },
    {
      "x": 8,
      "y": 14,
      "z": -7,
      "name": "Wood_Hardwood_Planks"
    },
    {
      "x": 8,
      "y": 15,
      "z": -7,
      "name": "Wood_Hardwood_Planks_Half"
    },
    {
      "x": 8,
      "y": 17,
      "z": -7,
      "name": "*Furniture_Crude_Trapdoor_State_Definitions_OpenDoorOut"
    },
    {
      "x": 8,
      "y": 19,
      "z": -7,
      "name": "Wood_Hardwood_Stairs",
      "rotation": 10
    },
    {
      "x": 8,
      "y": 20,
      "z": -7,
      "name": "Rock_Stone_Brick"
    },
    {
      "x": 8,
      "y": 22,
      "z": -7,
      "name": "Rock_Stone"
    },
    {
      "x": 8,
      "y": 23,
      "z": -7,
      "name": "Rock_Stone_Cobble_Stairs",
      "rotation": 1
    },
    {
      "x": 8,
      "y": 0,
      "z": -6,
      "name": "Soil_Grass"
    },
    {
      "x": 8,
      "y": 4,
      "z": -6,
      "name": "Wood_Hardwood_Planks"
    },
    {
      "x": 8,
      "y": 14,
      "z": -6,
      "name": "Wood_Hardwood_Planks"
    },
    {
      "x": 8,
      "y": 15,
      "z": -6,
      "name": "Wood_Hardwood_Planks_Half"
    },
    {
      "x": 8,
      "y": 19,
      "z": -6,
      "name": "Wood_Hardwood_Planks_Half",
      "rotation": 8
    },
    {
      "x": 8,
      "y": 20,
      "z": -6,
      "name": "Rock_Stone_Brick"
    },
    {
      "x": 8,
      "y": 22,
      "z": -6,
      "name": "Rock_Stone_Brick"
    },
    {
      "x": 8,
      "y": 23,
      "z": -6,
      "name": "Rock_Stone_Brick"
    },
    {
      "x": 8,
      "y": 24,
      "z": -6,
      "name": "Rock_Stone_Brick"
    },
    {
      "x": 8,
      "y": 25,
      "z": -6,
      "name": "Rock_Stone_Cobble_Stairs",
      "rotation": 1
    },
    {
      "x": 8,
      "y": 0,
      "z": -5,
      "name": "Soil_Grass"
    },
    {
      "x": 8,
      "y": 4,
      "z": -5,
      "name": "Wood_Hardwood_Planks"
    },
    {
      "x": 8,
      "y": 7,
      "z": -5,
      "name": "Wood_Torch_Wall",
      "rotation": 2
    },
    {
      "x": 8,
      "y": 14,
      "z": -5,
      "name": "Wood_Hardwood_Planks"
    },
    {
      "x": 8,
      "y": 15,
      "z": -5,
      "name": "Wood_Hardwood_Planks_Half"
    },
    {
      "x": 8,
      "y": 17,
      "z": -5,
      "name": "*Furniture_Crude_Trapdoor_State_Definitions_OpenDoorOut",
      "rotation": 2
    },
    {
      "x": 8,
      "y": 19,
      "z": -5,
      "name": "Wood_Hardwood_Stairs",
      "rotation": 8
    },
    {
      "x": 8,
      "y": 20,
      "z": -5,
      "name": "Rock_Stone"
    },
    {
      "x": 8,
      "y": 22,
      "z": -5,
      "name": "Rock_Stone_Brick"
    },
    {
      "x": 8,
      "y": 23,
      "z": -5,
      "name": "Rock_Stone_Cobble_Stairs",
      "rotation": 1
    },
    {
      "x": 8,
      "y": 0,
      "z": -4,
      "name": "Soil_Grass"
    },
    {
      "x": 8,
      "y": 1,
      "z": -4,
      "name": "Rock_Stone_Brick"
    },
    {
      "x": 8,
      "y": 2,
      "z": -4,
      "name": "Rock_Stone_Brick"
    },
    {
      "x": 8,
      "y": 3,
      "z": -4,
      "name": "Rock_Stone"
    },
    {
      "x": 8,
      "y": 4,
      "z": -4,
      "name": "Rock_Stone_Cobble"
    },
    {
      "x": 8,
      "y": 5,
      "z": -4,
      "name": "Rock_Stone"
    },
    {
      "x": 8,
      "y": 6,
      "z": -4,
      "name": "Rock_Calcite_Cobble"
    },
    {
      "x": 8,
      "y": 7,
      "z": -4,
      "name": "Rock_Stone_Cobble"
    },
    {
      "x": 8,
      "y": 8,
      "z": -4,
      "name": "Rock_Stone_Cobble"
    },
    {
      "x": 8,
      "y": 9,
      "z": -4,
      "name": "Rock_Stone"
    },
    {
      "x": 8,
      "y": 10,
      "z": -4,
      "name": "Rock_Stone"
    },
    {
      "x": 8,
      "y": 11,
      "z": -4,
      "name": "Rock_Stone"
    },
    {
      "x": 8,
      "y": 12,
      "z": -4,
      "name": "Rock_Stone"
    },
    {
      "x": 8,
      "y": 13,
      "z": -4,
      "name": "Rock_Stone"
    },
    {
      "x": 8,
      "y": 14,
      "z": -4,
      "name": "Rock_Stone_Cobble"
    },
    {
      "x": 8,
      "y": 15,
      "z": -4,
      "name": "Wood_Beech_Trunk",
      "rotation": 2
    },
    {
      "x": 8,
      "y": 16,
      "z": -4,
      "name": "Wood_Beech_Trunk",
      "rotation": 2
    },
    {
      "x": 8,
      "y": 17,
      "z": -4,
      "name": "Wood_Beech_Trunk",
      "rotation": 2
    },
    {
      "x": 8,
      "y": 18,
      "z": -4,
      "name": "Wood_Beech_Trunk",
      "rotation": 2
    },
    {
      "x": 8,
      "y": 19,
      "z": -4,
      "name": "Wood_Beech_Trunk",
      "rotation": 2
    },
    {
      "x": 8,
      "y": 20,
      "z": -4,
      "name": "Rock_Stone"
    },
    {
      "x": 8,
      "y": 21,
      "z": -4,
      "name": "Rock_Stone"
    },
    {
      "x": 8,
      "y": 0,
      "z": -3,
      "name": "Soil_Dirt"
    },
    {
      "x": 8,
      "y": 1,
      "z": -3,
      "name": "Rock_Stone_Cobble_Mossy"
    },
    {
      "x": 8,
      "y": 2,
      "z": -3,
      "name": "Rock_Stone_Cobble_Mossy"
    },
    {
      "x": 8,
      "y": 5,
      "z": -3,
      "name": "Rock_Stone_Brick_Half",
      "rotation": 4
    },
    {
      "x": 8,
      "y": 6,
      "z": -3,
      "name": "Rock_Stone_Brick_Half",
      "rotation": 4
    },
    {
      "x": 8,
      "y": 7,
      "z": -3,
      "name": "Rock_Stone_Brick_Half",
      "rotation": 4
    },
    {
      "x": 8,
      "y": 8,
      "z": -3,
      "name": "Rock_Stone_Brick_Half",
      "rotation": 4
    },
    {
      "x": 8,
      "y": 9,
      "z": -3,
      "name": "Rock_Stone_Brick_Half",
      "rotation": 4
    },
    {
      "x": 8,
      "y": 10,
      "z": -3,
      "name": "Rock_Stone_Brick_Half",
      "rotation": 4
    },
    {
      "x": 8,
      "y": 11,
      "z": -3,
      "name": "Plant_Leaves_Ash",
      "support": 15
    },
    {
      "x": 8,
      "y": 12,
      "z": -3,
      "name": "Rock_Stone_Cobble_Stairs",
      "rotation": 10
    },
    {
      "x": 8,
      "y": 13,
      "z": -3,
      "name": "Rock_Stone"
    },
    {
      "x": 8,
      "y": 14,
      "z": -3,
      "name": "Rock_Stone_Brick"
    },
    {
      "x": 8,
      "y": 15,
      "z": -3,
      "name": "Rock_Stone_Cobble"
    },
    {
      "x": 8,
      "y": 17,
      "z": -3,
      "name": "*Furniture_Crude_Trapdoor_State_Definitions_OpenDoorOut"
    },
    {
      "x": 8,
      "y": 19,
      "z": -3,
      "name": "Wood_Hardwood_Stairs",
      "rotation": 10
    },
    {
      "x": 8,
      "y": 20,
      "z": -3,
      "name": "Rock_Stone_Brick"
    },
    {
      "x": 8,
      "y": 21,
      "z": -3,
      "name": "Rock_Stone_Cobble_Half"
    },
    {
      "x": 8,
      "y": 0,
      "z": -2,
      "name": "Soil_Grass"
    },
    {
      "x": 8,
      "y": 1,
      "z": -2,
      "name": "Rock_Stone_Brick_Stairs"
    },
    {
      "x": 8,
      "y": 13,
      "z": -2,
      "name": "Rock_Stone_Brick_Stairs",
      "rotation": 10
    },
    {
      "x": 8,
      "y": 14,
      "z": -2,
      "name": "Rock_Stone_Brick_Stairs",
      "rotation": 9
    },
    {
      "x": 8,
      "y": 15,
      "z": -2,
      "name": "Rock_Stone"
    },
    {
      "x": 8,
      "y": 16,
      "z": -2,
      "name": "Rock_Stone_Cobble"
    },
    {
      "x": 8,
      "y": 19,
      "z": -2,
      "name": "Wood_Hardwood_Planks_Half",
      "rotation": 8
    },
    {
      "x": 8,
      "y": 20,
      "z": -2,
      "name": "Rock_Stone_Brick"
    },
    {
      "x": 8,
      "y": 21,
      "z": -2,
      "name": "Rock_Stone_Brick_Half"
    },
    {
      "x": 8,
      "y": 0,
      "z": -1,
      "name": "Soil_Grass"
    },
    {
      "x": 8,
      "y": 20,
      "z": -1,
      "name": "Rock_Stone_Brick_Half",
      "rotation": 4
    },
    {
      "x": 9,
      "y": 0,
      "z": -11,
      "name": "Soil_Grass"
    },
    {
      "x": 9,
      "y": 0,
      "z": -10,
      "name": "Soil_Grass"
    },
    {
      "x": 9,
      "y": 14,
      "z": -10,
      "name": "Rock_Stone_Brick_Half",
      "rotation": 6
    },
    {
      "x": 9,
      "y": 15,
      "z": -10,
      "name": "Rock_Stone_Brick_Half",
      "rotation": 6
    },
    {
      "x": 9,
      "y": 16,
      "z": -10,
      "name": "Rock_Stone_Brick_Half",
      "rotation": 6
    },
    {
      "x": 9,
      "y": 0,
      "z": -9,
      "name": "Soil_Grass"
    },
    {
      "x": 9,
      "y": 1,
      "z": -9,
      "name": "Rock_Stone_Cobble_Mossy_Half"
    },
    {
      "x": 9,
      "y": 2,
      "z": -9,
      "name": "Plant_Leaves_Ash",
      "support": 15
    },
    {
      "x": 9,
      "y": 13,
      "z": -9,
      "name": "Rock_Stone_Brick_Stairs",
      "rotation": 11
    },
    {
      "x": 9,
      "y": 14,
      "z": -9,
      "name": "Rock_Stone_Brick"
    },
    {
      "x": 9,
      "y": 15,
      "z": -9,
      "name": "Rock_Stone"
    },
    {
      "x": 9,
      "y": 16,
      "z": -9,
      "name": "Rock_Stone_Cobble"
    },
    {
      "x": 9,
      "y": 19,
      "z": -9,
      "name": "*Rock_Stone_Brick_Stairs_State_Definitions_Corner_Left",
      "rotation": 8
    },
    {
      "x": 9,
      "y": 20,
      "z": -9,
      "name": "Rock_Stone_Brick"
    },
    {
      "x": 9,
      "y": 0,
      "z": -8,
      "name": "Soil_Grass"
    },
    {
      "x": 9,
      "y": 1,
      "z": -8,
      "name": "Rock_Stone"
    },
    {
      "x": 9,
      "y": 2,
      "z": -8,
      "name": "Rock_Stone_Cobble"
    },
    {
      "x": 9,
      "y": 5,
      "z": -8,
      "name": "Rock_Stone_Brick_Half",
      "rotation": 5
    },
    {
      "x": 9,
      "y": 6,
      "z": -8,
      "name": "Plant_Leaves_Ash",
      "support": 15
    },
    {
      "x": 9,
      "y": 7,
      "z": -8,
      "name": "Rock_Stone_Brick_Half",
      "rotation": 5
    },
    {
      "x": 9,
      "y": 8,
      "z": -8,
      "name": "Rock_Stone_Brick_Half",
      "rotation": 5
    },
    {
      "x": 9,
      "y": 9,
      "z": -8,
      "name": "Rock_Stone_Brick_Half",
      "rotation": 5
    },
    {
      "x": 9,
      "y": 10,
      "z": -8,
      "name": "Plant_Leaves_Ash",
      "support": 15
    },
    {
      "x": 9,
      "y": 11,
      "z": -8,
      "name": "Plant_Leaves_Ash",
      "support": 15
    },
    {
      "x": 9,
      "y": 12,
      "z": -8,
      "name": "Rock_Stone_Cobble_Stairs",
      "rotation": 11
    },
    {
      "x": 9,
      "y": 13,
      "z": -8,
      "name": "Rock_Stone_Cobble"
    },
    {
      "x": 9,
      "y": 14,
      "z": -8,
      "name": "Rock_Stone_Cobble"
    },
    {
      "x": 9,
      "y": 15,
      "z": -8,
      "name": "Rock_Stone"
    },
    {
      "x": 9,
      "y": 17,
      "z": -8,
      "name": "*Furniture_Crude_Trapdoor_State_Definitions_OpenDoorOut",
      "rotation": 1
    },
    {
      "x": 9,
      "y": 19,
      "z": -8,
      "name": "Wood_Hardwood_Stairs",
      "rotation": 11
    },
    {
      "x": 9,
      "y": 20,
      "z": -8,
      "name": "Rock_Stone"
    },
    {
      "x": 9,
      "y": 21,
      "z": -8,
      "name": "Rock_Stone_Cobble_Half"
    },
    {
      "x": 9,
      "y": 0,
      "z": -7,
      "name": "Soil_Grass"
    },
    {
      "x": 9,
      "y": 1,
      "z": -7,
      "name": "Rock_Stone_Brick"
    },
    {
      "x": 9,
      "y": 2,
      "z": -7,
      "name": "Rock_Stone_Cobble"
    },
    {
      "x": 9,
      "y": 3,
      "z": -7,
      "name": "Rock_Stone_Cobble_Mossy"
    },
    {
      "x": 9,
      "y": 4,
      "z": -7,
      "name": "Rock_Calcite_Cobble"
    },
    {
      "x": 9,
      "y": 5,
      "z": -7,
      "name": "Rock_Stone_Cobble_Mossy"
    },
    {
      "x": 9,
      "y": 6,
      "z": -7,
      "name": "Rock_Stone"
    },
    {
      "x": 9,
      "y": 7,
      "z": -7,
      "name": "Rock_Stone_Brick"
    },
    {
      "x": 9,
      "y": 8,
      "z": -7,
      "name": "Rock_Stone_Cobble_Mossy"
    },
    {
      "x": 9,
      "y": 9,
      "z": -7,
      "name": "Rock_Stone"
    },
    {
      "x": 9,
      "y": 10,
      "z": -7,
      "name": "Rock_Stone_Brick"
    },
    {
      "x": 9,
      "y": 11,
      "z": -7,
      "name": "Rock_Stone"
    },
    {
      "x": 9,
      "y": 12,
      "z": -7,
      "name": "Rock_Calcite_Cobble"
    },
    {
      "x": 9,
      "y": 13,
      "z": -7,
      "name": "Rock_Stone_Cobble"
    },
    {
      "x": 9,
      "y": 14,
      "z": -7,
      "name": "Rock_Stone"
    },
    {
      "x": 9,
      "y": 15,
      "z": -7,
      "name": "Wood_Hardwood_Planks"
    },
    {
      "x": 9,
      "y": 20,
      "z": -7,
      "name": "Rock_Stone_Cobble"
    },
    {
      "x": 9,
      "y": 21,
      "z": -7,
      "name": "Rock_Stone_Cobble"
    },
    {
      "x": 9,
      "y": 0,
      "z": -6,
      "name": "Soil_Grass"
    },
    {
      "x": 9,
      "y": 1,
      "z": -6,
      "name": "Rock_Stone_Cobble"
    },
    {
      "x": 9,
      "y": 2,
      "z": -6,
      "name": "Rock_Stone_Brick"
    },
    {
      "x": 9,
      "y": 3,
      "z": -6,
      "name": "Rock_Stone_Cobble"
    },
    {
      "x": 9,
      "y": 4,
      "z": -6,
      "name": "Rock_Stone_Brick"
    },
    {
      "x": 9,
      "y": 5,
      "z": -6,
      "name": "Rock_Stone_Brick"
    },
    {
      "x": 9,
      "y": 6,
      "z": -6,
      "name": "Deco_Iron_Bars",
      "rotation": 1
    },
    {
      "x": 9,
      "y": 7,
      "z": -6,
      "name": "Deco_Iron_Bars",
      "rotation": 1
    },
    {
      "x": 9,
      "y": 8,
      "z": -6,
      "name": "Deco_Iron_Bars",
      "rotation": 1
    },
    {
      "x": 9,
      "y": 9,
      "z": -6,
      "name": "Rock_Stone_Brick"
    },
    {
      "x": 9,
      "y": 10,
      "z": -6,
      "name": "Rock_Calcite_Cobble"
    },
    {
      "x": 9,
      "y": 11,
      "z": -6,
      "name": "Rock_Stone"
    },
    {
      "x": 9,
      "y": 12,
      "z": -6,
      "name": "Rock_Stone"
    },
    {
      "x": 9,
      "y": 13,
      "z": -6,
      "name": "Rock_Stone_Cobble"
    },
    {
      "x": 9,
      "y": 14,
      "z": -6,
      "name": "Rock_Calcite_Cobble"
    },
    {
      "x": 9,
      "y": 15,
      "z": -6,
      "name": "Wood_Hardwood_Planks"
    },
    {
      "x": 9,
      "y": 19,
      "z": -6,
      "name": "Wood_Hardwood_Planks_Half",
      "rotation": 8
    },
    {
      "x": 9,
      "y": 20,
      "z": -6,
      "name": "Rock_Stone_Cobble"
    },
    {
      "x": 9,
      "y": 21,
      "z": -6,
      "name": "Rock_Stone"
    },
    {
      "x": 9,
      "y": 22,
      "z": -6,
      "name": "Rock_Stone_Cobble_Stairs",
      "rotation": 1
    },
    {
      "x": 9,
      "y": 0,
      "z": -5,
      "name": "Soil_Dirt"
    },
    {
      "x": 9,
      "y": 1,
      "z": -5,
      "name": "Rock_Stone"
    },
    {
      "x": 9,
      "y": 2,
      "z": -5,
      "name": "Rock_Stone"
    },
    {
      "x": 9,
      "y": 3,
      "z": -5,
      "name": "Rock_Stone_Cobble"
    },
    {
      "x": 9,
      "y": 4,
      "z": -5,
      "name": "Rock_Stone"
    },
    {
      "x": 9,
      "y": 5,
      "z": -5,
      "name": "Rock_Stone_Brick"
    },
    {
      "x": 9,
      "y": 6,
      "z": -5,
      "name": "Rock_Stone_Cobble_Mossy"
    },
    {
      "x": 9,
      "y": 7,
      "z": -5,
      "name": "Rock_Stone_Cobble"
    },
    {
      "x": 9,
      "y": 8,
      "z": -5,
      "name": "Rock_Stone_Brick"
    },
    {
      "x": 9,
      "y": 9,
      "z": -5,
      "name": "Rock_Calcite_Cobble"
    },
    {
      "x": 9,
      "y": 10,
      "z": -5,
      "name": "Rock_Stone_Brick"
    },
    {
      "x": 9,
      "y": 11,
      "z": -5,
      "name": "Rock_Stone_Cobble"
    },
    {
      "x": 9,
      "y": 12,
      "z": -5,
      "name": "Rock_Stone"
    },
    {
      "x": 9,
      "y": 13,
      "z": -5,
      "name": "Rock_Stone"
    },
    {
      "x": 9,
      "y": 14,
      "z": -5,
      "name": "Rock_Stone_Brick"
    },
    {
      "x": 9,
      "y": 15,
      "z": -5,
      "name": "Wood_Hardwood_Planks"
    },
    {
      "x": 9,
      "y": 20,
      "z": -5,
      "name": "Rock_Stone_Cobble"
    },
    {
      "x": 9,
      "y": 21,
      "z": -5,
      "name": "Rock_Stone"
    },
    {
      "x": 9,
      "y": 0,
      "z": -4,
      "name": "Soil_Grass"
    },
    {
      "x": 9,
      "y": 1,
      "z": -4,
      "name": "Rock_Stone_Cobble"
    },
    {
      "x": 9,
      "y": 2,
      "z": -4,
      "name": "Rock_Stone"
    },
    {
      "x": 9,
      "y": 4,
      "z": -4,
      "name": "Rock_Stone_Brick_Half",
      "rotation": 4
    },
    {
      "x": 9,
      "y": 8,
      "z": -4,
      "name": "Rock_Stone_Brick_Half",
      "rotation": 5
    },
    {
      "x": 9,
      "y": 9,
      "z": -4,
      "name": "Plant_Leaves_Ash",
      "support": 15
    },
    {
      "x": 9,
      "y": 10,
      "z": -4,
      "name": "Plant_Leaves_Ash",
      "support": 15
    },
    {
      "x": 9,
      "y": 11,
      "z": -4,
      "name": "Plant_Leaves_Ash",
      "support": 15
    },
    {
      "x": 9,
      "y": 12,
      "z": -4,
      "name": "Rock_Stone_Cobble_Stairs",
      "rotation": 11
    },
    {
      "x": 9,
      "y": 13,
      "z": -4,
      "name": "Rock_Stone_Cobble"
    },
    {
      "x": 9,
      "y": 14,
      "z": -4,
      "name": "Rock_Stone_Cobble"
    },
    {
      "x": 9,
      "y": 15,
      "z": -4,
      "name": "Rock_Stone_Brick"
    },
    {
      "x": 9,
      "y": 17,
      "z": -4,
      "name": "*Furniture_Crude_Trapdoor_State_Definitions_OpenDoorOut",
      "rotation": 1
    },
    {
      "x": 9,
      "y": 19,
      "z": -4,
      "name": "Wood_Hardwood_Stairs",
      "rotation": 11
    },
    {
      "x": 9,
      "y": 20,
      "z": -4,
      "name": "Rock_Stone_Brick"
    },
    {
      "x": 9,
      "y": 21,
      "z": -4,
      "name": "Rock_Stone_Cobble_Half"
    },
    {
      "x": 9,
      "y": 0,
      "z": -3,
      "name": "Soil_Grass"
    },
    {
      "x": 9,
      "y": 1,
      "z": -3,
      "name": "Rock_Stone_Brick_Stairs",
      "rotation": 1
    },
    {
      "x": 9,
      "y": 13,
      "z": -3,
      "name": "Rock_Stone_Brick_Stairs",
      "rotation": 10
    },
    {
      "x": 9,
      "y": 14,
      "z": -3,
      "name": "Rock_Stone_Brick"
    },
    {
      "x": 9,
      "y": 15,
      "z": -3,
      "name": "Rock_Stone_Brick"
    },
    {
      "x": 9,
      "y": 16,
      "z": -3,
      "name": "Rock_Stone_Cobble"
    },
    {
      "x": 9,
      "y": 19,
      "z": -3,
      "name": "*Rock_Stone_Brick_Stairs_State_Definitions_Corner_Right",
      "rotation": 10
    },
    {
      "x": 9,
      "y": 20,
      "z": -3,
      "name": "Rock_Stone_Brick"
    },
    {
      "x": 9,
      "y": 0,
      "z": -2,
      "name": "Soil_Grass"
    },
    {
      "x": 9,
      "y": 14,
      "z": -2,
      "name": "Rock_Stone_Brick_Half",
      "rotation": 4
    },
    {
      "x": 9,
      "y": 15,
      "z": -2,
      "name": "Rock_Stone_Brick_Half",
      "rotation": 4
    },
    {
      "x": 9,
      "y": 16,
      "z": -2,
      "name": "Rock_Stone_Brick_Half",
      "rotation": 4
    },
    {
      "x": 9,
      "y": 0,
      "z": -1,
      "name": "Soil_Grass"
    },
    {
      "x": 10,
      "y": 0,
      "z": -11,
      "name": "Soil_Grass"
    },
    {
      "x": 10,
      "y": 0,
      "z": -10,
      "name": "Soil_Grass"
    },
    {
      "x": 10,
      "y": 0,
      "z": -9,
      "name": "Soil_Grass"
    },
    {
      "x": 10,
      "y": 14,
      "z": -9,
      "name": "Rock_Stone_Brick_Half",
      "rotation": 5
    },
    {
      "x": 10,
      "y": 15,
      "z": -9,
      "name": "Rock_Stone_Brick_Half",
      "rotation": 5
    },
    {
      "x": 10,
      "y": 16,
      "z": -9,
      "name": "Rock_Stone_Brick_Half",
      "rotation": 5
    },
    {
      "x": 10,
      "y": 0,
      "z": -8,
      "name": "Soil_Dirt"
    },
    {
      "x": 10,
      "y": 1,
      "z": -8,
      "name": "Rock_Stone_Cobble"
    },
    {
      "x": 10,
      "y": 2,
      "z": -8,
      "name": "Rock_Stone_Brick_Stairs",
      "rotation": 1
    },
    {
      "x": 10,
      "y": 13,
      "z": -8,
      "name": "Rock_Stone_Brick_Stairs",
      "rotation": 11
    },
    {
      "x": 10,
      "y": 14,
      "z": -8,
      "name": "Rock_Stone_Brick_Stairs",
      "rotation": 10
    },
    {
      "x": 10,
      "y": 15,
      "z": -8,
      "name": "Rock_Stone"
    },
    {
      "x": 10,
      "y": 16,
      "z": -8,
      "name": "Rock_Stone_Brick"
    },
    {
      "x": 10,
      "y": 19,
      "z": -8,
      "name": "Wood_Hardwood_Planks_Half",
      "rotation": 8
    },
    {
      "x": 10,
      "y": 20,
      "z": -8,
      "name": "Rock_Stone_Brick"
    },
    {
      "x": 10,
      "y": 21,
      "z": -8,
      "name": "Rock_Stone_Brick_Half"
    },
    {
      "x": 10,
      "y": 0,
      "z": -7,
      "name": "Soil_Grass"
    },
    {
      "x": 10,
      "y": 1,
      "z": -7,
      "name": "Rock_Stone_Brick_Stairs",
      "rotation": 1
    },
    {
      "x": 10,
      "y": 2,
      "z": -7,
      "name": "Plant_Leaves_Ash",
      "support": 15
    },
    {
      "x": 10,
      "y": 4,
      "z": -7,
      "name": "Plant_Leaves_Ash",
      "support": 15
    },
    {
      "x": 10,
      "y": 5,
      "z": -7,
      "name": "Plant_Leaves_Ash",
      "support": 15
    },
    {
      "x": 10,
      "y": 6,
      "z": -7,
      "name": "Rock_Stone_Brick_Half",
      "rotation": 5
    },
    {
      "x": 10,
      "y": 7,
      "z": -7,
      "name": "Rock_Stone_Brick_Half",
      "rotation": 5
    },
    {
      "x": 10,
      "y": 8,
      "z": -7,
      "name": "Rock_Stone_Brick_Half",
      "rotation": 5
    },
    {
      "x": 10,
      "y": 9,
      "z": -7,
      "name": "Rock_Stone_Brick_Half",
      "rotation": 5
    },
    {
      "x": 10,
      "y": 10,
      "z": -7,
      "name": "Rock_Stone_Brick_Half",
      "rotation": 5
    },
    {
      "x": 10,
      "y": 12,
      "z": -7,
      "name": "Plant_Leaves_Ash",
      "support": 15
    },
    {
      "x": 10,
      "y": 13,
      "z": -7,
      "name": "Rock_Stone_Brick_Stairs",
      "rotation": 11
    },
    {
      "x": 10,
      "y": 15,
      "z": -7,
      "name": "Rock_Stone_Brick"
    },
    {
      "x": 10,
      "y": 16,
      "z": -7,
      "name": "Rock_Stone_Cobble_Wall",
      "rotation": 1
    },
    {
      "x": 10,
      "y": 20,
      "z": -7,
      "name": "Rock_Stone"
    },
    {
      "x": 10,
      "y": 21,
      "z": -7,
      "name": "Rock_Stone_Cobble_Half"
    },
    {
      "x": 10,
      "y": 0,
      "z": -6,
      "name": "Soil_Grass"
    },
    {
      "x": 10,
      "y": 1,
      "z": -6,
      "name": "Rock_Stone_Cobble"
    },
    {
      "x": 10,
      "y": 2,
      "z": -6,
      "name": "Rock_Stone_Brick_Stairs",
      "rotation": 2
    },
    {
      "x": 10,
      "y": 3,
      "z": -6,
      "name": "Plant_Leaves_Ash",
      "support": 15
    },
    {
      "x": 10,
      "y": 10,
      "z": -6,
      "name": "Rock_Stone_Brick_Half",
      "rotation": 5
    },
    {
      "x": 10,
      "y": 11,
      "z": -6,
      "name": "Rock_Stone_Brick_Half",
      "rotation": 5
    },
    {
      "x": 10,
      "y": 12,
      "z": -6,
      "name": "Rock_Stone_Brick_Half",
      "rotation": 5
    },
    {
      "x": 10,
      "y": 13,
      "z": -6,
      "name": "Rock_Stone_Brick_Stairs",
      "rotation": 11
    },
    {
      "x": 10,
      "y": 14,
      "z": -6,
      "name": "*Rock_Stone_Brick_Half_State_Definitions_Block",
      "rotation": 5
    },
    {
      "x": 10,
      "y": 15,
      "z": -6,
      "name": "Rock_Stone_Cobble"
    },
    {
      "x": 10,
      "y": 16,
      "z": -6,
      "name": "Rock_Stone_Brick_Stairs",
      "rotation": 3
    },
    {
      "x": 10,
      "y": 19,
      "z": -6,
      "name": "Wood_Hardwood_Planks_Half",
      "rotation": 8
    },
    {
      "x": 10,
      "y": 20,
      "z": -6,
      "name": "Rock_Stone_Cobble_Mossy"
    },
    {
      "x": 10,
      "y": 21,
      "z": -6,
      "name": "Rock_Stone"
    },
    {
      "x": 10,
      "y": 0,
      "z": -5,
      "name": "Soil_Grass"
    },
    {
      "x": 10,
      "y": 1,
      "z": -5,
      "name": "Rock_Stone_Cobble"
    },
    {
      "x": 10,
      "y": 2,
      "z": -5,
      "name": "Rock_Stone_Cobble"
    },
    {
      "x": 10,
      "y": 3,
      "z": -5,
      "name": "Rock_Stone_Cobble_Mossy_Half"
    },
    {
      "x": 10,
      "y": 4,
      "z": -5,
      "name": "Rock_Stone_Brick_Half",
      "rotation": 5
    },
    {
      "x": 10,
      "y": 5,
      "z": -5,
      "name": "Rock_Stone_Brick_Half",
      "rotation": 5
    },
    {
      "x": 10,
      "y": 6,
      "z": -5,
      "name": "Rock_Stone_Brick_Half",
      "rotation": 5
    },
    {
      "x": 10,
      "y": 7,
      "z": -5,
      "name": "Rock_Stone_Brick_Half",
      "rotation": 5
    },
    {
      "x": 10,
      "y": 13,
      "z": -5,
      "name": "Rock_Stone_Brick_Stairs",
      "rotation": 11
    },
    {
      "x": 10,
      "y": 15,
      "z": -5,
      "name": "Rock_Stone_Cobble_Mossy"
    },
    {
      "x": 10,
      "y": 16,
      "z": -5,
      "name": "Rock_Stone_Cobble_Wall",
      "rotation": 1
    },
    {
      "x": 10,
      "y": 20,
      "z": -5,
      "name": "Rock_Stone_Brick"
    },
    {
      "x": 10,
      "y": 21,
      "z": -5,
      "name": "Rock_Stone_Cobble_Half"
    },
    {
      "x": 10,
      "y": 0,
      "z": -4,
      "name": "Soil_Grass"
    },
    {
      "x": 10,
      "y": 1,
      "z": -4,
      "name": "Rock_Stone_Brick_Stairs"
    },
    {
      "x": 10,
      "y": 13,
