{
  "version": 8,
  "blockIdVersion": 11,
  "anchorX": 0,
  "anchorY": 0,
  "anchorZ": 0,
  "blocks": [
    {
      "x": 1,
      "y": 22,
      "z": -17,
      "name": "Rock_Stone_Brick"
    },
    {
      "x": 1,
      "y": 23,
      "z": -17,
      "name": "Rock_Stone_Brick"
    },
    {
      "x": 1,
      "y": 24,
      "z": -17,
      "name": "Rock_Stone_Brick"
    },
    {
      "x": 1,
      "y": 25,
      "z": -17,
      "name": "Rock_Stone_Brick"
    },
    {
      "x": 1,
      "y": 26,
      "z": -17,
      "name": "Rock_Stone_Brick"
    },
    {
      "x": 1,
      "y": 27,
      "z": -17,
      "name": "Rock_Stone_Brick"
    },
    {
      "x": 2,
      "y": 22,
      "z": -17,
      "name": "Rock_Stone_Cobble"
    },
    {
      "x": 2,
      "y": 23,
      "z": -17,
      "name": "Rock_Stone_Cobble"
    },
    {
      "x": 2,
      "y": 24,
      "z": -17,
      "name": "Rock_Stone_Cobble"
    },
    {
      "x": 2,
      "y": 25,
      "z": -17,
      "name": "Rock_Stone_Cobble"
    },
    {
      "x": 2,
      "y": 26,
      "z": -17,
      "name": "Rock_Stone_Cobble"
    },
    {
      "x": 2,
      "y": 27,
      "z": -17,
      "name": "Rock_Stone_Cobble"
    },
    {
      "x": 2,
      "y": 18,
      "z": -16,
      "name": "Rock_Stone_Brick"
    },
    {
      "x": 2,
      "y": 19,
      "z": -16,
      "name": "Rock_Stone_Brick"
    },
    {
      "x": 2,
      "y": 20,
      "z": -16,
      "name": "Rock_Stone_Brick"
    },
    {
      "x": 2,
      "y": 21,
      "z": -16,
      "name": "Rock_Stone_Brick"
    },
    {
      "x": 2,
      "y": 28,
      "z": -16,
      "name": "Rock_Stone_Brick"
    },
    {
      "x": 2,
      "y": 29,
      "z": -16,
      "name": "Rock_Stone_Brick"
    },
    {
      "x": 2,
      "y": 30,
      "z": -16,
      "name": "Rock_Stone_Brick"
    },
    {
      "x": 3,
      "y": 23,
      "z": -17,
      "name": "Rock_Stone_Cobble"
    },
    {
      "x": 3,
      "y": 24,
      "z": -17,
      "name": "Rock_Stone_Cobble"
    },
    {
      "x": 3,
      "y": 25,
      "z": -17,
      "name": "Rock_Stone_Cobble"
    },
    {
      "x": 3,
      "y": 26,
      "z": -17,
      "name": "Rock_Stone_Cobble"
    },
    {
      "x": 3,
      "y": 18,
      "z": -16,
      "name": "Rock_Stone_Cobble"
    },
    {
      "x": 3,
      "y": 19,
      "z": -16,
      "name": "Rock_Stone_Cobble"
    },
    {
      "x": 3,
      "y": 20,
      "z": -16,
      "name": "Rock_Stone_Cobble"
    },
    {
      "x": 3,
      "y": 21,
      "z": -16,
      "name": "Rock_Stone_Cobble"
    },
    {
      "x": 3,
      "y": 22,
      "z": -16,
      "name": "Rock_Stone_Cobble"
    },
    {
      "x": 3,
      "y": 27,
      "z": -16,
      "name": "Rock_Stone_Cobble"
    },
    {
      "x": 3,
      "y": 28,
      "z": -16,
      "name": "Rock_Stone_Cobble"
    },
    {
      "x": 3,
      "y": 29,
      "z": -16,
      "name": "Rock_Stone_Cobble"
    },
    {
      "x": 3,
      "y": 30,
      "z": -16,
      "name": "Rock_Stone_Cobble"
    },
    {
      "x": 3,
      "y": 15,
      "z": -15,
      "name": "Rock_Stone_Brick"
    },
    {
      "x": 3,
      "y": 16,
      "z": -15,
      "name": "Rock_Stone_Brick"
    },
    {
      "x": 3,
      "y": 17,
      "z": -15,
      "name": "Rock_Stone_Brick"
    },
    {
      "x": 3,
      "y": 31,
      "z": -15,
      "name": "Rock_Stone_Brick"
    },
    {
      "x": 3,
      "y": 32,
      "z": -15,
      "name": "Rock_Stone_Brick"
    },
    {
      "x": 4,
      "y": 20,
      "z": -16,
      "name": "Rock_Stone_Cobble"
    },
    {
      "x": 4,
      "y": 21,
      "z": -16,
      "name": "Rock_Stone_Cobble"
    },
    {
      "x": 4,
      "y": 22,
      "z": -16,
      "name": "Rock_Stone_Cobble"
    },
    {
      "x": 4,
      "y": 23,
      "z": -16,
      "name": "Rock_Stone_Cobble"
    },
    {
      "x": 4,
      "y": 24,
      "z": -16,
      "name": "Rock_Stone_Cobble"
    },
    {
      "x": 4,
      "y": 25,
      "z": -16,
      "name": "Rock_Stone_Cobble"
    },
    {
      "x": 4,
      "y": 26,
      "z": -16,
      "name": "Rock_Stone_Cobble"
    },
    {
      "x": 4,
      "y": 27,
      "z": -16,
      "name": "Rock_Stone_Cobble"
    },
    {
      "x": 4,
      "y": 28,
      "z": -16,
      "name": "Rock_Stone_Cobble"
    },
    {
      "x": 4,
      "y": 15,
      "z": -15,
      "name": "Rock_Stone_Cobble"
    },
    {
      "x": 4,
      "y": 16,
      "z": -15,
      "name": "Rock_Stone_Cobble"
    },
    {
      "x": 4,
      "y": 17,
      "z": -15,
      "name": "Rock_Stone_Cobble"
    },
    {
      "x": 4,
      "y": 18,
      "z": -15,
      "name": "Rock_Stone_Cobble"
    },
    {
      "x": 4,
      "y": 19,
      "z": -15,
      "name": "Rock_Stone_Cobble"
    },
    {
      "x": 4,
      "y": 29,
      "z": -15,
      "name": "Rock_Stone_Cobble"
    },
    {
      "x": 4,
      "y": 30,
      "z": -15,
      "name": "Rock_Stone_Cobble"
    },
    {
      "x": 4,
      "y": 31,
      "z": -15,
      "name": "Rock_Stone_Cobble"
    },
    {
      "x": 4,
      "y": 32,
      "z": -15,
      "name": "Rock_Stone_Cobble"
    },
    {
      "x": 4,
      "y": 13,
      "z": -14,
      "name": "Rock_Stone_Brick"
    },
    {
      "x": 4,
      "y": 14,
      "z": -14,
      "name": "Rock_Stone_Brick"
    },
    {
      "x": 4,
      "y": 33,
      "z": -14,
      "name": "Rock_Stone_Brick"
    },
    {
      "x": 5,
      "y": 16,
      "z": -15,
      "name": "Rock_Stone_Cobble"
    },
    {
      "x": 5,
      "y": 17,
      "z": -15,
      "name": "Rock_Stone_Cobble"
    },
    {
      "x": 5,
      "y": 18,
      "z": -15,
      "name": "Rock_Stone_Cobble"
    },
    {
      "x": 5,
      "y": 19,
      "z": -15,
      "name": "Rock_Stone_Cobble"
    },
    {
      "x": 5,
      "y": 20,
      "z": -15,
      "name": "Rock_Stone_Cobble"
    },
    {
      "x": 5,
      "y": 21,
      "z": -15,
      "name": "Rock_Stone_Cobble"
    },
    {
      "x": 5,
      "y": 22,
      "z": -15,
      "name": "Rock_Stone_Cobble"
    },
    {
      "x": 5,
      "y": 23,
      "z": -15,
      "name": "Rock_Stone_Brick"
    },
    {
      "x": 5,
      "y": 24,
      "z": -15,
      "name": "Rock_Stone_Brick"
    },
    {
      "x": 5,
      "y": 25,
      "z": -15,
      "name": "Rock_Stone_Brick"
    },
    {
      "x": 5,
      "y": 26,
      "z": -15,
      "name": "Rock_Stone_Brick"
    },
    {
      "x": 5,
      "y": 27,
      "z": -15,
      "name": "Rock_Stone_Brick"
    },
    {
      "x": 5,
      "y": 28,
      "z": -15,
      "name": "Rock_Stone_Brick"
    },
    {
      "x": 5,
      "y": 13,
      "z": -14,
      "name": "Rock_Stone_Cobble"
    },
    {
      "x": 5,
      "y": 14,
      "z": -14,
      "name": "Rock_Stone_Cobble"
    },
    {
      "x": 5,
      "y": 15,
      "z": -14,
      "name": "Rock_Stone_Cobble"
    },
    {
      "x": 5,
      "y": 29,
      "z": -14,
      "name": "Rock_Stone_Brick"
    },
    {
      "x": 5,
      "y": 30,
      "z": -14,
      "name": "Rock_Stone_Brick"
    },
    {
      "x": 5,
      "y": 31,
      "z": -14,
      "name": "Rock_Stone_Brick"
    },
    {
      "x": 5,
      "y": 32,
      "z": -14,
      "name": "Rock_Stone_Brick"
    },
    {
      "x": 5,
      "y": 33,
      "z": -14,
      "name": "Rock_Stone_Brick"
    },
    {
      "x": 5,
      "y": 12,
      "z": -13,
      "name": "Rock_Stone_Brick"
    },
    {
      "x": 5,
      "y": 34,
      "z": -13,
      "name": "Rock_Stone_Brick"
    },
    {
      "x": 5,
      "y": 21,
      "z": -6,
      "name": "Rock_Calcite_Brick_Smooth"
    },
    {
      "x": 5,
      "y": 22,
      "z": -6,
      "name": "Rock_Calcite_Brick_Smooth"
    },
    {
      "x": 5,
      "y": 20,
      "z": -5,
      "name": "Rock_Calcite_Brick_Smooth"
    },
    {
      "x": 5,
      "y": 21,
      "z": -5,
      "name": "Rock_Calcite_Brick_Smooth"
    },
    {
      "x": 5,
      "y": 22,
      "z": -5,
      "name": "Rock_Calcite_Brick_Smooth"
    },
    {
      "x": 5,
      "y": 19,
      "z": -4,
      "name": "Rock_Calcite_Brick_Smooth"
    },
    {
      "x": 5,
      "y": 20,
      "z": -4,
      "name": "Rock_Calcite_Brick_Smooth"
    },
    {
      "x": 5,
      "y": 21,
      "z": -4,
      "name": "Rock_Calcite_Brick_Smooth"
    },
    {
      "x": 5,
      "y": 21,
      "z": -3,
      "name": "Rock_Calcite_Brick_Smooth"
    },
    {
      "x": 6,
      "y": 14,
      "z": -14,
      "name": "Rock_Stone_Cobble"
    },
    {
      "x": 6,
      "y": 15,
      "z": -14,
      "name": "Rock_Stone_Cobble"
    },
    {
      "x": 6,
      "y": 16,
      "z": -14,
      "name": "Rock_Stone_Cobble"
    },
    {
      "x": 6,
      "y": 17,
      "z": -14,
      "name": "Rock_Stone_Cobble"
    },
    {
      "x": 6,
      "y": 18,
      "z": -14,
      "name": "Rock_Stone_Cobble"
    },
    {
      "x": 6,
      "y": 19,
      "z": -14,
      "name": "Rock_Stone_Brick"
    },
    {
      "x": 6,
      "y": 20,
      "z": -14,
      "name": "Rock_Stone_Brick"
    },
    {
      "x": 6,
      "y": 21,
      "z": -14,
      "name": "Rock_Stone_Brick"
    },
    {
      "x": 6,
      "y": 22,
      "z": -14,
      "name": "Rock_Stone_Brick"
    },
    {
      "x": 6,
      "y": 23,
      "z": -14,
      "name": "Rock_Stone_Cobble"
    },
    {
      "x": 6,
      "y": 24,
      "z": -14,
      "name": "Rock_Stone_Cobble"
    },
    {
      "x": 6,
      "y": 25,
      "z": -14,
      "name": "Rock_Stone_Cobble"
    },
    {
      "x": 6,
      "y": 26,
      "z": -14,
      "name": "Rock_Stone_Cobble"
    },
    {
      "x": 6,
      "y": 27,
      "z": -14,
      "name": "Rock_Stone_Cobble"
    },
    {
      "x": 6,
      "y": 28,
      "z": -14,
      "name": "Rock_Stone_Cobble"
    },
    {
      "x": 6,
      "y": 13,
      "z": -13,
      "name": "Rock_Stone_Cobble"
    },
    {
      "x": 6,
      "y": 29,
      "z": -13,
      "name": "Rock_Stone_Cobble"
    },
    {
      "x": 6,
      "y": 30,
      "z": -13,
      "name": "Rock_Stone_Cobble"
    },
    {
      "x": 6,
      "y": 31,
      "z": -13,
      "name": "Rock_Stone_Brick"
    },
    {
      "x": 6,
      "y": 32,
      "z": -13,
      "name": "Rock_Stone_Brick"
    },
    {
      "x": 6,
      "y": 33,
      "z": -13,
      "name": "Rock_Stone_Brick"
    },
    {
      "x": 6,
      "y": 11,
      "z": -12,
      "name": "Rock_Stone_Brick"
    },
    {
      "x": 6,
      "y": 12,
      "z": -12,
      "name": "Rock_Stone_Cobble"
    },
    {
      "x": 6,
      "y": 34,
      "z": -12,
      "name": "Rock_Stone_Brick"
    },
    {
      "x": 6,
      "y": 35,
      "z": -12,
      "name": "Rock_Stone_Brick"
    },
    {
      "x": 6,
      "y": 0,
      "z": -8,
      "name": "*Rock_Stone_Brick_Stairs_State_Definitions_Corner_Right",
      "rotation": 3
    },
    {
      "x": 6,
      "y": 23,
      "z": -8,
      "name": "Rock_Calcite_Brick_Smooth"
    },
    {
      "x": 6,
      "y": 24,
      "z": -8,
      "name": "Rock_Calcite_Brick_Smooth"
    },
    {
      "x": 6,
      "y": 0,
      "z": -7,
      "name": "Rock_Stone_Brick_Stairs",
      "rotation": 3
    },
    {
      "x": 6,
      "y": 21,
      "z": -7,
      "name": "Rock_Calcite_Brick_Smooth"
    },
    {
      "x": 6,
      "y": 22,
      "z": -7,
      "name": "Rock_Calcite_Brick_Smooth"
    },
    {
      "x": 6,
      "y": 23,
      "z": -7,
      "name": "Rock_Calcite_Brick_Smooth"
    },
    {
      "x": 6,
      "y": 24,
      "z": -7,
      "name": "Rock_Calcite_Brick_Smooth"
    },
    {
      "x": 6,
      "y": 0,
      "z": -6,
      "name": "Rock_Stone_Brick_Stairs",
      "rotation": 3
    },
    {
      "x": 6,
      "y": 21,
      "z": -6,
      "name": "Rock_Calcite_Brick_Smooth"
    },
    {
      "x": 6,
      "y": 22,
      "z": -6,
      "name": "Soil_Dirt"
    },
    {
      "x": 6,
      "y": 23,
      "z": -6,
      "name": "Rock_Calcite_Brick_Smooth"
    },
    {
      "x": 6,
      "y": 24,
      "z": -6,
      "name": "Rock_Calcite_Brick_Smooth"
    },
    {
      "x": 6,
      "y": 0,
      "z": -5,
      "name": "Rock_Stone_Brick_Stairs",
      "rotation": 3
    },
    {
      "x": 6,
      "y": 19,
      "z": -5,
      "name": "Rock_Calcite_Brick_Smooth"
    },
    {
      "x": 6,
      "y": 20,
      "z": -5,
      "name": "Rock_Calcite_Brick_Smooth"
    },
    {
      "x": 6,
      "y": 21,
      "z": -5,
      "name": "Soil_Dirt"
    },
    {
      "x": 6,
      "y": 22,
      "z": -5,
      "name": "Rock_Calcite_Brick_Smooth"
    },
    {
      "x": 6,
      "y": 23,
      "z": -5,
      "name": "Rock_Calcite_Brick_Smooth"
    },
    {
      "x": 6,
      "y": 0,
      "z": -4,
      "name": "*Rock_Stone_Brick_Stairs_State_Definitions_Corner_Right"
    },
    {
      "x": 6,
      "y": 18,
      "z": -4,
      "name": "Rock_Calcite_Brick_Smooth"
    },
    {
      "x": 6,
      "y": 19,
      "z": -4,
      "name": "Soil_Dirt"
    },
    {
      "x": 6,
      "y": 21,
      "z": -4,
      "name": "Soil_Dirt"
    },
    {
      "x": 6,
      "y": 22,
      "z": -4,
      "name": "Rock_Calcite_Brick_Smooth"
    },
    {
      "x": 6,
      "y": 19,
      "z": -3,
      "name": "Rock_Calcite_Brick_Smooth"
    },
    {
      "x": 6,
      "y": 20,
      "z": -3,
      "name": "Rock_Calcite_Brick_Smooth"
    },
    {
      "x": 6,
      "y": 21,
      "z": -3,
      "name": "Rock_Calcite_Brick_Smooth"
    },
    {
      "x": 6,
      "y": 20,
      "z": -2,
      "name": "Rock_Calcite_Brick_Smooth"
    },
    {
      "x": 7,
      "y": 14,
      "z": -13,
      "name": "Rock_Stone_Cobble"
    },
    {
      "x": 7,
      "y": 15,
      "z": -13,
      "name": "Rock_Stone_Cobble"
    },
    {
      "x": 7,
      "y": 16,
      "z": -13,
      "name": "Rock_Stone_Cobble"
    },
    {
      "x": 7,
      "y": 17,
      "z": -13,
      "name": "Rock_Stone_Brick"
    },
    {
      "x": 7,
      "y": 18,
      "z": -13,
      "name": "Rock_Stone_Brick"
    },
    {
      "x": 7,
      "y": 19,
      "z": -13,
      "name": "Rock_Stone_Cobble"
    },
    {
      "x": 7,
      "y": 20,
      "z": -13,
      "name": "Rock_Stone_Cobble"
    },
    {
      "x": 7,
      "y": 21,
      "z": -13,
      "name": "Rock_Stone_Cobble"
    },
    {
      "x": 7,
      "y": 22,
      "z": -13,
      "name": "Rock_Stone_Cobble"
    },
    {
      "x": 7,
      "y": 23,
      "z": -13,
      "name": "Rock_Stone_Cobble"
    },
    {
      "x": 7,
      "y": 24,
      "z": -13,
      "name": "Rock_Stone_Cobble"
    },
    {
      "x": 7,
      "y": 25,
      "z": -13,
      "name": "Rock_Stone_Cobble"
    },
    {
      "x": 7,
      "y": 26,
      "z": -13,
      "name": "Rock_Stone_Cobble"
    },
    {
      "x": 7,
      "y": 27,
      "z": -13,
      "name": "Rock_Stone_Cobble"
    },
    {
      "x": 7,
      "y": 28,
      "z": -13,
      "name": "Rock_Stone_Cobble"
    },
    {
      "x": 7,
      "y": 28,
      "z": -12,
      "name": "Rock_Stone_Brick"
    },
    {
      "x": 7,
      "y": 29,
      "z": -12,
      "name": "Rock_Stone_Brick"
    },
    {
      "x": 7,
      "y": 30,
      "z": -12,
      "name": "Rock_Stone_Brick"
    },
    {
      "x": 7,
      "y": 0,
      "z": -9,
      "name": "*Rock_Stone_Brick_Stairs_State_Definitions_Corner_Right",
      "rotation": 3
    },
    {
      "x": 7,
      "y": 23,
      "z": -9,
      "name": "Rock_Calcite_Brick_Smooth"
    },
    {
      "x": 7,
      "y": 24,
      "z": -9,
      "name": "Rock_Calcite_Brick_Smooth"
    },
    {
      "x": 7,
      "y": 0,
      "z": -8,
      "name": "*Rock_Stone_Brick_Stairs_State_Definitions_Inverted_Corner_Left",
      "rotation": 2
    },
    {
      "x": 7,
      "y": 22,
      "z": -8,
      "name": "Rock_Calcite_Brick_Smooth"
    },
    {
      "x": 7,
      "y": 23,
      "z": -8,
      "name": "Soil_Dirt"
    },
    {
      "x": 7,
      "y": 24,
      "z": -8,
      "name": "Soil_Dirt"
    },
    {
      "x": 7,
      "y": 25,
      "z": -8,
      "name": "Rock_Stone_Brick_Stairs",
      "rotation": 3
    },
    {
      "x": 7,
      "y": 0,
      "z": -7,
      "name": "Prototype_Rock_Concrete_Brick_Half",
      "rotation": 8
    },
    {
      "x": 7,
      "y": 21,
      "z": -7,
      "name": "Rock_Calcite_Brick_Smooth"
    },
    {
      "x": 7,
      "y": 22,
      "z": -7,
      "name": "Soil_Dirt"
    },
    {
      "x": 7,
      "y": 23,
      "z": -7,
      "name": "Soil_Dirt"
    },
    {
      "x": 7,
      "y": 24,
      "z": -7,
      "name": "Soil_Dirt"
    },
    {
      "x": 7,
      "y": 25,
      "z": -7,
      "name": "Rock_Stone_Brick_Stairs",
      "rotation": 3
    },
    {
      "x": 7,
      "y": 0,
      "z": -6,
      "name": "Prototype_Rock_Concrete_Brick_Half",
      "rotation": 8
    },
    {
      "x": 7,
      "y": 3,
      "z": -6,
      "name": "Rock_Stone_Brick"
    },
    {
      "x": 7,
      "y": 4,
      "z": -6,
      "name": "Rock_Stone"
    },
    {
      "x": 7,
      "y": 20,
      "z": -6,
      "name": "Rock_Calcite_Brick_Smooth"
    },
    {
      "x": 7,
      "y": 23,
      "z": -6,
      "name": "Soil_Dirt"
    },
    {
      "x": 7,
      "y": 24,
      "z": -6,
      "name": "Soil_Dirt"
    },
    {
      "x": 7,
      "y": 25,
      "z": -6,
      "name": "Rock_Stone_Brick_Stairs",
      "rotation": 3
    },
    {
      "x": 7,
      "y": 0,
      "z": -5,
      "name": "Prototype_Rock_Concrete_Brick_Half",
      "rotation": 8
    },
    {
      "x": 7,
      "y": 3,
      "z": -5,
      "name": "Rock_Stone_Brick"
    },
    {
      "x": 7,
      "y": 4,
      "z": -5,
      "name": "Rock_Stone"
    },
    {
      "x": 7,
      "y": 5,
      "z": -5,
      "name": "Rock_Stone"
    },
    {
      "x": 7,
      "y": 19,
      "z": -5,
      "name": "Rock_Calcite_Brick_Smooth"
    },
    {
      "x": 7,
      "y": 21,
      "z": -5,
      "name": "Soil_Dirt"
    },
    {
      "x": 7,
      "y": 22,
      "z": -5,
      "name": "Soil_Dirt"
    },
    {
      "x": 7,
      "y": 24,
      "z": -5,
      "name": "Rock_Calcite_Brick_Smooth"
    },
    {
      "x": 7,
      "y": 0,
      "z": -4,
      "name": "*Rock_Stone_Brick_Stairs_State_Definitions_Inverted_Corner_Left",
      "rotation": 3
    },
    {
      "x": 7,
      "y": 3,
      "z": -4,
      "name": "Rock_Stone_Brick"
    },
    {
      "x": 7,
      "y": 4,
      "z": -4,
      "name": "Rock_Stone"
    },
    {
      "x": 7,
      "y": 18,
      "z": -4,
      "name": "Rock_Calcite_Brick_Smooth"
    },
    {
      "x": 7,
      "y": 20,
      "z": -4,
      "name": "Soil_Dirt"
    },
    {
      "x": 7,
      "y": 21,
      "z": -4,
      "name": "Rock_Calcite_Brick_Smooth"
    },
    {
      "x": 7,
      "y": 22,
      "z": -4,
      "name": "Rock_Calcite_Brick_Smooth"
    },
    {
      "x": 7,
      "y": 23,
      "z": -4,
      "name": "Rock_Calcite_Brick_Smooth"
    },
    {
      "x": 7,
      "y": 0,
      "z": -3,
      "name": "*Rock_Stone_Brick_Stairs_State_Definitions_Corner_Right"
    },
    {
      "x": 7,
      "y": 3,
      "z": -3,
      "name": "Rock_Stone_Brick"
    },
    {
      "x": 7,
      "y": 19,
      "z": -3,
      "name": "Rock_Calcite_Brick_Smooth"
    },
    {
      "x": 7,
      "y": 20,
      "z": -3,
      "name": "Soil_Dirt"
    },
    {
      "x": 7,
      "y": 21,
      "z": -3,
      "name": "Rock_Calcite_Brick_Smooth"
    },
    {
      "x": 7,
      "y": 19,
      "z": -2,
      "name": "Rock_Calcite_Brick_Smooth"
    },
    {
      "x": 7,
      "y": 20,
      "z": -2,
      "name": "Rock_Calcite_Brick_Smooth"
    },
    {
      "x": 8,
      "y": 17,
      "z": -13,
      "name": "Rock_Stone_Cobble"
    },
    {
      "x": 8,
      "y": 18,
      "z": -13,
      "name": "Rock_Stone_Cobble"
    },
    {
      "x": 8,
      "y": 19,
      "z": -13,
      "name": "Rock_Stone_Cobble"
    },
    {
      "x": 8,
      "y": 20,
      "z": -13,
      "name": "Rock_Stone_Cobble"
    },
    {
      "x": 8,
      "y": 21,
      "z": -13,
      "name": "Rock_Stone_Cobble"
    },
    {
      "x": 8,
      "y": 15,
      "z": -12,
      "name": "Rock_Stone_Cobble"
    },
    {
      "x": 8,
      "y": 16,
      "z": -12,
      "name": "Rock_Stone_Brick"
    },
    {
      "x": 8,
      "y": 21,
      "z": -12,
      "name": "Rock_Stone_Cobble"
    },
    {
      "x": 8,
      "y": 22,
      "z": -12,
      "name": "Rock_Stone_Cobble"
    },
    {
      "x": 8,
      "y": 23,
      "z": -12,
      "name": "Rock_Stone_Cobble"
    },
    {
      "x": 8,
      "y": 24,
      "z": -12,
      "name": "Rock_Stone_Cobble"
    },
    {
      "x": 8,
      "y": 25,
      "z": -12,
      "name": "Rock_Stone_Cobble"
    },
    {
      "x": 8,
      "y": 26,
      "z": -12,
      "name": "Rock_Stone_Cobble"
    },
    {
      "x": 8,
      "y": 27,
      "z": -12,
      "name": "Rock_Stone_Cobble"
    },
    {
      "x": 8,
      "y": 26,
      "z": -11,
      "name": "Rock_Stone_Brick"
    },
    {
      "x": 8,
      "y": 27,
      "z": -11,
      "name": "Rock_Stone_Brick"
    },
    {
      "x": 8,
      "y": 0,
      "z": -10,
      "name": "*Rock_Stone_Brick_Stairs_State_Definitions_Corner_Right",
      "rotation": 3
    },
    {
      "x": 8,
      "y": 0,
      "z": -9,
      "name": "*Rock_Stone_Brick_Stairs_State_Definitions_Inverted_Corner_Left",
      "rotation": 2
    },
    {
      "x": 8,
      "y": 23,
      "z": -9,
      "name": "Rock_Calcite_Brick_Smooth"
    },
    {
      "x": 8,
      "y": 24,
      "z": -9,
      "name": "Rock_Calcite_Brick_Smooth"
    },
    {
      "x": 8,
      "y": 0,
      "z": -8,
      "name": "Prototype_Rock_Concrete_Brick_Half",
      "rotation": 8
    },
    {
      "x": 8,
      "y": 3,
      "z": -8,
      "name": "Rock_Stone_Brick"
    },
    {
      "x": 8,
      "y": 20,
      "z": -8,
      "name": "Rock_Stone"
    },
    {
      "x": 8,
      "y": 21,
      "z": -8,
      "name": "Rock_Stone"
    },
    {
      "x": 8,
      "y": 22,
      "z": -8,
      "name": "Rock_Calcite_Brick_Smooth"
    },
    {
      "x": 8,
      "y": 23,
      "z": -8,
      "name": "Rock_Stone_Cobble"
    },
    {
      "x": 8,
      "y": 24,
      "z": -8,
      "name": "Rock_Stone_Cobble"
    },
    {
      "x": 8,
      "y": 25,
      "z": -8,
      "name": "Rock_Calcite_Brick_Smooth"
    },
    {
      "x": 8,
      "y": 0,
      "z": -7,
      "name": "Prototype_Rock_Concrete_Brick_Half",
      "rotation": 8
    },
    {
      "x": 8,
      "y": 1,
      "z": -7,
      "name": "Prototype_Rock_Concrete_Brick"
    },
    {
      "x": 8,
      "y": 2,
      "z": -7,
      "name": "Prototype_Rock_Concrete_Brick_Half"
    },
    {
      "x": 8,
      "y": 3,
      "z": -7,
      "name": "Rock_Stone_Brick"
    },
    {
      "x": 8,
      "y": 4,
      "z": -7,
      "name": "Rock_Stone"
    },
    {
      "x": 8,
      "y": 14,
      "z": -7,
      "name": "Rock_Stone"
    },
    {
      "x": 8,
      "y": 15,
      "z": -7,
      "name": "Rock_Stone"
    },
    {
      "x": 8,
      "y": 16,
      "z": -7,
      "name": "Rock_Stone"
    },
    {
      "x": 8,
      "y": 17,
      "z": -7,
      "name": "Rock_Stone"
    },
    {
      "x": 8,
      "y": 18,
      "z": -7,
      "name": "Rock_Stone"
    },
    {
      "x": 8,
      "y": 19,
      "z": -7,
      "name": "Rock_Stone"
    },
    {
      "x": 8,
      "y": 20,
      "z": -7,
      "name": "Rock_Stone"
    },
    {
      "x": 8,
      "y": 21,
      "z": -7,
      "name": "Rock_Stone_Cobble"
    },
    {
      "x": 8,
      "y": 22,
      "z": -7,
      "name": "Rock_Stone_Cobble"
    },
    {
      "x": 8,
      "y": 23,
      "z": -7,
      "name": "Rock_Stone_Cobble"
    },
    {
      "x": 8,
      "y": 24,
      "z": -7,
      "name": "Rock_Stone_Cobble"
    },
    {
      "x": 8,
      "y": 25,
      "z": -7,
      "name": "Rock_Calcite_Brick_Smooth"
    },
    {
      "x": 8,
      "y": 0,
      "z": -6,
      "name": "Prototype_Rock_Concrete_Brick_Half",
      "rotation": 8
    },
    {
      "x": 8,
      "y": 1,
      "z": -6,
      "name": "Prototype_Rock_Concrete_Brick"
    },
    {
      "x": 8,
      "y": 2,
      "z": -6,
      "name": "Prototype_Rock_Concrete_Brick_Half"
    },
    {
      "x": 8,
      "y": 4,
      "z": -6,
      "name": "Rock_Stone"
    },
    {
      "x": 8,
      "y": 5,
      "z": -6,
      "name": "Rock_Stone"
    },
    {
      "x": 8,
      "y": 6,
      "z": -6,
      "name": "Rock_Stone"
    },
    {
      "x": 8,
      "y": 13,
      "z": -6,
      "name": "Rock_Stone"
    },
    {
      "x": 8,
      "y": 14,
      "z": -6,
      "name": "Rock_Stone"
    },
    {
      "x": 8,
      "y": 15,
      "z": -6,
      "name": "Rock_Stone"
    },
    {
      "x": 8,
      "y": 16,
      "z": -6,
      "name": "Rock_Stone"
    },
    {
      "x": 8,
      "y": 17,
      "z": -6,
      "name": "Rock_Stone"
    },
    {
      "x": 8,
      "y": 18,
      "z": -6,
      "name": "Rock_Stone"
    },
    {
      "x": 8,
      "y": 19,
      "z": -6,
      "name": "Rock_Stone"
    },
    {
      "x": 8,
      "y": 20,
      "z": -6,
      "name": "Rock_Stone_Cobble"
    },
    {
      "x": 8,
      "y": 21,
      "z": -6,
      "name": "Rock_Stone_Cobble"
    },
    {
      "x": 8,
      "y": 22,
      "z": -6,
      "name": "Rock_Stone_Cobble"
    },
    {
      "x": 8,
      "y": 23,
      "z": -6,
      "name": "Rock_Stone_Cobble"
    },
    {
      "x": 8,
      "y": 24,
      "z": -6,
      "name": "Rock_Stone_Cobble"
    },
    {
      "x": 8,
      "y": 25,
      "z": -6,
      "name": "Rock_Calcite_Brick_Smooth"
    },
    {
      "x": 8,
      "y": 0,
      "z": -5,
      "name": "Prototype_Rock_Concrete_Brick_Half",
      "rotation": 8
    },
    {
      "x": 8,
      "y": 1,
      "z": -5,
      "name": "Prototype_Rock_Concrete_Brick"
    },
    {
      "x": 8,
      "y": 2,
      "z": -5,
      "name": "Prototype_Rock_Concrete_Brick_Half"
    },
    {
      "x": 8,
      "y": 4,
      "z": -5,
      "name": "Rock_Stone"
    },
    {
      "x": 8,
      "y": 5,
      "z": -5,
      "name": "Rock_Stone"
    },
    {
      "x": 8,
      "y": 6,
      "z": -5,
      "name": "Rock_Stone"
    },
    {
      "x": 8,
      "y": 7,
      "z": -5,
      "name": "Rock_Stone"
    },
    {
      "x": 8,
      "y": 14,
      "z": -5,
      "name": "Rock_Stone"
    },
    {
      "x": 8,
      "y": 15,
      "z": -5,
      "name": "Rock_Stone"
    },
    {
      "x": 8,
      "y": 16,
      "z": -5,
      "name": "Rock_Stone"
    },
    {
      "x": 8,
      "y": 17,
      "z": -5,
      "name": "Rock_Stone"
    },
    {
      "x": 8,
      "y": 18,
      "z": -5,
      "name": "Rock_Stone"
    },
    {
      "x": 8,
      "y": 19,
      "z": -5,
      "name": "Rock_Stone_Cobble"
    },
    {
      "x": 8,
      "y": 20,
      "z": -5,
      "name": "Rock_Stone_Cobble"
    },
    {
      "x": 8,
      "y": 21,
      "z": -5,
      "name": "Rock_Stone_Cobble"
    },
    {
      "x": 8,
      "y": 22,
      "z": -5,
      "name": "Rock_Stone_Cobble"
    },
    {
      "x": 8,
      "y": 23,
      "z": -5,
      "name": "Soil_Dirt"
    },
    {
      "x": 8,
      "y": 24,
      "z": -5,
      "name": "Rock_Calcite_Brick_Smooth"
    },
    {
      "x": 8,
      "y": 0,
      "z": -4,
      "name": "Prototype_Rock_Concrete_Brick_Half",
      "rotation": 8
    },
    {
      "x": 8,
      "y": 4,
      "z": -4,
      "name": "Rock_Stone"
    },
    {
      "x": 8,
      "y": 5,
      "z": -4,
      "name": "Rock_Stone"
    },
    {
      "x": 8,
      "y": 6,
      "z": -4,
      "name": "Rock_Stone"
    },
    {
      "x": 8,
      "y": 17,
      "z": -4,
      "name": "Rock_Calcite_Brick_Smooth"
    },
    {
      "x": 8,
      "y": 18,
      "z": -4,
      "name": "Soil_Dirt"
    },
    {
      "x": 8,
      "y": 20,
      "z": -4,
      "name": "Soil_Dirt"
    },
    {
      "x": 8,
      "y": 21,
      "z": -4,
      "name": "Rock_Calcite_Brick_Smooth"
    },
    {
      "x": 8,
      "y": 22,
      "z": -4,
      "name": "Rock_Calcite_Brick_Smooth"
    },
    {
      "x": 8,
      "y": 23,
      "z": -4,
      "name": "Rock_Calcite_Brick_Smooth"
    },
    {
      "x": 8,
      "y": 0,
      "z": -3,
      "name": "*Rock_Stone_Brick_Stairs_State_Definitions_Inverted_Corner_Left",
      "rotation": 3
    },
    {
      "x": 8,
      "y": 4,
      "z": -3,
      "name": "Rock_Stone"
    },
    {
      "x": 8,
      "y": 5,
      "z": -3,
      "name": "Rock_Stone"
    },
    {
      "x": 8,
      "y": 18,
      "z": -3,
      "name": "Rock_Calcite_Brick_Smooth"
    },
    {
      "x": 8,
      "y": 19,
      "z": -3,
      "name": "Soil_Dirt"
    },
    {
      "x": 8,
      "y": 20,
      "z": -3,
      "name": "Soil_Dirt"
    },
    {
      "x": 8,
      "y": 21,
      "z": -3,
      "name": "Rock_Calcite_Brick_Smooth"
    },
    {
      "x": 8,
      "y": 0,
      "z": -2,
      "name": "*Rock_Stone_Brick_Stairs_State_Definitions_Corner_Right"
    },
    {
      "x": 8,
      "y": 4,
      "z": -2,
      "name": "Rock_Stone_Brick"
    },
    {
      "x": 8,
      "y": 5,
      "z": -2,
      "name": "Rock_Stone_Brick"
    },
    {
      "x": 8,
      "y": 19,
      "z": -2,
      "name": "Rock_Calcite_Brick_Smooth"
    },
    {
      "x": 8,
      "y": 20,
      "z": -2,
      "name": "Rock_Calcite_Brick_Smooth"
    },
    {
      "x": 9,
      "y": 16,
      "z": -12,
      "name": "Rock_Stone_Cobble"
    },
    {
      "x": 9,
      "y": 17,
      "z": -12,
      "name": "Rock_Stone_Cobble"
    },
    {
      "x": 9,
      "y": 18,
      "z": -12,
      "name": "Rock_Stone_Cobble"
    },
    {
      "x": 9,
      "y": 19,
      "z": -12,
      "name": "Rock_Stone_Cobble"
    },
    {
      "x": 9,
      "y": 20,
      "z": -12,
      "name": "Rock_Stone_Cobble"
    },
    {
      "x": 9,
      "y": 0,
      "z": -11,
      "name": "*Rock_Stone_Brick_Stairs_State_Definitions_Corner_Right",
      "rotation": 3
    },
    {
      "x": 9,
      "y": 15,
      "z": -11,
      "name": "Rock_Stone_Brick"
    },
    {
      "x": 9,
      "y": 21,
      "z": -11,
      "name": "Rock_Stone_Cobble"
    },
    {
      "x": 9,
      "y": 22,
      "z": -11,
      "name": "Rock_Stone_Cobble"
    },
    {
      "x": 9,
      "y": 23,
      "z": -11,
      "name": "Rock_Stone_Cobble"
    },
    {
      "x": 9,
      "y": 24,
      "z": -11,
      "name": "Rock_Stone_Cobble"
    },
    {
      "x": 9,
      "y": 25,
      "z": -11,
      "name": "Rock_Stone_Brick"
    },
    {
      "x": 9,
      "y": 0,
      "z": -10,
      "name": "*Rock_Stone_Brick_Stairs_State_Definitions_Inverted_Corner_Left",
      "rotation": 2
    },
    {
      "x": 9,
      "y": 0,
      "z": -9,
      "name": "Prototype_Rock_Concrete_Brick_Half",
      "rotation": 8
    },
    {
      "x": 9,
      "y": 3,
      "z": -9,
      "name": "Rock_Stone_Brick"
    },
    {
      "x": 9,
      "y": 20,
      "z": -9,
      "name": "Rock_Stone"
    },
    {
      "x": 9,
      "y": 21,
      "z": -9,
      "name": "Rock_Stone"
    },
    {
      "x": 9,
      "y": 22,
      "z": -9,
      "name": "Rock_Stone"
    },
    {
      "x": 9,
      "y": 23,
      "z": -9,
      "name": "Rock_Calcite_Brick_Smooth"
    },
    {
      "x": 9,
      "y": 24,
      "z": -9,
      "name": "Rock_Calcite_Brick_Smooth"
    },
    {
      "x": 9,
      "y": 0,
      "z": -8,
      "name": "Prototype_Rock_Concrete_Brick_Half",
      "rotation": 8
    },
    {
      "x": 9,
      "y": 1,
      "z": -8,
      "name": "Prototype_Rock_Concrete_Brick"
    },
    {
      "x": 9,
      "y": 2,
      "z": -8,
      "name": "Prototype_Rock_Concrete_Brick_Half"
    },
    {
      "x": 9,
      "y": 4,
      "z": -8,
      "name": "Rock_Stone"
    },
    {
      "x": 9,
      "y": 18,
      "z": -8,
      "name": "Rock_Stone"
    },
    {
      "x": 9,
      "y": 19,
      "z": -8,
      "name": "Rock_Stone"
    },
    {
      "x": 9,
      "y": 24,
      "z": -8,
      "name": "Rock_Stone_Cobble"
    },
    {
      "x": 9,
      "y": 25,
      "z": -8,
      "name": "Rock_Calcite_Brick_Smooth"
    },
    {
      "x": 9,
      "y": 0,
      "z": -7,
      "name": "Prototype_Rock_Concrete_Brick_Half",
      "rotation": 8
    },
    {
      "x": 9,
      "y": 1,
      "z": -7,
      "name": "Prototype_Rock_Concrete_Brick"
    },
    {
      "x": 9,
      "y": 2,
      "z": -7,
      "name": "Prototype_Rock_Concrete_Brick_Half"
    },
    {
      "x": 9,
      "y": 4,
      "z": -7,
      "name": "Rock_Stone"
    },
    {
      "x": 9,
      "y": 5,
      "z": -7,
      "name": "Rock_Stone"
    },
    {
      "x": 9,
      "y": 6,
      "z": -7,
      "name": "Rock_Stone"
    },
    {
      "x": 9,
      "y": 12,
      "z": -7,
      "name": "Rock_Stone"
    },
    {
      "x": 9,
      "y": 13,
      "z": -7,
      "name": "Rock_Stone"
    },
    {
      "x": 9,
      "y": 14,
      "z": -7,
      "name": "Rock_Stone"
    },
    {
      "x": 9,
      "y": 15,
      "z": -7,
      "name": "Rock_Stone"
    },
    {
      "x": 9,
      "y": 16,
      "z": -7,
      "name": "Rock_Stone"
    },
    {
      "x": 9,
      "y": 17,
      "z": -7,
      "name": "Rock_Stone"
    },
    {
      "x": 9,
      "y": 24,
      "z": -7,
      "name": "Rock_Stone_Cobble"
    },
    {
      "x": 9,
      "y": 25,
      "z": -7,
      "name": "Rock_Calcite_Brick_Smooth"
    },
    {
      "x": 9,
      "y": 0,
      "z": -6,
      "name": "Prototype_Rock_Concrete_Brick_Half",
      "rotation": 8
    },
    {
      "x": 9,
      "y": 1,
      "z": -6,
      "name": "Prototype_Rock_Concrete_Brick"
    },
    {
      "x": 9,
      "y": 2,
      "z": -6,
      "name": "Prototype_Rock_Concrete_Brick_Half"
    },
    {
      "x": 9,
      "y": 4,
      "z": -6,
      "name": "Rock_Stone"
    },
    {
      "x": 9,
      "y": 7,
      "z": -6,
      "name": "Rock_Stone"
    },
    {
      "x": 9,
      "y": 8,
      "z": -6,
      "name": "Rock_Stone"
    },
    {
      "x": 9,
      "y": 9,
      "z": -6,
      "name": "Rock_Stone"
    },
    {
      "x": 9,
      "y": 10,
      "z": -6,
      "name": "Rock_Stone"
    },
    {
      "x": 9,
      "y": 11,
      "z": -6,
      "name": "Rock_Stone"
    },
    {
      "x": 9,
      "y": 12,
      "z": -6,
      "name": "Rock_Stone"
    },
    {
      "x": 9,
      "y": 13,
      "z": -6,
      "name": "Rock_Stone_Cobble"
    },
    {
      "x": 9,
      "y": 14,
      "z": -6,
      "name": "Rock_Stone_Cobble"
    },
    {
      "x": 9,
      "y": 15,
      "z": -6,
      "name": "Rock_Stone_Cobble"
    },
    {
      "x": 9,
      "y": 16,
      "z": -6,
      "name": "Rock_Stone_Cobble"
    },
    {
      "x": 9,
      "y": 18,
      "z": -6,
      "name": "Rock_Stone"
    },
    {
      "x": 9,
      "y": 24,
      "z": -6,
      "name": "Rock_Stone_Cobble"
    },
    {
      "x": 9,
      "y": 25,
      "z": -6,
      "name": "Rock_Calcite_Brick_Smooth"
    },
    {
      "x": 9,
      "y": 0,
      "z": -5,
      "name": "Prototype_Rock_Concrete_Brick_Half",
      "rotation": 8
    },
    {
      "x": 9,
      "y": 1,
      "z": -5,
      "name": "Prototype_Rock_Concrete_Brick"
    },
    {
      "x": 9,
      "y": 2,
      "z": -5,
      "name": "Prototype_Rock_Concrete_Brick_Half"
    },
    {
      "x": 9,
      "y": 6,
      "z": -5,
      "name": "Rock_Stone"
    },
    {
      "x": 9,
      "y": 7,
      "z": -5,
      "name": "Rock_Stone"
    },
    {
      "x": 9,
      "y": 8,
      "z": -5,
      "name": "Rock_Stone"
    },
    {
      "x": 9,
      "y": 9,
      "z": -5,
      "name": "Rock_Stone"
    },
    {
      "x": 9,
      "y": 10,
      "z": -5,
      "name": "Rock_Stone"
    },
    {
      "x": 9,
      "y": 11,
      "z": -5,
      "name": "Rock_Stone"
    },
    {
      "x": 9,
      "y": 12,
      "z": -5,
      "name": "Rock_Stone"
    },
    {
      "x": 9,
      "y": 13,
      "z": -5,
      "name": "Rock_Stone"
    },
    {
      "x": 9,
      "y": 14,
      "z": -5,
      "name": "Rock_Stone_Cobble"
    },
    {
      "x": 9,
      "y": 15,
      "z": -5,
      "name": "Rock_Stone_Cobble"
    },
    {
      "x": 9,
      "y": 16,
      "z": -5,
      "name": "Rock_Stone_Cobble"
    },
    {
      "x": 9,
      "y": 17,
      "z": -5,
      "name": "Rock_Stone_Cobble"
    },
    {
      "x": 9,
      "y": 18,
      "z": -5,
      "name": "Rock_Stone_Cobble"
    },
    {
      "x": 9,
      "y": 19,
      "z": -5,
      "name": "Soil_Grass"
    },
    {
      "x": 9,
      "y": 21,
      "z": -5,
      "name": "Rock_Stone"
    },
    {
      "x": 9,
      "y": 22,
      "z": -5,
      "name": "Rock_Stone"
    },
    {
      "x": 9,
      "y": 23,
      "z": -5,
      "name": "Soil_Dirt"
    },
    {
      "x": 9,
      "y": 24,
      "z": -5,
      "name": "Rock_Calcite_Brick_Smooth"
    },
    {
      "x": 9,
      "y": 0,
      "z": -4,
      "name": "Prototype_Rock_Concrete_Brick_Half",
      "rotation": 8
    },
    {
      "x": 9,
      "y": 1,
      "z": -4,
      "name": "Prototype_Rock_Concrete_Brick"
    },
    {
      "x": 9,
      "y": 2,
      "z": -4,
      "name": "Prototype_Rock_Concrete_Brick_Half"
    },
    {
      "x": 9,
      "y": 6,
      "z": -4,
      "name": "Rock_Stone"
    },
    {
      "x": 9,
      "y": 7,
      "z": -4,
      "name": "Rock_Stone"
    },
    {
      "x": 9,
      "y": 8,
      "z": -4,
      "name": "Rock_Stone"
    },
    {
      "x": 9,
      "y": 9,
      "z": -4,
      "name": "Rock_Stone"
    },
    {
      "x": 9,
      "y": 10,
      "z": -4,
      "name": "Rock_Stone"
    },
    {
      "x": 9,
      "y": 11,
      "z": -4,
      "name": "Rock_Stone"
    },
    {
      "x": 9,
      "y": 12,
      "z": -4,
      "name": "Rock_Stone"
    },
    {
      "x": 9,
      "y": 13,
      "z": -4,
      "name": "Rock_Stone"
    },
    {
      "x": 9,
      "y": 14,
      "z": -4,
      "name": "Rock_Stone"
    },
    {
      "x": 9,
      "y": 15,
      "z": -4,
      "name": "Rock_Stone"
    },
    {
      "x": 9,
      "y": 16,
      "z": -4,
      "name": "Rock_Stone"
    },
    {
      "x": 9,
      "y": 18,
      "z": -4,
      "name": "Rock_Calcite_Brick_Smooth"
    },
    {
      "x": 9,
      "y": 19,
      "z": -4,
      "name": "Rock_Calcite_Brick_Smooth"
    },
    {
      "x": 9,
      "y": 20,
      "z": -4,
      "name": "Rock_Calcite_Brick_Smooth"
    },
    {
      "x": 9,
      "y": 23,
      "z": -4,
      "name": "Rock_Calcite_Brick_Smooth"
    },
    {
      "x": 9,
      "y": 0,
      "z": -3,
      "name": "Prototype_Rock_Concrete_Brick_Half",
      "rotation": 8
    },
    {
      "x": 9,
      "y": 6,
      "z": -3,
      "name": "Rock_Stone"
    },
    {
      "x": 9,
      "y": 7,
      "z": -3,
      "name": "Rock_Stone_Brick"
    },
    {
      "x": 9,
      "y": 8,
      "z": -3,
      "name": "Rock_Stone_Brick"
    },
    {
      "x": 9,
      "y": 16,
      "z": -3,
      "name": "Rock_Calcite_Brick_Smooth"
    },
    {
      "x": 9,
      "y": 17,
      "z": -3,
      "name": "Rock_Calcite_Brick_Smooth"
    },
    {
      "x": 9,
      "y": 18,
      "z": -3,
      "name": "Soil_Dirt"
    },
    {
      "x": 9,
      "y": 19,
      "z": -3,
      "name": "Soil_Dirt"
    },
    {
      "x": 9,
      "y": 20,
      "z": -3,
      "name": "Rock_Calcite_Brick_Smooth"
    },
    {
      "x": 9,
      "y": 21,
      "z": -3,
      "name": "Rock_Calcite_Brick_Smooth"
    },
    {
      "x": 9,
      "y": 0,
      "z": -2,
      "name": "*Rock_Stone_Brick_Stairs_State_Definitions_Inverted_Corner_Left",
      "rotation": 3
    },
    {
      "x": 9,
      "y": 6,
      "z": -2,
      "name": "Rock_Stone_Brick"
    },
    {
      "x": 9,
      "y": 18,
      "z": -2,
      "name": "Rock_Calcite_Brick_Smooth"
    },
    {
      "x": 9,
      "y": 19,
      "z": -2,
      "name": "Rock_Calcite_Brick_Smooth"
    },
    {
      "x": 9,
      "y": 20,
      "z": -2,
      "name": "Rock_Calcite_Brick_Smooth"
    },
    {
      "x": 9,
      "y": 0,
      "z": -1,
      "name": "*Rock_Stone_Brick_Stairs_State_Definitions_Corner_Right"
    },
    {
      "x": 10,
      "y": 0,
      "z": -11,
      "name": "Rock_Stone_Brick_Stairs",
      "rotation": 2
    },
    {
      "x": 10,
      "y": 0,
      "z": -10,
      "name": "Prototype_Rock_Concrete_Brick_Half",
      "rotation": 8
    },
    {
      "x": 10,
      "y": 3,
      "z": -10,
      "name": "Rock_Stone_Brick"
    },
    {
      "x": 10,
      "y": 22,
      "z": -10,
      "name": "Rock_Stone_Cobble"
    },
    {
      "x": 10,
      "y": 23,
      "z": -10,
      "name": "Rock_Stone_Cobble"
    },
    {
      "x": 10,
      "y": 24,
      "z": -10,
      "name": "Rock_Stone_Brick"
    },
    {
      "x": 10,
      "y": 0,
      "z": -9,
      "name": "Prototype_Rock_Concrete_Brick_Half",
      "rotation": 8
    },
    {
      "x": 10,
      "y": 1,
      "z": -9,
      "name": "Prototype_Rock_Concrete_Brick"
    },
    {
      "x": 10,
      "y": 2,
      "z": -9,
      "name": "Prototype_Rock_Concrete_Brick_Half"
    },
    {
      "x": 10,
      "y": 4,
      "z": -9,
      "name": "Rock_Stone"
    },
    {
      "x": 10,
      "y": 20,
      "z": -9,
      "name": "Rock_Stone"
    },
    {
      "x": 10,
      "y": 21,
      "z": -9,
      "name": "Rock_Stone"
    },
    {
      "x": 10,
      "y": 22,
      "z": -9,
      "name": "Rock_Stone"
    },
    {
      "x": 10,
      "y": 23,
      "z": -9,
      "name": "Rock_Calcite_Brick_Smooth"
    },
    {
      "x": 10,
      "y": 24,
      "z": -9,
      "name": "Rock_Calcite_Brick_Smooth"
    },
    {
      "x": 10,
      "y": 0,
      "z": -8,
      "name": "Prototype_Rock_Concrete_Brick_Half",
      "rotation": 8
    },
    {
      "x": 10,
      "y": 1,
      "z": -8,
      "name": "Prototype_Rock_Concrete_Brick"
    },
    {
      "x": 10,
      "y": 2,
      "z": -8,
      "name": "Prototype_Rock_Concrete_Brick_Half"
    },
    {
      "x": 10,
      "y": 4,
      "z": -8,
      "name": "Rock_Stone"
    },
    {
      "x": 10,
      "y": 5,
      "z": -8,
      "name": "Rock_Stone"
    },
    {
      "x": 10,
      "y": 14,
      "z": -8,
      "name": "Rock_Stone"
    },
    {
      "x": 10,
      "y": 15,
      "z": -8,
      "name": "Rock_Stone"
    },
    {
      "x": 10,
      "y": 16,
      "z": -8,
      "name": "Rock_Stone"
    },
    {
      "x": 10,
      "y": 17,
      "z": -8,
      "name": "Rock_Stone"
    },
    {
      "x": 10,
      "y": 18,
      "z": -8,
      "name": "Rock_Stone"
    },
    {
      "x": 10,
      "y": 19,
      "z": -8,
      "name": "Rock_Stone"
    },
    {
      "x": 10,
      "y": 24,
      "z": -8,
      "name": "Rock_Stone_Cobble"
    },
    {
      "x": 10,
      "y": 25,
      "z": -8,
      "name": "Rock_Stone_Brick_Stairs",
      "rotation": 3
    },
    {
      "x": 10,
      "y": 27,
      "z": -8,
      "name": "Rock_Stone_Cobble_Stairs",
      "rotation": 9
    },
    {
      "x": 10,
      "y": 28,
      "z": -8,
      "name": "Rock_Stone_Cobble"
    },
    {
      "x": 10,
      "y": 29,
      "z": -8,
      "name": "Rock_Stone_Brick_Stairs",
      "rotation": 3
    },
    {
      "x": 10,
      "y": 0,
      "z": -7,
      "name": "Prototype_Rock_Concrete_Brick_Half",
      "rotation": 8
    },
    {
      "x": 10,
      "y": 1,
      "z": -7,
      "name": "Prototype_Rock_Concrete_Brick"
    },
    {
      "x": 10,
      "y": 2,
      "z": -7,
      "name": "Prototype_Rock_Concrete_Brick_Half"
    },
    {
      "x": 10,
      "y": 6,
      "z": -7,
      "name": "Rock_Stone"
    },
    {
      "x": 10,
      "y": 7,
      "z": -7,
      "name": "Rock_Stone"
    },
    {
      "x": 10,
      "y": 11,
      "z": -7,
      "name": "Rock_Stone"
    },
    {
      "x": 10,
      "y": 12,
      "z": -7,
      "name": "Rock_Stone"
    },
    {
      "x": 10,
      "y": 13,
      "z": -7,
      "name": "Rock_Stone"
    },
    {
      "x": 10,
      "y": 24,
      "z": -7,
      "name": "Rock_Stone_Cobble"
    },
    {
      "x": 10,
      "y": 25,
      "z": -7,
      "name": "Rock_Stone_Brick_Stairs",
      "rotation": 3
    },
    {
      "x": 10,
      "y": 26,
      "z": -7,
      "name": "Rock_Stone_Cobble_Stairs",
      "rotation": 9
    },
    {
      "x": 10,
      "y": 27,
      "z": -7,
      "name": "Rock_Stone_Cobble"
    },
    {
      "x": 10,
      "y": 28,
      "z": -7,
      "name": "Rock_Stone_Cobble"
    },
    {
      "x": 10,
      "y": 29,
      "z": -7,
      "name": "Rock_Stone_Cobble"
    },
    {
      "x": 10,
      "y": 30,
      "z": -7,
      "name": "Rock_Stone_Brick"
    },
    {
      "x": 10,
      "y": 31,
      "z": -7,
      "name": "Rock_Stone_Brick_Stairs",
      "rotation": 1
    },
    {
      "x": 10,
      "y": 0,
      "z": -6,
      "name": "Prototype_Rock_Concrete_Brick_Half",
      "rotation": 8
    },
    {
      "x": 10,
      "y": 1,
      "z": -6,
      "name": "Rock_Stone_Brick"
    },
    {
      "x": 10,
      "y": 2,
      "z": -6,
      "name": "Rock_Stone_Brick"
    },
    {
      "x": 10,
      "y": 3,
      "z": -6,
      "name": "Rock_Stone_Brick"
    },
    {
      "x": 10,
      "y": 4,
      "z": -6,
      "name": "Rock_Stone_Brick"
    },
    {
      "x": 10,
      "y": 5,
      "z": -6,
      "name": "Rock_Stone_Brick"
    },
    {
      "x": 10,
      "y": 6,
      "z": -6,
      "name": "Rock_Stone_Brick"
    },
    {
      "x": 10,
      "y": 7,
      "z": -6,
      "name": "Rock_Stone_Brick"
    },
    {
      "x": 10,
      "y": 8,
      "z": -6,
      "name": "Rock_Stone"
    },
    {
      "x": 10,
      "y": 9,
      "z": -6,
      "name": "Rock_Stone"
    },
    {
      "x": 10,
      "y": 10,
      "z": -6,
      "name": "Rock_Stone"
    },
    {
      "x": 10,
      "y": 24,
      "z": -6,
      "name": "Rock_Calcite_Brick_Smooth"
    },
    {
      "x": 10,
      "y": 26,
      "z": -6,
      "name": "Rock_Stone_Cobble_Stairs",
      "rotation": 9
    },
    {
      "x": 10,
      "y": 27,
      "z": -6,
      "name": "Rock_Stone_Cobble"
    },
    {
      "x": 10,
      "y": 28,
      "z": -6,
      "name": "Rock_Stone_Cobble"
    },
    {
      "x": 10,
      "y": 29,
      "z": -6,
      "name": "Rock_Stone_Cobble"
    },
    {
      "x": 10,
      "y": 30,
      "z": -6,
      "name": "Rock_Stone_Brick"
    },
    {
      "x": 10,
      "y": 0,
      "z": -5,
      "name": "Prototype_Rock_Concrete_Brick_Half",
      "rotation": 8
    },
    {
      "x": 10,
      "y": 1,
      "z": -5,
      "name": "Rock_Stone_Brick"
    },
    {
      "x": 10,
      "y": 2,
      "z": -5,
      "name": "Rock_Stone_Brick"
    },
    {
      "x": 10,
      "y": 3,
      "z": -5,
      "name": "Rock_Stone_Brick"
    },
    {
      "x": 10,
      "y": 4,
      "z": -5,
      "name": "Rock_Stone_Brick"
    },
    {
      "x": 10,
      "y": 5,
      "z": -5,
      "name": "Rock_Stone_Brick"
    },
    {
      "x": 10,
      "y": 6,
      "z": -5,
      "name": "Rock_Stone_Brick"
    },
    {
      "x": 10,
      "y": 7,
      "z": -5,
      "name": "Rock_Stone_Brick"
    },
    {
      "x": 10,
      "y": 8,
      "z": -5,
      "name": "Rock_Stone_Brick"
    },
    {
      "x": 10,
      "y": 9,
      "z": -5,
      "name": "Rock_Stone_Brick"
    },
    {
      "x": 10,
      "y": 10,
      "z": -5,
      "name": "Rock_Stone_Cobble"
    },
    {
      "x": 10,
      "y": 11,
      "z": -5,
      "name": "Rock_Stone_Cobble"
    },
    {
      "x": 10,
      "y": 12,
      "z": -5,
      "name": "Rock_Stone_Cobble"
    },
    {
      "x": 10,
      "y": 13,
      "z": -5,
      "name": "Rock_Stone_Cobble"
    },
    {
      "x": 10,
      "y": 14,
      "z": -5,
      "name": "Rock_Stone_Cobble"
    },
    {
      "x": 10,
      "y": 15,
      "z": -5,
      "name": "Rock_Stone_Cobble"
    },
    {
      "x": 10,
      "y": 16,
      "z": -5,
      "name": "Rock_Stone_Cobble"
    },
    {
      "x": 10,
      "y": 17,
      "z": -5,
      "name": "Rock_Stone_Cobble"
    },
    {
      "x": 10,
      "y": 18,
      "z": -5,
      "name": "Rock_Stone"
    },
    {
      "x": 10,
      "y": 19,
      "z": -5,
      "name": "Rock_Stone"
    },
    {
      "x": 10,
      "y": 20,
      "z": -5,
      "name": "Rock_Stone"
    },
    {
      "x": 10,
      "y": 21,
      "z": -5,
      "name": "Rock_Stone"
    },
    {
      "x": 10,
      "y": 22,
      "z": -5,
      "name": "Rock_Stone"
    },
    {
      "x": 10,
      "y": 23,
      "z": -5,
      "name": "Rock_Stone"
    },
    {
      "x": 10,
      "y": 24,
      "z": -5,
      "name": "Rock_Calcite_Brick_Smooth"
    },
    {
      "x": 10,
      "y": 27,
      "z": -5,
      "name": "Rock_Stone_Cobble_Stairs",
      "rotation": 9
    },
    {
      "x": 10,
      "y": 28,
      "z": -5,
      "name": "Rock_Stone_Cobble_Stairs",
      "rotation": 11
    },
    {
      "x": 10,
      "y": 29,
      "z": -5,
      "name": "Rock_Stone_Cobble_Stairs"
    },
    {
      "x": 10,
      "y": 0,
      "z": -4,
      "name": "Prototype_Rock_Concrete_Brick_Half",
      "rotation": 8
    },
    {
      "x": 10,
      "y": 1,
      "z": -4,
      "name": "Prototype_Rock_Concrete_Brick"
    },
    {
      "x": 10,
      "y": 2,
      "z": -4,
      "name": "Prototype_Rock_Concrete_Brick_Half"
    },
    {
      "x": 10,
      "y": 10,
      "z": -4,
      "name": "Rock_Stone_Brick"
    },
    {
      "x": 10,
      "y": 11,
      "z": -4,
      "name": "Rock_Stone_Brick"
    },
    {
      "x": 10,
      "y": 12,
      "z": -4,
      "name": "Rock_Stone_Brick"
    },
    {
      "x": 10,
      "y": 13,
      "z": -4,
      "name": "Rock_Stone"
    },
    {
      "x": 10,
      "y": 14,
      "z": -4,
      "name": "Rock_Stone"
    },
    {
      "x": 10,
      "y": 15,
      "z": -4,
      "name": "Rock_Stone"
    },
    {
      "x": 10,
      "y": 16,
      "z": -4,
      "name": "Rock_Stone"
    },
    {
      "x": 10,
      "y": 17,
      "z": -4,
      "name": "Rock_Stone"
    },
    {
      "x": 10,
      "y": 0,
      "z": -3,
      "name": "Prototype_Rock_Concrete_Brick_Half",
      "rotation": 8
    },
    {
      "x": 10,
      "y": 1,
      "z": -3,
      "name": "Prototype_Rock_Concrete_Brick"
    },
    {
      "x": 10,
      "y": 2,
      "z": -3,
      "name": "Prototype_Rock_Concrete_Brick_Half"
    },
    {
      "x": 10,
      "y": 9,
      "z": -3,
      "name": "Rock_Stone_Brick"
    },
    {
      "x": 10,
      "y": 18,
      "z": -3,
      "name": "Rock_Calcite_Brick_Smooth"
    },
    {
      "x": 10,
      "y": 19,
      "z": -3,
      "name": "Rock_Calcite_Brick_Smooth"
    },
    {
      "x": 10,
      "y": 0,
      "z": -2,
      "name": "Prototype_Rock_Concrete_Brick_Half",
      "rotation": 8
    },
    {
      "x": 10,
      "y": 0,
      "z": -1,
      "name": "Rock_Stone_Brick_Stairs"
    },
    {
      "x": 11,
      "y": 0,
      "z": -11,
      "name": "Rock_Stone_Brick_Stairs",
      "rotation": 2
    },
    {
      "x": 11,
      "y": 0,
      "z": -10,
      "name": "Prototype_Rock_Concrete_Brick_Half",
      "rotation": 8
    },
    {
      "x": 11,
      "y": 3,
      "z": -10,
      "name": "Rock_Stone_Brick"
    },
    {
      "x": 11,
      "y": 23,
      "z": -10,
      "name": "Rock_Stone_Brick"
    },
    {
      "x": 11,
      "y": 0,
      "z": -9,
      "name": "Prototype_Rock_Concrete_Brick_Half",
      "rotation": 8
    },
    {
      "x": 11,
      "y": 1,
      "z": -9,
      "name": "Prototype_Rock_Concrete_Brick"
    },
    {
      "x": 11,
      "y": 2,
      "z": -9,
      "name": "Prototype_Rock_Concrete_Brick_Half"
    },
    {
      "x": 11,
      "y": 4,
      "z": -9,
      "name": "Rock_Stone"
    },
    {
      "x": 11,
      "y": 20,
      "z": -9,
      "name": "Rock_Stone"
    },
    {
      "x": 11,
      "y": 21,
      "z": -9,
      "name": "Rock_Stone"
    },
    {
      "x": 11,
      "y": 22,
      "z": -9,
      "name": "Rock_Stone"
    },
    {
      "x": 11,
      "y": 23,
      "z": -9,
      "name": "Rock_Stone_Cobble"
    },
    {
      "x": 11,
      "y": 24,
      "z": -9,
      "name": "Rock_Calcite_Brick_Smooth"
    },
    {
      "x": 11,
      "y": 27,
      "z": -9,
      "name": "Rock_Stone_Cobble"
    },
    {
      "x": 11,
      "y": 28,
      "z": -9,
      "name": "Rock_Stone_Cobble"
    },
    {
      "x": 11,
      "y": 29,
      "z": -9,
      "name": "Rock_Stone_Cobble"
    },
    {
      "x": 11,
      "y": 0,
      "z": -8,
      "name": "Prototype_Rock_Concrete_Brick_Half",
      "rotation": 8
    },
    {
      "x": 11,
      "y": 1,
      "z": -8,
      "name": "Prototype_Rock_Concrete_Brick"
    },
    {
      "x": 11,
      "y": 2,
      "z": -8,
      "name": "Prototype_Rock_Concrete_Brick_Half"
    },
    {
      "x": 11,
      "y": 5,
      "z": -8,
      "name": "Rock_Stone"
    },
    {
      "x": 11,
      "y": 14,
      "z": -8,
      "name": "Rock_Stone"
    },
    {
      "x": 11,
      "y": 15,
      "z": -8,
      "name": "Rock_Stone"
    },
    {
      "x": 11,
      "y": 16,
      "z": -8,
      "name": "Rock_Stone"
    },
    {
      "x": 11,
      "y": 17,
      "z": -8,
      "name": "Rock_Stone"
    },
    {
      "x": 11,
      "y": 18,
      "z": -8,
      "name": "Rock_Stone"
    },
    {
      "x": 11,
      "y": 19,
      "z": -8,
      "name": "Rock_Stone"
    },
    {
      "x": 11,
      "y": 23,
      "z": -8,
      "name": "Rock_Stone_Cobble"
    },
    {
      "x": 11,
      "y": 24,
      "z": -8,
      "name": "Rock_Stone"
    },
    {
      "x": 11,
      "y": 25,
      "z": -8,
      "name": "Rock_Stone"
    },
    {
      "x": 11,
      "y": 26,
      "z": -8,
      "name": "Rock_Stone_Cobble"
    },
    {
      "x": 11,
      "y": 27,
      "z": -8,
      "name": "Rock_Stone_Cobble"
    },
    {
      "x": 11,
      "y": 28,
      "z": -8,
      "name": "Rock_Stone_Cobble"
    },
    {
      "x": 11,
      "y": 29,
      "z": -8,
      "name": "Rock_Stone_Cobble"
    },
    {
      "x": 11,
      "y": 30,
      "z": -8,
      "name": "Rock_Stone_Cobble"
    },
    {
      "x": 11,
      "y": 0,
      "z": -7,
      "name": "Prototype_Rock_Concrete_Brick_Half",
      "rotation": 8
    },
    {
      "x": 11,
      "y": 1,
      "z": -7,
      "name": "Prototype_Rock_Concrete_Brick"
    },
    {
      "x": 11,
      "y": 2,
      "z": -7,
      "name": "Prototype_Rock_Concrete_Brick_Half"
    },
    {
      "x": 11,
      "y": 6,
      "z": -7,
      "name": "Rock_Stone"
    },
    {
      "x": 11,
      "y": 7,
      "z": -7,
      "name": "Rock_Stone"
    },
    {
      "x": 11,
      "y": 11,
      "z": -7,
      "name": "Rock_Stone"
    },
    {
      "x": 11,
      "y": 12,
      "z": -7,
      "name": "Rock_Stone"
    },
    {
      "x": 11,
      "y": 13,
      "z": -7,
      "name": "Rock_Stone"
    },
    {
      "x": 11,
      "y": 23,
      "z": -7,
      "name": "Soil_Dirt"
    },
    {
      "x": 11,
      "y": 24,
      "z": -7,
      "name": "Rock_Stone"
    },
    {
      "x": 11,
      "y": 25,
      "z": -7,
      "name": "Rock_Stone"
    },
    {
      "x": 11,
      "y": 26,
      "z": -7,
      "name": "Rock_Stone_Cobble"
    },
    {
      "x": 11,
      "y": 27,
      "z": -7,
      "name": "Rock_Stone_Cobble"
    },
    {
      "x": 11,
      "y": 29,
      "z": -7,
      "name": "Rock_Stone_Cobble"
    },
    {
      "x": 11,
      "y": 30,
      "z": -7,
      "name": "Rock_Stone_Cobble"
    },
    {
      "x": 11,
      "y": 0,
      "z": -6,
      "name": "Prototype_Rock_Concrete_Brick_Half",
      "rotation": 8
    },
    {
      "x": 11,
      "y": 1,
      "z": -6,
      "name": "Rock_Stone_Brick"
    },
    {
      "x": 11,
      "y": 2,
      "z": -6,
      "name": "Rock_Stone_Brick"
    },
    {
      "x": 11,
      "y": 3,
      "z": -6,
      "name": "Rock_Stone_Brick"
    },
    {
      "x": 11,
      "y": 4,
      "z": -6,
      "name": "Rock_Stone_Brick"
    },
    {
      "x": 11,
      "y": 5,
      "z": -6,
      "name": "Rock_Stone_Brick"
    },
    {
      "x": 11,
      "y": 6,
      "z": -6,
      "name": "Rock_Stone_Brick"
    },
    {
      "x": 11,
      "y": 7,
      "z": -6,
      "name": "Rock_Stone_Brick"
    },
    {
      "x": 11,
      "y": 8,
      "z": -6,
      "name": "Rock_Stone"
    },
    {
      "x": 11,
      "y": 9,
      "z": -6,
      "name": "Rock_Stone"
    },
    {
      "x": 11,
      "y": 10,
      "z": -6,
      "name": "Rock_Stone"
    },
    {
      "x": 11,
      "y": 11,
      "z": -6,
      "name": "Rock_Stone_Cobble"
    },
    {
      "x": 11,
      "y": 12,
      "z": -6,
      "name": "Rock_Stone_Cobble"
    },
    {
      "x": 11,
      "y": 13,
      "z": -6,
      "name": "Rock_Stone_Cobble"
    },
    {
      "x": 11,
      "y": 14,
      "z": -6,
      "name": "Rock_Stone_Cobble"
    },
    {
      "x": 11,
      "y": 15,
      "z": -6,
      "name": "Rock_Stone_Cobble"
    },
    {
      "x": 11,
      "y": 16,
      "z": -6,
      "name": "Rock_Stone_Cobble"
    },
    {
      "x": 11,
      "y": 17,
      "z": -6,
      "name": "Rock_Stone_Cobble"
    },
    {
      "x": 11,
      "y": 18,
      "z": -6,
      "name": "Rock_Stone_Cobble"
    },
    {
      "x": 11,
      "y": 19,
      "z": -6,
      "name": "Rock_Stone_Cobble"
    },
    {
      "x": 11,
      "y": 20,
      "z": -6,
      "name": "Rock_Stone_Cobble"
    },
    {
      "x": 11,
      "y": 21,
      "z": -6,
      "name": "Rock_Stone_Cobble"
    },
    {
      "x": 11,
      "y": 22,
      "z": -6,
      "name": "Rock_Stone_Cobble"
    },
    {
      "x": 11,
      "y": 23,
      "z": -6,
      "name": "Rock_Stone_Cobble"
    },
    {
      "x": 11,
      "y": 24,
      "z": -6,
      "name": "Rock_Calcite_Brick_Smooth"
    },
    {
      "x": 11,
      "y": 25,
      "z": -6,
      "name": "Rock_Stone_Cobble"
    },
    {
      "x": 11,
      "y": 26,
      "z": -6,
      "name": "Rock_Stone_Cobble"
    },
    {
      "x": 11,
      "y": 27,
      "z": -6,
      "name": "Rock_Stone_Cobble"
    },
    {
      "x": 11,
      "y": 28,
      "z": -6,
      "name": "Rock_Stone_Cobble"
    },
    {
      "x": 11,
      "y": 29,
      "z": -6,
      "name": "Rock_Stone_Cobble"
    },
    {
      "x": 11,
      "y": 30,
      "z": -6,
      "name": "Rock_Stone_Brick"
    },
    {
      "x": 11,
      "y": 0,
      "z": -5,
      "name": "Prototype_Rock_Concrete_Brick_Half",
      "rotation": 8
    },
    {
      "x": 11,
      "y": 1,
      "z": -5,
      "name": "Rock_Stone_Brick"
    },
    {
      "x": 11,
      "y": 2,
      "z": -5,
      "name": "Rock_Stone_Brick"
    },
    {
      "x": 11,
      "y": 3,
      "z": -5,
      "name": "Rock_Stone_Brick"
    },
    {
      "x": 11,
      "y": 4,
      "z": -5,
      "name": "Rock_Stone_Brick"
    },
    {
      "x": 11,
      "y": 5,
      "z": -5,
      "name": "Rock_Stone_Brick"
    },
    {
      "x": 11,
      "y": 6,
      "z": -5,
      "name": "Rock_Stone_Brick"
    },
    {
      "x": 11,
      "y": 7,
      "z": -5,
      "name": "Rock_Stone_Brick"
    },
    {
      "x": 11,
      "y": 8,
      "z": -5,
      "name": "Rock_Stone_Brick"
    },
    {
      "x": 11,
      "y": 9,
      "z": -5,
      "name": "Rock_Stone_Brick"
    },
    {
      "x": 11,
      "y": 10,
      "z": -5,
      "name": "Rock_Stone_Cobble"
    },
    {
      "x": 11,
      "y": 11,
      "z": -5,
      "name": "Rock_Stone_Cobble"
    },
    {
      "x": 11,
      "y": 12,
      "z": -5,
      "name": "Rock_Stone_Cobble"
    },
    {
      "x": 11,
      "y": 13,
      "z": -5,
      "name": "Rock_Stone_Cobble"
    },
    {
      "x": 11,
      "y": 14,
      "z": -5,
      "name": "Rock_Stone_Cobble"
    },
    {
      "x": 11,
      "y": 15,
      "z": -5,
      "name": "Rock_Stone_Cobble"
    },
    {
      "x": 11,
      "y": 16,
      "z": -5,
      "name": "Rock_Stone_Cobble"
    },
    {
      "x": 11,
      "y": 17,
      "z": -5,
      "name": "Rock_Stone_Cobble"
    },
    {
      "x": 11,
      "y": 18,
      "z": -5,
      "name": "Rock_Stone_Cobble"
    },
    {
      "x": 11,
      "y": 19,
      "z": -5,
      "name": "Soil_Grass"
    },
    {
      "x": 11,
      "y": 21,
      "z": -5,
      "name": "Rock_Stone"
    },
    {
      "x": 11,
      "y": 22,
      "z": -5,
      "name": "Rock_Stone"
    },
    {
      "x": 11,
      "y": 23,
      "z": -5,
      "name": "Rock_Stone"
    },
    {
      "x": 11,
      "y": 24,
      "z": -5,
      "name": "Rock_Calcite_Brick_Smooth"
    },
    {
      "x": 11,
      "y": 26,
      "z": -5,
      "name": "Rock_Stone_Cobble"
    },
    {
      "x": 11,
      "y": 27,
      "z": -5,
      "name": "Rock_Stone_Cobble"
    },
    {
      "x": 11,
      "y": 28,
      "z": -5,
      "name": "Rock_Stone_Cobble"
    },
    {
      "x": 11,
      "y": 29,
      "z": -5,
      "name": "Rock_Stone_Cobble"
    },
    {
      "x": 11,
      "y": 30,
      "z": -5,
      "name": "Rock_Stone_Brick"
    },
    {
      "x": 11,
      "y": 31,
      "z": -5,
      "name": "Rock_Stone_Brick_Stairs",
      "rotation": 2
    },
    {
      "x": 11,
      "y": 0,
      "z": -4,
      "name": "Prototype_Rock_Concrete_Brick_Half",
      "rotation": 8
    },
    {
      "x": 11,
      "y": 1,
      "z": -4,
      "name": "Prototype_Rock_Concrete_Brick"
    },
    {
      "x": 11,
      "y": 2,
      "z": -4,
      "name": "Prototype_Rock_Concrete_Brick_Half"
    },
    {
      "x": 11,
      "y": 7,
      "z": -4,
      "name": "Rock_Stone_Brick"
    },
    {
      "x": 11,
      "y": 8,
      "z": -4,
      "name": "Rock_Stone_Brick"
    },
    {
      "x": 11,
      "y": 9,
      "z": -4,
      "name": "Rock_Stone_Brick"
    },
    {
      "x": 11,
      "y": 10,
      "z": -4,
      "name": "Rock_Stone"
    },
    {
      "x": 11,
      "y": 11,
      "z": -4,
      "name": "Rock_Stone"
    },
    {
      "x": 11,
      "y": 12,
      "z": -4,
      "name": "Rock_Stone"
    },
    {
      "x": 11,
      "y": 13,
      "z": -4,
      "name": "Rock_Stone_Brick"
    },
    {
      "x": 11,
      "y": 14,
      "z": -4,
      "name": "Rock_Stone_Brick"
    },
    {
      "x": 11,
      "y": 15,
      "z": -4,
      "name": "Rock_Stone_Brick"
    },
    {
      "x": 11,
      "y": 16,
      "z": -4,
      "name": "Rock_Stone"
    },
    {
      "x": 11,
      "y": 17,
      "z": -4,
      "name": "Rock_Stone"
    },
    {
      "x": 11,
      "y": 18,
      "z": -4,
      "name": "Rock_Stone"
    },
    {
      "x": 11,
      "y": 19,
      "z": -4,
      "name": "Rock_Calcite_Brick_Smooth"
    },
    {
      "x": 11,
      "y": 20,
      "z": -4,
      "name": "Rock_Calcite_Brick_Smooth"
    },
    {
      "x": 11,
      "y": 0,
      "z": -3,
      "name": "Prototype_Rock_Concrete_Brick_Half",
      "rotation": 8
    },
    {
      "x": 11,
      "y": 1,
      "z": -3,
      "name": "Prototype_Rock_Concrete_Brick"
    },
    {
      "x": 11,
      "y": 2,
      "z": -3,
      "name": "Prototype_Rock_Concrete_Brick_Half"
    },
    {
      "x": 11,
      "y": 19,
      "z": -3,
      "name": "Rock_Calcite_Brick_Smooth"
    },
    {
      "x": 11,
      "y": 20,
      "z": -3,
      "name": "Rock_Calcite_Brick_Smooth"
    },
    {
      "x": 11,
      "y": 21,
      "z": -3,
      "name": "Rock_Calcite_Brick_Smooth"
    },
    {
      "x": 11,
      "y": 0,
      "z": -2,
      "name": "Prototype_Rock_Concrete_Brick_Half",
      "rotation": 8
    },
    {
      "x": 11,
      "y": 19,
      "z": -2,
      "name": "Rock_Calcite_Brick_Smooth"
    },
    {
      "x": 11,
      "y": 20,
      "z": -2,
      "name": "Rock_Calcite_Brick_Smooth"
    },
    {
      "x": 11,
      "y": 0,
      "z": -1,
      "name": "Rock_Stone_Brick_Stairs"
    },
    {
      "x": 12,
      "y": 0,
      "z": -11,
      "name": "Rock_Stone_Brick_Stairs",
      "rotation": 2
    },
    {
      "x": 12,
      "y": 0,
      "z": -10,
      "name": "Prototype_Rock_Concrete_Brick_Half",
      "rotation": 8
    },
    {
      "x": 12,
      "y": 3,
      "z": -10,
      "name": "Rock_Stone_Brick"
    },
    {
      "x": 12,
      "y": 22,
      "z": -10,
      "name": "Rock_Stone_Cobble"
    },
    {
      "x": 12,
      "y": 23,
      "z": -10,
      "name": "Rock_Stone_Cobble"
    },
    {
      "x": 12,
      "y": 24,
      "z": -10,
      "name": "Rock_Stone_Brick"
    },
    {
      "x": 12,
      "y": 0,
      "z": -9,
      "name": "Prototype_Rock_Concrete_Brick_Half",
      "rotation": 8
    },
    {
      "x": 12,
      "y": 1,
      "z": -9,
      "name": "Prototype_Rock_Concrete_Brick"
    },
    {
      "x": 12,
      "y": 2,
      "z": -9,
      "name": "Prototype_Rock_Concrete_Brick_Half"
    },
    {
      "x": 12,
      "y": 4,
      "z": -9,
      "name": "Rock_Stone"
    },
    {
      "x": 12,
      "y": 20,
      "z": -9,
      "name": "Rock_Stone"
    },
    {
      "x": 12,
      "y": 21,
      "z": -9,
      "name": "Rock_Stone"
    },
    {
      "x": 12,
      "y": 22,
      "z": -9,
      "name": "Rock_Stone"
    },
    {
      "x": 12,
      "y": 23,
      "z": -9,
      "name": "Rock_Calcite_Brick_Smooth"
    },
    {
      "x": 12,
      "y": 24,
      "z": -9,
      "name": "Rock_Calcite_Brick_Smooth"
    },
    {
      "x": 12,
      "y": 0,
      "z": -8,
      "name": "Prototype_Rock_Concrete_Brick_Half",
      "rotation": 8
    },
    {
      "x": 12,
      "y": 1,
      "z": -8,
      "name": "Prototype_Rock_Concrete_Brick"
    },
    {
      "x": 12,
      "y": 2,
      "z": -8,
      "name": "Prototype_Rock_Concrete_Brick_Half"
    },
    {
      "x": 12,
      "y": 5,
      "z": -8,
      "name": "Rock_Stone"
    },
    {
      "x": 12,
      "y": 15,
      "z": -8,
      "name": "Rock_Stone"
    },
    {
      "x": 12,
      "y": 16,
      "z": -8,
      "name": "Rock_Stone"
    },
    {
      "x": 12,
      "y": 17,
      "z": -8,
      "name": "Rock_Stone"
    },
    {
      "x": 12,
      "y": 18,
      "z": -8,
      "name": "Rock_Stone"
    },
    {
      "x": 12,
      "y": 19,
      "z": -8,
      "name": "Rock_Stone"
    },
    {
      "x": 12,
      "y": 24,
      "z": -8,
      "name": "Rock_Stone_Cobble"
    },
    {
      "x": 12,
      "y": 25,
      "z": -8,
      "name": "Rock_Stone_Brick_Stairs",
      "rotation": 1
    },
    {
      "x": 12,
      "y": 27,
      "z": -8,
      "name": "Rock_Stone_Brick_Stairs",
      "rotation": 11
    },
    {
      "x": 12,
      "y": 28,
      "z": -8,
      "name": "Rock_Stone_Cobble"
    },
    {
      "x": 12,
      "y": 29,
      "z": -8,
      "name": "Rock_Stone_Cobble_Stairs",
      "rotation": 1
    },
    {
      "x": 12,
      "y": 0,
      "z": -7,
      "name": "Prototype_Rock_Concrete_Brick_Half",
      "rotation": 8
    },
    {
      "x": 12,
      "y": 1,
      "z": -7,
      "name": "Prototype_Rock_Concrete_Brick"
    },
    {
      "x": 12,
      "y": 2,
      "z": -7,
      "name": "Prototype_Rock_Concrete_Brick_Half"
    },
    {
      "x": 12,
      "y": 6,
      "z": -7,
      "name": "Rock_Stone"
    },
    {
      "x": 12,
      "y": 7,
      "z": -7,
      "name": "Rock_Stone"
    },
    {
      "x": 12,
      "y": 12,
      "z": -7,
      "name": "Rock_Stone"
    },
    {
      "x": 12,
      "y": 13,
      "z": -7,
      "name": "Rock_Stone"
    },
    {
      "x": 12,
      "y": 14,
      "z": -7,
      "name": "Rock_Stone"
    },
    {
      "x": 12,
      "y": 24,
      "z": -7,
      "name": "Rock_Stone_Cobble"
    },
    {
      "x": 12,
      "y": 25,
      "z": -7,
      "name": "Rock_Stone_Brick_Stairs",
      "rotation": 1
    },
    {
      "x": 12,
      "y": 26,
      "z": -7,
      "name": "Rock_Stone_Cobble_Stairs",
      "rotation": 11
    },
    {
      "x": 12,
      "y": 27,
      "z": -7,
      "name": "Rock_Stone_Cobble"
    },
    {
      "x": 12,
      "y": 28,
      "z": -7,
      "name": "Rock_Stone_Cobble"
    },
    {
      "x": 12,
      "y": 29,
      "z": -7,
      "name": "Rock_Stone_Cobble"
    },
    {
      "x": 12,
      "y": 30,
      "z": -7,
      "name": "Rock_Stone_Brick"
    },
    {
      "x": 12,
      "y": 31,
      "z": -7,
      "name": "Rock_Stone_Brick_Stairs",
      "rotation": 3
    },
    {
      "x": 12,
      "y": 0,
      "z": -6,
      "name": "Prototype_Rock_Concrete_Brick_Half",
      "rotation": 8
    },
    {
      "x": 12,
      "y": 1,
      "z": -6,
      "name": "Rock_Stone_Brick"
    },
    {
      "x": 12,
      "y": 2,
      "z": -6,
      "name": "Rock_Stone_Brick"
    },
    {
      "x": 12,
      "y": 3,
      "z": -6,
      "name": "Rock_Stone_Brick"
    },
    {
      "x": 12,
      "y": 4,
      "z": -6,
      "name": "Rock_Stone_Brick"
    },
    {
      "x": 12,
      "y": 5,
      "z": -6,
      "name": "Rock_Stone_Brick"
    },
    {
      "x": 12,
      "y": 6,
      "z": -6,
      "name": "Rock_Stone_Brick"
    },
    {
      "x": 12,
      "y": 7,
      "z": -6,
      "name": "Rock_Stone_Brick"
    },
    {
      "x": 12,
      "y": 8,
      "z": -6,
      "name": "Rock_Stone"
    },
    {
      "x": 12,
      "y": 9,
      "z": -6,
      "name": "Rock_Stone"
    },
    {
      "x": 12,
      "y": 10,
      "z": -6,
      "name": "Rock_Stone"
    },
    {
      "x": 12,
      "y": 11,
      "z": -6,
      "name": "Rock_Stone"
    },
    {
      "x": 12,
      "y": 12,
      "z": -6,
      "name": "Rock_Stone"
    },
    {
      "x": 12,
      "y": 13,
      "z": -6,
      "name": "Rock_Stone"
    },
    {
      "x": 12,
      "y": 14,
      "z": -6,
      "name": "Rock_Stone"
    },
    {
      "x": 12,
      "y": 24,
      "z": -6,
      "name": "Rock_Calcite_Brick_Smooth"
    },
    {
      "x": 12,
      "y": 26,
      "z": -6,
      "name": "Rock_Stone_Cobble_Stairs",
      "rotation": 11
    },
    {
      "x": 12,
      "y": 27,
      "z": -6,
      "name": "Rock_Stone_Cobble"
    },
    {
      "x": 12,
      "y": 28,
      "z": -6,
      "name": "Rock_Stone_Cobble"
    },
    {
      "x": 12,
      "y": 29,
      "z": -6,
      "name": "Rock_Stone_Cobble"
    },
    {
      "x": 12,
      "y": 30,
      "z": -6,
      "name": "Rock_Stone_Brick"
    },
    {
      "x": 12,
      "y": 0,
      "z": -5,
      "name": "Prototype_Rock_Concrete_Brick_Half",
      "rotation": 8
    },
    {
      "x": 12,
      "y": 1,
      "z": -5,
      "name": "Rock_Stone_Brick"
    },
    {
      "x": 12,
      "y": 2,
      "z": -5,
      "name": "Rock_Stone_Brick"
    },
    {
      "x": 12,
      "y": 3,
      "z": -5,
      "name": "Rock_Stone_Brick"
    },
    {
      "x": 12,
      "y": 4,
      "z": -5,
      "name": "Rock_Stone_Brick"
    },
    {
      "x": 12,
      "y": 5,
      "z": -5,
      "name": "Rock_Stone_Brick"
    },
    {
      "x": 12,
      "y": 6,
      "z": -5,
      "name": "Rock_Stone_Brick"
    },
    {
      "x": 12,
      "y": 7,
      "z": -5,
      "name": "Rock_Stone_Brick"
    },
    {
      "x": 12,
      "y": 8,
      "z": -5,
      "name": "Rock_Stone_Brick"
    },
    {
      "x": 12,
      "y": 9,
      "z": -5,
      "name": "Rock_Stone"
    },
    {
      "x": 12,
      "y": 10,
      "z": -5,
      "name": "Rock_Stone"
    },
    {
      "x": 12,
      "y": 11,
      "z": -5,
      "name": "Rock_Stone"
    },
    {
      "x": 12,
      "y": 12,
      "z": -5,
      "name": "Rock_Stone"
    },
    {
      "x": 12,
      "y": 13,
      "z": -5,
      "name": "Rock_Stone"
    },
    {
      "x": 12,
      "y": 14,
      "z": -5,
      "name": "Rock_Stone"
    },
    {
      "x": 12,
      "y": 15,
      "z": -5,
      "name": "Rock_Stone"
    },
    {
      "x": 12,
      "y": 16,
      "z": -5,
      "name": "Rock_Stone_Cobble"
    },
    {
      "x": 12,
      "y": 17,
      "z": -5,
      "name": "Rock_Stone_Cobble"
    },
    {
      "x": 12,
      "y": 18,
      "z": -5,
      "name": "Rock_Stone"
    },
    {
      "x": 12,
      "y": 19,
      "z": -5,
      "name": "Rock_Stone"
    },
    {
      "x": 12,
      "y": 20,
      "z": -5,
      "name": "Rock_Stone"
    },
    {
      "x": 12,
      "y": 21,
      "z": -5,
      "name": "Rock_Stone"
    },
    {
      "x": 12,
      "y": 22,
      "z": -5,
      "name": "Rock_Stone"
    },
    {
      "x": 12,
      "y": 23,
      "z": -5,
      "name": "Rock_Stone"
    },
    {
      "x": 12,
      "y": 24,
      "z": -5,
      "name": "Rock_Calcite_Brick_Smooth"
    },
    {
      "x": 12,
      "y": 27,
      "z": -5,
      "name": "Rock_Stone_Cobble_Stairs",
      "rotation": 11
    },
    {
      "x": 12,
      "y": 28,
      "z": -5,
      "name": "Rock_Stone_Cobble_Stairs",
      "rotation": 9
    },
    {
      "x": 12,
      "y": 29,
      "z": -5,
      "name": "Rock_Stone_Cobble_Stairs"
    },
    {
      "x": 12,
      "y": 0,
      "z": -4,
      "name": "Prototype_Rock_Concrete_Brick_Half",
      "rotation": 8
    },
    {
      "x": 12,
      "y": 1,
      "z": -4,
      "name": "Prototype_Rock_Concrete_Brick"
    },
    {
      "x": 12,
      "y": 2,
      "z": -4,
      "name": "Prototype_Rock_Concrete_Brick_Half"
    },
    {
      "x": 12,
      "y": 5,
      "z": -4,
      "name": "Rock_Stone"
    },
    {
      "x": 12,
      "y": 6,
      "z": -4,
      "name": "Rock_Stone"
    },
    {
      "x": 12,
      "y": 7,
      "z": -4,
      "name": "Rock_Stone"
    },
    {
      "x": 12,
      "y": 8,
      "z": -4,
      "name": "Rock_Stone"
    },
    {
      "x": 12,
      "y": 9,
      "z": -4,
      "name": "Rock_Stone"
    },
    {
      "x": 12,
      "y": 10,
      "z": -4,
      "name": "Rock_Stone"
    },
    {
      "x": 12,
      "y": 11,
      "z": -4,
      "name": "Rock_Stone"
    },
    {
      "x": 12,
      "y": 12,
      "z": -4,
      "name": "Rock_Stone"
    },
    {
      "x": 12,
      "y": 13,
      "z": -4,
      "name": "Rock_Stone"
    },
    {
      "x": 12,
      "y": 16,
      "z": -4,
      "name": "Rock_Stone_Brick"
    },
    {
      "x": 12,
      "y": 17,
      "z": -4,
      "name": "Rock_Stone_Brick"
    },
    {
      "x": 12,
      "y": 0,
      "z": -3,
      "name": "Prototype_Rock_Concrete_Brick_Half",
      "rotation": 8
    },
    {
      "x": 12,
      "y": 1,
      "z": -3,
      "name": "Prototype_Rock_Concrete_Brick"
    },
    {
      "x": 12,
      "y": 2,
      "z": -3,
      "name": "Prototype_Rock_Concrete_Brick_Half"
    },
    {
      "x": 12,
      "y": 5,
      "z": -3,
      "name": "Rock_Stone_Brick"
    },
    {
      "x": 12,
      "y": 6,
      "z": -3,
      "name": "Rock_Stone_Brick"
    },
    {
      "x": 12,
      "y": 18,
      "z": -3,
      "name": "Rock_Calcite_Brick_Smooth"
    },
    {
      "x": 12,
      "y": 19,
      "z": -3,
      "name": "Rock_Calcite_Brick_Smooth"
    },
    {
      "x": 12,
      "y": 0,
      "z": -2,
      "name": "Prototype_Rock_Concrete_Brick_Half",
      "rotation": 8
    },
    {
      "x": 12,
      "y": 0,
      "z": -1,
      "name": "Rock_Stone_Brick_Stairs"
    },
    {
      "x": 13,
      "y": 16,
      "z": -12,
      "name": "Rock_Stone_Cobble"
    },
    {
      "x": 13,
      "y": 17,
      "z": -12,
      "name": "Rock_Stone_Cobble"
    },
    {
      "x": 13,
      "y": 18,
      "z": -12,
      "name": "Rock_Stone_Cobble"
    },
    {
      "x": 13,
      "y": 19,
      "z": -12,
      "name": "Rock_Stone_Cobble"
    },
    {
      "x": 13,
      "y": 20,
      "z": -12,
      "name": "Rock_Stone_Cobble"
    },
    {
      "x": 13,
      "y": 0,
      "z": -11,
      "name": "*Rock_Stone_Brick_Stairs_State_Definitions_Corner_Right",
      "rotation": 2
    },
    {
      "x": 13,
      "y": 15,
      "z": -11,
      "name": "Rock_Stone_Brick"
    },
    {
      "x": 13,
      "y": 21,
      "z": -11,
      "name": "Rock_Stone_Cobble"
    },
    {
      "x": 13,
      "y": 22,
      "z": -11,
      "name": "Rock_Stone_Cobble"
    },
    {
      "x": 13,
      "y": 23,
      "z": -11,
      "name": "Rock_Stone_Cobble"
    },
    {
      "x": 13,
      "y": 24,
      "z": -11,
      "name": "Rock_Stone_Cobble"
    },
    {
      "x": 13,
      "y": 25,
      "z": -11,
      "name": "Rock_Stone_Brick"
    },
    {
      "x": 13,
      "y": 0,
      "z": -10,
      "name": "*Rock_Stone_Brick_Stairs_State_Definitions_Inverted_Corner_Left",
      "rotation": 1
    },
    {
      "x": 13,
      "y": 3,
      "z": -10,
      "name": "Rock_Stone_Brick"
    },
    {
      "x": 13,
      "y": 24,
      "z": -10,
      "name": "Rock_Stone_Brick"
    },
    {
      "x": 13,
      "y": 0,
      "z": -9,
      "name": "Prototype_Rock_Concrete_Brick_Half",
      "rotation": 8
    },
    {
      "x": 13,
      "y": 4,
      "z": -9,
      "name": "Rock_Stone"
    },
    {
      "x": 13,
      "y": 20,
      "z": -9,
      "name": "Rock_Stone"
    },
    {
      "x": 13,
      "y": 21,
      "z": -9,
      "name": "Rock_Stone"
    },
    {
      "x": 13,
      "y": 22,
      "z": -9,
      "name": "Rock_Stone"
    },
    {
      "x": 13,
      "y": 23,
      "z": -9,
      "name": "Rock_Calcite_Brick_Smooth"
    },
    {
      "x": 13,
      "y": 24,
      "z": -9,
      "name": "Rock_Calcite_Brick_Smooth"
    },
    {
      "x": 13,
      "y": 0,
      "z": -8,
      "name": "Prototype_Rock_Concrete_Brick_Half",
      "rotation": 8
    },
    {
      "x": 13,
      "y": 1,
      "z": -8,
      "name": "Prototype_Rock_Concrete_Brick"
    },
    {
      "x": 13,
      "y": 2,
      "z": -8,
      "name": "Prototype_Rock_Concrete_Brick_Half"
    },
    {
      "x": 13,
      "y": 4,
      "z": -8,
      "name": "Rock_Stone"
    },
    {
      "x": 13,
      "y": 5,
      "z": -8,
      "name": "Rock_Stone"
    },
    {
      "x": 13,
      "y": 18,
      "z": -8,
      "name": "Rock_Stone"
    },
    {
      "x": 13,
      "y": 19,
      "z": -8,
      "name": "Rock_Stone"
    },
    {
      "x": 13,
      "y": 24,
      "z": -8,
      "name": "Rock_Stone_Cobble"
    },
    {
      "x": 13,
      "y": 25,
      "z": -8,
      "name": "Rock_Calcite_Brick_Smooth"
    },
    {
      "x": 13,
      "y": 0,
      "z": -7,
      "name": "Prototype_Rock_Concrete_Brick_Half",
      "rotation": 8
    },
    {
      "x": 13,
      "y": 1,
      "z": -7,
      "name": "Prototype_Rock_Concrete_Brick"
    },
    {
      "x": 13,
      "y": 2,
      "z": -7,
      "name": "Prototype_Rock_Concrete_Brick_Half"
    },
    {
      "x": 13,
      "y": 5,
      "z": -7,
      "name": "Rock_Stone"
    },
    {
      "x": 13,
      "y": 15,
      "z": -7,
      "name": "Rock_Stone"
    },
    {
      "x": 13,
      "y": 16,
      "z": -7,
      "name": "Rock_Stone"
    },
    {
      "x": 13,
      "y": 17,
      "z": -7,
      "name": "Rock_Stone"
    },
    {
      "x": 13,
      "y": 24,
      "z": -7,
      "name": "Rock_Stone_Cobble"
    },
    {
      "x": 13,
      "y": 25,
      "z": -7,
      "name": "Rock_Calcite_Brick_Smooth"
    },
    {
      "x": 13,
      "y": 0,
      "z": -6,
      "name": "Prototype_Rock_Concrete_Brick_Half",
      "rotation": 8
    },
    {
      "x": 13,
      "y": 1,
      "z": -6,
      "name": "Prototype_Rock_Concrete_Brick"
    },
    {
      "x": 13,
      "y": 2,
      "z": -6,
      "name": "Prototype_Rock_Concrete_Brick_Half"
    },
    {
      "x": 13,
      "y": 5,
      "z": -6,
      "name": "Rock_Stone"
    },
    {
      "x": 13,
      "y": 6,
      "z": -6,
      "name": "Rock_Stone"
    },
    {
      "x": 13,
      "y": 7,
      "z": -6,
      "name": "Rock_Stone"
    },
    {
      "x": 13,
      "y": 14,
      "z": -6,
      "name": "Rock_Stone"
    },
    {
      "x": 13,
      "y": 15,
      "z": -6,
      "name": "Rock_Stone"
    },
    {
      "x": 13,
      "y": 24,
      "z": -6,
      "name": "Rock_Stone_Cobble"
    },
    {
      "x": 13,
      "y": 25,
      "z": -6,
      "name": "Rock_Calcite_Brick_Smooth"
    },
    {
      "x": 13,
      "y": 0,
      "z": -5,
      "name": "Prototype_Rock_Concrete_Brick_Half",
      "rotation": 8
    },
    {
      "x": 13,
      "y": 1,
      "z": -5,
      "name": "Prototype_Rock_Concrete_Brick"
    },
    {
      "x": 13,
      "y": 2,
      "z": -5,
      "name": "Prototype_Rock_Concrete_Brick_Half"
    },
    {
      "x": 13,
      "y": 5,
      "z": -5,
      "name": "Rock_Stone"
    },
    {
      "x": 13,
      "y": 6,
      "z": -5,
      "name": "Rock_Stone"
    },
    {
      "x": 13,
      "y": 7,
      "z": -5,
      "name": "Rock_Stone"
    },
    {
      "x": 13,
      "y": 8,
      "z": -5,
      "name": "Rock_Stone"
    },
    {
      "x": 13,
      "y": 9,
      "z": -5,
      "name": "Rock_Stone"
    },
    {
      "x": 13,
      "y": 15,
      "z": -5,
      "name": "Rock_Stone"
    },
    {
      "x": 13,
      "y": 16,
      "z": -5,
      "name": "Rock_Stone"
    },
    {
      "x": 13,
      "y": 17,
      "z": -5,
      "name": "Rock_Stone"
    },
    {
      "x": 13,
      "y": 18,
      "z": -5,
      "name": "Rock_Stone_Cobble"
    },
    {
      "x": 13,
      "y": 19,
      "z": -5,
      "name": "Soil_Grass"
    },
    {
      "x": 13,
      "y": 21,
      "z": -5,
      "name": "Rock_Stone"
    },
    {
      "x": 13,
      "y": 22,
      "z": -5,
      "name": "Rock_Stone"
    },
    {
      "x": 13,
      "y": 23,
      "z": -5,
      "name": "Soil_Dirt"
    },
    {
      "x": 13,
      "y": 24,
      "z": -5,
      "name": "Rock_Calcite_Brick_Smooth"
    },
    {
      "x": 13,
      "y": 0,
      "z": -4,
      "name": "Prototype_Rock_Concrete_Brick_Half",
      "rotation": 8
    },
    {
      "x": 13,
      "y": 1,
      "z": -4,
      "name": "Prototype_Rock_Concrete_Brick"
    },
    {
      "x": 13,
      "y": 2,
      "z": -4,
      "name": "Prototype_Rock_Concrete_Brick_Half"
    },
    {
      "x": 13,
      "y": 4,
      "z": -4,
      "name": "Rock_Stone"
    },
    {
      "x": 13,
      "y": 5,
      "z": -4,
      "name": "Rock_Stone"
    },
    {
      "x": 13,
      "y": 6,
      "z": -4,
      "name": "Rock_Stone"
    },
    {
      "x": 13,
      "y": 18,
      "z": -4,
      "name": "Rock_Calcite_Brick_Smooth"
    },
    {
      "x": 13,
      "y": 19,
      "z": -4,
      "name": "Rock_Calcite_Brick_Smooth"
    },
    {
      "x": 13,
      "y": 20,
      "z": -4,
      "name": "Rock_Calcite_Brick_Smooth"
    },
    {
      "x": 13,
      "y": 23,
      "z": -4,
      "name": "Rock_Calcite_Brick_Smooth"
    },
    {
      "x": 13,
      "y": 0,
      "z": -3,
      "name": "Prototype_Rock_Concrete_Brick_Half",
      "rotation": 8
    },
    {
      "x": 13,
      "y": 4,
      "z": -3,
      "name": "Rock_Stone_Brick"
    },
    {
      "x": 13,
      "y": 16,
      "z": -3,
      "name": "Rock_Calcite_Brick_Smooth"
    },
    {
      "x": 13,
      "y": 17,
      "z": -3,
      "name": "Rock_Calcite_Brick_Smooth"
    },
    {
      "x": 13,
      "y": 18,
      "z": -3,
      "name": "Soil_Dirt"
    },
    {
      "x": 13,
      "y": 19,
      "z": -3,
      "name": "Soil_Dirt"
    },
    {
      "x": 13,
      "y": 20,
      "z": -3,
      "name": "Rock_Calcite_Brick_Smooth"
    },
    {
      "x": 13,
      "y": 21,
      "z": -3,
      "name": "Rock_Calcite_Brick_Smooth"
    },
    {
      "x": 13,
      "y": 0,
      "z": -2,
      "name": "*Rock_Stone_Brick_Stairs_State_Definitions_Inverted_Corner_Left"
    },
    {
      "x": 13,
      "y": 18,
      "z": -2,
      "name": "Rock_Calcite_Brick_Smooth"
    },
    {
      "x": 13,
      "y": 19,
      "z": -2,
      "name": "Rock_Calcite_Brick_Smooth"
    },
    {
      "x": 13,
      "y": 20,
      "z": -2,
      "name": "Rock_Calcite_Brick_Smooth"
    },
    {
      "x": 13,
      "y": 0,
      "z": -1,
      "name": "*Rock_Stone_Brick_Stairs_State_Definitions_Corner_Right",
      "rotation": 1
    },
    {
      "x": 14,
      "y": 17,
      "z": -13,
      "name": "Rock_Stone_Cobble"
    },
    {
      "x": 14,
      "y": 18,
      "z": -13,
      "name": "Rock_Stone_Cobble"
    },
    {
      "x": 14,
      "y": 19,
      "z": -13,
      "name": "Rock_Stone_Cobble"
    },
    {
      "x": 14,
      "y": 20,
      "z": -13,
      "name": "Rock_Stone_Cobble"
    },
    {
      "x": 14,
      "y": 21,
      "z": -13,
      "name": "Rock_Stone_Cobble"
    },
    {
      "x": 14,
      "y": 15,
      "z": -12,
      "name": "Rock_Stone_Cobble"
    },
    {
      "x": 14,
      "y": 16,
      "z": -12,
      "name": "Rock_Stone_Brick"
    },
    {
      "x": 14,
      "y": 21,
      "z": -12,
      "name": "Rock_Stone_Cobble"
    },
    {
      "x": 14,
      "y": 22,
      "z": -12,
      "name": "Rock_Stone_Cobble"
    },
    {
      "x": 14,
      "y": 23,
      "z": -12,
      "name": "Rock_Stone_Cobble"
    },
    {
      "x": 14,
      "y": 24,
      "z": -12,
      "name": "Rock_Stone_Cobble"
    },
    {
      "x": 14,
      "y": 25,
      "z": -12,
      "name": "Rock_Stone_Cobble"
    },
    {
      "x": 14,
      "y": 26,
      "z": -12,
      "name": "Rock_Stone_Cobble"
    },
    {
      "x": 14,
      "y": 27,
      "z": -12,
      "name": "Rock_Stone_Cobble"
    },
    {
      "x": 14,
      "y": 26,
      "z": -11,
      "name": "Rock_Stone_Brick"
    },
    {
      "x": 14,
      "y": 27,
      "z": -11,
      "name": "Rock_Stone_Brick"
    },
    {
      "x": 14,
      "y": 0,
      "z": -10,
      "name": "*Rock_Stone_Brick_Stairs_State_Definitions_Corner_Right",
      "rotation": 2
    },
    {
      "x": 14,
      "y": 0,
      "z": -9,
      "name": "*Rock_Stone_Brick_Stairs_State_Definitions_Inverted_Corner_Left",
      "rotation": 1
    },
    {
      "x": 14,
      "y": 3,
      "z": -9,
      "name": "Rock_Stone_Brick"
    },
    {
      "x": 14,
      "y": 23,
      "z": -9,
      "name": "Rock_Calcite_Brick_Smooth"
    },
    {
      "x": 14,
      "y": 24,
      "z": -9,
      "name": "Rock_Calcite_Brick_Smooth"
    },
    {
      "x": 14,
      "y": 0,
      "z": -8,
      "name": "Prototype_Rock_Concrete_Brick_Half",
      "rotation": 8
    },
    {
      "x": 14,
      "y": 4,
      "z": -8,
      "name": "Rock_Stone"
    },
    {
      "x": 14,
      "y": 20,
      "z": -8,
      "name": "Rock_Stone"
    },
    {
      "x": 14,
      "y": 21,
      "z": -8,
      "name": "Rock_Stone"
    },
    {
      "x": 14,
      "y": 22,
      "z": -8,
      "name": "Rock_Calcite_Brick_Smooth"
    },
    {
      "x": 14,
      "y": 23,
      "z": -8,
      "name": "Rock_Stone_Cobble"
    },
    {
      "x": 14,
      "y": 24,
      "z": -8,
      "name": "Rock_Stone_Cobble"
    },
    {
      "x": 14,
      "y": 25,
      "z": -8,
      "name": "Rock_Calcite_Brick_Smooth"
    },
    {
      "x": 14,
      "y": 0,
      "z": -7,
      "name": "Prototype_Rock_Concrete_Brick_Half",
      "rotation": 8
    },
    {
      "x": 14,
      "y": 1,
      "z": -7,
      "name": "Prototype_Rock_Concrete_Brick"
    },
    {
      "x": 14,
      "y": 2,
      "z": -7,
      "name": "Prototype_Rock_Concrete_Brick_Half"
    },
    {
      "x": 14,
      "y": 4,
      "z": -7,
      "name": "Rock_Stone"
    },
    {
      "x": 14,
      "y": 16,
      "z": -7,
      "name": "Rock_Stone"
    },
    {
      "x": 14,
      "y": 17,
      "z": -7,
      "name": "Rock_Stone"
    },
    {
      "x": 14,
      "y": 18,
      "z": -7,
      "name": "Rock_Stone"
    },
    {
      "x": 14,
      "y": 19,
      "z": -7,
      "name": "Rock_Stone"
    },
    {
      "x": 14,
      "y": 20,
      "z": -7,
      "name": "Rock_Stone"
    },
    {
      "x": 14,
      "y": 21,
      "z": -7,
      "name": "Rock_Stone_Cobble"
    },
    {
      "x": 14,
      "y": 22,
      "z": -7,
      "name": "Rock_Stone_Cobble"
    },
    {
      "x": 14,
      "y": 23,
      "z": -7,
      "name": "Rock_Stone_Cobble"
    },
    {
      "x": 14,
      "y": 24,
      "z": -7,
      "name": "Rock_Stone_Cobble"
    },
    {
      "x": 14,
      "y": 25,
      "z": -7,
      "name": "Rock_Calcite_Brick_Smooth"
    },
    {
      "x": 14,
      "y": 0,
      "z": -6,
      "name": "Prototype_Rock_Concrete_Brick_Half",
      "rotation": 8
    },
    {
      "x": 14,
      "y": 1,
      "z": -6,
      "name": "Prototype_Rock_Concrete_Brick"
    },
    {
      "x": 14,
      "y": 2,
      "z": -6,
      "name": "Prototype_Rock_Concrete_Brick_Half"
    },
    {
      "x": 14,
      "y": 4,
      "z": -6,
      "name": "Rock_Stone"
    },
    {
      "x": 14,
      "y": 16,
      "z": -6,
      "name": "Rock_Stone"
    },
    {
      "x": 14,
      "y": 17,
      "z": -6,
      "name": "Rock_Stone"
    },
    {
      "x": 14,
      "y": 18,
      "z": -6,
      "name": "Rock_Stone"
    },
    {
      "x": 14,
      "y": 19,
      "z": -6,
      "name": "Rock_Stone"
    },
    {
      "x": 14,
      "y": 20,
      "z": -6,
      "name": "Rock_Stone_Cobble"
    },
    {
      "x": 14,
      "y": 21,
      "z": -6,
      "name": "Rock_Stone_Cobble"
    },
    {
      "x": 14,
      "y": 22,
      "z": -6,
      "name": "Rock_Stone_Cobble"
    },
    {
      "x": 14,
      "y": 23,
      "z": -6,
      "name": "Rock_Stone_Cobble"
    },
    {
      "x": 14,
      "y": 24,
      "z": -6,
      "name": "Rock_Stone_Cobble"
    },
    {
      "x": 14,
      "y": 25,
      "z": -6,
      "name": "Rock_Calcite_Brick_Smooth"
    },
    {
      "x": 14,
      "y": 0,
      "z": -5,
      "name": "Prototype_Rock_Concrete_Brick_Half",
      "rotation": 8
    },
    {
      "x": 14,
      "y": 1,
      "z": -5,
      "name": "Prototype_Rock_Concrete_Brick"
    },
    {
      "x": 14,
      "y": 2,
      "z": -5,
      "name": "Prototype_Rock_Concrete_Brick_Half"
    },
    {
      "x": 14,
      "y": 3,
      "z": -5,
      "name": "Rock_Stone"
    },
    {
      "x": 14,
      "y": 4,
      "z": -5,
      "name": "Rock_Stone"
    },
    {
      "x": 14,
      "y": 5,
      "z": -5,
      "name": "Rock_Stone"
    },
    {
      "x": 14,
      "y": 18,
      "z": -5,
      "name": "Rock_Stone"
    },
    {
      "x": 14,
      "y": 19,
      "z": -5,
      "name": "Rock_Stone_Cobble"
    },
    {
      "x": 14,
      "y": 21,
      "z": -5,
      "name": "Rock_Stone_Cobble"
    },
    {
      "x": 14,
      "y": 22,
      "z": -5,
      "name": "Rock_Stone_Cobble"
    },
    {
      "x": 14,
      "y": 23,
      "z": -5,
      "name": "Soil_Dirt"
    },
    {
      "x": 14,
      "y": 24,
      "z": -5,
      "name": "Rock_Calcite_Brick_Smooth"
    },
    {
      "x": 14,
      "y": 0,
      "z": -4,
      "name": "Prototype_Rock_Concrete_Brick_Half",
      "rotation": 8
    },
    {
      "x": 14,
      "y": 3,
      "z": -4,
      "name": "Rock_Stone_Brick"
    },
    {
      "x": 14,
      "y": 17,
      "z": -4,
      "name": "Rock_Calcite_Brick_Smooth"
    },
    {
      "x": 14,
      "y": 18,
      "z": -4,
      "name": "Soil_Dirt"
    },
    {
      "x": 14,
      "y": 20,
      "z": -4,
      "name": "Soil_Dirt"
    },
    {
      "x": 14,
      "y": 21,
      "z": -4,
      "name": "Rock_Calcite_Brick_Smooth"
    },
    {
      "x": 14,
      "y": 22,
      "z": -4,
      "name": "Rock_Calcite_Brick_Smooth"
    },
    {
      "x": 14,
      "y": 23,
      "z": -4,
      "name": "Rock_Calcite_Brick_Smooth"
    },
    {
      "x": 14,
      "y": 0,
      "z": -3,
      "name": "*Rock_Stone_Brick_Stairs_State_Definitions_Inverted_Corner_Left"
    },
    {
      "x": 14,
      "y": 18,
      "z": -3,
      "name": "Rock_Calcite_Brick_Smooth"
    },
    {
      "x": 14,
      "y": 21,
      "z": -3,
      "name": "Rock_Calcite_Brick_Smooth"
    },
    {
      "x": 14,
      "y": 0,
      "z": -2,
      "name": "*Rock_Stone_Brick_Stairs_State_Definitions_Corner_Right",
      "rotation": 1
    },
    {
      "x": 14,
      "y": 19,
      "z": -2,
      "name": "Rock_Calcite_Brick_Smooth"
    },
    {
      "x": 14,
      "y": 20,
      "z": -2,
      "name": "Rock_Calcite_Brick_Smooth"
    },
    {
      "x": 15,
      "y": 14,
      "z": -13,
      "name": "Rock_Stone_Cobble"
    },
    {
      "x": 15,
      "y": 15,
      "z": -13,
      "name": "Rock_Stone_Cobble"
    },
    {
      "x": 15,
      "y": 16,
      "z": -13,
      "name": "Rock_Stone_Cobble"
    },
    {
      "x": 15,
      "y": 17,
      "z": -13,
      "name": "Rock_Stone_Brick"
    },
    {
      "x": 15,
      "y": 18,
      "z": -13,
      "name": "Rock_Stone_Brick"
    },
    {
      "x": 15,
      "y": 19,
      "z": -13,
      "name": "Rock_Stone_Cobble"
    },
    {
      "x": 15,
      "y": 20,
      "z": -13,
      "name": "Rock_Stone_Cobble"
    },
    {
      "x": 15,
      "y": 21,
      "z": -13,
      "name": "Rock_Stone_Cobble"
    },
    {
      "x": 15,
      "y": 22,
      "z": -13,
      "name": "Rock_Stone_Cobble"
    },
    {
      "x": 15,
      "y": 23,
      "z": -13,
      "name": "Rock_Stone_Cobble"
    },
    {
      "x": 15,
      "y": 24,
      "z": -13,
      "name": "Rock_Stone_Cobble"
    },
    {
      "x": 15,
      "y": 25,
      "z": -13,
      "name": "Rock_Stone_Cobble"
    },
    {
      "x": 15,
      "y": 26,
      "z": -13,
      "name": "Rock_Stone_Cobble"
    },
    {
      "x": 15,
      "y": 27,
      "z": -13,
      "name": "Rock_Stone_Cobble"
    },
    {
      "x": 15,
      "y": 28,
      "z": -13,
      "name": "Rock_Stone_Cobble"
    },
    {
      "x": 15,
      "y": 28,
      "z": -12,
      "name": "Rock_Stone_Brick"
    },
    {
      "x": 15,
      "y": 29,
      "z": -12,
      "name": "Rock_Stone_Brick"
    },
    {
      "x": 15,
      "y": 30,
      "z": -12,
      "name": "Rock_Stone_Brick"
    },
    {
      "x": 15,
      "y": 0,
      "z": -9,
      "name": "*Rock_Stone_Brick_Stairs_State_Definitions_Corner_Right",
      "rotation": 2
    },
    {
      "x": 15,
      "y": 23,
      "z": -9,
      "name": "Rock_Calcite_Brick_Smooth"
    },
    {
      "x": 15,
      "y": 24,
      "z": -9,
      "name": "Rock_Calcite_Brick_Smooth"
    },
    {
      "x": 15,
      "y": 0,
      "z": -8,
      "name": "*Rock_Stone_Brick_Stairs_State_Definitions_Inverted_Corner_Left",
      "rotation": 1
    },
    {
      "x": 15,
      "y": 3,
      "z": -8,
      "name": "Rock_Stone_Brick"
    },
    {
      "x": 15,
      "y": 22,
      "z": -8,
      "name": "Rock_Calcite_Brick_Smooth"
    },
    {
      "x": 15,
      "y": 25,
      "z": -8,
      "name": "Rock_Stone_Brick_Stairs",
      "rotation": 1
    },
    {
      "x": 15,
      "y": 0,
      "z": -7,
      "name": "Prototype_Rock_Concrete_Brick_Half",
      "rotation": 8
    },
    {
      "x": 15,
      "y": 3,
      "z": -7,
      "name": "Rock_Stone_Brick"
    },
    {
      "x": 15,
      "y": 21,
      "z": -7,
      "name": "Rock_Calcite_Brick_Smooth"
    },
    {
      "x": 15,
      "y": 22,
      "z": -7,
      "name": "Rock_Calcite_Brick_Smooth"
    },
    {
      "x": 15,
      "y": 25,
      "z": -7,
      "name": "Rock_Stone_Brick_Stairs",
      "rotation": 1
    },
    {
      "x": 15,
      "y": 0,
      "z": -6,
      "name": "Prototype_Rock_Concrete_Brick_Half",
      "rotation": 8
    },
    {
      "x": 15,
      "y": 3,
      "z": -6,
      "name": "Rock_Stone_Brick"
    },
    {
      "x": 15,
      "y": 20,
      "z": -6,
      "name": "Rock_Calcite_Brick_Smooth"
    },
    {
      "x": 15,
      "y": 25,
      "z": -6,
      "name": "Rock_Stone_Brick_Stairs",
      "rotation": 1
    },
    {
      "x": 15,
      "y": 0,
      "z": -5,
      "name": "Prototype_Rock_Concrete_Brick_Half",
      "rotation": 8
    },
    {
      "x": 15,
      "y": 3,
      "z": -5,
      "name": "Rock_Stone_Brick"
    },
    {
      "x": 15,
      "y": 19,
      "z": -5,
      "name": "Rock_Calcite_Brick_Smooth"
    },
    {
      "x": 15,
      "y": 23,
      "z": -5,
      "name": "Soil_Dirt"
    },
    {
      "x": 15,
      "y": 24,
      "z": -5,
      "name": "Rock_Calcite_Brick_Smooth"
    },
    {
      "x": 15,
      "y": 0,
      "z": -4,
      "name": "*Rock_Stone_Brick_Stairs_State_Definitions_Inverted_Corner_Left"
    },
    {
      "x": 15,
      "y": 18,
      "z": -4,
      "name": "Rock_Calcite_Brick_Smooth"
    },
    {
      "x": 15,
      "y": 20,
      "z": -4,
      "name": "Soil_Dirt"
    },
    {
      "x": 15,
      "y": 22,
      "z": -4,
      "name": "Rock_Calcite_Brick_Smooth"
    },
    {
      "x": 15,
      "y": 23,
      "z": -4,
      "name": "Rock_Calcite_Brick_Smooth"
    },
    {
      "x": 15,
      "y": 0,
      "z": -3,
      "name": "*Rock_Stone_Brick_Stairs_State_Definitions_Corner_Right",
      "rotation": 1
    },
    {
      "x": 15,
      "y": 19,
      "z": -3,
      "name": "Rock_Calcite_Brick_Smooth"
    },
    {
      "x": 15,
      "y": 21,
      "z": -3,
      "name": "Rock_Calcite_Brick_Smooth"
    },
    {
      "x": 15,
      "y": 19,
      "z": -2,
      "name": "Rock_Calcite_Brick_Smooth"
    },
    {
      "x": 15,
      "y": 20,
      "z": -2,
      "name": "Rock_Calcite_Brick_Smooth"
    },
    {
      "x": 16,
      "y": 14,
      "z": -14,
      "name": "Rock_Stone_Cobble"
    },
    {
      "x": 16,
      "y": 15,
      "z": -14,
      "name": "Rock_Stone_Cobble"
    },
    {
      "x": 16,
      "y": 16,
      "z": -14,
      "name": "Rock_Stone_Cobble"
    },
    {
      "x": 16,
      "y": 17,
      "z": -14,
      "name": "Rock_Stone_Cobble"
    },
    {
      "x": 16,
      "y": 18,
      "z": -14,
      "name": "Rock_Stone_Cobble"
    },
    {
      "x": 16,
      "y": 19,
      "z": -14,
      "name": "Rock_Stone_Brick"
    },
    {
      "x": 16,
      "y": 20,
      "z": -14,
      "name": "Rock_Stone_Brick"
    },
    {
      "x": 16,
      "y": 21,
      "z": -14,
      "name": "Rock_Stone_Brick"
    },
    {
      "x": 16,
      "y": 22,
      "z": -14,
      "name": "Rock_Stone_Brick"
    },
    {
      "x": 16,
      "y": 23,
      "z": -14,
      "name": "Rock_Stone_Cobble"
    },
    {
      "x": 16,
      "y": 24,
      "z": -14,
      "name": "Rock_Stone_Cobble"
    },
    {
      "x": 16,
      "y": 25,
      "z": -14,
      "name": "Rock_Stone_Cobble"
    },
    {
      "x": 16,
      "y": 26,
      "z": -14,
      "name": "Rock_Stone_Cobble"
    },
    {
      "x": 16,
      "y": 27,
      "z": -14,
      "name": "Rock_Stone_Cobble"
    },
    {
      "x": 16,
      "y": 28,
      "z": -14,
      "name": "Rock_Stone_Cobble"
    },
    {
      "x": 16,
      "y": 13,
      "z": -13,
      "name": "Rock_Stone_Cobble"
    },
    {
      "x": 16,
      "y": 28,
      "z": -13,
      "name": "Rock_Stone_Cobble"
    },
    {
      "x": 16,
      "y": 29,
      "z": -13,
      "name": "Rock_Stone_Cobble"
    },
    {
      "x": 16,
      "y": 30,
      "z": -13,
      "name": "Rock_Stone_Cobble"
    },
    {
      "x": 16,
      "y": 31,
      "z": -13,
      "name": "Rock_Stone_Brick"
    },
    {
      "x": 16,
      "y": 32,
      "z": -13,
      "name": "Rock_Stone_Brick"
    },
    {
      "x": 16,
      "y": 33,
      "z": -13,
      "name": "Rock_Stone_Brick"
    },
    {
      "x": 16,
      "y": 11,
      "z": -12,
      "name": "Rock_Stone_Brick"
    },
    {
      "x": 16,
      "y": 12,
      "z": -12,
      "name": "Rock_Stone_Cobble"
    },
    {
      "x": 16,
      "y": 34,
      "z": -12,
      "name": "Rock_Stone_Brick"
    },
    {
      "x": 16,
      "y": 35,
      "z": -12,
      "name": "Rock_Stone_Brick"
    },
    {
      "x": 16,
      "y": 0,
      "z": -8,
      "name": "*Rock_Stone_Brick_Stairs_State_Definitions_Corner_Right",
      "rotation": 2
    },
    {
      "x": 16,
      "y": 23,
      "z": -8,
      "name": "Rock_Calcite_Brick_Smooth"
    },
    {
      "x": 16,
      "y": 24,
      "z": -8,
      "name": "Rock_Calcite_Brick_Smooth"
    },
    {
      "x": 16,
      "y": 0,
      "z": -7,
      "name": "Rock_Stone_Brick_Stairs",
      "rotation": 1
    },
    {
      "x": 16,
      "y": 21,
      "z": -7,
      "name": "Rock_Calcite_Brick_Smooth"
    },
    {
      "x": 16,
