{
  "version": 8,
  "blockIdVersion": 11,
  "anchorX": 0,
  "anchorY": 0,
  "anchorZ": 0,
  "blocks": [
    {
      "x": 1,
      "y": 0,
      "z": -17,
      "name": "Soil_Grass",
      "rotation": 1
    },
    {
      "x": 1,
      "y": 0,
      "z": -16,
      "name": "Soil_Grass",
      "rotation": 1
    },
    {
      "x": 1,
      "y": 0,
      "z": -15,
      "name": "Soil_Grass",
      "rotation": 1
    },
    {
      "x": 1,
      "y": 0,
      "z": -14,
      "name": "Soil_Grass",
      "rotation": 1
    },
    {
      "x": 1,
      "y": 0,
      "z": -13,
      "name": "Soil_Grass",
      "rotation": 1
    },
    {
      "x": 1,
      "y": 0,
      "z": -12,
      "name": "Soil_Grass",
      "rotation": 1
    },
    {
      "x": 1,
      "y": 0,
      "z": -11,
      "name": "Soil_Grass",
      "rotation": 1
    },
    {
      "x": 1,
      "y": 0,
      "z": -10,
      "name": "Soil_Grass",
      "rotation": 1
    },
    {
      "x": 1,
      "y": 0,
      "z": -9,
      "name": "Soil_Grass",
      "rotation": 1
    },
    {
      "x": 1,
      "y": 0,
      "z": -8,
      "name": "Soil_Grass",
      "rotation": 1
    },
    {
      "x": 1,
      "y": 0,
      "z": -7,
      "name": "Soil_Grass",
      "rotation": 1
    },
    {
      "x": 1,
      "y": 0,
      "z": -6,
      "name": "Soil_Grass",
      "rotation": 1
    },
    {
      "x": 1,
      "y": 0,
      "z": -5,
      "name": "Soil_Grass",
      "rotation": 1
    },
    {
      "x": 1,
      "y": 0,
      "z": -4,
      "name": "Soil_Grass",
      "rotation": 1
    },
    {
      "x": 1,
      "y": 0,
      "z": -3,
      "name": "Soil_Grass",
      "rotation": 1
    },
    {
      "x": 1,
      "y": 12,
      "z": -3,
      "name": "Cloth_Block_Wool_White"
    },
    {
      "x": 1,
      "y": 13,
      "z": -3,
      "name": "Cloth_Block_Wool_White"
    },
    {
      "x": 1,
      "y": 0,
      "z": -2,
      "name": "Soil_Grass",
      "rotation": 1
    },
    {
      "x": 1,
      "y": 0,
      "z": -1,
      "name": "Soil_Grass",
      "rotation": 1
    },
    {
      "x": 2,
      "y": 0,
      "z": -17,
      "name": "Soil_Grass",
      "rotation": 1
    },
    {
      "x": 2,
      "y": 0,
      "z": -16,
      "name": "Soil_Grass",
      "rotation": 1
    },
    {
      "x": 2,
      "y": 0,
      "z": -15,
      "name": "Soil_Grass",
      "rotation": 1
    },
    {
      "x": 2,
      "y": 0,
      "z": -14,
      "name": "Soil_Grass",
      "rotation": 1
    },
    {
      "x": 2,
      "y": 0,
      "z": -13,
      "name": "Soil_Grass",
      "rotation": 1
    },
    {
      "x": 2,
      "y": 0,
      "z": -12,
      "name": "Soil_Grass",
      "rotation": 1
    },
    {
      "x": 2,
      "y": 0,
      "z": -11,
      "name": "Soil_Grass",
      "rotation": 1
    },
    {
      "x": 2,
      "y": 0,
      "z": -10,
      "name": "Soil_Grass",
      "rotation": 1
    },
    {
      "x": 2,
      "y": 0,
      "z": -9,
      "name": "Soil_Grass",
      "rotation": 1
    },
    {
      "x": 2,
      "y": 0,
      "z": -8,
      "name": "Soil_Grass",
      "rotation": 1
    },
    {
      "x": 2,
      "y": 0,
      "z": -7,
      "name": "Soil_Grass",
      "rotation": 1
    },
    {
      "x": 2,
      "y": 0,
      "z": -6,
      "name": "Soil_Grass",
      "rotation": 1
    },
    {
      "x": 2,
      "y": 0,
      "z": -5,
      "name": "Soil_Grass",
      "rotation": 1
    },
    {
      "x": 2,
      "y": 0,
      "z": -4,
      "name": "Soil_Grass",
      "rotation": 1
    },
    {
      "x": 2,
      "y": 0,
      "z": -3,
      "name": "Soil_Grass",
      "rotation": 1
    },
    {
      "x": 2,
      "y": 11,
      "z": -3,
      "name": "Cloth_Block_Wool_White"
    },
    {
      "x": 2,
      "y": 12,
      "z": -3,
      "name": "Cloth_Block_Wool_White"
    },
    {
      "x": 2,
      "y": 13,
      "z": -3,
      "name": "Wood_Lightwood_Fence"
    },
    {
      "x": 2,
      "y": 14,
      "z": -3,
      "name": "Wood_Hardwood_Stairs",
      "rotation": 3
    },
    {
      "x": 2,
      "y": 0,
      "z": -2,
      "name": "Soil_Grass",
      "rotation": 1
    },
    {
      "x": 2,
      "y": 0,
      "z": -1,
      "name": "Soil_Grass",
      "rotation": 1
    },
    {
      "x": 3,
      "y": 0,
      "z": -17,
      "name": "Soil_Grass",
      "rotation": 1
    },
    {
      "x": 3,
      "y": 0,
      "z": -16,
      "name": "Soil_Grass",
      "rotation": 1
    },
    {
      "x": 3,
      "y": 0,
      "z": -15,
      "name": "Soil_Grass",
      "rotation": 1
    },
    {
      "x": 3,
      "y": 11,
      "z": -15,
      "name": "Wood_Oak_Branch_Short",
      "support": 15,
      "rotation": 3
    },
    {
      "x": 3,
      "y": 21,
      "z": -15,
      "name": "Wood_Oak_Branch_Short",
      "support": 15,
      "rotation": 3
    },
    {
      "x": 3,
      "y": 0,
      "z": -14,
      "name": "Soil_Grass",
      "rotation": 1
    },
    {
      "x": 3,
      "y": 0,
      "z": -13,
      "name": "Soil_Grass",
      "rotation": 1
    },
    {
      "x": 3,
      "y": 0,
      "z": -12,
      "name": "Soil_Grass",
      "rotation": 1
    },
    {
      "x": 3,
      "y": 0,
      "z": -11,
      "name": "Soil_Grass",
      "rotation": 1
    },
    {
      "x": 3,
      "y": 26,
      "z": -11,
      "name": "Wood_Oak_Branch_Short",
      "support": 15,
      "rotation": 3
    },
    {
      "x": 3,
      "y": 0,
      "z": -10,
      "name": "Soil_Grass",
      "rotation": 1
    },
    {
      "x": 3,
      "y": 0,
      "z": -9,
      "name": "Soil_Grass",
      "rotation": 1
    },
    {
      "x": 3,
      "y": 0,
      "z": -8,
      "name": "Soil_Grass",
      "rotation": 1
    },
    {
      "x": 3,
      "y": 0,
      "z": -7,
      "name": "Soil_Grass",
      "rotation": 1
    },
    {
      "x": 3,
      "y": 11,
      "z": -7,
      "name": "Wood_Oak_Branch_Short",
      "support": 15,
      "rotation": 3
    },
    {
      "x": 3,
      "y": 21,
      "z": -7,
      "name": "Wood_Oak_Branch_Short",
      "support": 15,
      "rotation": 3
    },
    {
      "x": 3,
      "y": 0,
      "z": -6,
      "name": "Soil_Grass",
      "rotation": 1
    },
    {
      "x": 3,
      "y": 0,
      "z": -5,
      "name": "Soil_Grass",
      "rotation": 1
    },
    {
      "x": 3,
      "y": 0,
      "z": -4,
      "name": "Soil_Grass",
      "rotation": 1
    },
    {
      "x": 3,
      "y": 0,
      "z": -3,
      "name": "Soil_Grass",
      "rotation": 1
    },
    {
      "x": 3,
      "y": 10,
      "z": -3,
      "name": "Cloth_Block_Wool_White"
    },
    {
      "x": 3,
      "y": 11,
      "z": -3,
      "name": "Cloth_Block_Wool_White"
    },
    {
      "x": 3,
      "y": 12,
      "z": -3,
      "name": "Cloth_Block_Wool_White"
    },
    {
      "x": 3,
      "y": 13,
      "z": -3,
      "name": "Wood_Lightwood_Fence"
    },
    {
      "x": 3,
      "y": 14,
      "z": -3,
      "name": "Wood_Hardwood_Planks"
    },
    {
      "x": 3,
      "y": 15,
      "z": -3,
      "name": "Wood_Hardwood_Stairs",
      "rotation": 3
    },
    {
      "x": 3,
      "y": 0,
      "z": -2,
      "name": "Soil_Grass",
      "rotation": 1
    },
    {
      "x": 3,
      "y": 11,
      "z": -2,
      "name": "Cloth_Block_Wool_White"
    },
    {
      "x": 3,
      "y": 0,
      "z": -1,
      "name": "Soil_Grass",
      "rotation": 1
    },
    {
      "x": 4,
      "y": 0,
      "z": -17,
      "name": "Soil_Grass",
      "rotation": 1
    },
    {
      "x": 4,
      "y": 0,
      "z": -16,
      "name": "Soil_Grass",
      "rotation": 1
    },
    {
      "x": 4,
      "y": 0,
      "z": -15,
      "name": "Soil_Grass",
      "rotation": 1
    },
    {
      "x": 4,
      "y": 1,
      "z": -15,
      "name": "Rock_Calcite_Brick_Stairs",
      "rotation": 3
    },
    {
      "x": 4,
      "y": 2,
      "z": -15,
      "name": "Rock_Calcite_Brick_Stairs",
      "rotation": 35
    },
    {
      "x": 4,
      "y": 11,
      "z": -15,
      "name": "Wood_Oak_Trunk",
      "support": 15,
      "rotation": 5
    },
    {
      "x": 4,
      "y": 21,
      "z": -15,
      "name": "Wood_Oak_Trunk",
      "support": 15,
      "rotation": 5
    },
    {
      "x": 4,
      "y": 0,
      "z": -14,
      "name": "Soil_Grass",
      "rotation": 1
    },
    {
      "x": 4,
      "y": 0,
      "z": -13,
      "name": "Soil_Grass",
      "rotation": 1
    },
    {
      "x": 4,
      "y": 0,
      "z": -12,
      "name": "Soil_Grass",
      "rotation": 1
    },
    {
      "x": 4,
      "y": 16,
      "z": -12,
      "name": "*Furniture_Crude_Trapdoor_State_Definitions_OpenDoorOut",
      "rotation": 2
    },
    {
      "x": 4,
      "y": 0,
      "z": -11,
      "name": "Soil_Grass",
      "rotation": 1
    },
    {
      "x": 4,
      "y": 16,
      "z": -11,
      "name": "Wood_Oak_Trunk",
      "support": 15,
      "rotation": 5
    },
    {
      "x": 4,
      "y": 26,
      "z": -11,
      "name": "Wood_Oak_Trunk",
      "support": 15,
      "rotation": 5
    },
    {
      "x": 4,
      "y": 0,
      "z": -10,
      "name": "Soil_Grass",
      "rotation": 1
    },
    {
      "x": 4,
      "y": 16,
      "z": -10,
      "name": "*Furniture_Crude_Trapdoor_State_Definitions_OpenDoorOut"
    },
    {
      "x": 4,
      "y": 0,
      "z": -9,
      "name": "Soil_Grass",
      "rotation": 1
    },
    {
      "x": 4,
      "y": 0,
      "z": -8,
      "name": "Soil_Grass",
      "rotation": 1
    },
    {
      "x": 4,
      "y": 0,
      "z": -7,
      "name": "Soil_Grass",
      "rotation": 1
    },
    {
      "x": 4,
      "y": 1,
      "z": -7,
      "name": "Rock_Calcite_Brick_Stairs",
      "rotation": 3
    },
    {
      "x": 4,
      "y": 2,
      "z": -7,
      "name": "Rock_Calcite_Brick_Stairs",
      "rotation": 35
    },
    {
      "x": 4,
      "y": 11,
      "z": -7,
      "name": "Wood_Oak_Trunk",
      "support": 15,
      "rotation": 5
    },
    {
      "x": 4,
      "y": 21,
      "z": -7,
      "name": "Wood_Oak_Trunk",
      "support": 15,
      "rotation": 5
    },
    {
      "x": 4,
      "y": 0,
      "z": -6,
      "name": "Soil_Grass",
      "rotation": 1
    },
    {
      "x": 4,
      "y": 0,
      "z": -5,
      "name": "Soil_Grass",
      "rotation": 1
    },
    {
      "x": 4,
      "y": 0,
      "z": -4,
      "name": "Soil_Grass",
      "rotation": 1
    },
    {
      "x": 4,
      "y": 0,
      "z": -3,
      "name": "Soil_Grass",
      "rotation": 1
    },
    {
      "x": 4,
      "y": 10,
      "z": -3,
      "name": "Cloth_Block_Wool_White"
    },
    {
      "x": 4,
      "y": 11,
      "z": -3,
      "name": "Cloth_Block_Wool_White"
    },
    {
      "x": 4,
      "y": 12,
      "z": -3,
      "name": "Cloth_Block_Wool_White"
    },
    {
      "x": 4,
      "y": 13,
      "z": -3,
      "name": "Cloth_Block_Wool_White"
    },
    {
      "x": 4,
      "y": 14,
      "z": -3,
      "name": "Wood_Lightwood_Fence"
    },
    {
      "x": 4,
      "y": 15,
      "z": -3,
      "name": "Wood_Hardwood_Planks"
    },
    {
      "x": 4,
      "y": 0,
      "z": -2,
      "name": "Soil_Grass",
      "rotation": 1
    },
    {
      "x": 4,
      "y": 11,
      "z": -2,
      "name": "Cloth_Block_Wool_White"
    },
    {
      "x": 4,
      "y": 12,
      "z": -2,
      "name": "Cloth_Block_Wool_White"
    },
    {
      "x": 4,
      "y": 0,
      "z": -1,
      "name": "Soil_Grass",
      "rotation": 1
    },
    {
      "x": 5,
      "y": 0,
      "z": -17,
      "name": "Soil_Grass",
      "rotation": 1
    },
    {
      "x": 5,
      "y": 0,
      "z": -16,
      "name": "Soil_Dirt"
    },
    {
      "x": 5,
      "y": 1,
      "z": -16,
      "name": "Rock_Calcite_Brick_Smooth"
    },
    {
      "x": 5,
      "y": 8,
      "z": -16,
      "name": "*Wood_Hardwood_Stairs_State_Definitions_Corner_Right",
      "rotation": 34
    },
    {
      "x": 5,
      "y": 9,
      "z": -16,
      "name": "*Wood_Hardwood_Stairs_State_Definitions_Corner_Right",
      "rotation": 3
    },
    {
      "x": 5,
      "y": 10,
      "z": -16,
      "name": "Wood_Hardwood_Planks_Half",
      "rotation": 34
    },
    {
      "x": 5,
      "y": 11,
      "z": -16,
      "name": "Wood_Hardwood_Planks"
    },
    {
      "x": 5,
      "y": 12,
      "z": -16,
      "name": "Wood_Hardwood_Stairs",
      "rotation": 2
    },
    {
      "x": 5,
      "y": 20,
      "z": -16,
      "name": "Wood_Hardwood_Planks_Half",
      "rotation": 34
    },
    {
      "x": 5,
      "y": 21,
      "z": -16,
      "name": "Wood_Hardwood_Planks"
    },
    {
      "x": 5,
      "y": 22,
      "z": -16,
      "name": "Wood_Hardwood_Stairs",
      "rotation": 3
    },
    {
      "x": 5,
      "y": 0,
      "z": -15,
      "name": "Soil_Grass",
      "rotation": 1
    },
    {
      "x": 5,
      "y": 1,
      "z": -15,
      "name": "Wood_Oak_Trunk",
      "support": 15
    },
    {
      "x": 5,
      "y": 2,
      "z": -15,
      "name": "Wood_Oak_Trunk",
      "support": 15
    },
    {
      "x": 5,
      "y": 3,
      "z": -15,
      "name": "Wood_Hardwood_Stairs",
      "rotation": 3
    },
    {
      "x": 5,
      "y": 4,
      "z": -15,
      "name": "*Furniture_Kweebec_Trapdoor_State_Definitions_OpenDoorOut",
      "rotation": 3
    },
    {
      "x": 5,
      "y": 7,
      "z": -15,
      "name": "*Furniture_Kweebec_Trapdoor_State_Definitions_OpenDoorOut",
      "rotation": 3
    },
    {
      "x": 5,
      "y": 8,
      "z": -15,
      "name": "Wood_Hardwood_Stairs",
      "rotation": 35
    },
    {
      "x": 5,
      "y": 9,
      "z": -15,
      "name": "Wood_Hardwood_Stairs",
      "rotation": 3
    },
    {
      "x": 5,
      "y": 10,
      "z": -15,
      "name": "Wood_Hardwood_Stairs",
      "rotation": 35
    },
    {
      "x": 5,
      "y": 11,
      "z": -15,
      "name": "Wood_Oak_Trunk",
      "support": 15,
      "rotation": 5
    },
    {
      "x": 5,
      "y": 12,
      "z": -15,
      "name": "Wood_Hardwood_Planks"
    },
    {
      "x": 5,
      "y": 13,
      "z": -15,
      "name": "Wood_Hardwood_Stairs",
      "rotation": 2
    },
    {
      "x": 5,
      "y": 14,
      "z": -15,
      "name": "*Furniture_Kweebec_Trapdoor_State_Definitions_OpenDoorOut",
      "rotation": 3
    },
    {
      "x": 5,
      "y": 17,
      "z": -15,
      "name": "*Furniture_Kweebec_Trapdoor_State_Definitions_OpenDoorOut",
      "rotation": 3
    },
    {
      "x": 5,
      "y": 18,
      "z": -15,
      "name": "Wood_Hardwood_Stairs",
      "rotation": 35
    },
    {
      "x": 5,
      "y": 19,
      "z": -15,
      "name": "Wood_Hardwood_Stairs",
      "rotation": 3
    },
    {
      "x": 5,
      "y": 20,
      "z": -15,
      "name": "Wood_Hardwood_Stairs",
      "rotation": 35
    },
    {
      "x": 5,
      "y": 21,
      "z": -15,
      "name": "Wood_Oak_Trunk",
      "support": 15,
      "rotation": 5
    },
    {
      "x": 5,
      "y": 22,
      "z": -15,
      "name": "Wood_Hardwood_Planks"
    },
    {
      "x": 5,
      "y": 23,
      "z": -15,
      "name": "Wood_Hardwood_Stairs",
      "rotation": 2
    },
    {
      "x": 5,
      "y": 0,
      "z": -14,
      "name": "Soil_Grass",
      "rotation": 1
    },
    {
      "x": 5,
      "y": 1,
      "z": -14,
      "name": "Rock_Calcite_Brick_Smooth"
    },
    {
      "x": 5,
      "y": 8,
      "z": -14,
      "name": "*Wood_Hardwood_Stairs_State_Definitions_Corner_Right",
      "rotation": 35
    },
    {
      "x": 5,
      "y": 9,
      "z": -14,
      "name": "*Wood_Hardwood_Stairs_State_Definitions_Corner_Right"
    },
    {
      "x": 5,
      "y": 10,
      "z": -14,
      "name": "Wood_Hardwood_Stairs",
      "rotation": 35
    },
    {
      "x": 5,
      "y": 11,
      "z": -14,
      "name": "Wood_Hardwood_Planks"
    },
    {
      "x": 5,
      "y": 12,
      "z": -14,
      "name": "Wood_Hardwood_Stairs",
      "rotation": 32
    },
    {
      "x": 5,
      "y": 13,
      "z": -14,
      "name": "Wood_Hardwood_Planks"
    },
    {
      "x": 5,
      "y": 14,
      "z": -14,
      "name": "Wood_Hardwood_Stairs",
      "rotation": 2
    },
    {
      "x": 5,
      "y": 20,
      "z": -14,
      "name": "Wood_Hardwood_Stairs",
      "rotation": 35
    },
    {
      "x": 5,
      "y": 21,
      "z": -14,
      "name": "Wood_Hardwood_Planks"
    },
    {
      "x": 5,
      "y": 22,
      "z": -14,
      "name": "Wood_Hardwood_Stairs",
      "rotation": 32
    },
    {
      "x": 5,
      "y": 23,
      "z": -14,
      "name": "Wood_Hardwood_Planks"
    },
    {
      "x": 5,
      "y": 24,
      "z": -14,
      "name": "Wood_Hardwood_Stairs",
      "rotation": 2
    },
    {
      "x": 5,
      "y": 0,
      "z": -13,
      "name": "Soil_Grass",
      "rotation": 1
    },
    {
      "x": 5,
      "y": 1,
      "z": -13,
      "name": "Rock_Calcite_Brick_Smooth_Half"
    },
    {
      "x": 5,
      "y": 10,
      "z": -13,
      "name": "Wood_Hardwood_Stairs",
      "rotation": 35
    },
    {
      "x": 5,
      "y": 11,
      "z": -13,
      "name": "Wood_Hardwood_Planks"
    },
    {
      "x": 5,
      "y": 13,
      "z": -13,
      "name": "Wood_Hardwood_Stairs",
      "rotation": 32
    },
    {
      "x": 5,
      "y": 14,
      "z": -13,
      "name": "Wood_Hardwood_Planks"
    },
    {
      "x": 5,
      "y": 15,
      "z": -13,
      "name": "Wood_Hardwood_Stairs",
      "rotation": 2
    },
    {
      "x": 5,
      "y": 20,
      "z": -13,
      "name": "Wood_Hardwood_Stairs",
      "rotation": 35
    },
    {
      "x": 5,
      "y": 21,
      "z": -13,
      "name": "Wood_Hardwood_Planks"
    },
    {
      "x": 5,
      "y": 23,
      "z": -13,
      "name": "Wood_Hardwood_Stairs",
      "rotation": 32
    },
    {
      "x": 5,
      "y": 24,
      "z": -13,
      "name": "Wood_Hardwood_Planks"
    },
    {
      "x": 5,
      "y": 25,
      "z": -13,
      "name": "Wood_Hardwood_Stairs",
      "rotation": 2
    },
    {
      "x": 5,
      "y": 0,
      "z": -12,
      "name": "Soil_Grass",
      "rotation": 1
    },
    {
      "x": 5,
      "y": 10,
      "z": -12,
      "name": "Wood_Hardwood_Stairs",
      "rotation": 35
    },
    {
      "x": 5,
      "y": 11,
      "z": -12,
      "name": "Wood_Hardwood_Stairs"
    },
    {
      "x": 5,
      "y": 14,
      "z": -12,
      "name": "Wood_Hardwood_Stairs",
      "rotation": 32
    },
    {
      "x": 5,
      "y": 15,
      "z": -12,
      "name": "Wood_Hardwood_Planks"
    },
    {
      "x": 5,
      "y": 16,
      "z": -12,
      "name": "Wood_Hardwood_Stairs",
      "rotation": 2
    },
    {
      "x": 5,
      "y": 20,
      "z": -12,
      "name": "Wood_Hardwood_Stairs",
      "rotation": 35
    },
    {
      "x": 5,
      "y": 21,
      "z": -12,
      "name": "Wood_Hardwood_Stairs"
    },
    {
      "x": 5,
      "y": 24,
      "z": -12,
      "name": "Wood_Hardwood_Stairs",
      "rotation": 32
    },
    {
      "x": 5,
      "y": 25,
      "z": -12,
      "name": "Wood_Hardwood_Planks"
    },
    {
      "x": 5,
      "y": 26,
      "z": -12,
      "name": "Wood_Hardwood_Stairs",
      "rotation": 2
    },
    {
      "x": 5,
      "y": 0,
      "z": -11,
      "name": "Soil_Grass",
      "rotation": 1
    },
    {
      "x": 5,
      "y": 10,
      "z": -11,
      "name": "Wood_Hardwood_Stairs",
      "rotation": 35
    },
    {
      "x": 5,
      "y": 11,
      "z": -11,
      "name": "Wood_Hardwood_Planks_Half"
    },
    {
      "x": 5,
      "y": 15,
      "z": -11,
      "name": "Wood_Hardwood_Stairs",
      "rotation": 35
    },
    {
      "x": 5,
      "y": 16,
      "z": -11,
      "name": "Wood_Hardwood_Planks"
    },
    {
      "x": 5,
      "y": 17,
      "z": -11,
      "name": "Wood_Hardwood_Planks_Half"
    },
    {
      "x": 5,
      "y": 20,
      "z": -11,
      "name": "Wood_Hardwood_Stairs",
      "rotation": 35
    },
    {
      "x": 5,
      "y": 21,
      "z": -11,
      "name": "Wood_Hardwood_Planks_Half"
    },
    {
      "x": 5,
      "y": 25,
      "z": -11,
      "name": "Wood_Hardwood_Stairs",
      "rotation": 35
    },
    {
      "x": 5,
      "y": 26,
      "z": -11,
      "name": "Wood_Hardwood_Planks"
    },
    {
      "x": 5,
      "y": 27,
      "z": -11,
      "name": "Wood_Hardwood_Planks_Half"
    },
    {
      "x": 5,
      "y": 0,
      "z": -10,
      "name": "Soil_Grass",
      "rotation": 1
    },
    {
      "x": 5,
      "y": 10,
      "z": -10,
      "name": "Wood_Hardwood_Stairs",
      "rotation": 35
    },
    {
      "x": 5,
      "y": 11,
      "z": -10,
      "name": "Wood_Hardwood_Stairs",
      "rotation": 2
    },
    {
      "x": 5,
      "y": 14,
      "z": -10,
      "name": "Wood_Hardwood_Stairs",
      "rotation": 34
    },
    {
      "x": 5,
      "y": 15,
      "z": -10,
      "name": "Wood_Hardwood_Planks"
    },
    {
      "x": 5,
      "y": 16,
      "z": -10,
      "name": "Wood_Hardwood_Stairs"
    },
    {
      "x": 5,
      "y": 20,
      "z": -10,
      "name": "Wood_Hardwood_Stairs",
      "rotation": 35
    },
    {
      "x": 5,
      "y": 21,
      "z": -10,
      "name": "Wood_Hardwood_Stairs",
      "rotation": 2
    },
    {
      "x": 5,
      "y": 24,
      "z": -10,
      "name": "Wood_Hardwood_Stairs",
      "rotation": 34
    },
    {
      "x": 5,
      "y": 25,
      "z": -10,
      "name": "Wood_Hardwood_Planks"
    },
    {
      "x": 5,
      "y": 26,
      "z": -10,
      "name": "Wood_Hardwood_Stairs"
    },
    {
      "x": 5,
      "y": 0,
      "z": -9,
      "name": "Soil_Grass",
      "rotation": 1
    },
    {
      "x": 5,
      "y": 1,
      "z": -9,
      "name": "Rock_Calcite_Brick_Smooth_Half"
    },
    {
      "x": 5,
      "y": 10,
      "z": -9,
      "name": "Wood_Hardwood_Stairs",
      "rotation": 35
    },
    {
      "x": 5,
      "y": 11,
      "z": -9,
      "name": "Wood_Hardwood_Planks"
    },
    {
      "x": 5,
      "y": 13,
      "z": -9,
      "name": "Wood_Hardwood_Stairs",
      "rotation": 34
    },
    {
      "x": 5,
      "y": 14,
      "z": -9,
      "name": "Wood_Hardwood_Planks"
    },
    {
      "x": 5,
      "y": 15,
      "z": -9,
      "name": "Wood_Hardwood_Stairs"
    },
    {
      "x": 5,
      "y": 20,
      "z": -9,
      "name": "Wood_Hardwood_Stairs",
      "rotation": 35
    },
    {
      "x": 5,
      "y": 21,
      "z": -9,
      "name": "Wood_Hardwood_Planks"
    },
    {
      "x": 5,
      "y": 23,
      "z": -9,
      "name": "Wood_Hardwood_Stairs",
      "rotation": 34
    },
    {
      "x": 5,
      "y": 24,
      "z": -9,
      "name": "Wood_Hardwood_Planks"
    },
    {
      "x": 5,
      "y": 25,
      "z": -9,
      "name": "Wood_Hardwood_Stairs"
    },
    {
      "x": 5,
      "y": 0,
      "z": -8,
      "name": "Soil_Dirt"
    },
    {
      "x": 5,
      "y": 1,
      "z": -8,
      "name": "Rock_Calcite_Brick_Smooth"
    },
    {
      "x": 5,
      "y": 8,
      "z": -8,
      "name": "*Wood_Hardwood_Stairs_State_Definitions_Corner_Right",
      "rotation": 34
    },
    {
      "x": 5,
      "y": 9,
      "z": -8,
      "name": "Wood_Hardwood_Stairs",
      "rotation": 3
    },
    {
      "x": 5,
      "y": 10,
      "z": -8,
      "name": "Wood_Hardwood_Stairs",
      "rotation": 35
    },
    {
      "x": 5,
      "y": 11,
      "z": -8,
      "name": "Wood_Hardwood_Planks"
    },
    {
      "x": 5,
      "y": 12,
      "z": -8,
      "name": "Wood_Hardwood_Stairs",
      "rotation": 34
    },
    {
      "x": 5,
      "y": 13,
      "z": -8,
      "name": "Wood_Hardwood_Planks"
    },
    {
      "x": 5,
      "y": 14,
      "z": -8,
      "name": "Wood_Hardwood_Stairs"
    },
    {
      "x": 5,
      "y": 20,
      "z": -8,
      "name": "Wood_Hardwood_Stairs",
      "rotation": 35
    },
    {
      "x": 5,
      "y": 21,
      "z": -8,
      "name": "Wood_Hardwood_Planks"
    },
    {
      "x": 5,
      "y": 22,
      "z": -8,
      "name": "Wood_Hardwood_Stairs",
      "rotation": 34
    },
    {
      "x": 5,
      "y": 23,
      "z": -8,
      "name": "Wood_Hardwood_Planks"
    },
    {
      "x": 5,
      "y": 24,
      "z": -8,
      "name": "Wood_Hardwood_Stairs"
    },
    {
      "x": 5,
      "y": 0,
      "z": -7,
      "name": "Soil_Grass",
      "rotation": 1
    },
    {
      "x": 5,
      "y": 1,
      "z": -7,
      "name": "Rock_Calcite_Brick_Smooth"
    },
    {
      "x": 5,
      "y": 2,
      "z": -7,
      "name": "Wood_Oak_Trunk",
      "support": 15,
      "rotation": 5
    },
    {
      "x": 5,
      "y": 3,
      "z": -7,
      "name": "Wood_Hardwood_Stairs",
      "rotation": 3
    },
    {
      "x": 5,
      "y": 4,
      "z": -7,
      "name": "*Furniture_Kweebec_Trapdoor_State_Definitions_OpenDoorOut",
      "rotation": 3
    },
    {
      "x": 5,
      "y": 7,
      "z": -7,
      "name": "*Furniture_Kweebec_Trapdoor_State_Definitions_OpenDoorOut",
      "rotation": 3
    },
    {
      "x": 5,
      "y": 8,
      "z": -7,
      "name": "Wood_Hardwood_Stairs",
      "rotation": 35
    },
    {
      "x": 5,
      "y": 9,
      "z": -7,
      "name": "Wood_Hardwood_Stairs",
      "rotation": 3
    },
    {
      "x": 5,
      "y": 10,
      "z": -7,
      "name": "Wood_Hardwood_Stairs",
      "rotation": 35
    },
    {
      "x": 5,
      "y": 11,
      "z": -7,
      "name": "Wood_Oak_Trunk",
      "support": 15,
      "rotation": 5
    },
    {
      "x": 5,
      "y": 12,
      "z": -7,
      "name": "Wood_Hardwood_Planks"
    },
    {
      "x": 5,
      "y": 13,
      "z": -7,
      "name": "Wood_Hardwood_Stairs"
    },
    {
      "x": 5,
      "y": 14,
      "z": -7,
      "name": "*Furniture_Kweebec_Trapdoor_State_Definitions_OpenDoorOut",
      "rotation": 3
    },
    {
      "x": 5,
      "y": 17,
      "z": -7,
      "name": "*Furniture_Kweebec_Trapdoor_State_Definitions_OpenDoorOut",
      "rotation": 3
    },
    {
      "x": 5,
      "y": 18,
      "z": -7,
      "name": "Wood_Hardwood_Stairs",
      "rotation": 35
    },
    {
      "x": 5,
      "y": 19,
      "z": -7,
      "name": "Wood_Hardwood_Stairs",
      "rotation": 3
    },
    {
      "x": 5,
      "y": 20,
      "z": -7,
      "name": "Wood_Hardwood_Stairs",
      "rotation": 35
    },
    {
      "x": 5,
      "y": 21,
      "z": -7,
      "name": "Wood_Oak_Trunk",
      "support": 15,
      "rotation": 5
    },
    {
      "x": 5,
      "y": 22,
      "z": -7,
      "name": "Wood_Hardwood_Planks"
    },
    {
      "x": 5,
      "y": 23,
      "z": -7,
      "name": "Wood_Hardwood_Stairs"
    },
    {
      "x": 5,
      "y": 0,
      "z": -6,
      "name": "Soil_Grass",
      "rotation": 1
    },
    {
      "x": 5,
      "y": 1,
      "z": -6,
      "name": "Rock_Calcite_Brick_Smooth"
    },
    {
      "x": 5,
      "y": 8,
      "z": -6,
      "name": "*Wood_Hardwood_Stairs_State_Definitions_Corner_Right",
      "rotation": 35
    },
    {
      "x": 5,
      "y": 9,
      "z": -6,
      "name": "*Wood_Hardwood_Stairs_State_Definitions_Corner_Left",
      "rotation": 3
    },
    {
      "x": 5,
      "y": 10,
      "z": -6,
      "name": "Wood_Hardwood_Planks_Half",
      "rotation": 34
    },
    {
      "x": 5,
      "y": 11,
      "z": -6,
      "name": "Wood_Hardwood_Planks"
    },
    {
      "x": 5,
      "y": 12,
      "z": -6,
      "name": "Wood_Hardwood_Stairs"
    },
    {
      "x": 5,
      "y": 20,
      "z": -6,
      "name": "Wood_Hardwood_Planks_Half",
      "rotation": 34
    },
    {
      "x": 5,
      "y": 21,
      "z": -6,
      "name": "Wood_Hardwood_Planks"
    },
    {
      "x": 5,
      "y": 22,
      "z": -6,
      "name": "Wood_Hardwood_Stairs",
      "rotation": 3
    },
    {
      "x": 5,
      "y": 0,
      "z": -5,
      "name": "Soil_Grass",
      "rotation": 1
    },
    {
      "x": 5,
      "y": 0,
      "z": -4,
      "name": "Soil_Grass",
      "rotation": 1
    },
    {
      "x": 5,
      "y": 0,
      "z": -3,
      "name": "Soil_Grass",
      "rotation": 1
    },
    {
      "x": 5,
      "y": 11,
      "z": -3,
      "name": "Cloth_Block_Wool_White"
    },
    {
      "x": 5,
      "y": 12,
      "z": -3,
      "name": "Cloth_Block_Wool_White"
    },
    {
      "x": 5,
      "y": 13,
      "z": -3,
      "name": "Cloth_Block_Wool_White"
    },
    {
      "x": 5,
      "y": 14,
      "z": -3,
      "name": "Wood_Lightwood_Fence"
    },
    {
      "x": 5,
      "y": 15,
      "z": -3,
      "name": "Wood_Hardwood_Planks"
    },
    {
      "x": 5,
      "y": 16,
      "z": -3,
      "name": "Wood_Hardwood_Stairs",
      "rotation": 3
    },
    {
      "x": 5,
      "y": 21,
      "z": -3,
      "name": "Cloth_Block_Wool_White"
    },
    {
      "x": 5,
      "y": 22,
      "z": -3,
      "name": "Cloth_Block_Wool_White"
    },
    {
      "x": 5,
      "y": 0,
      "z": -2,
      "name": "Soil_Grass",
      "rotation": 1
    },
    {
      "x": 5,
      "y": 12,
      "z": -2,
      "name": "Cloth_Block_Wool_White"
    },
    {
      "x": 5,
      "y": 0,
      "z": -1,
      "name": "Soil_Grass",
      "rotation": 1
    },
    {
      "x": 6,
      "y": 0,
      "z": -17,
      "name": "Soil_Grass",
      "rotation": 1
    },
    {
      "x": 6,
      "y": 1,
      "z": -17,
      "name": "Rock_Calcite_Brick_Stairs",
      "rotation": 2
    },
    {
      "x": 6,
      "y": 2,
      "z": -17,
      "name": "Rock_Calcite_Brick_Stairs",
      "rotation": 34
    },
    {
      "x": 6,
      "y": 11,
      "z": -17,
      "name": "Wood_Oak_Trunk",
      "support": 15,
      "rotation": 4
    },
    {
      "x": 6,
      "y": 21,
      "z": -17,
      "name": "Wood_Oak_Trunk",
      "support": 15,
      "rotation": 4
    },
    {
      "x": 6,
      "y": 0,
      "z": -16,
      "name": "Soil_Dirt"
    },
    {
      "x": 6,
      "y": 1,
      "z": -16,
      "name": "Rock_Calcite_Brick_Smooth"
    },
    {
      "x": 6,
      "y": 2,
      "z": -16,
      "name": "Wood_Oak_Trunk",
      "support": 15
    },
    {
      "x": 6,
      "y": 3,
      "z": -16,
      "name": "Wood_Hardwood_Stairs",
      "rotation": 2
    },
    {
      "x": 6,
      "y": 4,
      "z": -16,
      "name": "*Furniture_Kweebec_Trapdoor_State_Definitions_OpenDoorOut",
      "rotation": 2
    },
    {
      "x": 6,
      "y": 7,
      "z": -16,
      "name": "*Furniture_Kweebec_Trapdoor_State_Definitions_OpenDoorOut",
      "rotation": 2
    },
    {
      "x": 6,
      "y": 8,
      "z": -16,
      "name": "Wood_Hardwood_Stairs",
      "rotation": 34
    },
    {
      "x": 6,
      "y": 9,
      "z": -16,
      "name": "Wood_Hardwood_Stairs",
      "rotation": 2
    },
    {
      "x": 6,
      "y": 10,
      "z": -16,
      "name": "Wood_Hardwood_Stairs",
      "rotation": 34
    },
    {
      "x": 6,
      "y": 11,
      "z": -16,
      "name": "Wood_Oak_Trunk",
      "support": 15,
      "rotation": 4
    },
    {
      "x": 6,
      "y": 12,
      "z": -16,
      "name": "Wood_Hardwood_Planks"
    },
    {
      "x": 6,
      "y": 13,
      "z": -16,
      "name": "Wood_Hardwood_Stairs",
      "rotation": 2
    },
    {
      "x": 6,
      "y": 14,
      "z": -16,
      "name": "*Furniture_Kweebec_Trapdoor_State_Definitions_OpenDoorOut",
      "rotation": 2
    },
    {
      "x": 6,
      "y": 17,
      "z": -16,
      "name": "*Furniture_Kweebec_Trapdoor_State_Definitions_OpenDoorOut",
      "rotation": 2
    },
    {
      "x": 6,
      "y": 18,
      "z": -16,
      "name": "Wood_Hardwood_Stairs",
      "rotation": 34
    },
    {
      "x": 6,
      "y": 19,
      "z": -16,
      "name": "Wood_Hardwood_Stairs",
      "rotation": 2
    },
    {
      "x": 6,
      "y": 20,
      "z": -16,
      "name": "Wood_Hardwood_Stairs",
      "rotation": 34
    },
    {
      "x": 6,
      "y": 21,
      "z": -16,
      "name": "Wood_Oak_Trunk",
      "support": 15,
      "rotation": 4
    },
    {
      "x": 6,
      "y": 22,
      "z": -16,
      "name": "Wood_Hardwood_Planks"
    },
    {
      "x": 6,
      "y": 23,
      "z": -16,
      "name": "Wood_Hardwood_Stairs",
      "rotation": 3
    },
    {
      "x": 6,
      "y": 0,
      "z": -15,
      "name": "Soil_Dirt"
    },
    {
      "x": 6,
      "y": 1,
      "z": -15,
      "name": "Rock_Calcite_Brick_Smooth"
    },
    {
      "x": 6,
      "y": 2,
      "z": -15,
      "name": "Wood_Oak_Trunk",
      "support": 15,
      "rotation": 2
    },
    {
      "x": 6,
      "y": 3,
      "z": -15,
      "name": "Wood_Oak_Trunk",
      "support": 15,
      "rotation": 2
    },
    {
      "x": 6,
      "y": 4,
      "z": -15,
      "name": "Wood_Oak_Trunk",
      "support": 15,
      "rotation": 2
    },
    {
      "x": 6,
      "y": 5,
      "z": -15,
      "name": "Wood_Oak_Trunk",
      "support": 15,
      "rotation": 2
    },
    {
      "x": 6,
      "y": 6,
      "z": -15,
      "name": "Wood_Oak_Trunk",
      "support": 15,
      "rotation": 2
    },
    {
      "x": 6,
      "y": 7,
      "z": -15,
      "name": "Wood_Oak_Trunk",
      "support": 15,
      "rotation": 2
    },
    {
      "x": 6,
      "y": 8,
      "z": -15,
      "name": "Wood_Oak_Trunk",
      "support": 15,
      "rotation": 2
    },
    {
      "x": 6,
      "y": 9,
      "z": -15,
      "name": "Wood_Oak_Trunk",
      "support": 15,
      "rotation": 2
    },
    {
      "x": 6,
      "y": 10,
      "z": -15,
      "name": "*Wood_Village_Wall_White_Full_State_Definitions_Bottom"
    },
    {
      "x": 6,
      "y": 11,
      "z": -15,
      "name": "*Wood_Village_Wall_White_Full_State_Definitions_Top"
    },
    {
      "x": 6,
      "y": 12,
      "z": -15,
      "name": "Wood_Oak_Trunk",
      "support": 15,
      "rotation": 5
    },
    {
      "x": 6,
      "y": 13,
      "z": -15,
      "name": "Wood_Oak_Trunk",
      "support": 15
    },
    {
      "x": 6,
      "y": 14,
      "z": -15,
      "name": "Wood_Oak_Trunk",
      "support": 15,
      "rotation": 2
    },
    {
      "x": 6,
      "y": 15,
      "z": -15,
      "name": "Wood_Oak_Trunk",
      "support": 15,
      "rotation": 2
    },
    {
      "x": 6,
      "y": 16,
      "z": -15,
      "name": "Wood_Oak_Trunk",
      "support": 15,
      "rotation": 2
    },
    {
      "x": 6,
      "y": 17,
      "z": -15,
      "name": "Wood_Oak_Trunk",
      "support": 15,
      "rotation": 2
    },
    {
      "x": 6,
      "y": 18,
      "z": -15,
      "name": "Wood_Oak_Trunk",
      "support": 15,
      "rotation": 2
    },
    {
      "x": 6,
      "y": 19,
      "z": -15,
      "name": "Wood_Oak_Trunk",
      "support": 15,
      "rotation": 2
    },
    {
      "x": 6,
      "y": 20,
      "z": -15,
      "name": "*Wood_Village_Wall_White_Full_State_Definitions_Bottom"
    },
    {
      "x": 6,
      "y": 21,
      "z": -15,
      "name": "*Wood_Village_Wall_White_Full_State_Definitions_Top"
    },
    {
      "x": 6,
      "y": 22,
      "z": -15,
      "name": "Soil_Clay_Smooth_Red"
    },
    {
      "x": 6,
      "y": 23,
      "z": -15,
      "name": "Rock_Chalk_Cobble_Roof_Flat",
      "rotation": 1
    },
    {
      "x": 6,
      "y": 0,
      "z": -14,
      "name": "Soil_Grass",
      "rotation": 1
    },
    {
      "x": 6,
      "y": 1,
      "z": -14,
      "name": "Rock_Calcite_Brick_Smooth"
    },
    {
      "x": 6,
      "y": 2,
      "z": -14,
      "name": "Wood_Oak_Trunk",
      "support": 15,
      "rotation": 4
    },
    {
      "x": 6,
      "y": 3,
      "z": -14,
      "name": "Wood_Hardwood_Stairs"
    },
    {
      "x": 6,
      "y": 4,
      "z": -14,
      "name": "*Furniture_Kweebec_Trapdoor_State_Definitions_OpenDoorOut"
    },
    {
      "x": 6,
      "y": 7,
      "z": -14,
      "name": "*Furniture_Kweebec_Trapdoor_State_Definitions_OpenDoorOut"
    },
    {
      "x": 6,
      "y": 8,
      "z": -14,
      "name": "Wood_Hardwood_Stairs",
      "rotation": 32
    },
    {
      "x": 6,
      "y": 9,
      "z": -14,
      "name": "Wood_Oak_Trunk",
      "support": 15,
      "rotation": 4
    },
    {
      "x": 6,
      "y": 10,
      "z": -14,
      "name": "*Wood_Village_Wall_White_Full_State_Definitions_Bottom"
    },
    {
      "x": 6,
      "y": 11,
      "z": -14,
      "name": "*Wood_Village_Wall_White_Full_State_Definitions_Middle"
    },
    {
      "x": 6,
      "y": 12,
      "z": -14,
      "name": "*Wood_Village_Wall_White_Full_State_Definitions_Top"
    },
    {
      "x": 6,
      "y": 13,
      "z": -14,
      "name": "Soil_Clay_Smooth_Red"
    },
    {
      "x": 6,
      "y": 14,
      "z": -14,
      "name": "Rock_Chalk_Cobble_Roof",
      "rotation": 2
    },
    {
      "x": 6,
      "y": 17,
      "z": -14,
      "name": "*Furniture_Kweebec_Trapdoor_State_Definitions_OpenDoorOut"
    },
    {
      "x": 6,
      "y": 18,
      "z": -14,
      "name": "Wood_Hardwood_Stairs",
      "rotation": 32
    },
    {
      "x": 6,
      "y": 19,
      "z": -14,
      "name": "Wood_Oak_Trunk",
      "support": 15,
      "rotation": 4
    },
    {
      "x": 6,
      "y": 20,
      "z": -14,
      "name": "*Wood_Village_Wall_White_Full_State_Definitions_Bottom"
    },
    {
      "x": 6,
      "y": 21,
      "z": -14,
      "name": "*Wood_Village_Wall_White_Full_State_Definitions_Middle"
    },
    {
      "x": 6,
      "y": 22,
      "z": -14,
      "name": "*Wood_Village_Wall_White_Full_State_Definitions_Top"
    },
    {
      "x": 6,
      "y": 23,
      "z": -14,
      "name": "Rock_Chalk_Cobble_Roof",
      "rotation": 2
    },
    {
      "x": 6,
      "y": 0,
      "z": -13,
      "name": "Soil_Grass",
      "rotation": 1
    },
    {
      "x": 6,
      "y": 1,
      "z": -13,
      "name": "Rock_Calcite_Brick_Stairs",
      "rotation": 3
    },
    {
      "x": 6,
      "y": 2,
      "z": -13,
      "name": "Rock_Calcite_Brick_Smooth_Half"
    },
    {
      "x": 6,
      "y": 5,
      "z": -13,
      "name": "Wood_Hardwood_Beam"
    },
    {
      "x": 6,
      "y": 6,
      "z": -13,
      "name": "Wood_Hardwood_Beam"
    },
    {
      "x": 6,
      "y": 7,
      "z": -13,
      "name": "Wood_Hardwood_Beam"
    },
    {
      "x": 6,
      "y": 8,
      "z": -13,
      "name": "Wood_Hardwood_Beam"
    },
    {
      "x": 6,
      "y": 9,
      "z": -13,
      "name": "Wood_Oak_Trunk",
      "support": 15,
      "rotation": 4
    },
    {
      "x": 6,
      "y": 10,
      "z": -13,
      "name": "*Wood_Village_Wall_White_Full_State_Definitions_Bottom"
    },
    {
      "x": 6,
      "y": 11,
      "z": -13,
      "name": "*Wood_Village_Wall_White_Full_State_Definitions_Middle"
    },
    {
      "x": 6,
      "y": 12,
      "z": -13,
      "name": "*Wood_Village_Wall_White_Full_State_Definitions_Middle"
    },
    {
      "x": 6,
      "y": 13,
      "z": -13,
      "name": "*Wood_Village_Wall_White_Full_State_Definitions_Top"
    },
    {
      "x": 6,
      "y": 14,
      "z": -13,
      "name": "Soil_Clay_Smooth_Red"
    },
    {
      "x": 6,
      "y": 15,
      "z": -13,
      "name": "Rock_Chalk_Cobble_Roof",
      "rotation": 2
    },
    {
      "x": 6,
      "y": 19,
      "z": -13,
      "name": "Wood_Oak_Trunk",
      "support": 15,
      "rotation": 4
    },
    {
      "x": 6,
      "y": 20,
      "z": -13,
      "name": "*Wood_Village_Wall_White_Full_State_Definitions_Bottom"
    },
    {
      "x": 6,
      "y": 21,
      "z": -13,
      "name": "*Wood_Village_Wall_White_Full_State_Definitions_Middle"
    },
    {
      "x": 6,
      "y": 22,
      "z": -13,
      "name": "*Wood_Village_Wall_White_Full_State_Definitions_Middle"
    },
    {
      "x": 6,
      "y": 23,
      "z": -13,
      "name": "Wood_Village_Wall_White_Full"
    },
    {
      "x": 6,
      "y": 24,
      "z": -13,
      "name": "Rock_Chalk_Cobble_Roof",
      "rotation": 2
    },
    {
      "x": 6,
      "y": 0,
      "z": -12,
      "name": "Soil_Grass",
      "rotation": 1
    },
    {
      "x": 6,
      "y": 1,
      "z": -12,
      "name": "Rock_Calcite_Brick_Stairs",
      "rotation": 3
    },
    {
      "x": 6,
      "y": 2,
      "z": -12,
      "name": "Rock_Calcite_Brick_Smooth_Half"
    },
    {
      "x": 6,
      "y": 9,
      "z": -12,
      "name": "Wood_Oak_Trunk",
      "support": 15,
      "rotation": 4
    },
    {
      "x": 6,
      "y": 10,
      "z": -12,
      "name": "*Wood_Village_Wall_White_Full_State_Definitions_Bottom"
    },
    {
      "x": 6,
      "y": 11,
      "z": -12,
      "name": "*Wood_Village_Wall_White_Full_State_Definitions_Top"
    },
    {
      "x": 6,
      "y": 12,
      "z": -12,
      "name": "Wood_Hardwood_Beam"
    },
    {
      "x": 6,
      "y": 13,
      "z": -12,
      "name": "Wood_Hardwood_Beam"
    },
    {
      "x": 6,
      "y": 14,
      "z": -12,
      "name": "Wood_Village_Wall_White_Full"
    },
    {
      "x": 6,
      "y": 15,
      "z": -12,
      "name": "Soil_Clay_Smooth_Red"
    },
    {
      "x": 6,
      "y": 16,
      "z": -12,
      "name": "Rock_Chalk_Cobble_Roof",
      "rotation": 2
    },
    {
      "x": 6,
      "y": 19,
      "z": -12,
      "name": "Wood_Oak_Trunk",
      "support": 15,
      "rotation": 4
    },
    {
      "x": 6,
      "y": 20,
      "z": -12,
      "name": "*Wood_Village_Wall_White_Full_State_Definitions_Bottom"
    },
    {
      "x": 6,
      "y": 21,
      "z": -12,
      "name": "*Wood_Village_Wall_White_Full_State_Definitions_Middle"
    },
    {
      "x": 6,
      "y": 22,
      "z": -12,
      "name": "*Wood_Village_Wall_White_Full_State_Definitions_Middle"
    },
    {
      "x": 6,
      "y": 23,
      "z": -12,
      "name": "Wood_Village_Wall_White_Full"
    },
    {
      "x": 6,
      "y": 24,
      "z": -12,
      "name": "Wood_Village_Wall_White_Full"
    },
    {
      "x": 6,
      "y": 25,
      "z": -12,
      "name": "Rock_Chalk_Cobble_Roof_Steep",
      "rotation": 2
    },
    {
      "x": 6,
      "y": 26,
      "z": -12,
      "name": "Rock_Chalk_Cobble_Roof_Steep",
      "filler": 1024,
      "rotation": 2
    },
    {
      "x": 6,
      "y": 0,
      "z": -11,
      "name": "Soil_Grass",
      "rotation": 1
    },
    {
      "x": 6,
      "y": 1,
      "z": -11,
      "name": "Rock_Calcite_Brick_Stairs",
      "rotation": 3
    },
    {
      "x": 6,
      "y": 2,
      "z": -11,
      "name": "Rock_Calcite_Brick_Smooth_Half"
    },
    {
      "x": 6,
      "y": 7,
      "z": -11,
      "name": "Wood_Hardwood_Beam"
    },
    {
      "x": 6,
      "y": 8,
      "z": -11,
      "name": "Wood_Hardwood_Beam"
    },
    {
      "x": 6,
      "y": 9,
      "z": -11,
      "name": "Wood_Oak_Trunk",
      "support": 15,
      "rotation": 4
    },
    {
      "x": 6,
      "y": 10,
      "z": -11,
      "name": "Wood_Village_Wall_White_Full"
    },
    {
      "x": 6,
      "y": 11,
      "z": -11,
      "name": "Wood_Hardwood_Beam"
    },
    {
      "x": 6,
      "y": 12,
      "z": -11,
      "name": "Wood_Hardwood_Beam"
    },
    {
      "x": 6,
      "y": 13,
      "z": -11,
      "name": "Wood_Hardwood_Beam"
    },
    {
      "x": 6,
      "y": 14,
      "z": -11,
      "name": "Wood_Hardwood_Beam"
    },
    {
      "x": 6,
      "y": 15,
      "z": -11,
      "name": "Wood_Village_Wall_White_Full"
    },
    {
      "x": 6,
      "y": 16,
      "z": -11,
      "name": "Soil_Clay_Smooth_Red"
    },
    {
      "x": 6,
      "y": 17,
      "z": -11,
      "name": "Rock_Chalk_Cobble_Roof_Flat",
      "rotation": 3
    },
    {
      "x": 6,
      "y": 19,
      "z": -11,
      "name": "Wood_Oak_Trunk",
      "support": 15,
      "rotation": 4
    },
    {
      "x": 6,
      "y": 20,
      "z": -11,
      "name": "*Wood_Village_Wall_White_Full_State_Definitions_Bottom"
    },
    {
      "x": 6,
      "y": 21,
      "z": -11,
      "name": "*Wood_Village_Wall_White_Full_State_Definitions_Top"
    },
    {
      "x": 6,
      "y": 22,
      "z": -11,
      "name": "*Furniture_Kweebec_Trapdoor_State_Definitions_OpenDoorOut",
      "rotation": 3
    },
    {
      "x": 6,
      "y": 23,
      "z": -11,
      "name": "*Furniture_Kweebec_Trapdoor_State_Definitions_OpenDoorOut",
      "rotation": 3
    },
    {
      "x": 6,
      "y": 24,
      "z": -11,
      "name": "Wood_Village_Wall_White_Full"
    },
    {
      "x": 6,
      "y": 25,
      "z": -11,
      "name": "Wood_Village_Wall_White_Full"
    },
    {
      "x": 6,
      "y": 27,
      "z": -11,
      "name": "Rock_Chalk_Cobble_Roof_Flat",
      "rotation": 3
    },
    {
      "x": 6,
      "y": 0,
      "z": -10,
      "name": "Soil_Grass",
      "rotation": 1
    },
    {
      "x": 6,
      "y": 1,
      "z": -10,
      "name": "Rock_Calcite_Brick_Stairs",
      "rotation": 3
    },
    {
      "x": 6,
      "y": 2,
      "z": -10,
      "name": "Rock_Calcite_Brick_Smooth_Half"
    },
    {
      "x": 6,
      "y": 9,
      "z": -10,
      "name": "Wood_Oak_Trunk",
      "support": 15,
      "rotation": 4
    },
    {
      "x": 6,
      "y": 10,
      "z": -10,
      "name": "*Wood_Village_Wall_White_Full_State_Definitions_Bottom"
    },
    {
      "x": 6,
      "y": 11,
      "z": -10,
      "name": "*Wood_Village_Wall_White_Full_State_Definitions_Top"
    },
    {
      "x": 6,
      "y": 12,
      "z": -10,
      "name": "Wood_Hardwood_Beam"
    },
    {
      "x": 6,
      "y": 13,
      "z": -10,
      "name": "Wood_Hardwood_Beam"
    },
    {
      "x": 6,
      "y": 14,
      "z": -10,
      "name": "Wood_Village_Wall_White_Full"
    },
    {
      "x": 6,
      "y": 15,
      "z": -10,
      "name": "Soil_Clay_Smooth_Red"
    },
    {
      "x": 6,
      "y": 16,
      "z": -10,
      "name": "Rock_Chalk_Cobble_Roof"
    },
    {
      "x": 6,
      "y": 19,
      "z": -10,
      "name": "Wood_Oak_Trunk",
      "support": 15,
      "rotation": 4
    },
    {
      "x": 6,
      "y": 20,
      "z": -10,
      "name": "Wood_Village_Wall_White_Full"
    },
    {
      "x": 6,
      "y": 21,
      "z": -10,
      "name": "Wood_Village_Wall_White_Full"
    },
    {
      "x": 6,
      "y": 22,
      "z": -10,
      "name": "Wood_Village_Wall_White_Full"
    },
    {
      "x": 6,
      "y": 23,
      "z": -10,
      "name": "Wood_Village_Wall_White_Full"
    },
    {
      "x": 6,
      "y": 24,
      "z": -10,
      "name": "Wood_Village_Wall_White_Full"
    },
    {
      "x": 6,
      "y": 25,
      "z": -10,
      "name": "Rock_Chalk_Cobble_Roof_Steep"
    },
    {
      "x": 6,
      "y": 26,
      "z": -10,
      "name": "Rock_Chalk_Cobble_Roof_Steep",
      "filler": 1024
    },
    {
      "x": 6,
      "y": 0,
      "z": -9,
      "name": "Soil_Grass",
      "rotation": 1
    },
    {
      "x": 6,
      "y": 1,
      "z": -9,
      "name": "Rock_Calcite_Brick_Stairs",
      "rotation": 3
    },
    {
      "x": 6,
      "y": 2,
      "z": -9,
      "name": "Rock_Calcite_Brick_Smooth_Half"
    },
    {
      "x": 6,
      "y": 5,
      "z": -9,
      "name": "Wood_Hardwood_Beam"
    },
    {
      "x": 6,
      "y": 6,
      "z": -9,
      "name": "Wood_Hardwood_Beam"
    },
    {
      "x": 6,
      "y": 7,
      "z": -9,
      "name": "Wood_Hardwood_Beam"
    },
    {
      "x": 6,
      "y": 8,
      "z": -9,
      "name": "Wood_Hardwood_Beam"
    },
    {
      "x": 6,
      "y": 9,
      "z": -9,
      "name": "Wood_Oak_Trunk",
      "support": 15,
      "rotation": 4
    },
    {
      "x": 6,
      "y": 10,
      "z": -9,
      "name": "*Wood_Village_Wall_White_Full_State_Definitions_Bottom"
    },
    {
      "x": 6,
      "y": 11,
      "z": -9,
      "name": "*Wood_Village_Wall_White_Full_State_Definitions_Middle"
    },
    {
      "x": 6,
      "y": 12,
      "z": -9,
      "name": "*Wood_Village_Wall_White_Full_State_Definitions_Middle"
    },
    {
      "x": 6,
      "y": 13,
      "z": -9,
      "name": "*Wood_Village_Wall_White_Full_State_Definitions_Top"
    },
    {
      "x": 6,
      "y": 14,
      "z": -9,
      "name": "Soil_Clay_Smooth_Red"
    },
    {
      "x": 6,
      "y": 15,
      "z": -9,
      "name": "Rock_Chalk_Cobble_Roof"
    },
    {
      "x": 6,
      "y": 19,
      "z": -9,
      "name": "Wood_Oak_Trunk",
      "support": 15,
      "rotation": 4
    },
    {
      "x": 6,
      "y": 20,
      "z": -9,
      "name": "*Wood_Village_Wall_White_Full_State_Definitions_Bottom"
    },
    {
      "x": 6,
      "y": 21,
      "z": -9,
      "name": "*Wood_Village_Wall_White_Full_State_Definitions_Middle"
    },
    {
      "x": 6,
      "y": 22,
      "z": -9,
      "name": "*Wood_Village_Wall_White_Full_State_Definitions_Middle"
    },
    {
      "x": 6,
      "y": 23,
      "z": -9,
      "name": "Wood_Village_Wall_White_Full"
    },
    {
      "x": 6,
      "y": 24,
      "z": -9,
      "name": "Rock_Chalk_Cobble_Roof"
    },
    {
      "x": 6,
      "y": 0,
      "z": -8,
      "name": "Soil_Dirt"
    },
    {
      "x": 6,
      "y": 1,
      "z": -8,
      "name": "Rock_Calcite_Brick_Smooth"
    },
    {
      "x": 6,
      "y": 2,
      "z": -8,
      "name": "Wood_Oak_Trunk",
      "support": 15,
      "rotation": 4
    },
    {
      "x": 6,
      "y": 3,
      "z": -8,
      "name": "Wood_Hardwood_Stairs",
      "rotation": 2
    },
    {
      "x": 6,
      "y": 4,
      "z": -8,
      "name": "*Furniture_Kweebec_Trapdoor_State_Definitions_OpenDoorOut",
      "rotation": 2
    },
    {
      "x": 6,
      "y": 7,
      "z": -8,
      "name": "*Furniture_Kweebec_Trapdoor_State_Definitions_OpenDoorOut",
      "rotation": 2
    },
    {
      "x": 6,
      "y": 8,
      "z": -8,
      "name": "Wood_Hardwood_Stairs",
      "rotation": 34
    },
    {
      "x": 6,
      "y": 9,
      "z": -8,
      "name": "Wood_Oak_Trunk",
      "support": 15,
      "rotation": 4
    },
    {
      "x": 6,
      "y": 10,
      "z": -8,
      "name": "*Wood_Village_Wall_White_Full_State_Definitions_Bottom"
    },
    {
      "x": 6,
      "y": 11,
      "z": -8,
      "name": "*Wood_Village_Wall_White_Full_State_Definitions_Middle"
    },
    {
      "x": 6,
      "y": 12,
      "z": -8,
      "name": "*Wood_Village_Wall_White_Full_State_Definitions_Top"
    },
    {
      "x": 6,
      "y": 13,
      "z": -8,
      "name": "Soil_Clay_Smooth_Red"
    },
    {
      "x": 6,
      "y": 14,
      "z": -8,
      "name": "Rock_Chalk_Cobble_Roof"
    },
    {
      "x": 6,
      "y": 17,
      "z": -8,
      "name": "*Furniture_Kweebec_Trapdoor_State_Definitions_OpenDoorOut",
      "rotation": 2
    },
    {
      "x": 6,
      "y": 18,
      "z": -8,
      "name": "Wood_Hardwood_Stairs",
      "rotation": 34
    },
    {
      "x": 6,
      "y": 19,
      "z": -8,
      "name": "Wood_Oak_Trunk",
      "support": 15,
      "rotation": 4
    },
    {
      "x": 6,
      "y": 20,
      "z": -8,
      "name": "*Wood_Village_Wall_White_Full_State_Definitions_Bottom"
    },
    {
      "x": 6,
      "y": 21,
      "z": -8,
      "name": "*Wood_Village_Wall_White_Full_State_Definitions_Middle"
    },
    {
      "x": 6,
      "y": 22,
      "z": -8,
      "name": "*Wood_Village_Wall_White_Full_State_Definitions_Top"
    },
    {
      "x": 6,
      "y": 23,
      "z": -8,
      "name": "Rock_Chalk_Cobble_Roof"
    },
    {
      "x": 6,
      "y": 0,
      "z": -7,
      "name": "Soil_Grass",
      "rotation": 1
    },
    {
      "x": 6,
      "y": 2,
      "z": -7,
      "name": "Wood_Oak_Trunk",
      "support": 15,
      "rotation": 2
    },
    {
      "x": 6,
      "y": 3,
      "z": -7,
      "name": "Wood_Oak_Trunk",
      "support": 15,
      "rotation": 2
    },
    {
      "x": 6,
      "y": 4,
      "z": -7,
      "name": "Wood_Oak_Trunk",
      "support": 15,
      "rotation": 2
    },
    {
      "x": 6,
      "y": 5,
      "z": -7,
      "name": "Wood_Oak_Trunk",
      "support": 15,
      "rotation": 2
    },
    {
      "x": 6,
      "y": 6,
      "z": -7,
      "name": "Wood_Oak_Trunk",
      "support": 15,
      "rotation": 2
    },
    {
      "x": 6,
      "y": 7,
      "z": -7,
      "name": "Wood_Oak_Trunk",
      "support": 15,
      "rotation": 2
    },
    {
      "x": 6,
      "y": 8,
      "z": -7,
      "name": "Wood_Oak_Trunk",
      "support": 15,
      "rotation": 2
    },
    {
      "x": 6,
      "y": 9,
      "z": -7,
      "name": "Wood_Oak_Trunk",
      "support": 15,
      "rotation": 2
    },
    {
      "x": 6,
      "y": 10,
      "z": -7,
      "name": "*Wood_Village_Wall_White_Full_State_Definitions_Bottom"
    },
    {
      "x": 6,
      "y": 11,
      "z": -7,
      "name": "*Wood_Village_Wall_White_Full_State_Definitions_Top"
    },
    {
      "x": 6,
      "y": 12,
      "z": -7,
      "name": "Soil_Clay_Smooth_Red"
    },
    {
      "x": 6,
      "y": 13,
      "z": -7,
      "name": "Wood_Oak_Trunk",
      "support": 15,
      "rotation": 2
    },
    {
      "x": 6,
      "y": 14,
      "z": -7,
      "name": "Wood_Oak_Trunk",
      "support": 15,
      "rotation": 2
    },
    {
      "x": 6,
      "y": 15,
      "z": -7,
      "name": "Wood_Oak_Trunk",
      "support": 15,
      "rotation": 2
    },
    {
      "x": 6,
      "y": 16,
      "z": -7,
      "name": "Wood_Oak_Trunk",
      "support": 15,
      "rotation": 2
    },
    {
      "x": 6,
      "y": 17,
      "z": -7,
      "name": "Wood_Oak_Trunk",
      "support": 15,
      "rotation": 2
    },
    {
      "x": 6,
      "y": 18,
      "z": -7,
      "name": "Wood_Oak_Trunk",
      "support": 15,
      "rotation": 2
    },
    {
      "x": 6,
      "y": 19,
      "z": -7,
      "name": "Wood_Oak_Trunk",
      "support": 15,
      "rotation": 2
    },
    {
      "x": 6,
      "y": 20,
      "z": -7,
      "name": "*Wood_Village_Wall_White_Full_State_Definitions_Bottom"
    },
    {
      "x": 6,
      "y": 21,
      "z": -7,
      "name": "*Wood_Village_Wall_White_Full_State_Definitions_Top"
    },
    {
      "x": 6,
      "y": 22,
      "z": -7,
      "name": "Soil_Clay_Smooth_Red"
    },
    {
      "x": 6,
      "y": 23,
      "z": -7,
      "name": "Rock_Chalk_Cobble_Roof_Flat"
    },
    {
      "x": 6,
      "y": 0,
      "z": -6,
      "name": "Soil_Grass",
      "rotation": 1
    },
    {
      "x": 6,
      "y": 1,
      "z": -6,
      "name": "Rock_Calcite_Brick_Smooth"
    },
    {
      "x": 6,
      "y": 2,
      "z": -6,
      "name": "Wood_Oak_Trunk",
      "support": 15,
      "rotation": 4
    },
    {
      "x": 6,
      "y": 3,
      "z": -6,
      "name": "Wood_Hardwood_Stairs"
    },
    {
      "x": 6,
      "y": 4,
      "z": -6,
      "name": "*Furniture_Kweebec_Trapdoor_State_Definitions_OpenDoorOut"
    },
    {
      "x": 6,
      "y": 7,
      "z": -6,
      "name": "*Furniture_Kweebec_Trapdoor_State_Definitions_OpenDoorOut"
    },
    {
      "x": 6,
      "y": 8,
      "z": -6,
      "name": "Wood_Hardwood_Stairs",
      "rotation": 32
    },
    {
      "x": 6,
      "y": 9,
      "z": -6,
      "name": "Wood_Hardwood_Stairs"
    },
    {
      "x": 6,
      "y": 10,
      "z": -6,
      "name": "Wood_Hardwood_Stairs",
      "rotation": 32
    },
    {
      "x": 6,
      "y": 11,
      "z": -6,
      "name": "Wood_Oak_Trunk",
      "support": 15,
      "rotation": 4
    },
    {
      "x": 6,
      "y": 12,
      "z": -6,
      "name": "Wood_Hardwood_Planks"
    },
    {
      "x": 6,
      "y": 13,
      "z": -6,
      "name": "Wood_Hardwood_Stairs"
    },
    {
      "x": 6,
      "y": 14,
      "z": -6,
      "name": "*Furniture_Kweebec_Trapdoor_State_Definitions_OpenDoorOut"
    },
    {
      "x": 6,
      "y": 17,
      "z": -6,
      "name": "*Furniture_Kweebec_Trapdoor_State_Definitions_OpenDoorOut"
    },
    {
      "x": 6,
      "y": 18,
      "z": -6,
      "name": "Wood_Hardwood_Stairs",
      "rotation": 32
    },
    {
      "x": 6,
      "y": 19,
      "z": -6,
      "name": "Wood_Hardwood_Stairs"
    },
    {
      "x": 6,
      "y": 20,
      "z": -6,
      "name": "Wood_Hardwood_Stairs",
      "rotation": 32
    },
    {
      "x": 6,
      "y": 21,
      "z": -6,
      "name": "Wood_Oak_Trunk",
      "support": 15,
      "rotation": 4
    },
    {
      "x": 6,
      "y": 22,
      "z": -6,
      "name": "Wood_Hardwood_Planks"
    },
    {
      "x": 6,
      "y": 23,
      "z": -6,
      "name": "Wood_Hardwood_Stairs",
      "rotation": 3
    },
    {
      "x": 6,
      "y": 0,
      "z": -5,
      "name": "Soil_Grass",
      "rotation": 1
    },
    {
      "x": 6,
      "y": 1,
      "z": -5,
      "name": "Rock_Calcite_Brick_Stairs"
    },
    {
      "x": 6,
      "y": 2,
      "z": -5,
      "name": "Rock_Calcite_Brick_Stairs",
      "rotation": 32
    },
    {
      "x": 6,
      "y": 11,
      "z": -5,
      "name": "Wood_Oak_Trunk",
      "support": 15,
      "rotation": 4
    },
    {
      "x": 6,
      "y": 21,
      "z": -5,
      "name": "Wood_Oak_Trunk",
      "support": 15,
      "rotation": 4
    },
    {
      "x": 6,
      "y": 0,
      "z": -4,
      "name": "Soil_Grass",
      "rotation": 1
    },
    {
      "x": 6,
      "y": 11,
      "z": -4,
      "name": "Wood_Oak_Branch_Short",
      "support": 15
    },
    {
      "x": 6,
      "y": 21,
      "z": -4,
      "name": "Wood_Oak_Branch_Short",
      "support": 15
    },
    {
      "x": 6,
      "y": 0,
      "z": -3,
      "name": "Soil_Grass",
      "rotation": 1
    },
    {
      "x": 6,
      "y": 12,
      "z": -3,
      "name": "Cloth_Block_Wool_White"
    },
    {
      "x": 6,
      "y": 13,
      "z": -3,
      "name": "Cloth_Block_Wool_White"
    },
    {
      "x": 6,
      "y": 14,
      "z": -3,
      "name": "Cloth_Block_Wool_White"
    },
    {
      "x": 6,
      "y": 15,
      "z": -3,
      "name": "Wood_Lightwood_Fence"
    },
    {
      "x": 6,
      "y": 16,
      "z": -3,
      "name": "Wood_Hardwood_Planks"
    },
    {
      "x": 6,
      "y": 20,
      "z": -3,
      "name": "Cloth_Block_Wool_White"
    },
    {
      "x": 6,
      "y": 21,
      "z": -3,
      "name": "Cloth_Block_Wool_White"
    },
    {
      "x": 6,
      "y": 22,
      "z": -3,
      "name": "Cloth_Block_Wool_White"
    },
    {
      "x": 6,
      "y": 23,
      "z": -3,
      "name": "Cloth_Block_Wool_White"
    },
    {
      "x": 6,
      "y": 0,
      "z": -2,
      "name": "Soil_Grass",
      "rotation": 1
    },
    {
      "x": 6,
      "y": 13,
      "z": -2,
      "name": "Cloth_Block_Wool_White"
    },
    {
      "x": 6,
      "y": 21,
      "z": -2,
      "name": "Cloth_Block_Wool_White"
    },
    {
      "x": 6,
      "y": 22,
      "z": -2,
      "name": "Cloth_Block_Wool_White"
    },
    {
      "x": 6,
      "y": 0,
      "z": -1,
      "name": "Soil_Grass",
      "rotation": 1
    },
    {
      "x": 7,
      "y": 0,
      "z": -17,
      "name": "Soil_Grass",
      "rotation": 1
    },
    {
      "x": 7,
      "y": 0,
      "z": -16,
      "name": "Soil_Grass",
      "rotation": 1
    },
    {
      "x": 7,
      "y": 1,
      "z": -16,
      "name": "Rock_Calcite_Brick_Smooth"
    },
    {
      "x": 7,
      "y": 8,
      "z": -16,
      "name": "*Wood_Hardwood_Stairs_State_Definitions_Corner_Right",
      "rotation": 33
    },
    {
      "x": 7,
      "y": 9,
      "z": -16,
      "name": "*Wood_Hardwood_Stairs_State_Definitions_Corner_Left",
      "rotation": 1
    },
    {
      "x": 7,
      "y": 10,
      "z": -16,
      "name": "Wood_Hardwood_Stairs",
      "rotation": 34
    },
    {
      "x": 7,
      "y": 11,
      "z": -16,
      "name": "Wood_Hardwood_Planks"
    },
    {
      "x": 7,
      "y": 12,
      "z": -16,
      "name": "Wood_Hardwood_Planks_Half"
    },
    {
      "x": 7,
      "y": 20,
      "z": -16,
      "name": "Wood_Hardwood_Stairs",
      "rotation": 34
    },
    {
      "x": 7,
      "y": 21,
      "z": -16,
      "name": "Wood_Hardwood_Planks"
    },
    {
      "x": 7,
      "y": 22,
      "z": -16,
      "name": "Wood_Hardwood_Stairs",
      "rotation": 33
    },
    {
      "x": 7,
      "y": 23,
      "z": -16,
      "name": "Wood_Hardwood_Planks"
    },
    {
      "x": 7,
      "y": 24,
      "z": -16,
      "name": "Wood_Hardwood_Stairs",
      "rotation": 3
    },
    {
      "x": 7,
      "y": 0,
      "z": -15,
      "name": "Soil_Dirt"
    },
    {
      "x": 7,
      "y": 1,
      "z": -15,
      "name": "Rock_Calcite_Brick_Smooth"
    },
    {
      "x": 7,
      "y": 2,
      "z": -15,
      "name": "Wood_Oak_Trunk",
      "support": 15
    },
    {
      "x": 7,
      "y": 3,
      "z": -15,
      "name": "Wood_Hardwood_Stairs",
      "rotation": 1
    },
    {
      "x": 7,
      "y": 4,
      "z": -15,
      "name": "*Furniture_Kweebec_Trapdoor_State_Definitions_OpenDoorOut",
      "rotation": 1
    },
    {
      "x": 7,
      "y": 7,
      "z": -15,
      "name": "*Furniture_Kweebec_Trapdoor_State_Definitions_OpenDoorOut",
      "rotation": 1
    },
    {
      "x": 7,
      "y": 8,
      "z": -15,
      "name": "Wood_Hardwood_Stairs",
      "rotation": 33
    },
    {
      "x": 7,
      "y": 9,
      "z": -15,
      "name": "Wood_Oak_Trunk",
      "support": 15,
      "rotation": 5
    },
    {
      "x": 7,
      "y": 10,
      "z": -15,
      "name": "*Wood_Village_Wall_White_Full_State_Definitions_Bottom"
    },
    {
      "x": 7,
      "y": 11,
      "z": -15,
      "name": "*Wood_Village_Wall_White_Full_State_Definitions_Top"
    },
    {
      "x": 7,
      "y": 12,
      "z": -15,
      "name": "Wood_Hardwood_Planks"
    },
    {
      "x": 7,
      "y": 13,
      "z": -15,
      "name": "Wood_Hardwood_Stairs",
      "rotation": 1
    },
    {
      "x": 7,
      "y": 14,
      "z": -15,
      "name": "*Furniture_Kweebec_Trapdoor_State_Definitions_OpenDoorOut",
      "rotation": 1
    },
    {
      "x": 7,
      "y": 17,
      "z": -15,
      "name": "*Furniture_Kweebec_Trapdoor_State_Definitions_OpenDoorOut",
      "rotation": 1
    },
    {
      "x": 7,
      "y": 18,
      "z": -15,
      "name": "*Wood_Hardwood_Stairs_State_Definitions_Inverted_Corner_Right",
      "rotation": 33
    },
    {
      "x": 7,
      "y": 19,
      "z": -15,
      "name": "Wood_Oak_Trunk",
      "support": 15,
      "rotation": 5
    },
    {
      "x": 7,
      "y": 20,
      "z": -15,
      "name": "*Wood_Village_Wall_White_Full_State_Definitions_Bottom"
    },
    {
      "x": 7,
      "y": 21,
      "z": -15,
      "name": "*Wood_Village_Wall_White_Full_State_Definitions_Middle"
    },
    {
      "x": 7,
      "y": 22,
      "z": -15,
      "name": "*Wood_Village_Wall_White_Full_State_Definitions_Top"
    },
    {
      "x": 7,
      "y": 23,
      "z": -15,
      "name": "Rock_Chalk_Cobble_Roof",
      "rotation": 3
    },
    {
      "x": 7,
      "y": 0,
      "z": -14,
      "name": "Soil_Grass",
      "rotation": 1
    },
    {
      "x": 7,
      "y": 1,
      "z": -14,
      "name": "Rock_Calcite_Brick_Smooth"
    },
    {
      "x": 7,
      "y": 2,
      "z": -14,
      "name": "*Wood_Village_Wall_White_Full_State_Definitions_Bottom"
    },
    {
      "x": 7,
      "y": 3,
      "z": -14,
      "name": "*Wood_Village_Wall_White_Full_State_Definitions_Middle"
    },
    {
      "x": 7,
      "y": 4,
      "z": -14,
      "name": "*Wood_Village_Wall_White_Full_State_Definitions_Middle"
    },
    {
      "x": 7,
      "y": 5,
      "z": -14,
      "name": "*Wood_Village_Wall_White_Full_State_Definitions_Middle"
    },
    {
      "x": 7,
      "y": 6,
      "z": -14,
      "name": "*Wood_Village_Wall_White_Full_State_Definitions_Middle"
    },
    {
      "x": 7,
      "y": 7,
      "z": -14,
      "name": "*Wood_Village_Wall_White_Full_State_Definitions_Middle"
    },
    {
      "x": 7,
      "y": 8,
      "z": -14,
      "name": "*Wood_Village_Wall_White_Full_State_Definitions_Top"
    },
    {
      "x": 7,
      "y": 9,
      "z": -14,
      "name": "Wood_Hardwood_Planks"
    },
    {
      "x": 7,
      "y": 10,
      "z": -14,
      "name": "Wood_Hardwood_Planks"
    },
    {
      "x": 7,
      "y": 11,
      "z": -14,
      "name": "Wood_Hardwood_Planks"
    },
    {
      "x": 7,
      "y": 12,
      "z": -14,
      "name": "Wood_Hardwood_Planks"
    },
    {
      "x": 7,
      "y": 13,
      "z": -14,
      "name": "*Wood_Village_Wall_White_Full_State_Definitions_Bottom"
    },
    {
      "x": 7,
      "y": 14,
      "z": -14,
      "name": "*Wood_Village_Wall_White_Full_State_Definitions_Middle"
    },
    {
      "x": 7,
      "y": 15,
      "z": -14,
      "name": "*Wood_Village_Wall_White_Full_State_Definitions_Middle"
    },
    {
      "x": 7,
      "y": 16,
      "z": -14,
      "name": "*Wood_Village_Wall_White_Full_State_Definitions_Middle"
    },
    {
      "x": 7,
      "y": 17,
      "z": -14,
      "name": "*Wood_Village_Wall_White_Full_State_Definitions_Middle"
    },
    {
      "x": 7,
      "y": 18,
      "z": -14,
      "name": "*Wood_Village_Wall_White_Full_State_Definitions_Top"
    },
    {
      "x": 7,
      "y": 19,
      "z": -14,
      "name": "Wood_Hardwood_Planks"
    },
    {
      "x": 7,
      "y": 23,
      "z": -14,
      "name": "*Rock_Chalk_Cobble_Roof_Hollow_State_Definitions_Inverted_Corner_Right",
      "rotation": 3
    },
    {
      "x": 7,
      "y": 0,
      "z": -13,
      "name": "Soil_Dirt"
    },
    {
      "x": 7,
      "y": 1,
      "z": -13,
      "name": "Rock_Calcite_Brick_Smooth"
    },
    {
      "x": 7,
      "y": 2,
      "z": -13,
      "name": "*Wood_Village_Wall_White_Full_State_Definitions_Bottom"
    },
    {
      "x": 7,
      "y": 3,
      "z": -13,
      "name": "*Wood_Village_Wall_White_Full_State_Definitions_Middle"
    },
    {
      "x": 7,
      "y": 4,
      "z": -13,
      "name": "*Wood_Village_Wall_White_Full_State_Definitions_Middle"
    },
    {
      "x": 7,
      "y": 5,
      "z": -13,
      "name": "*Wood_Village_Wall_White_Full_State_Definitions_Middle"
    },
    {
      "x": 7,
      "y": 6,
      "z": -13,
      "name": "*Wood_Village_Wall_White_Full_State_Definitions_Middle"
    },
    {
      "x": 7,
      "y": 7,
      "z": -13,
      "name": "*Wood_Village_Wall_White_Full_State_Definitions_Middle"
    },
    {
      "x": 7,
      "y": 8,
      "z": -13,
      "name": "*Wood_Village_Wall_White_Full_State_Definitions_Top"
    },
    {
      "x": 7,
      "y": 9,
      "z": -13,
      "name": "Wood_Hardwood_Planks"
    },
    {
      "x": 7,
      "y": 10,
      "z": -13,
      "name": "Wood_Hardwood_Planks"
    },
    {
      "x": 7,
      "y": 11,
      "z": -13,
      "name": "Wood_Hardwood_Planks"
    },
    {
      "x": 7,
      "y": 12,
      "z": -13,
      "name": "Wood_Hardwood_Planks"
    },
    {
      "x": 7,
      "y": 13,
      "z": -13,
      "name": "Wood_Hardwood_Planks"
    },
    {
      "x": 7,
      "y": 14,
      "z": -13,
      "name": "*Wood_Village_Wall_White_Full_State_Definitions_Bottom"
    },
    {
      "x": 7,
      "y": 15,
      "z": -13,
      "name": "*Wood_Village_Wall_White_Full_State_Definitions_Middle"
    },
    {
      "x": 7,
      "y": 16,
      "z": -13,
      "name": "*Wood_Village_Wall_White_Full_State_Definitions_Middle"
    },
    {
      "x": 7,
      "y": 17,
      "z": -13,
      "name": "*Wood_Village_Wall_White_Full_State_Definitions_Middle"
    },
    {
      "x": 7,
      "y": 18,
      "z": -13,
      "name": "*Wood_Village_Wall_White_Full_State_Definitions_Top"
    },
    {
      "x": 7,
      "y": 19,
      "z": -13,
      "name": "Wood_Hardwood_Planks"
    },
    {
      "x": 7,
      "y": 24,
      "z": -13,
      "name": "Rock_Chalk_Cobble_Roof_Hollow",
      "rotation": 2
    },
    {
      "x": 7,
      "y": 0,
      "z": -12,
      "name": "Soil_Dirt"
    },
    {
      "x": 7,
      "y": 1,
      "z": -12,
      "name": "Rock_Calcite_Brick_Smooth"
    },
    {
      "x": 7,
      "y": 2,
      "z": -12,
      "name": "*Wood_Village_Wall_White_Full_State_Definitions_Bottom"
    },
    {
      "x": 7,
      "y": 3,
      "z": -12,
      "name": "*Wood_Village_Wall_White_Full_State_Definitions_Top"
    },
    {
      "x": 7,
      "y": 4,
      "z": -12,
      "name": "Furniture_Tavern_Window",
      "rotation": 1
    },
    {
      "x": 7,
      "y": 5,
      "z": -12,
      "name": "Furniture_Tavern_Window",
      "rotation": 1
    },
    {
      "x": 7,
      "y": 6,
      "z": -12,
      "name": "Furniture_Tavern_Window",
      "rotation": 1
    },
    {
      "x": 7,
      "y": 7,
      "z": -12,
      "name": "*Wood_Village_Wall_White_Full_State_Definitions_Bottom"
    },
    {
      "x": 7,
      "y": 8,
      "z": -12,
      "name": "*Wood_Village_Wall_White_Full_State_Definitions_Top"
    },
    {
      "x": 7,
      "y": 9,
      "z": -12,
      "name": "Wood_Hardwood_Planks"
    },
    {
      "x": 7,
      "y": 10,
      "z": -12,
      "name": "Wood_Hardwood_Planks"
    },
    {
      "x": 7,
      "y": 11,
      "z": -12,
      "name": "Wood_Hardwood_Planks"
    },
    {
      "x": 7,
      "y": 14,
      "z": -12,
      "name": "Wood_Hardwood_Planks"
    },
    {
      "x": 7,
      "y": 15,
      "z": -12,
      "name": "*Wood_Village_Wall_White_Full_State_Definitions_Bottom"
    },
    {
      "x": 7,
      "y": 16,
      "z": -12,
      "name": "*Wood_Village_Wall_White_Full_State_Definitions_Middle"
    },
    {
      "x": 7,
      "y": 17,
      "z": -12,
      "name": "*Wood_Village_Wall_White_Full_State_Definitions_Middle"
    },
    {
      "x": 7,
      "y": 18,
      "z": -12,
      "name": "*Wood_Village_Wall_White_Full_State_Definitions_Top"
    },
    {
      "x": 7,
      "y": 19,
      "z": -12,
      "name": "Wood_Hardwood_Planks"
    },
    {
      "x": 7,
      "y": 25,
      "z": -12,
      "name": "Rock_Chalk_Cobble_Roof_Steep",
      "rotation": 2
    },
    {
      "x": 7,
      "y": 26,
      "z": -12,
      "name": "Rock_Chalk_Cobble_Roof_Steep",
      "filler": 1024,
      "rotation": 2
    },
    {
      "x": 7,
      "y": 0,
      "z": -11,
      "name": "Soil_Grass",
      "rotation": 1
    },
    {
      "x": 7,
      "y": 1,
      "z": -11,
      "name": "Rock_Calcite_Brick_Smooth"
    },
    {
      "x": 7,
      "y": 2,
      "z": -11,
      "name": "*Wood_Village_Wall_White_Full_State_Definitions_Bottom"
    },
    {
      "x": 7,
      "y": 3,
      "z": -11,
      "name": "*Wood_Village_Wall_White_Full_State_Definitions_Middle"
    },
    {
      "x": 7,
      "y": 4,
      "z": -11,
      "name": "*Wood_Village_Wall_White_Full_State_Definitions_Middle"
    },
    {
      "x": 7,
      "y": 5,
      "z": -11,
      "name": "*Wood_Village_Wall_White_Full_State_Definitions_Middle"
    },
    {
      "x": 7,
      "y": 6,
      "z": -11,
      "name": "*Wood_Village_Wall_White_Full_State_Definitions_Middle"
    },
    {
      "x": 7,
      "y": 7,
      "z": -11,
      "name": "*Wood_Village_Wall_White_Full_State_Definitions_Middle"
    },
    {
      "x": 7,
      "y": 8,
      "z": -11,
      "name": "*Wood_Village_Wall_White_Full_State_Definitions_Top"
    },
    {
      "x": 7,
      "y": 9,
      "z": -11,
      "name": "Wood_Hardwood_Planks"
    },
    {
      "x": 7,
      "y": 10,
      "z": -11,
      "name": "Wood_Hardwood_Planks"
    },
    {
      "x": 7,
      "y": 14,
      "z": -11,
      "name": "Wood_Hardwood_Stairs",
      "rotation": 35
    },
    {
      "x": 7,
      "y": 15,
      "z": -11,
      "name": "*Wood_Village_Wall_White_Full_State_Definitions_Bottom"
    },
    {
      "x": 7,
      "y": 16,
      "z": -11,
      "name": "*Wood_Village_Wall_White_Full_State_Definitions_Middle"
    },
    {
      "x": 7,
      "y": 17,
      "z": -11,
      "name": "*Wood_Village_Wall_White_Full_State_Definitions_Middle"
    },
    {
      "x": 7,
      "y": 18,
      "z": -11,
      "name": "*Wood_Village_Wall_White_Full_State_Definitions_Top"
    },
    {
      "x": 7,
      "y": 19,
      "z": -11,
      "name": "Wood_Hardwood_Planks"
    },
    {
      "x": 7,
      "y": 27,
      "z": -11,
      "name": "Rock_Chalk_Cobble_Roof_Flat",
      "rotation": 3
    },
    {
      "x": 7,
      "y": 0,
      "z": -10,
      "name": "Soil_Dirt"
    },
    {
      "x": 7,
      "y": 1,
      "z": -10,
      "name": "Rock_Calcite_Brick_Smooth"
    },
    {
      "x": 7,
      "y": 2,
      "z": -10,
      "name": "*Wood_Village_Wall_White_Full_State_Definitions_Bottom"
    },
    {
      "x": 7,
      "y": 3,
      "z": -10,
      "name": "*Wood_Village_Wall_White_Full_State_Definitions_Top"
    },
    {
      "x": 7,
      "y": 4,
      "z": -10,
      "name": "Furniture_Tavern_Window",
      "rotation": 1
    },
    {
      "x": 7,
      "y": 5,
      "z": -10,
      "name": "Furniture_Tavern_Window",
      "rotation": 1
    },
    {
      "x": 7,
      "y": 6,
      "z": -10,
      "name": "Furniture_Tavern_Window",
      "rotation": 1
    },
    {
      "x": 7,
      "y": 7,
      "z": -10,
      "name": "*Wood_Village_Wall_White_Full_State_Definitions_Bottom"
    },
    {
      "x": 7,
      "y": 8,
      "z": -10,
      "name": "*Wood_Village_Wall_White_Full_State_Definitions_Top"
    },
    {
      "x": 7,
      "y": 9,
      "z": -10,
      "name": "Wood_Hardwood_Planks"
    },
    {
      "x": 7,
      "y": 10,
      "z": -10,
      "name": "Wood_Hardwood_Planks"
    },
    {
      "x": 7,
      "y": 11,
      "z": -10,
      "name": "Wood_Hardwood_Planks"
    },
    {
      "x": 7,
      "y": 14,
      "z": -10,
      "name": "Wood_Hardwood_Planks"
    },
    {
      "x": 7,
      "y": 15,
      "z": -10,
      "name": "*Wood_Village_Wall_White_Full_State_Definitions_Bottom"
    },
    {
      "x": 7,
      "y": 16,
      "z": -10,
      "name": "*Wood_Village_Wall_White_Full_State_Definitions_Middle"
    },
    {
      "x": 7,
      "y": 17,
      "z": -10,
      "name": "*Wood_Village_Wall_White_Full_State_Definitions_Middle"
    },
    {
      "x": 7,
      "y": 18,
      "z": -10,
      "name": "*Wood_Village_Wall_White_Full_State_Definitions_Top"
    },
    {
      "x": 7,
      "y": 19,
      "z": -10,
      "name": "Wood_Hardwood_Planks"
    },
    {
      "x": 7,
      "y": 25,
      "z": -10,
      "name": "Rock_Chalk_Cobble_Roof_Steep"
    },
    {
      "x": 7,
      "y": 26,
      "z": -10,
      "name": "Rock_Chalk_Cobble_Roof_Steep",
      "filler": 1024
    },
    {
      "x": 7,
      "y": 0,
      "z": -9,
      "name": "Soil_Dirt"
    },
    {
      "x": 7,
      "y": 1,
      "z": -9,
      "name": "Rock_Calcite_Brick_Smooth"
    },
    {
      "x": 7,
      "y": 2,
      "z": -9,
      "name": "*Wood_Village_Wall_White_Full_State_Definitions_Bottom"
    },
    {
      "x": 7,
      "y": 3,
      "z": -9,
      "name": "*Wood_Village_Wall_White_Full_State_Definitions_Middle"
    },
    {
      "x": 7,
      "y": 4,
      "z": -9,
      "name": "*Wood_Village_Wall_White_Full_State_Definitions_Middle"
    },
    {
      "x": 7,
      "y": 5,
      "z": -9,
      "name": "*Wood_Village_Wall_White_Full_State_Definitions_Middle"
    },
    {
      "x": 7,
      "y": 6,
      "z": -9,
      "name": "*Wood_Village_Wall_White_Full_State_Definitions_Middle"
    },
    {
      "x": 7,
      "y": 7,
      "z": -9,
      "name": "*Wood_Village_Wall_White_Full_State_Definitions_Middle"
    },
    {
      "x": 7,
      "y": 8,
      "z": -9,
      "name": "*Wood_Village_Wall_White_Full_State_Definitions_Top"
    },
    {
      "x": 7,
      "y": 9,
      "z": -9,
      "name": "Wood_Hardwood_Planks"
    },
    {
      "x": 7,
      "y": 10,
      "z": -9,
      "name": "Wood_Hardwood_Planks"
    },
    {
      "x": 7,
      "y": 11,
      "z": -9,
      "name": "Wood_Hardwood_Planks"
    },
    {
      "x": 7,
      "y": 12,
      "z": -9,
      "name": "Wood_Hardwood_Planks"
    },
    {
      "x": 7,
      "y": 13,
      "z": -9,
      "name": "Wood_Hardwood_Planks"
    },
    {
      "x": 7,
      "y": 14,
      "z": -9,
      "name": "*Wood_Village_Wall_White_Full_State_Definitions_Bottom"
    },
    {
      "x": 7,
      "y": 15,
      "z": -9,
      "name": "*Wood_Village_Wall_White_Full_State_Definitions_Middle"
    },
    {
      "x": 7,
      "y": 16,
      "z": -9,
      "name": "*Wood_Village_Wall_White_Full_State_Definitions_Middle"
    },
    {
      "x": 7,
      "y": 17,
      "z": -9,
      "name": "*Wood_Village_Wall_White_Full_State_Definitions_Middle"
    },
    {
      "x": 7,
      "y": 18,
      "z": -9,
      "name": "*Wood_Village_Wall_White_Full_State_Definitions_Top"
    },
    {
      "x": 7,
      "y": 19,
      "z": -9,
      "name": "Wood_Hardwood_Planks"
    },
    {
      "x": 7,
      "y": 24,
      "z": -9,
      "name": "Rock_Chalk_Cobble_Roof_Hollow"
    },
    {
      "x": 7,
      "y": 0,
      "z": -8,
      "name": "Soil_Grass",
      "rotation": 1
    },
    {
      "x": 7,
      "y": 1,
      "z": -8,
      "name": "Rock_Calcite_Brick_Smooth"
    },
    {
      "x": 7,
      "y": 2,
      "z": -8,
      "name": "*Wood_Village_Wall_White_Full_State_Definitions_Bottom"
    },
    {
      "x": 7,
      "y": 3,
      "z": -8,
      "name": "*Wood_Village_Wall_White_Full_State_Definitions_Middle"
    },
    {
      "x": 7,
      "y": 4,
      "z": -8,
      "name": "*Wood_Village_Wall_White_Full_State_Definitions_Middle"
    },
    {
      "x": 7,
      "y": 5,
      "z": -8,
      "name": "*Wood_Village_Wall_White_Full_State_Definitions_Middle"
    },
    {
      "x": 7,
      "y": 6,
      "z": -8,
      "name": "*Wood_Village_Wall_White_Full_State_Definitions_Middle"
    },
    {
      "x": 7,
      "y": 7,
      "z": -8,
      "name": "*Wood_Village_Wall_White_Full_State_Definitions_Middle"
    },
    {
      "x": 7,
      "y": 8,
      "z": -8,
      "name": "*Wood_Village_Wall_White_Full_State_Definitions_Top"
    },
    {
      "x": 7,
      "y": 9,
      "z": -8,
      "name": "Wood_Hardwood_Planks"
    },
    {
      "x": 7,
      "y": 10,
      "z": -8,
      "name": "Wood_Hardwood_Planks"
    },
    {
      "x": 7,
      "y": 11,
      "z": -8,
      "name": "Wood_Hardwood_Planks"
    },
    {
      "x": 7,
      "y": 12,
      "z": -8,
      "name": "Wood_Hardwood_Planks"
    },
    {
      "x": 7,
      "y": 13,
      "z": -8,
      "name": "*Wood_Village_Wall_White_Full_State_Definitions_Bottom"
    },
    {
      "x": 7,
      "y": 14,
      "z": -8,
      "name": "*Wood_Village_Wall_White_Full_State_Definitions_Middle"
    },
    {
      "x": 7,
      "y": 15,
      "z": -8,
      "name": "*Wood_Village_Wall_White_Full_State_Definitions_Middle"
    },
    {
      "x": 7,
      "y": 16,
      "z": -8,
      "name": "*Wood_Village_Wall_White_Full_State_Definitions_Middle"
    },
    {
      "x": 7,
      "y": 17,
      "z": -8,
      "name": "*Wood_Village_Wall_White_Full_State_Definitions_Middle"
    },
    {
      "x": 7,
      "y": 18,
      "z": -8,
      "name": "*Wood_Village_Wall_White_Full_State_Definitions_Top"
    },
    {
      "x": 7,
      "y": 19,
      "z": -8,
      "name": "Wood_Hardwood_Planks"
    },
    {
      "x": 7,
      "y": 23,
      "z": -8,
      "name": "*Rock_Chalk_Cobble_Roof_Hollow_State_Definitions_Inverted_Corner_Left",
      "rotation": 3
    },
    {
      "x": 7,
      "y": 0,
      "z": -7,
      "name": "Soil_Dirt"
    },
    {
      "x": 7,
      "y": 1,
      "z": -7,
      "name": "Rock_Calcite_Brick_Smooth"
    },
    {
      "x": 7,
      "y": 2,
      "z": -7,
      "name": "Wood_Oak_Trunk",
      "support": 15,
      "rotation": 5
    },
    {
      "x": 7,
      "y": 3,
      "z": -7,
      "name": "Wood_Hardwood_Stairs",
      "rotation": 1
    },
    {
      "x": 7,
      "y": 4,
      "z": -7,
      "name": "*Furniture_Kweebec_Trapdoor_State_Definitions_OpenDoorOut",
      "rotation": 1
    },
    {
      "x": 7,
      "y": 7,
      "z": -7,
      "name": "*Furniture_Kweebec_Trapdoor_State_Definitions_OpenDoorOut",
      "rotation": 1
    },
    {
      "x": 7,
      "y": 8,
      "z": -7,
      "name": "Wood_Hardwood_Stairs",
      "rotation": 33
    },
    {
      "x": 7,
      "y": 9,
      "z": -7,
      "name": "Wood_Oak_Trunk",
      "support": 15,
      "rotation": 5
    },
    {
      "x": 7,
      "y": 10,
      "z": -7,
      "name": "*Wood_Village_Wall_White_Full_State_Definitions_Bottom"
    },
    {
      "x": 7,
      "y": 11,
      "z": -7,
      "name": "*Wood_Village_Wall_White_Full_State_Definitions_Top"
    },
    {
      "x": 7,
      "y": 12,
      "z": -7,
      "name": "Wood_Hardwood_Planks"
    },
    {
      "x": 7,
      "y": 13,
      "z": -7,
      "name": "Wood_Hardwood_Stairs",
      "rotation": 1
    },
    {
      "x": 7,
      "y": 14,
      "z": -7,
      "name": "*Furniture_Kweebec_Trapdoor_State_Definitions_OpenDoorOut",
      "rotation": 1
    },
    {
      "x": 7,
      "y": 17,
      "z": -7,
      "name": "*Furniture_Kweebec_Trapdoor_State_Definitions_OpenDoorOut",
      "rotation": 1
    },
    {
      "x": 7,
      "y": 18,
      "z": -7,
      "name": "Wood_Hardwood_Stairs",
      "rotation": 33
    },
    {
      "x": 7,
      "y": 19,
      "z": -7,
      "name": "Wood_Oak_Trunk",
      "support": 15,
      "rotation": 5
    },
    {
      "x": 7,
      "y": 20,
      "z": -7,
      "name": "*Wood_Village_Wall_White_Full_State_Definitions_Bottom"
    },
    {
      "x": 7,
      "y": 21,
      "z": -7,
      "name": "*Wood_Village_Wall_White_Full_State_Definitions_Middle"
    },
    {
      "x": 7,
      "y": 22,
      "z": -7,
      "name": "*Wood_Village_Wall_White_Full_State_Definitions_Top"
    },
    {
      "x": 7,
      "y": 23,
      "z": -7,
      "name": "Rock_Chalk_Cobble_Roof",
      "rotation": 3
    },
    {
      "x": 7,
      "y": 0,
      "z": -6,
      "name": "Soil_Dirt"
    },
    {
      "x": 7,
      "y": 1,
      "z": -6,
      "name": "Rock_Calcite_Brick_Smooth"
    },
    {
      "x": 7,
      "y": 2,
      "z": -6,
      "name": "Plant_Leaves_Beech",
      "support": 15
    },
    {
      "x": 7,
      "y": 3,
      "z": -6,
      "name": "Plant_Leaves_Beech",
      "support": 15
    },
    {
      "x": 7,
      "y": 8,
      "z": -6,
      "name": "*Wood_Hardwood_Stairs_State_Definitions_Corner_Right",
      "rotation": 32
    },
    {
      "x": 7,
      "y": 9,
      "z": -6,
      "name": "*Wood_Hardwood_Stairs_State_Definitions_Corner_Right",
      "rotation": 1
    },
    {
      "x": 7,
      "y": 10,
      "z": -6,
      "name": "Wood_Hardwood_Stairs",
      "rotation": 32
    },
    {
      "x": 7,
      "y": 11,
      "z": -6,
      "name": "Wood_Hardwood_Planks"
    },
    {
      "x": 7,
      "y": 12,
      "z": -6,
      "name": "Wood_Hardwood_Planks_Half"
    },
    {
      "x": 7,
      "y": 20,
      "z": -6,
      "name": "Wood_Hardwood_Stairs",
      "rotation": 32
    },
    {
      "x": 7,
      "y": 21,
      "z": -6,
      "name": "Wood_Hardwood_Planks"
    },
    {
      "x": 7,
      "y": 22,
      "z": -6,
      "name": "Wood_Hardwood_Stairs",
      "rotation": 33
    },
    {
      "x": 7,
      "y": 23,
      "z": -6,
      "name": "Wood_Hardwood_Planks"
    },
    {
      "x": 7,
      "y": 24,
      "z": -6,
      "name": "Wood_Hardwood_Stairs",
      "rotation": 3
    },
    {
      "x": 7,
      "y": 0,
      "z": -5,
      "name": "Soil_Grass",
      "rotation": 1
    },
    {
      "x": 7,
      "y": 0,
      "z": -4,
      "name": "Soil_Grass",
      "rotation": 1
    },
    {
      "x": 7,
      "y": 0,
      "z": -3,
      "name": "Soil_Grass",
      "rotation": 1
    },
    {
      "x": 7,
      "y": 13,
      "z": -3,
      "name": "Cloth_Block_Wool_White"
    },
    {
      "x": 7,
      "y": 14,
      "z": -3,
      "name": "Cloth_Block_Wool_White"
    },
    {
      "x": 7,
      "y": 15,
      "z": -3,
      "name": "Wood_Lightwood_Fence"
    },
    {
      "x": 7,
      "y": 16,
      "z": -3,
      "name": "Wood_Hardwood_Planks"
    },
    {
      "x": 7,
      "y": 19,
      "z": -3,
      "name": "Cloth_Block_Wool_White"
    },
    {
      "x": 7,
      "y": 20,
      "z": -3,
      "name": "Cloth_Block_Wool_White"
    },
    {
      "x": 7,
      "y": 21,
      "z": -3,
      "name": "Cloth_Block_Wool_White"
    },
    {
      "x": 7,
      "y": 22,
      "z": -3,
      "name": "Cloth_Block_Wool_White"
    },
    {
      "x": 7,
      "y": 23,
      "z": -3,
      "name": "Cloth_Block_Wool_White"
    },
    {
      "x": 7,
      "y": 24,
      "z": -3,
      "name": "Cloth_Block_Wool_White"
    },
    {
      "x": 7,
      "y": 0,
      "z": -2,
      "name": "Soil_Grass",
      "rotation": 1
    },
    {
      "x": 7,
      "y": 20,
      "z": -2,
      "name": "Cloth_Block_Wool_White"
    },
    {
      "x": 7,
      "y": 21,
      "z": -2,
      "name": "Cloth_Block_Wool_White"
    },
    {
      "x": 7,
      "y": 0,
      "z": -1,
      "name": "Soil_Grass",
      "rotation": 1
    },
    {
      "x": 8,
      "y": 0,
      "z": -17,
      "name": "Soil_Grass",
      "rotation": 1
    },
    {
      "x": 8,
      "y": 0,
      "z": -16,
      "name": "Soil_Grass",
      "rotation": 1
    },
    {
      "x": 8,
      "y": 1,
      "z": -16,
      "name": "Rock_Calcite_Brick_Smooth_Half"
    },
    {
      "x": 8,
      "y": 10,
      "z": -16,
      "name": "Wood_Hardwood_Stairs",
      "rotation": 34
    },
    {
      "x": 8,
      "y": 11,
      "z": -16,
      "name": "Wood_Hardwood_Planks"
    },
    {
      "x": 8,
      "y": 12,
      "z": -16,
      "name": "Wood_Hardwood_Planks_Half"
    },
    {
      "x": 8,
      "y": 20,
      "z": -16,
      "name": "Wood_Hardwood_Stairs",
      "rotation": 34
    },
    {
      "x": 8,
      "y": 21,
      "z": -16,
      "name": "Wood_Hardwood_Planks"
    },
    {
      "x": 8,
      "y": 23,
      "z": -16,
      "name": "Wood_Hardwood_Stairs",
      "rotation": 33
    },
    {
      "x": 8,
      "y": 24,
      "z": -16,
      "name": "Wood_Hardwood_Planks"
    },
    {
      "x": 8,
      "y": 25,
      "z": -16,
      "name": "Wood_Hardwood_Stairs",
      "rotation": 3
    },
    {
      "x": 8,
      "y": 0,
      "z": -15,
      "name": "Soil_Grass",
      "rotation": 1
    },
    {
      "x": 8,
      "y": 1,
      "z": -15,
      "name": "Rock_Calcite_Brick_Stairs",
      "rotation": 2
    },
    {
      "x": 8,
      "y": 2,
      "z": -15,
      "name": "Rock_Calcite_Brick_Smooth_Half"
    },
    {
      "x": 8,
      "y": 5,
      "z": -15,
      "name": "Wood_Hardwood_Beam"
    },
    {
      "x": 8,
      "y": 6,
      "z": -15,
      "name": "Wood_Hardwood_Beam"
    },
    {
      "x": 8,
      "y": 7,
      "z": -15,
      "name": "Wood_Hardwood_Beam"
    },
    {
      "x": 8,
      "y": 8,
      "z": -15,
      "name": "Wood_Hardwood_Beam"
    },
    {
      "x": 8,
      "y": 9,
      "z": -15,
      "name": "Wood_Oak_Trunk",
      "support": 15,
      "rotation": 5
    },
    {
      "x": 8,
      "y": 10,
      "z": -15,
      "name": "*Wood_Village_Wall_White_Full_State_Definitions_Bottom"
    },
    {
      "x": 8,
      "y": 11,
      "z": -15,
      "name": "*Wood_Village_Wall_White_Full_State_Definitions_Top"
    },
    {
      "x": 8,
      "y": 12,
      "z": -15,
      "name": "Wood_Hardwood_Planks"
    },
    {
      "x": 8,
      "y": 13,
      "z": -15,
      "name": "Wood_Hardwood_Planks_Half",
      "rotation": 6
    },
    {
      "x": 8,
      "y": 14,
      "z": -15,
      "name": "Wood_Hardwood_Planks_Half",
      "rotation": 6
    },
    {
      "x": 8,
      "y": 15,
      "z": -15,
      "name": "Wood_Hardwood_Planks_Half",
      "rotation": 6
    },
    {
      "x": 8,
      "y": 16,
      "z": -15,
      "name": "Wood_Hardwood_Planks_Half",
      "rotation": 6
    },
    {
      "x": 8,
      "y": 17,
      "z": -15,
      "name": "Wood_Hardwood_Planks_Half",
      "rotation": 6
    },
    {
      "x": 8,
      "y": 18,
      "z": -15,
      "name": "Wood_Hardwood_Stairs",
      "rotation": 34
    },
    {
      "x": 8,
      "y": 19,
      "z": -15,
      "name": "Wood_Oak_Trunk",
      "support": 15,
      "rotation": 5
    },
    {
      "x": 8,
      "y": 20,
      "z": -15,
      "name": "*Wood_Village_Wall_White_Full_State_Definitions_Bottom"
    },
    {
      "x": 8,
      "y": 21,
      "z": -15,
      "name": "*Wood_Village_Wall_White_Full_State_Definitions_Middle"
    },
    {
      "x": 8,
      "y": 22,
      "z": -15,
      "name": "*Wood_Village_Wall_White_Full_State_Definitions_Middle"
    },
    {
      "x": 8,
      "y": 23,
      "z": -15,
      "name": "*Wood_Village_Wall_White_Full_State_Definitions_Top"
    },
    {
      "x": 8,
      "y": 24,
      "z": -15,
      "name": "Rock_Chalk_Cobble_Roof",
      "rotation": 3
    },
    {
      "x": 8,
      "y": 0,
      "z": -14,
      "name": "Soil_Grass",
      "rotation": 1
    },
    {
      "x": 8,
      "y": 1,
      "z": -14,
      "name": "Rock_Calcite_Brick_Smooth"
    },
    {
      "x": 8,
      "y": 2,
      "z": -14,
      "name": "*Wood_Village_Wall_White_Full_State_Definitions_Bottom"
    },
    {
      "x": 8,
      "y": 3,
      "z": -14,
      "name": "*Wood_Village_Wall_White_Full_State_Definitions_Middle"
    },
    {
      "x": 8,
      "y": 4,
      "z": -14,
      "name": "*Wood_Village_Wall_White_Full_State_Definitions_Middle"
    },
    {
      "x": 8,
      "y": 5,
      "z": -14,
      "name": "*Wood_Village_Wall_White_Full_State_Definitions_Middle"
    },
    {
      "x": 8,
      "y": 6,
      "z": -14,
      "name": "*Wood_Village_Wall_White_Full_State_Definitions_Middle"
    },
    {
      "x": 8,
      "y": 7,
      "z": -14,
      "name": "*Wood_Village_Wall_White_Full_State_Definitions_Middle"
    },
    {
      "x": 8,
      "y": 8,
      "z": -14,
      "name": "*Wood_Village_Wall_White_Full_State_Definitions_Top"
    },
    {
      "x": 8,
      "y": 9,
      "z": -14,
      "name": "Wood_Hardwood_Planks"
    },
    {
      "x": 8,
      "y": 10,
      "z": -14,
      "name": "Wood_Hardwood_Planks"
    },
    {
      "x": 8,
      "y": 11,
      "z": -14,
      "name": "Wood_Hardwood_Planks"
    },
    {
      "x": 8,
      "y": 12,
      "z": -14,
      "name": "Wood_Hardwood_Planks"
    },
    {
      "x": 8,
      "y": 13,
      "z": -14,
      "name": "*Wood_Village_Wall_White_Full_State_Definitions_Bottom"
    },
    {
      "x": 8,
      "y": 14,
      "z": -14,
      "name": "*Wood_Village_Wall_White_Full_State_Definitions_Middle"
    },
    {
      "x": 8,
      "y": 15,
      "z": -14,
      "name": "*Wood_Village_Wall_White_Full_State_Definitions_Middle"
    },
    {
      "x": 8,
      "y": 16,
      "z": -14,
      "name": "*Wood_Village_Wall_White_Full_State_Definitions_Middle"
    },
    {
      "x": 8,
      "y": 17,
      "z": -14,
      "name": "*Wood_Village_Wall_White_Full_State_Definitions_Middle"
    },
    {
      "x": 8,
      "y": 18,
      "z": -14,
      "name": "*Wood_Village_Wall_White_Full_State_Definitions_Top"
    },
    {
      "x": 8,
      "y": 19,
      "z": -14,
      "name": "Wood_Hardwood_Planks"
    },
    {
      "x": 8,
      "y": 24,
      "z": -14,
      "name": "Rock_Chalk_Cobble_Roof_Hollow",
      "rotation": 3
    },
    {
      "x": 8,
      "y": 0,
      "z": -13,
      "name": "Soil_Dirt"
    },
    {
      "x": 8,
      "y": 1,
      "z": -13,
      "name": "Rock_Calcite_Brick_Smooth"
    },
    {
      "x": 8,
      "y": 2,
      "z": -13,
      "name": "Ingredient_Hay",
      "rotation": 4
    },
    {
      "x": 8,
      "y": 3,
      "z": -13,
      "name": "Ingredient_Hay",
      "rotation": 4
    },
    {
      "x": 8,
      "y": 4,
      "z": -13,
      "name": "Ingredient_Hay",
      "rotation": 1
    },
    {
      "x": 8,
      "y": 7,
      "z": -13,
      "name": "Deco_Spider_Cocoon",
      "filler": 31744,
      "rotation": 34
    },
    {
      "x": 8,
      "y": 8,
      "z": -13,
      "name": "Deco_Spider_Cocoon",
      "support": 15,
      "rotation": 34
    },
    {
      "x": 8,
      "y": 9,
      "z": -13,
      "name": "Wood_Hardwood_Planks"
    },
    {
      "x": 8,
      "y": 10,
      "z": -13,
      "name": "Ingredient_Hay"
    },
    {
      "x": 8,
      "y": 11,
      "z": -13,
      "name": "Ingredient_Hay"
    },
    {
      "x": 8,
      "y": 13,
      "z": -13,
      "name": "Wood_Hardwood_Planks"
    },
    {
      "x": 8,
      "y": 19,
      "z": -13,
      "name": "Wood_Hardwood_Planks"
    },
    {
      "x": 8,
      "y": 24,
      "z": -13,
      "name": "*Rock_Chalk_Cobble_Roof_Hollow_State_Definitions_Inverted_Corner_Left",
      "rotation": 2
    },
    {
      "x": 8,
      "y": 0,
      "z": -12,
      "name": "Soil_Dirt"
    },
    {
      "x": 8,
      "y": 1,
      "z": -12,
      "name": "Rock_Calcite_Brick_Smooth"
    },
    {
      "x": 8,
      "y": 2,
      "z": -12,
      "name": "Ingredient_Hay",
      "rotation": 2
    },
    {
      "x": 8,
      "y": 3,
      "z": -12,
      "name": "Cloth_Roof_Yellow_Flat"
    },
    {
      "x": 8,
      "y": 9,
      "z": -12,
      "name": "Wood_Hardwood_Planks"
    },
    {
      "x": 8,
      "y": 10,
      "z": -12,
      "name": "Ingredient_Hay"
    },
    {
      "x": 8,
      "y": 11,
      "z": -12,
      "name": "Ingredient_Hay"
    },
    {
      "x": 8,
      "y": 14,
      "z": -12,
      "name": "Wood_Hardwood_Planks"
    },
    {
      "x": 8,
      "y": 19,
      "z": -12,
      "name": "Wood_Hardwood_Planks"
    },
    {
      "x": 8,
      "y": 25,
      "z": -12,
      "name": "Rock_Chalk_Cobble_Roof_Steep",
      "rotation": 2
    },
    {
      "x": 8,
      "y": 26,
      "z": -12,
      "name": "Rock_Chalk_Cobble_Roof_Steep",
      "filler": 1024,
      "rotation": 2
    },
    {
      "x": 8,
      "y": 0,
      "z": -11,
      "name": "Soil_Grass",
      "rotation": 1
    },
    {
      "x": 8,
      "y": 1,
      "z": -11,
      "name": "Rock_Calcite_Brick_Smooth"
    },
    {
      "x": 8,
      "y": 2,
      "z": -11,
      "name": "Cloth_Roof_Yellow_Flat"
    },
    {
      "x": 8,
      "y": 9,
      "z": -11,
      "name": "Wood_Hardwood_Planks"
    },
    {
      "x": 8,
      "y": 14,
      "z": -11,
      "name": "Wood_Hardwood_Planks"
    },
    {
      "x": 8,
      "y": 19,
      "z": -11,
      "name": "Wood_Hardwood_Planks"
    },
    {
      "x": 8,
      "y": 27,
      "z": -11,
      "name": "Rock_Chalk_Cobble_Roof_Flat",
      "rotation": 3
    },
    {
      "x": 8,
      "y": 0,
      "z": -10,
      "name": "Soil_Grass",
      "rotation": 1
    },
    {
      "x": 8,
      "y": 1,
      "z": -10,
      "name": "Rock_Calcite_Brick_Smooth"
    },
    {
      "x": 8,
      "y": 2,
      "z": -10,
      "name": "Ingredient_Hay",
      "rotation": 5
    },
    {
      "x": 8,
      "y": 3,
      "z": -10,
      "name": "Ingredient_Hay",
      "rotation": 1
    },
    {
      "x": 8,
      "y": 9,
      "z": -10,
      "name": "Wood_Hardwood_Planks"
    },
    {
      "x": 8,
      "y": 10,
      "z": -10,
      "name": "Ingredient_Hay"
    },
    {
      "x": 8,
      "y": 14,
      "z": -10,
      "name": "Wood_Hardwood_Planks"
    },
    {
      "x": 8,
      "y": 19,
      "z": -10,
      "name": "Wood_Hardwood_Planks"
    },
    {
      "x": 8,
      "y": 25,
      "z": -10,
      "name": "Rock_Chalk_Cobble_Roof_Steep"
    },
    {
      "x": 8,
      "y": 26,
      "z": -10,
      "name": "Rock_Chalk_Cobble_Roof_Steep",
      "filler": 1024
    },
    {
      "x": 8,
      "y": 0,
      "z": -9,
      "name": "Soil_Dirt"
    },
    {
      "x": 8,
      "y": 1,
      "z": -9,
      "name": "Rock_Calcite_Brick_Smooth"
    },
    {
      "x": 8,
      "y": 2,
      "z": -9,
      "name": "Ingredient_Hay",
      "rotation": 4
    },
    {
      "x": 8,
      "y": 3,
      "z": -9,
      "name": "Ingredient_Hay",
      "rotation": 2
    },
    {
      "x": 8,
      "y": 4,
      "z": -9,
      "name": "Ingredient_Hay",
      "rotation": 1
    },
    {
      "x": 8,
      "y": 9,
      "z": -9,
      "name": "Wood_Hardwood_Planks"
    },
    {
      "x": 8,
      "y": 10,
      "z": -9,
      "name": "Ingredient_Hay"
    },
    {
      "x": 8,
      "y": 11,
      "z": -9,
      "name": "Ingredient_Hay"
    },
    {
      "x": 8,
      "y": 13,
      "z": -9,
      "name": "Wood_Hardwood_Planks"
    },
    {
      "x": 8,
      "y": 19,
      "z": -9,
      "name": "Wood_Hardwood_Planks"
    },
    {
      "x": 8,
      "y": 24,
      "z": -9,
      "name": "*Rock_Chalk_Cobble_Roof_Hollow_State_Definitions_Inverted_Corner_Right"
    },
    {
      "x": 8,
      "y": 0,
      "z": -8,
      "name": "Soil_Dirt"
    },
    {
      "x": 8,
      "y": 1,
      "z": -8,
      "name": "Rock_Calcite_Brick_Smooth"
    },
    {
      "x": 8,
      "y": 2,
      "z": -8,
      "name": "*Wood_Village_Wall_White_Full_State_Definitions_Bottom"
    },
    {
      "x": 8,
      "y": 3,
      "z": -8,
      "name": "*Wood_Village_Wall_White_Full_State_Definitions_Middle"
    },
    {
      "x": 8,
      "y": 4,
      "z": -8,
      "name": "*Wood_Village_Wall_White_Full_State_Definitions_Middle"
    },
    {
      "x": 8,
      "y": 5,
      "z": -8,
      "name": "*Wood_Village_Wall_White_Full_State_Definitions_Middle"
    },
    {
      "x": 8,
      "y": 6,
      "z": -8,
      "name": "*Wood_Village_Wall_White_Full_State_Definitions_Middle"
    },
    {
      "x": 8,
      "y": 7,
      "z": -8,
      "name": "*Wood_Village_Wall_White_Full_State_Definitions_Middle"
    },
    {
      "x": 8,
      "y": 8,
      "z": -8,
      "name": "*Wood_Village_Wall_White_Full_State_Definitions_Top"
    },
    {
      "x": 8,
      "y": 9,
      "z": -8,
      "name": "Wood_Hardwood_Planks"
    },
    {
      "x": 8,
      "y": 10,
      "z": -8,
      "name": "Wood_Hardwood_Planks"
    },
    {
      "x": 8,
      "y": 11,
      "z": -8,
      "name": "Wood_Hardwood_Planks"
    },
    {
      "x": 8,
      "y": 12,
      "z": -8,
      "name": "Wood_Hardwood_Planks"
    },
    {
      "x": 8,
      "y": 13,
      "z": -8,
      "name": "*Wood_Village_Wall_White_Full_State_Definitions_Bottom"
    },
    {
      "x": 8,
      "y": 14,
      "z": -8,
      "name": "*Wood_Village_Wall_White_Full_State_Definitions_Middle"
    },
    {
      "x": 8,
      "y": 15,
      "z": -8,
      "name": "*Wood_Village_Wall_White_Full_State_Definitions_Middle"
    },
    {
      "x": 8,
      "y": 16,
      "z": -8,
      "name": "*Wood_Village_Wall_White_Full_State_Definitions_Middle"
    },
    {
      "x": 8,
      "y": 17,
      "z": -8,
      "name": "*Wood_Village_Wall_White_Full_State_Definitions_Middle"
    },
    {
      "x": 8,
      "y": 18,
      "z": -8,
      "name": "*Wood_Village_Wall_White_Full_State_Definitions_Top"
    },
    {
      "x": 8,
      "y": 19,
      "z": -8,
      "name": "Wood_Hardwood_Planks"
    },
    {
      "x": 8,
      "y": 24,
      "z": -8,
      "name": "Rock_Chalk_Cobble_Roof_Hollow",
      "rotation": 3
    },
    {
      "x": 8,
      "y": 0,
      "z": -7,
      "name": "Soil_Grass",
      "rotation": 1
    },
    {
      "x": 8,
      "y": 1,
      "z": -7,
      "name": "Rock_Calcite_Brick_Stairs"
    },
    {
      "x": 8,
      "y": 2,
      "z": -7,
      "name": "Rock_Calcite_Brick_Smooth_Half"
    },
    {
      "x": 8,
      "y": 3,
      "z": -7,
      "name": "Plant_Leaves_Beech",
      "support": 15
    },
    {
      "x": 8,
      "y": 4,
      "z": -7,
      "name": "Plant_Leaves_Beech",
      "support": 15
    },
    {
      "x": 8,
      "y": 5,
      "z": -7,
      "name": "Wood_Hardwood_Beam"
    },
    {
      "x": 8,
      "y": 6,
      "z": -7,
      "name": "Wood_Hardwood_Beam"
    },
    {
      "x": 8,
      "y": 7,
      "z": -7,
      "name": "Wood_Hardwood_Beam"
    },
    {
      "x": 8,
      "y": 8,
      "z": -7,
      "name": "Wood_Hardwood_Beam"
    },
    {
      "x": 8,
      "y": 9,
      "z": -7,
      "name": "Wood_Oak_Trunk",
      "support": 15,
      "rotation": 5
    },
    {
      "x": 8,
      "y": 10,
      "z": -7,
