{
  "version": 8,
  "blockIdVersion": 11,
  "anchorX": 0,
  "anchorY": 0,
  "anchorZ": 0,
  "blocks": [
    {
      "x": -21,
      "y": 1,
      "z": 1,
      "name": "Rock_Stone_Cobble"
    },
    {
      "x": -21,
      "y": 1,
      "z": 2,
      "name": "Rock_Stone_Cobble"
    },
    {
      "x": -21,
      "y": 1,
      "z": 3,
      "name": "Rock_Stone_Cobble"
    },
    {
      "x": -21,
      "y": 1,
      "z": 4,
      "name": "Rock_Stone_Cobble"
    },
    {
      "x": -21,
      "y": 1,
      "z": 5,
      "name": "Rock_Stone_Cobble"
    },
    {
      "x": -21,
      "y": 1,
      "z": 6,
      "name": "Rock_Stone_Cobble"
    },
    {
      "x": -21,
      "y": 6,
      "z": 6,
      "name": "Wood_Softwood_Roof_Hollow",
      "rotation": 2
    },
    {
      "x": -21,
      "y": 1,
      "z": 7,
      "name": "Rock_Stone_Cobble"
    },
    {
      "x": -21,
      "y": 6,
      "z": 7,
      "name": "Wood_Beech_Branch_Corner",
      "support": 15,
      "rotation": 3
    },
    {
      "x": -21,
      "y": 7,
      "z": 7,
      "name": "Wood_Softwood_Roof_Shallow",
      "rotation": 2
    },
    {
      "x": -21,
      "y": 1,
      "z": 8,
      "name": "Rock_Stone_Cobble"
    },
    {
      "x": -21,
      "y": 5,
      "z": 8,
      "name": "Plant_Vine_Wall",
      "support": 15,
      "rotation": 3
    },
    {
      "x": -21,
      "y": 6,
      "z": 8,
      "name": "Plant_Vine",
      "support": 15,
      "rotation": 3
    },
    {
      "x": -21,
      "y": 7,
      "z": 8,
      "name": "Wood_Softwood_Roof_Shallow",
      "filler": 32,
      "rotation": 2
    },
    {
      "x": -21,
      "y": 1,
      "z": 9,
      "name": "Rock_Stone_Cobble"
    },
    {
      "x": -21,
      "y": 2,
      "z": 9,
      "name": "Rock_Stone_Brick_Stairs",
      "rotation": 2
    },
    {
      "x": -21,
      "y": 3,
      "z": 9,
      "name": "Rock_Stone_Brick_Half",
      "rotation": 6
    },
    {
      "x": -21,
      "y": 6,
      "z": 9,
      "name": "Wood_Beech_Branch_Short",
      "support": 15,
      "rotation": 3
    },
    {
      "x": -21,
      "y": 7,
      "z": 9,
      "name": "Wood_Softwood_Stairs",
      "rotation": 10
    },
    {
      "x": -21,
      "y": 8,
      "z": 9,
      "name": "Wood_Softwood_Roof_Shallow",
      "rotation": 2
    },
    {
      "x": -21,
      "y": 1,
      "z": 10,
      "name": "Rock_Stone_Cobble"
    },
    {
      "x": -21,
      "y": 2,
      "z": 10,
      "name": "Rock_Stone_Brick"
    },
    {
      "x": -21,
      "y": 3,
      "z": 10,
      "name": "Rock_Stone_Brick"
    },
    {
      "x": -21,
      "y": 4,
      "z": 10,
      "name": "Rock_Stone_Brick"
    },
    {
      "x": -21,
      "y": 5,
      "z": 10,
      "name": "Rock_Stone_Brick"
    },
    {
      "x": -21,
      "y": 6,
      "z": 10,
      "name": "Rock_Stone_Brick_Stairs",
      "rotation": 3
    },
    {
      "x": -21,
      "y": 7,
      "z": 10,
      "name": "Rock_Stone_Brick_Half",
      "rotation": 7
    },
    {
      "x": -21,
      "y": 8,
      "z": 10,
      "name": "Wood_Softwood_Roof_Shallow",
      "filler": 32,
      "rotation": 2
    },
    {
      "x": -21,
      "y": 1,
      "z": 11,
      "name": "Rock_Stone_Cobble"
    },
    {
      "x": -21,
      "y": 2,
      "z": 11,
      "name": "Rock_Stone_Brick"
    },
    {
      "x": -21,
      "y": 3,
      "z": 11,
      "name": "Rock_Stone_Brick"
    },
    {
      "x": -21,
      "y": 4,
      "z": 11,
      "name": "Rock_Stone_Brick"
    },
    {
      "x": -21,
      "y": 5,
      "z": 11,
      "name": "Rock_Stone_Brick"
    },
    {
      "x": -21,
      "y": 6,
      "z": 11,
      "name": "Rock_Stone_Brick_Stairs",
      "rotation": 3
    },
    {
      "x": -21,
      "y": 7,
      "z": 11,
      "name": "Rock_Stone_Brick_Half",
      "rotation": 7
    },
    {
      "x": -21,
      "y": 8,
      "z": 11,
      "name": "Wood_Softwood_Roof_Shallow",
      "filler": 992
    },
    {
      "x": -21,
      "y": 1,
      "z": 12,
      "name": "Rock_Stone_Cobble"
    },
    {
      "x": -21,
      "y": 2,
      "z": 12,
      "name": "Rock_Stone_Brick_Stairs"
    },
    {
      "x": -21,
      "y": 3,
      "z": 12,
      "name": "Rock_Stone_Brick_Half",
      "rotation": 4
    },
    {
      "x": -21,
      "y": 6,
      "z": 12,
      "name": "Wood_Beech_Branch_Short",
      "support": 15,
      "rotation": 3
    },
    {
      "x": -21,
      "y": 7,
      "z": 12,
      "name": "Wood_Softwood_Stairs",
      "rotation": 8
    },
    {
      "x": -21,
      "y": 8,
      "z": 12,
      "name": "Wood_Softwood_Roof_Shallow"
    },
    {
      "x": -21,
      "y": 1,
      "z": 13,
      "name": "Rock_Stone_Cobble"
    },
    {
      "x": -21,
      "y": 7,
      "z": 13,
      "name": "Wood_Softwood_Roof_Shallow",
      "filler": 992
    },
    {
      "x": -21,
      "y": 1,
      "z": 14,
      "name": "Rock_Stone_Cobble"
    },
    {
      "x": -21,
      "y": 6,
      "z": 14,
      "name": "Wood_Beech_Branch_Corner",
      "support": 15,
      "rotation": 3
    },
    {
      "x": -21,
      "y": 7,
      "z": 14,
      "name": "Wood_Softwood_Roof_Shallow"
    },
    {
      "x": -21,
      "y": 1,
      "z": 15,
      "name": "Rock_Stone_Cobble"
    },
    {
      "x": -21,
      "y": 6,
      "z": 15,
      "name": "Wood_Softwood_Roof_Hollow"
    },
    {
      "x": -21,
      "y": 1,
      "z": 16,
      "name": "Rock_Stone_Cobble"
    },
    {
      "x": -21,
      "y": 1,
      "z": 17,
      "name": "Rock_Stone_Cobble"
    },
    {
      "x": -21,
      "y": 1,
      "z": 18,
      "name": "Rock_Stone_Cobble"
    },
    {
      "x": -21,
      "y": 1,
      "z": 19,
      "name": "Rock_Stone_Cobble"
    },
    {
      "x": -21,
      "y": 1,
      "z": 20,
      "name": "Rock_Stone_Cobble"
    },
    {
      "x": -20,
      "y": 1,
      "z": 1,
      "name": "Rock_Stone_Cobble"
    },
    {
      "x": -20,
      "y": 1,
      "z": 2,
      "name": "Rock_Stone_Cobble"
    },
    {
      "x": -20,
      "y": 1,
      "z": 3,
      "name": "Rock_Stone_Cobble"
    },
    {
      "x": -20,
      "y": 1,
      "z": 4,
      "name": "Rock_Stone_Cobble"
    },
    {
      "x": -20,
      "y": 2,
      "z": 4,
      "name": "Furniture_Tavern_Barrel",
      "support": 15
    },
    {
      "x": -20,
      "y": 1,
      "z": 5,
      "name": "Rock_Stone_Cobble"
    },
    {
      "x": -20,
      "y": 1,
      "z": 6,
      "name": "Rock_Stone_Cobble"
    },
    {
      "x": -20,
      "y": 5,
      "z": 6,
      "name": "Wood_Beech_Branch_Corner",
      "support": 15,
      "rotation": 2
    },
    {
      "x": -20,
      "y": 6,
      "z": 6,
      "name": "Wood_Softwood_Roof",
      "rotation": 2
    },
    {
      "x": -20,
      "y": 1,
      "z": 7,
      "name": "Rock_Stone_Cobble"
    },
    {
      "x": -20,
      "y": 2,
      "z": 7,
      "name": "Wood_Beech_Trunk",
      "support": 15
    },
    {
      "x": -20,
      "y": 3,
      "z": 7,
      "name": "Wood_Beech_Trunk",
      "support": 15
    },
    {
      "x": -20,
      "y": 4,
      "z": 7,
      "name": "Wood_Beech_Trunk",
      "support": 15
    },
    {
      "x": -20,
      "y": 5,
      "z": 7,
      "name": "Wood_Beech_Trunk",
      "support": 15
    },
    {
      "x": -20,
      "y": 6,
      "z": 7,
      "name": "Wood_Beech_Trunk",
      "support": 15
    },
    {
      "x": -20,
      "y": 7,
      "z": 7,
      "name": "Wood_Softwood_Roof_Shallow",
      "rotation": 2
    },
    {
      "x": -20,
      "y": 1,
      "z": 8,
      "name": "Rock_Stone_Cobble"
    },
    {
      "x": -20,
      "y": 2,
      "z": 8,
      "name": "Rock_Stone_Brick"
    },
    {
      "x": -20,
      "y": 3,
      "z": 8,
      "name": "*Wood_Village_Wall_Full_State_Definitions_Bottom"
    },
    {
      "x": -20,
      "y": 4,
      "z": 8,
      "name": "*Wood_Village_Wall_Full_State_Definitions_Middle"
    },
    {
      "x": -20,
      "y": 5,
      "z": 8,
      "name": "*Wood_Village_Wall_Full_State_Definitions_Top"
    },
    {
      "x": -20,
      "y": 6,
      "z": 8,
      "name": "Wood_Beech_Trunk",
      "support": 15,
      "rotation": 4
    },
    {
      "x": -20,
      "y": 7,
      "z": 8,
      "name": "Wood_Softwood_Roof_Shallow",
      "filler": 32,
      "rotation": 2
    },
    {
      "x": -20,
      "y": 1,
      "z": 9,
      "name": "Rock_Stone_Cobble"
    },
    {
      "x": -20,
      "y": 2,
      "z": 9,
      "name": "Rock_Stone_Brick"
    },
    {
      "x": -20,
      "y": 3,
      "z": 9,
      "name": "Rock_Stone_Brick"
    },
    {
      "x": -20,
      "y": 4,
      "z": 9,
      "name": "*Wood_Village_Wall_Full_State_Definitions_Bottom"
    },
    {
      "x": -20,
      "y": 5,
      "z": 9,
      "name": "*Wood_Village_Wall_Full_State_Definitions_Top"
    },
    {
      "x": -20,
      "y": 6,
      "z": 9,
      "name": "Wood_Beech_Trunk",
      "support": 15,
      "rotation": 4
    },
    {
      "x": -20,
      "y": 7,
      "z": 9,
      "name": "Wood_Village_Wall_Full"
    },
    {
      "x": -20,
      "y": 8,
      "z": 9,
      "name": "Wood_Softwood_Roof",
      "rotation": 2
    },
    {
      "x": -20,
      "y": 1,
      "z": 10,
      "name": "Rock_Stone_Cobble"
    },
    {
      "x": -20,
      "y": 2,
      "z": 10,
      "name": "Rock_Stone_Brick"
    },
    {
      "x": -20,
      "y": 3,
      "z": 10,
      "name": "Rock_Stone_Brick"
    },
    {
      "x": -20,
      "y": 4,
      "z": 10,
      "name": "Rock_Stone_Brick"
    },
    {
      "x": -20,
      "y": 5,
      "z": 10,
      "name": "Rock_Stone_Brick"
    },
    {
      "x": -20,
      "y": 6,
      "z": 10,
      "name": "Rock_Stone_Brick"
    },
    {
      "x": -20,
      "y": 7,
      "z": 10,
      "name": "Rock_Stone_Brick"
    },
    {
      "x": -20,
      "y": 8,
      "z": 10,
      "name": "Rock_Stone_Brick"
    },
    {
      "x": -20,
      "y": 9,
      "z": 10,
      "name": "Rock_Stone_Brick"
    },
    {
      "x": -20,
      "y": 10,
      "z": 10,
      "name": "Furniture_Village_Planter",
      "support": 15
    },
    {
      "x": -20,
      "y": 11,
      "z": 10,
      "name": "Rock_Stone_Brick_Roof_Flat",
      "rotation": 3
    },
    {
      "x": -20,
      "y": 1,
      "z": 11,
      "name": "Rock_Stone_Cobble"
    },
    {
      "x": -20,
      "y": 2,
      "z": 11,
      "name": "Rock_Stone_Brick"
    },
    {
      "x": -20,
      "y": 3,
      "z": 11,
      "name": "Rock_Stone_Brick"
    },
    {
      "x": -20,
      "y": 4,
      "z": 11,
      "name": "Rock_Stone_Brick"
    },
    {
      "x": -20,
      "y": 5,
      "z": 11,
      "name": "Rock_Stone_Brick"
    },
    {
      "x": -20,
      "y": 6,
      "z": 11,
      "name": "Rock_Stone_Brick"
    },
    {
      "x": -20,
      "y": 7,
      "z": 11,
      "name": "Rock_Stone_Brick"
    },
    {
      "x": -20,
      "y": 8,
      "z": 11,
      "name": "Rock_Stone_Brick"
    },
    {
      "x": -20,
      "y": 9,
      "z": 11,
      "name": "Rock_Stone_Brick"
    },
    {
      "x": -20,
      "y": 10,
      "z": 11,
      "name": "Furniture_Village_Planter",
      "support": 15
    },
    {
      "x": -20,
      "y": 11,
      "z": 11,
      "name": "Rock_Stone_Brick_Roof_Flat",
      "rotation": 3
    },
    {
      "x": -20,
      "y": 1,
      "z": 12,
      "name": "Rock_Stone_Cobble"
    },
    {
      "x": -20,
      "y": 2,
      "z": 12,
      "name": "Rock_Stone_Brick"
    },
    {
      "x": -20,
      "y": 3,
      "z": 12,
      "name": "Rock_Stone_Brick"
    },
    {
      "x": -20,
      "y": 4,
      "z": 12,
      "name": "*Wood_Village_Wall_Full_State_Definitions_Bottom"
    },
    {
      "x": -20,
      "y": 5,
      "z": 12,
      "name": "*Wood_Village_Wall_Full_State_Definitions_Top"
    },
    {
      "x": -20,
      "y": 6,
      "z": 12,
      "name": "Wood_Beech_Trunk",
      "support": 15,
      "rotation": 4
    },
    {
      "x": -20,
      "y": 7,
      "z": 12,
      "name": "Wood_Village_Wall_Full"
    },
    {
      "x": -20,
      "y": 8,
      "z": 12,
      "name": "Wood_Softwood_Roof"
    },
    {
      "x": -20,
      "y": 1,
      "z": 13,
      "name": "Rock_Stone_Cobble"
    },
    {
      "x": -20,
      "y": 2,
      "z": 13,
      "name": "Rock_Stone_Brick"
    },
    {
      "x": -20,
      "y": 3,
      "z": 13,
      "name": "*Wood_Village_Wall_Full_State_Definitions_Bottom"
    },
    {
      "x": -20,
      "y": 4,
      "z": 13,
      "name": "*Wood_Village_Wall_Full_State_Definitions_Middle"
    },
    {
      "x": -20,
      "y": 5,
      "z": 13,
      "name": "*Wood_Village_Wall_Full_State_Definitions_Top"
    },
    {
      "x": -20,
      "y": 6,
      "z": 13,
      "name": "Wood_Beech_Trunk",
      "support": 15,
      "rotation": 4
    },
    {
      "x": -20,
      "y": 7,
      "z": 13,
      "name": "Wood_Softwood_Roof_Shallow",
      "filler": 992
    },
    {
      "x": -20,
      "y": 1,
      "z": 14,
      "name": "Rock_Stone_Cobble"
    },
    {
      "x": -20,
      "y": 2,
      "z": 14,
      "name": "Wood_Beech_Trunk",
      "support": 15
    },
    {
      "x": -20,
      "y": 3,
      "z": 14,
      "name": "Wood_Beech_Trunk",
      "support": 15
    },
    {
      "x": -20,
      "y": 4,
      "z": 14,
      "name": "Wood_Beech_Trunk",
      "support": 15
    },
    {
      "x": -20,
      "y": 5,
      "z": 14,
      "name": "Wood_Beech_Trunk",
      "support": 15
    },
    {
      "x": -20,
      "y": 6,
      "z": 14,
      "name": "Wood_Beech_Trunk",
      "support": 15
    },
    {
      "x": -20,
      "y": 7,
      "z": 14,
      "name": "Wood_Softwood_Roof_Shallow"
    },
    {
      "x": -20,
      "y": 1,
      "z": 15,
      "name": "Rock_Stone_Cobble"
    },
    {
      "x": -20,
      "y": 2,
      "z": 15,
      "name": "Rock_Stone_Brick_Wall",
      "rotation": 1
    },
    {
      "x": -20,
      "y": 3,
      "z": 15,
      "name": "Wood_Softwood_Fence",
      "rotation": 3
    },
    {
      "x": -20,
      "y": 5,
      "z": 15,
      "name": "Wood_Beech_Branch_Corner",
      "support": 15
    },
    {
      "x": -20,
      "y": 6,
      "z": 15,
      "name": "Wood_Softwood_Roof"
    },
    {
      "x": -20,
      "y": 1,
      "z": 16,
      "name": "Rock_Stone_Cobble"
    },
    {
      "x": -20,
      "y": 2,
      "z": 16,
      "name": "Rock_Stone_Brick_Wall",
      "rotation": 1
    },
    {
      "x": -20,
      "y": 3,
      "z": 16,
      "name": "Wood_Softwood_Fence",
      "rotation": 3
    },
    {
      "x": -20,
      "y": 1,
      "z": 17,
      "name": "Rock_Stone_Cobble"
    },
    {
      "x": -20,
      "y": 2,
      "z": 17,
      "name": "Rock_Stone_Brick_Wall",
      "rotation": 1
    },
    {
      "x": -20,
      "y": 3,
      "z": 17,
      "name": "Wood_Softwood_Fence",
      "rotation": 3
    },
    {
      "x": -20,
      "y": 1,
      "z": 18,
      "name": "Rock_Stone_Cobble"
    },
    {
      "x": -20,
      "y": 2,
      "z": 18,
      "name": "Rock_Stone_Brick_Wall",
      "rotation": 1
    },
    {
      "x": -20,
      "y": 3,
      "z": 18,
      "name": "Wood_Softwood_Fence",
      "rotation": 3
    },
    {
      "x": -20,
      "y": 1,
      "z": 19,
      "name": "Rock_Stone_Cobble"
    },
    {
      "x": -20,
      "y": 2,
      "z": 19,
      "name": "*Rock_Stone_Brick_Wall_State_Definitions_Corner",
      "rotation": 2
    },
    {
      "x": -20,
      "y": 3,
      "z": 19,
      "name": "*Wood_Softwood_Fence_State_Definitions_Corner",
      "rotation": 2
    },
    {
      "x": -20,
      "y": 1,
      "z": 20,
      "name": "Rock_Stone_Cobble"
    },
    {
      "x": -19,
      "y": 1,
      "z": 1,
      "name": "Rock_Stone_Cobble"
    },
    {
      "x": -19,
      "y": 1,
      "z": 2,
      "name": "Rock_Stone_Cobble"
    },
    {
      "x": -19,
      "y": 1,
      "z": 3,
      "name": "Rock_Stone_Cobble"
    },
    {
      "x": -19,
      "y": 1,
      "z": 4,
      "name": "Rock_Stone_Cobble"
    },
    {
      "x": -19,
      "y": 2,
      "z": 4,
      "name": "Furniture_Village_Crate"
    },
    {
      "x": -19,
      "y": 1,
      "z": 5,
      "name": "Rock_Stone_Cobble"
    },
    {
      "x": -19,
      "y": 1,
      "z": 6,
      "name": "Rock_Stone_Cobble"
    },
    {
      "x": -19,
      "y": 6,
      "z": 6,
      "name": "Wood_Softwood_Roof_Hollow",
      "rotation": 2
    },
    {
      "x": -19,
      "y": 1,
      "z": 7,
      "name": "Rock_Stone_Cobble"
    },
    {
      "x": -19,
      "y": 2,
      "z": 7,
      "name": "Rock_Stone_Brick"
    },
    {
      "x": -19,
      "y": 3,
      "z": 7,
      "name": "*Wood_Village_Wall_Full_State_Definitions_Bottom"
    },
    {
      "x": -19,
      "y": 4,
      "z": 7,
      "name": "*Wood_Village_Wall_Full_State_Definitions_Middle"
    },
    {
      "x": -19,
      "y": 5,
      "z": 7,
      "name": "*Wood_Village_Wall_Full_State_Definitions_Top"
    },
    {
      "x": -19,
      "y": 6,
      "z": 7,
      "name": "Wood_Beech_Trunk",
      "support": 15,
      "rotation": 5
    },
    {
      "x": -19,
      "y": 7,
      "z": 7,
      "name": "Wood_Softwood_Roof_Shallow",
      "rotation": 2
    },
    {
      "x": -19,
      "y": 1,
      "z": 8,
      "name": "Rock_Stone_Cobble"
    },
    {
      "x": -19,
      "y": 7,
      "z": 8,
      "name": "Wood_Softwood_Roof_Shallow",
      "filler": 32,
      "rotation": 2
    },
    {
      "x": -19,
      "y": 1,
      "z": 9,
      "name": "Rock_Stone_Cobble"
    },
    {
      "x": -19,
      "y": 2,
      "z": 9,
      "name": "Rock_Stone_Brick"
    },
    {
      "x": -19,
      "y": 3,
      "z": 9,
      "name": "Rock_Stone_Brick_Stairs",
      "rotation": 2
    },
    {
      "x": -19,
      "y": 4,
      "z": 9,
      "name": "Rock_Stone_Brick_Half",
      "rotation": 6
    },
    {
      "x": -19,
      "y": 7,
      "z": 9,
      "name": "Wood_Softwood_Stairs",
      "rotation": 10
    },
    {
      "x": -19,
      "y": 8,
      "z": 9,
      "name": "Wood_Softwood_Roof_Shallow",
      "rotation": 2
    },
    {
      "x": -19,
      "y": 1,
      "z": 10,
      "name": "Rock_Stone_Cobble"
    },
    {
      "x": -19,
      "y": 2,
      "z": 10,
      "name": "Bench_Furnace",
      "components": {
        "Components": {
          "BenchBlock": {
            "TierLevel": 1,
            "UpgradeItems": []
          },
          "ProcessingBenchBlock": {
            "InputContainer": {
              "Id": "Simple",
              "Capacity": 2,
              "Items": {}
            },
            "FuelContainer": {
              "Id": "Simple",
              "Capacity": 1,
              "Items": {}
            },
            "OutputContainer": {
              "Id": "Simple",
              "Capacity": 4,
              "Items": {}
            },
            "Progress": 0.0,
            "FuelTime": 0.0,
            "Active": false,
            "NextExtra": 2,
            "LastTickGameTime": "0001-02-02T17:49:42.514624111Z"
          },
          "PlacedByInteraction": {
            "WhoPlacedUuid": {
              "$binary": "sYi8yt9tSZKTSQi5wuBq4A==",
              "$type": "04"
            }
          }
        }
      },
      "support": 15,
      "rotation": 1
    },
    {
      "x": -19,
      "y": 3,
      "z": 10,
      "name": "Bench_Furnace",
      "support": 15,
      "filler": 1024,
      "rotation": 1
    },
    {
      "x": -19,
      "y": 4,
      "z": 10,
      "name": "Rock_Stone_Brick_Stairs",
      "rotation": 11
    },
    {
      "x": -19,
      "y": 5,
      "z": 10,
      "name": "Rock_Stone_Brick"
    },
    {
      "x": -19,
      "y": 8,
      "z": 10,
      "name": "Wood_Softwood_Roof_Shallow",
      "filler": 32,
      "rotation": 2
    },
    {
      "x": -19,
      "y": 1,
      "z": 11,
      "name": "Rock_Stone_Cobble"
    },
    {
      "x": -19,
      "y": 2,
      "z": 11,
      "name": "Bench_Furnace",
      "support": 15,
      "filler": 32,
      "rotation": 1
    },
    {
      "x": -19,
      "y": 3,
      "z": 11,
      "name": "Bench_Furnace",
      "support": 15,
      "filler": 1056,
      "rotation": 1
    },
    {
      "x": -19,
      "y": 4,
      "z": 11,
      "name": "Rock_Stone_Brick_Stairs",
      "rotation": 11
    },
    {
      "x": -19,
      "y": 5,
      "z": 11,
      "name": "Rock_Stone_Brick"
    },
    {
      "x": -19,
      "y": 8,
      "z": 11,
      "name": "Wood_Softwood_Roof_Shallow",
      "filler": 992
    },
    {
      "x": -19,
      "y": 1,
      "z": 12,
      "name": "Rock_Stone_Cobble"
    },
    {
      "x": -19,
      "y": 2,
      "z": 12,
      "name": "Rock_Stone_Brick"
    },
    {
      "x": -19,
      "y": 3,
      "z": 12,
      "name": "Rock_Stone_Brick_Stairs"
    },
    {
      "x": -19,
      "y": 4,
      "z": 12,
      "name": "Rock_Stone_Brick_Half",
      "rotation": 4
    },
    {
      "x": -19,
      "y": 7,
      "z": 12,
      "name": "Wood_Softwood_Stairs",
      "rotation": 8
    },
    {
      "x": -19,
      "y": 8,
      "z": 12,
      "name": "Wood_Softwood_Roof_Shallow"
    },
    {
      "x": -19,
      "y": 1,
      "z": 13,
      "name": "Rock_Stone_Cobble"
    },
    {
      "x": -19,
      "y": 7,
      "z": 13,
      "name": "Wood_Softwood_Roof_Shallow",
      "filler": 992
    },
    {
      "x": -19,
      "y": 1,
      "z": 14,
      "name": "Rock_Stone_Cobble"
    },
    {
      "x": -19,
      "y": 2,
      "z": 14,
      "name": "Rock_Stone_Brick"
    },
    {
      "x": -19,
      "y": 3,
      "z": 14,
      "name": "*Wood_Village_Wall_Full_State_Definitions_Bottom"
    },
    {
      "x": -19,
      "y": 4,
      "z": 14,
      "name": "*Wood_Village_Wall_Full_State_Definitions_Middle"
    },
    {
      "x": -19,
      "y": 5,
      "z": 14,
      "name": "*Wood_Village_Wall_Full_State_Definitions_Top"
    },
    {
      "x": -19,
      "y": 6,
      "z": 14,
      "name": "Wood_Beech_Trunk",
      "support": 15,
      "rotation": 5
    },
    {
      "x": -19,
      "y": 7,
      "z": 14,
      "name": "Wood_Softwood_Roof_Shallow"
    },
    {
      "x": -19,
      "y": 1,
      "z": 15,
      "name": "Rock_Stone_Cobble"
    },
    {
      "x": -19,
      "y": 2,
      "z": 15,
      "name": "Ingredient_Hay"
    },
    {
      "x": -19,
      "y": 3,
      "z": 15,
      "name": "Ingredient_Hay"
    },
    {
      "x": -19,
      "y": 4,
      "z": 15,
      "name": "Plant_Hay_Bundle",
      "support": 15
    },
    {
      "x": -19,
      "y": 6,
      "z": 15,
      "name": "Wood_Softwood_Roof_Hollow"
    },
    {
      "x": -19,
      "y": 1,
      "z": 16,
      "name": "Rock_Stone_Cobble"
    },
    {
      "x": -19,
      "y": 2,
      "z": 16,
      "name": "Ingredient_Hay"
    },
    {
      "x": -19,
      "y": 1,
      "z": 17,
      "name": "Rock_Stone_Cobble"
    },
    {
      "x": -19,
      "y": 1,
      "z": 18,
      "name": "Rock_Stone_Cobble"
    },
    {
      "x": -19,
      "y": 2,
      "z": 18,
      "name": "Deco_Target",
      "support": 15,
      "rotation": 1
    },
    {
      "x": -19,
      "y": 1,
      "z": 19,
      "name": "Rock_Stone_Cobble"
    },
    {
      "x": -19,
      "y": 2,
      "z": 19,
      "name": "Rock_Stone_Brick_Wall"
    },
    {
      "x": -19,
      "y": 3,
      "z": 19,
      "name": "Wood_Softwood_Fence"
    },
    {
      "x": -19,
      "y": 1,
      "z": 20,
      "name": "Rock_Stone_Cobble"
    },
    {
      "x": -18,
      "y": 1,
      "z": 1,
      "name": "Rock_Stone_Cobble"
    },
    {
      "x": -18,
      "y": 1,
      "z": 2,
      "name": "Rock_Stone_Cobble"
    },
    {
      "x": -18,
      "y": 1,
      "z": 3,
      "name": "Rock_Stone_Cobble"
    },
    {
      "x": -18,
      "y": 2,
      "z": 3,
      "name": "Furniture_Village_Crate"
    },
    {
      "x": -18,
      "y": 1,
      "z": 4,
      "name": "Rock_Stone_Cobble"
    },
    {
      "x": -18,
      "y": 2,
      "z": 4,
      "name": "Furniture_Village_Crate"
    },
    {
      "x": -18,
      "y": 3,
      "z": 4,
      "name": "Furniture_Tavern_Barrel",
      "support": 15
    },
    {
      "x": -18,
      "y": 1,
      "z": 5,
      "name": "Rock_Stone_Cobble"
    },
    {
      "x": -18,
      "y": 1,
      "z": 6,
      "name": "Rock_Stone_Cobble"
    },
    {
      "x": -18,
      "y": 6,
      "z": 6,
      "name": "Wood_Softwood_Roof_Hollow",
      "rotation": 2
    },
    {
      "x": -18,
      "y": 1,
      "z": 7,
      "name": "Rock_Stone_Cobble"
    },
    {
      "x": -18,
      "y": 2,
      "z": 7,
      "name": "Rock_Stone_Brick"
    },
    {
      "x": -18,
      "y": 3,
      "z": 7,
      "name": "Furniture_Village_Window"
    },
    {
      "x": -18,
      "y": 4,
      "z": 7,
      "name": "Furniture_Village_Window"
    },
    {
      "x": -18,
      "y": 5,
      "z": 7,
      "name": "Wood_Softwood_Stairs",
      "rotation": 8
    },
    {
      "x": -18,
      "y": 6,
      "z": 7,
      "name": "Wood_Beech_Trunk",
      "support": 15,
      "rotation": 5
    },
    {
      "x": -18,
      "y": 7,
      "z": 7,
      "name": "Wood_Softwood_Roof_Shallow",
      "rotation": 2
    },
    {
      "x": -18,
      "y": 1,
      "z": 8,
      "name": "Rock_Stone_Cobble"
    },
    {
      "x": -18,
      "y": 7,
      "z": 8,
      "name": "Wood_Softwood_Roof_Shallow",
      "filler": 32,
      "rotation": 2
    },
    {
      "x": -18,
      "y": 1,
      "z": 9,
      "name": "Rock_Stone_Cobble"
    },
    {
      "x": -18,
      "y": 7,
      "z": 9,
      "name": "Wood_Softwood_Stairs",
      "rotation": 10
    },
    {
      "x": -18,
      "y": 8,
      "z": 9,
      "name": "Wood_Softwood_Roof_Shallow",
      "rotation": 2
    },
    {
      "x": -18,
      "y": 1,
      "z": 10,
      "name": "Rock_Stone_Cobble"
    },
    {
      "x": -18,
      "y": 8,
      "z": 10,
      "name": "Wood_Softwood_Roof_Shallow",
      "filler": 32,
      "rotation": 2
    },
    {
      "x": -18,
      "y": 1,
      "z": 11,
      "name": "Rock_Stone_Cobble"
    },
    {
      "x": -18,
      "y": 8,
      "z": 11,
      "name": "Wood_Softwood_Roof_Shallow",
      "filler": 992
    },
    {
      "x": -18,
      "y": 1,
      "z": 12,
      "name": "Rock_Stone_Cobble"
    },
    {
      "x": -18,
      "y": 7,
      "z": 12,
      "name": "Wood_Softwood_Stairs",
      "rotation": 8
    },
    {
      "x": -18,
      "y": 8,
      "z": 12,
      "name": "Wood_Softwood_Roof_Shallow"
    },
    {
      "x": -18,
      "y": 1,
      "z": 13,
      "name": "Rock_Stone_Cobble"
    },
    {
      "x": -18,
      "y": 7,
      "z": 13,
      "name": "Wood_Softwood_Roof_Shallow",
      "filler": 992
    },
    {
      "x": -18,
      "y": 1,
      "z": 14,
      "name": "Rock_Stone_Cobble"
    },
    {
      "x": -18,
      "y": 2,
      "z": 14,
      "name": "Rock_Stone_Brick"
    },
    {
      "x": -18,
      "y": 3,
      "z": 14,
      "name": "Furniture_Village_Window"
    },
    {
      "x": -18,
      "y": 4,
      "z": 14,
      "name": "Furniture_Village_Window"
    },
    {
      "x": -18,
      "y": 5,
      "z": 14,
      "name": "Wood_Softwood_Stairs",
      "rotation": 10
    },
    {
      "x": -18,
      "y": 6,
      "z": 14,
      "name": "Wood_Beech_Trunk",
      "support": 15,
      "rotation": 5
    },
    {
      "x": -18,
      "y": 7,
      "z": 14,
      "name": "Wood_Softwood_Roof_Shallow"
    },
    {
      "x": -18,
      "y": 1,
      "z": 15,
      "name": "Rock_Stone_Cobble"
    },
    {
      "x": -18,
      "y": 2,
      "z": 15,
      "name": "Ingredient_Hay"
    },
    {
      "x": -18,
      "y": 3,
      "z": 15,
      "name": "Ingredient_Hay"
    },
    {
      "x": -18,
      "y": 6,
      "z": 15,
      "name": "Wood_Softwood_Roof_Hollow"
    },
    {
      "x": -18,
      "y": 1,
      "z": 16,
      "name": "Rock_Stone_Cobble"
    },
    {
      "x": -18,
      "y": 2,
      "z": 16,
      "name": "Ingredient_Hay"
    },
    {
      "x": -18,
      "y": 3,
      "z": 16,
      "name": "Plant_Hay_Bundle",
      "support": 15
    },
    {
      "x": -18,
      "y": 1,
      "z": 17,
      "name": "Rock_Stone_Cobble"
    },
    {
      "x": -18,
      "y": 1,
      "z": 18,
      "name": "Rock_Stone_Cobble"
    },
    {
      "x": -18,
      "y": 1,
      "z": 19,
      "name": "Rock_Stone_Cobble"
    },
    {
      "x": -18,
      "y": 2,
      "z": 19,
      "name": "Rock_Stone_Brick_Wall"
    },
    {
      "x": -18,
      "y": 3,
      "z": 19,
      "name": "Wood_Softwood_Fence"
    },
    {
      "x": -18,
      "y": 1,
      "z": 20,
      "name": "Rock_Stone_Cobble"
    },
    {
      "x": -17,
      "y": 1,
      "z": 1,
      "name": "Rock_Stone_Cobble"
    },
    {
      "x": -17,
      "y": 1,
      "z": 2,
      "name": "Rock_Stone_Cobble"
    },
    {
      "x": -17,
      "y": 2,
      "z": 2,
      "name": "Furniture_Tavern_Barrel",
      "support": 15
    },
    {
      "x": -17,
      "y": 1,
      "z": 3,
      "name": "Rock_Stone_Cobble"
    },
    {
      "x": -17,
      "y": 2,
      "z": 3,
      "name": "Furniture_Village_Crate"
    },
    {
      "x": -17,
      "y": 1,
      "z": 4,
      "name": "Rock_Stone_Cobble"
    },
    {
      "x": -17,
      "y": 1,
      "z": 5,
      "name": "Rock_Stone_Cobble"
    },
    {
      "x": -17,
      "y": 1,
      "z": 6,
      "name": "Rock_Stone_Cobble"
    },
    {
      "x": -17,
      "y": 6,
      "z": 6,
      "name": "Wood_Softwood_Roof_Hollow",
      "rotation": 2
    },
    {
      "x": -17,
      "y": 1,
      "z": 7,
      "name": "Rock_Stone_Brick"
    },
    {
      "x": -17,
      "y": 2,
      "z": 7,
      "name": "Rock_Stone_Brick"
    },
    {
      "x": -17,
      "y": 3,
      "z": 7,
      "name": "*Wood_Village_Wall_Full_State_Definitions_Bottom"
    },
    {
      "x": -17,
      "y": 4,
      "z": 7,
      "name": "*Wood_Village_Wall_Full_State_Definitions_Middle"
    },
    {
      "x": -17,
      "y": 5,
      "z": 7,
      "name": "*Wood_Village_Wall_Full_State_Definitions_Top"
    },
    {
      "x": -17,
      "y": 6,
      "z": 7,
      "name": "Wood_Beech_Trunk",
      "support": 15,
      "rotation": 5
    },
    {
      "x": -17,
      "y": 7,
      "z": 7,
      "name": "Wood_Softwood_Roof_Shallow",
      "rotation": 2
    },
    {
      "x": -17,
      "y": 1,
      "z": 8,
      "name": "Wood_Drywood_Planks"
    },
    {
      "x": -17,
      "y": 7,
      "z": 8,
      "name": "Wood_Softwood_Roof_Shallow",
      "filler": 32,
      "rotation": 2
    },
    {
      "x": -17,
      "y": 1,
      "z": 9,
      "name": "Cloth_Block_Wool_Gray"
    },
    {
      "x": -17,
      "y": 7,
      "z": 9,
      "name": "Wood_Softwood_Stairs",
      "rotation": 10
    },
    {
      "x": -17,
      "y": 8,
      "z": 9,
      "name": "Wood_Softwood_Roof_Shallow",
      "rotation": 2
    },
    {
      "x": -17,
      "y": 1,
      "z": 10,
      "name": "Cloth_Block_Wool_Gray_Light"
    },
    {
      "x": -17,
      "y": 8,
      "z": 10,
      "name": "Wood_Softwood_Roof_Shallow",
      "filler": 32,
      "rotation": 2
    },
    {
      "x": -17,
      "y": 1,
      "z": 11,
      "name": "Cloth_Block_Wool_Gray"
    },
    {
      "x": -17,
      "y": 8,
      "z": 11,
      "name": "Wood_Softwood_Roof_Shallow",
      "filler": 992
    },
    {
      "x": -17,
      "y": 1,
      "z": 12,
      "name": "Cloth_Block_Wool_Gray_Light"
    },
    {
      "x": -17,
      "y": 7,
      "z": 12,
      "name": "Wood_Softwood_Stairs",
      "rotation": 8
    },
    {
      "x": -17,
      "y": 8,
      "z": 12,
      "name": "Wood_Softwood_Roof_Shallow"
    },
    {
      "x": -17,
      "y": 1,
      "z": 13,
      "name": "Wood_Drywood_Planks"
    },
    {
      "x": -17,
      "y": 7,
      "z": 13,
      "name": "Wood_Softwood_Roof_Shallow",
      "filler": 992
    },
    {
      "x": -17,
      "y": 1,
      "z": 14,
      "name": "Rock_Stone_Brick"
    },
    {
      "x": -17,
      "y": 2,
      "z": 14,
      "name": "Rock_Stone_Brick"
    },
    {
      "x": -17,
      "y": 3,
      "z": 14,
      "name": "*Wood_Village_Wall_Full_State_Definitions_Bottom"
    },
    {
      "x": -17,
      "y": 4,
      "z": 14,
      "name": "*Wood_Village_Wall_Full_State_Definitions_Middle"
    },
    {
      "x": -17,
      "y": 5,
      "z": 14,
      "name": "*Wood_Village_Wall_Full_State_Definitions_Top"
    },
    {
      "x": -17,
      "y": 6,
      "z": 14,
      "name": "Wood_Beech_Trunk",
      "support": 15,
      "rotation": 5
    },
    {
      "x": -17,
      "y": 7,
      "z": 14,
      "name": "Wood_Softwood_Roof_Shallow"
    },
    {
      "x": -17,
      "y": 1,
      "z": 15,
      "name": "Rock_Stone_Cobble"
    },
    {
      "x": -17,
      "y": 2,
      "z": 15,
      "name": "Ingredient_Hay"
    },
    {
      "x": -17,
      "y": 6,
      "z": 15,
      "name": "Wood_Softwood_Roof_Hollow"
    },
    {
      "x": -17,
      "y": 1,
      "z": 16,
      "name": "Rock_Stone_Cobble"
    },
    {
      "x": -17,
      "y": 2,
      "z": 16,
      "name": "Ingredient_Hay"
    },
    {
      "x": -17,
      "y": 1,
      "z": 17,
      "name": "Rock_Stone_Cobble"
    },
    {
      "x": -17,
      "y": 1,
      "z": 18,
      "name": "Rock_Stone_Cobble"
    },
    {
      "x": -17,
      "y": 1,
      "z": 19,
      "name": "Rock_Stone_Cobble"
    },
    {
      "x": -17,
      "y": 2,
      "z": 19,
      "name": "Rock_Stone_Brick_Wall"
    },
    {
      "x": -17,
      "y": 3,
      "z": 19,
      "name": "Wood_Softwood_Fence"
    },
    {
      "x": -17,
      "y": 1,
      "z": 20,
      "name": "Rock_Stone_Cobble"
    },
    {
      "x": -16,
      "y": 1,
      "z": 1,
      "name": "Rock_Stone_Cobble"
    },
    {
      "x": -16,
      "y": 1,
      "z": 2,
      "name": "Rock_Stone_Cobble"
    },
    {
      "x": -16,
      "y": 1,
      "z": 3,
      "name": "Rock_Stone_Cobble"
    },
    {
      "x": -16,
      "y": 2,
      "z": 3,
      "name": "Furniture_Tavern_Barrel",
      "support": 15
    },
    {
      "x": -16,
      "y": 1,
      "z": 4,
      "name": "Rock_Stone_Cobble"
    },
    {
      "x": -16,
      "y": 1,
      "z": 5,
      "name": "Rock_Stone_Cobble"
    },
    {
      "x": -16,
      "y": 1,
      "z": 6,
      "name": "Rock_Stone_Cobble"
    },
    {
      "x": -16,
      "y": 2,
      "z": 6,
      "name": "Furniture_Tavern_Planter",
      "support": 15
    },
    {
      "x": -16,
      "y": 3,
      "z": 6,
      "name": "Plant_Flower_Tall_Pink",
      "support": 15
    },
    {
      "x": -16,
      "y": 6,
      "z": 6,
      "name": "Wood_Softwood_Roof_Hollow",
      "rotation": 2
    },
    {
      "x": -16,
      "y": 1,
      "z": 7,
      "name": "Rock_Stone_Brick"
    },
    {
      "x": -16,
      "y": 2,
      "z": 7,
      "name": "Wood_Beech_Trunk",
      "support": 15
    },
    {
      "x": -16,
      "y": 3,
      "z": 7,
      "name": "Wood_Beech_Trunk",
      "support": 15
    },
    {
      "x": -16,
      "y": 4,
      "z": 7,
      "name": "Wood_Beech_Trunk",
      "support": 15
    },
    {
      "x": -16,
      "y": 5,
      "z": 7,
      "name": "Wood_Beech_Trunk",
      "support": 15
    },
    {
      "x": -16,
      "y": 6,
      "z": 7,
      "name": "Wood_Beech_Trunk",
      "support": 15
    },
    {
      "x": -16,
      "y": 7,
      "z": 7,
      "name": "Wood_Softwood_Roof_Shallow",
      "rotation": 2
    },
    {
      "x": -16,
      "y": 1,
      "z": 8,
      "name": "Wood_Drywood_Planks"
    },
    {
      "x": -16,
      "y": 5,
      "z": 8,
      "name": "Deco_Lantern_Ceiling",
      "support": 15
    },
    {
      "x": -16,
      "y": 6,
      "z": 8,
      "name": "Deco_Rope",
      "support": 15
    },
    {
      "x": -16,
      "y": 7,
      "z": 8,
      "name": "Wood_Softwood_Roof_Shallow",
      "filler": 32,
      "rotation": 2
    },
    {
      "x": -16,
      "y": 1,
      "z": 9,
      "name": "Cloth_Block_Wool_Gray_Light"
    },
    {
      "x": -16,
      "y": 2,
      "z": 9,
      "name": "Furniture_Tavern_Bench",
      "support": 15,
      "filler": 31
    },
    {
      "x": -16,
      "y": 7,
      "z": 9,
      "name": "Wood_Softwood_Stairs",
      "rotation": 10
    },
    {
      "x": -16,
      "y": 8,
      "z": 9,
      "name": "Wood_Softwood_Roof_Shallow",
      "rotation": 2
    },
    {
      "x": -16,
      "y": 1,
      "z": 10,
      "name": "Cloth_Block_Wool_Gray"
    },
    {
      "x": -16,
      "y": 2,
      "z": 10,
      "name": "Furniture_Village_Table",
      "support": 15
    },
    {
      "x": -16,
      "y": 8,
      "z": 10,
      "name": "Wood_Softwood_Roof_Shallow",
      "filler": 32,
      "rotation": 2
    },
    {
      "x": -16,
      "y": 1,
      "z": 11,
      "name": "Cloth_Block_Wool_Gray_Light"
    },
    {
      "x": -16,
      "y": 2,
      "z": 11,
      "name": "Furniture_Village_Table",
      "support": 15,
      "filler": 32
    },
    {
      "x": -16,
      "y": 8,
      "z": 11,
      "name": "Wood_Softwood_Roof_Shallow",
      "filler": 992
    },
    {
      "x": -16,
      "y": 1,
      "z": 12,
      "name": "Cloth_Block_Wool_Gray"
    },
    {
      "x": -16,
      "y": 2,
      "z": 12,
      "name": "Furniture_Tavern_Bench",
      "support": 15,
      "rotation": 2
    },
    {
      "x": -16,
      "y": 7,
      "z": 12,
      "name": "Wood_Softwood_Stairs",
      "rotation": 8
    },
    {
      "x": -16,
      "y": 8,
      "z": 12,
      "name": "Wood_Softwood_Roof_Shallow"
    },
    {
      "x": -16,
      "y": 1,
      "z": 13,
      "name": "Wood_Drywood_Planks"
    },
    {
      "x": -16,
      "y": 5,
      "z": 13,
      "name": "Deco_Lantern_Ceiling",
      "support": 15
    },
    {
      "x": -16,
      "y": 6,
      "z": 13,
      "name": "Deco_Rope",
      "support": 15
    },
    {
      "x": -16,
      "y": 7,
      "z": 13,
      "name": "Wood_Softwood_Roof_Shallow",
      "filler": 992
    },
    {
      "x": -16,
      "y": 1,
      "z": 14,
      "name": "Rock_Stone_Brick"
    },
    {
      "x": -16,
      "y": 2,
      "z": 14,
      "name": "Wood_Beech_Trunk",
      "support": 15
    },
    {
      "x": -16,
      "y": 3,
      "z": 14,
      "name": "Wood_Beech_Trunk",
      "support": 15
    },
    {
      "x": -16,
      "y": 4,
      "z": 14,
      "name": "Wood_Beech_Trunk",
      "support": 15
    },
    {
      "x": -16,
      "y": 5,
      "z": 14,
      "name": "Wood_Beech_Trunk",
      "support": 15
    },
    {
      "x": -16,
      "y": 6,
      "z": 14,
      "name": "Wood_Beech_Trunk",
      "support": 15
    },
    {
      "x": -16,
      "y": 7,
      "z": 14,
      "name": "Wood_Softwood_Roof_Shallow"
    },
    {
      "x": -16,
      "y": 1,
      "z": 15,
      "name": "Rock_Stone_Cobble"
    },
    {
      "x": -16,
      "y": 2,
      "z": 15,
      "name": "Ingredient_Hay"
    },
    {
      "x": -16,
      "y": 3,
      "z": 15,
      "name": "Plant_Hay_Bundle",
      "support": 15
    },
    {
      "x": -16,
      "y": 6,
      "z": 15,
      "name": "Wood_Softwood_Roof_Hollow"
    },
    {
      "x": -16,
      "y": 1,
      "z": 16,
      "name": "Rock_Stone_Cobble"
    },
    {
      "x": -16,
      "y": 1,
      "z": 17,
      "name": "Rock_Stone_Cobble"
    },
    {
      "x": -16,
      "y": 1,
      "z": 18,
      "name": "Rock_Stone_Cobble"
    },
    {
      "x": -16,
      "y": 1,
      "z": 19,
      "name": "Rock_Stone_Cobble"
    },
    {
      "x": -16,
      "y": 2,
      "z": 19,
      "name": "Rock_Stone_Brick_Wall"
    },
    {
      "x": -16,
      "y": 3,
      "z": 19,
      "name": "Wood_Softwood_Fence"
    },
    {
      "x": -16,
      "y": 1,
      "z": 20,
      "name": "Rock_Stone_Cobble"
    },
    {
      "x": -15,
      "y": 1,
      "z": 1,
      "name": "Rock_Stone_Cobble"
    },
    {
      "x": -15,
      "y": 1,
      "z": 2,
      "name": "Rock_Stone_Cobble"
    },
    {
      "x": -15,
      "y": 1,
      "z": 3,
      "name": "Rock_Stone_Cobble"
    },
    {
      "x": -15,
      "y": 1,
      "z": 4,
      "name": "Rock_Stone_Cobble"
    },
    {
      "x": -15,
      "y": 1,
      "z": 5,
      "name": "Rock_Stone_Cobble"
    },
    {
      "x": -15,
      "y": 1,
      "z": 6,
      "name": "Rock_Stone_Cobble"
    },
    {
      "x": -15,
      "y": 6,
      "z": 6,
      "name": "Wood_Softwood_Roof_Hollow",
      "rotation": 2
    },
    {
      "x": -15,
      "y": 1,
      "z": 7,
      "name": "Rock_Stone_Brick"
    },
    {
      "x": -15,
      "y": 2,
      "z": 7,
      "name": "Rock_Stone_Brick"
    },
    {
      "x": -15,
      "y": 3,
      "z": 7,
      "name": "*Wood_Village_Wall_Full_State_Definitions_Bottom"
    },
    {
      "x": -15,
      "y": 4,
      "z": 7,
      "name": "*Wood_Village_Wall_Full_State_Definitions_Middle"
    },
    {
      "x": -15,
      "y": 5,
      "z": 7,
      "name": "*Wood_Village_Wall_Full_State_Definitions_Top"
    },
    {
      "x": -15,
      "y": 6,
      "z": 7,
      "name": "Wood_Beech_Trunk",
      "support": 15,
      "rotation": 5
    },
    {
      "x": -15,
      "y": 7,
      "z": 7,
      "name": "Wood_Softwood_Roof_Shallow",
      "rotation": 2
    },
    {
      "x": -15,
      "y": 1,
      "z": 8,
      "name": "Wood_Drywood_Planks"
    },
    {
      "x": -15,
      "y": 7,
      "z": 8,
      "name": "Wood_Softwood_Roof_Shallow",
      "filler": 32,
      "rotation": 2
    },
    {
      "x": -15,
      "y": 1,
      "z": 9,
      "name": "Cloth_Block_Wool_Gray"
    },
    {
      "x": -15,
      "y": 2,
      "z": 9,
      "name": "Furniture_Tavern_Bench",
      "support": 15
    },
    {
      "x": -15,
      "y": 7,
      "z": 9,
      "name": "Wood_Softwood_Stairs",
      "rotation": 10
    },
    {
      "x": -15,
      "y": 8,
      "z": 9,
      "name": "Wood_Softwood_Roof_Shallow",
      "rotation": 2
    },
    {
      "x": -15,
      "y": 1,
      "z": 10,
      "name": "Cloth_Block_Wool_Gray_Light"
    },
    {
      "x": -15,
      "y": 2,
      "z": 10,
      "name": "Furniture_Village_Table",
      "support": 15,
      "filler": 1
    },
    {
      "x": -15,
      "y": 8,
      "z": 10,
      "name": "Wood_Softwood_Roof_Shallow",
      "filler": 32,
      "rotation": 2
    },
    {
      "x": -15,
      "y": 1,
      "z": 11,
      "name": "Cloth_Block_Wool_Gray"
    },
    {
      "x": -15,
      "y": 2,
      "z": 11,
      "name": "Furniture_Village_Table",
      "support": 15,
      "filler": 33
    },
    {
      "x": -15,
      "y": 3,
      "z": 11,
      "name": "Deco_Book_Pile_Small",
      "rotation": 1
    },
    {
      "x": -15,
      "y": 8,
      "z": 11,
      "name": "Wood_Softwood_Roof_Shallow",
      "filler": 992
    },
    {
      "x": -15,
      "y": 1,
      "z": 12,
      "name": "Cloth_Block_Wool_Gray_Light"
    },
    {
      "x": -15,
      "y": 2,
      "z": 12,
      "name": "Furniture_Tavern_Bench",
      "support": 15,
      "filler": 1,
      "rotation": 2
    },
    {
      "x": -15,
      "y": 7,
      "z": 12,
      "name": "Wood_Softwood_Stairs",
      "rotation": 8
    },
    {
      "x": -15,
      "y": 8,
      "z": 12,
      "name": "Wood_Softwood_Roof_Shallow"
    },
    {
      "x": -15,
      "y": 1,
      "z": 13,
      "name": "Wood_Drywood_Planks"
    },
    {
      "x": -15,
      "y": 7,
      "z": 13,
      "name": "Wood_Softwood_Roof_Shallow",
      "filler": 992
    },
    {
      "x": -15,
      "y": 1,
      "z": 14,
      "name": "Rock_Stone_Brick"
    },
    {
      "x": -15,
      "y": 2,
      "z": 14,
      "name": "Rock_Stone_Brick"
    },
    {
      "x": -15,
      "y": 3,
      "z": 14,
      "name": "*Wood_Village_Wall_Full_State_Definitions_Bottom"
    },
    {
      "x": -15,
      "y": 4,
      "z": 14,
      "name": "*Wood_Village_Wall_Full_State_Definitions_Middle"
    },
    {
      "x": -15,
      "y": 5,
      "z": 14,
      "name": "*Wood_Village_Wall_Full_State_Definitions_Top"
    },
    {
      "x": -15,
      "y": 6,
      "z": 14,
      "name": "Wood_Beech_Trunk",
      "support": 15,
      "rotation": 5
    },
    {
      "x": -15,
      "y": 7,
      "z": 14,
      "name": "Wood_Softwood_Roof_Shallow"
    },
    {
      "x": -15,
      "y": 1,
      "z": 15,
      "name": "Rock_Stone_Cobble"
    },
    {
      "x": -15,
      "y": 6,
      "z": 15,
      "name": "Wood_Softwood_Roof_Hollow"
    },
    {
      "x": -15,
      "y": 1,
      "z": 16,
      "name": "Rock_Stone_Cobble"
    },
    {
      "x": -15,
      "y": 1,
      "z": 17,
      "name": "Rock_Stone_Cobble"
    },
    {
      "x": -15,
      "y": 1,
      "z": 18,
      "name": "Rock_Stone_Cobble"
    },
    {
      "x": -15,
      "y": 1,
      "z": 19,
      "name": "Rock_Stone_Cobble"
    },
    {
      "x": -15,
      "y": 2,
      "z": 19,
      "name": "Rock_Stone_Brick_Wall"
    },
    {
      "x": -15,
      "y": 3,
      "z": 19,
      "name": "Wood_Softwood_Fence"
    },
    {
      "x": -15,
      "y": 1,
      "z": 20,
      "name": "Rock_Stone_Cobble"
    },
    {
      "x": -14,
      "y": 1,
      "z": 1,
      "name": "Rock_Stone_Cobble"
    },
    {
      "x": -14,
      "y": 1,
      "z": 2,
      "name": "Rock_Stone_Cobble"
    },
    {
      "x": -14,
      "y": 1,
      "z": 3,
      "name": "Rock_Stone_Cobble"
    },
    {
      "x": -14,
      "y": 1,
      "z": 4,
      "name": "Rock_Stone_Cobble"
    },
    {
      "x": -14,
      "y": 1,
      "z": 5,
      "name": "Rock_Stone_Cobble"
    },
    {
      "x": -14,
      "y": 1,
      "z": 6,
      "name": "Rock_Stone_Cobble"
    },
    {
      "x": -14,
      "y": 2,
      "z": 6,
      "name": "Furniture_Tavern_Barrel",
      "support": 15
    },
    {
      "x": -14,
      "y": 6,
      "z": 6,
      "name": "Wood_Softwood_Roof_Hollow",
      "rotation": 2
    },
    {
      "x": -14,
      "y": 1,
      "z": 7,
      "name": "Rock_Stone_Cobble"
    },
    {
      "x": -14,
      "y": 2,
      "z": 7,
      "name": "Rock_Stone_Brick"
    },
    {
      "x": -14,
      "y": 3,
      "z": 7,
      "name": "Furniture_Village_Window"
    },
    {
      "x": -14,
      "y": 4,
      "z": 7,
      "name": "Furniture_Village_Window"
    },
    {
      "x": -14,
      "y": 5,
      "z": 7,
      "name": "Wood_Softwood_Stairs",
      "rotation": 8
    },
    {
      "x": -14,
      "y": 6,
      "z": 7,
      "name": "Wood_Beech_Trunk",
      "support": 15,
      "rotation": 5
    },
    {
      "x": -14,
      "y": 7,
      "z": 7,
      "name": "Wood_Softwood_Roof_Shallow",
      "rotation": 2
    },
    {
      "x": -14,
      "y": 1,
      "z": 8,
      "name": "Wood_Drywood_Planks"
    },
    {
      "x": -14,
      "y": 7,
      "z": 8,
      "name": "Wood_Softwood_Roof_Shallow",
      "filler": 32,
      "rotation": 2
    },
    {
      "x": -14,
      "y": 1,
      "z": 9,
      "name": "Cloth_Block_Wool_Gray_Light"
    },
    {
      "x": -14,
      "y": 7,
      "z": 9,
      "name": "Wood_Softwood_Stairs",
      "rotation": 10
    },
    {
      "x": -14,
      "y": 8,
      "z": 9,
      "name": "Wood_Softwood_Roof_Shallow",
      "rotation": 2
    },
    {
      "x": -14,
      "y": 1,
      "z": 10,
      "name": "Cloth_Block_Wool_Gray"
    },
    {
      "x": -14,
      "y": 8,
      "z": 10,
      "name": "Wood_Softwood_Roof_Shallow",
      "filler": 32,
      "rotation": 2
    },
    {
      "x": -14,
      "y": 1,
      "z": 11,
      "name": "Cloth_Block_Wool_Gray_Light"
    },
    {
      "x": -14,
      "y": 8,
      "z": 11,
      "name": "Wood_Softwood_Roof_Shallow",
      "filler": 992
    },
    {
      "x": -14,
      "y": 1,
      "z": 12,
      "name": "Cloth_Block_Wool_Gray"
    },
    {
      "x": -14,
      "y": 7,
      "z": 12,
      "name": "Wood_Softwood_Stairs",
      "rotation": 8
    },
    {
      "x": -14,
      "y": 8,
      "z": 12,
      "name": "Wood_Softwood_Roof_Shallow"
    },
    {
      "x": -14,
      "y": 1,
      "z": 13,
      "name": "Wood_Drywood_Planks"
    },
    {
      "x": -14,
      "y": 7,
      "z": 13,
      "name": "Wood_Softwood_Roof_Shallow",
      "filler": 992
    },
    {
      "x": -14,
      "y": 1,
      "z": 14,
      "name": "Rock_Stone_Cobble"
    },
    {
      "x": -14,
      "y": 2,
      "z": 14,
      "name": "Rock_Stone_Brick"
    },
    {
      "x": -14,
      "y": 3,
      "z": 14,
      "name": "Furniture_Village_Window"
    },
    {
      "x": -14,
      "y": 4,
      "z": 14,
      "name": "Furniture_Village_Window"
    },
    {
      "x": -14,
      "y": 5,
      "z": 14,
      "name": "Wood_Softwood_Stairs",
      "rotation": 10
    },
    {
      "x": -14,
      "y": 6,
      "z": 14,
      "name": "Wood_Beech_Trunk",
      "support": 15,
      "rotation": 5
    },
    {
      "x": -14,
      "y": 7,
      "z": 14,
      "name": "Wood_Softwood_Roof_Shallow"
    },
    {
      "x": -14,
      "y": 1,
      "z": 15,
      "name": "Rock_Stone_Cobble"
    },
    {
      "x": -14,
      "y": 6,
      "z": 15,
      "name": "Wood_Softwood_Roof_Hollow"
    },
    {
      "x": -14,
      "y": 1,
      "z": 16,
      "name": "Rock_Stone_Cobble"
    },
    {
      "x": -14,
      "y": 1,
      "z": 17,
      "name": "Rock_Stone_Cobble"
    },
    {
      "x": -14,
      "y": 1,
      "z": 18,
      "name": "Rock_Stone_Cobble"
    },
    {
      "x": -14,
      "y": 1,
      "z": 19,
      "name": "Rock_Stone_Cobble"
    },
    {
      "x": -14,
      "y": 2,
      "z": 19,
      "name": "Rock_Stone_Brick_Wall"
    },
    {
      "x": -14,
      "y": 3,
      "z": 19,
      "name": "Wood_Softwood_Fence"
    },
    {
      "x": -14,
      "y": 1,
      "z": 20,
      "name": "Rock_Stone_Cobble"
    },
    {
      "x": -13,
      "y": 1,
      "z": 1,
      "name": "Rock_Stone_Cobble"
    },
    {
      "x": -13,
      "y": 1,
      "z": 2,
      "name": "Rock_Stone_Cobble"
    },
    {
      "x": -13,
      "y": 1,
      "z": 3,
      "name": "Rock_Stone_Cobble"
    },
    {
      "x": -13,
      "y": 1,
      "z": 4,
      "name": "Rock_Stone_Cobble"
    },
    {
      "x": -13,
      "y": 1,
      "z": 5,
      "name": "Rock_Stone_Cobble"
    },
    {
      "x": -13,
      "y": 1,
      "z": 6,
      "name": "Rock_Stone_Cobble"
    },
    {
      "x": -13,
      "y": 2,
      "z": 6,
      "name": "Furniture_Village_Crate"
    },
    {
      "x": -13,
      "y": 3,
      "z": 6,
      "name": "Furniture_Tavern_Barrel",
      "support": 15
    },
    {
      "x": -13,
      "y": 5,
      "z": 6,
      "name": "Plant_Vine_Wall",
      "support": 15,
      "rotation": 2
    },
    {
      "x": -13,
      "y": 6,
      "z": 6,
      "name": "Wood_Softwood_Roof_Hollow",
      "rotation": 2
    },
    {
      "x": -13,
      "y": 1,
      "z": 7,
      "name": "Rock_Stone_Cobble"
    },
    {
      "x": -13,
      "y": 2,
      "z": 7,
      "name": "Rock_Stone_Brick"
    },
    {
      "x": -13,
      "y": 3,
      "z": 7,
      "name": "*Wood_Village_Wall_Full_State_Definitions_Bottom"
    },
    {
      "x": -13,
      "y": 4,
      "z": 7,
      "name": "*Wood_Village_Wall_Full_State_Definitions_Middle"
    },
    {
      "x": -13,
      "y": 5,
      "z": 7,
      "name": "*Wood_Village_Wall_Full_State_Definitions_Top"
    },
    {
      "x": -13,
      "y": 6,
      "z": 7,
      "name": "Wood_Beech_Trunk",
      "support": 15,
      "rotation": 5
    },
    {
      "x": -13,
      "y": 7,
      "z": 7,
      "name": "Wood_Softwood_Roof_Shallow",
      "rotation": 2
    },
    {
      "x": -13,
      "y": 1,
      "z": 8,
      "name": "Wood_Drywood_Planks"
    },
    {
      "x": -13,
      "y": 2,
      "z": 8,
      "name": "Furniture_Village_Bookcase",
      "support": 15,
      "rotation": 3
    },
    {
      "x": -13,
      "y": 3,
      "z": 8,
      "name": "Furniture_Village_Bookcase",
      "support": 15,
      "rotation": 3
    },
    {
      "x": -13,
      "y": 4,
      "z": 8,
      "name": "Furniture_Village_Bookcase",
      "support": 15,
      "rotation": 3
    },
    {
      "x": -13,
      "y": 5,
      "z": 8,
      "name": "Furniture_Village_Bookcase",
      "support": 15,
      "rotation": 3
    },
    {
      "x": -13,
      "y": 6,
      "z": 8,
      "name": "Wood_Beech_Trunk",
      "support": 15,
      "rotation": 4
    },
    {
      "x": -13,
      "y": 7,
      "z": 8,
      "name": "Wood_Softwood_Roof_Shallow",
      "filler": 32,
      "rotation": 2
    },
    {
      "x": -13,
      "y": 1,
      "z": 9,
      "name": "Wood_Drywood_Planks"
    },
    {
      "x": -13,
      "y": 6,
      "z": 9,
      "name": "Wood_Beech_Trunk",
      "support": 15,
      "rotation": 4
    },
    {
      "x": -13,
      "y": 7,
      "z": 9,
      "name": "Wood_Village_Wall_Full"
    },
    {
      "x": -13,
      "y": 8,
      "z": 9,
      "name": "Wood_Softwood_Roof_Shallow",
      "rotation": 2
    },
    {
      "x": -13,
      "y": 1,
      "z": 10,
      "name": "Wood_Drywood_Planks"
    },
    {
      "x": -13,
      "y": 6,
      "z": 10,
      "name": "Wood_Beech_Trunk",
      "support": 15,
      "rotation": 4
    },
    {
      "x": -13,
      "y": 7,
      "z": 10,
      "name": "Wood_Village_Wall_Full"
    },
    {
      "x": -13,
      "y": 8,
      "z": 10,
      "name": "Wood_Softwood_Roof_Shallow",
      "filler": 32,
      "rotation": 2
    },
    {
      "x": -13,
      "y": 1,
      "z": 11,
      "name": "Wood_Drywood_Planks"
    },
    {
      "x": -13,
      "y": 6,
      "z": 11,
      "name": "Wood_Beech_Trunk",
      "support": 15,
      "rotation": 4
    },
    {
      "x": -13,
      "y": 7,
      "z": 11,
      "name": "Wood_Village_Wall_Full"
    },
    {
      "x": -13,
      "y": 8,
      "z": 11,
      "name": "Wood_Softwood_Roof_Shallow",
      "filler": 992
    },
    {
      "x": -13,
      "y": 1,
      "z": 12,
      "name": "Wood_Drywood_Planks"
    },
    {
      "x": -13,
      "y": 6,
      "z": 12,
      "name": "Wood_Beech_Trunk",
      "support": 15,
      "rotation": 4
    },
    {
      "x": -13,
      "y": 7,
      "z": 12,
      "name": "Wood_Village_Wall_Full"
    },
    {
      "x": -13,
      "y": 8,
      "z": 12,
      "name": "Wood_Softwood_Roof_Shallow"
    },
    {
      "x": -13,
      "y": 1,
      "z": 13,
      "name": "Wood_Drywood_Planks"
    },
    {
      "x": -13,
      "y": 2,
      "z": 13,
      "name": "Furniture_Village_Bookcase",
      "support": 15,
      "rotation": 3
    },
    {
      "x": -13,
      "y": 3,
      "z": 13,
      "name": "Furniture_Village_Bookcase",
      "support": 15,
      "rotation": 3
    },
    {
      "x": -13,
      "y": 4,
      "z": 13,
      "name": "Furniture_Village_Bookcase",
      "support": 15,
      "rotation": 3
    },
    {
      "x": -13,
      "y": 5,
      "z": 13,
      "name": "Furniture_Village_Bookcase",
      "support": 15,
      "rotation": 3
    },
    {
      "x": -13,
      "y": 6,
      "z": 13,
      "name": "Wood_Beech_Trunk",
      "support": 15,
      "rotation": 4
    },
    {
      "x": -13,
      "y": 7,
      "z": 13,
      "name": "Wood_Softwood_Roof_Shallow",
      "filler": 992
    },
    {
      "x": -13,
      "y": 1,
      "z": 14,
      "name": "Rock_Stone_Cobble"
    },
    {
      "x": -13,
      "y": 2,
      "z": 14,
      "name": "Rock_Stone_Brick"
    },
    {
      "x": -13,
      "y": 3,
      "z": 14,
      "name": "*Wood_Village_Wall_Full_State_Definitions_Bottom"
    },
    {
      "x": -13,
      "y": 4,
      "z": 14,
      "name": "*Wood_Village_Wall_Full_State_Definitions_Middle"
    },
    {
      "x": -13,
      "y": 5,
      "z": 14,
      "name": "*Wood_Village_Wall_Full_State_Definitions_Top"
    },
    {
      "x": -13,
      "y": 6,
      "z": 14,
      "name": "Wood_Beech_Trunk",
      "support": 15,
      "rotation": 5
    },
    {
      "x": -13,
      "y": 7,
      "z": 14,
      "name": "Wood_Softwood_Roof_Shallow"
    },
    {
      "x": -13,
      "y": 1,
      "z": 15,
      "name": "Rock_Stone_Cobble"
    },
    {
      "x": -13,
      "y": 2,
      "z": 15,
      "name": "Furniture_Tavern_Barrel",
      "support": 15
    },
    {
      "x": -13,
      "y": 6,
      "z": 15,
      "name": "Wood_Softwood_Roof_Hollow"
    },
    {
      "x": -13,
      "y": 1,
      "z": 16,
      "name": "Rock_Stone_Cobble"
    },
    {
      "x": -13,
      "y": 1,
      "z": 17,
      "name": "Rock_Stone_Cobble"
    },
    {
      "x": -13,
      "y": 1,
      "z": 18,
      "name": "Rock_Stone_Cobble"
    },
    {
      "x": -13,
      "y": 1,
      "z": 19,
      "name": "Rock_Stone_Cobble"
    },
    {
      "x": -13,
      "y": 2,
      "z": 19,
      "name": "Rock_Stone_Brick_Wall"
    },
    {
      "x": -13,
      "y": 3,
      "z": 19,
      "name": "Wood_Softwood_Fence"
    },
    {
      "x": -13,
      "y": 1,
      "z": 20,
      "name": "Rock_Stone_Cobble"
    },
    {
      "x": -12,
      "y": 1,
      "z": 1,
      "name": "Rock_Stone_Cobble"
    },
    {
      "x": -12,
      "y": 6,
      "z": 1,
      "name": "Wood_Softwood_Roof_Hollow",
      "rotation": 3
    },
    {
      "x": -12,
      "y": 1,
      "z": 2,
      "name": "Rock_Stone_Cobble"
    },
    {
      "x": -12,
      "y": 5,
      "z": 2,
      "name": "Wood_Beech_Branch_Corner",
      "support": 15,
      "rotation": 3
    },
    {
      "x": -12,
      "y": 6,
      "z": 2,
      "name": "Wood_Softwood_Roof",
      "rotation": 3
    },
    {
      "x": -12,
      "y": 1,
      "z": 3,
      "name": "Rock_Stone_Cobble"
    },
    {
      "x": -12,
      "y": 6,
      "z": 3,
      "name": "Wood_Softwood_Roof_Hollow",
      "rotation": 3
    },
    {
      "x": -12,
      "y": 1,
      "z": 4,
      "name": "Rock_Stone_Cobble"
    },
    {
      "x": -12,
      "y": 6,
      "z": 4,
      "name": "Wood_Softwood_Roof_Hollow",
      "rotation": 3
    },
    {
      "x": -12,
      "y": 1,
      "z": 5,
      "name": "Rock_Stone_Cobble"
    },
    {
      "x": -12,
      "y": 2,
      "z": 5,
      "name": "Furniture_Tavern_Barrel",
      "support": 15
    },
    {
      "x": -12,
      "y": 4,
      "z": 5,
      "name": "Plant_Vine_Wall",
      "support": 15,
      "rotation": 3
    },
    {
      "x": -12,
      "y": 5,
      "z": 5,
      "name": "Plant_Vine",
      "support": 15,
      "rotation": 3
    },
    {
      "x": -12,
      "y": 6,
      "z": 5,
      "name": "Wood_Softwood_Roof_Hollow",
      "rotation": 3
    },
    {
      "x": -12,
      "y": 1,
      "z": 6,
      "name": "Rock_Stone_Cobble"
    },
    {
      "x": -12,
      "y": 2,
      "z": 6,
      "name": "Furniture_Village_Crate"
    },
    {
      "x": -12,
      "y": 3,
      "z": 6,
      "name": "Furniture_Village_Crate"
    },
    {
      "x": -12,
      "y": 4,
      "z": 6,
      "name": "Furniture_Tavern_Barrel",
      "support": 15
    },
    {
      "x": -12,
      "y": 5,
      "z": 6,
      "name": "Wood_Beech_Branch_Corner",
      "support": 15,
      "rotation": 2
    },
    {
      "x": -12,
      "y": 6,
      "z": 6,
      "name": "*Wood_Softwood_Roof_State_Definitions_Inverted_Corner_Left",
      "rotation": 2
    },
    {
      "x": -12,
      "y": 1,
      "z": 7,
      "name": "Rock_Stone_Cobble"
    },
    {
      "x": -12,
      "y": 2,
      "z": 7,
      "name": "Wood_Beech_Trunk",
      "support": 15
    },
    {
      "x": -12,
      "y": 3,
      "z": 7,
      "name": "Wood_Beech_Trunk",
      "support": 15
    },
    {
      "x": -12,
      "y": 4,
      "z": 7,
      "name": "Wood_Beech_Trunk",
      "support": 15
    },
    {
      "x": -12,
      "y": 5,
      "z": 7,
      "name": "Wood_Beech_Trunk",
      "support": 15
    },
    {
      "x": -12,
      "y": 6,
      "z": 7,
      "name": "Wood_Beech_Trunk",
      "support": 15
    },
    {
      "x": -12,
      "y": 7,
      "z": 7,
      "name": "Wood_Softwood_Roof_Shallow",
      "rotation": 2
    },
    {
      "x": -12,
      "y": 1,
      "z": 8,
      "name": "Rock_Stone_Cobble"
    },
    {
      "x": -12,
      "y": 2,
      "z": 8,
      "name": "Rock_Stone_Brick"
    },
    {
      "x": -12,
      "y": 3,
      "z": 8,
      "name": "*Wood_Village_Wall_Full_State_Definitions_Bottom"
    },
    {
      "x": -12,
      "y": 4,
      "z": 8,
      "name": "*Wood_Village_Wall_Full_State_Definitions_Middle"
    },
    {
      "x": -12,
      "y": 5,
      "z": 8,
      "name": "*Wood_Village_Wall_Full_State_Definitions_Middle"
    },
    {
      "x": -12,
      "y": 6,
      "z": 8,
      "name": "*Wood_Village_Wall_Full_State_Definitions_Top"
    },
    {
      "x": -12,
      "y": 7,
      "z": 8,
      "name": "Wood_Softwood_Roof_Shallow",
      "filler": 32,
      "rotation": 2
    },
    {
      "x": -12,
      "y": 1,
      "z": 9,
      "name": "Rock_Stone_Cobble"
    },
    {
      "x": -12,
      "y": 2,
      "z": 9,
      "name": "Wood_Softwood_Planks_Half",
      "rotation": 4
    },
    {
      "x": -12,
      "y": 3,
      "z": 9,
      "name": "Wood_Softwood_Planks_Half",
      "rotation": 4
    },
    {
      "x": -12,
      "y": 4,
      "z": 9,
      "name": "Wood_Softwood_Planks_Half",
      "rotation": 4
    },
    {
      "x": -12,
      "y": 5,
      "z": 9,
      "name": "Wood_Softwood_Stairs",
      "rotation": 10
    },
    {
      "x": -12,
      "y": 6,
      "z": 9,
      "name": "*Wood_Village_Wall_Full_State_Definitions_Bottom"
    },
    {
      "x": -12,
      "y": 7,
      "z": 9,
      "name": "*Wood_Village_Wall_Full_State_Definitions_Top"
    },
    {
      "x": -12,
      "y": 8,
      "z": 9,
      "name": "Wood_Softwood_Roof_Shallow",
      "rotation": 2
    },
    {
      "x": -12,
      "y": 1,
      "z": 10,
      "name": "Wood_Drywood_Planks"
    },
    {
      "x": -12,
      "y": 5,
      "z": 10,
      "name": "Wood_Softwood_Planks_Half",
      "rotation": 8
    },
    {
      "x": -12,
      "y": 6,
      "z": 10,
      "name": "*Wood_Village_Wall_Full_State_Definitions_Bottom"
    },
    {
      "x": -12,
      "y": 7,
      "z": 10,
      "name": "*Wood_Village_Wall_Full_State_Definitions_Top"
    },
    {
      "x": -12,
      "y": 8,
      "z": 10,
      "name": "Wood_Softwood_Roof_Shallow",
      "filler": 32,
      "rotation": 2
    },
    {
      "x": -12,
      "y": 1,
      "z": 11,
      "name": "Wood_Drywood_Planks"
    },
    {
      "x": -12,
      "y": 5,
      "z": 11,
      "name": "Wood_Softwood_Planks_Half",
      "rotation": 8
    },
    {
      "x": -12,
      "y": 6,
      "z": 11,
      "name": "*Wood_Village_Wall_Full_State_Definitions_Bottom"
    },
    {
      "x": -12,
      "y": 7,
      "z": 11,
      "name": "*Wood_Village_Wall_Full_State_Definitions_Top"
    },
    {
      "x": -12,
      "y": 8,
      "z": 11,
      "name": "Wood_Softwood_Roof_Shallow",
      "filler": 992
    },
    {
      "x": -12,
      "y": 1,
      "z": 12,
      "name": "Rock_Stone_Cobble"
    },
    {
      "x": -12,
      "y": 2,
      "z": 12,
      "name": "Wood_Softwood_Planks_Half",
      "rotation": 6
    },
    {
      "x": -12,
      "y": 3,
      "z": 12,
      "name": "Wood_Softwood_Planks_Half",
      "rotation": 6
    },
    {
      "x": -12,
      "y": 4,
      "z": 12,
      "name": "Wood_Softwood_Planks_Half",
      "rotation": 6
    },
    {
      "x": -12,
      "y": 5,
      "z": 12,
      "name": "Wood_Softwood_Stairs",
      "rotation": 8
    },
    {
      "x": -12,
      "y": 6,
      "z": 12,
      "name": "*Wood_Village_Wall_Full_State_Definitions_Bottom"
    },
    {
      "x": -12,
      "y": 7,
      "z": 12,
      "name": "*Wood_Village_Wall_Full_State_Definitions_Top"
    },
    {
      "x": -12,
      "y": 8,
      "z": 12,
      "name": "Wood_Softwood_Roof_Shallow"
    },
    {
      "x": -12,
      "y": 1,
      "z": 13,
      "name": "Rock_Stone_Cobble"
    },
    {
      "x": -12,
      "y": 2,
      "z": 13,
      "name": "Rock_Stone_Brick"
    },
    {
      "x": -12,
      "y": 3,
      "z": 13,
      "name": "*Wood_Village_Wall_Full_State_Definitions_Bottom"
    },
    {
      "x": -12,
      "y": 4,
      "z": 13,
      "name": "*Wood_Village_Wall_Full_State_Definitions_Middle"
    },
    {
      "x": -12,
      "y": 5,
      "z": 13,
      "name": "*Wood_Village_Wall_Full_State_Definitions_Middle"
    },
    {
      "x": -12,
      "y": 6,
      "z": 13,
      "name": "*Wood_Village_Wall_Full_State_Definitions_Top"
    },
    {
      "x": -12,
      "y": 7,
      "z": 13,
      "name": "Wood_Softwood_Roof_Shallow",
      "filler": 992
    },
    {
      "x": -12,
      "y": 1,
      "z": 14,
      "name": "Rock_Stone_Cobble"
    },
    {
      "x": -12,
      "y": 2,
      "z": 14,
      "name": "Wood_Beech_Trunk",
      "support": 15
    },
    {
      "x": -12,
      "y": 3,
      "z": 14,
      "name": "Wood_Beech_Trunk",
      "support": 15
    },
    {
      "x": -12,
      "y": 4,
      "z": 14,
      "name": "Wood_Beech_Trunk",
      "support": 15
    },
    {
      "x": -12,
      "y": 5,
      "z": 14,
      "name": "Wood_Beech_Trunk",
      "support": 15
    },
    {
      "x": -12,
      "y": 6,
      "z": 14,
      "name": "Wood_Beech_Trunk",
      "support": 15
    },
    {
      "x": -12,
      "y": 7,
      "z": 14,
      "name": "Wood_Softwood_Roof_Shallow"
    },
    {
      "x": -12,
      "y": 1,
      "z": 15,
      "name": "Rock_Stone_Cobble"
    },
    {
      "x": -12,
      "y": 2,
      "z": 15,
      "name": "Furniture_Village_Crate"
    },
    {
      "x": -12,
      "y": 3,
      "z": 15,
      "name": "Furniture_Tavern_Barrel",
      "support": 15
    },
    {
      "x": -12,
      "y": 4,
      "z": 15,
      "name": "Plant_Vine_Wall",
      "support": 15,
      "rotation": 3
    },
    {
      "x": -12,
      "y": 5,
      "z": 15,
      "name": "Wood_Beech_Branch_Corner",
      "support": 15
    },
    {
      "x": -12,
      "y": 6,
      "z": 15,
      "name": "*Wood_Softwood_Roof_State_Definitions_Inverted_Corner_Right"
    },
    {
      "x": -12,
      "y": 1,
      "z": 16,
      "name": "Rock_Stone_Cobble"
    },
    {
      "x": -12,
      "y": 2,
      "z": 16,
      "name": "Furniture_Tavern_Barrel",
      "support": 15
    },
    {
      "x": -12,
      "y": 5,
      "z": 16,
      "name": "Plant_Vine_Wall",
      "support": 15,
      "rotation": 3
    },
    {
      "x": -12,
      "y": 6,
      "z": 16,
      "name": "Wood_Softwood_Roof_Hollow",
      "rotation": 3
    },
    {
      "x": -12,
      "y": 1,
      "z": 17,
      "name": "Rock_Stone_Cobble"
    },
    {
      "x": -12,
      "y": 6,
      "z": 17,
      "name": "Wood_Softwood_Roof_Hollow",
      "rotation": 3
    },
    {
      "x": -12,
      "y": 1,
      "z": 18,
      "name": "Rock_Stone_Cobble"
    },
    {
      "x": -12,
      "y": 6,
      "z": 18,
      "name": "Wood_Softwood_Roof_Hollow",
      "rotation": 3
    },
    {
      "x": -12,
      "y": 1,
      "z": 19,
      "name": "Rock_Stone_Cobble"
    },
    {
      "x": -12,
      "y": 2,
      "z": 19,
      "name": "Rock_Stone_Brick_Wall"
    },
    {
      "x": -12,
      "y": 3,
      "z": 19,
      "name": "Wood_Softwood_Fence"
    },
    {
      "x": -12,
      "y": 5,
      "z": 19,
      "name": "Wood_Beech_Branch_Corner",
      "support": 15,
      "rotation": 3
    },
    {
      "x": -12,
      "y": 6,
      "z": 19,
      "name": "Wood_Softwood_Roof",
      "rotation": 3
    },
    {
      "x": -12,
      "y": 1,
      "z": 20,
      "name": "Rock_Stone_Cobble"
    },
    {
      "x": -12,
      "y": 6,
      "z": 20,
      "name": "Wood_Softwood_Roof_Hollow",
      "rotation": 3
    },
    {
      "x": -11,
      "y": 1,
      "z": 1,
      "name": "Rock_Stone_Cobble"
    },
    {
      "x": -11,
      "y": 2,
      "z": 1,
      "name": "Furniture_Tavern_Barrel",
      "support": 15
    },
    {
      "x": -11,
      "y": 6,
      "z": 1,
      "name": "Wood_Beech_Branch_Corner",
      "support": 15,
      "rotation": 2
    },
    {
      "x": -11,
      "y": 7,
      "z": 1,
      "name": "Wood_Softwood_Roof_Shallow",
      "rotation": 3
    },
    {
      "x": -11,
      "y": 1,
      "z": 2,
      "name": "Rock_Stone_Cobble"
    },
    {
      "x": -11,
      "y": 2,
      "z": 2,
      "name": "Wood_Beech_Trunk",
      "support": 15
    },
    {
      "x": -11,
      "y": 3,
      "z": 2,
      "name": "Wood_Beech_Trunk",
      "support": 15
    },
    {
      "x": -11,
      "y": 4,
      "z": 2,
      "name": "Wood_Beech_Trunk",
      "support": 15
    },
    {
      "x": -11,
      "y": 5,
      "z": 2,
      "name": "Wood_Beech_Trunk",
      "support": 15
    },
    {
      "x": -11,
      "y": 6,
      "z": 2,
      "name": "Wood_Beech_Trunk",
      "support": 15
    },
    {
      "x": -11,
      "y": 7,
      "z": 2,
      "name": "Wood_Softwood_Roof_Shallow",
      "rotation": 3
    },
    {
      "x": -11,
      "y": 1,
      "z": 3,
      "name": "Rock_Stone_Cobble"
    },
    {
      "x": -11,
      "y": 2,
      "z": 3,
      "name": "Rock_Stone_Brick"
    },
    {
      "x": -11,
      "y": 3,
      "z": 3,
      "name": "*Wood_Village_Wall_Full_State_Definitions_Bottom"
    },
    {
      "x": -11,
      "y": 4,
      "z": 3,
      "name": "*Wood_Village_Wall_Full_State_Definitions_Middle"
    },
    {
      "x": -11,
      "y": 5,
      "z": 3,
      "name": "*Wood_Village_Wall_Full_State_Definitions_Middle"
    },
    {
      "x": -11,
      "y": 6,
      "z": 3,
      "name": "*Wood_Village_Wall_Full_State_Definitions_Top"
    },
    {
      "x": -11,
      "y": 7,
      "z": 3,
      "name": "Wood_Softwood_Roof_Shallow",
      "rotation": 3
    },
    {
      "x": -11,
      "y": 1,
      "z": 4,
      "name": "Rock_Stone_Cobble"
    },
    {
      "x": -11,
      "y": 2,
      "z": 4,
      "name": "Rock_Stone_Brick"
    },
    {
      "x": -11,
      "y": 3,
      "z": 4,
      "name": "Furniture_Village_Window",
      "rotation": 1
    },
    {
      "x": -11,
      "y": 4,
      "z": 4,
      "name": "Furniture_Village_Window",
      "rotation": 1
    },
    {
      "x": -11,
      "y": 5,
      "z": 4,
      "name": "Wood_Softwood_Stairs",
      "rotation": 9
    },
    {
      "x": -11,
      "y": 6,
      "z": 4,
      "name": "Wood_Village_Wall_Full"
    },
    {
      "x": -11,
      "y": 7,
      "z": 4,
      "name": "Wood_Softwood_Roof_Shallow",
      "rotation": 3
    },
    {
      "x": -11,
      "y": 1,
      "z": 5,
      "name": "Rock_Stone_Cobble"
    },
    {
      "x": -11,
      "y": 2,
      "z": 5,
      "name": "Rock_Stone_Brick"
    },
    {
      "x": -11,
      "y": 3,
      "z": 5,
      "name": "*Wood_Village_Wall_Full_State_Definitions_Bottom"
    },
    {
      "x": -11,
      "y": 4,
      "z": 5,
      "name": "*Wood_Village_Wall_Full_State_Definitions_Middle"
    },
    {
      "x": -11,
      "y": 5,
      "z": 5,
      "name": "*Wood_Village_Wall_Full_State_Definitions_Middle"
    },
    {
      "x": -11,
      "y": 6,
      "z": 5,
      "name": "*Wood_Village_Wall_Full_State_Definitions_Top"
    },
    {
      "x": -11,
      "y": 7,
      "z": 5,
      "name": "Wood_Softwood_Roof_Shallow",
      "rotation": 3
    },
    {
      "x": -11,
      "y": 1,
      "z": 6,
      "name": "Rock_Stone_Cobble"
    },
    {
      "x": -11,
      "y": 2,
      "z": 6,
      "name": "Wood_Beech_Trunk",
      "support": 15
    },
    {
      "x": -11,
      "y": 3,
      "z": 6,
      "name": "Wood_Beech_Trunk",
      "support": 15
    },
    {
      "x": -11,
      "y": 4,
      "z": 6,
      "name": "Wood_Beech_Trunk",
      "support": 15
    },
    {
      "x": -11,
      "y": 5,
      "z": 6,
      "name": "Wood_Beech_Trunk",
      "support": 15
    },
    {
      "x": -11,
      "y": 6,
      "z": 6,
      "name": "Wood_Beech_Trunk",
      "support": 15
    },
    {
      "x": -11,
      "y": 7,
      "z": 6,
      "name": "Wood_Softwood_Roof_Shallow",
      "rotation": 3
    },
    {
      "x": -11,
      "y": 1,
      "z": 7,
      "name": "Rock_Stone_Cobble"
    },
    {
      "x": -11,
      "y": 2,
      "z": 7,
      "name": "Furniture_Village_Chest_Large",
      "components": {
        "Components": {
          "ItemContainerBlock": {
            "ItemContainer": {
              "Capacity": 36,
              "Items": {}
            },
            "Capacity": 36
          }
        }
      },
      "support": 15,
      "rotation": 1
    },
    {
      "x": -11,
      "y": 3,
      "z": 7,
      "name": "Furniture_Village_Chest_Large",
      "components": {
        "Components": {
          "ItemContainerBlock": {
            "ItemContainer": {
              "Capacity": 36,
              "Items": {}
            },
            "Capacity": 36
          }
        }
      },
      "support": 15,
      "rotation": 1
    },
    {
      "x": -11,
      "y": 4,
      "z": 7,
      "name": "Furniture_Village_Chest_Large",
      "components": {
        "Components": {
          "ItemContainerBlock": {
            "ItemContainer": {
              "Capacity": 36,
              "Items": {}
            },
            "Capacity": 36
          }
        }
      },
      "support": 15,
      "rotation": 1
    },
    {
      "x": -11,
      "y": 5,
      "z": 7,
      "name": "Wood_Beech_Trunk",
      "support": 15,
      "rotation": 4
    },
    {
      "x": -11,
      "y": 7,
      "z": 7,
      "name": "*Wood_Softwood_Roof_Shallow_State_Definitions_Inverted_Corner_Right",
      "rotation": 3
    },
    {
      "x": -11,
      "y": 1,
      "z": 8,
      "name": "Rock_Stone_Cobble"
    },
    {
      "x": -11,
      "y": 2,
      "z": 8,
      "name": "Furniture_Village_Chest_Large",
      "support": 15,
      "filler": 32,
      "rotation": 1
    },
    {
      "x": -11,
      "y": 3,
      "z": 8,
      "name": "Furniture_Village_Chest_Large",
      "support": 15,
      "filler": 32,
      "rotation": 1
    },
    {
      "x": -11,
      "y": 4,
      "z": 8,
      "name": "Furniture_Village_Chest_Large",
      "support": 15,
      "filler": 32,
      "rotation": 1
    },
    {
      "x": -11,
      "y": 5,
      "z": 8,
      "name": "Wood_Beech_Trunk",
      "support": 15,
      "rotation": 4
    },
    {
      "x": -11,
      "y": 7,
      "z": 8,
      "name": "*Wood_Softwood_Roof_Shallow_State_Definitions_Inverted_Corner_Right",
      "filler": 32,
      "rotation": 3
    },
    {
      "x": -11,
      "y": 1,
      "z": 9,
      "name": "Rock_Stone_Cobble"
    },
    {
      "x": -11,
      "y": 2,
      "z": 9,
      "name": "Wood_Softwood_Planks_Half",
      "rotation": 4
    },
    {
      "x": -11,
      "y": 3,
      "z": 9,
      "name": "Wood_Softwood_Planks_Half",
      "rotation": 4
    },
    {
      "x": -11,
      "y": 4,
      "z": 9,
      "name": "Wood_Softwood_Planks_Half",
      "rotation": 4
    },
    {
      "x": -11,
      "y": 5,
      "z": 9,
      "name": "Wood_Beech_Trunk",
      "support": 15,
      "rotation": 4
    },
    {
      "x": -11,
      "y": 7,
      "z": 9,
      "name": "Wood_Softwood_Stairs",
      "rotation": 10
    },
    {
      "x": -11,
      "y": 8,
      "z": 9,
      "name": "Wood_Softwood_Roof_Shallow",
      "rotation": 2
    },
    {
      "x": -11,
      "y": 1,
      "z": 10,
      "name": "Wood_Drywood_Planks"
    },
    {
      "x": -11,
      "y": 5,
      "z": 10,
      "name": "Wood_Beech_Trunk",
      "support": 15,
      "rotation": 4
    },
    {
      "x": -11,
      "y": 8,
      "z": 10,
      "name": "Wood_Softwood_Roof_Shallow",
      "filler": 32,
      "rotation": 2
    },
    {
      "x": -11,
      "y": 1,
      "z": 11,
      "name": "Wood_Drywood_Planks"
    },
    {
      "x": -11,
      "y": 5,
      "z": 11,
      "name": "Wood_Beech_Trunk",
      "support": 15,
      "rotation": 4
    },
    {
      "x": -11,
      "y": 8,
      "z": 11,
      "name": "Wood_Softwood_Roof_Shallow",
      "filler": 992
    },
    {
      "x": -11,
      "y": 1,
      "z": 12,
      "name": "Rock_Stone_Cobble"
    },
    {
      "x": -11,
      "y": 2,
      "z": 12,
      "name": "Wood_Softwood_Planks_Half",
      "rotation": 6
    },
    {
      "x": -11,
      "y": 3,
      "z": 12,
      "name": "Wood_Softwood_Planks_Half",
      "rotation": 6
    },
    {
      "x": -11,
      "y": 4,
      "z": 12,
      "name": "Wood_Softwood_Planks_Half",
      "rotation": 6
    },
    {
      "x": -11,
      "y": 5,
      "z": 12,
      "name": "Wood_Beech_Trunk",
      "support": 15,
      "rotation": 4
    },
    {
      "x": -11,
      "y": 7,
      "z": 12,
      "name": "Wood_Softwood_Stairs",
      "rotation": 8
    },
    {
      "x": -11,
      "y": 8,
      "z": 12,
      "name": "Wood_Softwood_Roof_Shallow"
    },
    {
      "x": -11,
      "y": 1,
      "z": 13,
      "name": "Rock_Stone_Cobble"
    },
    {
      "x": -11,
      "y": 2,
      "z": 13,
      "name": "Furniture_Village_Chest_Large",
      "components": {
        "Components": {
          "ItemContainerBlock": {
            "ItemContainer": {
              "Capacity": 36,
              "Items": {}
            },
            "Capacity": 36
          }
        }
      },
      "support": 15,
      "rotation": 1
    },
    {
      "x": -11,
      "y": 3,
      "z": 13,
      "name": "Furniture_Village_Chest_Large",
      "components": {
        "Components": {
          "ItemContainerBlock": {
            "ItemContainer": {
              "Capacity": 36,
              "Items": {}
            },
            "Capacity": 36
          }
        }
      },
      "support": 15,
      "rotation": 1
    },
    {
      "x": -11,
      "y": 4,
      "z": 13,
      "name": "Furniture_Village_Chest_Large",
      "components": {
        "Components": {
          "ItemContainerBlock": {
            "ItemContainer": {
              "Capacity": 36,
              "Items": {}
            },
            "Capacity": 36
          }
        }
      },
      "support": 15,
      "rotation": 1
    },
    {
      "x": -11,
      "y": 5,
      "z": 13,
      "name": "Wood_Beech_Trunk",
      "support": 15,
      "rotation": 4
    },
    {
      "x": -11,
      "y": 7,
      "z": 13,
      "name": "*Wood_Softwood_Roof_Shallow_State_Definitions_Inverted_Corner_Right",
      "filler": 992
    },
    {
      "x": -11,
      "y": 1,
      "z": 14,
      "name": "Rock_Stone_Cobble"
    },
    {
      "x": -11,
      "y": 2,
      "z": 14,
      "name": "Furniture_Village_Chest_Large",
      "support": 15,
      "filler": 32,
      "rotation": 1
    },
    {
      "x": -11,
      "y": 3,
      "z": 14,
      "name": "Furniture_Village_Chest_Large",
      "support": 15,
      "filler": 32,
      "rotation": 1
    },
    {
      "x": -11,
      "y": 4,
      "z": 14,
      "name": "Furniture_Village_Chest_Large",
      "support": 15,
      "filler": 32,
      "rotation": 1
    },
    {
      "x": -11,
      "y": 5,
      "z": 14,
      "name": "Wood_Beech_Trunk",
      "support": 15,
      "rotation": 4
    },
    {
      "x": -11,
      "y": 7,
      "z": 14,
      "name": "*Wood_Softwood_Roof_Shallow_State_Definitions_Inverted_Corner_Right"
    },
    {
      "x": -11,
      "y": 1,
      "z": 15,
      "name": "Rock_Stone_Cobble"
    },
    {
      "x": -11,
      "y": 2,
      "z": 15,
      "name": "Wood_Beech_Trunk",
      "support": 15
    },
    {
      "x": -11,
      "y": 3,
      "z": 15,
      "name": "Wood_Beech_Trunk",
      "support": 15
    },
    {
      "x": -11,
      "y": 4,
      "z": 15,
      "name": "Wood_Beech_Trunk",
      "support": 15
    },
    {
      "x": -11,
      "y": 5,
      "z": 15,
      "name": "Wood_Beech_Trunk",
      "support": 15
    },
    {
      "x": -11,
      "y": 6,
      "z": 15,
      "name": "Wood_Beech_Trunk",
      "support": 15
    },
    {
      "x": -11,
      "y": 7,
      "z": 15,
      "name": "Wood_Softwood_Roof_Shallow",
      "rotation": 3
    },
    {
      "x": -11,
      "y": 1,
      "z": 16,
      "name": "Rock_Stone_Cobble"
    },
    {
      "x": -11,
      "y": 2,
      "z": 16,
      "name": "Rock_Stone_Brick"
    },
    {
      "x": -11,
      "y": 3,
      "z": 16,
      "name": "*Wood_Village_Wall_Full_State_Definitions_Bottom"
    },
    {
      "x": -11,
      "y": 4,
      "z": 16,
      "name": "*Wood_Village_Wall_Full_State_Definitions_Middle"
    },
    {
      "x": -11,
      "y": 5,
      "z": 16,
      "name": "*Wood_Village_Wall_Full_State_Definitions_Middle"
    },
    {
      "x": -11,
      "y": 6,
      "z": 16,
      "name": "*Wood_Village_Wall_Full_State_Definitions_Top"
    },
    {
      "x": -11,
      "y": 7,
      "z": 16,
      "name": "Wood_Softwood_Roof_Shallow",
      "rotation": 3
    },
    {
      "x": -11,
      "y": 1,
      "z": 17,
      "name": "Rock_Stone_Cobble"
    },
    {
      "x": -11,
      "y": 2,
      "z": 17,
      "name": "*Furniture_Village_Door_State_Definitions_CloseDoorIn",
      "rotation": 3
    },
    {
      "x": -11,
      "y": 3,
      "z": 17,
      "name": "*Furniture_Village_Door_State_Definitions_CloseDoorIn",
      "filler": 1024,
      "rotation": 3
    },
    {
      "x": -11,
      "y": 4,
      "z": 17,
      "name": "Furniture_Village_Window",
      "rotation": 1
    },
    {
      "x": -11,
      "y": 5,
      "z": 17,
      "name": "Wood_Softwood_Stairs",
      "rotation": 9
    },
    {
      "x": -11,
      "y": 6,
      "z": 17,
      "name": "Wood_Village_Wall_Full"
    },
    {
      "x": -11,
      "y": 7,
      "z": 17,
      "name": "Wood_Softwood_Roof_Shallow",
      "rotation": 3
    },
    {
      "x": -11,
      "y": 1,
      "z": 18,
      "name": "Rock_Stone_Cobble"
    },
    {
      "x": -11,
      "y": 2,
      "z": 18,
      "name": "Rock_Stone_Brick"
    },
    {
      "x": -11,
      "y": 3,
      "z": 18,
      "name": "*Wood_Village_Wall_Full_State_Definitions_Bottom"
    },
    {
      "x": -11,
      "y": 4,
      "z": 18,
      "name": "*Wood_Village_Wall_Full_State_Definitions_Middle"
    },
    {
      "x": -11,
      "y": 5,
      "z": 18,
      "name": "*Wood_Village_Wall_Full_State_Definitions_Middle"
    },
    {
      "x": -11,
      "y": 6,
      "z": 18,
      "name": "*Wood_Village_Wall_Full_State_Definitions_Top"
    },
    {
      "x": -11,
      "y": 7,
      "z": 18,
      "name": "Wood_Softwood_Roof_Shallow",
      "rotation": 3
    },
    {
      "x": -11,
      "y": 1,
      "z": 19,
      "name": "Rock_Stone_Cobble"
    },
    {
      "x": -11,
      "y": 2,
      "z": 19,
      "name": "Wood_Beech_Trunk",
      "support": 15
    },
    {
      "x": -11,
      "y": 3,
      "z": 19,
      "name": "Wood_Beech_Trunk",
      "support": 15
    },
    {
      "x": -11,
      "y": 4,
      "z": 19,
      "name": "Wood_Beech_Trunk",
      "support": 15
    },
    {
      "x": -11,
      "y": 5,
      "z": 19,
      "name": "Wood_Beech_Trunk",
      "support": 15
    },
    {
      "x": -11,
      "y": 6,
      "z": 19,
      "name": "Wood_Beech_Trunk",
      "support": 15
    },
    {
      "x": -11,
      "y": 7,
      "z": 19,
      "name": "Wood_Softwood_Roof_Shallow",
      "rotation": 3
    },
    {
      "x": -11,
      "y": 1,
      "z": 20,
      "name": "Rock_Stone_Cobble"
    },
    {
      "x": -11,
      "y": 6,
      "z": 20,
      "name": "Wood_Beech_Branch_Corner",
      "support": 15
    },
    {
      "x": -11,
      "y": 7,
      "z": 20,
      "name": "Wood_Softwood_Roof_Shallow",
      "rotation": 3
    },
    {
      "x": -10,
      "y": 1,
      "z": 1,
      "name": "Rock_Stone_Cobble"
    },
    {
      "x": -10,
      "y": 2,
      "z": 1,
      "name": "Furniture_Village_Crate"
    },
    {
      "x": -10,
      "y": 3,
      "z": 1,
      "name": "Furniture_Tavern_Barrel",
      "support": 15
    },
    {
      "x": -10,
      "y": 7,
      "z": 1,
      "name": "Wood_Softwood_Roof_Shallow",
      "filler": 1,
      "rotation": 3
    },
    {
      "x": -10,
      "y": 1,
      "z": 2,
      "name": "Rock_Stone_Cobble"
    },
    {
      "x": -10,
      "y": 2,
      "z": 2,
      "name": "Rock_Stone_Brick"
    },
    {
      "x": -10,
      "y": 3,
      "z": 2,
      "name": "*Wood_Village_Wall_Full_State_Definitions_Bottom"
    },
    {
      "x": -10,
      "y": 4,
      "z": 2,
      "name": "*Wood_Village_Wall_Full_State_Definitions_Middle"
    },
    {
      "x": -10,
      "y": 5,
      "z": 2,
      "name": "*Wood_Village_Wall_Full_State_Definitions_Top"
    },
    {
      "x": -10,
      "y": 6,
      "z": 2,
      "name": "Wood_Beech_Trunk",
      "support": 15,
      "rotation": 5
    },
    {
      "x": -10,
      "y": 7,
      "z": 2,
      "name": "Wood_Softwood_Roof_Shallow",
      "filler": 1,
      "rotation": 3
    },
    {
      "x": -10,
      "y": 1,
      "z": 3,
      "name": "Rock_Stone_Cobble"
    },
    {
      "x": -10,
      "y": 2,
      "z": 3,
      "name": "Furniture_Tavern_Planter",
      "support": 15
    },
    {
      "x": -10,
      "y": 3,
      "z": 3,
      "name": "Plant_Flower_Common_Purple",
      "support": 15
    },
    {
      "x": -10,
      "y": 7,
      "z": 3,
      "name": "Wood_Softwood_Roof_Shallow",
      "filler": 1,
      "rotation": 3
    },
    {
      "x": -10,
      "y": 1,
      "z": 4,
      "name": "Rock_Stone_Cobble"
    },
    {
      "x": -10,
      "y": 5,
      "z": 4,
      "name": "Deco_Lantern_Ceiling",
      "support": 15
    },
    {
      "x": -10,
      "y": 6,
      "z": 4,
      "name": "Deco_Rope",
      "support": 15
    },
    {
      "x": -10,
      "y": 7,
      "z": 4,
      "name": "Wood_Softwood_Roof_Shallow",
      "filler": 1,
      "rotation": 3
    },
    {
      "x": -10,
      "y": 1,
      "z": 5,
      "name": "Rock_Stone_Cobble"
    },
    {
      "x": -10,
      "y": 7,
      "z": 5,
      "name": "Wood_Softwood_Roof_Shallow",
      "filler": 1,
      "rotation": 3
    },
    {
      "x": -10,
      "y": 1,
      "z": 6,
      "name": "Wood_Drywood_Planks"
    },
    {
      "x": -10,
      "y": 7,
      "z": 6,
      "name": "Wood_Softwood_Roof_Shallow",
      "filler": 1,
      "rotation": 3
    },
    {
      "x": -10,
      "y": 1,
      "z": 7,
      "name": "Wood_Drywood_Planks"
    },
    {
      "x": -10,
      "y": 7,
      "z": 7,
      "name": "*Wood_Softwood_Roof_Shallow_State_Definitions_Inverted_Corner_Right",
      "filler": 1,
      "rotation": 3
    },
    {
      "x": -10,
      "y": 1,
      "z": 8,
      "name": "Wood_Drywood_Planks"
    },
    {
      "x": -10,
      "y": 7,
      "z": 8,
      "name": "*Wood_Softwood_Roof_Shallow_State_Definitions_Inverted_Corner_Right",
      "filler": 33,
      "rotation": 3
    },
    {
      "x": -10,
      "y": 1,
      "z": 9,
      "name": "Wood_Drywood_Planks"
    },
    {
      "x": -10,
      "y": 7,
      "z": 9,
      "name": "Wood_Softwood_Stairs",
      "rotation": 10
    },
    {
      "x": -10,
      "y": 8,
      "z": 9,
      "name": "Wood_Softwood_Roof_Shallow",
      "rotation": 2
    },
    {
      "x": -10,
      "y": 1,
      "z": 10,
      "name": "Wood_Drywood_Planks"
    },
    {
      "x": -10,
      "y": 8,
      "z": 10,
      "name": "Wood_Softwood_Roof_Shallow",
      "filler": 32,
      "rotation": 2
    },
    {
      "x": -10,
      "y": 1,
      "z": 11,
      "name": "Wood_Drywood_Planks"
    },
    {
      "x": -10,
      "y": 8,
      "z": 11,
      "name": "Wood_Softwood_Roof_Shallow",
      "filler": 992
    },
    {
      "x": -10,
      "y": 1,
      "z": 12,
      "name": "Wood_Drywood_Planks"
    },
    {
      "x": -10,
      "y": 7,
      "z": 12,
      "name": "Wood_Softwood_Stairs",
      "rotation": 8
    },
    {
      "x": -10,
      "y": 8,
      "z": 12,
      "name": "Wood_Softwood_Roof_Shallow"
    },
    {
      "x": -10,
      "y": 1,
      "z": 13,
      "name": "Wood_Drywood_Planks"
    },
    {
      "x": -10,
      "y": 7,
      "z": 13,
      "name": "*Wood_Softwood_Roof_Shallow_State_Definitions_Inverted_Corner_Right",
      "filler": 993
    },
    {
      "x": -10,
      "y": 1,
      "z": 14,
      "name": "Wood_Drywood_Planks"
    },
    {
      "x": -10,
      "y": 7,
      "z": 14,
      "name": "*Wood_Softwood_Roof_Shallow_State_Definitions_Inverted_Corner_Right",
      "filler": 1
    },
    {
      "x": -10,
      "y": 1,
      "z": 15,
      "name": "Wood_Drywood_Planks"
    },
    {
      "x": -10,
      "y": 7,
      "z": 15,
      "name": "Wood_Softwood_Roof_Shallow",
      "filler": 1,
      "rotation": 3
    },
    {
      "x": -10,
      "y": 1,
      "z": 16,
      "name": "Rock_Stone_Cobble"
    },
    {
      "x": -10,
      "y": 7,
      "z": 16,
      "name": "Wood_Softwood_Roof_Shallow",
      "filler": 1,
      "rotation": 3
    },
    {
      "x": -10,
      "y": 1,
      "z": 17,
      "name": "Rock_Stone_Cobble"
    },
    {
      "x": -10,
      "y": 5,
      "z": 17,
      "name": "Deco_Lantern_Ceiling",
      "support": 15
    },
    {
      "x": -10,
      "y": 6,
      "z": 17,
      "name": "Deco_Rope",
      "support": 15
    },
    {
      "x": -10,
      "y": 7,
      "z": 17,
      "name": "Wood_Softwood_Roof_Shallow",
      "filler": 1,
      "rotation": 3
    },
    {
      "x": -10,
      "y": 1,
      "z": 18,
      "name": "Rock_Stone_Cobble"
    },
    {
      "x": -10,
      "y": 2,
      "z": 18,
      "name": "Furniture_Tavern_Planter",
      "support": 15
    },
    {
      "x": -10,
      "y": 3,
      "z": 18,
      "name": "Plant_Flower_Tall_Pink",
      "support": 15
    },
    {
      "x": -10,
      "y": 7,
      "z": 18,
      "name": "Wood_Softwood_Roof_Shallow",
      "filler": 1,
      "rotation": 3
    },
    {
      "x": -10,
      "y": 1,
      "z": 19,
      "name": "Rock_Stone_Cobble"
    },
    {
      "x": -10,
      "y": 2,
      "z": 19,
      "name": "Rock_Stone_Brick"
    },
    {
      "x": -10,
      "y": 3,
      "z": 19,
      "name": "*Wood_Village_Wall_Full_State_Definitions_Bottom"
    },
    {
      "x": -10,
      "y": 4,
      "z": 19,
      "name": "*Wood_Village_Wall_Full_State_Definitions_Middle"
    },
    {
      "x": -10,
      "y": 5,
      "z": 19,
      "name": "*Wood_Village_Wall_Full_State_Definitions_Top"
    },
    {
      "x": -10,
      "y": 6,
      "z": 19,
      "name": "Wood_Beech_Trunk",
      "support": 15,
      "rotation": 5
    },
    {
      "x": -10,
      "y": 7,
      "z": 19,
      "name": "Wood_Softwood_Roof_Shallow",
      "filler": 1,
      "rotation": 3
    },
    {
      "x": -10,
      "y": 1,
      "z": 20,
      "name": "Rock_Stone_Cobble"
    },
    {
      "x": -10,
      "y": 7,
      "z": 20,
      "name": "Wood_Softwood_Roof_Shallow",
      "filler": 1,
      "rotation": 3
    },
    {
      "x": -9,
      "y": 1,
      "z": 1,
      "name": "Rock_Stone_Cobble"
    },
    {
      "x": -9,
      "y": 2,
      "z": 1,
      "name": "Furniture_Tavern_Barrel",
      "support": 15
    },
    {
      "x": -9,
      "y": 7,
      "z": 1,
      "name": "Wood_Softwood_Stairs",
      "rotation": 11
    },
    {
      "x": -9,
      "y": 8,
      "z": 1,
      "name": "Wood_Softwood_Roof_Shallow",
      "rotation": 3
    },
    {
      "x": -9,
      "y": 1,
      "z": 2,
      "name": "Rock_Stone_Cobble"
    },
    {
      "x": -9,
      "y": 2,
      "z": 2,
      "name": "Rock_Stone_Brick"
    },
    {
      "x": -9,
      "y": 3,
      "z": 2,
      "name": "*Wood_Village_Wall_Full_State_Definitions_Bottom"
    },
    {
      "x": -9,
      "y": 4,
      "z": 2,
      "name": "*Wood_Village_Wall_Full_State_Definitions_Middle"
    },
    {
      "x": -9,
      "y": 5,
      "z": 2,
      "name": "*Wood_Village_Wall_Full_State_Definitions_Top"
    },
    {
      "x": -9,
      "y": 6,
      "z": 2,
      "name": "Wood_Beech_Trunk",
      "support": 15,
      "rotation": 5
    },
    {
      "x": -9,
      "y": 7,
      "z": 2,
      "name": "Wood_Village_Wall_Full"
    },
    {
      "x": -9,
      "y": 8,
      "z": 2,
      "name": "Wood_Softwood_Roof_Shallow",
      "rotation": 3
    },
    {
      "x": -9,
      "y": 1,
      "z": 3,
      "name": "Rock_Stone_Cobble"
    },
    {
      "x": -9,
      "y": 7,
      "z": 3,
      "name": "Wood_Softwood_Stairs",
      "rotation": 11
    },
    {
      "x": -9,
      "y": 8,
      "z": 3,
      "name": "Wood_Softwood_Roof_Shallow",
      "rotation": 3
    },
    {
      "x": -9,
      "y": 1,
      "z": 4,
      "name": "Rock_Stone_Cobble"
    },
    {
      "x": -9,
      "y": 7,
      "z": 4,
      "name": "Wood_Softwood_Stairs",
      "rotation": 11
    },
    {
      "x": -9,
      "y": 8,
      "z": 4,
      "name": "Wood_Softwood_Roof_Shallow",
      "rotation": 3
    },
    {
      "x": -9,
      "y": 1,
      "z": 5,
      "name": "Rock_Stone_Cobble"
    },
    {
      "x": -9,
      "y": 7,
      "z": 5,
      "name": "Wood_Softwood_Stairs",
      "rotation": 11
    },
    {
      "x": -9,
      "y": 8,
      "z": 5,
      "name": "Wood_Softwood_Roof_Shallow",
      "rotation": 3
    },
    {
      "x": -9,
      "y": 1,
      "z": 6,
      "name": "Wood_Drywood_Planks"
    },
    {
      "x": -9,
      "y": 7,
      "z": 6,
      "name": "Wood_Softwood_Stairs",
      "rotation": 11
    },
    {
      "x": -9,
      "y": 8,
      "z": 6,
      "name": "Wood_Softwood_Roof_Shallow",
      "rotation": 3
    },
    {
      "x": -9,
      "y": 1,
      "z": 7,
      "name": "Wood_Drywood_Planks"
    },
    {
      "x": -9,
      "y": 7,
      "z": 7,
      "name": "Wood_Softwood_Stairs",
      "rotation": 11
    },
    {
      "x": -9,
      "y": 8,
      "z": 7,
      "name": "Wood_Softwood_Roof_Shallow",
      "rotation": 3
    },
    {
      "x": -9,
      "y": 1,
      "z": 8,
      "name": "Wood_Drywood_Planks"
    },
    {
      "x": -9,
      "y": 7,
      "z": 8,
      "name": "Wood_Softwood_Stairs",
      "rotation": 11
    },
    {
      "x": -9,
      "y": 8,
      "z": 8,
      "name": "Wood_Softwood_Roof_Shallow",
      "rotation": 3
    },
    {
      "x": -9,
      "y": 1,
      "z": 9,
      "name": "Wood_Drywood_Planks"
    },
    {
      "x": -9,
      "y": 7,
      "z": 9,
      "name": "*Wood_Softwood_Stairs_State_Definitions_Corner_Right",
      "rotation": 10
    },
    {
      "x": -9,
      "y": 8,
      "z": 9,
      "name": "*Wood_Softwood_Roof_Shallow_State_Definitions_Inverted_Corner_Right",
      "rotation": 3
    },
    {
      "x": -9,
      "y": 1,
      "z": 10,
      "name": "Wood_Drywood_Planks"
    },
    {
      "x": -9,
      "y": 8,
      "z": 10,
      "name": "*Wood_Softwood_Roof_Shallow_State_Definitions_Inverted_Corner_Right",
      "filler": 32,
      "rotation": 3
    },
    {
      "x": -9,
      "y": 1,
      "z": 11,
      "name": "Wood_Drywood_Planks"
    },
    {
      "x": -9,
      "y": 8,
      "z": 11,
      "name": "*Wood_Softwood_Roof_Shallow_State_Definitions_Inverted_Corner_Left",
      "filler": 992,
      "rotation": 3
    },
    {
      "x": -9,
      "y": 1,
      "z": 12,
      "name": "Wood_Drywood_Planks"
    },
    {
      "x": -9,
      "y": 7,
      "z": 12,
      "name": "*Wood_Softwood_Stairs_State_Definitions_Corner_Right",
      "rotation": 11
    },
    {
      "x": -9,
      "y": 8,
      "z": 12,
      "name": "*Wood_Softwood_Roof_Shallow_State_Definitions_Inverted_Corner_Left",
      "rotation": 3
    },
    {
      "x": -9,
      "y": 1,
      "z": 13,
      "name": "Wood_Drywood_Planks"
    },
    {
      "x": -9,
      "y": 7,
      "z": 13,
      "name": "Wood_Softwood_Stairs",
      "rotation": 11
    },
    {
      "x": -9,
      "y": 8,
      "z": 13,
      "name": "Wood_Softwood_Roof_Shallow",
      "rotation": 3
    },
    {
      "x": -9,
      "y": 1,
      "z": 14,
      "name": "Wood_Drywood_Planks"
    },
    {
      "x": -9,
      "y": 7,
      "z": 14,
      "name": "Wood_Softwood_Stairs",
      "rotation": 11
    },
    {
      "x": -9,
      "y": 8,
      "z": 14,
      "name": "Wood_Softwood_Roof_Shallow",
      "rotation": 3
    },
    {
      "x": -9,
      "y": 1,
      "z": 15,
      "name": "Wood_Drywood_Planks"
    },
    {
      "x": -9,
      "y": 7,
      "z": 15,
      "name": "Wood_Softwood_Stairs",
      "rotation": 11
    },
    {
      "x": -9,
      "y": 8,
      "z": 15,
      "name": "Wood_Softwood_Roof_Shallow",
      "rotation": 3
    },
    {
      "x": -9,
      "y": 1,
      "z": 16,
      "name": "Rock_Stone_Cobble"
    },
    {
      "x": -9,
      "y": 7,
      "z": 16,
      "name": "Wood_Softwood_Stairs",
      "rotation": 11
    },
    {
      "x": -9,
      "y": 8,
      "z": 16,
      "name": "Wood_Softwood_Roof_Shallow",
      "rotation": 3
    },
    {
      "x": -9,
      "y": 1,
      "z": 17,
      "name": "Rock_Stone_Cobble"
    },
    {
      "x": -9,
      "y": 7,
      "z": 17,
      "name": "Wood_Softwood_Stairs",
      "rotation": 11
    },
    {
      "x": -9,
      "y": 8,
      "z": 17,
      "name": "Wood_Softwood_Roof_Shallow",
      "rotation": 3
    },
    {
      "x": -9,
      "y": 1,
      "z": 18,
      "name": "Rock_Stone_Cobble"
    },
    {
      "x": -9,
      "y": 7,
      "z": 18,
      "name": "Wood_Softwood_Stairs",
      "rotation": 11
    },
    {
      "x": -9,
      "y": 8,
      "z": 18,
      "name": "Wood_Softwood_Roof_Shallow",
      "rotation": 3
    },
    {
      "x": -9,
      "y": 1,
      "z": 19,
      "name": "Rock_Stone_Cobble"
    },
    {
      "x": -9,
      "y": 2,
      "z": 19,
      "name": "Rock_Stone_Brick"
    },
    {
      "x": -9,
      "y": 3,
      "z": 19,
      "name": "*Wood_Village_Wall_Full_State_Definitions_Bottom"
    },
    {
      "x": -9,
      "y": 4,
      "z": 19,
      "name": "*Wood_Village_Wall_Full_State_Definitions_Middle"
    },
    {
      "x": -9,
      "y": 5,
      "z": 19,
      "name": "*Wood_Village_Wall_Full_State_Definitions_Top"
    },
    {
      "x": -9,
      "y": 6,
      "z": 19,
      "name": "Wood_Beech_Trunk",
      "support": 15,
      "rotation": 5
    },
    {
      "x": -9,
      "y": 7,
      "z": 19,
      "name": "Wood_Village_Wall_Full"
    },
    {
      "x": -9,
      "y": 8,
      "z": 19,
      "name": "Wood_Softwood_Roof_Shallow",
      "rotation": 3
    },
    {
      "x": -9,
      "y": 1,
      "z": 20,
      "name": "Rock_Stone_Cobble"
    },
    {
      "x": -9,
      "y": 7,
      "z": 20,
      "name": "Wood_Softwood_Stairs",
      "rotation": 11
    },
    {
      "x": -9,
      "y": 8,
      "z": 20,
      "name": "Wood_Softwood_Roof_Shallow",
      "rotation": 3
    },
    {
      "x": -8,
      "y": 1,
      "z": 1,
      "name": "Rock_Stone_Cobble"
    },
    {
      "x": -8,
      "y": 6,
      "z": 1,
      "name": "Wood_Beech_Branch_Short",
      "support": 15,
      "rotation": 2
    },
    {
      "x": -8,
      "y": 7,
      "z": 1,
      "name": "Wood_Beech_Branch_Corner",
      "support": 15,
      "rotation": 2
    },
    {
      "x": -8,
      "y": 8,
      "z": 1,
      "name": "Wood_Softwood_Roof_Shallow",
      "filler": 1,
      "rotation": 3
    },
    {
      "x": -8,
      "y": 1,
      "z": 2,
      "name": "Rock_Stone_Cobble"
    },
    {
      "x": -8,
      "y": 2,
      "z": 2,
      "name": "Wood_Beech_Trunk",
      "support": 15
    },
    {
      "x": -8,
      "y": 3,
      "z": 2,
      "name": "Wood_Beech_Trunk",
      "support": 15
    },
    {
      "x": -8,
      "y": 4,
      "z": 2,
      "name": "Wood_Beech_Trunk",
      "support": 15
    },
    {
      "x": -8,
      "y": 5,
      "z": 2,
      "name": "Wood_Beech_Trunk",
      "support": 15
    },
    {
      "x": -8,
      "y": 6,
      "z": 2,
      "name": "Wood_Beech_Trunk",
      "support": 15
    },
    {
      "x": -8,
      "y": 7,
      "z": 2,
      "name": "Wood_Beech_Trunk",
      "support": 15
    },
    {
      "x": -8,
