{
  "version": 8,
  "blockIdVersion": 11,
  "anchorX": 0,
  "anchorY": 0,
  "anchorZ": 0,
  "blocks": [
    {
      "x": 1,
      "y": 0,
      "z": -21,
      "name": "Soil_Dirt"
    },
    {
      "x": 1,
      "y": 1,
      "z": -21,
      "name": "Soil_Grass"
    },
    {
      "x": 1,
      "y": 0,
      "z": -20,
      "name": "Soil_Dirt"
    },
    {
      "x": 1,
      "y": 1,
      "z": -20,
      "name": "Soil_Grass"
    },
    {
      "x": 1,
      "y": 0,
      "z": -19,
      "name": "Soil_Dirt"
    },
    {
      "x": 1,
      "y": 1,
      "z": -19,
      "name": "Soil_Gravel"
    },
    {
      "x": 1,
      "y": 0,
      "z": -18,
      "name": "Soil_Dirt"
    },
    {
      "x": 1,
      "y": 1,
      "z": -18,
      "name": "Soil_Dirt"
    },
    {
      "x": 1,
      "y": 0,
      "z": -17,
      "name": "Soil_Dirt"
    },
    {
      "x": 1,
      "y": 1,
      "z": -17,
      "name": "Rock_Calcite_Cobble"
    },
    {
      "x": 1,
      "y": 0,
      "z": -16,
      "name": "Soil_Dirt"
    },
    {
      "x": 1,
      "y": 1,
      "z": -16,
      "name": "Rock_Stone_Cobble_Mossy"
    },
    {
      "x": 1,
      "y": 0,
      "z": -15,
      "name": "Soil_Grass"
    },
    {
      "x": 1,
      "y": 1,
      "z": -15,
      "name": "Plant_Bush_Green"
    },
    {
      "x": 1,
      "y": 0,
      "z": -14,
      "name": "Soil_Grass"
    },
    {
      "x": 1,
      "y": 0,
      "z": -13,
      "name": "Soil_Dirt"
    },
    {
      "x": 1,
      "y": 1,
      "z": -13,
      "name": "Rock_Calcite_Cobble_Stairs",
      "rotation": 3
    },
    {
      "x": 1,
      "y": 0,
      "z": -12,
      "name": "Soil_Grass"
    },
    {
      "x": 1,
      "y": 0,
      "z": -11,
      "name": "Soil_Grass"
    },
    {
      "x": 1,
      "y": 1,
      "z": -11,
      "name": "Plant_Grass_Sharp_Wild"
    },
    {
      "x": 1,
      "y": 2,
      "z": -11,
      "name": "Plant_Grass_Sharp_Wild",
      "filler": 1024
    },
    {
      "x": 1,
      "y": 12,
      "z": -11,
      "name": "Rock_Calcite_Cobble_Stairs",
      "rotation": 9
    },
    {
      "x": 1,
      "y": 0,
      "z": -10,
      "name": "Soil_Grass"
    },
    {
      "x": 1,
      "y": 0,
      "z": -9,
      "name": "Soil_Grass"
    },
    {
      "x": 1,
      "y": 0,
      "z": -8,
      "name": "Soil_Gravel"
    },
    {
      "x": 1,
      "y": 0,
      "z": -7,
      "name": "Soil_Dirt_Burnt"
    },
    {
      "x": 1,
      "y": 0,
      "z": -6,
      "name": "Soil_Dirt"
    },
    {
      "x": 1,
      "y": 0,
      "z": -5,
      "name": "Soil_Dirt_Burnt"
    },
    {
      "x": 1,
      "y": 1,
      "z": -5,
      "name": "Plant_Grass_Sharp_Wild"
    },
    {
      "x": 1,
      "y": 2,
      "z": -5,
      "name": "Plant_Grass_Sharp_Wild",
      "filler": 1024
    },
    {
      "x": 1,
      "y": 0,
      "z": -4,
      "name": "Soil_Dirt"
    },
    {
      "x": 1,
      "y": 0,
      "z": -3,
      "name": "Soil_Dirt_Burnt"
    },
    {
      "x": 1,
      "y": 0,
      "z": -2,
      "name": "Soil_Dirt"
    },
    {
      "x": 1,
      "y": 0,
      "z": -1,
      "name": "Rock_Stone_Cobble_Mossy"
    },
    {
      "x": 2,
      "y": 0,
      "z": -21,
      "name": "Soil_Dirt"
    },
    {
      "x": 2,
      "y": 1,
      "z": -21,
      "name": "Soil_Gravel"
    },
    {
      "x": 2,
      "y": 0,
      "z": -20,
      "name": "Soil_Dirt"
    },
    {
      "x": 2,
      "y": 1,
      "z": -20,
      "name": "Soil_Grass"
    },
    {
      "x": 2,
      "y": 0,
      "z": -19,
      "name": "Soil_Dirt"
    },
    {
      "x": 2,
      "y": 1,
      "z": -19,
      "name": "Soil_Dirt_Burnt"
    },
    {
      "x": 2,
      "y": 2,
      "z": -19,
      "name": "Plant_Bush_Green"
    },
    {
      "x": 2,
      "y": 0,
      "z": -18,
      "name": "Soil_Dirt"
    },
    {
      "x": 2,
      "y": 1,
      "z": -18,
      "name": "Rock_Stone"
    },
    {
      "x": 2,
      "y": 0,
      "z": -17,
      "name": "Soil_Dirt"
    },
    {
      "x": 2,
      "y": 1,
      "z": -17,
      "name": "Soil_Dirt_Burnt"
    },
    {
      "x": 2,
      "y": 2,
      "z": -17,
      "name": "Furniture_Crude_Candle"
    },
    {
      "x": 2,
      "y": 0,
      "z": -16,
      "name": "Soil_Dirt"
    },
    {
      "x": 2,
      "y": 1,
      "z": -16,
      "name": "Soil_Grass"
    },
    {
      "x": 2,
      "y": 2,
      "z": -16,
      "name": "Plant_Leaves_Beech",
      "support": 15
    },
    {
      "x": 2,
      "y": 3,
      "z": -16,
      "name": "Plant_Leaves_Beech",
      "support": 15
    },
    {
      "x": 2,
      "y": 0,
      "z": -15,
      "name": "Soil_Dirt"
    },
    {
      "x": 2,
      "y": 1,
      "z": -15,
      "name": "Rock_Calcite_Cobble_Stairs",
      "rotation": 3
    },
    {
      "x": 2,
      "y": 0,
      "z": -14,
      "name": "Soil_Dirt"
    },
    {
      "x": 2,
      "y": 1,
      "z": -14,
      "name": "Rock_Stone_Brick"
    },
    {
      "x": 2,
      "y": 7,
      "z": -14,
      "name": "Rock_Basalt_Cobble_Roof_Hollow",
      "rotation": 2
    },
    {
      "x": 2,
      "y": 0,
      "z": -13,
      "name": "Soil_Dirt"
    },
    {
      "x": 2,
      "y": 1,
      "z": -13,
      "name": "Rock_Stone_Brick"
    },
    {
      "x": 2,
      "y": 2,
      "z": -13,
      "name": "Rock_Stone_Brick"
    },
    {
      "x": 2,
      "y": 3,
      "z": -13,
      "name": "Rock_Stone"
    },
    {
      "x": 2,
      "y": 4,
      "z": -13,
      "name": "Rock_Stone_Brick"
    },
    {
      "x": 2,
      "y": 5,
      "z": -13,
      "name": "Rock_Calcite_Cobble_Stairs",
      "rotation": 3
    },
    {
      "x": 2,
      "y": 6,
      "z": -13,
      "name": "Rock_Stone"
    },
    {
      "x": 2,
      "y": 7,
      "z": -13,
      "name": "Rock_Stone_Brick"
    },
    {
      "x": 2,
      "y": 8,
      "z": -13,
      "name": "Rock_Stone_Brick_Stairs",
      "rotation": 2
    },
    {
      "x": 2,
      "y": 9,
      "z": -13,
      "name": "Rock_Stone_Brick_Stairs",
      "rotation": 8
    },
    {
      "x": 2,
      "y": 10,
      "z": -13,
      "name": "Rock_Calcite_Cobble_Beam"
    },
    {
      "x": 2,
      "y": 0,
      "z": -12,
      "name": "Soil_Dirt"
    },
    {
      "x": 2,
      "y": 1,
      "z": -12,
      "name": "Rock_Stone_Brick"
    },
    {
      "x": 2,
      "y": 2,
      "z": -12,
      "name": "Rock_Stone_Brick_Stairs",
      "rotation": 3
    },
    {
      "x": 2,
      "y": 6,
      "z": -12,
      "name": "Rock_Stone_Brick_Stairs",
      "rotation": 10
    },
    {
      "x": 2,
      "y": 7,
      "z": -12,
      "name": "Rock_Stone_Brick_Stairs",
      "rotation": 10
    },
    {
      "x": 2,
      "y": 8,
      "z": -12,
      "name": "Rock_Stone"
    },
    {
      "x": 2,
      "y": 9,
      "z": -12,
      "name": "Rock_Stone"
    },
    {
      "x": 2,
      "y": 10,
      "z": -12,
      "name": "Rock_Stone_Brick_Stairs",
      "rotation": 2
    },
    {
      "x": 2,
      "y": 11,
      "z": -12,
      "name": "Rock_Calcite_Cobble_Stairs",
      "rotation": 8
    },
    {
      "x": 2,
      "y": 12,
      "z": -12,
      "name": "Rock_Calcite_Cobble_Beam"
    },
    {
      "x": 2,
      "y": 0,
      "z": -11,
      "name": "Soil_Dirt"
    },
    {
      "x": 2,
      "y": 1,
      "z": -11,
      "name": "Rock_Stone_Brick"
    },
    {
      "x": 2,
      "y": 2,
      "z": -11,
      "name": "Rock_Stone_Brick"
    },
    {
      "x": 2,
      "y": 7,
      "z": -11,
      "name": "Rock_Stone"
    },
    {
      "x": 2,
      "y": 8,
      "z": -11,
      "name": "Rock_Stone_Brick_Stairs",
      "rotation": 3
    },
    {
      "x": 2,
      "y": 10,
      "z": -11,
      "name": "Rock_Calcite_Cobble_Stairs",
      "rotation": 9
    },
    {
      "x": 2,
      "y": 11,
      "z": -11,
      "name": "Rock_Calcite_Cobble"
    },
    {
      "x": 2,
      "y": 12,
      "z": -11,
      "name": "Rock_Basalt_Cobble_Roof",
      "rotation": 1
    },
    {
      "x": 2,
      "y": 0,
      "z": -10,
      "name": "Soil_Dirt"
    },
    {
      "x": 2,
      "y": 1,
      "z": -10,
      "name": "Rock_Stone_Brick"
    },
    {
      "x": 2,
      "y": 2,
      "z": -10,
      "name": "Rock_Stone_Brick_Stairs",
      "rotation": 3
    },
    {
      "x": 2,
      "y": 6,
      "z": -10,
      "name": "Rock_Stone_Brick_Stairs",
      "rotation": 8
    },
    {
      "x": 2,
      "y": 7,
      "z": -10,
      "name": "Rock_Stone_Brick_Stairs",
      "rotation": 8
    },
    {
      "x": 2,
      "y": 8,
      "z": -10,
      "name": "Rock_Stone_Brick"
    },
    {
      "x": 2,
      "y": 9,
      "z": -10,
      "name": "Rock_Stone"
    },
    {
      "x": 2,
      "y": 10,
      "z": -10,
      "name": "Rock_Stone_Brick_Stairs"
    },
    {
      "x": 2,
      "y": 11,
      "z": -10,
      "name": "Rock_Stone_Brick_Stairs",
      "rotation": 10
    },
    {
      "x": 2,
      "y": 12,
      "z": -10,
      "name": "Rock_Stone_Brick_Beam"
    },
    {
      "x": 2,
      "y": 0,
      "z": -9,
      "name": "Soil_Dirt"
    },
    {
      "x": 2,
      "y": 1,
      "z": -9,
      "name": "Rock_Calcite_Cobble"
    },
    {
      "x": 2,
      "y": 2,
      "z": -9,
      "name": "Rock_Stone_Brick"
    },
    {
      "x": 2,
      "y": 3,
      "z": -9,
      "name": "Rock_Stone_Brick_Stairs"
    },
    {
      "x": 2,
      "y": 4,
      "z": -9,
      "name": "Rock_Calcite_Cobble"
    },
    {
      "x": 2,
      "y": 5,
      "z": -9,
      "name": "Rock_Stone_Brick"
    },
    {
      "x": 2,
      "y": 6,
      "z": -9,
      "name": "Rock_Stone_Brick"
    },
    {
      "x": 2,
      "y": 7,
      "z": -9,
      "name": "Rock_Stone"
    },
    {
      "x": 2,
      "y": 8,
      "z": -9,
      "name": "Rock_Stone_Brick_Stairs"
    },
    {
      "x": 2,
      "y": 9,
      "z": -9,
      "name": "Rock_Stone_Brick_Stairs",
      "rotation": 10
    },
    {
      "x": 2,
      "y": 10,
      "z": -9,
      "name": "Rock_Stone_Brick_Beam"
    },
    {
      "x": 2,
      "y": 0,
      "z": -8,
      "name": "Soil_Dirt"
    },
    {
      "x": 2,
      "y": 1,
      "z": -8,
      "name": "Rock_Calcite_Cobble_Stairs",
      "rotation": 3
    },
    {
      "x": 2,
      "y": 7,
      "z": -8,
      "name": "Rock_Basalt_Cobble_Roof_Hollow"
    },
    {
      "x": 2,
      "y": 0,
      "z": -7,
      "name": "Rock_Stone_Cobble"
    },
    {
      "x": 2,
      "y": 0,
      "z": -6,
      "name": "Rock_Stone_Cobble"
    },
    {
      "x": 2,
      "y": 0,
      "z": -5,
      "name": "Rock_Calcite_Cobble"
    },
    {
      "x": 2,
      "y": 0,
      "z": -4,
      "name": "Soil_Dirt"
    },
    {
      "x": 2,
      "y": 1,
      "z": -4,
      "name": "Rock_Stone_Brick_Stairs",
      "rotation": 3
    },
    {
      "x": 2,
      "y": 0,
      "z": -3,
      "name": "Soil_Dirt"
    },
    {
      "x": 2,
      "y": 0,
      "z": -2,
      "name": "Rock_Stone_Cobble"
    },
    {
      "x": 2,
      "y": 1,
      "z": -2,
      "name": "Furniture_Village_Tombstone"
    },
    {
      "x": 2,
      "y": 2,
      "z": -2,
      "name": "Furniture_Village_Tombstone",
      "filler": 1024
    },
    {
      "x": 2,
      "y": 0,
      "z": -1,
      "name": "Rock_Stone_Cobble"
    },
    {
      "x": 2,
      "y": 1,
      "z": -1,
      "name": "Furniture_Crude_Candle"
    },
    {
      "x": 3,
      "y": 0,
      "z": -21,
      "name": "Soil_Dirt"
    },
    {
      "x": 3,
      "y": 1,
      "z": -21,
      "name": "Soil_Gravel"
    },
    {
      "x": 3,
      "y": 2,
      "z": -21,
      "name": "Furniture_Crude_Candle"
    },
    {
      "x": 3,
      "y": 0,
      "z": -20,
      "name": "Soil_Dirt"
    },
    {
      "x": 3,
      "y": 1,
      "z": -20,
      "name": "Rock_Stone_Cobble"
    },
    {
      "x": 3,
      "y": 2,
      "z": -20,
      "name": "Furniture_Village_Tombstone",
      "rotation": 2
    },
    {
      "x": 3,
      "y": 3,
      "z": -20,
      "name": "Furniture_Village_Tombstone",
      "filler": 1024,
      "rotation": 2
    },
    {
      "x": 3,
      "y": 0,
      "z": -19,
      "name": "Soil_Dirt"
    },
    {
      "x": 3,
      "y": 1,
      "z": -19,
      "name": "Soil_Gravel"
    },
    {
      "x": 3,
      "y": 0,
      "z": -18,
      "name": "Soil_Dirt"
    },
    {
      "x": 3,
      "y": 1,
      "z": -18,
      "name": "Rock_Stone_Cobble"
    },
    {
      "x": 3,
      "y": 0,
      "z": -17,
      "name": "Soil_Dirt"
    },
    {
      "x": 3,
      "y": 1,
      "z": -17,
      "name": "Soil_Dirt"
    },
    {
      "x": 3,
      "y": 2,
      "z": -17,
      "name": "Furniture_Village_Tombstone",
      "rotation": 3
    },
    {
      "x": 3,
      "y": 3,
      "z": -17,
      "name": "Furniture_Village_Tombstone",
      "filler": 1024,
      "rotation": 3
    },
    {
      "x": 3,
      "y": 0,
      "z": -16,
      "name": "Soil_Dirt"
    },
    {
      "x": 3,
      "y": 1,
      "z": -16,
      "name": "Rock_Stone_Cobble"
    },
    {
      "x": 3,
      "y": 2,
      "z": -16,
      "name": "Plant_Leaves_Beech",
      "support": 15
    },
    {
      "x": 3,
      "y": 3,
      "z": -16,
      "name": "Plant_Leaves_Beech",
      "support": 15
    },
    {
      "x": 3,
      "y": 4,
      "z": -16,
      "name": "Plant_Leaves_Beech",
      "support": 15
    },
    {
      "x": 3,
      "y": 0,
      "z": -15,
      "name": "Soil_Dirt"
    },
    {
      "x": 3,
      "y": 1,
      "z": -15,
      "name": "Rock_Calcite_Cobble"
    },
    {
      "x": 3,
      "y": 2,
      "z": -15,
      "name": "Plant_Leaves_Beech",
      "support": 15
    },
    {
      "x": 3,
      "y": 3,
      "z": -15,
      "name": "Plant_Leaves_Beech",
      "support": 15
    },
    {
      "x": 3,
      "y": 4,
      "z": -15,
      "name": "Plant_Leaves_Beech",
      "support": 15
    },
    {
      "x": 3,
      "y": 5,
      "z": -15,
      "name": "Plant_Leaves_Beech",
      "support": 15
    },
    {
      "x": 3,
      "y": 7,
      "z": -15,
      "name": "Rock_Basalt_Cobble_Roof_Hollow",
      "rotation": 3
    },
    {
      "x": 3,
      "y": 8,
      "z": -15,
      "name": "Plant_Leaves_Beech",
      "support": 15
    },
    {
      "x": 3,
      "y": 9,
      "z": -15,
      "name": "Plant_Leaves_Beech",
      "support": 15
    },
    {
      "x": 3,
      "y": 0,
      "z": -14,
      "name": "Soil_Dirt"
    },
    {
      "x": 3,
      "y": 1,
      "z": -14,
      "name": "Rock_Stone_Brick"
    },
    {
      "x": 3,
      "y": 2,
      "z": -14,
      "name": "Rock_Stone_Brick"
    },
    {
      "x": 3,
      "y": 3,
      "z": -14,
      "name": "*Rock_Stone_Brick_Wall_State_Definitions_Corner",
      "rotation": 1
    },
    {
      "x": 3,
      "y": 5,
      "z": -14,
      "name": "Plant_Leaves_Beech",
      "support": 15
    },
    {
      "x": 3,
      "y": 6,
      "z": -14,
      "name": "Plant_Leaves_Beech",
      "support": 15
    },
    {
      "x": 3,
      "y": 7,
      "z": -14,
      "name": "*Rock_Basalt_Cobble_Roof_Hollow_State_Definitions_Inverted_Corner_Left",
      "rotation": 2
    },
    {
      "x": 3,
      "y": 0,
      "z": -13,
      "name": "Rock_Stone_Brick"
    },
    {
      "x": 3,
      "y": 1,
      "z": -13,
      "name": "Rock_Stone_Brick"
    },
    {
      "x": 3,
      "y": 2,
      "z": -13,
      "name": "Rock_Stone_Brick"
    },
    {
      "x": 3,
      "y": 3,
      "z": -13,
      "name": "Rock_Stone_Brick"
    },
    {
      "x": 3,
      "y": 4,
      "z": -13,
      "name": "Rock_Calcite_Cobble"
    },
    {
      "x": 3,
      "y": 5,
      "z": -13,
      "name": "Rock_Stone_Brick"
    },
    {
      "x": 3,
      "y": 6,
      "z": -13,
      "name": "Rock_Stone"
    },
    {
      "x": 3,
      "y": 7,
      "z": -13,
      "name": "Rock_Stone"
    },
    {
      "x": 3,
      "y": 8,
      "z": -13,
      "name": "Rock_Basalt_Cobble_Roof_Steep",
      "rotation": 2
    },
    {
      "x": 3,
      "y": 9,
      "z": -13,
      "name": "Rock_Basalt_Cobble_Roof_Steep",
      "filler": 1024,
      "rotation": 2
    },
    {
      "x": 3,
      "y": 0,
      "z": -12,
      "name": "Soil_Dirt"
    },
    {
      "x": 3,
      "y": 1,
      "z": -12,
      "name": "Rock_Stone_Brick"
    },
    {
      "x": 3,
      "y": 2,
      "z": -12,
      "name": "Rock_Stone_Brick"
    },
    {
      "x": 3,
      "y": 3,
      "z": -12,
      "name": "Furniture_Temple_Wind_Window",
      "rotation": 1
    },
    {
      "x": 3,
      "y": 4,
      "z": -12,
      "name": "Furniture_Temple_Wind_Window",
      "rotation": 1
    },
    {
      "x": 3,
      "y": 5,
      "z": -12,
      "name": "Furniture_Temple_Wind_Window",
      "rotation": 1
    },
    {
      "x": 3,
      "y": 6,
      "z": -12,
      "name": "Furniture_Temple_Wind_Window",
      "rotation": 1
    },
    {
      "x": 3,
      "y": 7,
      "z": -12,
      "name": "*Rock_Stone_Brick_Stairs_State_Definitions_Inverted_Corner_Right",
      "rotation": 10
    },
    {
      "x": 3,
      "y": 8,
      "z": -12,
      "name": "Rock_Stone"
    },
    {
      "x": 3,
      "y": 9,
      "z": -12,
      "name": "Wood_Darkwood_Planks"
    },
    {
      "x": 3,
      "y": 10,
      "z": -12,
      "name": "Rock_Basalt_Cobble_Roof_Steep",
      "rotation": 2
    },
    {
      "x": 3,
      "y": 11,
      "z": -12,
      "name": "Rock_Basalt_Cobble_Roof_Steep",
      "filler": 1024,
      "rotation": 2
    },
    {
      "x": 3,
      "y": 0,
      "z": -11,
      "name": "Soil_Dirt"
    },
    {
      "x": 3,
      "y": 1,
      "z": -11,
      "name": "Rock_Stone_Brick"
    },
    {
      "x": 3,
      "y": 2,
      "z": -11,
      "name": "Rock_Stone_Brick"
    },
    {
      "x": 3,
      "y": 3,
      "z": -11,
      "name": "Furniture_Temple_Wind_Window",
      "rotation": 1
    },
    {
      "x": 3,
      "y": 4,
      "z": -11,
      "name": "Furniture_Temple_Wind_Window",
      "rotation": 1
    },
    {
      "x": 3,
      "y": 5,
      "z": -11,
      "name": "Furniture_Temple_Wind_Window",
      "rotation": 1
    },
    {
      "x": 3,
      "y": 6,
      "z": -11,
      "name": "Furniture_Temple_Wind_Window",
      "rotation": 1
    },
    {
      "x": 3,
      "y": 7,
      "z": -11,
      "name": "Rock_Stone_Brick_Stairs",
      "rotation": 11
    },
    {
      "x": 3,
      "y": 8,
      "z": -11,
      "name": "Rock_Stone_Cobble"
    },
    {
      "x": 3,
      "y": 9,
      "z": -11,
      "name": "Rock_Stone"
    },
    {
      "x": 3,
      "y": 10,
      "z": -11,
      "name": "Rock_Stone"
    },
    {
      "x": 3,
      "y": 11,
      "z": -11,
      "name": "Wood_Darkwood_Planks"
    },
    {
      "x": 3,
      "y": 12,
      "z": -11,
      "name": "Rock_Basalt_Cobble_Roof_Flat",
      "rotation": 2
    },
    {
      "x": 3,
      "y": 0,
      "z": -10,
      "name": "Rock_Stone_Brick"
    },
    {
      "x": 3,
      "y": 1,
      "z": -10,
      "name": "Rock_Stone_Brick"
    },
    {
      "x": 3,
      "y": 2,
      "z": -10,
      "name": "Rock_Stone"
    },
    {
      "x": 3,
      "y": 3,
      "z": -10,
      "name": "Furniture_Temple_Wind_Window",
      "rotation": 1
    },
    {
      "x": 3,
      "y": 4,
      "z": -10,
      "name": "Furniture_Temple_Wind_Window",
      "rotation": 1
    },
    {
      "x": 3,
      "y": 5,
      "z": -10,
      "name": "Furniture_Temple_Wind_Window",
      "rotation": 1
    },
    {
      "x": 3,
      "y": 6,
      "z": -10,
      "name": "Furniture_Temple_Wind_Window",
      "rotation": 1
    },
    {
      "x": 3,
      "y": 7,
      "z": -10,
      "name": "*Rock_Stone_Brick_Stairs_State_Definitions_Inverted_Corner_Left",
      "rotation": 8
    },
    {
      "x": 3,
      "y": 8,
      "z": -10,
      "name": "Rock_Stone_Cobble"
    },
    {
      "x": 3,
      "y": 9,
      "z": -10,
      "name": "Wood_Darkwood_Planks"
    },
    {
      "x": 3,
      "y": 10,
      "z": -10,
      "name": "Rock_Basalt_Cobble_Roof_Steep"
    },
    {
      "x": 3,
      "y": 11,
      "z": -10,
      "name": "Rock_Basalt_Cobble_Roof_Steep",
      "filler": 1024
    },
    {
      "x": 3,
      "y": 0,
      "z": -9,
      "name": "Soil_Dirt"
    },
    {
      "x": 3,
      "y": 1,
      "z": -9,
      "name": "Rock_Stone_Brick"
    },
    {
      "x": 3,
      "y": 2,
      "z": -9,
      "name": "Rock_Stone"
    },
    {
      "x": 3,
      "y": 3,
      "z": -9,
      "name": "Rock_Stone_Brick"
    },
    {
      "x": 3,
      "y": 4,
      "z": -9,
      "name": "Rock_Stone"
    },
    {
      "x": 3,
      "y": 5,
      "z": -9,
      "name": "Rock_Stone"
    },
    {
      "x": 3,
      "y": 6,
      "z": -9,
      "name": "Rock_Stone"
    },
    {
      "x": 3,
      "y": 7,
      "z": -9,
      "name": "Rock_Stone"
    },
    {
      "x": 3,
      "y": 8,
      "z": -9,
      "name": "Rock_Basalt_Cobble_Roof_Steep"
    },
    {
      "x": 3,
      "y": 9,
      "z": -9,
      "name": "Rock_Basalt_Cobble_Roof_Steep",
      "filler": 1024
    },
    {
      "x": 3,
      "y": 0,
      "z": -8,
      "name": "Soil_Dirt"
    },
    {
      "x": 3,
      "y": 1,
      "z": -8,
      "name": "Rock_Stone_Brick"
    },
    {
      "x": 3,
      "y": 2,
      "z": -8,
      "name": "Rock_Stone_Brick"
    },
    {
      "x": 3,
      "y": 3,
      "z": -8,
      "name": "Rock_Stone_Brick_Stairs",
      "rotation": 3
    },
    {
      "x": 3,
      "y": 7,
      "z": -8,
      "name": "*Rock_Basalt_Cobble_Roof_Hollow_State_Definitions_Inverted_Corner_Left",
      "rotation": 3
    },
    {
      "x": 3,
      "y": 0,
      "z": -7,
      "name": "Soil_Dirt"
    },
    {
      "x": 3,
      "y": 1,
      "z": -7,
      "name": "Rock_Calcite_Cobble"
    },
    {
      "x": 3,
      "y": 7,
      "z": -7,
      "name": "Rock_Basalt_Cobble_Roof_Hollow",
      "rotation": 3
    },
    {
      "x": 3,
      "y": 0,
      "z": -6,
      "name": "Soil_Dirt"
    },
    {
      "x": 3,
      "y": 1,
      "z": -6,
      "name": "Rock_Stone_Brick_Stairs",
      "rotation": 3
    },
    {
      "x": 3,
      "y": 7,
      "z": -6,
      "name": "Rock_Basalt_Cobble_Roof_Hollow",
      "rotation": 3
    },
    {
      "x": 3,
      "y": 0,
      "z": -5,
      "name": "Soil_Dirt"
    },
    {
      "x": 3,
      "y": 1,
      "z": -5,
      "name": "Rock_Stone_Brick"
    },
    {
      "x": 3,
      "y": 2,
      "z": -5,
      "name": "Rock_Calcite_Cobble_Stairs",
      "rotation": 3
    },
    {
      "x": 3,
      "y": 7,
      "z": -5,
      "name": "Rock_Basalt_Cobble_Roof_Hollow",
      "rotation": 3
    },
    {
      "x": 3,
      "y": 0,
      "z": -4,
      "name": "Soil_Dirt"
    },
    {
      "x": 3,
      "y": 1,
      "z": -4,
      "name": "Rock_Stone_Brick"
    },
    {
      "x": 3,
      "y": 2,
      "z": -4,
      "name": "Rock_Calcite_Cobble"
    },
    {
      "x": 3,
      "y": 7,
      "z": -4,
      "name": "Rock_Basalt_Cobble_Roof_Hollow",
      "rotation": 3
    },
    {
      "x": 3,
      "y": 0,
      "z": -3,
      "name": "Rock_Stone_Cobble"
    },
    {
      "x": 3,
      "y": 1,
      "z": -3,
      "name": "Rock_Calcite_Cobble"
    },
    {
      "x": 3,
      "y": 0,
      "z": -2,
      "name": "Soil_Dirt"
    },
    {
      "x": 3,
      "y": 1,
      "z": -2,
      "name": "Plant_Bush_Green"
    },
    {
      "x": 3,
      "y": 0,
      "z": -1,
      "name": "Rock_Stone"
    },
    {
      "x": 4,
      "y": 0,
      "z": -21,
      "name": "Soil_Dirt"
    },
    {
      "x": 4,
      "y": 1,
      "z": -21,
      "name": "Soil_Dirt_Burnt"
    },
    {
      "x": 4,
      "y": 2,
      "z": -21,
      "name": "Plant_Bush_Green"
    },
    {
      "x": 4,
      "y": 0,
      "z": -20,
      "name": "Soil_Dirt"
    },
    {
      "x": 4,
      "y": 1,
      "z": -20,
      "name": "Soil_Dirt"
    },
    {
      "x": 4,
      "y": 2,
      "z": -20,
      "name": "Plant_Bush_Green"
    },
    {
      "x": 4,
      "y": 0,
      "z": -19,
      "name": "Soil_Dirt"
    },
    {
      "x": 4,
      "y": 1,
      "z": -19,
      "name": "Soil_Dirt_Burnt"
    },
    {
      "x": 4,
      "y": 2,
      "z": -19,
      "name": "Rock_Stone_Brick_Smooth_Half"
    },
    {
      "x": 4,
      "y": 21,
      "z": -19,
      "name": "Rock_Stone_Brick_Stairs",
      "rotation": 9
    },
    {
      "x": 4,
      "y": 22,
      "z": -19,
      "name": "Rock_Stone_Brick"
    },
    {
      "x": 4,
      "y": 23,
      "z": -19,
      "name": "Rock_Calcite_Cobble_Stairs",
      "rotation": 3
    },
    {
      "x": 4,
      "y": 0,
      "z": -18,
      "name": "Soil_Dirt"
    },
    {
      "x": 4,
      "y": 1,
      "z": -18,
      "name": "Soil_Dirt_Burnt"
    },
    {
      "x": 4,
      "y": 2,
      "z": -18,
      "name": "Rock_Stone_Brick"
    },
    {
      "x": 4,
      "y": 22,
      "z": -18,
      "name": "Rock_Stone_Brick_Stairs",
      "rotation": 9
    },
    {
      "x": 4,
      "y": 23,
      "z": -18,
      "name": "Rock_Calcite_Cobble_Half"
    },
    {
      "x": 4,
      "y": 0,
      "z": -17,
      "name": "Soil_Dirt"
    },
    {
      "x": 4,
      "y": 1,
      "z": -17,
      "name": "Soil_Gravel"
    },
    {
      "x": 4,
      "y": 2,
      "z": -17,
      "name": "Rock_Stone_Brick"
    },
    {
      "x": 4,
      "y": 3,
      "z": -17,
      "name": "Rock_Stone_Brick_Stairs",
      "rotation": 2
    },
    {
      "x": 4,
      "y": 21,
      "z": -17,
      "name": "Rock_Stone_Brick_Stairs",
      "rotation": 9
    },
    {
      "x": 4,
      "y": 22,
      "z": -17,
      "name": "Rock_Stone_Brick"
    },
    {
      "x": 4,
      "y": 23,
      "z": -17,
      "name": "Rock_Stone_Brick_Beam"
    },
    {
      "x": 4,
      "y": 0,
      "z": -16,
      "name": "Soil_Dirt"
    },
    {
      "x": 4,
      "y": 1,
      "z": -16,
      "name": "Soil_Gravel"
    },
    {
      "x": 4,
      "y": 2,
      "z": -16,
      "name": "Rock_Stone"
    },
    {
      "x": 4,
      "y": 3,
      "z": -16,
      "name": "Rock_Stone_Brick"
    },
    {
      "x": 4,
      "y": 4,
      "z": -16,
      "name": "Rock_Stone_Brick_Wall",
      "rotation": 1
    },
    {
      "x": 4,
      "y": 10,
      "z": -16,
      "name": "Plant_Leaves_Beech",
      "support": 15
    },
    {
      "x": 4,
      "y": 11,
      "z": -16,
      "name": "Plant_Leaves_Beech",
      "support": 15
    },
    {
      "x": 4,
      "y": 22,
      "z": -16,
      "name": "Rock_Calcite_Cobble_Stairs",
      "rotation": 9
    },
    {
      "x": 4,
      "y": 23,
      "z": -16,
      "name": "Rock_Stone_Brick_Smooth_Half"
    },
    {
      "x": 4,
      "y": 0,
      "z": -15,
      "name": "Soil_Dirt"
    },
    {
      "x": 4,
      "y": 1,
      "z": -15,
      "name": "Rock_Calcite_Cobble"
    },
    {
      "x": 4,
      "y": 2,
      "z": -15,
      "name": "Rock_Stone_Brick"
    },
    {
      "x": 4,
      "y": 3,
      "z": -15,
      "name": "Rock_Stone_Brick"
    },
    {
      "x": 4,
      "y": 4,
      "z": -15,
      "name": "Rock_Calcite_Cobble"
    },
    {
      "x": 4,
      "y": 5,
      "z": -15,
      "name": "Rock_Stone"
    },
    {
      "x": 4,
      "y": 6,
      "z": -15,
      "name": "Rock_Stone_Brick"
    },
    {
      "x": 4,
      "y": 7,
      "z": -15,
      "name": "Rock_Stone_Brick"
    },
    {
      "x": 4,
      "y": 8,
      "z": -15,
      "name": "Rock_Stone_Brick_Stairs",
      "rotation": 3
    },
    {
      "x": 4,
      "y": 9,
      "z": -15,
      "name": "Rock_Stone_Brick_Stairs",
      "rotation": 9
    },
    {
      "x": 4,
      "y": 21,
      "z": -15,
      "name": "Rock_Stone_Brick_Stairs",
      "rotation": 9
    },
    {
      "x": 4,
      "y": 22,
      "z": -15,
      "name": "Rock_Calcite_Cobble"
    },
    {
      "x": 4,
      "y": 23,
      "z": -15,
      "name": "Rock_Stone_Brick_Stairs",
      "rotation": 3
    },
    {
      "x": 4,
      "y": 0,
      "z": -14,
      "name": "Soil_Dirt"
    },
    {
      "x": 4,
      "y": 1,
      "z": -14,
      "name": "Rock_Stone_Brick"
    },
    {
      "x": 4,
      "y": 2,
      "z": -14,
      "name": "Rock_Stone_Brick"
    },
    {
      "x": 4,
      "y": 3,
      "z": -14,
      "name": "Rock_Stone_Brick"
    },
    {
      "x": 4,
      "y": 4,
      "z": -14,
      "name": "Rock_Calcite_Cobble"
    },
    {
      "x": 4,
      "y": 5,
      "z": -14,
      "name": "Rock_Stone"
    },
    {
      "x": 4,
      "y": 6,
      "z": -14,
      "name": "Rock_Stone"
    },
    {
      "x": 4,
      "y": 7,
      "z": -14,
      "name": "Rock_Calcite_Cobble"
    },
    {
      "x": 4,
      "y": 8,
      "z": -14,
      "name": "Rock_Basalt_Cobble_Roof_Steep",
      "rotation": 3
    },
    {
      "x": 4,
      "y": 9,
      "z": -14,
      "name": "Rock_Basalt_Cobble_Roof_Steep",
      "filler": 1024,
      "rotation": 3
    },
    {
      "x": 4,
      "y": 0,
      "z": -13,
      "name": "Soil_Dirt"
    },
    {
      "x": 4,
      "y": 1,
      "z": -13,
      "name": "Rock_Stone_Brick"
    },
    {
      "x": 4,
      "y": 2,
      "z": -13,
      "name": "Rock_Calcite_Cobble"
    },
    {
      "x": 4,
      "y": 3,
      "z": -13,
      "name": "Rock_Stone_Brick"
    },
    {
      "x": 4,
      "y": 4,
      "z": -13,
      "name": "Rock_Stone"
    },
    {
      "x": 4,
      "y": 5,
      "z": -13,
      "name": "Rock_Stone"
    },
    {
      "x": 4,
      "y": 6,
      "z": -13,
      "name": "Rock_Calcite_Cobble"
    },
    {
      "x": 4,
      "y": 7,
      "z": -13,
      "name": "Rock_Calcite_Cobble"
    },
    {
      "x": 4,
      "y": 8,
      "z": -13,
      "name": "*Rock_Basalt_Cobble_Roof_Steep_State_Definitions_Inverted_Corner_Left",
      "rotation": 2
    },
    {
      "x": 4,
      "y": 9,
      "z": -13,
      "name": "*Rock_Basalt_Cobble_Roof_Steep_State_Definitions_Inverted_Corner_Left",
      "filler": 1024,
      "rotation": 2
    },
    {
      "x": 4,
      "y": 0,
      "z": -12,
      "name": "Soil_Dirt"
    },
    {
      "x": 4,
      "y": 1,
      "z": -12,
      "name": "Rock_Stone_Brick"
    },
    {
      "x": 4,
      "y": 2,
      "z": -12,
      "name": "Rock_Stone_Brick"
    },
    {
      "x": 4,
      "y": 6,
      "z": -12,
      "name": "Rock_Stone_Brick_Stairs",
      "rotation": 10
    },
    {
      "x": 4,
      "y": 7,
      "z": -12,
      "name": "Rock_Stone_Brick_Stairs",
      "rotation": 10
    },
    {
      "x": 4,
      "y": 8,
      "z": -12,
      "name": "Rock_Stone"
    },
    {
      "x": 4,
      "y": 9,
      "z": -12,
      "name": "Wood_Darkwood_Planks"
    },
    {
      "x": 4,
      "y": 10,
      "z": -12,
      "name": "Rock_Basalt_Cobble_Roof_Steep",
      "rotation": 2
    },
    {
      "x": 4,
      "y": 11,
      "z": -12,
      "name": "Rock_Basalt_Cobble_Roof_Steep",
      "filler": 1024,
      "rotation": 2
    },
    {
      "x": 4,
      "y": 0,
      "z": -11,
      "name": "Soil_Dirt"
    },
    {
      "x": 4,
      "y": 1,
      "z": -11,
      "name": "Rock_Stone_Brick"
    },
    {
      "x": 4,
      "y": 2,
      "z": -11,
      "name": "Rock_Stone_Brick"
    },
    {
      "x": 4,
      "y": 7,
      "z": -11,
      "name": "Rock_Stone"
    },
    {
      "x": 4,
      "y": 8,
      "z": -11,
      "name": "Rock_Stone"
    },
    {
      "x": 4,
      "y": 9,
      "z": -11,
      "name": "Rock_Stone"
    },
    {
      "x": 4,
      "y": 10,
      "z": -11,
      "name": "Rock_Stone"
    },
    {
      "x": 4,
      "y": 11,
      "z": -11,
      "name": "Wood_Darkwood_Planks"
    },
    {
      "x": 4,
      "y": 12,
      "z": -11,
      "name": "Rock_Basalt_Cobble_Roof_Flat",
      "rotation": 2
    },
    {
      "x": 4,
      "y": 0,
      "z": -10,
      "name": "Soil_Dirt"
    },
    {
      "x": 4,
      "y": 1,
      "z": -10,
      "name": "Rock_Stone_Brick"
    },
    {
      "x": 4,
      "y": 2,
      "z": -10,
      "name": "Rock_Stone_Brick_Stairs",
      "rotation": 1
    },
    {
      "x": 4,
      "y": 6,
      "z": -10,
      "name": "Rock_Calcite_Cobble_Stairs",
      "rotation": 8
    },
    {
      "x": 4,
      "y": 7,
      "z": -10,
      "name": "Rock_Stone_Brick_Stairs",
      "rotation": 8
    },
    {
      "x": 4,
      "y": 8,
      "z": -10,
      "name": "Rock_Stone"
    },
    {
      "x": 4,
      "y": 9,
      "z": -10,
      "name": "Wood_Darkwood_Planks"
    },
    {
      "x": 4,
      "y": 10,
      "z": -10,
      "name": "Rock_Basalt_Cobble_Roof_Steep"
    },
    {
      "x": 4,
      "y": 11,
      "z": -10,
      "name": "Rock_Basalt_Cobble_Roof_Steep",
      "filler": 1024
    },
    {
      "x": 4,
      "y": 0,
      "z": -9,
      "name": "Soil_Dirt"
    },
    {
      "x": 4,
      "y": 1,
      "z": -9,
      "name": "Rock_Stone_Brick"
    },
    {
      "x": 4,
      "y": 2,
      "z": -9,
      "name": "Rock_Stone_Brick"
    },
    {
      "x": 4,
      "y": 3,
      "z": -9,
      "name": "Rock_Stone_Brick"
    },
    {
      "x": 4,
      "y": 4,
      "z": -9,
      "name": "Rock_Stone"
    },
    {
      "x": 4,
      "y": 5,
      "z": -9,
      "name": "Rock_Calcite_Cobble"
    },
    {
      "x": 4,
      "y": 6,
      "z": -9,
      "name": "Rock_Stone"
    },
    {
      "x": 4,
      "y": 7,
      "z": -9,
      "name": "Rock_Stone"
    },
    {
      "x": 4,
      "y": 8,
      "z": -9,
      "name": "*Rock_Basalt_Cobble_Roof_Steep_State_Definitions_Inverted_Corner_Right"
    },
    {
      "x": 4,
      "y": 9,
      "z": -9,
      "name": "*Rock_Basalt_Cobble_Roof_Steep_State_Definitions_Inverted_Corner_Right",
      "filler": 1024
    },
    {
      "x": 4,
      "y": 0,
      "z": -8,
      "name": "Soil_Dirt"
    },
    {
      "x": 4,
      "y": 1,
      "z": -8,
      "name": "Rock_Stone_Brick"
    },
    {
      "x": 4,
      "y": 2,
      "z": -8,
      "name": "Rock_Stone_Brick"
    },
    {
      "x": 4,
      "y": 3,
      "z": -8,
      "name": "Rock_Stone_Brick"
    },
    {
      "x": 4,
      "y": 4,
      "z": -8,
      "name": "Rock_Stone_Brick"
    },
    {
      "x": 4,
      "y": 5,
      "z": -8,
      "name": "Rock_Stone_Brick"
    },
    {
      "x": 4,
      "y": 6,
      "z": -8,
      "name": "Rock_Stone"
    },
    {
      "x": 4,
      "y": 7,
      "z": -8,
      "name": "Rock_Stone"
    },
    {
      "x": 4,
      "y": 8,
      "z": -8,
      "name": "Rock_Basalt_Cobble_Roof_Steep",
      "rotation": 3
    },
    {
      "x": 4,
      "y": 9,
      "z": -8,
      "name": "Rock_Basalt_Cobble_Roof_Steep",
      "filler": 1024,
      "rotation": 3
    },
    {
      "x": 4,
      "y": 0,
      "z": -7,
      "name": "Soil_Dirt"
    },
    {
      "x": 4,
      "y": 1,
      "z": -7,
      "name": "Rock_Stone_Brick"
    },
    {
      "x": 4,
      "y": 2,
      "z": -7,
      "name": "Rock_Calcite_Cobble"
    },
    {
      "x": 4,
      "y": 3,
      "z": -7,
      "name": "Rock_Stone"
    },
    {
      "x": 4,
      "y": 4,
      "z": -7,
      "name": "Rock_Stone"
    },
    {
      "x": 4,
      "y": 5,
      "z": -7,
      "name": "Rock_Stone"
    },
    {
      "x": 4,
      "y": 6,
      "z": -7,
      "name": "Rock_Calcite_Cobble"
    },
    {
      "x": 4,
      "y": 7,
      "z": -7,
      "name": "Rock_Stone"
    },
    {
      "x": 4,
      "y": 8,
      "z": -7,
      "name": "Rock_Basalt_Cobble_Roof_Steep",
      "rotation": 3
    },
    {
      "x": 4,
      "y": 9,
      "z": -7,
      "name": "Rock_Basalt_Cobble_Roof_Steep",
      "filler": 1024,
      "rotation": 3
    },
    {
      "x": 4,
      "y": 0,
      "z": -6,
      "name": "Soil_Dirt"
    },
    {
      "x": 4,
      "y": 1,
      "z": -6,
      "name": "Rock_Stone_Brick"
    },
    {
      "x": 4,
      "y": 2,
      "z": -6,
      "name": "Rock_Calcite_Cobble"
    },
    {
      "x": 4,
      "y": 3,
      "z": -6,
      "name": "Rock_Stone_Brick"
    },
    {
      "x": 4,
      "y": 4,
      "z": -6,
      "name": "Rock_Stone_Brick"
    },
    {
      "x": 4,
      "y": 5,
      "z": -6,
      "name": "Rock_Stone"
    },
    {
      "x": 4,
      "y": 6,
      "z": -6,
      "name": "Rock_Stone"
    },
    {
      "x": 4,
      "y": 7,
      "z": -6,
      "name": "Rock_Stone"
    },
    {
      "x": 4,
      "y": 8,
      "z": -6,
      "name": "Rock_Basalt_Cobble_Roof_Steep",
      "rotation": 3
    },
    {
      "x": 4,
      "y": 9,
      "z": -6,
      "name": "Rock_Basalt_Cobble_Roof_Steep",
      "filler": 1024,
      "rotation": 3
    },
    {
      "x": 4,
      "y": 0,
      "z": -5,
      "name": "Soil_Dirt"
    },
    {
      "x": 4,
      "y": 1,
      "z": -5,
      "name": "Rock_Stone_Brick"
    },
    {
      "x": 4,
      "y": 2,
      "z": -5,
      "name": "Rock_Stone_Brick"
    },
    {
      "x": 4,
      "y": 3,
      "z": -5,
      "name": "Rock_Stone_Brick"
    },
    {
      "x": 4,
      "y": 4,
      "z": -5,
      "name": "Rock_Stone_Brick"
    },
    {
      "x": 4,
      "y": 5,
      "z": -5,
      "name": "Rock_Stone"
    },
    {
      "x": 4,
      "y": 6,
      "z": -5,
      "name": "Rock_Stone_Brick"
    },
    {
      "x": 4,
      "y": 7,
      "z": -5,
      "name": "Rock_Calcite_Cobble"
    },
    {
      "x": 4,
      "y": 8,
      "z": -5,
      "name": "Rock_Basalt_Cobble_Roof_Steep",
      "rotation": 3
    },
    {
      "x": 4,
      "y": 9,
      "z": -5,
      "name": "Rock_Basalt_Cobble_Roof_Steep",
      "filler": 1024,
      "rotation": 3
    },
    {
      "x": 4,
      "y": 0,
      "z": -4,
      "name": "Soil_Dirt"
    },
    {
      "x": 4,
      "y": 1,
      "z": -4,
      "name": "Rock_Stone_Brick"
    },
    {
      "x": 4,
      "y": 2,
      "z": -4,
      "name": "Rock_Stone_Brick"
    },
    {
      "x": 4,
      "y": 3,
      "z": -4,
      "name": "Rock_Stone_Brick"
    },
    {
      "x": 4,
      "y": 4,
      "z": -4,
      "name": "Rock_Stone_Brick"
    },
    {
      "x": 4,
      "y": 5,
      "z": -4,
      "name": "Rock_Stone_Brick"
    },
    {
      "x": 4,
      "y": 6,
      "z": -4,
      "name": "Rock_Calcite_Cobble"
    },
    {
      "x": 4,
      "y": 7,
      "z": -4,
      "name": "Rock_Stone"
    },
    {
      "x": 4,
      "y": 8,
      "z": -4,
      "name": "Rock_Basalt_Cobble_Roof_Steep",
      "rotation": 3
    },
    {
      "x": 4,
      "y": 9,
      "z": -4,
      "name": "Rock_Basalt_Cobble_Roof_Steep",
      "filler": 1024,
      "rotation": 3
    },
    {
      "x": 4,
      "y": 0,
      "z": -3,
      "name": "Soil_Dirt"
    },
    {
      "x": 4,
      "y": 1,
      "z": -3,
      "name": "Rock_Stone_Brick"
    },
    {
      "x": 4,
      "y": 2,
      "z": -3,
      "name": "Rock_Stone_Brick"
    },
    {
      "x": 4,
      "y": 3,
      "z": -3,
      "name": "Rock_Stone_Brick"
    },
    {
      "x": 4,
      "y": 4,
      "z": -3,
      "name": "Rock_Calcite_Cobble"
    },
    {
      "x": 4,
      "y": 5,
      "z": -3,
      "name": "Rock_Stone_Brick"
    },
    {
      "x": 4,
      "y": 6,
      "z": -3,
      "name": "Rock_Stone_Brick_Wall",
      "rotation": 2
    },
    {
      "x": 4,
      "y": 7,
      "z": -3,
      "name": "Rock_Stone_Brick"
    },
    {
      "x": 4,
      "y": 8,
      "z": -3,
      "name": "Rock_Stone_Brick_Stairs",
      "rotation": 3
    },
    {
      "x": 4,
      "y": 9,
      "z": -3,
      "name": "Rock_Stone_Brick_Stairs",
      "rotation": 9
    },
    {
      "x": 4,
      "y": 10,
      "z": -3,
      "name": "Rock_Calcite_Cobble_Beam"
    },
    {
      "x": 4,
      "y": 0,
      "z": -2,
      "name": "Rock_Stone_Cobble"
    },
    {
      "x": 4,
      "y": 1,
      "z": -2,
      "name": "Rock_Stone_Brick_Stairs",
      "rotation": 3
    },
    {
      "x": 4,
      "y": 0,
      "z": -1,
      "name": "Rock_Stone_Cobble"
    },
    {
      "x": 5,
      "y": 0,
      "z": -21,
      "name": "Soil_Dirt"
    },
    {
      "x": 5,
      "y": 1,
      "z": -21,
      "name": "Soil_Dirt_Burnt"
    },
    {
      "x": 5,
      "y": 2,
      "z": -21,
      "name": "Plant_Bush_Green"
    },
    {
      "x": 5,
      "y": 0,
      "z": -20,
      "name": "Soil_Dirt"
    },
    {
      "x": 5,
      "y": 1,
      "z": -20,
      "name": "Rock_Stone_Cobble_Mossy"
    },
    {
      "x": 5,
      "y": 2,
      "z": -20,
      "name": "Rock_Stone_Brick"
    },
    {
      "x": 5,
      "y": 3,
      "z": -20,
      "name": "Rock_Stone_Brick"
    },
    {
      "x": 5,
      "y": 4,
      "z": -20,
      "name": "Rock_Stone_Brick_Stairs",
      "rotation": 2
    },
    {
      "x": 5,
      "y": 21,
      "z": -20,
      "name": "Rock_Calcite_Cobble_Stairs",
      "rotation": 8
    },
    {
      "x": 5,
      "y": 22,
      "z": -20,
      "name": "Rock_Stone_Brick"
    },
    {
      "x": 5,
      "y": 23,
      "z": -20,
      "name": "Rock_Stone_Brick_Stairs",
      "rotation": 2
    },
    {
      "x": 5,
      "y": 0,
      "z": -19,
      "name": "Soil_Dirt"
    },
    {
      "x": 5,
      "y": 1,
      "z": -19,
      "name": "Rock_Stone"
    },
    {
      "x": 5,
      "y": 2,
      "z": -19,
      "name": "Rock_Stone_Brick"
    },
    {
      "x": 5,
      "y": 3,
      "z": -19,
      "name": "Rock_Stone_Brick"
    },
    {
      "x": 5,
      "y": 4,
      "z": -19,
      "name": "Rock_Calcite_Cobble"
    },
    {
      "x": 5,
      "y": 5,
      "z": -19,
      "name": "Rock_Stone_Brick"
    },
    {
      "x": 5,
      "y": 6,
      "z": -19,
      "name": "Rock_Stone_Brick"
    },
    {
      "x": 5,
      "y": 7,
      "z": -19,
      "name": "Rock_Stone_Brick_Stairs",
      "rotation": 8
    },
    {
      "x": 5,
      "y": 8,
      "z": -19,
      "name": "Rock_Stone_Brick"
    },
    {
      "x": 5,
      "y": 9,
      "z": -19,
      "name": "Rock_Stone_Brick"
    },
    {
      "x": 5,
      "y": 10,
      "z": -19,
      "name": "Rock_Calcite_Cobble"
    },
    {
      "x": 5,
      "y": 11,
      "z": -19,
      "name": "Rock_Stone_Brick"
    },
    {
      "x": 5,
      "y": 12,
      "z": -19,
      "name": "*Rock_Stone_Brick_Wall_State_Definitions_Corner",
      "rotation": 1
    },
    {
      "x": 5,
      "y": 13,
      "z": -19,
      "name": "Rock_Stone_Brick"
    },
    {
      "x": 5,
      "y": 14,
      "z": -19,
      "name": "Rock_Calcite_Cobble"
    },
    {
      "x": 5,
      "y": 15,
      "z": -19,
      "name": "Rock_Stone_Brick_Stairs",
      "rotation": 9
    },
    {
      "x": 5,
      "y": 16,
      "z": -19,
      "name": "Rock_Stone_Brick"
    },
    {
      "x": 5,
      "y": 17,
      "z": -19,
      "name": "Rock_Calcite_Cobble"
    },
    {
      "x": 5,
      "y": 18,
      "z": -19,
      "name": "Rock_Stone_Cobble"
    },
    {
      "x": 5,
      "y": 19,
      "z": -19,
      "name": "Rock_Calcite_Cobble"
    },
    {
      "x": 5,
      "y": 20,
      "z": -19,
      "name": "Rock_Stone_Brick"
    },
    {
      "x": 5,
      "y": 21,
      "z": -19,
      "name": "Rock_Stone"
    },
    {
      "x": 5,
      "y": 22,
      "z": -19,
      "name": "Rock_Calcite_Cobble"
    },
    {
      "x": 5,
      "y": 23,
      "z": -19,
      "name": "Wood_Darkwood_Planks"
    },
    {
      "x": 5,
      "y": 24,
      "z": -19,
      "name": "Rock_Stone_Brick"
    },
    {
      "x": 5,
      "y": 25,
      "z": -19,
      "name": "Rock_Stone_Brick_Beam"
    },
    {
      "x": 5,
      "y": 0,
      "z": -18,
      "name": "Soil_Dirt"
    },
    {
      "x": 5,
      "y": 1,
      "z": -18,
      "name": "Soil_Dirt"
    },
    {
      "x": 5,
      "y": 2,
      "z": -18,
      "name": "Rock_Stone_Brick"
    },
    {
      "x": 5,
      "y": 3,
      "z": -18,
      "name": "Rock_Stone_Brick"
    },
    {
      "x": 5,
      "y": 4,
      "z": -18,
      "name": "Rock_Stone_Brick"
    },
    {
      "x": 5,
      "y": 5,
      "z": -18,
      "name": "Rock_Stone_Brick"
    },
    {
      "x": 5,
      "y": 6,
      "z": -18,
      "name": "Rock_Stone_Brick"
    },
    {
      "x": 5,
      "y": 7,
      "z": -18,
      "name": "Rock_Calcite_Cobble"
    },
    {
      "x": 5,
      "y": 8,
      "z": -18,
      "name": "Rock_Stone"
    },
    {
      "x": 5,
      "y": 9,
      "z": -18,
      "name": "Rock_Stone_Brick"
    },
    {
      "x": 5,
      "y": 10,
      "z": -18,
      "name": "Rock_Calcite_Cobble"
    },
    {
      "x": 5,
      "y": 11,
      "z": -18,
      "name": "Rock_Stone"
    },
    {
      "x": 5,
      "y": 12,
      "z": -18,
      "name": "Rock_Stone"
    },
    {
      "x": 5,
      "y": 13,
      "z": -18,
      "name": "Rock_Stone"
    },
    {
      "x": 5,
      "y": 14,
      "z": -18,
      "name": "Rock_Stone"
    },
    {
      "x": 5,
      "y": 15,
      "z": -18,
      "name": "Rock_Stone"
    },
    {
      "x": 5,
      "y": 16,
      "z": -18,
      "name": "Rock_Stone_Brick_Stairs",
      "rotation": 3
    },
    {
      "x": 5,
      "y": 17,
      "z": -18,
      "name": "Rock_Calcite_Cobble_Half"
    },
    {
      "x": 5,
      "y": 19,
      "z": -18,
      "name": "Rock_Calcite_Cobble_Stairs",
      "rotation": 10
    },
    {
      "x": 5,
      "y": 20,
      "z": -18,
      "name": "Rock_Stone_Brick_Stairs",
      "rotation": 10
    },
    {
      "x": 5,
      "y": 21,
      "z": -18,
      "name": "Rock_Stone"
    },
    {
      "x": 5,
      "y": 22,
      "z": -18,
      "name": "Rock_Stone_Cobble"
    },
    {
      "x": 5,
      "y": 23,
      "z": -18,
      "name": "Wood_Darkwood_Planks"
    },
    {
      "x": 5,
      "y": 24,
      "z": -18,
      "name": "Wood_Darkwood_Planks"
    },
    {
      "x": 5,
      "y": 25,
      "z": -18,
      "name": "Wood_Darkwood_Stairs",
      "rotation": 2
    },
    {
      "x": 5,
      "y": 0,
      "z": -17,
      "name": "Soil_Dirt"
    },
    {
      "x": 5,
      "y": 1,
      "z": -17,
      "name": "Rock_Stone_Cobble"
    },
    {
      "x": 5,
      "y": 2,
      "z": -17,
      "name": "Rock_Stone_Brick"
    },
    {
      "x": 5,
      "y": 3,
      "z": -17,
      "name": "Rock_Stone_Brick"
    },
    {
      "x": 5,
      "y": 4,
      "z": -17,
      "name": "Rock_Stone"
    },
    {
      "x": 5,
      "y": 5,
      "z": -17,
      "name": "Furniture_Tavern_Window",
      "rotation": 1
    },
    {
      "x": 5,
      "y": 6,
      "z": -17,
      "name": "Furniture_Tavern_Window",
      "rotation": 1
    },
    {
      "x": 5,
      "y": 7,
      "z": -17,
      "name": "Furniture_Tavern_Window",
      "rotation": 1
    },
    {
      "x": 5,
      "y": 8,
      "z": -17,
      "name": "Rock_Stone_Brick_Stairs",
      "rotation": 9
    },
    {
      "x": 5,
      "y": 9,
      "z": -17,
      "name": "Rock_Stone"
    },
    {
      "x": 5,
      "y": 10,
      "z": -17,
      "name": "Rock_Stone_Brick"
    },
    {
      "x": 5,
      "y": 11,
      "z": -17,
      "name": "Rock_Stone"
    },
    {
      "x": 5,
      "y": 12,
      "z": -17,
      "name": "Furniture_Tavern_Window",
      "rotation": 1
    },
    {
      "x": 5,
      "y": 13,
      "z": -17,
      "name": "Furniture_Tavern_Window",
      "rotation": 1
    },
    {
      "x": 5,
      "y": 14,
      "z": -17,
      "name": "Rock_Stone_Brick_Stairs",
      "rotation": 9
    },
    {
      "x": 5,
      "y": 15,
      "z": -17,
      "name": "Rock_Stone"
    },
    {
      "x": 5,
      "y": 16,
      "z": -17,
      "name": "Rock_Stone_Brick"
    },
    {
      "x": 5,
      "y": 17,
      "z": -17,
      "name": "Rock_Calcite_Cobble_Beam"
    },
    {
      "x": 5,
      "y": 18,
      "z": -17,
      "name": "Rock_Stone_Brick_Beam"
    },
    {
      "x": 5,
      "y": 19,
      "z": -17,
      "name": "Rock_Stone_Brick_Beam"
    },
    {
      "x": 5,
      "y": 20,
      "z": -17,
      "name": "Rock_Stone"
    },
    {
      "x": 5,
      "y": 21,
      "z": -17,
      "name": "Rock_Calcite_Cobble"
    },
    {
      "x": 5,
      "y": 22,
      "z": -17,
      "name": "Rock_Stone"
    },
    {
      "x": 5,
      "y": 23,
      "z": -17,
      "name": "Wood_Darkwood_Planks"
    },
    {
      "x": 5,
      "y": 24,
      "z": -17,
      "name": "Wood_Darkwood_Planks"
    },
    {
      "x": 5,
      "y": 25,
      "z": -17,
      "name": "Wood_Darkwood_Planks"
    },
    {
      "x": 5,
      "y": 26,
      "z": -17,
      "name": "Wood_Darkwood_Stairs",
      "rotation": 3
    },
    {
      "x": 5,
      "y": 0,
      "z": -16,
      "name": "Soil_Dirt"
    },
    {
      "x": 5,
      "y": 1,
      "z": -16,
      "name": "Rock_Calcite_Cobble"
    },
    {
      "x": 5,
      "y": 2,
      "z": -16,
      "name": "Rock_Stone_Brick"
    },
    {
      "x": 5,
      "y": 3,
      "z": -16,
      "name": "Rock_Stone_Brick"
    },
    {
      "x": 5,
      "y": 4,
      "z": -16,
      "name": "Rock_Stone_Brick"
    },
    {
      "x": 5,
      "y": 5,
      "z": -16,
      "name": "Rock_Stone"
    },
    {
      "x": 5,
      "y": 6,
      "z": -16,
      "name": "Rock_Stone"
    },
    {
      "x": 5,
      "y": 7,
      "z": -16,
      "name": "Rock_Stone_Brick"
    },
    {
      "x": 5,
      "y": 8,
      "z": -16,
      "name": "Rock_Stone"
    },
    {
      "x": 5,
      "y": 9,
      "z": -16,
      "name": "Rock_Stone"
    },
    {
      "x": 5,
      "y": 10,
      "z": -16,
      "name": "Rock_Stone"
    },
    {
      "x": 5,
      "y": 11,
      "z": -16,
      "name": "Rock_Stone"
    },
    {
      "x": 5,
      "y": 12,
      "z": -16,
      "name": "Rock_Stone"
    },
    {
      "x": 5,
      "y": 13,
      "z": -16,
      "name": "Rock_Stone"
    },
    {
      "x": 5,
      "y": 14,
      "z": -16,
      "name": "Rock_Stone_Cobble"
    },
    {
      "x": 5,
      "y": 15,
      "z": -16,
      "name": "Rock_Stone"
    },
    {
      "x": 5,
      "y": 16,
      "z": -16,
      "name": "Rock_Stone_Brick_Stairs",
      "rotation": 3
    },
    {
      "x": 5,
      "y": 17,
      "z": -16,
      "name": "Prototype_Rock_Concrete_Brick_Half"
    },
    {
      "x": 5,
      "y": 19,
      "z": -16,
      "name": "Rock_Stone_Brick_Stairs",
      "rotation": 8
    },
    {
      "x": 5,
      "y": 20,
      "z": -16,
      "name": "Rock_Stone_Brick_Stairs",
      "rotation": 8
    },
    {
      "x": 5,
      "y": 21,
      "z": -16,
      "name": "Rock_Calcite_Cobble"
    },
    {
      "x": 5,
      "y": 22,
      "z": -16,
      "name": "Rock_Stone"
    },
    {
      "x": 5,
      "y": 23,
      "z": -16,
      "name": "Wood_Darkwood_Planks"
    },
    {
      "x": 5,
      "y": 24,
      "z": -16,
      "name": "Wood_Darkwood_Planks"
    },
    {
      "x": 5,
      "y": 25,
      "z": -16,
      "name": "Wood_Darkwood_Stairs"
    },
    {
      "x": 5,
      "y": 0,
      "z": -15,
      "name": "Soil_Dirt"
    },
    {
      "x": 5,
      "y": 1,
      "z": -15,
      "name": "Rock_Stone_Brick"
    },
    {
      "x": 5,
      "y": 2,
      "z": -15,
      "name": "Rock_Stone_Brick"
    },
    {
      "x": 5,
      "y": 3,
      "z": -15,
      "name": "Rock_Stone_Brick"
    },
    {
      "x": 5,
      "y": 4,
      "z": -15,
      "name": "Rock_Stone"
    },
    {
      "x": 5,
      "y": 5,
      "z": -15,
      "name": "Rock_Stone"
    },
    {
      "x": 5,
      "y": 6,
      "z": -15,
      "name": "Rock_Calcite_Cobble"
    },
    {
      "x": 5,
      "y": 7,
      "z": -15,
      "name": "Rock_Calcite_Cobble"
    },
    {
      "x": 5,
      "y": 8,
      "z": -15,
      "name": "Rock_Stone_Brick"
    },
    {
      "x": 5,
      "y": 9,
      "z": -15,
      "name": "Rock_Stone_Brick"
    },
    {
      "x": 5,
      "y": 10,
      "z": -15,
      "name": "Rock_Calcite_Cobble"
    },
    {
      "x": 5,
      "y": 11,
      "z": -15,
      "name": "Rock_Stone_Brick_Stairs",
      "rotation": 9
    },
    {
      "x": 5,
      "y": 12,
      "z": -15,
      "name": "Rock_Stone_Brick"
    },
    {
      "x": 5,
      "y": 13,
      "z": -15,
      "name": "Rock_Stone_Brick"
    },
    {
      "x": 5,
      "y": 14,
      "z": -15,
      "name": "Rock_Stone_Brick_Stairs"
    },
    {
      "x": 5,
      "y": 15,
      "z": -15,
      "name": "Rock_Stone_Brick"
    },
    {
      "x": 5,
      "y": 16,
      "z": -15,
      "name": "Rock_Stone_Brick"
    },
    {
      "x": 5,
      "y": 17,
      "z": -15,
      "name": "Rock_Stone_Brick"
    },
    {
      "x": 5,
      "y": 18,
      "z": -15,
      "name": "Rock_Calcite_Cobble"
    },
    {
      "x": 5,
      "y": 19,
      "z": -15,
      "name": "Rock_Stone_Brick"
    },
    {
      "x": 5,
      "y": 20,
      "z": -15,
      "name": "Rock_Calcite_Cobble"
    },
    {
      "x": 5,
      "y": 21,
      "z": -15,
      "name": "Rock_Stone"
    },
    {
      "x": 5,
      "y": 22,
      "z": -15,
      "name": "Rock_Calcite_Cobble"
    },
    {
      "x": 5,
      "y": 23,
      "z": -15,
      "name": "Wood_Darkwood_Planks"
    },
    {
      "x": 5,
      "y": 24,
      "z": -15,
      "name": "Rock_Calcite_Cobble"
    },
    {
      "x": 5,
      "y": 25,
      "z": -15,
      "name": "Rock_Calcite_Cobble_Beam"
    },
    {
      "x": 5,
      "y": 0,
      "z": -14,
      "name": "Rock_Stone_Brick"
    },
    {
      "x": 5,
      "y": 1,
      "z": -14,
      "name": "Rock_Stone_Brick"
    },
    {
      "x": 5,
      "y": 2,
      "z": -14,
      "name": "Rock_Stone_Brick"
    },
    {
      "x": 5,
      "y": 8,
      "z": -14,
      "name": "Wood_Darkwood_Stairs",
      "rotation": 11
    },
    {
      "x": 5,
      "y": 9,
      "z": -14,
      "name": "Wood_Darkwood_Planks"
    },
    {
      "x": 5,
      "y": 10,
      "z": -14,
      "name": "Rock_Basalt_Cobble_Roof_Steep",
      "rotation": 3
    },
    {
      "x": 5,
      "y": 11,
      "z": -14,
      "name": "Rock_Basalt_Cobble_Roof_Steep",
      "filler": 1024,
      "rotation": 3
    },
    {
      "x": 5,
      "y": 21,
      "z": -14,
      "name": "Rock_Stone_Brick_Stairs",
      "rotation": 10
    },
    {
      "x": 5,
      "y": 22,
      "z": -14,
      "name": "Rock_Stone_Brick"
    },
    {
      "x": 5,
      "y": 23,
      "z": -14,
      "name": "Rock_Calcite_Cobble_Stairs"
    },
    {
      "x": 5,
      "y": 0,
      "z": -13,
      "name": "Rock_Stone_Brick"
    },
    {
      "x": 5,
      "y": 1,
      "z": -13,
      "name": "Rock_Stone_Brick"
    },
    {
      "x": 5,
      "y": 2,
      "z": -13,
      "name": "Rock_Stone"
    },
    {
      "x": 5,
      "y": 7,
      "z": -13,
      "name": "Wood_Hardwood_Stairs",
      "rotation": 11
    },
    {
      "x": 5,
      "y": 8,
      "z": -13,
      "name": "Wood_Beech_Trunk_Full",
      "rotation": 5
    },
    {
      "x": 5,
      "y": 9,
      "z": -13,
      "name": "Wood_Darkwood_Planks"
    },
    {
      "x": 5,
      "y": 10,
      "z": -13,
      "name": "Rock_Basalt_Cobble_Roof_Steep",
      "rotation": 3
    },
    {
      "x": 5,
      "y": 11,
      "z": -13,
      "name": "Rock_Basalt_Cobble_Roof_Steep",
      "filler": 1024,
      "rotation": 3
    },
    {
      "x": 5,
      "y": 0,
      "z": -12,
      "name": "Rock_Stone_Brick"
    },
    {
      "x": 5,
      "y": 1,
      "z": -12,
      "name": "Rock_Stone_Brick"
    },
    {
      "x": 5,
      "y": 2,
      "z": -12,
      "name": "Rock_Stone_Brick_Stairs"
    },
    {
      "x": 5,
      "y": 9,
      "z": -12,
      "name": "Wood_Darkwood_Planks"
    },
    {
      "x": 5,
      "y": 10,
      "z": -12,
      "name": "*Rock_Basalt_Cobble_Roof_Steep_State_Definitions_Inverted_Corner_Left",
      "rotation": 2
    },
    {
      "x": 5,
      "y": 11,
      "z": -12,
      "name": "*Rock_Basalt_Cobble_Roof_Steep_State_Definitions_Inverted_Corner_Left",
      "filler": 1024,
      "rotation": 2
    },
    {
      "x": 5,
      "y": 0,
      "z": -11,
      "name": "Rock_Stone_Brick"
    },
    {
      "x": 5,
      "y": 1,
      "z": -11,
      "name": "Rock_Stone"
    },
    {
      "x": 5,
      "y": 8,
      "z": -11,
      "name": "Wood_Darkwood_Stairs",
      "rotation": 11
    },
    {
      "x": 5,
      "y": 9,
      "z": -11,
      "name": "Wood_Darkwood_Planks"
    },
    {
      "x": 5,
      "y": 10,
      "z": -11,
      "name": "Wood_Darkwood_Stairs",
      "rotation": 11
    },
    {
      "x": 5,
      "y": 11,
      "z": -11,
      "name": "Wood_Darkwood_Planks"
    },
    {
      "x": 5,
      "y": 12,
      "z": -11,
      "name": "Rock_Basalt_Cobble_Roof_Flat",
      "rotation": 2
    },
    {
      "x": 5,
      "y": 0,
      "z": -10,
      "name": "Rock_Stone_Brick"
    },
    {
      "x": 5,
      "y": 1,
      "z": -10,
      "name": "Rock_Stone_Brick"
    },
    {
      "x": 5,
      "y": 9,
      "z": -10,
      "name": "Wood_Darkwood_Planks"
    },
    {
      "x": 5,
      "y": 10,
      "z": -10,
      "name": "*Rock_Basalt_Cobble_Roof_Steep_State_Definitions_Inverted_Corner_Right"
    },
    {
      "x": 5,
      "y": 11,
      "z": -10,
      "name": "*Rock_Basalt_Cobble_Roof_Steep_State_Definitions_Inverted_Corner_Right",
      "filler": 1024
    },
    {
      "x": 5,
      "y": 0,
      "z": -9,
      "name": "Rock_Stone_Brick"
    },
    {
      "x": 5,
      "y": 1,
      "z": -9,
      "name": "Rock_Stone_Brick"
    },
    {
      "x": 5,
      "y": 2,
      "z": -9,
      "name": "Furniture_Village_Bench",
      "rotation": 2
    },
    {
      "x": 5,
      "y": 3,
      "z": -9,
      "name": "Furniture_Village_Bench",
      "filler": 1024,
      "rotation": 2
    },
    {
      "x": 5,
      "y": 7,
      "z": -9,
      "name": "Wood_Hardwood_Stairs",
      "rotation": 11
    },
    {
      "x": 5,
      "y": 8,
      "z": -9,
      "name": "Wood_Beech_Trunk_Full",
      "rotation": 5
    },
    {
      "x": 5,
      "y": 9,
      "z": -9,
      "name": "Wood_Darkwood_Planks"
    },
    {
      "x": 5,
      "y": 10,
      "z": -9,
      "name": "Rock_Basalt_Cobble_Roof_Steep",
      "rotation": 3
    },
    {
      "x": 5,
      "y": 11,
      "z": -9,
      "name": "Rock_Basalt_Cobble_Roof_Steep",
      "filler": 1024,
      "rotation": 3
    },
    {
      "x": 5,
      "y": 0,
      "z": -8,
      "name": "Rock_Stone_Brick"
    },
    {
      "x": 5,
      "y": 1,
      "z": -8,
      "name": "Rock_Stone_Brick"
    },
    {
      "x": 5,
      "y": 8,
      "z": -8,
      "name": "Wood_Darkwood_Stairs",
      "rotation": 11
    },
    {
      "x": 5,
      "y": 9,
      "z": -8,
      "name": "Wood_Darkwood_Planks"
    },
    {
      "x": 5,
      "y": 10,
      "z": -8,
      "name": "Rock_Basalt_Cobble_Roof_Steep",
      "rotation": 3
    },
    {
      "x": 5,
      "y": 11,
      "z": -8,
      "name": "Rock_Basalt_Cobble_Roof_Steep",
      "filler": 1024,
      "rotation": 3
    },
    {
      "x": 5,
      "y": 0,
      "z": -7,
      "name": "Rock_Stone_Brick"
    },
    {
      "x": 5,
      "y": 1,
      "z": -7,
      "name": "Rock_Stone_Brick"
    },
    {
      "x": 5,
      "y": 2,
      "z": -7,
      "name": "Furniture_Village_Bench",
      "rotation": 2
    },
    {
      "x": 5,
      "y": 3,
      "z": -7,
      "name": "Furniture_Village_Bench",
      "filler": 1024,
      "rotation": 2
    },
    {
      "x": 5,
      "y": 8,
      "z": -7,
      "name": "Wood_Darkwood_Stairs",
      "rotation": 11
    },
    {
      "x": 5,
      "y": 9,
      "z": -7,
      "name": "Wood_Darkwood_Planks"
    },
    {
      "x": 5,
      "y": 10,
      "z": -7,
      "name": "Rock_Basalt_Cobble_Roof_Steep",
      "rotation": 3
    },
    {
      "x": 5,
      "y": 11,
      "z": -7,
      "name": "Rock_Basalt_Cobble_Roof_Steep",
      "filler": 1024,
      "rotation": 3
    },
    {
      "x": 5,
      "y": 0,
      "z": -6,
      "name": "Rock_Stone_Brick"
    },
    {
      "x": 5,
      "y": 1,
      "z": -6,
      "name": "Rock_Stone_Brick"
    },
    {
      "x": 5,
      "y": 8,
      "z": -6,
      "name": "Wood_Darkwood_Stairs",
      "rotation": 11
    },
    {
      "x": 5,
      "y": 9,
      "z": -6,
      "name": "Wood_Darkwood_Planks"
    },
    {
      "x": 5,
      "y": 10,
      "z": -6,
      "name": "Rock_Basalt_Cobble_Roof_Steep",
      "rotation": 3
    },
    {
      "x": 5,
      "y": 11,
      "z": -6,
      "name": "Rock_Basalt_Cobble_Roof_Steep",
      "filler": 1024,
      "rotation": 3
    },
    {
      "x": 5,
      "y": 0,
      "z": -5,
      "name": "Rock_Stone_Brick"
    },
    {
      "x": 5,
      "y": 1,
      "z": -5,
      "name": "Rock_Stone_Brick"
    },
    {
      "x": 5,
      "y": 2,
      "z": -5,
      "name": "Rock_Stone_Brick"
    },
    {
      "x": 5,
      "y": 3,
      "z": -5,
      "name": "Rock_Stone"
    },
    {
      "x": 5,
      "y": 4,
      "z": -5,
      "name": "Rock_Stone_Brick"
    },
    {
      "x": 5,
      "y": 5,
      "z": -5,
      "name": "Rock_Calcite_Cobble"
    },
    {
      "x": 5,
      "y": 6,
      "z": -5,
      "name": "Rock_Stone"
    },
    {
      "x": 5,
      "y": 7,
      "z": -5,
      "name": "Rock_Stone"
    },
    {
      "x": 5,
      "y": 8,
      "z": -5,
      "name": "Rock_Stone"
    },
    {
      "x": 5,
      "y": 9,
      "z": -5,
      "name": "Wood_Darkwood_Planks"
    },
    {
      "x": 5,
      "y": 10,
      "z": -5,
      "name": "Rock_Basalt_Cobble_Roof_Steep",
      "rotation": 3
    },
    {
      "x": 5,
      "y": 11,
      "z": -5,
      "name": "Rock_Basalt_Cobble_Roof_Steep",
      "filler": 1024,
      "rotation": 3
    },
    {
      "x": 5,
      "y": 0,
      "z": -4,
      "name": "Rock_Stone_Brick"
    },
    {
      "x": 5,
      "y": 1,
      "z": -4,
      "name": "Rock_Stone_Brick"
    },
    {
      "x": 5,
      "y": 2,
      "z": -4,
      "name": "Rock_Stone_Brick"
    },
    {
      "x": 5,
      "y": 3,
      "z": -4,
      "name": "Rock_Stone_Brick"
    },
    {
      "x": 5,
      "y": 4,
      "z": -4,
      "name": "Rock_Stone"
    },
    {
      "x": 5,
      "y": 5,
      "z": -4,
      "name": "Rock_Stone"
    },
    {
      "x": 5,
      "y": 6,
      "z": -4,
      "name": "Rock_Stone"
    },
    {
      "x": 5,
      "y": 7,
      "z": -4,
      "name": "Rock_Calcite_Cobble"
    },
    {
      "x": 5,
      "y": 8,
      "z": -4,
      "name": "Rock_Stone"
    },
    {
      "x": 5,
      "y": 9,
      "z": -4,
      "name": "Wood_Darkwood_Planks"
    },
    {
      "x": 5,
      "y": 10,
      "z": -4,
      "name": "Rock_Basalt_Cobble_Roof_Steep",
      "rotation": 3
    },
    {
      "x": 5,
      "y": 11,
      "z": -4,
      "name": "Rock_Basalt_Cobble_Roof_Steep",
      "filler": 1024,
      "rotation": 3
    },
    {
      "x": 5,
      "y": 0,
      "z": -3,
      "name": "Soil_Dirt"
    },
    {
      "x": 5,
      "y": 1,
      "z": -3,
      "name": "Rock_Stone_Brick"
    },
    {
      "x": 5,
      "y": 2,
      "z": -3,
      "name": "Rock_Stone_Brick"
    },
    {
      "x": 5,
      "y": 3,
      "z": -3,
      "name": "Rock_Stone_Brick"
    },
    {
      "x": 5,
      "y": 4,
      "z": -3,
      "name": "Rock_Stone"
    },
    {
      "x": 5,
      "y": 5,
      "z": -3,
      "name": "Rock_Stone_Brick"
    },
    {
      "x": 5,
      "y": 6,
      "z": -3,
      "name": "Rock_Calcite_Cobble"
    },
    {
      "x": 5,
      "y": 7,
      "z": -3,
      "name": "Rock_Stone"
    },
    {
      "x": 5,
      "y": 8,
      "z": -3,
      "name": "Rock_Calcite_Cobble_Stairs",
      "rotation": 11
    },
    {
      "x": 5,
      "y": 9,
      "z": -3,
      "name": "Rock_Stone"
    },
    {
      "x": 5,
      "y": 10,
      "z": -3,
      "name": "Rock_Calcite_Cobble_Stairs",
      "rotation": 3
    },
    {
      "x": 5,
      "y": 11,
      "z": -3,
      "name": "Rock_Stone_Brick_Stairs",
      "rotation": 9
    },
    {
      "x": 5,
      "y": 12,
      "z": -3,
      "name": "Rock_Stone_Brick_Beam"
    },
    {
      "x": 5,
      "y": 0,
      "z": -2,
      "name": "Soil_Gravel"
    },
    {
      "x": 5,
      "y": 1,
      "z": -2,
      "name": "Rock_Stone_Brick"
    },
    {
      "x": 5,
      "y": 2,
      "z": -2,
      "name": "Furniture_Village_Statue"
    },
    {
      "x": 5,
      "y": 3,
      "z": -2,
      "name": "Furniture_Village_Statue",
      "filler": 1024
    },
    {
      "x": 5,
      "y": 4,
      "z": -2,
      "name": "Furniture_Village_Statue",
      "filler": 2048
    },
    {
      "x": 5,
      "y": 0,
      "z": -1,
      "name": "Soil_Dirt"
    },
    {
      "x": 6,
      "y": 0,
      "z": -21,
      "name": "Soil_Dirt"
    },
    {
      "x": 6,
      "y": 1,
      "z": -21,
      "name": "Rock_Stone_Cobble_Mossy"
    },
    {
      "x": 6,
      "y": 0,
      "z": -20,
      "name": "Soil_Dirt"
    },
    {
      "x": 6,
      "y": 1,
      "z": -20,
      "name": "Rock_Stone_Cobble"
    },
    {
      "x": 6,
      "y": 2,
      "z": -20,
      "name": "Rock_Stone"
    },
    {
      "x": 6,
      "y": 3,
      "z": -20,
      "name": "Rock_Stone_Brick_Stairs",
      "rotation": 2
    },
    {
      "x": 6,
      "y": 22,
      "z": -20,
      "name": "Rock_Calcite_Cobble_Stairs",
      "rotation": 8
    },
    {
      "x": 6,
      "y": 23,
      "z": -20,
      "name": "Rock_Stone_Brick_Smooth_Half"
    },
    {
      "x": 6,
      "y": 0,
      "z": -19,
      "name": "Soil_Dirt"
    },
    {
      "x": 6,
      "y": 1,
      "z": -19,
      "name": "Soil_Gravel"
    },
    {
      "x": 6,
      "y": 2,
      "z": -19,
      "name": "Rock_Stone_Brick"
    },
    {
      "x": 6,
      "y": 3,
      "z": -19,
      "name": "Rock_Stone_Brick"
    },
    {
      "x": 6,
      "y": 4,
      "z": -19,
      "name": "Rock_Stone_Brick"
    },
    {
      "x": 6,
      "y": 5,
      "z": -19,
      "name": "Rock_Stone"
    },
    {
      "x": 6,
      "y": 6,
      "z": -19,
      "name": "Rock_Stone_Brick"
    },
    {
      "x": 6,
      "y": 7,
      "z": -19,
      "name": "Rock_Stone"
    },
    {
      "x": 6,
      "y": 8,
      "z": -19,
      "name": "Rock_Stone_Brick"
    },
    {
      "x": 6,
      "y": 9,
      "z": -19,
      "name": "Rock_Calcite_Cobble"
    },
    {
      "x": 6,
      "y": 10,
      "z": -19,
      "name": "Rock_Stone"
    },
    {
      "x": 6,
      "y": 11,
      "z": -19,
      "name": "Rock_Stone"
    },
    {
      "x": 6,
      "y": 12,
      "z": -19,
      "name": "Rock_Stone"
    },
    {
      "x": 6,
      "y": 13,
      "z": -19,
      "name": "Rock_Stone"
    },
    {
      "x": 6,
      "y": 14,
      "z": -19,
      "name": "Rock_Stone"
    },
    {
      "x": 6,
      "y": 15,
      "z": -19,
      "name": "Rock_Calcite_Cobble"
    },
    {
      "x": 6,
      "y": 16,
      "z": -19,
      "name": "Rock_Stone_Brick_Stairs",
      "rotation": 2
    },
    {
      "x": 6,
      "y": 17,
      "z": -19,
      "name": "Prototype_Rock_Concrete_Brick_Half"
    },
    {
      "x": 6,
      "y": 19,
      "z": -19,
      "name": "Rock_Stone_Brick_Stairs",
      "rotation": 11
    },
    {
      "x": 6,
      "y": 20,
      "z": -19,
      "name": "Rock_Stone_Brick_Stairs",
      "rotation": 11
    },
    {
      "x": 6,
      "y": 21,
      "z": -19,
      "name": "Rock_Calcite_Cobble"
    },
    {
      "x": 6,
      "y": 22,
      "z": -19,
      "name": "Rock_Calcite_Cobble"
    },
    {
      "x": 6,
      "y": 23,
      "z": -19,
      "name": "Wood_Darkwood_Planks"
    },
    {
      "x": 6,
      "y": 24,
      "z": -19,
      "name": "Wood_Darkwood_Planks"
    },
    {
      "x": 6,
      "y": 25,
      "z": -19,
      "name": "Wood_Darkwood_Stairs",
      "rotation": 3
    },
    {
      "x": 6,
      "y": 0,
      "z": -18,
      "name": "Soil_Dirt"
    },
    {
      "x": 6,
      "y": 1,
      "z": -18,
      "name": "Soil_Gravel"
    },
    {
      "x": 6,
      "y": 2,
      "z": -18,
      "name": "Rock_Calcite_Cobble"
    },
    {
      "x": 6,
      "y": 3,
      "z": -18,
      "name": "Bench_Arcane",
      "components": {
        "Components": {
          "PlacedByInteraction": {
            "WhoPlacedUuid": {
              "$binary": "CGDBch1dRNaCa5bbX/Qg3A==",
              "$type": "04"
            }
          },
          "BenchBlock": {
            "TierLevel": 1,
            "UpgradeItems": []
          }
        }
      },
      "rotation": 1
    },
    {
      "x": 6,
      "y": 4,
      "z": -18,
      "name": "Bench_Arcane",
      "filler": 1024,
      "rotation": 1
    },
    {
      "x": 6,
      "y": 10,
      "z": -18,
      "name": "Wood_Hardwood_Planks_Half",
      "rotation": 8
    },
    {
      "x": 6,
      "y": 15,
      "z": -18,
      "name": "Wood_Hardwood_Planks_Half",
      "rotation": 8
    },
    {
      "x": 6,
      "y": 21,
      "z": -18,
      "name": "Wood_Hardwood_Planks_Half",
      "rotation": 8
    },
    {
      "x": 6,
      "y": 22,
      "z": -18,
      "name": "Wood_Hardwood_Planks"
    },
    {
      "x": 6,
      "y": 23,
      "z": -18,
      "name": "Wood_Darkwood_Planks"
    },
    {
      "x": 6,
      "y": 24,
      "z": -18,
      "name": "Wood_Darkwood_Planks"
    },
    {
      "x": 6,
      "y": 25,
      "z": -18,
      "name": "Wood_Darkwood_Planks"
    },
    {
      "x": 6,
      "y": 26,
      "z": -18,
      "name": "Wood_Darkwood_Planks"
    },
    {
      "x": 6,
      "y": 27,
      "z": -18,
      "name": "Wood_Darkwood_Planks_Half"
    },
    {
      "x": 6,
      "y": 0,
      "z": -17,
      "name": "Soil_Dirt"
    },
    {
      "x": 6,
      "y": 1,
      "z": -17,
      "name": "Rock_Calcite_Cobble"
    },
    {
      "x": 6,
      "y": 2,
      "z": -17,
      "name": "Rock_Stone_Brick"
    },
    {
      "x": 6,
      "y": 3,
      "z": -17,
      "name": "Bench_Arcane",
      "filler": 32,
      "rotation": 1
    },
    {
      "x": 6,
      "y": 4,
      "z": -17,
      "name": "Bench_Arcane",
      "filler": 1056,
      "rotation": 1
    },
    {
      "x": 6,
      "y": 10,
      "z": -17,
      "name": "Wood_Beech_Trunk",
      "rotation": 5
    },
    {
      "x": 6,
      "y": 15,
      "z": -17,
      "name": "Wood_Beech_Trunk",
      "rotation": 5
    },
    {
      "x": 6,
      "y": 21,
      "z": -17,
      "name": "Wood_Beech_Trunk",
      "rotation": 5
    },
    {
      "x": 6,
      "y": 23,
      "z": -17,
      "name": "Wood_Darkwood_Planks"
    },
    {
      "x": 6,
      "y": 24,
      "z": -17,
      "name": "Wood_Darkwood_Planks"
    },
    {
      "x": 6,
      "y": 25,
      "z": -17,
      "name": "Wood_Darkwood_Planks"
    },
    {
      "x": 6,
      "y": 26,
      "z": -17,
      "name": "Wood_Darkwood_Planks"
    },
    {
      "x": 6,
      "y": 27,
      "z": -17,
      "name": "Wood_Darkwood_Planks"
    },
    {
      "x": 6,
      "y": 28,
      "z": -17,
      "name": "Wood_Darkwood_Planks"
    },
    {
      "x": 6,
      "y": 29,
      "z": -17,
      "name": "Wood_Darkwood_Stairs",
      "rotation": 3
    },
    {
      "x": 6,
      "y": 0,
      "z": -16,
      "name": "Soil_Dirt_Burnt"
    },
    {
      "x": 6,
      "y": 1,
      "z": -16,
      "name": "Rock_Calcite_Cobble"
    },
    {
      "x": 6,
      "y": 2,
      "z": -16,
      "name": "Rock_Stone_Brick"
    },
    {
      "x": 6,
      "y": 3,
      "z": -16,
      "name": "Furniture_Crude_Shelf",
      "rotation": 1
    },
    {
      "x": 6,
      "y": 4,
      "z": -16,
      "name": "Aetherhaven_Management_Block",
      "components": {
        "Components": {
          "AetherhavenManagementBlock": {
            "PlotId": "",
            "TownId": ""
          },
          "PlacedByInteraction": {
            "WhoPlacedUuid": {
              "$binary": "CGDBch1dRNaCa5bbX/Qg3A==",
              "$type": "04"
            }
          }
        }
      },
      "rotation": 1
    },
    {
      "x": 6,
      "y": 5,
      "z": -16,
      "name": "Furniture_Village_Bookcase",
      "rotation": 1
    },
    {
      "x": 6,
      "y": 6,
      "z": -16,
      "name": "Furniture_Village_Bookcase",
      "rotation": 1
    },
    {
      "x": 6,
      "y": 10,
      "z": -16,
      "name": "Wood_Hardwood_Planks_Half",
      "rotation": 8
    },
    {
      "x": 6,
      "y": 15,
      "z": -16,
      "name": "Wood_Hardwood_Planks_Half",
      "rotation": 8
    },
    {
      "x": 6,
      "y": 21,
      "z": -16,
      "name": "Wood_Hardwood_Planks_Half",
      "rotation": 8
    },
    {
      "x": 6,
      "y": 22,
      "z": -16,
      "name": "Wood_Hardwood_Planks"
    },
    {
      "x": 6,
      "y": 23,
      "z": -16,
      "name": "Wood_Darkwood_Planks"
    },
    {
      "x": 6,
      "y": 24,
      "z": -16,
      "name": "Wood_Darkwood_Planks"
    },
    {
      "x": 6,
      "y": 25,
      "z": -16,
      "name": "Wood_Darkwood_Planks"
    },
    {
      "x": 6,
      "y": 26,
      "z": -16,
      "name": "Wood_Darkwood_Planks"
    },
    {
      "x": 6,
      "y": 27,
      "z": -16,
      "name": "Wood_Darkwood_Planks_Half"
    },
    {
      "x": 6,
      "y": 0,
      "z": -15,
      "name": "Soil_Dirt"
    },
    {
      "x": 6,
      "y": 1,
      "z": -15,
      "name": "Rock_Stone_Brick"
    },
    {
      "x": 6,
      "y": 2,
      "z": -15,
      "name": "Rock_Stone_Brick"
    },
    {
      "x": 6,
      "y": 3,
      "z": -15,
      "name": "Rock_Stone_Brick"
    },
    {
      "x": 6,
      "y": 4,
      "z": -15,
      "name": "Rock_Calcite_Cobble"
    },
    {
      "x": 6,
      "y": 5,
      "z": -15,
      "name": "Rock_Calcite_Cobble"
    },
    {
      "x": 6,
      "y": 6,
      "z": -15,
      "name": "Rock_Stone_Brick_Stairs",
      "rotation": 9
    },
    {
      "x": 6,
      "y": 7,
      "z": -15,
      "name": "Rock_Stone_Brick_Stairs",
      "rotation": 3
    },
    {
      "x": 6,
      "y": 8,
      "z": -15,
      "name": "Rock_Stone"
    },
    {
      "x": 6,
      "y": 9,
      "z": -15,
      "name": "Rock_Stone"
    },
    {
      "x": 6,
      "y": 10,
      "z": -15,
      "name": "Rock_Stone"
    },
    {
      "x": 6,
      "y": 11,
      "z": -15,
      "name": "Rock_Stone"
    },
    {
      "x": 6,
      "y": 12,
      "z": -15,
      "name": "Rock_Stone_Cobble"
    },
    {
      "x": 6,
      "y": 13,
      "z": -15,
      "name": "Rock_Stone"
    },
    {
      "x": 6,
      "y": 14,
      "z": -15,
      "name": "Rock_Stone"
    },
    {
      "x": 6,
      "y": 15,
      "z": -15,
      "name": "Rock_Stone"
    },
    {
      "x": 6,
      "y": 16,
      "z": -15,
      "name": "Rock_Stone_Brick_Stairs"
    },
    {
      "x": 6,
      "y": 17,
      "z": -15,
      "name": "Prototype_Rock_Concrete_Brick_Half"
    },
    {
      "x": 6,
      "y": 19,
      "z": -15,
      "name": "Rock_Stone_Brick_Stairs",
      "rotation": 11
    },
    {
      "x": 6,
      "y": 20,
      "z": -15,
      "name": "Rock_Stone_Brick_Stairs",
      "rotation": 11
    },
    {
      "x": 6,
      "y": 21,
      "z": -15,
      "name": "Rock_Calcite_Cobble"
    },
    {
      "x": 6,
      "y": 22,
      "z": -15,
      "name": "Rock_Stone"
    },
    {
      "x": 6,
      "y": 23,
      "z": -15,
      "name": "Wood_Darkwood_Planks"
    },
    {
      "x": 6,
      "y": 24,
      "z": -15,
      "name": "Wood_Darkwood_Planks"
    },
    {
      "x": 6,
      "y": 25,
      "z": -15,
      "name": "Wood_Darkwood_Stairs",
      "rotation": 3
    },
    {
      "x": 6,
      "y": 0,
      "z": -14,
      "name": "Rock_Stone_Brick"
    },
    {
      "x": 6,
      "y": 1,
      "z": -14,
      "name": "Rock_Stone_Brick"
    },
    {
      "x": 6,
      "y": 2,
      "z": -14,
      "name": "Rock_Stone_Brick"
    },
    {
      "x": 6,
      "y": 6,
      "z": -14,
      "name": "Furniture_Tavern_Chandelier",
      "filler": 32767
    },
    {
      "x": 6,
      "y": 7,
      "z": -14,
      "name": "Furniture_Tavern_Chandelier",
      "filler": 1023
    },
    {
      "x": 6,
      "y": 9,
      "z": -14,
      "name": "Wood_Darkwood_Planks"
    },
    {
      "x": 6,
      "y": 10,
      "z": -14,
      "name": "Wood_Darkwood_Stairs",
      "rotation": 11
    },
    {
      "x": 6,
      "y": 11,
      "z": -14,
      "name": "Wood_Darkwood_Planks"
    },
    {
      "x": 6,
      "y": 12,
      "z": -14,
      "name": "Rock_Basalt_Cobble_Roof",
      "rotation": 3
    },
    {
      "x": 6,
      "y": 22,
      "z": -14,
      "name": "Rock_Stone_Brick_Stairs",
      "rotation": 10
    },
    {
      "x": 6,
      "y": 23,
      "z": -14,
      "name": "Rock_Calcite_Cobble_Half"
    },
    {
      "x": 6,
      "y": 0,
      "z": -13,
      "name": "Rock_Stone_Brick"
    },
    {
      "x": 6,
      "y": 1,
      "z": -13,
      "name": "Rock_Stone_Brick"
    },
    {
      "x": 6,
      "y": 2,
      "z": -13,
      "name": "Rock_Stone_Brick"
    },
    {
      "x": 6,
      "y": 6,
      "z": -13,
      "name": "Furniture_Tavern_Chandelier",
      "filler": 31775
    },
    {
      "x": 6,
      "y": 7,
      "z": -13,
      "name": "Furniture_Tavern_Chandelier",
      "filler": 31
    },
    {
      "x": 6,
      "y": 8,
      "z": -13,
      "name": "Wood_Beech_Trunk_Full",
      "rotation": 5
    },
    {
      "x": 6,
      "y": 10,
      "z": -13,
      "name": "Wood_Darkwood_Planks_Half",
      "rotation": 8
    },
    {
      "x": 6,
      "y": 11,
      "z": -13,
      "name": "Wood_Darkwood_Planks"
    },
    {
      "x": 6,
      "y": 12,
      "z": -13,
      "name": "Rock_Basalt_Cobble_Roof",
      "rotation": 3
    },
    {
      "x": 6,
      "y": 0,
      "z": -12,
      "name": "Rock_Stone_Brick"
    },
    {
      "x": 6,
      "y": 1,
      "z": -12,
      "name": "Rock_Stone_Brick"
    },
    {
      "x": 6,
      "y": 2,
      "z": -12,
      "name": "Rock_Stone_Brick"
    },
    {
      "x": 6,
      "y": 6,
      "z": -12,
      "name": "Furniture_Tavern_Chandelier",
      "filler": 31807
    },
    {
      "x": 6,
      "y": 7,
      "z": -12,
      "name": "Furniture_Tavern_Chandelier",
      "filler": 63
    },
    {
      "x": 6,
      "y": 9,
      "z": -12,
      "name": "Wood_Darkwood_Planks"
    },
    {
      "x": 6,
      "y": 10,
      "z": -12,
      "name": "Wood_Darkwood_Planks_Half",
      "rotation": 8
    },
    {
      "x": 6,
      "y": 11,
      "z": -12,
      "name": "Wood_Darkwood_Planks"
    },
    {
      "x": 6,
      "y": 12,
      "z": -12,
      "name": "Rock_Basalt_Cobble_Roof",
      "rotation": 3
    },
    {
      "x": 6,
      "y": 0,
      "z": -11,
      "name": "Rock_Stone_Brick"
    },
    {
      "x": 6,
      "y": 1,
      "z": -11,
      "name": "Rock_Stone_Brick"
    },
    {
      "x": 6,
      "y": 9,
      "z": -11,
      "name": "Wood_Darkwood_Planks"
    },
    {
      "x": 6,
      "y": 11,
      "z": -11,
      "name": "Wood_Darkwood_Planks"
    },
    {
      "x": 6,
      "y": 12,
      "z": -11,
      "name": "Rock_Basalt_Cobble_Roof",
      "rotation": 3
    },
    {
      "x": 6,
      "y": 0,
      "z": -10,
      "name": "Rock_Stone_Brick"
    },
    {
      "x": 6,
      "y": 1,
      "z": -10,
      "name": "Rock_Calcite_Cobble"
    },
    {
      "x": 6,
      "y": 6,
      "z": -10,
      "name": "Furniture_Tavern_Chandelier",
      "filler": 32767
    },
    {
      "x": 6,
      "y": 7,
      "z": -10,
      "name": "Furniture_Tavern_Chandelier",
      "filler": 1023
    },
    {
      "x": 6,
      "y": 9,
      "z": -10,
      "name": "Wood_Darkwood_Planks"
    },
    {
      "x": 6,
      "y": 11,
      "z": -10,
      "name": "Wood_Darkwood_Planks"
    },
    {
      "x": 6,
      "y": 12,
      "z": -10,
      "name": "Rock_Basalt_Cobble_Roof",
      "rotation": 3
    },
    {
      "x": 6,
      "y": 0,
      "z": -9,
      "name": "Rock_Stone_Brick"
    },
    {
      "x": 6,
      "y": 1,
      "z": -9,
      "name": "Rock_Stone_Brick"
    },
    {
      "x": 6,
      "y": 2,
      "z": -9,
      "name": "Furniture_Village_Bench",
      "filler": 1,
      "rotation": 2
    },
    {
      "x": 6,
      "y": 3,
      "z": -9,
      "name": "Furniture_Village_Bench",
      "filler": 1025,
      "rotation": 2
    },
    {
      "x": 6,
      "y": 6,
      "z": -9,
      "name": "Furniture_Tavern_Chandelier",
      "filler": 31775
    },
    {
      "x": 6,
      "y": 7,
      "z": -9,
      "name": "Furniture_Tavern_Chandelier",
      "filler": 31
    },
    {
      "x": 6,
      "y": 8,
      "z": -9,
      "name": "Wood_Beech_Trunk_Full",
      "rotation": 5
    },
    {
      "x": 6,
      "y": 10,
      "z": -9,
      "name": "Wood_Darkwood_Planks_Half",
      "rotation": 8
    },
    {
      "x": 6,
      "y": 11,
      "z": -9,
      "name": "Wood_Darkwood_Planks"
    },
    {
      "x": 6,
      "y": 12,
      "z": -9,
      "name": "Rock_Basalt_Cobble_Roof",
      "rotation": 3
    },
    {
      "x": 6,
      "y": 0,
      "z": -8,
      "name": "Rock_Stone_Brick"
    },
    {
      "x": 6,
      "y": 1,
      "z": -8,
      "name": "Rock_Stone_Brick"
    },
    {
      "x": 6,
      "y": 6,
      "z": -8,
      "name": "Furniture_Tavern_Chandelier",
      "filler": 31807
    },
    {
      "x": 6,
      "y": 7,
      "z": -8,
      "name": "Furniture_Tavern_Chandelier",
      "filler": 63
    },
    {
      "x": 6,
      "y": 9,
      "z": -8,
      "name": "Wood_Darkwood_Planks"
    },
    {
      "x": 6,
      "y": 10,
      "z": -8,
      "name": "*Wood_Darkwood_Stairs_State_Definitions_Inverted_Corner_Left",
      "rotation": 11
    },
    {
      "x": 6,
      "y": 11,
      "z": -8,
      "name": "Wood_Darkwood_Planks"
    },
    {
      "x": 6,
      "y": 12,
      "z": -8,
      "name": "Rock_Basalt_Cobble_Roof",
      "rotation": 3
    },
    {
      "x": 6,
      "y": 0,
      "z": -7,
      "name": "Rock_Stone_Brick"
    },
    {
      "x": 6,
      "y": 1,
      "z": -7,
      "name": "Rock_Stone_Brick"
    },
    {
      "x": 6,
      "y": 2,
      "z": -7,
      "name": "Furniture_Village_Bench",
      "filler": 1,
      "rotation": 2
    },
    {
      "x": 6,
      "y": 3,
      "z": -7,
      "name": "Furniture_Village_Bench",
      "filler": 1025,
      "rotation": 2
    },
    {
      "x": 6,
      "y": 9,
      "z": -7,
      "name": "Wood_Darkwood_Planks"
    },
    {
      "x": 6,
      "y": 10,
      "z": -7,
      "name": "Wood_Darkwood_Stairs",
      "rotation": 11
    },
    {
      "x": 6,
      "y": 11,
      "z": -7,
      "name": "Wood_Darkwood_Planks"
    },
    {
      "x": 6,
      "y": 12,
      "z": -7,
      "name": "Rock_Basalt_Cobble_Roof",
      "rotation": 3
    },
    {
      "x": 6,
      "y": 0,
      "z": -6,
      "name": "Rock_Stone_Brick"
    },
    {
      "x": 6,
      "y": 1,
      "z": -6,
      "name": "Rock_Calcite_Cobble"
    },
    {
      "x": 6,
      "y": 9,
      "z": -6,
      "name": "*Wood_Darkwood_Stairs_State_Definitions_Inverted_Corner_Left",
      "rotation": 11
    },
    {
      "x": 6,
      "y": 10,
      "z": -6,
      "name": "Wood_Darkwood_Stairs",
      "rotation": 11
    },
    {
      "x": 6,
      "y": 11,
      "z": -6,
      "name": "Wood_Darkwood_Planks"
    },
    {
      "x": 6,
      "y": 12,
      "z": -6,
      "name": "Rock_Basalt_Cobble_Roof",
      "rotation": 3
    },
    {
      "x": 6,
      "y": 0,
      "z": -5,
      "name": "Rock_Stone_Brick"
    },
    {
      "x": 6,
      "y": 1,
      "z": -5,
      "name": "Rock_Stone_Brick"
    },
    {
      "x": 6,
      "y": 4,
      "z": -5,
      "name": "Rock_Stone_Brick_Smooth_Half",
      "rotation": 8
    },
    {
      "x": 6,
      "y": 5,
      "z": -5,
      "name": "Rock_Stone"
    },
    {
      "x": 6,
      "y": 6,
      "z": -5,
      "name": "Rock_Stone_Brick_Stairs",
      "rotation": 8
    },
    {
      "x": 6,
      "y": 10,
      "z": -5,
      "name": "Rock_Stone_Brick_Stairs",
      "rotation": 11
    },
    {
      "x": 6,
      "y": 11,
      "z": -5,
      "name": "Wood_Darkwood_Planks"
    },
    {
      "x": 6,
      "y": 12,
      "z": -5,
      "name": "Rock_Basalt_Cobble_Roof",
      "rotation": 3
    },
    {
      "x": 6,
      "y": 0,
      "z": -4,
      "name": "Rock_Stone_Brick"
    },
    {
      "x": 6,
      "y": 1,
      "z": -4,
      "name": "Rock_Stone_Brick"
    },
    {
      "x": 6,
      "y": 2,
      "z": -4,
      "name": "Rock_Stone_Brick"
    },
    {
      "x": 6,
      "y": 3,
      "z": -4,
      "name": "Rock_Stone_Brick"
    },
    {
      "x": 6,
      "y": 4,
      "z": -4,
      "name": "Rock_Stone_Brick"
    },
    {
      "x": 6,
      "y": 5,
      "z": -4,
      "name": "Rock_Stone_Brick"
    },
    {
      "x": 6,
      "y": 6,
      "z": -4,
      "name": "Rock_Stone"
    },
    {
      "x": 6,
      "y": 7,
      "z": -4,
      "name": "Furniture_Temple_Wind_Window"
    },
    {
      "x": 6,
      "y": 8,
      "z": -4,
      "name": "Furniture_Temple_Wind_Window"
    },
    {
      "x": 6,
      "y": 9,
      "z": -4,
      "name": "Furniture_Temple_Wind_Window"
    },
    {
      "x": 6,
      "y": 10,
      "z": -4,
      "name": "Furniture_Temple_Wind_Window"
    },
    {
      "x": 6,
      "y": 11,
      "z": -4,
      "name": "Wood_Darkwood_Planks"
    },
    {
      "x": 6,
      "y": 12,
      "z": -4,
      "name": "Rock_Basalt_Cobble_Roof",
      "rotation": 3
    },
    {
      "x": 6,
      "y": 0,
      "z": -3,
      "name": "Soil_Dirt"
    },
    {
      "x": 6,
      "y": 1,
      "z": -3,
      "name": "Rock_Stone"
    },
    {
      "x": 6,
      "y": 5,
      "z": -3,
      "name": "Rock_Calcite_Cobble"
    },
    {
      "x": 6,
      "y": 6,
      "z": -3,
      "name": "Rock_Stone_Brick_Smooth_Half"
    },
    {
      "x": 6,
      "y": 10,
      "z": -3,
      "name": "Rock_Stone_Brick_Stairs",
      "rotation": 11
    },
    {
      "x": 6,
      "y": 11,
      "z": -3,
      "name": "Rock_Stone_Brick"
    },
    {
      "x": 6,
      "y": 12,
      "z": -3,
      "name": "Rock_Stone_Brick_Stairs",
      "rotation": 3
    },
    {
      "x": 6,
      "y": 13,
      "z": -3,
      "name": "Rock_Stone_Brick_Stairs",
      "rotation": 9
    },
    {
      "x": 6,
      "y": 14,
      "z": -3,
      "name": "Rock_Stone_Brick_Beam"
    },
    {
      "x": 6,
      "y": 0,
      "z": -2,
      "name": "Soil_Dirt"
    },
    {
      "x": 6,
      "y": 1,
      "z": -2,
      "name": "Rock_Stone_Brick_Stairs"
    },
    {
      "x": 6,
      "y": 0,
      "z": -1,
      "name": "Soil_Dirt_Burnt"
    },
    {
      "x": 7,
      "y": 0,
      "z": -21,
      "name": "Soil_Dirt"
    },
    {
      "x": 7,
      "y": 1,
      "z": -21,
      "name": "Soil_Dirt_Burnt"
    },
    {
      "x": 7,
      "y": 2,
      "z": -21,
      "name": "Rock_Calcite_Cobble_Half"
    },
    {
      "x": 7,
      "y": 0,
      "z": -20,
      "name": "Soil_Dirt"
    },
    {
      "x": 7,
      "y": 1,
      "z": -20,
      "name": "Soil_Dirt"
    },
    {
      "x": 7,
      "y": 2,
      "z": -20,
      "name": "Rock_Stone_Brick"
    },
    {
      "x": 7,
      "y": 3,
      "z": -20,
      "name": "Rock_Stone"
    },
    {
      "x": 7,
      "y": 4,
      "z": -20,
      "name": "Rock_Calcite_Cobble_Half"
    },
    {
      "x": 7,
      "y": 21,
      "z": -20,
      "name": "Rock_Stone_Brick_Stairs",
      "rotation": 8
    },
    {
      "x": 7,
      "y": 22,
      "z": -20,
      "name": "Rock_Stone_Brick"
    },
    {
      "x": 7,
      "y": 23,
      "z": -20,
      "name": "Rock_Stone_Brick_Beam"
    },
    {
      "x": 7,
      "y": 0,
      "z": -19,
      "name": "Soil_Dirt"
    },
    {
      "x": 7,
      "y": 1,
      "z": -19,
      "name": "Rock_Calcite_Cobble"
    },
    {
      "x": 7,
      "y": 2,
      "z": -19,
      "name": "Rock_Stone_Brick"
    },
    {
      "x": 7,
      "y": 3,
      "z": -19,
      "name": "Rock_Stone_Brick"
    },
    {
      "x": 7,
      "y": 4,
      "z": -19,
      "name": "Rock_Calcite_Cobble"
    },
    {
      "x": 7,
      "y": 5,
      "z": -19,
      "name": "Furniture_Tavern_Window"
    },
    {
      "x": 7,
      "y": 6,
      "z": -19,
      "name": "Furniture_Tavern_Window"
    },
    {
      "x": 7,
      "y": 7,
      "z": -19,
      "name": "Furniture_Tavern_Window"
    },
    {
      "x": 7,
      "y": 8,
      "z": -19,
      "name": "Rock_Stone_Brick_Stairs",
      "rotation": 8
    },
    {
      "x": 7,
      "y": 9,
      "z": -19,
      "name": "Rock_Calcite_Cobble"
    },
    {
      "x": 7,
      "y": 10,
      "z": -19,
      "name": "Rock_Stone"
    },
    {
      "x": 7,
      "y": 11,
      "z": -19,
      "name": "Rock_Stone"
    },
    {
      "x": 7,
      "y": 12,
      "z": -19,
      "name": "Furniture_Tavern_Window"
    },
    {
      "x": 7,
      "y": 13,
      "z": -19,
      "name": "Furniture_Tavern_Window"
    },
    {
      "x": 7,
      "y": 14,
      "z": -19,
      "name": "Rock_Stone_Brick_Stairs",
      "rotation": 8
    },
    {
      "x": 7,
      "y": 15,
      "z": -19,
      "name": "Rock_Calcite_Cobble"
    },
    {
      "x": 7,
      "y": 16,
      "z": -19,
      "name": "Rock_Stone"
    },
    {
      "x": 7,
      "y": 17,
      "z": -19,
      "name": "Rock_Stone_Brick_Beam"
    },
    {
      "x": 7,
      "y": 18,
      "z": -19,
      "name": "Rock_Calcite_Cobble_Beam"
    },
    {
      "x": 7,
      "y": 19,
      "z": -19,
      "name": "Rock_Calcite_Cobble_Beam"
    },
    {
      "x": 7,
      "y": 20,
      "z": -19,
      "name": "Rock_Calcite_Cobble"
    },
    {
      "x": 7,
      "y": 21,
      "z": -19,
      "name": "Rock_Calcite_Cobble"
    },
    {
      "x": 7,
      "y": 22,
      "z": -19,
      "name": "Rock_Calcite_Cobble"
    },
    {
      "x": 7,
      "y": 23,
      "z": -19,
      "name": "Wood_Darkwood_Planks"
    },
    {
      "x": 7,
      "y": 24,
      "z": -19,
      "name": "Wood_Darkwood_Planks"
    },
    {
      "x": 7,
      "y": 25,
      "z": -19,
      "name": "Wood_Darkwood_Planks"
    },
    {
      "x": 7,
      "y": 26,
      "z": -19,
      "name": "Wood_Darkwood_Stairs",
      "rotation": 2
    },
    {
      "x": 7,
      "y": 0,
      "z": -18,
      "name": "Soil_Dirt"
    },
    {
      "x": 7,
      "y": 1,
      "z": -18,
      "name": "Soil_Gravel"
    },
    {
      "x": 7,
      "y": 2,
      "z": -18,
      "name": "Rock_Stone_Brick"
    },
    {
      "x": 7,
      "y": 10,
      "z": -18,
      "name": "Wood_Beech_Trunk",
      "rotation": 4
    },
    {
      "x": 7,
      "y": 15,
      "z": -18,
      "name": "Wood_Beech_Trunk",
      "rotation": 4
    },
    {
      "x": 7,
      "y": 21,
      "z": -18,
      "name": "Wood_Beech_Trunk",
      "rotation": 4
    },
    {
      "x": 7,
      "y": 23,
      "z": -18,
      "name": "Wood_Darkwood_Planks"
    },
    {
      "x": 7,
      "y": 24,
      "z": -18,
      "name": "Wood_Darkwood_Planks"
    },
    {
      "x": 7,
      "y": 25,
      "z": -18,
      "name": "Wood_Darkwood_Planks"
    },
    {
      "x": 7,
      "y": 26,
      "z": -18,
      "name": "Wood_Darkwood_Planks"
    },
    {
      "x": 7,
      "y": 27,
      "z": -18,
      "name": "Wood_Darkwood_Planks"
    },
    {
      "x": 7,
      "y": 28,
      "z": -18,
      "name": "Wood_Darkwood_Planks"
    },
    {
      "x": 7,
      "y": 29,
      "z": -18,
      "name": "Wood_Darkwood_Stairs",
      "rotation": 2
    },
    {
      "x": 7,
      "y": 0,
      "z": -17,
      "name": "Soil_Dirt"
    },
    {
      "x": 7,
      "y": 1,
      "z": -17,
      "name": "Rock_Calcite_Cobble"
    },
    {
      "x": 7,
      "y": 2,
      "z": -17,
      "name": "Rock_Calcite_Cobble"
    },
    {
      "x": 7,
      "y": 7,
      "z": -17,
      "name": "Deco_Lantern_Ceiling"
    },
    {
      "x": 7,
      "y": 8,
      "z": -17,
      "name": "Deco_Iron_Chain_Small",
      "rotation": 2
    },
    {
      "x": 7,
      "y": 9,
      "z": -17,
      "name": "Deco_Iron_Chain_Small",
      "rotation": 2
    },
    {
      "x": 7,
      "y": 10,
      "z": -17,
      "name": "Wood_Beech_Trunk",
      "rotation": 4
    },
    {
      "x": 7,
      "y": 14,
      "z": -17,
      "name": "Deco_Lantern_Ceiling"
    },
    {
      "x": 7,
      "y": 15,
      "z": -17,
      "name": "Wood_Beech_Trunk",
      "rotation": 4
    },
    {
      "x": 7,
      "y": 19,
      "z": -17,
      "name": "Deco_Iron_Chain_Small",
      "rotation": 2
    },
    {
      "x": 7,
      "y": 20,
      "z": -17,
      "name": "Rock_Stone_Brick_Beam"
    },
    {
      "x": 7,
      "y": 21,
      "z": -17,
      "name": "Wood_Beech_Trunk",
      "rotation": 5
    },
    {
      "x": 7,
      "y": 26,
      "z": -17,
      "name": "Wood_Darkwood_Planks"
    },
    {
      "x": 7,
      "y": 27,
      "z": -17,
      "name": "Wood_Darkwood_Planks"
    },
    {
      "x": 7,
      "y": 28,
      "z": -17,
      "name": "Wood_Darkwood_Planks"
    },
    {
      "x": 7,
      "y": 29,
      "z": -17,
      "name": "Wood_Darkwood_Planks"
    },
    {
      "x": 7,
      "y": 30,
      "z": -17,
      "name": "Wood_Darkwood_Planks"
    },
    {
      "x": 7,
      "y": 31,
      "z": -17,
      "name": "Wood_Darkwood_Planks"
    },
    {
      "x": 7,
      "y": 32,
      "z": -17,
      "name": "Rock_Stone_Brick"
    },
    {
      "x": 7,
      "y": 33,
      "z": -17,
      "name": "Rock_Stone_Brick_Beam"
    },
    {
      "x": 7,
      "y": 34,
      "z": -17,
      "name": "Rock_Stone_Brick_Beam"
    },
    {
      "x": 7,
      "y": 35,
      "z": -17,
      "name": "Wood_Blackwood_Beam"
    },
    {
      "x": 7,
      "y": 36,
      "z": -17,
      "name": "Wood_Blackwood_Beam"
    },
    {
      "x": 7,
      "y": 37,
      "z": -17,
      "name": "Wood_Blackwood_Beam"
    },
    {
      "x": 7,
      "y": 38,
      "z": -17,
      "name": "Wood_Blackwood_Fence"
    },
    {
      "x": 7,
      "y": 39,
      "z": -17,
      "name": "Wood_Blackwood_Fence"
    },
    {
      "x": 7,
      "y": 0,
      "z": -16,
      "name": "Soil_Dirt"
    },
    {
      "x": 7,
      "y": 1,
      "z": -16,
      "name": "Soil_Gravel"
    },
    {
      "x": 7,
      "y": 2,
      "z": -16,
      "name": "Rock_Calcite_Cobble"
    },
    {
      "x": 7,
      "y": 3,
      "z": -16,
      "name": "*Furniture_Village_Door_State_Definitions_OpenDoorOut",
      "filler": 992
    },
    {
      "x": 7,
      "y": 4,
      "z": -16,
      "name": "*Furniture_Village_Door_State_Definitions_OpenDoorOut",
      "filler": 2016
    },
    {
      "x": 7,
      "y": 10,
      "z": -16,
      "name": "Wood_Beech_Trunk",
      "rotation": 4
    },
    {
      "x": 7,
      "y": 15,
      "z": -16,
      "name": "Wood_Beech_Trunk",
      "rotation": 4
    },
    {
      "x": 7,
      "y": 21,
      "z": -16,
      "name": "Wood_Beech_Trunk",
      "rotation": 4
    },
    {
      "x": 7,
      "y": 23,
      "z": -16,
      "name": "Wood_Darkwood_Planks"
    },
    {
      "x": 7,
      "y": 24,
      "z": -16,
      "name": "Wood_Darkwood_Planks"
    },
    {
      "x": 7,
      "y": 25,
      "z": -16,
      "name": "Wood_Darkwood_Planks"
    },
    {
      "x": 7,
      "y": 26,
      "z": -16,
      "name": "Wood_Darkwood_Planks"
    },
    {
      "x": 7,
      "y": 27,
      "z": -16,
      "name": "Wood_Darkwood_Planks"
    },
    {
      "x": 7,
      "y": 28,
      "z": -16,
      "name": "Wood_Darkwood_Planks"
    },
    {
      "x": 7,
      "y": 29,
      "z": -16,
      "name": "Wood_Darkwood_Stairs"
    },
    {
      "x": 7,
      "y": 0,
      "z": -15,
      "name": "Soil_Dirt"
    },
    {
      "x": 7,
      "y": 1,
      "z": -15,
      "name": "Rock_Stone_Brick"
    },
    {
      "x": 7,
      "y": 2,
      "z": -15,
      "name": "Rock_Stone_Brick"
    },
    {
      "x": 7,
      "y": 3,
      "z": -15,
      "name": "*Furniture_Village_Door_State_Definitions_OpenDoorOut"
    },
    {
      "x": 7,
      "y": 4,
      "z": -15,
      "name": "*Furniture_Village_Door_State_Definitions_OpenDoorOut",
      "filler": 1024
    },
    {
      "x": 7,
      "y": 5,
      "z": -15,
      "name": "Rock_Stone_Brick_Stairs",
      "rotation": 10
    },
    {
      "x": 7,
      "y": 6,
      "z": -15,
      "name": "Rock_Stone_Brick_Stairs"
    },
    {
      "x": 7,
      "y": 7,
      "z": -15,
      "name": "Rock_Stone_Brick_Stairs",
      "rotation": 10
    },
    {
      "x": 7,
      "y": 8,
      "z": -15,
      "name": "Rock_Stone"
    },
    {
      "x": 7,
      "y": 9,
      "z": -15,
      "name": "Rock_Stone"
    },
    {
      "x": 7,
      "y": 10,
      "z": -15,
      "name": "Rock_Stone"
    },
    {
      "x": 7,
      "y": 11,
      "z": -15,
      "name": "Rock_Stone"
    },
    {
      "x": 7,
      "y": 12,
      "z": -15,
      "name": "Rock_Stone"
    },
    {
      "x": 7,
      "y": 13,
      "z": -15,
      "name": "Rock_Calcite_Cobble"
    },
    {
      "x": 7,
      "y": 14,
      "z": -15,
      "name": "Rock_Calcite_Cobble"
    },
    {
      "x": 7,
      "y": 15,
      "z": -15,
      "name": "Rock_Stone"
    },
    {
      "x": 7,
      "y": 16,
      "z": -15,
      "name": "Rock_Stone_Brick"
    },
    {
      "x": 7,
      "y": 17,
      "z": -15,
      "name": "Rock_Stone_Brick_Beam"
    },
    {
      "x": 7,
      "y": 18,
      "z": -15,
      "name": "Rock_Stone_Brick_Beam"
    },
    {
      "x": 7,
      "y": 19,
      "z": -15,
      "name": "Rock_Stone_Brick_Beam"
    },
    {
      "x": 7,
      "y": 20,
      "z": -15,
      "name": "Rock_Calcite_Cobble"
    },
    {
      "x": 7,
      "y": 21,
      "z": -15,
      "name": "Rock_Stone"
    },
    {
      "x": 7,
      "y": 22,
      "z": -15,
      "name": "Rock_Calcite_Cobble"
    },
    {
      "x": 7,
      "y": 23,
      "z": -15,
      "name": "Wood_Darkwood_Planks"
    },
    {
      "x": 7,
      "y": 24,
      "z": -15,
      "name": "Wood_Darkwood_Planks"
    },
    {
      "x": 7,
      "y": 25,
      "z": -15,
      "name": "Wood_Darkwood_Planks"
    },
    {
      "x": 7,
      "y": 26,
      "z": -15,
      "name": "Wood_Darkwood_Stairs"
    },
    {
      "x": 7,
      "y": 0,
      "z": -14,
      "name": "Rock_Stone_Brick"
    },
    {
      "x": 7,
      "y": 1,
      "z": -14,
      "name": "Rock_Stone_Brick"
    },
    {
      "x": 7,
      "y": 2,
      "z": -14,
      "name": "Rock_Stone"
    },
    {
      "x": 7,
      "y": 6,
      "z": -14,
      "name": "Furniture_Tavern_Chandelier",
      "filler": 32736
    },
    {
      "x": 7,
      "y": 7,
      "z": -14,
      "name": "Furniture_Tavern_Chandelier",
      "filler": 992
    },
    {
      "x": 7,
      "y": 8,
      "z": -14,
      "name": "Wood_Hardwood_Stairs",
      "rotation": 8
    },
    {
      "x": 7,
      "y": 9,
      "z": -14,
      "name": "Wood_Beech_Trunk_Full",
      "rotation": 4
    },
    {
      "x": 7,
      "y": 11,
      "z": -14,
      "name": "Wood_Darkwood_Planks"
    },
    {
      "x": 7,
      "y": 12,
      "z": -14,
      "name": "Wood_Darkwood_Planks"
    },
    {
      "x": 7,
      "y": 13,
      "z": -14,
      "name": "Rock_Basalt_Cobble_Roof"
    },
    {
      "x": 7,
      "y": 21,
      "z": -14,
      "name": "Rock_Stone_Brick_Stairs",
      "rotation": 10
    },
    {
      "x": 7,
      "y": 22,
      "z": -14,
      "name": "Rock_Stone_Brick"
    },
    {
      "x": 7,
      "y": 23,
      "z": -14,
      "name": "Rock_Stone_Brick_Beam"
    },
    {
      "x": 7,
      "y": 0,
      "z": -13,
      "name": "Rock_Stone_Brick"
    },
    {
      "x": 7,
      "y": 1,
      "z": -13,
      "name": "Rock_Stone_Brick"
    },
    {
      "x": 7,
      "y": 2,
      "z": -13,
      "name": "Rock_Stone_Brick"
    },
    {
      "x": 7,
      "y": 6,
      "z": -13,
      "name": "Furniture_Tavern_Chandelier",
      "filler": 31744
    },
    {
      "x": 7,
      "y": 7,
      "z": -13,
      "name": "Furniture_Tavern_Chandelier"
    },
    {
      "x": 7,
      "y": 8,
      "z": -13,
      "name": "Wood_Beech_Trunk_Full",
      "rotation": 5
    },
    {
