{
  "version": 8,
  "blockIdVersion": 11,
  "anchorX": 0,
  "anchorY": 0,
  "anchorZ": 0,
  "blocks": [
    {
      "x": 1,
      "y": 25,
      "z": -14,
      "name": "*Furniture_Crude_Trapdoor_State_Definitions_OpenDoorOut",
      "rotation": 3
    },
    {
      "x": 1,
      "y": 24,
      "z": -13,
      "name": "*Furniture_Crude_Trapdoor_State_Definitions_OpenDoorOut",
      "rotation": 3
    },
    {
      "x": 1,
      "y": 25,
      "z": -13,
      "name": "Rock_Calcite_Brick_Smooth_Half",
      "rotation": 7
    },
    {
      "x": 1,
      "y": 26,
      "z": -13,
      "name": "*Furniture_Crude_Trapdoor_State_Definitions_OpenDoorOut",
      "rotation": 3
    },
    {
      "x": 1,
      "y": 25,
      "z": -12,
      "name": "*Furniture_Crude_Trapdoor_State_Definitions_OpenDoorOut",
      "rotation": 3
    },
    {
      "x": 2,
      "y": 24,
      "z": -16,
      "name": "Wood_Hardwood_Planks_Half",
      "rotation": 8
    },
    {
      "x": 2,
      "y": 25,
      "z": -16,
      "name": "Wood_Hardwood_Planks"
    },
    {
      "x": 2,
      "y": 26,
      "z": -16,
      "name": "Wood_Hardwood_Planks_Half"
    },
    {
      "x": 2,
      "y": 25,
      "z": -15,
      "name": "Wood_Hardwood_Planks"
    },
    {
      "x": 2,
      "y": 24,
      "z": -14,
      "name": "Wood_Hardwood_Stairs",
      "rotation": 8
    },
    {
      "x": 2,
      "y": 25,
      "z": -14,
      "name": "Wood_Hardwood_Planks"
    },
    {
      "x": 2,
      "y": 26,
      "z": -14,
      "name": "Wood_Hardwood_Stairs",
      "rotation": 2
    },
    {
      "x": 2,
      "y": 21,
      "z": -13,
      "name": "Wood_Hardwood_Beam"
    },
    {
      "x": 2,
      "y": 22,
      "z": -13,
      "name": "Wood_Hardwood_Planks"
    },
    {
      "x": 2,
      "y": 23,
      "z": -13,
      "name": "Wood_Hardwood_Planks"
    },
    {
      "x": 2,
      "y": 24,
      "z": -13,
      "name": "Wood_Hardwood_Planks"
    },
    {
      "x": 2,
      "y": 26,
      "z": -13,
      "name": "Wood_Hardwood_Planks"
    },
    {
      "x": 2,
      "y": 27,
      "z": -13,
      "name": "Wood_Hardwood_Planks"
    },
    {
      "x": 2,
      "y": 28,
      "z": -13,
      "name": "Wood_Hardwood_Planks"
    },
    {
      "x": 2,
      "y": 29,
      "z": -13,
      "name": "Wood_Hardwood_Beam"
    },
    {
      "x": 2,
      "y": 24,
      "z": -12,
      "name": "Wood_Hardwood_Stairs",
      "rotation": 10
    },
    {
      "x": 2,
      "y": 25,
      "z": -12,
      "name": "Wood_Hardwood_Planks"
    },
    {
      "x": 2,
      "y": 26,
      "z": -12,
      "name": "Wood_Hardwood_Stairs"
    },
    {
      "x": 2,
      "y": 25,
      "z": -11,
      "name": "Wood_Hardwood_Planks"
    },
    {
      "x": 2,
      "y": 24,
      "z": -10,
      "name": "Wood_Hardwood_Planks_Half",
      "rotation": 8
    },
    {
      "x": 2,
      "y": 25,
      "z": -10,
      "name": "Wood_Hardwood_Planks"
    },
    {
      "x": 2,
      "y": 26,
      "z": -10,
      "name": "Wood_Hardwood_Planks_Half"
    },
    {
      "x": 3,
      "y": 24,
      "z": -18,
      "name": "Wood_Hardwood_Beam"
    },
    {
      "x": 3,
      "y": 25,
      "z": -18,
      "name": "Wood_Hardwood_Planks"
    },
    {
      "x": 3,
      "y": 26,
      "z": -18,
      "name": "Wood_Hardwood_Beam"
    },
    {
      "x": 3,
      "y": 24,
      "z": -17,
      "name": "Wood_Hardwood_Planks_Half",
      "rotation": 8
    },
    {
      "x": 3,
      "y": 25,
      "z": -17,
      "name": "Wood_Hardwood_Planks"
    },
    {
      "x": 3,
      "y": 26,
      "z": -17,
      "name": "Wood_Hardwood_Planks_Half"
    },
    {
      "x": 3,
      "y": 24,
      "z": -16,
      "name": "Cloth_Block_Wool_Red"
    },
    {
      "x": 3,
      "y": 25,
      "z": -16,
      "name": "Cloth_Block_Wool_Red"
    },
    {
      "x": 3,
      "y": 26,
      "z": -16,
      "name": "Cloth_Block_Wool_Red"
    },
    {
      "x": 3,
      "y": 23,
      "z": -15,
      "name": "Cloth_Block_Wool_Red"
    },
    {
      "x": 3,
      "y": 24,
      "z": -15,
      "name": "Cloth_Block_Wool_Red"
    },
    {
      "x": 3,
      "y": 25,
      "z": -15,
      "name": "Cloth_Block_Wool_Red"
    },
    {
      "x": 3,
      "y": 26,
      "z": -15,
      "name": "Cloth_Block_Wool_Red"
    },
    {
      "x": 3,
      "y": 27,
      "z": -15,
      "name": "Cloth_Block_Wool_Red"
    },
    {
      "x": 3,
      "y": 22,
      "z": -14,
      "name": "Cloth_Block_Wool_White"
    },
    {
      "x": 3,
      "y": 23,
      "z": -14,
      "name": "Cloth_Block_Wool_White"
    },
    {
      "x": 3,
      "y": 24,
      "z": -14,
      "name": "Cloth_Block_Wool_White"
    },
    {
      "x": 3,
      "y": 25,
      "z": -14,
      "name": "Cloth_Block_Wool_White"
    },
    {
      "x": 3,
      "y": 26,
      "z": -14,
      "name": "Cloth_Block_Wool_White"
    },
    {
      "x": 3,
      "y": 27,
      "z": -14,
      "name": "Cloth_Block_Wool_White"
    },
    {
      "x": 3,
      "y": 28,
      "z": -14,
      "name": "Cloth_Block_Wool_White"
    },
    {
      "x": 3,
      "y": 19,
      "z": -13,
      "name": "Wood_Hardwood_Beam"
    },
    {
      "x": 3,
      "y": 20,
      "z": -13,
      "name": "Wood_Hardwood_Planks"
    },
    {
      "x": 3,
      "y": 21,
      "z": -13,
      "name": "Wood_Hardwood_Planks"
    },
    {
      "x": 3,
      "y": 22,
      "z": -13,
      "name": "Cloth_Block_Wool_White"
    },
    {
      "x": 3,
      "y": 23,
      "z": -13,
      "name": "Cloth_Block_Wool_White"
    },
    {
      "x": 3,
      "y": 24,
      "z": -13,
      "name": "Cloth_Block_Wool_White"
    },
    {
      "x": 3,
      "y": 26,
      "z": -13,
      "name": "Cloth_Block_Wool_White"
    },
    {
      "x": 3,
      "y": 27,
      "z": -13,
      "name": "Cloth_Block_Wool_White"
    },
    {
      "x": 3,
      "y": 28,
      "z": -13,
      "name": "Cloth_Block_Wool_White"
    },
    {
      "x": 3,
      "y": 29,
      "z": -13,
      "name": "Wood_Hardwood_Planks"
    },
    {
      "x": 3,
      "y": 30,
      "z": -13,
      "name": "Wood_Hardwood_Planks"
    },
    {
      "x": 3,
      "y": 31,
      "z": -13,
      "name": "Wood_Hardwood_Beam"
    },
    {
      "x": 3,
      "y": 22,
      "z": -12,
      "name": "Cloth_Block_Wool_White"
    },
    {
      "x": 3,
      "y": 23,
      "z": -12,
      "name": "Cloth_Block_Wool_White"
    },
    {
      "x": 3,
      "y": 24,
      "z": -12,
      "name": "Cloth_Block_Wool_White"
    },
    {
      "x": 3,
      "y": 25,
      "z": -12,
      "name": "Cloth_Block_Wool_White"
    },
    {
      "x": 3,
      "y": 26,
      "z": -12,
      "name": "Cloth_Block_Wool_White"
    },
    {
      "x": 3,
      "y": 27,
      "z": -12,
      "name": "Cloth_Block_Wool_White"
    },
    {
      "x": 3,
      "y": 28,
      "z": -12,
      "name": "Cloth_Block_Wool_White"
    },
    {
      "x": 3,
      "y": 23,
      "z": -11,
      "name": "Cloth_Block_Wool_Red"
    },
    {
      "x": 3,
      "y": 24,
      "z": -11,
      "name": "Cloth_Block_Wool_Red"
    },
    {
      "x": 3,
      "y": 25,
      "z": -11,
      "name": "Cloth_Block_Wool_Red"
    },
    {
      "x": 3,
      "y": 26,
      "z": -11,
      "name": "Cloth_Block_Wool_Red"
    },
    {
      "x": 3,
      "y": 27,
      "z": -11,
      "name": "Cloth_Block_Wool_Red"
    },
    {
      "x": 3,
      "y": 24,
      "z": -10,
      "name": "Cloth_Block_Wool_Red"
    },
    {
      "x": 3,
      "y": 25,
      "z": -10,
      "name": "Cloth_Block_Wool_Red"
    },
    {
      "x": 3,
      "y": 26,
      "z": -10,
      "name": "Cloth_Block_Wool_Red"
    },
    {
      "x": 3,
      "y": 24,
      "z": -9,
      "name": "Wood_Hardwood_Planks_Half",
      "rotation": 8
    },
    {
      "x": 3,
      "y": 25,
      "z": -9,
      "name": "Wood_Hardwood_Planks"
    },
    {
      "x": 3,
      "y": 26,
      "z": -9,
      "name": "Wood_Hardwood_Planks_Half"
    },
    {
      "x": 3,
      "y": 24,
      "z": -8,
      "name": "Wood_Hardwood_Beam"
    },
    {
      "x": 3,
      "y": 25,
      "z": -8,
      "name": "Wood_Hardwood_Planks"
    },
    {
      "x": 3,
      "y": 26,
      "z": -8,
      "name": "Wood_Hardwood_Beam"
    },
    {
      "x": 4,
      "y": 24,
      "z": -19,
      "name": "Wood_Hardwood_Beam"
    },
    {
      "x": 4,
      "y": 25,
      "z": -19,
      "name": "Wood_Hardwood_Planks"
    },
    {
      "x": 4,
      "y": 26,
      "z": -19,
      "name": "Wood_Hardwood_Beam"
    },
    {
      "x": 4,
      "y": 23,
      "z": -18,
      "name": "Cloth_Block_Wool_Red"
    },
    {
      "x": 4,
      "y": 24,
      "z": -18,
      "name": "Cloth_Block_Wool_Red"
    },
    {
      "x": 4,
      "y": 25,
      "z": -18,
      "name": "Cloth_Block_Wool_Red"
    },
    {
      "x": 4,
      "y": 26,
      "z": -18,
      "name": "Cloth_Block_Wool_Red"
    },
    {
      "x": 4,
      "y": 27,
      "z": -18,
      "name": "Cloth_Block_Wool_Red"
    },
    {
      "x": 4,
      "y": 22,
      "z": -17,
      "name": "Cloth_Block_Wool_Red"
    },
    {
      "x": 4,
      "y": 23,
      "z": -17,
      "name": "Cloth_Block_Wool_Red"
    },
    {
      "x": 4,
      "y": 24,
      "z": -17,
      "name": "Cloth_Block_Wool_Red"
    },
    {
      "x": 4,
      "y": 25,
      "z": -17,
      "name": "Cloth_Block_Wool_Red"
    },
    {
      "x": 4,
      "y": 26,
      "z": -17,
      "name": "Cloth_Block_Wool_Red"
    },
    {
      "x": 4,
      "y": 27,
      "z": -17,
      "name": "Cloth_Block_Wool_Red"
    },
    {
      "x": 4,
      "y": 28,
      "z": -17,
      "name": "Cloth_Block_Wool_Red"
    },
    {
      "x": 4,
      "y": 21,
      "z": -16,
      "name": "Cloth_Block_Wool_Red"
    },
    {
      "x": 4,
      "y": 22,
      "z": -16,
      "name": "Cloth_Block_Wool_Red"
    },
    {
      "x": 4,
      "y": 23,
      "z": -16,
      "name": "Cloth_Block_Wool_Red"
    },
    {
      "x": 4,
      "y": 27,
      "z": -16,
      "name": "Cloth_Block_Wool_Red"
    },
    {
      "x": 4,
      "y": 28,
      "z": -16,
      "name": "Cloth_Block_Wool_Red"
    },
    {
      "x": 4,
      "y": 29,
      "z": -16,
      "name": "Cloth_Block_Wool_Red"
    },
    {
      "x": 4,
      "y": 20,
      "z": -15,
      "name": "Cloth_Block_Wool_Red"
    },
    {
      "x": 4,
      "y": 21,
      "z": -15,
      "name": "Cloth_Block_Wool_Red"
    },
    {
      "x": 4,
      "y": 22,
      "z": -15,
      "name": "Cloth_Block_Wool_Red"
    },
    {
      "x": 4,
      "y": 28,
      "z": -15,
      "name": "Cloth_Block_Wool_Red"
    },
    {
      "x": 4,
      "y": 29,
      "z": -15,
      "name": "Cloth_Block_Wool_Red"
    },
    {
      "x": 4,
      "y": 30,
      "z": -15,
      "name": "Cloth_Block_Wool_Red"
    },
    {
      "x": 4,
      "y": 20,
      "z": -14,
      "name": "Cloth_Block_Wool_White"
    },
    {
      "x": 4,
      "y": 21,
      "z": -14,
      "name": "Cloth_Block_Wool_White"
    },
    {
      "x": 4,
      "y": 29,
      "z": -14,
      "name": "Cloth_Block_Wool_White"
    },
    {
      "x": 4,
      "y": 30,
      "z": -14,
      "name": "Cloth_Block_Wool_White"
    },
    {
      "x": 4,
      "y": 18,
      "z": -13,
      "name": "Wood_Hardwood_Beam"
    },
    {
      "x": 4,
      "y": 19,
      "z": -13,
      "name": "Wood_Hardwood_Planks"
    },
    {
      "x": 4,
      "y": 20,
      "z": -13,
      "name": "Cloth_Block_Wool_White"
    },
    {
      "x": 4,
      "y": 21,
      "z": -13,
      "name": "Cloth_Block_Wool_White"
    },
    {
      "x": 4,
      "y": 29,
      "z": -13,
      "name": "Cloth_Block_Wool_White"
    },
    {
      "x": 4,
      "y": 30,
      "z": -13,
      "name": "Cloth_Block_Wool_White"
    },
    {
      "x": 4,
      "y": 31,
      "z": -13,
      "name": "Wood_Hardwood_Planks"
    },
    {
      "x": 4,
      "y": 32,
      "z": -13,
      "name": "Wood_Hardwood_Beam"
    },
    {
      "x": 4,
      "y": 20,
      "z": -12,
      "name": "Cloth_Block_Wool_White"
    },
    {
      "x": 4,
      "y": 21,
      "z": -12,
      "name": "Cloth_Block_Wool_White"
    },
    {
      "x": 4,
      "y": 29,
      "z": -12,
      "name": "Cloth_Block_Wool_White"
    },
    {
      "x": 4,
      "y": 30,
      "z": -12,
      "name": "Cloth_Block_Wool_White"
    },
    {
      "x": 4,
      "y": 20,
      "z": -11,
      "name": "Cloth_Block_Wool_Red"
    },
    {
      "x": 4,
      "y": 21,
      "z": -11,
      "name": "Cloth_Block_Wool_Red"
    },
    {
      "x": 4,
      "y": 22,
      "z": -11,
      "name": "Cloth_Block_Wool_Red"
    },
    {
      "x": 4,
      "y": 28,
      "z": -11,
      "name": "Cloth_Block_Wool_Red"
    },
    {
      "x": 4,
      "y": 29,
      "z": -11,
      "name": "Cloth_Block_Wool_Red"
    },
    {
      "x": 4,
      "y": 30,
      "z": -11,
      "name": "Cloth_Block_Wool_Red"
    },
    {
      "x": 4,
      "y": 21,
      "z": -10,
      "name": "Cloth_Block_Wool_Red"
    },
    {
      "x": 4,
      "y": 22,
      "z": -10,
      "name": "Cloth_Block_Wool_Red"
    },
    {
      "x": 4,
      "y": 23,
      "z": -10,
      "name": "Cloth_Block_Wool_Red"
    },
    {
      "x": 4,
      "y": 27,
      "z": -10,
      "name": "Cloth_Block_Wool_Red"
    },
    {
      "x": 4,
      "y": 28,
      "z": -10,
      "name": "Cloth_Block_Wool_Red"
    },
    {
      "x": 4,
      "y": 29,
      "z": -10,
      "name": "Cloth_Block_Wool_Red"
    },
    {
      "x": 4,
      "y": 22,
      "z": -9,
      "name": "Cloth_Block_Wool_Red"
    },
    {
      "x": 4,
      "y": 23,
      "z": -9,
      "name": "Cloth_Block_Wool_Red"
    },
    {
      "x": 4,
      "y": 24,
      "z": -9,
      "name": "Cloth_Block_Wool_Red"
    },
    {
      "x": 4,
      "y": 25,
      "z": -9,
      "name": "Cloth_Block_Wool_Red"
    },
    {
      "x": 4,
      "y": 26,
      "z": -9,
      "name": "Cloth_Block_Wool_Red"
    },
    {
      "x": 4,
      "y": 27,
      "z": -9,
      "name": "Cloth_Block_Wool_Red"
    },
    {
      "x": 4,
      "y": 28,
      "z": -9,
      "name": "Cloth_Block_Wool_Red"
    },
    {
      "x": 4,
      "y": 23,
      "z": -8,
      "name": "Cloth_Block_Wool_Red"
    },
    {
      "x": 4,
      "y": 24,
      "z": -8,
      "name": "Cloth_Block_Wool_Red"
    },
    {
      "x": 4,
      "y": 25,
      "z": -8,
      "name": "Cloth_Block_Wool_Red"
    },
    {
      "x": 4,
      "y": 26,
      "z": -8,
      "name": "Cloth_Block_Wool_Red"
    },
    {
      "x": 4,
      "y": 27,
      "z": -8,
      "name": "Cloth_Block_Wool_Red"
    },
    {
      "x": 4,
      "y": 24,
      "z": -7,
      "name": "Wood_Hardwood_Beam"
    },
    {
      "x": 4,
      "y": 25,
      "z": -7,
      "name": "Wood_Hardwood_Planks"
    },
    {
      "x": 4,
      "y": 26,
      "z": -7,
      "name": "Wood_Hardwood_Beam"
    },
    {
      "x": 5,
      "y": 12,
      "z": -20,
      "name": "*Furniture_Crude_Trapdoor_State_Definitions_OpenDoorOut",
      "rotation": 3
    },
    {
      "x": 5,
      "y": 24,
      "z": -20,
      "name": "Wood_Hardwood_Stairs",
      "rotation": 9
    },
    {
      "x": 5,
      "y": 25,
      "z": -20,
      "name": "Wood_Hardwood_Planks"
    },
    {
      "x": 5,
      "y": 26,
      "z": -20,
      "name": "Wood_Hardwood_Stairs",
      "rotation": 3
    },
    {
      "x": 5,
      "y": 22,
      "z": -19,
      "name": "Cloth_Block_Wool_White"
    },
    {
      "x": 5,
      "y": 23,
      "z": -19,
      "name": "Cloth_Block_Wool_White"
    },
    {
      "x": 5,
      "y": 24,
      "z": -19,
      "name": "Cloth_Block_Wool_White"
    },
    {
      "x": 5,
      "y": 25,
      "z": -19,
      "name": "Cloth_Block_Wool_White"
    },
    {
      "x": 5,
      "y": 26,
      "z": -19,
      "name": "Cloth_Block_Wool_White"
    },
    {
      "x": 5,
      "y": 27,
      "z": -19,
      "name": "Cloth_Block_Wool_White"
    },
    {
      "x": 5,
      "y": 28,
      "z": -19,
      "name": "Cloth_Block_Wool_White"
    },
    {
      "x": 5,
      "y": 21,
      "z": -18,
      "name": "Cloth_Block_Wool_Red"
    },
    {
      "x": 5,
      "y": 22,
      "z": -18,
      "name": "Cloth_Block_Wool_Red"
    },
    {
      "x": 5,
      "y": 28,
      "z": -18,
      "name": "Cloth_Block_Wool_Red"
    },
    {
      "x": 5,
      "y": 29,
      "z": -18,
      "name": "Cloth_Block_Wool_Red"
    },
    {
      "x": 5,
      "y": 20,
      "z": -17,
      "name": "Cloth_Block_Wool_Red"
    },
    {
      "x": 5,
      "y": 21,
      "z": -17,
      "name": "Cloth_Block_Wool_Red"
    },
    {
      "x": 5,
      "y": 29,
      "z": -17,
      "name": "Cloth_Block_Wool_Red"
    },
    {
      "x": 5,
      "y": 30,
      "z": -17,
      "name": "Cloth_Block_Wool_Red"
    },
    {
      "x": 5,
      "y": 19,
      "z": -16,
      "name": "Cloth_Block_Wool_Red"
    },
    {
      "x": 5,
      "y": 20,
      "z": -16,
      "name": "Cloth_Block_Wool_Red"
    },
    {
      "x": 5,
      "y": 30,
      "z": -16,
      "name": "Cloth_Block_Wool_Red"
    },
    {
      "x": 5,
      "y": 31,
      "z": -16,
      "name": "Cloth_Block_Wool_Red"
    },
    {
      "x": 5,
      "y": 19,
      "z": -15,
      "name": "Cloth_Block_Wool_Red"
    },
    {
      "x": 5,
      "y": 31,
      "z": -15,
      "name": "Cloth_Block_Wool_Red"
    },
    {
      "x": 5,
      "y": 19,
      "z": -14,
      "name": "Cloth_Block_Wool_White"
    },
    {
      "x": 5,
      "y": 31,
      "z": -14,
      "name": "Cloth_Block_Wool_White"
    },
    {
      "x": 5,
      "y": 17,
      "z": -13,
      "name": "Wood_Hardwood_Beam"
    },
    {
      "x": 5,
      "y": 18,
      "z": -13,
      "name": "Wood_Hardwood_Planks"
    },
    {
      "x": 5,
      "y": 19,
      "z": -13,
      "name": "Cloth_Block_Wool_White"
    },
    {
      "x": 5,
      "y": 31,
      "z": -13,
      "name": "Cloth_Block_Wool_White"
    },
    {
      "x": 5,
      "y": 32,
      "z": -13,
      "name": "Wood_Hardwood_Planks"
    },
    {
      "x": 5,
      "y": 33,
      "z": -13,
      "name": "Wood_Hardwood_Beam"
    },
    {
      "x": 5,
      "y": 19,
      "z": -12,
      "name": "Cloth_Block_Wool_White"
    },
    {
      "x": 5,
      "y": 31,
      "z": -12,
      "name": "Cloth_Block_Wool_White"
    },
    {
      "x": 5,
      "y": 19,
      "z": -11,
      "name": "Cloth_Block_Wool_Red"
    },
    {
      "x": 5,
      "y": 31,
      "z": -11,
      "name": "Cloth_Block_Wool_Red"
    },
    {
      "x": 5,
      "y": 19,
      "z": -10,
      "name": "Cloth_Block_Wool_Red"
    },
    {
      "x": 5,
      "y": 20,
      "z": -10,
      "name": "Cloth_Block_Wool_Red"
    },
    {
      "x": 5,
      "y": 30,
      "z": -10,
      "name": "Cloth_Block_Wool_Red"
    },
    {
      "x": 5,
      "y": 31,
      "z": -10,
      "name": "Cloth_Block_Wool_Red"
    },
    {
      "x": 5,
      "y": 20,
      "z": -9,
      "name": "Cloth_Block_Wool_Red"
    },
    {
      "x": 5,
      "y": 21,
      "z": -9,
      "name": "Cloth_Block_Wool_Red"
    },
    {
      "x": 5,
      "y": 29,
      "z": -9,
      "name": "Cloth_Block_Wool_Red"
    },
    {
      "x": 5,
      "y": 30,
      "z": -9,
      "name": "Cloth_Block_Wool_Red"
    },
    {
      "x": 5,
      "y": 21,
      "z": -8,
      "name": "Cloth_Block_Wool_Red"
    },
    {
      "x": 5,
      "y": 22,
      "z": -8,
      "name": "Cloth_Block_Wool_Red"
    },
    {
      "x": 5,
      "y": 28,
      "z": -8,
      "name": "Cloth_Block_Wool_Red"
    },
    {
      "x": 5,
      "y": 29,
      "z": -8,
      "name": "Cloth_Block_Wool_Red"
    },
    {
      "x": 5,
      "y": 22,
      "z": -7,
      "name": "Cloth_Block_Wool_White"
    },
    {
      "x": 5,
      "y": 23,
      "z": -7,
      "name": "Cloth_Block_Wool_White"
    },
    {
      "x": 5,
      "y": 24,
      "z": -7,
      "name": "Cloth_Block_Wool_White"
    },
    {
      "x": 5,
      "y": 25,
      "z": -7,
      "name": "Cloth_Block_Wool_White"
    },
    {
      "x": 5,
      "y": 26,
      "z": -7,
      "name": "Cloth_Block_Wool_White"
    },
    {
      "x": 5,
      "y": 27,
      "z": -7,
      "name": "Cloth_Block_Wool_White"
    },
    {
      "x": 5,
      "y": 28,
      "z": -7,
      "name": "Cloth_Block_Wool_White"
    },
    {
      "x": 5,
      "y": 10,
      "z": -6,
      "name": "*Furniture_Crude_Trapdoor_State_Definitions_OpenDoorOut",
      "rotation": 3
    },
    {
      "x": 5,
      "y": 24,
      "z": -6,
      "name": "Wood_Hardwood_Stairs",
      "rotation": 9
    },
    {
      "x": 5,
      "y": 25,
      "z": -6,
      "name": "Wood_Hardwood_Planks"
    },
    {
      "x": 5,
      "y": 26,
      "z": -6,
      "name": "Wood_Hardwood_Stairs",
      "rotation": 3
    },
    {
      "x": 6,
      "y": 12,
      "z": -21,
      "name": "*Furniture_Crude_Trapdoor_State_Definitions_OpenDoorOut",
      "rotation": 2
    },
    {
      "x": 6,
      "y": 24,
      "z": -21,
      "name": "Wood_Hardwood_Stairs",
      "rotation": 8
    },
    {
      "x": 6,
      "y": 25,
      "z": -21,
      "name": "Wood_Hardwood_Planks"
    },
    {
      "x": 6,
      "y": 26,
      "z": -21,
      "name": "Wood_Hardwood_Stairs",
      "rotation": 2
    },
    {
      "x": 6,
      "y": 11,
      "z": -20,
      "name": "Furniture_Crude_Trapdoor",
      "rotation": 2
    },
    {
      "x": 6,
      "y": 12,
      "z": -20,
      "name": "Rock_Crystal_Yellow_Block"
    },
    {
      "x": 6,
      "y": 13,
      "z": -20,
      "name": "Wood_Hardwood_Planks"
    },
    {
      "x": 6,
      "y": 14,
      "z": -20,
      "name": "Wood_Hardwood_Beam"
    },
    {
      "x": 6,
      "y": 15,
      "z": -20,
      "name": "Wood_Hardwood_Beam"
    },
    {
      "x": 6,
      "y": 16,
      "z": -20,
      "name": "Wood_Hardwood_Beam"
    },
    {
      "x": 6,
      "y": 17,
      "z": -20,
      "name": "Wood_Hardwood_Beam"
    },
    {
      "x": 6,
      "y": 18,
      "z": -20,
      "name": "Wood_Hardwood_Beam"
    },
    {
      "x": 6,
      "y": 19,
      "z": -20,
      "name": "Rock_Stone_Brick_Beam"
    },
    {
      "x": 6,
      "y": 20,
      "z": -20,
      "name": "Wood_Hardwood_Planks"
    },
    {
      "x": 6,
      "y": 21,
      "z": -20,
      "name": "Wood_Hardwood_Planks"
    },
    {
      "x": 6,
      "y": 22,
      "z": -20,
      "name": "Wood_Hardwood_Planks"
    },
    {
      "x": 6,
      "y": 23,
      "z": -20,
      "name": "Wood_Hardwood_Planks"
    },
    {
      "x": 6,
      "y": 24,
      "z": -20,
      "name": "Wood_Hardwood_Planks"
    },
    {
      "x": 6,
      "y": 25,
      "z": -20,
      "name": "Cloth_Block_Wool_White"
    },
    {
      "x": 6,
      "y": 26,
      "z": -20,
      "name": "Wood_Hardwood_Planks"
    },
    {
      "x": 6,
      "y": 27,
      "z": -20,
      "name": "Wood_Hardwood_Planks"
    },
    {
      "x": 6,
      "y": 28,
      "z": -20,
      "name": "Wood_Hardwood_Planks"
    },
    {
      "x": 6,
      "y": 29,
      "z": -20,
      "name": "Wood_Hardwood_Planks"
    },
    {
      "x": 6,
      "y": 30,
      "z": -20,
      "name": "Wood_Hardwood_Planks"
    },
    {
      "x": 6,
      "y": 31,
      "z": -20,
      "name": "Wood_Hardwood_Beam"
    },
    {
      "x": 6,
      "y": 12,
      "z": -19,
      "name": "*Furniture_Crude_Trapdoor_State_Definitions_OpenDoorOut"
    },
    {
      "x": 6,
      "y": 20,
      "z": -19,
      "name": "Cloth_Block_Wool_White"
    },
    {
      "x": 6,
      "y": 21,
      "z": -19,
      "name": "Cloth_Block_Wool_White"
    },
    {
      "x": 6,
      "y": 29,
      "z": -19,
      "name": "Cloth_Block_Wool_White"
    },
    {
      "x": 6,
      "y": 30,
      "z": -19,
      "name": "Cloth_Block_Wool_White"
    },
    {
      "x": 6,
      "y": 19,
      "z": -18,
      "name": "Cloth_Block_Wool_White"
    },
    {
      "x": 6,
      "y": 20,
      "z": -18,
      "name": "Cloth_Block_Wool_Red"
    },
    {
      "x": 6,
      "y": 21,
      "z": -18,
      "name": "Cloth_Block_Wool_White"
    },
    {
      "x": 6,
      "y": 30,
      "z": -18,
      "name": "Cloth_Block_Wool_Red"
    },
    {
      "x": 6,
      "y": 31,
      "z": -18,
      "name": "Cloth_Block_Wool_White"
    },
    {
      "x": 6,
      "y": 19,
      "z": -17,
      "name": "Cloth_Block_Wool_Red"
    },
    {
      "x": 6,
      "y": 31,
      "z": -17,
      "name": "Cloth_Block_Wool_Red"
    },
    {
      "x": 6,
      "y": 18,
      "z": -16,
      "name": "Cloth_Block_Wool_Red"
    },
    {
      "x": 6,
      "y": 32,
      "z": -16,
      "name": "Cloth_Block_Wool_Red"
    },
    {
      "x": 6,
      "y": 18,
      "z": -15,
      "name": "Cloth_Block_Wool_Red"
    },
    {
      "x": 6,
      "y": 32,
      "z": -15,
      "name": "Cloth_Block_Wool_Red"
    },
    {
      "x": 6,
      "y": 18,
      "z": -14,
      "name": "Cloth_Block_Wool_White"
    },
    {
      "x": 6,
      "y": 32,
      "z": -14,
      "name": "Cloth_Block_Wool_White"
    },
    {
      "x": 6,
      "y": 16,
      "z": -13,
      "name": "Wood_Hardwood_Beam"
    },
    {
      "x": 6,
      "y": 17,
      "z": -13,
      "name": "Wood_Hardwood_Planks"
    },
    {
      "x": 6,
      "y": 18,
      "z": -13,
      "name": "Cloth_Block_Wool_White"
    },
    {
      "x": 6,
      "y": 32,
      "z": -13,
      "name": "Cloth_Block_Wool_White"
    },
    {
      "x": 6,
      "y": 33,
      "z": -13,
      "name": "Wood_Hardwood_Planks"
    },
    {
      "x": 6,
      "y": 34,
      "z": -13,
      "name": "Wood_Hardwood_Beam"
    },
    {
      "x": 6,
      "y": 18,
      "z": -12,
      "name": "Cloth_Block_Wool_White"
    },
    {
      "x": 6,
      "y": 32,
      "z": -12,
      "name": "Cloth_Block_Wool_White"
    },
    {
      "x": 6,
      "y": 18,
      "z": -11,
      "name": "Cloth_Block_Wool_Red"
    },
    {
      "x": 6,
      "y": 32,
      "z": -11,
      "name": "Cloth_Block_Wool_Red"
    },
    {
      "x": 6,
      "y": 18,
      "z": -10,
      "name": "Cloth_Block_Wool_Red"
    },
    {
      "x": 6,
      "y": 32,
      "z": -10,
      "name": "Cloth_Block_Wool_Red"
    },
    {
      "x": 6,
      "y": 19,
      "z": -9,
      "name": "Cloth_Block_Wool_Red"
    },
    {
      "x": 6,
      "y": 31,
      "z": -9,
      "name": "Cloth_Block_Wool_Red"
    },
    {
      "x": 6,
      "y": 19,
      "z": -8,
      "name": "Cloth_Block_Wool_White"
    },
    {
      "x": 6,
      "y": 20,
      "z": -8,
      "name": "Cloth_Block_Wool_Red"
    },
    {
      "x": 6,
      "y": 21,
      "z": -8,
      "name": "Cloth_Block_Wool_White"
    },
    {
      "x": 6,
      "y": 30,
      "z": -8,
      "name": "Cloth_Block_Wool_Red"
    },
    {
      "x": 6,
      "y": 31,
      "z": -8,
      "name": "Cloth_Block_Wool_White"
    },
    {
      "x": 6,
      "y": 10,
      "z": -7,
      "name": "*Furniture_Crude_Trapdoor_State_Definitions_OpenDoorOut",
      "rotation": 2
    },
    {
      "x": 6,
      "y": 20,
      "z": -7,
      "name": "Cloth_Block_Wool_White"
    },
    {
      "x": 6,
      "y": 21,
      "z": -7,
      "name": "Cloth_Block_Wool_White"
    },
    {
      "x": 6,
      "y": 29,
      "z": -7,
      "name": "Cloth_Block_Wool_White"
    },
    {
      "x": 6,
      "y": 30,
      "z": -7,
      "name": "Cloth_Block_Wool_White"
    },
    {
      "x": 6,
      "y": 9,
      "z": -6,
      "name": "Furniture_Crude_Trapdoor"
    },
    {
      "x": 6,
      "y": 10,
      "z": -6,
      "name": "Rock_Crystal_Yellow_Block"
    },
    {
      "x": 6,
      "y": 11,
      "z": -6,
      "name": "Wood_Hardwood_Planks"
    },
    {
      "x": 6,
      "y": 12,
      "z": -6,
      "name": "Wood_Hardwood_Beam"
    },
    {
      "x": 6,
      "y": 13,
      "z": -6,
      "name": "Wood_Hardwood_Beam"
    },
    {
      "x": 6,
      "y": 14,
      "z": -6,
      "name": "Wood_Hardwood_Beam"
    },
    {
      "x": 6,
      "y": 15,
      "z": -6,
      "name": "Wood_Hardwood_Beam"
    },
    {
      "x": 6,
      "y": 16,
      "z": -6,
      "name": "Wood_Hardwood_Beam"
    },
    {
      "x": 6,
      "y": 17,
      "z": -6,
      "name": "Wood_Hardwood_Beam"
    },
    {
      "x": 6,
      "y": 18,
      "z": -6,
      "name": "Wood_Hardwood_Beam"
    },
    {
      "x": 6,
      "y": 19,
      "z": -6,
      "name": "Rock_Stone_Brick_Beam"
    },
    {
      "x": 6,
      "y": 20,
      "z": -6,
      "name": "Wood_Hardwood_Planks"
    },
    {
      "x": 6,
      "y": 21,
      "z": -6,
      "name": "Wood_Hardwood_Planks"
    },
    {
      "x": 6,
      "y": 22,
      "z": -6,
      "name": "Wood_Hardwood_Planks"
    },
    {
      "x": 6,
      "y": 23,
      "z": -6,
      "name": "Wood_Hardwood_Planks"
    },
    {
      "x": 6,
      "y": 24,
      "z": -6,
      "name": "Wood_Hardwood_Planks"
    },
    {
      "x": 6,
      "y": 25,
      "z": -6,
      "name": "Cloth_Block_Wool_White"
    },
    {
      "x": 6,
      "y": 26,
      "z": -6,
      "name": "Wood_Hardwood_Planks"
    },
    {
      "x": 6,
      "y": 27,
      "z": -6,
      "name": "Wood_Hardwood_Planks"
    },
    {
      "x": 6,
      "y": 28,
      "z": -6,
      "name": "Wood_Hardwood_Planks"
    },
    {
      "x": 6,
      "y": 29,
      "z": -6,
      "name": "Wood_Hardwood_Planks"
    },
    {
      "x": 6,
      "y": 30,
      "z": -6,
      "name": "Wood_Hardwood_Planks"
    },
    {
      "x": 6,
      "y": 31,
      "z": -6,
      "name": "Wood_Hardwood_Beam"
    },
    {
      "x": 6,
      "y": 10,
      "z": -5,
      "name": "*Furniture_Crude_Trapdoor_State_Definitions_OpenDoorOut"
    },
    {
      "x": 6,
      "y": 24,
      "z": -5,
      "name": "Wood_Hardwood_Stairs",
      "rotation": 10
    },
    {
      "x": 6,
      "y": 25,
      "z": -5,
      "name": "Wood_Hardwood_Planks"
    },
    {
      "x": 6,
      "y": 26,
      "z": -5,
      "name": "Wood_Hardwood_Stairs"
    },
    {
      "x": 7,
      "y": 24,
      "z": -22,
      "name": "Wood_Hardwood_Beam"
    },
    {
      "x": 7,
      "y": 25,
      "z": -22,
      "name": "Wood_Hardwood_Planks"
    },
    {
      "x": 7,
      "y": 26,
      "z": -22,
      "name": "Wood_Hardwood_Beam"
    },
    {
      "x": 7,
      "y": 22,
      "z": -21,
      "name": "Cloth_Block_Wool_White"
    },
    {
      "x": 7,
      "y": 23,
      "z": -21,
      "name": "Cloth_Block_Wool_White"
    },
    {
      "x": 7,
      "y": 24,
      "z": -21,
      "name": "Cloth_Block_Wool_White"
    },
    {
      "x": 7,
      "y": 25,
      "z": -21,
      "name": "Cloth_Block_Wool_White"
    },
    {
      "x": 7,
      "y": 26,
      "z": -21,
      "name": "Cloth_Block_Wool_White"
    },
    {
      "x": 7,
      "y": 27,
      "z": -21,
      "name": "Cloth_Block_Wool_White"
    },
    {
      "x": 7,
      "y": 28,
      "z": -21,
      "name": "Cloth_Block_Wool_White"
    },
    {
      "x": 7,
      "y": 12,
      "z": -20,
      "name": "*Furniture_Crude_Trapdoor_State_Definitions_OpenDoorOut",
      "rotation": 1
    },
    {
      "x": 7,
      "y": 20,
      "z": -20,
      "name": "Cloth_Block_Wool_White"
    },
    {
      "x": 7,
      "y": 21,
      "z": -20,
      "name": "Cloth_Block_Wool_White"
    },
    {
      "x": 7,
      "y": 29,
      "z": -20,
      "name": "Cloth_Block_Wool_White"
    },
    {
      "x": 7,
      "y": 30,
      "z": -20,
      "name": "Cloth_Block_Wool_White"
    },
    {
      "x": 7,
      "y": 17,
      "z": -19,
      "name": "Wood_Hardwood_Beam"
    },
    {
      "x": 7,
      "y": 18,
      "z": -19,
      "name": "Wood_Hardwood_Planks"
    },
    {
      "x": 7,
      "y": 19,
      "z": -19,
      "name": "Wood_Hardwood_Planks"
    },
    {
      "x": 7,
      "y": 31,
      "z": -19,
      "name": "Wood_Hardwood_Planks"
    },
    {
      "x": 7,
      "y": 32,
      "z": -19,
      "name": "Wood_Hardwood_Planks"
    },
    {
      "x": 7,
      "y": 33,
      "z": -19,
      "name": "Wood_Hardwood_Beam"
    },
    {
      "x": 7,
      "y": 18,
      "z": -18,
      "name": "Cloth_Block_Wool_White"
    },
    {
      "x": 7,
      "y": 31,
      "z": -18,
      "name": "Cloth_Block_Wool_White"
    },
    {
      "x": 7,
      "y": 32,
      "z": -18,
      "name": "Cloth_Block_Wool_White"
    },
    {
      "x": 7,
      "y": 18,
      "z": -17,
      "name": "Cloth_Block_Wool_Red"
    },
    {
      "x": 7,
      "y": 32,
      "z": -17,
      "name": "Cloth_Block_Wool_Red"
    },
    {
      "x": 7,
      "y": 17,
      "z": -16,
      "name": "Cloth_Block_Wool_Red"
    },
    {
      "x": 7,
      "y": 33,
      "z": -16,
      "name": "Cloth_Block_Wool_Red"
    },
    {
      "x": 7,
      "y": 16,
      "z": -15,
      "name": "Wood_Hardwood_Planks"
    },
    {
      "x": 7,
      "y": 17,
      "z": -15,
      "name": "Cloth_Block_Wool_Red"
    },
    {
      "x": 7,
      "y": 33,
      "z": -15,
      "name": "Cloth_Block_Wool_Red"
    },
    {
      "x": 7,
      "y": 16,
      "z": -14,
      "name": "Wood_Hardwood_Planks"
    },
    {
      "x": 7,
      "y": 17,
      "z": -14,
      "name": "Cloth_Block_Wool_White"
    },
    {
      "x": 7,
      "y": 33,
      "z": -14,
      "name": "Cloth_Block_Wool_White"
    },
    {
      "x": 7,
      "y": 14,
      "z": -13,
      "name": "Wood_Hardwood_Beam"
    },
    {
      "x": 7,
      "y": 15,
      "z": -13,
      "name": "Wood_Hardwood_Planks"
    },
    {
      "x": 7,
      "y": 16,
      "z": -13,
      "name": "Wood_Hardwood_Planks"
    },
    {
      "x": 7,
      "y": 17,
      "z": -13,
      "name": "Cloth_Block_Wool_White"
    },
    {
      "x": 7,
      "y": 33,
      "z": -13,
      "name": "Cloth_Block_Wool_White"
    },
    {
      "x": 7,
      "y": 34,
      "z": -13,
      "name": "Wood_Hardwood_Planks"
    },
    {
      "x": 7,
      "y": 35,
      "z": -13,
      "name": "Wood_Hardwood_Beam"
    },
    {
      "x": 7,
      "y": 16,
      "z": -12,
      "name": "Wood_Hardwood_Planks"
    },
    {
      "x": 7,
      "y": 17,
      "z": -12,
      "name": "Cloth_Block_Wool_White"
    },
    {
      "x": 7,
      "y": 33,
      "z": -12,
      "name": "Cloth_Block_Wool_White"
    },
    {
      "x": 7,
      "y": 16,
      "z": -11,
      "name": "Wood_Hardwood_Planks"
    },
    {
      "x": 7,
      "y": 17,
      "z": -11,
      "name": "Cloth_Block_Wool_Red"
    },
    {
      "x": 7,
      "y": 33,
      "z": -11,
      "name": "Cloth_Block_Wool_Red"
    },
    {
      "x": 7,
      "y": 17,
      "z": -10,
      "name": "Cloth_Block_Wool_Red"
    },
    {
      "x": 7,
      "y": 33,
      "z": -10,
      "name": "Cloth_Block_Wool_Red"
    },
    {
      "x": 7,
      "y": 18,
      "z": -9,
      "name": "Cloth_Block_Wool_Red"
    },
    {
      "x": 7,
      "y": 32,
      "z": -9,
      "name": "Cloth_Block_Wool_Red"
    },
    {
      "x": 7,
      "y": 18,
      "z": -8,
      "name": "Cloth_Block_Wool_White"
    },
    {
      "x": 7,
      "y": 19,
      "z": -8,
      "name": "Cloth_Block_Wool_White"
    },
    {
      "x": 7,
      "y": 32,
      "z": -8,
      "name": "Cloth_Block_Wool_White"
    },
    {
      "x": 7,
      "y": 17,
      "z": -7,
      "name": "Wood_Hardwood_Beam"
    },
    {
      "x": 7,
      "y": 18,
      "z": -7,
      "name": "Wood_Hardwood_Planks"
    },
    {
      "x": 7,
      "y": 19,
      "z": -7,
      "name": "Wood_Hardwood_Planks"
    },
    {
      "x": 7,
      "y": 31,
      "z": -7,
      "name": "Wood_Hardwood_Planks"
    },
    {
      "x": 7,
      "y": 32,
      "z": -7,
      "name": "Wood_Hardwood_Planks"
    },
    {
      "x": 7,
      "y": 33,
      "z": -7,
      "name": "Wood_Hardwood_Beam"
    },
    {
      "x": 7,
      "y": 10,
      "z": -6,
      "name": "*Furniture_Crude_Trapdoor_State_Definitions_OpenDoorOut",
      "rotation": 1
    },
    {
      "x": 7,
      "y": 20,
      "z": -6,
      "name": "Cloth_Block_Wool_White"
    },
    {
      "x": 7,
      "y": 21,
      "z": -6,
      "name": "Cloth_Block_Wool_White"
    },
    {
      "x": 7,
      "y": 29,
      "z": -6,
      "name": "Cloth_Block_Wool_White"
    },
    {
      "x": 7,
      "y": 30,
      "z": -6,
      "name": "Cloth_Block_Wool_White"
    },
    {
      "x": 7,
      "y": 22,
      "z": -5,
      "name": "Cloth_Block_Wool_White"
    },
    {
      "x": 7,
      "y": 23,
      "z": -5,
      "name": "Cloth_Block_Wool_White"
    },
    {
      "x": 7,
      "y": 24,
      "z": -5,
      "name": "Cloth_Block_Wool_White"
    },
    {
      "x": 7,
      "y": 25,
      "z": -5,
      "name": "Cloth_Block_Wool_White"
    },
    {
      "x": 7,
      "y": 26,
      "z": -5,
      "name": "Cloth_Block_Wool_White"
    },
    {
      "x": 7,
      "y": 27,
      "z": -5,
      "name": "Cloth_Block_Wool_White"
    },
    {
      "x": 7,
      "y": 28,
      "z": -5,
      "name": "Cloth_Block_Wool_White"
    },
    {
      "x": 7,
      "y": 24,
      "z": -4,
      "name": "Wood_Hardwood_Beam"
    },
    {
      "x": 7,
      "y": 25,
      "z": -4,
      "name": "Wood_Hardwood_Planks"
    },
    {
      "x": 7,
      "y": 26,
      "z": -4,
      "name": "Wood_Hardwood_Beam"
    },
    {
      "x": 8,
      "y": 24,
      "z": -23,
      "name": "Wood_Hardwood_Beam",
      "rotation": 1
    },
    {
      "x": 8,
      "y": 25,
      "z": -23,
      "name": "Wood_Hardwood_Planks"
    },
    {
      "x": 8,
      "y": 26,
      "z": -23,
      "name": "Wood_Hardwood_Beam",
      "rotation": 1
    },
    {
      "x": 8,
      "y": 23,
      "z": -22,
      "name": "Cloth_Block_Wool_Red"
    },
    {
      "x": 8,
      "y": 24,
      "z": -22,
      "name": "Cloth_Block_Wool_Red"
    },
    {
      "x": 8,
      "y": 25,
      "z": -22,
      "name": "Cloth_Block_Wool_Red"
    },
    {
      "x": 8,
      "y": 26,
      "z": -22,
      "name": "Cloth_Block_Wool_Red"
    },
    {
      "x": 8,
      "y": 27,
      "z": -22,
      "name": "Cloth_Block_Wool_Red"
    },
    {
      "x": 8,
      "y": 21,
      "z": -21,
      "name": "Cloth_Block_Wool_Red"
    },
    {
      "x": 8,
      "y": 22,
      "z": -21,
      "name": "Cloth_Block_Wool_Red"
    },
    {
      "x": 8,
      "y": 28,
      "z": -21,
      "name": "Cloth_Block_Wool_Red"
    },
    {
      "x": 8,
      "y": 29,
      "z": -21,
      "name": "Cloth_Block_Wool_Red"
    },
    {
      "x": 8,
      "y": 19,
      "z": -20,
      "name": "Cloth_Block_Wool_White"
    },
    {
      "x": 8,
      "y": 20,
      "z": -20,
      "name": "Cloth_Block_Wool_Red"
    },
    {
      "x": 8,
      "y": 21,
      "z": -20,
      "name": "Cloth_Block_Wool_White"
    },
    {
      "x": 8,
      "y": 30,
      "z": -20,
      "name": "Cloth_Block_Wool_Red"
    },
    {
      "x": 8,
      "y": 31,
      "z": -20,
      "name": "Cloth_Block_Wool_White"
    },
    {
      "x": 8,
      "y": 18,
      "z": -19,
      "name": "Cloth_Block_Wool_White"
    },
    {
      "x": 8,
      "y": 19,
      "z": -19,
      "name": "Cloth_Block_Wool_White"
    },
    {
      "x": 8,
      "y": 32,
      "z": -19,
      "name": "Cloth_Block_Wool_White"
    },
    {
      "x": 8,
      "y": 16,
      "z": -18,
      "name": "Wood_Hardwood_Beam"
    },
    {
      "x": 8,
      "y": 17,
      "z": -18,
      "name": "Wood_Hardwood_Planks"
    },
    {
      "x": 8,
      "y": 18,
      "z": -18,
      "name": "Cloth_Block_Wool_White"
    },
    {
      "x": 8,
      "y": 32,
      "z": -18,
      "name": "Cloth_Block_Wool_White"
    },
    {
      "x": 8,
      "y": 33,
      "z": -18,
      "name": "Wood_Hardwood_Planks"
    },
    {
      "x": 8,
      "y": 34,
      "z": -18,
      "name": "Wood_Hardwood_Beam"
    },
    {
      "x": 8,
      "y": 17,
      "z": -17,
      "name": "Cloth_Block_Wool_White"
    },
    {
      "x": 8,
      "y": 33,
      "z": -17,
      "name": "Cloth_Block_Wool_White"
    },
    {
      "x": 8,
      "y": 16,
      "z": -16,
      "name": "Wood_Hardwood_Planks"
    },
    {
      "x": 8,
      "y": 17,
      "z": -16,
      "name": "Cloth_Block_Wool_Red"
    },
    {
      "x": 8,
      "y": 33,
      "z": -16,
      "name": "Cloth_Block_Wool_Red"
    },
    {
      "x": 8,
      "y": 16,
      "z": -15,
      "name": "Cloth_Block_Wool_Red"
    },
    {
      "x": 8,
      "y": 34,
      "z": -15,
      "name": "Cloth_Block_Wool_Red"
    },
    {
      "x": 8,
      "y": 14,
      "z": -14,
      "name": "Wood_Hardwood_Planks"
    },
    {
      "x": 8,
      "y": 15,
      "z": -14,
      "name": "Cloth_Block_Wool_Red"
    },
    {
      "x": 8,
      "y": 16,
      "z": -14,
      "name": "Cloth_Block_Wool_White"
    },
    {
      "x": 8,
      "y": 34,
      "z": -14,
      "name": "Cloth_Block_Wool_White"
    },
    {
      "x": 8,
      "y": 12,
      "z": -13,
      "name": "Wood_Hardwood_Beam"
    },
    {
      "x": 8,
      "y": 13,
      "z": -13,
      "name": "Wood_Hardwood_Beam"
    },
    {
      "x": 8,
      "y": 14,
      "z": -13,
      "name": "Wood_Hardwood_Planks"
    },
    {
      "x": 8,
      "y": 15,
      "z": -13,
      "name": "Cloth_Block_Wool_Red"
    },
    {
      "x": 8,
      "y": 16,
      "z": -13,
      "name": "Cloth_Block_Wool_White"
    },
    {
      "x": 8,
      "y": 34,
      "z": -13,
      "name": "Cloth_Block_Wool_White"
    },
    {
      "x": 8,
      "y": 35,
      "z": -13,
      "name": "Wood_Hardwood_Planks"
    },
    {
      "x": 8,
      "y": 14,
      "z": -12,
      "name": "Wood_Hardwood_Planks"
    },
    {
      "x": 8,
      "y": 15,
      "z": -12,
      "name": "Cloth_Block_Wool_Red"
    },
    {
      "x": 8,
      "y": 16,
      "z": -12,
      "name": "Cloth_Block_Wool_White"
    },
    {
      "x": 8,
      "y": 34,
      "z": -12,
      "name": "Cloth_Block_Wool_White"
    },
    {
      "x": 8,
      "y": 16,
      "z": -11,
      "name": "Cloth_Block_Wool_Red"
    },
    {
      "x": 8,
      "y": 34,
      "z": -11,
      "name": "Cloth_Block_Wool_Red"
    },
    {
      "x": 8,
      "y": 16,
      "z": -10,
      "name": "Wood_Hardwood_Planks"
    },
    {
      "x": 8,
      "y": 17,
      "z": -10,
      "name": "Cloth_Block_Wool_Red"
    },
    {
      "x": 8,
      "y": 33,
      "z": -10,
      "name": "Cloth_Block_Wool_Red"
    },
    {
      "x": 8,
      "y": 17,
      "z": -9,
      "name": "Cloth_Block_Wool_White"
    },
    {
      "x": 8,
      "y": 33,
      "z": -9,
      "name": "Cloth_Block_Wool_White"
    },
    {
      "x": 8,
      "y": 16,
      "z": -8,
      "name": "Wood_Hardwood_Beam"
    },
    {
      "x": 8,
      "y": 17,
      "z": -8,
      "name": "Wood_Hardwood_Planks"
    },
    {
      "x": 8,
      "y": 18,
      "z": -8,
      "name": "Cloth_Block_Wool_White"
    },
    {
      "x": 8,
      "y": 32,
      "z": -8,
      "name": "Cloth_Block_Wool_White"
    },
    {
      "x": 8,
      "y": 33,
      "z": -8,
      "name": "Wood_Hardwood_Planks"
    },
    {
      "x": 8,
      "y": 34,
      "z": -8,
      "name": "Wood_Hardwood_Beam"
    },
    {
      "x": 8,
      "y": 18,
      "z": -7,
      "name": "Cloth_Block_Wool_White"
    },
    {
      "x": 8,
      "y": 31,
      "z": -7,
      "name": "Cloth_Block_Wool_White"
    },
    {
      "x": 8,
      "y": 32,
      "z": -7,
      "name": "Cloth_Block_Wool_White"
    },
    {
      "x": 8,
      "y": 19,
      "z": -6,
      "name": "Cloth_Block_Wool_White"
    },
    {
      "x": 8,
      "y": 20,
      "z": -6,
      "name": "Cloth_Block_Wool_Red"
    },
    {
      "x": 8,
      "y": 21,
      "z": -6,
      "name": "Cloth_Block_Wool_White"
    },
    {
      "x": 8,
      "y": 30,
      "z": -6,
      "name": "Cloth_Block_Wool_Red"
    },
    {
      "x": 8,
      "y": 31,
      "z": -6,
      "name": "Cloth_Block_Wool_White"
    },
    {
      "x": 8,
      "y": 21,
      "z": -5,
      "name": "Cloth_Block_Wool_Red"
    },
    {
      "x": 8,
      "y": 22,
      "z": -5,
      "name": "Cloth_Block_Wool_Red"
    },
    {
      "x": 8,
      "y": 28,
      "z": -5,
      "name": "Cloth_Block_Wool_Red"
    },
    {
      "x": 8,
      "y": 29,
      "z": -5,
      "name": "Cloth_Block_Wool_Red"
    },
    {
      "x": 8,
      "y": 23,
      "z": -4,
      "name": "Cloth_Block_Wool_Red"
    },
    {
      "x": 8,
      "y": 24,
      "z": -4,
      "name": "Cloth_Block_Wool_Red"
    },
    {
      "x": 8,
      "y": 25,
      "z": -4,
      "name": "Cloth_Block_Wool_Red"
    },
    {
      "x": 8,
      "y": 26,
      "z": -4,
      "name": "Cloth_Block_Wool_Red"
    },
    {
      "x": 8,
      "y": 27,
      "z": -4,
      "name": "Cloth_Block_Wool_Red"
    },
    {
      "x": 8,
      "y": 24,
      "z": -3,
      "name": "Wood_Hardwood_Beam",
      "rotation": 1
    },
    {
      "x": 8,
      "y": 25,
      "z": -3,
      "name": "Wood_Hardwood_Planks"
    },
    {
      "x": 8,
      "y": 26,
      "z": -3,
      "name": "Wood_Hardwood_Beam",
      "rotation": 1
    },
    {
      "x": 9,
      "y": 24,
      "z": -23,
      "name": "Wood_Hardwood_Planks_Half",
      "rotation": 8
    },
    {
      "x": 9,
      "y": 25,
      "z": -23,
      "name": "Wood_Hardwood_Planks"
    },
    {
      "x": 9,
      "y": 26,
      "z": -23,
      "name": "Wood_Hardwood_Planks_Half"
    },
    {
      "x": 9,
      "y": 22,
      "z": -22,
      "name": "Cloth_Block_Wool_Red"
    },
    {
      "x": 9,
      "y": 23,
      "z": -22,
      "name": "Cloth_Block_Wool_Red"
    },
    {
      "x": 9,
      "y": 24,
      "z": -22,
      "name": "Cloth_Block_Wool_Red"
    },
    {
      "x": 9,
      "y": 25,
      "z": -22,
      "name": "Cloth_Block_Wool_Red"
    },
    {
      "x": 9,
      "y": 26,
      "z": -22,
      "name": "Cloth_Block_Wool_Red"
    },
    {
      "x": 9,
      "y": 27,
      "z": -22,
      "name": "Cloth_Block_Wool_Red"
    },
    {
      "x": 9,
      "y": 28,
      "z": -22,
      "name": "Cloth_Block_Wool_Red"
    },
    {
      "x": 9,
      "y": 20,
      "z": -21,
      "name": "Cloth_Block_Wool_Red"
    },
    {
      "x": 9,
      "y": 21,
      "z": -21,
      "name": "Cloth_Block_Wool_Red"
    },
    {
      "x": 9,
      "y": 29,
      "z": -21,
      "name": "Cloth_Block_Wool_Red"
    },
    {
      "x": 9,
      "y": 30,
      "z": -21,
      "name": "Cloth_Block_Wool_Red"
    },
    {
      "x": 9,
      "y": 19,
      "z": -20,
      "name": "Cloth_Block_Wool_Red"
    },
    {
      "x": 9,
      "y": 31,
      "z": -20,
      "name": "Cloth_Block_Wool_Red"
    },
    {
      "x": 9,
      "y": 18,
      "z": -19,
      "name": "Cloth_Block_Wool_Red"
    },
    {
      "x": 9,
      "y": 32,
      "z": -19,
      "name": "Cloth_Block_Wool_Red"
    },
    {
      "x": 9,
      "y": 17,
      "z": -18,
      "name": "Cloth_Block_Wool_White"
    },
    {
      "x": 9,
      "y": 33,
      "z": -18,
      "name": "Cloth_Block_Wool_White"
    },
    {
      "x": 9,
      "y": 15,
      "z": -17,
      "name": "Wood_Hardwood_Beam"
    },
    {
      "x": 9,
      "y": 16,
      "z": -17,
      "name": "Wood_Hardwood_Planks"
    },
    {
      "x": 9,
      "y": 17,
      "z": -17,
      "name": "Cloth_Block_Wool_White"
    },
    {
      "x": 9,
      "y": 33,
      "z": -17,
      "name": "Cloth_Block_Wool_White"
    },
    {
      "x": 9,
      "y": 34,
      "z": -17,
      "name": "Wood_Hardwood_Planks"
    },
    {
      "x": 9,
      "y": 35,
      "z": -17,
      "name": "Wood_Hardwood_Beam"
    },
    {
      "x": 9,
      "y": 16,
      "z": -16,
      "name": "Cloth_Block_Wool_White"
    },
    {
      "x": 9,
      "y": 34,
      "z": -16,
      "name": "Cloth_Block_Wool_White"
    },
    {
      "x": 9,
      "y": 14,
      "z": -15,
      "name": "Wood_Hardwood_Planks"
    },
    {
      "x": 9,
      "y": 15,
      "z": -15,
      "name": "Cloth_Block_Wool_Red"
    },
    {
      "x": 9,
      "y": 16,
      "z": -15,
      "name": "Cloth_Block_Wool_Red"
    },
    {
      "x": 9,
      "y": 34,
      "z": -15,
      "name": "Cloth_Block_Wool_Red"
    },
    {
      "x": 9,
      "y": 14,
      "z": -14,
      "name": "Cloth_Block_Wool_Red"
    },
    {
      "x": 9,
      "y": 15,
      "z": -14,
      "name": "Cloth_Block_Wool_Red"
    },
    {
      "x": 9,
      "y": 16,
      "z": -14,
      "name": "Cloth_Block_Wool_White"
    },
    {
      "x": 9,
      "y": 34,
      "z": -14,
      "name": "Cloth_Block_Wool_White"
    },
    {
      "x": 9,
      "y": 11,
      "z": -13,
      "name": "Wood_Hardwood_Beam"
    },
    {
      "x": 9,
      "y": 12,
      "z": -13,
      "name": "Wood_Hardwood_Beam"
    },
    {
      "x": 9,
      "y": 13,
      "z": -13,
      "name": "Cloth_Block_Wool_Red"
    },
    {
      "x": 9,
      "y": 14,
      "z": -13,
      "name": "Cloth_Block_Wool_Red"
    },
    {
      "x": 9,
      "y": 15,
      "z": -13,
      "name": "Cloth_Block_Wool_Red"
    },
    {
      "x": 9,
      "y": 16,
      "z": -13,
      "name": "Cloth_Block_Wool_White"
    },
    {
      "x": 9,
      "y": 34,
      "z": -13,
      "name": "Cloth_Block_Wool_White"
    },
    {
      "x": 9,
      "y": 35,
      "z": -13,
      "name": "Wood_Hardwood_Planks"
    },
    {
      "x": 9,
      "y": 36,
      "z": -13,
      "name": "Wood_Hardwood_Beam"
    },
    {
      "x": 9,
      "y": 14,
      "z": -12,
      "name": "Cloth_Block_Wool_Red"
    },
    {
      "x": 9,
      "y": 15,
      "z": -12,
      "name": "Cloth_Block_Wool_Red"
    },
    {
      "x": 9,
      "y": 16,
      "z": -12,
      "name": "Cloth_Block_Wool_White"
    },
    {
      "x": 9,
      "y": 34,
      "z": -12,
      "name": "Cloth_Block_Wool_White"
    },
    {
      "x": 9,
      "y": 14,
      "z": -11,
      "name": "Wood_Hardwood_Planks"
    },
    {
      "x": 9,
      "y": 15,
      "z": -11,
      "name": "Cloth_Block_Wool_Red"
    },
    {
      "x": 9,
      "y": 16,
      "z": -11,
      "name": "Cloth_Block_Wool_Red"
    },
    {
      "x": 9,
      "y": 34,
      "z": -11,
      "name": "Cloth_Block_Wool_Red"
    },
    {
      "x": 9,
      "y": 16,
      "z": -10,
      "name": "Cloth_Block_Wool_White"
    },
    {
      "x": 9,
      "y": 34,
      "z": -10,
      "name": "Cloth_Block_Wool_White"
    },
    {
      "x": 9,
      "y": 15,
      "z": -9,
      "name": "Wood_Hardwood_Beam"
    },
    {
      "x": 9,
      "y": 16,
      "z": -9,
      "name": "Wood_Hardwood_Planks"
    },
    {
      "x": 9,
      "y": 17,
      "z": -9,
      "name": "Cloth_Block_Wool_White"
    },
    {
      "x": 9,
      "y": 33,
      "z": -9,
      "name": "Cloth_Block_Wool_White"
    },
    {
      "x": 9,
      "y": 34,
      "z": -9,
      "name": "Wood_Hardwood_Planks"
    },
    {
      "x": 9,
      "y": 35,
      "z": -9,
      "name": "Wood_Hardwood_Beam"
    },
    {
      "x": 9,
      "y": 17,
      "z": -8,
      "name": "Cloth_Block_Wool_White"
    },
    {
      "x": 9,
      "y": 33,
      "z": -8,
      "name": "Cloth_Block_Wool_White"
    },
    {
      "x": 9,
      "y": 18,
      "z": -7,
      "name": "Cloth_Block_Wool_Red"
    },
    {
      "x": 9,
      "y": 32,
      "z": -7,
      "name": "Cloth_Block_Wool_Red"
    },
    {
      "x": 9,
      "y": 19,
      "z": -6,
      "name": "Cloth_Block_Wool_Red"
    },
    {
      "x": 9,
      "y": 31,
      "z": -6,
      "name": "Cloth_Block_Wool_Red"
    },
    {
      "x": 9,
      "y": 20,
      "z": -5,
      "name": "Cloth_Block_Wool_Red"
    },
    {
      "x": 9,
      "y": 21,
      "z": -5,
      "name": "Cloth_Block_Wool_Red"
    },
    {
      "x": 9,
      "y": 29,
      "z": -5,
      "name": "Cloth_Block_Wool_Red"
    },
    {
      "x": 9,
      "y": 30,
      "z": -5,
      "name": "Cloth_Block_Wool_Red"
    },
    {
      "x": 9,
      "y": 22,
      "z": -4,
      "name": "Cloth_Block_Wool_Red"
    },
    {
      "x": 9,
      "y": 23,
      "z": -4,
      "name": "Cloth_Block_Wool_Red"
    },
    {
      "x": 9,
      "y": 24,
      "z": -4,
      "name": "Cloth_Block_Wool_Red"
    },
    {
      "x": 9,
      "y": 25,
      "z": -4,
      "name": "Cloth_Block_Wool_Red"
    },
    {
      "x": 9,
      "y": 26,
      "z": -4,
      "name": "Cloth_Block_Wool_Red"
    },
    {
      "x": 9,
      "y": 27,
      "z": -4,
      "name": "Cloth_Block_Wool_Red"
    },
    {
      "x": 9,
      "y": 28,
      "z": -4,
      "name": "Cloth_Block_Wool_Red"
    },
    {
      "x": 9,
      "y": 24,
      "z": -3,
      "name": "Wood_Hardwood_Planks_Half",
      "rotation": 8
    },
    {
      "x": 9,
      "y": 25,
      "z": -3,
      "name": "Wood_Hardwood_Planks"
    },
    {
      "x": 9,
      "y": 26,
      "z": -3,
      "name": "Wood_Hardwood_Planks_Half"
    },
    {
      "x": 10,
      "y": 24,
      "z": -24,
      "name": "Wood_Hardwood_Planks_Half",
      "rotation": 8
    },
    {
      "x": 10,
      "y": 25,
      "z": -24,
      "name": "Wood_Hardwood_Planks"
    },
    {
      "x": 10,
      "y": 26,
      "z": -24,
      "name": "Wood_Hardwood_Planks_Half"
    },
    {
      "x": 10,
      "y": 24,
      "z": -23,
      "name": "Cloth_Block_Wool_Red"
    },
    {
      "x": 10,
      "y": 25,
      "z": -23,
      "name": "Cloth_Block_Wool_Red"
    },
    {
      "x": 10,
      "y": 26,
      "z": -23,
      "name": "Cloth_Block_Wool_Red"
    },
    {
      "x": 10,
      "y": 21,
      "z": -22,
      "name": "Cloth_Block_Wool_Red"
    },
    {
      "x": 10,
      "y": 22,
      "z": -22,
      "name": "Cloth_Block_Wool_Red"
    },
    {
      "x": 10,
      "y": 23,
      "z": -22,
      "name": "Cloth_Block_Wool_Red"
    },
    {
      "x": 10,
      "y": 27,
      "z": -22,
      "name": "Cloth_Block_Wool_Red"
    },
    {
      "x": 10,
      "y": 28,
      "z": -22,
      "name": "Cloth_Block_Wool_Red"
    },
    {
      "x": 10,
      "y": 29,
      "z": -22,
      "name": "Cloth_Block_Wool_Red"
    },
    {
      "x": 10,
      "y": 19,
      "z": -21,
      "name": "Cloth_Block_Wool_Red"
    },
    {
      "x": 10,
      "y": 20,
      "z": -21,
      "name": "Cloth_Block_Wool_Red"
    },
    {
      "x": 10,
      "y": 30,
      "z": -21,
      "name": "Cloth_Block_Wool_Red"
    },
    {
      "x": 10,
      "y": 31,
      "z": -21,
      "name": "Cloth_Block_Wool_Red"
    },
    {
      "x": 10,
      "y": 18,
      "z": -20,
      "name": "Cloth_Block_Wool_Red"
    },
    {
      "x": 10,
      "y": 32,
      "z": -20,
      "name": "Cloth_Block_Wool_Red"
    },
    {
      "x": 10,
      "y": 17,
      "z": -19,
      "name": "Cloth_Block_Wool_Red"
    },
    {
      "x": 10,
      "y": 33,
      "z": -19,
      "name": "Cloth_Block_Wool_Red"
    },
    {
      "x": 10,
      "y": 16,
      "z": -18,
      "name": "Wood_Hardwood_Planks"
    },
    {
      "x": 10,
      "y": 17,
      "z": -18,
      "name": "Cloth_Block_Wool_Red"
    },
    {
      "x": 10,
      "y": 33,
      "z": -18,
      "name": "Cloth_Block_Wool_Red"
    },
    {
      "x": 10,
      "y": 16,
      "z": -17,
      "name": "Cloth_Block_Wool_White"
    },
    {
      "x": 10,
      "y": 34,
      "z": -17,
      "name": "Cloth_Block_Wool_White"
    },
    {
      "x": 10,
      "y": 14,
      "z": -16,
      "name": "Wood_Hardwood_Planks"
    },
    {
      "x": 10,
      "y": 15,
      "z": -16,
      "name": "Cloth_Block_Wool_Red"
    },
    {
      "x": 10,
      "y": 16,
      "z": -16,
      "name": "Cloth_Block_Wool_White"
    },
    {
      "x": 10,
      "y": 34,
      "z": -16,
      "name": "Cloth_Block_Wool_White"
    },
    {
      "x": 10,
      "y": 35,
      "z": -16,
      "name": "Wood_Hardwood_Planks"
    },
    {
      "x": 10,
      "y": 36,
      "z": -16,
      "name": "Wood_Hardwood_Beam"
    },
    {
      "x": 10,
      "y": 5,
      "z": -15,
      "name": "Wood_Hardwood_Planks_Half",
      "rotation": 7
    },
    {
      "x": 10,
      "y": 14,
      "z": -15,
      "name": "Cloth_Block_Wool_Red"
    },
    {
      "x": 10,
      "y": 15,
      "z": -15,
      "name": "Cloth_Block_Wool_Red"
    },
    {
      "x": 10,
      "y": 16,
      "z": -15,
      "name": "Cloth_Block_Wool_White"
    },
    {
      "x": 10,
      "y": 34,
      "z": -15,
      "name": "Cloth_Block_Wool_White"
    },
    {
      "x": 10,
      "y": 9,
      "z": -14,
      "name": "Wood_Hardwood_Planks_Half",
      "rotation": 7
    },
    {
      "x": 10,
      "y": 12,
      "z": -14,
      "name": "Cloth_Block_Wool_Red"
    },
    {
      "x": 10,
      "y": 13,
      "z": -14,
      "name": "Cloth_Block_Wool_Red"
    },
    {
      "x": 10,
      "y": 14,
      "z": -14,
      "name": "Cloth_Block_Wool_Red"
    },
    {
      "x": 10,
      "y": 15,
      "z": -14,
      "name": "Cloth_Block_Wool_White"
    },
    {
      "x": 10,
      "y": 35,
      "z": -14,
      "name": "Cloth_Block_Wool_White"
    },
    {
      "x": 10,
      "y": 5,
      "z": -13,
      "name": "*Furniture_Crude_Trapdoor_State_Definitions_OpenDoorOut",
      "rotation": 3
    },
    {
      "x": 10,
      "y": 9,
      "z": -13,
      "name": "Wood_Hardwood_Planks_Half",
      "rotation": 7
    },
    {
      "x": 10,
      "y": 10,
      "z": -13,
      "name": "Wood_Hardwood_Planks_Half",
      "rotation": 7
    },
    {
      "x": 10,
      "y": 11,
      "z": -13,
      "name": "Wood_Hardwood_Planks_Half",
      "rotation": 7
    },
    {
      "x": 10,
      "y": 12,
      "z": -13,
      "name": "Cloth_Block_Wool_Red"
    },
    {
      "x": 10,
      "y": 13,
      "z": -13,
      "name": "Cloth_Block_Wool_Red"
    },
    {
      "x": 10,
      "y": 14,
      "z": -13,
      "name": "Cloth_Block_Wool_Red"
    },
    {
      "x": 10,
      "y": 15,
      "z": -13,
      "name": "Cloth_Block_Wool_White"
    },
    {
      "x": 10,
      "y": 35,
      "z": -13,
      "name": "Cloth_Block_Wool_White"
    },
    {
      "x": 10,
      "y": 36,
      "z": -13,
      "name": "Wood_Hardwood_Planks"
    },
    {
      "x": 10,
      "y": 9,
      "z": -12,
      "name": "Wood_Hardwood_Planks_Half",
      "rotation": 7
    },
    {
      "x": 10,
      "y": 12,
      "z": -12,
      "name": "Cloth_Block_Wool_Red"
    },
    {
      "x": 10,
      "y": 13,
      "z": -12,
      "name": "Cloth_Block_Wool_Red"
    },
    {
      "x": 10,
      "y": 14,
      "z": -12,
      "name": "Cloth_Block_Wool_Red"
    },
    {
      "x": 10,
      "y": 15,
      "z": -12,
      "name": "Cloth_Block_Wool_White"
    },
    {
      "x": 10,
      "y": 35,
      "z": -12,
      "name": "Cloth_Block_Wool_White"
    },
    {
      "x": 10,
      "y": 5,
      "z": -11,
      "name": "Wood_Hardwood_Planks_Half",
      "rotation": 7
    },
    {
      "x": 10,
      "y": 14,
      "z": -11,
      "name": "Cloth_Block_Wool_Red"
    },
    {
      "x": 10,
      "y": 15,
      "z": -11,
      "name": "Cloth_Block_Wool_Red"
    },
    {
      "x": 10,
      "y": 16,
      "z": -11,
      "name": "Cloth_Block_Wool_White"
    },
    {
      "x": 10,
      "y": 34,
      "z": -11,
      "name": "Cloth_Block_Wool_White"
    },
    {
      "x": 10,
      "y": 13,
      "z": -10,
      "name": "Wood_Hardwood_Beam"
    },
    {
      "x": 10,
      "y": 14,
      "z": -10,
      "name": "Wood_Hardwood_Planks"
    },
    {
      "x": 10,
      "y": 15,
      "z": -10,
      "name": "Cloth_Block_Wool_Red"
    },
    {
      "x": 10,
      "y": 16,
      "z": -10,
      "name": "Cloth_Block_Wool_White"
    },
    {
      "x": 10,
      "y": 34,
      "z": -10,
      "name": "Cloth_Block_Wool_White"
    },
    {
      "x": 10,
      "y": 35,
      "z": -10,
      "name": "Wood_Hardwood_Planks"
    },
    {
      "x": 10,
      "y": 36,
      "z": -10,
      "name": "Wood_Hardwood_Beam"
    },
    {
      "x": 10,
      "y": 16,
      "z": -9,
      "name": "Cloth_Block_Wool_White"
    },
    {
      "x": 10,
      "y": 34,
      "z": -9,
      "name": "Cloth_Block_Wool_White"
    },
    {
      "x": 10,
      "y": 16,
      "z": -8,
      "name": "Wood_Hardwood_Planks"
    },
    {
      "x": 10,
      "y": 17,
      "z": -8,
      "name": "Cloth_Block_Wool_Red"
    },
    {
      "x": 10,
      "y": 33,
      "z": -8,
      "name": "Cloth_Block_Wool_Red"
    },
    {
      "x": 10,
      "y": 17,
      "z": -7,
      "name": "Cloth_Block_Wool_Red"
    },
    {
      "x": 10,
      "y": 33,
      "z": -7,
      "name": "Cloth_Block_Wool_Red"
    },
    {
      "x": 10,
      "y": 18,
      "z": -6,
      "name": "Cloth_Block_Wool_Red"
    },
    {
      "x": 10,
      "y": 32,
      "z": -6,
      "name": "Cloth_Block_Wool_Red"
    },
    {
      "x": 10,
      "y": 19,
      "z": -5,
      "name": "Cloth_Block_Wool_Red"
    },
    {
      "x": 10,
      "y": 20,
      "z": -5,
      "name": "Cloth_Block_Wool_Red"
    },
    {
      "x": 10,
      "y": 30,
      "z": -5,
      "name": "Cloth_Block_Wool_Red"
    },
    {
      "x": 10,
      "y": 31,
      "z": -5,
      "name": "Cloth_Block_Wool_Red"
    },
    {
      "x": 10,
      "y": 21,
      "z": -4,
      "name": "Cloth_Block_Wool_Red"
    },
    {
      "x": 10,
      "y": 22,
      "z": -4,
      "name": "Cloth_Block_Wool_Red"
    },
    {
      "x": 10,
      "y": 23,
      "z": -4,
      "name": "Cloth_Block_Wool_Red"
    },
    {
      "x": 10,
      "y": 27,
      "z": -4,
      "name": "Cloth_Block_Wool_Red"
    },
    {
      "x": 10,
      "y": 28,
      "z": -4,
      "name": "Cloth_Block_Wool_Red"
    },
    {
      "x": 10,
      "y": 29,
      "z": -4,
      "name": "Cloth_Block_Wool_Red"
    },
    {
      "x": 10,
      "y": 24,
      "z": -3,
      "name": "Cloth_Block_Wool_Red"
    },
    {
      "x": 10,
      "y": 25,
      "z": -3,
      "name": "Cloth_Block_Wool_Red"
    },
    {
      "x": 10,
      "y": 26,
      "z": -3,
      "name": "Cloth_Block_Wool_Red"
    },
    {
      "x": 10,
      "y": 24,
      "z": -2,
      "name": "Wood_Hardwood_Planks_Half",
      "rotation": 8
    },
    {
      "x": 10,
      "y": 25,
      "z": -2,
      "name": "Wood_Hardwood_Planks"
    },
    {
      "x": 10,
      "y": 26,
      "z": -2,
      "name": "Wood_Hardwood_Planks_Half"
    },
    {
      "x": 11,
      "y": 25,
      "z": -24,
      "name": "Wood_Hardwood_Planks"
    },
    {
      "x": 11,
      "y": 23,
      "z": -23,
      "name": "Cloth_Block_Wool_Red"
    },
    {
      "x": 11,
      "y": 24,
      "z": -23,
      "name": "Cloth_Block_Wool_Red"
    },
    {
      "x": 11,
      "y": 25,
      "z": -23,
      "name": "Cloth_Block_Wool_Red"
    },
    {
      "x": 11,
      "y": 26,
      "z": -23,
      "name": "Cloth_Block_Wool_Red"
    },
    {
      "x": 11,
      "y": 27,
      "z": -23,
      "name": "Cloth_Block_Wool_Red"
    },
    {
      "x": 11,
      "y": 20,
      "z": -22,
      "name": "Cloth_Block_Wool_Red"
    },
    {
      "x": 11,
      "y": 21,
      "z": -22,
      "name": "Cloth_Block_Wool_Red"
    },
    {
      "x": 11,
      "y": 22,
      "z": -22,
      "name": "Cloth_Block_Wool_Red"
    },
    {
      "x": 11,
      "y": 28,
      "z": -22,
      "name": "Cloth_Block_Wool_Red"
    },
    {
      "x": 11,
      "y": 29,
      "z": -22,
      "name": "Cloth_Block_Wool_Red"
    },
    {
      "x": 11,
      "y": 30,
      "z": -22,
      "name": "Cloth_Block_Wool_Red"
    },
    {
      "x": 11,
      "y": 19,
      "z": -21,
      "name": "Cloth_Block_Wool_Red"
    },
    {
      "x": 11,
      "y": 31,
      "z": -21,
      "name": "Cloth_Block_Wool_Red"
    },
    {
      "x": 11,
      "y": 18,
      "z": -20,
      "name": "Cloth_Block_Wool_Red"
    },
    {
      "x": 11,
      "y": 32,
      "z": -20,
      "name": "Cloth_Block_Wool_Red"
    },
    {
      "x": 11,
      "y": 16,
      "z": -19,
      "name": "Wood_Hardwood_Planks"
    },
    {
      "x": 11,
      "y": 17,
      "z": -19,
      "name": "Cloth_Block_Wool_Red"
    },
    {
      "x": 11,
      "y": 33,
      "z": -19,
      "name": "Cloth_Block_Wool_Red"
    },
    {
      "x": 11,
      "y": 16,
      "z": -18,
      "name": "Cloth_Block_Wool_Red"
    },
    {
      "x": 11,
      "y": 34,
      "z": -18,
      "name": "Cloth_Block_Wool_Red"
    },
    {
      "x": 11,
      "y": 14,
      "z": -17,
      "name": "Wood_Hardwood_Planks"
    },
    {
      "x": 11,
      "y": 15,
      "z": -17,
      "name": "Cloth_Block_Wool_Red"
    },
    {
      "x": 11,
      "y": 16,
      "z": -17,
      "name": "Cloth_Block_Wool_Red"
    },
    {
      "x": 11,
      "y": 34,
      "z": -17,
      "name": "Cloth_Block_Wool_Red"
    },
    {
      "x": 11,
      "y": 5,
      "z": -16,
      "name": "Wood_Hardwood_Planks_Half",
      "rotation": 6
    },
    {
      "x": 11,
      "y": 14,
      "z": -16,
      "name": "Cloth_Block_Wool_Red"
    },
    {
      "x": 11,
      "y": 15,
      "z": -16,
      "name": "Cloth_Block_Wool_Red"
    },
    {
      "x": 11,
      "y": 16,
      "z": -16,
      "name": "Cloth_Block_Wool_White"
    },
    {
      "x": 11,
      "y": 34,
      "z": -16,
      "name": "Cloth_Block_Wool_White"
    },
    {
      "x": 11,
      "y": 3,
      "z": -15,
      "name": "Furniture_Village_Crate"
    },
    {
      "x": 11,
      "y": 4,
      "z": -15,
      "name": "Deco_Rope"
    },
    {
      "x": 11,
      "y": 5,
      "z": -15,
      "name": "*Wood_Hardwood_Planks_Half_State_Definitions_Block",
      "rotation": 8
    },
    {
      "x": 11,
      "y": 6,
      "z": -15,
      "name": "Rock_Calcite_Brick_Beam"
    },
    {
      "x": 11,
      "y": 7,
      "z": -15,
      "name": "Wood_Hardwood_Beam"
    },
    {
      "x": 11,
      "y": 8,
      "z": -15,
      "name": "Wood_Hardwood_Beam"
    },
    {
      "x": 11,
      "y": 9,
      "z": -15,
      "name": "Wood_Hardwood_Beam"
    },
    {
      "x": 11,
      "y": 10,
      "z": -15,
      "name": "Wood_Hardwood_Beam"
    },
    {
      "x": 11,
      "y": 11,
      "z": -15,
      "name": "Wood_Hardwood_Beam"
    },
    {
      "x": 11,
      "y": 12,
      "z": -15,
      "name": "Cloth_Block_Wool_Red"
    },
    {
      "x": 11,
      "y": 13,
      "z": -15,
      "name": "Cloth_Block_Wool_Red"
    },
    {
      "x": 11,
      "y": 14,
      "z": -15,
      "name": "Cloth_Block_Wool_Red"
    },
    {
      "x": 11,
      "y": 15,
      "z": -15,
      "name": "Cloth_Block_Wool_White"
    },
    {
      "x": 11,
      "y": 35,
      "z": -15,
      "name": "Cloth_Block_Wool_White"
    },
    {
      "x": 11,
      "y": 36,
      "z": -15,
      "name": "Wood_Hardwood_Planks"
    },
    {
      "x": 11,
      "y": 4,
      "z": -14,
      "name": "Wood_Hardwood_Beam"
    },
    {
      "x": 11,
      "y": 5,
      "z": -14,
      "name": "Wood_Hardwood_Stairs"
    },
    {
      "x": 11,
      "y": 9,
      "z": -14,
      "name": "Wood_Hardwood_Planks"
    },
    {
      "x": 11,
      "y": 10,
      "z": -14,
      "name": "Cloth_Block_Wool_Red"
    },
    {
      "x": 11,
      "y": 11,
      "z": -14,
      "name": "Cloth_Block_Wool_Red"
    },
    {
      "x": 11,
      "y": 12,
      "z": -14,
      "name": "Cloth_Block_Wool_Red"
    },
    {
      "x": 11,
      "y": 15,
      "z": -14,
      "name": "Cloth_Block_Wool_Red"
    },
    {
      "x": 11,
      "y": 35,
      "z": -14,
      "name": "Cloth_Block_Wool_Red"
    },
    {
      "x": 11,
      "y": 4,
      "z": -13,
      "name": "Wood_Hardwood_Stairs",
      "rotation": 9
    },
    {
      "x": 11,
      "y": 5,
      "z": -13,
      "name": "Wood_Hardwood_Planks"
    },
    {
      "x": 11,
      "y": 9,
      "z": -13,
      "name": "Wood_Hardwood_Planks"
    },
    {
      "x": 11,
      "y": 10,
      "z": -13,
      "name": "Cloth_Block_Wool_Red"
    },
    {
      "x": 11,
      "y": 11,
      "z": -13,
      "name": "Cloth_Block_Wool_Red"
    },
    {
      "x": 11,
      "y": 12,
      "z": -13,
      "name": "Cloth_Block_Wool_Red"
    },
    {
      "x": 11,
      "y": 15,
      "z": -13,
      "name": "Cloth_Block_Wool_White"
    },
    {
      "x": 11,
      "y": 35,
      "z": -13,
      "name": "Cloth_Block_Wool_White"
    },
    {
      "x": 11,
      "y": 36,
      "z": -13,
      "name": "Wood_Hardwood_Planks"
    },
    {
      "x": 11,
      "y": 4,
      "z": -12,
      "name": "Wood_Hardwood_Beam"
    },
    {
      "x": 11,
      "y": 5,
      "z": -12,
      "name": "Wood_Hardwood_Stairs",
      "rotation": 2
    },
    {
      "x": 11,
      "y": 9,
      "z": -12,
      "name": "Wood_Hardwood_Planks"
    },
    {
      "x": 11,
      "y": 10,
      "z": -12,
      "name": "Cloth_Block_Wool_Red"
    },
    {
      "x": 11,
      "y": 11,
      "z": -12,
      "name": "Cloth_Block_Wool_Red"
    },
    {
      "x": 11,
      "y": 12,
      "z": -12,
      "name": "Cloth_Block_Wool_Red"
    },
    {
      "x": 11,
      "y": 15,
      "z": -12,
      "name": "Cloth_Block_Wool_Red"
    },
    {
      "x": 11,
      "y": 35,
      "z": -12,
      "name": "Cloth_Block_Wool_Red"
    },
    {
      "x": 11,
      "y": 3,
      "z": -11,
      "name": "Furniture_Village_Crate"
    },
    {
      "x": 11,
      "y": 4,
      "z": -11,
      "name": "Deco_Rope"
    },
    {
      "x": 11,
      "y": 5,
      "z": -11,
      "name": "*Wood_Hardwood_Planks_Half_State_Definitions_Block",
      "rotation": 8
    },
    {
      "x": 11,
      "y": 6,
      "z": -11,
      "name": "Rock_Calcite_Brick_Beam"
    },
    {
      "x": 11,
      "y": 7,
      "z": -11,
      "name": "Wood_Hardwood_Beam"
    },
    {
      "x": 11,
      "y": 8,
      "z": -11,
      "name": "Wood_Hardwood_Beam"
    },
    {
      "x": 11,
      "y": 9,
      "z": -11,
      "name": "Wood_Hardwood_Beam"
    },
    {
      "x": 11,
      "y": 10,
      "z": -11,
      "name": "Wood_Hardwood_Beam"
    },
    {
      "x": 11,
      "y": 11,
      "z": -11,
      "name": "Wood_Hardwood_Beam"
    },
    {
      "x": 11,
      "y": 12,
      "z": -11,
      "name": "Cloth_Block_Wool_Red"
    },
    {
      "x": 11,
      "y": 13,
      "z": -11,
      "name": "Cloth_Block_Wool_Red"
    },
    {
      "x": 11,
      "y": 14,
      "z": -11,
      "name": "Cloth_Block_Wool_Red"
    },
    {
      "x": 11,
      "y": 15,
      "z": -11,
      "name": "Cloth_Block_Wool_White"
    },
    {
      "x": 11,
      "y": 35,
      "z": -11,
      "name": "Cloth_Block_Wool_White"
    },
    {
      "x": 11,
      "y": 36,
      "z": -11,
      "name": "Wood_Hardwood_Planks"
    },
    {
      "x": 11,
      "y": 5,
      "z": -10,
      "name": "Wood_Hardwood_Planks_Half",
      "rotation": 4
    },
    {
      "x": 11,
      "y": 14,
      "z": -10,
      "name": "Cloth_Block_Wool_Red"
    },
    {
      "x": 11,
      "y": 15,
      "z": -10,
      "name": "Cloth_Block_Wool_Red"
    },
    {
      "x": 11,
      "y": 16,
      "z": -10,
      "name": "Cloth_Block_Wool_White"
    },
    {
      "x": 11,
      "y": 34,
      "z": -10,
      "name": "Cloth_Block_Wool_White"
    },
    {
      "x": 11,
      "y": 14,
      "z": -9,
      "name": "Wood_Hardwood_Planks"
    },
    {
      "x": 11,
      "y": 15,
      "z": -9,
      "name": "Cloth_Block_Wool_Red"
    },
    {
      "x": 11,
      "y": 16,
      "z": -9,
      "name": "Cloth_Block_Wool_Red"
    },
    {
      "x": 11,
      "y": 34,
      "z": -9,
      "name": "Cloth_Block_Wool_Red"
    },
    {
      "x": 11,
      "y": 16,
      "z": -8,
      "name": "Cloth_Block_Wool_Red"
    },
    {
      "x": 11,
      "y": 34,
      "z": -8,
      "name": "Cloth_Block_Wool_Red"
    },
    {
      "x": 11,
      "y": 16,
      "z": -7,
      "name": "Wood_Hardwood_Planks"
    },
    {
      "x": 11,
      "y": 17,
      "z": -7,
      "name": "Cloth_Block_Wool_Red"
    },
    {
      "x": 11,
      "y": 33,
      "z": -7,
      "name": "Cloth_Block_Wool_Red"
    },
    {
      "x": 11,
      "y": 18,
      "z": -6,
      "name": "Cloth_Block_Wool_Red"
    },
    {
      "x": 11,
      "y": 32,
      "z": -6,
      "name": "Cloth_Block_Wool_Red"
    },
    {
      "x": 11,
      "y": 19,
      "z": -5,
      "name": "Cloth_Block_Wool_Red"
    },
    {
      "x": 11,
      "y": 31,
      "z": -5,
      "name": "Cloth_Block_Wool_Red"
    },
    {
      "x": 11,
      "y": 20,
      "z": -4,
      "name": "Cloth_Block_Wool_Red"
    },
    {
      "x": 11,
      "y": 21,
      "z": -4,
      "name": "Cloth_Block_Wool_Red"
    },
    {
      "x": 11,
      "y": 22,
      "z": -4,
      "name": "Cloth_Block_Wool_Red"
    },
    {
      "x": 11,
      "y": 28,
      "z": -4,
      "name": "Cloth_Block_Wool_Red"
    },
    {
      "x": 11,
      "y": 29,
      "z": -4,
      "name": "Cloth_Block_Wool_Red"
    },
    {
      "x": 11,
      "y": 30,
      "z": -4,
      "name": "Cloth_Block_Wool_Red"
    },
    {
      "x": 11,
      "y": 23,
      "z": -3,
      "name": "Cloth_Block_Wool_Red"
    },
    {
      "x": 11,
      "y": 24,
      "z": -3,
      "name": "Cloth_Block_Wool_Red"
    },
    {
      "x": 11,
      "y": 25,
      "z": -3,
      "name": "Cloth_Block_Wool_Red"
    },
    {
      "x": 11,
      "y": 26,
      "z": -3,
      "name": "Cloth_Block_Wool_Red"
    },
    {
      "x": 11,
      "y": 27,
      "z": -3,
      "name": "Cloth_Block_Wool_Red"
    },
    {
      "x": 11,
      "y": 25,
      "z": -2,
      "name": "Wood_Hardwood_Planks"
    },
    {
      "x": 12,
      "y": 25,
      "z": -25,
      "name": "*Furniture_Crude_Trapdoor_State_Definitions_OpenDoorOut",
      "rotation": 2
    },
    {
      "x": 12,
      "y": 24,
      "z": -24,
      "name": "Wood_Hardwood_Stairs",
      "rotation": 9
    },
    {
      "x": 12,
      "y": 25,
      "z": -24,
      "name": "Wood_Hardwood_Planks"
    },
    {
      "x": 12,
      "y": 26,
      "z": -24,
      "name": "Wood_Hardwood_Stairs",
      "rotation": 3
    },
    {
      "x": 12,
      "y": 22,
      "z": -23,
      "name": "Cloth_Block_Wool_White"
    },
    {
      "x": 12,
      "y": 23,
      "z": -23,
      "name": "Cloth_Block_Wool_White"
    },
    {
      "x": 12,
      "y": 24,
      "z": -23,
      "name": "Cloth_Block_Wool_White"
    },
    {
      "x": 12,
      "y": 25,
      "z": -23,
      "name": "Cloth_Block_Wool_White"
    },
    {
      "x": 12,
      "y": 26,
      "z": -23,
      "name": "Cloth_Block_Wool_White"
    },
    {
      "x": 12,
      "y": 27,
      "z": -23,
      "name": "Cloth_Block_Wool_White"
    },
    {
      "x": 12,
      "y": 28,
      "z": -23,
      "name": "Cloth_Block_Wool_White"
    },
    {
      "x": 12,
      "y": 20,
      "z": -22,
      "name": "Cloth_Block_Wool_White"
    },
    {
      "x": 12,
      "y": 21,
      "z": -22,
      "name": "Cloth_Block_Wool_White"
    },
    {
      "x": 12,
      "y": 29,
      "z": -22,
      "name": "Cloth_Block_Wool_White"
    },
    {
      "x": 12,
      "y": 30,
      "z": -22,
      "name": "Cloth_Block_Wool_White"
    },
    {
      "x": 12,
      "y": 19,
      "z": -21,
      "name": "Cloth_Block_Wool_White"
    },
    {
      "x": 12,
      "y": 31,
      "z": -21,
      "name": "Cloth_Block_Wool_White"
    },
    {
      "x": 12,
      "y": 18,
      "z": -20,
      "name": "Cloth_Block_Wool_White"
    },
    {
      "x": 12,
      "y": 32,
      "z": -20,
      "name": "Cloth_Block_Wool_White"
    },
    {
      "x": 12,
      "y": 16,
      "z": -19,
      "name": "Wood_Hardwood_Planks"
    },
    {
      "x": 12,
      "y": 17,
      "z": -19,
      "name": "Cloth_Block_Wool_White"
    },
    {
      "x": 12,
      "y": 33,
      "z": -19,
      "name": "Cloth_Block_Wool_White"
    },
    {
      "x": 12,
      "y": 14,
      "z": -18,
      "name": "Wood_Hardwood_Planks"
    },
    {
      "x": 12,
      "y": 15,
      "z": -18,
      "name": "Cloth_Block_Wool_Red"
    },
    {
      "x": 12,
      "y": 16,
      "z": -18,
      "name": "Cloth_Block_Wool_White"
    },
    {
      "x": 12,
      "y": 34,
      "z": -18,
      "name": "Cloth_Block_Wool_White"
    },
    {
      "x": 12,
      "y": 14,
      "z": -17,
      "name": "Cloth_Block_Wool_Red"
    },
    {
      "x": 12,
      "y": 15,
      "z": -17,
      "name": "Cloth_Block_Wool_Red"
    },
    {
      "x": 12,
      "y": 16,
      "z": -17,
      "name": "Cloth_Block_Wool_White"
    },
    {
      "x": 12,
      "y": 34,
      "z": -17,
      "name": "Cloth_Block_Wool_White"
    },
    {
      "x": 12,
      "y": 9,
      "z": -16,
      "name": "Wood_Hardwood_Planks_Half",
      "rotation": 6
    },
    {
      "x": 12,
      "y": 12,
      "z": -16,
      "name": "Cloth_Block_Wool_Red"
    },
    {
      "x": 12,
      "y": 13,
      "z": -16,
      "name": "Cloth_Block_Wool_Red"
    },
    {
      "x": 12,
      "y": 14,
      "z": -16,
      "name": "Cloth_Block_Wool_Red"
    },
    {
      "x": 12,
      "y": 15,
      "z": -16,
      "name": "Cloth_Block_Wool_White"
    },
    {
      "x": 12,
      "y": 35,
      "z": -16,
      "name": "Cloth_Block_Wool_White"
    },
    {
      "x": 12,
      "y": 4,
      "z": -15,
      "name": "Wood_Hardwood_Beam",
      "rotation": 1
    },
    {
      "x": 12,
      "y": 5,
      "z": -15,
      "name": "Wood_Hardwood_Stairs",
      "rotation": 1
    },
    {
      "x": 12,
      "y": 9,
      "z": -15,
      "name": "*Wood_Hardwood_Planks_Half_State_Definitions_Block",
      "rotation": 6
    },
    {
      "x": 12,
      "y": 10,
      "z": -15,
      "name": "Cloth_Block_Wool_Red"
    },
    {
      "x": 12,
      "y": 11,
      "z": -15,
      "name": "Cloth_Block_Wool_Red"
    },
    {
      "x": 12,
      "y": 12,
      "z": -15,
      "name": "Cloth_Block_Wool_Red"
    },
    {
      "x": 12,
      "y": 15,
      "z": -15,
      "name": "Cloth_Block_Wool_Red"
    },
    {
      "x": 12,
      "y": 35,
      "z": -15,
      "name": "Cloth_Block_Wool_Red"
    },
    {
      "x": 12,
      "y": 4,
      "z": -14,
      "name": "Wood_Hardwood_Planks"
    },
    {
      "x": 12,
      "y": 5,
      "z": -14,
      "name": "Furniture_Village_Crate"
    },
    {
      "x": 12,
      "y": 9,
      "z": -14,
      "name": "Wood_Hardwood_Planks"
    },
    {
      "x": 12,
      "y": 15,
      "z": -14,
      "name": "Cloth_Block_Wool_Red"
    },
    {
      "x": 12,
      "y": 35,
      "z": -14,
      "name": "Cloth_Block_Wool_Red"
    },
    {
      "x": 12,
      "y": 36,
      "z": -14,
      "name": "Wood_Hardwood_Planks"
    },
    {
      "x": 12,
      "y": 2,
      "z": -13,
      "name": "Rock_Calcite_Brick_Smooth_Half",
      "rotation": 7
    },
    {
      "x": 12,
      "y": 3,
      "z": -13,
      "name": "Rock_Calcite_Brick_Smooth"
    },
    {
      "x": 12,
      "y": 4,
      "z": -13,
      "name": "Wood_Hardwood_Planks_Half"
    },
    {
      "x": 12,
      "y": 9,
      "z": -13,
      "name": "Wood_Hardwood_Planks_Half",
      "rotation": 8
    },
    {
      "x": 12,
      "y": 15,
      "z": -13,
      "name": "Cloth_Block_Wool_Red"
    },
    {
      "x": 12,
      "y": 35,
      "z": -13,
      "name": "Cloth_Block_Wool_Red"
    },
    {
      "x": 12,
      "y": 36,
      "z": -13,
      "name": "Wood_Hardwood_Planks"
    },
    {
      "x": 12,
      "y": 37,
      "z": -13,
      "name": "Wood_Hardwood_Planks_Half"
    },
    {
      "x": 12,
      "y": 4,
      "z": -12,
      "name": "Wood_Hardwood_Planks"
    },
    {
      "x": 12,
      "y": 9,
      "z": -12,
      "name": "Wood_Hardwood_Planks"
    },
    {
      "x": 12,
      "y": 15,
      "z": -12,
      "name": "Cloth_Block_Wool_Red"
    },
    {
      "x": 12,
      "y": 35,
      "z": -12,
      "name": "Cloth_Block_Wool_Red"
    },
    {
      "x": 12,
      "y": 36,
      "z": -12,
      "name": "Wood_Hardwood_Planks"
    },
    {
      "x": 12,
      "y": 4,
      "z": -11,
      "name": "Wood_Hardwood_Beam",
      "rotation": 1
    },
    {
      "x": 12,
      "y": 5,
      "z": -11,
      "name": "Wood_Hardwood_Stairs",
      "rotation": 1
    },
    {
      "x": 12,
      "y": 9,
      "z": -11,
      "name": "Wood_Hardwood_Planks"
    },
    {
      "x": 12,
      "y": 10,
      "z": -11,
      "name": "Cloth_Block_Wool_Red"
    },
    {
      "x": 12,
      "y": 11,
      "z": -11,
      "name": "Cloth_Block_Wool_Red"
    },
    {
      "x": 12,
      "y": 12,
      "z": -11,
      "name": "Cloth_Block_Wool_Red"
    },
    {
      "x": 12,
      "y": 15,
      "z": -11,
      "name": "Cloth_Block_Wool_Red"
    },
    {
      "x": 12,
      "y": 35,
      "z": -11,
      "name": "Cloth_Block_Wool_Red"
    },
    {
      "x": 12,
      "y": 9,
      "z": -10,
      "name": "Wood_Hardwood_Planks_Half",
      "rotation": 4
    },
    {
      "x": 12,
      "y": 12,
      "z": -10,
      "name": "Cloth_Block_Wool_Red"
    },
    {
      "x": 12,
      "y": 13,
      "z": -10,
      "name": "Cloth_Block_Wool_Red"
    },
    {
      "x": 12,
      "y": 14,
      "z": -10,
      "name": "Cloth_Block_Wool_Red"
    },
    {
      "x": 12,
      "y": 15,
      "z": -10,
      "name": "Cloth_Block_Wool_White"
    },
    {
      "x": 12,
      "y": 35,
      "z": -10,
      "name": "Cloth_Block_Wool_White"
    },
    {
      "x": 12,
      "y": 14,
      "z": -9,
      "name": "Cloth_Block_Wool_Red"
    },
    {
      "x": 12,
      "y": 15,
      "z": -9,
      "name": "Cloth_Block_Wool_Red"
    },
    {
      "x": 12,
      "y": 16,
      "z": -9,
      "name": "Cloth_Block_Wool_White"
    },
    {
      "x": 12,
      "y": 34,
      "z": -9,
      "name": "Cloth_Block_Wool_White"
    },
    {
      "x": 12,
      "y": 14,
      "z": -8,
      "name": "Wood_Hardwood_Planks"
    },
    {
      "x": 12,
      "y": 15,
      "z": -8,
      "name": "Cloth_Block_Wool_Red"
    },
    {
      "x": 12,
      "y": 16,
      "z": -8,
      "name": "Cloth_Block_Wool_White"
    },
    {
      "x": 12,
      "y": 34,
      "z": -8,
      "name": "Cloth_Block_Wool_White"
    },
    {
      "x": 12,
      "y": 16,
      "z": -7,
      "name": "Wood_Hardwood_Planks"
    },
    {
      "x": 12,
      "y": 17,
      "z": -7,
      "name": "Cloth_Block_Wool_White"
    },
    {
      "x": 12,
      "y": 33,
      "z": -7,
      "name": "Cloth_Block_Wool_White"
    },
    {
      "x": 12,
      "y": 18,
      "z": -6,
      "name": "Cloth_Block_Wool_White"
    },
    {
      "x": 12,
      "y": 32,
      "z": -6,
      "name": "Cloth_Block_Wool_White"
    },
    {
      "x": 12,
      "y": 19,
      "z": -5,
      "name": "Cloth_Block_Wool_White"
    },
    {
      "x": 12,
      "y": 31,
      "z": -5,
      "name": "Cloth_Block_Wool_White"
    },
    {
      "x": 12,
      "y": 20,
      "z": -4,
      "name": "Cloth_Block_Wool_White"
    },
    {
      "x": 12,
      "y": 21,
      "z": -4,
      "name": "Cloth_Block_Wool_White"
    },
    {
      "x": 12,
      "y": 29,
      "z": -4,
      "name": "Cloth_Block_Wool_White"
    },
    {
      "x": 12,
      "y": 30,
      "z": -4,
      "name": "Cloth_Block_Wool_White"
    },
    {
      "x": 12,
      "y": 22,
      "z": -3,
      "name": "Cloth_Block_Wool_White"
    },
    {
      "x": 12,
      "y": 23,
      "z": -3,
      "name": "Cloth_Block_Wool_White"
    },
    {
      "x": 12,
      "y": 24,
      "z": -3,
      "name": "Cloth_Block_Wool_White"
    },
    {
      "x": 12,
      "y": 25,
      "z": -3,
      "name": "Cloth_Block_Wool_White"
    },
    {
      "x": 12,
      "y": 26,
      "z": -3,
      "name": "Cloth_Block_Wool_White"
    },
    {
      "x": 12,
      "y": 27,
      "z": -3,
      "name": "Cloth_Block_Wool_White"
    },
    {
      "x": 12,
      "y": 28,
      "z": -3,
      "name": "Cloth_Block_Wool_White"
    },
    {
      "x": 12,
      "y": 24,
      "z": -2,
      "name": "Wood_Hardwood_Stairs",
      "rotation": 9
    },
    {
      "x": 12,
      "y": 25,
      "z": -2,
      "name": "Wood_Hardwood_Planks"
    },
    {
      "x": 12,
      "y": 26,
      "z": -2,
      "name": "Wood_Hardwood_Stairs",
      "rotation": 3
    },
    {
      "x": 12,
      "y": 25,
      "z": -1,
      "name": "*Furniture_Crude_Trapdoor_State_Definitions_OpenDoorOut"
    },
    {
      "x": 13,
      "y": 24,
      "z": -25,
      "name": "*Furniture_Crude_Trapdoor_State_Definitions_OpenDoorOut",
      "rotation": 2
    },
    {
      "x": 13,
      "y": 25,
      "z": -25,
      "name": "Rock_Calcite_Brick_Smooth_Half",
      "rotation": 6
    },
    {
      "x": 13,
      "y": 26,
      "z": -25,
      "name": "*Furniture_Crude_Trapdoor_State_Definitions_OpenDoorOut",
      "rotation": 2
    },
    {
      "x": 13,
      "y": 21,
      "z": -24,
      "name": "Wood_Hardwood_Beam",
      "rotation": 1
    },
    {
      "x": 13,
      "y": 22,
      "z": -24,
      "name": "Wood_Hardwood_Planks"
    },
    {
      "x": 13,
      "y": 23,
      "z": -24,
      "name": "Wood_Hardwood_Planks"
    },
    {
      "x": 13,
      "y": 24,
      "z": -24,
      "name": "Wood_Hardwood_Planks"
    },
    {
      "x": 13,
      "y": 26,
      "z": -24,
      "name": "Wood_Hardwood_Planks"
    },
    {
      "x": 13,
      "y": 27,
      "z": -24,
      "name": "Wood_Hardwood_Planks"
    },
    {
      "x": 13,
      "y": 28,
      "z": -24,
      "name": "Wood_Hardwood_Planks"
    },
    {
      "x": 13,
      "y": 29,
      "z": -24,
      "name": "Wood_Hardwood_Beam",
      "rotation": 1
    },
    {
      "x": 13,
      "y": 19,
      "z": -23,
      "name": "Wood_Hardwood_Beam",
      "rotation": 1
    },
    {
      "x": 13,
      "y": 20,
      "z": -23,
      "name": "Wood_Hardwood_Planks"
    },
    {
      "x": 13,
      "y": 21,
      "z": -23,
      "name": "Wood_Hardwood_Planks"
    },
    {
      "x": 13,
      "y": 22,
      "z": -23,
      "name": "Cloth_Block_Wool_White"
    },
    {
      "x": 13,
      "y": 23,
      "z": -23,
      "name": "Cloth_Block_Wool_White"
    },
    {
      "x": 13,
      "y": 24,
      "z": -23,
      "name": "Cloth_Block_Wool_White"
    },
    {
      "x": 13,
      "y": 26,
      "z": -23,
      "name": "Cloth_Block_Wool_White"
    },
    {
      "x": 13,
      "y": 27,
      "z": -23,
      "name": "Cloth_Block_Wool_White"
    },
    {
      "x": 13,
      "y": 28,
      "z": -23,
      "name": "Cloth_Block_Wool_White"
    },
    {
      "x": 13,
      "y": 29,
      "z": -23,
      "name": "Wood_Hardwood_Planks"
    },
    {
      "x": 13,
      "y": 30,
      "z": -23,
      "name": "Wood_Hardwood_Planks"
    },
    {
      "x": 13,
      "y": 31,
      "z": -23,
      "name": "Wood_Hardwood_Beam",
      "rotation": 1
    },
    {
      "x": 13,
      "y": 18,
      "z": -22,
      "name": "Wood_Hardwood_Beam",
      "rotation": 1
    },
    {
      "x": 13,
      "y": 19,
      "z": -22,
      "name": "Wood_Hardwood_Planks"
    },
    {
      "x": 13,
      "y": 20,
      "z": -22,
      "name": "Cloth_Block_Wool_White"
    },
    {
      "x": 13,
      "y": 21,
      "z": -22,
      "name": "Cloth_Block_Wool_White"
    },
    {
      "x": 13,
      "y": 29,
      "z": -22,
      "name": "Cloth_Block_Wool_White"
    },
    {
      "x": 13,
      "y": 30,
      "z": -22,
      "name": "Cloth_Block_Wool_White"
    },
    {
      "x": 13,
      "y": 31,
      "z": -22,
      "name": "Wood_Hardwood_Planks"
    },
    {
      "x": 13,
      "y": 32,
      "z": -22,
      "name": "Wood_Hardwood_Beam",
      "rotation": 1
    },
    {
      "x": 13,
      "y": 17,
      "z": -21,
      "name": "Wood_Hardwood_Beam",
      "rotation": 1
    },
    {
      "x": 13,
      "y": 18,
      "z": -21,
      "name": "Wood_Hardwood_Planks"
    },
    {
      "x": 13,
      "y": 19,
      "z": -21,
      "name": "Cloth_Block_Wool_White"
    },
    {
      "x": 13,
      "y": 31,
      "z": -21,
      "name": "Cloth_Block_Wool_White"
    },
    {
      "x": 13,
      "y": 32,
      "z": -21,
      "name": "Wood_Hardwood_Planks"
    },
    {
      "x": 13,
      "y": 33,
      "z": -21,
      "name": "Wood_Hardwood_Beam",
      "rotation": 1
    },
    {
      "x": 13,
      "y": 16,
      "z": -20,
      "name": "Wood_Hardwood_Beam",
      "rotation": 1
    },
    {
      "x": 13,
      "y": 17,
      "z": -20,
      "name": "Wood_Hardwood_Planks"
    },
    {
      "x": 13,
      "y": 18,
      "z": -20,
      "name": "Cloth_Block_Wool_White"
    },
    {
      "x": 13,
      "y": 32,
      "z": -20,
      "name": "Cloth_Block_Wool_White"
    },
    {
      "x": 13,
      "y": 33,
      "z": -20,
      "name": "Wood_Hardwood_Planks"
    },
    {
      "x": 13,
      "y": 34,
      "z": -20,
      "name": "Wood_Hardwood_Beam",
      "rotation": 1
    },
    {
      "x": 13,
      "y": 14,
      "z": -19,
      "name": "Wood_Hardwood_Beam",
      "rotation": 1
    },
    {
      "x": 13,
      "y": 15,
      "z": -19,
      "name": "Wood_Hardwood_Planks"
    },
    {
      "x": 13,
      "y": 16,
      "z": -19,
      "name": "Wood_Hardwood_Planks"
    },
    {
      "x": 13,
      "y": 17,
      "z": -19,
      "name": "Cloth_Block_Wool_White"
    },
    {
      "x": 13,
      "y": 33,
      "z": -19,
      "name": "Cloth_Block_Wool_White"
    },
    {
      "x": 13,
      "y": 34,
      "z": -19,
      "name": "Wood_Hardwood_Planks"
    },
    {
      "x": 13,
      "y": 35,
      "z": -19,
      "name": "Wood_Hardwood_Beam",
      "rotation": 1
    },
    {
      "x": 13,
      "y": 13,
      "z": -18,
      "name": "Wood_Hardwood_Beam",
      "rotation": 1
    },
    {
      "x": 13,
      "y": 14,
      "z": -18,
      "name": "Wood_Hardwood_Planks"
    },
    {
      "x": 13,
      "y": 15,
      "z": -18,
      "name": "Cloth_Block_Wool_Red"
    },
    {
      "x": 13,
      "y": 16,
      "z": -18,
      "name": "Cloth_Block_Wool_White"
    },
    {
      "x": 13,
      "y": 34,
      "z": -18,
      "name": "Cloth_Block_Wool_White"
    },
    {
      "x": 13,
      "y": 35,
      "z": -18,
      "name": "Wood_Hardwood_Planks"
    },
    {
      "x": 13,
      "y": 5,
      "z": -17,
      "name": "Furniture_Crude_Platform"
    },
    {
      "x": 13,
      "y": 11,
      "z": -17,
      "name": "Wood_Hardwood_Beam"
    },
    {
      "x": 13,
      "y": 12,
      "z": -17,
      "name": "Wood_Hardwood_Beam"
    },
    {
      "x": 13,
      "y": 13,
      "z": -17,
      "name": "Cloth_Block_Wool_Red"
    },
    {
      "x": 13,
      "y": 14,
      "z": -17,
      "name": "Cloth_Block_Wool_Red"
    },
    {
      "x": 13,
      "y": 15,
      "z": -17,
      "name": "Cloth_Block_Wool_Red"
    },
    {
      "x": 13,
      "y": 16,
      "z": -17,
      "name": "Cloth_Block_Wool_White"
    },
    {
      "x": 13,
      "y": 34,
      "z": -17,
      "name": "Cloth_Block_Wool_White"
    },
    {
      "x": 13,
      "y": 35,
      "z": -17,
      "name": "Wood_Hardwood_Planks"
    },
    {
      "x": 13,
      "y": 36,
      "z": -17,
      "name": "Wood_Hardwood_Beam",
      "rotation": 1
    },
    {
      "x": 13,
      "y": 5,
      "z": -16,
      "name": "Furniture_Crude_Platform"
    },
    {
      "x": 13,
      "y": 9,
      "z": -16,
      "name": "Wood_Hardwood_Planks_Half",
      "rotation": 6
    },
    {
      "x": 13,
      "y": 10,
      "z": -16,
      "name": "Wood_Hardwood_Planks_Half",
      "rotation": 6
    },
    {
      "x": 13,
      "y": 11,
      "z": -16,
      "name": "Wood_Hardwood_Planks_Half",
      "rotation": 6
    },
    {
      "x": 13,
      "y": 12,
      "z": -16,
      "name": "Cloth_Block_Wool_Red"
    },
    {
      "x": 13,
      "y": 13,
      "z": -16,
      "name": "Cloth_Block_Wool_Red"
    },
    {
      "x": 13,
      "y": 14,
      "z": -16,
      "name": "Cloth_Block_Wool_Red"
    },
    {
      "x": 13,
      "y": 15,
      "z": -16,
      "name": "Cloth_Block_Wool_White"
    },
    {
      "x": 13,
      "y": 35,
      "z": -16,
      "name": "Cloth_Block_Wool_White"
    },
    {
      "x": 13,
      "y": 36,
      "z": -16,
      "name": "Wood_Hardwood_Planks"
    },
    {
      "x": 13,
      "y": 4,
      "z": -15,
      "name": "Wood_Hardwood_Stairs",
      "rotation": 8
    },
    {
      "x": 13,
      "y": 5,
      "z": -15,
      "name": "Wood_Hardwood_Planks"
    },
    {
      "x": 13,
      "y": 9,
      "z": -15,
      "name": "Wood_Hardwood_Planks"
    },
    {
      "x": 13,
      "y": 10,
      "z": -15,
      "name": "Cloth_Block_Wool_Red"
    },
    {
      "x": 13,
      "y": 11,
      "z": -15,
      "name": "Cloth_Block_Wool_Red"
    },
    {
      "x": 13,
      "y": 12,
      "z": -15,
      "name": "Cloth_Block_Wool_Red"
    },
    {
      "x": 13,
      "y": 15,
      "z": -15,
      "name": "Cloth_Block_Wool_White"
    },
    {
      "x": 13,
      "y": 35,
      "z": -15,
      "name": "Cloth_Block_Wool_White"
    },
    {
      "x": 13,
      "y": 36,
      "z": -15,
      "name": "Wood_Hardwood_Planks"
    },
    {
      "x": 13,
      "y": 2,
      "z": -14,
      "name": "Rock_Calcite_Brick_Smooth_Half",
      "rotation": 6
    },
    {
      "x": 13,
      "y": 3,
      "z": -14,
      "name": "Rock_Calcite_Brick_Smooth"
    },
    {
      "x": 13,
      "y": 4,
      "z": -14,
      "name": "Wood_Hardwood_Planks_Half"
    },
    {
      "x": 13,
      "y": 9,
      "z": -14,
      "name": "Wood_Hardwood_Planks_Half",
      "rotation": 8
    },
    {
      "x": 13,
      "y": 15,
      "z": -14,
      "name": "Cloth_Block_Wool_Red"
    },
    {
      "x": 13,
      "y": 35,
      "z": -14,
      "name": "Cloth_Block_Wool_Red"
    },
    {
      "x": 13,
      "y": 36,
      "z": -14,
      "name": "Wood_Hardwood_Planks"
    },
    {
      "x": 13,
      "y": 37,
      "z": -14,
      "name": "Wood_Hardwood_Planks_Half"
    },
    {
      "x": 13,
      "y": 1,
      "z": -13,
      "name": "Rock_Calcite_Brick_Smooth"
    },
    {
      "x": 13,
      "y": 2,
      "z": -13,
      "name": "Rock_Calcite_Brick_Smooth"
    },
    {
      "x": 13,
      "y": 3,
      "z": -13,
      "name": "Rock_Calcite_Brick_Smooth"
    },
    {
      "x": 13,
      "y": 7,
      "z": -13,
      "name": "Deco_Iron_Chain_Small"
    },
    {
      "x": 13,
      "y": 8,
      "z": -13,
      "name": "*Rock_Calcite_Brick_Smooth_Half_State_Definitions_Block",
      "rotation": 8
    },
    {
      "x": 13,
      "y": 9,
      "z": -13,
      "name": "*Rock_Calcite_Brick_Smooth_Half_State_Definitions_Block",
      "rotation": 8
    },
    {
      "x": 13,
      "y": 10,
      "z": -13,
      "name": "Furniture_Crude_Brazier"
    },
    {
      "x": 13,
      "y": 11,
      "z": -13,
      "name": "Deco_Iron_Chain_Small",
      "rotation": 2
    },
    {
      "x": 13,
      "y": 12,
      "z": -13,
      "name": "Deco_Iron_Chain_Small",
      "rotation": 2
    },
    {
      "x": 13,
      "y": 13,
      "z": -13,
      "name": "Deco_Iron_Chain_Small",
      "rotation": 2
    },
    {
      "x": 13,
      "y": 14,
      "z": -13,
      "name": "Deco_Iron_Chain_Small",
      "rotation": 2
    },
    {
      "x": 13,
      "y": 15,
      "z": -13,
      "name": "Cloth_Block_Wool_Red"
    },
    {
      "x": 13,
      "y": 35,
      "z": -13,
      "name": "Cloth_Block_Wool_Red"
    },
    {
      "x": 13,
      "y": 36,
      "z": -13,
      "name": "Wood_Hardwood_Planks"
    },
    {
      "x": 13,
      "y": 37,
      "z": -13,
      "name": "Wood_Hardwood_Planks"
    },
    {
      "x": 13,
      "y": 2,
      "z": -12,
      "name": "Rock_Calcite_Brick_Smooth_Half",
      "rotation": 4
    },
    {
      "x": 13,
      "y": 3,
      "z": -12,
      "name": "Rock_Calcite_Brick_Smooth"
    },
    {
      "x": 13,
      "y": 4,
      "z": -12,
      "name": "Wood_Hardwood_Planks_Half"
    },
    {
      "x": 13,
      "y": 9,
      "z": -12,
      "name": "Wood_Hardwood_Planks_Half",
      "rotation": 8
    },
    {
      "x": 13,
      "y": 15,
      "z": -12,
      "name": "Cloth_Block_Wool_Red"
    },
    {
      "x": 13,
      "y": 35,
      "z": -12,
      "name": "Cloth_Block_Wool_Red"
    },
    {
      "x": 13,
      "y": 36,
      "z": -12,
      "name": "Wood_Hardwood_Planks"
    },
    {
      "x": 13,
      "y": 37,
      "z": -12,
      "name": "Wood_Hardwood_Planks_Half"
    },
    {
      "x": 13,
      "y": 4,
      "z": -11,
      "name": "Wood_Hardwood_Stairs",
      "rotation": 10
    },
    {
      "x": 13,
      "y": 5,
      "z": -11,
      "name": "Wood_Hardwood_Planks"
    },
    {
      "x": 13,
      "y": 9,
      "z": -11,
      "name": "Wood_Hardwood_Planks"
    },
    {
      "x": 13,
      "y": 10,
      "z": -11,
      "name": "Cloth_Block_Wool_Red"
    },
    {
      "x": 13,
      "y": 11,
      "z": -11,
      "name": "Cloth_Block_Wool_Red"
    },
    {
      "x": 13,
      "y": 12,
      "z": -11,
      "name": "Cloth_Block_Wool_Red"
    },
    {
      "x": 13,
      "y": 15,
      "z": -11,
      "name": "Cloth_Block_Wool_White"
    },
    {
      "x": 13,
      "y": 35,
      "z": -11,
      "name": "Cloth_Block_Wool_White"
    },
    {
      "x": 13,
      "y": 36,
      "z": -11,
      "name": "Wood_Hardwood_Planks"
    },
    {
      "x": 13,
      "y": 5,
      "z": -10,
      "name": "*Furniture_Crude_Trapdoor_State_Definitions_OpenDoorOut"
    },
    {
      "x": 13,
      "y": 9,
      "z": -10,
      "name": "Wood_Hardwood_Planks_Half",
      "rotation": 4
    },
    {
      "x": 13,
      "y": 10,
      "z": -10,
      "name": "Wood_Hardwood_Planks_Half",
      "rotation": 4
    },
    {
      "x": 13,
      "y": 11,
      "z": -10,
      "name": "Wood_Hardwood_Planks_Half",
      "rotation": 4
    },
    {
      "x": 13,
      "y": 12,
      "z": -10,
      "name": "Cloth_Block_Wool_Red"
    },
    {
      "x": 13,
      "y": 13,
      "z": -10,
      "name": "Cloth_Block_Wool_Red"
    },
    {
      "x": 13,
      "y": 14,
      "z": -10,
      "name": "Cloth_Block_Wool_Red"
    },
    {
      "x": 13,
      "y": 15,
      "z": -10,
      "name": "Cloth_Block_Wool_White"
    },
    {
      "x": 13,
      "y": 35,
      "z": -10,
      "name": "Cloth_Block_Wool_White"
    },
    {
      "x": 13,
      "y": 36,
      "z": -10,
      "name": "Wood_Hardwood_Planks"
    },
    {
      "x": 13,
      "y": 11,
      "z": -9,
      "name": "Wood_Hardwood_Beam"
    },
    {
      "x": 13,
      "y": 12,
      "z": -9,
      "name": "Wood_Hardwood_Beam"
    },
    {
      "x": 13,
      "y": 13,
      "z": -9,
      "name": "Cloth_Block_Wool_Red"
    },
    {
      "x": 13,
      "y": 14,
      "z": -9,
      "name": "Cloth_Block_Wool_Red"
    },
    {
      "x": 13,
      "y": 15,
      "z": -9,
      "name": "Cloth_Block_Wool_Red"
    },
    {
      "x": 13,
      "y": 16,
      "z": -9,
      "name": "Cloth_Block_Wool_White"
    },
    {
      "x": 13,
      "y": 34,
      "z": -9,
      "name": "Cloth_Block_Wool_White"
    },
    {
      "x": 13,
      "y": 35,
      "z": -9,
      "name": "Wood_Hardwood_Planks"
    },
    {
      "x": 13,
      "y": 36,
      "z": -9,
      "name": "Wood_Hardwood_Beam",
      "rotation": 1
    },
    {
      "x": 13,
      "y": 12,
      "z": -8,
      "name": "Wood_Hardwood_Beam"
    },
    {
      "x": 13,
      "y": 13,
      "z": -8,
      "name": "Wood_Hardwood_Beam",
      "rotation": 1
    },
    {
      "x": 13,
      "y": 14,
      "z": -8,
      "name": "Wood_Hardwood_Planks"
    },
    {
      "x": 13,
      "y": 15,
      "z": -8,
      "name": "Cloth_Block_Wool_Red"
    },
    {
      "x": 13,
      "y": 16,
      "z": -8,
      "name": "Cloth_Block_Wool_White"
    },
    {
      "x": 13,
      "y": 34,
      "z": -8,
      "name": "Cloth_Block_Wool_White"
    },
    {
      "x": 13,
      "y": 35,
      "z": -8,
      "name": "Wood_Hardwood_Planks"
    },
    {
      "x": 13,
      "y": 14,
      "z": -7,
      "name": "Wood_Hardwood_Beam",
      "rotation": 1
    },
    {
      "x": 13,
      "y": 15,
      "z": -7,
      "name": "Wood_Hardwood_Planks"
    },
    {
      "x": 13,
      "y": 16,
      "z": -7,
