{
  "version": 8,
  "blockIdVersion": 11,
  "anchorX": 0,
  "anchorY": 0,
  "anchorZ": 0,
  "blocks": [
    {
      "x": -5,
      "y": 0,
      "z": -7,
      "name": "Rock_Stone_Cobble"
    },
    {
      "x": -5,
      "y": 4,
      "z": -7,
      "name": "Wood_Softwood_Roof_Hollow",
      "rotation": 3
    },
    {
      "x": -5,
      "y": 0,
      "z": -6,
      "name": "Rock_Stone_Cobble"
    },
    {
      "x": -5,
      "y": 4,
      "z": -6,
      "name": "Wood_Softwood_Roof_Hollow",
      "rotation": 3
    },
    {
      "x": -5,
      "y": 0,
      "z": -5,
      "name": "Rock_Stone_Cobble_Mossy"
    },
    {
      "x": -5,
      "y": 3,
      "z": -5,
      "name": "Plant_Vine_Wall",
      "support": 15,
      "rotation": 3
    },
    {
      "x": -5,
      "y": 4,
      "z": -5,
      "name": "Wood_Softwood_Roof_Hollow",
      "rotation": 3
    },
    {
      "x": -5,
      "y": 0,
      "z": -4,
      "name": "Rock_Stone_Cobble"
    },
    {
      "x": -5,
      "y": 4,
      "z": -4,
      "name": "Wood_Softwood_Roof_Hollow",
      "rotation": 3
    },
    {
      "x": -5,
      "y": 0,
      "z": -3,
      "name": "Rock_Stone_Cobble"
    },
    {
      "x": -5,
      "y": 4,
      "z": -3,
      "name": "Wood_Softwood_Roof_Hollow",
      "rotation": 3
    },
    {
      "x": -5,
      "y": 0,
      "z": -2,
      "name": "Rock_Stone_Cobble"
    },
    {
      "x": -5,
      "y": 4,
      "z": -2,
      "name": "Wood_Softwood_Roof_Hollow",
      "rotation": 3
    },
    {
      "x": -5,
      "y": 0,
      "z": -1,
      "name": "Rock_Stone_Cobble"
    },
    {
      "x": -5,
      "y": 4,
      "z": -1,
      "name": "Wood_Softwood_Roof_Hollow",
      "rotation": 3
    },
    {
      "x": -5,
      "y": 0,
      "z": 0,
      "name": "Rock_Stone_Cobble"
    },
    {
      "x": -5,
      "y": 3,
      "z": 0,
      "name": "Plant_Vine_Wall",
      "support": 15,
      "rotation": 3
    },
    {
      "x": -5,
      "y": 4,
      "z": 0,
      "name": "Wood_Softwood_Roof_Hollow",
      "rotation": 3
    },
    {
      "x": -5,
      "y": 0,
      "z": 1,
      "name": "Rock_Stone_Cobble"
    },
    {
      "x": -5,
      "y": 3,
      "z": 1,
      "name": "Cloth_Roof_Red_Flap",
      "rotation": 3
    },
    {
      "x": -5,
      "y": 4,
      "z": 1,
      "name": "Wood_Softwood_Roof_Hollow",
      "rotation": 3
    },
    {
      "x": -5,
      "y": 0,
      "z": 2,
      "name": "Rock_Stone_Cobble"
    },
    {
      "x": -5,
      "y": 3,
      "z": 2,
      "name": "Cloth_Roof_White_Flap",
      "rotation": 3
    },
    {
      "x": -5,
      "y": 0,
      "z": 3,
      "name": "Rock_Stone_Cobble_Mossy"
    },
    {
      "x": -5,
      "y": 3,
      "z": 3,
      "name": "Cloth_Roof_Red_Flap",
      "rotation": 3
    },
    {
      "x": -5,
      "y": 0,
      "z": 4,
      "name": "Rock_Stone_Cobble_Mossy"
    },
    {
      "x": -5,
      "y": 3,
      "z": 4,
      "name": "Cloth_Roof_White_Flap",
      "rotation": 3
    },
    {
      "x": -5,
      "y": 0,
      "z": 5,
      "name": "Rock_Stone_Cobble"
    },
    {
      "x": -5,
      "y": 0,
      "z": 6,
      "name": "Rock_Stone_Cobble"
    },
    {
      "x": -4,
      "y": 0,
      "z": -7,
      "name": "Rock_Stone_Cobble"
    },
    {
      "x": -4,
      "y": 4,
      "z": -7,
      "name": "Wood_Beech_Branch_Corner",
      "support": 15,
      "rotation": 2
    },
    {
      "x": -4,
      "y": 5,
      "z": -7,
      "name": "Wood_Softwood_Roof",
      "rotation": 3
    },
    {
      "x": -4,
      "y": 0,
      "z": -6,
      "name": "Rock_Stone_Cobble"
    },
    {
      "x": -4,
      "y": 1,
      "z": -6,
      "name": "Wood_Beech_Trunk",
      "support": 15
    },
    {
      "x": -4,
      "y": 2,
      "z": -6,
      "name": "Wood_Beech_Trunk",
      "support": 15
    },
    {
      "x": -4,
      "y": 3,
      "z": -6,
      "name": "Wood_Beech_Trunk",
      "support": 15
    },
    {
      "x": -4,
      "y": 4,
      "z": -6,
      "name": "Wood_Beech_Trunk",
      "support": 15
    },
    {
      "x": -4,
      "y": 5,
      "z": -6,
      "name": "Wood_Softwood_Roof",
      "rotation": 3
    },
    {
      "x": -4,
      "y": 0,
      "z": -5,
      "name": "Rock_Stone_Cobble"
    },
    {
      "x": -4,
      "y": 1,
      "z": -5,
      "name": "Rock_Stone_Brick"
    },
    {
      "x": -4,
      "y": 2,
      "z": -5,
      "name": "*Wood_Village_Wall_Full_State_Definitions_Bottom"
    },
    {
      "x": -4,
      "y": 3,
      "z": -5,
      "name": "*Wood_Village_Wall_Full_State_Definitions_Top"
    },
    {
      "x": -4,
      "y": 4,
      "z": -5,
      "name": "Wood_Beech_Trunk",
      "support": 15,
      "rotation": 4
    },
    {
      "x": -4,
      "y": 5,
      "z": -5,
      "name": "Wood_Softwood_Roof",
      "rotation": 3
    },
    {
      "x": -4,
      "y": 0,
      "z": -4,
      "name": "Rock_Stone_Cobble_Mossy"
    },
    {
      "x": -4,
      "y": 1,
      "z": -4,
      "name": "Rock_Stone_Brick"
    },
    {
      "x": -4,
      "y": 2,
      "z": -4,
      "name": "Furniture_Village_Window",
      "rotation": 1
    },
    {
      "x": -4,
      "y": 3,
      "z": -4,
      "name": "Wood_Village_Wall_Full"
    },
    {
      "x": -4,
      "y": 4,
      "z": -4,
      "name": "Wood_Beech_Trunk",
      "support": 15,
      "rotation": 4
    },
    {
      "x": -4,
      "y": 5,
      "z": -4,
      "name": "Wood_Softwood_Roof",
      "rotation": 3
    },
    {
      "x": -4,
      "y": 0,
      "z": -3,
      "name": "Rock_Stone_Cobble"
    },
    {
      "x": -4,
      "y": 1,
      "z": -3,
      "name": "Rock_Stone_Brick"
    },
    {
      "x": -4,
      "y": 2,
      "z": -3,
      "name": "*Wood_Village_Wall_Full_State_Definitions_Bottom"
    },
    {
      "x": -4,
      "y": 3,
      "z": -3,
      "name": "*Wood_Village_Wall_Full_State_Definitions_Top"
    },
    {
      "x": -4,
      "y": 4,
      "z": -3,
      "name": "Wood_Beech_Trunk",
      "support": 15,
      "rotation": 4
    },
    {
      "x": -4,
      "y": 5,
      "z": -3,
      "name": "Wood_Softwood_Roof",
      "rotation": 3
    },
    {
      "x": -4,
      "y": 0,
      "z": -2,
      "name": "Rock_Stone_Cobble"
    },
    {
      "x": -4,
      "y": 1,
      "z": -2,
      "name": "Rock_Stone_Brick_Mossy"
    },
    {
      "x": -4,
      "y": 2,
      "z": -2,
      "name": "Furniture_Village_Window",
      "rotation": 1
    },
    {
      "x": -4,
      "y": 3,
      "z": -2,
      "name": "Wood_Village_Wall_Full"
    },
    {
      "x": -4,
      "y": 4,
      "z": -2,
      "name": "Wood_Beech_Trunk",
      "support": 15,
      "rotation": 4
    },
    {
      "x": -4,
      "y": 5,
      "z": -2,
      "name": "Wood_Softwood_Roof",
      "rotation": 3
    },
    {
      "x": -4,
      "y": 0,
      "z": -1,
      "name": "Rock_Stone_Cobble"
    },
    {
      "x": -4,
      "y": 1,
      "z": -1,
      "name": "Rock_Stone_Brick"
    },
    {
      "x": -4,
      "y": 2,
      "z": -1,
      "name": "*Wood_Village_Wall_Full_State_Definitions_Bottom"
    },
    {
      "x": -4,
      "y": 3,
      "z": -1,
      "name": "*Wood_Village_Wall_Full_State_Definitions_Top"
    },
    {
      "x": -4,
      "y": 4,
      "z": -1,
      "name": "Wood_Beech_Trunk",
      "support": 15,
      "rotation": 4
    },
    {
      "x": -4,
      "y": 5,
      "z": -1,
      "name": "Wood_Softwood_Roof",
      "rotation": 3
    },
    {
      "x": -4,
      "y": 0,
      "z": 0,
      "name": "Rock_Stone_Cobble_Mossy"
    },
    {
      "x": -4,
      "y": 1,
      "z": 0,
      "name": "Wood_Beech_Trunk",
      "support": 15
    },
    {
      "x": -4,
      "y": 2,
      "z": 0,
      "name": "Wood_Beech_Trunk",
      "support": 15
    },
    {
      "x": -4,
      "y": 3,
      "z": 0,
      "name": "Wood_Beech_Trunk",
      "support": 15
    },
    {
      "x": -4,
      "y": 4,
      "z": 0,
      "name": "Wood_Beech_Trunk",
      "support": 15
    },
    {
      "x": -4,
      "y": 5,
      "z": 0,
      "name": "Wood_Softwood_Roof",
      "rotation": 3
    },
    {
      "x": -4,
      "y": 0,
      "z": 1,
      "name": "Rock_Stone_Brick_Smooth"
    },
    {
      "x": -4,
      "y": 2,
      "z": 1,
      "name": "Wood_Torch_Wall",
      "support": 15
    },
    {
      "x": -4,
      "y": 4,
      "z": 1,
      "name": "Cloth_Roof_Red",
      "rotation": 3
    },
    {
      "x": -4,
      "y": 5,
      "z": 1,
      "name": "Wood_Softwood_Roof_Hollow",
      "rotation": 3
    },
    {
      "x": -4,
      "y": 0,
      "z": 2,
      "name": "Rock_Stone_Brick_Smooth"
    },
    {
      "x": -4,
      "y": 4,
      "z": 2,
      "name": "Cloth_Roof_White",
      "rotation": 3
    },
    {
      "x": -4,
      "y": 0,
      "z": 3,
      "name": "Rock_Stone_Brick_Smooth"
    },
    {
      "x": -4,
      "y": 4,
      "z": 3,
      "name": "Cloth_Roof_Red",
      "rotation": 3
    },
    {
      "x": -4,
      "y": 0,
      "z": 4,
      "name": "Rock_Stone_Cobble"
    },
    {
      "x": -4,
      "y": 1,
      "z": 4,
      "name": "Wood_Beech_Trunk",
      "support": 15
    },
    {
      "x": -4,
      "y": 2,
      "z": 4,
      "name": "Wood_Softwood_Beam"
    },
    {
      "x": -4,
      "y": 3,
      "z": 4,
      "name": "Wood_Softwood_Beam"
    },
    {
      "x": -4,
      "y": 4,
      "z": 4,
      "name": "*Cloth_Roof_White_State_Definitions_Corner_Right"
    },
    {
      "x": -4,
      "y": 0,
      "z": 5,
      "name": "Rock_Stone_Cobble"
    },
    {
      "x": -4,
      "y": 1,
      "z": 5,
      "name": "Furniture_Tavern_Planter",
      "support": 15
    },
    {
      "x": -4,
      "y": 2,
      "z": 5,
      "name": "Plant_Flower_Common_Yellow2",
      "support": 15
    },
    {
      "x": -4,
      "y": 3,
      "z": 5,
      "name": "Cloth_Roof_White_Flap"
    },
    {
      "x": -4,
      "y": 0,
      "z": 6,
      "name": "Rock_Stone_Cobble_Mossy"
    },
    {
      "x": -3,
      "y": 0,
      "z": -7,
      "name": "Rock_Stone_Cobble"
    },
    {
      "x": -3,
      "y": 2,
      "z": -7,
      "name": "Plant_Vine_Wall",
      "support": 15,
      "rotation": 2
    },
    {
      "x": -3,
      "y": 5,
      "z": -7,
      "name": "Wood_Softwood_Stairs",
      "rotation": 11
    },
    {
      "x": -3,
      "y": 6,
      "z": -7,
      "name": "Wood_Softwood_Roof_Steep",
      "rotation": 3
    },
    {
      "x": -3,
      "y": 7,
      "z": -7,
      "name": "Wood_Softwood_Roof_Steep",
      "filler": 1024,
      "rotation": 3
    },
    {
      "x": -3,
      "y": 0,
      "z": -6,
      "name": "Rock_Stone_Cobble"
    },
    {
      "x": -3,
      "y": 1,
      "z": -6,
      "name": "Rock_Stone_Brick"
    },
    {
      "x": -3,
      "y": 2,
      "z": -6,
      "name": "*Wood_Village_Wall_Full_State_Definitions_Bottom"
    },
    {
      "x": -3,
      "y": 3,
      "z": -6,
      "name": "*Wood_Village_Wall_Full_State_Definitions_Top"
    },
    {
      "x": -3,
      "y": 4,
      "z": -6,
      "name": "Wood_Beech_Trunk",
      "support": 15,
      "rotation": 5
    },
    {
      "x": -3,
      "y": 5,
      "z": -6,
      "name": "Wood_Village_Wall_Full"
    },
    {
      "x": -3,
      "y": 6,
      "z": -6,
      "name": "Wood_Softwood_Roof_Steep",
      "rotation": 3
    },
    {
      "x": -3,
      "y": 7,
      "z": -6,
      "name": "Wood_Softwood_Roof_Steep",
      "filler": 1024,
      "rotation": 3
    },
    {
      "x": -3,
      "y": 0,
      "z": -5,
      "name": "Wood_Softwood_Planks"
    },
    {
      "x": -3,
      "y": 1,
      "z": -5,
      "name": "Furniture_Village_Crate"
    },
    {
      "x": -3,
      "y": 2,
      "z": -5,
      "name": "Furniture_Village_Crate"
    },
    {
      "x": -3,
      "y": 4,
      "z": -5,
      "name": "Furniture_Village_Platform",
      "support": 15,
      "rotation": 1
    },
    {
      "x": -3,
      "y": 5,
      "z": -5,
      "name": "Wood_Softwood_Stairs",
      "rotation": 11
    },
    {
      "x": -3,
      "y": 6,
      "z": -5,
      "name": "Wood_Softwood_Roof_Steep",
      "rotation": 3
    },
    {
      "x": -3,
      "y": 7,
      "z": -5,
      "name": "Wood_Softwood_Roof_Steep",
      "filler": 1024,
      "rotation": 3
    },
    {
      "x": -3,
      "y": 0,
      "z": -4,
      "name": "Wood_Softwood_Planks"
    },
    {
      "x": -3,
      "y": 1,
      "z": -4,
      "name": "Furniture_Village_Crate"
    },
    {
      "x": -3,
      "y": 2,
      "z": -4,
      "name": "Furniture_Ancient_Sack",
      "support": 15,
      "rotation": 1
    },
    {
      "x": -3,
      "y": 5,
      "z": -4,
      "name": "Wood_Softwood_Stairs",
      "rotation": 11
    },
    {
      "x": -3,
      "y": 6,
      "z": -4,
      "name": "Wood_Softwood_Roof_Steep",
      "rotation": 3
    },
    {
      "x": -3,
      "y": 7,
      "z": -4,
      "name": "Wood_Softwood_Roof_Steep",
      "filler": 1024,
      "rotation": 3
    },
    {
      "x": -3,
      "y": 0,
      "z": -3,
      "name": "Wood_Softwood_Planks"
    },
    {
      "x": -3,
      "y": 1,
      "z": -3,
      "name": "Furniture_Tavern_Chest_Large",
      "components": {
        "Components": {
          "ItemContainerBlock": {
            "ItemContainer": {
              "Capacity": 36,
              "Items": {}
            },
            "Capacity": 36
          }
        }
      },
      "support": 15,
      "rotation": 1
    },
    {
      "x": -3,
      "y": 5,
      "z": -3,
      "name": "Wood_Softwood_Stairs",
      "rotation": 11
    },
    {
      "x": -3,
      "y": 6,
      "z": -3,
      "name": "Wood_Softwood_Roof_Steep",
      "rotation": 3
    },
    {
      "x": -3,
      "y": 7,
      "z": -3,
      "name": "Wood_Softwood_Roof_Steep",
      "filler": 1024,
      "rotation": 3
    },
    {
      "x": -3,
      "y": 0,
      "z": -2,
      "name": "Wood_Softwood_Planks"
    },
    {
      "x": -3,
      "y": 1,
      "z": -2,
      "name": "Furniture_Tavern_Chest_Large",
      "support": 15,
      "filler": 32,
      "rotation": 1
    },
    {
      "x": -3,
      "y": 5,
      "z": -2,
      "name": "Wood_Softwood_Stairs",
      "rotation": 11
    },
    {
      "x": -3,
      "y": 6,
      "z": -2,
      "name": "Wood_Softwood_Roof_Steep",
      "rotation": 3
    },
    {
      "x": -3,
      "y": 7,
      "z": -2,
      "name": "Wood_Softwood_Roof_Steep",
      "filler": 1024,
      "rotation": 3
    },
    {
      "x": -3,
      "y": 0,
      "z": -1,
      "name": "Wood_Softwood_Planks"
    },
    {
      "x": -3,
      "y": 5,
      "z": -1,
      "name": "Wood_Softwood_Stairs",
      "rotation": 11
    },
    {
      "x": -3,
      "y": 6,
      "z": -1,
      "name": "Wood_Softwood_Roof_Steep",
      "rotation": 3
    },
    {
      "x": -3,
      "y": 7,
      "z": -1,
      "name": "Wood_Softwood_Roof_Steep",
      "filler": 1024,
      "rotation": 3
    },
    {
      "x": -3,
      "y": 0,
      "z": 0,
      "name": "Wood_Softwood_Planks"
    },
    {
      "x": -3,
      "y": 1,
      "z": 0,
      "name": "Wood_Softwood_Stairs",
      "rotation": 11
    },
    {
      "x": -3,
      "y": 2,
      "z": 0,
      "name": "Aetherhaven_Shop_Spot",
      "components": {
        "Components": {
          "AetherhavenShopSpotBlock": {
            "SpotId": "ba35353b-14a3-43c0-b452-a0740fa52e9d",
            "TownId": "d87b9d18-a6de-42a7-9697-90f4c2aa0d9f",
            "PlotId": "00000000-0000-0000-0000-000000000000",
            "PlayerControlled": false,
            "LootTableId": "merchant_large_furniture",
            "Configured": true
          },
          "PlacedByInteraction": {
            "WhoPlacedUuid": {
              "$binary": "v7RyWIT/TYKnXA2XcxdQtw==",
              "$type": "04"
            }
          }
        }
      }
    },
    {
      "x": -3,
      "y": 3,
      "z": 0,
      "name": "Wood_Softwood_Stairs",
      "rotation": 11
    },
    {
      "x": -3,
      "y": 4,
      "z": 0,
      "name": "Wood_Beech_Trunk",
      "support": 15,
      "rotation": 5
    },
    {
      "x": -3,
      "y": 5,
      "z": 0,
      "name": "Wood_Village_Wall_Full"
    },
    {
      "x": -3,
      "y": 6,
      "z": 0,
      "name": "Wood_Softwood_Roof_Steep",
      "rotation": 3
    },
    {
      "x": -3,
      "y": 7,
      "z": 0,
      "name": "Wood_Softwood_Roof_Steep",
      "filler": 1024,
      "rotation": 3
    },
    {
      "x": -3,
      "y": 0,
      "z": 1,
      "name": "Rock_Stone_Brick"
    },
    {
      "x": -3,
      "y": 5,
      "z": 1,
      "name": "Cloth_Roof_White_Flat"
    },
    {
      "x": -3,
      "y": 6,
      "z": 1,
      "name": "Wood_Softwood_Roof_Steep",
      "rotation": 3
    },
    {
      "x": -3,
      "y": 7,
      "z": 1,
      "name": "Wood_Softwood_Roof_Steep",
      "filler": 1024,
      "rotation": 3
    },
    {
      "x": -3,
      "y": 0,
      "z": 2,
      "name": "Rock_Stone_Brick_Mossy"
    },
    {
      "x": -3,
      "y": 5,
      "z": 2,
      "name": "Cloth_Roof_Red_Flat"
    },
    {
      "x": -3,
      "y": 0,
      "z": 3,
      "name": "Rock_Stone_Brick"
    },
    {
      "x": -3,
      "y": 5,
      "z": 3,
      "name": "Cloth_Roof_White_Flat"
    },
    {
      "x": -3,
      "y": 0,
      "z": 4,
      "name": "Rock_Stone_Brick_Smooth"
    },
    {
      "x": -3,
      "y": 4,
      "z": 4,
      "name": "Cloth_Roof_Red"
    },
    {
      "x": -3,
      "y": 0,
      "z": 5,
      "name": "Rock_Stone_Cobble_Mossy"
    },
    {
      "x": -3,
      "y": 3,
      "z": 5,
      "name": "Cloth_Roof_Red_Flap"
    },
    {
      "x": -3,
      "y": 0,
      "z": 6,
      "name": "Rock_Stone_Cobble"
    },
    {
      "x": -2,
      "y": 0,
      "z": -7,
      "name": "Rock_Stone_Cobble_Mossy"
    },
    {
      "x": -2,
      "y": 7,
      "z": -7,
      "name": "Wood_Softwood_Stairs",
      "rotation": 11
    },
    {
      "x": -2,
      "y": 8,
      "z": -7,
      "name": "Wood_Softwood_Roof",
      "rotation": 3
    },
    {
      "x": -2,
      "y": 0,
      "z": -6,
      "name": "Rock_Stone_Cobble"
    },
    {
      "x": -2,
      "y": 1,
      "z": -6,
      "name": "Rock_Stone_Brick_Mossy"
    },
    {
      "x": -2,
      "y": 2,
      "z": -6,
      "name": "Furniture_Village_Window"
    },
    {
      "x": -2,
      "y": 3,
      "z": -6,
      "name": "Furniture_Village_Window"
    },
    {
      "x": -2,
      "y": 4,
      "z": -6,
      "name": "Wood_Beech_Trunk",
      "support": 15,
      "rotation": 5
    },
    {
      "x": -2,
      "y": 5,
      "z": -6,
      "name": "*Wood_Village_Wall_Full_State_Definitions_Bottom"
    },
    {
      "x": -2,
      "y": 6,
      "z": -6,
      "name": "*Wood_Village_Wall_Full_State_Definitions_Middle"
    },
    {
      "x": -2,
      "y": 7,
      "z": -6,
      "name": "*Wood_Village_Wall_Full_State_Definitions_Top"
    },
    {
      "x": -2,
      "y": 8,
      "z": -6,
      "name": "Wood_Softwood_Roof",
      "rotation": 3
    },
    {
      "x": -2,
      "y": 0,
      "z": -5,
      "name": "Wood_Softwood_Planks"
    },
    {
      "x": -2,
      "y": 1,
      "z": -5,
      "name": "Furniture_Tavern_Barrel",
      "support": 15
    },
    {
      "x": -2,
      "y": 4,
      "z": -5,
      "name": "Furniture_Village_Platform",
      "support": 15,
      "rotation": 1
    },
    {
      "x": -2,
      "y": 5,
      "z": -5,
      "name": "Furniture_Village_Crate"
    },
    {
      "x": -2,
      "y": 7,
      "z": -5,
      "name": "Wood_Softwood_Stairs",
      "rotation": 11
    },
    {
      "x": -2,
      "y": 8,
      "z": -5,
      "name": "Wood_Softwood_Roof",
      "rotation": 3
    },
    {
      "x": -2,
      "y": 0,
      "z": -4,
      "name": "Wood_Softwood_Planks"
    },
    {
      "x": -2,
      "y": 7,
      "z": -4,
      "name": "Wood_Softwood_Stairs",
      "rotation": 11
    },
    {
      "x": -2,
      "y": 8,
      "z": -4,
      "name": "Wood_Softwood_Roof",
      "rotation": 3
    },
    {
      "x": -2,
      "y": 0,
      "z": -3,
      "name": "Wood_Softwood_Planks"
    },
    {
      "x": -2,
      "y": 4,
      "z": -3,
      "name": "Deco_Lantern_Ceiling",
      "support": 15
    },
    {
      "x": -2,
      "y": 5,
      "z": -3,
      "name": "Deco_Rope",
      "support": 15
    },
    {
      "x": -2,
      "y": 6,
      "z": -3,
      "name": "Deco_Rope",
      "support": 15
    },
    {
      "x": -2,
      "y": 7,
      "z": -3,
      "name": "Wood_Softwood_Planks"
    },
    {
      "x": -2,
      "y": 8,
      "z": -3,
      "name": "Wood_Softwood_Roof",
      "rotation": 3
    },
    {
      "x": -2,
      "y": 0,
      "z": -2,
      "name": "Wood_Softwood_Planks"
    },
    {
      "x": -2,
      "y": 7,
      "z": -2,
      "name": "Wood_Softwood_Stairs",
      "rotation": 11
    },
    {
      "x": -2,
      "y": 8,
      "z": -2,
      "name": "Wood_Softwood_Roof",
      "rotation": 3
    },
    {
      "x": -2,
      "y": 0,
      "z": -1,
      "name": "Wood_Softwood_Planks"
    },
    {
      "x": -2,
      "y": 7,
      "z": -1,
      "name": "Wood_Softwood_Stairs",
      "rotation": 11
    },
    {
      "x": -2,
      "y": 8,
      "z": -1,
      "name": "Wood_Softwood_Roof",
      "rotation": 3
    },
    {
      "x": -2,
      "y": 0,
      "z": 0,
      "name": "Wood_Softwood_Planks"
    },
    {
      "x": -2,
      "y": 1,
      "z": 0,
      "name": "Wood_Softwood_Planks_Half",
      "rotation": 8
    },
    {
      "x": -2,
      "y": 2,
      "z": 0,
      "name": "Aetherhaven_Shop_Spot",
      "components": {
        "Components": {
          "AetherhavenShopSpotBlock": {
            "SpotId": "8838785c-2c48-4265-9bfb-c27d384d5895",
            "TownId": "d87b9d18-a6de-42a7-9697-90f4c2aa0d9f",
            "PlotId": "00000000-0000-0000-0000-000000000000",
            "PlayerControlled": false,
            "LootTableId": "merchant_furniture",
            "Configured": true
          },
          "PlacedByInteraction": {
            "WhoPlacedUuid": {
              "$binary": "v7RyWIT/TYKnXA2XcxdQtw==",
              "$type": "04"
            }
          }
        }
      }
    },
    {
      "x": -2,
      "y": 4,
      "z": 0,
      "name": "Wood_Beech_Trunk",
      "support": 15,
      "rotation": 5
    },
    {
      "x": -2,
      "y": 5,
      "z": 0,
      "name": "*Wood_Village_Wall_Full_State_Definitions_Bottom"
    },
    {
      "x": -2,
      "y": 6,
      "z": 0,
      "name": "*Wood_Village_Wall_Full_State_Definitions_Middle"
    },
    {
      "x": -2,
      "y": 7,
      "z": 0,
      "name": "*Wood_Village_Wall_Full_State_Definitions_Top"
    },
    {
      "x": -2,
      "y": 8,
      "z": 0,
      "name": "Wood_Softwood_Roof",
      "rotation": 3
    },
    {
      "x": -2,
      "y": 0,
      "z": 1,
      "name": "Rock_Stone_Brick"
    },
    {
      "x": -2,
      "y": 5,
      "z": 1,
      "name": "Cloth_Roof_Red_Flat"
    },
    {
      "x": -2,
      "y": 7,
      "z": 1,
      "name": "Wood_Softwood_Stairs",
      "rotation": 11
    },
    {
      "x": -2,
      "y": 8,
      "z": 1,
      "name": "Wood_Softwood_Roof",
      "rotation": 3
    },
    {
      "x": -2,
      "y": 0,
      "z": 2,
      "name": "Rock_Stone_Brick"
    },
    {
      "x": -2,
      "y": 5,
      "z": 2,
      "name": "Cloth_Roof_White_Flat"
    },
    {
      "x": -2,
      "y": 0,
      "z": 3,
      "name": "Rock_Stone_Brick"
    },
    {
      "x": -2,
      "y": 5,
      "z": 3,
      "name": "Cloth_Roof_Red_Flat"
    },
    {
      "x": -2,
      "y": 0,
      "z": 4,
      "name": "Rock_Stone_Brick_Smooth"
    },
    {
      "x": -2,
      "y": 4,
      "z": 4,
      "name": "Cloth_Roof_White"
    },
    {
      "x": -2,
      "y": 0,
      "z": 5,
      "name": "Rock_Stone_Cobble"
    },
    {
      "x": -2,
      "y": 3,
      "z": 5,
      "name": "Cloth_Roof_White_Flap"
    },
    {
      "x": -2,
      "y": 0,
      "z": 6,
      "name": "Rock_Stone_Cobble_Mossy"
    },
    {
      "x": -1,
      "y": 0,
      "z": -7,
      "name": "Rock_Stone_Cobble"
    },
    {
      "x": -1,
      "y": 4,
      "z": -7,
      "name": "Wood_Beech_Branch_Short",
      "support": 15,
      "rotation": 2
    },
    {
      "x": -1,
      "y": 8,
      "z": -7,
      "name": "Wood_Softwood_Stairs",
      "rotation": 11
    },
    {
      "x": -1,
      "y": 9,
      "z": -7,
      "name": "Wood_Softwood_Roof_Flat"
    },
    {
      "x": -1,
      "y": 0,
      "z": -6,
      "name": "Rock_Stone_Cobble"
    },
    {
      "x": -1,
      "y": 1,
      "z": -6,
      "name": "Rock_Stone_Brick"
    },
    {
      "x": -1,
      "y": 2,
      "z": -6,
      "name": "Furniture_Village_Window"
    },
    {
      "x": -1,
      "y": 3,
      "z": -6,
      "name": "Furniture_Village_Window"
    },
    {
      "x": -1,
      "y": 4,
      "z": -6,
      "name": "Wood_Beech_Trunk",
      "support": 15,
      "rotation": 5
    },
    {
      "x": -1,
      "y": 5,
      "z": -6,
      "name": "*Wood_Village_Wall_Full_State_Definitions_Bottom"
    },
    {
      "x": -1,
      "y": 6,
      "z": -6,
      "name": "*Wood_Village_Wall_Full_State_Definitions_Middle"
    },
    {
      "x": -1,
      "y": 7,
      "z": -6,
      "name": "*Wood_Village_Wall_Full_State_Definitions_Middle"
    },
    {
      "x": -1,
      "y": 8,
      "z": -6,
      "name": "*Wood_Village_Wall_Full_State_Definitions_Top"
    },
    {
      "x": -1,
      "y": 9,
      "z": -6,
      "name": "Wood_Softwood_Roof_Flat"
    },
    {
      "x": -1,
      "y": 0,
      "z": -5,
      "name": "Wood_Softwood_Planks"
    },
    {
      "x": -1,
      "y": 4,
      "z": -5,
      "name": "Furniture_Village_Platform",
      "support": 15,
      "rotation": 1
    },
    {
      "x": -1,
      "y": 5,
      "z": -5,
      "name": "Furniture_Tavern_Barrel",
      "support": 15
    },
    {
      "x": -1,
      "y": 8,
      "z": -5,
      "name": "Wood_Softwood_Stairs",
      "rotation": 11
    },
    {
      "x": -1,
      "y": 9,
      "z": -5,
      "name": "Wood_Softwood_Roof_Flat"
    },
    {
      "x": -1,
      "y": 0,
      "z": -4,
      "name": "Wood_Softwood_Planks"
    },
    {
      "x": -1,
      "y": 8,
      "z": -4,
      "name": "Wood_Softwood_Stairs",
      "rotation": 11
    },
    {
      "x": -1,
      "y": 9,
      "z": -4,
      "name": "Wood_Softwood_Roof_Flat"
    },
    {
      "x": -1,
      "y": 0,
      "z": -3,
      "name": "Wood_Softwood_Planks"
    },
    {
      "x": -1,
      "y": 1,
      "z": -3,
      "name": "Cloth_Roof_Red_Flat"
    },
    {
      "x": -1,
      "y": 8,
      "z": -3,
      "name": "Wood_Softwood_Stairs",
      "rotation": 11
    },
    {
      "x": -1,
      "y": 9,
      "z": -3,
      "name": "Wood_Softwood_Roof_Flat"
    },
    {
      "x": -1,
      "y": 0,
      "z": -2,
      "name": "Wood_Softwood_Planks"
    },
    {
      "x": -1,
      "y": 1,
      "z": -2,
      "name": "Cloth_Roof_Red_Flat"
    },
    {
      "x": -1,
      "y": 8,
      "z": -2,
      "name": "Wood_Softwood_Stairs",
      "rotation": 11
    },
    {
      "x": -1,
      "y": 9,
      "z": -2,
      "name": "Wood_Softwood_Roof_Flat"
    },
    {
      "x": -1,
      "y": 0,
      "z": -1,
      "name": "Wood_Softwood_Planks"
    },
    {
      "x": -1,
      "y": 8,
      "z": -1,
      "name": "Wood_Softwood_Stairs",
      "rotation": 11
    },
    {
      "x": -1,
      "y": 9,
      "z": -1,
      "name": "Wood_Softwood_Roof_Flat"
    },
    {
      "x": -1,
      "y": 0,
      "z": 0,
      "name": "Wood_Softwood_Planks"
    },
    {
      "x": -1,
      "y": 1,
      "z": 0,
      "name": "Wood_Softwood_Planks_Half",
      "rotation": 8
    },
    {
      "x": -1,
      "y": 2,
      "z": 0,
      "name": "Aetherhaven_Shop_Spot",
      "components": {
        "Components": {
          "AetherhavenShopSpotBlock": {
            "SpotId": "94ae0406-e674-46e7-b2df-3be5ecb2d395",
            "TownId": "d87b9d18-a6de-42a7-9697-90f4c2aa0d9f",
            "PlotId": "00000000-0000-0000-0000-000000000000",
            "PlayerControlled": false,
            "LootTableId": "merchant_furniture",
            "Configured": true
          },
          "PlacedByInteraction": {
            "WhoPlacedUuid": {
              "$binary": "v7RyWIT/TYKnXA2XcxdQtw==",
              "$type": "04"
            }
          }
        }
      }
    },
    {
      "x": -1,
      "y": 4,
      "z": 0,
      "name": "Wood_Beech_Trunk",
      "support": 15,
      "rotation": 5
    },
    {
      "x": -1,
      "y": 5,
      "z": 0,
      "name": "*Wood_Village_Wall_Full_State_Definitions_Bottom"
    },
    {
      "x": -1,
      "y": 6,
      "z": 0,
      "name": "*Wood_Village_Wall_Full_State_Definitions_Middle"
    },
    {
      "x": -1,
      "y": 7,
      "z": 0,
      "name": "*Wood_Village_Wall_Full_State_Definitions_Middle"
    },
    {
      "x": -1,
      "y": 8,
      "z": 0,
      "name": "*Wood_Village_Wall_Full_State_Definitions_Top"
    },
    {
      "x": -1,
      "y": 9,
      "z": 0,
      "name": "Wood_Softwood_Roof_Flat"
    },
    {
      "x": -1,
      "y": 0,
      "z": 1,
      "name": "Rock_Stone_Brick"
    },
    {
      "x": -1,
      "y": 4,
      "z": 1,
      "name": "Wood_Beech_Branch_Short",
      "support": 15
    },
    {
      "x": -1,
      "y": 5,
      "z": 1,
      "name": "Cloth_Roof_White_Flat"
    },
    {
      "x": -1,
      "y": 6,
      "z": 1,
      "name": "Plant_Vine_Wall",
      "support": 15
    },
    {
      "x": -1,
      "y": 8,
      "z": 1,
      "name": "Wood_Softwood_Stairs",
      "rotation": 11
    },
    {
      "x": -1,
      "y": 9,
      "z": 1,
      "name": "Wood_Softwood_Roof_Flat"
    },
    {
      "x": -1,
      "y": 0,
      "z": 2,
      "name": "Rock_Stone_Brick"
    },
    {
      "x": -1,
      "y": 5,
      "z": 2,
      "name": "Cloth_Roof_Red_Flat"
    },
    {
      "x": -1,
      "y": 0,
      "z": 3,
      "name": "Rock_Stone_Brick"
    },
    {
      "x": -1,
      "y": 5,
      "z": 3,
      "name": "Cloth_Roof_White_Flat"
    },
    {
      "x": -1,
      "y": 0,
      "z": 4,
      "name": "Rock_Stone_Brick_Smooth"
    },
    {
      "x": -1,
      "y": 4,
      "z": 4,
      "name": "Cloth_Roof_Red"
    },
    {
      "x": -1,
      "y": 0,
      "z": 5,
      "name": "Rock_Stone_Cobble"
    },
    {
      "x": -1,
      "y": 3,
      "z": 5,
      "name": "Cloth_Roof_Red_Flap"
    },
    {
      "x": -1,
      "y": 0,
      "z": 6,
      "name": "Rock_Stone_Cobble"
    },
    {
      "x": 0,
      "y": 0,
      "z": -7,
      "name": "Rock_Stone_Cobble"
    },
    {
      "x": 0,
      "y": 4,
      "z": -7,
      "name": "Plant_Vine_Wall",
      "support": 15,
      "rotation": 2
    },
    {
      "x": 0,
      "y": 8,
      "z": -7,
      "name": "Wood_Softwood_Planks_Half",
      "rotation": 8
    },
    {
      "x": 0,
      "y": 9,
      "z": -7,
      "name": "Wood_Softwood_Roof_Flat"
    },
    {
      "x": 0,
      "y": 0,
      "z": -6,
      "name": "Rock_Stone_Cobble"
    },
    {
      "x": 0,
      "y": 1,
      "z": -6,
      "name": "Rock_Stone_Brick"
    },
    {
      "x": 0,
      "y": 2,
      "z": -6,
      "name": "*Wood_Village_Wall_Full_State_Definitions_Bottom"
    },
    {
      "x": 0,
      "y": 3,
      "z": -6,
      "name": "*Wood_Village_Wall_Full_State_Definitions_Top"
    },
    {
      "x": 0,
      "y": 4,
      "z": -6,
      "name": "Wood_Beech_Trunk",
      "support": 15,
      "rotation": 5
    },
    {
      "x": 0,
      "y": 5,
      "z": -6,
      "name": "Furniture_Village_Window"
    },
    {
      "x": 0,
      "y": 6,
      "z": -6,
      "name": "Furniture_Village_Window"
    },
    {
      "x": 0,
      "y": 7,
      "z": -6,
      "name": "*Wood_Village_Wall_Full_State_Definitions_Bottom"
    },
    {
      "x": 0,
      "y": 8,
      "z": -6,
      "name": "*Wood_Village_Wall_Full_State_Definitions_Top"
    },
    {
      "x": 0,
      "y": 9,
      "z": -6,
      "name": "Wood_Softwood_Roof_Flat"
    },
    {
      "x": 0,
      "y": 0,
      "z": -5,
      "name": "Wood_Softwood_Planks"
    },
    {
      "x": 0,
      "y": 1,
      "z": -5,
      "name": "Furniture_Village_Counter",
      "support": 15,
      "filler": 31
    },
    {
      "x": 0,
      "y": 2,
      "z": -5,
      "name": "Aetherhaven_Management_Block",
      "components": {
        "Components": {
          "AetherhavenManagementBlock": {
            "PlotId": "",
            "TownId": ""
          },
          "PlacedByInteraction": {
            "WhoPlacedUuid": {
              "$binary": "v7RyWIT/TYKnXA2XcxdQtw==",
              "$type": "04"
            }
          }
        }
      }
    },
    {
      "x": 0,
      "y": 4,
      "z": -5,
      "name": "Furniture_Village_Platform",
      "support": 15,
      "rotation": 1
    },
    {
      "x": 0,
      "y": 8,
      "z": -5,
      "name": "Wood_Softwood_Planks_Half",
      "rotation": 8
    },
    {
      "x": 0,
      "y": 9,
      "z": -5,
      "name": "Wood_Softwood_Roof_Flat"
    },
    {
      "x": 0,
      "y": 0,
      "z": -4,
      "name": "Wood_Softwood_Planks"
    },
    {
      "x": 0,
      "y": 8,
      "z": -4,
      "name": "Wood_Softwood_Planks_Half",
      "rotation": 8
    },
    {
      "x": 0,
      "y": 9,
      "z": -4,
      "name": "Wood_Softwood_Roof_Flat"
    },
    {
      "x": 0,
      "y": 0,
      "z": -3,
      "name": "Wood_Softwood_Planks"
    },
    {
      "x": 0,
      "y": 1,
      "z": -3,
      "name": "Cloth_Roof_Red_Flat"
    },
    {
      "x": 0,
      "y": 8,
      "z": -3,
      "name": "Wood_Softwood_Planks_Half",
      "rotation": 8
    },
    {
      "x": 0,
      "y": 9,
      "z": -3,
      "name": "Wood_Softwood_Roof_Flat"
    },
    {
      "x": 0,
      "y": 0,
      "z": -2,
      "name": "Wood_Softwood_Planks"
    },
    {
      "x": 0,
      "y": 1,
      "z": -2,
      "name": "Cloth_Roof_Red_Flat"
    },
    {
      "x": 0,
      "y": 8,
      "z": -2,
      "name": "Wood_Softwood_Planks_Half",
      "rotation": 8
    },
    {
      "x": 0,
      "y": 9,
      "z": -2,
      "name": "Wood_Softwood_Roof_Flat"
    },
    {
      "x": 0,
      "y": 0,
      "z": -1,
      "name": "Wood_Softwood_Planks"
    },
    {
      "x": 0,
      "y": 8,
      "z": -1,
      "name": "Wood_Softwood_Planks_Half",
      "rotation": 8
    },
    {
      "x": 0,
      "y": 9,
      "z": -1,
      "name": "Wood_Softwood_Roof_Flat"
    },
    {
      "x": 0,
      "y": 0,
      "z": 0,
      "name": "Wood_Softwood_Planks"
    },
    {
      "x": 0,
      "y": 1,
      "z": 0,
      "name": "Furniture_Village_Counter",
      "support": 15,
      "rotation": 2
    },
    {
      "x": 0,
      "y": 2,
      "z": 0,
      "name": "Aetherhaven_Shop_Spot",
      "components": {
        "Components": {
          "AetherhavenShopSpotBlock": {
            "SpotId": "082d2182-4576-4be5-86bb-2ee1aa24aa30",
            "TownId": "d87b9d18-a6de-42a7-9697-90f4c2aa0d9f",
            "PlotId": "00000000-0000-0000-0000-000000000000",
            "PlayerControlled": false,
            "LootTableId": "merchant_potions",
            "Configured": true
          },
          "PlacedByInteraction": {
            "WhoPlacedUuid": {
              "$binary": "v7RyWIT/TYKnXA2XcxdQtw==",
              "$type": "04"
            }
          }
        }
      }
    },
    {
      "x": 0,
      "y": 4,
      "z": 0,
      "name": "Wood_Beech_Trunk",
      "support": 15,
      "rotation": 5
    },
    {
      "x": 0,
      "y": 5,
      "z": 0,
      "name": "Furniture_Village_Window"
    },
    {
      "x": 0,
      "y": 6,
      "z": 0,
      "name": "Furniture_Village_Window"
    },
    {
      "x": 0,
      "y": 7,
      "z": 0,
      "name": "*Wood_Village_Wall_Full_State_Definitions_Bottom"
    },
    {
      "x": 0,
      "y": 8,
      "z": 0,
      "name": "*Wood_Village_Wall_Full_State_Definitions_Top"
    },
    {
      "x": 0,
      "y": 9,
      "z": 0,
      "name": "Wood_Softwood_Roof_Flat"
    },
    {
      "x": 0,
      "y": 0,
      "z": 1,
      "name": "Rock_Stone_Brick"
    },
    {
      "x": 0,
      "y": 5,
      "z": 1,
      "name": "Cloth_Roof_Red_Flat"
    },
    {
      "x": 0,
      "y": 8,
      "z": 1,
      "name": "Wood_Softwood_Planks_Half",
      "rotation": 8
    },
    {
      "x": 0,
      "y": 9,
      "z": 1,
      "name": "Wood_Softwood_Roof_Flat"
    },
    {
      "x": 0,
      "y": 0,
      "z": 2,
      "name": "Rock_Stone_Brick"
    },
    {
      "x": 0,
      "y": 5,
      "z": 2,
      "name": "Cloth_Roof_White_Flat"
    },
    {
      "x": 0,
      "y": 0,
      "z": 3,
      "name": "Rock_Stone_Brick_Mossy"
    },
    {
      "x": 0,
      "y": 5,
      "z": 3,
      "name": "Cloth_Roof_Red_Flat"
    },
    {
      "x": 0,
      "y": 0,
      "z": 4,
      "name": "Rock_Stone_Brick_Smooth"
    },
    {
      "x": 0,
      "y": 4,
      "z": 4,
      "name": "Cloth_Roof_White"
    },
    {
      "x": 0,
      "y": 0,
      "z": 5,
      "name": "Rock_Stone_Cobble"
    },
    {
      "x": 0,
      "y": 3,
      "z": 5,
      "name": "Cloth_Roof_White_Flap"
    },
    {
      "x": 0,
      "y": 0,
      "z": 6,
      "name": "Rock_Stone_Cobble"
    },
    {
      "x": 1,
      "y": 0,
      "z": -7,
      "name": "Rock_Stone_Cobble"
    },
    {
      "x": 1,
      "y": 8,
      "z": -7,
      "name": "Wood_Softwood_Planks_Half",
      "rotation": 8
    },
    {
      "x": 1,
      "y": 9,
      "z": -7,
      "name": "Wood_Softwood_Roof_Flat"
    },
    {
      "x": 1,
      "y": 0,
      "z": -6,
      "name": "Rock_Stone_Cobble_Mossy"
    },
    {
      "x": 1,
      "y": 1,
      "z": -6,
      "name": "Rock_Stone_Brick"
    },
    {
      "x": 1,
      "y": 2,
      "z": -6,
      "name": "*Wood_Village_Wall_Full_State_Definitions_Bottom"
    },
    {
      "x": 1,
      "y": 3,
      "z": -6,
      "name": "*Wood_Village_Wall_Full_State_Definitions_Top"
    },
    {
      "x": 1,
      "y": 4,
      "z": -6,
      "name": "Wood_Beech_Trunk",
      "support": 15,
      "rotation": 5
    },
    {
      "x": 1,
      "y": 5,
      "z": -6,
      "name": "Furniture_Village_Window"
    },
    {
      "x": 1,
      "y": 6,
      "z": -6,
      "name": "Furniture_Village_Window"
    },
    {
      "x": 1,
      "y": 7,
      "z": -6,
      "name": "*Wood_Village_Wall_Full_State_Definitions_Bottom"
    },
    {
      "x": 1,
      "y": 8,
      "z": -6,
      "name": "*Wood_Village_Wall_Full_State_Definitions_Top"
    },
    {
      "x": 1,
      "y": 9,
      "z": -6,
      "name": "Wood_Softwood_Roof_Flat"
    },
    {
      "x": 1,
      "y": 0,
      "z": -5,
      "name": "Wood_Softwood_Planks"
    },
    {
      "x": 1,
      "y": 1,
      "z": -5,
      "name": "Furniture_Village_Counter",
      "support": 15
    },
    {
      "x": 1,
      "y": 2,
      "z": -5,
      "name": "Furniture_Crude_Candle",
      "support": 15
    },
    {
      "x": 1,
      "y": 4,
      "z": -5,
      "name": "Furniture_Village_Platform",
      "support": 15,
      "rotation": 1
    },
    {
      "x": 1,
      "y": 8,
      "z": -5,
      "name": "Wood_Softwood_Planks_Half",
      "rotation": 8
    },
    {
      "x": 1,
      "y": 9,
      "z": -5,
      "name": "Wood_Softwood_Roof_Flat"
    },
    {
      "x": 1,
      "y": 0,
      "z": -4,
      "name": "Wood_Softwood_Planks"
    },
    {
      "x": 1,
      "y": 8,
      "z": -4,
      "name": "Wood_Softwood_Planks_Half",
      "rotation": 8
    },
    {
      "x": 1,
      "y": 9,
      "z": -4,
      "name": "Wood_Softwood_Roof_Flat"
    },
    {
      "x": 1,
      "y": 0,
      "z": -3,
      "name": "Wood_Softwood_Planks"
    },
    {
      "x": 1,
      "y": 1,
      "z": -3,
      "name": "Cloth_Roof_Red_Flat"
    },
    {
      "x": 1,
      "y": 8,
      "z": -3,
      "name": "Wood_Softwood_Planks_Half",
      "rotation": 8
    },
    {
      "x": 1,
      "y": 9,
      "z": -3,
      "name": "Wood_Softwood_Roof_Flat"
    },
    {
      "x": 1,
      "y": 0,
      "z": -2,
      "name": "Wood_Softwood_Planks"
    },
    {
      "x": 1,
      "y": 1,
      "z": -2,
      "name": "Cloth_Roof_Red_Flat"
    },
    {
      "x": 1,
      "y": 8,
      "z": -2,
      "name": "Wood_Softwood_Planks_Half",
      "rotation": 8
    },
    {
      "x": 1,
      "y": 9,
      "z": -2,
      "name": "Wood_Softwood_Roof_Flat"
    },
    {
      "x": 1,
      "y": 0,
      "z": -1,
      "name": "Wood_Softwood_Planks"
    },
    {
      "x": 1,
      "y": 8,
      "z": -1,
      "name": "Wood_Softwood_Planks_Half",
      "rotation": 8
    },
    {
      "x": 1,
      "y": 9,
      "z": -1,
      "name": "Wood_Softwood_Roof_Flat"
    },
    {
      "x": 1,
      "y": 0,
      "z": 0,
      "name": "Wood_Softwood_Planks"
    },
    {
      "x": 1,
      "y": 1,
      "z": 0,
      "name": "Furniture_Village_Counter",
      "support": 15,
      "filler": 1,
      "rotation": 2
    },
    {
      "x": 1,
      "y": 2,
      "z": 0,
      "name": "Aetherhaven_Shop_Spot",
      "components": {
        "Components": {
          "AetherhavenShopSpotBlock": {
            "SpotId": "4a53ba70-3a48-4a7f-94a1-aadc1f1445f6",
            "TownId": "d87b9d18-a6de-42a7-9697-90f4c2aa0d9f",
            "PlotId": "00000000-0000-0000-0000-000000000000",
            "PlayerControlled": false,
            "LootTableId": "merchant_food",
            "Configured": true
          },
          "PlacedByInteraction": {
            "WhoPlacedUuid": {
              "$binary": "v7RyWIT/TYKnXA2XcxdQtw==",
              "$type": "04"
            }
          }
        }
      }
    },
    {
      "x": 1,
      "y": 4,
      "z": 0,
      "name": "Wood_Beech_Trunk",
      "support": 15,
      "rotation": 5
    },
    {
      "x": 1,
      "y": 5,
      "z": 0,
      "name": "Furniture_Village_Window"
    },
    {
      "x": 1,
      "y": 6,
      "z": 0,
      "name": "Furniture_Village_Window"
    },
    {
      "x": 1,
      "y": 7,
      "z": 0,
      "name": "*Wood_Village_Wall_Full_State_Definitions_Bottom"
    },
    {
      "x": 1,
      "y": 8,
      "z": 0,
      "name": "*Wood_Village_Wall_Full_State_Definitions_Top"
    },
    {
      "x": 1,
      "y": 9,
      "z": 0,
      "name": "Wood_Softwood_Roof_Flat"
    },
    {
      "x": 1,
      "y": 0,
      "z": 1,
      "name": "Rock_Stone_Brick"
    },
    {
      "x": 1,
      "y": 5,
      "z": 1,
      "name": "Cloth_Roof_White_Flat"
    },
    {
      "x": 1,
      "y": 8,
      "z": 1,
      "name": "Wood_Softwood_Planks_Half",
      "rotation": 8
    },
    {
      "x": 1,
      "y": 9,
      "z": 1,
      "name": "Wood_Softwood_Roof_Flat"
    },
    {
      "x": 1,
      "y": 0,
      "z": 2,
      "name": "Rock_Stone_Brick"
    },
    {
      "x": 1,
      "y": 5,
      "z": 2,
      "name": "Cloth_Roof_Red_Flat"
    },
    {
      "x": 1,
      "y": 0,
      "z": 3,
      "name": "Rock_Stone_Brick"
    },
    {
      "x": 1,
      "y": 5,
      "z": 3,
      "name": "Cloth_Roof_White_Flat"
    },
    {
      "x": 1,
      "y": 0,
      "z": 4,
      "name": "Rock_Stone_Brick_Smooth"
    },
    {
      "x": 1,
      "y": 4,
      "z": 4,
      "name": "Cloth_Roof_Red"
    },
    {
      "x": 1,
      "y": 0,
      "z": 5,
      "name": "Rock_Stone_Cobble"
    },
    {
      "x": 1,
      "y": 3,
      "z": 5,
      "name": "Cloth_Roof_Red_Flap"
    },
    {
      "x": 1,
      "y": 0,
      "z": 6,
      "name": "Rock_Stone_Cobble"
    },
    {
      "x": 2,
      "y": 0,
      "z": -7,
      "name": "Rock_Stone_Cobble"
    },
    {
      "x": 2,
      "y": 4,
      "z": -7,
      "name": "Wood_Beech_Branch_Short",
      "support": 15,
      "rotation": 2
    },
    {
      "x": 2,
      "y": 8,
      "z": -7,
      "name": "Wood_Softwood_Stairs",
      "rotation": 9
    },
    {
      "x": 2,
      "y": 9,
      "z": -7,
      "name": "Wood_Softwood_Roof_Flat"
    },
    {
      "x": 2,
      "y": 0,
      "z": -6,
      "name": "Rock_Stone_Cobble"
    },
    {
      "x": 2,
      "y": 1,
      "z": -6,
      "name": "Rock_Stone_Brick_Mossy"
    },
    {
      "x": 2,
      "y": 2,
      "z": -6,
      "name": "Furniture_Village_Window"
    },
    {
      "x": 2,
      "y": 3,
      "z": -6,
      "name": "Furniture_Village_Window"
    },
    {
      "x": 2,
      "y": 4,
      "z": -6,
      "name": "Wood_Beech_Trunk",
      "support": 15,
      "rotation": 5
    },
    {
      "x": 2,
      "y": 5,
      "z": -6,
      "name": "*Wood_Village_Wall_Full_State_Definitions_Bottom"
    },
    {
      "x": 2,
      "y": 6,
      "z": -6,
      "name": "*Wood_Village_Wall_Full_State_Definitions_Middle"
    },
    {
      "x": 2,
      "y": 7,
      "z": -6,
      "name": "*Wood_Village_Wall_Full_State_Definitions_Middle"
    },
    {
      "x": 2,
      "y": 8,
      "z": -6,
      "name": "*Wood_Village_Wall_Full_State_Definitions_Top"
    },
    {
      "x": 2,
      "y": 9,
      "z": -6,
      "name": "Wood_Softwood_Roof_Flat"
    },
    {
      "x": 2,
      "y": 0,
      "z": -5,
      "name": "Wood_Softwood_Planks"
    },
    {
      "x": 2,
      "y": 1,
      "z": -5,
      "name": "Furniture_Tavern_Chest_Large",
      "support": 15,
      "filler": 31
    },
    {
      "x": 2,
      "y": 4,
      "z": -5,
      "name": "Furniture_Village_Platform",
      "support": 15,
      "rotation": 1
    },
    {
      "x": 2,
      "y": 5,
      "z": -5,
      "name": "Furniture_Village_Crate"
    },
    {
      "x": 2,
      "y": 8,
      "z": -5,
      "name": "Wood_Softwood_Stairs",
      "rotation": 9
    },
    {
      "x": 2,
      "y": 9,
      "z": -5,
      "name": "Wood_Softwood_Roof_Flat"
    },
    {
      "x": 2,
      "y": 0,
      "z": -4,
      "name": "Wood_Softwood_Planks"
    },
    {
      "x": 2,
      "y": 8,
      "z": -4,
      "name": "Wood_Softwood_Stairs",
      "rotation": 9
    },
    {
      "x": 2,
      "y": 9,
      "z": -4,
      "name": "Wood_Softwood_Roof_Flat"
    },
    {
      "x": 2,
      "y": 0,
      "z": -3,
      "name": "Wood_Softwood_Planks"
    },
    {
      "x": 2,
      "y": 1,
      "z": -3,
      "name": "Cloth_Roof_Red_Flat"
    },
    {
      "x": 2,
      "y": 8,
      "z": -3,
      "name": "Wood_Softwood_Stairs",
      "rotation": 9
    },
    {
      "x": 2,
      "y": 9,
      "z": -3,
      "name": "Wood_Softwood_Roof_Flat"
    },
    {
      "x": 2,
      "y": 0,
      "z": -2,
      "name": "Wood_Softwood_Planks"
    },
    {
      "x": 2,
      "y": 1,
      "z": -2,
      "name": "Cloth_Roof_Red_Flat"
    },
    {
      "x": 2,
      "y": 8,
      "z": -2,
      "name": "Wood_Softwood_Stairs",
      "rotation": 9
    },
    {
      "x": 2,
      "y": 9,
      "z": -2,
      "name": "Wood_Softwood_Roof_Flat"
    },
    {
      "x": 2,
      "y": 0,
      "z": -1,
      "name": "Wood_Softwood_Planks"
    },
    {
      "x": 2,
      "y": 8,
      "z": -1,
      "name": "Wood_Softwood_Stairs",
      "rotation": 9
    },
    {
      "x": 2,
      "y": 9,
      "z": -1,
      "name": "Wood_Softwood_Roof_Flat"
    },
    {
      "x": 2,
      "y": 0,
      "z": 0,
      "name": "Wood_Softwood_Planks"
    },
    {
      "x": 2,
      "y": 1,
      "z": 0,
      "name": "Wood_Softwood_Planks_Half",
      "rotation": 8
    },
    {
      "x": 2,
      "y": 2,
      "z": 0,
      "name": "Aetherhaven_Shop_Spot",
      "components": {
        "Components": {
          "AetherhavenShopSpotBlock": {
            "SpotId": "7f2a6f8b-093e-42a0-9f7d-444de8a7386e",
            "TownId": "d87b9d18-a6de-42a7-9697-90f4c2aa0d9f",
            "PlotId": "00000000-0000-0000-0000-000000000000",
            "PlayerControlled": false,
            "LootTableId": "merchant_metal_blocks",
            "Configured": true
          },
          "PlacedByInteraction": {
            "WhoPlacedUuid": {
              "$binary": "v7RyWIT/TYKnXA2XcxdQtw==",
              "$type": "04"
            }
          }
        }
      }
    },
    {
      "x": 2,
      "y": 4,
      "z": 0,
      "name": "Wood_Beech_Trunk",
      "support": 15,
      "rotation": 5
    },
    {
      "x": 2,
      "y": 5,
      "z": 0,
      "name": "*Wood_Village_Wall_Full_State_Definitions_Bottom"
    },
    {
      "x": 2,
      "y": 6,
      "z": 0,
      "name": "*Wood_Village_Wall_Full_State_Definitions_Middle"
    },
    {
      "x": 2,
      "y": 7,
      "z": 0,
      "name": "*Wood_Village_Wall_Full_State_Definitions_Middle"
    },
    {
      "x": 2,
      "y": 8,
      "z": 0,
      "name": "*Wood_Village_Wall_Full_State_Definitions_Top"
    },
    {
      "x": 2,
      "y": 9,
      "z": 0,
      "name": "Wood_Softwood_Roof_Flat"
    },
    {
      "x": 2,
      "y": 0,
      "z": 1,
      "name": "Rock_Stone_Brick"
    },
    {
      "x": 2,
      "y": 4,
      "z": 1,
      "name": "Wood_Beech_Branch_Short",
      "support": 15
    },
    {
      "x": 2,
      "y": 5,
      "z": 1,
      "name": "Cloth_Roof_Red_Flat"
    },
    {
      "x": 2,
      "y": 8,
      "z": 1,
      "name": "Wood_Softwood_Stairs",
      "rotation": 9
    },
    {
      "x": 2,
      "y": 9,
      "z": 1,
      "name": "Wood_Softwood_Roof_Flat"
    },
    {
      "x": 2,
      "y": 0,
      "z": 2,
      "name": "Rock_Stone_Brick"
    },
    {
      "x": 2,
      "y": 5,
      "z": 2,
      "name": "Cloth_Roof_White_Flat"
    },
    {
      "x": 2,
      "y": 0,
      "z": 3,
      "name": "Rock_Stone_Brick"
    },
    {
      "x": 2,
      "y": 5,
      "z": 3,
      "name": "Cloth_Roof_Red_Flat"
    },
    {
      "x": 2,
      "y": 0,
      "z": 4,
      "name": "Rock_Stone_Brick_Smooth"
    },
    {
      "x": 2,
      "y": 4,
      "z": 4,
      "name": "Cloth_Roof_White"
    },
    {
      "x": 2,
      "y": 0,
      "z": 5,
      "name": "Rock_Stone_Cobble"
    },
    {
      "x": 2,
      "y": 3,
      "z": 5,
      "name": "Cloth_Roof_White_Flap"
    },
    {
      "x": 2,
      "y": 0,
      "z": 6,
      "name": "Rock_Stone_Cobble_Mossy"
    },
    {
      "x": 3,
      "y": 0,
      "z": -7,
      "name": "Rock_Stone_Cobble"
    },
    {
      "x": 3,
      "y": 7,
      "z": -7,
      "name": "Wood_Softwood_Stairs",
      "rotation": 9
    },
    {
      "x": 3,
      "y": 8,
      "z": -7,
      "name": "Wood_Softwood_Roof",
      "rotation": 1
    },
    {
      "x": 3,
      "y": 0,
      "z": -6,
      "name": "Rock_Stone_Cobble_Mossy"
    },
    {
      "x": 3,
      "y": 1,
      "z": -6,
      "name": "Rock_Stone_Brick"
    },
    {
      "x": 3,
      "y": 2,
      "z": -6,
      "name": "Furniture_Village_Window"
    },
    {
      "x": 3,
      "y": 3,
      "z": -6,
      "name": "Furniture_Village_Window"
    },
    {
      "x": 3,
      "y": 4,
      "z": -6,
      "name": "Wood_Beech_Trunk",
      "support": 15,
      "rotation": 5
    },
    {
      "x": 3,
      "y": 5,
      "z": -6,
      "name": "*Wood_Village_Wall_Full_State_Definitions_Bottom"
    },
    {
      "x": 3,
      "y": 6,
      "z": -6,
      "name": "*Wood_Village_Wall_Full_State_Definitions_Middle"
    },
    {
      "x": 3,
      "y": 7,
      "z": -6,
      "name": "*Wood_Village_Wall_Full_State_Definitions_Top"
    },
    {
      "x": 3,
      "y": 8,
      "z": -6,
      "name": "Wood_Softwood_Roof",
      "rotation": 1
    },
    {
      "x": 3,
      "y": 0,
      "z": -5,
      "name": "Wood_Softwood_Planks"
    },
    {
      "x": 3,
      "y": 1,
      "z": -5,
      "name": "Furniture_Tavern_Chest_Large",
      "components": {
        "Components": {
          "ItemContainerBlock": {
            "ItemContainer": {
              "Capacity": 36,
              "Items": {}
            },
            "Capacity": 36
          }
        }
      },
      "support": 15
    },
    {
      "x": 3,
      "y": 4,
      "z": -5,
      "name": "Furniture_Village_Platform",
      "support": 15,
      "rotation": 1
    },
    {
      "x": 3,
      "y": 5,
      "z": -5,
      "name": "Furniture_Village_Crate"
    },
    {
      "x": 3,
      "y": 6,
      "z": -5,
      "name": "Furniture_Tavern_Barrel",
      "support": 15
    },
    {
      "x": 3,
      "y": 7,
      "z": -5,
      "name": "Wood_Softwood_Stairs",
      "rotation": 9
    },
    {
      "x": 3,
      "y": 8,
      "z": -5,
      "name": "Wood_Softwood_Roof",
      "rotation": 1
    },
    {
      "x": 3,
      "y": 0,
      "z": -4,
      "name": "Wood_Softwood_Planks"
    },
    {
      "x": 3,
      "y": 7,
      "z": -4,
      "name": "Wood_Softwood_Stairs",
      "rotation": 9
    },
    {
      "x": 3,
      "y": 8,
      "z": -4,
      "name": "Wood_Softwood_Roof",
      "rotation": 1
    },
    {
      "x": 3,
      "y": 0,
      "z": -3,
      "name": "Wood_Softwood_Planks"
    },
    {
      "x": 3,
      "y": 4,
      "z": -3,
      "name": "Deco_Lantern_Ceiling",
      "support": 15
    },
    {
      "x": 3,
      "y": 5,
      "z": -3,
      "name": "Deco_Rope",
      "support": 15
    },
    {
      "x": 3,
      "y": 6,
      "z": -3,
      "name": "Deco_Rope",
      "support": 15
    },
    {
      "x": 3,
      "y": 7,
      "z": -3,
      "name": "Wood_Softwood_Planks"
    },
    {
      "x": 3,
      "y": 8,
      "z": -3,
      "name": "Wood_Softwood_Roof",
      "rotation": 1
    },
    {
      "x": 3,
      "y": 0,
      "z": -2,
      "name": "Wood_Softwood_Planks"
    },
    {
      "x": 3,
      "y": 7,
      "z": -2,
      "name": "Wood_Softwood_Stairs",
      "rotation": 9
    },
    {
      "x": 3,
      "y": 8,
      "z": -2,
      "name": "Wood_Softwood_Roof",
      "rotation": 1
    },
    {
      "x": 3,
      "y": 0,
      "z": -1,
      "name": "Wood_Softwood_Planks"
    },
    {
      "x": 3,
      "y": 7,
      "z": -1,
      "name": "Wood_Softwood_Stairs",
      "rotation": 9
    },
    {
      "x": 3,
      "y": 8,
      "z": -1,
      "name": "Wood_Softwood_Roof",
      "rotation": 1
    },
    {
      "x": 3,
      "y": 0,
      "z": 0,
      "name": "Wood_Softwood_Planks"
    },
    {
      "x": 3,
      "y": 1,
      "z": 0,
      "name": "Wood_Softwood_Planks_Half",
      "rotation": 8
    },
    {
      "x": 3,
      "y": 2,
      "z": 0,
      "name": "Aetherhaven_Shop_Spot",
      "components": {
        "Components": {
          "AetherhavenShopSpotBlock": {
            "SpotId": "67b25b6d-6f5c-43cf-afdb-9e3132668ceb",
            "TownId": "d87b9d18-a6de-42a7-9697-90f4c2aa0d9f",
            "PlotId": "00000000-0000-0000-0000-000000000000",
            "PlayerControlled": false,
            "LootTableId": "merchant_blocks",
            "Configured": true
          },
          "PlacedByInteraction": {
            "WhoPlacedUuid": {
              "$binary": "v7RyWIT/TYKnXA2XcxdQtw==",
              "$type": "04"
            }
          }
        }
      }
    },
    {
      "x": 3,
      "y": 4,
      "z": 0,
      "name": "Wood_Beech_Trunk",
      "support": 15,
      "rotation": 5
    },
    {
      "x": 3,
      "y": 5,
      "z": 0,
      "name": "*Wood_Village_Wall_Full_State_Definitions_Bottom"
    },
    {
      "x": 3,
      "y": 6,
      "z": 0,
      "name": "*Wood_Village_Wall_Full_State_Definitions_Middle"
    },
    {
      "x": 3,
      "y": 7,
      "z": 0,
      "name": "*Wood_Village_Wall_Full_State_Definitions_Top"
    },
    {
      "x": 3,
      "y": 8,
      "z": 0,
      "name": "Wood_Softwood_Roof",
      "rotation": 1
    },
    {
      "x": 3,
      "y": 0,
      "z": 1,
      "name": "Rock_Stone_Brick_Mossy"
    },
    {
      "x": 3,
      "y": 5,
      "z": 1,
      "name": "Cloth_Roof_White_Flat"
    },
    {
      "x": 3,
      "y": 7,
      "z": 1,
      "name": "Wood_Softwood_Stairs",
      "rotation": 9
    },
    {
      "x": 3,
      "y": 8,
      "z": 1,
      "name": "Wood_Softwood_Roof",
      "rotation": 1
    },
    {
      "x": 3,
      "y": 0,
      "z": 2,
      "name": "Rock_Stone_Brick"
    },
    {
      "x": 3,
      "y": 5,
      "z": 2,
      "name": "Cloth_Roof_Red_Flat"
    },
    {
      "x": 3,
      "y": 0,
      "z": 3,
      "name": "Rock_Stone_Brick"
    },
    {
      "x": 3,
      "y": 5,
      "z": 3,
      "name": "Cloth_Roof_White_Flat"
    },
    {
      "x": 3,
      "y": 0,
      "z": 4,
      "name": "Rock_Stone_Brick_Smooth"
    },
    {
      "x": 3,
      "y": 4,
      "z": 4,
      "name": "Cloth_Roof_Red"
    },
    {
      "x": 3,
      "y": 0,
      "z": 5,
      "name": "Rock_Stone_Cobble"
    },
    {
      "x": 3,
      "y": 3,
      "z": 5,
      "name": "Cloth_Roof_Red_Flap"
    },
    {
      "x": 3,
      "y": 0,
      "z": 6,
      "name": "Rock_Stone_Cobble"
    },
    {
      "x": 4,
      "y": 0,
      "z": -7,
      "name": "Rock_Stone_Cobble"
    },
    {
      "x": 4,
      "y": 5,
      "z": -7,
      "name": "Wood_Softwood_Stairs",
      "rotation": 9
    },
    {
      "x": 4,
      "y": 6,
      "z": -7,
      "name": "Wood_Softwood_Roof_Steep",
      "rotation": 1
    },
    {
      "x": 4,
      "y": 7,
      "z": -7,
      "name": "Wood_Softwood_Roof_Steep",
      "filler": 1024,
      "rotation": 1
    },
    {
      "x": 4,
      "y": 0,
      "z": -6,
      "name": "Rock_Stone_Cobble"
    },
    {
      "x": 4,
      "y": 1,
      "z": -6,
      "name": "Rock_Stone_Brick"
    },
    {
      "x": 4,
      "y": 2,
      "z": -6,
      "name": "*Wood_Village_Wall_Full_State_Definitions_Bottom"
    },
    {
      "x": 4,
      "y": 3,
      "z": -6,
      "name": "*Wood_Village_Wall_Full_State_Definitions_Top"
    },
    {
      "x": 4,
      "y": 4,
      "z": -6,
      "name": "Wood_Beech_Trunk",
      "support": 15,
      "rotation": 5
    },
    {
      "x": 4,
      "y": 5,
      "z": -6,
      "name": "Wood_Village_Wall_Full"
    },
    {
      "x": 4,
      "y": 6,
      "z": -6,
      "name": "Wood_Softwood_Roof_Steep",
      "rotation": 1
    },
    {
      "x": 4,
      "y": 7,
      "z": -6,
      "name": "Wood_Softwood_Roof_Steep",
      "filler": 1024,
      "rotation": 1
    },
    {
      "x": 4,
      "y": 0,
      "z": -5,
      "name": "Wood_Softwood_Planks"
    },
    {
      "x": 4,
      "y": 1,
      "z": -5,
      "name": "Furniture_Tavern_Barrel",
      "support": 15
    },
    {
      "x": 4,
      "y": 4,
      "z": -5,
      "name": "Furniture_Village_Platform",
      "support": 15,
      "rotation": 1
    },
    {
      "x": 4,
      "y": 5,
      "z": -5,
      "name": "Wood_Softwood_Stairs",
      "rotation": 9
    },
    {
      "x": 4,
      "y": 6,
      "z": -5,
      "name": "Wood_Softwood_Roof_Steep",
      "rotation": 1
    },
    {
      "x": 4,
      "y": 7,
      "z": -5,
      "name": "Wood_Softwood_Roof_Steep",
      "filler": 1024,
      "rotation": 1
    },
    {
      "x": 4,
      "y": 0,
      "z": -4,
      "name": "Wood_Softwood_Planks"
    },
    {
      "x": 4,
      "y": 5,
      "z": -4,
      "name": "Wood_Softwood_Stairs",
      "rotation": 9
    },
    {
      "x": 4,
      "y": 6,
      "z": -4,
      "name": "Wood_Softwood_Roof_Steep",
      "rotation": 1
    },
    {
      "x": 4,
      "y": 7,
      "z": -4,
      "name": "Wood_Softwood_Roof_Steep",
      "filler": 1024,
      "rotation": 1
    },
    {
      "x": 4,
      "y": 0,
      "z": -3,
      "name": "Wood_Softwood_Planks"
    },
    {
      "x": 4,
      "y": 5,
      "z": -3,
      "name": "Wood_Softwood_Stairs",
      "rotation": 9
    },
    {
      "x": 4,
      "y": 6,
      "z": -3,
      "name": "Wood_Softwood_Roof_Steep",
      "rotation": 1
    },
    {
      "x": 4,
      "y": 7,
      "z": -3,
      "name": "Wood_Softwood_Roof_Steep",
      "filler": 1024,
      "rotation": 1
    },
    {
      "x": 4,
      "y": 0,
      "z": -2,
      "name": "Wood_Softwood_Planks"
    },
    {
      "x": 4,
      "y": 1,
      "z": -2,
      "name": "Furniture_Village_Crate"
    },
    {
      "x": 4,
      "y": 2,
      "z": -2,
      "name": "Furniture_Ancient_Sack",
      "support": 15,
      "rotation": 3
    },
    {
      "x": 4,
      "y": 5,
      "z": -2,
      "name": "Wood_Softwood_Stairs",
      "rotation": 9
    },
    {
      "x": 4,
      "y": 6,
      "z": -2,
      "name": "Wood_Softwood_Roof_Steep",
      "rotation": 1
    },
    {
      "x": 4,
      "y": 7,
      "z": -2,
      "name": "Wood_Softwood_Roof_Steep",
      "filler": 1024,
      "rotation": 1
    },
    {
      "x": 4,
      "y": 0,
      "z": -1,
      "name": "Wood_Softwood_Planks"
    },
    {
      "x": 4,
      "y": 1,
      "z": -1,
      "name": "Furniture_Village_Crate"
    },
    {
      "x": 4,
      "y": 5,
      "z": -1,
      "name": "Wood_Softwood_Stairs",
      "rotation": 9
    },
    {
      "x": 4,
      "y": 6,
      "z": -1,
      "name": "Wood_Softwood_Roof_Steep",
      "rotation": 1
    },
    {
      "x": 4,
      "y": 7,
      "z": -1,
      "name": "Wood_Softwood_Roof_Steep",
      "filler": 1024,
      "rotation": 1
    },
    {
      "x": 4,
      "y": 0,
      "z": 0,
      "name": "Wood_Softwood_Planks"
    },
    {
      "x": 4,
      "y": 1,
      "z": 0,
      "name": "Wood_Softwood_Stairs",
      "rotation": 9
    },
    {
      "x": 4,
      "y": 2,
      "z": 0,
      "name": "Aetherhaven_Shop_Spot",
      "components": {
        "Components": {
          "AetherhavenShopSpotBlock": {
            "SpotId": "cc03d958-40d5-4512-973a-d2e4b152f6a6",
            "TownId": "d87b9d18-a6de-42a7-9697-90f4c2aa0d9f",
            "PlotId": "00000000-0000-0000-0000-000000000000",
            "PlayerControlled": false,
            "LootTableId": "merchant_blocks2",
            "Configured": true
          },
          "PlacedByInteraction": {
            "WhoPlacedUuid": {
              "$binary": "v7RyWIT/TYKnXA2XcxdQtw==",
              "$type": "04"
            }
          }
        }
      }
    },
    {
      "x": 4,
      "y": 3,
      "z": 0,
      "name": "Wood_Softwood_Stairs",
      "rotation": 9
    },
    {
      "x": 4,
      "y": 4,
      "z": 0,
      "name": "Wood_Beech_Trunk",
      "support": 15,
      "rotation": 5
    },
    {
      "x": 4,
      "y": 5,
      "z": 0,
      "name": "Wood_Village_Wall_Full"
    },
    {
      "x": 4,
      "y": 6,
      "z": 0,
      "name": "Wood_Softwood_Roof_Steep",
      "rotation": 1
    },
    {
      "x": 4,
      "y": 7,
      "z": 0,
      "name": "Wood_Softwood_Roof_Steep",
      "filler": 1024,
      "rotation": 1
    },
    {
      "x": 4,
      "y": 0,
      "z": 1,
      "name": "Rock_Stone_Brick"
    },
    {
      "x": 4,
      "y": 5,
      "z": 1,
      "name": "Cloth_Roof_Red_Flat"
    },
    {
      "x": 4,
      "y": 6,
      "z": 1,
      "name": "Wood_Softwood_Roof_Steep",
      "rotation": 1
    },
    {
      "x": 4,
      "y": 7,
      "z": 1,
      "name": "Wood_Softwood_Roof_Steep",
      "filler": 1024,
      "rotation": 1
    },
    {
      "x": 4,
      "y": 0,
      "z": 2,
      "name": "Rock_Stone_Brick"
    },
    {
      "x": 4,
      "y": 5,
      "z": 2,
      "name": "Cloth_Roof_White_Flat"
    },
    {
      "x": 4,
      "y": 0,
      "z": 3,
      "name": "Rock_Stone_Brick"
    },
    {
      "x": 4,
      "y": 5,
      "z": 3,
      "name": "Cloth_Roof_Red_Flat"
    },
    {
      "x": 4,
      "y": 0,
      "z": 4,
      "name": "Rock_Stone_Brick_Smooth"
    },
    {
      "x": 4,
      "y": 4,
      "z": 4,
      "name": "Cloth_Roof_White"
    },
    {
      "x": 4,
      "y": 0,
      "z": 5,
      "name": "Rock_Stone_Cobble"
    },
    {
      "x": 4,
      "y": 3,
      "z": 5,
      "name": "Cloth_Roof_White_Flap"
    },
    {
      "x": 4,
      "y": 0,
      "z": 6,
      "name": "Rock_Stone_Cobble"
    },
    {
      "x": 5,
      "y": 0,
      "z": -7,
      "name": "Rock_Stone_Cobble"
    },
    {
      "x": 5,
      "y": 3,
      "z": -7,
      "name": "Plant_Vine_Wall",
      "support": 15,
      "rotation": 2
    },
    {
      "x": 5,
      "y": 4,
      "z": -7,
      "name": "Wood_Beech_Branch_Corner",
      "support": 15,
      "rotation": 2
    },
    {
      "x": 5,
      "y": 5,
      "z": -7,
      "name": "Wood_Softwood_Roof",
      "rotation": 1
    },
    {
      "x": 5,
      "y": 0,
      "z": -6,
      "name": "Rock_Stone_Cobble"
    },
    {
      "x": 5,
      "y": 1,
      "z": -6,
      "name": "Wood_Beech_Trunk",
      "support": 15
    },
    {
      "x": 5,
      "y": 2,
      "z": -6,
      "name": "Wood_Beech_Trunk",
      "support": 15
    },
    {
      "x": 5,
      "y": 3,
      "z": -6,
      "name": "Wood_Beech_Trunk",
      "support": 15
    },
    {
      "x": 5,
      "y": 4,
      "z": -6,
      "name": "Wood_Beech_Trunk",
      "support": 15
    },
    {
      "x": 5,
      "y": 5,
      "z": -6,
      "name": "Wood_Softwood_Roof",
      "rotation": 1
    },
    {
      "x": 5,
      "y": 0,
      "z": -5,
      "name": "Rock_Stone_Cobble"
    },
    {
      "x": 5,
      "y": 1,
      "z": -5,
      "name": "Rock_Stone_Brick"
    },
    {
      "x": 5,
      "y": 2,
      "z": -5,
      "name": "*Wood_Village_Wall_Full_State_Definitions_Bottom"
    },
    {
      "x": 5,
      "y": 3,
      "z": -5,
      "name": "*Wood_Village_Wall_Full_State_Definitions_Top"
    },
    {
      "x": 5,
      "y": 4,
      "z": -5,
      "name": "Wood_Beech_Trunk",
      "support": 15,
      "rotation": 4
    },
    {
      "x": 5,
      "y": 5,
      "z": -5,
      "name": "Wood_Softwood_Roof",
      "rotation": 1
    },
    {
      "x": 5,
      "y": 0,
      "z": -4,
      "name": "Rock_Stone_Cobble"
    },
    {
      "x": 5,
      "y": 1,
      "z": -4,
      "name": "Rock_Stone_Brick"
    },
    {
      "x": 5,
      "y": 2,
      "z": -4,
      "name": "*Wood_Village_Wall_Full_State_Definitions_Bottom"
    },
    {
      "x": 5,
      "y": 3,
      "z": -4,
      "name": "*Wood_Village_Wall_Full_State_Definitions_Top"
    },
    {
      "x": 5,
      "y": 4,
      "z": -4,
      "name": "Wood_Beech_Trunk",
      "support": 15,
      "rotation": 4
    },
    {
      "x": 5,
      "y": 5,
      "z": -4,
      "name": "Wood_Softwood_Roof",
      "rotation": 1
    },
    {
      "x": 5,
      "y": 0,
      "z": -3,
      "name": "Wood_Softwood_Planks"
    },
    {
      "x": 5,
      "y": 1,
      "z": -3,
      "name": "Furniture_Village_Door",
      "rotation": 1
    },
    {
      "x": 5,
      "y": 2,
      "z": -3,
      "name": "Furniture_Village_Door",
      "filler": 1024,
      "rotation": 1
    },
    {
      "x": 5,
      "y": 3,
      "z": -3,
      "name": "Wood_Village_Wall_Full"
    },
    {
      "x": 5,
      "y": 4,
      "z": -3,
      "name": "Wood_Beech_Trunk",
      "support": 15,
      "rotation": 4
    },
    {
      "x": 5,
      "y": 5,
      "z": -3,
      "name": "Wood_Softwood_Roof",
      "rotation": 1
    },
    {
      "x": 5,
      "y": 0,
      "z": -2,
      "name": "Rock_Stone_Cobble"
    },
    {
      "x": 5,
      "y": 1,
      "z": -2,
      "name": "Rock_Stone_Brick"
    },
    {
      "x": 5,
      "y": 2,
      "z": -2,
      "name": "*Wood_Village_Wall_Full_State_Definitions_Bottom"
    },
    {
      "x": 5,
      "y": 3,
      "z": -2,
      "name": "*Wood_Village_Wall_Full_State_Definitions_Top"
    },
    {
      "x": 5,
      "y": 4,
      "z": -2,
      "name": "Wood_Beech_Trunk",
      "support": 15,
      "rotation": 4
    },
    {
      "x": 5,
      "y": 5,
      "z": -2,
      "name": "Wood_Softwood_Roof",
      "rotation": 1
    },
    {
      "x": 5,
      "y": 0,
      "z": -1,
      "name": "Rock_Stone_Cobble"
    },
    {
      "x": 5,
      "y": 1,
      "z": -1,
      "name": "Rock_Stone_Brick"
    },
    {
      "x": 5,
      "y": 2,
      "z": -1,
      "name": "*Wood_Village_Wall_Full_State_Definitions_Bottom"
    },
    {
      "x": 5,
      "y": 3,
      "z": -1,
      "name": "*Wood_Village_Wall_Full_State_Definitions_Top"
    },
    {
      "x": 5,
      "y": 4,
      "z": -1,
      "name": "Wood_Beech_Trunk",
      "support": 15,
      "rotation": 4
    },
    {
      "x": 5,
      "y": 5,
      "z": -1,
      "name": "Wood_Softwood_Roof",
      "rotation": 1
    },
    {
      "x": 5,
      "y": 0,
      "z": 0,
      "name": "Rock_Stone_Cobble_Mossy"
    },
    {
      "x": 5,
      "y": 1,
      "z": 0,
      "name": "Wood_Beech_Trunk",
      "support": 15
    },
    {
      "x": 5,
      "y": 2,
      "z": 0,
      "name": "Wood_Beech_Trunk",
      "support": 15
    },
    {
      "x": 5,
      "y": 3,
      "z": 0,
      "name": "Wood_Beech_Trunk",
      "support": 15
    },
    {
      "x": 5,
      "y": 4,
      "z": 0,
      "name": "Wood_Beech_Trunk",
      "support": 15
    },
    {
      "x": 5,
      "y": 5,
      "z": 0,
      "name": "Wood_Softwood_Roof",
      "rotation": 1
    },
    {
      "x": 5,
      "y": 0,
      "z": 1,
      "name": "Rock_Stone_Brick_Smooth"
    },
    {
      "x": 5,
      "y": 2,
      "z": 1,
      "name": "Wood_Torch_Wall",
      "support": 15
    },
    {
      "x": 5,
      "y": 4,
      "z": 1,
      "name": "Cloth_Roof_White",
      "rotation": 1
    },
    {
      "x": 5,
      "y": 5,
      "z": 1,
      "name": "Wood_Softwood_Roof_Hollow",
      "rotation": 1
    },
    {
      "x": 5,
      "y": 0,
      "z": 2,
      "name": "Rock_Stone_Brick_Smooth"
    },
    {
      "x": 5,
      "y": 4,
      "z": 2,
      "name": "Cloth_Roof_Red",
      "rotation": 1
    },
    {
      "x": 5,
      "y": 0,
      "z": 3,
      "name": "Rock_Stone_Brick_Smooth"
    },
    {
      "x": 5,
      "y": 4,
      "z": 3,
      "name": "Cloth_Roof_White",
      "rotation": 1
    },
    {
      "x": 5,
      "y": 0,
      "z": 4,
      "name": "Rock_Stone_Cobble"
    },
    {
      "x": 5,
      "y": 1,
      "z": 4,
      "name": "Wood_Beech_Trunk",
      "support": 15
    },
    {
      "x": 5,
      "y": 2,
      "z": 4,
      "name": "Wood_Softwood_Beam"
    },
    {
      "x": 5,
      "y": 3,
      "z": 4,
      "name": "Wood_Softwood_Beam"
    },
    {
      "x": 5,
      "y": 4,
      "z": 4,
      "name": "*Cloth_Roof_Red_State_Definitions_Corner_Left"
    },
    {
      "x": 5,
      "y": 0,
      "z": 5,
      "name": "Rock_Stone_Cobble"
    },
    {
      "x": 5,
      "y": 1,
      "z": 5,
      "name": "Furniture_Tavern_Planter",
      "support": 15
    },
    {
      "x": 5,
      "y": 2,
      "z": 5,
      "name": "Plant_Flower_Common_Red2",
      "support": 15
    },
    {
      "x": 5,
      "y": 3,
      "z": 5,
      "name": "Cloth_Roof_Red_Flap"
    },
    {
      "x": 5,
      "y": 0,
      "z": 6,
      "name": "Rock_Stone_Cobble_Mossy"
    },
    {
      "x": 6,
      "y": 0,
      "z": -7,
      "name": "Rock_Stone_Cobble"
    },
    {
      "x": 6,
      "y": 4,
      "z": -7,
      "name": "Wood_Softwood_Roof_Hollow",
      "rotation": 1
    },
    {
      "x": 6,
      "y": 0,
      "z": -6,
      "name": "Rock_Stone_Cobble"
    },
    {
      "x": 6,
      "y": 3,
      "z": -6,
      "name": "Wood_Beech_Branch_Corner",
      "support": 15,
      "rotation": 1
    },
    {
      "x": 6,
      "y": 4,
      "z": -6,
      "name": "Wood_Softwood_Roof",
      "rotation": 1
    },
    {
      "x": 6,
      "y": 0,
      "z": -5,
      "name": "Rock_Stone_Cobble"
    },
    {
      "x": 6,
      "y": 2,
      "z": -5,
      "name": "Plant_Vine_Wall",
      "support": 15,
      "rotation": 1
    },
    {
      "x": 6,
      "y": 4,
      "z": -5,
      "name": "Wood_Softwood_Roof_Hollow",
      "rotation": 1
    },
    {
      "x": 6,
      "y": 0,
      "z": -4,
      "name": "Rock_Stone_Cobble"
    },
    {
      "x": 6,
      "y": 4,
      "z": -4,
      "name": "Wood_Softwood_Roof_Hollow",
      "rotation": 1
    },
    {
      "x": 6,
      "y": 0,
      "z": -3,
      "name": "Rock_Stone_Cobble_Mossy"
    },
    {
      "x": 6,
      "y": 4,
      "z": -3,
      "name": "Wood_Softwood_Roof_Hollow",
      "rotation": 1
    },
    {
      "x": 6,
      "y": 0,
      "z": -2,
      "name": "Rock_Stone_Cobble_Mossy"
    },
    {
      "x": 6,
      "y": 4,
      "z": -2,
      "name": "Wood_Softwood_Roof_Hollow",
      "rotation": 1
    },
    {
      "x": 6,
      "y": 0,
      "z": -1,
      "name": "Rock_Stone_Cobble"
    },
    {
      "x": 6,
      "y": 3,
      "z": -1,
      "name": "Plant_Vine_Wall",
      "support": 15,
      "rotation": 1
    },
    {
      "x": 6,
      "y": 4,
      "z": -1,
      "name": "Wood_Softwood_Roof_Hollow",
      "rotation": 1
    },
    {
      "x": 6,
      "y": 0,
      "z": 0,
      "name": "Rock_Stone_Cobble"
    },
    {
      "x": 6,
      "y": 3,
      "z": 0,
      "name": "Wood_Beech_Branch_Corner",
      "support": 15,
      "rotation": 1
    },
    {
      "x": 6,
      "y": 4,
      "z": 0,
      "name": "Wood_Softwood_Roof",
      "rotation": 1
    },
    {
      "x": 6,
      "y": 0,
      "z": 1,
      "name": "Rock_Stone_Cobble"
    },
    {
      "x": 6,
      "y": 3,
      "z": 1,
      "name": "Cloth_Roof_White_Flap",
      "rotation": 1
    },
    {
      "x": 6,
      "y": 4,
      "z": 1,
      "name": "Wood_Softwood_Roof_Hollow",
      "rotation": 1
    },
    {
      "x": 6,
      "y": 0,
      "z": 2,
      "name": "Rock_Stone_Cobble"
    },
    {
      "x": 6,
      "y": 3,
      "z": 2,
      "name": "Cloth_Roof_Red_Flap",
      "rotation": 1
    },
    {
      "x": 6,
      "y": 0,
      "z": 3,
      "name": "Rock_Stone_Cobble_Mossy"
    },
    {
      "x": 6,
      "y": 3,
      "z": 3,
      "name": "Cloth_Roof_White_Flap",
      "rotation": 1
    },
    {
      "x": 6,
      "y": 0,
      "z": 4,
      "name": "Rock_Stone_Cobble"
    },
    {
      "x": 6,
      "y": 3,
      "z": 4,
      "name": "Cloth_Roof_Red_Flap",
      "rotation": 1
    },
    {
      "x": 6,
      "y": 0,
      "z": 5,
      "name": "Rock_Stone_Cobble"
    },
    {
      "x": 6,
      "y": 0,
      "z": 6,
      "name": "Rock_Stone_Cobble"
    }
  ]
}