{
  "version": 8,
  "blockIdVersion": 11,
  "anchorX": 0,
  "anchorY": 0,
  "anchorZ": 0,
  "blocks": [
    {
      "x": -32,
      "y": 10,
      "z": 17,
      "name": "Wood_Softwood_Stairs",
      "rotation": 9
    },
    {
      "x": -31,
      "y": 6,
      "z": 9,
      "name": "Wood_Softwood_Roof_Hollow",
      "rotation": 2
    },
    {
      "x": -31,
      "y": 6,
      "z": 10,
      "name": "Wood_Oak_Branch_Short",
      "support": 15,
      "rotation": 3
    },
    {
      "x": -31,
      "y": 7,
      "z": 10,
      "name": "Wood_Softwood_Roof_Shallow",
      "rotation": 2
    },
    {
      "x": -31,
      "y": 7,
      "z": 11,
      "name": "Wood_Softwood_Roof_Shallow",
      "filler": 32,
      "rotation": 2
    },
    {
      "x": -31,
      "y": 7,
      "z": 12,
      "name": "Wood_Softwood_Stairs",
      "rotation": 10
    },
    {
      "x": -31,
      "y": 8,
      "z": 12,
      "name": "Wood_Softwood_Roof_Shallow",
      "rotation": 2
    },
    {
      "x": -31,
      "y": 6,
      "z": 13,
      "name": "Wood_Oak_Branch_Short",
      "support": 15,
      "rotation": 3
    },
    {
      "x": -31,
      "y": 8,
      "z": 13,
      "name": "Wood_Softwood_Roof_Shallow",
      "filler": 32,
      "rotation": 2
    },
    {
      "x": -31,
      "y": 8,
      "z": 14,
      "name": "Wood_Softwood_Stairs",
      "rotation": 10
    },
    {
      "x": -31,
      "y": 9,
      "z": 14,
      "name": "Wood_Softwood_Roof_Flat",
      "rotation": 2
    },
    {
      "x": -31,
      "y": 8,
      "z": 15,
      "name": "Wood_Softwood_Planks_Half",
      "rotation": 8
    },
    {
      "x": -31,
      "y": 9,
      "z": 15,
      "name": "Wood_Softwood_Roof_Shallow",
      "rotation": 2
    },
    {
      "x": -31,
      "y": 9,
      "z": 16,
      "name": "Wood_Softwood_Roof_Shallow",
      "filler": 32,
      "rotation": 2
    },
    {
      "x": -31,
      "y": 6,
      "z": 17,
      "name": "Wood_Oak_Branch_Short",
      "support": 15,
      "rotation": 3
    },
    {
      "x": -31,
      "y": 9,
      "z": 17,
      "name": "Wood_Softwood_Planks_Half",
      "rotation": 8
    },
    {
      "x": -31,
      "y": 10,
      "z": 17,
      "name": "Wood_Softwood_Stairs",
      "rotation": 1
    },
    {
      "x": -31,
      "y": 9,
      "z": 18,
      "name": "Wood_Softwood_Roof_Shallow",
      "filler": 992
    },
    {
      "x": -31,
      "y": 8,
      "z": 19,
      "name": "Wood_Softwood_Planks_Half",
      "rotation": 8
    },
    {
      "x": -31,
      "y": 9,
      "z": 19,
      "name": "Wood_Softwood_Roof_Shallow"
    },
    {
      "x": -31,
      "y": 8,
      "z": 20,
      "name": "Wood_Softwood_Stairs",
      "rotation": 8
    },
    {
      "x": -31,
      "y": 9,
      "z": 20,
      "name": "Wood_Softwood_Roof_Flat"
    },
    {
      "x": -31,
      "y": 6,
      "z": 21,
      "name": "Wood_Oak_Branch_Short",
      "support": 15,
      "rotation": 3
    },
    {
      "x": -31,
      "y": 8,
      "z": 21,
      "name": "Wood_Softwood_Roof_Shallow",
      "filler": 992
    },
    {
      "x": -31,
      "y": 7,
      "z": 22,
      "name": "Wood_Softwood_Stairs",
      "rotation": 8
    },
    {
      "x": -31,
      "y": 8,
      "z": 22,
      "name": "Wood_Softwood_Roof_Shallow"
    },
    {
      "x": -31,
      "y": 7,
      "z": 23,
      "name": "Wood_Softwood_Roof_Shallow",
      "filler": 992
    },
    {
      "x": -31,
      "y": 6,
      "z": 24,
      "name": "Wood_Oak_Branch_Short",
      "support": 15,
      "rotation": 3
    },
    {
      "x": -31,
      "y": 7,
      "z": 24,
      "name": "Wood_Softwood_Roof_Shallow"
    },
    {
      "x": -31,
      "y": 6,
      "z": 25,
      "name": "Wood_Softwood_Roof_Hollow"
    },
    {
      "x": -30,
      "y": 6,
      "z": 9,
      "name": "Wood_Softwood_Roof_Hollow",
      "rotation": 2
    },
    {
      "x": -30,
      "y": 0,
      "z": 10,
      "name": "Wood_Oak_Trunk",
      "support": 15
    },
    {
      "x": -30,
      "y": 1,
      "z": 10,
      "name": "Wood_Oak_Trunk",
      "support": 15
    },
    {
      "x": -30,
      "y": 2,
      "z": 10,
      "name": "Wood_Oak_Trunk",
      "support": 15
    },
    {
      "x": -30,
      "y": 3,
      "z": 10,
      "name": "Wood_Oak_Trunk",
      "support": 15
    },
    {
      "x": -30,
      "y": 4,
      "z": 10,
      "name": "Wood_Oak_Trunk",
      "support": 15
    },
    {
      "x": -30,
      "y": 5,
      "z": 10,
      "name": "Wood_Oak_Trunk",
      "support": 15
    },
    {
      "x": -30,
      "y": 6,
      "z": 10,
      "name": "Wood_Oak_Trunk",
      "support": 15
    },
    {
      "x": -30,
      "y": 7,
      "z": 10,
      "name": "Wood_Softwood_Roof_Shallow",
      "rotation": 2
    },
    {
      "x": -30,
      "y": 0,
      "z": 11,
      "name": "Rock_Stone_Cobble"
    },
    {
      "x": -30,
      "y": 1,
      "z": 11,
      "name": "Rock_Stone_Cobble"
    },
    {
      "x": -30,
      "y": 2,
      "z": 11,
      "name": "Wood_Oak_Trunk",
      "support": 15,
      "rotation": 4
    },
    {
      "x": -30,
      "y": 3,
      "z": 11,
      "name": "Wood_Hardwood_Fence",
      "rotation": 3
    },
    {
      "x": -30,
      "y": 6,
      "z": 11,
      "name": "Wood_Oak_Trunk",
      "support": 15,
      "rotation": 4
    },
    {
      "x": -30,
      "y": 7,
      "z": 11,
      "name": "Wood_Softwood_Roof_Shallow",
      "filler": 32,
      "rotation": 2
    },
    {
      "x": -30,
      "y": 0,
      "z": 12,
      "name": "Rock_Stone_Brick"
    },
    {
      "x": -30,
      "y": 1,
      "z": 12,
      "name": "Rock_Stone_Cobble"
    },
    {
      "x": -30,
      "y": 2,
      "z": 12,
      "name": "Wood_Oak_Trunk",
      "support": 15,
      "rotation": 4
    },
    {
      "x": -30,
      "y": 3,
      "z": 12,
      "name": "Wood_Hardwood_Fence",
      "rotation": 3
    },
    {
      "x": -30,
      "y": 6,
      "z": 12,
      "name": "Wood_Oak_Trunk",
      "support": 15,
      "rotation": 4
    },
    {
      "x": -30,
      "y": 7,
      "z": 12,
      "name": "Wood_Softwood_Stairs",
      "rotation": 10
    },
    {
      "x": -30,
      "y": 8,
      "z": 12,
      "name": "Wood_Softwood_Roof_Shallow",
      "rotation": 2
    },
    {
      "x": -30,
      "y": 0,
      "z": 13,
      "name": "Wood_Oak_Trunk",
      "support": 15
    },
    {
      "x": -30,
      "y": 1,
      "z": 13,
      "name": "Wood_Oak_Trunk",
      "support": 15
    },
    {
      "x": -30,
      "y": 2,
      "z": 13,
      "name": "Wood_Oak_Trunk",
      "support": 15
    },
    {
      "x": -30,
      "y": 3,
      "z": 13,
      "name": "Wood_Oak_Trunk",
      "support": 15
    },
    {
      "x": -30,
      "y": 4,
      "z": 13,
      "name": "Wood_Oak_Trunk",
      "support": 15
    },
    {
      "x": -30,
      "y": 5,
      "z": 13,
      "name": "Wood_Oak_Trunk",
      "support": 15
    },
    {
      "x": -30,
      "y": 6,
      "z": 13,
      "name": "Wood_Oak_Trunk",
      "support": 15,
      "rotation": 4
    },
    {
      "x": -30,
      "y": 7,
      "z": 13,
      "name": "Wood_Oak_Trunk",
      "support": 15
    },
    {
      "x": -30,
      "y": 8,
      "z": 13,
      "name": "Wood_Softwood_Roof_Shallow",
      "filler": 32,
      "rotation": 2
    },
    {
      "x": -30,
      "y": 0,
      "z": 14,
      "name": "Rock_Stone_Cobble"
    },
    {
      "x": -30,
      "y": 1,
      "z": 14,
      "name": "Rock_Stone_Brick"
    },
    {
      "x": -30,
      "y": 2,
      "z": 14,
      "name": "Wood_Oak_Trunk",
      "support": 15,
      "rotation": 4
    },
    {
      "x": -30,
      "y": 3,
      "z": 14,
      "name": "Wood_Hardwood_Fence",
      "rotation": 3
    },
    {
      "x": -30,
      "y": 6,
      "z": 14,
      "name": "Wood_Oak_Trunk",
      "support": 15,
      "rotation": 4
    },
    {
      "x": -30,
      "y": 8,
      "z": 14,
      "name": "Wood_Softwood_Stairs",
      "rotation": 10
    },
    {
      "x": -30,
      "y": 9,
      "z": 14,
      "name": "Wood_Softwood_Roof_Flat",
      "rotation": 2
    },
    {
      "x": -30,
      "y": 0,
      "z": 15,
      "name": "Rock_Stone_Brick"
    },
    {
      "x": -30,
      "y": 1,
      "z": 15,
      "name": "Rock_Stone_Cobble"
    },
    {
      "x": -30,
      "y": 2,
      "z": 15,
      "name": "Wood_Oak_Trunk",
      "support": 15,
      "rotation": 4
    },
    {
      "x": -30,
      "y": 3,
      "z": 15,
      "name": "Wood_Hardwood_Fence",
      "rotation": 3
    },
    {
      "x": -30,
      "y": 6,
      "z": 15,
      "name": "Wood_Oak_Trunk",
      "support": 15,
      "rotation": 4
    },
    {
      "x": -30,
      "y": 8,
      "z": 15,
      "name": "Wood_Softwood_Planks_Half",
      "rotation": 8
    },
    {
      "x": -30,
      "y": 9,
      "z": 15,
      "name": "Wood_Softwood_Roof_Shallow",
      "rotation": 2
    },
    {
      "x": -30,
      "y": 0,
      "z": 16,
      "name": "Rock_Stone_Brick"
    },
    {
      "x": -30,
      "y": 1,
      "z": 16,
      "name": "Rock_Stone_Brick"
    },
    {
      "x": -30,
      "y": 2,
      "z": 16,
      "name": "Wood_Oak_Trunk",
      "support": 15,
      "rotation": 4
    },
    {
      "x": -30,
      "y": 3,
      "z": 16,
      "name": "Wood_Hardwood_Fence",
      "rotation": 3
    },
    {
      "x": -30,
      "y": 6,
      "z": 16,
      "name": "Wood_Oak_Trunk",
      "support": 15,
      "rotation": 4
    },
    {
      "x": -30,
      "y": 9,
      "z": 16,
      "name": "Wood_Softwood_Roof_Shallow",
      "filler": 32,
      "rotation": 2
    },
    {
      "x": -30,
      "y": 0,
      "z": 17,
      "name": "Rock_Stone_Cobble"
    },
    {
      "x": -30,
      "y": 1,
      "z": 17,
      "name": "Rock_Stone_Cobble"
    },
    {
      "x": -30,
      "y": 2,
      "z": 17,
      "name": "Wood_Oak_Trunk",
      "support": 15,
      "rotation": 4
    },
    {
      "x": -30,
      "y": 3,
      "z": 17,
      "name": "Wood_Hardwood_Fence",
      "rotation": 3
    },
    {
      "x": -30,
      "y": 6,
      "z": 17,
      "name": "Wood_Oak_Trunk",
      "support": 15,
      "rotation": 4
    },
    {
      "x": -30,
      "y": 9,
      "z": 17,
      "name": "Wood_Softwood_Stairs",
      "rotation": 9
    },
    {
      "x": -30,
      "y": 10,
      "z": 17,
      "name": "Wood_Softwood_Planks_Half"
    },
    {
      "x": -30,
      "y": 0,
      "z": 18,
      "name": "Rock_Stone_Cobble"
    },
    {
      "x": -30,
      "y": 1,
      "z": 18,
      "name": "Rock_Stone_Brick"
    },
    {
      "x": -30,
      "y": 2,
      "z": 18,
      "name": "Wood_Oak_Trunk",
      "support": 15,
      "rotation": 4
    },
    {
      "x": -30,
      "y": 3,
      "z": 18,
      "name": "Wood_Hardwood_Fence",
      "rotation": 3
    },
    {
      "x": -30,
      "y": 6,
      "z": 18,
      "name": "Wood_Oak_Trunk",
      "support": 15,
      "rotation": 4
    },
    {
      "x": -30,
      "y": 9,
      "z": 18,
      "name": "Wood_Softwood_Roof_Shallow",
      "filler": 992
    },
    {
      "x": -30,
      "y": 0,
      "z": 19,
      "name": "Rock_Stone_Brick"
    },
    {
      "x": -30,
      "y": 1,
      "z": 19,
      "name": "Rock_Stone_Cobble"
    },
    {
      "x": -30,
      "y": 2,
      "z": 19,
      "name": "Wood_Oak_Trunk",
      "support": 15,
      "rotation": 4
    },
    {
      "x": -30,
      "y": 3,
      "z": 19,
      "name": "Wood_Hardwood_Fence",
      "rotation": 3
    },
    {
      "x": -30,
      "y": 6,
      "z": 19,
      "name": "Wood_Oak_Trunk",
      "support": 15,
      "rotation": 4
    },
    {
      "x": -30,
      "y": 8,
      "z": 19,
      "name": "Wood_Softwood_Planks_Half",
      "rotation": 8
    },
    {
      "x": -30,
      "y": 9,
      "z": 19,
      "name": "Wood_Softwood_Roof_Shallow"
    },
    {
      "x": -30,
      "y": 0,
      "z": 20,
      "name": "Rock_Stone_Cobble"
    },
    {
      "x": -30,
      "y": 1,
      "z": 20,
      "name": "Rock_Stone_Cobble"
    },
    {
      "x": -30,
      "y": 2,
      "z": 20,
      "name": "Wood_Oak_Trunk",
      "support": 15,
      "rotation": 4
    },
    {
      "x": -30,
      "y": 3,
      "z": 20,
      "name": "Wood_Hardwood_Fence",
      "rotation": 3
    },
    {
      "x": -30,
      "y": 6,
      "z": 20,
      "name": "Wood_Oak_Trunk",
      "support": 15,
      "rotation": 4
    },
    {
      "x": -30,
      "y": 8,
      "z": 20,
      "name": "Wood_Softwood_Stairs",
      "rotation": 8
    },
    {
      "x": -30,
      "y": 9,
      "z": 20,
      "name": "Wood_Softwood_Roof_Flat"
    },
    {
      "x": -30,
      "y": 0,
      "z": 21,
      "name": "Wood_Oak_Trunk",
      "support": 15
    },
    {
      "x": -30,
      "y": 1,
      "z": 21,
      "name": "Wood_Oak_Trunk",
      "support": 15
    },
    {
      "x": -30,
      "y": 2,
      "z": 21,
      "name": "Wood_Oak_Trunk",
      "support": 15
    },
    {
      "x": -30,
      "y": 3,
      "z": 21,
      "name": "Wood_Oak_Trunk",
      "support": 15
    },
    {
      "x": -30,
      "y": 4,
      "z": 21,
      "name": "Wood_Oak_Trunk",
      "support": 15
    },
    {
      "x": -30,
      "y": 5,
      "z": 21,
      "name": "Wood_Oak_Trunk",
      "support": 15
    },
    {
      "x": -30,
      "y": 6,
      "z": 21,
      "name": "Wood_Oak_Trunk",
      "support": 15
    },
    {
      "x": -30,
      "y": 7,
      "z": 21,
      "name": "Wood_Oak_Trunk",
      "support": 15
    },
    {
      "x": -30,
      "y": 8,
      "z": 21,
      "name": "Wood_Softwood_Roof_Shallow",
      "filler": 992
    },
    {
      "x": -30,
      "y": 0,
      "z": 22,
      "name": "Rock_Stone_Cobble"
    },
    {
      "x": -30,
      "y": 1,
      "z": 22,
      "name": "Rock_Stone_Cobble"
    },
    {
      "x": -30,
      "y": 2,
      "z": 22,
      "name": "Wood_Oak_Trunk",
      "support": 15,
      "rotation": 4
    },
    {
      "x": -30,
      "y": 3,
      "z": 22,
      "name": "Wood_Hardwood_Fence",
      "rotation": 3
    },
    {
      "x": -30,
      "y": 6,
      "z": 22,
      "name": "Wood_Oak_Trunk",
      "support": 15,
      "rotation": 4
    },
    {
      "x": -30,
      "y": 7,
      "z": 22,
      "name": "Wood_Softwood_Stairs",
      "rotation": 8
    },
    {
      "x": -30,
      "y": 8,
      "z": 22,
      "name": "Wood_Softwood_Roof_Shallow"
    },
    {
      "x": -30,
      "y": 0,
      "z": 23,
      "name": "Rock_Stone_Brick"
    },
    {
      "x": -30,
      "y": 1,
      "z": 23,
      "name": "Rock_Stone_Cobble"
    },
    {
      "x": -30,
      "y": 2,
      "z": 23,
      "name": "Wood_Oak_Trunk",
      "support": 15,
      "rotation": 4
    },
    {
      "x": -30,
      "y": 3,
      "z": 23,
      "name": "Wood_Hardwood_Fence",
      "rotation": 3
    },
    {
      "x": -30,
      "y": 6,
      "z": 23,
      "name": "Wood_Oak_Trunk",
      "support": 15,
      "rotation": 4
    },
    {
      "x": -30,
      "y": 7,
      "z": 23,
      "name": "Wood_Softwood_Roof_Shallow",
      "filler": 992
    },
    {
      "x": -30,
      "y": 0,
      "z": 24,
      "name": "Wood_Oak_Trunk",
      "support": 15
    },
    {
      "x": -30,
      "y": 1,
      "z": 24,
      "name": "Wood_Oak_Trunk",
      "support": 15
    },
    {
      "x": -30,
      "y": 2,
      "z": 24,
      "name": "Wood_Oak_Trunk",
      "support": 15
    },
    {
      "x": -30,
      "y": 3,
      "z": 24,
      "name": "Wood_Oak_Trunk",
      "support": 15
    },
    {
      "x": -30,
      "y": 4,
      "z": 24,
      "name": "Wood_Oak_Trunk",
      "support": 15
    },
    {
      "x": -30,
      "y": 5,
      "z": 24,
      "name": "Wood_Oak_Trunk",
      "support": 15
    },
    {
      "x": -30,
      "y": 6,
      "z": 24,
      "name": "Wood_Oak_Trunk",
      "support": 15
    },
    {
      "x": -30,
      "y": 7,
      "z": 24,
      "name": "Wood_Softwood_Roof_Shallow"
    },
    {
      "x": -30,
      "y": 6,
      "z": 25,
      "name": "Wood_Softwood_Roof_Hollow"
    },
    {
      "x": -29,
      "y": 6,
      "z": 9,
      "name": "Wood_Softwood_Roof_Hollow",
      "rotation": 2
    },
    {
      "x": -29,
      "y": 0,
      "z": 10,
      "name": "Rock_Stone_Brick"
    },
    {
      "x": -29,
      "y": 1,
      "z": 10,
      "name": "Rock_Stone_Cobble"
    },
    {
      "x": -29,
      "y": 2,
      "z": 10,
      "name": "Wood_Oak_Trunk",
      "support": 15,
      "rotation": 5
    },
    {
      "x": -29,
      "y": 3,
      "z": 10,
      "name": "Wood_Hardwood_Fence",
      "rotation": 2
    },
    {
      "x": -29,
      "y": 6,
      "z": 10,
      "name": "Wood_Oak_Trunk",
      "support": 15,
      "rotation": 5
    },
    {
      "x": -29,
      "y": 7,
      "z": 10,
      "name": "Wood_Softwood_Roof_Shallow",
      "rotation": 2
    },
    {
      "x": -29,
      "y": 2,
      "z": 11,
      "name": "Rock_Stone_Cobble"
    },
    {
      "x": -29,
      "y": 3,
      "z": 11,
      "name": "Wood_Oak_Trunk",
      "support": 15
    },
    {
      "x": -29,
      "y": 4,
      "z": 11,
      "name": "Wood_Oak_Trunk",
      "support": 15
    },
    {
      "x": -29,
      "y": 5,
      "z": 11,
      "name": "Wood_Oak_Trunk",
      "support": 15
    },
    {
      "x": -29,
      "y": 6,
      "z": 11,
      "name": "Wood_Oak_Trunk",
      "support": 15
    },
    {
      "x": -29,
      "y": 7,
      "z": 11,
      "name": "Wood_Softwood_Roof_Shallow",
      "filler": 32,
      "rotation": 2
    },
    {
      "x": -29,
      "y": 2,
      "z": 12,
      "name": "Rock_Stone_Cobble"
    },
    {
      "x": -29,
      "y": 7,
      "z": 12,
      "name": "Wood_Softwood_Stairs",
      "rotation": 10
    },
    {
      "x": -29,
      "y": 8,
      "z": 12,
      "name": "Wood_Softwood_Roof_Shallow",
      "rotation": 2
    },
    {
      "x": -29,
      "y": 2,
      "z": 13,
      "name": "Rock_Stone_Cobble"
    },
    {
      "x": -29,
      "y": 8,
      "z": 13,
      "name": "Wood_Softwood_Roof_Shallow",
      "filler": 32,
      "rotation": 2
    },
    {
      "x": -29,
      "y": 2,
      "z": 14,
      "name": "Rock_Stone_Cobble"
    },
    {
      "x": -29,
      "y": 8,
      "z": 14,
      "name": "Wood_Softwood_Stairs",
      "rotation": 10
    },
    {
      "x": -29,
      "y": 9,
      "z": 14,
      "name": "Wood_Softwood_Roof_Flat",
      "rotation": 2
    },
    {
      "x": -29,
      "y": 2,
      "z": 15,
      "name": "Rock_Stone_Cobble"
    },
    {
      "x": -29,
      "y": 8,
      "z": 15,
      "name": "Wood_Softwood_Planks_Half",
      "rotation": 8
    },
    {
      "x": -29,
      "y": 9,
      "z": 15,
      "name": "Wood_Softwood_Roof_Shallow",
      "rotation": 2
    },
    {
      "x": -29,
      "y": 2,
      "z": 16,
      "name": "Rock_Stone_Cobble"
    },
    {
      "x": -29,
      "y": 9,
      "z": 16,
      "name": "Wood_Softwood_Roof_Shallow",
      "filler": 32,
      "rotation": 2
    },
    {
      "x": -29,
      "y": 2,
      "z": 17,
      "name": "Rock_Stone_Cobble"
    },
    {
      "x": -29,
      "y": 3,
      "z": 17,
      "name": "Wood_Oak_Trunk",
      "support": 15
    },
    {
      "x": -29,
      "y": 4,
      "z": 17,
      "name": "Wood_Oak_Trunk",
      "support": 15
    },
    {
      "x": -29,
      "y": 5,
      "z": 17,
      "name": "Wood_Oak_Trunk",
      "support": 15
    },
    {
      "x": -29,
      "y": 6,
      "z": 17,
      "name": "Wood_Oak_Trunk",
      "support": 15
    },
    {
      "x": -29,
      "y": 7,
      "z": 17,
      "name": "Wood_Oak_Trunk",
      "support": 15
    },
    {
      "x": -29,
      "y": 8,
      "z": 17,
      "name": "Wood_Oak_Trunk",
      "support": 15
    },
    {
      "x": -29,
      "y": 9,
      "z": 17,
      "name": "Wood_Oak_Trunk",
      "support": 15
    },
    {
      "x": -29,
      "y": 10,
      "z": 17,
      "name": "Wood_Softwood_Planks_Half"
    },
    {
      "x": -29,
      "y": 2,
      "z": 18,
      "name": "Rock_Stone_Cobble"
    },
    {
      "x": -29,
      "y": 9,
      "z": 18,
      "name": "Wood_Softwood_Roof_Shallow",
      "filler": 992
    },
    {
      "x": -29,
      "y": 2,
      "z": 19,
      "name": "Rock_Stone_Cobble"
    },
    {
      "x": -29,
      "y": 8,
      "z": 19,
      "name": "Wood_Softwood_Planks_Half",
      "rotation": 8
    },
    {
      "x": -29,
      "y": 9,
      "z": 19,
      "name": "Wood_Softwood_Roof_Shallow"
    },
    {
      "x": -29,
      "y": 2,
      "z": 20,
      "name": "Rock_Stone_Cobble"
    },
    {
      "x": -29,
      "y": 8,
      "z": 20,
      "name": "Wood_Softwood_Stairs",
      "rotation": 8
    },
    {
      "x": -29,
      "y": 9,
      "z": 20,
      "name": "Wood_Softwood_Roof_Flat"
    },
    {
      "x": -29,
      "y": 2,
      "z": 21,
      "name": "Rock_Stone_Cobble"
    },
    {
      "x": -29,
      "y": 8,
      "z": 21,
      "name": "Wood_Softwood_Roof_Shallow",
      "filler": 992
    },
    {
      "x": -29,
      "y": 2,
      "z": 22,
      "name": "Rock_Stone_Cobble"
    },
    {
      "x": -29,
      "y": 7,
      "z": 22,
      "name": "Wood_Softwood_Stairs",
      "rotation": 8
    },
    {
      "x": -29,
      "y": 8,
      "z": 22,
      "name": "Wood_Softwood_Roof_Shallow"
    },
    {
      "x": -29,
      "y": 2,
      "z": 23,
      "name": "Rock_Stone_Cobble"
    },
    {
      "x": -29,
      "y": 3,
      "z": 23,
      "name": "Wood_Oak_Trunk",
      "support": 15
    },
    {
      "x": -29,
      "y": 4,
      "z": 23,
      "name": "Wood_Oak_Trunk",
      "support": 15
    },
    {
      "x": -29,
      "y": 5,
      "z": 23,
      "name": "Wood_Oak_Trunk",
      "support": 15
    },
    {
      "x": -29,
      "y": 6,
      "z": 23,
      "name": "Wood_Oak_Trunk",
      "support": 15
    },
    {
      "x": -29,
      "y": 7,
      "z": 23,
      "name": "Wood_Softwood_Roof_Shallow",
      "filler": 992
    },
    {
      "x": -29,
      "y": 0,
      "z": 24,
      "name": "Rock_Stone_Brick"
    },
    {
      "x": -29,
      "y": 1,
      "z": 24,
      "name": "Rock_Stone_Cobble"
    },
    {
      "x": -29,
      "y": 2,
      "z": 24,
      "name": "Wood_Oak_Trunk",
      "support": 15,
      "rotation": 5
    },
    {
      "x": -29,
      "y": 3,
      "z": 24,
      "name": "Wood_Hardwood_Fence"
    },
    {
      "x": -29,
      "y": 6,
      "z": 24,
      "name": "Wood_Oak_Trunk",
      "support": 15,
      "rotation": 5
    },
    {
      "x": -29,
      "y": 7,
      "z": 24,
      "name": "Wood_Softwood_Roof_Shallow"
    },
    {
      "x": -29,
      "y": 6,
      "z": 25,
      "name": "Wood_Softwood_Roof_Hollow"
    },
    {
      "x": -29,
      "y": 13,
      "z": 28,
      "name": "Wood_Softwood_Stairs",
      "rotation": 9
    },
    {
      "x": -28,
      "y": 6,
      "z": 9,
      "name": "Wood_Softwood_Roof_Hollow",
      "rotation": 2
    },
    {
      "x": -28,
      "y": 0,
      "z": 10,
      "name": "Rock_Stone_Brick"
    },
    {
      "x": -28,
      "y": 1,
      "z": 10,
      "name": "Rock_Stone_Cobble"
    },
    {
      "x": -28,
      "y": 2,
      "z": 10,
      "name": "Wood_Oak_Trunk",
      "support": 15,
      "rotation": 5
    },
    {
      "x": -28,
      "y": 3,
      "z": 10,
      "name": "Wood_Hardwood_Fence",
      "rotation": 2
    },
    {
      "x": -28,
      "y": 6,
      "z": 10,
      "name": "Wood_Oak_Trunk",
      "support": 15,
      "rotation": 5
    },
    {
      "x": -28,
      "y": 7,
      "z": 10,
      "name": "Wood_Softwood_Roof_Shallow",
      "rotation": 2
    },
    {
      "x": -28,
      "y": 2,
      "z": 11,
      "name": "Rock_Stone_Cobble"
    },
    {
      "x": -28,
      "y": 6,
      "z": 11,
      "name": "Wood_Softwood_Planks_Half",
      "rotation": 8
    },
    {
      "x": -28,
      "y": 7,
      "z": 11,
      "name": "Wood_Softwood_Roof_Shallow",
      "filler": 32,
      "rotation": 2
    },
    {
      "x": -28,
      "y": 2,
      "z": 12,
      "name": "Rock_Stone_Cobble"
    },
    {
      "x": -28,
      "y": 7,
      "z": 12,
      "name": "Wood_Softwood_Stairs",
      "rotation": 10
    },
    {
      "x": -28,
      "y": 8,
      "z": 12,
      "name": "Wood_Softwood_Roof_Shallow",
      "rotation": 2
    },
    {
      "x": -28,
      "y": 2,
      "z": 13,
      "name": "Rock_Stone_Cobble"
    },
    {
      "x": -28,
      "y": 8,
      "z": 13,
      "name": "Wood_Softwood_Roof_Shallow",
      "filler": 32,
      "rotation": 2
    },
    {
      "x": -28,
      "y": 2,
      "z": 14,
      "name": "Rock_Stone_Cobble"
    },
    {
      "x": -28,
      "y": 8,
      "z": 14,
      "name": "Wood_Softwood_Stairs",
      "rotation": 10
    },
    {
      "x": -28,
      "y": 9,
      "z": 14,
      "name": "Wood_Softwood_Roof_Flat",
      "rotation": 2
    },
    {
      "x": -28,
      "y": 2,
      "z": 15,
      "name": "Rock_Stone_Cobble"
    },
    {
      "x": -28,
      "y": 8,
      "z": 15,
      "name": "Wood_Softwood_Planks_Half",
      "rotation": 8
    },
    {
      "x": -28,
      "y": 9,
      "z": 15,
      "name": "Wood_Softwood_Roof_Shallow",
      "rotation": 2
    },
    {
      "x": -28,
      "y": 2,
      "z": 16,
      "name": "Rock_Stone_Cobble"
    },
    {
      "x": -28,
      "y": 9,
      "z": 16,
      "name": "Wood_Softwood_Roof_Shallow",
      "filler": 32,
      "rotation": 2
    },
    {
      "x": -28,
      "y": 2,
      "z": 17,
      "name": "Rock_Stone_Cobble"
    },
    {
      "x": -28,
      "y": 9,
      "z": 17,
      "name": "Wood_Softwood_Planks"
    },
    {
      "x": -28,
      "y": 10,
      "z": 17,
      "name": "Wood_Softwood_Planks_Half"
    },
    {
      "x": -28,
      "y": 2,
      "z": 18,
      "name": "Rock_Stone_Cobble"
    },
    {
      "x": -28,
      "y": 9,
      "z": 18,
      "name": "Wood_Softwood_Roof_Shallow",
      "filler": 992
    },
    {
      "x": -28,
      "y": 2,
      "z": 19,
      "name": "Rock_Stone_Cobble"
    },
    {
      "x": -28,
      "y": 8,
      "z": 19,
      "name": "Wood_Softwood_Planks_Half",
      "rotation": 8
    },
    {
      "x": -28,
      "y": 9,
      "z": 19,
      "name": "Wood_Softwood_Roof_Shallow"
    },
    {
      "x": -28,
      "y": 2,
      "z": 20,
      "name": "Rock_Stone_Cobble"
    },
    {
      "x": -28,
      "y": 3,
      "z": 20,
      "name": "Wood_Oak_Trunk",
      "support": 15,
      "rotation": 5
    },
    {
      "x": -28,
      "y": 8,
      "z": 20,
      "name": "Wood_Softwood_Stairs",
      "rotation": 8
    },
    {
      "x": -28,
      "y": 9,
      "z": 20,
      "name": "Wood_Softwood_Roof_Flat"
    },
    {
      "x": -28,
      "y": 2,
      "z": 21,
      "name": "Rock_Stone_Cobble"
    },
    {
      "x": -28,
      "y": 8,
      "z": 21,
      "name": "Wood_Softwood_Roof_Shallow",
      "filler": 992
    },
    {
      "x": -28,
      "y": 2,
      "z": 22,
      "name": "Rock_Stone_Cobble"
    },
    {
      "x": -28,
      "y": 7,
      "z": 22,
      "name": "Wood_Softwood_Stairs",
      "rotation": 8
    },
    {
      "x": -28,
      "y": 8,
      "z": 22,
      "name": "Wood_Softwood_Roof_Shallow"
    },
    {
      "x": -28,
      "y": 2,
      "z": 23,
      "name": "Rock_Stone_Cobble"
    },
    {
      "x": -28,
      "y": 6,
      "z": 23,
      "name": "Wood_Softwood_Planks_Half",
      "rotation": 8
    },
    {
      "x": -28,
      "y": 7,
      "z": 23,
      "name": "Wood_Softwood_Planks"
    },
    {
      "x": -28,
      "y": 8,
      "z": 23,
      "name": "Wood_Softwood_Roof_Flat"
    },
    {
      "x": -28,
      "y": 0,
      "z": 24,
      "name": "Rock_Stone_Brick"
    },
    {
      "x": -28,
      "y": 1,
      "z": 24,
      "name": "Rock_Stone_Cobble"
    },
    {
      "x": -28,
      "y": 2,
      "z": 24,
      "name": "Wood_Oak_Trunk",
      "support": 15,
      "rotation": 5
    },
    {
      "x": -28,
      "y": 3,
      "z": 24,
      "name": "Wood_Hardwood_Fence"
    },
    {
      "x": -28,
      "y": 6,
      "z": 24,
      "name": "Wood_Oak_Trunk",
      "support": 15,
      "rotation": 5
    },
    {
      "x": -28,
      "y": 7,
      "z": 24,
      "name": "Wood_Softwood_Roof"
    },
    {
      "x": -28,
      "y": 8,
      "z": 24,
      "name": "Wood_Softwood_Roof_Hollow",
      "rotation": 2
    },
    {
      "x": -28,
      "y": 6,
      "z": 25,
      "name": "Wood_Softwood_Roof_Hollow"
    },
    {
      "x": -28,
      "y": 8,
      "z": 25,
      "name": "Wood_Softwood_Stairs",
      "rotation": 10
    },
    {
      "x": -28,
      "y": 9,
      "z": 25,
      "name": "Wood_Softwood_Roof_Steep",
      "rotation": 2
    },
    {
      "x": -28,
      "y": 10,
      "z": 25,
      "name": "Wood_Softwood_Roof_Steep",
      "filler": 1024,
      "rotation": 2
    },
    {
      "x": -28,
      "y": 10,
      "z": 26,
      "name": "Wood_Softwood_Stairs",
      "rotation": 10
    },
    {
      "x": -28,
      "y": 11,
      "z": 26,
      "name": "Wood_Softwood_Roof",
      "rotation": 2
    },
    {
      "x": -28,
      "y": 11,
      "z": 27,
      "name": "Wood_Softwood_Stairs",
      "rotation": 10
    },
    {
      "x": -28,
      "y": 12,
      "z": 27,
      "name": "Wood_Softwood_Roof",
      "rotation": 2
    },
    {
      "x": -28,
      "y": 6,
      "z": 28,
      "name": "Wood_Oak_Branch_Short",
      "support": 15,
      "rotation": 3
    },
    {
      "x": -28,
      "y": 10,
      "z": 28,
      "name": "Wood_Oak_Branch_Short",
      "support": 15,
      "rotation": 3
    },
    {
      "x": -28,
      "y": 12,
      "z": 28,
      "name": "Wood_Softwood_Stairs",
      "rotation": 9
    },
    {
      "x": -28,
      "y": 13,
      "z": 28,
      "name": "Wood_Softwood_Stairs",
      "rotation": 1
    },
    {
      "x": -28,
      "y": 11,
      "z": 29,
      "name": "Wood_Softwood_Stairs",
      "rotation": 8
    },
    {
      "x": -28,
      "y": 12,
      "z": 29,
      "name": "Wood_Softwood_Roof"
    },
    {
      "x": -28,
      "y": 10,
      "z": 30,
      "name": "Wood_Softwood_Stairs",
      "rotation": 8
    },
    {
      "x": -28,
      "y": 11,
      "z": 30,
      "name": "Wood_Softwood_Roof"
    },
    {
      "x": -28,
      "y": 8,
      "z": 31,
      "name": "Wood_Softwood_Stairs",
      "rotation": 8
    },
    {
      "x": -28,
      "y": 9,
      "z": 31,
      "name": "Wood_Softwood_Roof_Steep"
    },
    {
      "x": -28,
      "y": 10,
      "z": 31,
      "name": "Wood_Softwood_Roof_Steep",
      "filler": 1024
    },
    {
      "x": -28,
      "y": 6,
      "z": 32,
      "name": "Wood_Oak_Branch_Short",
      "support": 15,
      "rotation": 3
    },
    {
      "x": -28,
      "y": 7,
      "z": 32,
      "name": "Wood_Softwood_Roof_Steep"
    },
    {
      "x": -28,
      "y": 8,
      "z": 32,
      "name": "Wood_Softwood_Roof_Steep",
      "filler": 1024
    },
    {
      "x": -28,
      "y": 6,
      "z": 33,
      "name": "Wood_Softwood_Roof_Hollow"
    },
    {
      "x": -27,
      "y": 6,
      "z": 9,
      "name": "Wood_Softwood_Roof_Hollow",
      "rotation": 2
    },
    {
      "x": -27,
      "y": 0,
      "z": 10,
      "name": "Rock_Stone_Cobble"
    },
    {
      "x": -27,
      "y": 1,
      "z": 10,
      "name": "Rock_Stone_Brick"
    },
    {
      "x": -27,
      "y": 2,
      "z": 10,
      "name": "Wood_Oak_Trunk",
      "support": 15,
      "rotation": 5
    },
    {
      "x": -27,
      "y": 3,
      "z": 10,
      "name": "Wood_Hardwood_Fence",
      "rotation": 2
    },
    {
      "x": -27,
      "y": 6,
      "z": 10,
      "name": "Wood_Oak_Trunk",
      "support": 15,
      "rotation": 5
    },
    {
      "x": -27,
      "y": 7,
      "z": 10,
      "name": "Wood_Softwood_Roof_Shallow",
      "rotation": 2
    },
    {
      "x": -27,
      "y": 2,
      "z": 11,
      "name": "Rock_Stone_Cobble"
    },
    {
      "x": -27,
      "y": 3,
      "z": 11,
      "name": "Wood_Beech_Trunk",
      "support": 15,
      "rotation": 4
    },
    {
      "x": -27,
      "y": 6,
      "z": 11,
      "name": "Wood_Softwood_Planks_Half",
      "rotation": 8
    },
    {
      "x": -27,
      "y": 7,
      "z": 11,
      "name": "Wood_Softwood_Roof_Shallow",
      "filler": 32,
      "rotation": 2
    },
    {
      "x": -27,
      "y": 2,
      "z": 12,
      "name": "Rock_Stone_Cobble"
    },
    {
      "x": -27,
      "y": 3,
      "z": 12,
      "name": "Wood_Beech_Trunk",
      "support": 15,
      "rotation": 4
    },
    {
      "x": -27,
      "y": 7,
      "z": 12,
      "name": "Wood_Softwood_Stairs",
      "rotation": 10
    },
    {
      "x": -27,
      "y": 8,
      "z": 12,
      "name": "Wood_Softwood_Roof_Shallow",
      "rotation": 2
    },
    {
      "x": -27,
      "y": 2,
      "z": 13,
      "name": "Rock_Stone_Cobble"
    },
    {
      "x": -27,
      "y": 3,
      "z": 13,
      "name": "Wood_Beech_Trunk",
      "support": 15,
      "rotation": 4
    },
    {
      "x": -27,
      "y": 8,
      "z": 13,
      "name": "Wood_Softwood_Roof_Shallow",
      "filler": 32,
      "rotation": 2
    },
    {
      "x": -27,
      "y": 2,
      "z": 14,
      "name": "Rock_Stone_Cobble"
    },
    {
      "x": -27,
      "y": 3,
      "z": 14,
      "name": "Wood_Beech_Trunk",
      "support": 15,
      "rotation": 4
    },
    {
      "x": -27,
      "y": 8,
      "z": 14,
      "name": "Wood_Softwood_Stairs",
      "rotation": 10
    },
    {
      "x": -27,
      "y": 9,
      "z": 14,
      "name": "Wood_Softwood_Roof_Flat",
      "rotation": 2
    },
    {
      "x": -27,
      "y": 2,
      "z": 15,
      "name": "Rock_Stone_Cobble"
    },
    {
      "x": -27,
      "y": 3,
      "z": 15,
      "name": "Wood_Beech_Trunk",
      "support": 15,
      "rotation": 4
    },
    {
      "x": -27,
      "y": 8,
      "z": 15,
      "name": "Wood_Softwood_Planks_Half",
      "rotation": 8
    },
    {
      "x": -27,
      "y": 9,
      "z": 15,
      "name": "Wood_Softwood_Roof_Shallow",
      "rotation": 2
    },
    {
      "x": -27,
      "y": 2,
      "z": 16,
      "name": "Rock_Stone_Cobble"
    },
    {
      "x": -27,
      "y": 3,
      "z": 16,
      "name": "Wood_Beech_Trunk",
      "support": 15,
      "rotation": 4
    },
    {
      "x": -27,
      "y": 9,
      "z": 16,
      "name": "Wood_Softwood_Roof_Shallow",
      "filler": 32,
      "rotation": 2
    },
    {
      "x": -27,
      "y": 2,
      "z": 17,
      "name": "Rock_Stone_Cobble"
    },
    {
      "x": -27,
      "y": 9,
      "z": 17,
      "name": "Wood_Softwood_Planks"
    },
    {
      "x": -27,
      "y": 10,
      "z": 17,
      "name": "Wood_Softwood_Planks_Half"
    },
    {
      "x": -27,
      "y": 2,
      "z": 18,
      "name": "Rock_Stone_Cobble"
    },
    {
      "x": -27,
      "y": 9,
      "z": 18,
      "name": "Wood_Softwood_Roof_Shallow",
      "filler": 992
    },
    {
      "x": -27,
      "y": 2,
      "z": 19,
      "name": "Rock_Stone_Cobble"
    },
    {
      "x": -27,
      "y": 3,
      "z": 19,
      "name": "Wood_Beech_Trunk",
      "support": 15,
      "rotation": 5
    },
    {
      "x": -27,
      "y": 8,
      "z": 19,
      "name": "Wood_Softwood_Planks_Half",
      "rotation": 8
    },
    {
      "x": -27,
      "y": 9,
      "z": 19,
      "name": "Wood_Softwood_Roof_Shallow"
    },
    {
      "x": -27,
      "y": 2,
      "z": 20,
      "name": "Rock_Stone_Cobble"
    },
    {
      "x": -27,
      "y": 3,
      "z": 20,
      "name": "Wood_Oak_Trunk",
      "support": 15,
      "rotation": 5
    },
    {
      "x": -27,
      "y": 4,
      "z": 20,
      "name": "Wood_Beech_Trunk",
      "support": 15,
      "rotation": 5
    },
    {
      "x": -27,
      "y": 8,
      "z": 20,
      "name": "Wood_Softwood_Stairs",
      "rotation": 8
    },
    {
      "x": -27,
      "y": 9,
      "z": 20,
      "name": "Wood_Softwood_Roof_Flat"
    },
    {
      "x": -27,
      "y": 2,
      "z": 21,
      "name": "Rock_Stone_Cobble"
    },
    {
      "x": -27,
      "y": 3,
      "z": 21,
      "name": "Wood_Ash_Trunk",
      "support": 15,
      "rotation": 5
    },
    {
      "x": -27,
      "y": 8,
      "z": 21,
      "name": "Wood_Softwood_Roof_Shallow",
      "filler": 992
    },
    {
      "x": -27,
      "y": 2,
      "z": 22,
      "name": "Rock_Stone_Cobble"
    },
    {
      "x": -27,
      "y": 7,
      "z": 22,
      "name": "Wood_Softwood_Stairs",
      "rotation": 8
    },
    {
      "x": -27,
      "y": 8,
      "z": 22,
      "name": "Wood_Softwood_Roof_Shallow"
    },
    {
      "x": -27,
      "y": 2,
      "z": 23,
      "name": "Rock_Stone_Cobble"
    },
    {
      "x": -27,
      "y": 5,
      "z": 23,
      "name": "Wood_Torch_Wall",
      "rotation": 2
    },
    {
      "x": -27,
      "y": 6,
      "z": 23,
      "name": "Wood_Softwood_Stairs",
      "rotation": 8
    },
    {
      "x": -27,
      "y": 7,
      "z": 23,
      "name": "Wood_Softwood_Planks"
    },
    {
      "x": -27,
      "y": 8,
      "z": 23,
      "name": "Wood_Softwood_Roof_Flat"
    },
    {
      "x": -27,
      "y": 0,
      "z": 24,
      "name": "Wood_Oak_Trunk",
      "support": 15
    },
    {
      "x": -27,
      "y": 1,
      "z": 24,
      "name": "Wood_Oak_Trunk",
      "support": 15
    },
    {
      "x": -27,
      "y": 2,
      "z": 24,
      "name": "Wood_Oak_Trunk",
      "support": 15
    },
    {
      "x": -27,
      "y": 3,
      "z": 24,
      "name": "Wood_Oak_Trunk",
      "support": 15
    },
    {
      "x": -27,
      "y": 4,
      "z": 24,
      "name": "Wood_Oak_Trunk",
      "support": 15
    },
    {
      "x": -27,
      "y": 5,
      "z": 24,
      "name": "Wood_Oak_Trunk",
      "support": 15
    },
    {
      "x": -27,
      "y": 6,
      "z": 24,
      "name": "Wood_Oak_Trunk",
      "support": 15
    },
    {
      "x": -27,
      "y": 7,
      "z": 24,
      "name": "Wood_Oak_Trunk",
      "support": 15
    },
    {
      "x": -27,
      "y": 8,
      "z": 24,
      "name": "Wood_Softwood_Roof",
      "rotation": 2
    },
    {
      "x": -27,
      "y": 6,
      "z": 25,
      "name": "Wood_Oak_Trunk",
      "support": 15,
      "rotation": 4
    },
    {
      "x": -27,
      "y": 8,
      "z": 25,
      "name": "Wood_Softwood_Stairs",
      "rotation": 10
    },
    {
      "x": -27,
      "y": 9,
      "z": 25,
      "name": "Wood_Softwood_Roof_Steep",
      "rotation": 2
    },
    {
      "x": -27,
      "y": 10,
      "z": 25,
      "name": "Wood_Softwood_Roof_Steep",
      "filler": 1024,
      "rotation": 2
    },
    {
      "x": -27,
      "y": 6,
      "z": 26,
      "name": "Wood_Oak_Trunk",
      "support": 15,
      "rotation": 4
    },
    {
      "x": -27,
      "y": 10,
      "z": 26,
      "name": "Wood_Oak_Trunk",
      "support": 15,
      "rotation": 4
    },
    {
      "x": -27,
      "y": 11,
      "z": 26,
      "name": "Wood_Softwood_Roof",
      "rotation": 2
    },
    {
      "x": -27,
      "y": 6,
      "z": 27,
      "name": "Wood_Oak_Trunk",
      "support": 15,
      "rotation": 4
    },
    {
      "x": -27,
      "y": 10,
      "z": 27,
      "name": "Wood_Oak_Trunk",
      "support": 15,
      "rotation": 4
    },
    {
      "x": -27,
      "y": 11,
      "z": 27,
      "name": "Wood_Softwood_Stairs",
      "rotation": 10
    },
    {
      "x": -27,
      "y": 12,
      "z": 27,
      "name": "Wood_Softwood_Roof",
      "rotation": 2
    },
    {
      "x": -27,
      "y": 6,
      "z": 28,
      "name": "Wood_Oak_Trunk",
      "support": 15,
      "rotation": 4
    },
    {
      "x": -27,
      "y": 10,
      "z": 28,
      "name": "Wood_Oak_Trunk",
      "support": 15,
      "rotation": 4
    },
    {
      "x": -27,
      "y": 12,
      "z": 28,
      "name": "Wood_Softwood_Planks"
    },
    {
      "x": -27,
      "y": 13,
      "z": 28,
      "name": "Wood_Softwood_Planks_Half"
    },
    {
      "x": -27,
      "y": 6,
      "z": 29,
      "name": "Wood_Oak_Trunk",
      "support": 15,
      "rotation": 4
    },
    {
      "x": -27,
      "y": 10,
      "z": 29,
      "name": "Wood_Oak_Trunk",
      "support": 15,
      "rotation": 4
    },
    {
      "x": -27,
      "y": 11,
      "z": 29,
      "name": "Wood_Softwood_Stairs",
      "rotation": 8
    },
    {
      "x": -27,
      "y": 12,
      "z": 29,
      "name": "Wood_Softwood_Roof"
    },
    {
      "x": -27,
      "y": 6,
      "z": 30,
      "name": "Wood_Oak_Trunk",
      "support": 15,
      "rotation": 4
    },
    {
      "x": -27,
      "y": 10,
      "z": 30,
      "name": "Wood_Oak_Trunk",
      "support": 15,
      "rotation": 4
    },
    {
      "x": -27,
      "y": 11,
      "z": 30,
      "name": "Wood_Softwood_Roof"
    },
    {
      "x": -27,
      "y": 6,
      "z": 31,
      "name": "Wood_Oak_Trunk",
      "support": 15,
      "rotation": 4
    },
    {
      "x": -27,
      "y": 8,
      "z": 31,
      "name": "Wood_Softwood_Stairs",
      "rotation": 8
    },
    {
      "x": -27,
      "y": 9,
      "z": 31,
      "name": "Wood_Softwood_Roof_Steep"
    },
    {
      "x": -27,
      "y": 10,
      "z": 31,
      "name": "Wood_Softwood_Roof_Steep",
      "filler": 1024
    },
    {
      "x": -27,
      "y": 0,
      "z": 32,
      "name": "Wood_Oak_Trunk",
      "support": 15
    },
    {
      "x": -27,
      "y": 1,
      "z": 32,
      "name": "Wood_Oak_Trunk",
      "support": 15
    },
    {
      "x": -27,
      "y": 2,
      "z": 32,
      "name": "Wood_Oak_Trunk",
      "support": 15
    },
    {
      "x": -27,
      "y": 3,
      "z": 32,
      "name": "Wood_Oak_Trunk",
      "support": 15
    },
    {
      "x": -27,
      "y": 4,
      "z": 32,
      "name": "Wood_Oak_Trunk",
      "support": 15
    },
    {
      "x": -27,
      "y": 5,
      "z": 32,
      "name": "Wood_Oak_Trunk",
      "support": 15
    },
    {
      "x": -27,
      "y": 6,
      "z": 32,
      "name": "Wood_Oak_Trunk",
      "support": 15
    },
    {
      "x": -27,
      "y": 7,
      "z": 32,
      "name": "Wood_Softwood_Roof_Steep"
    },
    {
      "x": -27,
      "y": 8,
      "z": 32,
      "name": "Wood_Softwood_Roof_Steep",
      "filler": 1024
    },
    {
      "x": -27,
      "y": 6,
      "z": 33,
      "name": "Wood_Softwood_Roof_Hollow"
    },
    {
      "x": -26,
      "y": 0,
      "z": 6,
      "name": "Wood_Oak_Trunk",
      "support": 15
    },
    {
      "x": -26,
      "y": 1,
      "z": 6,
      "name": "Wood_Oak_Trunk",
      "support": 15
    },
    {
      "x": -26,
      "y": 2,
      "z": 6,
      "name": "Wood_Oak_Trunk",
      "support": 15
    },
    {
      "x": -26,
      "y": 3,
      "z": 6,
      "name": "Wood_Oak_Trunk",
      "support": 15
    },
    {
      "x": -26,
      "y": 0,
      "z": 7,
      "name": "Rock_Stone_Cobble"
    },
    {
      "x": -26,
      "y": 1,
      "z": 7,
      "name": "Rock_Stone_Brick"
    },
    {
      "x": -26,
      "y": 2,
      "z": 7,
      "name": "Wood_Oak_Trunk",
      "support": 15,
      "rotation": 4
    },
    {
      "x": -26,
      "y": 3,
      "z": 7,
      "name": "Wood_Hardwood_Fence",
      "rotation": 3
    },
    {
      "x": -26,
      "y": 0,
      "z": 8,
      "name": "Rock_Stone_Brick"
    },
    {
      "x": -26,
      "y": 1,
      "z": 8,
      "name": "Rock_Stone_Cobble"
    },
    {
      "x": -26,
      "y": 2,
      "z": 8,
      "name": "Wood_Oak_Trunk",
      "support": 15,
      "rotation": 4
    },
    {
      "x": -26,
      "y": 3,
      "z": 8,
      "name": "Wood_Hardwood_Fence",
      "rotation": 3
    },
    {
      "x": -26,
      "y": 0,
      "z": 9,
      "name": "Rock_Stone_Brick"
    },
    {
      "x": -26,
      "y": 1,
      "z": 9,
      "name": "Rock_Stone_Brick"
    },
    {
      "x": -26,
      "y": 2,
      "z": 9,
      "name": "Wood_Oak_Trunk",
      "support": 15,
      "rotation": 4
    },
    {
      "x": -26,
      "y": 3,
      "z": 9,
      "name": "Wood_Hardwood_Fence",
      "rotation": 3
    },
    {
      "x": -26,
      "y": 6,
      "z": 9,
      "name": "Wood_Softwood_Roof_Hollow",
      "rotation": 2
    },
    {
      "x": -26,
      "y": 0,
      "z": 10,
      "name": "Rock_Stone_Cobble"
    },
    {
      "x": -26,
      "y": 1,
      "z": 10,
      "name": "Rock_Stone_Cobble"
    },
    {
      "x": -26,
      "y": 2,
      "z": 10,
      "name": "Wood_Oak_Trunk",
      "support": 15,
      "rotation": 5
    },
    {
      "x": -26,
      "y": 3,
      "z": 10,
      "name": "*Wood_Hardwood_Fence_State_Definitions_Corner",
      "rotation": 3
    },
    {
      "x": -26,
      "y": 6,
      "z": 10,
      "name": "Wood_Oak_Trunk",
      "support": 15,
      "rotation": 5
    },
    {
      "x": -26,
      "y": 7,
      "z": 10,
      "name": "Wood_Softwood_Roof_Shallow",
      "rotation": 2
    },
    {
      "x": -26,
      "y": 2,
      "z": 11,
      "name": "Rock_Stone_Cobble"
    },
    {
      "x": -26,
      "y": 3,
      "z": 11,
      "name": "Wood_Ash_Trunk",
      "support": 15,
      "rotation": 4
    },
    {
      "x": -26,
      "y": 6,
      "z": 11,
      "name": "Wood_Softwood_Planks_Half",
      "rotation": 8
    },
    {
      "x": -26,
      "y": 7,
      "z": 11,
      "name": "Wood_Softwood_Roof_Shallow",
      "filler": 32,
      "rotation": 2
    },
    {
      "x": -26,
      "y": 2,
      "z": 12,
      "name": "Rock_Stone_Cobble"
    },
    {
      "x": -26,
      "y": 3,
      "z": 12,
      "name": "Wood_Oak_Trunk",
      "support": 15,
      "rotation": 4
    },
    {
      "x": -26,
      "y": 4,
      "z": 12,
      "name": "Wood_Oak_Trunk",
      "support": 15,
      "rotation": 4
    },
    {
      "x": -26,
      "y": 7,
      "z": 12,
      "name": "Wood_Softwood_Stairs",
      "rotation": 10
    },
    {
      "x": -26,
      "y": 8,
      "z": 12,
      "name": "Wood_Softwood_Roof_Shallow",
      "rotation": 2
    },
    {
      "x": -26,
      "y": 2,
      "z": 13,
      "name": "Rock_Stone_Cobble"
    },
    {
      "x": -26,
      "y": 3,
      "z": 13,
      "name": "Wood_Oak_Trunk",
      "support": 15,
      "rotation": 4
    },
    {
      "x": -26,
      "y": 4,
      "z": 13,
      "name": "Wood_Oak_Trunk",
      "support": 15,
      "rotation": 4
    },
    {
      "x": -26,
      "y": 8,
      "z": 13,
      "name": "Wood_Softwood_Roof_Shallow",
      "filler": 32,
      "rotation": 2
    },
    {
      "x": -26,
      "y": 2,
      "z": 14,
      "name": "Rock_Stone_Cobble"
    },
    {
      "x": -26,
      "y": 3,
      "z": 14,
      "name": "Wood_Oak_Trunk",
      "support": 15,
      "rotation": 4
    },
    {
      "x": -26,
      "y": 4,
      "z": 14,
      "name": "Wood_Oak_Trunk",
      "support": 15,
      "rotation": 4
    },
    {
      "x": -26,
      "y": 8,
      "z": 14,
      "name": "Wood_Softwood_Stairs",
      "rotation": 10
    },
    {
      "x": -26,
      "y": 9,
      "z": 14,
      "name": "Wood_Softwood_Roof_Flat",
      "rotation": 2
    },
    {
      "x": -26,
      "y": 2,
      "z": 15,
      "name": "Rock_Stone_Cobble"
    },
    {
      "x": -26,
      "y": 3,
      "z": 15,
      "name": "Wood_Oak_Trunk",
      "support": 15,
      "rotation": 4
    },
    {
      "x": -26,
      "y": 4,
      "z": 15,
      "name": "Wood_Oak_Trunk",
      "support": 15,
      "rotation": 4
    },
    {
      "x": -26,
      "y": 8,
      "z": 15,
      "name": "Wood_Softwood_Planks_Half",
      "rotation": 8
    },
    {
      "x": -26,
      "y": 9,
      "z": 15,
      "name": "Wood_Softwood_Roof_Shallow",
      "rotation": 2
    },
    {
      "x": -26,
      "y": 2,
      "z": 16,
      "name": "Rock_Stone_Cobble"
    },
    {
      "x": -26,
      "y": 3,
      "z": 16,
      "name": "Wood_Oak_Trunk",
      "support": 15,
      "rotation": 4
    },
    {
      "x": -26,
      "y": 4,
      "z": 16,
      "name": "Wood_Oak_Trunk",
      "support": 15,
      "rotation": 4
    },
    {
      "x": -26,
      "y": 9,
      "z": 16,
      "name": "Wood_Softwood_Roof_Shallow",
      "filler": 32,
      "rotation": 2
    },
    {
      "x": -26,
      "y": 2,
      "z": 17,
      "name": "Rock_Stone_Cobble"
    },
    {
      "x": -26,
      "y": 3,
      "z": 17,
      "name": "Wood_Ash_Trunk",
      "support": 15,
      "rotation": 4
    },
    {
      "x": -26,
      "y": 9,
      "z": 17,
      "name": "Wood_Softwood_Planks"
    },
    {
      "x": -26,
      "y": 10,
      "z": 17,
      "name": "Wood_Softwood_Planks_Half"
    },
    {
      "x": -26,
      "y": 2,
      "z": 18,
      "name": "Rock_Stone_Cobble"
    },
    {
      "x": -26,
      "y": 9,
      "z": 18,
      "name": "Wood_Softwood_Roof_Shallow",
      "filler": 992
    },
    {
      "x": -26,
      "y": 2,
      "z": 19,
      "name": "Rock_Stone_Cobble"
    },
    {
      "x": -26,
      "y": 3,
      "z": 19,
      "name": "Wood_Beech_Trunk",
      "support": 15,
      "rotation": 5
    },
    {
      "x": -26,
      "y": 8,
      "z": 19,
      "name": "Wood_Softwood_Planks_Half",
      "rotation": 8
    },
    {
      "x": -26,
      "y": 9,
      "z": 19,
      "name": "Wood_Softwood_Roof_Shallow"
    },
    {
      "x": -26,
      "y": 2,
      "z": 20,
      "name": "Rock_Stone_Cobble"
    },
    {
      "x": -26,
      "y": 3,
      "z": 20,
      "name": "Wood_Oak_Trunk",
      "support": 15,
      "rotation": 5
    },
    {
      "x": -26,
      "y": 4,
      "z": 20,
      "name": "Wood_Beech_Trunk",
      "support": 15,
      "rotation": 5
    },
    {
      "x": -26,
      "y": 8,
      "z": 20,
      "name": "Wood_Softwood_Stairs",
      "rotation": 8
    },
    {
      "x": -26,
      "y": 9,
      "z": 20,
      "name": "Wood_Softwood_Roof_Flat"
    },
    {
      "x": -26,
      "y": 2,
      "z": 21,
      "name": "Rock_Stone_Cobble"
    },
    {
      "x": -26,
      "y": 3,
      "z": 21,
      "name": "Wood_Ash_Trunk",
      "support": 15,
      "rotation": 5
    },
    {
      "x": -26,
      "y": 8,
      "z": 21,
      "name": "Wood_Softwood_Roof_Shallow",
      "filler": 992
    },
    {
      "x": -26,
      "y": 2,
      "z": 22,
      "name": "Rock_Stone_Cobble"
    },
    {
      "x": -26,
      "y": 7,
      "z": 22,
      "name": "Wood_Softwood_Stairs",
      "rotation": 8
    },
    {
      "x": -26,
      "y": 8,
      "z": 22,
      "name": "Wood_Softwood_Roof_Shallow"
    },
    {
      "x": -26,
      "y": 2,
      "z": 23,
      "name": "Rock_Stone_Cobble"
    },
    {
      "x": -26,
      "y": 6,
      "z": 23,
      "name": "Wood_Softwood_Planks_Half",
      "rotation": 8
    },
    {
      "x": -26,
      "y": 7,
      "z": 23,
      "name": "Wood_Softwood_Planks"
    },
    {
      "x": -26,
      "y": 8,
      "z": 23,
      "name": "Wood_Softwood_Roof_Flat"
    },
    {
      "x": -26,
      "y": 2,
      "z": 24,
      "name": "Rock_Stone_Cobble"
    },
    {
      "x": -26,
      "y": 6,
      "z": 24,
      "name": "Wood_Oak_Trunk",
      "support": 15,
      "rotation": 5
    },
    {
      "x": -26,
      "y": 7,
      "z": 24,
      "name": "Wood_Softwood_Planks"
    },
    {
      "x": -26,
      "y": 8,
      "z": 24,
      "name": "Wood_Softwood_Roof",
      "rotation": 2
    },
    {
      "x": -26,
      "y": 0,
      "z": 25,
      "name": "Rock_Stone_Cobble"
    },
    {
      "x": -26,
      "y": 1,
      "z": 25,
      "name": "Rock_Stone_Cobble"
    },
    {
      "x": -26,
      "y": 2,
      "z": 25,
      "name": "Rock_Stone_Cobble"
    },
    {
      "x": -26,
      "y": 3,
      "z": 25,
      "name": "Rock_Stone_Brick"
    },
    {
      "x": -26,
      "y": 4,
      "z": 25,
      "name": "Rock_Quartzite"
    },
    {
      "x": -26,
      "y": 5,
      "z": 25,
      "name": "Rock_Quartzite"
    },
    {
      "x": -26,
      "y": 6,
      "z": 25,
      "name": "Wood_Softwood_Planks"
    },
    {
      "x": -26,
      "y": 7,
      "z": 25,
      "name": "Rock_Quartzite"
    },
    {
      "x": -26,
      "y": 8,
      "z": 25,
      "name": "Rock_Quartzite"
    },
    {
      "x": -26,
      "y": 9,
      "z": 25,
      "name": "Wood_Softwood_Roof_Steep",
      "rotation": 2
    },
    {
      "x": -26,
      "y": 10,
      "z": 25,
      "name": "Wood_Softwood_Roof_Steep",
      "filler": 1024,
      "rotation": 2
    },
    {
      "x": -26,
      "y": 0,
      "z": 26,
      "name": "Rock_Stone_Cobble"
    },
    {
      "x": -26,
      "y": 1,
      "z": 26,
      "name": "Rock_Stone_Cobble"
    },
    {
      "x": -26,
      "y": 2,
      "z": 26,
      "name": "Rock_Stone_Cobble"
    },
    {
      "x": -26,
      "y": 3,
      "z": 26,
      "name": "Rock_Stone_Brick"
    },
    {
      "x": -26,
      "y": 4,
      "z": 26,
      "name": "Rock_Quartzite"
    },
    {
      "x": -26,
      "y": 5,
      "z": 26,
      "name": "Rock_Quartzite"
    },
    {
      "x": -26,
      "y": 6,
      "z": 26,
      "name": "Wood_Softwood_Planks"
    },
    {
      "x": -26,
      "y": 7,
      "z": 26,
      "name": "Rock_Quartzite"
    },
    {
      "x": -26,
      "y": 8,
      "z": 26,
      "name": "Rock_Quartzite"
    },
    {
      "x": -26,
      "y": 9,
      "z": 26,
      "name": "Rock_Quartzite"
    },
    {
      "x": -26,
      "y": 10,
      "z": 26,
      "name": "Rock_Quartzite"
    },
    {
      "x": -26,
      "y": 11,
      "z": 26,
      "name": "Wood_Softwood_Roof",
      "rotation": 2
    },
    {
      "x": -26,
      "y": 0,
      "z": 27,
      "name": "Rock_Stone_Cobble"
    },
    {
      "x": -26,
      "y": 1,
      "z": 27,
      "name": "Rock_Stone_Cobble"
    },
    {
      "x": -26,
      "y": 2,
      "z": 27,
      "name": "Rock_Stone_Cobble"
    },
    {
      "x": -26,
      "y": 3,
      "z": 27,
      "name": "Rock_Stone_Brick"
    },
    {
      "x": -26,
      "y": 4,
      "z": 27,
      "name": "Furniture_Tavern_Window",
      "rotation": 1
    },
    {
      "x": -26,
      "y": 5,
      "z": 27,
      "name": "Furniture_Tavern_Window",
      "rotation": 1
    },
    {
      "x": -26,
      "y": 6,
      "z": 27,
      "name": "Wood_Softwood_Planks"
    },
    {
      "x": -26,
      "y": 7,
      "z": 27,
      "name": "Rock_Quartzite"
    },
    {
      "x": -26,
      "y": 8,
      "z": 27,
      "name": "Rock_Quartzite"
    },
    {
      "x": -26,
      "y": 9,
      "z": 27,
      "name": "Rock_Quartzite"
    },
    {
      "x": -26,
      "y": 10,
      "z": 27,
      "name": "Rock_Quartzite"
    },
    {
      "x": -26,
      "y": 11,
      "z": 27,
      "name": "Rock_Quartzite"
    },
    {
      "x": -26,
      "y": 12,
      "z": 27,
      "name": "Wood_Softwood_Roof",
      "rotation": 2
    },
    {
      "x": -26,
      "y": 0,
      "z": 28,
      "name": "Rock_Stone_Cobble"
    },
    {
      "x": -26,
      "y": 1,
      "z": 28,
      "name": "Rock_Stone_Cobble"
    },
    {
      "x": -26,
      "y": 2,
      "z": 28,
      "name": "Rock_Stone_Cobble"
    },
    {
      "x": -26,
      "y": 3,
      "z": 28,
      "name": "Wood_Oak_Trunk",
      "support": 15
    },
    {
      "x": -26,
      "y": 4,
      "z": 28,
      "name": "Wood_Oak_Trunk",
      "support": 15
    },
    {
      "x": -26,
      "y": 5,
      "z": 28,
      "name": "Wood_Oak_Trunk",
      "support": 15
    },
    {
      "x": -26,
      "y": 6,
      "z": 28,
      "name": "Wood_Softwood_Planks"
    },
    {
      "x": -26,
      "y": 7,
      "z": 28,
      "name": "Wood_Oak_Trunk",
      "support": 15
    },
    {
      "x": -26,
      "y": 8,
      "z": 28,
      "name": "Wood_Oak_Trunk",
      "support": 15
    },
    {
      "x": -26,
      "y": 9,
      "z": 28,
      "name": "Wood_Oak_Trunk",
      "support": 15
    },
    {
      "x": -26,
      "y": 10,
      "z": 28,
      "name": "Wood_Oak_Trunk",
      "support": 15
    },
    {
      "x": -26,
      "y": 11,
      "z": 28,
      "name": "Wood_Oak_Trunk",
      "support": 15
    },
    {
      "x": -26,
      "y": 12,
      "z": 28,
      "name": "Wood_Oak_Trunk",
      "support": 15
    },
    {
      "x": -26,
      "y": 13,
      "z": 28,
      "name": "Wood_Softwood_Planks_Half"
    },
    {
      "x": -26,
      "y": 0,
      "z": 29,
      "name": "Rock_Stone_Cobble"
    },
    {
      "x": -26,
      "y": 1,
      "z": 29,
      "name": "Rock_Stone_Cobble"
    },
    {
      "x": -26,
      "y": 2,
      "z": 29,
      "name": "Rock_Stone_Cobble"
    },
    {
      "x": -26,
      "y": 3,
      "z": 29,
      "name": "Rock_Stone_Brick"
    },
    {
      "x": -26,
      "y": 4,
      "z": 29,
      "name": "Rock_Quartzite"
    },
    {
      "x": -26,
      "y": 5,
      "z": 29,
      "name": "Rock_Quartzite"
    },
    {
      "x": -26,
      "y": 6,
      "z": 29,
      "name": "Wood_Softwood_Planks"
    },
    {
      "x": -26,
      "y": 7,
      "z": 29,
      "name": "Rock_Quartzite"
    },
    {
      "x": -26,
      "y": 8,
      "z": 29,
      "name": "Rock_Quartzite"
    },
    {
      "x": -26,
      "y": 9,
      "z": 29,
      "name": "Rock_Quartzite"
    },
    {
      "x": -26,
      "y": 10,
      "z": 29,
      "name": "Rock_Quartzite"
    },
    {
      "x": -26,
      "y": 11,
      "z": 29,
      "name": "Rock_Quartzite"
    },
    {
      "x": -26,
      "y": 12,
      "z": 29,
      "name": "Wood_Softwood_Roof"
    },
    {
      "x": -26,
      "y": 0,
      "z": 30,
      "name": "Rock_Stone_Cobble"
    },
    {
      "x": -26,
      "y": 1,
      "z": 30,
      "name": "Rock_Stone_Cobble"
    },
    {
      "x": -26,
      "y": 2,
      "z": 30,
      "name": "Rock_Stone_Cobble"
    },
    {
      "x": -26,
      "y": 3,
      "z": 30,
      "name": "Rock_Stone_Brick"
    },
    {
      "x": -26,
      "y": 4,
      "z": 30,
      "name": "Rock_Quartzite"
    },
    {
      "x": -26,
      "y": 5,
      "z": 30,
      "name": "Rock_Quartzite"
    },
    {
      "x": -26,
      "y": 6,
      "z": 30,
      "name": "Wood_Softwood_Planks"
    },
    {
      "x": -26,
      "y": 7,
      "z": 30,
      "name": "Rock_Quartzite"
    },
    {
      "x": -26,
      "y": 8,
      "z": 30,
      "name": "Rock_Quartzite"
    },
    {
      "x": -26,
      "y": 9,
      "z": 30,
      "name": "Rock_Quartzite"
    },
    {
      "x": -26,
      "y": 10,
      "z": 30,
      "name": "Rock_Quartzite"
    },
    {
      "x": -26,
      "y": 11,
      "z": 30,
      "name": "Wood_Softwood_Roof"
    },
    {
      "x": -26,
      "y": 0,
      "z": 31,
      "name": "Rock_Stone_Cobble"
    },
    {
      "x": -26,
      "y": 1,
      "z": 31,
      "name": "Rock_Stone_Cobble"
    },
    {
      "x": -26,
      "y": 2,
      "z": 31,
      "name": "Rock_Stone_Cobble"
    },
    {
      "x": -26,
      "y": 3,
      "z": 31,
      "name": "Rock_Stone_Brick"
    },
    {
      "x": -26,
      "y": 4,
      "z": 31,
      "name": "Rock_Quartzite"
    },
    {
      "x": -26,
      "y": 5,
      "z": 31,
      "name": "Rock_Quartzite"
    },
    {
      "x": -26,
      "y": 6,
      "z": 31,
      "name": "Wood_Softwood_Planks"
    },
    {
      "x": -26,
      "y": 7,
      "z": 31,
      "name": "Rock_Quartzite"
    },
    {
      "x": -26,
      "y": 8,
      "z": 31,
      "name": "Rock_Quartzite"
    },
    {
      "x": -26,
      "y": 9,
      "z": 31,
      "name": "Wood_Softwood_Roof_Steep"
    },
    {
      "x": -26,
      "y": 10,
      "z": 31,
      "name": "Wood_Softwood_Roof_Steep",
      "filler": 1024
    },
    {
      "x": -26,
      "y": 6,
      "z": 32,
      "name": "Wood_Oak_Trunk",
      "support": 15,
      "rotation": 5
    },
    {
      "x": -26,
      "y": 7,
      "z": 32,
      "name": "Wood_Softwood_Roof_Steep"
    },
    {
      "x": -26,
      "y": 8,
      "z": 32,
      "name": "Wood_Softwood_Roof_Steep",
      "filler": 1024
    },
    {
      "x": -26,
      "y": 6,
      "z": 33,
      "name": "Wood_Softwood_Roof_Hollow"
    },
    {
      "x": -25,
      "y": 0,
      "z": 5,
      "name": "Rock_Stone_Cobble_Stairs",
      "rotation": 2
    },
    {
      "x": -25,
      "y": 1,
      "z": 6,
      "name": "Rock_Stone_Cobble_Stairs",
      "rotation": 2
    },
    {
      "x": -25,
      "y": 2,
      "z": 7,
      "name": "Rock_Stone_Cobble_Stairs",
      "rotation": 2
    },
    {
      "x": -25,
      "y": 2,
      "z": 8,
      "name": "Rock_Stone_Cobble"
    },
    {
      "x": -25,
      "y": 2,
      "z": 9,
      "name": "Rock_Stone_Cobble"
    },
    {
      "x": -25,
      "y": 6,
      "z": 9,
      "name": "Wood_Softwood_Roof_Hollow",
      "rotation": 2
    },
    {
      "x": -25,
      "y": 0,
      "z": 10,
      "name": "Rock_Stone_Cobble"
    },
    {
      "x": -25,
      "y": 1,
      "z": 10,
      "name": "Rock_Stone_Cobble"
    },
    {
      "x": -25,
      "y": 2,
      "z": 10,
      "name": "Wood_Oak_Trunk",
      "support": 15,
      "rotation": 5
    },
    {
      "x": -25,
      "y": 6,
      "z": 10,
      "name": "Wood_Oak_Trunk",
      "support": 15,
      "rotation": 5
    },
    {
      "x": -25,
      "y": 7,
      "z": 10,
      "name": "Wood_Softwood_Roof_Shallow",
      "rotation": 2
    },
    {
      "x": -25,
      "y": 2,
      "z": 11,
      "name": "Rock_Stone_Cobble"
    },
    {
      "x": -25,
      "y": 6,
      "z": 11,
      "name": "Wood_Softwood_Planks_Half",
      "rotation": 8
    },
    {
      "x": -25,
      "y": 7,
      "z": 11,
      "name": "Wood_Softwood_Roof_Shallow",
      "filler": 32,
      "rotation": 2
    },
    {
      "x": -25,
      "y": 2,
      "z": 12,
      "name": "Rock_Stone_Cobble"
    },
    {
      "x": -25,
      "y": 3,
      "z": 12,
      "name": "Wood_Beech_Trunk",
      "support": 15,
      "rotation": 4
    },
    {
      "x": -25,
      "y": 7,
      "z": 12,
      "name": "Wood_Softwood_Stairs",
      "rotation": 10
    },
    {
      "x": -25,
      "y": 8,
      "z": 12,
      "name": "Wood_Softwood_Roof_Shallow",
      "rotation": 2
    },
    {
      "x": -25,
      "y": 2,
      "z": 13,
      "name": "Rock_Stone_Cobble"
    },
    {
      "x": -25,
      "y": 3,
      "z": 13,
      "name": "Wood_Beech_Trunk",
      "support": 15,
      "rotation": 4
    },
    {
      "x": -25,
      "y": 8,
      "z": 13,
      "name": "Wood_Softwood_Roof_Shallow",
      "filler": 32,
      "rotation": 2
    },
    {
      "x": -25,
      "y": 2,
      "z": 14,
      "name": "Rock_Stone_Cobble"
    },
    {
      "x": -25,
      "y": 3,
      "z": 14,
      "name": "Wood_Beech_Trunk",
      "support": 15,
      "rotation": 4
    },
    {
      "x": -25,
      "y": 8,
      "z": 14,
      "name": "Wood_Softwood_Stairs",
      "rotation": 10
    },
    {
      "x": -25,
      "y": 9,
      "z": 14,
      "name": "Wood_Softwood_Roof_Flat",
      "rotation": 2
    },
    {
      "x": -25,
      "y": 2,
      "z": 15,
      "name": "Rock_Stone_Cobble"
    },
    {
      "x": -25,
      "y": 3,
      "z": 15,
      "name": "Wood_Beech_Trunk",
      "support": 15,
      "rotation": 4
    },
    {
      "x": -25,
      "y": 8,
      "z": 15,
      "name": "Wood_Softwood_Planks_Half",
      "rotation": 8
    },
    {
      "x": -25,
      "y": 9,
      "z": 15,
      "name": "Wood_Softwood_Roof_Shallow",
      "rotation": 2
    },
    {
      "x": -25,
      "y": 2,
      "z": 16,
      "name": "Rock_Stone_Cobble"
    },
    {
      "x": -25,
      "y": 3,
      "z": 16,
      "name": "Wood_Beech_Trunk",
      "support": 15,
      "rotation": 4
    },
    {
      "x": -25,
      "y": 9,
      "z": 16,
      "name": "Wood_Softwood_Roof_Shallow",
      "filler": 32,
      "rotation": 2
    },
    {
      "x": -25,
      "y": 2,
      "z": 17,
      "name": "Rock_Stone_Cobble"
    },
    {
      "x": -25,
      "y": 9,
      "z": 17,
      "name": "Wood_Softwood_Planks"
    },
    {
      "x": -25,
      "y": 10,
      "z": 17,
      "name": "Wood_Softwood_Planks_Half"
    },
    {
      "x": -25,
      "y": 2,
      "z": 18,
      "name": "Rock_Stone_Cobble"
    },
    {
      "x": -25,
      "y": 9,
      "z": 18,
      "name": "Wood_Softwood_Roof_Shallow",
      "filler": 992
    },
    {
      "x": -25,
      "y": 2,
      "z": 19,
      "name": "Rock_Stone_Cobble"
    },
    {
      "x": -25,
      "y": 3,
      "z": 19,
      "name": "Wood_Beech_Trunk",
      "support": 15,
      "rotation": 5
    },
    {
      "x": -25,
      "y": 8,
      "z": 19,
      "name": "Wood_Softwood_Planks_Half",
      "rotation": 8
    },
    {
      "x": -25,
      "y": 9,
      "z": 19,
      "name": "Wood_Softwood_Roof_Shallow"
    },
    {
      "x": -25,
      "y": 2,
      "z": 20,
      "name": "Rock_Stone_Cobble"
    },
    {
      "x": -25,
      "y": 3,
      "z": 20,
      "name": "Wood_Oak_Trunk",
      "support": 15,
      "rotation": 5
    },
    {
      "x": -25,
      "y": 4,
      "z": 20,
      "name": "Wood_Beech_Trunk",
      "support": 15,
      "rotation": 5
    },
    {
      "x": -25,
      "y": 8,
      "z": 20,
      "name": "Wood_Softwood_Stairs",
      "rotation": 8
    },
    {
      "x": -25,
      "y": 9,
      "z": 20,
      "name": "Wood_Softwood_Roof_Flat"
    },
    {
      "x": -25,
      "y": 2,
      "z": 21,
      "name": "Rock_Stone_Cobble"
    },
    {
      "x": -25,
      "y": 3,
      "z": 21,
      "name": "Wood_Ash_Trunk",
      "support": 15,
      "rotation": 5
    },
    {
      "x": -25,
      "y": 8,
      "z": 21,
      "name": "Wood_Softwood_Roof_Shallow",
      "filler": 992
    },
    {
      "x": -25,
      "y": 2,
      "z": 22,
      "name": "Rock_Stone_Cobble"
    },
    {
      "x": -25,
      "y": 7,
      "z": 22,
      "name": "Wood_Softwood_Stairs",
      "rotation": 8
    },
    {
      "x": -25,
      "y": 8,
      "z": 22,
      "name": "Wood_Softwood_Roof_Shallow"
    },
    {
      "x": -25,
      "y": 2,
      "z": 23,
      "name": "Rock_Stone_Cobble"
    },
    {
      "x": -25,
      "y": 6,
      "z": 23,
      "name": "Wood_Softwood_Planks_Half",
      "rotation": 8
    },
    {
      "x": -25,
      "y": 7,
      "z": 23,
      "name": "Wood_Softwood_Planks"
    },
    {
      "x": -25,
      "y": 8,
      "z": 23,
      "name": "Wood_Softwood_Roof_Flat"
    },
    {
      "x": -25,
      "y": 2,
      "z": 24,
      "name": "Rock_Stone_Cobble"
    },
    {
      "x": -25,
      "y": 6,
      "z": 24,
      "name": "Wood_Oak_Trunk",
      "support": 15,
      "rotation": 5
    },
    {
      "x": -25,
      "y": 7,
      "z": 24,
      "name": "Wood_Softwood_Planks"
    },
    {
      "x": -25,
      "y": 8,
      "z": 24,
      "name": "Wood_Softwood_Roof",
      "rotation": 2
    },
    {
      "x": -25,
      "y": 2,
      "z": 25,
      "name": "Rock_Stone_Cobble"
    },
    {
      "x": -25,
      "y": 3,
      "z": 25,
      "name": "Rock_Stone_Brick"
    },
    {
      "x": -25,
      "y": 4,
      "z": 25,
      "name": "Rock_Quartzite"
    },
    {
      "x": -25,
      "y": 5,
      "z": 25,
      "name": "Rock_Quartzite"
    },
    {
      "x": -25,
      "y": 6,
      "z": 25,
      "name": "Wood_Softwood_Planks"
    },
    {
      "x": -25,
      "y": 8,
      "z": 25,
      "name": "Wood_Softwood_Planks"
    },
    {
      "x": -25,
      "y": 9,
      "z": 25,
      "name": "Wood_Softwood_Roof_Steep",
      "rotation": 2
    },
    {
      "x": -25,
      "y": 10,
      "z": 25,
      "name": "Wood_Softwood_Roof_Steep",
      "filler": 1024,
      "rotation": 2
    },
    {
      "x": -25,
      "y": 2,
      "z": 26,
      "name": "Wood_Softwood_Planks"
    },
    {
      "x": -25,
      "y": 3,
      "z": 26,
      "name": "Furniture_Village_Counter",
      "filler": 31
    },
    {
      "x": -25,
      "y": 6,
      "z": 26,
      "name": "Wood_Softwood_Planks"
    },
    {
      "x": -25,
      "y": 11,
      "z": 26,
      "name": "Wood_Softwood_Roof_Hollow",
      "rotation": 2
    },
    {
      "x": -25,
      "y": 2,
      "z": 27,
      "name": "Wood_Softwood_Planks"
    },
    {
      "x": -25,
      "y": 3,
      "z": 27,
      "name": "Furniture_Village_Counter",
      "rotation": 1
    },
    {
      "x": -25,
      "y": 4,
      "z": 27,
      "name": "Deco_Inkwell",
      "rotation": 1
    },
    {
      "x": -25,
      "y": 6,
      "z": 27,
      "name": "Wood_Softwood_Planks"
    },
    {
      "x": -25,
      "y": 12,
      "z": 27,
      "name": "Wood_Softwood_Roof_Hollow",
      "rotation": 2
    },
    {
      "x": -25,
      "y": 2,
      "z": 28,
      "name": "Wood_Softwood_Planks"
    },
    {
      "x": -25,
      "y": 3,
      "z": 28,
      "name": "Furniture_Village_Counter",
      "filler": 32,
      "rotation": 1
    },
    {
      "x": -25,
      "y": 4,
      "z": 28,
      "name": "Deco_Book_Pile_Small",
      "rotation": 1
    },
    {
      "x": -25,
      "y": 6,
      "z": 28,
      "name": "Wood_Softwood_Planks"
    },
    {
      "x": -25,
      "y": 13,
      "z": 28,
      "name": "Wood_Softwood_Planks_Half"
    },
    {
      "x": -25,
      "y": 2,
      "z": 29,
      "name": "Wood_Softwood_Planks"
    },
    {
      "x": -25,
      "y": 3,
      "z": 29,
      "name": "Aetherhaven_Production_Storage",
      "rotation": 1
    },
    {
      "x": -25,
      "y": 4,
      "z": 29,
      "name": "Aetherhaven_Production_Storage",
      "filler": 1024,
      "rotation": 1
    },
    {
      "x": -25,
      "y": 5,
      "z": 29,
      "name": "Aetherhaven_Management_Block",
      "components": {
        "Components": {
          "AetherhavenManagementBlock": {
            "PlotId": "",
            "TownId": ""
          },
          "PlacedByInteraction": {
            "WhoPlacedUuid": {
              "$binary": "gqJcCRGLSleXtmq6BvFR8g==",
              "$type": "04"
            }
          }
        }
      },
      "rotation": 1
    },
    {
      "x": -25,
      "y": 6,
      "z": 29,
      "name": "Wood_Softwood_Planks"
    },
    {
      "x": -25,
      "y": 12,
      "z": 29,
      "name": "Wood_Softwood_Roof_Hollow"
    },
    {
      "x": -25,
      "y": 2,
      "z": 30,
      "name": "Wood_Softwood_Planks"
    },
    {
      "x": -25,
      "y": 3,
      "z": 30,
      "name": "Aetherhaven_Production_Storage",
      "filler": 32,
      "rotation": 1
    },
    {
      "x": -25,
      "y": 4,
      "z": 30,
      "name": "Aetherhaven_Production_Storage",
      "filler": 1056,
      "rotation": 1
    },
    {
      "x": -25,
      "y": 5,
      "z": 30,
      "name": "Furniture_Village_Bookcase",
      "rotation": 1
    },
    {
      "x": -25,
      "y": 6,
      "z": 30,
      "name": "Wood_Softwood_Planks"
    },
    {
      "x": -25,
      "y": 11,
      "z": 30,
      "name": "Wood_Softwood_Roof_Hollow"
    },
    {
      "x": -25,
      "y": 0,
      "z": 31,
      "name": "Rock_Stone_Cobble"
    },
    {
      "x": -25,
      "y": 1,
      "z": 31,
      "name": "Rock_Stone_Cobble"
    },
    {
      "x": -25,
      "y": 2,
      "z": 31,
      "name": "Rock_Stone_Cobble"
    },
    {
      "x": -25,
      "y": 3,
      "z": 31,
      "name": "Rock_Stone_Brick"
    },
    {
      "x": -25,
      "y": 4,
      "z": 31,
      "name": "Furniture_Tavern_Window"
    },
    {
      "x": -25,
      "y": 5,
      "z": 31,
      "name": "Furniture_Tavern_Window"
    },
    {
      "x": -25,
      "y": 6,
      "z": 31,
      "name": "Wood_Softwood_Planks"
    },
    {
      "x": -25,
      "y": 8,
      "z": 31,
      "name": "Wood_Softwood_Planks"
    },
    {
      "x": -25,
      "y": 9,
      "z": 31,
      "name": "Wood_Softwood_Roof_Steep"
    },
    {
      "x": -25,
      "y": 10,
      "z": 31,
      "name": "Wood_Softwood_Roof_Steep",
      "filler": 1024
    },
    {
      "x": -25,
      "y": 6,
      "z": 32,
      "name": "Wood_Oak_Trunk",
      "support": 15,
      "rotation": 5
    },
    {
      "x": -25,
      "y": 7,
      "z": 32,
      "name": "Wood_Softwood_Roof_Steep"
    },
    {
      "x": -25,
      "y": 8,
      "z": 32,
      "name": "Wood_Softwood_Roof_Steep",
      "filler": 1024
    },
    {
      "x": -25,
      "y": 6,
      "z": 33,
      "name": "Wood_Softwood_Roof_Hollow"
    },
    {
      "x": -24,
      "y": 0,
      "z": 5,
      "name": "Rock_Stone_Cobble_Stairs",
      "rotation": 2
    },
    {
      "x": -24,
      "y": 1,
      "z": 6,
      "name": "Rock_Stone_Cobble_Stairs",
      "rotation": 2
    },
    {
      "x": -24,
      "y": 2,
      "z": 7,
      "name": "Rock_Stone_Cobble_Stairs",
      "rotation": 2
    },
    {
      "x": -24,
      "y": 2,
      "z": 8,
      "name": "Rock_Stone_Cobble"
    },
    {
      "x": -24,
      "y": 2,
      "z": 9,
      "name": "Rock_Stone_Cobble"
    },
    {
      "x": -24,
      "y": 6,
      "z": 9,
      "name": "Wood_Softwood_Roof_Hollow",
      "rotation": 2
    },
    {
      "x": -24,
      "y": 0,
      "z": 10,
      "name": "Rock_Stone_Cobble"
    },
    {
      "x": -24,
      "y": 1,
      "z": 10,
      "name": "Rock_Stone_Cobble"
    },
    {
      "x": -24,
      "y": 2,
      "z": 10,
      "name": "Wood_Oak_Trunk",
      "support": 15,
      "rotation": 5
    },
    {
      "x": -24,
      "y": 6,
      "z": 10,
      "name": "Wood_Oak_Trunk",
      "support": 15,
      "rotation": 5
    },
    {
      "x": -24,
      "y": 7,
      "z": 10,
      "name": "Wood_Softwood_Roof_Shallow",
      "rotation": 2
    },
    {
      "x": -24,
      "y": 2,
      "z": 11,
      "name": "Rock_Stone_Cobble"
    },
    {
      "x": -24,
      "y": 6,
      "z": 11,
      "name": "Wood_Softwood_Planks_Half",
      "rotation": 8
    },
    {
      "x": -24,
      "y": 7,
      "z": 11,
      "name": "Wood_Softwood_Roof_Shallow",
      "filler": 32,
      "rotation": 2
    },
    {
      "x": -24,
      "y": 2,
      "z": 12,
      "name": "Rock_Stone_Cobble"
    },
    {
      "x": -24,
      "y": 7,
      "z": 12,
      "name": "Wood_Softwood_Stairs",
      "rotation": 10
    },
    {
      "x": -24,
      "y": 8,
      "z": 12,
      "name": "Wood_Softwood_Roof_Shallow",
      "rotation": 2
    },
    {
      "x": -24,
      "y": 2,
      "z": 13,
      "name": "Rock_Stone_Cobble"
    },
    {
      "x": -24,
      "y": 8,
      "z": 13,
      "name": "Wood_Softwood_Roof_Shallow",
      "filler": 32,
      "rotation": 2
    },
    {
      "x": -24,
      "y": 2,
      "z": 14,
      "name": "Rock_Stone_Cobble"
    },
    {
      "x": -24,
      "y": 8,
      "z": 14,
      "name": "Wood_Softwood_Stairs",
      "rotation": 10
    },
    {
      "x": -24,
      "y": 9,
      "z": 14,
      "name": "Wood_Softwood_Roof_Flat",
      "rotation": 2
    },
    {
      "x": -24,
      "y": 2,
      "z": 15,
      "name": "Rock_Stone_Cobble"
    },
    {
      "x": -24,
      "y": 8,
      "z": 15,
      "name": "Wood_Softwood_Planks_Half",
      "rotation": 8
    },
    {
      "x": -24,
      "y": 9,
      "z": 15,
      "name": "Wood_Softwood_Roof_Shallow",
      "rotation": 2
    },
    {
      "x": -24,
      "y": 2,
      "z": 16,
      "name": "Rock_Stone_Cobble"
    },
    {
      "x": -24,
      "y": 9,
      "z": 16,
      "name": "Wood_Softwood_Roof_Shallow",
      "filler": 32,
      "rotation": 2
    },
    {
      "x": -24,
      "y": 2,
      "z": 17,
      "name": "Rock_Stone_Cobble"
    },
    {
      "x": -24,
      "y": 9,
      "z": 17,
      "name": "Wood_Softwood_Planks"
    },
    {
      "x": -24,
      "y": 10,
      "z": 17,
      "name": "Wood_Softwood_Planks_Half"
    },
    {
      "x": -24,
      "y": 2,
      "z": 18,
      "name": "Rock_Stone_Cobble"
    },
    {
      "x": -24,
      "y": 9,
      "z": 18,
      "name": "Wood_Softwood_Roof_Shallow",
      "filler": 992
    },
    {
      "x": -24,
      "y": 2,
      "z": 19,
      "name": "Rock_Stone_Cobble"
    },
    {
      "x": -24,
      "y": 3,
      "z": 19,
      "name": "Wood_Beech_Trunk",
      "support": 15,
      "rotation": 5
    },
    {
      "x": -24,
      "y": 8,
      "z": 19,
      "name": "Wood_Softwood_Planks_Half",
      "rotation": 8
    },
    {
      "x": -24,
      "y": 9,
      "z": 19,
      "name": "Wood_Softwood_Roof_Shallow"
    },
    {
      "x": -24,
      "y": 2,
      "z": 20,
      "name": "Rock_Stone_Cobble"
    },
    {
      "x": -24,
      "y": 3,
      "z": 20,
      "name": "Wood_Oak_Trunk",
      "support": 15,
      "rotation": 5
    },
    {
      "x": -24,
      "y": 4,
      "z": 20,
      "name": "Wood_Beech_Trunk",
      "support": 15,
      "rotation": 5
    },
    {
      "x": -24,
      "y": 8,
      "z": 20,
      "name": "Wood_Softwood_Stairs",
      "rotation": 8
    },
    {
      "x": -24,
      "y": 9,
      "z": 20,
      "name": "Wood_Softwood_Roof_Flat"
    },
    {
      "x": -24,
      "y": 2,
      "z": 21,
      "name": "Rock_Stone_Cobble"
    },
    {
      "x": -24,
      "y": 3,
      "z": 21,
      "name": "Wood_Ash_Trunk",
      "support": 15,
      "rotation": 5
    },
    {
      "x": -24,
      "y": 8,
      "z": 21,
      "name": "Wood_Softwood_Roof_Shallow",
      "filler": 992
    },
    {
      "x": -24,
      "y": 2,
      "z": 22,
      "name": "Rock_Stone_Cobble"
    },
    {
      "x": -24,
      "y": 7,
      "z": 22,
      "name": "Wood_Softwood_Stairs",
      "rotation": 8
    },
    {
      "x": -24,
      "y": 8,
      "z": 22,
      "name": "Wood_Softwood_Roof_Shallow"
    },
    {
      "x": -24,
      "y": 2,
      "z": 23,
      "name": "Rock_Stone_Cobble"
    },
    {
      "x": -24,
      "y": 6,
      "z": 23,
      "name": "Wood_Softwood_Planks_Half",
      "rotation": 8
    },
    {
      "x": -24,
      "y": 7,
      "z": 23,
      "name": "Wood_Softwood_Planks"
    },
    {
      "x": -24,
      "y": 8,
      "z": 23,
      "name": "Wood_Softwood_Roof_Flat"
    },
    {
      "x": -24,
      "y": 2,
      "z": 24,
      "name": "Rock_Stone_Cobble"
    },
    {
      "x": -24,
      "y": 6,
      "z": 24,
      "name": "Wood_Oak_Trunk",
      "support": 15,
      "rotation": 5
    },
    {
      "x": -24,
      "y": 7,
      "z": 24,
      "name": "Wood_Softwood_Planks"
    },
    {
      "x": -24,
      "y": 8,
      "z": 24,
      "name": "Wood_Softwood_Roof",
      "rotation": 2
    },
    {
      "x": -24,
      "y": 2,
      "z": 25,
      "name": "Rock_Stone_Cobble"
    },
    {
      "x": -24,
      "y": 3,
      "z": 25,
      "name": "Rock_Stone_Brick"
    },
    {
      "x": -24,
      "y": 4,
      "z": 25,
      "name": "Rock_Quartzite"
    },
    {
      "x": -24,
      "y": 5,
      "z": 25,
      "name": "Rock_Quartzite"
    },
    {
      "x": -24,
      "y": 6,
      "z": 25,
      "name": "Wood_Softwood_Planks"
    },
    {
      "x": -24,
      "y": 8,
      "z": 25,
      "name": "Wood_Softwood_Planks"
    },
    {
      "x": -24,
      "y": 9,
      "z": 25,
      "name": "Wood_Softwood_Roof_Steep",
      "rotation": 2
    },
    {
      "x": -24,
      "y": 10,
      "z": 25,
      "name": "Wood_Softwood_Roof_Steep",
      "filler": 1024,
      "rotation": 2
    },
    {
      "x": -24,
      "y": 2,
      "z": 26,
      "name": "Wood_Softwood_Planks"
    },
    {
      "x": -24,
      "y": 3,
      "z": 26,
      "name": "Furniture_Village_Counter"
    },
    {
      "x": -24,
      "y": 4,
      "z": 26,
      "name": "Recipe_Book_Magic_Air"
    },
    {
      "x": -24,
      "y": 6,
      "z": 26,
      "name": "Wood_Softwood_Planks"
    },
    {
      "x": -24,
      "y": 11,
      "z": 26,
      "name": "Wood_Softwood_Roof_Hollow",
      "rotation": 2
    },
    {
      "x": -24,
      "y": 2,
      "z": 27,
      "name": "Wood_Softwood_Planks"
    },
    {
      "x": -24,
      "y": 3,
      "z": 27,
      "name": "Furniture_Village_Chair",
      "rotation": 2
    },
    {
      "x": -24,
      "y": 4,
      "z": 27,
      "name": "Furniture_Village_Chair",
      "filler": 1024,
      "rotation": 2
    },
    {
      "x": -24,
      "y": 6,
      "z": 27,
      "name": "Wood_Softwood_Planks"
    },
    {
      "x": -24,
      "y": 12,
      "z": 27,
      "name": "Wood_Softwood_Roof_Hollow",
      "rotation": 2
    },
    {
      "x": -24,
      "y": 2,
      "z": 28,
      "name": "Wood_Softwood_Planks"
    },
    {
      "x": -24,
      "y": 6,
      "z": 28,
      "name": "Wood_Softwood_Planks"
    },
    {
      "x": -24,
      "y": 13,
      "z": 28,
      "name": "Wood_Softwood_Planks_Half"
    },
    {
      "x": -24,
      "y": 2,
      "z": 29,
      "name": "Wood_Softwood_Planks"
    },
    {
      "x": -24,
      "y": 6,
      "z": 29,
      "name": "Wood_Softwood_Planks"
    },
    {
      "x": -24,
      "y": 12,
      "z": 29,
      "name": "Wood_Softwood_Roof_Hollow"
    },
    {
      "x": -24,
      "y": 2,
      "z": 30,
      "name": "Wood_Softwood_Planks"
    },
    {
      "x": -24,
      "y": 6,
      "z": 30,
      "name": "Wood_Softwood_Planks"
    },
    {
      "x": -24,
      "y": 11,
      "z": 30,
      "name": "Wood_Softwood_Roof_Hollow"
    },
    {
      "x": -24,
      "y": 0,
      "z": 31,
      "name": "Rock_Stone_Cobble"
    },
    {
      "x": -24,
      "y": 1,
      "z": 31,
      "name": "Rock_Stone_Cobble"
    },
    {
      "x": -24,
      "y": 2,
      "z": 31,
      "name": "Rock_Stone_Cobble"
    },
    {
      "x": -24,
      "y": 3,
      "z": 31,
      "name": "Rock_Stone_Brick"
    },
    {
      "x": -24,
      "y": 4,
      "z": 31,
      "name": "Rock_Quartzite"
    },
    {
      "x": -24,
      "y": 5,
      "z": 31,
      "name": "Rock_Quartzite"
    },
    {
      "x": -24,
      "y": 6,
      "z": 31,
      "name": "Wood_Softwood_Planks"
    },
    {
      "x": -24,
      "y": 8,
      "z": 31,
      "name": "Wood_Softwood_Planks"
    },
    {
      "x": -24,
      "y": 9,
      "z": 31,
      "name": "Wood_Softwood_Roof_Steep"
    },
    {
      "x": -24,
      "y": 10,
      "z": 31,
      "name": "Wood_Softwood_Roof_Steep",
      "filler": 1024
    },
    {
      "x": -24,
      "y": 6,
      "z": 32,
      "name": "Wood_Oak_Trunk",
      "support": 15,
      "rotation": 5
    },
    {
      "x": -24,
      "y": 7,
      "z": 32,
      "name": "Wood_Softwood_Roof_Steep"
    },
    {
      "x": -24,
      "y": 8,
      "z": 32,
      "name": "Wood_Softwood_Roof_Steep",
      "filler": 1024
    },
    {
      "x": -24,
      "y": 6,
      "z": 33,
      "name": "Wood_Softwood_Roof_Hollow"
    },
    {
      "x": -23,
      "y": 0,
      "z": 6,
      "name": "Wood_Oak_Trunk",
      "support": 15
    },
    {
      "x": -23,
      "y": 1,
      "z": 6,
      "name": "Wood_Oak_Trunk",
      "support": 15
    },
    {
      "x": -23,
      "y": 2,
      "z": 6,
      "name": "Wood_Oak_Trunk",
      "support": 15
    },
    {
      "x": -23,
      "y": 3,
      "z": 6,
      "name": "Wood_Oak_Trunk",
      "support": 15
    },
    {
      "x": -23,
      "y": 0,
      "z": 7,
      "name": "Rock_Stone_Cobble"
    },
    {
      "x": -23,
      "y": 1,
      "z": 7,
      "name": "Rock_Stone_Cobble"
    },
    {
      "x": -23,
      "y": 2,
      "z": 7,
      "name": "Wood_Oak_Trunk",
      "support": 15,
      "rotation": 4
    },
    {
      "x": -23,
      "y": 0,
      "z": 8,
      "name": "Rock_Stone_Cobble"
    },
    {
      "x": -23,
      "y": 1,
      "z": 8,
      "name": "Rock_Stone_Cobble"
    },
    {
      "x": -23,
      "y": 2,
      "z": 8,
      "name": "Wood_Oak_Trunk",
      "support": 15,
      "rotation": 4
    },
    {
      "x": -23,
      "y": 0,
      "z": 9,
      "name": "Rock_Stone_Cobble"
    },
    {
      "x": -23,
      "y": 1,
      "z": 9,
      "name": "Rock_Stone_Cobble"
    },
    {
      "x": -23,
      "y": 2,
      "z": 9,
      "name": "Wood_Oak_Trunk",
      "support": 15,
      "rotation": 4
    },
    {
      "x": -23,
      "y": 6,
      "z": 9,
      "name": "Wood_Softwood_Roof_Hollow",
      "rotation": 2
    },
    {
      "x": -23,
      "y": 0,
      "z": 10,
      "name": "Wood_Oak_Trunk",
      "support": 15
    },
    {
      "x": -23,
      "y": 1,
      "z": 10,
      "name": "Wood_Oak_Trunk",
      "support": 15
    },
    {
      "x": -23,
      "y": 2,
      "z": 10,
      "name": "Wood_Oak_Trunk",
      "support": 15
    },
    {
      "x": -23,
      "y": 3,
      "z": 10,
      "name": "Wood_Oak_Trunk",
      "support": 15
    },
    {
      "x": -23,
      "y": 4,
      "z": 10,
      "name": "Wood_Oak_Trunk",
      "support": 15
    },
    {
      "x": -23,
      "y": 5,
      "z": 10,
      "name": "Wood_Oak_Trunk",
      "support": 15
    },
    {
      "x": -23,
      "y": 6,
      "z": 10,
      "name": "Wood_Oak_Trunk",
      "support": 15,
      "rotation": 5
    },
    {
      "x": -23,
      "y": 7,
      "z": 10,
      "name": "Wood_Softwood_Roof_Shallow",
      "rotation": 2
    },
    {
      "x": -23,
      "y": 2,
      "z": 11,
      "name": "Rock_Stone_Cobble"
    },
    {
      "x": -23,
      "y": 5,
      "z": 11,
      "name": "Wood_Torch_Wall"
    },
    {
      "x": -23,
      "y": 6,
      "z": 11,
      "name": "Wood_Softwood_Stairs",
      "rotation": 10
    },
    {
      "x": -23,
      "y": 7,
      "z": 11,
      "name": "Wood_Softwood_Roof_Shallow",
      "filler": 32,
      "rotation": 2
    },
    {
      "x": -23,
      "y": 2,
      "z": 12,
      "name": "Rock_Stone_Cobble"
    },
    {
      "x": -23,
      "y": 7,
      "z": 12,
      "name": "Wood_Softwood_Stairs",
      "rotation": 10
    },
    {
      "x": -23,
      "y": 8,
      "z": 12,
      "name": "Wood_Softwood_Roof_Shallow",
      "rotation": 2
    },
    {
      "x": -23,
      "y": 2,
      "z": 13,
      "name": "Rock_Stone_Cobble"
    },
    {
      "x": -23,
      "y": 8,
      "z": 13,
      "name": "Wood_Softwood_Roof_Shallow",
      "filler": 32,
      "rotation": 2
    },
    {
      "x": -23,
      "y": 2,
      "z": 14,
      "name": "Rock_Stone_Cobble"
    },
    {
      "x": -23,
      "y": 8,
      "z": 14,
      "name": "Wood_Softwood_Stairs",
      "rotation": 10
    },
    {
      "x": -23,
      "y": 9,
      "z": 14,
      "name": "Wood_Softwood_Roof_Flat",
      "rotation": 2
    },
    {
      "x": -23,
      "y": 2,
      "z": 15,
      "name": "Rock_Stone_Cobble"
    },
    {
      "x": -23,
      "y": 8,
      "z": 15,
      "name": "Wood_Softwood_Planks_Half",
      "rotation": 8
    },
    {
      "x": -23,
      "y": 9,
      "z": 15,
      "name": "Wood_Softwood_Roof_Shallow",
      "rotation": 2
    },
    {
      "x": -23,
      "y": 2,
      "z": 16,
      "name": "Rock_Stone_Cobble"
    },
    {
      "x": -23,
      "y": 9,
      "z": 16,
      "name": "Wood_Softwood_Roof_Shallow",
      "filler": 32,
      "rotation": 2
    },
    {
      "x": -23,
      "y": 2,
      "z": 17,
      "name": "Rock_Stone_Cobble"
    },
    {
      "x": -23,
      "y": 7,
      "z": 17,
      "name": "Deco_Lantern_Ceiling"
    },
    {
      "x": -23,
      "y": 8,
      "z": 17,
      "name": "Deco_Rope"
    },
    {
      "x": -23,
      "y": 9,
      "z": 17,
      "name": "Wood_Softwood_Planks"
    },
    {
      "x": -23,
      "y": 10,
      "z": 17,
      "name": "Wood_Softwood_Planks_Half"
    },
    {
      "x": -23,
      "y": 2,
      "z": 18,
      "name": "Rock_Stone_Cobble"
    },
    {
      "x": -23,
      "y": 9,
      "z": 18,
      "name": "Wood_Softwood_Roof_Shallow",
      "filler": 992
    },
    {
      "x": -23,
      "y": 2,
      "z": 19,
      "name": "Rock_Stone_Cobble"
    },
    {
      "x": -23,
      "y": 3,
      "z": 19,
      "name": "Wood_Beech_Trunk",
      "support": 15,
      "rotation": 5
    },
    {
      "x": -23,
      "y": 8,
      "z": 19,
      "name": "Wood_Softwood_Planks_Half",
      "rotation": 8
    },
    {
      "x": -23,
      "y": 9,
      "z": 19,
      "name": "Wood_Softwood_Roof_Shallow"
    },
    {
      "x": -23,
      "y": 2,
      "z": 20,
      "name": "Rock_Stone_Cobble"
    },
    {
      "x": -23,
      "y": 3,
      "z": 20,
      "name": "Wood_Oak_Trunk",
      "support": 15,
      "rotation": 5
    },
    {
      "x": -23,
      "y": 4,
      "z": 20,
      "name": "Wood_Beech_Trunk",
      "support": 15,
      "rotation": 5
    },
    {
      "x": -23,
      "y": 8,
      "z": 20,
      "name": "Wood_Softwood_Stairs",
      "rotation": 8
    },
    {
      "x": -23,
      "y": 9,
      "z": 20,
      "name": "Wood_Softwood_Roof_Flat"
    },
    {
      "x": -23,
      "y": 2,
      "z": 21,
      "name": "Rock_Stone_Cobble"
    },
    {
      "x": -23,
      "y": 3,
      "z": 21,
      "name": "Wood_Ash_Trunk",
      "support": 15,
      "rotation": 5
    },
    {
      "x": -23,
      "y": 8,
      "z": 21,
      "name": "Wood_Softwood_Roof_Shallow",
      "filler": 992
    },
    {
      "x": -23,
      "y": 2,
      "z": 22,
      "name": "Rock_Stone_Cobble"
    },
    {
      "x": -23,
      "y": 7,
      "z": 22,
      "name": "Wood_Softwood_Stairs",
      "rotation": 8
    },
    {
      "x": -23,
      "y": 8,
      "z": 22,
      "name": "Wood_Softwood_Roof_Shallow"
    },
    {
      "x": -23,
      "y": 2,
      "z": 23,
      "name": "Rock_Stone_Cobble"
    },
    {
      "x": -23,
      "y": 6,
      "z": 23,
      "name": "Wood_Softwood_Planks_Half",
      "rotation": 8
    },
    {
      "x": -23,
      "y": 7,
      "z": 23,
      "name": "Wood_Softwood_Planks"
    },
    {
      "x": -23,
      "y": 8,
      "z": 23,
      "name": "Wood_Softwood_Roof_Flat"
    },
    {
      "x": -23,
      "y": 2,
      "z": 24,
      "name": "Rock_Stone_Cobble"
    },
    {
      "x": -23,
      "y": 6,
      "z": 24,
      "name": "Wood_Oak_Trunk",
      "support": 15,
      "rotation": 5
    },
    {
      "x": -23,
      "y": 7,
      "z": 24,
      "name": "Wood_Softwood_Planks"
    },
    {
      "x": -23,
      "y": 8,
      "z": 24,
      "name": "Wood_Softwood_Roof",
      "rotation": 2
    },
    {
      "x": -23,
      "y": 2,
      "z": 25,
      "name": "Rock_Stone_Cobble"
    },
    {
      "x": -23,
      "y": 3,
      "z": 25,
      "name": "Wood_Oak_Trunk",
      "support": 15
    },
    {
      "x": -23,
      "y": 4,
      "z": 25,
      "name": "Wood_Oak_Trunk",
      "support": 15
    },
    {
      "x": -23,
      "y": 5,
      "z": 25,
      "name": "Wood_Oak_Trunk",
      "support": 15
    },
    {
      "x": -23,
      "y": 6,
      "z": 25,
      "name": "Wood_Softwood_Planks"
    },
    {
      "x": -23,
      "y": 8,
      "z": 25,
      "name": "Wood_Softwood_Planks"
    },
    {
      "x": -23,
      "y": 9,
      "z": 25,
      "name": "Wood_Softwood_Roof_Steep",
      "rotation": 2
    },
    {
      "x": -23,
      "y": 10,
      "z": 25,
      "name": "Wood_Softwood_Roof_Steep",
      "filler": 1024,
      "rotation": 2
    },
    {
      "x": -23,
      "y": 2,
      "z": 26,
      "name": "Wood_Softwood_Planks"
    },
    {
      "x": -23,
      "y": 3,
      "z": 26,
      "name": "Furniture_Village_Counter",
      "filler": 31
    },
    {
      "x": -23,
      "y": 4,
      "z": 26,
      "name": "Deco_Map"
    },
    {
      "x": -23,
      "y": 6,
      "z": 26,
      "name": "Wood_Softwood_Planks"
    },
    {
      "x": -23,
      "y": 11,
      "z": 26,
      "name": "Wood_Softwood_Roof_Hollow",
      "rotation": 2
    },
    {
      "x": -23,
      "y": 2,
      "z": 27,
      "name": "Wood_Softwood_Planks"
    },
    {
      "x": -23,
      "y": 6,
      "z": 27,
      "name": "Wood_Softwood_Planks"
    },
    {
      "x": -23,
      "y": 12,
      "z": 27,
      "name": "Wood_Softwood_Roof_Hollow",
      "rotation": 2
    },
    {
      "x": -23,
      "y": 2,
      "z": 28,
      "name": "Wood_Softwood_Planks"
    },
    {
      "x": -23,
      "y": 6,
      "z": 28,
      "name": "Wood_Softwood_Planks"
    },
    {
      "x": -23,
      "y": 13,
      "z": 28,
      "name": "Wood_Softwood_Planks_Half"
    },
    {
      "x": -23,
      "y": 2,
      "z": 29,
      "name": "Wood_Softwood_Planks"
    },
    {
      "x": -23,
      "y": 6,
      "z": 29,
      "name": "Wood_Softwood_Planks"
    },
    {
      "x": -23,
      "y": 12,
      "z": 29,
      "name": "Wood_Softwood_Roof_Hollow"
    },
    {
      "x": -23,
      "y": 2,
      "z": 30,
      "name": "Wood_Softwood_Planks"
    },
    {
      "x": -23,
      "y": 6,
      "z": 30,
      "name": "Wood_Softwood_Planks"
    },
    {
      "x": -23,
      "y": 11,
      "z": 30,
      "name": "Wood_Softwood_Roof_Hollow"
    },
    {
      "x": -23,
      "y": 0,
      "z": 31,
      "name": "Rock_Stone_Cobble"
    },
    {
      "x": -23,
      "y": 1,
      "z": 31,
      "name": "Rock_Stone_Cobble"
    },
    {
      "x": -23,
      "y": 2,
      "z": 31,
      "name": "Rock_Stone_Cobble"
    },
    {
      "x": -23,
      "y": 3,
      "z": 31,
      "name": "Wood_Oak_Trunk",
      "support": 15
    },
    {
      "x": -23,
      "y": 4,
      "z": 31,
      "name": "Wood_Oak_Trunk",
      "support": 15
    },
    {
      "x": -23,
      "y": 5,
      "z": 31,
      "name": "Wood_Oak_Trunk",
      "support": 15
    },
    {
      "x": -23,
      "y": 6,
      "z": 31,
      "name": "Wood_Softwood_Planks"
    },
    {
      "x": -23,
      "y": 8,
      "z": 31,
      "name": "Wood_Softwood_Planks"
    },
    {
      "x": -23,
      "y": 9,
      "z": 31,
      "name": "Wood_Softwood_Roof_Steep"
    },
    {
      "x": -23,
      "y": 10,
      "z": 31,
      "name": "Wood_Softwood_Roof_Steep",
      "filler": 1024
    },
    {
      "x": -23,
      "y": 6,
      "z": 32,
      "name": "Wood_Oak_Trunk",
      "support": 15,
      "rotation": 5
    },
    {
      "x": -23,
      "y": 7,
      "z": 32,
      "name": "Wood_Softwood_Roof_Steep"
    },
    {
      "x": -23,
      "y": 8,
      "z": 32,
      "name": "Wood_Softwood_Roof_Steep",
      "filler": 1024
    },
    {
      "x": -23,
      "y": 6,
      "z": 33,
      "name": "Wood_Softwood_Roof_Hollow"
    },
    {
      "x": -22,
      "y": 0,
      "z": 6,
      "name": "Rock_Stone_Brick"
    },
    {
      "x": -22,
      "y": 1,
      "z": 6,
      "name": "Rock_Stone_Cobble"
    },
    {
      "x": -22,
      "y": 2,
      "z": 6,
      "name": "Wood_Oak_Trunk",
      "support": 15,
      "rotation": 5
    },
    {
      "x": -22,
      "y": 3,
      "z": 6,
      "name": "Wood_Hardwood_Fence",
      "rotation": 2
    },
    {
      "x": -22,
      "y": 2,
      "z": 7,
      "name": "Rock_Stone_Cobble"
    },
    {
      "x": -22,
      "y": 2,
      "z": 8,
      "name": "Rock_Stone_Cobble"
    },
    {
      "x": -22,
      "y": 2,
      "z": 9,
      "name": "Rock_Stone_Cobble"
    },
    {
      "x": -22,
      "y": 6,
      "z": 9,
      "name": "Wood_Softwood_Roof_Hollow",
      "rotation": 2
    },
    {
      "x": -22,
      "y": 2,
      "z": 10,
      "name": "Wood_Oak_Trunk",
      "support": 15,
      "rotation": 5
    },
    {
      "x": -22,
      "y": 6,
      "z": 10,
      "name": "Wood_Oak_Trunk",
      "support": 15,
      "rotation": 5
    },
    {
      "x": -22,
      "y": 7,
      "z": 10,
      "name": "Wood_Softwood_Roof_Shallow",
      "rotation": 2
    },
    {
      "x": -22,
      "y": 2,
      "z": 11,
      "name": "Rock_Stone_Cobble"
    },
    {
      "x": -22,
      "y": 6,
      "z": 11,
      "name": "Wood_Softwood_Planks_Half",
      "rotation": 8
    },
    {
      "x": -22,
      "y": 7,
      "z": 11,
      "name": "Wood_Softwood_Roof_Shallow",
      "filler": 32,
      "rotation": 2
    },
    {
      "x": -22,
      "y": 2,
      "z": 12,
      "name": "Rock_Stone_Cobble"
    },
    {
      "x": -22,
      "y": 7,
      "z": 12,
      "name": "Wood_Softwood_Stairs",
      "rotation": 10
    },
    {
      "x": -22,
      "y": 8,
      "z": 12,
      "name": "Wood_Softwood_Roof_Shallow",
      "rotation": 2
    },
    {
      "x": -22,
      "y": 2,
      "z": 13,
      "name": "Rock_Stone_Cobble"
    },
    {
      "x": -22,
      "y": 8,
      "z": 13,
      "name": "Wood_Softwood_Roof_Shallow",
      "filler": 32,
      "rotation": 2
    },
    {
      "x": -22,
      "y": 2,
      "z": 14,
      "name": "Rock_Stone_Cobble"
    },
    {
      "x": -22,
      "y": 8,
      "z": 14,
      "name": "Wood_Softwood_Stairs",
      "rotation": 10
    },
    {
      "x": -22,
      "y": 9,
      "z": 14,
      "name": "Wood_Softwood_Roof_Flat",
      "rotation": 2
    },
    {
      "x": -22,
      "y": 2,
      "z": 15,
      "name": "Rock_Stone_Cobble"
    },
    {
      "x": -22,
      "y": 8,
      "z": 15,
      "name": "Wood_Softwood_Planks_Half",
      "rotation": 8
    },
    {
      "x": -22,
      "y": 9,
      "z": 15,
      "name": "Wood_Softwood_Roof_Shallow",
      "rotation": 2
    },
    {
      "x": -22,
      "y": 2,
      "z": 16,
      "name": "Rock_Stone_Cobble"
    },
    {
      "x": -22,
      "y": 9,
      "z": 16,
      "name": "Wood_Softwood_Roof_Shallow",
      "filler": 32,
      "rotation": 2
    },
    {
      "x": -22,
      "y": 2,
      "z": 17,
      "name": "Rock_Stone_Cobble"
    },
    {
      "x": -22,
      "y": 9,
      "z": 17,
      "name": "Wood_Softwood_Planks"
    },
    {
      "x": -22,
      "y": 10,
      "z": 17,
      "name": "Wood_Softwood_Planks_Half"
    },
    {
      "x": -22,
      "y": 2,
      "z": 18,
      "name": "Rock_Stone_Cobble"
    },
    {
      "x": -22,
      "y": 9,
      "z": 18,
      "name": "Wood_Softwood_Roof_Shallow",
      "filler": 992
    },
    {
      "x": -22,
      "y": 2,
      "z": 19,
      "name": "Rock_Stone_Cobble"
    },
    {
      "x": -22,
      "y": 3,
      "z": 19,
      "name": "Wood_Beech_Trunk",
      "support": 15,
      "rotation": 5
    },
    {
      "x": -22,
      "y": 8,
      "z": 19,
      "name": "Wood_Softwood_Planks_Half",
      "rotation": 8
    },
    {
      "x": -22,
      "y": 9,
      "z": 19,
      "name": "Wood_Softwood_Roof_Shallow"
    },
    {
      "x": -22,
      "y": 2,
      "z": 20,
      "name": "Rock_Stone_Cobble"
    },
    {
      "x": -22,
      "y": 3,
      "z": 20,
      "name": "Wood_Oak_Trunk",
      "support": 15,
      "rotation": 5
    },
    {
      "x": -22,
      "y": 8,
      "z": 20,
      "name": "Wood_Softwood_Stairs",
      "rotation": 8
    },
    {
      "x": -22,
      "y": 9,
      "z": 20,
      "name": "Wood_Softwood_Roof_Flat"
    },
    {
      "x": -22,
      "y": 2,
      "z": 21,
      "name": "Rock_Stone_Cobble"
    },
    {
      "x": -22,
      "y": 3,
      "z": 21,
      "name": "Wood_Ash_Trunk",
      "support": 15,
      "rotation": 5
    },
    {
      "x": -22,
      "y": 8,
      "z": 21,
      "name": "Wood_Softwood_Roof_Shallow",
      "filler": 992
    },
    {
      "x": -22,
      "y": 2,
      "z": 22,
      "name": "Rock_Stone_Cobble"
    },
    {
      "x": -22,
      "y": 7,
      "z": 22,
      "name": "Wood_Softwood_Stairs",
      "rotation": 8
    },
    {
      "x": -22,
      "y": 8,
      "z": 22,
      "name": "Wood_Softwood_Roof_Shallow"
    },
    {
      "x": -22,
      "y": 2,
      "z": 23,
      "name": "Rock_Stone_Cobble"
    },
    {
      "x": -22,
      "y": 6,
      "z": 23,
      "name": "Wood_Softwood_Planks_Half",
      "rotation": 8
    },
    {
      "x": -22,
      "y": 7,
      "z": 23,
      "name": "Wood_Softwood_Planks"
    },
    {
      "x": -22,
      "y": 8,
      "z": 23,
      "name": "Wood_Softwood_Roof_Flat"
    },
    {
      "x": -22,
      "y": 2,
      "z": 24,
      "name": "Rock_Stone_Cobble"
    },
    {
      "x": -22,
      "y": 6,
      "z": 24,
      "name": "Wood_Oak_Trunk",
      "support": 15,
      "rotation": 5
    },
    {
      "x": -22,
      "y": 7,
      "z": 24,
      "name": "Wood_Softwood_Planks"
    },
    {
      "x": -22,
      "y": 8,
      "z": 24,
      "name": "Wood_Softwood_Roof",
      "rotation": 2
    },
    {
      "x": -22,
      "y": 2,
      "z": 25,
      "name": "Rock_Stone_Cobble"
    },
    {
